{"id":"mbp-btcusdt","status":"ok","subbed":"market.btcusdt.mbp.150","ts":1784133636357}
{"ch":"market.btcusdt.mbp.150","ts":1784133636402,"tick":{"seqNum":191847885982,"prevSeqNum":191847885965,"bids":[[64855.69,0.0],[64855.65,0.0],[64790.98,0.228625],[64787.73,0.424587],[64784.49,0.78852],[64783.2,18.500348],[64627.41,0.310672],[64625.74,0.154219]],"asks":[[64855.54,0.023802],[64855.65,0.039628],[64855.66,0.023802],[64859.73,0.229398],[64859.74,0.0],[64899.87,0.087892],[64899.96,0.114314],[64903.2,0.212295],[64906.44,0.394259],[64907.74,9.252582],[64941.97,0.002309],[65087.71,0.0],[65090.17,0.0],[65090.18,0.0],[65097.53,0.0],[65105.25,0.0],[65111.81,0.0],[65112.27,0.0],[65115.78,0.0]]}}
{"id":"trd-btcusdt","status":"ok","subbed":"market.btcusdt.trade.detail","ts":1784133636413}
{"ch":"market.btcusdt.trade.detail","ts":1784133630547,"tick":{"id":191847884294,"ts":1784133630545,"data":[{"id":1918478842941642289150464334,"ts":1784133630545,"tradeId":103626665738,"amount":0.107271,"price":64849.69,"direction":"buy","isRpiTrade":false}]}}
{"ch":"market.btcusdt.mbp.150","ts":1784133636508,"tick":{"seqNum":191847886025,"prevSeqNum":191847885982,"bids":[[64814.91,2.252817],[64784.45,0.0],[64776.21,0.094834],[64774.73,0.0],[64771.49,0.0],[64770.19,0.0],[64769.73,0.094831],[64763.25,0.094839],[64761.95,17.645273],[64707.88,0.0],[64707.86,8.536114],[64620.68,2.7855711422844E-5],[64620.45,0.151456],[64618.7,5.268957227286E-6]],"asks":[[64865.97,0.493636],[64866.38,0.0],[64895.26,0.0],[64901.94,0.0],[64902.43,2.312832],[64906.35,0.087887],[64911.67,0.0],[64912.84,0.0],[64914.13,0.0],[64914.91,0.0],[64916.21,0.0],[65032.17,3.439562],[65087.71,0.020559],[65090.17,0.001807],[65090.18,0.03176],[65097.53,0.13629],[65105.25,1.72E-6]]}}
{"ch":"market.btcusdt.mbp.150","ts":1784133636635,"tick":{"seqNum":191847886063,"prevSeqNum":191847886025,"bids":[[64852.0,0.0],[64850.56,0.229398],[64824.61,0.67653],[64707.86,0.0],[64707.84,8.491343],[64618.7,0.0]],"asks":[[64902.43,6.938496],[65032.17,10.318686]]}}
{"ch":"market.btcusdt.mbp.150","ts":1784133636706,"tick":{"seqNum":191847886097,"prevSeqNum":191847886063,"bids":[[64834.36,0.397482],[64824.61,0.0],[64784.45,0.073244],[64774.73,0.07324],[64771.49,0.073238],[64770.19,0.073242],[64707.88,7.772207],[64707.84,0.0],[64705.36,0.154183],[64640.52,0.154183],[64629.25,0.0],[64627.55,0.0],[64627.41,0.0],[64625.74,0.0],[64620.68,0.0],[64620.45,0.0]],"asks":[[64901.94,0.073243],[64902.43,9.251328],[64911.67,0.073236],[64914.91,0.073244],[64916.21,0.073241],[64981.05,0.154183],[65045.9,0.154183],[65081.11,0.0],[65087.71,0.0],[65090.17,0.0],[65090.18,0.0],[65097.53,0.0],[65105.25,0.0]]}}
{"ch":"market.btcusdt.mbp.150","ts":1784133636820,"tick":{"seqNum":191847886141,"prevSeqNum":191847886097,"bids":[[64855.53,0.116447],[64834.36,0.0],[64834.35,0.362465],[64824.66,0.726059],[64707.88,0.0],[64707.83,7.826269],[64629.29,0.0]],"asks":[[64855.54,0.116447],[64855.65,0.0],[64855.7,0.024802],[64859.72,0.039628],[64902.43,0.0],[64932.37,0.0],[65032.17,0.0],[65081.11,0.113894],[65087.71,0.020559],[65090.17,0.001807]]}}
{"ch":"market.btcusdt.mbp.150","ts":1784133636963,"tick":{"seqNum":191847886158,"prevSeqNum":191847886141,"bids":[[64776.21,0.090204],[64769.73,0.090201],[64763.25,0.090207],[64761.95,5.939796]],"asks":[[64901.82,0.0],[64908.3,0.0],[64914.78,0.0],[64916.08,0.0],[64938.85,0.0],[64945.34,0.0],[64946.63,0.0],[65024.81,0.0],[65090.18,0.03176],[65097.53,0.13629],[65105.25,1.72E-6],[65110.75,0.154183],[65111.81,0.15982],[65112.27,3.084915],[65115.78,9.256316],[65117.08,0.142111]]}}
{"ch":"market.btcusdt.mbp.150","ts":1784133637048,"tick":{"seqNum":191847886165,"prevSeqNum":191847886158,"bids":[[64834.35,0.0],[64824.66,0.0],[64710.95,6.169983],[64707.83,0.0],[64629.29,0.135349],[64629.25,0.004892],[64627.55,0.109031]],"asks":[[64959.98,0.0],[65121.97,0.158121]]}}
{"ch":"market.btcusdt.mbp.150","ts":1784133637143,"tick":{"seqNum":191847886193,"prevSeqNum":191847886165,"bids":[[64776.21,0.092519],[64769.73,0.092516],[64763.25,0.092523],[64761.95,11.792531],[64707.83,7.425546],[64627.55,0.0]],"asks":[[64902.43,2.312832],[64914.78,0.00231],[64932.37,0.00231],[64938.85,0.002309],[64945.34,0.002309],[64946.63,5.852755],[65032.17,3.439562],[65105.25,0.0],[65110.75,0.0],[65111.81,0.0],[65112.27,0.0],[65115.78,0.0],[65117.08,0.0],[65121.97,0.0]]}}
{"ch":"market.btcusdt.mbp.150","ts":1784133637210,"tick":{"seqNum":191847886221,"prevSeqNum":191847886193,"bids":[[64776.21,0.094834],[64769.73,0.094831],[64763.25,0.094839],[64761.95,17.645258],[64707.83,0.0],[64627.55,0.109031]],"asks":[[64894.65,0.493636],[64901.82,0.002311],[64902.43,4.625664],[64908.3,0.00231],[64916.08,5.852738],[65032.17,6.879124],[65087.71,0.0],[65090.17,0.0],[65090.18,0.0],[65097.53,0.0]]}}
{"ch":"market.btcusdt.mbp.150","ts":1784133637339,"tick":{"seqNum":191847886238,"prevSeqNum":191847886221,"bids":[[64834.34,0.391935],[64824.64,0.77714],[64707.84,7.916044],[64629.29,0.0],[64629.25,0.0],[64627.55,0.0]],"asks":[[64902.43,6.938496],[64927.22,1.696077],[65081.11,0.0]]}}
{"ch":"market.btcusdt.mbp.150","ts":1784133637419,"tick":{"seqNum":191847886267,"prevSeqNum":191847886238,"bids":[[64834.34,0.0],[64758.38,0.002316],[64751.9,0.002316],[64745.41,0.002316],[64744.12,5.852729],[64629.29,0.135349]],"asks":[[64902.43,0.0],[65032.17,0.0],[65033.17,0.0],[65039.66,0.0],[65046.14,0.0],[65047.44,0.0],[65081.11,0.113894],[65087.71,0.020559],[65090.17,0.001807],[65090.18,0.03176],[65097.53,0.13629],[65105.25,1.72E-6]]}}
{"ch":"market.btcusdt.mbp.150","ts":1784133637503,"tick":{"seqNum":191847886292,"prevSeqNum":191847886267,"bids":[[64855.64,0.023802],[64834.36,0.380753],[64824.66,0.65225],[64824.64,0.0],[64707.83,7.686095],[64632.65,0.0],[64631.57,0.0],[64629.29,0.0]],"asks":[[64855.54,0.0],[64855.66,0.0],[64855.7,0.001],[64859.72,0.0],[64902.43,2.312832],[65032.17,3.439562],[65110.75,0.154183]]}}
{"ch":"market.btcusdt.mbp.150","ts":1784133637618,"tick":{"seqNum":191847886325,"prevSeqNum":191847886292,"bids":[[64855.69,0.023802],[64855.53,0.092645],[64834.36,0.0],[64834.33,0.382756],[64824.66,0.0],[64824.62,0.695505],[64776.21,0.006945],[64769.73,0.006945],[64763.25,0.006948],[64761.95,17.557368],[64707.84,0.0],[64707.83,0.0],[64707.82,8.147597]],"asks":[[64855.7,0.093645],[64859.72,0.039628],[64859.73,0.0],[64893.38,0.0],[64899.87,0.0],[64902.43,4.625658],[64906.35,0.0],[64907.65,0.0],[64927.22,1.696073],[65032.17,6.879134],[65111.81,0.15982],[65112.27,3.084915],[65115.78,9.256316],[65117.08,0.142111]]}}
{"ch":"market.btcusdt.mbp.150","ts":1784133637720,"tick":{"seqNum":191847886359,"prevSeqNum":191847886325,"bids":[[64814.91,0.0],[64758.38,0.004632],[64751.9,0.004632],[64745.41,0.004632],[64744.12,11.705462],[64708.35,0.0],[64692.37,5.95331],[64643.53,0.0],[64632.65,3.7037037037037E-4],[64631.57,3.8917835671342E-5],[64629.29,0.135349]],"asks":[[64859.72,0.0],[64859.74,0.039628],[64902.43,0.0],[64961.7,0.0],[64985.92,0.0],[65026.53,0.0],[65032.17,0.0],[65033.17,0.002306],[65039.66,0.002306],[65046.14,0.002306],[65047.44,5.852765],[65050.75,0.0],[65121.97,0.158121],[65124.49,0.143528]]}}
{"ch":"market.btcusdt.mbp.150","ts":1784133637805,"tick":{"seqNum":191847886399,"prevSeqNum":191847886359,"bids":[[64834.34,0.420805],[64834.33,0.0],[64824.62,0.0],[64824.61,0.701516],[64814.92,2.352395],[64814.87,0.0],[64790.98,0.114313],[64787.73,0.212293],[64784.49,0.394261],[64783.2,9.250388],[64776.21,0.094833],[64769.73,0.094837],[64763.25,0.094834],[64761.95,17.64526],[64707.83,8.153588],[64707.82,0.0],[64692.37,2.867872]],"asks":[[64893.38,0.08789],[64893.47,0.0],[64896.71,0.0],[64899.87,0.087888],[64899.95,0.0],[64901.25,0.0],[64902.43,2.312826],[64906.35,0.08789],[64907.65,0.087894],[64914.53,0.0],[64964.3,0.0],[65029.12,0.0],[65032.17,3.439572],[65130.26,0.004892]]}}
{"ch":"market.btcusdt.mbp.150","ts":1784133637921,"tick":{"seqNum":191847886463,"prevSeqNum":191847886399,"bids":[[64834.34,0.0],[64824.65,0.734624],[64824.61,0.0],[64814.85,2.411199],[64790.98,0.0],[64790.67,0.0],[64788.31,0.0],[64787.73,0.0],[64787.43,0.0],[64785.07,0.0],[64784.49,0.0],[64784.19,0.0],[64783.2,0.0],[64782.89,0.0],[64781.82,0.0],[64780.53,0.0],[64707.87,7.82619],[64629.25,0.004892],[64627.41,0.310672],[64625.74,0.154219],[64620.68,2.7855711422844E-5],[64620.45,0.151456],[64618.7,5.268957227286E-6],[64617.55,0.030837],[64615.53,0.142918],[64614.47,18.506289],[64613.88,0.138342],[64611.59,2.7755511022044E-4]],"asks":[[64899.96,0.0],[64902.43,4.625652],[64903.2,0.0],[64906.44,0.0],[64906.75,0.0],[64907.74,0.0],[64909.99,0.0],[64913.0,0.0],[64913.23,0.0],[64916.25,0.0],[64919.49,0.0],[64920.78,0.0],[65032.17,6.879144],[65131.9,0.34],[65136.78,0.167526],[65136.98,0.13388],[65137.84,0.020559],[65138.03,0.009655],[65150.0,0.00349055],[65150.3,0.03176],[65165.16,0.05617],[65177.11,9.253181],[65180.6,0.850331],[65183.48,2.03E-6]]}}
{"ch":"market.btcusdt.mbp.150","ts":1784133638036,"tick":{"seqNum":191847886515,"prevSeqNum":191847886463,"bids":[[64855.69,0.0],[64855.64,0.0],[64834.35,0.379804],[64824.65,0.0],[64814.92,2.315971],[64814.85,0.0],[64710.95,0.0],[64707.87,0.0],[64707.83,0.0],[64707.82,7.92418],[64646.12,0.0],[64609.21,0.03176],[64606.49,2.19559339008512E-4],[64600.0,0.005080013383674088],[64599.9,0.45],[64598.1,0.030837],[64594.96,1.603206412825E-6]],"asks":[[64855.54,0.023802],[64855.64,0.039628],[64855.65,0.023802],[64855.7,0.117447],[64859.74,0.0],[64902.43,2.312826],[64927.22,0.0],[64953.49,0.0],[65018.32,0.0],[65032.17,3.439572],[65165.16,0.027253],[65187.56,4.78E-6]]}}
{"ch":"market.btcusdt.mbp.150","ts":1784133638118,"tick":{"seqNum":191847886561,"prevSeqNum":191847886515,"bids":[[64834.35,0.0],[64824.66,0.646202],[64814.92,0.0],[64790.98,0.114314],[64790.67,0.114314],[64788.31,0.04001],[64787.73,0.212295],[64787.43,0.212292],[64785.07,0.074302],[64784.49,0.394258],[64784.19,0.394258],[64783.2,9.252437],[64782.89,9.252769],[64781.82,0.13799],[64780.53,9.250509],[64718.36,6.169031],[64707.83,7.12189],[64707.82,0.0],[64653.52,0.657974],[64620.45,0.0],[64618.7,0.0],[64617.55,0.0],[64615.53,0.0],[64614.47,0.0],[64613.88,0.0],[64611.59,0.0],[64609.21,0.0],[64606.49,0.0],[64600.0,0.0],[64599.9,0.0],[64598.1,0.0],[64594.96,0.0]],"asks":[[64893.47,0.114313],[64896.71,0.212295],[64899.95,0.394259],[64901.25,9.252437],[64902.43,4.625658],[64906.44,0.394261],[64906.75,0.114314],[64909.99,0.212293],[64913.0,0.040012],[64913.23,0.39426],[64914.53,9.252769],[64916.25,0.074302],[64919.49,0.137993],[64920.79,9.250509],[64927.22,1.696077],[64966.09,6.169031],[65030.94,3.854436],[65032.17,6.879134],[65117.08,0.0],[65121.97,0.0],[65124.49,0.0],[65130.26,0.0],[65131.9,0.0],[65136.78,0.0],[65136.98,0.0],[65137.84,0.0],[65138.03,0.0],[65150.0,0.0],[65150.3,0.0],[65165.16,0.0],[65177.11,0.0],[65180.6,0.0],[65183.48,0.0],[65187.56,0.0]]}}
{"ch":"market.btcusdt.mbp.150","ts":1784133638234,"tick":{"seqNum":191847886593,"prevSeqNum":191847886561,"bids":[[64855.53,0.023802],[64790.98,0.228628],[64787.73,0.42459],[64784.49,0.788518],[64783.2,18.505019],[64776.21,0.092518],[64769.73,0.092522],[64763.25,0.092518],[64761.95,11.793354],[64758.38,0.002316],[64751.9,0.002316],[64745.41,0.002316],[64744.12,5.852733],[64718.36,11.142798]],"asks":[[64855.7,0.024802],[64899.96,0.114314],[64902.46,0.0],[64903.2,0.212293],[64907.74,9.252582],[64908.95,0.0],[64915.43,0.0],[64916.73,0.0],[64927.22,0.0],[64935.48,0.0],[64941.97,0.0],[64948.45,0.0],[64949.75,0.0],[64972.58,6.169031],[65037.42,3.852391],[65117.08,0.142111],[65121.97,0.158121],[65124.49,0.143528],[65130.26,0.004892]]}}
{"ch":"market.btcusdt.mbp.150","ts":1784133638331,"tick":{"seqNum":191847886639,"prevSeqNum":191847886593,"bids":[[64824.66,0.0],[64814.92,2.497562],[64808.91,0.00162],[64784.45,0.0],[64774.73,0.0],[64771.49,0.0],[64770.19,0.0],[64707.83,8.294419],[64620.45,0.151456],[64618.7,5.268957227286E-6],[64617.55,0.030837]],"asks":[[64855.54,0.0],[64901.94,0.0],[64902.43,2.312832],[64911.67,0.0],[64914.91,0.0],[64916.21,0.0],[65032.17,3.439562],[65131.9,0.34],[65136.78,0.167526],[65136.98,0.13388],[65137.84,0.020559],[65138.03,0.009655]]}}
{"ch":"market.btcusdt.mbp.150","ts":1784133638418,"tick":{"seqNum":191847886671,"prevSeqNum":191847886639,"bids":[[64855.69,0.023802],[64855.63,0.2532],[64854.34,0.092645],[64814.89,2.266153],[64707.83,0.0],[64692.37,0.0],[64618.7,0.0],[64617.55,0.0]],"asks":[[64855.64,0.0],[64855.65,0.0],[64855.7,0.001],[64859.74,0.039628],[64902.43,4.62566],[64902.47,0.002311],[64927.22,1.696073],[64994.2,0.0],[65032.17,6.879132],[65059.02,0.0],[65150.0,0.00349055]]}}
{"ch":"market.btcusdt.mbp.150","ts":1784133638503,"tick":{"seqNum":191847886694,"prevSeqNum":191847886671,"bids":[[64776.21,0.094833],[64769.73,0.094837],[64763.25,0.094834],[64761.95,17.646084],[64758.38,0.004632],[64751.89,0.002316],[64745.41,0.004632],[64744.12,11.705468],[64697.13,3.084915],[64632.3,0.10873],[64625.74,0.0],[64620.68,0.0],[64620.45,0.0]],"asks":[[64861.29,0.0],[64866.25,0.0],[64868.9,0.0],[64908.95,0.00231],[64910.07,0.0],[64915.43,0.00231],[64916.73,5.85275],[64935.49,0.002309],[64941.97,0.002309],[64948.45,0.002309],[64949.75,5.852752],[64981.57,1.610919],[65046.41,0.002316],[65136.78,0.0],[65136.98,0.0],[65137.84,0.0],[65138.03,0.0],[65150.0,0.0]]}}
{"ch":"market.btcusdt.mbp.150","ts":1784133638615,"tick":{"seqNum":191847886738,"prevSeqNum":191847886694,"bids":[[64855.69,0.645606],[64854.34,0.0],[64850.55,0.0],[64815.92,0.493636],[64814.92,0.0],[64814.89,0.0],[64813.92,0.0],[64808.9,0.0],[64785.45,0.073237],[64775.73,0.073241],[64772.49,0.07324],[64771.19,0.073195],[64625.74,0.154219]],"asks":[[64872.8,0.0],[64886.91,0.0],[64891.86,3.53794],[64896.55,0.0],[64902.42,0.229398],[64902.43,0.0],[64902.94,0.073241],[64912.67,0.073245],[64915.91,0.073241],[64917.21,0.073242],[64922.99,7.783486],[64927.22,0.0],[64973.18,0.0],[64995.64,4.688854],[65032.17,0.0],[65131.9,0.0]]}}
{"ch":"market.btcusdt.mbp.150","ts":1784133638748,"tick":{"seqNum":191847886762,"prevSeqNum":191847886738,"bids":[[64836.39,0.423516],[64826.62,1.222208],[64816.87,1.927692],[64815.92,0.0],[64788.12,0.0],[64784.88,0.0],[64781.64,0.0],[64780.34,0.0],[64709.86,7.857079],[64620.68,2.7855711422844E-5]],"asks":[[64902.73,0.008117],[64904.44,2.312826],[64926.17,0.0],[64929.22,1.696073],[64929.41,0.0],[64932.65,0.028253],[64933.95,0.0],[65034.18,3.439572],[65130.26,0.0]]}}
{"ch":"market.btcusdt.mbp.150","ts":1784133638810,"tick":{"seqNum":191847886777,"prevSeqNum":191847886762,"bids":[[64845.59,0.493636],[64818.97,1.161405],[64792.43,0.0],[64778.73,0.002315],[64772.25,0.002315],[64765.77,0.002316],[64764.47,5.852737],[64699.64,2.587826],[64631.57,0.0],[64629.29,0.0],[64629.25,0.0],[64627.41,0.0],[64625.74,0.0],[64620.68,0.0]],"asks":[[64877.84,1.160351],[64902.15,0.002311],[64908.64,0.00231],[64915.12,0.00231],[64916.42,5.852746],[64981.26,0.002316],[65046.1,0.00232],[65110.75,0.0],[65111.81,0.0],[65112.27,0.0],[65115.78,0.0],[65117.08,0.0],[65121.97,0.0],[65124.49,0.0]]}}
{"ch":"market.btcusdt.mbp.150","ts":1784133638952,"tick":{"seqNum":191847886813,"prevSeqNum":191847886777,"bids":[[64855.69,0.738251],[64836.93,0.359485],[64836.39,0.0],[64835.75,0.0],[64827.17,1.175305],[64826.62,0.0],[64822.15,0.006831],[64817.43,1.711525],[64816.87,0.0],[64808.45,0.017077],[64806.12,0.0],[64710.45,8.350377],[64709.86,0.0]],"asks":[[64904.44,0.0],[64905.01,2.312826],[64929.22,0.0],[64929.79,1.696073],[64934.18,0.04001],[65034.18,0.0],[65034.75,3.439572],[65105.25,0.0]]}}
{"ch":"market.btcusdt.mbp.150","ts":1784133639003,"tick":{"seqNum":191847886825,"prevSeqNum":191847886813,"bids":[[64790.11,0.040009],[64786.87,0.074303],[64783.63,0.137993],[64782.33,9.253051],[64717.49,6.168555],[64652.65,1.672339],[64637.0,0.0],[64636.59,0.0],[64635.79,0.0],[64632.95,0.0],[64632.65,0.0],[64632.3,0.0]],"asks":[[64908.3,0.0],[64937.43,0.074303],[64940.67,0.137992],[64941.96,9.253051],[65006.82,6.168555],[65071.67,4.325307],[65087.71,0.0],[65090.17,0.0],[65090.18,0.0],[65097.53,0.0]]}}
{"ch":"market.btcusdt.mbp.150","ts":1784133639121,"tick":{"seqNum":191847886854,"prevSeqNum":191847886825,"bids":[[64827.17,0.0],[64776.21,0.090203],[64769.73,0.090207],[64763.25,0.090202],[64761.95,5.940622],[64690.55,0.0],[64637.0,0.030837],[64636.59,0.020559]],"asks":[[64875.85,0.0],[64886.55,0.0],[64891.85,0.229398],[64901.82,0.0],[64909.85,0.0],[64914.78,0.0],[64916.08,0.0],[64932.37,0.0],[64938.85,0.0],[64945.34,0.0],[64946.63,0.0],[64967.86,0.0],[65032.7,0.0],[65081.11,0.0],[65087.71,0.020559],[65090.17,0.001807],[65090.18,0.03176],[65105.25,1.72E-6],[65110.75,0.154183],[65111.81,0.15982],[65112.27,3.084915],[65115.78,9.256316],[65117.08,0.142111],[65124.49,0.143528],[65127.54,0.164751],[65130.26,0.004892]]}}
{"ch":"market.btcusdt.mbp.150","ts":1784133639202,"tick":{"seqNum":191847886895,"prevSeqNum":191847886854,"bids":[[64836.93,0.0],[64836.89,0.388425],[64827.21,1.070019],[64817.49,1.896428],[64817.45,2.239778],[64817.43,0.0],[64710.45,0.0],[64710.4,8.248573],[64637.0,0.0],[64636.59,0.0]],"asks":[[64891.17,0.002725],[64929.79,0.0],[64949.82,0.029002],[65093.64,0.122878],[65127.54,0.0],[65130.26,0.0]]}}
{"ch":"market.btcusdt.mbp.150","ts":1784133639313,"tick":{"seqNum":191847886939,"prevSeqNum":191847886895,"bids":[[64855.69,0.714449],[64855.63,0.229398],[64855.53,0.0],[64836.95,0.387259],[64836.89,0.0],[64827.21,0.0],[64827.18,0.937352],[64817.49,2.209407],[64817.45,0.0],[64778.73,0.00463],[64772.25,0.00463],[64765.77,0.004632],[64764.47,11.705475],[64710.42,7.502318],[64710.4,0.0],[64637.0,0.030837],[64636.59,0.020559]],"asks":[[64855.7,0.024802],[64865.36,0.620904],[64868.91,0.229398],[64878.42,0.077067],[64904.1,0.002311],[64905.01,6.938478],[64910.58,0.00231],[64917.07,0.00231],[64918.36,2.927549],[64929.79,1.696073],[65034.75,10.318716],[65093.64,0.0],[65105.25,0.0],[65110.75,0.0],[65111.81,0.0],[65112.27,0.0],[65115.78,0.0],[65117.08,0.0],[65124.49,0.0]]}}
{"ch":"market.btcusdt.mbp.150","ts":1784133639407,"tick":{"seqNum":191847886954,"prevSeqNum":191847886939,"bids":[[64814.58,0.493636],[64778.73,0.006945],[64772.25,0.006945],[64765.77,0.006948],[64764.47,17.558206],[64699.64,5.672627],[64636.59,0.0]],"asks":[[64934.65,0.00231],[64941.14,0.002309],[64947.62,0.002309],[64948.92,4.39015],[65013.76,0.002315],[65079.42,0.0],[65080.59,0.0],[65087.71,0.0],[65090.17,0.0],[65090.18,0.0]]}}
{"ch":"market.btcusdt.mbp.150","ts":1784133639512,"tick":{"seqNum":191847886984,"prevSeqNum":191847886954,"bids":[[64855.69,0.738251],[64836.95,0.0],[64827.18,0.0],[64636.59,0.020559],[64635.79,1.27254509018E-6]],"asks":[[64855.7,0.001],[64905.01,2.312826],[64929.79,0.0],[65034.75,0.0],[65078.6,0.002322],[65079.42,9.253108]]}}
{"ch":"market.btcusdt.mbp.150","ts":1784133639620,"tick":{"seqNum":191847887026,"prevSeqNum":191847886984,"bids":[[64836.89,0.386676],[64827.16,0.964523],[64817.47,2.04992],[64790.98,0.114314],[64787.73,0.212295],[64784.49,0.39426],[64783.2,9.252582],[64710.42,0.0],[64636.59,0.0],[64635.79,0.0]],"asks":[[64893.47,0.0],[64896.71,0.0],[64899.95,0.0],[64901.25,0.0],[64905.01,4.625652],[64929.79,1.696073],[65034.75,6.879144],[65080.59,12.337039],[65087.71,0.020559]]}}
{"ch":"market.btcusdt.mbp.150","ts":1784133639723,"tick":{"seqNum":191847887031,"prevSeqNum":191847887026,"bids":[[64836.89,0.0],[64827.16,0.0],[64763.25,0.002316],[64636.59,0.020559],[64635.79,1.27254509018E-6]],"asks":[[64855.7,0.024802],[64929.79,0.0],[65090.17,0.001807]]}}
{"ch":"market.btcusdt.mbp.150","ts":1784133639804,"tick":{"seqNum":191847887095,"prevSeqNum":191847887031,"bids":[[64836.89,0.352076],[64827.15,1.051185],[64790.98,0.0],[64790.67,0.0],[64787.73,0.0],[64787.43,0.0],[64784.49,0.0],[64784.19,0.0],[64783.2,0.0],[64782.89,0.0],[64776.21,0.002315],[64769.73,0.002315],[64761.95,5.85273],[64710.42,8.402006],[64634.81,0.199763],[64632.95,2.1232464929859E-5],[64632.65,3.7037037037037E-4],[64632.3,0.10873],[64631.57,3.8917835671342E-5]],"asks":[[64893.38,0.0],[64899.87,0.0],[64899.96,0.0],[64903.2,0.0],[64905.01,0.0],[64906.35,0.0],[64906.44,0.0],[64906.75,0.0],[64907.65,0.0],[64907.74,0.0],[64909.99,0.0],[64913.23,0.0],[64914.53,0.0],[64929.79,1.696073],[65033.17,0.0],[65034.75,0.0],[65090.18,0.03176],[65093.64,0.122878],[65105.25,1.72E-6],[65110.75,0.154183],[65111.81,0.15982],[65112.27,3.084915],[65115.78,9.256316],[65117.08,0.142111],[65124.49,0.143528],[65127.54,0.164751],[65130.26,0.004892],[65131.9,0.34],[65136.78,0.167526],[65136.98,0.13388]]}}
{"ch":"market.btcusdt.mbp.150","ts":1784133639936,"tick":{"seqNum":191847887111,"prevSeqNum":191847887095,"bids":[[64852.01,0.0],[64792.7,0.114314],[64789.46,0.212293],[64786.22,0.394259],[64784.92,9.251168],[64758.38,0.002316],[64751.9,0.0],[64745.41,0.002316],[64744.12,5.852735],[64632.3,0.0],[64631.57,0.0]],"asks":[[64901.75,0.114312],[64904.99,0.212295],[64908.23,0.394259],[64909.53,9.252437],[65039.66,0.0],[65046.14,0.0],[65047.44,0.0],[65136.98,0.0]]}}
{"ch":"market.btcusdt.mbp.150","ts":1784133640014,"tick":{"seqNum":191847887130,"prevSeqNum":191847887111,"bids":[[64850.57,6.1E-5],[64836.89,0.0],[64827.15,0.0],[64778.73,0.094834],[64772.25,0.094834],[64765.77,0.094842],[64764.47,17.646098],[64699.64,5.826846],[64695.35,0.0],[64634.81,0.353982],[64632.3,0.10873],[64631.57,3.8917835671342E-5]],"asks":[[64895.67,0.087894],[64902.15,0.090197],[64908.63,0.08789],[64909.93,0.087888],[64929.79,0.0],[64974.77,0.154219],[65039.61,0.154219],[65104.45,0.136335],[65124.49,0.0],[65127.54,0.0],[65130.26,0.0],[65131.9,0.0],[65136.78,0.0]]}}
{"ch":"market.btcusdt.mbp.150","ts":1784133640119,"tick":{"seqNum":191847887188,"prevSeqNum":191847887130,"bids":[[64827.22,0.884196],[64798.88,0.030837],[64796.49,0.0],[64792.7,0.342939],[64789.46,0.636883],[64786.22,1.182778],[64784.92,27.753082],[64772.3,0.030837],[64769.91,0.0],[64760.9,0.002316],[64754.41,0.002316],[64747.93,0.002316],[64746.63,5.852726],[64730.16,0.030837],[64727.76,0.0],[64717.19,0.030837],[64714.8,0.0],[64710.44,7.806602],[64697.74,0.030837],[64678.29,0.030837],[64675.9,0.0],[64658.84,0.030837],[64656.45,0.0],[64639.39,0.030837],[64637.0,0.0],[64636.59,0.0],[64635.79,0.0],[64634.81,0.0],[64632.95,0.0],[64632.65,0.0],[64632.3,0.0],[64631.57,0.0]],"asks":[[64905.01,2.312826],[64908.23,0.508573],[64911.48,0.212293],[64914.72,0.508569],[64916.02,9.252582],[64917.96,0.212294],[64921.21,0.394261],[64922.5,9.25048],[64929.79,1.696073],[65034.75,3.439572],[65035.46,0.002306],[65041.94,0.002306],[65048.43,0.002305],[65049.72,5.852764],[65079.42,0.0],[65080.59,0.0],[65087.71,0.0],[65090.17,0.0],[65090.18,0.0],[65093.64,0.0],[65104.45,0.0],[65105.25,0.0],[65110.75,0.0],[65111.81,0.0],[65112.27,0.0],[65115.78,0.0],[65117.08,0.0]]}}
{"ch":"market.btcusdt.mbp.150","ts":1784133640221,"tick":{"seqNum":191847887215,"prevSeqNum":191847887188,"bids":[[64836.9,0.375154],[64827.22,0.0],[64785.45,0.0],[64775.73,0.0],[64772.49,0.0],[64771.19,0.0],[64710.44,0.0],[64710.42,0.0],[64710.41,8.210942],[64636.59,0.020559],[64635.79,1.27254509018E-6],[64634.81,0.353982],[64632.95,2.1232464929859E-5],[64632.65,3.7037037037037E-4]],"asks":[[64902.94,0.0],[64905.01,4.625652],[64912.67,0.0],[64915.91,0.0],[64917.21,0.0],[65034.75,6.879144],[65079.42,9.253108],[65080.59,12.337039],[65087.71,0.020559],[65090.17,0.001807]]}}
{"ch":"market.btcusdt.mbp.150","ts":1784133640316,"tick":{"seqNum":191847887228,"prevSeqNum":191847887215,"bids":[[64836.9,0.0],[64827.21,1.022728],[64788.31,0.0],[64785.07,0.0],[64781.82,0.0],[64780.53,0.0],[64632.3,0.10873],[64631.57,3.8917835671342E-5],[64629.29,0.135349],[64629.25,0.004892]],"asks":[[64886.0,0.0],[64913.0,0.0],[64916.25,0.0],[64919.49,0.0],[64920.79,0.0],[64929.79,0.0],[65090.18,0.03176],[65093.64,0.122878],[65104.45,0.136335],[65105.25,1.72E-6],[65110.75,0.154183],[65111.81,0.15982]]}}
{"ch":"market.btcusdt.mbp.150","ts":1784133640431,"tick":{"seqNum":191847887301,"prevSeqNum":191847887228,"bids":[[64827.21,0.0],[64776.21,0.0],[64769.73,0.0],[64763.25,0.0],[64761.95,0.0],[64758.38,0.0],[64751.89,0.0],[64745.41,0.0],[64744.12,0.0],[64718.06,0.0],[64710.41,0.0],[64710.4,8.550506],[64627.41,0.310672],[64620.68,2.7855711422844E-5],[64620.45,0.151456],[64619.94,0.030837],[64618.7,5.268957227286E-6],[64615.53,0.142918],[64614.47,18.506289],[64613.88,0.138342],[64611.59,2.7755511022044E-4],[64609.21,0.03176]],"asks":[[64902.47,0.0],[64905.01,2.312826],[64908.95,0.0],[64915.43,0.0],[64916.73,0.0],[64935.49,0.0],[64941.97,0.0],[64948.45,0.0],[64949.75,0.0],[65034.75,3.439572],[65112.27,3.084915],[65115.78,9.256316],[65117.08,0.142111],[65124.49,0.143528],[65127.54,0.164751],[65130.26,0.004892],[65131.9,0.34],[65136.78,0.167526]]}}
{"ch":"market.btcusdt.mbp.150","ts":1784133640540,"tick":{"seqNum":191847887327,"prevSeqNum":191847887301,"bids":[[64836.94,0.356356],[64827.18,0.922411],[64790.11,0.080018],[64789.45,0.073242],[64779.72,0.073242],[64776.48,0.073241],[64775.19,0.073186],[64710.42,7.658438],[64710.4,0.0],[64618.7,0.0],[64615.53,0.0],[64614.47,0.0],[64613.88,0.0],[64611.59,0.0],[64609.21,0.0]],"asks":[[64905.01,4.625652],[64906.94,0.073242],[64916.67,0.073245],[64919.91,0.073243],[64921.21,0.4675],[64929.79,1.696073],[64979.37,0.0],[65034.75,6.879144],[65044.21,0.0],[65131.9,0.0],[65136.78,0.0]]}}
{"ch":"market.btcusdt.mbp.150","ts":1784133640607,"tick":{"seqNum":191847887343,"prevSeqNum":191847887327,"bids":[[64786.87,0.148606],[64785.26,0.002315],[64783.63,0.275984],[64782.33,18.50356],[64778.78,0.002315],[64772.3,0.033152],[64771.0,5.852396],[64627.41,0.0],[64620.45,0.0],[64619.94,0.0]],"asks":[[64898.2,0.002311],[64904.69,0.002311],[64911.17,0.00231],[64912.47,3.086044],[64921.21,0.507511],[64924.45,0.074303],[64927.69,0.137993],[64928.99,9.250509],[65111.81,0.0],[65112.27,0.0],[65115.78,0.0],[65117.08,0.0],[65124.49,0.0],[65127.54,0.0],[65130.26,0.0]]}}
{"ping":1784133640666}
{"ch":"market.btcusdt.mbp.150","ts":1784133640702,"tick":{"seqNum":191847887391,"prevSeqNum":191847887343,"bids":[[64836.96,0.41388],[64836.94,0.0],[64827.2,0.926614],[64827.18,0.0],[64767.43,0.002315],[64760.94,0.002316],[64754.46,0.002316],[64753.16,5.85273],[64738.11,0.0],[64731.62,0.0],[64725.14,0.014644],[64718.66,0.0],[64712.17,0.139076],[64710.43,8.858363],[64710.42,0.0],[64692.23,0.0]],"asks":[[64865.36,0.0],[64905.01,0.0],[64924.99,0.0],[64929.79,0.0],[64931.22,0.00231],[64931.48,0.0],[64937.7,0.002309],[64937.96,0.0],[64944.19,0.002309],[64944.44,0.0],[64945.48,5.852759],[64950.93,0.0],[64974.81,0.0],[65034.75,0.0],[65039.64,0.0],[65111.81,0.15982],[65112.27,3.084915],[65115.78,9.256316],[65117.08,0.142111],[65124.49,0.143528],[65127.54,0.164751],[65130.26,0.004892]]}}
{"ch":"market.btcusdt.mbp.150","ts":1784133640801,"tick":{"seqNum":191847887411,"prevSeqNum":191847887391,"bids":[[64836.96,0.0],[64827.2,0.0],[64778.73,0.092519],[64772.25,0.092519],[64765.77,0.092526],[64764.47,11.793361],[64710.43,0.0],[64620.45,0.151456],[64619.94,0.030837],[64618.7,5.268957227286E-6]],"asks":[[64865.81,0.620904],[64902.15,0.087886],[64905.01,4.625652],[64908.64,0.0],[64915.12,0.0],[64916.42,0.0],[65034.75,3.439572]]}}
{"ch":"market.btcusdt.mbp.150","ts":1784133640920,"tick":{"seqNum":191847887442,"prevSeqNum":191847887411,"bids":[[64836.91,0.414239],[64710.4,8.604316],[64710.39,7.602505],[64620.45,0.0],[64619.94,0.0],[64618.7,0.0]],"asks":[[64905.01,6.938478],[64929.79,1.696073],[65034.75,10.318716],[65130.26,0.0]]}}
{"ch":"market.btcusdt.mbp.150","ts":1784133641012,"tick":{"seqNum":191847887495,"prevSeqNum":191847887442,"bids":[[64836.96,0.417665],[64836.91,0.0],[64827.16,0.996796],[64740.5,0.009766],[64734.02,0.030087],[64727.54,0.092717],[64721.05,0.285719],[64714.57,12.337039],[64710.4,0.0],[64710.39,0.0],[64631.57,0.0],[64629.29,0.0],[64629.25,0.0],[64620.68,0.0]],"asks":[[64855.7,0.001],[64905.01,2.312826],[64927.4,0.009766],[64933.88,0.030089],[64940.36,0.092716],[64946.85,0.285716],[64953.33,12.337039],[65034.75,3.439572],[65112.27,0.0],[65115.78,0.0],[65117.08,0.0],[65124.49,0.0],[65127.54,0.0]]}}
{"ch":"market.btcusdt.mbp.150","ts":1784133641132,"tick":{"seqNum":191847887524,"prevSeqNum":191847887495,"bids":[[64836.96,0.0],[64827.16,0.0],[64785.26,0.00463],[64778.78,0.00463],[64772.3,0.035467],[64771.0,11.704821],[64710.44,7.296042],[64699.2,0.0],[64631.57,3.8917835671342E-5],[64629.29,0.135349]],"asks":[[64895.61,0.002311],[64902.09,0.002311],[64905.01,4.625652],[64908.58,0.00231],[64909.87,4.097698],[65034.75,6.879144],[65104.45,0.0],[65105.25,0.0],[65110.75,0.0],[65111.81,0.0]]}}
{"ch":"market.btcusdt.mbp.150","ts":1784133641213,"tick":{"seqNum":191847887534,"prevSeqNum":191847887524,"bids":[[64778.73,0.090204],[64725.14,0.0],[64718.65,0.0],[64712.17,0.0],[64705.69,0.0],[64629.25,0.004892],[64620.68,2.7855711422844E-5],[64620.45,0.151456],[64619.94,0.030837]],"asks":[[65036.06,0.0],[65042.54,0.0],[65049.03,0.0],[65055.51,0.0],[65061.99,0.0],[65104.45,0.136335],[65105.25,1.72E-6],[65110.75,0.154183],[65111.81,0.15982],[65112.27,3.084915]]}}
{"ch":"market.btcusdt.mbp.150","ts":1784133641325,"tick":{"seqNum":191847887560,"prevSeqNum":191847887534,"bids":[[64827.21,0.925921],[64772.25,0.090204],[64765.77,0.09021],[64764.47,5.940623],[64619.94,0.0]],"asks":[[64904.1,0.0],[64905.01,0.0],[64910.58,0.0],[64917.07,0.0],[64918.36,0.0],[64929.79,0.0],[65034.75,0.0],[65115.78,9.256316],[65117.08,0.142111],[65124.49,0.143528],[65127.54,0.164751],[65130.26,0.004892],[65131.9,0.34],[65136.78,0.167526]]}}
{"ch":"market.btcusdt.mbp.150","ts":1784133641420,"tick":{"seqNum":191847887607,"prevSeqNum":191847887560,"bids":[[64836.94,0.403999],[64827.21,0.0],[64778.73,0.087889],[64772.25,0.087889],[64765.77,0.087894],[64764.47,0.087892],[64727.53,0.014645],[64721.05,0.33085],[64714.56,0.139074],[64710.44,0.0],[64710.4,8.596436],[64708.08,0.428576],[64701.6,8.469632],[64629.29,0.0],[64629.25,0.0],[64620.68,0.0],[64620.45,0.0]],"asks":[[64905.01,4.625652],[64929.79,1.696073],[64934.65,0.0],[64941.14,0.0],[64947.62,0.0],[64948.92,0.0],[65034.75,6.879144],[65038.47,0.014646],[65044.96,0.045131],[65051.44,0.139075],[65057.92,0.428574],[65064.41,13.879188],[65127.54,0.0],[65130.26,0.0],[65131.9,0.0],[65136.78,0.0]]}}
{"ch":"market.btcusdt.mbp.150","ts":1784133641504,"tick":{"seqNum":191847887635,"prevSeqNum":191847887607,"bids":[[64855.69,0.714449],[64855.63,0.0],[64836.94,0.0],[64790.11,0.040009],[64786.87,0.074303],[64785.26,0.006945],[64783.63,0.137991],[64782.33,9.250509],[64778.78,0.006945],[64772.3,0.037782],[64771.0,17.557558],[64710.4,0.0],[64706.16,3.084801],[64641.33,0.309918],[64629.29,0.135349]],"asks":[[64855.7,0.024802],[64865.8,0.229398],[64897.56,0.002311],[64904.04,0.002311],[64908.23,0.394259],[64910.52,0.00231],[64911.82,4.39015],[64929.79,0.0],[64934.18,0.0],[64937.43,0.0],[64940.67,0.0],[64941.96,0.0],[64976.65,0.002317],[65041.49,0.002318],[65117.08,0.0],[65124.49,0.0]]}}
{"ping":1784133641671}
{"ch":"market.btcusdt.mbp.150","ts":1784133641688,"tick":{"seqNum":191847887724,"prevSeqNum":191847887635,"bids":[[64792.7,0.0],[64789.46,0.0],[64786.22,0.0],[64785.26,0.00926],[64784.92,0.0],[64778.78,0.00926],[64772.3,0.040097],[64771.0,23.41029],[64629.25,0.004892],[64620.68,2.7855711422844E-5],[64620.45,0.151456],[64619.94,0.030837]],"asks":[[64901.75,0.0],[64904.99,0.0],[64905.01,2.312826],[64908.23,0.0],[64909.53,0.0],[64911.48,0.0],[64914.72,0.0],[64916.02,0.0],[64917.96,0.0],[64921.21,0.11325],[64922.5,0.0],[64928.11,0.00231],[64929.79,1.696073],[64934.59,0.00231],[64941.08,0.002309],[64941.97,9.250347],[64942.37,5.397233],[65034.75,3.439572],[65117.08,0.142111],[65124.49,0.143528],[65127.54,0.164751]]}}
{"ch":"market.btcusdt.mbp.150","ts":1784133641762,"tick":{"seqNum":191847887732,"prevSeqNum":191847887724,"bids":[[64790.11,0.08002],[64789.46,0.212292],[64786.87,0.148605],[64783.63,0.275983],[64782.33,18.500856],[64619.94,0.0]],"asks":[[64934.18,0.040011],[64937.43,0.074304],[64940.67,0.13799],[65117.08,0.0],[65124.49,0.0],[65127.54,0.0]]}}
{"ch":"market.btcusdt.mbp.150","ts":1784133641803,"tick":{"seqNum":191847887748,"prevSeqNum":191847887732,"bids":[[64855.69,0.738251],[64792.7,0.228623],[64789.46,0.424584],[64786.22,0.788519],[64784.92,18.502581],[64629.25,0.0],[64620.68,0.0],[64620.45,0.0]],"asks":[[64901.75,0.114314],[64904.99,0.212293],[64908.23,0.508571],[64909.53,9.252437],[64911.48,0.212295],[64914.72,0.394261],[64916.02,9.252582],[65093.64,0.0],[65104.45,0.0],[65105.25,0.0],[65110.75,0.0],[65111.81,0.0],[65112.27,0.0],[65115.78,0.0]]}}
{"ch":"market.btcusdt.mbp.150","ts":1784133641909,"tick":{"seqNum":191847887772,"prevSeqNum":191847887748,"bids":[[64836.92,0.422185],[64792.7,0.342936],[64789.46,0.636879],[64786.22,1.182779],[64784.92,27.753061],[64720.08,2.959331],[64679.29,3.084915],[64631.57,0.0],[64629.29,0.0]],"asks":[[64905.01,0.0],[64914.72,0.508574],[64917.96,0.212294],[64921.21,0.507511],[64922.5,9.25048],[64929.79,0.0],[64987.36,6.168555],[65014.58,0.0],[65034.75,0.0],[65052.21,3.856998],[65079.42,0.0],[65093.64,0.122878]]}}
{"ch":"market.btcusdt.mbp.150","ts":1784133642012,"tick":{"seqNum":191847887801,"prevSeqNum":191847887772,"bids":[[64836.93,0.402937],[64836.92,0.0],[64827.16,1.111034],[64710.43,7.999527],[64710.38,8.208653],[64632.95,0.0],[64632.65,0.0],[64632.3,0.0]],"asks":[[64905.01,4.625652],[65034.75,6.879144],[65090.18,0.0],[65093.64,0.0]]}}
{"ch":"market.btcusdt.mbp.150","ts":1784133642114,"tick":{"seqNum":191847887831,"prevSeqNum":191847887801,"bids":[[64836.93,0.0],[64836.89,0.359445],[64827.22,1.075129],[64827.16,0.0],[64798.88,0.0],[64778.73,0.0],[64772.25,0.0],[64765.77,0.0],[64764.47,0.0],[64710.43,0.0],[64710.39,8.369734],[64710.38,0.0],[64632.95,2.1232464929859E-5],[64632.65,3.7037037037037E-4],[64632.3,0.10873],[64631.57,3.8917835671342E-5],[64629.29,0.135349],[64629.25,0.004892]],"asks":[[64895.67,0.0],[64902.15,0.0],[64905.01,6.938478],[64908.63,0.0],[64909.93,0.0],[64929.79,1.696073],[65034.75,10.318716],[65090.18,0.03176],[65093.64,0.122878],[65104.45,0.136335]]}}
{"ch":"market.btcusdt.mbp.150","ts":1784133642250,"tick":{"seqNum":191847887902,"prevSeqNum":191847887831,"bids":[[64836.89,0.0],[64827.22,0.0],[64798.88,0.030837],[64789.45,0.0],[64779.72,0.0],[64776.48,0.0],[64775.19,0.0],[64710.39,8.287094],[64620.68,2.7855711422844E-5],[64620.45,0.151456],[64619.94,0.030837],[64618.7,5.268957227286E-6],[64615.53,0.142918]],"asks":[[64905.01,2.312826],[64906.94,0.0],[64916.67,0.0],[64919.91,0.0],[64921.21,0.434272],[64929.79,0.0],[65034.75,0.0],[65105.25,1.72E-6],[65110.75,0.154183],[65111.81,0.15982],[65112.27,3.084915],[65115.78,9.256316]]}}
{"id":"req-btcusdt","status":"ok","ts":1784133642358,"rep":"market.btcusdt.mbp.150","data":{"seqNum":191847887560,"bids":[[64855.69,0.738251],[64855.63,0.229398],[64850.57,6.1E-5],[64850.56,0.229398],[64849.39,0.002693],[64847.08,0.229398],[64846.62,0.00247],[64845.59,0.493636],[64843.69,0.230298],[64841.09,0.229398],[64835.6,0.229398],[64833.49,2.940984],[64832.92,0.229398],[64832.91,0.023802],[64830.5,0.008974],[64829.89,0.229398],[64827.21,0.925921],[64826.6,0.229398],[64822.15,0.006831],[64821.11,0.008671],[64818.97,1.161405],[64817.49,2.209407],[64817.47,2.04992],[64814.58,0.493636],[64808.91,0.00162],[64808.45,0.017077],[64798.88,0.030837],[64792.7,0.342939],[64790.11,0.080018],[64789.57,0.03176],[64789.46,0.636883],[64789.45,0.073242],[64786.96,0.020559],[64786.87,0.148606],[64786.22,1.182778],[64785.26,0.00463],[64784.92,27.753082],[64783.63,0.275984],[64783.08,0.028399],[64782.33,18.50356],[64779.72,0.073242],[64778.78,0.00463],[64778.73,0.090204],[64776.48,0.073241],[64775.19,0.073186],[64772.3,0.035467],[64772.25,0.090204],[64771.0,11.704821],[64770.35,0.026842],[64767.43,0.002315],[64766.29,8.016032064128E-6],[64765.77,0.09021],[64764.57,0.031644],[64764.47,5.940623],[64763.13,0.003769289289289289],[64762.5,0.003161845661094985],[64762.15,7.372533306621E-6],[64761.42,1.623246492985E-6],[64760.94,0.002316],[64760.9,0.002316],[64760.16,5.93593593593593E-4],[64756.69,2.865731462924E-6],[64756.6,8.26826826826826E-4],[64754.46,0.002316],[64754.41,0.002316],[64753.16,5.85273],[64750.0,1.98396793587174E-4],[64747.93,0.002316],[64746.63,5.852726],[64740.5,0.009766],[64739.0,4.6E-5],[64736.84,0.020590904237203243],[64734.02,0.030087],[64731.16,0.009659829914957478],[64730.16,0.030837],[64729.83,0.001719719719719719],[64729.45,0.036652],[64728.48,1.342281879194E-6],[64728.26,1.0517880396674E-5],[64727.54,0.092717],[64727.05,3.34669338677354E-4],[64722.63,9.67935871743486E-4],[64721.05,0.285719],[64718.36,11.142798],[64718.25,5.97175197836321E-4],[64717.49,6.168555],[64717.25,0.01929488020563388],[64717.19,0.030837],[64715.69,6.169031],[64715.26,0.068832],[64714.7,3.5310621242484E-5],[64714.57,12.337039],[64710.44,7.296042],[64708.1,0.001807],[64708.09,7.09358717434868E-4],[64706.29,0.001604604604604604],[64705.88,0.002270109185615546],[64705.36,0.154183],[64702.53,0.167912],[64701.56,0.054002],[64700.45,2.07414829659318E-4],[64700.0,0.026536],[64699.64,5.826846],[64697.74,0.030837],[64697.13,3.084915],[64696.96,1.553106212424E-6],[64693.0,0.143944],[64690.17,2.59259259259259E-4],[64689.97,1.99199199199199E-4],[64686.71,0.020559],[64685.56,1.91382765531062E-4],[64680.82,2.194388777555E-6],[64679.29,6.16983],[64678.57,0.022896848424212107],[64678.29,0.030837],[64675.18,0.103118],[64669.33,0.03176],[64668.64,6.32264529058116E-4],[64668.46,4.2444889779559E-5],[64666.66,0.00245575319385902],[64666.0,1.5E-4],[64664.33,1.78303115296003E-4],[64662.36,2.6903392079159E-5],[64658.84,0.030837],[64657.62,2.735470941883E-6],[64653.52,0.657974],[64652.65,1.672339],[64651.23,6.521085845938E-6],[64650.85,1.779583],[64650.0,6.8E-4],[64647.34,6.16983],[64645.46,6.951818090754E-6],[64643.77,0.086041],[64642.56,0.117386],[64640.52,0.154183],[64639.44,7.0941883767535E-4],[64639.39,0.030837],[64639.17,7.532805769808E-6],[64637.37,1.843687374749E-6],[64636.59,0.020559],[64635.79,1.27254509018E-6],[64634.81,0.353982],[64632.95,2.1232464929859E-5],[64632.65,3.7037037037037E-4],[64632.3,0.10873],[64631.57,3.8917835671342E-5],[64629.29,0.135349],[64629.25,0.004892],[64620.68,2.7855711422844E-5],[64620.45,0.151456]],"asks":[[64855.7,0.001],[64859.74,0.039628],[64859.75,2.377157],[64861.0,3.6E-4],[64862.0,3.6E-4],[64865.81,0.620904],[64865.97,0.493636],[64868.91,0.229398],[64870.0,7.2E-4],[64871.55,0.229398],[64877.84,1.160351],[64878.42,0.077067],[64878.93,0.229398],[64884.28,0.611131],[64884.6,0.006601],[64886.72,0.229398],[64887.21,0.020559],[64887.24,0.011469],[64888.0,0.00144],[64891.17,0.002725],[64891.85,0.229398],[64891.86,3.53794],[64892.85,0.0228854],[64893.09,0.004324],[64894.0,0.00144],[64894.51,0.229398],[64894.65,0.493636],[64895.61,0.002311],[64895.67,0.087894],[64896.0,0.00144],[64896.86,0.016957],[64898.0,0.00144],[64898.2,0.002311],[64898.82,0.229398],[64901.75,0.114312],[64902.09,0.002311],[64902.15,0.087886],[64902.42,0.229398],[64902.73,0.008117],[64904.59,0.118758],[64904.69,0.002311],[64904.99,0.212295],[64906.94,0.073242],[64908.23,0.508573],[64908.58,0.00231],[64908.63,0.08789],[64909.53,9.252437],[64909.81,0.03176],[64909.87,4.097698],[64909.93,0.087888],[64911.17,0.00231],[64911.48,0.212293],[64912.47,3.086044],[64914.72,0.508569],[64916.02,9.252582],[64916.67,0.073245],[64917.96,0.212294],[64918.16,0.027289],[64919.91,0.073243],[64921.21,0.507511],[64922.5,9.25048],[64922.99,7.783486],[64924.45,0.074303],[64927.4,0.009766],[64927.69,0.137993],[64928.99,9.250509],[64929.85,0.004892],[64931.22,0.00231],[64932.65,0.028253],[64933.88,0.030089],[64934.18,0.04001],[64934.65,0.00231],[64937.34,0.020559],[64937.43,0.074303],[64937.7,0.002309],[64940.36,0.092716],[64940.67,0.137992],[64941.14,0.002309],[64941.96,9.253051],[64943.14,0.169898],[64944.19,0.002309],[64945.48,5.852759],[64946.85,0.285716],[64947.62,0.002309],[64948.06,12.23679],[64948.92,4.39015],[64949.82,0.029002],[64953.33,12.337039],[64966.09,6.169031],[64967.0,0.0015],[64968.0,0.0015],[64969.93,0.03176],[64970.0,0.0015],[64972.0,0.0011],[64972.58,6.169031],[64973.09,0.067495],[64974.6,0.050059],[64974.77,0.154219],[64981.05,0.154183],[64981.26,0.002316],[64981.57,1.610919],[64985.63,6.169031],[64987.46,0.020559],[64995.64,4.688854],[65000.0,0.0228854],[65006.82,6.168555],[65008.38,0.073515],[65013.76,0.002315],[65014.58,3.084915],[65015.76,6.16983],[65030.06,0.036652],[65030.94,3.854436],[65033.99,0.083787],[65035.46,0.002306],[65037.42,3.852391],[65037.59,0.020559],[65039.61,0.154219],[65041.94,0.002306],[65045.0,0.001],[65045.9,0.154183],[65046.1,0.00232],[65046.41,0.002316],[65048.43,0.002305],[65049.72,5.852764],[65050.47,4.322943],[65051.0,0.001],[65052.1,0.6],[65058.0,0.001],[65063.32,0.09748],[65066.92,1.38E-6],[65071.67,4.325307],[65078.6,0.002322],[65079.42,9.253108],[65080.59,12.337039],[65087.71,0.020559],[65090.17,0.001807],[65090.18,0.03176],[65093.64,0.122878],[65104.45,0.136335],[65105.25,1.72E-6],[65110.75,0.154183],[65111.81,0.15982],[65112.27,3.084915],[65115.78,9.256316],[65117.08,0.142111],[65124.49,0.143528],[65127.54,0.164751],[65130.26,0.004892],[65131.9,0.34],[65136.78,0.167526]]}}
{"ch":"market.btcusdt.mbp.150","ts":1784133642392,"tick":{"seqNum":191847887934,"prevSeqNum":191847887902,"bids":[[64789.45,0.073243],[64785.26,0.097147],[64778.78,0.097149],[64772.3,0.127982],[64771.0,23.498175],[64760.9,0.0],[64754.41,0.0],[64747.93,0.0],[64746.63,0.0],[64614.47,9.253181],[64613.88,0.138342],[64611.59,2.7755511022044E-4]],"asks":[[64889.12,0.087888],[64895.61,0.090202],[64902.09,0.090197],[64903.39,0.087894],[64905.01,4.625652],[65034.75,3.439572],[65035.46,0.0],[65041.94,0.0],[65048.43,0.0],[65049.72,0.0],[65117.08,0.142111]]}}
{"ch":"market.btcusdt.mbp.150","ts":1784133642420,"tick":{"seqNum":191847887956,"prevSeqNum":191847887934,"bids":[[64836.92,0.357441],[64827.16,1.216668],[64779.72,0.073239],[64776.48,0.073238],[64775.19,0.073191],[64618.7,0.0],[64615.53,0.0],[64614.47,0.0],[64613.88,0.0],[64611.59,0.0]],"asks":[[64905.01,6.938478],[64906.94,0.07324],[64916.67,0.073236],[64919.91,0.073245],[64921.21,0.50751],[64929.79,1.696073],[65034.75,6.879144],[65111.81,0.0],[65112.27,0.0],[65115.78,0.0],[65117.08,0.0]]}}
{"ch":"market.btcusdt.mbp.150","ts":1784133642506,"tick":{"seqNum":191847887995,"prevSeqNum":191847887956,"bids":[[64836.92,0.0],[64827.16,0.0],[64827.15,1.152693],[64710.39,8.475223],[64618.7,5.268957227286E-6]],"asks":[[64905.01,2.312826],[65034.75,3.439572]]}}
{"ch":"market.btcusdt.mbp.150","ts":1784133642638,"tick":{"seqNum":191847888029,"prevSeqNum":191847887995,"bids":[[64836.92,0.367068],[64827.18,0.81997],[64827.15,0.0],[64767.43,0.0],[64767.42,0.002315],[64753.16,5.852736],[64710.45,7.733553],[64710.39,0.0],[64618.7,0.0]],"asks":[[64898.2,0.0],[64905.01,4.625652],[64931.22,0.0],[64937.7,0.0],[64944.19,0.0],[64945.48,0.0],[65028.91,0.002306],[65034.75,6.879144],[65035.39,0.002306],[65041.87,0.002306],[65043.17,5.852764],[65111.81,0.15982]]}}
{"ch":"market.btcusdt.mbp.150","ts":1784133642723,"tick":{"seqNum":191847888039,"prevSeqNum":191847888029,"bids":[[64790.11,0.040011],[64785.26,0.094832],[64778.78,0.094834],[64772.3,0.125667],[64771.0,17.645779]],"asks":[[64860.62,0.620904],[64865.81,0.0],[64904.69,0.0],[64911.17,0.0],[64912.47,0.0],[65112.27,3.084915],[65115.78,9.256316],[65117.08,0.142111]]}}
{"ch":"market.btcusdt.mbp.150","ts":1784133642819,"tick":{"seqNum":191847888077,"prevSeqNum":191847888039,"bids":[[64855.69,0.714449],[64850.56,0.0],[64849.71,0.229398],[64836.92,0.0],[64827.18,0.0],[64786.87,0.074302],[64783.63,0.137992],[64782.33,9.250347],[64618.7,5.268957227286E-6],[64615.53,0.142918]],"asks":[[64859.72,0.039628],[64859.73,0.229398],[64859.74,0.0],[64905.01,0.0],[64921.21,0.467499],[64924.45,0.0],[64927.69,0.0],[64928.99,0.0],[64929.79,0.0],[65034.75,0.0],[65124.49,0.143528],[65127.54,0.164751],[65130.26,0.004892],[65131.9,0.34],[65136.78,0.167526]]}}
{"ch":"market.btcusdt.mbp.150","ts":1784133642984,"tick":{"seqNum":191847888106,"prevSeqNum":191847888077,"bids":[[64771.0,17.645764],[64767.42,0.00463],[64760.94,0.004632],[64754.46,0.004632],[64753.16,11.705475],[64688.33,3.084801],[64623.49,9.250672],[64618.7,0.0],[64615.53,0.0]],"asks":[[64895.61,0.087891],[64898.21,0.002311],[64902.09,0.087886],[64904.69,0.002311],[64908.58,0.0],[64909.87,0.0],[64911.17,0.00231],[64912.47,5.852758],[64927.69,0.137993],[64931.22,0.00231],[64937.71,0.002309],[64944.19,0.002309],[64945.49,5.852758],[65010.32,3.084801],[65075.15,9.250672],[65111.81,0.0],[65112.27,0.0],[65115.78,0.0],[65117.08,0.0],[65124.49,0.0],[65127.54,0.0],[65130.26,0.0],[65131.9,0.0],[65136.78,0.0]]}}
{"ch":"market.btcusdt.mbp.150","ts":1784133643016,"tick":{"seqNum":191847888115,"prevSeqNum":191847888106,"bids":[[64855.69,0.738251],[64790.11,0.08002],[64786.87,0.148606],[64783.63,0.275985],[64782.33,18.500856],[64679.29,0.0],[64618.7,5.268957227286E-6]],"asks":[[64921.21,0.507511],[64924.45,0.074305],[64928.99,9.250509],[65105.25,0.0],[65110.75,0.0]]}}
{"ch":"market.btcusdt.mbp.150","ts":1784133643104,"tick":{"seqNum":191847888123,"prevSeqNum":191847888115,"bids":[[64827.17,0.78597],[64710.45,0.0]],"asks":[]}}
{"ch":"market.btcusdt.mbp.150","ts":1784133643213,"tick":{"seqNum":191847888172,"prevSeqNum":191847888123,"bids":[[64855.69,0.117347],[64854.95,0.620904],[64845.59,0.0],[64837.7,0.493636],[64827.17,0.0],[64814.58,0.0],[64809.24,0.493636],[64785.26,0.097147],[64784.92,18.501626],[64778.78,0.097149],[64772.3,0.127982],[64771.0,23.498203]],"asks":[[64895.61,0.090202],[64902.09,0.090197],[64905.01,4.625652],[64908.58,0.00231],[64909.87,5.852741],[64929.79,1.696073],[65034.75,6.879144],[65087.71,0.0],[65090.17,0.0],[65090.18,0.0],[65093.64,0.0],[65104.45,0.0]]}}
{"ch":"market.btcusdt.mbp.150","ts":1784133643309,"tick":{"seqNum":191847888181,"prevSeqNum":191847888172,"bids":[[64792.7,0.228624],[64789.46,0.424587],[64786.22,0.788519]],"asks":[[64904.99,0.0],[64908.23,0.394259],[64911.48,0.0],[64914.72,0.114313],[64916.02,0.0],[65087.71,0.020559],[65090.17,0.001807],[65090.18,0.03176]]}}
{"ch":"market.btcusdt.mbp.150","ts":1784133643464,"tick":{"seqNum":191847888214,"prevSeqNum":191847888181,"bids":[[64792.7,0.114313],[64789.46,0.212295],[64786.22,0.39426],[64785.26,0.094832],[64784.92,9.25048],[64778.78,0.094834],[64772.3,0.125667],[64771.0,17.645466]],"asks":[[64859.73,0.0],[64897.56,0.0],[64901.75,0.0],[64904.04,0.0],[64905.01,0.0],[64908.23,0.0],[64909.53,0.0],[64910.52,0.0],[64911.82,0.0],[64929.79,0.0],[65034.75,0.0],[65093.64,0.122878],[65104.45,0.136335],[65105.25,1.72E-6],[65110.75,0.154183],[65111.81,0.15982],[65115.78,9.256316],[65117.08,0.142111],[65124.49,0.143528],[65127.54,0.164751],[65130.26,0.004892],[65131.9,0.34]]}}
{"ch":"market.btcusdt.mbp.150","ts":1784133643509,"tick":{"seqNum":191847888226,"prevSeqNum":191847888214,"bids":[[64792.7,0.228625],[64789.46,0.424588],[64786.22,0.788519],[64784.92,18.501915]],"asks":[[64855.7,0.093645],[64859.72,0.0],[64859.74,0.039628],[64908.23,0.114313],[64911.48,0.212295],[64914.72,0.508572],[64916.02,9.252582],[65127.54,0.0],[65130.26,0.0],[65131.9,0.0]]}}
{"ch":"market.btcusdt.mbp.150","ts":1784133643623,"tick":{"seqNum":191847888247,"prevSeqNum":191847888226,"bids":[[64855.69,0.024702],[64792.7,0.342939],[64789.46,0.636883],[64786.22,1.18278],[64785.26,0.092517],[64784.92,27.753053],[64771.0,11.792734]],"asks":[[64855.7,0.001],[64859.74,0.0],[64901.75,0.114311],[64904.99,0.212294],[64908.23,0.508573],[64909.53,9.252437],[64928.11,0.0],[64934.59,0.0],[64941.08,0.0],[64942.37,0.0],[65127.54,0.164751],[65130.26,0.004892]]}}
{"ch":"market.btcusdt.mbp.150","ts":1784133643703,"tick":{"seqNum":191847888266,"prevSeqNum":191847888247,"bids":[[64792.7,0.228626],[64789.46,0.424588],[64786.22,0.78852],[64785.26,0.094832],[64784.92,18.502573],[64771.0,17.645462]],"asks":[[64855.7,0.024802],[64859.74,0.039628],[64897.56,0.002311],[64904.04,0.002311],[64910.52,0.00231],[64911.82,4.39015],[64914.72,0.394259],[64917.96,0.0],[64921.21,0.11325],[64922.5,0.0],[65124.49,0.0],[65127.54,0.0],[65130.26,0.0]]}}
{"ch":"market.btcusdt.mbp.150","ts":1784133643806,"tick":{"seqNum":191847888282,"prevSeqNum":191847888266,"bids":[[64854.95,0.0],[64615.53,0.142918]],"asks":[[64905.01,2.312826],[65034.75,3.439572],[65115.78,0.0],[65117.08,0.0]]}}
{"ch":"market.btcusdt.mbp.150","ts":1784133643920,"tick":{"seqNum":191847888306,"prevSeqNum":191847888282,"bids":[[64853.4,0.620904],[64827.21,0.788762],[64785.26,0.097147],[64778.78,0.097149],[64772.3,0.127982],[64771.0,23.4982],[64710.46,8.032801],[64710.42,8.1753],[64620.45,0.0],[64619.94,0.0],[64618.7,0.0],[64615.53,0.0]],"asks":[[64905.01,4.625652],[64928.11,0.00231],[64929.79,1.696073],[64934.59,0.00231],[64941.08,0.002309],[64942.37,5.852747],[65034.75,6.879144],[65093.64,0.0],[65104.45,0.0],[65105.25,0.0],[65110.75,0.0],[65111.81,0.0]]}}
{"ch":"market.btcusdt.mbp.150","ts":1784133644005,"tick":{"seqNum":191847888368,"prevSeqNum":191847888306,"bids":[[64855.69,9.0E-4],[64853.4,0.0],[64849.71,0.0],[64849.02,0.620904],[64847.08,0.0],[64843.7,0.229398],[64843.69,9.0E-4],[64836.94,0.408449],[64827.21,0.0],[64827.2,0.728657],[64818.98,0.229398],[64808.91,0.0],[64792.7,0.34294],[64789.46,0.636881],[64786.22,1.182779],[64784.92,27.753053],[64710.46,0.0],[64710.42,0.0],[64710.38,8.250157],[64620.45,0.151456]],"asks":[[64855.7,0.518438],[64859.72,0.039628],[64859.73,0.229398],[64859.74,0.0],[64865.97,0.0],[64875.16,0.493636],[64894.65,0.0],[64902.42,0.0],[64905.01,2.312826],[64914.72,0.508572],[64917.96,0.212294],[64921.21,0.507511],[64922.5,9.25048],[65034.75,3.439572],[65090.18,0.0]]}}
{"ch":"market.btcusdt.mbp.150","ts":1784133644105,"tick":{"seqNum":191847888371,"prevSeqNum":191847888368,"bids":[[64849.02,0.0],[64827.2,0.0],[64619.94,0.030837],[64618.7,5.268957227286E-6]],"asks":[[64875.15,0.229398],[65090.17,0.0]]}}
{"ch":"market.btcusdt.mbp.150","ts":1784133644212,"tick":{"seqNum":191847888405,"prevSeqNum":191847888371,"bids":[[64836.94,0.0],[64836.93,0.055436],[64827.15,0.032955],[64790.11,0.040009],[64789.45,0.0],[64786.87,0.074304],[64783.63,0.137993],[64782.33,9.250509],[64779.72,0.0],[64776.48,0.0],[64775.19,0.0],[64678.29,0.0],[64615.53,0.142918],[64613.88,0.138342],[64611.59,2.7755511022044E-4],[64609.21,0.03176]],"asks":[[64860.62,0.0],[64905.01,4.625652],[64906.94,0.0],[64916.67,0.0],[64919.91,0.0],[64921.21,0.434273],[64934.18,0.0],[64937.43,0.0],[64940.67,0.0],[64941.97,0.0],[65034.75,6.879144],[65090.17,0.001807],[65090.18,0.03176],[65093.64,0.122878],[65104.45,0.136335],[65105.25,1.72E-6],[65110.75,0.154183],[65111.81,0.15982],[65115.78,9.256316]]}}
{"ch":"market.btcusdt.mbp.150","ts":1784133644370,"tick":{"seqNum":191847888469,"prevSeqNum":191847888405,"bids":[[64836.9,0.080956],[64827.19,0.03725],[64785.26,0.00926],[64778.78,0.00926],[64772.3,0.040097],[64771.0,23.410315],[64678.29,0.030837],[64613.88,0.0],[64611.59,0.0],[64609.21,0.0]],"asks":[[64855.7,0.611083],[64889.12,0.0],[64895.61,0.002311],[64902.09,0.002311],[64903.39,0.0],[64905.01,2.312826],[64929.79,0.0],[65117.08,0.142111],[65124.49,0.143528],[65127.54,0.164751]]}}
{"ch":"market.btcusdt.mbp.150","ts":1784133644402,"tick":{"seqNum":191847888482,"prevSeqNum":191847888469,"bids":[[64785.65,0.073237],[64781.94,0.137991],[64775.93,0.073242],[64772.69,0.073239],[64771.39,0.073234],[64620.68,0.0],[64620.45,0.0],[64619.94,0.0],[64618.7,0.0],[64615.53,0.0]],"asks":[[64903.14,0.073237],[64905.01,4.625652],[64912.87,0.073242],[64916.11,0.073243],[64917.41,0.073243],[65115.78,0.0],[65117.08,0.0],[65124.49,0.0],[65127.54,0.0]]}}
{"ch":"market.btcusdt.mbp.150","ts":1784133644528,"tick":{"seqNum":191847888499,"prevSeqNum":191847888482,"bids":[[64855.69,0.024702],[64788.43,0.040012],[64785.18,0.074303],[64780.65,9.250347],[64629.29,0.0],[64629.25,0.0],[64623.49,0.0]],"asks":[[64902.09,0.090202],[64928.26,0.040011],[64931.5,0.074304],[64934.75,0.137991],[64936.04,9.250347],[65034.75,10.318716],[65104.45,0.0],[65105.25,0.0],[65110.75,0.0],[65111.81,0.0]]}}
{"ch":"market.btcusdt.mbp.150","ts":1784133644603,"tick":{"seqNum":191847888568,"prevSeqNum":191847888499,"bids":[[64855.69,0.0],[64843.7,0.0],[64843.69,0.0],[64841.09,0.0],[64838.24,0.229398],[64837.7,0.0],[64836.93,0.0],[64836.9,0.0],[64827.19,0.0],[64827.15,0.0],[64818.97,0.0],[64817.49,0.0],[64811.19,0.229398],[64792.71,0.00162],[64785.26,0.09715],[64778.78,0.097146],[64772.3,0.127984],[64771.0,23.498202],[64767.42,0.002315],[64760.94,0.002316],[64754.46,0.002316],[64753.16,5.852739],[64629.29,0.135349],[64629.25,0.004892],[64623.49,9.250672],[64620.68,2.7855711422844E-5],[64620.45,0.151456],[64619.94,0.030837],[64618.7,5.268957227286E-6],[64615.53,0.142918]],"asks":[[64852.31,0.039628],[64852.32,0.322043],[64853.68,0.620904],[64854.92,0.229398],[64855.7,0.518438],[64859.72,0.0],[64875.16,0.0],[64877.84,0.0],[64889.12,0.087894],[64894.51,0.0],[64895.61,0.090197],[64898.82,0.0],[64903.39,0.087891],[64905.01,0.0],[65028.91,0.0],[65034.75,0.0],[65035.39,0.0],[65041.87,0.0],[65043.17,0.0],[65104.45,0.136335],[65105.25,1.72E-6],[65110.75,0.154183],[65111.81,0.15982],[65117.08,0.142111]]}}
{"ch":"market.btcusdt.mbp.150","ts":1784133644702,"tick":{"seqNum":191847888574,"prevSeqNum":191847888568,"bids":[[64850.58,0.023802],[64798.89,0.00162],[64792.71,0.0],[64615.53,0.0]],"asks":[[64853.68,0.0],[64855.7,0.028302],[65124.49,0.143528]]}}
{"ch":"market.btcusdt.mbp.150","ts":1784133644816,"tick":{"seqNum":191847888584,"prevSeqNum":191847888574,"bids":[[64851.33,0.023802],[64831.08,0.493636],[64809.25,0.00162],[64798.89,0.0],[64619.94,0.0],[64618.7,0.0]],"asks":[[64851.34,0.493636],[64852.31,0.0],[64852.32,0.229398],[64852.52,0.620904],[65035.39,0.002306],[65117.08,0.0],[65124.49,0.0]]}}
{"ch":"market.btcusdt.mbp.150","ts":1784133644917,"tick":{"seqNum":191847888614,"prevSeqNum":191847888584,"bids":[[64834.38,0.155822],[64824.66,0.071758],[64814.9,2.984356],[64812.68,1.161518],[64767.42,0.00463],[64760.94,0.004632],[64754.46,0.004632],[64753.16,11.705475],[64688.33,6.169602],[64629.25,0.0],[64623.49,0.0],[64620.68,0.0],[64620.45,0.0]],"asks":[[64852.31,0.039628],[64871.55,1.389862],[64902.43,2.312982],[64912.47,0.0],[64927.22,1.696187],[65028.91,0.002306],[65032.17,3.439303],[65041.87,0.002306],[65043.17,5.852753],[65090.18,0.0],[65093.64,0.0],[65104.45,0.0],[65105.25,0.0],[65110.75,0.0],[65111.81,0.0]]}}
{"ch":"market.btcusdt.mbp.150","ts":1784133645018,"tick":{"seqNum":191847888646,"prevSeqNum":191847888614,"bids":[[64849.39,0.0],[64834.39,0.142952],[64824.61,0.078007],[64792.7,0.228628],[64789.46,0.424588],[64786.22,0.78852],[64785.26,0.094835],[64784.92,18.501618],[64778.78,0.094831],[64772.3,0.125669],[64771.0,17.645792],[64629.29,0.0]],"asks":[[64851.34,0.586281],[64898.21,0.0],[64902.43,4.625964],[64904.69,0.0],[64908.23,0.39426],[64911.17,0.0],[64911.48,0.0],[64914.72,0.114313],[64916.02,0.0],[65032.17,6.878606],[65090.18,0.03176],[65093.64,0.122878],[65104.45,0.136335],[65105.25,1.72E-6],[65108.01,3.084801]]}}
{"ch":"market.btcusdt.mbp.150","ts":1784133645102,"tick":{"seqNum":191847888669,"prevSeqNum":191847888646,"bids":[[64840.98,0.004286],[64792.7,0.114314],[64789.46,0.212293],[64786.22,0.394259],[64784.92,9.25048],[64767.42,0.002315],[64760.94,0.002316],[64754.46,0.002316],[64753.16,5.852736],[64631.57,0.0]],"asks":[[64851.34,0.092645],[64887.99,0.002558],[64893.09,0.0],[64901.75,0.0],[64904.99,0.0],[64908.23,0.0],[64909.53,0.0],[64927.22,0.0],[64931.22,0.0],[64937.71,0.0],[64944.19,0.0],[64945.49,0.0],[64949.82,0.0],[65110.75,0.154183],[65111.81,0.15982],[65117.08,0.142111],[65124.49,0.143528],[65130.26,0.004892],[65131.9,0.34],[65136.78,0.167526],[65136.98,0.13388],[65137.84,0.020559],[65138.03,0.009655]]}}
{"ch":"market.btcusdt.mbp.150","ts":1784133645217,"tick":{"seqNum":191847888723,"prevSeqNum":191847888669,"bids":[[64790.11,0.0],[64786.87,0.0],[64785.26,0.09252],[64783.63,0.0],[64782.33,0.0],[64778.78,0.092516],[64772.3,0.123354],[64771.0,11.793353],[64631.57,3.8917835671342E-5],[64629.29,0.135349],[64629.25,0.004892],[64623.49,18.501344]],"asks":[[64851.34,0.023802],[64852.29,0.039628],[64852.3,0.023802],[64852.31,0.0],[64855.7,0.0045],[64895.61,0.087886],[64902.09,0.087891],[64902.43,0.0],[64908.58,0.0],[64909.87,0.0],[64921.21,0.394261],[64924.45,0.0],[64927.69,0.0],[64928.99,0.0],[65032.17,0.0],[65150.0,0.00349055],[65150.3,0.03176],[65165.16,0.701986],[65172.84,9.250672],[65183.48,2.03E-6],[65187.56,4.78E-6]]}}
{"ch":"market.btcusdt.mbp.150","ts":1784133645311,"tick":{"seqNum":191847888751,"prevSeqNum":191847888723,"bids":[[64789.24,0.114312],[64786.0,0.212293],[64782.75,0.394259],[64781.46,9.252582],[64781.29,9.252437],[64767.42,0.00463],[64760.94,0.004632],[64754.46,0.004632],[64753.16,11.705482],[64632.3,0.0],[64631.57,0.0],[64629.29,0.0],[64629.25,0.0],[64623.49,0.0]],"asks":[[64852.27,0.039628],[64852.28,0.229398],[64852.29,0.0],[64852.32,0.0],[64899.1,0.114312],[64902.34,0.212292],[64902.43,2.312982],[64905.58,0.394261],[64906.88,9.252582],[64927.22,1.696187],[64931.22,0.00231],[64937.71,0.002309],[64944.19,0.002309],[64945.49,5.852751],[65032.17,3.439303],[65131.9,0.0],[65136.78,0.0],[65136.98,0.0],[65137.84,0.0],[65138.03,0.0],[65150.0,0.0],[65150.3,0.0],[65165.16,0.0],[65172.84,0.0],[65183.48,0.0],[65187.56,0.0]]}}
{"ch":"market.btcusdt.mbp.150","ts":1784133645401,"tick":{"seqNum":191847888786,"prevSeqNum":191847888751,"bids":[[64851.33,0.0],[64850.58,0.0],[64838.24,0.0],[64835.6,0.0],[64834.39,0.0],[64834.38,0.0],[64833.49,0.0],[64824.66,0.0],[64824.61,0.0],[64817.47,0.0],[64814.91,0.229398],[64814.9,0.0],[64792.7,0.0],[64789.46,0.0],[64789.07,0.114314],[64786.22,0.0],[64785.83,0.212295],[64784.92,0.0],[64782.59,0.394258],[64632.3,0.10873],[64631.57,3.8917835671342E-5],[64629.29,0.135349],[64629.25,0.004892],[64623.49,18.501344],[64620.68,2.7855711422844E-5],[64619.94,0.030837],[64618.7,5.268957227286E-6],[64613.88,0.138342],[64611.59,2.7755511022044E-4],[64609.7,0.154286]],"asks":[[64852.27,0.0],[64852.52,0.0],[64859.75,0.0],[64884.28,0.0],[64891.86,0.0],[64892.77,0.114312],[64896.01,0.212296],[64899.26,0.394258],[64900.55,9.252437],[64919.31,0.017403],[65121.78,0.149661],[65130.26,0.0]]}}
{"ch":"market.btcusdt.trade.detail","ts":1784133645432,"tick":{"id":191847888815,"ts":1784133645430,"data":[{"id":1918478888151642289133519782,"ts":1784133645430,"tradeId":103626665740,"amount":0.00247,"price":64846.62,"direction":"sell","isRpiTrade":false},{"id":1918478888151642289074275844,"ts":1784133645430,"tradeId":103626665739,"amount":6.1E-5,"price":64850.57,"direction":"sell","isRpiTrade":false}]}}
{"ch":"market.btcusdt.trade.detail","ts":1784133645433,"tick":{"id":191847888817,"ts":1784133645430,"data":[{"id":1918478888171642289141942245,"ts":1784133645430,"tradeId":103626665741,"amount":0.009877,"price":64846.62,"direction":"sell","isRpiTrade":false}]}}
{"ch":"market.btcusdt.mbp.150","ts":1784133645508,"tick":{"seqNum":191847888951,"prevSeqNum":191847888786,"bids":[[64850.57,0.0],[64846.62,0.0],[64840.98,0.0],[64834.85,0.023802],[64834.84,0.004909],[64832.92,0.0],[64831.08,0.0],[64829.89,0.0],[64828.46,0.002813],[64824.1,2.941178],[64822.15,0.0],[64821.11,0.0],[64818.68,0.001578],[64818.64,0.493636],[64813.09,0.008205],[64812.68,0.0],[64809.25,0.0],[64809.24,0.0],[64808.45,0.0],[64806.41,0.00162],[64806.4,0.229398],[64806.39,1.16163],[64805.5,0.006574],[64803.4,0.229398],[64796.15,0.016705],[64795.61,0.229398],[64791.81,0.016436],[64789.24,0.0],[64789.07,0.0],[64788.43,0.0],[64786.0,0.0],[64785.83,0.0],[64785.26,0.0],[64785.18,0.0],[64783.08,0.0],[64782.75,0.0],[64782.59,0.0],[64781.94,0.0],[64781.46,0.0],[64781.29,0.0],[64780.65,0.0],[64778.78,0.0],[64777.58,0.04001],[64774.34,0.074306],[64772.3,0.030837],[64771.09,0.137997],[64771.0,0.0],[64769.8,9.250509],[64768.88,0.027886],[64764.57,0.0],[64740.5,0.0],[64734.02,0.0],[64731.49,0.052558],[64727.54,0.0],[64721.05,0.045131],[64714.57,0.0],[64675.18,0.0],[64629.29,0.0],[64625.06,0.121921],[64609.7,0.0],[64609.21,0.03176],[64606.49,2.19559339008512E-4],[64600.49,0.030837],[64600.0,0.005080013383674088],[64599.9,0.45],[64599.38,0.166284],[64594.96,1.603206412825E-6],[64593.68,0.154874],[64592.27,1.422845691382E-6],[64591.83,1.72234468937875E-4],[64591.72,4.478957915831E-6],[64591.16,0.138837],[64588.05,1.382349994991E-6],[64586.46,0.020559]],"asks":[[64837.84,0.039628],[64837.85,0.229398],[64840.92,0.023802],[64840.93,0.620904],[64840.96,0.229398],[64843.59,0.229398],[64846.19,0.229398],[64848.79,0.229398],[64849.09,0.493636],[64850.58,0.027302],[64851.34,0.0],[64852.3,0.0],[64855.7,0.001],[64865.25,1.160576],[64871.55,0.0],[64875.15,0.0],[64878.93,0.0],[64880.8,3.538548],[64885.97,0.002423],[64886.72,0.0],[64891.17,0.0],[64891.85,0.0],[64902.14,0.04001],[64902.32,0.121228],[64902.43,0.0],[64904.59,0.0],[64905.38,0.074306],[64908.62,0.137997],[64909.92,9.250509],[64921.29,1.696207],[64922.99,0.0],[64927.22,0.0],[64927.4,0.0],[64933.88,0.0],[64940.36,0.0],[64946.85,0.0],[64953.33,0.0],[65032.17,0.0],[65105.52,0.133351],[65117.08,0.0],[65119.96,0.139237],[65121.78,0.0],[65124.49,0.0]]}}
{"ch":"market.btcusdt.mbp.150","ts":1784133645601,"tick":{"seqNum":191847888992,"prevSeqNum":191847888951,"bids":[[64834.84,0.0],[64826.6,0.0],[64824.5,0.004296],[64824.11,0.229398],[64824.1,0.0],[64818.64,0.0],[64806.41,0.0],[64806.39,0.0],[64785.66,0.00162],[64785.65,0.0],[64775.93,0.0],[64772.69,0.0],[64771.39,0.0],[64715.69,0.0],[64702.53,0.0],[64650.85,0.0],[64595.61,0.145124],[64591.16,0.0],[64585.71,6.81157968546529E-4],[64583.34,1.6773547094188E-5],[64583.33,1.362725450901E-6],[64582.51,12.337039],[64580.7,10.668515],[64580.11,3.7244488977955E-5],[64580.0,0.0015],[64578.1,11.448422],[64578.0,0.0026],[64575.69,0.092999]],"asks":[[64834.86,0.2532],[64837.82,0.039628],[64837.83,0.023802],[64837.84,0.0],[64840.93,0.0],[64865.25,0.0],[64867.83,0.006801],[64868.91,0.0],[64880.57,0.016884],[64884.6,0.0],[64896.86,0.0],[64900.38,0.026912],[64914.72,0.0],[64917.96,0.0],[64918.16,0.0],[64921.21,0.0],[64922.5,0.0],[64954.89,0.06801],[64973.09,0.0],[64985.63,0.0],[65050.47,0.0],[65121.78,0.149661],[65130.26,0.004892],[65131.9,0.34],[65136.78,0.167526],[65136.98,0.13388],[65137.84,0.020559],[65138.03,0.009655]]}}
{"ping":1784133645669}
{"ch":"market.btcusdt.mbp.150","ts":1784133645703,"tick":{"seqNum":191847889022,"prevSeqNum":191847888992,"bids":[[64834.85,0.0],[64828.46,0.0],[64815.81,2.941437],[64785.66,0.0],[64777.59,0.039629],[64767.42,0.0],[64760.94,0.0],[64754.46,0.0],[64753.16,0.0],[64682.36,0.167282],[64595.61,0.0],[64591.16,0.147463],[64580.7,0.0],[64578.1,0.0],[64574.24,0.005924],[64571.42,0.022896848424212107],[64570.01,0.074337],[64569.99,0.154219],[64566.82,1.1E-4],[64564.74,1.713426853707E-6]],"asks":[[64834.85,0.039628],[64837.82,0.0],[64909.76,7.785509],[64921.29,0.0],[64933.44,0.285732],[65015.04,0.086058],[65033.99,0.0],[65138.03,0.0]]}}
{"ch":"market.btcusdt.mbp.150","ts":1784133645806,"tick":{"seqNum":191847889058,"prevSeqNum":191847889022,"bids":[[64824.11,0.0],[64819.19,0.01908],[64818.68,0.0],[64809.49,0.01377],[64799.76,3.291998],[64798.29,1.161776],[64777.59,0.0],[64777.58,0.0],[64774.35,0.039629],[64774.34,0.0],[64771.09,0.0],[64769.8,0.0],[64727.11,0.009766],[64720.63,0.030091],[64714.14,0.092723],[64707.66,0.285731],[64701.18,12.337039],[64569.99,0.0],[64566.82,0.0],[64564.74,0.0]],"asks":[[64834.86,0.345845],[64857.14,1.160722],[64887.26,2.313605],[64910.52,0.0],[64912.03,1.696643],[64913.99,0.009765],[64920.47,0.03009],[64926.96,0.092721],[64939.92,12.337039],[65016.97,3.438223],[65119.96,0.0],[65121.78,0.0],[65130.26,0.0],[65131.9,0.0],[65136.78,0.0],[65136.98,0.0],[65137.84,0.0]]}}
{"ch":"market.btcusdt.mbp.150","ts":1784133645983,"tick":{"seqNum":191847889076,"prevSeqNum":191847889058,"bids":[[64799.77,0.00162],[64774.35,0.0],[64774.02,0.114316],[64770.78,0.212303],[64767.54,0.394278],[64766.24,9.25048],[64575.69,0.0],[64574.24,0.0],[64571.42,0.0],[64570.01,0.0]],"asks":[[64854.91,6.1E-5],[64889.6,0.114319],[64892.84,0.212306],[64896.08,0.39428],[64897.38,9.250445],[64897.56,0.0],[64904.04,0.0],[64911.82,0.0],[64928.11,0.0],[64934.59,0.0],[64941.08,0.0],[64942.37,0.0],[65119.96,0.139237],[65121.78,0.149661]]}}
{"ch":"market.btcusdt.mbp.150","ts":1784133646021,"tick":{"seqNum":191847889077,"prevSeqNum":191847889076,"bids":[],"asks":[[65121.78,0.0],[65130.26,0.004892]]}}
{"ch":"market.btcusdt.mbp.150","ts":1784133646102,"tick":{"seqNum":191847889117,"prevSeqNum":191847889077,"bids":[[64834.84,0.023802],[64825.08,0.229398],[64822.28,0.229398],[64819.17,0.018912],[64809.43,0.012261],[64583.33,0.0],[64582.51,0.0],[64580.11,0.0],[64580.0,0.0],[64578.0,0.0]],"asks":[[64834.86,0.0],[64836.24,0.620904],[64837.85,0.0],[64848.21,2.377157],[64870.15,0.002365],[64872.69,0.611814],[64875.12,0.004889],[64887.99,0.0],[64912.03,0.0],[64932.65,0.0],[65111.81,0.0],[65119.96,0.0],[65131.9,0.34],[65136.78,0.167526]]}}
{"ch":"market.btcusdt.mbp.150","ts":1784133646208,"tick":{"seqNum":191847889134,"prevSeqNum":191847889117,"bids":[],"asks":[[64834.85,0.493636],[64836.23,0.039628],[64836.24,0.0],[64887.26,4.627175],[64903.14,0.0],[64912.03,1.696618],[64912.87,0.0],[64916.11,0.0],[64917.41,0.0],[65016.97,6.876506],[65136.98,0.13388],[65137.84,0.020559],[65138.03,0.009655]]}}
{"ch":"market.btcusdt.mbp.150","ts":1784133646306,"tick":{"seqNum":191847889145,"prevSeqNum":191847889134,"bids":[[64827.9,0.229398],[64824.83,0.620904],[64813.18,0.493636],[64806.41,0.00162],[64799.77,0.0],[64586.46,0.0],[64585.71,0.0],[64583.34,0.0]],"asks":[[64834.85,0.0],[64836.23,0.0],[64837.82,0.039628],[64837.83,0.0],[65149.92,0.781061],[65150.0,0.00349055]]}}
{"ch":"market.btcusdt.mbp.150","ts":1784133646402,"tick":{"seqNum":191847889191,"prevSeqNum":191847889145,"bids":[[64834.84,0.0],[64824.83,0.0],[64819.15,0.194757],[64809.5,0.00162],[64809.46,0.101612],[64806.41,0.0],[64799.74,3.019287],[64588.05,0.0]],"asks":[[64837.82,0.0],[64840.79,0.06343],[64840.9,0.023802],[64840.96,0.0],[64887.26,2.313462],[64912.03,1.696539],[65016.97,3.43847],[65149.92,0.386261]]}}
{"ch":"market.btcusdt.mbp.150","ts":1784133646519,"tick":{"seqNum":191847889225,"prevSeqNum":191847889191,"bids":[[64832.99,0.023802],[64832.98,0.229398],[64798.88,0.0],[64784.79,0.030846],[64772.3,0.0],[64766.47,0.073248],[64758.22,0.030846],[64756.74,0.073248],[64753.5,0.073244],[64752.21,0.073245],[64730.16,0.0],[64717.19,0.0],[64716.08,0.030846],[64703.12,0.030846],[64697.74,0.0],[64683.67,0.030846],[64678.29,0.0],[64664.23,0.030846],[64658.84,0.0],[64644.78,0.030846],[64639.39,0.0],[64625.34,0.030846],[64619.94,0.0],[64605.89,0.030846],[64600.49,0.0],[64593.68,0.0],[64592.27,0.0],[64591.83,0.0],[64591.72,0.0],[64591.16,0.0]],"asks":[[64840.9,0.116447],[64883.93,0.073248],[64893.65,0.073242],[64896.89,0.073241],[64898.19,0.073244],[65045.44,0.098585],[65099.15,0.132366],[65106.64,0.15894],[65131.9,0.0],[65136.78,0.0],[65136.98,0.0],[65137.84,0.0],[65138.03,0.0],[65149.92,0.0],[65150.0,0.0]]}}
{"ch":"market.btcusdt.mbp.150","ts":1784133646648,"tick":{"seqNum":191847889237,"prevSeqNum":191847889225,"bids":[],"asks":[[64840.78,0.039628],[64840.79,0.023802],[64840.89,0.229398],[64887.26,0.0],[64889.12,0.0],[64895.61,0.0],[64902.09,0.0],[64903.39,0.0],[64912.03,0.0],[65131.9,0.34],[65136.78,0.167526],[65136.98,0.13388],[65137.84,0.020559]]}}
{"ch":"market.btcusdt.mbp.150","ts":1784133646702,"tick":{"seqNum":191847889256,"prevSeqNum":191847889237,"bids":[[64832.98,0.0],[64819.18,0.20032],[64705.36,0.0],[64593.68,0.154874]],"asks":[[64887.26,2.313497],[64912.03,1.696565],[65016.97,3.438409],[65136.98,0.0],[65137.84,0.0]]}}
{"ch":"market.btcusdt.mbp.150","ts":1784133646819,"tick":{"seqNum":191847889279,"prevSeqNum":191847889256,"bids":[[64833.45,0.023802],[64833.44,0.229398],[64727.53,0.0],[64721.05,0.0],[64714.56,0.0],[64708.08,0.0],[64701.6,0.0],[64640.52,0.0],[64592.27,1.422845691382E-6],[64591.83,1.72234468937875E-4],[64591.72,4.478957915831E-6],[64591.16,0.147463]],"asks":[[64856.0,3.6E-4],[64859.0,3.6E-4],[64892.77,0.0],[64896.01,0.0],[64899.26,0.0],[64900.55,0.0],[64905.58,0.0],[64981.05,0.0],[65038.47,0.0],[65044.96,0.0],[65045.9,0.0],[65051.44,0.0],[65057.92,0.0],[65064.41,0.0],[65110.75,0.0],[65136.98,0.13388],[65137.84,0.020559],[65138.03,0.009655],[65149.92,0.333287],[65150.0,0.00349055],[65150.3,0.03176],[65172.84,9.250672],[65183.48,2.03E-6],[65187.56,4.78E-6],[65187.96,0.020559],[65189.87,1.95E-6]]}}
{"ch":"market.btcusdt.mbp.150","ts":1784133646914,"tick":{"seqNum":191847889303,"prevSeqNum":191847889279,"bids":[[64834.28,0.023802],[64767.03,0.087891],[64760.54,0.087892],[64754.06,0.08789],[64752.77,0.087897],[64593.68,0.0],[64592.27,0.0],[64591.83,0.0],[64591.72,0.0],[64591.16,0.0]],"asks":[[64839.59,0.039628],[64840.78,0.0],[64840.9,0.023802],[64879.17,0.087898],[64885.65,0.08789],[64892.13,0.087892],[64893.43,0.087881],[64899.1,0.0],[64902.34,0.0],[64906.88,0.0],[65028.91,0.0],[65035.39,0.0],[65041.87,0.0],[65043.17,0.0],[65201.6,2.119E-5],[65206.47,1.563E-5],[65210.0,3.4E-4]]}}
{"ch":"market.btcusdt.mbp.150","ts":1784133647002,"tick":{"seqNum":191847889341,"prevSeqNum":191847889303,"bids":[[64788.74,0.493636],[64773.27,0.114318],[64770.03,0.212304],[64766.78,0.394278],[64765.49,9.252437],[64605.89,0.0],[64600.0,0.0],[64599.9,0.0],[64599.38,0.0],[64594.96,0.0]],"asks":[[64838.39,0.039628],[64838.4,0.493636],[64839.59,0.0],[64839.84,0.620904],[64849.09,0.0],[64875.18,0.114318],[64878.42,0.28937],[64881.66,0.394276],[64882.96,9.252406],[64887.26,2.313474],[64912.03,1.696548],[64928.26,0.0],[64931.5,0.0],[64934.75,0.0],[64936.04,0.0],[65016.97,3.438449],[65149.92,0.397434]]}}
{"ch":"market.btcusdt.mbp.150","ts":1784133647134,"tick":{"seqNum":191847889383,"prevSeqNum":191847889341,"bids":[[64809.48,0.117128],[64773.35,0.114317],[64770.11,0.212304],[64766.87,0.39428],[64765.57,9.251903],[64749.19,0.002316],[64742.71,0.002316],[64736.23,0.002317],[64734.93,5.853012],[64713.44,0.014647],[64706.96,0.045132],[64700.48,0.13908],[64694.0,0.428597],[64687.52,8.471498],[64632.95,0.0],[64632.65,0.0],[64632.3,0.0],[64631.57,0.0],[64629.25,0.0],[64625.34,0.0],[64625.06,0.0],[64623.49,0.0],[64620.68,0.0],[64618.7,0.0],[64613.88,0.0],[64611.59,0.0],[64609.21,0.0],[64606.49,0.0]],"asks":[[64840.89,0.0],[64881.58,0.114318],[64884.82,0.212304],[64887.26,4.626991],[64888.06,0.394279],[64889.36,9.251903],[64912.03,1.696579],[65016.97,6.876824],[65018.94,0.002307],[65024.34,0.014645],[65025.42,0.002306],[65030.83,0.045135],[65031.91,0.002306],[65033.2,5.853048],[65037.31,0.139081],[65043.79,0.428595],[65050.27,13.876474],[65115.09,9.256416],[65137.84,0.0],[65138.03,0.0],[65149.92,0.0],[65150.0,0.0],[65150.3,0.0],[65172.84,0.0],[65183.48,0.0],[65187.56,0.0],[65187.96,0.0],[65189.87,0.0],[65201.6,0.0],[65206.47,0.0],[65210.0,0.0]]}}
{"ch":"market.btcusdt.mbp.150","ts":1784133647201,"tick":{"seqNum":191847889449,"prevSeqNum":191847889383,"bids":[[64839.82,9.0E-4],[64838.19,0.229398],[64832.81,0.002492],[64819.19,0.0],[64819.18,0.0],[64819.17,0.0],[64819.15,0.0],[64815.81,0.0],[64813.09,0.0],[64809.5,0.0],[64809.49,0.0],[64809.48,0.0],[64809.46,0.0],[64809.43,0.0],[64806.41,0.00162],[64799.76,0.0],[64799.74,0.0],[64798.29,0.0],[64795.61,0.0],[64788.74,0.0],[64778.16,0.040012],[64774.92,0.074309],[64771.68,0.137997],[64770.38,9.250347],[64632.95,2.1232464929859E-5],[64632.65,3.7037037037037E-4],[64632.3,0.10873],[64631.57,3.8917835671342E-5],[64629.25,0.004892],[64625.34,0.030846],[64625.06,0.121921],[64623.49,18.501344]],"asks":[[64838.39,0.0],[64838.4,0.0],[64839.84,0.0],[64840.79,0.0],[64840.9,0.0],[64840.92,0.0],[64843.59,0.0],[64846.19,0.0],[64848.17,0.023802],[64848.18,0.039628],[64848.19,0.023802],[64848.2,0.229398],[64848.79,0.0],[64850.58,0.023802],[64852.28,0.0],[64854.92,0.0],[64857.13,0.229398],[64857.14,0.0],[64872.68,0.229398],[64880.47,0.229398],[64887.2,0.229398],[64894.99,0.229398],[64916.72,0.040012],[64919.96,0.074306],[64923.2,0.138],[64924.5,9.250347],[64931.22,0.0],[64937.71,0.0],[64944.19,0.0],[64945.49,0.0],[65103.63,0.163359],[65106.64,0.0],[65137.84,0.020559],[65138.03,0.009655],[65149.92,0.72759]]}}
{"ch":"market.btcusdt.mbp.150","ts":1784133647301,"tick":{"seqNum":191847889492,"prevSeqNum":191847889449,"bids":[[64841.21,0.229398],[64821.8,2.941301],[64803.4,0.0],[64767.03,0.090206],[64760.55,0.002316],[64754.06,0.090206],[64752.77,5.940909],[64625.06,0.0],[64623.49,0.0]],"asks":[[64845.07,0.039628],[64848.15,0.023802],[64848.18,0.0],[64854.53,0.229398],[64863.15,1.160614],[64887.26,0.0],[64888.25,0.002311],[64894.73,0.002311],[64901.21,0.002311],[64902.51,5.853028],[64912.03,0.0],[65016.97,0.0],[65136.98,0.0],[65137.84,0.0],[65138.03,0.0],[65149.92,0.0]]}}
{"ch":"market.btcusdt.mbp.150","ts":1784133647407,"tick":{"seqNum":191847889528,"prevSeqNum":191847889492,"bids":[[64833.45,0.0],[64832.99,0.0],[64832.91,0.0],[64804.29,1.161668],[64802.93,2.626288],[64710.38,0.0],[64625.06,0.121921],[64623.49,18.501344]],"asks":[[64845.07,0.0],[64848.13,0.023802],[64848.14,0.039628],[64848.17,0.0],[64848.19,0.0],[64850.58,0.0],[64890.48,2.313274],[65020.2,3.438796]]}}
{"ch":"market.btcusdt.mbp.150","ts":1784133647544,"tick":{"seqNum":191847889565,"prevSeqNum":191847889528,"bids":[[64841.22,0.023802],[64822.41,0.423726],[64812.72,0.589735],[64802.93,0.0],[64802.92,2.363013],[64754.06,0.092522],[64749.19,0.004632],[64742.71,0.004632],[64736.23,0.004634],[64734.93,11.706025],[64695.9,8.179999],[64629.25,0.0],[64625.34,0.0],[64625.06,0.0],[64623.49,0.0]],"asks":[[64848.08,0.039628],[64848.09,0.023802],[64848.11,0.023802],[64848.14,0.0],[64887.24,0.0],[64890.48,4.626494],[64915.25,1.696361],[64921.26,0.00231],[64927.74,0.00231],[64934.22,0.00231],[64935.52,5.853027],[65020.2,6.877687],[65105.52,0.0],[65108.01,0.0],[65115.09,0.0],[65130.26,0.0],[65131.9,0.0],[65136.78,0.0]]}}
{"ch":"market.btcusdt.mbp.150","ts":1784133647607,"tick":{"seqNum":191847889590,"prevSeqNum":191847889565,"bids":[[64841.9,0.620904],[64767.03,0.092521],[64760.55,0.004632],[64752.77,11.793917],[64631.57,0.0]],"asks":[[64843.84,0.092645],[64885.65,0.090201],[64890.48,0.0],[64892.13,0.090203],[64898.62,0.002311],[64899.91,5.853022],[65020.2,0.0],[65105.25,0.0]]}}
{"ping":1784133647666}
{"ch":"market.btcusdt.mbp.150","ts":1784133647706,"tick":{"seqNum":191847889627,"prevSeqNum":191847889590,"bids":[[64843.85,0.229398],[64843.83,0.023802],[64841.91,0.023802],[64841.9,0.0],[64838.45,0.002587],[64830.5,0.0],[64822.41,0.0],[64812.72,0.0],[64807.06,0.015292],[64806.41,0.0],[64806.4,0.0],[64768.88,0.0],[64663.21,0.102725],[64631.57,3.8917835671342E-5]],"asks":[[64843.84,0.0],[64848.05,0.023802],[64848.06,0.039628],[64848.07,0.023802],[64848.08,0.0],[64848.11,0.0],[64848.13,0.0],[64848.15,0.0],[64848.2,0.0],[64863.14,0.229398],[64902.14,0.0],[64905.38,0.0],[64908.62,0.0],[64909.92,0.0],[64915.25,0.0],[65105.25,1.72E-6],[65106.42,0.156193],[65108.01,3.084801],[65115.09,9.256416],[65130.26,0.004892],[65131.9,0.34],[65136.78,0.167526]]}}
{"ch":"market.btcusdt.mbp.150","ts":1784133647803,"tick":{"seqNum":191847889650,"prevSeqNum":191847889627,"bids":[[64843.85,0.0],[64843.83,0.0],[64841.21,0.0],[64828.04,0.493636],[64774.02,0.0],[64770.78,0.0],[64767.54,0.0],[64766.24,0.0],[64629.25,0.004892],[64625.34,0.030846],[64625.06,0.121921],[64623.49,18.501344],[64620.68,2.7855711422844E-5],[64618.7,5.268957227286E-6]],"asks":[[64847.8,0.023802],[64848.06,0.0],[64848.2,0.229398],[64889.6,0.0],[64892.84,0.0],[64896.08,0.0],[64897.38,0.0],[65136.98,0.13388],[65137.84,0.020559],[65138.03,0.009655]]}}
{"ch":"market.btcusdt.mbp.150","ts":1784133647903,"tick":{"seqNum":191847889679,"prevSeqNum":191847889650,"bids":[[64841.91,0.0],[64838.19,0.0],[64822.45,0.421493],[64812.71,0.737525],[64802.97,2.309973],[64802.92,0.0],[64695.9,0.0],[64611.59,2.7755511022044E-4]],"asks":[[64844.79,0.039628],[64844.8,0.229398],[64890.49,2.313279],[64894.99,0.0],[64915.26,1.696405],[65020.21,3.438788],[65136.78,0.0],[65136.98,0.0],[65137.84,0.0],[65138.03,0.0]]}}
{"ch":"market.btcusdt.mbp.150","ts":1784133648030,"tick":{"seqNum":191847889707,"prevSeqNum":191847889679,"bids":[[64805.51,0.00162],[64780.69,0.11432],[64778.29,0.040013],[64777.45,0.212306],[64775.04,0.074308],[64774.21,0.394277],[64772.91,9.25048],[64771.8,0.137999],[64770.51,9.250509],[64705.68,6.169954],[64640.85,1.783273],[64632.95,0.0],[64632.65,0.0],[64632.3,0.0],[64631.57,0.0],[64629.25,0.0],[64625.34,0.0],[64625.06,0.0],[64623.49,0.0],[64620.68,0.0],[64618.7,0.0],[64611.59,0.0]],"asks":[[64854.91,0.0],[64887.19,0.012382],[64897.32,0.114319],[64900.57,0.212304],[64903.62,0.040011],[64903.81,0.394279],[64905.1,9.250447],[64906.86,0.074309],[64910.11,0.137999],[64911.4,9.250509],[64976.24,6.169954],[65041.07,4.324019],[65063.32,0.0],[65099.15,0.0],[65103.63,0.0],[65104.45,0.0],[65105.25,0.0],[65106.42,0.0],[65108.01,0.0],[65115.09,0.0],[65130.26,0.0],[65131.9,0.0]]}}
{"ch":"market.btcusdt.mbp.150","ts":1784133648112,"tick":{"seqNum":191847889729,"prevSeqNum":191847889707,"bids":[[64843.72,0.023802],[64843.71,0.092645],[64807.07,0.00162],[64805.51,0.0],[64796.15,0.0],[64767.03,0.094836],[64760.55,0.006948],[64754.07,0.002316],[64752.77,17.646935],[64718.36,4.973767],[64653.52,0.0],[64634.81,0.0]],"asks":[[64887.59,0.002311],[64894.08,0.002311],[64900.56,0.002311],[64901.86,5.853018],[64915.26,0.0],[64966.09,0.0],[65030.94,0.0],[65093.64,0.0]]}}
{"ch":"market.btcusdt.mbp.150","ts":1784133648206,"tick":{"seqNum":191847889767,"prevSeqNum":191847889729,"bids":[[64843.72,0.0],[64833.44,0.0],[64830.5,0.229398],[64822.45,0.0],[64822.42,0.410387],[64813.18,0.0],[64812.71,0.0],[64807.07,0.0],[64804.3,0.00162],[64802.97,0.0],[64802.96,2.589547],[64718.36,0.0],[64695.95,8.565284],[64634.81,0.353982],[64632.95,2.1232464929859E-5],[64632.65,3.7037037037037E-4]],"asks":[[64890.49,2.313235],[64915.26,1.696372],[64972.58,0.0],[65020.21,3.438865],[65037.42,0.0],[65093.64,0.122878]]}}
{"ch":"market.btcusdt.mbp.150","ts":1784133648313,"tick":{"seqNum":191847889784,"prevSeqNum":191847889767,"bids":[[64843.71,0.116447],[64767.03,0.097151],[64766.47,0.0],[64760.55,0.009264],[64756.74,0.0],[64754.07,0.004632],[64753.5,0.0],[64752.77,23.499943],[64752.21,0.0],[64632.3,0.10873],[64631.57,3.8917835671342E-5],[64629.25,0.004892],[64625.34,0.030846]],"asks":[[64883.93,0.0],[64893.65,0.0],[64896.89,0.0],[64898.19,0.0],[64918.14,0.00231],[64924.62,0.00231],[64931.11,0.00231],[64932.4,5.853027]]}}
{"ch":"market.btcusdt.mbp.150","ts":1784133648404,"tick":{"seqNum":191847889798,"prevSeqNum":191847889784,"bids":[[64844.78,0.023802],[64833.49,0.229398],[64807.07,0.00162],[64804.3,0.0],[64629.25,0.0],[64625.34,0.0]],"asks":[[64844.79,0.0],[64844.8,0.0],[64845.41,0.229398],[64845.46,0.039628],[64845.47,0.620904],[64915.26,0.0]]}}
{"ch":"market.btcusdt.mbp.150","ts":1784133648513,"tick":{"seqNum":191847889847,"prevSeqNum":191847889798,"bids":[[64837.87,0.620904],[64822.42,0.0],[64822.41,0.360824],[64812.65,0.644272],[64807.07,0.0],[64802.92,2.367132],[64697.13,0.0],[64695.95,0.0],[64644.78,0.0],[64632.3,0.0],[64629.25,0.004892],[64625.34,0.030846]],"asks":[[64844.79,0.493636],[64845.46,0.0],[64845.47,0.0],[64848.04,0.039628],[64853.06,0.493636],[64890.49,0.0],[64915.26,1.696349],[64981.57,0.0],[65020.21,0.0],[65046.41,0.0],[65099.15,0.132366],[65104.45,0.136335]]}}
{"ch":"market.btcusdt.mbp.150","ts":1784133648611,"tick":{"seqNum":191847889895,"prevSeqNum":191847889847,"bids":[[64812.65,0.0],[64784.79,0.030842],[64774.76,0.073242],[64773.35,0.0],[64773.27,0.0],[64770.11,0.0],[64770.03,0.0],[64766.87,0.0],[64766.78,0.0],[64765.57,0.0],[64765.49,0.0],[64765.04,0.07324],[64761.8,0.073241],[64760.5,0.073241],[64758.22,0.030842],[64716.08,0.030842],[64703.12,0.030842],[64695.68,0.154183],[64683.67,0.030842],[64664.23,0.030842],[64644.78,0.030842],[64630.85,0.154183],[64625.34,0.030842],[64623.49,18.501344],[64620.68,2.7855711422844E-5]],"asks":[[64875.18,0.0],[64878.42,0.077067],[64881.58,0.0],[64881.66,0.0],[64882.96,0.0],[64884.82,0.0],[64888.06,0.0],[64889.36,0.0],[64892.23,0.073242],[64901.96,0.073241],[64905.2,0.073243],[64906.49,0.073246],[64971.33,0.154183],[65036.17,0.154183],[65101.0,0.154183]]}}
{"ping":1784133648666}
{"ch":"market.btcusdt.mbp.150","ts":1784133648750,"tick":{"seqNum":191847889918,"prevSeqNum":191847889895,"bids":[[64844.78,0.0],[64843.71,0.0],[64837.87,0.0],[64828.04,0.0],[64822.41,0.0],[64804.3,0.00162],[64780.74,0.027773],[64619.94,0.150111],[64618.7,5.268957227286E-6],[64611.59,2.7755511022044E-4]],"asks":[[64841.23,0.229398],[64844.78,0.039628],[64848.04,0.0],[64853.06,0.0],[64887.2,0.0],[64915.26,0.0],[65075.75,0.12519],[65105.25,1.72E-6]]}}
{"ch":"market.btcusdt.mbp.150","ts":1784133648801,"tick":{"seqNum":191847889943,"prevSeqNum":191847889918,"bids":[[64822.38,0.409853],[64812.73,0.300894],[64781.07,0.114318],[64777.83,0.212306],[64774.59,0.394279],[64773.29,9.252437],[64708.47,6.169954],[64695.94,6.275039],[64630.85,0.0],[64629.25,0.0],[64625.34,0.0],[64623.49,0.0],[64620.68,0.0],[64619.94,0.0],[64618.7,0.0],[64611.59,0.0]],"asks":[[64883.97,0.114317],[64887.21,0.232862],[64890.46,0.394277],[64890.49,2.313343],[64915.26,1.696451],[64956.59,6.169954],[65020.21,3.438678],[65090.18,0.0],[65093.64,0.0],[65099.15,0.0],[65101.0,0.0],[65104.45,0.0],[65105.25,0.0]]}}
{"ch":"market.btcusdt.mbp.150","ts":1784133649007,"tick":{"seqNum":191847889970,"prevSeqNum":191847889943,"bids":[[64812.73,0.0],[64781.56,0.114317],[64778.32,0.212305],[64775.08,0.394279],[64773.78,9.251903],[64767.03,0.00926],[64760.54,0.0],[64754.06,0.004632],[64752.77,23.412046],[64708.96,4.976652],[64699.64,3.23902],[64643.64,0.659529],[64634.81,0.0],[64632.95,0.0],[64632.65,0.0],[64631.57,0.0]],"asks":[[64879.17,0.0],[64885.65,0.002311],[64889.97,0.114317],[64891.75,9.252437],[64892.13,0.002311],[64893.21,0.212303],[64893.43,0.0],[64896.45,0.394278],[64897.75,9.251903],[64915.26,0.0],[64962.58,6.169954],[64981.26,0.0],[65021.42,3.853484],[65027.41,3.852119],[65046.1,0.0],[65080.59,0.0],[65087.71,0.0],[65090.17,0.0]]}}
{"ch":"market.btcusdt.mbp.150","ts":1784133649008,"tick":{"seqNum":191847889971,"prevSeqNum":191847889970,"bids":[],"asks":[[65071.67,0.0],[65080.59,12.337039]]}}
{"ch":"market.btcusdt.mbp.150","ts":1784133649107,"tick":{"seqNum":191847890009,"prevSeqNum":191847889971,"bids":[[64822.43,0.36138],[64812.66,0.274025],[64805.51,0.00162],[64804.3,0.0],[64749.19,0.002316],[64742.71,0.002316],[64736.23,0.002317],[64734.93,5.853013],[64717.49,0.0],[64695.98,6.974761],[64652.65,0.0],[64635.79,0.0]],"asks":[[64841.23,0.322043],[64915.26,1.696451],[65006.82,0.0],[65018.94,0.0],[65025.42,0.0],[65031.91,0.0],[65033.2,0.0],[65087.71,0.020559],[65090.17,0.001807],[65090.18,0.03176],[65093.64,0.122878]]}}
{"ch":"market.btcusdt.mbp.150","ts":1784133649204,"tick":{"seqNum":191847890037,"prevSeqNum":191847890009,"bids":[[64822.43,0.0],[64822.38,0.0],[64812.71,0.274545],[64812.66,0.0],[64805.51,0.0],[64804.3,0.00162],[64767.18,0.08789],[64760.7,0.087897],[64754.22,0.087897],[64752.92,0.087894],[64695.98,0.0],[64695.94,0.0]],"asks":[[64841.23,0.345845],[64841.95,0.039628],[64841.96,0.620904],[64844.78,0.0],[64848.05,0.0],[64848.07,0.0],[64848.09,0.0],[64879.01,0.087894],[64885.49,0.087895],[64891.98,0.087889],[64893.27,0.087883],[64915.26,0.0],[65093.64,0.0]]}}
{"ch":"market.btcusdt.mbp.150","ts":1784133649350,"tick":{"seqNum":191847890079,"prevSeqNum":191847890037,"bids":[[64822.45,0.387817],[64821.2,0.493636],[64812.71,0.0],[64792.76,0.493636],[64767.03,0.006945],[64760.55,0.006948],[64754.06,0.002316],[64752.77,17.559034],[64749.35,0.002316],[64742.87,0.002316],[64736.38,0.002317],[64735.09,5.853023],[64695.94,6.628575],[64642.56,0.0],[64641.33,0.0],[64640.85,0.0],[64639.44,0.0],[64639.17,0.0],[64637.37,0.0],[64636.59,0.0]],"asks":[[64841.23,0.116447],[64841.95,0.0],[64841.96,0.0],[64844.78,0.039628],[64888.25,0.0],[64890.49,4.626686],[64894.73,0.0],[64901.21,0.0],[64902.51,0.0],[64915.26,1.696451],[65018.78,0.002307],[65025.27,0.002306],[65031.75,0.002306],[65033.04,5.853034]]}}
{"ch":"market.btcusdt.mbp.150","ts":1784133649413,"tick":{"seqNum":191847890095,"prevSeqNum":191847890079,"bids":[[64699.64,0.154219]],"asks":[[64890.49,0.0],[65020.21,0.0],[65093.64,0.122878],[65099.15,0.132366]]}}
{"ch":"market.btcusdt.mbp.150","ts":1784133649506,"tick":{"seqNum":191847890117,"prevSeqNum":191847890095,"bids":[[64822.45,0.0],[64767.03,0.00463],[64760.55,0.004632],[64754.06,0.0],[64752.77,11.706026],[64749.19,0.0],[64742.71,0.0],[64736.23,0.0],[64734.93,0.0],[64642.56,0.117386],[64641.33,0.309918],[64640.85,1.783273],[64639.44,7.0941883767535E-4],[64639.17,7.532805769808E-6],[64637.37,1.843687374749E-6]],"asks":[[64885.65,0.0],[64890.49,2.313343],[64892.13,0.0],[64898.62,0.0],[64899.91,0.0],[64915.26,0.0],[64921.26,0.0],[64927.74,0.0],[64934.22,0.0],[64935.52,0.0],[65013.76,0.0],[65078.6,0.0],[65101.0,0.154183],[65104.45,0.136335],[65105.25,1.72E-6],[65106.42,0.156193],[65108.01,3.084801],[65109.66,0.16455],[65115.09,9.256416],[65130.26,0.004892],[65131.9,0.34],[65136.78,0.167526]]}}
{"ch":"market.btcusdt.mbp.150","ts":1784133649601,"tick":{"seqNum":191847890165,"prevSeqNum":191847890117,"bids":[[64822.43,0.359035],[64805.51,0.00162],[64804.3,0.0],[64767.1,0.002315],[64760.62,0.002316],[64754.14,0.002316],[64752.84,5.853015],[64695.95,6.748534],[64695.94,0.0],[64688.02,3.085472],[64642.56,0.0],[64641.33,0.0],[64640.85,0.0],[64639.44,0.0],[64639.17,0.0],[64637.37,0.0]],"asks":[[64888.17,0.002311],[64890.49,4.626686],[64894.65,0.002311],[64901.14,0.002311],[64902.43,5.85302],[64967.26,3.085472],[65020.21,6.877356],[65032.08,1.049802],[65106.42,0.0],[65108.01,0.0],[65109.66,0.0],[65115.09,0.0],[65130.26,0.0],[65131.9,0.0],[65136.78,0.0]]}}
{"ping":1784133649669}
{"ch":"market.btcusdt.mbp.150","ts":1784133649714,"tick":{"seqNum":191847890212,"prevSeqNum":191847890165,"bids":[[64822.43,0.0],[64822.41,0.359599],[64805.51,0.0],[64778.16,0.0],[64774.92,0.0],[64771.68,0.0],[64770.38,0.0],[64695.95,0.0],[64642.56,0.117386],[64641.33,0.309918],[64640.85,1.783273],[64639.44,7.0941883767535E-4],[64639.17,7.532805769808E-6],[64637.37,1.843687374749E-6]],"asks":[[64890.49,2.313343],[64915.26,1.696451],[64916.72,0.0],[64919.96,0.0],[64923.2,0.0],[64924.5,0.0],[65020.21,3.438678],[65029.49,0.053206],[65106.42,0.156193],[65108.01,3.084801]]}}
{"ch":"market.btcusdt.mbp.150","ts":1784133649859,"tick":{"seqNum":191847890233,"prevSeqNum":191847890212,"bids":[[64841.22,0.116447],[64804.3,0.00162],[64767.1,0.00463],[64760.62,0.004632],[64754.14,0.004632],[64752.84,11.706035],[64749.27,0.002316],[64742.78,0.002316],[64736.3,0.002317],[64735.01,5.853007],[64688.02,5.674551],[64641.33,0.0],[64640.85,0.0],[64639.44,0.0],[64639.17,0.0],[64637.37,0.0]],"asks":[[64841.9,0.620904],[64885.58,0.002311],[64892.06,0.002311],[64898.54,0.002311],[64899.84,5.853034],[64921.19,0.00231],[64927.67,0.00231],[64934.15,0.00231],[64935.45,5.853026],[64964.66,3.085472],[65087.71,0.0],[65090.17,0.0],[65090.18,0.0],[65093.64,0.0],[65099.15,0.0],[65101.0,0.0],[65104.45,0.0],[65105.25,0.0],[65106.42,0.0],[65108.01,0.0]]}}
{"ch":"market.btcusdt.mbp.150","ts":1784133649910,"tick":{"seqNum":191847890246,"prevSeqNum":191847890233,"bids":[[64780.69,0.0],[64777.45,0.0],[64774.21,0.0],[64772.91,0.0],[64641.33,0.309918],[64640.85,1.783273],[64639.44,7.0941883767535E-4],[64639.17,7.532805769808E-6]],"asks":[[64841.89,0.269026],[64844.78,0.0],[64897.32,0.0],[64900.57,0.0],[64903.81,0.0],[64905.1,0.0],[64915.26,0.0],[65053.73,4.326601],[65087.71,0.020559],[65090.17,0.001807],[65090.18,0.03176],[65093.64,0.122878]]}}
{"ch":"market.btcusdt.mbp.150","ts":1784133650001,"tick":{"seqNum":191847890295,"prevSeqNum":191847890246,"bids":[[64833.45,0.620904],[64812.7,0.14269],[64807.07,0.00162],[64804.3,0.0],[64778.6,0.040012],[64775.36,0.074308],[64772.12,0.137999],[64770.82,9.250347],[64705.99,6.169954],[64695.96,6.327543],[64644.78,0.0],[64643.77,0.0],[64643.64,0.0],[64642.56,0.0],[64641.33,0.0],[64640.85,0.0],[64639.44,0.0],[64639.17,0.0]],"asks":[[64841.88,0.039628],[64841.89,0.229398],[64854.52,6.1E-5],[64878.13,0.493636],[64890.49,0.0],[64915.26,1.696451],[64916.28,0.040013],[64919.52,0.074307],[64922.76,0.137996],[64924.06,9.250347],[64988.89,6.169954],[65020.21,0.0],[65075.15,0.0],[65075.75,0.0],[65080.59,0.0],[65087.71,0.0],[65090.17,0.0],[65090.18,0.0],[65093.64,0.0]]}}
{"ch":"market.btcusdt.mbp.150","ts":1784133650124,"tick":{"seqNum":191847890310,"prevSeqNum":191847890295,"bids":[[64767.03,0.002315],[64760.55,0.002316],[64754.07,0.002316],[64752.77,5.853008],[64699.64,0.0],[64644.78,0.030842]],"asks":[[64887.59,0.0],[64894.08,0.0],[64900.56,0.0],[64901.86,0.0],[64915.26,0.0],[64974.77,0.0],[65039.61,0.0],[65075.15,9.250672],[65075.75,0.12519],[65080.59,12.337039],[65087.71,0.020559],[65090.17,0.001807],[65090.18,0.03176],[65093.64,0.122878]]}}
{"ch":"market.btcusdt.mbp.150","ts":1784133650203,"tick":{"seqNum":191847890448,"prevSeqNum":191847890310,"bids":[[64841.22,0.0],[64839.82,0.0],[64838.45,0.0],[64834.28,0.0],[64833.49,0.0],[64833.45,0.0],[64832.81,0.0],[64830.5,0.0],[64829.48,0.023802],[64829.47,0.004416],[64827.9,0.0],[64825.08,0.0],[64822.43,0.296879],[64822.42,0.229398],[64822.41,0.0],[64822.28,0.0],[64821.8,0.0],[64821.2,0.0],[64818.98,0.0],[64818.95,0.229398],[64816.31,0.229398],[64814.91,0.0],[64812.7,0.0],[64812.67,0.151138],[64811.5,2.941534],[64811.19,0.0],[64807.13,0.00162],[64807.12,0.229398],[64807.07,0.0],[64804.3,0.229398],[64804.29,0.0],[64802.96,0.0],[64796.51,0.229398],[64788.72,0.229398],[64781.56,0.0],[64781.07,0.0],[64778.6,0.0],[64778.32,0.0],[64778.29,0.0],[64777.83,0.0],[64775.36,0.0],[64775.08,0.0],[64775.04,0.0],[64774.59,0.0],[64773.78,0.0],[64773.29,0.0],[64772.12,0.0],[64771.8,0.0],[64770.82,0.0],[64770.51,0.0],[64767.03,0.0],[64760.55,0.0],[64754.07,0.0],[64752.77,0.0],[64727.11,0.0],[64720.63,0.0],[64714.14,0.0],[64707.66,0.0],[64701.18,0.0],[64695.98,6.672925],[64695.96,0.0],[64643.77,0.086041],[64643.64,0.659529],[64641.33,0.309918],[64641.17,1.677535],[64640.85,1.783273],[64639.44,7.0941883767535E-4],[64639.17,7.532805769808E-6],[64637.37,1.843687374749E-6],[64636.59,0.020559],[64635.79,1.27254509018E-6],[64632.95,2.1232464929859E-5],[64632.65,3.7037037037037E-4],[64631.57,3.8917835671342E-5],[64630.85,0.154183],[64629.25,0.004892],[64625.34,0.030842],[64623.49,18.501344],[64623.21,0.109535],[64620.68,2.7855711422844E-5],[64619.94,0.150111],[64618.7,5.268957227286E-6],[64611.59,2.7755511022044E-4],[64609.21,0.03176],[64606.49,2.19559339008512E-4],[64605.89,0.030842],[64605.53,0.150489],[64600.0,0.005080013383674088],[64599.9,0.45],[64598.04,0.152126],[64594.96,1.603206412825E-6],[64592.27,1.422845691382E-6],[64591.83,1.72234468937875E-4],[64591.72,4.478957915831E-6]],"asks":[[64836.36,0.023802],[64836.37,0.229398],[64838.97,0.229398],[64839.83,0.023802],[64841.23,0.493636],[64841.88,0.0],[64841.9,0.0],[64844.79,0.0],[64863.15,0.0],[64870.15,0.0],[64872.68,0.0],[64873.23,0.002512],[64878.13,0.0],[64880.47,0.0],[64883.97,0.0],[64887.21,0.020559],[64890.46,0.0],[64890.49,2.313368],[64891.75,0.0],[64896.9,0.114319],[64900.14,0.212303],[64903.39,0.39428],[64903.62,0.0],[64904.68,9.250448],[64906.86,0.0],[64910.11,0.0],[64911.4,0.0],[64913.99,0.0],[64915.26,1.696469],[64918.14,0.0],[64920.47,0.0],[64924.62,0.0],[64926.96,0.0],[64931.11,0.0],[64932.4,0.0],[64933.44,0.0],[64939.92,0.0],[65020.21,3.438634],[65101.0,0.154183],[65102.58,0.155431],[65105.25,1.72E-6],[65106.42,0.156193],[65108.01,3.084801],[65109.66,0.16455],[65115.09,9.256416],[65130.26,0.004892],[65131.9,0.34],[65136.78,0.167526],[65136.98,0.13388],[65137.84,0.020559]]}}
{"ch":"market.btcusdt.mbp.150","ts":1784133650310,"tick":{"seqNum":191847890506,"prevSeqNum":191847890448,"bids":[[64829.48,0.0],[64829.47,0.0],[64824.51,0.023802],[64824.5,0.0],[64819.13,0.00483],[64814.16,0.005076],[64811.51,0.229398],[64807.13,0.0],[64802.92,0.0],[64792.77,0.00162],[64792.72,0.01712],[64780.74,0.0],[64774.76,0.0],[64765.04,0.0],[64761.8,0.0],[64760.5,0.0],[64760.49,0.03347],[64663.21,0.0],[64643.95,0.112178],[64598.04,0.0],[64591.06,0.158119],[64588.05,1.382349994991E-6],[64586.46,0.020559],[64586.44,0.030842]],"asks":[[64832.92,0.023802],[64832.94,0.023802],[64832.96,0.023802],[64832.97,0.229398],[64836.36,0.0],[64839.83,0.0],[64848.21,0.0],[64865.8,0.0],[64890.49,0.0],[64892.23,0.0],[64901.96,0.0],[64905.2,0.0],[64906.49,0.0],[65020.21,0.0],[65138.03,0.009655],[65150.0,0.00349055],[65150.3,0.03176],[65172.84,9.250672],[65179.91,0.853029],[65183.48,2.03E-6]]}}
{"ch":"market.btcusdt.mbp.150","ts":1784133650406,"tick":{"seqNum":191847890553,"prevSeqNum":191847890506,"bids":[[64825.58,0.023802],[64822.43,0.0],[64822.42,0.0],[64818.95,0.0],[64812.67,0.0],[64805.5,0.0],[64792.77,0.0],[64791.81,0.0],[64789.68,0.006647],[64775.99,0.016617],[64770.35,0.0],[64767.19,0.039629],[64757.91,9.250509],[64753.12,0.026586],[64715.26,0.0],[64696.87,0.066707],[64643.77,0.0],[64624.49,0.083083],[64585.71,6.81157968546529E-4],[64585.31,0.159867]],"asks":[[64829.8,0.039628],[64829.81,0.229398],[64863.14,0.0],[64871.56,3.539169],[64872.69,0.0],[64880.8,0.0],[64889.97,0.0],[64893.21,0.0],[64896.45,0.0],[64897.75,0.0],[64915.26,0.0],[64925.58,0.164018],[64943.14,0.0],[65108.53,0.166541],[65109.66,0.0],[65115.12,0.164018],[65115.2,0.132932],[65136.78,0.0],[65136.98,0.0],[65187.56,4.78E-6],[65187.96,0.020559],[65189.87,1.95E-6],[65201.6,2.119E-5],[65206.47,1.563E-5]]}}
{"ch":"market.btcusdt.mbp.150","ts":1784133650521,"tick":{"seqNum":191847890597,"prevSeqNum":191847890553,"bids":[[64765.69,0.040012],[64765.24,0.11432],[64762.45,0.074309],[64762.0,0.212304],[64761.95,0.002316],[64760.77,0.073247],[64759.21,0.137996],[64758.76,0.394277],[64757.47,9.252437],[64755.47,0.002316],[64748.99,0.002316],[64747.69,4.382495],[64720.72,0.009763],[64714.24,0.030089],[64707.76,0.092723],[64701.27,0.285729],[64694.79,12.336152],[64611.59,0.0],[64609.21,0.0],[64606.49,0.0],[64605.89,0.0],[64605.53,0.0],[64600.0,0.0],[64599.9,0.0],[64594.96,0.0],[64592.27,0.0],[64591.83,0.0],[64591.72,0.0],[64591.06,0.0],[64588.05,0.0],[64586.46,0.0],[64586.44,0.0],[64585.71,0.0],[64585.31,0.0]],"asks":[[64866.59,3.539401],[64871.56,0.0],[64871.8,0.114317],[64875.04,0.212303],[64878.28,0.394277],[64879.58,9.252437],[64894.02,0.04001],[64897.26,0.074308],[64897.71,7.786701],[64900.51,0.137999],[64901.8,9.250509],[64907.58,0.009764],[64909.76,0.0],[64911.82,0.00231],[64914.06,0.030091],[64918.3,0.00231],[64920.54,0.092723],[64924.78,0.00231],[64926.08,5.853027],[64927.03,0.285732],[64933.51,12.336152],[64970.33,4.684178],[64990.9,3.085743],[64995.64,0.0],[65055.72,1.048051],[65108.01,0.0],[65108.53,0.0],[65115.09,0.0],[65115.12,0.0],[65115.2,0.0],[65130.26,0.0],[65131.9,0.0],[65137.84,0.0],[65138.03,0.0],[65150.0,0.0],[65150.3,0.0],[65172.84,0.0],[65179.91,0.0],[65183.48,0.0],[65187.56,0.0],[65187.96,0.0],[65189.87,0.0],[65201.6,0.0],[65206.47,0.0]]}}
{"ch":"market.btcusdt.mbp.150","ts":1784133650602,"tick":{"seqNum":191847890622,"prevSeqNum":191847890597,"bids":[[64810.34,0.02243],[64800.66,0.042512],[64790.94,3.24408],[64790.31,1.161919],[64776.0,0.039629],[64767.19,0.0],[64751.05,0.073246],[64747.81,0.073248],[64746.51,0.073239],[64695.98,0.0],[64683.96,4.948094],[64625.34,0.0],[64624.49,0.0],[64623.49,0.0],[64623.21,0.0],[64620.68,0.0],[64619.94,0.0],[64618.7,0.0]],"asks":[[64829.81,0.322043],[64849.16,1.160864],[64878.22,0.073245],[64887.94,0.073241],[64891.19,0.073242],[64892.48,0.073242],[64903.2,1.696805],[65090.18,0.0],[65093.64,0.0],[65101.0,0.0],[65102.58,0.0],[65105.25,0.0],[65106.42,0.0]]}}
{"ping":1784133650668}
{"ch":"market.btcusdt.mbp.150","ts":1784133650707,"tick":{"seqNum":191847890682,"prevSeqNum":191847890622,"bids":[[64792.77,0.00162],[64790.92,3.594473],[64784.79,0.0],[64779.1,0.030851],[64776.0,0.0],[64765.64,0.114318],[64762.4,0.212303],[64759.16,0.39428],[64758.22,0.0],[64757.86,9.251903],[64752.52,0.030851],[64716.08,0.0],[64710.39,0.030851],[64703.12,0.0],[64697.43,0.030851],[64683.89,5.187184],[64683.67,0.0],[64677.99,0.030851],[64664.23,0.0],[64658.54,0.030851],[64644.78,0.0],[64639.1,0.030851],[64635.79,0.0],[64632.95,0.0],[64632.65,0.0],[64631.57,0.0],[64630.85,0.0],[64629.25,0.0]],"asks":[[64828.53,0.023802],[64828.55,0.023802],[64828.57,0.620904],[64829.8,0.0],[64829.81,0.229398],[64832.94,0.0],[64832.96,0.0],[64871.49,0.002603],[64875.12,0.0],[64877.89,0.114316],[64878.43,4.627674],[64881.13,0.212303],[64884.38,0.394279],[64885.67,9.251901],[64903.2,0.0],[65008.13,6.875642],[65075.15,0.0],[65075.75,0.0],[65080.59,0.0],[65087.71,0.0],[65090.17,0.0]]}}
{"ch":"market.btcusdt.mbp.150","ts":1784133650852,"tick":{"seqNum":191847890716,"prevSeqNum":191847890682,"bids":[[64825.58,0.0],[64816.31,0.0],[64814.17,0.229398],[64810.34,0.0],[64809.0,0.101858],[64806.34,0.493636],[64800.66,0.0],[64799.22,0.050702],[64792.78,0.00162],[64792.77,0.229398],[64792.76,0.0],[64767.18,0.0],[64760.7,0.0],[64754.22,0.0],[64752.92,0.0],[64635.79,1.27254509018E-6],[64632.95,2.1232464929859E-5],[64632.65,3.7037037037037E-4],[64631.57,3.8917835671342E-5]],"asks":[[64826.09,0.039628],[64826.1,0.229398],[64828.57,0.0],[64859.73,0.0],[65008.13,6.875603]]}}
{"ch":"market.btcusdt.mbp.150","ts":1784133650904,"tick":{"seqNum":191847890737,"prevSeqNum":191847890716,"bids":[],"asks":[[64825.79,0.493636],[64836.16,2.377157],[64861.65,0.612191],[64878.43,0.0],[65008.13,0.0],[65066.92,0.0]]}}
{"ch":"market.btcusdt.mbp.150","ts":1784133651041,"tick":{"seqNum":191847890746,"prevSeqNum":191847890737,"bids":[[64825.77,0.023802],[64631.57,0.0]],"asks":[[64825.78,0.039628],[64826.09,0.0],[64841.23,0.0],[64919.31,0.0],[65066.92,1.38E-6],[65075.15,9.250672]]}}
{"ch":"market.btcusdt.mbp.150","ts":1784133651102,"tick":{"seqNum":191847890759,"prevSeqNum":191847890746,"bids":[],"asks":[[64825.78,0.0],[64825.79,0.0],[64826.1,0.0],[64828.52,0.039628],[64858.02,0.002788],[64862.99,0.004489],[64873.23,0.0],[65060.55,0.128227]]}}
{"ch":"market.btcusdt.mbp.150","ts":1784133651201,"tick":{"seqNum":191847890774,"prevSeqNum":191847890759,"bids":[[64809.0,0.0],[64799.22,0.0],[64749.35,0.0],[64742.87,0.0],[64736.38,0.0],[64735.09,0.0],[64631.57,3.8917835671342E-5],[64630.85,0.154183],[64629.25,0.004892],[64624.49,0.083083],[64623.49,18.501344],[64623.21,0.109535]],"asks":[[64828.5,0.039628],[64828.51,0.023802],[64828.52,0.0],[64828.55,0.0],[64832.92,0.0],[65018.78,0.0],[65025.27,0.0],[65031.75,0.0],[65033.04,0.0],[65075.75,0.12519],[65080.59,12.337039],[65086.97,0.151184],[65087.71,0.020559],[65090.17,0.001807]]}}
{"ch":"market.btcusdt.mbp.150","ts":1784133651303,"tick":{"seqNum":191847890812,"prevSeqNum":191847890774,"bids":[[64827.17,0.023802],[64809.01,0.00162],[64809.0,0.146897],[64808.98,0.16074],[64799.25,0.077947],[64799.23,0.075907],[64792.78,0.0],[64630.85,0.0],[64629.25,0.0],[64624.49,0.0],[64623.49,0.0],[64623.21,0.0]],"asks":[[64827.18,0.322043],[64828.49,0.023802],[64828.5,0.0],[64836.15,0.039628],[64877.02,4.627689],[64879.01,0.0],[64885.49,0.0],[64891.98,0.0],[64893.27,0.0],[64901.79,1.696819],[65006.71,6.875615],[65090.17,0.0]]}}
{"ch":"market.btcusdt.mbp.150","ts":1784133651452,"tick":{"seqNum":191847890816,"prevSeqNum":191847890812,"bids":[],"asks":[[64827.48,0.039628],[64827.49,0.620904],[64836.15,0.0],[64877.02,2.313845],[65087.71,0.0]]}}
{"ch":"market.btcusdt.mbp.150","ts":1784133651516,"tick":{"seqNum":191847890842,"prevSeqNum":191847890816,"bids":[[64816.43,0.620904],[64741.3,0.002316],[64734.82,0.002317],[64728.34,0.002317],[64727.05,5.853341669338677],[64635.79,0.0],[64632.95,0.0],[64632.65,0.0],[64631.57,0.0]],"asks":[[64827.18,0.815679],[64877.02,0.0],[64894.65,0.0],[65006.71,0.0],[65009.83,0.002307],[65016.31,0.002307],[65022.79,0.002306],[65024.09,5.853027],[65086.97,0.0]]}}
{"ch":"market.btcusdt.mbp.150","ts":1784133651637,"tick":{"seqNum":191847890873,"prevSeqNum":191847890842,"bids":[[64821.79,0.002411],[64814.16,0.0],[64767.1,0.002315],[64760.62,0.002316],[64759.14,0.087898],[64754.14,0.002316],[64752.84,5.85302],[64752.66,0.087892],[64746.18,0.087891],[64744.88,0.087896],[64706.16,0.0],[64680.07,0.154177],[64641.33,0.0],[64639.1,0.0],[64637.37,0.0],[64636.59,0.0]],"asks":[[64827.49,0.0],[64870.05,0.08789],[64876.54,0.087895],[64883.02,0.087897],[64884.31,0.087894],[64888.17,0.0],[64901.14,0.0],[64901.79,0.0],[64902.43,0.0],[64949.13,0.154177],[64976.65,0.0],[65013.94,0.154177],[65041.49,0.0],[65078.76,0.136402]]}}
{"ping":1784133651675}
{"ch":"market.btcusdt.mbp.150","ts":1784133651717,"tick":{"seqNum":191847890930,"prevSeqNum":191847890873,"bids":[[64827.17,0.0],[64825.77,0.0],[64819.13,0.0],[64816.43,0.0],[64814.17,0.0],[64811.52,0.229398],[64811.51,0.0],[64811.5,0.0],[64803.29,2.941989],[64790.31,0.0],[64767.1,0.0],[64765.69,0.0],[64762.45,0.0],[64760.62,0.0],[64759.21,0.0],[64757.91,0.0],[64754.14,0.0],[64752.84,0.0],[64749.27,0.0],[64742.78,0.0],[64736.3,0.0],[64735.01,0.0],[64639.1,0.030851],[64637.37,1.843687374749E-6],[64636.59,0.020559],[64635.79,1.27254509018E-6],[64632.95,2.1232464929859E-5],[64632.65,3.7037037037037E-4],[64631.57,3.8917835671342E-5],[64630.85,0.154183],[64629.25,0.004892],[64624.49,0.083083],[64623.49,18.501344],[64623.21,0.109535],[64620.68,2.7855711422844E-5],[64619.94,0.150111],[64619.65,0.030851],[64618.7,5.268957227286E-6],[64615.26,0.154177],[64611.59,2.7755511022044E-4]],"asks":[[64824.52,0.322043],[64827.17,0.039628],[64827.18,0.723034],[64827.48,0.0],[64849.16,0.0],[64851.0,0.006694],[64857.13,0.0],[64867.83,0.0],[64877.02,2.313844],[64885.58,0.0],[64892.06,0.0],[64898.54,0.0],[64899.84,0.0],[64900.14,0.0],[64901.79,1.696819],[64921.19,0.0],[64927.67,0.0],[64934.15,0.0],[64935.45,0.0],[65006.71,3.437809],[65086.97,0.151184],[65087.71,0.020559],[65090.17,0.001807],[65090.18,0.03176],[65091.94,0.14253],[65093.64,0.122878],[65101.0,0.154183]]}}
{"ch":"market.btcusdt.mbp.150","ts":1784133651813,"tick":{"seqNum":191847890954,"prevSeqNum":191847890930,"bids":[[64814.16,0.004606],[64809.01,0.0],[64809.0,0.0],[64808.98,0.0],[64799.25,0.0],[64799.23,0.0],[64790.94,0.0],[64790.92,0.0],[64765.65,0.039629],[64683.96,0.0],[64683.89,0.0],[64609.21,0.03176],[64606.49,2.19559339008512E-4],[64605.53,0.150489],[64600.21,0.030851],[64600.0,0.005080013383674088],[64599.9,0.45],[64594.96,1.603206412825E-6]],"asks":[[64863.63,0.01689],[64877.02,0.0],[64880.57,0.0],[64896.9,0.0],[64903.39,0.0],[64904.68,0.0],[65006.71,0.0],[65105.25,1.72E-6],[65108.01,3.084801],[65115.09,9.256416],[65115.12,0.164018],[65115.2,0.132932]]}}
{"ch":"market.btcusdt.mbp.150","ts":1784133651901,"tick":{"seqNum":191847890965,"prevSeqNum":191847890954,"bids":[[64785.21,1.16201],[64766.3,0.039629],[64765.65,0.0],[64741.31,0.002316],[64728.34,0.004634],[64720.08,0.0],[64594.96,0.0]],"asks":[[64844.06,1.160956],[64901.79,0.0],[64925.1,0.00231],[64987.36,0.0],[65052.21,0.0],[65130.26,0.004892]]}}
{"ch":"market.btcusdt.mbp.150","ts":1784133652002,"tick":{"seqNum":191847890999,"prevSeqNum":191847890965,"bids":[[64809.0,0.00162],[64808.99,0.098816],[64799.21,0.051525],[64789.51,3.239562],[64766.3,0.0],[64760.16,0.1149115935935936],[64756.92,0.212306],[64753.68,0.394278],[64752.39,9.25048],[64734.83,0.002317],[64727.05,11.706357669338677],[64687.58,2.966041],[64682.54,5.011853],[64618.7,0.0],[64615.26,0.0],[64611.59,0.0],[64609.21,0.0],[64606.49,0.0],[64605.53,0.0],[64600.21,0.0],[64600.0,0.0],[64599.9,0.0]],"asks":[[64836.15,6.1E-5],[64854.52,0.0],[64877.02,2.313939],[64879.66,0.114316],[64882.9,0.212305],[64886.14,0.394279],[64887.43,9.25048],[64912.14,0.00231],[64918.62,0.00231],[64926.4,5.853027],[64952.25,6.171772],[65006.71,3.437644],[65017.07,3.853749],[65090.17,0.0],[65090.18,0.0],[65091.94,0.0],[65093.64,0.0],[65101.0,0.0],[65105.25,0.0],[65108.01,0.0],[65115.09,0.0],[65115.12,0.0],[65115.2,0.0],[65130.26,0.0]]}}
{"ch":"market.btcusdt.mbp.150","ts":1784133652110,"tick":{"seqNum":191847891049,"prevSeqNum":191847890999,"bids":[[64808.94,0.098313],[64799.27,0.047072],[64765.24,0.0],[64762.0,0.0],[64758.76,0.0],[64757.47,0.0],[64682.48,4.216537],[64618.7,5.268957227286E-6]],"asks":[[64826.18,0.620904],[64871.8,0.0],[64875.04,0.0],[64878.28,0.0],[64879.58,0.0],[64901.79,1.696888],[64936.78,0.068496],[64954.89,0.0],[65052.1,0.0],[65090.17,0.001807],[65090.18,0.03176],[65091.94,0.14253]]}}
{"ch":"market.btcusdt.mbp.150","ts":1784133652212,"tick":{"seqNum":191847891056,"prevSeqNum":191847891049,"bids":[],"asks":[[64826.17,0.039628],[64827.17,0.0],[64877.02,4.627878]]}}
{"ch":"market.btcusdt.mbp.150","ts":1784133652311,"tick":{"seqNum":191847891082,"prevSeqNum":191847891056,"bids":[[64814.24,0.229398],[64814.23,0.620904],[64760.77,0.0],[64751.05,0.0],[64747.81,0.0],[64746.51,0.0],[64615.26,0.154177],[64611.59,2.7755511022044E-4]],"asks":[[64824.52,0.815679],[64825.89,0.039628],[64825.9,0.11],[64826.17,0.0],[64877.02,6.941817],[64878.22,0.0],[64887.94,0.0],[64891.19,0.0],[64892.48,0.0],[64901.79,0.0],[64916.28,0.0],[64919.52,0.0],[64922.76,0.0],[64924.06,0.0],[65006.71,6.875288],[65093.64,0.122878],[65101.0,0.154183],[65105.25,1.72E-6],[65108.01,3.084801],[65115.09,9.256416],[65115.12,0.164018],[65115.2,0.132932],[65130.26,0.004892]]}}
{"ch":"market.btcusdt.mbp.150","ts":1784133652406,"tick":{"seqNum":191847891133,"prevSeqNum":191847891082,"bids":[[64773.33,0.493636],[64765.64,0.0],[64762.4,0.0],[64761.95,0.0],[64759.77,0.114317],[64759.16,0.0],[64757.86,0.0],[64756.53,0.212304],[64755.47,0.0],[64753.29,0.39428],[64751.99,9.252437],[64748.99,0.0],[64747.69,0.0],[64609.21,0.03176],[64606.49,2.19559339008512E-4],[64605.53,0.150489]],"asks":[[64865.88,0.114317],[64869.12,0.212303],[64872.36,0.394279],[64873.66,9.252433],[64877.02,0.0],[64877.89,0.0],[64881.13,0.0],[64884.38,0.0],[64885.67,0.0],[64911.82,0.0],[64918.3,0.0],[64924.78,0.0],[64926.08,0.0],[65006.71,0.0],[65131.9,0.34],[65137.84,0.020559],[65138.03,0.009655],[65139.64,0.386234],[65150.0,0.00349055],[65150.3,0.03176]]}}
{"ch":"market.btcusdt.mbp.150","ts":1784133652501,"tick":{"seqNum":191847891153,"prevSeqNum":191847891133,"bids":[[64713.44,0.0],[64706.96,0.0],[64700.48,0.0],[64694.0,0.0],[64687.52,0.0],[64600.21,0.030851],[64600.0,0.005080013383674088],[64599.9,0.45],[64594.96,1.603206412825E-6],[64592.27,1.422845691382E-6]],"asks":[[64877.02,2.313939],[65006.71,3.437644],[65024.34,0.0],[65030.83,0.0],[65037.31,0.0],[65043.79,0.0],[65050.27,0.0],[65139.64,0.759604],[65172.84,9.250672],[65179.91,0.853029],[65183.48,2.03E-6]]}}
{"ch":"market.btcusdt.mbp.150","ts":1784133652607,"tick":{"seqNum":191847891203,"prevSeqNum":191847891153,"bids":[[64759.09,0.004632],[64757.19,0.040012],[64755.08,0.073243],[64753.95,0.074309],[64752.6,0.004632],[64750.7,0.137999],[64749.41,9.250347],[64746.12,0.004632],[64745.35,0.073244],[64744.83,2.929967],[64742.11,0.073244],[64740.82,0.073239],[64619.65,0.0],[64618.7,0.0],[64615.26,0.0],[64611.59,0.0],[64609.21,0.0],[64606.49,0.0],[64605.53,0.0],[64600.21,0.0],[64600.0,0.0],[64599.9,0.0],[64594.96,0.0],[64592.27,0.0]],"asks":[[64824.52,0.839481],[64828.51,0.0],[64828.53,0.0],[64872.52,0.073243],[64877.02,4.627878],[64878.54,0.002312],[64882.24,0.073241],[64885.02,0.002311],[64885.48,0.073239],[64886.78,0.073244],[64891.5,0.002311],[64892.8,5.85302],[64894.02,0.0],[64897.26,0.0],[64898.3,0.040011],[64900.51,0.0],[64901.54,0.074306],[64901.79,1.696888],[64901.8,0.0],[64904.78,0.137996],[64906.07,9.250347],[64909.08,0.00231],[64915.56,0.00231],[64922.05,0.00231],[64923.34,5.853028],[64957.61,3.085876],[65006.71,6.875288],[65022.43,0.049973],[65115.09,0.0],[65115.12,0.0],[65115.2,0.0],[65130.26,0.0],[65131.9,0.0],[65137.84,0.0],[65138.03,0.0],[65139.64,0.0],[65150.0,0.0],[65150.3,0.0],[65172.84,0.0],[65179.91,0.0],[65183.48,0.0]]}}
{"ping":1784133652674}
{"ch":"market.btcusdt.mbp.150","ts":1784133652713,"tick":{"seqNum":191847891229,"prevSeqNum":191847891203,"bids":[[64760.11,0.114318],[64756.87,0.212305],[64753.63,0.39428],[64752.34,9.251903],[64697.43,0.0],[64623.21,0.0],[64620.68,0.0],[64619.94,0.0]],"asks":[[64872.02,0.114319],[64875.26,0.212305],[64877.02,0.0],[64878.5,0.394279],[64879.8,9.251898],[65006.71,0.0],[65105.25,0.0],[65108.01,0.0]]}}
{"ch":"market.btcusdt.mbp.150","ts":1784133652805,"tick":{"seqNum":191847891261,"prevSeqNum":191847891229,"bids":[[64779.1,0.0],[64776.3,0.030852],[64752.52,0.0],[64749.72,0.030852],[64710.39,0.0],[64707.6,0.030852],[64704.96,0.014647],[64698.48,0.045132],[64694.63,0.030852],[64691.99,0.13908],[64685.51,0.428596],[64679.03,8.472777],[64677.99,0.0],[64675.19,0.030852],[64658.54,0.0],[64655.75,0.030852],[64639.1,0.0],[64636.3,0.030852],[64632.65,0.0],[64631.57,0.0],[64630.85,0.0],[64629.25,0.0],[64624.49,0.0],[64623.49,0.0]],"asks":[[64825.89,0.0],[64826.18,0.0],[64827.17,0.039628],[65015.82,0.014646],[65022.3,0.045132],[65028.79,0.139083],[65035.27,0.428597],[65041.75,13.876474],[65090.18,0.0],[65091.94,0.0],[65093.64,0.0],[65101.0,0.0]]}}
{"ch":"market.btcusdt.mbp.150","ts":1784133652903,"tick":{"seqNum":191847891272,"prevSeqNum":191847891261,"bids":[[64757.3,0.040012],[64754.06,0.074309],[64750.82,0.137998],[64749.52,9.250509],[64636.59,0.0],[64636.3,0.0],[64635.79,0.0],[64632.95,0.0]],"asks":[[64827.96,0.620904],[64885.21,0.040011],[64887.19,0.0],[64888.45,0.074308],[64891.69,0.137998],[64892.99,9.250509],[65075.15,0.0],[65086.97,0.0],[65087.71,0.0],[65090.17,0.0]]}}
{"ch":"market.btcusdt.mbp.150","ts":1784133653006,"tick":{"seqNum":191847891286,"prevSeqNum":191847891272,"bids":[[64688.33,3.084801]],"asks":[[64824.52,0.345845],[64877.02,2.313939],[65006.71,3.437644],[65010.32,0.0],[65080.59,0.0]]}}
{"ch":"market.btcusdt.mbp.150","ts":1784133653104,"tick":{"seqNum":191847891303,"prevSeqNum":191847891286,"bids":[[64825.89,0.023802],[64819.73,0.229398],[64819.47,0.620904],[64817.08,0.229398],[64814.23,0.0],[64639.44,0.0],[64639.17,0.0],[64637.37,0.0]],"asks":[[64824.52,0.0],[64825.9,0.202645],[64827.18,0.0],[64829.81,0.0],[64863.61,0.493636],[64865.87,0.01253],[65080.59,12.337039]]}}
{"ch":"market.btcusdt.mbp.150","ts":1784133653226,"tick":{"seqNum":191847891310,"prevSeqNum":191847891303,"bids":[[64809.0,0.0],[64807.13,0.00162]],"asks":[[64827.17,0.0],[64836.15,0.039689],[64836.97,0.493636],[64901.79,0.0],[65006.71,6.875373],[65086.97,0.151184]]}}
{"ch":"market.btcusdt.mbp.150","ts":1784133653437,"tick":{"seqNum":191847891345,"prevSeqNum":191847891310,"bids":[[64809.0,0.00162],[64808.96,0.325054],[64807.13,0.0],[64799.22,0.166728],[64789.52,2.772201],[64643.64,0.0],[64641.17,0.0],[64640.85,0.0]],"asks":[[64827.96,0.0],[64832.96,0.039628],[64836.15,6.1E-5],[64877.02,0.0],[64884.31,0.0],[64901.79,1.696852],[65006.71,0.0],[65087.71,0.020559],[65090.17,0.001807]]}}
{"ch":"market.btcusdt.mbp.150","ts":1784133653524,"tick":{"seqNum":191847891354,"prevSeqNum":191847891345,"bids":[[64759.14,0.0],[64752.66,0.0],[64746.18,0.0],[64744.88,0.0],[64643.64,0.659529],[64641.17,1.677535],[64640.85,1.783273],[64639.44,7.0941883767535E-4]],"asks":[[64870.05,0.0],[64876.54,0.0],[64883.02,0.0],[64901.79,0.0],[65009.83,0.0],[65090.18,0.03176],[65091.94,0.14253],[65093.64,0.122878],[65101.0,0.154183],[65105.25,1.72E-6]]}}
{"ch":"market.btcusdt.mbp.150","ts":1784133653614,"tick":{"seqNum":191847891373,"prevSeqNum":191847891354,"bids":[[64760.16,5.93593593593593E-4],[64756.92,0.0],[64753.68,0.0],[64752.39,0.0],[64741.3,0.0],[64734.82,0.0],[64728.34,0.002317],[64727.05,5.853350669338678],[64639.17,7.532805769808E-6],[64637.37,1.843687374749E-6],[64636.59,0.020559],[64636.3,0.030852],[64635.79,1.27254509018E-6]],"asks":[[64879.66,0.0],[64882.9,0.0],[64886.14,0.0],[64887.43,0.0],[65006.71,3.437729],[65016.31,0.0],[65022.79,0.0],[65024.09,0.0],[65108.01,3.084801],[65115.09,9.256416],[65115.12,0.164018],[65115.2,0.132932],[65130.26,0.004892],[65131.9,0.34]]}}
{"ping":1784133653666}
{"ch":"market.btcusdt.mbp.150","ts":1784133653703,"tick":{"seqNum":191847891382,"prevSeqNum":191847891373,"bids":[],"asks":[[64828.96,0.620904],[64832.96,0.0],[64836.15,0.039689],[64870.1,0.087895],[64877.02,2.31389],[64901.79,1.696852],[65115.2,0.0],[65130.26,0.0],[65131.9,0.0]]}}
{"ch":"market.btcusdt.mbp.150","ts":1784133653858,"tick":{"seqNum":191847891415,"prevSeqNum":191847891382,"bids":[[64759.77,0.0],[64759.61,0.114317],[64759.09,0.092521],[64756.53,0.0],[64756.37,0.212303],[64753.29,0.0],[64753.13,0.394277],[64752.61,0.087893],[64751.99,0.0],[64751.83,9.25048],[64746.12,0.092529],[64744.83,3.017864],[64741.25,0.002316],[64734.77,0.002317],[64728.29,0.002317],[64727.0,5.853004],[64639.17,0.0],[64637.37,0.0],[64636.59,0.0],[64636.3,0.0],[64635.79,0.0]],"asks":[[64825.9,0.226447],[64865.88,0.0],[64869.12,0.0],[64872.36,0.0],[64873.66,0.0],[64876.59,0.087892],[64879.01,0.114318],[64882.25,0.212305],[64883.07,0.087892],[64884.36,0.087895],[64885.49,0.394278],[64886.79,9.25048],[64901.79,0.0],[65009.86,0.002307],[65016.34,0.002307],[65022.82,0.002306],[65024.12,5.853039],[65093.64,0.0],[65101.0,0.0],[65105.25,0.0],[65108.01,0.0],[65115.09,0.0],[65115.12,0.0]]}}
{"ch":"market.btcusdt.mbp.150","ts":1784133653993,"tick":{"seqNum":191847891441,"prevSeqNum":191847891415,"bids":[[64741.31,0.0],[64734.83,0.0],[64728.34,0.0],[64727.05,3.34669338677354E-4],[64639.17,7.532805769808E-6],[64637.37,1.843687374749E-6],[64636.59,0.020559]],"asks":[[64836.15,0.039628],[64901.79,1.696852],[64912.14,0.0],[64918.62,0.0],[64925.1,0.0],[64926.4,0.0],[65093.64,0.122878],[65101.0,0.154183],[65105.25,1.72E-6]]}}
{"ch":"market.btcusdt.mbp.150","ts":1784133654009,"tick":{"seqNum":191847891450,"prevSeqNum":191847891441,"bids":[[64825.89,0.116447],[64759.58,0.114318],[64756.34,0.212304],[64753.1,0.394278],[64751.8,9.252437],[64639.44,0.0],[64639.17,0.0],[64637.37,0.0],[64636.59,0.0]],"asks":[[64866.07,0.114319],[64869.31,0.212302],[64872.55,0.394276],[64873.85,9.252435],[65091.94,0.0],[65093.64,0.0],[65101.0,0.0],[65105.25,0.0]]}}
{"ch":"market.btcusdt.mbp.150","ts":1784133654112,"tick":{"seqNum":191847891464,"prevSeqNum":191847891450,"bids":[[64825.89,0.023802]],"asks":[[64832.96,6.1E-5],[64877.02,4.62778],[64901.79,3.393704],[65006.71,10.313187],[65090.18,0.0]]}}
{"ch":"market.btcusdt.mbp.150","ts":1784133654218,"tick":{"seqNum":191847891528,"prevSeqNum":191847891464,"bids":[[64760.11,0.0],[64756.87,0.0],[64755.08,0.0],[64753.63,0.0],[64752.34,0.0],[64745.35,0.0],[64742.11,0.0],[64741.25,0.004632],[64740.82,0.0],[64734.77,0.004634],[64728.29,0.004634],[64727.0,11.706016],[64662.19,3.085876],[64639.44,7.0941883767535E-4],[64639.17,7.532805769808E-6],[64637.37,1.843687374749E-6],[64636.59,0.020559],[64636.3,0.030852],[64635.79,1.27254509018E-6],[64632.95,2.1232464929859E-5]],"asks":[[64872.02,0.0],[64872.52,0.0],[64875.26,0.0],[64877.02,2.31389],[64878.5,0.0],[64879.8,0.0],[64882.24,0.0],[64885.48,0.0],[64886.78,0.0],[64901.79,0.0],[64912.19,0.00231],[64918.67,0.00231],[64925.16,0.00231],[64926.45,5.853037],[64991.27,3.085876],[65006.71,3.437729],[65056.08,9.250672],[65090.18,0.03176],[65091.94,0.14253],[65093.64,0.122878]]}}
{"ch":"market.btcusdt.mbp.150","ts":1784133654301,"tick":{"seqNum":191847891548,"prevSeqNum":191847891528,"bids":[],"asks":[[64825.9,0.202645],[64828.49,0.0],[64832.97,0.0],[64836.13,0.039628],[64836.15,0.0],[64836.37,0.0],[64838.97,0.0],[64861.64,0.229398],[64866.58,0.229398],[64877.02,4.62778],[64901.79,1.696852],[65006.71,6.875458],[65101.0,0.154183]]}}
{"ch":"market.btcusdt.mbp.150","ts":1784133654404,"tick":{"seqNum":191847891568,"prevSeqNum":191847891548,"bids":[[64809.0,0.0],[64808.99,0.0],[64808.96,0.0],[64808.94,0.0],[64807.13,0.00162],[64799.27,0.0],[64799.22,0.0],[64799.21,0.0],[64632.65,3.7037037037037E-4],[64631.57,3.8917835671342E-5],[64630.85,0.154183],[64629.25,0.004892],[64624.49,0.083083],[64623.49,9.250672]],"asks":[[64828.96,0.0],[64830.68,0.039628],[64830.69,0.229398],[64830.7,0.620904],[64836.13,0.229398],[64883.51,0.394277],[64884.81,9.251902],[65090.18,0.0],[65091.94,0.0],[65093.64,0.0],[65101.0,0.0]]}}
{"ch":"market.btcusdt.mbp.150","ts":1784133654574,"tick":{"seqNum":191847891597,"prevSeqNum":191847891568,"bids":[[64799.2,0.161193],[64763.9,0.114318],[64760.66,0.212306],[64759.47,0.073241],[64757.42,0.394278],[64756.12,9.251903],[64749.75,0.073243],[64746.51,0.073246],[64745.22,0.073239],[64636.3,0.0],[64635.79,0.0],[64632.95,0.0],[64632.65,0.0],[64631.57,0.0],[64630.85,0.0],[64629.25,0.0],[64624.49,0.0],[64623.49,0.0]],"asks":[[64876.92,0.073242],[64877.02,0.0],[64877.03,0.114317],[64880.27,0.212303],[64886.64,0.073239],[64889.88,0.073243],[64891.18,0.07324],[64901.79,0.0],[65006.71,0.0],[65086.97,0.0],[65087.71,0.0],[65090.17,0.0]]}}
{"ch":"market.btcusdt.mbp.150","ts":1784133654609,"tick":{"seqNum":191847891619,"prevSeqNum":191847891597,"bids":[[64808.99,0.00162],[64808.98,0.332434],[64807.13,0.0],[64759.09,0.090205],[64752.6,0.002316],[64746.12,0.090213],[64744.83,1.552878],[64636.59,0.0]],"asks":[[64877.02,2.31389],[64878.54,0.0],[64885.02,0.0],[64891.5,0.0],[64892.8,0.0],[64901.79,1.696852],[64915.56,0.0],[65006.71,3.437729],[65086.97,0.151184],[65087.71,0.020559]]}}
{"ping":1784133654674}
{"ch":"market.btcusdt.mbp.150","ts":1784133654721,"tick":{"seqNum":191847891627,"prevSeqNum":191847891619,"bids":[[64825.89,0.0],[64759.09,0.087889],[64752.6,0.0],[64746.12,0.087897],[64744.83,0.087897],[64636.59,0.020559],[64636.3,0.030852]],"asks":[[64909.08,0.0],[64922.05,0.0],[64923.34,0.0],[65090.17,0.001807],[65090.18,0.03176],[65091.94,0.14253]]}}
{"ch":"market.btcusdt.mbp.150","ts":1784133654802,"tick":{"seqNum":191847891669,"prevSeqNum":191847891627,"bids":[[64824.51,0.0],[64819.73,0.0],[64819.47,0.0],[64720.72,0.0],[64714.24,0.0],[64707.76,0.0],[64701.27,0.0],[64694.79,0.0],[64635.79,1.27254509018E-6],[64632.95,2.1232464929859E-5],[64632.65,3.7037037037037E-4],[64631.57,3.8917835671342E-5],[64630.85,0.154183],[64629.25,0.004892],[64624.49,0.083083],[64623.49,9.250672]],"asks":[[64823.98,0.023802],[64824.84,0.023802],[64825.9,0.11],[64830.68,0.0],[64877.02,0.0],[64901.79,0.0],[64907.58,0.0],[64914.06,0.0],[64920.54,0.0],[64927.03,0.0],[64933.51,0.0],[65006.71,0.0],[65093.64,0.122878],[65101.0,0.154183],[65105.25,1.72E-6],[65108.01,3.084801],[65115.09,9.256416],[65115.12,0.164018],[65115.2,0.132932]]}}
{"ch":"market.btcusdt.mbp.150","ts":1784133654951,"tick":{"seqNum":191847891720,"prevSeqNum":191847891669,"bids":[[64822.89,0.229398],[64821.8,0.023802],[64776.3,0.030853],[64759.13,0.004632],[64752.65,0.004632],[64749.72,0.030853],[64746.17,0.004632],[64744.88,8.450669],[64707.6,0.030853],[64694.63,0.030853],[64688.33,0.0],[64675.19,0.030853],[64655.75,0.030853],[64636.3,0.030853],[64631.57,0.0],[64630.85,0.0],[64629.25,0.0],[64624.49,0.0],[64623.49,0.0]],"asks":[[64823.95,0.06343],[64823.96,0.023802],[64824.84,0.0],[64847.0,7.2E-4],[64878.49,0.002312],[64884.97,0.002311],[64891.45,0.002311],[64892.75,5.85302],[64909.03,0.00231],[64915.51,0.00231],[64922.0,0.00231],[64923.29,5.853017],[65090.17,0.0],[65090.18,0.0],[65091.94,0.0],[65093.64,0.0],[65101.0,0.0],[65105.25,0.0],[65108.01,0.0],[65115.09,0.0],[65115.12,0.0],[65115.2,0.0]]}}
{"ch":"market.btcusdt.mbp.150","ts":1784133655059,"tick":{"seqNum":191847891745,"prevSeqNum":191847891720,"bids":[[64823.94,0.023802],[64822.9,0.023802],[64822.89,0.0],[64808.98,0.0],[64757.19,0.0],[64753.95,0.0],[64750.7,0.0],[64749.41,0.0],[64717.93,0.009764],[64711.45,0.03009],[64704.97,0.09272],[64698.49,0.285732],[64692.0,12.336152],[64632.65,0.0]],"asks":[[64898.3,0.0],[64901.54,0.0],[64904.77,0.009766],[64904.78,0.0],[64906.07,0.0],[64911.25,0.030089],[64917.73,0.092722],[64924.21,0.285731],[64930.7,12.336152],[65087.71,0.0]]}}
{"ch":"market.btcusdt.mbp.150","ts":1784133655107,"tick":{"seqNum":191847891761,"prevSeqNum":191847891745,"bids":[[64820.17,0.620904],[64809.0,0.249178],[64808.99,0.0],[64807.13,0.00162],[64799.27,0.146722],[64799.2,0.0],[64635.79,0.0],[64632.95,0.0]],"asks":[[64877.02,2.313959],[64901.79,1.696903],[65006.71,3.437609],[65078.76,0.0],[65080.59,0.0],[65086.97,0.0]]}}
{"ch":"market.btcusdt.mbp.150","ts":1784133655208,"tick":{"seqNum":191847891777,"prevSeqNum":191847891761,"bids":[[64809.01,0.00162],[64807.13,0.0],[64757.3,0.0],[64754.06,0.0],[64750.82,0.0],[64749.52,0.0],[64635.79,1.27254509018E-6],[64632.95,2.1232464929859E-5],[64632.65,3.7037037037037E-4],[64631.57,3.8917835671342E-5]],"asks":[[64885.21,0.0],[64888.45,0.0],[64891.69,0.0],[64892.99,0.0],[64901.79,0.0],[65006.71,6.875218],[65078.76,0.136402],[65080.59,12.337039],[65086.97,0.151184],[65087.71,0.020559],[65090.17,0.001807]]}}
{"ch":"market.btcusdt.mbp.150","ts":1784133655304,"tick":{"seqNum":191847891809,"prevSeqNum":191847891777,"bids":[[64809.0,0.470245],[64760.59,0.040012],[64757.35,0.074306],[64754.11,0.137999],[64752.81,9.250347],[64635.79,0.0],[64632.95,0.0],[64632.65,0.0],[64631.57,0.0]],"asks":[[64830.68,0.229398],[64830.69,0.0],[64877.02,4.627918],[64903.69,0.040013],[64906.93,0.074308],[64910.17,0.137999],[64911.47,9.250344],[65080.59,0.0],[65086.97,0.0],[65087.71,0.0],[65090.17,0.0]]}}
{"ch":"market.btcusdt.mbp.150","ts":1784133655415,"tick":{"seqNum":191847891846,"prevSeqNum":191847891809,"bids":[[64820.17,0.0],[64817.08,0.0],[64814.79,0.229398],[64814.24,0.0],[64757.07,0.040012],[64635.79,1.27254509018E-6]],"asks":[[64877.02,0.0],[65006.71,0.0],[65080.59,12.337039],[65086.97,0.151184]]}}
{"ch":"market.btcusdt.mbp.150","ts":1784133655510,"tick":{"seqNum":191847891883,"prevSeqNum":191847891846,"bids":[[64819.07,0.620904],[64759.61,0.0],[64759.58,0.0],[64756.37,0.0],[64756.34,0.0],[64753.83,0.074308],[64753.13,0.0],[64753.1,0.0],[64751.83,0.0],[64751.8,0.0],[64750.59,0.137997],[64749.3,9.250509],[64632.95,2.1232464929859E-5],[64632.65,3.7037037037037E-4],[64631.57,3.8917835671342E-5],[64630.85,0.154183]],"asks":[[64866.07,0.0],[64869.31,0.0],[64872.55,0.0],[64873.85,0.0],[64877.02,2.313959],[64879.01,0.0],[64882.25,0.0],[64885.49,0.0],[64886.79,0.0],[64887.44,0.040013],[64890.68,0.074307],[64893.92,0.137999],[64895.21,9.250509],[65006.71,3.437609],[65087.71,0.020559],[65090.17,0.001807]]}}
{"ch":"market.btcusdt.mbp.150","ts":1784133655620,"tick":{"seqNum":191847891903,"prevSeqNum":191847891883,"bids":[[64819.07,0.0],[64809.0,0.221067],[64629.25,0.004892]],"asks":[[64823.95,0.116447],[64830.67,0.039628],[64832.41,0.493636],[64836.97,0.0],[64863.61,0.0],[64877.02,4.627918],[64901.79,1.696903],[65006.71,6.875218],[65090.17,0.0]]}}
{"ping":1784133655666}
{"ch":"market.btcusdt.mbp.150","ts":1784133655702,"tick":{"seqNum":191847891949,"prevSeqNum":191847891903,"bids":[[64809.01,0.0],[64809.0,0.0],[64807.13,0.00162],[64799.27,0.0],[64789.52,0.0],[64789.51,0.0],[64759.09,0.0],[64757.69,0.114317],[64754.45,0.212305],[64752.61,0.0],[64751.21,0.394279],[64751.15,0.394277],[64749.92,9.250403],[64749.86,9.252437],[64746.12,0.0],[64744.83,0.0],[64624.49,0.083083],[64623.21,0.109535]],"asks":[[64870.02,0.114317],[64870.1,0.0],[64876.59,0.0],[64877.02,0.0],[64877.8,9.252436],[64882.93,0.11432],[64883.07,0.0],[64884.36,0.0],[64886.17,0.212306],[64889.41,0.394279],[64890.71,9.250478],[65006.71,0.0]]}}
{"ch":"market.btcusdt.mbp.150","ts":1784133655826,"tick":{"seqNum":191847891969,"prevSeqNum":191847891949,"bids":[[64808.98,0.119927],[64799.21,0.052054],[64789.54,2.682],[64757.63,0.114319],[64754.39,0.212305],[64631.57,0.0],[64630.85,0.0],[64629.25,0.0],[64624.49,0.0],[64623.21,0.0]],"asks":[[64873.26,0.212305],[64876.5,0.394277],[64877.02,2.313959],[64901.79,0.0],[65006.71,3.437609],[65009.86,0.0],[65086.97,0.0],[65087.71,0.0]]}}
{"ch":"market.btcusdt.mbp.150","ts":1784133655913,"tick":{"seqNum":191847892001,"prevSeqNum":191847891969,"bids":[[64818.85,0.620904],[64808.99,0.00162],[64808.96,0.228662],[64807.13,0.0],[64799.27,0.112756],[64789.53,3.417756],[64763.9,0.0],[64760.66,0.0],[64757.42,0.0],[64756.12,0.0],[64741.25,0.002316],[64734.77,0.002317],[64728.29,0.002317],[64727.0,5.853012]],"asks":[[64877.02,4.627918],[64877.03,0.0],[64880.27,0.0],[64882.26,0.087894],[64883.51,0.0],[64884.81,0.0],[64901.79,1.696903],[65006.71,6.875218],[65016.34,0.0],[65022.82,0.0],[65024.12,0.0],[65086.97,0.151184],[65087.71,0.020559],[65090.17,0.001807],[65090.18,0.03176],[65091.94,0.14253]]}}
{"ch":"market.btcusdt.mbp.150","ts":1784133656007,"tick":{"seqNum":191847892027,"prevSeqNum":191847892001,"bids":[[64755.2,0.087893],[64748.72,0.087894],[64742.23,0.087892],[64740.94,0.087893],[64636.3,0.0],[64635.79,0.0],[64632.95,0.0],[64632.65,0.0]],"asks":[[64832.96,0.0],[64836.12,6.1E-5],[64868.0,0.087896],[64874.48,0.087896],[64877.02,0.0],[64880.96,0.087891],[64888.74,5.853024],[65006.71,0.0],[65090.18,0.0],[65091.94,0.0]]}}
{"ch":"market.btcusdt.mbp.150","ts":1784133656110,"tick":{"seqNum":191847892056,"prevSeqNum":191847892027,"bids":[[64755.2,0.092525],[64748.72,0.092526],[64742.23,0.092524],[64740.94,11.793893],[64737.36,0.002317],[64730.88,0.002317],[64724.4,0.002317],[64723.11,5.852995],[64658.3,3.086019],[64640.85,0.0],[64639.44,0.0],[64639.17,0.0],[64637.37,0.0],[64636.59,0.0]],"asks":[[64874.48,0.090208],[64876.17,0.114317],[64877.08,0.002312],[64880.96,0.090202],[64883.56,0.002311],[64887.44,0.042324],[64890.04,0.002311],[64891.33,5.853019],[64901.79,0.0],[65007.75,0.002307],[65014.23,0.002307],[65020.71,0.002306],[65022.01,5.853031],[65060.55,0.0],[65066.92,0.0],[65075.75,0.0],[65078.76,0.0],[65080.59,0.0],[65086.97,0.0],[65087.71,0.0],[65090.17,0.0]]}}
{"ch":"market.btcusdt.mbp.150","ts":1784133656219,"tick":{"seqNum":191847892086,"prevSeqNum":191847892056,"bids":[[64759.47,0.0],[64757.96,0.114319],[64754.72,0.212302],[64751.48,0.394278],[64750.18,9.251903],[64749.75,0.0],[64746.51,0.0],[64745.22,0.0]],"asks":[[64876.92,0.0],[64877.02,4.627918],[64879.42,0.212305],[64882.66,0.394279],[64883.95,9.2519],[64886.64,0.0],[64889.88,0.0],[64891.18,0.0],[65006.71,3.437609],[65058.0,0.0]]}}
{"ch":"market.btcusdt.mbp.150","ts":1784133656301,"tick":{"seqNum":191847892130,"prevSeqNum":191847892086,"bids":[[64808.99,0.0],[64808.98,0.0],[64808.96,0.0],[64808.95,0.020733],[64807.13,0.00162],[64799.27,0.0],[64799.26,0.008801],[64799.21,0.0],[64647.34,0.0],[64640.85,1.783273],[64639.44,7.0941883767535E-4],[64639.17,7.532805769808E-6]],"asks":[[64861.99,0.493636],[64877.02,2.313959],[64901.79,1.696903],[64912.19,0.0],[65015.76,0.0]]}}
{"ch":"market.btcusdt.mbp.150","ts":1784133656414,"tick":{"seqNum":191847892139,"prevSeqNum":191847892130,"bids":[[64799.21,0.010104],[64741.25,0.0],[64734.77,0.0],[64728.29,0.0],[64727.0,0.0],[64637.37,1.843687374749E-6],[64636.59,0.020559],[64636.3,0.030853]],"asks":[[64901.79,0.0],[64918.67,0.0],[64925.16,0.0],[64926.45,0.0],[65058.0,0.001],[65060.55,0.128227],[65066.92,1.38E-6],[65075.75,0.12519]]}}
{"ch":"market.btcusdt.mbp.150","ts":1784133656539,"tick":{"seqNum":191847892165,"prevSeqNum":191847892139,"bids":[[64808.95,0.0],[64799.26,0.0],[64799.21,0.0],[64754.92,0.073243],[64745.2,0.073239],[64741.96,0.073248],[64740.66,0.073247],[64636.3,0.0]],"asks":[[64874.68,0.073247],[64877.02,4.627918],[64884.4,0.073241],[64887.64,0.073247],[64888.94,0.073248],[64901.79,1.696903],[64932.27,12.235713],[64948.06,0.0],[64953.58,0.049192],[65006.71,6.875218],[65008.38,0.0],[65056.08,0.0],[65058.0,0.0],[65060.55,0.0],[65066.92,0.0],[65075.75,0.0]]}}
{"ping":1784133656671}
{"ch":"market.btcusdt.mbp.150","ts":1784133656675,"tick":{"seqNum":191847892190,"prevSeqNum":191847892165,"bids":[[64737.36,0.004634],[64730.88,0.004634],[64724.4,0.004634],[64723.11,11.706003]],"asks":[[64877.02,0.0],[64901.79,0.0],[64910.08,0.00231],[64916.57,0.00231],[64923.05,0.00231],[64924.34,5.853037],[65006.71,0.0],[65055.72,0.0]]}}
{"ch":"market.btcusdt.mbp.150","ts":1784133656715,"tick":{"seqNum":191847892191,"prevSeqNum":191847892190,"bids":[],"asks":[[64830.7,0.0],[65055.72,1.048051]]}}
{"ch":"market.btcusdt.mbp.150","ts":1784133656864,"tick":{"seqNum":191847892216,"prevSeqNum":191847892191,"bids":[[64806.33,0.139715],[64796.59,0.076072],[64759.13,0.002316],[64752.65,0.002316],[64746.17,0.002316],[64744.88,4.210058],[64637.37,0.0],[64636.59,0.0]],"asks":[[64825.42,0.039628],[64825.43,0.620904],[64830.67,0.0],[64874.38,2.313959],[64909.03,0.0],[64915.51,0.0],[64922.0,0.0],[64923.29,0.0],[65056.08,9.250672],[65058.0,0.001]]}}
{"ch":"market.btcusdt.mbp.150","ts":1784133656913,"tick":{"seqNum":191847892233,"prevSeqNum":191847892216,"bids":[[64759.13,0.0],[64752.65,0.0],[64746.17,0.0],[64744.88,0.0],[64655.75,0.0],[64637.37,1.843687374749E-6],[64636.59,0.020559],[64636.3,0.030853],[64635.79,1.27254509018E-6],[64632.95,2.1232464929859E-5]],"asks":[[64874.38,0.0],[64878.49,0.0],[64884.97,0.0],[64891.45,0.0],[64892.75,0.0],[65060.55,0.128227],[65066.92,1.38E-6],[65075.75,0.12519],[65078.76,0.136402],[65086.82,3.086019]]}}
{"ch":"market.btcusdt.mbp.150","ts":1784133657014,"tick":{"seqNum":191847892251,"prevSeqNum":191847892233,"bids":[[64776.3,0.0],[64773.3,0.030852],[64749.72,0.0],[64746.73,0.030852],[64707.6,0.0],[64704.6,0.030852],[64694.63,0.0],[64691.64,0.030852],[64675.19,0.0],[64672.2,0.030852],[64652.76,0.030852],[64636.3,0.0],[64633.31,0.030852],[64632.95,0.0]],"asks":[[64906.97,0.00231],[65086.82,0.0]]}}
{"ch":"market.btcusdt.mbp.150","ts":1784133657135,"tick":{"seqNum":191847892262,"prevSeqNum":191847892251,"bids":[[64755.2,0.094841],[64748.72,0.094842],[64742.23,0.09484],[64740.94,23.49991]],"asks":[[64854.88,0.002725],[64862.99,0.0],[64913.45,0.00231],[64919.93,0.00231],[64921.23,5.853024],[65066.92,0.0],[65075.75,0.0],[65078.76,0.0]]}}
{"ch":"market.btcusdt.mbp.150","ts":1784133657225,"tick":{"seqNum":191847892279,"prevSeqNum":191847892262,"bids":[[64806.36,0.21476],[64806.33,0.0],[64796.59,0.0],[64755.2,0.097157],[64748.72,0.097158],[64742.23,0.097156],[64682.54,0.0],[64632.95,2.1232464929859E-5],[64632.65,3.7037037037037E-4]],"asks":[[64823.95,0.156075],[64825.42,0.0],[64876.43,0.002312],[64882.91,0.002311],[64889.39,0.002311],[64890.69,5.85302],[65056.08,0.0],[65058.0,0.0],[65060.55,0.0]]}}
{"ch":"market.btcusdt.mbp.150","ts":1784133657344,"tick":{"seqNum":191847892300,"prevSeqNum":191847892279,"bids":[[64796.6,0.110743],[64757.69,0.0],[64754.45,0.0],[64754.39,0.0],[64751.21,0.0],[64749.92,0.0],[64679.85,5.284891],[64631.57,3.8917835671342E-5],[64630.85,0.154183],[64629.25,0.004892]],"asks":[[64874.38,2.313959],[64882.93,0.0],[64886.17,0.0],[64889.41,0.0],[64890.71,0.0],[64899.15,1.696903],[65004.06,3.437609],[65056.08,9.250672]]}}
{"ch":"market.btcusdt.mbp.150","ts":1784133657403,"tick":{"seqNum":191847892312,"prevSeqNum":191847892300,"bids":[[64823.94,0.0],[64757.63,0.0],[64751.15,0.0],[64749.86,0.0],[64624.49,0.083083],[64623.21,0.109535],[64620.68,2.7855711422844E-5],[64619.94,0.150111]],"asks":[[64823.95,0.116447],[64825.41,0.229398],[64870.02,0.0],[64873.26,0.0],[64876.5,0.0],[64877.8,0.0],[65058.0,0.001],[65060.55,0.128227],[65066.92,1.38E-6]]}}
{"ch":"market.btcusdt.mbp.150","ts":1784133657504,"tick":{"seqNum":191847892343,"prevSeqNum":191847892312,"bids":[[64822.9,0.0],[64814.79,0.0],[64814.12,0.229398],[64618.7,5.268957227286E-6]],"asks":[[64823.96,0.0],[64823.98,0.0],[64874.38,2.313997],[64899.15,1.696931],[65004.06,3.437542],[65075.75,0.12519],[65078.76,0.136402]]}}
{"ch":"market.btcusdt.mbp.150","ts":1784133657603,"tick":{"seqNum":191847892372,"prevSeqNum":191847892343,"bids":[[64821.79,0.0],[64760.7,0.114317],[64757.46,0.212306],[64754.22,0.394277],[64752.92,9.250444],[64701.56,0.0],[64619.94,0.0],[64618.7,0.0]],"asks":[[64823.89,0.023802],[64823.91,0.023802],[64823.95,0.092645],[64866.1,0.114318],[64879.51,0.114317],[64882.76,0.212305],[64886.0,0.394278],[64887.29,9.25048],[64899.15,0.0],[65056.08,0.0],[65058.0,0.0],[65060.55,0.0],[65066.92,0.0],[65075.75,0.0],[65078.76,0.0]]}}
