{"event":"subscribe","channel":"book_lv2","symbols":["BTC_USDT"]}
{"channel":"book_lv2","data":[{"symbol":"BTC_USDT","createTime":1784090304561,"asks":[["64805.04","0.020000"],["64811.13","0.000062"],["64811.18","0.000062"],["64816.2","0.02"],["64829.16","0.100415"],["64843.97","0.009617"],["64845.91","0.029316"],["64847.2","0.017856"],["64848.5","0.030028"],["64849.15","0.029313"],["64850.44","0.033161"],["64850.45","0.030029"],["64851.74","0.055767"],["64852.39","0.029317"],["64853.68","2.755621"],["64853.69","0.05577"],["64854.98","0.103572"],["64855.63","0.029319"],["64856.27","0.015448"],["64856.93","0.103569"]],"bids":[["64799.86","0.000062"],["64799.85","0.219899"],["64796.93","0.000062"],["64793.71","0.000341"],["64793.51","0.00113"],["64793.31","0.00083"],["64793.11","0.00061"],["64792.9","0.000519"],["64792.71","0.000329"],["64792.51","0.000242"],["64792.31","0.000177"],["64790.13","0.2251"],["64785","0.376054"],["64775.29","0.800776"],["64765.58","0.695184"],["64765.51","0.848451"],["64764.98","0.02"],["64756.95","0.02"],["64749.35","0.180419"],["64749.3","0.107125"]],"lastId":7649223674,"id":7649223675,"ts":1784090304579}],"action":"snapshot"}
{"channel":"book_lv2","data":[{"symbol":"BTC_USDT","createTime":1784090304576,"asks":[],"bids":[["64749.35","0.107128"]],"lastId":7649223675,"id":7649223678,"ts":1784090304594}],"action":"update"}
{"channel":"book_lv2","data":[{"symbol":"BTC_USDT","createTime":1784090304581,"asks":[["64849.79","0.231472"],["64856.93","0"]],"bids":[],"lastId":7649223678,"id":7649223687,"ts":1784090304605}],"action":"update"}
{"channel":"book_lv2","data":[{"symbol":"BTC_USDT","createTime":1784090304601,"asks":[["64829.16","0"],["64856.93","0.103569"]],"bids":[],"lastId":7649223687,"id":7649223693,"ts":1784090304624}],"action":"update"}
{"event":"subscribe","channel":"trades","symbols":["BTC_USDT"]}
{"channel":"book_lv2","data":[{"symbol":"BTC_USDT","createTime":1784090304622,"asks":[],"bids":[["64775.29","0"],["64739.63","0.238058"]],"lastId":7649223693,"id":7649223694,"ts":1784090304640}],"action":"update"}
{"channel":"book_lv2","data":[{"symbol":"BTC_USDT","createTime":1784090304623,"asks":[],"bids":[["64785","0"],["64739.58","0.130933"]],"lastId":7649223694,"id":7649223695,"ts":1784090304641}],"action":"update"}
{"channel":"book_lv2","data":[{"symbol":"BTC_USDT","createTime":1784090304646,"asks":[["64854.33","0.033169"],["64856.93","0"]],"bids":[],"lastId":7649223695,"id":7649223697,"ts":1784090304657}],"action":"update"}
{"channel":"book_lv2","data":[{"symbol":"BTC_USDT","createTime":1784090304646,"asks":[["64847.85","0.009619"],["64856.27","0"]],"bids":[],"lastId":7649223697,"id":7649223698,"ts":1784090304658}],"action":"update"}
{"channel":"book_lv2","data":[{"symbol":"BTC_USDT","createTime":1784090304649,"asks":[["64851.09","0.017861"],["64855.63","0"]],"bids":[],"lastId":7649223698,"id":7649223702,"ts":1784090304664}],"action":"update"}
{"channel":"book_lv2","data":[{"symbol":"BTC_USDT","createTime":1784090304671,"asks":[["64829.16","0.100415"],["64854.98","0"]],"bids":[],"lastId":7649223702,"id":7649223707,"ts":1784090304686}],"action":"update"}
{"channel":"book_lv2","data":[{"symbol":"BTC_USDT","createTime":1784090304688,"asks":[["64829.16","0"],["64854.98","0.103572"]],"bids":[],"lastId":7649223707,"id":7649223708,"ts":1784090304703}],"action":"update"}
{"channel":"book_lv2","data":[{"symbol":"BTC_USDT","createTime":1784090304745,"asks":[],"bids":[["64785","0.422142"],["64739.58","0"]],"lastId":7649223708,"id":7649223711,"ts":1784090304761}],"action":"update"}
{"channel":"book_lv2","data":[{"symbol":"BTC_USDT","createTime":1784090304748,"asks":[],"bids":[["64775.28","0.822345"],["64739.63","0"]],"lastId":7649223711,"id":7649223712,"ts":1784090304762}],"action":"update"}
{"channel":"book_lv2","data":[{"symbol":"BTC_USDT","createTime":1784090304751,"asks":[["64829.16","0.100415"],["64854.98","0"]],"bids":[],"lastId":7649223712,"id":7649223720,"ts":1784090304772}],"action":"update"}
{"channel":"book_lv2","data":[{"symbol":"BTC_USDT","createTime":1784090304752,"asks":[["64849.79","0"],["64854.98","0.103572"]],"bids":[],"lastId":7649223720,"id":7649223726,"ts":1784090304779}],"action":"update"}
{"channel":"book_lv2","data":[{"symbol":"BTC_USDT","createTime":1784090304764,"asks":[["64849.79","0.231472"],["64854.98","0"]],"bids":[],"lastId":7649223726,"id":7649223731,"ts":1784090304798}],"action":"update"}
{"channel":"book_lv2","data":[{"symbol":"BTC_USDT","createTime":1784090304768,"asks":[["64829.16","0"],["64854.98","0.103572"]],"bids":[],"lastId":7649223731,"id":7649223732,"ts":1784090304803}],"action":"update"}
{"channel":"book_lv2","data":[{"symbol":"BTC_USDT","createTime":1784090304784,"asks":[],"bids":[["64785","0"],["64739.63","0.238058"]],"lastId":7649223732,"id":7649223735,"ts":1784090304806}],"action":"update"}
{"channel":"book_lv2","data":[{"symbol":"BTC_USDT","createTime":1784090304784,"asks":[],"bids":[["64775.28","0"],["64739.58","0.130933"]],"lastId":7649223735,"id":7649223737,"ts":1784090304809}],"action":"update"}
{"channel":"book_lv2","data":[{"symbol":"BTC_USDT","createTime":1784090304836,"asks":[["64829.16","0.100415"],["64854.98","0"]],"bids":[],"lastId":7649223737,"id":7649223739,"ts":1784090304853}],"action":"update"}
{"channel":"book_lv2","data":[{"symbol":"BTC_USDT","createTime":1784090304850,"asks":[],"bids":[["64749.35","0.180422"]],"lastId":7649223739,"id":7649223740,"ts":1784090304866}],"action":"update"}
{"channel":"book_lv2","data":[{"symbol":"BTC_USDT","createTime":1784090304851,"asks":[["64829.16","0"],["64854.98","0.103572"]],"bids":[],"lastId":7649223740,"id":7649223741,"ts":1784090304867}],"action":"update"}
{"channel":"book_lv2","data":[{"symbol":"BTC_USDT","createTime":1784090304852,"asks":[],"bids":[["64742.87","0.073297"],["64739.58","0"]],"lastId":7649223741,"id":7649223742,"ts":1784090304868}],"action":"update"}
{"channel":"book_lv2","data":[{"symbol":"BTC_USDT","createTime":1784090304854,"asks":[],"bids":[["64739.63","0.311349"]],"lastId":7649223742,"id":7649223744,"ts":1784090304871}],"action":"update"}
{"channel":"book_lv2","data":[{"symbol":"BTC_USDT","createTime":1784090304898,"asks":[],"bids":[["64749.35","0.073294"]],"lastId":7649223744,"id":7649223748,"ts":1784090304910}],"action":"update"}
{"channel":"book_lv2","data":[{"symbol":"BTC_USDT","createTime":1784090304898,"asks":[],"bids":[["64739.63","0.180419"]],"lastId":7649223748,"id":7649223751,"ts":1784090304914}],"action":"update"}
{"channel":"book_lv2","data":[{"symbol":"BTC_USDT","createTime":1784090304913,"asks":[["64829.16","0.100415"],["64854.98","0"]],"bids":[],"lastId":7649223751,"id":7649223756,"ts":1784090304921}],"action":"update"}
{"channel":"book_lv2","data":[{"symbol":"BTC_USDT","createTime":1784090304927,"asks":[["64829.16","0"],["64854.98","0.103572"]],"bids":[],"lastId":7649223756,"id":7649223757,"ts":1784090304943}],"action":"update"}
{"channel":"book_lv2","data":[{"symbol":"BTC_USDT","createTime":1784090304992,"asks":[["64845.91","0"],["64855.63","0.029319"]],"bids":[],"lastId":7649223757,"id":7649223761,"ts":1784090305012}],"action":"update"}
{"channel":"book_lv2","data":[{"symbol":"BTC_USDT","createTime":1784090304992,"asks":[["64852.39","0"],["64856.93","0.103569"]],"bids":[],"lastId":7649223761,"id":7649223762,"ts":1784090305013}],"action":"update"}
{"channel":"book_lv2","data":[{"symbol":"BTC_USDT","createTime":1784090304993,"asks":[["64855.63","0"],["64857.04","0.180422"]],"bids":[],"lastId":7649223762,"id":7649223763,"ts":1784090305015}],"action":"update"}
{"channel":"book_lv2","data":[{"symbol":"BTC_USDT","createTime":1784090304993,"asks":[["64849.15","0"],["64857.57","2.75621"]],"bids":[],"lastId":7649223763,"id":7649223765,"ts":1784090305018}],"action":"update"}
{"channel":"book_lv2","data":[{"symbol":"BTC_USDT","createTime":1784090304995,"asks":[["64829.16","0.100415"],["64857.57","0"]],"bids":[],"lastId":7649223765,"id":7649223766,"ts":1784090305019}],"action":"update"}
{"channel":"book_lv2","data":[{"symbol":"BTC_USDT","createTime":1784090305013,"asks":[["64829.16","0"],["64857.57","2.75621"]],"bids":[],"lastId":7649223766,"id":7649223767,"ts":1784090305033}],"action":"update"}
{"channel":"book_lv2","data":[{"symbol":"BTC_USDT","createTime":1784090305051,"asks":[["64849.79","0"],["64858.22","7.716401"]],"bids":[],"lastId":7649223767,"id":7649223772,"ts":1784090305067}],"action":"update"}
{"channel":"book_lv2","data":[{"symbol":"BTC_USDT","createTime":1784090305070,"asks":[["64848.5","0"],["64860.16","7.716305"]],"bids":[],"lastId":7649223772,"id":7649223778,"ts":1784090305090}],"action":"update"}
{"channel":"book_lv2","data":[{"symbol":"BTC_USDT","createTime":1784090305070,"asks":[["64858.22","0"],["64863.52","0.073298"]],"bids":[],"lastId":7649223778,"id":7649223779,"ts":1784090305091}],"action":"update"}
{"channel":"book_lv2","data":[{"symbol":"BTC_USDT","createTime":1784090305070,"asks":[["64851.74","0"],["64866.76","0.154366"]],"bids":[],"lastId":7649223779,"id":7649223780,"ts":1784090305092}],"action":"update"}
{"channel":"book_lv2","data":[{"symbol":"BTC_USDT","createTime":1784090305071,"asks":[["64854.98","0"],["64873.24","0.107126"]],"bids":[],"lastId":7649223780,"id":7649223783,"ts":1784090305096}],"action":"update"}
{"channel":"book_lv2","data":[{"symbol":"BTC_USDT","createTime":1784090305085,"asks":[["64829.16","0.100415"],["64873.24","0"]],"bids":[],"lastId":7649223783,"id":7649223784,"ts":1784090305104}],"action":"update"}
{"channel":"book_lv2","data":[{"symbol":"BTC_USDT","createTime":1784090305102,"asks":[["64829.16","0"],["64873.24","0.107126"]],"bids":[],"lastId":7649223784,"id":7649223785,"ts":1784090305112}],"action":"update"}
{"channel":"book_lv2","data":[{"symbol":"BTC_USDT","createTime":1784090305141,"asks":[["64856.27","0.014398"],["64873.24","0"]],"bids":[],"lastId":7649223785,"id":7649223786,"ts":1784090305154}],"action":"update"}
{"channel":"book_lv2","data":[{"symbol":"BTC_USDT","createTime":1784090305145,"asks":[],"bids":[["64775.31","0.703286"],["64739.63","0"]],"lastId":7649223786,"id":7649223788,"ts":1784090305157}],"action":"update"}
{"channel":"book_lv2","data":[{"symbol":"BTC_USDT","createTime":1784090305147,"asks":[],"bids":[["64784.97","0.390871"],["64742.87","0"]],"lastId":7649223788,"id":7649223789,"ts":1784090305158}],"action":"update"}
{"channel":"book_lv2","data":[{"symbol":"BTC_USDT","createTime":1784090305162,"asks":[["64865.99","0.007656"],["64866.76","0"]],"bids":[],"lastId":7649223789,"id":7649223793,"ts":1784090305183}],"action":"update"}
{"channel":"book_lv2","data":[{"symbol":"BTC_USDT","createTime":1784090305167,"asks":[],"bids":[["64799.85","0"],["64742.87","0.073297"]],"lastId":7649223793,"id":7649223797,"ts":1784090305189}],"action":"update"}
{"channel":"book_lv2","data":[{"symbol":"BTC_USDT","createTime":1784090305168,"asks":[],"bids":[["64749.3","0"],["64739.63","0.311354"]],"lastId":7649223797,"id":7649223803,"ts":1784090305196}],"action":"update"}
{"channel":"book_lv2","data":[{"symbol":"BTC_USDT","createTime":1784090305168,"asks":[],"bids":[["64790.13","0"],["64736.39","0.042462"]],"lastId":7649223803,"id":7649223805,"ts":1784090305199}],"action":"update"}
{"channel":"book_lv2","data":[{"symbol":"BTC_USDT","createTime":1784090305168,"asks":[["64857.04","0.073297"]],"bids":[],"lastId":7649223805,"id":7649223806,"ts":1784090305200}],"action":"update"}
{"channel":"book_lv2","data":[{"symbol":"BTC_USDT","createTime":1784090305170,"asks":[["64857.04","0.180425"]],"bids":[],"lastId":7649223806,"id":7649223807,"ts":1784090305201}],"action":"update"}
{"channel":"book_lv2","data":[{"symbol":"BTC_USDT","createTime":1784090305172,"asks":[],"bids":[["64749.35","0.180421"]],"lastId":7649223807,"id":7649223808,"ts":1784090305202}],"action":"update"}
{"channel":"book_lv2","data":[{"symbol":"BTC_USDT","createTime":1784090305177,"asks":[["64849.79","0.231472"],["64865.99","0"]],"bids":[],"lastId":7649223808,"id":7649223812,"ts":1784090305207}],"action":"update"}
{"channel":"book_lv2","data":[{"symbol":"BTC_USDT","createTime":1784090305178,"asks":[["64862.75","0.231472"],["64863.52","0"]],"bids":[],"lastId":7649223812,"id":7649223813,"ts":1784090305209}],"action":"update"}
{"channel":"book_lv2","data":[{"symbol":"BTC_USDT","createTime":1784090305187,"asks":[["64829.16","0.100415"],["64862.75","0"]],"bids":[],"lastId":7649223813,"id":7649223818,"ts":1784090305215}],"action":"update"}
{"channel":"book_lv2","data":[{"symbol":"BTC_USDT","createTime":1784090305222,"asks":[],"bids":[["64784.97","0"],["64733.7","0.065170"]],"lastId":7649223818,"id":7649223819,"ts":1784090305232}],"action":"update"}
{"channel":"book_lv2","data":[{"symbol":"BTC_USDT","createTime":1784090305222,"asks":[],"bids":[["64775.31","0"],["64733.15","0.13093"]],"lastId":7649223819,"id":7649223820,"ts":1784090305233}],"action":"update"}
{"channel":"book_lv2","data":[{"symbol":"BTC_USDT","createTime":1784090305245,"asks":[["64829.16","0"],["64862.75","0.231472"]],"bids":[],"lastId":7649223820,"id":7649223821,"ts":1784090305254}],"action":"update"}
{"channel":"book_lv2","data":[{"symbol":"BTC_USDT","createTime":1784090305247,"asks":[],"bids":[["64739.63","0.204226"]],"lastId":7649223821,"id":7649223827,"ts":1784090305261}],"action":"update"}
{"channel":"book_lv2","data":[{"symbol":"BTC_USDT","createTime":1784090305247,"asks":[],"bids":[["64733.15","0"],["64731.85","0.160032"]],"lastId":7649223827,"id":7649223829,"ts":1784090305264}],"action":"update"}
{"channel":"book_lv2","data":[{"symbol":"BTC_USDT","createTime":1784090305264,"asks":[["64855.63","0.029316"],["64862.75","0"]],"bids":[],"lastId":7649223829,"id":7649223830,"ts":1784090305281}],"action":"update"}
{"channel":"book_lv2","data":[{"symbol":"BTC_USDT","createTime":1784090305266,"asks":[["64852.39","0.029319"],["64860.16","0"]],"bids":[],"lastId":7649223830,"id":7649223831,"ts":1784090305282}],"action":"update"}
{"channel":"book_lv2","data":[{"symbol":"BTC_USDT","createTime":1784090305271,"asks":[["64849.15","0.029315"],["64857.57","0"]],"bids":[],"lastId":7649223831,"id":7649223834,"ts":1784090305286}],"action":"update"}
{"channel":"book_lv2","data":[{"symbol":"BTC_USDT","createTime":1784090305273,"asks":[["64845.91","0.029319"],["64857.04","0"]],"bids":[],"lastId":7649223834,"id":7649223835,"ts":1784090305288}],"action":"update"}
{"channel":"book_lv2","data":[{"symbol":"BTC_USDT","createTime":1784090305314,"asks":[["64829.16","0.100415"],["64856.93","0"]],"bids":[],"lastId":7649223835,"id":7649223841,"ts":1784090305328}],"action":"update"}
{"channel":"book_lv2","data":[{"symbol":"BTC_USDT","createTime":1784090305329,"asks":[["64829.16","0"],["64856.93","0.103569"]],"bids":[],"lastId":7649223841,"id":7649223842,"ts":1784090305340}],"action":"update"}
{"channel":"book_lv2","data":[{"symbol":"BTC_USDT","createTime":1784090305339,"asks":[["64848.5","0.030032"],["64856.93","0"]],"bids":[],"lastId":7649223842,"id":7649223843,"ts":1784090305350}],"action":"update"}
{"channel":"book_lv2","data":[{"symbol":"BTC_USDT","createTime":1784090305341,"asks":[],"bids":[["64733.7","0.095199"]],"lastId":7649223843,"id":7649223844,"ts":1784090305351}],"action":"update"}
{"channel":"book_lv2","data":[{"symbol":"BTC_USDT","createTime":1784090305343,"asks":[["64854.98","0.103571"],["64856.27","0"]],"bids":[],"lastId":7649223844,"id":7649223847,"ts":1784090305355}],"action":"update"}
{"channel":"book_lv2","data":[{"symbol":"BTC_USDT","createTime":1784090305346,"asks":[["64851.74","0.05577"],["64855.63","0"]],"bids":[],"lastId":7649223847,"id":7649223850,"ts":1784090305359}],"action":"update"}
{"channel":"book_lv2","data":[{"symbol":"BTC_USDT","createTime":1784090305351,"asks":[["64849.79","0"],["64855.63","0.029316"]],"bids":[],"lastId":7649223850,"id":7649223853,"ts":1784090305369}],"action":"update"}
{"channel":"book_lv2","data":[{"symbol":"BTC_USDT","createTime":1784090305388,"asks":[["64829.16","0.100415"],["64855.63","0"]],"bids":[],"lastId":7649223853,"id":7649223858,"ts":1784090305397}],"action":"update"}
{"channel":"book_lv2","data":[{"symbol":"BTC_USDT","createTime":1784090305402,"asks":[["64829.16","0"],["64855.63","0.029316"]],"bids":[],"lastId":7649223858,"id":7649223859,"ts":1784090305411}],"action":"update"}
{"channel":"book_lv2","data":[{"symbol":"BTC_USDT","createTime":1784090305440,"asks":[],"bids":[["64784.99","0.410245"],["64731.85","0"]],"lastId":7649223859,"id":7649223860,"ts":1784090305453}],"action":"update"}
{"channel":"book_lv2","data":[{"symbol":"BTC_USDT","createTime":1784090305442,"asks":[],"bids":[["64775.26","0.760615"],["64733.7","0"]],"lastId":7649223860,"id":7649223861,"ts":1784090305455}],"action":"update"}
{"channel":"book_lv2","data":[{"symbol":"BTC_USDT","createTime":1784090305451,"asks":[],"bids":[["64799.85","0.219904"],["64736.39","0"]],"lastId":7649223861,"id":7649223867,"ts":1784090305463}],"action":"update"}
{"channel":"book_lv2","data":[{"symbol":"BTC_USDT","createTime":1784090305453,"asks":[],"bids":[["64790.13","0.225095"],["64739.63","0"]],"lastId":7649223867,"id":7649223868,"ts":1784090305466}],"action":"update"}
{"channel":"book_lv2","data":[{"symbol":"BTC_USDT","createTime":1784090305453,"asks":[],"bids":[["64749.3","0.107129"],["64742.87","0"]],"lastId":7649223868,"id":7649223869,"ts":1784090305467}],"action":"update"}
{"channel":"book_lv2","data":[{"symbol":"BTC_USDT","createTime":1784090305462,"asks":[["64829.16","0.100415"],["64855.63","0"]],"bids":[],"lastId":7649223869,"id":7649223875,"ts":1784090305479}],"action":"update"}
{"channel":"book_lv2","data":[{"symbol":"BTC_USDT","createTime":1784090305474,"asks":[["64849.79","0.230751"],["64854.98","0"]],"bids":[],"lastId":7649223875,"id":7649223882,"ts":1784090305493}],"action":"update"}
{"channel":"book_lv2","data":[{"symbol":"BTC_USDT","createTime":1784090305476,"asks":[["64829.16","0"],["64854.98","0.103571"]],"bids":[],"lastId":7649223882,"id":7649223885,"ts":1784090305497}],"action":"update"}
{"channel":"book_lv2","data":[{"symbol":"BTC_USDT","createTime":1784090305522,"asks":[],"bids":[["64784.99","0"],["64742.87","0.073297"]],"lastId":7649223885,"id":7649223888,"ts":1784090305535}],"action":"update"}
{"channel":"book_lv2","data":[{"symbol":"BTC_USDT","createTime":1784090305522,"asks":[],"bids":[["64775.26","0"],["64739.63","0.204226"]],"lastId":7649223888,"id":7649223889,"ts":1784090305537}],"action":"update"}
{"channel":"book_lv2","data":[{"symbol":"BTC_USDT","createTime":1784090305525,"asks":[],"bids":[["64739.63","0.311355"]],"lastId":7649223889,"id":7649223892,"ts":1784090305541}],"action":"update"}
{"channel":"book_lv2","data":[{"symbol":"BTC_USDT","createTime":1784090305548,"asks":[["64829.16","0.100415"],["64854.98","0"]],"bids":[],"lastId":7649223892,"id":7649223898,"ts":1784090305561}],"action":"update"}
{"channel":"book_lv2","data":[{"symbol":"BTC_USDT","createTime":1784090305564,"asks":[["64829.16","0"],["64854.98","0.103571"]],"bids":[],"lastId":7649223898,"id":7649223899,"ts":1784090305576}],"action":"update"}
{"channel":"book_lv2","data":[{"symbol":"BTC_USDT","createTime":1784090305624,"asks":[["64829.16","0.100415"],["64854.98","0"]],"bids":[],"lastId":7649223899,"id":7649223900,"ts":1784090305640}],"action":"update"}
{"channel":"book_lv2","data":[{"symbol":"BTC_USDT","createTime":1784090305627,"asks":[["64853.68","0"],["64854.98","0.103571"]],"bids":[],"lastId":7649223900,"id":7649223902,"ts":1784090305640}],"action":"update"}
{"channel":"book_lv2","data":[{"symbol":"BTC_USDT","createTime":1784090305627,"asks":[["64843.97","0"],["64855.63","0.029316"]],"bids":[],"lastId":7649223902,"id":7649223903,"ts":1784090305641}],"action":"update"}
{"channel":"book_lv2","data":[{"symbol":"BTC_USDT","createTime":1784090305627,"asks":[["64850.44","0"],["64856.27","0.013855"]],"bids":[],"lastId":7649223903,"id":7649223904,"ts":1784090305642}],"action":"update"}
{"channel":"book_lv2","data":[{"symbol":"BTC_USDT","createTime":1784090305629,"asks":[["64847.2","0"],["64856.93","0.103569"]],"bids":[],"lastId":7649223904,"id":7649223906,"ts":1784090305645}],"action":"update"}
{"channel":"book_lv2","data":[{"symbol":"BTC_USDT","createTime":1784090305642,"asks":[["64829.16","0"],["64857.04","0.287552"]],"bids":[],"lastId":7649223906,"id":7649223909,"ts":1784090305660}],"action":"update"}
{"channel":"book_lv2","data":[{"symbol":"BTC_USDT","createTime":1784090305645,"asks":[["64856.27","0.026946"]],"bids":[],"lastId":7649223909,"id":7649223910,"ts":1784090305668}],"action":"update"}
{"channel":"book_lv2","data":[{"symbol":"BTC_USDT","createTime":1784090305648,"asks":[],"bids":[["64785.01","0.371949"],["64739.63","0"]],"lastId":7649223910,"id":7649223911,"ts":1784090305670}],"action":"update"}
{"channel":"book_lv2","data":[{"symbol":"BTC_USDT","createTime":1784090305648,"asks":[],"bids":[["64775.26","0.735074"],["64742.87","0"]],"lastId":7649223911,"id":7649223914,"ts":1784090305673}],"action":"update"}
{"channel":"book_lv2","data":[{"symbol":"BTC_USDT","createTime":1784090305652,"asks":[["64856.27","0.013091"]],"bids":[],"lastId":7649223914,"id":7649223916,"ts":1784090305676}],"action":"update"}
{"channel":"book_lv2","data":[{"symbol":"BTC_USDT","createTime":1784090305652,"asks":[["64849.79","0"],["64857.57","2.75621"]],"bids":[],"lastId":7649223916,"id":7649223918,"ts":1784090305678}],"action":"update"}
{"channel":"book_lv2","data":[{"symbol":"BTC_USDT","createTime":1784090305652,"asks":[["64856.27","0"],["64858.22","7.716401"]],"bids":[],"lastId":7649223918,"id":7649223921,"ts":1784090305682}],"action":"update"}
{"channel":"book_lv2","data":[{"symbol":"BTC_USDT","createTime":1784090305668,"asks":[["64849.79","0.230751"],["64858.22","0"]],"bids":[],"lastId":7649223921,"id":7649223930,"ts":1784090305693}],"action":"update"}
{"channel":"book_lv2","data":[{"symbol":"BTC_USDT","createTime":1784090305696,"asks":[["64829.16","0.100415"],["64857.57","0"]],"bids":[],"lastId":7649223930,"id":7649223934,"ts":1784090305712}],"action":"update"}
{"channel":"book_lv2","data":[{"symbol":"BTC_USDT","createTime":1784090305711,"asks":[["64829.16","0"],["64857.57","2.75621"]],"bids":[],"lastId":7649223934,"id":7649223935,"ts":1784090305724}],"action":"update"}
{"channel":"book_lv2","data":[{"symbol":"BTC_USDT","createTime":1784090305725,"asks":[],"bids":[["64785.01","0"],["64742.87","0.073297"]],"lastId":7649223935,"id":7649223936,"ts":1784090305733}],"action":"update"}
{"channel":"book_lv2","data":[{"symbol":"BTC_USDT","createTime":1784090305725,"asks":[],"bids":[["64775.26","0"],["64739.63","0.311355"]],"lastId":7649223936,"id":7649223937,"ts":1784090305734}],"action":"update"}
{"channel":"book_lv2","data":[{"symbol":"BTC_USDT","createTime":1784090305766,"asks":[["64829.16","0.100415"],["64857.57","0"]],"bids":[],"lastId":7649223937,"id":7649223941,"ts":1784090305779}],"action":"update"}
{"channel":"book_lv2","data":[{"symbol":"BTC_USDT","createTime":1784090305779,"asks":[["64829.16","0"],["64857.57","2.75621"]],"bids":[],"lastId":7649223941,"id":7649223942,"ts":1784090305790}],"action":"update"}
{"channel":"book_lv2","data":[{"symbol":"BTC_USDT","createTime":1784090305850,"asks":[["64829.16","0.100415"],["64857.57","0"]],"bids":[],"lastId":7649223942,"id":7649223943,"ts":1784090305863}],"action":"update"}
{"channel":"book_lv2","data":[{"symbol":"BTC_USDT","createTime":1784090305866,"asks":[["64829.16","0"],["64857.57","2.75621"]],"bids":[],"lastId":7649223943,"id":7649223944,"ts":1784090305876}],"action":"update"}
{"channel":"book_lv2","data":[{"symbol":"BTC_USDT","createTime":1784090305904,"asks":[["64853.68","2.620553"],["64857.57","0"]],"bids":[],"lastId":7649223944,"id":7649223947,"ts":1784090305915}],"action":"update"}
{"channel":"book_lv2","data":[{"symbol":"BTC_USDT","createTime":1784090305904,"asks":[["64850.44","0.031534"],["64857.04","0"]],"bids":[],"lastId":7649223947,"id":7649223948,"ts":1784090305916}],"action":"update"}
{"channel":"book_lv2","data":[{"symbol":"BTC_USDT","createTime":1784090305904,"asks":[["64847.2","0.016982"],["64856.93","0"]],"bids":[],"lastId":7649223948,"id":7649223949,"ts":1784090305917}],"action":"update"}
{"channel":"book_lv2","data":[{"symbol":"BTC_USDT","createTime":1784090305904,"asks":[["64843.97","0.009145"],["64855.63","0"]],"bids":[],"lastId":7649223949,"id":7649223951,"ts":1784090305920}],"action":"update"}
{"channel":"book_lv2","data":[{"symbol":"BTC_USDT","createTime":1784090305923,"asks":[["64829.16","0.100415"],["64854.98","0"]],"bids":[],"lastId":7649223951,"id":7649223955,"ts":1784090305937}],"action":"update"}
{"channel":"trades","data":[{"symbol":"BTC_USDT","amount":"1208.44317384","quantity":"0.018648","takerSide":"buy","createTime":1784090305940,"price":"64802.83","id":"225823471","ts":1784090305949}]}
{"channel":"trades","data":[{"symbol":"BTC_USDT","amount":"1391.51116859","quantity":"0.021473","takerSide":"buy","createTime":1784090305940,"price":"64802.83","id":"225823472","ts":1784090305949}]}
{"channel":"trades","data":[{"symbol":"BTC_USDT","amount":"1208.44317384","quantity":"0.018648","takerSide":"buy","createTime":1784090305940,"price":"64802.83","id":"225823473","ts":1784090305949}]}
{"channel":"book_lv2","data":[{"symbol":"BTC_USDT","createTime":1784090305940,"asks":[["64802.83","0.018648"],["64854.33","0"]],"bids":[],"lastId":7649223955,"id":7649223956,"ts":1784090305951}],"action":"update"}
{"channel":"book_lv2","data":[{"symbol":"BTC_USDT","createTime":1784090305940,"asks":[["64802.83","0.058769"]],"bids":[],"lastId":7649223956,"id":7649223957,"ts":1784090305952}],"action":"update"}
{"channel":"book_lv2","data":[{"symbol":"BTC_USDT","createTime":1784090305940,"asks":[["64802.83","0.018648"]],"bids":[],"lastId":7649223957,"id":7649223958,"ts":1784090305953}],"action":"update"}
{"channel":"book_lv2","data":[{"symbol":"BTC_USDT","createTime":1784090305940,"asks":[["64802.83","0"],["64854.33","0.033169"]],"bids":[],"lastId":7649223958,"id":7649223959,"ts":1784090305954}],"action":"update"}
{"channel":"book_lv2","data":[{"symbol":"BTC_USDT","createTime":1784090305951,"asks":[["64849.79","0"],["64854.98","0.103571"]],"bids":[],"lastId":7649223959,"id":7649223963,"ts":1784090305967}],"action":"update"}
{"channel":"book_lv2","data":[{"symbol":"BTC_USDT","createTime":1784090305982,"asks":[["64829.16","0"],["64855.63","0.029316"]],"bids":[],"lastId":7649223963,"id":7649223965,"ts":1784090305996}],"action":"update"}
{"channel":"book_lv2","data":[{"symbol":"BTC_USDT","createTime":1784090306016,"asks":[["64853.69","0"],["64857.04","0.287552"]],"bids":[],"lastId":7649223965,"id":7649223967,"ts":1784090306035}],"action":"update"}
{"channel":"book_lv2","data":[{"symbol":"BTC_USDT","createTime":1784090306016,"asks":[["64850.45","0"],["64857.57","2.75621"]],"bids":[],"lastId":7649223967,"id":7649223969,"ts":1784090306037}],"action":"update"}
{"channel":"book_lv2","data":[{"symbol":"BTC_USDT","createTime":1784090306048,"asks":[["64829.16","0.100415"],["64857.57","0"]],"bids":[],"lastId":7649223969,"id":7649223974,"ts":1784090306062}],"action":"update"}
{"channel":"book_lv2","data":[{"symbol":"BTC_USDT","createTime":1784090306061,"asks":[["64829.16","0"],["64857.57","2.75621"]],"bids":[],"lastId":7649223974,"id":7649223976,"ts":1784090306076}],"action":"update"}
{"channel":"book_lv2","data":[{"symbol":"BTC_USDT","createTime":1784090306066,"asks":[],"bids":[["64785","0.372759"],["64739.63","0"]],"lastId":7649223976,"id":7649223977,"ts":1784090306078}],"action":"update"}
{"channel":"book_lv2","data":[{"symbol":"BTC_USDT","createTime":1784090306068,"asks":[],"bids":[["64775.3","0.739633"],["64742.87","0"]],"lastId":7649223977,"id":7649223979,"ts":1784090306080}],"action":"update"}
{"channel":"book_lv2","data":[{"symbol":"BTC_USDT","createTime":1784090306070,"asks":[["64856.28","0.001127"],["64857.57","0"]],"bids":[],"lastId":7649223979,"id":7649223980,"ts":1784090306081}],"action":"update"}
{"channel":"book_lv2","data":[{"symbol":"BTC_USDT","createTime":1784090306087,"asks":[["64849.8","0.096814"],["64857.04","0"]],"bids":[],"lastId":7649223980,"id":7649223984,"ts":1784090306098}],"action":"update"}
{"channel":"book_lv2","data":[{"symbol":"BTC_USDT","createTime":1784090306132,"asks":[["64829.16","0.100415"],["64856.28","0"]],"bids":[],"lastId":7649223984,"id":7649223993,"ts":1784090306147}],"action":"update"}
{"channel":"book_lv2","data":[{"symbol":"BTC_USDT","createTime":1784090306148,"asks":[["64829.16","0"],["64856.28","0.001127"]],"bids":[],"lastId":7649223993,"id":7649223994,"ts":1784090306165}],"action":"update"}
{"channel":"book_lv2","data":[{"symbol":"BTC_USDT","createTime":1784090306212,"asks":[["64805.04","0"],["64857.04","0.287552"]],"bids":[],"lastId":7649223994,"id":7649223995,"ts":1784090306222}],"action":"update"}
{"channel":"book_lv2","data":[{"symbol":"BTC_USDT","createTime":1784090306224,"asks":[["64829.16","0.100415"],["64857.04","0"]],"bids":[],"lastId":7649223995,"id":7649223997,"ts":1784090306236}],"action":"update"}
{"channel":"book_lv2","data":[{"symbol":"BTC_USDT","createTime":1784090306229,"asks":[],"bids":[["64756.95","0"],["64742.87","0.073297"]],"lastId":7649223997,"id":7649223998,"ts":1784090306246}],"action":"update"}
{"channel":"book_lv2","data":[{"symbol":"BTC_USDT","createTime":1784090306234,"asks":[["64811.13","0.020062"]],"bids":[],"lastId":7649223998,"id":7649223999,"ts":1784090306247}],"action":"update"}
{"channel":"book_lv2","data":[{"symbol":"BTC_USDT","createTime":1784090306241,"asks":[["64811.13","0.000062"]],"bids":[],"lastId":7649223999,"id":7649224000,"ts":1784090306260}],"action":"update"}
{"channel":"book_lv2","data":[{"symbol":"BTC_USDT","createTime":1784090306243,"asks":[["64829.16","0"],["64857.04","0.287552"]],"bids":[],"lastId":7649224000,"id":7649224001,"ts":1784090306261}],"action":"update"}
{"channel":"book_lv2","data":[{"symbol":"BTC_USDT","createTime":1784090306249,"asks":[["64856.28","0"],["64857.57","2.75621"]],"bids":[],"lastId":7649224001,"id":7649224002,"ts":1784090306263}],"action":"update"}
{"channel":"book_lv2","data":[{"symbol":"BTC_USDT","createTime":1784090306253,"asks":[],"bids":[["64765.51","0"],["64739.63","0.311355"]],"lastId":7649224002,"id":7649224004,"ts":1784090306273}],"action":"update"}
{"channel":"book_lv2","data":[{"symbol":"BTC_USDT","createTime":1784090306254,"asks":[["64849.8","0"],["64858.22","7.716401"]],"bids":[],"lastId":7649224004,"id":7649224011,"ts":1784090306282}],"action":"update"}
{"channel":"book_lv2","data":[{"symbol":"BTC_USDT","createTime":1784090306255,"asks":[],"bids":[["64785","0"],["64739.58","0.130935"]],"lastId":7649224011,"id":7649224012,"ts":1784090306283}],"action":"update"}
{"channel":"book_lv2","data":[{"symbol":"BTC_USDT","createTime":1784090306255,"asks":[],"bids":[["64775.3","0"],["64736.39","0.042462"]],"lastId":7649224012,"id":7649224013,"ts":1784090306284}],"action":"update"}
{"channel":"book_lv2","data":[{"symbol":"BTC_USDT","createTime":1784090306294,"asks":[["64853.99","0.055767"],["64858.22","0"]],"bids":[],"lastId":7649224013,"id":7649224014,"ts":1784090306306}],"action":"update"}
{"channel":"book_lv2","data":[{"symbol":"BTC_USDT","createTime":1784090306296,"asks":[["64850.75","0.03003"],["64857.57","0"]],"bids":[],"lastId":7649224014,"id":7649224017,"ts":1784090306309}],"action":"update"}
{"channel":"book_lv2","data":[{"symbol":"BTC_USDT","createTime":1784090306341,"asks":[],"bids":[["64796.93","0"],["64734","0.03003"]],"lastId":7649224017,"id":7649224025,"ts":1784090306359}],"action":"update"}
{"channel":"book_lv2","data":[{"symbol":"BTC_USDT","createTime":1784090306352,"asks":[["64838.88","0.100415"],["64857.04","0"]],"bids":[],"lastId":7649224025,"id":7649224026,"ts":1784090306363}],"action":"update"}
{"channel":"book_lv2","data":[{"symbol":"BTC_USDT","createTime":1784090306379,"asks":[["64838.88","0"],["64857.04","0.287552"]],"bids":[],"lastId":7649224026,"id":7649224027,"ts":1784090306390}],"action":"update"}
{"channel":"book_lv2","data":[{"symbol":"BTC_USDT","createTime":1784090306437,"asks":[["64838.88","0.100415"],["64857.04","0"]],"bids":[],"lastId":7649224027,"id":7649224028,"ts":1784090306453}],"action":"update"}
{"channel":"book_lv2","data":[{"symbol":"BTC_USDT","createTime":1784090306454,"asks":[["64838.88","0"],["64857.04","0.287552"]],"bids":[],"lastId":7649224028,"id":7649224029,"ts":1784090306465}],"action":"update"}
{"channel":"book_lv2","data":[{"symbol":"BTC_USDT","createTime":1784090306500,"asks":[],"bids":[["64739.63","0.238064"]],"lastId":7649224029,"id":7649224030,"ts":1784090306511}],"action":"update"}
{"channel":"book_lv2","data":[{"symbol":"BTC_USDT","createTime":1784090306500,"asks":[],"bids":[["64742.87","0"],["64733.7","0.065151"]],"lastId":7649224030,"id":7649224032,"ts":1784090306514}],"action":"update"}
{"channel":"book_lv2","data":[{"symbol":"BTC_USDT","createTime":1784090306501,"asks":[],"bids":[["64736.39","0"],["64733.15","0.130935"]],"lastId":7649224032,"id":7649224034,"ts":1784090306516}],"action":"update"}
{"channel":"book_lv2","data":[{"symbol":"BTC_USDT","createTime":1784090306503,"asks":[["64857.04","0.214255"]],"bids":[],"lastId":7649224034,"id":7649224035,"ts":1784090306518}],"action":"update"}
{"channel":"book_lv2","data":[{"symbol":"BTC_USDT","createTime":1784090306503,"asks":[],"bids":[["64749.35","0.107127"]],"lastId":7649224035,"id":7649224036,"ts":1784090306519}],"action":"update"}
{"channel":"book_lv2","data":[{"symbol":"BTC_USDT","createTime":1784090306520,"asks":[["64838.88","0.100415"],["64857.04","0"]],"bids":[],"lastId":7649224036,"id":7649224037,"ts":1784090306534}],"action":"update"}
{"channel":"book_lv2","data":[{"symbol":"BTC_USDT","createTime":1784090306534,"asks":[["64838.88","0"],["64857.04","0.214255"]],"bids":[],"lastId":7649224037,"id":7649224038,"ts":1784090306547}],"action":"update"}
{"channel":"book_lv2","data":[{"symbol":"BTC_USDT","createTime":1784090306559,"asks":[],"bids":[["64733.7","0.047573"]],"lastId":7649224038,"id":7649224042,"ts":1784090306574}],"action":"update"}
{"channel":"book_lv2","data":[{"symbol":"BTC_USDT","createTime":1784090306559,"asks":[["64851.09","0"],["64857.23","0.10357"]],"bids":[],"lastId":7649224042,"id":7649224043,"ts":1784090306575}],"action":"update"}
{"channel":"book_lv2","data":[{"symbol":"BTC_USDT","createTime":1784090306561,"asks":[["64847.85","0"],["64858.22","7.716401"]],"bids":[],"lastId":7649224043,"id":7649224046,"ts":1784090306579}],"action":"update"}
{"channel":"book_lv2","data":[{"symbol":"BTC_USDT","createTime":1784090306561,"asks":[["64854.33","0"],["64860.47","7.716305"]],"bids":[],"lastId":7649224046,"id":7649224047,"ts":1784090306580}],"action":"update"}
{"channel":"book_lv2","data":[{"symbol":"BTC_USDT","createTime":1784090306565,"asks":[],"bids":[["64805.54","0.000062"],["64733.15","0"]],"lastId":7649224047,"id":7649224048,"ts":1784090306581}],"action":"update"}
{"channel":"book_lv2","data":[{"symbol":"BTC_USDT","createTime":1784090306567,"asks":[],"bids":[["64808.78","0.000062"],["64733.7","0"]],"lastId":7649224048,"id":7649224049,"ts":1784090306583}],"action":"update"}
{"channel":"book_lv2","data":[{"symbol":"BTC_USDT","createTime":1784090306621,"asks":[["64838.88","0.100415"],["64860.47","0"]],"bids":[],"lastId":7649224049,"id":7649224050,"ts":1784090306640}],"action":"update"}
{"channel":"book_lv2","data":[{"symbol":"BTC_USDT","createTime":1784090306637,"asks":[["64838.88","0"],["64860.47","7.716305"]],"bids":[],"lastId":7649224050,"id":7649224051,"ts":1784090306655}],"action":"update"}
{"channel":"book_lv2","data":[{"symbol":"BTC_USDT","createTime":1784090306685,"asks":[],"bids":[["64774.91","1.45667"],["64734","0"]],"lastId":7649224051,"id":7649224053,"ts":1784090306698}],"action":"update"}
{"channel":"book_lv2","data":[{"symbol":"BTC_USDT","createTime":1784090306685,"asks":[],"bids":[["64794.41","0.36355"],["64739.58","0"]],"lastId":7649224053,"id":7649224054,"ts":1784090306699}],"action":"update"}
{"channel":"book_lv2","data":[{"symbol":"BTC_USDT","createTime":1784090306687,"asks":[],"bids":[["64784.69","0.202343"],["64739.63","0"]],"lastId":7649224054,"id":7649224056,"ts":1784090306702}],"action":"update"}
{"channel":"book_lv2","data":[{"symbol":"BTC_USDT","createTime":1784090306692,"asks":[],"bids":[["64784.69","0"],["64739.63","0.238064"]],"lastId":7649224056,"id":7649224057,"ts":1784090306711}],"action":"update"}
{"channel":"book_lv2","data":[{"symbol":"BTC_USDT","createTime":1784090306692,"asks":[],"bids":[["64794.41","0"],["64739.58","0.130935"]],"lastId":7649224057,"id":7649224058,"ts":1784090306712}],"action":"update"}
{"channel":"book_lv2","data":[{"symbol":"BTC_USDT","createTime":1784090306698,"asks":[["64838.88","0.100415"],["64860.47","0"]],"bids":[],"lastId":7649224058,"id":7649224060,"ts":1784090306715}],"action":"update"}
{"channel":"book_lv2","data":[{"symbol":"BTC_USDT","createTime":1784090306712,"asks":[["64838.88","0"],["64860.47","7.716305"]],"bids":[],"lastId":7649224060,"id":7649224065,"ts":1784090306724}],"action":"update"}
{"channel":"book_lv2","data":[{"symbol":"BTC_USDT","createTime":1784090306719,"asks":[["64859.17","0.231445"],["64860.47","0"]],"bids":[],"lastId":7649224065,"id":7649224066,"ts":1784090306731}],"action":"update"}
{"channel":"book_lv2","data":[{"symbol":"BTC_USDT","createTime":1784090306773,"asks":[],"bids":[["64756.34","0.073295"],["64739.58","0"]],"lastId":7649224066,"id":7649224070,"ts":1784090306785}],"action":"update"}
{"channel":"book_lv2","data":[{"symbol":"BTC_USDT","createTime":1784090306776,"asks":[["64838.88","0.100415"],["64859.17","0"]],"bids":[],"lastId":7649224070,"id":7649224072,"ts":1784090306787}],"action":"update"}
{"channel":"book_lv2","data":[{"symbol":"BTC_USDT","createTime":1784090306777,"asks":[],"bids":[["64749.86","0.073297"],["64739.63","0"]],"lastId":7649224072,"id":7649224073,"ts":1784090306792}],"action":"update"}
{"channel":"book_lv2","data":[{"symbol":"BTC_USDT","createTime":1784090306790,"asks":[["64838.88","0"],["64859.17","0.231445"]],"bids":[],"lastId":7649224073,"id":7649224076,"ts":1784090306801}],"action":"update"}
{"channel":"book_lv2","data":[{"symbol":"BTC_USDT","createTime":1784090306834,"asks":[["64848.15","0.003855"],["64859.17","0"]],"bids":[],"lastId":7649224076,"id":7649224080,"ts":1784090306845}],"action":"update"}
{"channel":"book_lv2","data":[{"symbol":"BTC_USDT","createTime":1784090306834,"asks":[["64854.63","0.005921"],["64858.22","0"]],"bids":[],"lastId":7649224080,"id":7649224082,"ts":1784090306847}],"action":"update"}
{"channel":"book_lv2","data":[{"symbol":"BTC_USDT","createTime":1784090306834,"asks":[["64851.39","0.003854"],["64857.23","0"]],"bids":[],"lastId":7649224082,"id":7649224083,"ts":1784090306849}],"action":"update"}
{"channel":"book_lv2","data":[{"symbol":"BTC_USDT","createTime":1784090306852,"asks":[["64838.88","0.100415"],["64857.04","0"]],"bids":[],"lastId":7649224083,"id":7649224088,"ts":1784090306869}],"action":"update"}
{"channel":"book_lv2","data":[{"symbol":"BTC_USDT","createTime":1784090306869,"asks":[["64838.88","0"],["64857.04","0.214255"]],"bids":[],"lastId":7649224088,"id":7649224095,"ts":1784090306879}],"action":"update"}
{"channel":"book_lv2","data":[{"symbol":"BTC_USDT","createTime":1784090306934,"asks":[["64838.88","0.100415"],["64857.04","0"]],"bids":[],"lastId":7649224095,"id":7649224096,"ts":1784090306944}],"action":"update"}
{"channel":"book_lv2","data":[{"symbol":"BTC_USDT","createTime":1784090306964,"asks":[["64838.88","0"],["64857.04","0.214255"]],"bids":[],"lastId":7649224096,"id":7649224100,"ts":1784090306991}],"action":"update"}
{"channel":"book_lv2","data":[{"symbol":"BTC_USDT","createTime":1784090306975,"asks":[],"bids":[["64749.35","0"],["64746.62","0.073293"]],"lastId":7649224100,"id":7649224106,"ts":1784090306998}],"action":"update"}
{"channel":"book_lv2","data":[{"symbol":"BTC_USDT","createTime":1784090306975,"asks":[["64857.04","0.107127"]],"bids":[],"lastId":7649224106,"id":7649224107,"ts":1784090307000}],"action":"update"}
{"channel":"book_lv2","data":[{"symbol":"BTC_USDT","createTime":1784090307004,"asks":[["64852.39","0"],["64857.23","0.10357"]],"bids":[],"lastId":7649224107,"id":7649224112,"ts":1784090307020}],"action":"update"}
{"channel":"book_lv2","data":[{"symbol":"BTC_USDT","createTime":1784090307004,"asks":[["64849.15","0"],["64857.87","0.489139"]],"bids":[],"lastId":7649224112,"id":7649224114,"ts":1784090307023}],"action":"update"}
{"channel":"book_lv2","data":[{"symbol":"BTC_USDT","createTime":1784090307004,"asks":[["64855.63","0"],["64858.22","7.716401"]],"bids":[],"lastId":7649224114,"id":7649224116,"ts":1784090307026}],"action":"update"}
{"channel":"book_lv2","data":[{"symbol":"BTC_USDT","createTime":1784090307005,"asks":[["64845.91","0"],["64860.47","7.716305"]],"bids":[],"lastId":7649224116,"id":7649224118,"ts":1784090307029}],"action":"update"}
{"channel":"book_lv2","data":[{"symbol":"BTC_USDT","createTime":1784090307022,"asks":[],"bids":[["64793.51","0"],["64743.38","0.042431"]],"lastId":7649224118,"id":7649224120,"ts":1784090307040}],"action":"update"}
{"channel":"book_lv2","data":[{"symbol":"BTC_USDT","createTime":1784090307022,"asks":[],"bids":[["64793.11","0"],["64739.63","0.107129"]],"lastId":7649224120,"id":7649224121,"ts":1784090307041}],"action":"update"}
{"channel":"book_lv2","data":[{"symbol":"BTC_USDT","createTime":1784090307022,"asks":[],"bids":[["64792.31","0"],["64739.58","0.130935"]],"lastId":7649224121,"id":7649224122,"ts":1784090307043}],"action":"update"}
{"channel":"book_lv2","data":[{"symbol":"BTC_USDT","createTime":1784090307022,"asks":[],"bids":[["64792.71","0"],["64734","0.05005"]],"lastId":7649224122,"id":7649224123,"ts":1784090307044}],"action":"update"}
{"channel":"book_lv2","data":[{"symbol":"BTC_USDT","createTime":1784090307022,"asks":[],"bids":[["64793.71","0"],["64733.7","0.047573"]],"lastId":7649224123,"id":7649224124,"ts":1784090307045}],"action":"update"}
{"channel":"book_lv2","data":[{"symbol":"BTC_USDT","createTime":1784090307023,"asks":[],"bids":[["64799.86","0"],["64733.15","0.130935"]],"lastId":7649224124,"id":7649224125,"ts":1784090307047}],"action":"update"}
{"channel":"book_lv2","data":[{"symbol":"BTC_USDT","createTime":1784090307023,"asks":[],"bids":[["64792.51","0"],["64731.85","0.160032"]],"lastId":7649224125,"id":7649224126,"ts":1784090307048}],"action":"update"}
{"channel":"book_lv2","data":[{"symbol":"BTC_USDT","createTime":1784090307023,"asks":[["64811.13","0"],["64864.04","0.07329"]],"bids":[],"lastId":7649224126,"id":7649224127,"ts":1784090307049}],"action":"update"}
{"channel":"book_lv2","data":[{"symbol":"BTC_USDT","createTime":1784090307024,"asks":[],"bids":[["64792.9","0"],["64731.8","0.160032"]],"lastId":7649224127,"id":7649224128,"ts":1784090307051}],"action":"update"}
{"channel":"book_lv2","data":[{"symbol":"BTC_USDT","createTime":1784090307024,"asks":[],"bids":[["64793.31","0"],["64730.76","0.092947"]],"lastId":7649224128,"id":7649224129,"ts":1784090307052}],"action":"update"}
{"channel":"book_lv2","data":[{"symbol":"BTC_USDT","createTime":1784090307024,"asks":[["64811.18","0"],["64866.76","0.130936"]],"bids":[],"lastId":7649224129,"id":7649224130,"ts":1784090307053}],"action":"update"}
{"channel":"book_lv2","data":[{"symbol":"BTC_USDT","createTime":1784090307057,"asks":[["64838.88","0.100415"],["64866.76","0"]],"bids":[],"lastId":7649224130,"id":7649224131,"ts":1784090307066}],"action":"update"}
{"channel":"book_lv2","data":[{"symbol":"BTC_USDT","createTime":1784090307074,"asks":[["64838.88","0"],["64866.76","0.130936"]],"bids":[],"lastId":7649224131,"id":7649224132,"ts":1784090307091}],"action":"update"}
{"channel":"book_lv2","data":[{"symbol":"BTC_USDT","createTime":1784090307078,"asks":[],"bids":[["64733.7","0.017544"]],"lastId":7649224132,"id":7649224133,"ts":1784090307093}],"action":"update"}
{"channel":"book_lv2","data":[{"symbol":"BTC_USDT","createTime":1784090307078,"asks":[["64851.74","0"],["64870.52","0.073294"]],"bids":[],"lastId":7649224133,"id":7649224134,"ts":1784090307094}],"action":"update"}
{"channel":"book_lv2","data":[{"symbol":"BTC_USDT","createTime":1784090307078,"asks":[["64848.5","0"],["64873.24","0.107127"]],"bids":[],"lastId":7649224134,"id":7649224136,"ts":1784090307097}],"action":"update"}
{"channel":"book_lv2","data":[{"symbol":"BTC_USDT","createTime":1784090307079,"asks":[["64858.22","0"],["64873.76","0.023428"]],"bids":[],"lastId":7649224136,"id":7649224138,"ts":1784090307100}],"action":"update"}
{"channel":"book_lv2","data":[{"symbol":"BTC_USDT","createTime":1784090307079,"asks":[["64854.98","0"],["64874.53","0.160029"]],"bids":[],"lastId":7649224138,"id":7649224140,"ts":1784090307102}],"action":"update"}
{"channel":"book_lv2","data":[{"symbol":"BTC_USDT","createTime":1784090307115,"asks":[],"bids":[["64784.64","0.183741"],["64730.76","0"]],"lastId":7649224140,"id":7649224142,"ts":1784090307126}],"action":"update"}
{"channel":"book_lv2","data":[{"symbol":"BTC_USDT","createTime":1784090307115,"asks":[["64865.66","0.122796"],["64874.53","0"]],"bids":[],"lastId":7649224142,"id":7649224143,"ts":1784090307128}],"action":"update"}
{"channel":"book_lv2","data":[{"symbol":"BTC_USDT","createTime":1784090307115,"asks":[],"bids":[["64794.38","0.402413"],["64731.8","0"]],"lastId":7649224143,"id":7649224144,"ts":1784090307129}],"action":"update"}
{"channel":"book_lv2","data":[{"symbol":"BTC_USDT","createTime":1784090307123,"asks":[],"bids":[["64794.38","0"],["64731.8","0.160032"]],"lastId":7649224144,"id":7649224146,"ts":1784090307145}],"action":"update"}
{"channel":"book_lv2","data":[{"symbol":"BTC_USDT","createTime":1784090307123,"asks":[],"bids":[["64784.64","0"],["64730.76","0.092947"]],"lastId":7649224146,"id":7649224147,"ts":1784090307145}],"action":"update"}
{"channel":"book_lv2","data":[{"symbol":"BTC_USDT","createTime":1784090307134,"asks":[["64859.17","0.231445"],["64873.76","0"]],"bids":[],"lastId":7649224147,"id":7649224151,"ts":1784090307154}],"action":"update"}
{"channel":"book_lv2","data":[{"symbol":"BTC_USDT","createTime":1784090307151,"asks":[["64838.88","0.100415"],["64873.24","0"]],"bids":[],"lastId":7649224151,"id":7649224154,"ts":1784090307167}],"action":"update"}
{"channel":"book_lv2","data":[{"symbol":"BTC_USDT","createTime":1784090307152,"asks":[["64859.17","0"],["64873.24","0.107127"]],"bids":[],"lastId":7649224154,"id":7649224158,"ts":1784090307172}],"action":"update"}
{"channel":"book_lv2","data":[{"symbol":"BTC_USDT","createTime":1784090307152,"asks":[["64872.14","0.231445"],["64873.24","0"]],"bids":[],"lastId":7649224158,"id":7649224160,"ts":1784090307175}],"action":"update"}
{"channel":"book_lv2","data":[{"symbol":"BTC_USDT","createTime":1784090307153,"asks":[["64865.66","0"],["64873.24","0.107127"]],"bids":[],"lastId":7649224160,"id":7649224163,"ts":1784090307179}],"action":"update"}
{"channel":"book_lv2","data":[{"symbol":"BTC_USDT","createTime":1784090307162,"asks":[],"bids":[["64813.58","0.040115"],["64730.76","0"]],"lastId":7649224163,"id":7649224164,"ts":1784090307181}],"action":"update"}
{"channel":"trades","data":[{"symbol":"BTC_USDT","amount":"1671.60704178","quantity":"0.025791","takerSide":"sell","createTime":1784090307164,"price":"64813.58","id":"225823474","ts":1784090307189}]}
{"channel":"trades","data":[{"symbol":"BTC_USDT","amount":"928.38971992","quantity":"0.014324","takerSide":"sell","createTime":1784090307164,"price":"64813.58","id":"225823475","ts":1784090307189}]}
{"channel":"trades","data":[{"symbol":"BTC_USDT","amount":"1671.60704178","quantity":"0.025791","takerSide":"buy","createTime":1784090307168,"price":"64813.58","id":"225823476","ts":1784090307195}]}
{"channel":"book_lv2","data":[{"symbol":"BTC_USDT","createTime":1784090307164,"asks":[],"bids":[["64813.58","0.014324"]],"lastId":7649224164,"id":7649224165,"ts":1784090307197}],"action":"update"}
{"channel":"book_lv2","data":[{"symbol":"BTC_USDT","createTime":1784090307164,"asks":[["64813.58","0.025791"],["64873.24","0"]],"bids":[["64813.58","0"],["64730.76","0.092947"]],"lastId":7649224165,"id":7649224166,"ts":1784090307198}],"action":"update"}
{"channel":"book_lv2","data":[{"symbol":"BTC_USDT","createTime":1784090307168,"asks":[["64838.88","0"],["64873.24","0.107127"]],"bids":[],"lastId":7649224166,"id":7649224167,"ts":1784090307199}],"action":"update"}
{"channel":"book_lv2","data":[{"symbol":"BTC_USDT","createTime":1784090307168,"asks":[["64813.58","0"],["64873.76","0.023428"]],"bids":[],"lastId":7649224167,"id":7649224168,"ts":1784090307201}],"action":"update"}
{"channel":"book_lv2","data":[{"symbol":"BTC_USDT","createTime":1784090307252,"asks":[],"bids":[["64756.34","0.180401"]],"lastId":7649224168,"id":7649224169,"ts":1784090307270}],"action":"update"}
{"channel":"book_lv2","data":[{"symbol":"BTC_USDT","createTime":1784090307253,"asks":[],"bids":[["64749.3","0"],["64730.46","0.032581"]],"lastId":7649224169,"id":7649224170,"ts":1784090307271}],"action":"update"}
{"channel":"book_lv2","data":[{"symbol":"BTC_USDT","createTime":1784090307253,"asks":[],"bids":[["64731.8","0"],["64729.91","2.642030"]],"lastId":7649224170,"id":7649224171,"ts":1784090307272}],"action":"update"}
{"channel":"book_lv2","data":[{"symbol":"BTC_USDT","createTime":1784090307253,"asks":[],"bids":[["64799.85","0"],["64729.86","6.171695"]],"lastId":7649224171,"id":7649224173,"ts":1784090307275}],"action":"update"}
{"channel":"book_lv2","data":[{"symbol":"BTC_USDT","createTime":1784090307253,"asks":[["64857.04","0"],["64874.53","0.160029"]],"bids":[],"lastId":7649224173,"id":7649224174,"ts":1784090307276}],"action":"update"}
{"channel":"book_lv2","data":[{"symbol":"BTC_USDT","createTime":1784090307254,"asks":[],"bids":[["64746.62","0.204203"]],"lastId":7649224174,"id":7649224175,"ts":1784090307278}],"action":"update"}
{"channel":"book_lv2","data":[{"symbol":"BTC_USDT","createTime":1784090307254,"asks":[["64864.04","0.180398"]],"bids":[],"lastId":7649224175,"id":7649224176,"ts":1784090307279}],"action":"update"}
{"channel":"book_lv2","data":[{"symbol":"BTC_USDT","createTime":1784090307254,"asks":[["64873.76","0.154335"]],"bids":[],"lastId":7649224176,"id":7649224177,"ts":1784090307280}],"action":"update"}
{"channel":"book_lv2","data":[{"symbol":"BTC_USDT","createTime":1784090307254,"asks":[["64866.76","0"],["64878.4","0.002712"]],"bids":[],"lastId":7649224177,"id":7649224178,"ts":1784090307281}],"action":"update"}
{"channel":"book_lv2","data":[{"symbol":"BTC_USDT","createTime":1784090307254,"asks":[],"bids":[["64790.13","0"],["64727.52","0.172614"]],"lastId":7649224178,"id":7649224179,"ts":1784090307283}],"action":"update"}
{"channel":"book_lv2","data":[{"symbol":"BTC_USDT","createTime":1784090307254,"asks":[],"bids":[["64729.86","0"],["64727.22","0.060511"]],"lastId":7649224179,"id":7649224180,"ts":1784090307284}],"action":"update"}
{"channel":"book_lv2","data":[{"symbol":"BTC_USDT","createTime":1784090307254,"asks":[["64874.53","0"],["64879.72","0.130934"]],"bids":[],"lastId":7649224180,"id":7649224181,"ts":1784090307285}],"action":"update"}
{"channel":"book_lv2","data":[{"symbol":"BTC_USDT","createTime":1784090307254,"asks":[],"bids":[["64739.58","0"],["64724.28","10.340061"]],"lastId":7649224181,"id":7649224182,"ts":1784090307286}],"action":"update"}
{"channel":"book_lv2","data":[{"symbol":"BTC_USDT","createTime":1784090307256,"asks":[],"bids":[["64738.84","0.159998"],["64724.28","0"]],"lastId":7649224182,"id":7649224183,"ts":1784090307287}],"action":"update"}
{"channel":"book_lv2","data":[{"symbol":"BTC_USDT","createTime":1784090307258,"asks":[["64838.88","0.100415"],["64879.72","0"]],"bids":[],"lastId":7649224183,"id":7649224185,"ts":1784090307290}],"action":"update"}
{"channel":"book_lv2","data":[{"symbol":"BTC_USDT","createTime":1784090307274,"asks":[],"bids":[["64736.9","6.171695"],["64727.22","0"]],"lastId":7649224185,"id":7649224187,"ts":1784090307294}],"action":"update"}
{"channel":"book_lv2","data":[{"symbol":"BTC_USDT","createTime":1784090307275,"asks":[["64838.88","0"],["64879.72","0.130934"]],"bids":[],"lastId":7649224187,"id":7649224191,"ts":1784090307299}],"action":"update"}
{"channel":"book_lv2","data":[{"symbol":"BTC_USDT","createTime":1784090307286,"asks":[["64855.93","0.029309"],["64879.72","0"]],"bids":[],"lastId":7649224191,"id":7649224193,"ts":1784090307306}],"action":"update"}
{"channel":"book_lv2","data":[{"symbol":"BTC_USDT","createTime":1784090307288,"asks":[["64852.69","0.029309"],["64878.4","0"]],"bids":[],"lastId":7649224193,"id":7649224196,"ts":1784090307310}],"action":"update"}
{"channel":"book_lv2","data":[{"symbol":"BTC_USDT","createTime":1784090307292,"asks":[["64849.45","0.02931"],["64873.76","0"]],"bids":[],"lastId":7649224196,"id":7649224198,"ts":1784090307312}],"action":"update"}
{"channel":"book_lv2","data":[{"symbol":"BTC_USDT","createTime":1784090307292,"asks":[],"bids":[["64732.05","0.02931"],["64727.52","0"]],"lastId":7649224198,"id":7649224199,"ts":1784090307313}],"action":"update"}
{"channel":"book_lv2","data":[{"symbol":"BTC_USDT","createTime":1784090307293,"asks":[["64846.21","0.029305"],["64873.24","0"]],"bids":[],"lastId":7649224199,"id":7649224200,"ts":1784090307315}],"action":"update"}
{"channel":"book_lv2","data":[{"symbol":"BTC_USDT","createTime":1784090307341,"asks":[],"bids":[["64808.78","0"],["64728.81","0.029313"]],"lastId":7649224200,"id":7649224203,"ts":1784090307357}],"action":"update"}
{"channel":"book_lv2","data":[{"symbol":"BTC_USDT","createTime":1784090307349,"asks":[["64838.88","0.100415"],["64872.14","0"]],"bids":[],"lastId":7649224203,"id":7649224204,"ts":1784090307362}],"action":"update"}
{"channel":"book_lv2","data":[{"symbol":"BTC_USDT","createTime":1784090307354,"asks":[["64848.8","0.030025"],["64870.52","0"]],"bids":[],"lastId":7649224204,"id":7649224208,"ts":1784090307375}],"action":"update"}
{"channel":"book_lv2","data":[{"symbol":"BTC_USDT","createTime":1784090307354,"asks":[],"bids":[["64734","0.080076"]],"lastId":7649224208,"id":7649224209,"ts":1784090307376}],"action":"update"}
{"channel":"book_lv2","data":[{"symbol":"BTC_USDT","createTime":1784090307354,"asks":[],"bids":[["64730.76","0.148705"]],"lastId":7649224209,"id":7649224210,"ts":1784090307378}],"action":"update"}
{"channel":"book_lv2","data":[{"symbol":"BTC_USDT","createTime":1784090307357,"asks":[["64858.52","7.716401"],["64864.04","0"]],"bids":[],"lastId":7649224210,"id":7649224211,"ts":1784090307379}],"action":"update"}
{"channel":"book_lv2","data":[{"symbol":"BTC_USDT","createTime":1784090307357,"asks":[["64852.04","0.05576"],["64860.47","0"]],"bids":[],"lastId":7649224211,"id":7649224213,"ts":1784090307382}],"action":"update"}
{"channel":"book_lv2","data":[{"symbol":"BTC_USDT","createTime":1784090307357,"asks":[["64855.28","0.10355"],["64858.52","0"]],"bids":[],"lastId":7649224213,"id":7649224214,"ts":1784090307383}],"action":"update"}
{"channel":"book_lv2","data":[{"symbol":"BTC_USDT","createTime":1784090307364,"asks":[["64838.88","0"],["64858.52","7.716401"]],"bids":[],"lastId":7649224214,"id":7649224216,"ts":1784090307386}],"action":"update"}
{"channel":"book_lv2","data":[{"symbol":"BTC_USDT","createTime":1784090307441,"asks":[],"bids":[["64805.54","0"],["64727.52","0.276167"]],"lastId":7649224216,"id":7649224217,"ts":1784090307457}],"action":"update"}
{"channel":"book_lv2","data":[{"symbol":"BTC_USDT","createTime":1784090307472,"asks":[["64838.88","0.100415"],["64858.52","0"]],"bids":[],"lastId":7649224217,"id":7649224218,"ts":1784090307489}],"action":"update"}
{"channel":"book_lv2","data":[{"symbol":"BTC_USDT","createTime":1784090307488,"asks":[],"bids":[["64794.4","0.353836"],["64727.52","0"]],"lastId":7649224218,"id":7649224220,"ts":1784090307498}],"action":"update"}
{"channel":"book_lv2","data":[{"symbol":"BTC_USDT","createTime":1784090307489,"asks":[],"bids":[["64733.15","0"],["64727.52","0.276167"]],"lastId":7649224220,"id":7649224222,"ts":1784090307503}],"action":"update"}
{"channel":"book_lv2","data":[{"symbol":"BTC_USDT","createTime":1784090307489,"asks":[],"bids":[["64729.91","0"],["64727.22","0.060511"]],"lastId":7649224222,"id":7649224223,"ts":1784090307505}],"action":"update"}
{"channel":"book_lv2","data":[{"symbol":"BTC_USDT","createTime":1784090307490,"asks":[],"bids":[["64731.85","0"],["64725.58","0.029307"]],"lastId":7649224223,"id":7649224225,"ts":1784090307507}],"action":"update"}
{"channel":"book_lv2","data":[{"symbol":"BTC_USDT","createTime":1784090307490,"asks":[],"bids":[["64784.65","0.182817"],["64725.58","0"]],"lastId":7649224225,"id":7649224228,"ts":1784090307511}],"action":"update"}
{"channel":"book_lv2","data":[{"symbol":"BTC_USDT","createTime":1784090307491,"asks":[],"bids":[["64739.63","0"],["64725.58","0.029307"]],"lastId":7649224228,"id":7649224229,"ts":1784090307512}],"action":"update"}
{"channel":"book_lv2","data":[{"symbol":"BTC_USDT","createTime":1784090307498,"asks":[["64838.88","0"],["64858.52","7.716401"]],"bids":[],"lastId":7649224229,"id":7649224232,"ts":1784090307516}],"action":"update"}
{"channel":"book_lv2","data":[{"symbol":"BTC_USDT","createTime":1784090307498,"asks":[],"bids":[["64727.22","0"],["64724.28","18.056462"]],"lastId":7649224232,"id":7649224233,"ts":1784090307517}],"action":"update"}
{"channel":"book_lv2","data":[{"symbol":"BTC_USDT","createTime":1784090307498,"asks":[["64843.97","0"],["64860.47","7.716305"]],"bids":[],"lastId":7649224233,"id":7649224234,"ts":1784090307518}],"action":"update"}
{"channel":"book_lv2","data":[{"symbol":"BTC_USDT","createTime":1784090307498,"asks":[["64847.2","0"],["64864.04","0.180398"]],"bids":[],"lastId":7649224234,"id":7649224235,"ts":1784090307519}],"action":"update"}
{"channel":"book_lv2","data":[{"symbol":"BTC_USDT","createTime":1784090307498,"asks":[["64850.44","0"],["64865.66","0.148619"]],"bids":[],"lastId":7649224235,"id":7649224236,"ts":1784090307521}],"action":"update"}
{"channel":"book_lv2","data":[{"symbol":"BTC_USDT","createTime":1784090307499,"asks":[],"bids":[["64730.46","0"],["64723.98","2.648020"]],"lastId":7649224236,"id":7649224237,"ts":1784090307522}],"action":"update"}
{"channel":"book_lv2","data":[{"symbol":"BTC_USDT","createTime":1784090307501,"asks":[],"bids":[["64723.98","0"],["64722.34","0.029312"]],"lastId":7649224237,"id":7649224238,"ts":1784090307523}],"action":"update"}
{"channel":"book_lv2","data":[{"symbol":"BTC_USDT","createTime":1784090307501,"asks":[["64853.68","0"],["64870.52","0.073294"]],"bids":[],"lastId":7649224238,"id":7649224239,"ts":1784090307524}],"action":"update"}
{"channel":"book_lv2","data":[{"symbol":"BTC_USDT","createTime":1784090307502,"asks":[],"bids":[["64733.7","0"],["64704.5","5.554955"]],"lastId":7649224239,"id":7649224241,"ts":1784090307527}],"action":"update"}
{"channel":"book_lv2","data":[{"symbol":"BTC_USDT","createTime":1784090307509,"asks":[["64859.17","0.231442"],["64870.52","0"]],"bids":[],"lastId":7649224241,"id":7649224244,"ts":1784090307535}],"action":"update"}
{"channel":"book_lv2","data":[{"symbol":"BTC_USDT","createTime":1784090307523,"asks":[],"bids":[["64794.4","0"],["64697.51","5.555555"]],"lastId":7649224244,"id":7649224246,"ts":1784090307539}],"action":"update"}
{"channel":"book_lv2","data":[{"symbol":"BTC_USDT","createTime":1784090307529,"asks":[],"bids":[["64795.81","0.225137"],["64697.51","0"]],"lastId":7649224246,"id":7649224249,"ts":1784090307542}],"action":"update"}
{"channel":"book_lv2","data":[{"symbol":"BTC_USDT","createTime":1784090307533,"asks":[["64864.04","0.287505"]],"bids":[],"lastId":7649224249,"id":7649224251,"ts":1784090307545}],"action":"update"}
{"channel":"book_lv2","data":[{"symbol":"BTC_USDT","createTime":1784090307533,"asks":[],"bids":[["64754.97","0.107109"],["64704.5","0"]],"lastId":7649224251,"id":7649224252,"ts":1784090307546}],"action":"update"}
{"channel":"book_lv2","data":[{"symbol":"BTC_USDT","createTime":1784090307533,"asks":[],"bids":[["64805.53","0.219862"],["64722.34","0"]],"lastId":7649224252,"id":7649224253,"ts":1784090307547}],"action":"update"}
{"channel":"book_lv2","data":[{"symbol":"BTC_USDT","createTime":1784090307546,"asks":[],"bids":[["64745.25","0.130907"],["64724.28","0"]],"lastId":7649224253,"id":7649224255,"ts":1784090307556}],"action":"update"}
{"channel":"book_lv2","data":[{"symbol":"BTC_USDT","createTime":1784090307548,"asks":[],"bids":[["64737.47","0.159998"],["64725.58","0"]],"lastId":7649224255,"id":7649224256,"ts":1784090307559}],"action":"update"}
{"channel":"book_lv2","data":[{"symbol":"BTC_USDT","createTime":1784090307549,"asks":[],"bids":[["64735.53","6.171695"],["64727.52","0"]],"lastId":7649224256,"id":7649224257,"ts":1784090307561}],"action":"update"}
{"channel":"book_lv2","data":[{"symbol":"BTC_USDT","createTime":1784090307568,"asks":[["64838.88","0.100415"],["64865.66","0"]],"bids":[],"lastId":7649224257,"id":7649224259,"ts":1784090307577}],"action":"update"}
{"channel":"book_lv2","data":[{"symbol":"BTC_USDT","createTime":1784090307581,"asks":[["64838.88","0"],["64865.66","0.148619"]],"bids":[],"lastId":7649224259,"id":7649224260,"ts":1784090307591}],"action":"update"}
{"channel":"book_lv2","data":[{"symbol":"BTC_USDT","createTime":1784090307583,"asks":[],"bids":[["64807.65","0.000062"],["64728.81","0"]],"lastId":7649224260,"id":7649224261,"ts":1784090307600}],"action":"update"}
{"channel":"book_lv2","data":[{"symbol":"BTC_USDT","createTime":1784090307586,"asks":[],"bids":[["64804.41","0.000062"],["64730.76","0"]],"lastId":7649224261,"id":7649224262,"ts":1784090307601}],"action":"update"}
{"channel":"book_lv2","data":[{"symbol":"BTC_USDT","createTime":1784090307586,"asks":[["64812.49","0.000062"],["64865.66","0"]],"bids":[],"lastId":7649224262,"id":7649224263,"ts":1784090307603}],"action":"update"}
{"channel":"book_lv2","data":[{"symbol":"BTC_USDT","createTime":1784090307586,"asks":[["64809.25","0.000062"],["64864.04","0"]],"bids":[],"lastId":7649224263,"id":7649224264,"ts":1784090307604}],"action":"update"}
{"channel":"book_lv2","data":[{"symbol":"BTC_USDT","createTime":1784090307646,"asks":[["64838.88","0.100415"],["64860.47","0"]],"bids":[],"lastId":7649224264,"id":7649224265,"ts":1784090307664}],"action":"update"}
{"channel":"book_lv2","data":[{"symbol":"BTC_USDT","createTime":1784090307649,"asks":[["64809.25","0"],["64860.47","7.716305"]],"bids":[],"lastId":7649224265,"id":7649224266,"ts":1784090307665}],"action":"update"}
{"channel":"book_lv2","data":[{"symbol":"BTC_USDT","createTime":1784090307660,"asks":[["64838.88","0"],["64864.04","0.287505"]],"bids":[],"lastId":7649224266,"id":7649224267,"ts":1784090307676}],"action":"update"}
{"channel":"book_lv2","data":[{"symbol":"BTC_USDT","createTime":1784090307724,"asks":[["64838.88","0.100415"],["64864.04","0"]],"bids":[],"lastId":7649224267,"id":7649224271,"ts":1784090307741}],"action":"update"}
{"channel":"book_lv2","data":[{"symbol":"BTC_USDT","createTime":1784090307741,"asks":[["64838.88","0"],["64864.04","0.287505"]],"bids":[],"lastId":7649224271,"id":7649224272,"ts":1784090307755}],"action":"update"}
{"channel":"book_lv2","data":[{"symbol":"BTC_USDT","createTime":1784090307753,"asks":[],"bids":[["64784.65","0"],["64730.76","0.148705"]],"lastId":7649224272,"id":7649224273,"ts":1784090307768}],"action":"update"}
{"channel":"book_lv2","data":[{"symbol":"BTC_USDT","createTime":1784090307754,"asks":[["64859.17","0"],["64870.52","0.073294"]],"bids":[],"lastId":7649224273,"id":7649224278,"ts":1784090307777}],"action":"update"}
{"channel":"book_lv2","data":[{"symbol":"BTC_USDT","createTime":1784090307767,"asks":[],"bids":[["64740.14","0.130908"],["64730.76","0"]],"lastId":7649224278,"id":7649224281,"ts":1784090307782}],"action":"update"}
{"channel":"book_lv2","data":[{"symbol":"BTC_USDT","createTime":1784090307768,"asks":[],"bids":[["64738.85","0.16"],["64732.05","0"]],"lastId":7649224281,"id":7649224283,"ts":1784090307785}],"action":"update"}
{"channel":"book_lv2","data":[{"symbol":"BTC_USDT","createTime":1784090307769,"asks":[["64853.98","0.492023"],["64870.52","0"]],"bids":[],"lastId":7649224283,"id":7649224284,"ts":1784090307786}],"action":"update"}
{"channel":"book_lv2","data":[{"symbol":"BTC_USDT","createTime":1784090307771,"asks":[],"bids":[["64746.62","0.311309"]],"lastId":7649224284,"id":7649224285,"ts":1784090307788}],"action":"update"}
{"channel":"book_lv2","data":[{"symbol":"BTC_USDT","createTime":1784090307771,"asks":[["64850.74","0.005954"],["64864.04","0"]],"bids":[],"lastId":7649224285,"id":7649224288,"ts":1784090307792}],"action":"update"}
{"channel":"book_lv2","data":[{"symbol":"BTC_USDT","createTime":1784090307775,"asks":[],"bids":[["64734","0.100094"]],"lastId":7649224288,"id":7649224291,"ts":1784090307796}],"action":"update"}
{"channel":"book_lv2","data":[{"symbol":"BTC_USDT","createTime":1784090307778,"asks":[["64847.5","0.003855"],["64860.47","0"]],"bids":[],"lastId":7649224291,"id":7649224292,"ts":1784090307797}],"action":"update"}
{"channel":"book_lv2","data":[{"symbol":"BTC_USDT","createTime":1784090307778,"asks":[["64844.27","0.003855"],["64858.52","0"]],"bids":[],"lastId":7649224292,"id":7649224293,"ts":1784090307798}],"action":"update"}
{"channel":"book_lv2","data":[{"symbol":"BTC_USDT","createTime":1784090307786,"asks":[],"bids":[["64736.9","8.813475"]],"lastId":7649224293,"id":7649224295,"ts":1784090307801}],"action":"update"}
{"channel":"book_lv2","data":[{"symbol":"BTC_USDT","createTime":1784090307801,"asks":[["64838.88","0.100415"],["64857.87","0"]],"bids":[],"lastId":7649224295,"id":7649224297,"ts":1784090307810}],"action":"update"}
{"channel":"book_lv2","data":[{"symbol":"BTC_USDT","createTime":1784090307817,"asks":[["64838.88","0"],["64857.87","0.489139"]],"bids":[],"lastId":7649224297,"id":7649224298,"ts":1784090307834}],"action":"update"}
{"channel":"book_lv2","data":[{"symbol":"BTC_USDT","createTime":1784090307844,"asks":[],"bids":[["64784.62","0.186654"],["64734","0"]],"lastId":7649224298,"id":7649224300,"ts":1784090307856}],"action":"update"}
{"channel":"book_lv2","data":[{"symbol":"BTC_USDT","createTime":1784090307846,"asks":[],"bids":[["64794.38","0.347639"],["64735.53","0"]],"lastId":7649224300,"id":7649224301,"ts":1784090307858}],"action":"update"}
{"channel":"book_lv2","data":[{"symbol":"BTC_USDT","createTime":1784090307885,"asks":[["64838.88","0.100415"],["64857.87","0"]],"bids":[],"lastId":7649224301,"id":7649224311,"ts":1784090307898}],"action":"update"}
{"channel":"book_lv2","data":[{"symbol":"BTC_USDT","createTime":1784090307901,"asks":[["64838.88","0"],["64857.87","0.489139"]],"bids":[],"lastId":7649224311,"id":7649224312,"ts":1784090307911}],"action":"update"}
{"channel":"book_lv2","data":[{"symbol":"BTC_USDT","createTime":1784090307941,"asks":[],"bids":[["64794.37","0.410511"],["64736.9","0"]],"lastId":7649224312,"id":7649224313,"ts":1784090307953}],"action":"update"}
{"channel":"book_lv2","data":[{"symbol":"BTC_USDT","createTime":1784090307945,"asks":[],"bids":[["64784.64","0.194165"],["64737.47","0"]],"lastId":7649224313,"id":7649224317,"ts":1784090307963}],"action":"update"}
{"channel":"book_lv2","data":[{"symbol":"BTC_USDT","createTime":1784090307969,"asks":[["64838.88","0.100415"],["64857.87","0"]],"bids":[],"lastId":7649224317,"id":7649224323,"ts":1784090307981}],"action":"update"}
{"channel":"book_lv2","data":[{"symbol":"BTC_USDT","createTime":1784090307983,"asks":[["64838.88","0"],["64857.87","0.489139"]],"bids":[],"lastId":7649224323,"id":7649224325,"ts":1784090307994}],"action":"update"}
{"channel":"book_lv2","data":[{"symbol":"BTC_USDT","createTime":1784090308011,"asks":[["64850.75","0"],["64858.52","7.716401"]],"bids":[],"lastId":7649224325,"id":7649224327,"ts":1784090308029}],"action":"update"}
{"channel":"book_lv2","data":[{"symbol":"BTC_USDT","createTime":1784090308011,"asks":[["64857.23","0"],["64859.17","0.462896"]],"bids":[],"lastId":7649224327,"id":7649224329,"ts":1784090308032}],"action":"update"}
{"channel":"book_lv2","data":[{"symbol":"BTC_USDT","createTime":1784090308014,"asks":[["64853.99","0"],["64864.04","0.287505"]],"bids":[],"lastId":7649224329,"id":7649224332,"ts":1784090308035}],"action":"update"}
{"channel":"book_lv2","data":[{"symbol":"BTC_USDT","createTime":1784090308023,"asks":[],"bids":[["64784.64","0"],["64737.47","0.159998"]],"lastId":7649224332,"id":7649224334,"ts":1784090308041}],"action":"update"}
{"channel":"book_lv2","data":[{"symbol":"BTC_USDT","createTime":1784090308024,"asks":[],"bids":[["64784.62","0"],["64736.9","8.813475"]],"lastId":7649224334,"id":7649224335,"ts":1784090308042}],"action":"update"}
{"channel":"book_lv2","data":[{"symbol":"BTC_USDT","createTime":1784090308024,"asks":[],"bids":[["64794.38","0"],["64735.53","6.171695"]],"lastId":7649224335,"id":7649224336,"ts":1784090308043}],"action":"update"}
{"channel":"book_lv2","data":[{"symbol":"BTC_USDT","createTime":1784090308024,"asks":[],"bids":[["64794.37","0"],["64734","0.070064"]],"lastId":7649224336,"id":7649224337,"ts":1784090308044}],"action":"update"}
{"channel":"book_lv2","data":[{"symbol":"BTC_USDT","createTime":1784090308036,"asks":[],"bids":[["64802.93","0.000868"],["64734","0"]],"lastId":7649224337,"id":7649224338,"ts":1784090308053}],"action":"update"}
{"channel":"book_lv2","data":[{"symbol":"BTC_USDT","createTime":1784090308036,"asks":[],"bids":[["64803.13","0.00107"],["64735.53","0"]],"lastId":7649224338,"id":7649224339,"ts":1784090308054}],"action":"update"}
{"channel":"book_lv2","data":[{"symbol":"BTC_USDT","createTime":1784090308041,"asks":[["64812.49","0"],["64865.66","0.303720"]],"bids":[],"lastId":7649224339,"id":7649224340,"ts":1784090308056}],"action":"update"}
{"channel":"book_lv2","data":[{"symbol":"BTC_USDT","createTime":1784090308041,"asks":[],"bids":[["64802.73","0.000638"],["64736.9","0"]],"lastId":7649224340,"id":7649224341,"ts":1784090308057}],"action":"update"}
{"channel":"book_lv2","data":[{"symbol":"BTC_USDT","createTime":1784090308041,"asks":[],"bids":[["64803.33","0.000323"],["64737.47","0"]],"lastId":7649224341,"id":7649224342,"ts":1784090308058}],"action":"update"}
{"channel":"book_lv2","data":[{"symbol":"BTC_USDT","createTime":1784090308041,"asks":[],"bids":[["64802.53","0.000469"],["64738.84","0"]],"lastId":7649224342,"id":7649224343,"ts":1784090308060}],"action":"update"}
{"channel":"book_lv2","data":[{"symbol":"BTC_USDT","createTime":1784090308045,"asks":[["64838.88","0.100415"],["64865.66","0"]],"bids":[],"lastId":7649224343,"id":7649224344,"ts":1784090308061}],"action":"update"}
{"channel":"book_lv2","data":[{"symbol":"BTC_USDT","createTime":1784090308055,"asks":[["64859.17","0.231445"]],"bids":[],"lastId":7649224344,"id":7649224357,"ts":1784090308082}],"action":"update"}
{"channel":"book_lv2","data":[{"symbol":"BTC_USDT","createTime":1784090308057,"asks":[["64859.17","0"],["64870.52","0.073294"]],"bids":[],"lastId":7649224357,"id":7649224361,"ts":1784090308088}],"action":"update"}
{"channel":"book_lv2","data":[{"symbol":"BTC_USDT","createTime":1784090308058,"asks":[["64838.88","0"],["64873.76","0.285242"]],"bids":[],"lastId":7649224361,"id":7649224364,"ts":1784090308091}],"action":"update"}
{"channel":"book_lv2","data":[{"symbol":"BTC_USDT","createTime":1784090308059,"asks":[],"bids":[["64802.13","0.000253"],["64738.85","0"]],"lastId":7649224364,"id":7649224365,"ts":1784090308093}],"action":"update"}
{"channel":"book_lv2","data":[{"symbol":"BTC_USDT","createTime":1784090308063,"asks":[],"bids":[["64801.93","0.000186"],["64740.14","0"]],"lastId":7649224365,"id":7649224366,"ts":1784090308094}],"action":"update"}
{"channel":"book_lv2","data":[{"symbol":"BTC_USDT","createTime":1784090308065,"asks":[],"bids":[["64802.33","0.000344"],["64743.38","0"]],"lastId":7649224366,"id":7649224367,"ts":1784090308095}],"action":"update"}
{"channel":"book_lv2","data":[{"symbol":"BTC_USDT","createTime":1784090308126,"asks":[["64838.88","0.100415"],["64873.76","0"]],"bids":[],"lastId":7649224367,"id":7649224368,"ts":1784090308146}],"action":"update"}
{"channel":"book_lv2","data":[{"symbol":"BTC_USDT","createTime":1784090308141,"asks":[["64838.88","0"],["64873.76","0.285242"]],"bids":[],"lastId":7649224368,"id":7649224369,"ts":1784090308156}],"action":"update"}
{"channel":"book_lv2","data":[{"symbol":"BTC_USDT","createTime":1784090308152,"asks":[],"bids":[["64804.41","0"],["64743.38","0.042431"]],"lastId":7649224369,"id":7649224370,"ts":1784090308170}],"action":"update"}
{"channel":"book_lv2","data":[{"symbol":"BTC_USDT","createTime":1784090308152,"asks":[],"bids":[["64784.65","0.175964"],["64743.38","0"]],"lastId":7649224370,"id":7649224373,"ts":1784090308174}],"action":"update"}
{"channel":"book_lv2","data":[{"symbol":"BTC_USDT","createTime":1784090308154,"asks":[["64865.66","0.157014"],["64873.76","0"]],"bids":[],"lastId":7649224373,"id":7649224374,"ts":1784090308175}],"action":"update"}
{"channel":"book_lv2","data":[{"symbol":"BTC_USDT","createTime":1784090308154,"asks":[],"bids":[["64794.34","0.380456"],["64745.25","0"]],"lastId":7649224374,"id":7649224375,"ts":1784090308176}],"action":"update"}
{"channel":"book_lv2","data":[{"symbol":"BTC_USDT","createTime":1784090308173,"asks":[["64859.17","0.231445"],["64870.52","0"]],"bids":[],"lastId":7649224375,"id":7649224380,"ts":1784090308188}],"action":"update"}
{"channel":"book_lv2","data":[{"symbol":"BTC_USDT","createTime":1784090308206,"asks":[["64838.88","0.100415"],["64865.66","0"]],"bids":[],"lastId":7649224380,"id":7649224383,"ts":1784090308220}],"action":"update"}
{"channel":"book_lv2","data":[{"symbol":"BTC_USDT","createTime":1784090308221,"asks":[["64838.88","0"],["64865.66","0.157014"]],"bids":[],"lastId":7649224383,"id":7649224384,"ts":1784090308234}],"action":"update"}
{"channel":"book_lv2","data":[{"symbol":"BTC_USDT","createTime":1784090308224,"asks":[],"bids":[["64794.34","0"],["64745.25","0.130907"]],"lastId":7649224384,"id":7649224385,"ts":1784090308244}],"action":"update"}
{"channel":"book_lv2","data":[{"symbol":"BTC_USDT","createTime":1784090308283,"asks":[["64860.47","7.716305"],["64865.66","0"]],"bids":[],"lastId":7649224385,"id":7649224390,"ts":1784090308301}],"action":"update"}
{"channel":"book_lv2","data":[{"symbol":"BTC_USDT","createTime":1784090308285,"asks":[["64857.23","0.103553"],["64864.04","0"]],"bids":[],"lastId":7649224390,"id":7649224392,"ts":1784090308304}],"action":"update"}
{"channel":"book_lv2","data":[{"symbol":"BTC_USDT","createTime":1784090308285,"asks":[["64850.75","0.030024"],["64860.47","0"]],"bids":[],"lastId":7649224392,"id":7649224393,"ts":1784090308305}],"action":"update"}
{"channel":"book_lv2","data":[{"symbol":"BTC_USDT","createTime":1784090308287,"asks":[["64853.99","0.055757"],["64859.17","0"]],"bids":[],"lastId":7649224393,"id":7649224395,"ts":1784090308307}],"action":"update"}
{"channel":"book_lv2","data":[{"symbol":"BTC_USDT","createTime":1784090308331,"asks":[["64838.88","0.100415"],["64858.52","0"]],"bids":[],"lastId":7649224395,"id":7649224397,"ts":1784090308348}],"action":"update"}
{"channel":"book_lv2","data":[{"symbol":"BTC_USDT","createTime":1784090308358,"asks":[["64838.88","0"],["64858.52","7.716401"]],"bids":[],"lastId":7649224397,"id":7649224405,"ts":1784090308382}],"action":"update"}
{"channel":"book_lv2","data":[{"symbol":"BTC_USDT","createTime":1784090308424,"asks":[["64838.88","0.100415"],["64858.52","0"]],"bids":[],"lastId":7649224405,"id":7649224406,"ts":1784090308435}],"action":"update"}
{"channel":"book_lv2","data":[{"symbol":"BTC_USDT","createTime":1784090308440,"asks":[["64838.88","0"],["64858.52","7.716401"]],"bids":[],"lastId":7649224406,"id":7649224407,"ts":1784090308461}],"action":"update"}
{"channel":"book_lv2","data":[{"symbol":"BTC_USDT","createTime":1784090308448,"asks":[],"bids":[["64784.67","0.204977"],["64745.25","0"]],"lastId":7649224407,"id":7649224408,"ts":1784090308462}],"action":"update"}
{"channel":"book_lv2","data":[{"symbol":"BTC_USDT","createTime":1784090308449,"asks":[],"bids":[["64784.65","0"],["64745.25","0.130907"]],"lastId":7649224408,"id":7649224409,"ts":1784090308463}],"action":"update"}
{"channel":"book_lv2","data":[{"symbol":"BTC_USDT","createTime":1784090308449,"asks":[],"bids":[["64784.67","0"],["64743.38","0.042431"]],"lastId":7649224409,"id":7649224410,"ts":1784090308465}],"action":"update"}
{"channel":"book_lv2","data":[{"symbol":"BTC_USDT","createTime":1784090308495,"asks":[],"bids":[["64746.62","0.238016"]],"lastId":7649224410,"id":7649224422,"ts":1784090308509}],"action":"update"}
{"channel":"book_lv2","data":[{"symbol":"BTC_USDT","createTime":1784090308495,"asks":[],"bids":[["64756.34","0.107106"]],"lastId":7649224422,"id":7649224424,"ts":1784090308512}],"action":"update"}
{"channel":"book_lv2","data":[{"symbol":"BTC_USDT","createTime":1784090308495,"asks":[],"bids":[["64749.86","0"],["64740.14","0.130908"]],"lastId":7649224424,"id":7649224425,"ts":1784090308513}],"action":"update"}
{"channel":"book_lv2","data":[{"symbol":"BTC_USDT","createTime":1784090308497,"asks":[],"bids":[["64743.38","0"],["64738.85","0.16"]],"lastId":7649224425,"id":7649224426,"ts":1784090308514}],"action":"update"}
{"channel":"book_lv2","data":[{"symbol":"BTC_USDT","createTime":1784090308521,"asks":[["64838.88","0.100415"],["64858.52","0"]],"bids":[],"lastId":7649224426,"id":7649224428,"ts":1784090308530}],"action":"update"}
{"channel":"book_lv2","data":[{"symbol":"BTC_USDT","createTime":1784090308537,"asks":[["64838.88","0"],["64858.52","7.716401"]],"bids":[],"lastId":7649224428,"id":7649224429,"ts":1784090308551}],"action":"update"}
{"channel":"book_lv2","data":[{"symbol":"BTC_USDT","createTime":1784090308580,"asks":[["64818.74","0.000062"],["64858.52","0"]],"bids":[],"lastId":7649224429,"id":7649224430,"ts":1784090308601}],"action":"update"}
{"channel":"book_lv2","data":[{"symbol":"BTC_USDT","createTime":1784090308580,"asks":[],"bids":[["64813.9","0.000062"],["64738.85","0"]],"lastId":7649224430,"id":7649224431,"ts":1784090308603}],"action":"update"}
{"channel":"book_lv2","data":[{"symbol":"BTC_USDT","createTime":1784090308582,"asks":[["64821.98","0.000062"],["64857.87","0"]],"bids":[],"lastId":7649224431,"id":7649224432,"ts":1784090308604}],"action":"update"}
{"channel":"book_lv2","data":[{"symbol":"BTC_USDT","createTime":1784090308614,"asks":[["64838.88","0.100415"],["64857.23","0"]],"bids":[],"lastId":7649224432,"id":7649224433,"ts":1784090308640}],"action":"update"}
{"channel":"book_lv2","data":[{"symbol":"BTC_USDT","createTime":1784090308627,"asks":[["64838.88","0"],["64857.23","0.103553"]],"bids":[],"lastId":7649224433,"id":7649224434,"ts":1784090308647}],"action":"update"}
{"channel":"book_lv2","data":[{"symbol":"BTC_USDT","createTime":1784090308651,"asks":[["64818.74","0"],["64857.87","0.489139"]],"bids":[],"lastId":7649224434,"id":7649224435,"ts":1784090308666}],"action":"update"}
{"channel":"book_lv2","data":[{"symbol":"BTC_USDT","createTime":1784090308691,"asks":[["64838.88","0.100415"],["64857.87","0"]],"bids":[],"lastId":7649224435,"id":7649224441,"ts":1784090308714}],"action":"update"}
{"channel":"book_lv2","data":[{"symbol":"BTC_USDT","createTime":1784090308693,"asks":[],"bids":[["64765.58","0"],["64738.85","0.16"]],"lastId":7649224441,"id":7649224446,"ts":1784090308720}],"action":"update"}
{"channel":"book_lv2","data":[{"symbol":"BTC_USDT","createTime":1784090308707,"asks":[["64851.39","0"],["64857.87","0.489139"]],"bids":[],"lastId":7649224446,"id":7649224448,"ts":1784090308725}],"action":"update"}
{"channel":"book_lv2","data":[{"symbol":"BTC_USDT","createTime":1784090308707,"asks":[["64848.15","0"],["64858.52","7.716401"]],"bids":[],"lastId":7649224448,"id":7649224449,"ts":1784090308726}],"action":"update"}
{"channel":"book_lv2","data":[{"symbol":"BTC_USDT","createTime":1784090308709,"asks":[["64854.63","0"],["64860.47","7.716305"]],"bids":[],"lastId":7649224449,"id":7649224453,"ts":1784090308731}],"action":"update"}
{"channel":"book_lv2","data":[{"symbol":"BTC_USDT","createTime":1784090308709,"asks":[["64857.87","0"],["64864.04","0.214215"]],"bids":[],"lastId":7649224453,"id":7649224454,"ts":1784090308732}],"action":"update"}
{"channel":"book_lv2","data":[{"symbol":"BTC_USDT","createTime":1784090308767,"asks":[["64864.04","0.287499"]],"bids":[],"lastId":7649224454,"id":7649224456,"ts":1784090308783}],"action":"update"}
{"channel":"book_lv2","data":[{"symbol":"BTC_USDT","createTime":1784090308770,"asks":[],"bids":[["64749.86","0.073285"],["64738.85","0"]],"lastId":7649224456,"id":7649224458,"ts":1784090308786}],"action":"update"}
{"channel":"book_lv2","data":[{"symbol":"BTC_USDT","createTime":1784090308770,"asks":[],"bids":[["64756.34","0.180384"]],"lastId":7649224458,"id":7649224459,"ts":1784090308787}],"action":"update"}
{"channel":"book_lv2","data":[{"symbol":"BTC_USDT","createTime":1784090308770,"asks":[],"bids":[["64746.62","0.311302"]],"lastId":7649224459,"id":7649224460,"ts":1784090308788}],"action":"update"}
{"channel":"book_lv2","data":[{"symbol":"BTC_USDT","createTime":1784090308784,"asks":[],"bids":[["64743.38","0.042468"],["64740.14","0"]],"lastId":7649224460,"id":7649224462,"ts":1784090308796}],"action":"update"}
{"channel":"book_lv2","data":[{"symbol":"BTC_USDT","createTime":1784090308785,"asks":[],"bids":[["64774.96","1.262419"],["64743.38","0"]],"lastId":7649224462,"id":7649224463,"ts":1784090308798}],"action":"update"}
{"channel":"book_lv2","data":[{"symbol":"BTC_USDT","createTime":1784090308790,"asks":[],"bids":[["64784.68","0.172385"],["64745.25","0"]],"lastId":7649224463,"id":7649224465,"ts":1784090308801}],"action":"update"}
{"channel":"book_lv2","data":[{"symbol":"BTC_USDT","createTime":1784090308790,"asks":[],"bids":[["64794.39","0.40495"],["64746.62","0"]],"lastId":7649224465,"id":7649224467,"ts":1784090308804}],"action":"update"}
{"channel":"book_lv2","data":[{"symbol":"BTC_USDT","createTime":1784090308808,"asks":[["64859.17","0.231427"],["64864.04","0"]],"bids":[],"lastId":7649224467,"id":7649224472,"ts":1784090308820}],"action":"update"}
{"channel":"book_lv2","data":[{"symbol":"BTC_USDT","createTime":1784090308975,"asks":[["64848.16","0.003855"],["64860.47","0"]],"bids":[],"lastId":7649224472,"id":7649224476,"ts":1784090308985}],"action":"update"}
{"channel":"book_lv2","data":[{"symbol":"BTC_USDT","createTime":1784090308977,"asks":[["64851.4","0.003854"],["64859.17","0"]],"bids":[],"lastId":7649224476,"id":7649224478,"ts":1784090308992}],"action":"update"}
{"channel":"book_lv2","data":[{"symbol":"BTC_USDT","createTime":1784090308981,"asks":[["64857.88","0.464295"],["64858.52","0"]],"bids":[],"lastId":7649224478,"id":7649224481,"ts":1784090308996}],"action":"update"}
{"channel":"book_lv2","data":[{"symbol":"BTC_USDT","createTime":1784090308983,"asks":[["64854.64","0.005625"],["64857.88","0"]],"bids":[],"lastId":7649224481,"id":7649224482,"ts":1784090308997}],"action":"update"}
{"channel":"book_lv2","data":[{"symbol":"BTC_USDT","createTime":1784090308995,"asks":[],"bids":[["64756.34","0.073278"]],"lastId":7649224482,"id":7649224490,"ts":1784090309010}],"action":"update"}
{"channel":"book_lv2","data":[{"symbol":"BTC_USDT","createTime":1784090308998,"asks":[["64838.88","0"],["64857.88","0.464295"]],"bids":[],"lastId":7649224490,"id":7649224492,"ts":1784090309013}],"action":"update"}
{"channel":"book_lv2","data":[{"symbol":"BTC_USDT","createTime":1784090309001,"asks":[],"bids":[["64794.39","0"],["64746.62","0.180392"]],"lastId":7649224492,"id":7649224498,"ts":1784090309034}],"action":"update"}
{"channel":"book_lv2","data":[{"symbol":"BTC_USDT","createTime":1784090309001,"asks":[],"bids":[["64784.68","0"],["64745.25","0.130907"]],"lastId":7649224498,"id":7649224499,"ts":1784090309035}],"action":"update"}
{"channel":"book_lv2","data":[{"symbol":"BTC_USDT","createTime":1784090309022,"asks":[],"bids":[["64802.73","0"],["64743.38","0.042468"]],"lastId":7649224499,"id":7649224505,"ts":1784090309059}],"action":"update"}
{"channel":"book_lv2","data":[{"symbol":"BTC_USDT","createTime":1784090309022,"asks":[],"bids":[["64802.13","0"],["64740.14","0.130908"]],"lastId":7649224505,"id":7649224506,"ts":1784090309061}],"action":"update"}
{"channel":"book_lv2","data":[{"symbol":"BTC_USDT","createTime":1784090309022,"asks":[],"bids":[["64801.93","0"],["64738.85","0.16"]],"lastId":7649224506,"id":7649224507,"ts":1784090309062}],"action":"update"}
{"channel":"book_lv2","data":[{"symbol":"BTC_USDT","createTime":1784090309022,"asks":[],"bids":[["64802.33","0"],["64737.47","0.159998"]],"lastId":7649224507,"id":7649224508,"ts":1784090309063}],"action":"update"}
{"channel":"book_lv2","data":[{"symbol":"BTC_USDT","createTime":1784090309022,"asks":[],"bids":[["64803.13","0"],["64736.9","2.641780"]],"lastId":7649224508,"id":7649224509,"ts":1784090309064}],"action":"update"}
{"channel":"book_lv2","data":[{"symbol":"BTC_USDT","createTime":1784090309024,"asks":[],"bids":[["64802.93","0"],["64735.53","6.171695"]],"lastId":7649224509,"id":7649224510,"ts":1784090309066}],"action":"update"}
{"channel":"book_lv2","data":[{"symbol":"BTC_USDT","createTime":1784090309024,"asks":[],"bids":[["64803.33","0"],["64734","0.100086"]],"lastId":7649224510,"id":7649224511,"ts":1784090309067}],"action":"update"}
{"channel":"book_lv2","data":[{"symbol":"BTC_USDT","createTime":1784090309025,"asks":[],"bids":[["64802.53","0"],["64732.05","0.02931"]],"lastId":7649224511,"id":7649224512,"ts":1784090309068}],"action":"update"}
{"channel":"book_lv2","data":[{"symbol":"BTC_USDT","createTime":1784090309067,"asks":[["64838.88","0.100415"],["64857.88","0"]],"bids":[],"lastId":7649224512,"id":7649224513,"ts":1784090309077}],"action":"update"}
{"channel":"book_lv2","data":[{"symbol":"BTC_USDT","createTime":1784090309085,"asks":[["64838.88","0"],["64857.88","0.464295"]],"bids":[],"lastId":7649224513,"id":7649224514,"ts":1784090309101}],"action":"update"}
{"channel":"book_lv2","data":[{"symbol":"BTC_USDT","createTime":1784090309093,"asks":[["64849.45","0"],["64858.52","7.716401"]],"bids":[],"lastId":7649224514,"id":7649224516,"ts":1784090309108}],"action":"update"}
{"channel":"book_lv2","data":[{"symbol":"BTC_USDT","createTime":1784090309093,"asks":[["64855.93","0"],["64860.47","7.716305"]],"bids":[],"lastId":7649224516,"id":7649224518,"ts":1784090309110}],"action":"update"}
{"channel":"book_lv2","data":[{"symbol":"BTC_USDT","createTime":1784090309094,"asks":[["64846.21","0"],["64864.04","0.180391"]],"bids":[],"lastId":7649224518,"id":7649224520,"ts":1784090309112}],"action":"update"}
{"channel":"book_lv2","data":[{"symbol":"BTC_USDT","createTime":1784090309094,"asks":[],"bids":[["64732.05","0"],["64730.76","0.185862"]],"lastId":7649224520,"id":7649224521,"ts":1784090309113}],"action":"update"}
{"channel":"book_lv2","data":[{"symbol":"BTC_USDT","createTime":1784090309094,"asks":[["64852.69","0"],["64870.52","0.073286"]],"bids":[],"lastId":7649224521,"id":7649224522,"ts":1784090309115}],"action":"update"}
{"channel":"book_lv2","data":[{"symbol":"BTC_USDT","createTime":1784090309100,"asks":[],"bids":[["64784.62","0.172921"],["64730.76","0"]],"lastId":7649224522,"id":7649224524,"ts":1784090309117}],"action":"update"}
{"channel":"book_lv2","data":[{"symbol":"BTC_USDT","createTime":1784090309102,"asks":[["64865.66","0.142655"],["64870.52","0"]],"bids":[],"lastId":7649224524,"id":7649224526,"ts":1784090309120}],"action":"update"}
{"channel":"book_lv2","data":[{"symbol":"BTC_USDT","createTime":1784090309104,"asks":[],"bids":[["64794.38","0.377071"],["64734","0"]],"lastId":7649224526,"id":7649224527,"ts":1784090309121}],"action":"update"}
{"channel":"book_lv2","data":[{"symbol":"BTC_USDT","createTime":1784090309117,"asks":[["64859.17","0.231427"],["64865.66","0"]],"bids":[],"lastId":7649224527,"id":7649224528,"ts":1784090309140}],"action":"update"}
{"channel":"book_lv2","data":[{"symbol":"BTC_USDT","createTime":1784090309124,"asks":[],"bids":[["64794.38","0"],["64734","0.100086"]],"lastId":7649224528,"id":7649224533,"ts":1784090309140}],"action":"update"}
{"channel":"book_lv2","data":[{"symbol":"BTC_USDT","createTime":1784090309148,"asks":[["64838.88","0.100364"],["64864.04","0"]],"bids":[],"lastId":7649224533,"id":7649224536,"ts":1784090309158}],"action":"update"}
{"channel":"book_lv2","data":[{"symbol":"BTC_USDT","createTime":1784090309152,"asks":[],"bids":[["64813.9","0"],["64730.76","0.185862"]],"lastId":7649224536,"id":7649224537,"ts":1784090309159}],"action":"update"}
{"channel":"book_lv2","data":[{"symbol":"BTC_USDT","createTime":1784090309163,"asks":[["64838.88","0"],["64864.04","0.180391"]],"bids":[],"lastId":7649224537,"id":7649224538,"ts":1784090309178}],"action":"update"}
{"channel":"book_lv2","data":[{"symbol":"BTC_USDT","createTime":1784090309181,"asks":[["64858.52","0"],["64865.66","0.142655"]],"bids":[],"lastId":7649224538,"id":7649224540,"ts":1784090309197}],"action":"update"}
{"channel":"book_lv2","data":[{"symbol":"BTC_USDT","createTime":1784090309181,"asks":[],"bids":[["64734","0.070060"]],"lastId":7649224540,"id":7649224541,"ts":1784090309199}],"action":"update"}
{"channel":"book_lv2","data":[{"symbol":"BTC_USDT","createTime":1784090309181,"asks":[["64848.8","0"],["64870.52","0.073286"]],"bids":[],"lastId":7649224541,"id":7649224542,"ts":1784090309200}],"action":"update"}
{"channel":"book_lv2","data":[{"symbol":"BTC_USDT","createTime":1784090309181,"asks":[["64855.28","0"],["64872.14","0.231427"]],"bids":[],"lastId":7649224542,"id":7649224543,"ts":1784090309201}],"action":"update"}
{"channel":"book_lv2","data":[{"symbol":"BTC_USDT","createTime":1784090309182,"asks":[["64852.04","0"],["64873.76","0.154350"]],"bids":[],"lastId":7649224543,"id":7649224545,"ts":1784090309203}],"action":"update"}
{"channel":"book_lv2","data":[{"symbol":"BTC_USDT","createTime":1784090309182,"asks":[],"bids":[["64730.76","0.130104"]],"lastId":7649224545,"id":7649224546,"ts":1784090309205}],"action":"update"}
{"channel":"book_lv2","data":[{"symbol":"BTC_USDT","createTime":1784090309227,"asks":[["64838.88","0.100364"],["64873.76","0"]],"bids":[],"lastId":7649224546,"id":7649224553,"ts":1784090309235}],"action":"update"}
{"channel":"book_lv2","data":[{"symbol":"BTC_USDT","createTime":1784090309233,"asks":[],"bids":[["64784.62","0"],["64727.52","0.241617"]],"lastId":7649224553,"id":7649224554,"ts":1784090309248}],"action":"update"}
{"channel":"book_lv2","data":[{"symbol":"BTC_USDT","createTime":1784090309233,"asks":[["64872.14","0"],["64873.76","0.154350"]],"bids":[],"lastId":7649224554,"id":7649224556,"ts":1784090309250}],"action":"update"}
{"channel":"book_lv2","data":[{"symbol":"BTC_USDT","createTime":1784090309243,"asks":[["64838.88","0"],["64875.38","0.097834"]],"bids":[],"lastId":7649224556,"id":7649224558,"ts":1784090309261}],"action":"update"}
{"channel":"book_lv2","data":[{"symbol":"BTC_USDT","createTime":1784090309244,"asks":[["64875.38","0.185752"]],"bids":[],"lastId":7649224558,"id":7649224559,"ts":1784090309262}],"action":"update"}
{"channel":"book_lv2","data":[{"symbol":"BTC_USDT","createTime":1784090309248,"asks":[],"bids":[["64784.67","0.207949"],["64727.52","0"]],"lastId":7649224559,"id":7649224560,"ts":1784090309263}],"action":"update"}
{"channel":"book_lv2","data":[{"symbol":"BTC_USDT","createTime":1784090309248,"asks":[["64865.66","0.276150"]],"bids":[],"lastId":7649224560,"id":7649224561,"ts":1784090309264}],"action":"update"}
{"channel":"book_lv2","data":[{"symbol":"BTC_USDT","createTime":1784090309248,"asks":[],"bids":[["64794.35","0.386322"],["64730.76","0"]],"lastId":7649224561,"id":7649224563,"ts":1784090309267}],"action":"update"}
{"channel":"book_lv2","data":[{"symbol":"BTC_USDT","createTime":1784090309254,"asks":[["64865.66","0.133495"]],"bids":[],"lastId":7649224563,"id":7649224564,"ts":1784090309270}],"action":"update"}
{"channel":"book_lv2","data":[{"symbol":"BTC_USDT","createTime":1784090309255,"asks":[["64875.38","0.087918"]],"bids":[],"lastId":7649224564,"id":7649224566,"ts":1784090309273}],"action":"update"}
{"channel":"book_lv2","data":[{"symbol":"BTC_USDT","createTime":1784090309256,"asks":[["64859.17","0"],["64878.4","0.002712"]],"bids":[],"lastId":7649224566,"id":7649224569,"ts":1784090309276}],"action":"update"}
{"channel":"book_lv2","data":[{"symbol":"BTC_USDT","createTime":1784090309257,"asks":[["64875.38","0"],["64880.24","0.107109"]],"bids":[],"lastId":7649224569,"id":7649224570,"ts":1784090309277}],"action":"update"}
{"channel":"book_lv2","data":[{"symbol":"BTC_USDT","createTime":1784090309258,"asks":[["64865.66","0"],["64881.54","0.160001"]],"bids":[],"lastId":7649224570,"id":7649224571,"ts":1784090309279}],"action":"update"}
{"channel":"book_lv2","data":[{"symbol":"BTC_USDT","createTime":1784090309263,"asks":[["64872.14","0.231427"],["64881.54","0"]],"bids":[],"lastId":7649224571,"id":7649224576,"ts":1784090309285}],"action":"update"}
{"channel":"book_lv2","data":[{"symbol":"BTC_USDT","createTime":1784090309263,"asks":[["64859.17","0.231427"],["64880.24","0"]],"bids":[],"lastId":7649224576,"id":7649224577,"ts":1784090309286}],"action":"update"}
{"channel":"book_lv2","data":[{"symbol":"BTC_USDT","createTime":1784090309269,"asks":[],"bids":[["64746.62","0.311301"]],"lastId":7649224577,"id":7649224579,"ts":1784090309289}],"action":"update"}
{"channel":"book_lv2","data":[{"symbol":"BTC_USDT","createTime":1784090309273,"asks":[["64864.04","0.287499"]],"bids":[],"lastId":7649224579,"id":7649224580,"ts":1784090309290}],"action":"update"}
{"channel":"book_lv2","data":[{"symbol":"BTC_USDT","createTime":1784090309273,"asks":[],"bids":[["64756.34","0.180385"]],"lastId":7649224580,"id":7649224581,"ts":1784090309291}],"action":"update"}
{"channel":"book_lv2","data":[{"symbol":"BTC_USDT","createTime":1784090309274,"asks":[],"bids":[["64738.84","0.16"],["64734","0"]],"lastId":7649224581,"id":7649224582,"ts":1784090309292}],"action":"update"}
{"channel":"book_lv2","data":[{"symbol":"BTC_USDT","createTime":1784090309280,"asks":[["64873.76","0.285258"]],"bids":[],"lastId":7649224582,"id":7649224585,"ts":1784090309296}],"action":"update"}
{"channel":"book_lv2","data":[{"symbol":"BTC_USDT","createTime":1784090309296,"asks":[],"bids":[["64736.9","8.813475"]],"lastId":7649224585,"id":7649224588,"ts":1784090309313}],"action":"update"}
{"channel":"book_lv2","data":[{"symbol":"BTC_USDT","createTime":1784090309314,"asks":[["64838.88","0.100364"],["64878.4","0"]],"bids":[],"lastId":7649224588,"id":7649224589,"ts":1784090309330}],"action":"update"}
{"channel":"book_lv2","data":[{"symbol":"BTC_USDT","createTime":1784090309329,"asks":[["64838.88","0"],["64878.4","0.002712"]],"bids":[],"lastId":7649224589,"id":7649224590,"ts":1784090309346}],"action":"update"}
{"channel":"book_lv2","data":[{"symbol":"BTC_USDT","createTime":1784090309367,"asks":[["64846.21","0.029306"],["64878.4","0"]],"bids":[],"lastId":7649224590,"id":7649224591,"ts":1784090309379}],"action":"update"}
{"channel":"book_lv2","data":[{"symbol":"BTC_USDT","createTime":1784090309370,"asks":[["64849.45","0.029312"],["64873.76","0"]],"bids":[],"lastId":7649224591,"id":7649224592,"ts":1784090309380}],"action":"update"}
{"channel":"book_lv2","data":[{"symbol":"BTC_USDT","createTime":1784090309372,"asks":[["64855.93","0.029304"],["64872.14","0"]],"bids":[],"lastId":7649224592,"id":7649224593,"ts":1784090309383}],"action":"update"}
{"channel":"book_lv2","data":[{"symbol":"BTC_USDT","createTime":1784090309376,"asks":[["64852.69","0.029311"],["64870.52","0"]],"bids":[],"lastId":7649224593,"id":7649224598,"ts":1784090309389}],"action":"update"}
{"channel":"trades","data":[{"symbol":"BTC_USDT","amount":"2599.9422053","quantity":"0.040115","takerSide":"buy","createTime":1784090309397,"price":"64812.22","id":"225823477","ts":1784090309419}]}
{"channel":"trades","data":[{"symbol":"BTC_USDT","amount":"1148.60216284","quantity":"0.017722","takerSide":"sell","createTime":1784090309399,"price":"64812.22","id":"225823478","ts":1784090309419}]}
{"channel":"book_lv2","data":[{"symbol":"BTC_USDT","createTime":1784090309396,"asks":[["64812.22","0.040115"],["64864.04","0"]],"bids":[],"lastId":7649224598,"id":7649224599,"ts":1784090309420}],"action":"update"}
{"channel":"book_lv2","data":[{"symbol":"BTC_USDT","createTime":1784090309397,"asks":[["64812.22","0"],["64864.04","0.287499"]],"bids":[],"lastId":7649224599,"id":7649224600,"ts":1784090309422}],"action":"update"}
{"channel":"book_lv2","data":[{"symbol":"BTC_USDT","createTime":1784090309399,"asks":[],"bids":[["64812.22","0.017722"],["64735.53","0"]],"lastId":7649224600,"id":7649224601,"ts":1784090309423}],"action":"update"}
{"channel":"book_lv2","data":[{"symbol":"BTC_USDT","createTime":1784090309399,"asks":[],"bids":[["64812.22","0"],["64735.53","6.171695"]],"lastId":7649224601,"id":7649224602,"ts":1784090309425}],"action":"update"}
{"channel":"book_lv2","data":[{"symbol":"BTC_USDT","createTime":1784090309421,"asks":[["64838.88","0.100364"],["64864.04","0"]],"bids":[],"lastId":7649224602,"id":7649224603,"ts":1784090309436}],"action":"update"}
{"channel":"book_lv2","data":[{"symbol":"BTC_USDT","createTime":1784090309436,"asks":[["64838.88","0"],["64864.04","0.287499"]],"bids":[],"lastId":7649224603,"id":7649224604,"ts":1784090309452}],"action":"update"}
{"channel":"book_lv2","data":[{"symbol":"BTC_USDT","createTime":1784090309458,"asks":[["64848.81","0.030025"],["64864.04","0"]],"bids":[],"lastId":7649224604,"id":7649224605,"ts":1784090309468}],"action":"update"}
{"channel":"book_lv2","data":[{"symbol":"BTC_USDT","createTime":1784090309466,"asks":[["64852.05","0.055761"],["64860.47","0"]],"bids":[],"lastId":7649224605,"id":7649224609,"ts":1784090309483}],"action":"update"}
{"channel":"book_lv2","data":[{"symbol":"BTC_USDT","createTime":1784090309466,"asks":[["64855.28","0.103553"],["64859.17","0"]],"bids":[],"lastId":7649224609,"id":7649224611,"ts":1784090309486}],"action":"update"}
{"channel":"book_lv2","data":[{"symbol":"BTC_USDT","createTime":1784090309473,"asks":[["64847.5","0"],["64858.52","7.716401"]],"bids":[],"lastId":7649224611,"id":7649224613,"ts":1784090309488}],"action":"update"}
{"channel":"book_lv2","data":[{"symbol":"BTC_USDT","createTime":1784090309473,"asks":[["64850.74","0"],["64859.17","0.231427"]],"bids":[],"lastId":7649224613,"id":7649224614,"ts":1784090309489}],"action":"update"}
{"channel":"book_lv2","data":[{"symbol":"BTC_USDT","createTime":1784090309474,"asks":[["64844.27","0"],["64860.47","7.716305"]],"bids":[],"lastId":7649224614,"id":7649224616,"ts":1784090309492}],"action":"update"}
{"channel":"book_lv2","data":[{"symbol":"BTC_USDT","createTime":1784090309476,"asks":[["64853.98","0"],["64864.04","0.287499"]],"bids":[],"lastId":7649224616,"id":7649224620,"ts":1784090309497}],"action":"update"}
{"channel":"book_lv2","data":[{"symbol":"BTC_USDT","createTime":1784090309514,"asks":[["64838.88","0.100364"],["64864.04","0"]],"bids":[],"lastId":7649224620,"id":7649224621,"ts":1784090309527}],"action":"update"}
{"channel":"book_lv2","data":[{"symbol":"BTC_USDT","createTime":1784090309523,"asks":[],"bids":[["64784.67","0"],["64734","0.080067"]],"lastId":7649224621,"id":7649224622,"ts":1784090309539}],"action":"update"}
{"channel":"book_lv2","data":[{"symbol":"BTC_USDT","createTime":1784090309529,"asks":[["64838.88","0"],["64864.04","0.287499"]],"bids":[],"lastId":7649224622,"id":7649224623,"ts":1784090309540}],"action":"update"}
{"channel":"book_lv2","data":[{"symbol":"BTC_USDT","createTime":1784090309540,"asks":[],"bids":[["64745.25","0"],["64732.05","0.029308"]],"lastId":7649224623,"id":7649224624,"ts":1784090309552}],"action":"update"}
{"channel":"book_lv2","data":[{"symbol":"BTC_USDT","createTime":1784090309540,"asks":[],"bids":[["64805.53","0"],["64730.76","0.148692"]],"lastId":7649224624,"id":7649224625,"ts":1784090309553}],"action":"update"}
{"channel":"book_lv2","data":[{"symbol":"BTC_USDT","createTime":1784090309540,"asks":[],"bids":[["64737.47","0"],["64728.81","0.02931"]],"lastId":7649224625,"id":7649224627,"ts":1784090309555}],"action":"update"}
{"channel":"book_lv2","data":[{"symbol":"BTC_USDT","createTime":1784090309540,"asks":[],"bids":[["64735.53","0"],["64727.52","0.276136"]],"lastId":7649224627,"id":7649224628,"ts":1784090309557}],"action":"update"}
{"channel":"book_lv2","data":[{"symbol":"BTC_USDT","createTime":1784090309541,"asks":[],"bids":[["64795.81","0"],["64725.57","0.02931"]],"lastId":7649224628,"id":7649224630,"ts":1784090309559}],"action":"update"}
{"channel":"book_lv2","data":[{"symbol":"BTC_USDT","createTime":1784090309541,"asks":[["64864.04","0.180392"]],"bids":[],"lastId":7649224630,"id":7649224632,"ts":1784090309562}],"action":"update"}
{"channel":"book_lv2","data":[{"symbol":"BTC_USDT","createTime":1784090309541,"asks":[],"bids":[["64754.97","0"],["64724.28","18.056483"]],"lastId":7649224632,"id":7649224633,"ts":1784090309563}],"action":"update"}
{"channel":"book_lv2","data":[{"symbol":"BTC_USDT","createTime":1784090309553,"asks":[["64859.17","0"],["64870.52","0.073286"]],"bids":[],"lastId":7649224633,"id":7649224635,"ts":1784090309566}],"action":"update"}
{"channel":"book_lv2","data":[{"symbol":"BTC_USDT","createTime":1784090309554,"asks":[],"bids":[["64794.35","0"],["64722.33","0.029304"]],"lastId":7649224635,"id":7649224636,"ts":1784090309567}],"action":"update"}
{"channel":"book_lv2","data":[{"symbol":"BTC_USDT","createTime":1784090309585,"asks":[["64814.18","0.000062"],["64870.52","0"]],"bids":[],"lastId":7649224636,"id":7649224642,"ts":1784090309606}],"action":"update"}
{"channel":"book_lv2","data":[{"symbol":"BTC_USDT","createTime":1784090309585,"asks":[],"bids":[["64812.58","0.000062"],["64722.33","0"]],"lastId":7649224642,"id":7649224643,"ts":1784090309607}],"action":"update"}
{"channel":"book_lv2","data":[{"symbol":"BTC_USDT","createTime":1784090309586,"asks":[["64817.42","0.000062"],["64864.04","0"]],"bids":[],"lastId":7649224643,"id":7649224644,"ts":1784090309608}],"action":"update"}
{"channel":"book_lv2","data":[{"symbol":"BTC_USDT","createTime":1784090309598,"asks":[["64838.88","0.100364"],["64860.47","0"]],"bids":[],"lastId":7649224644,"id":7649224645,"ts":1784090309613}],"action":"update"}
{"channel":"book_lv2","data":[{"symbol":"BTC_USDT","createTime":1784090309613,"asks":[["64838.88","0"],["64860.47","7.716305"]],"bids":[],"lastId":7649224645,"id":7649224646,"ts":1784090309625}],"action":"update"}
{"channel":"book_lv2","data":[{"symbol":"BTC_USDT","createTime":1784090309650,"asks":[],"bids":[["64807.65","0"],["64722.33","0.029304"]],"lastId":7649224646,"id":7649224647,"ts":1784090309667}],"action":"update"}
{"channel":"book_lv2","data":[{"symbol":"BTC_USDT","createTime":1784090309650,"asks":[],"bids":[["64812.58","0"],["64704.5","5.554955"]],"lastId":7649224647,"id":7649224648,"ts":1784090309668}],"action":"update"}
{"channel":"book_lv2","data":[{"symbol":"BTC_USDT","createTime":1784090309650,"asks":[["64821.98","0"],["64864.04","0.180392"]],"bids":[],"lastId":7649224648,"id":7649224649,"ts":1784090309669}],"action":"update"}
{"channel":"book_lv2","data":[{"symbol":"BTC_USDT","createTime":1784090309672,"asks":[],"bids":[["64740.14","0"],["64697.41","0.00272"]],"lastId":7649224649,"id":7649224651,"ts":1784090309691}],"action":"update"}
{"channel":"book_lv2","data":[{"symbol":"BTC_USDT","createTime":1784090309672,"asks":[],"bids":[["64736.9","6.171695"]],"lastId":7649224651,"id":7649224652,"ts":1784090309694}],"action":"update"}
{"channel":"book_lv2","data":[{"symbol":"BTC_USDT","createTime":1784090309672,"asks":[],"bids":[["64738.85","0"],["64672.09","3.07431"]],"lastId":7649224652,"id":7649224654,"ts":1784090309697}],"action":"update"}
{"channel":"book_lv2","data":[{"symbol":"BTC_USDT","createTime":1784090309674,"asks":[],"bids":[["64746.62","0.204195"]],"lastId":7649224654,"id":7649224655,"ts":1784090309698}],"action":"update"}
{"channel":"book_lv2","data":[{"symbol":"BTC_USDT","createTime":1784090309685,"asks":[["64838.88","0.100364"],["64864.04","0"]],"bids":[],"lastId":7649224655,"id":7649224658,"ts":1784090309703}],"action":"update"}
{"channel":"book_lv2","data":[{"symbol":"BTC_USDT","createTime":1784090309700,"asks":[["64838.88","0"],["64864.04","0.180392"]],"bids":[],"lastId":7649224658,"id":7649224659,"ts":1784090309716}],"action":"update"}
{"channel":"book_lv2","data":[{"symbol":"BTC_USDT","createTime":1784090309747,"asks":[],"bids":[["64794.41","0.367943"],["64672.09","0"]],"lastId":7649224659,"id":7649224661,"ts":1784090309760}],"action":"update"}
{"channel":"book_lv2","data":[{"symbol":"BTC_USDT","createTime":1784090309747,"asks":[],"bids":[["64784.67","0.259595"],["64697.41","0"]],"lastId":7649224661,"id":7649224662,"ts":1784090309761}],"action":"update"}
{"channel":"book_lv2","data":[{"symbol":"BTC_USDT","createTime":1784090309750,"asks":[["64850.75","0.035666"]],"bids":[],"lastId":7649224662,"id":7649224665,"ts":1784090309765}],"action":"update"}
{"channel":"book_lv2","data":[{"symbol":"BTC_USDT","createTime":1784090309750,"asks":[],"bids":[["64724.28","20.688912"]],"lastId":7649224665,"id":7649224666,"ts":1784090309766}],"action":"update"}
{"channel":"book_lv2","data":[{"symbol":"BTC_USDT","createTime":1784090309750,"asks":[["64853.99","0.521347"]],"bids":[],"lastId":7649224666,"id":7649224667,"ts":1784090309767}],"action":"update"}
{"channel":"book_lv2","data":[{"symbol":"BTC_USDT","createTime":1784090309752,"asks":[["64844.27","0.003855"],["64864.04","0"]],"bids":[],"lastId":7649224667,"id":7649224668,"ts":1784090309769}],"action":"update"}
{"channel":"book_lv2","data":[{"symbol":"BTC_USDT","createTime":1784090309752,"asks":[],"bids":[["64727.52","0.345171"]],"lastId":7649224668,"id":7649224669,"ts":1784090309770}],"action":"update"}
{"channel":"book_lv2","data":[{"symbol":"BTC_USDT","createTime":1784090309755,"asks":[],"bids":[["64730.76","0.185867"]],"lastId":7649224669,"id":7649224670,"ts":1784090309773}],"action":"update"}
{"channel":"book_lv2","data":[{"symbol":"BTC_USDT","createTime":1784090309756,"asks":[["64847.51","0.003855"],["64860.47","0"]],"bids":[],"lastId":7649224670,"id":7649224671,"ts":1784090309774}],"action":"update"}
{"channel":"book_lv2","data":[{"symbol":"BTC_USDT","createTime":1784090309757,"asks":[],"bids":[["64734","0.100083"]],"lastId":7649224671,"id":7649224672,"ts":1784090309776}],"action":"update"}
{"channel":"book_lv2","data":[{"symbol":"BTC_USDT","createTime":1784090309771,"asks":[["64838.88","0.100364"],["64858.52","0"]],"bids":[],"lastId":7649224672,"id":7649224678,"ts":1784090309787}],"action":"update"}
{"channel":"book_lv2","data":[{"symbol":"BTC_USDT","createTime":1784090309786,"asks":[["64838.88","0"],["64858.52","7.716401"]],"bids":[],"lastId":7649224678,"id":7649224681,"ts":1784090309799}],"action":"update"}
{"channel":"book_lv2","data":[{"symbol":"BTC_USDT","createTime":1784090309819,"asks":[],"bids":[["64736.9","12.343390"]],"lastId":7649224681,"id":7649224686,"ts":1784090309837}],"action":"update"}
{"channel":"book_lv2","data":[{"symbol":"BTC_USDT","createTime":1784090309820,"asks":[],"bids":[["64756.34","0.287495"]],"lastId":7649224686,"id":7649224688,"ts":1784090309839}],"action":"update"}
{"channel":"book_lv2","data":[{"symbol":"BTC_USDT","createTime":1784090309822,"asks":[],"bids":[["64797.18","0.225134"],["64704.5","0"]],"lastId":7649224688,"id":7649224689,"ts":1784090309840}],"action":"update"}
{"channel":"book_lv2","data":[{"symbol":"BTC_USDT","createTime":1784090309822,"asks":[],"bids":[["64784.67","0"],["64704.5","5.554955"]],"lastId":7649224689,"id":7649224691,"ts":1784090309843}],"action":"update"}
{"channel":"book_lv2","data":[{"symbol":"BTC_USDT","createTime":1784090309823,"asks":[],"bids":[["64806.9","0.219865"],["64704.5","0"]],"lastId":7649224691,"id":7649224692,"ts":1784090309844}],"action":"update"}
{"channel":"book_lv2","data":[{"symbol":"BTC_USDT","createTime":1784090309836,"asks":[],"bids":[["64738.84","0.320002"]],"lastId":7649224692,"id":7649224695,"ts":1784090309848}],"action":"update"}
{"channel":"book_lv2","data":[{"symbol":"BTC_USDT","createTime":1784090309839,"asks":[],"bids":[["64746.62","0.335105"]],"lastId":7649224695,"id":7649224698,"ts":1784090309853}],"action":"update"}
{"channel":"book_lv2","data":[{"symbol":"BTC_USDT","createTime":1784090309859,"asks":[],"bids":[["64774.97","0.02"],["64722.33","0"]],"lastId":7649224698,"id":7649224709,"ts":1784090309883}],"action":"update"}
{"channel":"book_lv2","data":[{"symbol":"BTC_USDT","createTime":1784090309880,"asks":[["64838.88","0.100364"],["64858.52","0"]],"bids":[],"lastId":7649224709,"id":7649224710,"ts":1784090309891}],"action":"update"}
{"channel":"book_lv2","data":[{"symbol":"BTC_USDT","createTime":1784090309896,"asks":[["64838.88","0"],["64858.52","7.716401"]],"bids":[],"lastId":7649224710,"id":7649224711,"ts":1784090309905}],"action":"update"}
{"channel":"book_lv2","data":[{"symbol":"BTC_USDT","createTime":1784090309948,"asks":[],"bids":[["64746.62","0.442215"]],"lastId":7649224711,"id":7649224713,"ts":1784090309959}],"action":"update"}
{"channel":"book_lv2","data":[{"symbol":"BTC_USDT","createTime":1784090309950,"asks":[],"bids":[["64740.14","0.13091"],["64724.28","0"]],"lastId":7649224713,"id":7649224715,"ts":1784090309965}],"action":"update"}
{"channel":"book_lv2","data":[{"symbol":"BTC_USDT","createTime":1784090309952,"asks":[],"bids":[["64738.84","0.480006"]],"lastId":7649224715,"id":7649224716,"ts":1784090309966}],"action":"update"}
{"channel":"book_lv2","data":[{"symbol":"BTC_USDT","createTime":1784090309958,"asks":[["64838.88","0.100364"],["64858.52","0"]],"bids":[],"lastId":7649224716,"id":7649224717,"ts":1784090309972}],"action":"update"}
{"channel":"book_lv2","data":[{"symbol":"BTC_USDT","createTime":1784090309963,"asks":[],"bids":[["64736.9","14.985159"]],"lastId":7649224717,"id":7649224718,"ts":1784090309973}],"action":"update"}
{"channel":"book_lv2","data":[{"symbol":"BTC_USDT","createTime":1784090309973,"asks":[["64838.88","0"],["64858.52","7.716401"]],"bids":[],"lastId":7649224718,"id":7649224723,"ts":1784090309984}],"action":"update"}
{"channel":"book_lv2","data":[{"symbol":"BTC_USDT","createTime":1784090309975,"asks":[],"bids":[["64784.67","0.284015"],["64725.57","0"]],"lastId":7649224723,"id":7649224724,"ts":1784090309987}],"action":"update"}
{"channel":"book_lv2","data":[{"symbol":"BTC_USDT","createTime":1784090309975,"asks":[],"bids":[["64794.36","0.403628"],["64727.52","0"]],"lastId":7649224724,"id":7649224725,"ts":1784090309988}],"action":"update"}
{"channel":"book_lv2","data":[{"symbol":"BTC_USDT","createTime":1784090310018,"asks":[],"bids":[["64730.76","0.130107"]],"lastId":7649224725,"id":7649224734,"ts":1784090310035}],"action":"update"}
{"channel":"book_lv2","data":[{"symbol":"BTC_USDT","createTime":1784090310019,"asks":[],"bids":[["64734","0.070058"]],"lastId":7649224734,"id":7649224736,"ts":1784090310037}],"action":"update"}
{"channel":"book_lv2","data":[{"symbol":"BTC_USDT","createTime":1784090310019,"asks":[["64850.75","0.005642"]],"bids":[],"lastId":7649224736,"id":7649224738,"ts":1784090310040}],"action":"update"}
{"channel":"book_lv2","data":[{"symbol":"BTC_USDT","createTime":1784090310020,"asks":[["64853.99","0.465590"]],"bids":[],"lastId":7649224738,"id":7649224740,"ts":1784090310042}],"action":"update"}
{"channel":"book_lv2","data":[{"symbol":"BTC_USDT","createTime":1784090310020,"asks":[["64857.23","0"],["64859.17","0.231443"]],"bids":[],"lastId":7649224740,"id":7649224741,"ts":1784090310044}],"action":"update"}
{"channel":"book_lv2","data":[{"symbol":"BTC_USDT","createTime":1784090310023,"asks":[],"bids":[["64794.41","0"],["64727.52","0.241620"]],"lastId":7649224741,"id":7649224745,"ts":1784090310050}],"action":"update"}
{"channel":"book_lv2","data":[{"symbol":"BTC_USDT","createTime":1784090310024,"asks":[],"bids":[["64784.67","0"],["64725.57","0.02931"]],"lastId":7649224745,"id":7649224746,"ts":1784090310051}],"action":"update"}
{"channel":"book_lv2","data":[{"symbol":"BTC_USDT","createTime":1784090310024,"asks":[],"bids":[["64794.36","0"],["64724.28","12.972607"]],"lastId":7649224746,"id":7649224747,"ts":1784090310052}],"action":"update"}
{"channel":"book_lv2","data":[{"symbol":"BTC_USDT","createTime":1784090310040,"asks":[["64838.88","0.100364"],["64859.17","0"]],"bids":[],"lastId":7649224747,"id":7649224748,"ts":1784090310055}],"action":"update"}
{"channel":"book_lv2","data":[{"symbol":"BTC_USDT","createTime":1784090310043,"asks":[],"bids":[["64804.97","0.000102"],["64724.28","0"]],"lastId":7649224748,"id":7649224749,"ts":1784090310056}],"action":"update"}
{"channel":"book_lv2","data":[{"symbol":"BTC_USDT","createTime":1784090310045,"asks":[],"bids":[["64804.57","0.000826"],["64725.57","0"]],"lastId":7649224749,"id":7649224750,"ts":1784090310057}],"action":"update"}
{"channel":"book_lv2","data":[{"symbol":"BTC_USDT","createTime":1784090310045,"asks":[],"bids":[["64804.37","0.000607"],["64727.52","0"]],"lastId":7649224750,"id":7649224751,"ts":1784090310059}],"action":"update"}
{"channel":"book_lv2","data":[{"symbol":"BTC_USDT","createTime":1784090310045,"asks":[],"bids":[["64804.77","0.001124"],["64728.81","0"]],"lastId":7649224751,"id":7649224752,"ts":1784090310060}],"action":"update"}
{"channel":"book_lv2","data":[{"symbol":"BTC_USDT","createTime":1784090310045,"asks":[],"bids":[["64804.17","0.000446"],["64730.76","0"]],"lastId":7649224752,"id":7649224753,"ts":1784090310061}],"action":"update"}
{"channel":"book_lv2","data":[{"symbol":"BTC_USDT","createTime":1784090310055,"asks":[["64838.88","0"],["64859.17","0.231443"]],"bids":[],"lastId":7649224753,"id":7649224754,"ts":1784090310066}],"action":"update"}
{"channel":"book_lv2","data":[{"symbol":"BTC_USDT","createTime":1784090310073,"asks":[],"bids":[["64803.97","0.000327"],["64732.05","0"]],"lastId":7649224754,"id":7649224755,"ts":1784090310082}],"action":"update"}
{"channel":"book_lv2","data":[{"symbol":"BTC_USDT","createTime":1784090310073,"asks":[],"bids":[["64803.77","0.00024"],["64734","0"]],"lastId":7649224755,"id":7649224756,"ts":1784090310083}],"action":"update"}
{"channel":"book_lv2","data":[{"symbol":"BTC_USDT","createTime":1784090310073,"asks":[],"bids":[["64803.57","0.000176"],["64736.9","0"]],"lastId":7649224756,"id":7649224757,"ts":1784090310084}],"action":"update"}
{"channel":"book_lv2","data":[{"symbol":"BTC_USDT","createTime":1784090310126,"asks":[["64838.88","0.100364"],["64859.17","0"]],"bids":[],"lastId":7649224757,"id":7649224758,"ts":1784090310141}],"action":"update"}
{"channel":"book_lv2","data":[{"symbol":"BTC_USDT","createTime":1784090310141,"asks":[["64838.88","0"],["64859.17","0.231443"]],"bids":[],"lastId":7649224758,"id":7649224759,"ts":1784090310158}],"action":"update"}
{"channel":"book_lv2","data":[{"symbol":"BTC_USDT","createTime":1784090310153,"asks":[["64814.18","0"],["64864.04","0.287500"]],"bids":[],"lastId":7649224759,"id":7649224760,"ts":1784090310171}],"action":"update"}
{"channel":"book_lv2","data":[{"symbol":"BTC_USDT","createTime":1784090310154,"asks":[["64859.17","0"],["64865.66","0.147872"]],"bids":[],"lastId":7649224760,"id":7649224762,"ts":1784090310174}],"action":"update"}
{"channel":"book_lv2","data":[{"symbol":"BTC_USDT","createTime":1784090310156,"asks":[["64865.66","0"],["64870.52","0.073286"]],"bids":[],"lastId":7649224762,"id":7649224767,"ts":1784090310180}],"action":"update"}
{"channel":"book_lv2","data":[{"symbol":"BTC_USDT","createTime":1784090310211,"asks":[["64838.88","0.100364"],["64870.52","0"]],"bids":[],"lastId":7649224767,"id":7649224771,"ts":1784090310227}],"action":"update"}
{"channel":"book_lv2","data":[{"symbol":"BTC_USDT","createTime":1784090310227,"asks":[["64838.88","0"],["64870.52","0.073286"]],"bids":[],"lastId":7649224771,"id":7649224772,"ts":1784090310241}],"action":"update"}
{"channel":"book_lv2","data":[{"symbol":"BTC_USDT","createTime":1784090310257,"asks":[],"bids":[["64794.35","0.422238"],["64738.84","0"]],"lastId":7649224772,"id":7649224774,"ts":1784090310268}],"action":"update"}
{"channel":"book_lv2","data":[{"symbol":"BTC_USDT","createTime":1784090310259,"asks":[["64865.66","0.132414"],["64870.52","0"]],"bids":[],"lastId":7649224774,"id":7649224775,"ts":1784090310271}],"action":"update"}
{"channel":"book_lv2","data":[{"symbol":"BTC_USDT","createTime":1784090310259,"asks":[],"bids":[["64784.67","0.25418"],["64740.14","0"]],"lastId":7649224775,"id":7649224776,"ts":1784090310272}],"action":"update"}
{"channel":"book_lv2","data":[{"symbol":"BTC_USDT","createTime":1784090310273,"asks":[["64859.17","0.231443"],["64865.66","0"]],"bids":[],"lastId":7649224776,"id":7649224779,"ts":1784090310285}],"action":"update"}
{"channel":"book_lv2","data":[{"symbol":"BTC_USDT","createTime":1784090310294,"asks":[["64857.23","0.103555"],["64864.04","0"]],"bids":[],"lastId":7649224779,"id":7649224784,"ts":1784090310308}],"action":"update"}
{"channel":"book_lv2","data":[{"symbol":"BTC_USDT","createTime":1784090310299,"asks":[["64853.99","0.521351"]],"bids":[],"lastId":7649224784,"id":7649224789,"ts":1784090310314}],"action":"update"}
{"channel":"book_lv2","data":[{"symbol":"BTC_USDT","createTime":1784090310302,"asks":[["64850.75","0.035669"]],"bids":[],"lastId":7649224789,"id":7649224790,"ts":1784090310320}],"action":"update"}
{"channel":"book_lv2","data":[{"symbol":"BTC_USDT","createTime":1784090310303,"asks":[["64838.88","0.100364"],["64859.17","0"]],"bids":[],"lastId":7649224790,"id":7649224791,"ts":1784090310321}],"action":"update"}
{"channel":"book_lv2","data":[{"symbol":"BTC_USDT","createTime":1784090310318,"asks":[["64838.88","0"],["64859.17","0.231443"]],"bids":[],"lastId":7649224791,"id":7649224794,"ts":1784090310332}],"action":"update"}
{"channel":"book_lv2","data":[{"symbol":"BTC_USDT","createTime":1784090310324,"asks":[],"bids":[["64794.35","0"],["64740.14","0.13091"]],"lastId":7649224794,"id":7649224795,"ts":1784090310338}],"action":"update"}
{"channel":"book_lv2","data":[{"symbol":"BTC_USDT","createTime":1784090310324,"asks":[],"bids":[["64784.67","0"],["64738.84","0.480006"]],"lastId":7649224795,"id":7649224796,"ts":1784090310339}],"action":"update"}
{"channel":"book_lv2","data":[{"symbol":"BTC_USDT","createTime":1784090310342,"asks":[["64817.42","0"],["64860.47","7.716305"]],"bids":[],"lastId":7649224796,"id":7649224797,"ts":1784090310355}],"action":"update"}
{"channel":"book_lv2","data":[{"symbol":"BTC_USDT","createTime":1784090310410,"asks":[["64838.88","0.100364"],["64860.47","0"]],"bids":[],"lastId":7649224797,"id":7649224798,"ts":1784090310425}],"action":"update"}
{"channel":"book_lv2","data":[{"symbol":"BTC_USDT","createTime":1784090310441,"asks":[["64838.88","0"],["64860.47","7.716305"]],"bids":[],"lastId":7649224798,"id":7649224799,"ts":1784090310459}],"action":"update"}
{"channel":"book_lv2","data":[{"symbol":"BTC_USDT","createTime":1784090310457,"asks":[["64859.17","0"],["64864.04","0.287500"]],"bids":[],"lastId":7649224799,"id":7649224809,"ts":1784090310481}],"action":"update"}
{"channel":"book_lv2","data":[{"symbol":"BTC_USDT","createTime":1784090310457,"asks":[],"bids":[["64794.39","0.422713"],["64738.84","0"]],"lastId":7649224809,"id":7649224810,"ts":1784090310482}],"action":"update"}
{"channel":"book_lv2","data":[{"symbol":"BTC_USDT","createTime":1784090310457,"asks":[],"bids":[["64784.62","0.28101"],["64740.14","0"]],"lastId":7649224810,"id":7649224811,"ts":1784090310483}],"action":"update"}
{"channel":"book_lv2","data":[{"symbol":"BTC_USDT","createTime":1784090310477,"asks":[["64859.17","0.23144"],["64864.04","0"]],"bids":[],"lastId":7649224811,"id":7649224816,"ts":1784090310490}],"action":"update"}
{"channel":"book_lv2","data":[{"symbol":"BTC_USDT","createTime":1784090310509,"asks":[["64838.88","0.100364"],["64860.47","0"]],"bids":[],"lastId":7649224816,"id":7649224818,"ts":1784090310523}],"action":"update"}
{"channel":"book_lv2","data":[{"symbol":"BTC_USDT","createTime":1784090310517,"asks":[],"bids":[["64794.39","0"],["64740.14","0.13091"]],"lastId":7649224818,"id":7649224819,"ts":1784090310537}],"action":"update"}
{"channel":"book_lv2","data":[{"symbol":"BTC_USDT","createTime":1784090310517,"asks":[],"bids":[["64784.62","0"],["64738.84","0.480006"]],"lastId":7649224819,"id":7649224820,"ts":1784090310538}],"action":"update"}
{"channel":"book_lv2","data":[{"symbol":"BTC_USDT","createTime":1784090310526,"asks":[["64838.88","0"],["64860.47","7.716305"]],"bids":[],"lastId":7649224820,"id":7649224821,"ts":1784090310540}],"action":"update"}
{"channel":"book_lv2","data":[{"symbol":"BTC_USDT","createTime":1784090310544,"asks":[],"bids":[["64756.34","0.214217"]],"lastId":7649224821,"id":7649224822,"ts":1784090310558}],"action":"update"}
{"channel":"book_lv2","data":[{"symbol":"BTC_USDT","createTime":1784090310544,"asks":[],"bids":[["64743.38","0"],["64736.9","14.985159"]],"lastId":7649224822,"id":7649224823,"ts":1784090310559}],"action":"update"}
{"channel":"book_lv2","data":[{"symbol":"BTC_USDT","createTime":1784090310544,"asks":[],"bids":[["64746.62","0.368929"]],"lastId":7649224823,"id":7649224824,"ts":1784090310560}],"action":"update"}
{"channel":"book_lv2","data":[{"symbol":"BTC_USDT","createTime":1784090310545,"asks":[],"bids":[["64749.86","0"],["64734","0.100085"]],"lastId":7649224824,"id":7649224827,"ts":1784090310564}],"action":"update"}
{"channel":"book_lv2","data":[{"symbol":"BTC_USDT","createTime":1784090310591,"asks":[["64818.87","0.000062"],["64860.47","0"]],"bids":[],"lastId":7649224827,"id":7649224829,"ts":1784090310603}],"action":"update"}
{"channel":"book_lv2","data":[{"symbol":"BTC_USDT","createTime":1784090310596,"asks":[["64838.88","0.100364"],["64859.17","0"]],"bids":[],"lastId":7649224829,"id":7649224830,"ts":1784090310616}],"action":"update"}
{"channel":"book_lv2","data":[{"symbol":"BTC_USDT","createTime":1784090310599,"asks":[["64822.11","0.000062"],["64858.52","0"]],"bids":[],"lastId":7649224830,"id":7649224831,"ts":1784090310617}],"action":"update"}
{"channel":"book_lv2","data":[{"symbol":"BTC_USDT","createTime":1784090310609,"asks":[],"bids":[["64814.03","0.000062"],["64734","0"]],"lastId":7649224831,"id":7649224832,"ts":1784090310627}],"action":"update"}
{"channel":"book_lv2","data":[{"symbol":"BTC_USDT","createTime":1784090310609,"asks":[["64838.88","0"],["64858.52","7.716401"]],"bids":[],"lastId":7649224832,"id":7649224833,"ts":1784090310628}],"action":"update"}
{"channel":"book_lv2","data":[{"symbol":"BTC_USDT","createTime":1784090310682,"asks":[["64838.88","0.100364"],["64858.52","0"]],"bids":[],"lastId":7649224833,"id":7649224836,"ts":1784090310697}],"action":"update"}
{"channel":"book_lv2","data":[{"symbol":"BTC_USDT","createTime":1784090310729,"asks":[["64838.88","0"],["64858.52","7.716401"]],"bids":[],"lastId":7649224836,"id":7649224837,"ts":1784090310745}],"action":"update"}
{"channel":"book_lv2","data":[{"symbol":"BTC_USDT","createTime":1784090310796,"asks":[["64838.88","0.100364"],["64858.52","0"]],"bids":[],"lastId":7649224837,"id":7649224842,"ts":1784090310804}],"action":"update"}
{"channel":"book_lv2","data":[{"symbol":"BTC_USDT","createTime":1784090310813,"asks":[["64838.88","0"],["64858.52","7.716401"]],"bids":[],"lastId":7649224842,"id":7649224843,"ts":1784090310831}],"action":"update"}
{"channel":"book_lv2","data":[{"symbol":"BTC_USDT","createTime":1784090310818,"asks":[],"bids":[["64749.86","0.073282"],["64736.9","0"]],"lastId":7649224843,"id":7649224844,"ts":1784090310833}],"action":"update"}
{"channel":"book_lv2","data":[{"symbol":"BTC_USDT","createTime":1784090310822,"asks":[],"bids":[["64756.34","0.287502"]],"lastId":7649224844,"id":7649224846,"ts":1784090310839}],"action":"update"}
{"channel":"book_lv2","data":[{"symbol":"BTC_USDT","createTime":1784090310824,"asks":[],"bids":[["64746.62","0.442207"]],"lastId":7649224846,"id":7649224848,"ts":1784090310841}],"action":"update"}
{"channel":"book_lv2","data":[{"symbol":"BTC_USDT","createTime":1784090310832,"asks":[],"bids":[["64784.66","0.252856"],["64738.84","0"]],"lastId":7649224848,"id":7649224849,"ts":1784090310847}],"action":"update"}
{"channel":"book_lv2","data":[{"symbol":"BTC_USDT","createTime":1784090310834,"asks":[],"bids":[["64794.37","0.374947"],["64740.14","0"]],"lastId":7649224849,"id":7649224851,"ts":1784090310850}],"action":"update"}
{"channel":"book_lv2","data":[{"symbol":"BTC_USDT","createTime":1784090310881,"asks":[["64838.88","0.100364"],["64858.52","0"]],"bids":[],"lastId":7649224851,"id":7649224863,"ts":1784090310897}],"action":"update"}
{"channel":"book_lv2","data":[{"symbol":"BTC_USDT","createTime":1784090310896,"asks":[],"bids":[["64746.62","0.311298"]],"lastId":7649224863,"id":7649224867,"ts":1784090310913}],"action":"update"}
{"channel":"book_lv2","data":[{"symbol":"BTC_USDT","createTime":1784090310897,"asks":[],"bids":[["64756.34","0.180395"]],"lastId":7649224867,"id":7649224871,"ts":1784090310918}],"action":"update"}
{"channel":"book_lv2","data":[{"symbol":"BTC_USDT","createTime":1784090310903,"asks":[["64848.16","0"],["64858.52","7.716401"]],"bids":[],"lastId":7649224871,"id":7649224872,"ts":1784090310919}],"action":"update"}
{"channel":"book_lv2","data":[{"symbol":"BTC_USDT","createTime":1784090310903,"asks":[["64851.4","0"],["64859.17","0.231427"]],"bids":[],"lastId":7649224872,"id":7649224875,"ts":1784090310923}],"action":"update"}
{"channel":"book_lv2","data":[{"symbol":"BTC_USDT","createTime":1784090310903,"asks":[["64857.88","0"],["64860.47","7.716305"]],"bids":[],"lastId":7649224875,"id":7649224876,"ts":1784090310924}],"action":"update"}
{"channel":"book_lv2","data":[{"symbol":"BTC_USDT","createTime":1784090310905,"asks":[["64854.64","0"],["64864.04","0.180395"]],"bids":[],"lastId":7649224876,"id":7649224879,"ts":1784090310928}],"action":"update"}
{"channel":"book_lv2","data":[{"symbol":"BTC_USDT","createTime":1784090310925,"asks":[],"bids":[["64784.66","0"],["64743.38","0.04247"]],"lastId":7649224879,"id":7649224880,"ts":1784090310936}],"action":"update"}
{"channel":"book_lv2","data":[{"symbol":"BTC_USDT","createTime":1784090310949,"asks":[["64846.21","0"],["64865.66","0.161221"]],"bids":[],"lastId":7649224880,"id":7649224881,"ts":1784090310960}],"action":"update"}
{"channel":"book_lv2","data":[{"symbol":"BTC_USDT","createTime":1784090310949,"asks":[["64855.93","0"],["64870.52","0.073287"]],"bids":[],"lastId":7649224881,"id":7649224883,"ts":1784090310962}],"action":"update"}
{"channel":"book_lv2","data":[{"symbol":"BTC_USDT","createTime":1784090310949,"asks":[["64852.69","0"],["64872.14","0.231427"]],"bids":[],"lastId":7649224883,"id":7649224884,"ts":1784090310963}],"action":"update"}
{"channel":"book_lv2","data":[{"symbol":"BTC_USDT","createTime":1784090310950,"asks":[["64849.45","0"],["64873.76","0.154350"]],"bids":[],"lastId":7649224884,"id":7649224885,"ts":1784090310964}],"action":"update"}
{"channel":"book_lv2","data":[{"symbol":"BTC_USDT","createTime":1784090311008,"asks":[["64838.88","0"],["64875.38","0.105856"]],"bids":[],"lastId":7649224885,"id":7649224889,"ts":1784090311021}],"action":"update"}
{"channel":"book_lv2","data":[{"symbol":"BTC_USDT","createTime":1784090311055,"asks":[["64875.38","0"],["64878.4","0.002712"]],"bids":[],"lastId":7649224889,"id":7649224894,"ts":1784090311070}],"action":"update"}
{"channel":"book_lv2","data":[{"symbol":"BTC_USDT","createTime":1784090311056,"asks":[["64872.14","0"],["64880.25","0.107108"]],"bids":[],"lastId":7649224894,"id":7649224896,"ts":1784090311072}],"action":"update"}
{"channel":"book_lv2","data":[{"symbol":"BTC_USDT","createTime":1784090311056,"asks":[["64865.66","0"],["64881.54","0.160002"]],"bids":[],"lastId":7649224896,"id":7649224897,"ts":1784090311073}],"action":"update"}
{"channel":"book_lv2","data":[{"symbol":"BTC_USDT","createTime":1784090311056,"asks":[["64859.17","0"],["64883.49","6.171695"]],"bids":[],"lastId":7649224897,"id":7649224899,"ts":1784090311076}],"action":"update"}
{"channel":"book_lv2","data":[{"symbol":"BTC_USDT","createTime":1784090311083,"asks":[["64838.88","0.100364"],["64883.49","0"]],"bids":[],"lastId":7649224899,"id":7649224900,"ts":1784090311101}],"action":"update"}
{"channel":"book_lv2","data":[{"symbol":"BTC_USDT","createTime":1784090311108,"asks":[["64838.88","0"],["64883.49","6.171695"]],"bids":[],"lastId":7649224900,"id":7649224901,"ts":1784090311122}],"action":"update"}
{"channel":"book_lv2","data":[{"symbol":"BTC_USDT","createTime":1784090311142,"asks":[],"bids":[["64794.37","0"],["64740.14","0.13091"]],"lastId":7649224901,"id":7649224902,"ts":1784090311155}],"action":"update"}
{"channel":"book_lv2","data":[{"symbol":"BTC_USDT","createTime":1784090311153,"asks":[["64865.66","0.192033"],["64883.49","0"]],"bids":[],"lastId":7649224902,"id":7649224903,"ts":1784090311167}],"action":"update"}
{"channel":"book_lv2","data":[{"symbol":"BTC_USDT","createTime":1784090311155,"asks":[],"bids":[["64794.38","0.396598"],["64740.14","0"]],"lastId":7649224903,"id":7649224904,"ts":1784090311168}],"action":"update"}
{"channel":"book_lv2","data":[{"symbol":"BTC_USDT","createTime":1784090311159,"asks":[["64875.38","0.091309"],["64881.54","0"]],"bids":[],"lastId":7649224904,"id":7649224905,"ts":1784090311172}],"action":"update"}
{"channel":"book_lv2","data":[{"symbol":"BTC_USDT","createTime":1784090311159,"asks":[],"bids":[["64784.61","0.235544"],["64743.38","0"]],"lastId":7649224905,"id":7649224907,"ts":1784090311174}],"action":"update"}
{"channel":"book_lv2","data":[{"symbol":"BTC_USDT","createTime":1784090311172,"asks":[],"bids":[["64755.84","0.107108"],["64746.62","0"]],"lastId":7649224907,"id":7649224909,"ts":1784090311187}],"action":"update"}
{"channel":"book_lv2","data":[{"symbol":"BTC_USDT","createTime":1784090311172,"asks":[["64863.64","0.107111"],["64880.25","0"]],"bids":[],"lastId":7649224909,"id":7649224910,"ts":1784090311188}],"action":"update"}
{"channel":"book_lv2","data":[{"symbol":"BTC_USDT","createTime":1784090311172,"asks":[["64873.36","0.130913"],["64878.4","0"]],"bids":[],"lastId":7649224910,"id":7649224911,"ts":1784090311190}],"action":"update"}
{"channel":"book_lv2","data":[{"symbol":"BTC_USDT","createTime":1784090311174,"asks":[["64857.88","0.604605"],["64875.38","0"]],"bids":[],"lastId":7649224911,"id":7649224916,"ts":1784090311197}],"action":"update"}
{"channel":"book_lv2","data":[{"symbol":"BTC_USDT","createTime":1784090311175,"asks":[["64854.64","0.007298"],["64873.76","0"]],"bids":[],"lastId":7649224916,"id":7649224917,"ts":1784090311199}],"action":"update"}
{"channel":"book_lv2","data":[{"symbol":"BTC_USDT","createTime":1784090311175,"asks":[["64838.88","0.100364"],["64873.36","0"]],"bids":[],"lastId":7649224917,"id":7649224918,"ts":1784090311200}],"action":"update"}
{"channel":"book_lv2","data":[{"symbol":"BTC_USDT","createTime":1784090311178,"asks":[["64859.17","0.231427"],["64870.52","0"]],"bids":[],"lastId":7649224918,"id":7649224924,"ts":1784090311207}],"action":"update"}
{"channel":"book_lv2","data":[{"symbol":"BTC_USDT","createTime":1784090311178,"asks":[["64851.4","0.003928"],["64865.66","0"]],"bids":[],"lastId":7649224924,"id":7649224925,"ts":1784090311208}],"action":"update"}
{"channel":"book_lv2","data":[{"symbol":"BTC_USDT","createTime":1784090311182,"asks":[["64848.16","0.003855"],["64864.04","0"]],"bids":[],"lastId":7649224925,"id":7649224926,"ts":1784090311210}],"action":"update"}
{"channel":"book_lv2","data":[{"symbol":"BTC_USDT","createTime":1784090311190,"asks":[["64838.88","0"],["64864.04","0.180395"]],"bids":[],"lastId":7649224926,"id":7649224933,"ts":1784090311219}],"action":"update"}
{"channel":"book_lv2","data":[{"symbol":"BTC_USDT","createTime":1784090311225,"asks":[["64852.69","0.029305"],["64864.04","0"]],"bids":[],"lastId":7649224933,"id":7649224938,"ts":1784090311239}],"action":"update"}
{"channel":"book_lv2","data":[{"symbol":"BTC_USDT","createTime":1784090311228,"asks":[["64849.45","0.029306"],["64863.64","0"]],"bids":[],"lastId":7649224938,"id":7649224940,"ts":1784090311241}],"action":"update"}
{"channel":"book_lv2","data":[{"symbol":"BTC_USDT","createTime":1784090311230,"asks":[["64846.21","0.029312"],["64860.47","0"]],"bids":[],"lastId":7649224940,"id":7649224942,"ts":1784090311248}],"action":"update"}
{"channel":"book_lv2","data":[{"symbol":"BTC_USDT","createTime":1784090311234,"asks":[["64855.93","0.029306"],["64859.17","0"]],"bids":[],"lastId":7649224942,"id":7649224945,"ts":1784090311252}],"action":"update"}
{"channel":"book_lv2","data":[{"symbol":"BTC_USDT","createTime":1784090311264,"asks":[["64838.88","0.100364"],["64858.52","0"]],"bids":[],"lastId":7649224945,"id":7649224946,"ts":1784090311272}],"action":"update"}
{"channel":"book_lv2","data":[{"symbol":"BTC_USDT","createTime":1784090311279,"asks":[["64838.88","0"],["64858.52","7.716401"]],"bids":[],"lastId":7649224946,"id":7649224947,"ts":1784090311297}],"action":"update"}
{"channel":"book_lv2","data":[{"symbol":"BTC_USDT","createTime":1784090311356,"asks":[],"bids":[["64784.61","0"],["64746.62","0.311298"]],"lastId":7649224947,"id":7649224951,"ts":1784090311379}],"action":"update"}
{"channel":"book_lv2","data":[{"symbol":"BTC_USDT","createTime":1784090311358,"asks":[],"bids":[["64794.38","0"],["64746.12","0.130911"]],"lastId":7649224951,"id":7649224958,"ts":1784090311387}],"action":"update"}
{"channel":"book_lv2","data":[{"symbol":"BTC_USDT","createTime":1784090311365,"asks":[["64838.88","0.100364"],["64858.52","0"]],"bids":[],"lastId":7649224958,"id":7649224960,"ts":1784090311390}],"action":"update"}
{"channel":"book_lv2","data":[{"symbol":"BTC_USDT","createTime":1784090311378,"asks":[["64838.88","0"],["64858.52","7.716401"]],"bids":[],"lastId":7649224960,"id":7649224961,"ts":1784090311396}],"action":"update"}
{"channel":"book_lv2","data":[{"symbol":"BTC_USDT","createTime":1784090311390,"asks":[["64855.28","0"],["64860.47","7.716305"]],"bids":[],"lastId":7649224961,"id":7649224964,"ts":1784090311405}],"action":"update"}
{"channel":"book_lv2","data":[{"symbol":"BTC_USDT","createTime":1784090311390,"asks":[["64848.81","0"],["64863.64","0.107111"]],"bids":[],"lastId":7649224964,"id":7649224965,"ts":1784090311407}],"action":"update"}
{"channel":"book_lv2","data":[{"symbol":"BTC_USDT","createTime":1784090311390,"asks":[["64858.52","0"],["64864.04","0.180395"]],"bids":[],"lastId":7649224965,"id":7649224966,"ts":1784090311408}],"action":"update"}
{"channel":"book_lv2","data":[{"symbol":"BTC_USDT","createTime":1784090311391,"asks":[["64852.05","0"],["64870.52","0.073287"]],"bids":[],"lastId":7649224966,"id":7649224968,"ts":1784090311410}],"action":"update"}
{"channel":"book_lv2","data":[{"symbol":"BTC_USDT","createTime":1784090311474,"asks":[["64853.99","0.055761"]],"bids":[],"lastId":7649224968,"id":7649224971,"ts":1784090311487}],"action":"update"}
{"channel":"book_lv2","data":[{"symbol":"BTC_USDT","createTime":1784090311474,"asks":[["64844.27","0"],["64873.36","0.130913"]],"bids":[],"lastId":7649224971,"id":7649224972,"ts":1784090311488}],"action":"update"}
{"channel":"book_lv2","data":[{"symbol":"BTC_USDT","createTime":1784090311474,"asks":[["64850.75","0.030027"]],"bids":[],"lastId":7649224972,"id":7649224974,"ts":1784090311491}],"action":"update"}
{"channel":"book_lv2","data":[{"symbol":"BTC_USDT","createTime":1784090311476,"asks":[["64847.51","0"],["64873.76","0.154350"]],"bids":[],"lastId":7649224974,"id":7649224976,"ts":1784090311493}],"action":"update"}
{"channel":"book_lv2","data":[{"symbol":"BTC_USDT","createTime":1784090311499,"asks":[["64838.88","0.100364"],["64873.76","0"]],"bids":[],"lastId":7649224976,"id":7649224978,"ts":1784090311507}],"action":"update"}
{"channel":"book_lv2","data":[{"symbol":"BTC_USDT","createTime":1784090311502,"asks":[],"bids":[["64756.34","0.073285"]],"lastId":7649224978,"id":7649224981,"ts":1784090311513}],"action":"update"}
{"channel":"book_lv2","data":[{"symbol":"BTC_USDT","createTime":1784090311502,"asks":[],"bids":[["64797.18","0"],["64743.38","0.04247"]],"lastId":7649224981,"id":7649224982,"ts":1784090311515}],"action":"update"}
{"channel":"book_lv2","data":[{"symbol":"BTC_USDT","createTime":1784090311504,"asks":[],"bids":[["64806.9","0"],["64740.14","0.13091"]],"lastId":7649224982,"id":7649224984,"ts":1784090311518}],"action":"update"}
{"channel":"book_lv2","data":[{"symbol":"BTC_USDT","createTime":1784090311504,"asks":[],"bids":[["64746.62","0.180388"]],"lastId":7649224984,"id":7649224985,"ts":1784090311520}],"action":"update"}
{"channel":"book_lv2","data":[{"symbol":"BTC_USDT","createTime":1784090311505,"asks":[["64864.04","0.073287"]],"bids":[],"lastId":7649224985,"id":7649224988,"ts":1784090311523}],"action":"update"}
{"channel":"book_lv2","data":[{"symbol":"BTC_USDT","createTime":1784090311522,"asks":[],"bids":[["64794.41","0.091823"],["64740.14","0"]],"lastId":7649224988,"id":7649224989,"ts":1784090311536}],"action":"update"}
{"channel":"book_lv2","data":[{"symbol":"BTC_USDT","createTime":1784090311523,"asks":[["64838.88","0"],["64873.76","0.023437"]],"bids":[],"lastId":7649224989,"id":7649224990,"ts":1784090311537}],"action":"update"}
{"channel":"book_lv2","data":[{"symbol":"BTC_USDT","createTime":1784090311524,"asks":[["64865.66","0.285835"],["64873.76","0"]],"bids":[],"lastId":7649224990,"id":7649224991,"ts":1784090311538}],"action":"update"}
{"channel":"book_lv2","data":[{"symbol":"BTC_USDT","createTime":1784090311524,"asks":[],"bids":[["64784.67","0.04911"],["64743.38","0"]],"lastId":7649224991,"id":7649224992,"ts":1784090311539}],"action":"update"}
{"channel":"book_lv2","data":[{"symbol":"BTC_USDT","createTime":1784090311557,"asks":[["64872.14","0.231427"],["64873.36","0"]],"bids":[],"lastId":7649224992,"id":7649225000,"ts":1784090311574}],"action":"update"}
{"channel":"book_lv2","data":[{"symbol":"BTC_USDT","createTime":1784090311559,"asks":[["64859.17","0.231427"],["64872.14","0"]],"bids":[],"lastId":7649225000,"id":7649225001,"ts":1784090311575}],"action":"update"}
{"channel":"book_lv2","data":[{"symbol":"BTC_USDT","createTime":1784090311626,"asks":[["64838.88","0.100364"],["64870.52","0"]],"bids":[],"lastId":7649225001,"id":7649225004,"ts":1784090311640}],"action":"update"}
{"channel":"book_lv2","data":[{"symbol":"BTC_USDT","createTime":1784090311650,"asks":[["64838.88","0"],["64870.52","0.073287"]],"bids":[],"lastId":7649225004,"id":7649225005,"ts":1784090311662}],"action":"update"}
{"channel":"book_lv2","data":[{"symbol":"BTC_USDT","createTime":1784090311656,"asks":[["64865.66","0"],["64872.14","0.231427"]],"bids":[],"lastId":7649225005,"id":7649225006,"ts":1784090311669}],"action":"update"}
{"channel":"book_lv2","data":[{"symbol":"BTC_USDT","createTime":1784090311656,"asks":[["64859.17","0"],["64873.36","0.130913"]],"bids":[],"lastId":7649225006,"id":7649225009,"ts":1784090311673}],"action":"update"}
{"channel":"book_lv2","data":[{"symbol":"BTC_USDT","createTime":1784090311669,"asks":[["64858.53","7.716401"],["64873.36","0"]],"bids":[],"lastId":7649225009,"id":7649225016,"ts":1784090311686}],"action":"update"}
{"channel":"book_lv2","data":[{"symbol":"BTC_USDT","createTime":1784090311670,"asks":[["64855.29","0.103555"],["64872.14","0"]],"bids":[],"lastId":7649225016,"id":7649225017,"ts":1784090311687}],"action":"update"}
{"channel":"book_lv2","data":[{"symbol":"BTC_USDT","createTime":1784090311671,"asks":[["64852.05","0.055759"],["64870.52","0"]],"bids":[],"lastId":7649225017,"id":7649225019,"ts":1784090311690}],"action":"update"}
{"channel":"book_lv2","data":[{"symbol":"BTC_USDT","createTime":1784090311672,"asks":[["64848.81","0.030026"],["64864.04","0"]],"bids":[],"lastId":7649225019,"id":7649225022,"ts":1784090311695}],"action":"update"}
{"channel":"book_lv2","data":[{"symbol":"BTC_USDT","createTime":1784090311717,"asks":[["64838.88","0.100364"],["64863.64","0"]],"bids":[],"lastId":7649225022,"id":7649225024,"ts":1784090311728}],"action":"update"}
{"channel":"book_lv2","data":[{"symbol":"BTC_USDT","createTime":1784090311734,"asks":[["64838.88","0"],["64863.64","0.107111"]],"bids":[],"lastId":7649225024,"id":7649225025,"ts":1784090311751}],"action":"update"}
{"channel":"book_lv2","data":[{"symbol":"BTC_USDT","createTime":1784090311745,"asks":[["64850.75","0.040003"]],"bids":[],"lastId":7649225025,"id":7649225026,"ts":1784090311761}],"action":"update"}
{"channel":"book_lv2","data":[{"symbol":"BTC_USDT","createTime":1784090311752,"asks":[["64853.99","0.883859"]],"bids":[],"lastId":7649225026,"id":7649225030,"ts":1784090311770}],"action":"update"}
{"channel":"book_lv2","data":[{"symbol":"BTC_USDT","createTime":1784090311756,"asks":[["64844.27","0.003855"],["64863.64","0"]],"bids":[],"lastId":7649225030,"id":7649225033,"ts":1784090311773}],"action":"update"}
{"channel":"book_lv2","data":[{"symbol":"BTC_USDT","createTime":1784090311756,"asks":[["64847.51","0.005373"],["64860.47","0"]],"bids":[],"lastId":7649225033,"id":7649225035,"ts":1784090311776}],"action":"update"}
{"channel":"book_lv2","data":[{"symbol":"BTC_USDT","createTime":1784090311771,"asks":[],"bids":[["64802.9","0.219866"],["64746.12","0"]],"lastId":7649225035,"id":7649225040,"ts":1784090311784}],"action":"update"}
{"channel":"book_lv2","data":[{"symbol":"BTC_USDT","createTime":1784090311773,"asks":[],"bids":[["64793.18","0.225133"],["64746.62","0"]],"lastId":7649225040,"id":7649225041,"ts":1784090311785}],"action":"update"}
{"channel":"book_lv2","data":[{"symbol":"BTC_USDT","createTime":1784090311776,"asks":[],"bids":[["64752.34","0.107111"],["64749.86","0"]],"lastId":7649225041,"id":7649225043,"ts":1784090311788}],"action":"update"}
{"channel":"book_lv2","data":[{"symbol":"BTC_USDT","createTime":1784090311794,"asks":[["64838.88","0.100364"],["64858.53","0"]],"bids":[],"lastId":7649225043,"id":7649225047,"ts":1784090311808}],"action":"update"}
{"channel":"book_lv2","data":[{"symbol":"BTC_USDT","createTime":1784090311807,"asks":[["64838.88","0"],["64858.53","7.716401"]],"bids":[],"lastId":7649225047,"id":7649225051,"ts":1784090311822}],"action":"update"}
{"channel":"book_lv2","data":[{"symbol":"BTC_USDT","createTime":1784090311874,"asks":[["64838.88","0.100364"],["64858.53","0"]],"bids":[],"lastId":7649225051,"id":7649225052,"ts":1784090311885}],"action":"update"}
{"channel":"book_lv2","data":[{"symbol":"BTC_USDT","createTime":1784090311892,"asks":[["64838.88","0"],["64858.53","7.716401"]],"bids":[],"lastId":7649225052,"id":7649225053,"ts":1784090311909}],"action":"update"}
{"channel":"book_lv2","data":[{"symbol":"BTC_USDT","createTime":1784090311902,"asks":[],"bids":[["64784.68","0.051318"],["64752.34","0"]],"lastId":7649225053,"id":7649225054,"ts":1784090311919}],"action":"update"}
{"channel":"book_lv2","data":[{"symbol":"BTC_USDT","createTime":1784090311904,"asks":[],"bids":[["64794.37","0.108968"],["64755.84","0"]],"lastId":7649225054,"id":7649225055,"ts":1784090311921}],"action":"update"}
{"channel":"book_lv2","data":[{"symbol":"BTC_USDT","createTime":1784090311957,"asks":[],"bids":[["64774.91","0"],["64755.84","0.107108"]],"lastId":7649225055,"id":7649225083,"ts":1784090311983}],"action":"update"}
{"channel":"book_lv2","data":[{"symbol":"BTC_USDT","createTime":1784090311997,"asks":[["64838.88","0.100364"],["64858.53","0"]],"bids":[],"lastId":7649225083,"id":7649225086,"ts":1784090312004}],"action":"update"}
{"channel":"book_lv2","data":[{"symbol":"BTC_USDT","createTime":1784090312028,"asks":[["64838.88","0"],["64858.53","7.716401"]],"bids":[],"lastId":7649225086,"id":7649225087,"ts":1784090312038}],"action":"update"}
{"channel":"book_lv2","data":[{"symbol":"BTC_USDT","createTime":1784090312061,"asks":[],"bids":[["64774.96","2.991888"]],"lastId":7649225087,"id":7649225089,"ts":1784090312071}],"action":"update"}
{"channel":"book_lv2","data":[{"symbol":"BTC_USDT","createTime":1784090312109,"asks":[["64838.88","0.100364"],["64858.53","0"]],"bids":[],"lastId":7649225089,"id":7649225099,"ts":1784090312139}],"action":"update"}
{"channel":"book_lv2","data":[{"symbol":"BTC_USDT","createTime":1784090312157,"asks":[["64838.88","0"],["64858.53","7.716401"]],"bids":[],"lastId":7649225099,"id":7649225103,"ts":1784090312167}],"action":"update"}
{"channel":"book_lv2","data":[{"symbol":"BTC_USDT","createTime":1784090312193,"asks":[["64857.23","0"],["64859.17","0.231427"]],"bids":[],"lastId":7649225103,"id":7649225104,"ts":1784090312210}],"action":"update"}
{"channel":"book_lv2","data":[{"symbol":"BTC_USDT","createTime":1784090312193,"asks":[["64853.99","0.828098"]],"bids":[],"lastId":7649225104,"id":7649225105,"ts":1784090312211}],"action":"update"}
{"channel":"book_lv2","data":[{"symbol":"BTC_USDT","createTime":1784090312193,"asks":[["64850.75","0.009976"]],"bids":[],"lastId":7649225105,"id":7649225107,"ts":1784090312214}],"action":"update"}
{"channel":"book_lv2","data":[{"symbol":"BTC_USDT","createTime":1784090312221,"asks":[["64838.88","0.100364"],["64859.17","0"]],"bids":[],"lastId":7649225107,"id":7649225112,"ts":1784090312232}],"action":"update"}
{"channel":"book_lv2","data":[{"symbol":"BTC_USDT","createTime":1784090312238,"asks":[["64838.88","0"],["64859.17","0.231427"]],"bids":[],"lastId":7649225112,"id":7649225118,"ts":1784090312251}],"action":"update"}
{"channel":"book_lv2","data":[{"symbol":"BTC_USDT","createTime":1784090312257,"asks":[["64859.17","0"],["64860.04","0.107111"]],"bids":[],"lastId":7649225118,"id":7649225132,"ts":1784090312273}],"action":"update"}
{"channel":"book_lv2","data":[{"symbol":"BTC_USDT","createTime":1784090312304,"asks":[["64838.88","0.100364"],["64860.04","0"]],"bids":[],"lastId":7649225132,"id":7649225143,"ts":1784090312318}],"action":"update"}
{"channel":"book_lv2","data":[{"symbol":"BTC_USDT","createTime":1784090312320,"asks":[["64838.88","0"],["64860.04","0.107111"]],"bids":[],"lastId":7649225143,"id":7649225144,"ts":1784090312333}],"action":"update"}
{"channel":"book_lv2","data":[{"symbol":"BTC_USDT","createTime":1784090312378,"asks":[["64838.88","0.100364"],["64860.04","0"]],"bids":[],"lastId":7649225144,"id":7649225145,"ts":1784090312389}],"action":"update"}
{"channel":"book_lv2","data":[{"symbol":"BTC_USDT","createTime":1784090312394,"asks":[["64838.88","0"],["64860.04","0.107111"]],"bids":[],"lastId":7649225145,"id":7649225146,"ts":1784090312411}],"action":"update"}
{"channel":"book_lv2","data":[{"symbol":"BTC_USDT","createTime":1784090312465,"asks":[["64857.23","0.103554"],["64860.04","0"]],"bids":[],"lastId":7649225146,"id":7649225147,"ts":1784090312481}],"action":"update"}
{"channel":"book_lv2","data":[{"symbol":"BTC_USDT","createTime":1784090312471,"asks":[["64850.75","0.040002"]],"bids":[],"lastId":7649225147,"id":7649225151,"ts":1784090312486}],"action":"update"}
{"channel":"book_lv2","data":[{"symbol":"BTC_USDT","createTime":1784090312473,"asks":[["64853.99","0.883857"]],"bids":[],"lastId":7649225151,"id":7649225152,"ts":1784090312493}],"action":"update"}
{"channel":"book_lv2","data":[{"symbol":"BTC_USDT","createTime":1784090312479,"asks":[],"bids":[["64756.34","0"],["64752.34","0.107111"]],"lastId":7649225152,"id":7649225158,"ts":1784090312505}],"action":"update"}
{"channel":"book_lv2","data":[{"symbol":"BTC_USDT","createTime":1784090312499,"asks":[["64838.88","0.100364"],["64858.53","0"]],"bids":[],"lastId":7649225158,"id":7649225162,"ts":1784090312517}],"action":"update"}
{"channel":"book_lv2","data":[{"symbol":"BTC_USDT","createTime":1784090312513,"asks":[["64838.88","0"],["64858.53","7.716401"]],"bids":[],"lastId":7649225162,"id":7649225163,"ts":1784090312528}],"action":"update"}
{"channel":"trades","data":[{"symbol":"BTC_USDT","amount":"2599.94896506","quantity":"0.040113","takerSide":"sell","createTime":1784090312545,"price":"64815.62","id":"225823479","ts":1784090312552}]}
{"channel":"trades","data":[{"symbol":"BTC_USDT","amount":"2599.94896506","quantity":"0.040113","takerSide":"sell","createTime":1784090312545,"price":"64815.62","id":"225823480","ts":1784090312552}]}
{"channel":"book_lv2","data":[{"symbol":"BTC_USDT","createTime":1784090312543,"asks":[],"bids":[["64815.62","0.040113"],["64752.34","0"]],"lastId":7649225163,"id":7649225164,"ts":1784090312554}],"action":"update"}
{"channel":"book_lv2","data":[{"symbol":"BTC_USDT","createTime":1784090312545,"asks":[],"bids":[["64815.62","0.080226"]],"lastId":7649225164,"id":7649225165,"ts":1784090312555}],"action":"update"}
{"channel":"book_lv2","data":[{"symbol":"BTC_USDT","createTime":1784090312545,"asks":[],"bids":[["64815.62","0.040113"]],"lastId":7649225165,"id":7649225166,"ts":1784090312556}],"action":"update"}
{"channel":"book_lv2","data":[{"symbol":"BTC_USDT","createTime":1784090312545,"asks":[],"bids":[["64815.62","0"],["64752.34","0.107111"]],"lastId":7649225166,"id":7649225167,"ts":1784090312557}],"action":"update"}
{"channel":"book_lv2","data":[{"symbol":"BTC_USDT","createTime":1784090312546,"asks":[],"bids":[["64755.84","0"],["64742.62","0.238023"]],"lastId":7649225167,"id":7649225171,"ts":1784090312563}],"action":"update"}
{"channel":"book_lv2","data":[{"symbol":"BTC_USDT","createTime":1784090312568,"asks":[],"bids":[["64774.97","0"],["64736.14","0.130912"]],"lastId":7649225171,"id":7649225174,"ts":1784090312585}],"action":"update"}
