{"channel":"l2_data","timestamp":"2026-07-15T03:40:04.962730179Z","sequence_num":30,"events":[{"type":"update","product_id":"BTC-USD","updates":[{"side":"bid","event_time":"2026-07-15T03:40:04.855626Z","price_level":"64591.36","new_quantity":"0"},{"side":"bid","event_time":"2026-07-15T03:40:04.855626Z","price_level":"64586","new_quantity":"0"},{"side":"bid","event_time":"2026-07-15T03:40:04.855626Z","price_level":"64584.42","new_quantity":"0"},{"side":"bid","event_time":"2026-07-15T03:40:04.855626Z","price_level":"64583.26","new_quantity":"0"},{"side":"bid","event_time":"2026-07-15T03:40:04.855626Z","price_level":"64582","new_quantity":"0.0257"},{"side":"bid","event_time":"2026-07-15T03:40:04.855626Z","price_level":"64577.98","new_quantity":"0.04656107"},{"side":"bid","event_time":"2026-07-15T03:40:04.855626Z","price_level":"64577.97","new_quantity":"0"},{"side":"bid","event_time":"2026-07-15T03:40:04.855626Z","price_level":"64577.61","new_quantity":"0.12388194"},{"side":"bid","event_time":"2026-07-15T03:40:04.855626Z","price_level":"64577.27","new_quantity":"0"},{"side":"bid","event_time":"2026-07-15T03:40:04.855626Z","price_level":"64577.26","new_quantity":"0"},{"side":"bid","event_time":"2026-07-15T03:40:04.855626Z","price_level":"64577.25","new_quantity":"0"},{"side":"bid","event_time":"2026-07-15T03:40:04.855626Z","price_level":"64576.61","new_quantity":"0.15485481"},{"side":"bid","event_time":"2026-07-15T03:40:04.855626Z","price_level":"64573.68","new_quantity":"0"},{"side":"bid","event_time":"2026-07-15T03:40:04.855626Z","price_level":"64573.66","new_quantity":"0"},{"side":"bid","event_time":"2026-07-15T03:40:04.855626Z","price_level":"64572.38","new_quantity":"0.12378505"},{"side":"bid","event_time":"2026-07-15T03:40:04.855626Z","price_level":"64572","new_quantity":"0"},{"side":"bid","event_time":"2026-07-15T03:40:04.855626Z","price_level":"64571.62","new_quantity":"0"},{"side":"bid","event_time":"2026-07-15T03:40:04.855626Z","price_level":"64571.23","new_quantity":"0"},{"side":"bid","event_time":"2026-07-15T03:40:04.855626Z","price_level":"64570.42","new_quantity":"0.00029931"},{"side":"bid","event_time":"2026-07-15T03:40:04.855626Z","price_level":"64570.35","new_quantity":"0.03093532"},{"side":"bid","event_time":"2026-07-15T03:40:04.855626Z","price_level":"64570.14","new_quantity":"0.00077406"},{"side":"bid","event_time":"2026-07-15T03:40:04.855626Z","price_level":"64569.65","new_quantity":"0"},{"side":"bid","event_time":"2026-07-15T03:40:04.855626Z","price_level":"64568.36","new_quantity":"0.00059861"},{"side":"bid","event_time":"2026-07-15T03:40:04.855626Z","price_level":"64567.17","new_quantity":"0.12378505"},{"side":"bid","event_time":"2026-07-15T03:40:04.855626Z","price_level":"64566.23","new_quantity":"0"},{"side":"bid","event_time":"2026-07-15T03:40:04.855626Z","price_level":"64565.61","new_quantity":"0"},{"side":"bid","event_time":"2026-07-15T03:40:04.855626Z","price_level":"64563.47","new_quantity":"0"},{"side":"bid","event_time":"2026-07-15T03:40:04.855626Z","price_level":"64563.29","new_quantity":"0.12378505"},{"side":"bid","event_time":"2026-07-15T03:40:04.855626Z","price_level":"64562.58","new_quantity":"0"},{"side":"bid","event_time":"2026-07-15T03:40:04.855626Z","price_level":"64562.36","new_quantity":"0"},{"side":"bid","event_time":"2026-07-15T03:40:04.855626Z","price_level":"64561.93","new_quantity":"0.00772597"},{"side":"bid","event_time":"2026-07-15T03:40:04.855626Z","price_level":"64561.14","new_quantity":"0"},{"side":"bid","event_time":"2026-07-15T03:40:04.855626Z","price_level":"64560.61","new_quantity":"0.12378505"},{"side":"bid","event_time":"2026-07-15T03:40:04.855626Z","price_level":"64560.6","new_quantity":"0"},{"side":"bid","event_time":"2026-07-15T03:40:04.855626Z","price_level":"64560.27","new_quantity":"0"},{"side":"bid","event_time":"2026-07-15T03:40:04.855626Z","price_level":"64559.8","new_quantity":"0.93152649"},{"side":"bid","event_time":"2026-07-15T03:40:04.855626Z","price_level":"64558.19","new_quantity":"0"},{"side":"bid","event_time":"2026-07-15T03:40:04.855626Z","price_level":"64553.44","new_quantity":"0.034861"},{"side":"bid","event_time":"2026-07-15T03:40:04.855626Z","price_level":"64550.8","new_quantity":"0"},{"side":"bid","event_time":"2026-07-15T03:40:04.855626Z","price_level":"64550.7","new_quantity":"0.12378505"},{"side":"bid","event_time":"2026-07-15T03:40:04.855626Z","price_level":"64546.82","new_quantity":"0.12378505"},{"side":"bid","event_time":"2026-07-15T03:40:04.855626Z","price_level":"64545.72","new_quantity":"0.00299307"},{"side":"bid","event_time":"2026-07-15T03:40:04.855626Z","price_level":"64542.94","new_quantity":"0.12378505"},{"side":"bid","event_time":"2026-07-15T03:40:04.855626Z","price_level":"64540.1","new_quantity":"0.448637"},{"side":"bid","event_time":"2026-07-15T03:40:04.855626Z","price_level":"64529.99","new_quantity":"0"},{"side":"bid","event_time":"2026-07-15T03:40:04.855626Z","price_level":"64529.84","new_quantity":"0"},{"side":"bid","event_time":"2026-07-15T03:40:04.855626Z","price_level":"64529.16","new_quantity":"0"},{"side":"bid","event_time":"2026-07-15T03:40:04.855626Z","price_level":"64527.21","new_quantity":"0"},{"side":"bid","event_time":"2026-07-15T03:40:04.855626Z","price_level":"64522.06","new_quantity":"0.03093532"},{"side":"bid","event_time":"2026-07-15T03:40:04.855626Z","price_level":"64522.04","new_quantity":"0"},{"side":"bid","event_time":"2026-07-15T03:40:04.855626Z","price_level":"64510.01","new_quantity":"0"},{"side":"bid","event_time":"2026-07-15T03:40:04.855626Z","price_level":"64502.57","new_quantity":"2.15504247"},{"side":"bid","event_time":"2026-07-15T03:40:04.855626Z","price_level":"64499.4","new_quantity":"0.00748267"},{"side":"bid","event_time":"2026-07-15T03:40:04.855626Z","price_level":"64468.52","new_quantity":"0.00897921"},{"side":"bid","event_time":"2026-07-15T03:40:04.855626Z","price_level":"64355.86","new_quantity":"0.01"},{"side":"bid","event_time":"2026-07-15T03:40:04.855626Z","price_level":"64310.36","new_quantity":"1.39946342"},{"side":"bid","event_time":"2026-07-15T03:40:04.855626Z","price_level":"64230.8","new_quantity":"0"},{"side":"bid","event_time":"2026-07-15T03:40:04.855626Z","price_level":"64192.03","new_quantity":"0.46450975"},{"side":"bid","event_time":"2026-07-15T03:40:04.855626Z","price_level":"56517.64","new_quantity":"0"},{"side":"offer","event_time":"2026-07-15T03:40:04.855626Z","price_level":"64588","new_quantity":"0.0257"},{"side":"offer","event_time":"2026-07-15T03:40:04.855626Z","price_level":"64590.37","new_quantity":"0.0334"},{"side":"offer","event_time":"2026-07-15T03:40:04.855626Z","price_level":"64591.36","new_quantity":"0.0667662"},{"side":"offer","event_time":"2026-07-15T03:40:04.855626Z","price_level":"64591.37","new_quantity":"0.34368424"},{"side":"offer","event_time":"2026-07-15T03:40:04.855626Z","price_level":"64591.8","new_quantity":"0.00774094"},{"side":"offer","event_time":"2026-07-15T03:40:04.855626Z","price_level":"64591.81","new_quantity":"0.14657171"},{"side":"offer","event_time":"2026-07-15T03:40:04.855626Z","price_level":"64592.56","new_quantity":"0"},{"side":"offer","event_time":"2026-07-15T03:40:04.855626Z","price_level":"64595.04","new_quantity":"0.12378505"},{"side":"offer","event_time":"2026-07-15T03:40:04.855626Z","price_level":"64595.6","new_quantity":"0.00967618"},{"side":"offer","event_time":"2026-07-15T03:40:04.855626Z","price_level":"64595.78","new_quantity":"0"},{"side":"offer","event_time":"2026-07-15T03:40:04.855626Z","price_level":"64597.27","new_quantity":"0.00772597"},{"side":"offer","event_time":"2026-07-15T03:40:04.855626Z","price_level":"64598.73","new_quantity":"0.12378505"},{"side":"offer","event_time":"2026-07-15T03:40:04.855626Z","price_level":"64599.37","new_quantity":"0.07326"},{"side":"offer","event_time":"2026-07-15T03:40:04.855626Z","price_level":"64600.66","new_quantity":"0"},{"side":"offer","event_time":"2026-07-15T03:40:04.855626Z","price_level":"64601.4","new_quantity":"0.05418743"},{"side":"offer","event_time":"2026-07-15T03:40:04.855626Z","price_level":"64604.41","new_quantity":"0.00153313"},{"side":"offer","event_time":"2026-07-15T03:40:04.855626Z","price_level":"64607.07","new_quantity":"0"},{"side":"offer","event_time":"2026-07-15T03:40:04.855626Z","price_level":"64609.38","new_quantity":"0.06631824"},{"side":"offer","event_time":"2026-07-15T03:40:04.855626Z","price_level":"64609.75","new_quantity":"0.2488876"},{"side":"offer","event_time":"2026-07-15T03:40:04.855626Z","price_level":"64610.26","new_quantity":"0"},{"side":"offer","event_time":"2026-07-15T03:40:04.855626Z","price_level":"64613.45","new_quantity":"0"},{"side":"offer","event_time":"2026-07-15T03:40:04.855626Z","price_level":"64616.64","new_quantity":"0"},{"side":"offer","event_time":"2026-07-15T03:40:04.855626Z","price_level":"64616.76","new_quantity":"0.00306626"},{"side":"offer","event_time":"2026-07-15T03:40:04.855626Z","price_level":"64619.41","new_quantity":"0.06804739"},{"side":"offer","event_time":"2026-07-15T03:40:04.855626Z","price_level":"64619.83","new_quantity":"0"},{"side":"offer","event_time":"2026-07-15T03:40:04.855626Z","price_level":"64619.87","new_quantity":"0"},{"side":"offer","event_time":"2026-07-15T03:40:04.855626Z","price_level":"64622.64","new_quantity":"0.35147335"},{"side":"offer","event_time":"2026-07-15T03:40:04.855626Z","price_level":"64622.65","new_quantity":"0.49634033"},{"side":"offer","event_time":"2026-07-15T03:40:04.855626Z","price_level":"64623.02","new_quantity":"0"},{"side":"offer","event_time":"2026-07-15T03:40:04.855626Z","price_level":"64625.97","new_quantity":"0"},{"side":"offer","event_time":"2026-07-15T03:40:04.855626Z","price_level":"64626.21","new_quantity":"0"},{"side":"offer","event_time":"2026-07-15T03:40:04.855626Z","price_level":"64627.87","new_quantity":"0"},{"side":"offer","event_time":"2026-07-15T03:40:04.855626Z","price_level":"64628.31","new_quantity":"0.04626534"},{"side":"offer","event_time":"2026-07-15T03:40:04.855626Z","price_level":"64628.77","new_quantity":"0.06652002"},{"side":"offer","event_time":"2026-07-15T03:40:04.855626Z","price_level":"64629.4","new_quantity":"0"},{"side":"offer","event_time":"2026-07-15T03:40:04.855626Z","price_level":"64632.59","new_quantity":"0"},{"side":"offer","event_time":"2026-07-15T03:40:04.855626Z","price_level":"64635.78","new_quantity":"0"},{"side":"offer","event_time":"2026-07-15T03:40:04.855626Z","price_level":"64638.97","new_quantity":"0"},{"side":"offer","event_time":"2026-07-15T03:40:04.855626Z","price_level":"64641","new_quantity":"1"},{"side":"offer","event_time":"2026-07-15T03:40:04.855626Z","price_level":"64643.93","new_quantity":"0.9989771"},{"side":"offer","event_time":"2026-07-15T03:40:04.855626Z","price_level":"64643.94","new_quantity":"1.62351659"},{"side":"offer","event_time":"2026-07-15T03:40:04.855626Z","price_level":"64643.95","new_quantity":"0"},{"side":"offer","event_time":"2026-07-15T03:40:04.855626Z","price_level":"64649.13","new_quantity":"0.9011001"},{"side":"offer","event_time":"2026-07-15T03:40:04.855626Z","price_level":"64649.14","new_quantity":"0"},{"side":"offer","event_time":"2026-07-15T03:40:04.855626Z","price_level":"64649.99","new_quantity":"0"},{"side":"offer","event_time":"2026-07-15T03:40:04.855626Z","price_level":"64650.46","new_quantity":"0.00077406"},{"side":"offer","event_time":"2026-07-15T03:40:04.855626Z","price_level":"64654.63","new_quantity":"0"},{"side":"offer","event_time":"2026-07-15T03:40:04.855626Z","price_level":"64655.79","new_quantity":"0"},{"side":"offer","event_time":"2026-07-15T03:40:04.855626Z","price_level":"64664.78","new_quantity":"0.00766564"},{"side":"offer","event_time":"2026-07-15T03:40:04.855626Z","price_level":"64668.4","new_quantity":"0.01331"},{"side":"offer","event_time":"2026-07-15T03:40:04.855626Z","price_level":"64676.1","new_quantity":"0"},{"side":"offer","event_time":"2026-07-15T03:40:04.855626Z","price_level":"64692.97","new_quantity":"0.04798094"},{"side":"offer","event_time":"2026-07-15T03:40:04.855626Z","price_level":"64704.95","new_quantity":"0.00958205"},{"side":"offer","event_time":"2026-07-15T03:40:04.855626Z","price_level":"64816.92","new_quantity":"0.01"},{"side":"offer","event_time":"2026-07-15T03:40:04.855626Z","price_level":"64966.98","new_quantity":"0.46450975"},{"side":"offer","event_time":"2026-07-15T03:40:04.855626Z","price_level":"65006.34","new_quantity":"0"}]}]}
{"channel":"l2_data","timestamp":"2026-07-15T03:40:05.140282974Z","sequence_num":31,"events":[{"type":"update","product_id":"BTC-USD","updates":[{"side":"bid","event_time":"2026-07-15T03:40:04.905431Z","price_level":"64587.68","new_quantity":"0"},{"side":"bid","event_time":"2026-07-15T03:40:04.905431Z","price_level":"64584.43","new_quantity":"0"},{"side":"bid","event_time":"2026-07-15T03:40:04.905431Z","price_level":"64584","new_quantity":"0.000018"},{"side":"bid","event_time":"2026-07-15T03:40:04.905431Z","price_level":"64580","new_quantity":"0.0245"},{"side":"bid","event_time":"2026-07-15T03:40:04.905431Z","price_level":"64578.7","new_quantity":"0"},{"side":"bid","event_time":"2026-07-15T03:40:04.905431Z","price_level":"64577.61","new_quantity":"0"},{"side":"bid","event_time":"2026-07-15T03:40:04.905431Z","price_level":"64577.27","new_quantity":"0.03093532"},{"side":"bid","event_time":"2026-07-15T03:40:04.905431Z","price_level":"64576.61","new_quantity":"0"},{"side":"bid","event_time":"2026-07-15T03:40:04.905431Z","price_level":"64575.54","new_quantity":"0.1238859"},{"side":"bid","event_time":"2026-07-15T03:40:04.905431Z","price_level":"64574.81","new_quantity":"0.12378505"},{"side":"bid","event_time":"2026-07-15T03:40:04.905431Z","price_level":"64573.76","new_quantity":"0"},{"side":"bid","event_time":"2026-07-15T03:40:04.905431Z","price_level":"64573.3","new_quantity":"0.02"},{"side":"bid","event_time":"2026-07-15T03:40:04.905431Z","price_level":"64570.14","new_quantity":"0"},{"side":"bid","event_time":"2026-07-15T03:40:04.905431Z","price_level":"64567.18","new_quantity":"0.0984207"},{"side":"bid","event_time":"2026-07-15T03:40:04.905431Z","price_level":"64561.99","new_quantity":"0.00119723"},{"side":"bid","event_time":"2026-07-15T03:40:04.905431Z","price_level":"64560.18","new_quantity":"0.14"},{"side":"bid","event_time":"2026-07-15T03:40:04.905431Z","price_level":"64559.81","new_quantity":"0"},{"side":"bid","event_time":"2026-07-15T03:40:04.905431Z","price_level":"64559.8","new_quantity":"0"},{"side":"bid","event_time":"2026-07-15T03:40:04.905431Z","price_level":"64559.79","new_quantity":"0"},{"side":"bid","event_time":"2026-07-15T03:40:04.905431Z","price_level":"64556.57","new_quantity":"0.07389967"},{"side":"bid","event_time":"2026-07-15T03:40:04.905431Z","price_level":"64556.15","new_quantity":"0.00077406"},{"side":"bid","event_time":"2026-07-15T03:40:04.905431Z","price_level":"64554.69","new_quantity":"0"},{"side":"bid","event_time":"2026-07-15T03:40:04.905431Z","price_level":"64554.68","new_quantity":"0"},{"side":"bid","event_time":"2026-07-15T03:40:04.905431Z","price_level":"64554.16","new_quantity":"0.93160788"},{"side":"bid","event_time":"2026-07-15T03:40:04.905431Z","price_level":"64552.84","new_quantity":"0"},{"side":"bid","event_time":"2026-07-15T03:40:04.905431Z","price_level":"64552.77","new_quantity":"0.04301271"},{"side":"bid","event_time":"2026-07-15T03:40:04.905431Z","price_level":"64550.71","new_quantity":"0.07482699"},{"side":"bid","event_time":"2026-07-15T03:40:04.905431Z","price_level":"64548.26","new_quantity":"0.60979812"},{"side":"bid","event_time":"2026-07-15T03:40:04.905431Z","price_level":"64548.25","new_quantity":"0.11069106"},{"side":"bid","event_time":"2026-07-15T03:40:04.905431Z","price_level":"64544.34","new_quantity":"0.04719266"},{"side":"bid","event_time":"2026-07-15T03:40:04.905431Z","price_level":"64542.94","new_quantity":"0"},{"side":"bid","event_time":"2026-07-15T03:40:04.905431Z","price_level":"64540.11","new_quantity":"0.26878821"},{"side":"bid","event_time":"2026-07-15T03:40:04.905431Z","price_level":"64529.58","new_quantity":"0"},{"side":"bid","event_time":"2026-07-15T03:40:04.905431Z","price_level":"64525.18","new_quantity":"0"},{"side":"bid","event_time":"2026-07-15T03:40:04.905431Z","price_level":"64523.43","new_quantity":"0.00510637"},{"side":"bid","event_time":"2026-07-15T03:40:04.905431Z","price_level":"64522.67","new_quantity":"0"},{"side":"bid","event_time":"2026-07-15T03:40:04.905431Z","price_level":"64522.06","new_quantity":"1.02181314"},{"side":"bid","event_time":"2026-07-15T03:40:04.905431Z","price_level":"64522.02","new_quantity":"0"},{"side":"bid","event_time":"2026-07-15T03:40:04.905431Z","price_level":"64508.38","new_quantity":"0"},{"side":"bid","event_time":"2026-07-15T03:40:04.905431Z","price_level":"64506.47","new_quantity":"0.001858"},{"side":"bid","event_time":"2026-07-15T03:40:04.905431Z","price_level":"64495","new_quantity":"0"},{"side":"bid","event_time":"2026-07-15T03:40:04.905431Z","price_level":"64328.21","new_quantity":"0"},{"side":"bid","event_time":"2026-07-15T03:40:04.905431Z","price_level":"64288.42","new_quantity":"50.522538"},{"side":"offer","event_time":"2026-07-15T03:40:04.905431Z","price_level":"64586","new_quantity":"0.0245"},{"side":"offer","event_time":"2026-07-15T03:40:04.905431Z","price_level":"64587","new_quantity":"0.0334"},{"side":"offer","event_time":"2026-07-15T03:40:04.905431Z","price_level":"64587.68","new_quantity":"0.03175423"},{"side":"offer","event_time":"2026-07-15T03:40:04.905431Z","price_level":"64587.69","new_quantity":"0.24377565"},{"side":"offer","event_time":"2026-07-15T03:40:04.905431Z","price_level":"64587.99","new_quantity":"0"},{"side":"offer","event_time":"2026-07-15T03:40:04.905431Z","price_level":"64588","new_quantity":"0.0257"},{"side":"offer","event_time":"2026-07-15T03:40:04.905431Z","price_level":"64589.61","new_quantity":"0.00774139"},{"side":"offer","event_time":"2026-07-15T03:40:04.905431Z","price_level":"64590","new_quantity":"0.0257"},{"side":"offer","event_time":"2026-07-15T03:40:04.905431Z","price_level":"64590.37","new_quantity":"0"},{"side":"offer","event_time":"2026-07-15T03:40:04.905431Z","price_level":"64591.34","new_quantity":"0"},{"side":"offer","event_time":"2026-07-15T03:40:04.905431Z","price_level":"64591.36","new_quantity":"0"},{"side":"offer","event_time":"2026-07-15T03:40:04.905431Z","price_level":"64591.37","new_quantity":"0"},{"side":"offer","event_time":"2026-07-15T03:40:04.905431Z","price_level":"64591.48","new_quantity":"0.12385535"},{"side":"offer","event_time":"2026-07-15T03:40:04.905431Z","price_level":"64591.78","new_quantity":"0.12378505"},{"side":"offer","event_time":"2026-07-15T03:40:04.905431Z","price_level":"64591.79","new_quantity":"0.00967674"},{"side":"offer","event_time":"2026-07-15T03:40:04.905431Z","price_level":"64591.8","new_quantity":"0"},{"side":"offer","event_time":"2026-07-15T03:40:04.905431Z","price_level":"64591.81","new_quantity":"0.022717"},{"side":"offer","event_time":"2026-07-15T03:40:04.905431Z","price_level":"64592.98","new_quantity":"0"},{"side":"offer","event_time":"2026-07-15T03:40:04.905431Z","price_level":"64593.42","new_quantity":"0"},{"side":"offer","event_time":"2026-07-15T03:40:04.905431Z","price_level":"64593.53","new_quantity":"0"},{"side":"offer","event_time":"2026-07-15T03:40:04.905431Z","price_level":"64593.99","new_quantity":"0.00772597"},{"side":"offer","event_time":"2026-07-15T03:40:04.905431Z","price_level":"64595.01","new_quantity":"0.15472037"},{"side":"offer","event_time":"2026-07-15T03:40:04.905431Z","price_level":"64595.02","new_quantity":"0"},{"side":"offer","event_time":"2026-07-15T03:40:04.905431Z","price_level":"64595.04","new_quantity":"0"},{"side":"offer","event_time":"2026-07-15T03:40:04.905431Z","price_level":"64595.56","new_quantity":"0.07326"},{"side":"offer","event_time":"2026-07-15T03:40:04.905431Z","price_level":"64595.6","new_quantity":"0"},{"side":"offer","event_time":"2026-07-15T03:40:04.905431Z","price_level":"64597.27","new_quantity":"0"},{"side":"offer","event_time":"2026-07-15T03:40:04.905431Z","price_level":"64597.28","new_quantity":"0"},{"side":"offer","event_time":"2026-07-15T03:40:04.905431Z","price_level":"64597.55","new_quantity":"0.00100849"},{"side":"offer","event_time":"2026-07-15T03:40:04.905431Z","price_level":"64597.59","new_quantity":"0"},{"side":"offer","event_time":"2026-07-15T03:40:04.905431Z","price_level":"64598.73","new_quantity":"0"},{"side":"offer","event_time":"2026-07-15T03:40:04.905431Z","price_level":"64600.67","new_quantity":"0"},{"side":"offer","event_time":"2026-07-15T03:40:04.905431Z","price_level":"64600.73","new_quantity":"0.12378505"},{"side":"offer","event_time":"2026-07-15T03:40:04.905431Z","price_level":"64603.54","new_quantity":"0.03093532"},{"side":"offer","event_time":"2026-07-15T03:40:04.905431Z","price_level":"64603.55","new_quantity":"0.09734139"},{"side":"offer","event_time":"2026-07-15T03:40:04.905431Z","price_level":"64603.56","new_quantity":"0.04656107"},{"side":"offer","event_time":"2026-07-15T03:40:04.905431Z","price_level":"64604.57","new_quantity":"0.12378505"},{"side":"offer","event_time":"2026-07-15T03:40:04.905431Z","price_level":"64606.5","new_quantity":"0.16712422"},{"side":"offer","event_time":"2026-07-15T03:40:04.905431Z","price_level":"64606.77","new_quantity":"0.00077411"},{"side":"offer","event_time":"2026-07-15T03:40:04.905431Z","price_level":"64607.93","new_quantity":"0.14"},{"side":"offer","event_time":"2026-07-15T03:40:04.905431Z","price_level":"64609.79","new_quantity":"0"},{"side":"offer","event_time":"2026-07-15T03:40:04.905431Z","price_level":"64610","new_quantity":"0"},{"side":"offer","event_time":"2026-07-15T03:40:04.905431Z","price_level":"64610.08","new_quantity":"0.00592"},{"side":"offer","event_time":"2026-07-15T03:40:04.905431Z","price_level":"64612","new_quantity":"0"},{"side":"offer","event_time":"2026-07-15T03:40:04.905431Z","price_level":"64618.66","new_quantity":"0.49634033"},{"side":"offer","event_time":"2026-07-15T03:40:04.905431Z","price_level":"64619.41","new_quantity":"0.03793203"},{"side":"offer","event_time":"2026-07-15T03:40:04.905431Z","price_level":"64620.43","new_quantity":"0.12378505"},{"side":"offer","event_time":"2026-07-15T03:40:04.905431Z","price_level":"64621.38","new_quantity":"0"},{"side":"offer","event_time":"2026-07-15T03:40:04.905431Z","price_level":"64622.65","new_quantity":"0"},{"side":"offer","event_time":"2026-07-15T03:40:04.905431Z","price_level":"64628.31","new_quantity":"0.08006286"},{"side":"offer","event_time":"2026-07-15T03:40:04.905431Z","price_level":"64634.42","new_quantity":"0"},{"side":"offer","event_time":"2026-07-15T03:40:04.905431Z","price_level":"64636.32","new_quantity":"0.00158694"},{"side":"offer","event_time":"2026-07-15T03:40:04.905431Z","price_level":"64638.78","new_quantity":"0"},{"side":"offer","event_time":"2026-07-15T03:40:04.905431Z","price_level":"64638.79","new_quantity":"0.83182468"},{"side":"offer","event_time":"2026-07-15T03:40:04.905431Z","price_level":"64639.37","new_quantity":"0"},{"side":"offer","event_time":"2026-07-15T03:40:04.905431Z","price_level":"64641","new_quantity":"0"},{"side":"offer","event_time":"2026-07-15T03:40:04.905431Z","price_level":"64643.94","new_quantity":"1.62274259"},{"side":"offer","event_time":"2026-07-15T03:40:04.905431Z","price_level":"64646.46","new_quantity":"0"},{"side":"offer","event_time":"2026-07-15T03:40:04.905431Z","price_level":"64649.12","new_quantity":"1.41200301"},{"side":"offer","event_time":"2026-07-15T03:40:04.905431Z","price_level":"64649.98","new_quantity":"0"},{"side":"offer","event_time":"2026-07-15T03:40:04.905431Z","price_level":"64658.11","new_quantity":"0"},{"side":"offer","event_time":"2026-07-15T03:40:04.905431Z","price_level":"64695","new_quantity":"0"},{"side":"offer","event_time":"2026-07-15T03:40:04.905431Z","price_level":"64725.97","new_quantity":"0"},{"side":"offer","event_time":"2026-07-15T03:40:04.905431Z","price_level":"64805.23","new_quantity":"14.307383"},{"side":"offer","event_time":"2026-07-15T03:40:04.905431Z","price_level":"64871.55","new_quantity":"0"}]}]}
{"channel":"l2_data","timestamp":"2026-07-15T03:40:05.188534195Z","sequence_num":32,"events":[{"type":"update","product_id":"BTC-USD","updates":[{"side":"bid","event_time":"2026-07-15T03:40:05.137348Z","price_level":"64584","new_quantity":"0"},{"side":"bid","event_time":"2026-07-15T03:40:05.137348Z","price_level":"64582","new_quantity":"0"},{"side":"bid","event_time":"2026-07-15T03:40:05.137348Z","price_level":"64581.95","new_quantity":"0.0077421"},{"side":"bid","event_time":"2026-07-15T03:40:05.137348Z","price_level":"64581.55","new_quantity":"0.0015533"},{"side":"bid","event_time":"2026-07-15T03:40:05.137348Z","price_level":"64580","new_quantity":"0"},{"side":"bid","event_time":"2026-07-15T03:40:05.137348Z","price_level":"64578.36","new_quantity":"0.0015533"},{"side":"bid","event_time":"2026-07-15T03:40:05.137348Z","price_level":"64578.08","new_quantity":"0"},{"side":"bid","event_time":"2026-07-15T03:40:05.137348Z","price_level":"64578","new_quantity":"0.0245"},{"side":"bid","event_time":"2026-07-15T03:40:05.137348Z","price_level":"64577.7","new_quantity":"0"},{"side":"bid","event_time":"2026-07-15T03:40:05.137348Z","price_level":"64577.28","new_quantity":"0.02"},{"side":"bid","event_time":"2026-07-15T03:40:05.137348Z","price_level":"64577.27","new_quantity":"0"},{"side":"bid","event_time":"2026-07-15T03:40:05.137348Z","price_level":"64576.5","new_quantity":"1"},{"side":"bid","event_time":"2026-07-15T03:40:05.137348Z","price_level":"64575.6","new_quantity":"0.02"},{"side":"bid","event_time":"2026-07-15T03:40:05.137348Z","price_level":"64575.55","new_quantity":"0.03093532"},{"side":"bid","event_time":"2026-07-15T03:40:05.137348Z","price_level":"64575.54","new_quantity":"0"},{"side":"bid","event_time":"2026-07-15T03:40:05.137348Z","price_level":"64575.17","new_quantity":"0.0015533"},{"side":"bid","event_time":"2026-07-15T03:40:05.137348Z","price_level":"64575.15","new_quantity":"0"},{"side":"bid","event_time":"2026-07-15T03:40:05.137348Z","price_level":"64574.81","new_quantity":"0"},{"side":"bid","event_time":"2026-07-15T03:40:05.137348Z","price_level":"64573.9","new_quantity":"0"},{"side":"bid","event_time":"2026-07-15T03:40:05.137348Z","price_level":"64573.45","new_quantity":"0"},{"side":"bid","event_time":"2026-07-15T03:40:05.137348Z","price_level":"64573.3","new_quantity":"0"},{"side":"bid","event_time":"2026-07-15T03:40:05.137348Z","price_level":"64572.99","new_quantity":"0"},{"side":"bid","event_time":"2026-07-15T03:40:05.137348Z","price_level":"64572.81","new_quantity":"0.10867832"},{"side":"bid","event_time":"2026-07-15T03:40:05.137348Z","price_level":"64572.8","new_quantity":"0.12389116"},{"side":"bid","event_time":"2026-07-15T03:40:05.137348Z","price_level":"64572.38","new_quantity":"0"},{"side":"bid","event_time":"2026-07-15T03:40:05.137348Z","price_level":"64572.17","new_quantity":"0"},{"side":"bid","event_time":"2026-07-15T03:40:05.137348Z","price_level":"64572.02","new_quantity":"0"},{"side":"bid","event_time":"2026-07-15T03:40:05.137348Z","price_level":"64571.98","new_quantity":"0.0015533"},{"side":"bid","event_time":"2026-07-15T03:40:05.137348Z","price_level":"64570.37","new_quantity":"0.13312877"},{"side":"bid","event_time":"2026-07-15T03:40:05.137348Z","price_level":"64570.36","new_quantity":"0.03093532"},{"side":"bid","event_time":"2026-07-15T03:40:05.137348Z","price_level":"64570.35","new_quantity":"0"},{"side":"bid","event_time":"2026-07-15T03:40:05.137348Z","price_level":"64570.34","new_quantity":"0.15486985"},{"side":"bid","event_time":"2026-07-15T03:40:05.137348Z","price_level":"64570","new_quantity":"0"},{"side":"bid","event_time":"2026-07-15T03:40:05.137348Z","price_level":"64569.53","new_quantity":"0"},{"side":"bid","event_time":"2026-07-15T03:40:05.137348Z","price_level":"64568.79","new_quantity":"0.0015533"},{"side":"bid","event_time":"2026-07-15T03:40:05.137348Z","price_level":"64567.59","new_quantity":"0.048285"},{"side":"bid","event_time":"2026-07-15T03:40:05.137348Z","price_level":"64567.18","new_quantity":"0"},{"side":"bid","event_time":"2026-07-15T03:40:05.137348Z","price_level":"64567.17","new_quantity":"0"},{"side":"bid","event_time":"2026-07-15T03:40:05.137348Z","price_level":"64565.6","new_quantity":"0.0015713"},{"side":"bid","event_time":"2026-07-15T03:40:05.137348Z","price_level":"64565.53","new_quantity":"0"},{"side":"bid","event_time":"2026-07-15T03:40:05.137348Z","price_level":"64565.3","new_quantity":"0.09236806"},{"side":"bid","event_time":"2026-07-15T03:40:05.137348Z","price_level":"64565.29","new_quantity":"0.12378505"},{"side":"bid","event_time":"2026-07-15T03:40:05.137348Z","price_level":"64565.03","new_quantity":"0"},{"side":"bid","event_time":"2026-07-15T03:40:05.137348Z","price_level":"64563.95","new_quantity":"0.0245"},{"side":"bid","event_time":"2026-07-15T03:40:05.137348Z","price_level":"64563.29","new_quantity":"0"},{"side":"bid","event_time":"2026-07-15T03:40:05.137348Z","price_level":"64563.28","new_quantity":"0.00772597"},{"side":"bid","event_time":"2026-07-15T03:40:05.137348Z","price_level":"64563.27","new_quantity":"0.07923813"},{"side":"bid","event_time":"2026-07-15T03:40:05.137348Z","price_level":"64563.26","new_quantity":"0.12378505"},{"side":"bid","event_time":"2026-07-15T03:40:05.137348Z","price_level":"64562.41","new_quantity":"0.0015533"},{"side":"bid","event_time":"2026-07-15T03:40:05.137348Z","price_level":"64562","new_quantity":"0"},{"side":"bid","event_time":"2026-07-15T03:40:05.137348Z","price_level":"64561.93","new_quantity":"0"},{"side":"bid","event_time":"2026-07-15T03:40:05.137348Z","price_level":"64561.48","new_quantity":"0.04835571"},{"side":"bid","event_time":"2026-07-15T03:40:05.137348Z","price_level":"64560.61","new_quantity":"0"},{"side":"bid","event_time":"2026-07-15T03:40:05.137348Z","price_level":"64560.58","new_quantity":"0.23785167"},{"side":"bid","event_time":"2026-07-15T03:40:05.137348Z","price_level":"64560.57","new_quantity":"0.12378505"},{"side":"bid","event_time":"2026-07-15T03:40:05.137348Z","price_level":"64560.28","new_quantity":"0"},{"side":"bid","event_time":"2026-07-15T03:40:05.137348Z","price_level":"64560.19","new_quantity":"0"},{"side":"bid","event_time":"2026-07-15T03:40:05.137348Z","price_level":"64560.18","new_quantity":"0"},{"side":"bid","event_time":"2026-07-15T03:40:05.137348Z","price_level":"64559.48","new_quantity":"0"},{"side":"bid","event_time":"2026-07-15T03:40:05.137348Z","price_level":"64559.22","new_quantity":"0.0015533"},{"side":"bid","event_time":"2026-07-15T03:40:05.137348Z","price_level":"64559.07","new_quantity":"0.00583"},{"side":"bid","event_time":"2026-07-15T03:40:05.137348Z","price_level":"64558.64","new_quantity":"0.00583"},{"side":"bid","event_time":"2026-07-15T03:40:05.137348Z","price_level":"64558.61","new_quantity":"0"},{"side":"bid","event_time":"2026-07-15T03:40:05.137348Z","price_level":"64557.69","new_quantity":"0"},{"side":"bid","event_time":"2026-07-15T03:40:05.137348Z","price_level":"64557.25","new_quantity":"0"},{"side":"bid","event_time":"2026-07-15T03:40:05.137348Z","price_level":"64556.71","new_quantity":"0"},{"side":"bid","event_time":"2026-07-15T03:40:05.137348Z","price_level":"64556.57","new_quantity":"0.07467376"},{"side":"bid","event_time":"2026-07-15T03:40:05.137348Z","price_level":"64556.15","new_quantity":"0"},{"side":"bid","event_time":"2026-07-15T03:40:05.137348Z","price_level":"64556.03","new_quantity":"0.0015533"},{"side":"bid","event_time":"2026-07-15T03:40:05.137348Z","price_level":"64554.59","new_quantity":"0.16592872"},{"side":"bid","event_time":"2026-07-15T03:40:05.137348Z","price_level":"64554.25","new_quantity":"0.00239446"},{"side":"bid","event_time":"2026-07-15T03:40:05.137348Z","price_level":"64554.16","new_quantity":"0"},{"side":"bid","event_time":"2026-07-15T03:40:05.137348Z","price_level":"64554.12","new_quantity":"0"},{"side":"bid","event_time":"2026-07-15T03:40:05.137348Z","price_level":"64553.04","new_quantity":"0"},{"side":"bid","event_time":"2026-07-15T03:40:05.137348Z","price_level":"64552.85","new_quantity":"0"},{"side":"bid","event_time":"2026-07-15T03:40:05.137348Z","price_level":"64552.84","new_quantity":"0.0015533"},{"side":"bid","event_time":"2026-07-15T03:40:05.137348Z","price_level":"64552.77","new_quantity":"0"},{"side":"bid","event_time":"2026-07-15T03:40:05.137348Z","price_level":"64552","new_quantity":"0.00003194"},{"side":"bid","event_time":"2026-07-15T03:40:05.137348Z","price_level":"64551.86","new_quantity":"0"},{"side":"bid","event_time":"2026-07-15T03:40:05.137348Z","price_level":"64551.01","new_quantity":"0.07437255"},{"side":"bid","event_time":"2026-07-15T03:40:05.137348Z","price_level":"64551","new_quantity":"0"},{"side":"bid","event_time":"2026-07-15T03:40:05.137348Z","price_level":"64550.71","new_quantity":"0"},{"side":"bid","event_time":"2026-07-15T03:40:05.137348Z","price_level":"64549.66","new_quantity":"0"},{"side":"bid","event_time":"2026-07-15T03:40:05.137348Z","price_level":"64549.65","new_quantity":"0.0015533"},{"side":"bid","event_time":"2026-07-15T03:40:05.137348Z","price_level":"64548.28","new_quantity":"0.67111568"},{"side":"bid","event_time":"2026-07-15T03:40:05.137348Z","price_level":"64548.27","new_quantity":"0.93169289"},{"side":"bid","event_time":"2026-07-15T03:40:05.137348Z","price_level":"64548.26","new_quantity":"0"},{"side":"bid","event_time":"2026-07-15T03:40:05.137348Z","price_level":"64548.25","new_quantity":"0"},{"side":"bid","event_time":"2026-07-15T03:40:05.137348Z","price_level":"64546.46","new_quantity":"0.0015533"},{"side":"bid","event_time":"2026-07-15T03:40:05.137348Z","price_level":"64545.01","new_quantity":"0.48516387"},{"side":"bid","event_time":"2026-07-15T03:40:05.137348Z","price_level":"64545","new_quantity":"0"},{"side":"bid","event_time":"2026-07-15T03:40:05.137348Z","price_level":"64544.5","new_quantity":"0.0005"},{"side":"bid","event_time":"2026-07-15T03:40:05.137348Z","price_level":"64544.36","new_quantity":"0"},{"side":"bid","event_time":"2026-07-15T03:40:05.137348Z","price_level":"64544.35","new_quantity":"0.60983506"},{"side":"bid","event_time":"2026-07-15T03:40:05.137348Z","price_level":"64544.34","new_quantity":"0"},{"side":"bid","event_time":"2026-07-15T03:40:05.137348Z","price_level":"64542.94","new_quantity":"0.12378505"},{"side":"bid","event_time":"2026-07-15T03:40:05.137348Z","price_level":"64539.06","new_quantity":"0.12378505"},{"side":"bid","event_time":"2026-07-15T03:40:05.137348Z","price_level":"64536.96","new_quantity":"0"},{"side":"bid","event_time":"2026-07-15T03:40:05.137348Z","price_level":"64536.47","new_quantity":"0.04626534"},{"side":"bid","event_time":"2026-07-15T03:40:05.137348Z","price_level":"64533.26","new_quantity":"0.00154736"},{"side":"bid","event_time":"2026-07-15T03:40:05.137348Z","price_level":"64533.17","new_quantity":"0"},{"side":"bid","event_time":"2026-07-15T03:40:05.137348Z","price_level":"64529.99","new_quantity":"0.06389177"},{"side":"bid","event_time":"2026-07-15T03:40:05.137348Z","price_level":"64527.32","new_quantity":"0.0015533"},{"side":"bid","event_time":"2026-07-15T03:40:05.137348Z","price_level":"64526.81","new_quantity":"0.00773683"},{"side":"bid","event_time":"2026-07-15T03:40:05.137348Z","price_level":"64524.13","new_quantity":"0.0015533"},{"side":"bid","event_time":"2026-07-15T03:40:05.137348Z","price_level":"64523.43","new_quantity":"0"},{"side":"bid","event_time":"2026-07-15T03:40:05.137348Z","price_level":"64523.22","new_quantity":"0"},{"side":"bid","event_time":"2026-07-15T03:40:05.137348Z","price_level":"64522.06","new_quantity":"0.03093532"},{"side":"bid","event_time":"2026-07-15T03:40:05.137348Z","price_level":"64522.05","new_quantity":"0"},{"side":"bid","event_time":"2026-07-15T03:40:05.137348Z","price_level":"64521.9","new_quantity":"0"},{"side":"bid","event_time":"2026-07-15T03:40:05.137348Z","price_level":"64521.26","new_quantity":"0"},{"side":"bid","event_time":"2026-07-15T03:40:05.137348Z","price_level":"64521.22","new_quantity":"0.00510654"},{"side":"bid","event_time":"2026-07-15T03:40:05.137348Z","price_level":"64520.94","new_quantity":"0.0015533"},{"side":"bid","event_time":"2026-07-15T03:40:05.137348Z","price_level":"64519.76","new_quantity":"0.14210937"},{"side":"bid","event_time":"2026-07-15T03:40:05.137348Z","price_level":"64519.35","new_quantity":"0.00598614"},{"side":"bid","event_time":"2026-07-15T03:40:05.137348Z","price_level":"64515.96","new_quantity":"0"},{"side":"bid","event_time":"2026-07-15T03:40:05.137348Z","price_level":"64515.95","new_quantity":"0.83924051"},{"side":"bid","event_time":"2026-07-15T03:40:05.137348Z","price_level":"64512.53","new_quantity":"1.09789055"},{"side":"bid","event_time":"2026-07-15T03:40:05.137348Z","price_level":"64512.52","new_quantity":"1.34961982"},{"side":"bid","event_time":"2026-07-15T03:40:05.137348Z","price_level":"64512.51","new_quantity":"0"},{"side":"bid","event_time":"2026-07-15T03:40:05.137348Z","price_level":"64508.39","new_quantity":"0"},{"side":"bid","event_time":"2026-07-15T03:40:05.137348Z","price_level":"64503.1","new_quantity":"0"},{"side":"bid","event_time":"2026-07-15T03:40:05.137348Z","price_level":"64502.58","new_quantity":"2.86937154"},{"side":"bid","event_time":"2026-07-15T03:40:05.137348Z","price_level":"64502.57","new_quantity":"0"},{"side":"bid","event_time":"2026-07-15T03:40:05.137348Z","price_level":"64502.56","new_quantity":"0"},{"side":"bid","event_time":"2026-07-15T03:40:05.137348Z","price_level":"64500.32","new_quantity":"0.2999"},{"side":"bid","event_time":"2026-07-15T03:40:05.137348Z","price_level":"64500","new_quantity":"3.11110077"},{"side":"bid","event_time":"2026-07-15T03:40:05.137348Z","price_level":"64499.18","new_quantity":"0"},{"side":"bid","event_time":"2026-07-15T03:40:05.137348Z","price_level":"64499.17","new_quantity":"0"},{"side":"bid","event_time":"2026-07-15T03:40:05.137348Z","price_level":"64497.11","new_quantity":"0.00807752"},{"side":"bid","event_time":"2026-07-15T03:40:05.137348Z","price_level":"64489.27","new_quantity":"2.17866484"},{"side":"bid","event_time":"2026-07-15T03:40:05.137348Z","price_level":"64481.7","new_quantity":"0.00348385"},{"side":"bid","event_time":"2026-07-15T03:40:05.137348Z","price_level":"64468.32","new_quantity":"0.00268902"},{"side":"bid","event_time":"2026-07-15T03:40:05.137348Z","price_level":"64463.81","new_quantity":"0"},{"side":"bid","event_time":"2026-07-15T03:40:05.137348Z","price_level":"64462.24","new_quantity":"0.00002323"},{"side":"bid","event_time":"2026-07-15T03:40:05.137348Z","price_level":"64454.86","new_quantity":"0.04394965"},{"side":"bid","event_time":"2026-07-15T03:40:05.137348Z","price_level":"64452.4","new_quantity":"0.03030967"},{"side":"bid","event_time":"2026-07-15T03:40:05.137348Z","price_level":"64450.7","new_quantity":"0.03476688"},{"side":"bid","event_time":"2026-07-15T03:40:05.137348Z","price_level":"64394.35","new_quantity":"0"},{"side":"bid","event_time":"2026-07-15T03:40:05.137348Z","price_level":"64385.28","new_quantity":"0.000018"},{"side":"bid","event_time":"2026-07-15T03:40:05.137348Z","price_level":"64377.53","new_quantity":"0"},{"side":"bid","event_time":"2026-07-15T03:40:05.137348Z","price_level":"64344.02","new_quantity":"0.00583"},{"side":"bid","event_time":"2026-07-15T03:40:05.137348Z","price_level":"64343.98","new_quantity":"0"},{"side":"bid","event_time":"2026-07-15T03:40:05.137348Z","price_level":"64343.96","new_quantity":"0"},{"side":"bid","event_time":"2026-07-15T03:40:05.137348Z","price_level":"64343.84","new_quantity":"0"},{"side":"bid","event_time":"2026-07-15T03:40:05.137348Z","price_level":"64296.83","new_quantity":"3.645726"},{"side":"bid","event_time":"2026-07-15T03:40:05.137348Z","price_level":"64212","new_quantity":"0.01557341"},{"side":"bid","event_time":"2026-07-15T03:40:05.137348Z","price_level":"64129.75","new_quantity":"0"},{"side":"bid","event_time":"2026-07-15T03:40:05.137348Z","price_level":"64129.38","new_quantity":"0.00583"},{"side":"bid","event_time":"2026-07-15T03:40:05.137348Z","price_level":"64128.83","new_quantity":"0"},{"side":"bid","event_time":"2026-07-15T03:40:05.137348Z","price_level":"64128.39","new_quantity":"0"},{"side":"bid","event_time":"2026-07-15T03:40:05.137348Z","price_level":"64128.24","new_quantity":"0.01937554"},{"side":"bid","event_time":"2026-07-15T03:40:05.137348Z","price_level":"64080.84","new_quantity":"0.00015578"},{"side":"bid","event_time":"2026-07-15T03:40:05.137348Z","price_level":"63955.21","new_quantity":"0"},{"side":"bid","event_time":"2026-07-15T03:40:05.137348Z","price_level":"63915.35","new_quantity":"0.00583"},{"side":"bid","event_time":"2026-07-15T03:40:05.137348Z","price_level":"63915.12","new_quantity":"0"},{"side":"bid","event_time":"2026-07-15T03:40:05.137348Z","price_level":"63915.1","new_quantity":"0"},{"side":"bid","event_time":"2026-07-15T03:40:05.137348Z","price_level":"63914.98","new_quantity":"0"},{"side":"bid","event_time":"2026-07-15T03:40:05.137348Z","price_level":"63740.76","new_quantity":"0"},{"side":"bid","event_time":"2026-07-15T03:40:05.137348Z","price_level":"63700.52","new_quantity":"0.00583"},{"side":"bid","event_time":"2026-07-15T03:40:05.137348Z","price_level":"63526.22","new_quantity":"0"},{"side":"bid","event_time":"2026-07-15T03:40:05.137348Z","price_level":"63486.49","new_quantity":"0.00583"},{"side":"bid","event_time":"2026-07-15T03:40:05.137348Z","price_level":"63486.26","new_quantity":"0"},{"side":"bid","event_time":"2026-07-15T03:40:05.137348Z","price_level":"63486.06","new_quantity":"0"},{"side":"bid","event_time":"2026-07-15T03:40:05.137348Z","price_level":"63306.59","new_quantity":"0"},{"side":"bid","event_time":"2026-07-15T03:40:05.137348Z","price_level":"63271.63","new_quantity":"0"},{"side":"bid","event_time":"2026-07-15T03:40:05.137348Z","price_level":"63058.06","new_quantity":"0.00583"},{"side":"bid","event_time":"2026-07-15T03:40:05.137348Z","price_level":"63057.2","new_quantity":"0"},{"side":"bid","event_time":"2026-07-15T03:40:05.137348Z","price_level":"56510.35","new_quantity":"0.0132912"},{"side":"bid","event_time":"2026-07-15T03:40:05.137348Z","price_level":"51673.09","new_quantity":"0.0002"},{"side":"offer","event_time":"2026-07-15T03:40:05.137348Z","price_level":"64583.26","new_quantity":"0.21424533"},{"side":"offer","event_time":"2026-07-15T03:40:05.137348Z","price_level":"64584","new_quantity":"0.03224189"},{"side":"offer","event_time":"2026-07-15T03:40:05.137348Z","price_level":"64584.01","new_quantity":"0"},{"side":"offer","event_time":"2026-07-15T03:40:05.137348Z","price_level":"64584.26","new_quantity":"0.09781853"},{"side":"offer","event_time":"2026-07-15T03:40:05.137348Z","price_level":"64584.27","new_quantity":"0"},{"side":"offer","event_time":"2026-07-15T03:40:05.137348Z","price_level":"64584.43","new_quantity":"0"},{"side":"offer","event_time":"2026-07-15T03:40:05.137348Z","price_level":"64584.44","new_quantity":"0"},{"side":"offer","event_time":"2026-07-15T03:40:05.137348Z","price_level":"64584.56","new_quantity":"0.00774179"},{"side":"offer","event_time":"2026-07-15T03:40:05.137348Z","price_level":"64585.62","new_quantity":"0.00774189"},{"side":"offer","event_time":"2026-07-15T03:40:05.137348Z","price_level":"64585.68","new_quantity":"0.12386646"},{"side":"offer","event_time":"2026-07-15T03:40:05.137348Z","price_level":"64586","new_quantity":"0.0245"},{"side":"offer","event_time":"2026-07-15T03:40:05.137348Z","price_level":"64587","new_quantity":"0"},{"side":"offer","event_time":"2026-07-15T03:40:05.137348Z","price_level":"64587.67","new_quantity":"0"},{"side":"offer","event_time":"2026-07-15T03:40:05.137348Z","price_level":"64587.68","new_quantity":"0.06413355"},{"side":"offer","event_time":"2026-07-15T03:40:05.137348Z","price_level":"64587.69","new_quantity":"0"},{"side":"offer","event_time":"2026-07-15T03:40:05.137348Z","price_level":"64587.8","new_quantity":"0.00967737"},{"side":"offer","event_time":"2026-07-15T03:40:05.137348Z","price_level":"64587.93","new_quantity":"0.0015533"},{"side":"offer","event_time":"2026-07-15T03:40:05.137348Z","price_level":"64587.98","new_quantity":"0.03093532"},{"side":"offer","event_time":"2026-07-15T03:40:05.137348Z","price_level":"64587.99","new_quantity":"0"},{"side":"offer","event_time":"2026-07-15T03:40:05.137348Z","price_level":"64589.16","new_quantity":"0.048285"},{"side":"offer","event_time":"2026-07-15T03:40:05.137348Z","price_level":"64589.61","new_quantity":"0"},{"side":"offer","event_time":"2026-07-15T03:40:05.137348Z","price_level":"64590.3","new_quantity":"0.00038328"},{"side":"offer","event_time":"2026-07-15T03:40:05.137348Z","price_level":"64591.12","new_quantity":"0.0015533"},{"side":"offer","event_time":"2026-07-15T03:40:05.137348Z","price_level":"64591.33","new_quantity":"0.15514271"},{"side":"offer","event_time":"2026-07-15T03:40:05.137348Z","price_level":"64591.36","new_quantity":"0.000018"},{"side":"offer","event_time":"2026-07-15T03:40:05.137348Z","price_level":"64591.48","new_quantity":"0"},{"side":"offer","event_time":"2026-07-15T03:40:05.137348Z","price_level":"64591.77","new_quantity":"0"},{"side":"offer","event_time":"2026-07-15T03:40:05.137348Z","price_level":"64591.79","new_quantity":"0"},{"side":"offer","event_time":"2026-07-15T03:40:05.137348Z","price_level":"64591.8","new_quantity":"0.07326"},{"side":"offer","event_time":"2026-07-15T03:40:05.137348Z","price_level":"64591.99","new_quantity":"0.00772597"},{"side":"offer","event_time":"2026-07-15T03:40:05.137348Z","price_level":"64593.39","new_quantity":"0.00076656"},{"side":"offer","event_time":"2026-07-15T03:40:05.137348Z","price_level":"64593.54","new_quantity":"0.12305386"},{"side":"offer","event_time":"2026-07-15T03:40:05.137348Z","price_level":"64593.74","new_quantity":"0"},{"side":"offer","event_time":"2026-07-15T03:40:05.137348Z","price_level":"64593.99","new_quantity":"0"},{"side":"offer","event_time":"2026-07-15T03:40:05.137348Z","price_level":"64594.05","new_quantity":"0"},{"side":"offer","event_time":"2026-07-15T03:40:05.137348Z","price_level":"64594.31","new_quantity":"0.0015533"},{"side":"offer","event_time":"2026-07-15T03:40:05.137348Z","price_level":"64594.57","new_quantity":"0"},{"side":"offer","event_time":"2026-07-15T03:40:05.137348Z","price_level":"64595.03","new_quantity":"0"},{"side":"offer","event_time":"2026-07-15T03:40:05.137348Z","price_level":"64595.19","new_quantity":"0.00100854"},{"side":"offer","event_time":"2026-07-15T03:40:05.137348Z","price_level":"64595.56","new_quantity":"0"},{"side":"offer","event_time":"2026-07-15T03:40:05.137348Z","price_level":"64597.5","new_quantity":"0.0015533"},{"side":"offer","event_time":"2026-07-15T03:40:05.137348Z","price_level":"64597.55","new_quantity":"0"},{"side":"offer","event_time":"2026-07-15T03:40:05.137348Z","price_level":"64597.65","new_quantity":"0"},{"side":"offer","event_time":"2026-07-15T03:40:05.137348Z","price_level":"64597.95","new_quantity":"0.04313986"},{"side":"offer","event_time":"2026-07-15T03:40:05.137348Z","price_level":"64597.96","new_quantity":"0.04656107"},{"side":"offer","event_time":"2026-07-15T03:40:05.137348Z","price_level":"64599.36","new_quantity":"0"},{"side":"offer","event_time":"2026-07-15T03:40:05.137348Z","price_level":"64599.37","new_quantity":"0"},{"side":"offer","event_time":"2026-07-15T03:40:05.137348Z","price_level":"64600.37","new_quantity":"0.00583"},{"side":"offer","event_time":"2026-07-15T03:40:05.137348Z","price_level":"64600.69","new_quantity":"0.0015533"},{"side":"offer","event_time":"2026-07-15T03:40:05.137348Z","price_level":"64600.72","new_quantity":"0.12182129"},{"side":"offer","event_time":"2026-07-15T03:40:05.137348Z","price_level":"64602.95","new_quantity":"0"},{"side":"offer","event_time":"2026-07-15T03:40:05.137348Z","price_level":"64603.27","new_quantity":"0.04314479"},{"side":"offer","event_time":"2026-07-15T03:40:05.137348Z","price_level":"64603.41","new_quantity":"0.00077418"},{"side":"offer","event_time":"2026-07-15T03:40:05.137348Z","price_level":"64603.49","new_quantity":"0.77183623"},{"side":"offer","event_time":"2026-07-15T03:40:05.137348Z","price_level":"64603.5","new_quantity":"1"},{"side":"offer","event_time":"2026-07-15T03:40:05.137348Z","price_level":"64603.55","new_quantity":"0"},{"side":"offer","event_time":"2026-07-15T03:40:05.137348Z","price_level":"64603.88","new_quantity":"0.0015533"},{"side":"offer","event_time":"2026-07-15T03:40:05.137348Z","price_level":"64606","new_quantity":"0"},{"side":"offer","event_time":"2026-07-15T03:40:05.137348Z","price_level":"64606.04","new_quantity":"0"},{"side":"offer","event_time":"2026-07-15T03:40:05.137348Z","price_level":"64606.49","new_quantity":"0.24862324"},{"side":"offer","event_time":"2026-07-15T03:40:05.137348Z","price_level":"64606.5","new_quantity":"0"},{"side":"offer","event_time":"2026-07-15T03:40:05.137348Z","price_level":"64606.77","new_quantity":"0"},{"side":"offer","event_time":"2026-07-15T03:40:05.137348Z","price_level":"64607.07","new_quantity":"0.0015533"},{"side":"offer","event_time":"2026-07-15T03:40:05.137348Z","price_level":"64608","new_quantity":"0"},{"side":"offer","event_time":"2026-07-15T03:40:05.137348Z","price_level":"64609.75","new_quantity":"0.58086254"},{"side":"offer","event_time":"2026-07-15T03:40:05.137348Z","price_level":"64610.26","new_quantity":"0.0015533"},{"side":"offer","event_time":"2026-07-15T03:40:05.137348Z","price_level":"64610.34","new_quantity":"0.06"},{"side":"offer","event_time":"2026-07-15T03:40:05.137348Z","price_level":"64611.14","new_quantity":"0.01647578"},{"side":"offer","event_time":"2026-07-15T03:40:05.137348Z","price_level":"64612.22","new_quantity":"0.63853705"},{"side":"offer","event_time":"2026-07-15T03:40:05.137348Z","price_level":"64613.05","new_quantity":"0"},{"side":"offer","event_time":"2026-07-15T03:40:05.137348Z","price_level":"64613.06","new_quantity":"0"},{"side":"offer","event_time":"2026-07-15T03:40:05.137348Z","price_level":"64613.07","new_quantity":"0"},{"side":"offer","event_time":"2026-07-15T03:40:05.137348Z","price_level":"64613.42","new_quantity":"0.10877345"},{"side":"offer","event_time":"2026-07-15T03:40:05.137348Z","price_level":"64613.45","new_quantity":"0.0015533"},{"side":"offer","event_time":"2026-07-15T03:40:05.137348Z","price_level":"64616.49","new_quantity":"0.00104515"},{"side":"offer","event_time":"2026-07-15T03:40:05.137348Z","price_level":"64616.64","new_quantity":"0.0015533"},{"side":"offer","event_time":"2026-07-15T03:40:05.137348Z","price_level":"64617.27","new_quantity":"0.01939241"},{"side":"offer","event_time":"2026-07-15T03:40:05.137348Z","price_level":"64618.66","new_quantity":"0"},{"side":"offer","event_time":"2026-07-15T03:40:05.137348Z","price_level":"64619","new_quantity":"0.00003194"},{"side":"offer","event_time":"2026-07-15T03:40:05.137348Z","price_level":"64619.41","new_quantity":"0.10698217"},{"side":"offer","event_time":"2026-07-15T03:40:05.137348Z","price_level":"64619.83","new_quantity":"0.0015533"},{"side":"offer","event_time":"2026-07-15T03:40:05.137348Z","price_level":"64622.59","new_quantity":"0"},{"side":"offer","event_time":"2026-07-15T03:40:05.137348Z","price_level":"64622.64","new_quantity":"0.05423085"},{"side":"offer","event_time":"2026-07-15T03:40:05.137348Z","price_level":"64623.02","new_quantity":"0.0015533"},{"side":"offer","event_time":"2026-07-15T03:40:05.137348Z","price_level":"64624.12","new_quantity":"0.00077413"},{"side":"offer","event_time":"2026-07-15T03:40:05.137348Z","price_level":"64624.13","new_quantity":"0"},{"side":"offer","event_time":"2026-07-15T03:40:05.137348Z","price_level":"64626.21","new_quantity":"0.0015533"},{"side":"offer","event_time":"2026-07-15T03:40:05.137348Z","price_level":"64629.19","new_quantity":"0.02726552"},{"side":"offer","event_time":"2026-07-15T03:40:05.137348Z","price_level":"64629.4","new_quantity":"0.0015533"},{"side":"offer","event_time":"2026-07-15T03:40:05.137348Z","price_level":"64630.5","new_quantity":"0"},{"side":"offer","event_time":"2026-07-15T03:40:05.137348Z","price_level":"64631.12","new_quantity":"0.00383282"},{"side":"offer","event_time":"2026-07-15T03:40:05.137348Z","price_level":"64631.82","new_quantity":"0"},{"side":"offer","event_time":"2026-07-15T03:40:05.137348Z","price_level":"64632.59","new_quantity":"0.0015533"},{"side":"offer","event_time":"2026-07-15T03:40:05.137348Z","price_level":"64633.52","new_quantity":"1.18432764"},{"side":"offer","event_time":"2026-07-15T03:40:05.137348Z","price_level":"64633.53","new_quantity":"1.43146722"},{"side":"offer","event_time":"2026-07-15T03:40:05.137348Z","price_level":"64633.54","new_quantity":"0"},{"side":"offer","event_time":"2026-07-15T03:40:05.137348Z","price_level":"64633.78","new_quantity":"0"},{"side":"offer","event_time":"2026-07-15T03:40:05.137348Z","price_level":"64635.17","new_quantity":"0.45865736"},{"side":"offer","event_time":"2026-07-15T03:40:05.137348Z","price_level":"64635.78","new_quantity":"0.0015533"},{"side":"offer","event_time":"2026-07-15T03:40:05.137348Z","price_level":"64636","new_quantity":"0"},{"side":"offer","event_time":"2026-07-15T03:40:05.137348Z","price_level":"64636.26","new_quantity":"0"},{"side":"offer","event_time":"2026-07-15T03:40:05.137348Z","price_level":"64636.27","new_quantity":"0"},{"side":"offer","event_time":"2026-07-15T03:40:05.137348Z","price_level":"64636.28","new_quantity":"0.0212865"},{"side":"offer","event_time":"2026-07-15T03:40:05.137348Z","price_level":"64638.79","new_quantity":"0.10993027"},{"side":"offer","event_time":"2026-07-15T03:40:05.137348Z","price_level":"64638.97","new_quantity":"0.0015533"},{"side":"offer","event_time":"2026-07-15T03:40:05.137348Z","price_level":"64640.45","new_quantity":"0"},{"side":"offer","event_time":"2026-07-15T03:40:05.137348Z","price_level":"64640.99","new_quantity":"0"},{"side":"offer","event_time":"2026-07-15T03:40:05.137348Z","price_level":"64641.43","new_quantity":"0.00077409"},{"side":"offer","event_time":"2026-07-15T03:40:05.137348Z","price_level":"64643.91","new_quantity":"1.26066345"},{"side":"offer","event_time":"2026-07-15T03:40:05.137348Z","price_level":"64643.92","new_quantity":"2.02636415"},{"side":"offer","event_time":"2026-07-15T03:40:05.137348Z","price_level":"64643.93","new_quantity":"0"},{"side":"offer","event_time":"2026-07-15T03:40:05.137348Z","price_level":"64643.94","new_quantity":"0"},{"side":"offer","event_time":"2026-07-15T03:40:05.137348Z","price_level":"64643.96","new_quantity":"0"},{"side":"offer","event_time":"2026-07-15T03:40:05.137348Z","price_level":"64648.53","new_quantity":"0.00077411"},{"side":"offer","event_time":"2026-07-15T03:40:05.137348Z","price_level":"64649.11","new_quantity":"0.0278077"},{"side":"offer","event_time":"2026-07-15T03:40:05.137348Z","price_level":"64649.12","new_quantity":"0"},{"side":"offer","event_time":"2026-07-15T03:40:05.137348Z","price_level":"64649.13","new_quantity":"0"},{"side":"offer","event_time":"2026-07-15T03:40:05.137348Z","price_level":"64650.46","new_quantity":"0"},{"side":"offer","event_time":"2026-07-15T03:40:05.137348Z","price_level":"64651.73","new_quantity":"0"},{"side":"offer","event_time":"2026-07-15T03:40:05.137348Z","price_level":"64654.92","new_quantity":"0"},{"side":"offer","event_time":"2026-07-15T03:40:05.137348Z","price_level":"64658.1","new_quantity":"0"},{"side":"offer","event_time":"2026-07-15T03:40:05.137348Z","price_level":"64658.78","new_quantity":"0"},{"side":"offer","event_time":"2026-07-15T03:40:05.137348Z","price_level":"64661.12","new_quantity":"0"},{"side":"offer","event_time":"2026-07-15T03:40:05.137348Z","price_level":"64664.47","new_quantity":"0"},{"side":"offer","event_time":"2026-07-15T03:40:05.137348Z","price_level":"64685","new_quantity":"3"},{"side":"offer","event_time":"2026-07-15T03:40:05.137348Z","price_level":"64690","new_quantity":"0"},{"side":"offer","event_time":"2026-07-15T03:40:05.137348Z","price_level":"64690.72","new_quantity":"0"},{"side":"offer","event_time":"2026-07-15T03:40:05.137348Z","price_level":"64692.97","new_quantity":"0"},{"side":"offer","event_time":"2026-07-15T03:40:05.137348Z","price_level":"64695","new_quantity":"0"},{"side":"offer","event_time":"2026-07-15T03:40:05.137348Z","price_level":"64747.72","new_quantity":"0.01149846"},{"side":"offer","event_time":"2026-07-15T03:40:05.137348Z","price_level":"64760.98","new_quantity":"0"},{"side":"offer","event_time":"2026-07-15T03:40:05.137348Z","price_level":"64814.95","new_quantity":"0.00583"},{"side":"offer","event_time":"2026-07-15T03:40:05.137348Z","price_level":"64871.04","new_quantity":"0"}]}]}
{"channel":"market_trades","timestamp":"2026-07-15T03:40:05.199951581Z","sequence_num":33,"events":[{"type":"update","trades":[{"product_id":"BTC-USD","trade_id":"1056309389","price":"64584.43","size":"0.0213","time":"2026-07-15T03:40:04.811247Z","side":"BUY"},{"product_id":"BTC-USD","trade_id":"1056309388","price":"64584.43","size":"0.01098201","time":"2026-07-15T03:40:04.809465Z","side":"BUY"},{"product_id":"BTC-USD","trade_id":"1056309387","price":"64587.68","size":"0.0356","time":"2026-07-15T03:40:04.809465Z","side":"BUY"},{"product_id":"BTC-USD","trade_id":"1056309386","price":"64587.68","size":"0.00001799","time":"2026-07-15T03:40:04.809465Z","side":"BUY"},{"product_id":"BTC-USD","trade_id":"1056309385","price":"64587.68","size":"0.00000001","time":"2026-07-15T03:40:04.804003Z","side":"BUY"},{"product_id":"BTC-USD","trade_id":"1056309384","price":"64588","size":"0.00005171","time":"2026-07-15T03:40:04.798444Z","side":"SELL"},{"product_id":"BTC-USD","trade_id":"1056309383","price":"64588","size":"0.0058717","time":"2026-07-15T03:40:04.796138Z","side":"SELL"}]}]}
{"channel":"l2_data","timestamp":"2026-07-15T03:40:05.23167605Z","sequence_num":34,"events":[{"type":"update","product_id":"BTC-USD","updates":[{"side":"bid","event_time":"2026-07-15T03:40:05.175066Z","price_level":"64575.6","new_quantity":"0"},{"side":"bid","event_time":"2026-07-15T03:40:05.175066Z","price_level":"64575.55","new_quantity":"0"},{"side":"bid","event_time":"2026-07-15T03:40:05.175066Z","price_level":"64572.81","new_quantity":"0"},{"side":"bid","event_time":"2026-07-15T03:40:05.175066Z","price_level":"64572.8","new_quantity":"0"},{"side":"bid","event_time":"2026-07-15T03:40:05.175066Z","price_level":"64571.35","new_quantity":"0.12389395"},{"side":"bid","event_time":"2026-07-15T03:40:05.175066Z","price_level":"64563.28","new_quantity":"0"},{"side":"bid","event_time":"2026-07-15T03:40:05.175066Z","price_level":"64562.42","new_quantity":"0.00772597"},{"side":"bid","event_time":"2026-07-15T03:40:05.175066Z","price_level":"64558.64","new_quantity":"0"},{"side":"bid","event_time":"2026-07-15T03:40:05.175066Z","price_level":"64557.68","new_quantity":"0.04"},{"side":"bid","event_time":"2026-07-15T03:40:05.175066Z","price_level":"64556.57","new_quantity":"0.07389967"},{"side":"bid","event_time":"2026-07-15T03:40:05.175066Z","price_level":"64551.77","new_quantity":"0.00077411"},{"side":"bid","event_time":"2026-07-15T03:40:05.175066Z","price_level":"64534.31","new_quantity":"0.01632186"},{"side":"bid","event_time":"2026-07-15T03:40:05.175066Z","price_level":"64534.3","new_quantity":"0.02423914"},{"side":"bid","event_time":"2026-07-15T03:40:05.175066Z","price_level":"64521.22","new_quantity":"0"},{"side":"bid","event_time":"2026-07-15T03:40:05.175066Z","price_level":"64481.7","new_quantity":"0"},{"side":"bid","event_time":"2026-07-15T03:40:05.175066Z","price_level":"64129.46","new_quantity":"0.00583"},{"side":"bid","event_time":"2026-07-15T03:40:05.175066Z","price_level":"64129.38","new_quantity":"0"},{"side":"bid","event_time":"2026-07-15T03:40:05.175066Z","price_level":"63955.62","new_quantity":"0.03909624"},{"side":"bid","event_time":"2026-07-15T03:40:05.175066Z","price_level":"63915.35","new_quantity":"0"},{"side":"bid","event_time":"2026-07-15T03:40:05.175066Z","price_level":"63914.57","new_quantity":"0.00583"},{"side":"bid","event_time":"2026-07-15T03:40:05.175066Z","price_level":"63700.6","new_quantity":"0"},{"side":"bid","event_time":"2026-07-15T03:40:05.175066Z","price_level":"63700.52","new_quantity":"0"},{"side":"bid","event_time":"2026-07-15T03:40:05.175066Z","price_level":"63486.49","new_quantity":"0"},{"side":"bid","event_time":"2026-07-15T03:40:05.175066Z","price_level":"63058.06","new_quantity":"0"},{"side":"bid","event_time":"2026-07-15T03:40:05.175066Z","price_level":"56510.35","new_quantity":"0"},{"side":"offer","event_time":"2026-07-15T03:40:05.175066Z","price_level":"64585.61","new_quantity":"0.00319954"},{"side":"offer","event_time":"2026-07-15T03:40:05.175066Z","price_level":"64592.82","new_quantity":"0.00100854"},{"side":"offer","event_time":"2026-07-15T03:40:05.175066Z","price_level":"64595.19","new_quantity":"0"},{"side":"offer","event_time":"2026-07-15T03:40:05.175066Z","price_level":"64595.26","new_quantity":"0"},{"side":"offer","event_time":"2026-07-15T03:40:05.175066Z","price_level":"64595.85","new_quantity":"0.06162924"},{"side":"offer","event_time":"2026-07-15T03:40:05.175066Z","price_level":"64604.46","new_quantity":"0"}]}]}
{"channel":"l2_data","timestamp":"2026-07-15T03:40:05.284418481Z","sequence_num":35,"events":[{"type":"update","product_id":"BTC-USD","updates":[{"side":"bid","event_time":"2026-07-15T03:40:05.251539Z","price_level":"64583.25","new_quantity":"0"},{"side":"bid","event_time":"2026-07-15T03:40:05.251539Z","price_level":"64581.95","new_quantity":"0"},{"side":"bid","event_time":"2026-07-15T03:40:05.251539Z","price_level":"64581.55","new_quantity":"0"},{"side":"bid","event_time":"2026-07-15T03:40:05.251539Z","price_level":"64578.36","new_quantity":"0"},{"side":"bid","event_time":"2026-07-15T03:40:05.251539Z","price_level":"64578","new_quantity":"0"},{"side":"bid","event_time":"2026-07-15T03:40:05.251539Z","price_level":"64577.98","new_quantity":"0"},{"side":"bid","event_time":"2026-07-15T03:40:05.251539Z","price_level":"64577.28","new_quantity":"0"},{"side":"bid","event_time":"2026-07-15T03:40:05.251539Z","price_level":"64576.5","new_quantity":"0"},{"side":"bid","event_time":"2026-07-15T03:40:05.251539Z","price_level":"64572.72","new_quantity":"0.03093532"},{"side":"bid","event_time":"2026-07-15T03:40:05.251539Z","price_level":"64572.71","new_quantity":"0.04656107"},{"side":"bid","event_time":"2026-07-15T03:40:05.251539Z","price_level":"64572","new_quantity":"1"},{"side":"bid","event_time":"2026-07-15T03:40:05.251539Z","price_level":"64571.35","new_quantity":"0"},{"side":"bid","event_time":"2026-07-15T03:40:05.251539Z","price_level":"64570.37","new_quantity":"0"},{"side":"bid","event_time":"2026-07-15T03:40:05.251539Z","price_level":"64570.36","new_quantity":"0"},{"side":"bid","event_time":"2026-07-15T03:40:05.251539Z","price_level":"64570.34","new_quantity":"0"},{"side":"bid","event_time":"2026-07-15T03:40:05.251539Z","price_level":"64570.12","new_quantity":"0"},{"side":"bid","event_time":"2026-07-15T03:40:05.251539Z","price_level":"64569.59","new_quantity":"0.12389732"},{"side":"bid","event_time":"2026-07-15T03:40:05.251539Z","price_level":"64568.5","new_quantity":"0.04"},{"side":"bid","event_time":"2026-07-15T03:40:05.251539Z","price_level":"64567.79","new_quantity":"0.09246097"},{"side":"bid","event_time":"2026-07-15T03:40:05.251539Z","price_level":"64567.78","new_quantity":"0.15487599"},{"side":"bid","event_time":"2026-07-15T03:40:05.251539Z","price_level":"64567.6","new_quantity":"0.04720341"},{"side":"bid","event_time":"2026-07-15T03:40:05.251539Z","price_level":"64567.59","new_quantity":"0"},{"side":"bid","event_time":"2026-07-15T03:40:05.251539Z","price_level":"64565.31","new_quantity":"0.07749639"},{"side":"bid","event_time":"2026-07-15T03:40:05.251539Z","price_level":"64565.3","new_quantity":"0"},{"side":"bid","event_time":"2026-07-15T03:40:05.251539Z","price_level":"64565.29","new_quantity":"0"},{"side":"bid","event_time":"2026-07-15T03:40:05.251539Z","price_level":"64565.02","new_quantity":"0"},{"side":"bid","event_time":"2026-07-15T03:40:05.251539Z","price_level":"64564.37","new_quantity":"0.07397438"},{"side":"bid","event_time":"2026-07-15T03:40:05.251539Z","price_level":"64564.36","new_quantity":"0.048285"},{"side":"bid","event_time":"2026-07-15T03:40:05.251539Z","price_level":"64563.27","new_quantity":"0"},{"side":"bid","event_time":"2026-07-15T03:40:05.251539Z","price_level":"64563.26","new_quantity":"0"},{"side":"bid","event_time":"2026-07-15T03:40:05.251539Z","price_level":"64562.42","new_quantity":"0"},{"side":"bid","event_time":"2026-07-15T03:40:05.251539Z","price_level":"64560.58","new_quantity":"0.05864015"},{"side":"bid","event_time":"2026-07-15T03:40:05.251539Z","price_level":"64560.57","new_quantity":"0"},{"side":"bid","event_time":"2026-07-15T03:40:05.251539Z","price_level":"64559.79","new_quantity":"0.00772597"},{"side":"bid","event_time":"2026-07-15T03:40:05.251539Z","price_level":"64558.54","new_quantity":"0"},{"side":"bid","event_time":"2026-07-15T03:40:05.251539Z","price_level":"64558.5","new_quantity":"0"},{"side":"bid","event_time":"2026-07-15T03:40:05.251539Z","price_level":"64557.69","new_quantity":"0"},{"side":"bid","event_time":"2026-07-15T03:40:05.251539Z","price_level":"64557.68","new_quantity":"0"},{"side":"bid","event_time":"2026-07-15T03:40:05.251539Z","price_level":"64556.57","new_quantity":"0"},{"side":"bid","event_time":"2026-07-15T03:40:05.251539Z","price_level":"64556.56","new_quantity":"0"},{"side":"bid","event_time":"2026-07-15T03:40:05.251539Z","price_level":"64554.59","new_quantity":"0.06773992"},{"side":"bid","event_time":"2026-07-15T03:40:05.251539Z","price_level":"64554.58","new_quantity":"0"},{"side":"bid","event_time":"2026-07-15T03:40:05.251539Z","price_level":"64552.95","new_quantity":"0"},{"side":"bid","event_time":"2026-07-15T03:40:05.251539Z","price_level":"64550.27","new_quantity":"0.02736486"},{"side":"bid","event_time":"2026-07-15T03:40:05.251539Z","price_level":"64548.28","new_quantity":"0.07661386"},{"side":"bid","event_time":"2026-07-15T03:40:05.251539Z","price_level":"64548.27","new_quantity":"0"},{"side":"bid","event_time":"2026-07-15T03:40:05.251539Z","price_level":"64548.24","new_quantity":"0"},{"side":"bid","event_time":"2026-07-15T03:40:05.251539Z","price_level":"64545.03","new_quantity":"0.6776395"},{"side":"bid","event_time":"2026-07-15T03:40:05.251539Z","price_level":"64545.02","new_quantity":"0.9317398"},{"side":"bid","event_time":"2026-07-15T03:40:05.251539Z","price_level":"64545.01","new_quantity":"0"},{"side":"bid","event_time":"2026-07-15T03:40:05.251539Z","price_level":"64544.35","new_quantity":"0"},{"side":"bid","event_time":"2026-07-15T03:40:05.251539Z","price_level":"64540.13","new_quantity":"0.70678327"},{"side":"bid","event_time":"2026-07-15T03:40:05.251539Z","price_level":"64540.12","new_quantity":"0.61064918"},{"side":"bid","event_time":"2026-07-15T03:40:05.251539Z","price_level":"64540.11","new_quantity":"0"},{"side":"bid","event_time":"2026-07-15T03:40:05.251539Z","price_level":"64535.19","new_quantity":"0.08929776"},{"side":"bid","event_time":"2026-07-15T03:40:05.251539Z","price_level":"64535.18","new_quantity":"0.12378505"},{"side":"bid","event_time":"2026-07-15T03:40:05.251539Z","price_level":"64534.31","new_quantity":"0"},{"side":"bid","event_time":"2026-07-15T03:40:05.251539Z","price_level":"64533.26","new_quantity":"0"},{"side":"bid","event_time":"2026-07-15T03:40:05.251539Z","price_level":"64531.31","new_quantity":"0.13404841"},{"side":"bid","event_time":"2026-07-15T03:40:05.251539Z","price_level":"64531.3","new_quantity":"0.12378505"},{"side":"bid","event_time":"2026-07-15T03:40:05.251539Z","price_level":"64529.99","new_quantity":"0.01158896"},{"side":"bid","event_time":"2026-07-15T03:40:05.251539Z","price_level":"64527.75","new_quantity":"0.03781399"},{"side":"bid","event_time":"2026-07-15T03:40:05.251539Z","price_level":"64526.81","new_quantity":"0"},{"side":"bid","event_time":"2026-07-15T03:40:05.251539Z","price_level":"64526.12","new_quantity":"0.04656107"},{"side":"bid","event_time":"2026-07-15T03:40:05.251539Z","price_level":"64515.92","new_quantity":"0"},{"side":"bid","event_time":"2026-07-15T03:40:05.251539Z","price_level":"64515.23","new_quantity":"0.00510702"},{"side":"bid","event_time":"2026-07-15T03:40:05.251539Z","price_level":"64512.55","new_quantity":"1.0978903"},{"side":"bid","event_time":"2026-07-15T03:40:05.251539Z","price_level":"64512.54","new_quantity":"1.3496194"},{"side":"bid","event_time":"2026-07-15T03:40:05.251539Z","price_level":"64512.53","new_quantity":"0"},{"side":"bid","event_time":"2026-07-15T03:40:05.251539Z","price_level":"64512.52","new_quantity":"0"},{"side":"bid","event_time":"2026-07-15T03:40:05.251539Z","price_level":"64485.8","new_quantity":"0.06123664"},{"side":"bid","event_time":"2026-07-15T03:40:05.251539Z","price_level":"64450.65","new_quantity":"0.00310314"},{"side":"bid","event_time":"2026-07-15T03:40:05.251539Z","price_level":"63699.94","new_quantity":"0.00583"},{"side":"bid","event_time":"2026-07-15T03:40:05.251539Z","price_level":"63485.51","new_quantity":"0.00583"},{"side":"offer","event_time":"2026-07-15T03:40:05.251539Z","price_level":"64580.33","new_quantity":"0.57185656"},{"side":"offer","event_time":"2026-07-15T03:40:05.251539Z","price_level":"64581.55","new_quantity":"0.00159977"},{"side":"offer","event_time":"2026-07-15T03:40:05.251539Z","price_level":"64581.56","new_quantity":"0.15364131"},{"side":"offer","event_time":"2026-07-15T03:40:05.251539Z","price_level":"64581.96","new_quantity":"0.1238736"},{"side":"offer","event_time":"2026-07-15T03:40:05.251539Z","price_level":"64582","new_quantity":"0.0245"},{"side":"offer","event_time":"2026-07-15T03:40:05.251539Z","price_level":"64583.25","new_quantity":"0.00774202"},{"side":"offer","event_time":"2026-07-15T03:40:05.251539Z","price_level":"64583.26","new_quantity":"0.10124"},{"side":"offer","event_time":"2026-07-15T03:40:05.251539Z","price_level":"64584","new_quantity":"0.0245"},{"side":"offer","event_time":"2026-07-15T03:40:05.251539Z","price_level":"64584.26","new_quantity":"0.04998462"},{"side":"offer","event_time":"2026-07-15T03:40:05.251539Z","price_level":"64584.4","new_quantity":"0.048285"},{"side":"offer","event_time":"2026-07-15T03:40:05.251539Z","price_level":"64584.56","new_quantity":"0"},{"side":"offer","event_time":"2026-07-15T03:40:05.251539Z","price_level":"64584.87","new_quantity":"0.00774202"},{"side":"offer","event_time":"2026-07-15T03:40:05.251539Z","price_level":"64585.61","new_quantity":"0"},{"side":"offer","event_time":"2026-07-15T03:40:05.251539Z","price_level":"64585.62","new_quantity":"0"},{"side":"offer","event_time":"2026-07-15T03:40:05.251539Z","price_level":"64585.68","new_quantity":"0"},{"side":"offer","event_time":"2026-07-15T03:40:05.251539Z","price_level":"64587.68","new_quantity":"0.04223173"},{"side":"offer","event_time":"2026-07-15T03:40:05.251539Z","price_level":"64587.97","new_quantity":"0"},{"side":"offer","event_time":"2026-07-15T03:40:05.251539Z","price_level":"64587.98","new_quantity":"0"},{"side":"offer","event_time":"2026-07-15T03:40:05.251539Z","price_level":"64587.99","new_quantity":"0.00772597"},{"side":"offer","event_time":"2026-07-15T03:40:05.251539Z","price_level":"64589.16","new_quantity":"0"},{"side":"offer","event_time":"2026-07-15T03:40:05.251539Z","price_level":"64590.03","new_quantity":"0.00100855"},{"side":"offer","event_time":"2026-07-15T03:40:05.251539Z","price_level":"64591.99","new_quantity":"0"},{"side":"offer","event_time":"2026-07-15T03:40:05.251539Z","price_level":"64592.82","new_quantity":"0"},{"side":"offer","event_time":"2026-07-15T03:40:05.251539Z","price_level":"64597.83","new_quantity":"0.07709305"},{"side":"offer","event_time":"2026-07-15T03:40:05.251539Z","price_level":"64597.84","new_quantity":"0.05687302"},{"side":"offer","event_time":"2026-07-15T03:40:05.251539Z","price_level":"64597.95","new_quantity":"0"},{"side":"offer","event_time":"2026-07-15T03:40:05.251539Z","price_level":"64599.6","new_quantity":"0.0007742"},{"side":"offer","event_time":"2026-07-15T03:40:05.251539Z","price_level":"64600.49","new_quantity":"0.72305403"},{"side":"offer","event_time":"2026-07-15T03:40:05.251539Z","price_level":"64600.5","new_quantity":"1"},{"side":"offer","event_time":"2026-07-15T03:40:05.251539Z","price_level":"64600.72","new_quantity":"0"},{"side":"offer","event_time":"2026-07-15T03:40:05.251539Z","price_level":"64601.89","new_quantity":"0.00592"},{"side":"offer","event_time":"2026-07-15T03:40:05.251539Z","price_level":"64603.41","new_quantity":"0"},{"side":"offer","event_time":"2026-07-15T03:40:05.251539Z","price_level":"64603.49","new_quantity":"0.13742204"},{"side":"offer","event_time":"2026-07-15T03:40:05.251539Z","price_level":"64603.5","new_quantity":"0"},{"side":"offer","event_time":"2026-07-15T03:40:05.251539Z","price_level":"64604","new_quantity":"0"},{"side":"offer","event_time":"2026-07-15T03:40:05.251539Z","price_level":"64606.49","new_quantity":"0.16686352"},{"side":"offer","event_time":"2026-07-15T03:40:05.251539Z","price_level":"64607.73","new_quantity":"0"},{"side":"offer","event_time":"2026-07-15T03:40:05.251539Z","price_level":"64607.93","new_quantity":"0"},{"side":"offer","event_time":"2026-07-15T03:40:05.251539Z","price_level":"64611.13","new_quantity":"0.63854782"},{"side":"offer","event_time":"2026-07-15T03:40:05.251539Z","price_level":"64612.22","new_quantity":"0"},{"side":"offer","event_time":"2026-07-15T03:40:05.251539Z","price_level":"64633.5","new_quantity":"1.18433494"},{"side":"offer","event_time":"2026-07-15T03:40:05.251539Z","price_level":"64633.51","new_quantity":"1.8901368"},{"side":"offer","event_time":"2026-07-15T03:40:05.251539Z","price_level":"64633.52","new_quantity":"0"},{"side":"offer","event_time":"2026-07-15T03:40:05.251539Z","price_level":"64633.53","new_quantity":"0"},{"side":"offer","event_time":"2026-07-15T03:40:05.251539Z","price_level":"64635.17","new_quantity":"0"},{"side":"offer","event_time":"2026-07-15T03:40:05.251539Z","price_level":"64638.77","new_quantity":"1.97131424"},{"side":"offer","event_time":"2026-07-15T03:40:05.251539Z","price_level":"64638.78","new_quantity":"2.02652529"},{"side":"offer","event_time":"2026-07-15T03:40:05.251539Z","price_level":"64638.79","new_quantity":"0"},{"side":"offer","event_time":"2026-07-15T03:40:05.251539Z","price_level":"64641.19","new_quantity":"1.39230126"},{"side":"offer","event_time":"2026-07-15T03:40:05.251539Z","price_level":"64641.44","new_quantity":"0"},{"side":"offer","event_time":"2026-07-15T03:40:05.251539Z","price_level":"64643.91","new_quantity":"0"},{"side":"offer","event_time":"2026-07-15T03:40:05.251539Z","price_level":"64643.92","new_quantity":"0"},{"side":"offer","event_time":"2026-07-15T03:40:05.251539Z","price_level":"64643.96","new_quantity":"0.05092405"},{"side":"offer","event_time":"2026-07-15T03:40:05.251539Z","price_level":"64649.02","new_quantity":"0.00240002"},{"side":"offer","event_time":"2026-07-15T03:40:05.251539Z","price_level":"64649.11","new_quantity":"0"},{"side":"offer","event_time":"2026-07-15T03:40:05.251539Z","price_level":"64650.48","new_quantity":"0"},{"side":"offer","event_time":"2026-07-15T03:40:05.251539Z","price_level":"64666.17","new_quantity":"0"},{"side":"offer","event_time":"2026-07-15T03:40:05.251539Z","price_level":"64672.58","new_quantity":"0.05162642"},{"side":"offer","event_time":"2026-07-15T03:40:05.251539Z","price_level":"64710.86","new_quantity":"0"},{"side":"offer","event_time":"2026-07-15T03:40:05.251539Z","price_level":"64710.87","new_quantity":"0"},{"side":"offer","event_time":"2026-07-15T03:40:05.251539Z","price_level":"64849.18","new_quantity":"0"},{"side":"offer","event_time":"2026-07-15T03:40:05.251539Z","price_level":"64869.4","new_quantity":"0"},{"side":"offer","event_time":"2026-07-15T03:40:05.251539Z","price_level":"65261.77","new_quantity":"0"}]}]}
{"channel":"market_trades","timestamp":"2026-07-15T03:40:05.286607282Z","sequence_num":36,"events":[{"type":"update","trades":[{"product_id":"BTC-USD","trade_id":"1056309391","price":"64583.25","size":"0.00120367","time":"2026-07-15T03:40:05.218944Z","side":"BUY"},{"product_id":"BTC-USD","trade_id":"1056309390","price":"64584","size":"0.000018","time":"2026-07-15T03:40:04.94243Z","side":"BUY"}]}]}
{"channel":"l2_data","timestamp":"2026-07-15T03:40:05.332747501Z","sequence_num":37,"events":[{"type":"update","product_id":"BTC-USD","updates":[{"side":"bid","event_time":"2026-07-15T03:40:05.288951Z","price_level":"64574.26","new_quantity":"0.00774302"},{"side":"bid","event_time":"2026-07-15T03:40:05.288951Z","price_level":"64563.95","new_quantity":"0"},{"side":"bid","event_time":"2026-07-15T03:40:05.288951Z","price_level":"64560.62","new_quantity":"0.12378505"},{"side":"bid","event_time":"2026-07-15T03:40:05.288951Z","price_level":"64560.58","new_quantity":"0"},{"side":"bid","event_time":"2026-07-15T03:40:05.288951Z","price_level":"64558.28","new_quantity":"0.12378505"},{"side":"bid","event_time":"2026-07-15T03:40:05.288951Z","price_level":"64556.35","new_quantity":"0.11302051"},{"side":"bid","event_time":"2026-07-15T03:40:05.288951Z","price_level":"64556.34","new_quantity":"0.12378505"},{"side":"bid","event_time":"2026-07-15T03:40:05.288951Z","price_level":"64555.69","new_quantity":"0.08"},{"side":"bid","event_time":"2026-07-15T03:40:05.288951Z","price_level":"64554.59","new_quantity":"0.13297918"},{"side":"bid","event_time":"2026-07-15T03:40:05.288951Z","price_level":"64554.16","new_quantity":"0.12378505"},{"side":"offer","event_time":"2026-07-15T03:40:05.288951Z","price_level":"64581.63","new_quantity":"0.00774214"},{"side":"offer","event_time":"2026-07-15T03:40:05.288951Z","price_level":"64587.67","new_quantity":"0.00772597"},{"side":"offer","event_time":"2026-07-15T03:40:05.288951Z","price_level":"64587.68","new_quantity":"0.0759563"},{"side":"offer","event_time":"2026-07-15T03:40:05.288951Z","price_level":"64587.89","new_quantity":"0.07326"},{"side":"offer","event_time":"2026-07-15T03:40:05.288951Z","price_level":"64587.99","new_quantity":"0"},{"side":"offer","event_time":"2026-07-15T03:40:05.288951Z","price_level":"64590.03","new_quantity":"0"},{"side":"offer","event_time":"2026-07-15T03:40:05.288951Z","price_level":"64590.26","new_quantity":"0"},{"side":"offer","event_time":"2026-07-15T03:40:05.288951Z","price_level":"64590.33","new_quantity":"0.00100855"}]}]}
{"channel":"l2_data","timestamp":"2026-07-15T03:40:05.382367627Z","sequence_num":38,"events":[{"type":"update","product_id":"BTC-USD","updates":[{"side":"bid","event_time":"2026-07-15T03:40:05.349763Z","price_level":"64570.66","new_quantity":"0.12389526"},{"side":"bid","event_time":"2026-07-15T03:40:05.349763Z","price_level":"64569.59","new_quantity":"0"},{"side":"bid","event_time":"2026-07-15T03:40:05.349763Z","price_level":"64568.9","new_quantity":"0.02"},{"side":"bid","event_time":"2026-07-15T03:40:05.349763Z","price_level":"64560.63","new_quantity":"0.19911191"},{"side":"bid","event_time":"2026-07-15T03:40:05.349763Z","price_level":"64555.69","new_quantity":"0.14"},{"side":"bid","event_time":"2026-07-15T03:40:05.349763Z","price_level":"64545.05","new_quantity":"0.67763933"},{"side":"bid","event_time":"2026-07-15T03:40:05.349763Z","price_level":"64545.04","new_quantity":"0.93173951"},{"side":"bid","event_time":"2026-07-15T03:40:05.349763Z","price_level":"64545.03","new_quantity":"0"},{"side":"bid","event_time":"2026-07-15T03:40:05.349763Z","price_level":"64545.02","new_quantity":"0"},{"side":"bid","event_time":"2026-07-15T03:40:05.349763Z","price_level":"64540.15","new_quantity":"0.70724533"},{"side":"bid","event_time":"2026-07-15T03:40:05.349763Z","price_level":"64540.14","new_quantity":"0.60987484"},{"side":"bid","event_time":"2026-07-15T03:40:05.349763Z","price_level":"64540.13","new_quantity":"0"},{"side":"bid","event_time":"2026-07-15T03:40:05.349763Z","price_level":"64540.12","new_quantity":"0.00077415"},{"side":"bid","event_time":"2026-07-15T03:40:05.349763Z","price_level":"64529.87","new_quantity":"0.00154744"},{"side":"bid","event_time":"2026-07-15T03:40:05.349763Z","price_level":"64523.42","new_quantity":"0.00773723"},{"side":"bid","event_time":"2026-07-15T03:40:05.349763Z","price_level":"64517.75","new_quantity":"0.0015533"},{"side":"bid","event_time":"2026-07-15T03:40:05.349763Z","price_level":"64514.56","new_quantity":"0.0015533"},{"side":"bid","event_time":"2026-07-15T03:40:05.349763Z","price_level":"64512.57","new_quantity":"1.09789004"},{"side":"bid","event_time":"2026-07-15T03:40:05.349763Z","price_level":"64512.56","new_quantity":"1.34961898"},{"side":"bid","event_time":"2026-07-15T03:40:05.349763Z","price_level":"64512.55","new_quantity":"0"},{"side":"bid","event_time":"2026-07-15T03:40:05.349763Z","price_level":"64512.54","new_quantity":"0"},{"side":"bid","event_time":"2026-07-15T03:40:05.349763Z","price_level":"51673.09","new_quantity":"0"},{"side":"offer","event_time":"2026-07-15T03:40:05.349763Z","price_level":"64580.61","new_quantity":"0"},{"side":"offer","event_time":"2026-07-15T03:40:05.349763Z","price_level":"64581.56","new_quantity":"0"},{"side":"offer","event_time":"2026-07-15T03:40:05.349763Z","price_level":"64581.95","new_quantity":"0.09320103"},{"side":"offer","event_time":"2026-07-15T03:40:05.349763Z","price_level":"64583.26","new_quantity":"0"},{"side":"offer","event_time":"2026-07-15T03:40:05.349763Z","price_level":"64584.26","new_quantity":"0.13412079"},{"side":"offer","event_time":"2026-07-15T03:40:05.349763Z","price_level":"64584.74","new_quantity":"0.0015533"},{"side":"offer","event_time":"2026-07-15T03:40:05.349763Z","price_level":"64584.81","new_quantity":"0.15483517"},{"side":"offer","event_time":"2026-07-15T03:40:05.349763Z","price_level":"64590.33","new_quantity":"0"},{"side":"offer","event_time":"2026-07-15T03:40:05.349763Z","price_level":"64590.45","new_quantity":"0"},{"side":"offer","event_time":"2026-07-15T03:40:05.349763Z","price_level":"64590.74","new_quantity":"0.00100855"},{"side":"offer","event_time":"2026-07-15T03:40:05.349763Z","price_level":"64591.8","new_quantity":"0"},{"side":"offer","event_time":"2026-07-15T03:40:05.349763Z","price_level":"64600.5","new_quantity":"0"},{"side":"offer","event_time":"2026-07-15T03:40:05.349763Z","price_level":"64603.33","new_quantity":"0.14"},{"side":"offer","event_time":"2026-07-15T03:40:05.349763Z","price_level":"64609.72","new_quantity":"0.62284765"},{"side":"offer","event_time":"2026-07-15T03:40:05.349763Z","price_level":"64609.73","new_quantity":"0.63856166"},{"side":"offer","event_time":"2026-07-15T03:40:05.349763Z","price_level":"64609.75","new_quantity":"0"},{"side":"offer","event_time":"2026-07-15T03:40:05.349763Z","price_level":"64610.08","new_quantity":"0"},{"side":"offer","event_time":"2026-07-15T03:40:05.349763Z","price_level":"64611.13","new_quantity":"0"},{"side":"offer","event_time":"2026-07-15T03:40:05.349763Z","price_level":"64629.19","new_quantity":"0.88005266"},{"side":"offer","event_time":"2026-07-15T03:40:05.349763Z","price_level":"64631.82","new_quantity":"1.43150509"},{"side":"offer","event_time":"2026-07-15T03:40:05.349763Z","price_level":"64633.48","new_quantity":"0.32974884"},{"side":"offer","event_time":"2026-07-15T03:40:05.349763Z","price_level":"64633.49","new_quantity":"0.45866929"},{"side":"offer","event_time":"2026-07-15T03:40:05.349763Z","price_level":"64633.5","new_quantity":"0"},{"side":"offer","event_time":"2026-07-15T03:40:05.349763Z","price_level":"64633.51","new_quantity":"0"},{"side":"offer","event_time":"2026-07-15T03:40:05.349763Z","price_level":"64636.28","new_quantity":"1.22843304"},{"side":"offer","event_time":"2026-07-15T03:40:05.349763Z","price_level":"64637.05","new_quantity":"2.02657953"},{"side":"offer","event_time":"2026-07-15T03:40:05.349763Z","price_level":"64638.77","new_quantity":"0.66407602"},{"side":"offer","event_time":"2026-07-15T03:40:05.349763Z","price_level":"64638.78","new_quantity":"0"},{"side":"offer","event_time":"2026-07-15T03:40:05.349763Z","price_level":"64648.54","new_quantity":"0"},{"side":"offer","event_time":"2026-07-15T03:40:05.349763Z","price_level":"64667.02","new_quantity":"0.2999"}]}]}
{"channel":"l2_data","timestamp":"2026-07-15T03:40:05.432703421Z","sequence_num":39,"events":[{"type":"update","product_id":"BTC-USD","updates":[{"side":"bid","event_time":"2026-07-15T03:40:05.385396Z","price_level":"64580.32","new_quantity":"0.00013119"},{"side":"bid","event_time":"2026-07-15T03:40:05.385396Z","price_level":"64574.26","new_quantity":"0"},{"side":"bid","event_time":"2026-07-15T03:40:05.385396Z","price_level":"64572","new_quantity":"0"},{"side":"bid","event_time":"2026-07-15T03:40:05.385396Z","price_level":"64537.86","new_quantity":"0.42413608"},{"side":"bid","event_time":"2026-07-15T03:40:05.385396Z","price_level":"64537.85","new_quantity":"0.631396"},{"side":"bid","event_time":"2026-07-15T03:40:05.385396Z","price_level":"64536.47","new_quantity":"0"},{"side":"bid","event_time":"2026-07-15T03:40:05.385396Z","price_level":"56507.78","new_quantity":"0.0132912"},{"side":"offer","event_time":"2026-07-15T03:40:05.385396Z","price_level":"64580.33","new_quantity":"0.62939391"},{"side":"offer","event_time":"2026-07-15T03:40:05.385396Z","price_level":"64590.74","new_quantity":"0"},{"side":"offer","event_time":"2026-07-15T03:40:05.385396Z","price_level":"64591.01","new_quantity":"0.00100855"},{"side":"offer","event_time":"2026-07-15T03:40:05.385396Z","price_level":"64600.49","new_quantity":"0.12605403"},{"side":"offer","event_time":"2026-07-15T03:40:05.385396Z","price_level":"64620.81","new_quantity":"0.00350089"}]}]}
{"channel":"l2_data","timestamp":"2026-07-15T03:40:05.486994073Z","sequence_num":40,"events":[{"type":"update","product_id":"BTC-USD","updates":[{"side":"bid","event_time":"2026-07-15T03:40:05.446196Z","price_level":"64575.17","new_quantity":"0"},{"side":"bid","event_time":"2026-07-15T03:40:05.446196Z","price_level":"64572.72","new_quantity":"0"},{"side":"bid","event_time":"2026-07-15T03:40:05.446196Z","price_level":"64571.98","new_quantity":"0"},{"side":"bid","event_time":"2026-07-15T03:40:05.446196Z","price_level":"64570.66","new_quantity":"0"},{"side":"bid","event_time":"2026-07-15T03:40:05.446196Z","price_level":"64570.5","new_quantity":"0"},{"side":"bid","event_time":"2026-07-15T03:40:05.446196Z","price_level":"64568.79","new_quantity":"0"},{"side":"bid","event_time":"2026-07-15T03:40:05.446196Z","price_level":"64565.6","new_quantity":"0.000018"},{"side":"bid","event_time":"2026-07-15T03:40:05.446196Z","price_level":"64562.41","new_quantity":"0"},{"side":"bid","event_time":"2026-07-15T03:40:05.446196Z","price_level":"64559.22","new_quantity":"0"},{"side":"bid","event_time":"2026-07-15T03:40:05.446196Z","price_level":"64558.18","new_quantity":"0.15486001"},{"side":"bid","event_time":"2026-07-15T03:40:05.446196Z","price_level":"64556.03","new_quantity":"0"},{"side":"bid","event_time":"2026-07-15T03:40:05.446196Z","price_level":"64555.69","new_quantity":"0.02"},{"side":"bid","event_time":"2026-07-15T03:40:05.446196Z","price_level":"64552.84","new_quantity":"0"},{"side":"bid","event_time":"2026-07-15T03:40:05.446196Z","price_level":"64550.27","new_quantity":"0"},{"side":"bid","event_time":"2026-07-15T03:40:05.446196Z","price_level":"64549.65","new_quantity":"0"},{"side":"bid","event_time":"2026-07-15T03:40:05.446196Z","price_level":"64546.46","new_quantity":"0"},{"side":"bid","event_time":"2026-07-15T03:40:05.446196Z","price_level":"64545.07","new_quantity":"0.67763915"},{"side":"bid","event_time":"2026-07-15T03:40:05.446196Z","price_level":"64545.06","new_quantity":"0.93173922"},{"side":"bid","event_time":"2026-07-15T03:40:05.446196Z","price_level":"64545.05","new_quantity":"0"},{"side":"bid","event_time":"2026-07-15T03:40:05.446196Z","price_level":"64545.04","new_quantity":"0"},{"side":"bid","event_time":"2026-07-15T03:40:05.446196Z","price_level":"64544.4","new_quantity":"0.01947116"},{"side":"bid","event_time":"2026-07-15T03:40:05.446196Z","price_level":"64544.38","new_quantity":"0.06586087"},{"side":"bid","event_time":"2026-07-15T03:40:05.446196Z","price_level":"64543.27","new_quantity":"0"},{"side":"bid","event_time":"2026-07-15T03:40:05.446196Z","price_level":"64540.17","new_quantity":"0.70631789"},{"side":"bid","event_time":"2026-07-15T03:40:05.446196Z","price_level":"64540.16","new_quantity":"0.60987465"},{"side":"bid","event_time":"2026-07-15T03:40:05.446196Z","price_level":"64540.15","new_quantity":"0"},{"side":"bid","event_time":"2026-07-15T03:40:05.446196Z","price_level":"64540.14","new_quantity":"0"},{"side":"bid","event_time":"2026-07-15T03:40:05.446196Z","price_level":"64540.08","new_quantity":"0"},{"side":"bid","event_time":"2026-07-15T03:40:05.446196Z","price_level":"64538.46","new_quantity":"0.02653269"},{"side":"bid","event_time":"2026-07-15T03:40:05.446196Z","price_level":"64529.99","new_quantity":"0"},{"side":"bid","event_time":"2026-07-15T03:40:05.446196Z","price_level":"64528.13","new_quantity":"0.0145301"},{"side":"bid","event_time":"2026-07-15T03:40:05.446196Z","price_level":"64526.13","new_quantity":"0.01158896"},{"side":"bid","event_time":"2026-07-15T03:40:05.446196Z","price_level":"64525.02","new_quantity":"0.04582507"},{"side":"bid","event_time":"2026-07-15T03:40:05.446196Z","price_level":"64525.01","new_quantity":"0.06746838"},{"side":"bid","event_time":"2026-07-15T03:40:05.446196Z","price_level":"64513.47","new_quantity":"0.00077503"},{"side":"bid","event_time":"2026-07-15T03:40:05.446196Z","price_level":"64512.59","new_quantity":"1.0978898"},{"side":"bid","event_time":"2026-07-15T03:40:05.446196Z","price_level":"64512.58","new_quantity":"1.34961857"},{"side":"bid","event_time":"2026-07-15T03:40:05.446196Z","price_level":"64512.57","new_quantity":"0"},{"side":"bid","event_time":"2026-07-15T03:40:05.446196Z","price_level":"64512.56","new_quantity":"0"},{"side":"bid","event_time":"2026-07-15T03:40:05.446196Z","price_level":"64505.65","new_quantity":"0.04043924"},{"side":"bid","event_time":"2026-07-15T03:40:05.446196Z","price_level":"64505.64","new_quantity":"0.06773742"},{"side":"bid","event_time":"2026-07-15T03:40:05.446196Z","price_level":"64486.27","new_quantity":"0.06802664"},{"side":"bid","event_time":"2026-07-15T03:40:05.446196Z","price_level":"64485.8","new_quantity":"0.09022795"},{"side":"offer","event_time":"2026-07-15T03:40:05.446196Z","price_level":"64580.64","new_quantity":"0.12387614"},{"side":"offer","event_time":"2026-07-15T03:40:05.446196Z","price_level":"64581.16","new_quantity":"0.022695"},{"side":"offer","event_time":"2026-07-15T03:40:05.446196Z","price_level":"64581.55","new_quantity":"0"},{"side":"offer","event_time":"2026-07-15T03:40:05.446196Z","price_level":"64581.95","new_quantity":"0.01924849"},{"side":"offer","event_time":"2026-07-15T03:40:05.446196Z","price_level":"64581.96","new_quantity":"0"},{"side":"offer","event_time":"2026-07-15T03:40:05.446196Z","price_level":"64583.99","new_quantity":"0.00280351"},{"side":"offer","event_time":"2026-07-15T03:40:05.446196Z","price_level":"64584.25","new_quantity":"0.03093532"},{"side":"offer","event_time":"2026-07-15T03:40:05.446196Z","price_level":"64589.76","new_quantity":"0.03093532"},{"side":"offer","event_time":"2026-07-15T03:40:05.446196Z","price_level":"64591.01","new_quantity":"0"},{"side":"offer","event_time":"2026-07-15T03:40:05.446196Z","price_level":"64591.08","new_quantity":"0"},{"side":"offer","event_time":"2026-07-15T03:40:05.446196Z","price_level":"64591.17","new_quantity":"0"},{"side":"offer","event_time":"2026-07-15T03:40:05.446196Z","price_level":"64591.25","new_quantity":"0.00100855"},{"side":"offer","event_time":"2026-07-15T03:40:05.446196Z","price_level":"64591.81","new_quantity":"0"},{"side":"offer","event_time":"2026-07-15T03:40:05.446196Z","price_level":"64597.83","new_quantity":"0.66469905"},{"side":"offer","event_time":"2026-07-15T03:40:05.446196Z","price_level":"64599","new_quantity":"1"},{"side":"offer","event_time":"2026-07-15T03:40:05.446196Z","price_level":"64609.7","new_quantity":"0.61931353"},{"side":"offer","event_time":"2026-07-15T03:40:05.446196Z","price_level":"64609.71","new_quantity":"0.63856185"},{"side":"offer","event_time":"2026-07-15T03:40:05.446196Z","price_level":"64609.72","new_quantity":"0"},{"side":"offer","event_time":"2026-07-15T03:40:05.446196Z","price_level":"64609.73","new_quantity":"0"},{"side":"offer","event_time":"2026-07-15T03:40:05.446196Z","price_level":"64610.34","new_quantity":"0"},{"side":"offer","event_time":"2026-07-15T03:40:05.446196Z","price_level":"64633.46","new_quantity":"0.32974892"},{"side":"offer","event_time":"2026-07-15T03:40:05.446196Z","price_level":"64633.47","new_quantity":"0.45866943"},{"side":"offer","event_time":"2026-07-15T03:40:05.446196Z","price_level":"64633.48","new_quantity":"0"},{"side":"offer","event_time":"2026-07-15T03:40:05.446196Z","price_level":"64633.49","new_quantity":"0"},{"side":"offer","event_time":"2026-07-15T03:40:05.446196Z","price_level":"64640.01","new_quantity":"0.00077242"},{"side":"offer","event_time":"2026-07-15T03:40:05.446196Z","price_level":"64643.96","new_quantity":"0.03245567"},{"side":"offer","event_time":"2026-07-15T03:40:05.446196Z","price_level":"64643.97","new_quantity":"0"},{"side":"offer","event_time":"2026-07-15T03:40:05.446196Z","price_level":"64670.99","new_quantity":"0"},{"side":"offer","event_time":"2026-07-15T03:40:05.446196Z","price_level":"64741.83","new_quantity":"0"}]}]}
{"channel":"l2_data","timestamp":"2026-07-15T03:40:05.530888979Z","sequence_num":41,"events":[{"type":"update","product_id":"BTC-USD","updates":[{"side":"bid","event_time":"2026-07-15T03:40:05.487032Z","price_level":"64568.5","new_quantity":"0"},{"side":"bid","event_time":"2026-07-15T03:40:05.487032Z","price_level":"64556.35","new_quantity":"0.07482699"},{"side":"bid","event_time":"2026-07-15T03:40:05.487032Z","price_level":"64555.69","new_quantity":"0"},{"side":"bid","event_time":"2026-07-15T03:40:05.487032Z","price_level":"64544.4","new_quantity":"0"},{"side":"bid","event_time":"2026-07-15T03:40:05.487032Z","price_level":"64544.38","new_quantity":"0"},{"side":"bid","event_time":"2026-07-15T03:40:05.487032Z","price_level":"64538.46","new_quantity":"0"},{"side":"bid","event_time":"2026-07-15T03:40:05.487032Z","price_level":"64537.86","new_quantity":"0.42413608"},{"side":"bid","event_time":"2026-07-15T03:40:05.487032Z","price_level":"64537.5","new_quantity":"0"},{"side":"bid","event_time":"2026-07-15T03:40:05.487032Z","price_level":"64528.13","new_quantity":"0"},{"side":"bid","event_time":"2026-07-15T03:40:05.487032Z","price_level":"56507.78","new_quantity":"0"},{"side":"offer","event_time":"2026-07-15T03:40:05.487032Z","price_level":"64580.33","new_quantity":"0.63466687"},{"side":"offer","event_time":"2026-07-15T03:40:05.487032Z","price_level":"64591.25","new_quantity":"0"},{"side":"offer","event_time":"2026-07-15T03:40:05.487032Z","price_level":"64591.35","new_quantity":"0.00100855"},{"side":"offer","event_time":"2026-07-15T03:40:05.487032Z","price_level":"64609.34","new_quantity":"0.01647578"},{"side":"offer","event_time":"2026-07-15T03:40:05.487032Z","price_level":"64614.66","new_quantity":"0.0116743"},{"side":"offer","event_time":"2026-07-15T03:40:05.487032Z","price_level":"64617.9","new_quantity":"0"},{"side":"offer","event_time":"2026-07-15T03:40:05.487032Z","price_level":"64620.81","new_quantity":"0.00144074"}]}]}
{"channel":"l2_data","timestamp":"2026-07-15T03:40:05.583170343Z","sequence_num":42,"events":[{"type":"update","product_id":"BTC-USD","updates":[{"side":"bid","event_time":"2026-07-15T03:40:05.544389Z","price_level":"64580.32","new_quantity":"0.00013113"},{"side":"bid","event_time":"2026-07-15T03:40:05.544389Z","price_level":"64571.82","new_quantity":"0.12378505"},{"side":"bid","event_time":"2026-07-15T03:40:05.544389Z","price_level":"64570.31","new_quantity":"0.12389594"},{"side":"bid","event_time":"2026-07-15T03:40:05.544389Z","price_level":"64568.9","new_quantity":"0"},{"side":"bid","event_time":"2026-07-15T03:40:05.544389Z","price_level":"64567.94","new_quantity":"0.12378505"},{"side":"bid","event_time":"2026-07-15T03:40:05.544389Z","price_level":"64567.79","new_quantity":"0"},{"side":"bid","event_time":"2026-07-15T03:40:05.544389Z","price_level":"64567.6","new_quantity":"0"},{"side":"bid","event_time":"2026-07-15T03:40:05.544389Z","price_level":"64567.5","new_quantity":"1"},{"side":"bid","event_time":"2026-07-15T03:40:05.544389Z","price_level":"64564.06","new_quantity":"0.12378505"},{"side":"bid","event_time":"2026-07-15T03:40:05.544389Z","price_level":"64545.09","new_quantity":"0.67671166"},{"side":"bid","event_time":"2026-07-15T03:40:05.544389Z","price_level":"64545.08","new_quantity":"0.93173893"},{"side":"bid","event_time":"2026-07-15T03:40:05.544389Z","price_level":"64545.07","new_quantity":"0"},{"side":"bid","event_time":"2026-07-15T03:40:05.544389Z","price_level":"64545.06","new_quantity":"0"},{"side":"bid","event_time":"2026-07-15T03:40:05.544389Z","price_level":"64540.18","new_quantity":"0.60987446"},{"side":"bid","event_time":"2026-07-15T03:40:05.544389Z","price_level":"64540.17","new_quantity":"0"},{"side":"bid","event_time":"2026-07-15T03:40:05.544389Z","price_level":"64540.16","new_quantity":"0"},{"side":"bid","event_time":"2026-07-15T03:40:05.544389Z","price_level":"64539.06","new_quantity":"0"},{"side":"bid","event_time":"2026-07-15T03:40:05.544389Z","price_level":"64535.19","new_quantity":"0"},{"side":"bid","event_time":"2026-07-15T03:40:05.544389Z","price_level":"64535.18","new_quantity":"0"},{"side":"bid","event_time":"2026-07-15T03:40:05.544389Z","price_level":"64531.31","new_quantity":"0.05415395"},{"side":"bid","event_time":"2026-07-15T03:40:05.544389Z","price_level":"64531.3","new_quantity":"0"},{"side":"bid","event_time":"2026-07-15T03:40:05.544389Z","price_level":"64516.47","new_quantity":"0.73834393"},{"side":"bid","event_time":"2026-07-15T03:40:05.544389Z","price_level":"64516.46","new_quantity":"1.236757"},{"side":"bid","event_time":"2026-07-15T03:40:05.544389Z","price_level":"64512.61","new_quantity":"1.09788955"},{"side":"bid","event_time":"2026-07-15T03:40:05.544389Z","price_level":"64512.6","new_quantity":"1.34961815"},{"side":"bid","event_time":"2026-07-15T03:40:05.544389Z","price_level":"64512.59","new_quantity":"0"},{"side":"bid","event_time":"2026-07-15T03:40:05.544389Z","price_level":"64512.58","new_quantity":"0"},{"side":"bid","event_time":"2026-07-15T03:40:05.544389Z","price_level":"64502.58","new_quantity":"0"},{"side":"bid","event_time":"2026-07-15T03:40:05.544389Z","price_level":"64501.16","new_quantity":"5.383486"},{"side":"bid","event_time":"2026-07-15T03:40:05.544389Z","price_level":"64486.25","new_quantity":"9.751537"},{"side":"bid","event_time":"2026-07-15T03:40:05.544389Z","price_level":"64485.8","new_quantity":"0.02899131"},{"side":"offer","event_time":"2026-07-15T03:40:05.544389Z","price_level":"64580.33","new_quantity":"0.64266868"},{"side":"offer","event_time":"2026-07-15T03:40:05.544389Z","price_level":"64581.95","new_quantity":"0.09380758"},{"side":"offer","event_time":"2026-07-15T03:40:05.544389Z","price_level":"64582.27","new_quantity":"0.12378505"},{"side":"offer","event_time":"2026-07-15T03:40:05.544389Z","price_level":"64583.25","new_quantity":"0"},{"side":"offer","event_time":"2026-07-15T03:40:05.544389Z","price_level":"64584.13","new_quantity":"0.00967787"},{"side":"offer","event_time":"2026-07-15T03:40:05.544389Z","price_level":"64584.22","new_quantity":"0.25698158"},{"side":"offer","event_time":"2026-07-15T03:40:05.544389Z","price_level":"64584.23","new_quantity":"0.12378505"},{"side":"offer","event_time":"2026-07-15T03:40:05.544389Z","price_level":"64584.24","new_quantity":"0.04656107"},{"side":"offer","event_time":"2026-07-15T03:40:05.544389Z","price_level":"64584.26","new_quantity":"0"},{"side":"offer","event_time":"2026-07-15T03:40:05.544389Z","price_level":"64584.87","new_quantity":"0"},{"side":"offer","event_time":"2026-07-15T03:40:05.544389Z","price_level":"64587.67","new_quantity":"0"},{"side":"offer","event_time":"2026-07-15T03:40:05.544389Z","price_level":"64587.68","new_quantity":"0.15823536"},{"side":"offer","event_time":"2026-07-15T03:40:05.544389Z","price_level":"64587.8","new_quantity":"0"},{"side":"offer","event_time":"2026-07-15T03:40:05.544389Z","price_level":"64587.88","new_quantity":"0.00772597"},{"side":"offer","event_time":"2026-07-15T03:40:05.544389Z","price_level":"64588.11","new_quantity":"0.12378505"},{"side":"offer","event_time":"2026-07-15T03:40:05.544389Z","price_level":"64606.49","new_quantity":"0.50076794"},{"side":"offer","event_time":"2026-07-15T03:40:05.544389Z","price_level":"64609.69","new_quantity":"0.63856205"},{"side":"offer","event_time":"2026-07-15T03:40:05.544389Z","price_level":"64609.7","new_quantity":"0"},{"side":"offer","event_time":"2026-07-15T03:40:05.544389Z","price_level":"64609.71","new_quantity":"0"},{"side":"offer","event_time":"2026-07-15T03:40:05.544389Z","price_level":"64609.75","new_quantity":"0.18380372"},{"side":"offer","event_time":"2026-07-15T03:40:05.544389Z","price_level":"64613.42","new_quantity":"0.03569384"},{"side":"offer","event_time":"2026-07-15T03:40:05.544389Z","price_level":"64614.41","new_quantity":"0"},{"side":"offer","event_time":"2026-07-15T03:40:05.544389Z","price_level":"64616.54","new_quantity":"0.23807862"},{"side":"offer","event_time":"2026-07-15T03:40:05.544389Z","price_level":"64616.55","new_quantity":"0"},{"side":"offer","event_time":"2026-07-15T03:40:05.544389Z","price_level":"64619.41","new_quantity":"0.03793203"},{"side":"offer","event_time":"2026-07-15T03:40:05.544389Z","price_level":"64620.42","new_quantity":"0.00077417"},{"side":"offer","event_time":"2026-07-15T03:40:05.544389Z","price_level":"64620.43","new_quantity":"0"},{"side":"offer","event_time":"2026-07-15T03:40:05.544389Z","price_level":"64624.12","new_quantity":"0"},{"side":"offer","event_time":"2026-07-15T03:40:05.544389Z","price_level":"64631.11","new_quantity":"0.00077418"},{"side":"offer","event_time":"2026-07-15T03:40:05.544389Z","price_level":"64633.44","new_quantity":"0.329749"},{"side":"offer","event_time":"2026-07-15T03:40:05.544389Z","price_level":"64633.45","new_quantity":"0.45866957"},{"side":"offer","event_time":"2026-07-15T03:40:05.544389Z","price_level":"64633.46","new_quantity":"0"},{"side":"offer","event_time":"2026-07-15T03:40:05.544389Z","price_level":"64633.47","new_quantity":"0"},{"side":"offer","event_time":"2026-07-15T03:40:05.544389Z","price_level":"64641.43","new_quantity":"0"},{"side":"offer","event_time":"2026-07-15T03:40:05.544389Z","price_level":"64672.58","new_quantity":"0"},{"side":"offer","event_time":"2026-07-15T03:40:05.544389Z","price_level":"64698.83","new_quantity":"12.399512"},{"side":"offer","event_time":"2026-07-15T03:40:05.544389Z","price_level":"64705.78","new_quantity":"0.00030969"}]}]}
{"channel":"market_trades","timestamp":"2026-07-15T03:40:05.58428319Z","sequence_num":43,"events":[{"type":"update","trades":[{"product_id":"BTC-USD","trade_id":"1056309392","price":"64580.32","size":"0.00000006","time":"2026-07-15T03:40:05.509856Z","side":"BUY"}]}]}
{"channel":"l2_data","timestamp":"2026-07-15T03:40:05.634239785Z","sequence_num":44,"events":[{"type":"update","product_id":"BTC-USD","updates":[{"side":"bid","event_time":"2026-07-15T03:40:05.604379Z","price_level":"64580.32","new_quantity":"0"},{"side":"bid","event_time":"2026-07-15T03:40:05.604379Z","price_level":"64577.24","new_quantity":"0"},{"side":"bid","event_time":"2026-07-15T03:40:05.604379Z","price_level":"64576.64","new_quantity":"0.00002636"},{"side":"bid","event_time":"2026-07-15T03:40:05.604379Z","price_level":"64572.71","new_quantity":"0"},{"side":"bid","event_time":"2026-07-15T03:40:05.604379Z","price_level":"64572.16","new_quantity":"0"},{"side":"bid","event_time":"2026-07-15T03:40:05.604379Z","price_level":"64572","new_quantity":"0.0245"},{"side":"bid","event_time":"2026-07-15T03:40:05.604379Z","price_level":"64571.82","new_quantity":"0"},{"side":"bid","event_time":"2026-07-15T03:40:05.604379Z","price_level":"64570.5","new_quantity":"0.04656107"},{"side":"bid","event_time":"2026-07-15T03:40:05.604379Z","price_level":"64570.49","new_quantity":"0"},{"side":"bid","event_time":"2026-07-15T03:40:05.604379Z","price_level":"64570.42","new_quantity":"0"},{"side":"bid","event_time":"2026-07-15T03:40:05.604379Z","price_level":"64570.31","new_quantity":"0"},{"side":"bid","event_time":"2026-07-15T03:40:05.604379Z","price_level":"64569.08","new_quantity":"0"},{"side":"bid","event_time":"2026-07-15T03:40:05.604379Z","price_level":"64568.36","new_quantity":"0"},{"side":"bid","event_time":"2026-07-15T03:40:05.604379Z","price_level":"64567.94","new_quantity":"0"},{"side":"bid","event_time":"2026-07-15T03:40:05.604379Z","price_level":"64567.78","new_quantity":"0"},{"side":"bid","event_time":"2026-07-15T03:40:05.604379Z","price_level":"64567.5","new_quantity":"0"},{"side":"bid","event_time":"2026-07-15T03:40:05.604379Z","price_level":"64566.61","new_quantity":"0"},{"side":"bid","event_time":"2026-07-15T03:40:05.604379Z","price_level":"64566.08","new_quantity":"0.03093532"},{"side":"bid","event_time":"2026-07-15T03:40:05.604379Z","price_level":"64566.07","new_quantity":"0"},{"side":"bid","event_time":"2026-07-15T03:40:05.604379Z","price_level":"64565.31","new_quantity":"0.04656107"},{"side":"bid","event_time":"2026-07-15T03:40:05.604379Z","price_level":"64564.37","new_quantity":"0"},{"side":"bid","event_time":"2026-07-15T03:40:05.604379Z","price_level":"64564.36","new_quantity":"0"},{"side":"bid","event_time":"2026-07-15T03:40:05.604379Z","price_level":"64563.06","new_quantity":"0.15488731"},{"side":"bid","event_time":"2026-07-15T03:40:05.604379Z","price_level":"64561.48","new_quantity":"0"},{"side":"bid","event_time":"2026-07-15T03:40:05.604379Z","price_level":"64560.65","new_quantity":"0.03093532"},{"side":"bid","event_time":"2026-07-15T03:40:05.604379Z","price_level":"64560.64","new_quantity":"0"},{"side":"bid","event_time":"2026-07-15T03:40:05.604379Z","price_level":"64559.79","new_quantity":"0"},{"side":"bid","event_time":"2026-07-15T03:40:05.604379Z","price_level":"64559.07","new_quantity":"0"},{"side":"bid","event_time":"2026-07-15T03:40:05.604379Z","price_level":"64558.18","new_quantity":"0"},{"side":"bid","event_time":"2026-07-15T03:40:05.604379Z","price_level":"64556.36","new_quantity":"0.00772597"},{"side":"bid","event_time":"2026-07-15T03:40:05.604379Z","price_level":"64554.59","new_quantity":"0"},{"side":"bid","event_time":"2026-07-15T03:40:05.604379Z","price_level":"64554.29","new_quantity":"0"},{"side":"bid","event_time":"2026-07-15T03:40:05.604379Z","price_level":"64553.44","new_quantity":"0"},{"side":"bid","event_time":"2026-07-15T03:40:05.604379Z","price_level":"64545.89","new_quantity":"0.033747"},{"side":"bid","event_time":"2026-07-15T03:40:05.604379Z","price_level":"64544.5","new_quantity":"0"},{"side":"bid","event_time":"2026-07-15T03:40:05.604379Z","price_level":"64539","new_quantity":"1"},{"side":"bid","event_time":"2026-07-15T03:40:05.604379Z","price_level":"64519.75","new_quantity":"0"},{"side":"bid","event_time":"2026-07-15T03:40:05.604379Z","price_level":"64515.95","new_quantity":"0"},{"side":"bid","event_time":"2026-07-15T03:40:05.604379Z","price_level":"64515.94","new_quantity":"0"},{"side":"bid","event_time":"2026-07-15T03:40:05.604379Z","price_level":"64485.86","new_quantity":"0"},{"side":"bid","event_time":"2026-07-15T03:40:05.604379Z","price_level":"64481.84","new_quantity":"0"},{"side":"bid","event_time":"2026-07-15T03:40:05.604379Z","price_level":"64452.4","new_quantity":"0.03462545"},{"side":"bid","event_time":"2026-07-15T03:40:05.604379Z","price_level":"64297.18","new_quantity":"1.39975024"},{"side":"offer","event_time":"2026-07-15T03:40:05.604379Z","price_level":"64576.65","new_quantity":"0.4623393"},{"side":"offer","event_time":"2026-07-15T03:40:05.604379Z","price_level":"64577.24","new_quantity":"0.00319954"},{"side":"offer","event_time":"2026-07-15T03:40:05.604379Z","price_level":"64578","new_quantity":"0.0245"},{"side":"offer","event_time":"2026-07-15T03:40:05.604379Z","price_level":"64579.98","new_quantity":"0.12378505"},{"side":"offer","event_time":"2026-07-15T03:40:05.604379Z","price_level":"64580.3","new_quantity":"0.15484599"},{"side":"offer","event_time":"2026-07-15T03:40:05.604379Z","price_level":"64580.32","new_quantity":"0.02774251"},{"side":"offer","event_time":"2026-07-15T03:40:05.604379Z","price_level":"64580.33","new_quantity":"0.02815786"},{"side":"offer","event_time":"2026-07-15T03:40:05.604379Z","price_level":"64580.64","new_quantity":"0"},{"side":"offer","event_time":"2026-07-15T03:40:05.604379Z","price_level":"64581.63","new_quantity":"0"},{"side":"offer","event_time":"2026-07-15T03:40:05.604379Z","price_level":"64581.95","new_quantity":"0.02699078"},{"side":"offer","event_time":"2026-07-15T03:40:05.604379Z","price_level":"64582.27","new_quantity":"0"},{"side":"offer","event_time":"2026-07-15T03:40:05.604379Z","price_level":"64583.99","new_quantity":"0"},{"side":"offer","event_time":"2026-07-15T03:40:05.604379Z","price_level":"64584.2","new_quantity":"0.2082812"},{"side":"offer","event_time":"2026-07-15T03:40:05.604379Z","price_level":"64584.21","new_quantity":"0.12378505"},{"side":"offer","event_time":"2026-07-15T03:40:05.604379Z","price_level":"64584.22","new_quantity":"0"},{"side":"offer","event_time":"2026-07-15T03:40:05.604379Z","price_level":"64584.23","new_quantity":"0"},{"side":"offer","event_time":"2026-07-15T03:40:05.604379Z","price_level":"64584.81","new_quantity":"0"},{"side":"offer","event_time":"2026-07-15T03:40:05.604379Z","price_level":"64585.42","new_quantity":"0.07326"},{"side":"offer","event_time":"2026-07-15T03:40:05.604379Z","price_level":"64587.67","new_quantity":"0.00772597"},{"side":"offer","event_time":"2026-07-15T03:40:05.604379Z","price_level":"64587.68","new_quantity":"0.15592255"},{"side":"offer","event_time":"2026-07-15T03:40:05.604379Z","price_level":"64587.88","new_quantity":"0"},{"side":"offer","event_time":"2026-07-15T03:40:05.604379Z","price_level":"64588.09","new_quantity":"0.12378505"},{"side":"offer","event_time":"2026-07-15T03:40:05.604379Z","price_level":"64588.11","new_quantity":"0"},{"side":"offer","event_time":"2026-07-15T03:40:05.604379Z","price_level":"64591.35","new_quantity":"0"},{"side":"offer","event_time":"2026-07-15T03:40:05.604379Z","price_level":"64591.45","new_quantity":"0.00100858"},{"side":"offer","event_time":"2026-07-15T03:40:05.604379Z","price_level":"64597.81","new_quantity":"0.13611202"},{"side":"offer","event_time":"2026-07-15T03:40:05.604379Z","price_level":"64597.82","new_quantity":"0.12378505"},{"side":"offer","event_time":"2026-07-15T03:40:05.604379Z","price_level":"64597.83","new_quantity":"0"},{"side":"offer","event_time":"2026-07-15T03:40:05.604379Z","price_level":"64598.96","new_quantity":"0.00002323"},{"side":"offer","event_time":"2026-07-15T03:40:05.604379Z","price_level":"64599","new_quantity":"0"},{"side":"offer","event_time":"2026-07-15T03:40:05.604379Z","price_level":"64600","new_quantity":"0"},{"side":"offer","event_time":"2026-07-15T03:40:05.604379Z","price_level":"64601.4","new_quantity":"0"},{"side":"offer","event_time":"2026-07-15T03:40:05.604379Z","price_level":"64601.74","new_quantity":"0.06"},{"side":"offer","event_time":"2026-07-15T03:40:05.604379Z","price_level":"64602","new_quantity":"0"},{"side":"offer","event_time":"2026-07-15T03:40:05.604379Z","price_level":"64603.33","new_quantity":"0"},{"side":"offer","event_time":"2026-07-15T03:40:05.604379Z","price_level":"64609.75","new_quantity":"0.10990404"},{"side":"offer","event_time":"2026-07-15T03:40:05.604379Z","price_level":"64612.23","new_quantity":"0"},{"side":"offer","event_time":"2026-07-15T03:40:05.604379Z","price_level":"64628.29","new_quantity":"0.94063288"},{"side":"offer","event_time":"2026-07-15T03:40:05.604379Z","price_level":"64628.3","new_quantity":"1.43158306"},{"side":"offer","event_time":"2026-07-15T03:40:05.604379Z","price_level":"64628.31","new_quantity":"0"},{"side":"offer","event_time":"2026-07-15T03:40:05.604379Z","price_level":"64629.19","new_quantity":"0.02726552"},{"side":"offer","event_time":"2026-07-15T03:40:05.604379Z","price_level":"64631.82","new_quantity":"0"},{"side":"offer","event_time":"2026-07-15T03:40:05.604379Z","price_level":"64633.44","new_quantity":"1.49749441"},{"side":"offer","event_time":"2026-07-15T03:40:05.604379Z","price_level":"64635.17","new_quantity":"2.02663847"},{"side":"offer","event_time":"2026-07-15T03:40:05.604379Z","price_level":"64636.28","new_quantity":"0.0212865"},{"side":"offer","event_time":"2026-07-15T03:40:05.604379Z","price_level":"64637.05","new_quantity":"0"},{"side":"offer","event_time":"2026-07-15T03:40:05.604379Z","price_level":"64645.35","new_quantity":"0"},{"side":"offer","event_time":"2026-07-15T03:40:05.604379Z","price_level":"64664.94","new_quantity":"1.01683138"},{"side":"offer","event_time":"2026-07-15T03:40:05.604379Z","price_level":"64666.66","new_quantity":"0"},{"side":"offer","event_time":"2026-07-15T03:40:05.604379Z","price_level":"64685","new_quantity":"0"},{"side":"offer","event_time":"2026-07-15T03:40:05.604379Z","price_level":"64704.07","new_quantity":"0.00004035"}]}]}
{"channel":"l2_data","timestamp":"2026-07-15T03:40:05.682918899Z","sequence_num":45,"events":[{"type":"update","product_id":"BTC-USD","updates":[{"side":"bid","event_time":"2026-07-15T03:40:05.638402Z","price_level":"64576.64","new_quantity":"0"},{"side":"bid","event_time":"2026-07-15T03:40:05.638402Z","price_level":"64572.96","new_quantity":"0.00001797"},{"side":"bid","event_time":"2026-07-15T03:40:05.638402Z","price_level":"64572","new_quantity":"0"},{"side":"bid","event_time":"2026-07-15T03:40:05.638402Z","price_level":"64570","new_quantity":"0.0245"},{"side":"bid","event_time":"2026-07-15T03:40:05.638402Z","price_level":"64568","new_quantity":"0.0245"},{"side":"bid","event_time":"2026-07-15T03:40:05.638402Z","price_level":"64566.07","new_quantity":"0.12378505"},{"side":"bid","event_time":"2026-07-15T03:40:05.638402Z","price_level":"64565.1","new_quantity":"0.04"},{"side":"bid","event_time":"2026-07-15T03:40:05.638402Z","price_level":"64563.79","new_quantity":"0.12390845"},{"side":"bid","event_time":"2026-07-15T03:40:05.638402Z","price_level":"64556.86","new_quantity":"0.00029931"},{"side":"bid","event_time":"2026-07-15T03:40:05.638402Z","price_level":"64556.36","new_quantity":"0"},{"side":"bid","event_time":"2026-07-15T03:40:05.638402Z","price_level":"64554.8","new_quantity":"0.00059861"},{"side":"bid","event_time":"2026-07-15T03:40:05.638402Z","price_level":"64552.09","new_quantity":"0.02"},{"side":"bid","event_time":"2026-07-15T03:40:05.638402Z","price_level":"64551.77","new_quantity":"0"},{"side":"bid","event_time":"2026-07-15T03:40:05.638402Z","price_level":"64548.29","new_quantity":"0.00077421"},{"side":"bid","event_time":"2026-07-15T03:40:05.638402Z","price_level":"64547.04","new_quantity":"0"},{"side":"bid","event_time":"2026-07-15T03:40:05.638402Z","price_level":"64545.72","new_quantity":"0"},{"side":"bid","event_time":"2026-07-15T03:40:05.638402Z","price_level":"64545.09","new_quantity":"0"},{"side":"bid","event_time":"2026-07-15T03:40:05.638402Z","price_level":"64545.08","new_quantity":"0"},{"side":"bid","event_time":"2026-07-15T03:40:05.638402Z","price_level":"64542.46","new_quantity":"0"},{"side":"bid","event_time":"2026-07-15T03:40:05.638402Z","price_level":"64541.02","new_quantity":"0.0186897"},{"side":"bid","event_time":"2026-07-15T03:40:05.638402Z","price_level":"64540.19","new_quantity":"0.93180953"},{"side":"bid","event_time":"2026-07-15T03:40:05.638402Z","price_level":"64540.18","new_quantity":"0"},{"side":"bid","event_time":"2026-07-15T03:40:05.638402Z","price_level":"64535.08","new_quantity":"0.02668701"},{"side":"bid","event_time":"2026-07-15T03:40:05.638402Z","price_level":"64534.31","new_quantity":"0.60992994"},{"side":"bid","event_time":"2026-07-15T03:40:05.638402Z","price_level":"64529.87","new_quantity":"0"},{"side":"bid","event_time":"2026-07-15T03:40:05.638402Z","price_level":"64527.31","new_quantity":"0"},{"side":"bid","event_time":"2026-07-15T03:40:05.638402Z","price_level":"64524.75","new_quantity":"0.01505938"},{"side":"bid","event_time":"2026-07-15T03:40:05.638402Z","price_level":"64523.42","new_quantity":"0"},{"side":"bid","event_time":"2026-07-15T03:40:05.638402Z","price_level":"64520.87","new_quantity":"0"},{"side":"bid","event_time":"2026-07-15T03:40:05.638402Z","price_level":"64519.76","new_quantity":"0"},{"side":"bid","event_time":"2026-07-15T03:40:05.638402Z","price_level":"64515.23","new_quantity":"0"},{"side":"bid","event_time":"2026-07-15T03:40:05.638402Z","price_level":"64513.23","new_quantity":"0.00510718"},{"side":"bid","event_time":"2026-07-15T03:40:05.638402Z","price_level":"64512.61","new_quantity":"0"},{"side":"bid","event_time":"2026-07-15T03:40:05.638402Z","price_level":"64512.6","new_quantity":"0"},{"side":"bid","event_time":"2026-07-15T03:40:05.638402Z","price_level":"64505.66","new_quantity":"1.34976335"},{"side":"bid","event_time":"2026-07-15T03:40:05.638402Z","price_level":"64505.65","new_quantity":"0"},{"side":"bid","event_time":"2026-07-15T03:40:05.638402Z","price_level":"64497.11","new_quantity":"0"},{"side":"bid","event_time":"2026-07-15T03:40:05.638402Z","price_level":"64490.94","new_quantity":"0.232057"},{"side":"bid","event_time":"2026-07-15T03:40:05.638402Z","price_level":"64489.27","new_quantity":"0.02317792"},{"side":"bid","event_time":"2026-07-15T03:40:05.638402Z","price_level":"64476.31","new_quantity":"2.15592018"},{"side":"bid","event_time":"2026-07-15T03:40:05.638402Z","price_level":"64445.13","new_quantity":"0.232057"},{"side":"offer","event_time":"2026-07-15T03:40:05.638402Z","price_level":"64572.97","new_quantity":"0.16355066"},{"side":"offer","event_time":"2026-07-15T03:40:05.638402Z","price_level":"64574","new_quantity":"0.0245"},{"side":"offer","event_time":"2026-07-15T03:40:05.638402Z","price_level":"64574.22","new_quantity":"0.12388846"},{"side":"offer","event_time":"2026-07-15T03:40:05.638402Z","price_level":"64574.59","new_quantity":"0.00774317"},{"side":"offer","event_time":"2026-07-15T03:40:05.638402Z","price_level":"64576","new_quantity":"0.0245"},{"side":"offer","event_time":"2026-07-15T03:40:05.638402Z","price_level":"64576.4","new_quantity":"0.12378505"},{"side":"offer","event_time":"2026-07-15T03:40:05.638402Z","price_level":"64576.64","new_quantity":"0.02"},{"side":"offer","event_time":"2026-07-15T03:40:05.638402Z","price_level":"64576.65","new_quantity":"0.12388378"},{"side":"offer","event_time":"2026-07-15T03:40:05.638402Z","price_level":"64576.77","new_quantity":"0.00967897"},{"side":"offer","event_time":"2026-07-15T03:40:05.638402Z","price_level":"64578.26","new_quantity":"0"},{"side":"offer","event_time":"2026-07-15T03:40:05.638402Z","price_level":"64580.3","new_quantity":"0"},{"side":"offer","event_time":"2026-07-15T03:40:05.638402Z","price_level":"64580.32","new_quantity":"0.02"},{"side":"offer","event_time":"2026-07-15T03:40:05.638402Z","price_level":"64580.44","new_quantity":"0"},{"side":"offer","event_time":"2026-07-15T03:40:05.638402Z","price_level":"64581.31","new_quantity":"0.07326"},{"side":"offer","event_time":"2026-07-15T03:40:05.638402Z","price_level":"64581.95","new_quantity":"0.01924849"},{"side":"offer","event_time":"2026-07-15T03:40:05.638402Z","price_level":"64583.99","new_quantity":"0.00772597"},{"side":"offer","event_time":"2026-07-15T03:40:05.638402Z","price_level":"64584.13","new_quantity":"0"},{"side":"offer","event_time":"2026-07-15T03:40:05.638402Z","price_level":"64584.4","new_quantity":"0"},{"side":"offer","event_time":"2026-07-15T03:40:05.638402Z","price_level":"64587.67","new_quantity":"0"},{"side":"offer","event_time":"2026-07-15T03:40:05.638402Z","price_level":"64587.89","new_quantity":"0"},{"side":"offer","event_time":"2026-07-15T03:40:05.638402Z","price_level":"64589.43","new_quantity":"0.00100864"},{"side":"offer","event_time":"2026-07-15T03:40:05.638402Z","price_level":"64591.33","new_quantity":"0.47637859"},{"side":"offer","event_time":"2026-07-15T03:40:05.638402Z","price_level":"64591.45","new_quantity":"0"},{"side":"offer","event_time":"2026-07-15T03:40:05.638402Z","price_level":"64591.97","new_quantity":"0.591937"},{"side":"offer","event_time":"2026-07-15T03:40:05.638402Z","price_level":"64596","new_quantity":"0"},{"side":"offer","event_time":"2026-07-15T03:40:05.638402Z","price_level":"64597.49","new_quantity":"0.13705321"},{"side":"offer","event_time":"2026-07-15T03:40:05.638402Z","price_level":"64597.5","new_quantity":"0.0015533"},{"side":"offer","event_time":"2026-07-15T03:40:05.638402Z","price_level":"64597.81","new_quantity":"0"},{"side":"offer","event_time":"2026-07-15T03:40:05.638402Z","price_level":"64606.47","new_quantity":"0.52212005"},{"side":"offer","event_time":"2026-07-15T03:40:05.638402Z","price_level":"64606.48","new_quantity":"0.63859378"},{"side":"offer","event_time":"2026-07-15T03:40:05.638402Z","price_level":"64606.49","new_quantity":"0"},{"side":"offer","event_time":"2026-07-15T03:40:05.638402Z","price_level":"64609.69","new_quantity":"0"},{"side":"offer","event_time":"2026-07-15T03:40:05.638402Z","price_level":"64609.73","new_quantity":"0.05447275"},{"side":"offer","event_time":"2026-07-15T03:40:05.638402Z","price_level":"64609.75","new_quantity":"0"},{"side":"offer","event_time":"2026-07-15T03:40:05.638402Z","price_level":"64609.76","new_quantity":"0"},{"side":"offer","event_time":"2026-07-15T03:40:05.638402Z","price_level":"64628.28","new_quantity":"0.45870626"},{"side":"offer","event_time":"2026-07-15T03:40:05.638402Z","price_level":"64633.45","new_quantity":"0"},{"side":"offer","event_time":"2026-07-15T03:40:05.638402Z","price_level":"64642.16","new_quantity":"0"},{"side":"offer","event_time":"2026-07-15T03:40:05.638402Z","price_level":"64685","new_quantity":"3"},{"side":"offer","event_time":"2026-07-15T03:40:05.638402Z","price_level":"64843.2","new_quantity":"0.3"},{"side":"offer","event_time":"2026-07-15T03:40:05.638402Z","price_level":"65285.6","new_quantity":"1.5"}]}]}
{"channel":"market_trades","timestamp":"2026-07-15T03:40:05.685692004Z","sequence_num":46,"events":[{"type":"update","trades":[{"product_id":"BTC-USD","trade_id":"1056309399","price":"64572.96","size":"0.00000003","time":"2026-07-15T03:40:05.626101Z","side":"BUY"},{"product_id":"BTC-USD","trade_id":"1056309398","price":"64576.64","size":"0.00000836","time":"2026-07-15T03:40:05.604201Z","side":"BUY"},{"product_id":"BTC-USD","trade_id":"1056309397","price":"64576.64","size":"0.000018","time":"2026-07-15T03:40:05.604201Z","side":"BUY"},{"product_id":"BTC-USD","trade_id":"1056309396","price":"64577.24","size":"0.00013113","time":"2026-07-15T03:40:05.558419Z","side":"BUY"},{"product_id":"BTC-USD","trade_id":"1056309395","price":"64577.24","size":"0.32893146","time":"2026-07-15T03:40:05.558267Z","side":"BUY"},{"product_id":"BTC-USD","trade_id":"1056309394","price":"64580.32","size":"0.00011319","time":"2026-07-15T03:40:05.558267Z","side":"BUY"},{"product_id":"BTC-USD","trade_id":"1056309393","price":"64580.32","size":"0.00001794","time":"2026-07-15T03:40:05.558267Z","side":"BUY"}]}]}
{"channel":"l2_data","timestamp":"2026-07-15T03:40:05.732036413Z","sequence_num":47,"events":[{"type":"update","product_id":"BTC-USD","updates":[{"side":"bid","event_time":"2026-07-15T03:40:05.680809Z","price_level":"64568.26","new_quantity":"0.12378505"},{"side":"bid","event_time":"2026-07-15T03:40:05.680809Z","price_level":"64563.79","new_quantity":"0"},{"side":"bid","event_time":"2026-07-15T03:40:05.680809Z","price_level":"64563.12","new_quantity":"0.12390972"},{"side":"bid","event_time":"2026-07-15T03:40:05.680809Z","price_level":"64563.06","new_quantity":"0"},{"side":"bid","event_time":"2026-07-15T03:40:05.680809Z","price_level":"64561.99","new_quantity":"0"},{"side":"bid","event_time":"2026-07-15T03:40:05.680809Z","price_level":"64558.93","new_quantity":"0"},{"side":"bid","event_time":"2026-07-15T03:40:05.680809Z","price_level":"64554.57","new_quantity":"0.00772597"},{"side":"bid","event_time":"2026-07-15T03:40:05.680809Z","price_level":"64554.25","new_quantity":"0"},{"side":"bid","event_time":"2026-07-15T03:40:05.680809Z","price_level":"64554.17","new_quantity":"0.12993788"},{"side":"bid","event_time":"2026-07-15T03:40:05.680809Z","price_level":"64549","new_quantity":"0.00119723"},{"side":"bid","event_time":"2026-07-15T03:40:05.680809Z","price_level":"64543.01","new_quantity":"0.10169663"},{"side":"bid","event_time":"2026-07-15T03:40:05.680809Z","price_level":"64540.77","new_quantity":"0.00239446"},{"side":"bid","event_time":"2026-07-15T03:40:05.680809Z","price_level":"64540.2","new_quantity":"0.82461334"},{"side":"bid","event_time":"2026-07-15T03:40:05.680809Z","price_level":"64539","new_quantity":"0"},{"side":"bid","event_time":"2026-07-15T03:40:05.680809Z","price_level":"64537.86","new_quantity":"0.04719266"},{"side":"bid","event_time":"2026-07-15T03:40:05.680809Z","price_level":"64537.85","new_quantity":"0"},{"side":"bid","event_time":"2026-07-15T03:40:05.680809Z","price_level":"64535.09","new_quantity":"0.3914529"},{"side":"bid","event_time":"2026-07-15T03:40:05.680809Z","price_level":"64532.16","new_quantity":"0.00299307"},{"side":"bid","event_time":"2026-07-15T03:40:05.680809Z","price_level":"64526.13","new_quantity":"0"},{"side":"bid","event_time":"2026-07-15T03:40:05.680809Z","price_level":"64522.08","new_quantity":"0.01158896"},{"side":"bid","event_time":"2026-07-15T03:40:05.680809Z","price_level":"64522.07","new_quantity":"0.02298329"},{"side":"bid","event_time":"2026-07-15T03:40:05.680809Z","price_level":"64512.51","new_quantity":"0.29216751"},{"side":"bid","event_time":"2026-07-15T03:40:05.680809Z","price_level":"64505.67","new_quantity":"0.84624796"},{"side":"bid","event_time":"2026-07-15T03:40:05.680809Z","price_level":"64501.17","new_quantity":"5.25032246"},{"side":"bid","event_time":"2026-07-15T03:40:05.680809Z","price_level":"64499.4","new_quantity":"0"},{"side":"bid","event_time":"2026-07-15T03:40:05.680809Z","price_level":"64490.95","new_quantity":"0.13853803"},{"side":"bid","event_time":"2026-07-15T03:40:05.680809Z","price_level":"64489.27","new_quantity":"0.86347768"},{"side":"bid","event_time":"2026-07-15T03:40:05.680809Z","price_level":"64486.26","new_quantity":"0.15455147"},{"side":"bid","event_time":"2026-07-15T03:40:05.680809Z","price_level":"64485.8","new_quantity":"0"},{"side":"bid","event_time":"2026-07-15T03:40:05.680809Z","price_level":"64484.17","new_quantity":"0.00748267"},{"side":"bid","event_time":"2026-07-15T03:40:05.680809Z","price_level":"64468.52","new_quantity":"0"},{"side":"bid","event_time":"2026-07-15T03:40:05.680809Z","price_level":"64468.32","new_quantity":"0"},{"side":"bid","event_time":"2026-07-15T03:40:05.680809Z","price_level":"64453.3","new_quantity":"0.00897921"},{"side":"bid","event_time":"2026-07-15T03:40:05.680809Z","price_level":"64401.96","new_quantity":"12.838378"},{"side":"bid","event_time":"2026-07-15T03:40:05.680809Z","price_level":"64296.83","new_quantity":"0"},{"side":"bid","event_time":"2026-07-15T03:40:05.680809Z","price_level":"56501.34","new_quantity":"0.0132912"},{"side":"offer","event_time":"2026-07-15T03:40:05.680809Z","price_level":"64572.97","new_quantity":"0.16355066"},{"side":"offer","event_time":"2026-07-15T03:40:05.680809Z","price_level":"64573.83","new_quantity":"0.12388921"},{"side":"offer","event_time":"2026-07-15T03:40:05.680809Z","price_level":"64574.22","new_quantity":"0"},{"side":"offer","event_time":"2026-07-15T03:40:05.680809Z","price_level":"64576.4","new_quantity":"0"},{"side":"offer","event_time":"2026-07-15T03:40:05.680809Z","price_level":"64576.64","new_quantity":"0"},{"side":"offer","event_time":"2026-07-15T03:40:05.680809Z","price_level":"64580.32","new_quantity":"0"},{"side":"offer","event_time":"2026-07-15T03:40:05.680809Z","price_level":"64591.33","new_quantity":"0.15514271"},{"side":"offer","event_time":"2026-07-15T03:40:05.680809Z","price_level":"64591.58","new_quantity":"0.00153313"},{"side":"offer","event_time":"2026-07-15T03:40:05.680809Z","price_level":"64591.97","new_quantity":"0"},{"side":"offer","event_time":"2026-07-15T03:40:05.680809Z","price_level":"64600.49","new_quantity":"0.12605403"},{"side":"offer","event_time":"2026-07-15T03:40:05.680809Z","price_level":"64602","new_quantity":"0"},{"side":"offer","event_time":"2026-07-15T03:40:05.680809Z","price_level":"64603.93","new_quantity":"0.00306626"},{"side":"offer","event_time":"2026-07-15T03:40:05.680809Z","price_level":"64604.41","new_quantity":"0"},{"side":"offer","event_time":"2026-07-15T03:40:05.680809Z","price_level":"64616.76","new_quantity":"0"},{"side":"offer","event_time":"2026-07-15T03:40:05.680809Z","price_level":"64622.64","new_quantity":"0.89309483"},{"side":"offer","event_time":"2026-07-15T03:40:05.680809Z","price_level":"64624.45","new_quantity":"1.43166835"},{"side":"offer","event_time":"2026-07-15T03:40:05.680809Z","price_level":"64628.27","new_quantity":"0.35982543"},{"side":"offer","event_time":"2026-07-15T03:40:05.680809Z","price_level":"64628.29","new_quantity":"0"},{"side":"offer","event_time":"2026-07-15T03:40:05.680809Z","price_level":"64628.3","new_quantity":"0"},{"side":"offer","event_time":"2026-07-15T03:40:05.680809Z","price_level":"64629.19","new_quantity":"1.23587219"},{"side":"offer","event_time":"2026-07-15T03:40:05.680809Z","price_level":"64631.82","new_quantity":"2.02674352"},{"side":"offer","event_time":"2026-07-15T03:40:05.680809Z","price_level":"64633.44","new_quantity":"0"},{"side":"offer","event_time":"2026-07-15T03:40:05.680809Z","price_level":"64633.56","new_quantity":"0.05592327"},{"side":"offer","event_time":"2026-07-15T03:40:05.680809Z","price_level":"64635.17","new_quantity":"0"},{"side":"offer","event_time":"2026-07-15T03:40:05.680809Z","price_level":"64641.18","new_quantity":"0.00077422"},{"side":"offer","event_time":"2026-07-15T03:40:05.680809Z","price_level":"64648.53","new_quantity":"0"},{"side":"offer","event_time":"2026-07-15T03:40:05.680809Z","price_level":"64651.93","new_quantity":"0.00766564"},{"side":"offer","event_time":"2026-07-15T03:40:05.680809Z","price_level":"64664.78","new_quantity":"0"}]}]}
{"channel":"l2_data","timestamp":"2026-07-15T03:40:05.781803393Z","sequence_num":48,"events":[{"type":"update","product_id":"BTC-USD","updates":[{"side":"bid","event_time":"2026-07-15T03:40:05.734632Z","price_level":"64572.96","new_quantity":"0"},{"side":"bid","event_time":"2026-07-15T03:40:05.734632Z","price_level":"64570.5","new_quantity":"0"},{"side":"bid","event_time":"2026-07-15T03:40:05.734632Z","price_level":"64570","new_quantity":"0"},{"side":"bid","event_time":"2026-07-15T03:40:05.734632Z","price_level":"64568.26","new_quantity":"0"},{"side":"bid","event_time":"2026-07-15T03:40:05.734632Z","price_level":"64568","new_quantity":"0"},{"side":"bid","event_time":"2026-07-15T03:40:05.734632Z","price_level":"64566.08","new_quantity":"0"},{"side":"bid","event_time":"2026-07-15T03:40:05.734632Z","price_level":"64566.07","new_quantity":"0"},{"side":"bid","event_time":"2026-07-15T03:40:05.734632Z","price_level":"64566","new_quantity":"0.0245"},{"side":"bid","event_time":"2026-07-15T03:40:05.734632Z","price_level":"64565.1","new_quantity":"0"},{"side":"bid","event_time":"2026-07-15T03:40:05.734632Z","price_level":"64564.96","new_quantity":"0.1239062"},{"side":"bid","event_time":"2026-07-15T03:40:05.734632Z","price_level":"64564.06","new_quantity":"0"},{"side":"bid","event_time":"2026-07-15T03:40:05.734632Z","price_level":"64563.12","new_quantity":"0"},{"side":"bid","event_time":"2026-07-15T03:40:05.734632Z","price_level":"64560.86","new_quantity":"0.15489259"},{"side":"bid","event_time":"2026-07-15T03:40:05.734632Z","price_level":"64560.63","new_quantity":"0"},{"side":"bid","event_time":"2026-07-15T03:40:05.734632Z","price_level":"64560.62","new_quantity":"0"},{"side":"bid","event_time":"2026-07-15T03:40:05.734632Z","price_level":"64559.8","new_quantity":"0.02"},{"side":"bid","event_time":"2026-07-15T03:40:05.734632Z","price_level":"64559.79","new_quantity":"0"},{"side":"bid","event_time":"2026-07-15T03:40:05.734632Z","price_level":"64559.26","new_quantity":"0.12378505"},{"side":"bid","event_time":"2026-07-15T03:40:05.734632Z","price_level":"64558.87","new_quantity":"0"},{"side":"bid","event_time":"2026-07-15T03:40:05.734632Z","price_level":"64558.28","new_quantity":"0"},{"side":"bid","event_time":"2026-07-15T03:40:05.734632Z","price_level":"64555.94","new_quantity":"0.05814958"},{"side":"bid","event_time":"2026-07-15T03:40:05.734632Z","price_level":"64554.57","new_quantity":"0"},{"side":"bid","event_time":"2026-07-15T03:40:05.734632Z","price_level":"64552.1","new_quantity":"0.00772597"},{"side":"bid","event_time":"2026-07-15T03:40:05.734632Z","price_level":"64551.99","new_quantity":"0.08"},{"side":"bid","event_time":"2026-07-15T03:40:05.734632Z","price_level":"64548.95","new_quantity":"0.05236978"},{"side":"bid","event_time":"2026-07-15T03:40:05.734632Z","price_level":"64548.28","new_quantity":"0.1105184"},{"side":"bid","event_time":"2026-07-15T03:40:05.734632Z","price_level":"64547.2","new_quantity":"0.000018"},{"side":"bid","event_time":"2026-07-15T03:40:05.734632Z","price_level":"64545.22","new_quantity":"0.04397981"},{"side":"bid","event_time":"2026-07-15T03:40:05.734632Z","price_level":"64541.02","new_quantity":"0"},{"side":"bid","event_time":"2026-07-15T03:40:05.734632Z","price_level":"64540.21","new_quantity":"0.12378505"},{"side":"bid","event_time":"2026-07-15T03:40:05.734632Z","price_level":"64540.2","new_quantity":"0"},{"side":"bid","event_time":"2026-07-15T03:40:05.734632Z","price_level":"64540.19","new_quantity":"0"},{"side":"bid","event_time":"2026-07-15T03:40:05.734632Z","price_level":"64540.12","new_quantity":"0"},{"side":"bid","event_time":"2026-07-15T03:40:05.734632Z","price_level":"64536.89","new_quantity":"0"},{"side":"bid","event_time":"2026-07-15T03:40:05.734632Z","price_level":"64536.47","new_quantity":"0.93186324"},{"side":"bid","event_time":"2026-07-15T03:40:05.734632Z","price_level":"64536.33","new_quantity":"0.12378505"},{"side":"bid","event_time":"2026-07-15T03:40:05.734632Z","price_level":"64536","new_quantity":"1"},{"side":"bid","event_time":"2026-07-15T03:40:05.734632Z","price_level":"64535.08","new_quantity":"0"},{"side":"bid","event_time":"2026-07-15T03:40:05.734632Z","price_level":"64534.31","new_quantity":"0.61070419"},{"side":"bid","event_time":"2026-07-15T03:40:05.734632Z","price_level":"64524.75","new_quantity":"0"},{"side":"bid","event_time":"2026-07-15T03:40:05.734632Z","price_level":"64513.23","new_quantity":"0"},{"side":"bid","event_time":"2026-07-15T03:40:05.734632Z","price_level":"64511.24","new_quantity":"0.00510733"},{"side":"bid","event_time":"2026-07-15T03:40:05.734632Z","price_level":"64501.17","new_quantity":"0"},{"side":"bid","event_time":"2026-07-15T03:40:05.734632Z","price_level":"64500","new_quantity":"0.11110077"},{"side":"bid","event_time":"2026-07-15T03:40:05.734632Z","price_level":"56501.34","new_quantity":"0"},{"side":"offer","event_time":"2026-07-15T03:40:05.734632Z","price_level":"64569.29","new_quantity":"0.05817423"},{"side":"offer","event_time":"2026-07-15T03:40:05.734632Z","price_level":"64570","new_quantity":"0.0245"},{"side":"offer","event_time":"2026-07-15T03:40:05.734632Z","price_level":"64572","new_quantity":"0.0245"},{"side":"offer","event_time":"2026-07-15T03:40:05.734632Z","price_level":"64572.96","new_quantity":"0.00774339"},{"side":"offer","event_time":"2026-07-15T03:40:05.734632Z","price_level":"64572.97","new_quantity":"0"},{"side":"offer","event_time":"2026-07-15T03:40:05.734632Z","price_level":"64573.83","new_quantity":"0"},{"side":"offer","event_time":"2026-07-15T03:40:05.734632Z","price_level":"64576.63","new_quantity":"0.04656107"},{"side":"offer","event_time":"2026-07-15T03:40:05.734632Z","price_level":"64576.64","new_quantity":"0.12378505"},{"side":"offer","event_time":"2026-07-15T03:40:05.734632Z","price_level":"64577.24","new_quantity":"0"},{"side":"offer","event_time":"2026-07-15T03:40:05.734632Z","price_level":"64578.16","new_quantity":"0.048285"},{"side":"offer","event_time":"2026-07-15T03:40:05.734632Z","price_level":"64579.27","new_quantity":"0.07326"},{"side":"offer","event_time":"2026-07-15T03:40:05.734632Z","price_level":"64579.69","new_quantity":"0.05814958"},{"side":"offer","event_time":"2026-07-15T03:40:05.734632Z","price_level":"64581.94","new_quantity":"0.00772597"},{"side":"offer","event_time":"2026-07-15T03:40:05.734632Z","price_level":"64583.99","new_quantity":"0"},{"side":"offer","event_time":"2026-07-15T03:40:05.734632Z","price_level":"64584","new_quantity":"0.024518"},{"side":"offer","event_time":"2026-07-15T03:40:05.734632Z","price_level":"64584.97","new_quantity":"0.05839053"},{"side":"offer","event_time":"2026-07-15T03:40:05.734632Z","price_level":"64585.42","new_quantity":"0"},{"side":"offer","event_time":"2026-07-15T03:40:05.734632Z","price_level":"64587.48","new_quantity":"0.00100869"},{"side":"offer","event_time":"2026-07-15T03:40:05.734632Z","price_level":"64589.15","new_quantity":"0"},{"side":"offer","event_time":"2026-07-15T03:40:05.734632Z","price_level":"64589.43","new_quantity":"0"},{"side":"offer","event_time":"2026-07-15T03:40:05.734632Z","price_level":"64591.33","new_quantity":"0.12184441"},{"side":"offer","event_time":"2026-07-15T03:40:05.734632Z","price_level":"64592","new_quantity":"0"},{"side":"offer","event_time":"2026-07-15T03:40:05.734632Z","price_level":"64594","new_quantity":"0"},{"side":"offer","event_time":"2026-07-15T03:40:05.734632Z","price_level":"64595.85","new_quantity":"0"},{"side":"offer","event_time":"2026-07-15T03:40:05.734632Z","price_level":"64600.49","new_quantity":"0.45962975"},{"side":"offer","event_time":"2026-07-15T03:40:05.734632Z","price_level":"64600.5","new_quantity":"0"},{"side":"offer","event_time":"2026-07-15T03:40:05.734632Z","price_level":"64601.73","new_quantity":"0.63864073"},{"side":"offer","event_time":"2026-07-15T03:40:05.734632Z","price_level":"64601.74","new_quantity":"0"},{"side":"offer","event_time":"2026-07-15T03:40:05.734632Z","price_level":"64606.47","new_quantity":"0.14087956"},{"side":"offer","event_time":"2026-07-15T03:40:05.734632Z","price_level":"64606.48","new_quantity":"0"},{"side":"offer","event_time":"2026-07-15T03:40:05.734632Z","price_level":"64610.24","new_quantity":"0.00104535"},{"side":"offer","event_time":"2026-07-15T03:40:05.734632Z","price_level":"64616.49","new_quantity":"0"},{"side":"offer","event_time":"2026-07-15T03:40:05.734632Z","price_level":"64616.75","new_quantity":"0.00077422"},{"side":"offer","event_time":"2026-07-15T03:40:05.734632Z","price_level":"64620.42","new_quantity":"0"},{"side":"offer","event_time":"2026-07-15T03:40:05.734632Z","price_level":"64624.44","new_quantity":"0.45873352"},{"side":"offer","event_time":"2026-07-15T03:40:05.734632Z","price_level":"64628.27","new_quantity":"0.0859778"},{"side":"offer","event_time":"2026-07-15T03:40:05.734632Z","price_level":"64628.28","new_quantity":"0"},{"side":"offer","event_time":"2026-07-15T03:40:05.734632Z","price_level":"64638.8","new_quantity":"0.04656107"},{"side":"offer","event_time":"2026-07-15T03:40:05.734632Z","price_level":"64638.97","new_quantity":"0"},{"side":"offer","event_time":"2026-07-15T03:40:05.734632Z","price_level":"64643.96","new_quantity":"0"},{"side":"offer","event_time":"2026-07-15T03:40:05.734632Z","price_level":"64643.99","new_quantity":"0"},{"side":"offer","event_time":"2026-07-15T03:40:05.734632Z","price_level":"64685","new_quantity":"0"},{"side":"offer","event_time":"2026-07-15T03:40:05.734632Z","price_level":"64687.04","new_quantity":"0"},{"side":"offer","event_time":"2026-07-15T03:40:05.734632Z","price_level":"64848.96","new_quantity":"0"}]}]}
{"channel":"market_trades","timestamp":"2026-07-15T03:40:05.784841678Z","sequence_num":49,"events":[{"type":"update","trades":[{"product_id":"BTC-USD","trade_id":"1056309400","price":"64572.96","size":"0.00001797","time":"2026-07-15T03:40:05.71219Z","side":"BUY"}]}]}
{"channel":"l2_data","timestamp":"2026-07-15T03:40:05.833720151Z","sequence_num":50,"events":[{"type":"update","product_id":"BTC-USD","updates":[{"side":"bid","event_time":"2026-07-15T03:40:05.793591Z","price_level":"64567","new_quantity":"0.0334"},{"side":"bid","event_time":"2026-07-15T03:40:05.793591Z","price_level":"64565.78","new_quantity":"0.12390463"},{"side":"bid","event_time":"2026-07-15T03:40:05.793591Z","price_level":"64564.96","new_quantity":"0"},{"side":"bid","event_time":"2026-07-15T03:40:05.793591Z","price_level":"64564.23","new_quantity":"0.12378505"},{"side":"bid","event_time":"2026-07-15T03:40:05.793591Z","price_level":"64561.26","new_quantity":"0.12378505"},{"side":"bid","event_time":"2026-07-15T03:40:05.793591Z","price_level":"64551.99","new_quantity":"0.12"},{"side":"bid","event_time":"2026-07-15T03:40:05.793591Z","price_level":"64548.29","new_quantity":"0"},{"side":"bid","event_time":"2026-07-15T03:40:05.793591Z","price_level":"64543.01","new_quantity":"0.10247089"},{"side":"bid","event_time":"2026-07-15T03:40:05.793591Z","price_level":"64536.65","new_quantity":"0.06612991"},{"side":"bid","event_time":"2026-07-15T03:40:05.793591Z","price_level":"64536","new_quantity":"0"},{"side":"bid","event_time":"2026-07-15T03:40:05.793591Z","price_level":"64535.09","new_quantity":"0"},{"side":"bid","event_time":"2026-07-15T03:40:05.793591Z","price_level":"64534.31","new_quantity":"0.00077425"},{"side":"bid","event_time":"2026-07-15T03:40:05.793591Z","price_level":"64529.99","new_quantity":"0.60997077"},{"side":"bid","event_time":"2026-07-15T03:40:05.793591Z","price_level":"64505.67","new_quantity":"0"},{"side":"bid","event_time":"2026-07-15T03:40:05.793591Z","price_level":"64505.66","new_quantity":"0"},{"side":"bid","event_time":"2026-07-15T03:40:05.793591Z","price_level":"64501.17","new_quantity":"1.34985731"},{"side":"bid","event_time":"2026-07-15T03:40:05.793591Z","price_level":"64480.01","new_quantity":"2.15579647"},{"side":"bid","event_time":"2026-07-15T03:40:05.793591Z","price_level":"64480","new_quantity":"3"},{"side":"bid","event_time":"2026-07-15T03:40:05.793591Z","price_level":"64476.31","new_quantity":"0"},{"side":"offer","event_time":"2026-07-15T03:40:05.793591Z","price_level":"64572.94","new_quantity":"0.00159977"},{"side":"offer","event_time":"2026-07-15T03:40:05.793591Z","price_level":"64575.14","new_quantity":"0.12388668"},{"side":"offer","event_time":"2026-07-15T03:40:05.793591Z","price_level":"64576.62","new_quantity":"0.03093532"},{"side":"offer","event_time":"2026-07-15T03:40:05.793591Z","price_level":"64576.85","new_quantity":"0.07326"},{"side":"offer","event_time":"2026-07-15T03:40:05.793591Z","price_level":"64581.3","new_quantity":"0.00772597"},{"side":"offer","event_time":"2026-07-15T03:40:05.793591Z","price_level":"64581.94","new_quantity":"0"},{"side":"offer","event_time":"2026-07-15T03:40:05.793591Z","price_level":"64587.48","new_quantity":"0"},{"side":"offer","event_time":"2026-07-15T03:40:05.793591Z","price_level":"64587.55","new_quantity":"0.00100869"},{"side":"offer","event_time":"2026-07-15T03:40:05.793591Z","price_level":"64593.54","new_quantity":"0.67456319"},{"side":"offer","event_time":"2026-07-15T03:40:05.793591Z","price_level":"64594.5","new_quantity":"1"},{"side":"offer","event_time":"2026-07-15T03:40:05.793591Z","price_level":"64597.49","new_quantity":"0.20311123"},{"side":"offer","event_time":"2026-07-15T03:40:05.793591Z","price_level":"64599.63","new_quantity":"0.14"},{"side":"offer","event_time":"2026-07-15T03:40:05.793591Z","price_level":"64602","new_quantity":"0.00003194"},{"side":"offer","event_time":"2026-07-15T03:40:05.793591Z","price_level":"64618.33","new_quantity":"0.00383282"},{"side":"offer","event_time":"2026-07-15T03:40:05.793591Z","price_level":"64619","new_quantity":"0"},{"side":"offer","event_time":"2026-07-15T03:40:05.793591Z","price_level":"64619.41","new_quantity":"0.87948839"},{"side":"offer","event_time":"2026-07-15T03:40:05.793591Z","price_level":"64621.67","new_quantity":"1.43172994"},{"side":"offer","event_time":"2026-07-15T03:40:05.793591Z","price_level":"64622.64","new_quantity":"0.31225274"},{"side":"offer","event_time":"2026-07-15T03:40:05.793591Z","price_level":"64624.45","new_quantity":"0"},{"side":"offer","event_time":"2026-07-15T03:40:05.793591Z","price_level":"64628.25","new_quantity":"1.29601033"},{"side":"offer","event_time":"2026-07-15T03:40:05.793591Z","price_level":"64628.26","new_quantity":"2.02685516"},{"side":"offer","event_time":"2026-07-15T03:40:05.793591Z","price_level":"64628.27","new_quantity":"0"},{"side":"offer","event_time":"2026-07-15T03:40:05.793591Z","price_level":"64629.19","new_quantity":"0.02726552"},{"side":"offer","event_time":"2026-07-15T03:40:05.793591Z","price_level":"64631.12","new_quantity":"0"},{"side":"offer","event_time":"2026-07-15T03:40:05.793591Z","price_level":"64631.82","new_quantity":"0"},{"side":"offer","event_time":"2026-07-15T03:40:05.793591Z","price_level":"64668.75","new_quantity":"0.0479989"},{"side":"offer","event_time":"2026-07-15T03:40:05.793591Z","price_level":"64680","new_quantity":"3"},{"side":"offer","event_time":"2026-07-15T03:40:05.793591Z","price_level":"64690.62","new_quantity":"0.00958205"},{"side":"offer","event_time":"2026-07-15T03:40:05.793591Z","price_level":"64704.95","new_quantity":"0"},{"side":"offer","event_time":"2026-07-15T03:40:05.793591Z","price_level":"65222.4","new_quantity":"1.8"},{"side":"offer","event_time":"2026-07-15T03:40:05.793591Z","price_level":"65664.8","new_quantity":"0"}]}]}
{"channel":"l2_data","timestamp":"2026-07-15T03:40:05.885921864Z","sequence_num":51,"events":[{"type":"update","product_id":"BTC-USD","updates":[{"side":"bid","event_time":"2026-07-15T03:40:05.841385Z","price_level":"64567","new_quantity":"0"},{"side":"bid","event_time":"2026-07-15T03:40:05.841385Z","price_level":"64566","new_quantity":"0"},{"side":"bid","event_time":"2026-07-15T03:40:05.841385Z","price_level":"64565.78","new_quantity":"0"},{"side":"bid","event_time":"2026-07-15T03:40:05.841385Z","price_level":"64565.31","new_quantity":"0"},{"side":"bid","event_time":"2026-07-15T03:40:05.841385Z","price_level":"64564.39","new_quantity":"0.1239073"},{"side":"bid","event_time":"2026-07-15T03:40:05.841385Z","price_level":"64564.23","new_quantity":"0"},{"side":"bid","event_time":"2026-07-15T03:40:05.841385Z","price_level":"64561.26","new_quantity":"0"},{"side":"bid","event_time":"2026-07-15T03:40:05.841385Z","price_level":"64560.87","new_quantity":"0"},{"side":"bid","event_time":"2026-07-15T03:40:05.841385Z","price_level":"64560.65","new_quantity":"0"},{"side":"bid","event_time":"2026-07-15T03:40:05.841385Z","price_level":"64559.78","new_quantity":"0"},{"side":"bid","event_time":"2026-07-15T03:40:05.841385Z","price_level":"64559.26","new_quantity":"0"},{"side":"bid","event_time":"2026-07-15T03:40:05.841385Z","price_level":"64556.37","new_quantity":"0.06286963"},{"side":"bid","event_time":"2026-07-15T03:40:05.841385Z","price_level":"64556.36","new_quantity":"0.04656107"},{"side":"bid","event_time":"2026-07-15T03:40:05.841385Z","price_level":"64556.35","new_quantity":"0"},{"side":"bid","event_time":"2026-07-15T03:40:05.841385Z","price_level":"64556.34","new_quantity":"0"},{"side":"bid","event_time":"2026-07-15T03:40:05.841385Z","price_level":"64554.67","new_quantity":"0"},{"side":"bid","event_time":"2026-07-15T03:40:05.841385Z","price_level":"64554.17","new_quantity":"0"},{"side":"bid","event_time":"2026-07-15T03:40:05.841385Z","price_level":"64554.16","new_quantity":"0"},{"side":"bid","event_time":"2026-07-15T03:40:05.841385Z","price_level":"64552.1","new_quantity":"0"},{"side":"bid","event_time":"2026-07-15T03:40:05.841385Z","price_level":"64552.09","new_quantity":"0"},{"side":"bid","event_time":"2026-07-15T03:40:05.841385Z","price_level":"64551.99","new_quantity":"0"},{"side":"bid","event_time":"2026-07-15T03:40:05.841385Z","price_level":"64551.76","new_quantity":"0"},{"side":"bid","event_time":"2026-07-15T03:40:05.841385Z","price_level":"64551.02","new_quantity":"0.00772597"},{"side":"bid","event_time":"2026-07-15T03:40:05.841385Z","price_level":"64551.01","new_quantity":"0.10180004"},{"side":"bid","event_time":"2026-07-15T03:40:05.841385Z","price_level":"64550.7","new_quantity":"0"},{"side":"bid","event_time":"2026-07-15T03:40:05.841385Z","price_level":"64550.19","new_quantity":"0.12378505"},{"side":"bid","event_time":"2026-07-15T03:40:05.841385Z","price_level":"64549.65","new_quantity":"0.03093532"},{"side":"bid","event_time":"2026-07-15T03:40:05.841385Z","price_level":"64548.28","new_quantity":"0.09583174"},{"side":"bid","event_time":"2026-07-15T03:40:05.841385Z","price_level":"64546.82","new_quantity":"0"},{"side":"bid","event_time":"2026-07-15T03:40:05.841385Z","price_level":"64546.31","new_quantity":"0.12378505"},{"side":"bid","event_time":"2026-07-15T03:40:05.841385Z","price_level":"64545.89","new_quantity":"0"},{"side":"bid","event_time":"2026-07-15T03:40:05.841385Z","price_level":"64544.34","new_quantity":"0.11465322"},{"side":"bid","event_time":"2026-07-15T03:40:05.841385Z","price_level":"64543.08","new_quantity":"0.12378505"},{"side":"bid","event_time":"2026-07-15T03:40:05.841385Z","price_level":"64543.01","new_quantity":"0.00077426"},{"side":"bid","event_time":"2026-07-15T03:40:05.841385Z","price_level":"64542.94","new_quantity":"0"},{"side":"bid","event_time":"2026-07-15T03:40:05.841385Z","price_level":"64540.22","new_quantity":"0"},{"side":"bid","event_time":"2026-07-15T03:40:05.841385Z","price_level":"64540.21","new_quantity":"0"},{"side":"bid","event_time":"2026-07-15T03:40:05.841385Z","price_level":"64540.1","new_quantity":"0"},{"side":"bid","event_time":"2026-07-15T03:40:05.841385Z","price_level":"64539.43","new_quantity":"0.0194383"},{"side":"bid","event_time":"2026-07-15T03:40:05.841385Z","price_level":"64539.24","new_quantity":"0.0912699"},{"side":"bid","event_time":"2026-07-15T03:40:05.841385Z","price_level":"64539.23","new_quantity":"0.033361"},{"side":"bid","event_time":"2026-07-15T03:40:05.841385Z","price_level":"64539.2","new_quantity":"0.12378505"},{"side":"bid","event_time":"2026-07-15T03:40:05.841385Z","price_level":"64537.86","new_quantity":"0.06590089"},{"side":"bid","event_time":"2026-07-15T03:40:05.841385Z","price_level":"64536.65","new_quantity":"0"},{"side":"bid","event_time":"2026-07-15T03:40:05.841385Z","price_level":"64536.47","new_quantity":"0"},{"side":"bid","event_time":"2026-07-15T03:40:05.841385Z","price_level":"64536.33","new_quantity":"0"},{"side":"bid","event_time":"2026-07-15T03:40:05.841385Z","price_level":"64536.07","new_quantity":"0"},{"side":"bid","event_time":"2026-07-15T03:40:05.841385Z","price_level":"64535.32","new_quantity":"0.12378505"},{"side":"bid","event_time":"2026-07-15T03:40:05.841385Z","price_level":"64534.31","new_quantity":"0"},{"side":"bid","event_time":"2026-07-15T03:40:05.841385Z","price_level":"64533.7","new_quantity":"0"},{"side":"bid","event_time":"2026-07-15T03:40:05.841385Z","price_level":"64532.45","new_quantity":"0.12378505"},{"side":"bid","event_time":"2026-07-15T03:40:05.841385Z","price_level":"64531.33","new_quantity":"0.97374943"},{"side":"bid","event_time":"2026-07-15T03:40:05.841385Z","price_level":"64531.32","new_quantity":"0.93193761"},{"side":"bid","event_time":"2026-07-15T03:40:05.841385Z","price_level":"64531.31","new_quantity":"0"},{"side":"bid","event_time":"2026-07-15T03:40:05.841385Z","price_level":"64528.58","new_quantity":"0.11171367"},{"side":"bid","event_time":"2026-07-15T03:40:05.841385Z","price_level":"64528.57","new_quantity":"0.12378505"},{"side":"bid","event_time":"2026-07-15T03:40:05.841385Z","price_level":"64527.75","new_quantity":"0"},{"side":"bid","event_time":"2026-07-15T03:40:05.841385Z","price_level":"64525.02","new_quantity":"0.10924697"},{"side":"bid","event_time":"2026-07-15T03:40:05.841385Z","price_level":"64524.69","new_quantity":"0.12378505"},{"side":"bid","event_time":"2026-07-15T03:40:05.841385Z","price_level":"64522.07","new_quantity":"0.3527128"},{"side":"bid","event_time":"2026-07-15T03:40:05.841385Z","price_level":"64520.81","new_quantity":"0.12378505"},{"side":"bid","event_time":"2026-07-15T03:40:05.841385Z","price_level":"64520.68","new_quantity":"0.448644"},{"side":"bid","event_time":"2026-07-15T03:40:05.841385Z","price_level":"64516.93","new_quantity":"0.12378505"},{"side":"bid","event_time":"2026-07-15T03:40:05.841385Z","price_level":"64516.48","new_quantity":"0.07749639"},{"side":"bid","event_time":"2026-07-15T03:40:05.841385Z","price_level":"64511.24","new_quantity":"0"},{"side":"bid","event_time":"2026-07-15T03:40:05.841385Z","price_level":"64506.15","new_quantity":"0.08670458"},{"side":"bid","event_time":"2026-07-15T03:40:05.841385Z","price_level":"64506.14","new_quantity":"0.07749639"},{"side":"bid","event_time":"2026-07-15T03:40:05.841385Z","price_level":"64505.65","new_quantity":"0"},{"side":"bid","event_time":"2026-07-15T03:40:05.841385Z","price_level":"64501.18","new_quantity":"4.26518727"},{"side":"bid","event_time":"2026-07-15T03:40:05.841385Z","price_level":"64486.26","new_quantity":"1.76987242"},{"side":"bid","event_time":"2026-07-15T03:40:05.841385Z","price_level":"64348.29","new_quantity":"16.113428"},{"side":"offer","event_time":"2026-07-15T03:40:05.841385Z","price_level":"64569.29","new_quantity":"0.25209674"},{"side":"offer","event_time":"2026-07-15T03:40:05.841385Z","price_level":"64571.23","new_quantity":"0.12378505"},{"side":"offer","event_time":"2026-07-15T03:40:05.841385Z","price_level":"64573.63","new_quantity":"0.12378505"},{"side":"offer","event_time":"2026-07-15T03:40:05.841385Z","price_level":"64579.27","new_quantity":"0"},{"side":"offer","event_time":"2026-07-15T03:40:05.841385Z","price_level":"64581.31","new_quantity":"0"},{"side":"offer","event_time":"2026-07-15T03:40:05.841385Z","price_level":"64585.56","new_quantity":"0.00100869"},{"side":"offer","event_time":"2026-07-15T03:40:05.841385Z","price_level":"64585.8","new_quantity":"0.05821782"},{"side":"offer","event_time":"2026-07-15T03:40:05.841385Z","price_level":"64587.55","new_quantity":"0"},{"side":"offer","event_time":"2026-07-15T03:40:05.841385Z","price_level":"64595.25","new_quantity":"0.00077433"},{"side":"offer","event_time":"2026-07-15T03:40:05.841385Z","price_level":"64597.49","new_quantity":"0.57594681"},{"side":"offer","event_time":"2026-07-15T03:40:05.841385Z","price_level":"64597.84","new_quantity":"0"},{"side":"offer","event_time":"2026-07-15T03:40:05.841385Z","price_level":"64599.6","new_quantity":"0"},{"side":"offer","event_time":"2026-07-15T03:40:05.841385Z","price_level":"64599.62","new_quantity":"0.63866159"},{"side":"offer","event_time":"2026-07-15T03:40:05.841385Z","price_level":"64599.63","new_quantity":"0"},{"side":"offer","event_time":"2026-07-15T03:40:05.841385Z","price_level":"64600.49","new_quantity":"0.0783803"},{"side":"offer","event_time":"2026-07-15T03:40:05.841385Z","price_level":"64601.73","new_quantity":"0"},{"side":"offer","event_time":"2026-07-15T03:40:05.841385Z","price_level":"64603.26","new_quantity":"0.07485218"},{"side":"offer","event_time":"2026-07-15T03:40:05.841385Z","price_level":"64603.39","new_quantity":"0.04257049"},{"side":"offer","event_time":"2026-07-15T03:40:05.841385Z","price_level":"64603.49","new_quantity":"0"},{"side":"offer","event_time":"2026-07-15T03:40:05.841385Z","price_level":"64604.57","new_quantity":"0"},{"side":"offer","event_time":"2026-07-15T03:40:05.841385Z","price_level":"64606.47","new_quantity":"0.06697989"},{"side":"offer","event_time":"2026-07-15T03:40:05.841385Z","price_level":"64606.51","new_quantity":"0"},{"side":"offer","event_time":"2026-07-15T03:40:05.841385Z","price_level":"64616.75","new_quantity":"0"},{"side":"offer","event_time":"2026-07-15T03:40:05.841385Z","price_level":"64621.66","new_quantity":"0.45875325"},{"side":"offer","event_time":"2026-07-15T03:40:05.841385Z","price_level":"64622.63","new_quantity":"0.00077426"},{"side":"offer","event_time":"2026-07-15T03:40:05.841385Z","price_level":"64622.64","new_quantity":"0.01940645"},{"side":"offer","event_time":"2026-07-15T03:40:05.841385Z","price_level":"64624.44","new_quantity":"0"},{"side":"offer","event_time":"2026-07-15T03:40:05.841385Z","price_level":"64624.46","new_quantity":"0"},{"side":"offer","event_time":"2026-07-15T03:40:05.841385Z","price_level":"64624.8","new_quantity":"0.00158739"},{"side":"offer","event_time":"2026-07-15T03:40:05.841385Z","price_level":"64631.11","new_quantity":"0"},{"side":"offer","event_time":"2026-07-15T03:40:05.841385Z","price_level":"64633.62","new_quantity":"0.00077427"},{"side":"offer","event_time":"2026-07-15T03:40:05.841385Z","price_level":"64636.32","new_quantity":"0"},{"side":"offer","event_time":"2026-07-15T03:40:05.841385Z","price_level":"64641.18","new_quantity":"0"},{"side":"offer","event_time":"2026-07-15T03:40:05.841385Z","price_level":"64867","new_quantity":"0"}]}]}
{"channel":"l2_data","timestamp":"2026-07-15T03:40:05.93552149Z","sequence_num":52,"events":[{"type":"update","product_id":"BTC-USD","updates":[{"side":"bid","event_time":"2026-07-15T03:40:05.902713Z","price_level":"64569.28","new_quantity":"0"},{"side":"bid","event_time":"2026-07-15T03:40:05.902713Z","price_level":"64564.39","new_quantity":"0"},{"side":"bid","event_time":"2026-07-15T03:40:05.902713Z","price_level":"64564","new_quantity":"0"},{"side":"bid","event_time":"2026-07-15T03:40:05.902713Z","price_level":"64562","new_quantity":"0.0245"},{"side":"bid","event_time":"2026-07-15T03:40:05.902713Z","price_level":"64560.86","new_quantity":"0"},{"side":"bid","event_time":"2026-07-15T03:40:05.902713Z","price_level":"64560","new_quantity":"0.0245"},{"side":"bid","event_time":"2026-07-15T03:40:05.902713Z","price_level":"64559.8","new_quantity":"0"},{"side":"bid","event_time":"2026-07-15T03:40:05.902713Z","price_level":"64559.29","new_quantity":"0"},{"side":"bid","event_time":"2026-07-15T03:40:05.902713Z","price_level":"64557.22","new_quantity":"0"},{"side":"bid","event_time":"2026-07-15T03:40:05.902713Z","price_level":"64556.86","new_quantity":"0.03369931"},{"side":"bid","event_time":"2026-07-15T03:40:05.902713Z","price_level":"64556.77","new_quantity":"0"},{"side":"bid","event_time":"2026-07-15T03:40:05.902713Z","price_level":"64556.39","new_quantity":"0.04656107"},{"side":"bid","event_time":"2026-07-15T03:40:05.902713Z","price_level":"64556.38","new_quantity":"0.02"},{"side":"bid","event_time":"2026-07-15T03:40:05.902713Z","price_level":"64556.37","new_quantity":"0"},{"side":"bid","event_time":"2026-07-15T03:40:05.902713Z","price_level":"64556.36","new_quantity":"0"},{"side":"bid","event_time":"2026-07-15T03:40:05.902713Z","price_level":"64554.19","new_quantity":"0"},{"side":"bid","event_time":"2026-07-15T03:40:05.902713Z","price_level":"64554.15","new_quantity":"0"},{"side":"bid","event_time":"2026-07-15T03:40:05.902713Z","price_level":"64551.02","new_quantity":"0"},{"side":"bid","event_time":"2026-07-15T03:40:05.902713Z","price_level":"64550.2","new_quantity":"0.04656107"},{"side":"bid","event_time":"2026-07-15T03:40:05.902713Z","price_level":"64550.19","new_quantity":"0"},{"side":"bid","event_time":"2026-07-15T03:40:05.902713Z","price_level":"64546.31","new_quantity":"0"},{"side":"bid","event_time":"2026-07-15T03:40:05.902713Z","price_level":"64543.01","new_quantity":"0"},{"side":"bid","event_time":"2026-07-15T03:40:05.902713Z","price_level":"64539.69","new_quantity":"0.41612097"},{"side":"bid","event_time":"2026-07-15T03:40:05.902713Z","price_level":"64539.68","new_quantity":"0"},{"side":"bid","event_time":"2026-07-15T03:40:05.902713Z","price_level":"64539.43","new_quantity":"0"},{"side":"bid","event_time":"2026-07-15T03:40:05.902713Z","price_level":"64539.31","new_quantity":"0"},{"side":"bid","event_time":"2026-07-15T03:40:05.902713Z","price_level":"64539.24","new_quantity":"0"},{"side":"bid","event_time":"2026-07-15T03:40:05.902713Z","price_level":"64539.23","new_quantity":"0"},{"side":"bid","event_time":"2026-07-15T03:40:05.902713Z","price_level":"64538.58","new_quantity":"0.04626534"},{"side":"bid","event_time":"2026-07-15T03:40:05.902713Z","price_level":"64537.86","new_quantity":"0"},{"side":"bid","event_time":"2026-07-15T03:40:05.902713Z","price_level":"64535.33","new_quantity":"0.73834655"},{"side":"bid","event_time":"2026-07-15T03:40:05.902713Z","price_level":"64533","new_quantity":"1"},{"side":"bid","event_time":"2026-07-15T03:40:05.902713Z","price_level":"64531.44","new_quantity":"0"},{"side":"bid","event_time":"2026-07-15T03:40:05.902713Z","price_level":"64531.33","new_quantity":"0.60989538"},{"side":"bid","event_time":"2026-07-15T03:40:05.902713Z","price_level":"64531.32","new_quantity":"0.93193761"},{"side":"bid","event_time":"2026-07-15T03:40:05.902713Z","price_level":"64530.53","new_quantity":"0.0005"},{"side":"bid","event_time":"2026-07-15T03:40:05.902713Z","price_level":"64529.99","new_quantity":"0"},{"side":"bid","event_time":"2026-07-15T03:40:05.902713Z","price_level":"64528.58","new_quantity":"0.46159648"},{"side":"bid","event_time":"2026-07-15T03:40:05.902713Z","price_level":"64527.75","new_quantity":"0.60999194"},{"side":"bid","event_time":"2026-07-15T03:40:05.902713Z","price_level":"64519.35","new_quantity":"0"},{"side":"bid","event_time":"2026-07-15T03:40:05.902713Z","price_level":"64516.93","new_quantity":"0"},{"side":"bid","event_time":"2026-07-15T03:40:05.902713Z","price_level":"64516.46","new_quantity":"0"},{"side":"bid","event_time":"2026-07-15T03:40:05.902713Z","price_level":"64513.47","new_quantity":"0"},{"side":"bid","event_time":"2026-07-15T03:40:05.902713Z","price_level":"64512.51","new_quantity":"0.41199559"},{"side":"bid","event_time":"2026-07-15T03:40:05.902713Z","price_level":"64511.02","new_quantity":"0"},{"side":"bid","event_time":"2026-07-15T03:40:05.902713Z","price_level":"64504.4","new_quantity":"0.26328496"},{"side":"bid","event_time":"2026-07-15T03:40:05.902713Z","price_level":"64501.17","new_quantity":"0"},{"side":"bid","event_time":"2026-07-15T03:40:05.902713Z","price_level":"64501.16","new_quantity":"0"},{"side":"bid","event_time":"2026-07-15T03:40:05.902713Z","price_level":"64493.38","new_quantity":"0"},{"side":"bid","event_time":"2026-07-15T03:40:05.902713Z","price_level":"64490.97","new_quantity":"0.94453042"},{"side":"bid","event_time":"2026-07-15T03:40:05.902713Z","price_level":"64490.96","new_quantity":"1.35007101"},{"side":"bid","event_time":"2026-07-15T03:40:05.902713Z","price_level":"64490.95","new_quantity":"0"},{"side":"bid","event_time":"2026-07-15T03:40:05.902713Z","price_level":"64486.26","new_quantity":"0.60001232"},{"side":"bid","event_time":"2026-07-15T03:40:05.902713Z","price_level":"64475.02","new_quantity":"0.04986811"},{"side":"bid","event_time":"2026-07-15T03:40:05.902713Z","price_level":"64470.84","new_quantity":"0.01095977"},{"side":"bid","event_time":"2026-07-15T03:40:05.902713Z","price_level":"64448.3","new_quantity":"0.01079298"},{"side":"bid","event_time":"2026-07-15T03:40:05.902713Z","price_level":"64447.13","new_quantity":"0"},{"side":"bid","event_time":"2026-07-15T03:40:05.902713Z","price_level":"64442.83","new_quantity":"0.00002324"},{"side":"bid","event_time":"2026-07-15T03:40:05.902713Z","price_level":"64425.76","new_quantity":"0.01057203"},{"side":"bid","event_time":"2026-07-15T03:40:05.902713Z","price_level":"64418.09","new_quantity":"0"},{"side":"bid","event_time":"2026-07-15T03:40:05.902713Z","price_level":"64355.54","new_quantity":"0.023205"},{"side":"offer","event_time":"2026-07-15T03:40:05.902713Z","price_level":"64565.61","new_quantity":"0.27731367"},{"side":"offer","event_time":"2026-07-15T03:40:05.902713Z","price_level":"64566","new_quantity":"0.0245"},{"side":"offer","event_time":"2026-07-15T03:40:05.902713Z","price_level":"64568.28","new_quantity":"0.0665662"},{"side":"offer","event_time":"2026-07-15T03:40:05.902713Z","price_level":"64568.29","new_quantity":"0.22195125"},{"side":"offer","event_time":"2026-07-15T03:40:05.902713Z","price_level":"64569.26","new_quantity":"0.15487247"},{"side":"offer","event_time":"2026-07-15T03:40:05.902713Z","price_level":"64569.28","new_quantity":"0.00774384"},{"side":"offer","event_time":"2026-07-15T03:40:05.902713Z","price_level":"64569.29","new_quantity":"0"},{"side":"offer","event_time":"2026-07-15T03:40:05.902713Z","price_level":"64570.9","new_quantity":"0.00774384"},{"side":"offer","event_time":"2026-07-15T03:40:05.902713Z","price_level":"64571.14","new_quantity":"0.048285"},{"side":"offer","event_time":"2026-07-15T03:40:05.902713Z","price_level":"64571.21","new_quantity":"0.03093532"},{"side":"offer","event_time":"2026-07-15T03:40:05.902713Z","price_level":"64571.22","new_quantity":"0.17034612"},{"side":"offer","event_time":"2026-07-15T03:40:05.902713Z","price_level":"64571.23","new_quantity":"0"},{"side":"offer","event_time":"2026-07-15T03:40:05.902713Z","price_level":"64572.71","new_quantity":"0"},{"side":"offer","event_time":"2026-07-15T03:40:05.902713Z","price_level":"64572.94","new_quantity":"0"},{"side":"offer","event_time":"2026-07-15T03:40:05.902713Z","price_level":"64572.96","new_quantity":"0"},{"side":"offer","event_time":"2026-07-15T03:40:05.902713Z","price_level":"64573.08","new_quantity":"0.0096798"},{"side":"offer","event_time":"2026-07-15T03:40:05.902713Z","price_level":"64573.63","new_quantity":"0"},{"side":"offer","event_time":"2026-07-15T03:40:05.902713Z","price_level":"64574.59","new_quantity":"0"},{"side":"offer","event_time":"2026-07-15T03:40:05.902713Z","price_level":"64575.14","new_quantity":"0"},{"side":"offer","event_time":"2026-07-15T03:40:05.902713Z","price_level":"64575.99","new_quantity":"0.00772597"},{"side":"offer","event_time":"2026-07-15T03:40:05.902713Z","price_level":"64576.61","new_quantity":"0.12378505"},{"side":"offer","event_time":"2026-07-15T03:40:05.902713Z","price_level":"64576.64","new_quantity":"0"},{"side":"offer","event_time":"2026-07-15T03:40:05.902713Z","price_level":"64576.65","new_quantity":"0"},{"side":"offer","event_time":"2026-07-15T03:40:05.902713Z","price_level":"64576.77","new_quantity":"0"},{"side":"offer","event_time":"2026-07-15T03:40:05.902713Z","price_level":"64578.16","new_quantity":"0"},{"side":"offer","event_time":"2026-07-15T03:40:05.902713Z","price_level":"64579.68","new_quantity":"0.12378505"},{"side":"offer","event_time":"2026-07-15T03:40:05.902713Z","price_level":"64579.98","new_quantity":"0"},{"side":"offer","event_time":"2026-07-15T03:40:05.902713Z","price_level":"64581.29","new_quantity":"0.179558"},{"side":"offer","event_time":"2026-07-15T03:40:05.902713Z","price_level":"64581.3","new_quantity":"0"},{"side":"offer","event_time":"2026-07-15T03:40:05.902713Z","price_level":"64581.86","new_quantity":"0"},{"side":"offer","event_time":"2026-07-15T03:40:05.902713Z","price_level":"64581.94","new_quantity":"0.00100869"},{"side":"offer","event_time":"2026-07-15T03:40:05.902713Z","price_level":"64583.85","new_quantity":"0.21997127"},{"side":"offer","event_time":"2026-07-15T03:40:05.902713Z","price_level":"64583.86","new_quantity":"0.12378505"},{"side":"offer","event_time":"2026-07-15T03:40:05.902713Z","price_level":"64584.2","new_quantity":"0"},{"side":"offer","event_time":"2026-07-15T03:40:05.902713Z","price_level":"64584.21","new_quantity":"0"},{"side":"offer","event_time":"2026-07-15T03:40:05.902713Z","price_level":"64584.74","new_quantity":"0"},{"side":"offer","event_time":"2026-07-15T03:40:05.902713Z","price_level":"64585.56","new_quantity":"0"},{"side":"offer","event_time":"2026-07-15T03:40:05.902713Z","price_level":"64587.66","new_quantity":"0.14056461"},{"side":"offer","event_time":"2026-07-15T03:40:05.902713Z","price_level":"64587.67","new_quantity":"0.12378505"},{"side":"offer","event_time":"2026-07-15T03:40:05.902713Z","price_level":"64587.68","new_quantity":"0"},{"side":"offer","event_time":"2026-07-15T03:40:05.902713Z","price_level":"64587.93","new_quantity":"0"},{"side":"offer","event_time":"2026-07-15T03:40:05.902713Z","price_level":"64588.09","new_quantity":"0"},{"side":"offer","event_time":"2026-07-15T03:40:05.902713Z","price_level":"64589.33","new_quantity":"0.06"},{"side":"offer","event_time":"2026-07-15T03:40:05.902713Z","price_level":"64589.59","new_quantity":"0.448644"},{"side":"offer","event_time":"2026-07-15T03:40:05.902713Z","price_level":"64590.26","new_quantity":"0.02739466"},{"side":"offer","event_time":"2026-07-15T03:40:05.902713Z","price_level":"64590.3","new_quantity":"0"},{"side":"offer","event_time":"2026-07-15T03:40:05.902713Z","price_level":"64591.12","new_quantity":"0"},{"side":"offer","event_time":"2026-07-15T03:40:05.902713Z","price_level":"64591.79","new_quantity":"0.00077433"},{"side":"offer","event_time":"2026-07-15T03:40:05.902713Z","price_level":"64593.39","new_quantity":"0"},{"side":"offer","event_time":"2026-07-15T03:40:05.902713Z","price_level":"64593.54","new_quantity":"0.12305386"},{"side":"offer","event_time":"2026-07-15T03:40:05.902713Z","price_level":"64594.31","new_quantity":"0"},{"side":"offer","event_time":"2026-07-15T03:40:05.902713Z","price_level":"64594.5","new_quantity":"0"},{"side":"offer","event_time":"2026-07-15T03:40:05.902713Z","price_level":"64595.25","new_quantity":"0"},{"side":"offer","event_time":"2026-07-15T03:40:05.902713Z","price_level":"64597.5","new_quantity":"0"},{"side":"offer","event_time":"2026-07-15T03:40:05.902713Z","price_level":"64600.69","new_quantity":"0"},{"side":"offer","event_time":"2026-07-15T03:40:05.902713Z","price_level":"64601.89","new_quantity":"0"},{"side":"offer","event_time":"2026-07-15T03:40:05.902713Z","price_level":"64603.88","new_quantity":"0"},{"side":"offer","event_time":"2026-07-15T03:40:05.902713Z","price_level":"64606.47","new_quantity":"0.04942803"},{"side":"offer","event_time":"2026-07-15T03:40:05.902713Z","price_level":"64606.62","new_quantity":"0"},{"side":"offer","event_time":"2026-07-15T03:40:05.902713Z","price_level":"64607.07","new_quantity":"0"},{"side":"offer","event_time":"2026-07-15T03:40:05.902713Z","price_level":"64610.26","new_quantity":"0"},{"side":"offer","event_time":"2026-07-15T03:40:05.902713Z","price_level":"64613.41","new_quantity":"0"},{"side":"offer","event_time":"2026-07-15T03:40:05.902713Z","price_level":"64613.45","new_quantity":"0"},{"side":"offer","event_time":"2026-07-15T03:40:05.902713Z","price_level":"64616.52","new_quantity":"1.43184405"},{"side":"offer","event_time":"2026-07-15T03:40:05.902713Z","price_level":"64616.54","new_quantity":"0"},{"side":"offer","event_time":"2026-07-15T03:40:05.902713Z","price_level":"64618.67","new_quantity":"0"},{"side":"offer","event_time":"2026-07-15T03:40:05.902713Z","price_level":"64620.77","new_quantity":"0"},{"side":"offer","event_time":"2026-07-15T03:40:05.902713Z","price_level":"64621.67","new_quantity":"0"},{"side":"offer","event_time":"2026-07-15T03:40:05.902713Z","price_level":"64628.14","new_quantity":"2.12739258"},{"side":"offer","event_time":"2026-07-15T03:40:05.902713Z","price_level":"64628.15","new_quantity":"1.39258208"},{"side":"offer","event_time":"2026-07-15T03:40:05.902713Z","price_level":"64628.25","new_quantity":"0"},{"side":"offer","event_time":"2026-07-15T03:40:05.902713Z","price_level":"64633.56","new_quantity":"0.03791712"},{"side":"offer","event_time":"2026-07-15T03:40:05.902713Z","price_level":"64633.57","new_quantity":"0"},{"side":"offer","event_time":"2026-07-15T03:40:05.902713Z","price_level":"64638.8","new_quantity":"0"},{"side":"offer","event_time":"2026-07-15T03:40:05.902713Z","price_level":"64648.45","new_quantity":"0.01096735"},{"side":"offer","event_time":"2026-07-15T03:40:05.902713Z","price_level":"64662.68","new_quantity":"0"},{"side":"offer","event_time":"2026-07-15T03:40:05.902713Z","price_level":"64662.69","new_quantity":"0"},{"side":"offer","event_time":"2026-07-15T03:40:05.902713Z","price_level":"64671.06","new_quantity":"0.01096844"},{"side":"offer","event_time":"2026-07-15T03:40:05.902713Z","price_level":"64680","new_quantity":"0"},{"side":"offer","event_time":"2026-07-15T03:40:05.902713Z","price_level":"64681.96","new_quantity":"0"},{"side":"offer","event_time":"2026-07-15T03:40:05.902713Z","price_level":"64704.07","new_quantity":"0"},{"side":"offer","event_time":"2026-07-15T03:40:05.902713Z","price_level":"64747.72","new_quantity":"0"},{"side":"offer","event_time":"2026-07-15T03:40:05.902713Z","price_level":"64856.92","new_quantity":"0"}]}]}
{"channel":"l2_data","timestamp":"2026-07-15T03:40:05.982059162Z","sequence_num":53,"events":[{"type":"update","product_id":"BTC-USD","updates":[{"side":"bid","event_time":"2026-07-15T03:40:05.955355Z","price_level":"64562","new_quantity":"0"},{"side":"bid","event_time":"2026-07-15T03:40:05.955355Z","price_level":"64560","new_quantity":"0"},{"side":"bid","event_time":"2026-07-15T03:40:05.955355Z","price_level":"64556.86","new_quantity":"0"},{"side":"bid","event_time":"2026-07-15T03:40:05.955355Z","price_level":"64556.4","new_quantity":"0.04656107"},{"side":"bid","event_time":"2026-07-15T03:40:05.955355Z","price_level":"64556.39","new_quantity":"0"},{"side":"bid","event_time":"2026-07-15T03:40:05.955355Z","price_level":"64555.94","new_quantity":"0"},{"side":"bid","event_time":"2026-07-15T03:40:05.955355Z","price_level":"64554.8","new_quantity":"0"},{"side":"bid","event_time":"2026-07-15T03:40:05.955355Z","price_level":"64552","new_quantity":"0"},{"side":"bid","event_time":"2026-07-15T03:40:05.955355Z","price_level":"64551.01","new_quantity":"0"},{"side":"bid","event_time":"2026-07-15T03:40:05.955355Z","price_level":"64549.65","new_quantity":"0"},{"side":"bid","event_time":"2026-07-15T03:40:05.955355Z","price_level":"64548.28","new_quantity":"0.03390454"},{"side":"bid","event_time":"2026-07-15T03:40:05.955355Z","price_level":"64544.34","new_quantity":"0.04672758"},{"side":"bid","event_time":"2026-07-15T03:40:05.955355Z","price_level":"64543.08","new_quantity":"0"},{"side":"bid","event_time":"2026-07-15T03:40:05.955355Z","price_level":"64543.01","new_quantity":"0"},{"side":"bid","event_time":"2026-07-15T03:40:05.955355Z","price_level":"64540.08","new_quantity":"0.12378505"},{"side":"bid","event_time":"2026-07-15T03:40:05.955355Z","price_level":"64539.69","new_quantity":"0"},{"side":"bid","event_time":"2026-07-15T03:40:05.955355Z","price_level":"64539.2","new_quantity":"0"},{"side":"bid","event_time":"2026-07-15T03:40:05.955355Z","price_level":"64537.87","new_quantity":"0.00077439"},{"side":"bid","event_time":"2026-07-15T03:40:05.955355Z","price_level":"64537.43","new_quantity":"0.12378505"},{"side":"bid","event_time":"2026-07-15T03:40:05.955355Z","price_level":"64535.33","new_quantity":"0"},{"side":"bid","event_time":"2026-07-15T03:40:05.955355Z","price_level":"64535.32","new_quantity":"0"},{"side":"bid","event_time":"2026-07-15T03:40:05.955355Z","price_level":"64535.3","new_quantity":"0.12378505"},{"side":"bid","event_time":"2026-07-15T03:40:05.955355Z","price_level":"64534.3","new_quantity":"0"},{"side":"bid","event_time":"2026-07-15T03:40:05.955355Z","price_level":"64533.57","new_quantity":"0.02684355"},{"side":"bid","event_time":"2026-07-15T03:40:05.955355Z","price_level":"64533.31","new_quantity":"0.12378505"},{"side":"bid","event_time":"2026-07-15T03:40:05.955355Z","price_level":"64533","new_quantity":"0.00003194"},{"side":"bid","event_time":"2026-07-15T03:40:05.955355Z","price_level":"64532.45","new_quantity":"0"},{"side":"bid","event_time":"2026-07-15T03:40:05.955355Z","price_level":"64531.34","new_quantity":"0.12378505"},{"side":"bid","event_time":"2026-07-15T03:40:05.955355Z","price_level":"64531.33","new_quantity":"0"},{"side":"bid","event_time":"2026-07-15T03:40:05.955355Z","price_level":"64531.32","new_quantity":"0"},{"side":"bid","event_time":"2026-07-15T03:40:05.955355Z","price_level":"64530.51","new_quantity":"0"},{"side":"bid","event_time":"2026-07-15T03:40:05.955355Z","price_level":"64528.58","new_quantity":"0"},{"side":"bid","event_time":"2026-07-15T03:40:05.955355Z","price_level":"64527.32","new_quantity":"0"},{"side":"bid","event_time":"2026-07-15T03:40:05.955355Z","price_level":"64526.13","new_quantity":"0.93201257"},{"side":"bid","event_time":"2026-07-15T03:40:05.955355Z","price_level":"64525.5","new_quantity":"1"},{"side":"bid","event_time":"2026-07-15T03:40:05.955355Z","price_level":"64522.08","new_quantity":"0"},{"side":"bid","event_time":"2026-07-15T03:40:05.955355Z","price_level":"64516.93","new_quantity":"0.12378505"},{"side":"bid","event_time":"2026-07-15T03:40:05.955355Z","price_level":"64516.49","new_quantity":"0"},{"side":"bid","event_time":"2026-07-15T03:40:05.955355Z","price_level":"64516.47","new_quantity":"0"},{"side":"bid","event_time":"2026-07-15T03:40:05.955355Z","price_level":"64513.05","new_quantity":"0.12378505"},{"side":"bid","event_time":"2026-07-15T03:40:05.955355Z","price_level":"64512.51","new_quantity":"0.29216751"},{"side":"bid","event_time":"2026-07-15T03:40:05.955355Z","price_level":"64509.17","new_quantity":"0"},{"side":"bid","event_time":"2026-07-15T03:40:05.955355Z","price_level":"64506.47","new_quantity":"0"},{"side":"bid","event_time":"2026-07-15T03:40:05.955355Z","price_level":"64506.16","new_quantity":"0.01158896"},{"side":"bid","event_time":"2026-07-15T03:40:05.955355Z","price_level":"64506.15","new_quantity":"0.2328007"},{"side":"bid","event_time":"2026-07-15T03:40:05.955355Z","price_level":"64502.56","new_quantity":"1.07837154"},{"side":"bid","event_time":"2026-07-15T03:40:05.955355Z","price_level":"64502.31","new_quantity":"0.00598614"},{"side":"bid","event_time":"2026-07-15T03:40:05.955355Z","price_level":"64501.18","new_quantity":"0"},{"side":"bid","event_time":"2026-07-15T03:40:05.955355Z","price_level":"64501.16","new_quantity":"0.00510813"},{"side":"bid","event_time":"2026-07-15T03:40:05.955355Z","price_level":"64489.27","new_quantity":"0.84029976"},{"side":"bid","event_time":"2026-07-15T03:40:05.955355Z","price_level":"64488.03","new_quantity":"0.001859"},{"side":"bid","event_time":"2026-07-15T03:40:05.955355Z","price_level":"64486.26","new_quantity":"0"},{"side":"bid","event_time":"2026-07-15T03:40:05.955355Z","price_level":"64476.3","new_quantity":"0"},{"side":"bid","event_time":"2026-07-15T03:40:05.955355Z","price_level":"64470.01","new_quantity":"0.02317792"},{"side":"bid","event_time":"2026-07-15T03:40:05.955355Z","price_level":"64450.7","new_quantity":"0"},{"side":"bid","event_time":"2026-07-15T03:40:05.955355Z","price_level":"64436.61","new_quantity":"0.03476688"},{"side":"offer","event_time":"2026-07-15T03:40:05.955355Z","price_level":"64565.61","new_quantity":"0.31202564"},{"side":"offer","event_time":"2026-07-15T03:40:05.955355Z","price_level":"64565.87","new_quantity":"0.17034612"},{"side":"offer","event_time":"2026-07-15T03:40:05.955355Z","price_level":"64565.88","new_quantity":"0.03093532"},{"side":"offer","event_time":"2026-07-15T03:40:05.955355Z","price_level":"64565.89","new_quantity":"0.12390444"},{"side":"offer","event_time":"2026-07-15T03:40:05.955355Z","price_level":"64568.27","new_quantity":"0.12378505"},{"side":"offer","event_time":"2026-07-15T03:40:05.955355Z","price_level":"64568.28","new_quantity":"0.00159977"},{"side":"offer","event_time":"2026-07-15T03:40:05.955355Z","price_level":"64568.29","new_quantity":"0"},{"side":"offer","event_time":"2026-07-15T03:40:05.955355Z","price_level":"64571.14","new_quantity":"0"},{"side":"offer","event_time":"2026-07-15T03:40:05.955355Z","price_level":"64573.16","new_quantity":"0.07326"},{"side":"offer","event_time":"2026-07-15T03:40:05.955355Z","price_level":"64575.42","new_quantity":"0.00038328"},{"side":"offer","event_time":"2026-07-15T03:40:05.955355Z","price_level":"64575.69","new_quantity":"0.05933069"},{"side":"offer","event_time":"2026-07-15T03:40:05.955355Z","price_level":"64578.02","new_quantity":"0"},{"side":"offer","event_time":"2026-07-15T03:40:05.955355Z","price_level":"64578.51","new_quantity":"0.00076656"},{"side":"offer","event_time":"2026-07-15T03:40:05.955355Z","price_level":"64581.29","new_quantity":"0"},{"side":"offer","event_time":"2026-07-15T03:40:05.955355Z","price_level":"64581.94","new_quantity":"0"},{"side":"offer","event_time":"2026-07-15T03:40:05.955355Z","price_level":"64582.08","new_quantity":"0"},{"side":"offer","event_time":"2026-07-15T03:40:05.955355Z","price_level":"64584.97","new_quantity":"0"},{"side":"offer","event_time":"2026-07-15T03:40:05.955355Z","price_level":"64587.66","new_quantity":"0.42509803"},{"side":"offer","event_time":"2026-07-15T03:40:05.955355Z","price_level":"64587.67","new_quantity":"0.12455943"},{"side":"offer","event_time":"2026-07-15T03:40:05.955355Z","price_level":"64588","new_quantity":"0"},{"side":"offer","event_time":"2026-07-15T03:40:05.955355Z","price_level":"64589.79","new_quantity":"0.04447109"},{"side":"offer","event_time":"2026-07-15T03:40:05.955355Z","price_level":"64590","new_quantity":"0"},{"side":"offer","event_time":"2026-07-15T03:40:05.955355Z","price_level":"64591.33","new_quantity":"0.49308925"},{"side":"offer","event_time":"2026-07-15T03:40:05.955355Z","price_level":"64591.77","new_quantity":"0.63873921"},{"side":"offer","event_time":"2026-07-15T03:40:05.955355Z","price_level":"64591.79","new_quantity":"0"},{"side":"offer","event_time":"2026-07-15T03:40:05.955355Z","price_level":"64597.49","new_quantity":"0.1017105"},{"side":"offer","event_time":"2026-07-15T03:40:05.955355Z","price_level":"64599.62","new_quantity":"0"},{"side":"offer","event_time":"2026-07-15T03:40:05.955355Z","price_level":"64600.49","new_quantity":"0"},{"side":"offer","event_time":"2026-07-15T03:40:05.955355Z","price_level":"64600.73","new_quantity":"0"},{"side":"offer","event_time":"2026-07-15T03:40:05.955355Z","price_level":"64603.55","new_quantity":"0.00104541"},{"side":"offer","event_time":"2026-07-15T03:40:05.955355Z","price_level":"64610.24","new_quantity":"0"},{"side":"offer","event_time":"2026-07-15T03:40:05.955355Z","price_level":"64613.42","new_quantity":"0.76499093"},{"side":"offer","event_time":"2026-07-15T03:40:05.955355Z","price_level":"64614.15","new_quantity":"0.26328496"},{"side":"offer","event_time":"2026-07-15T03:40:05.955355Z","price_level":"64615.49","new_quantity":"0.45879706"},{"side":"offer","event_time":"2026-07-15T03:40:05.955355Z","price_level":"64615.5","new_quantity":"0"},{"side":"offer","event_time":"2026-07-15T03:40:05.955355Z","price_level":"64616.51","new_quantity":"0.88808593"},{"side":"offer","event_time":"2026-07-15T03:40:05.955355Z","price_level":"64616.52","new_quantity":"1.43184405"},{"side":"offer","event_time":"2026-07-15T03:40:05.955355Z","price_level":"64617.27","new_quantity":"0"},{"side":"offer","event_time":"2026-07-15T03:40:05.955355Z","price_level":"64619.41","new_quantity":"0.03793203"},{"side":"offer","event_time":"2026-07-15T03:40:05.955355Z","price_level":"64621.66","new_quantity":"0"},{"side":"offer","event_time":"2026-07-15T03:40:05.955355Z","price_level":"64628.4","new_quantity":"0"},{"side":"offer","event_time":"2026-07-15T03:40:05.955355Z","price_level":"64631.83","new_quantity":"0"},{"side":"offer","event_time":"2026-07-15T03:40:05.955355Z","price_level":"64633.56","new_quantity":"0"},{"side":"offer","event_time":"2026-07-15T03:40:05.955355Z","price_level":"64633.63","new_quantity":"0"},{"side":"offer","event_time":"2026-07-15T03:40:05.955355Z","price_level":"64635.78","new_quantity":"0"},{"side":"offer","event_time":"2026-07-15T03:40:05.955355Z","price_level":"64660.32","new_quantity":"0.00348472"},{"side":"offer","event_time":"2026-07-15T03:40:05.955355Z","price_level":"64670","new_quantity":"3"},{"side":"offer","event_time":"2026-07-15T03:40:05.955355Z","price_level":"64682.47","new_quantity":"0"},{"side":"offer","event_time":"2026-07-15T03:40:05.955355Z","price_level":"64730.94","new_quantity":"0.01149846"},{"side":"offer","event_time":"2026-07-15T03:40:05.955355Z","price_level":"64854.5","new_quantity":"0"}]}]}
{"channel":"market_trades","timestamp":"2026-07-15T03:40:05.984986465Z","sequence_num":54,"events":[{"type":"update","trades":[{"product_id":"BTC-USD","trade_id":"1056309403","price":"64561.92","size":"0.000018","time":"2026-07-15T03:40:05.94056Z","side":"BUY"},{"product_id":"BTC-USD","trade_id":"1056309402","price":"64565.6","size":"0.000018","time":"2026-07-15T03:40:05.94056Z","side":"BUY"},{"product_id":"BTC-USD","trade_id":"1056309401","price":"64569.28","size":"0.000018","time":"2026-07-15T03:40:05.85039Z","side":"BUY"}]}]}
{"channel":"l2_data","timestamp":"2026-07-15T03:40:06.032432216Z","sequence_num":55,"events":[{"type":"update","product_id":"BTC-USD","updates":[{"side":"bid","event_time":"2026-07-15T03:40:05.994796Z","price_level":"64565.6","new_quantity":"0"},{"side":"bid","event_time":"2026-07-15T03:40:05.994796Z","price_level":"64561.92","new_quantity":"0"},{"side":"bid","event_time":"2026-07-15T03:40:05.994796Z","price_level":"64556.38","new_quantity":"0"},{"side":"bid","event_time":"2026-07-15T03:40:05.994796Z","price_level":"64556","new_quantity":"0.0245"},{"side":"bid","event_time":"2026-07-15T03:40:05.994796Z","price_level":"64549.07","new_quantity":"0.15492088"},{"side":"bid","event_time":"2026-07-15T03:40:05.994796Z","price_level":"64549","new_quantity":"0"},{"side":"bid","event_time":"2026-07-15T03:40:05.994796Z","price_level":"64545.22","new_quantity":"0"},{"side":"bid","event_time":"2026-07-15T03:40:05.994796Z","price_level":"64544.66","new_quantity":"0.048285"},{"side":"bid","event_time":"2026-07-15T03:40:05.994796Z","price_level":"64544.34","new_quantity":"0"},{"side":"bid","event_time":"2026-07-15T03:40:05.994796Z","price_level":"64542.55","new_quantity":"0.00029931"},{"side":"bid","event_time":"2026-07-15T03:40:05.994796Z","price_level":"64541.38","new_quantity":"0.12378505"},{"side":"bid","event_time":"2026-07-15T03:40:05.994796Z","price_level":"64540.77","new_quantity":"0"},{"side":"bid","event_time":"2026-07-15T03:40:05.994796Z","price_level":"64540.49","new_quantity":"0.00059861"},{"side":"bid","event_time":"2026-07-15T03:40:05.994796Z","price_level":"64540.08","new_quantity":"0"},{"side":"bid","event_time":"2026-07-15T03:40:05.994796Z","price_level":"64539.43","new_quantity":"0.12378505"},{"side":"bid","event_time":"2026-07-15T03:40:05.994796Z","price_level":"64533.57","new_quantity":"0"},{"side":"bid","event_time":"2026-07-15T03:40:05.994796Z","price_level":"64532.16","new_quantity":"0"},{"side":"bid","event_time":"2026-07-15T03:40:05.994796Z","price_level":"64530.43","new_quantity":"0.04430812"},{"side":"bid","event_time":"2026-07-15T03:40:05.994796Z","price_level":"64528.66","new_quantity":"0.032983"},{"side":"bid","event_time":"2026-07-15T03:40:05.994796Z","price_level":"64527.75","new_quantity":"0"},{"side":"bid","event_time":"2026-07-15T03:40:05.994796Z","price_level":"64526.26","new_quantity":"0.01899558"},{"side":"bid","event_time":"2026-07-15T03:40:05.994796Z","price_level":"64525.5","new_quantity":"0"},{"side":"bid","event_time":"2026-07-15T03:40:05.994796Z","price_level":"64525.02","new_quantity":"0"},{"side":"bid","event_time":"2026-07-15T03:40:05.994796Z","price_level":"64525.01","new_quantity":"0"},{"side":"bid","event_time":"2026-07-15T03:40:05.994796Z","price_level":"64522.08","new_quantity":"0.61004555"},{"side":"bid","event_time":"2026-07-15T03:40:05.994796Z","price_level":"64522.07","new_quantity":"0"},{"side":"bid","event_time":"2026-07-15T03:40:05.994796Z","price_level":"64520.32","new_quantity":"0.02653478"},{"side":"bid","event_time":"2026-07-15T03:40:05.994796Z","price_level":"64516.93","new_quantity":"0"},{"side":"bid","event_time":"2026-07-15T03:40:05.994796Z","price_level":"64513.05","new_quantity":"0"},{"side":"bid","event_time":"2026-07-15T03:40:05.994796Z","price_level":"64501.16","new_quantity":"0"},{"side":"bid","event_time":"2026-07-15T03:40:05.994796Z","price_level":"64500.32","new_quantity":"0"},{"side":"bid","event_time":"2026-07-15T03:40:05.994796Z","price_level":"64497.17","new_quantity":"0.00510845"},{"side":"bid","event_time":"2026-07-15T03:40:05.994796Z","price_level":"64490.98","new_quantity":"1.35007059"},{"side":"bid","event_time":"2026-07-15T03:40:05.994796Z","price_level":"64490.97","new_quantity":"0"},{"side":"bid","event_time":"2026-07-15T03:40:05.994796Z","price_level":"64490.96","new_quantity":"0"},{"side":"bid","event_time":"2026-07-15T03:40:05.994796Z","price_level":"64486.25","new_quantity":"0"},{"side":"bid","event_time":"2026-07-15T03:40:05.994796Z","price_level":"64450.65","new_quantity":"0"},{"side":"bid","event_time":"2026-07-15T03:40:05.994796Z","price_level":"56491.68","new_quantity":"0.0132912"},{"side":"offer","event_time":"2026-07-15T03:40:05.994796Z","price_level":"64561.92","new_quantity":"0.91218227"},{"side":"offer","event_time":"2026-07-15T03:40:05.994796Z","price_level":"64561.93","new_quantity":"0"},{"side":"offer","event_time":"2026-07-15T03:40:05.994796Z","price_level":"64562","new_quantity":"0.0245"},{"side":"offer","event_time":"2026-07-15T03:40:05.994796Z","price_level":"64562.37","new_quantity":"0"},{"side":"offer","event_time":"2026-07-15T03:40:05.994796Z","price_level":"64563.26","new_quantity":"0"},{"side":"offer","event_time":"2026-07-15T03:40:05.994796Z","price_level":"64563.34","new_quantity":"0.07397386"},{"side":"offer","event_time":"2026-07-15T03:40:05.994796Z","price_level":"64563.35","new_quantity":"0.12390931"},{"side":"offer","event_time":"2026-07-15T03:40:05.994796Z","price_level":"64564.59","new_quantity":"0.23849649"},{"side":"offer","event_time":"2026-07-15T03:40:05.994796Z","price_level":"64564.6","new_quantity":"0.00161777"},{"side":"offer","event_time":"2026-07-15T03:40:05.994796Z","price_level":"64564.61","new_quantity":"0"},{"side":"offer","event_time":"2026-07-15T03:40:05.994796Z","price_level":"64565.03","new_quantity":"0.02266"},{"side":"offer","event_time":"2026-07-15T03:40:05.994796Z","price_level":"64565.59","new_quantity":"0.048285"},{"side":"offer","event_time":"2026-07-15T03:40:05.994796Z","price_level":"64565.6","new_quantity":"0.00774428"},{"side":"offer","event_time":"2026-07-15T03:40:05.994796Z","price_level":"64565.61","new_quantity":"0"},{"side":"offer","event_time":"2026-07-15T03:40:05.994796Z","price_level":"64565.86","new_quantity":"0.04656107"},{"side":"offer","event_time":"2026-07-15T03:40:05.994796Z","price_level":"64565.87","new_quantity":"0.12378505"},{"side":"offer","event_time":"2026-07-15T03:40:05.994796Z","price_level":"64565.89","new_quantity":"0"},{"side":"offer","event_time":"2026-07-15T03:40:05.994796Z","price_level":"64566.15","new_quantity":"0.15487991"},{"side":"offer","event_time":"2026-07-15T03:40:05.994796Z","price_level":"64567.22","new_quantity":"0.00774428"},{"side":"offer","event_time":"2026-07-15T03:40:05.994796Z","price_level":"64568.26","new_quantity":"0.09872738"},{"side":"offer","event_time":"2026-07-15T03:40:05.994796Z","price_level":"64568.28","new_quantity":"0"},{"side":"offer","event_time":"2026-07-15T03:40:05.994796Z","price_level":"64569.26","new_quantity":"0"},{"side":"offer","event_time":"2026-07-15T03:40:05.994796Z","price_level":"64569.28","new_quantity":"0"},{"side":"offer","event_time":"2026-07-15T03:40:05.994796Z","price_level":"64569.4","new_quantity":"0.00968035"},{"side":"offer","event_time":"2026-07-15T03:40:05.994796Z","price_level":"64569.58","new_quantity":"0.07326"},{"side":"offer","event_time":"2026-07-15T03:40:05.994796Z","price_level":"64569.99","new_quantity":"0.00772597"},{"side":"offer","event_time":"2026-07-15T03:40:05.994796Z","price_level":"64570.9","new_quantity":"0"},{"side":"offer","event_time":"2026-07-15T03:40:05.994796Z","price_level":"64571.21","new_quantity":"0.21140001"},{"side":"offer","event_time":"2026-07-15T03:40:05.994796Z","price_level":"64573.08","new_quantity":"0"},{"side":"offer","event_time":"2026-07-15T03:40:05.994796Z","price_level":"64574.3","new_quantity":"0"},{"side":"offer","event_time":"2026-07-15T03:40:05.994796Z","price_level":"64574.59","new_quantity":"0.00100878"},{"side":"offer","event_time":"2026-07-15T03:40:05.994796Z","price_level":"64575.99","new_quantity":"0.17852774"},{"side":"offer","event_time":"2026-07-15T03:40:05.994796Z","price_level":"64579.67","new_quantity":"0.12542522"},{"side":"offer","event_time":"2026-07-15T03:40:05.994796Z","price_level":"64581.16","new_quantity":"0"},{"side":"offer","event_time":"2026-07-15T03:40:05.994796Z","price_level":"64583.85","new_quantity":"0.15846604"},{"side":"offer","event_time":"2026-07-15T03:40:05.994796Z","price_level":"64583.9","new_quantity":"0.00592"},{"side":"offer","event_time":"2026-07-15T03:40:05.994796Z","price_level":"64583.99","new_quantity":"0.00077442"},{"side":"offer","event_time":"2026-07-15T03:40:05.994796Z","price_level":"64584","new_quantity":"0.000018"},{"side":"offer","event_time":"2026-07-15T03:40:05.994796Z","price_level":"64586","new_quantity":"0"},{"side":"offer","event_time":"2026-07-15T03:40:05.994796Z","price_level":"64587.67","new_quantity":"0.12378505"},{"side":"offer","event_time":"2026-07-15T03:40:05.994796Z","price_level":"64591.58","new_quantity":"0"},{"side":"offer","event_time":"2026-07-15T03:40:05.994796Z","price_level":"64597.06","new_quantity":"0.00104547"},{"side":"offer","event_time":"2026-07-15T03:40:05.994796Z","price_level":"64597.49","new_quantity":"0.02781083"},{"side":"offer","event_time":"2026-07-15T03:40:05.994796Z","price_level":"64597.82","new_quantity":"0"},{"side":"offer","event_time":"2026-07-15T03:40:05.994796Z","price_level":"64603.55","new_quantity":"0"},{"side":"offer","event_time":"2026-07-15T03:40:05.994796Z","price_level":"64603.93","new_quantity":"0"},{"side":"offer","event_time":"2026-07-15T03:40:05.994796Z","price_level":"64609.33","new_quantity":"0.00077437"},{"side":"offer","event_time":"2026-07-15T03:40:05.994796Z","price_level":"64613.42","new_quantity":"0.46584948"},{"side":"offer","event_time":"2026-07-15T03:40:05.994796Z","price_level":"64613.53","new_quantity":"0.00158757"},{"side":"offer","event_time":"2026-07-15T03:40:05.994796Z","price_level":"64624.8","new_quantity":"0"},{"side":"offer","event_time":"2026-07-15T03:40:05.994796Z","price_level":"64629.19","new_quantity":"0"},{"side":"offer","event_time":"2026-07-15T03:40:05.994796Z","price_level":"64632.59","new_quantity":"0"},{"side":"offer","event_time":"2026-07-15T03:40:05.994796Z","price_level":"64633.39","new_quantity":"0.00240072"},{"side":"offer","event_time":"2026-07-15T03:40:05.994796Z","price_level":"64649.02","new_quantity":"0"},{"side":"offer","event_time":"2026-07-15T03:40:05.994796Z","price_level":"64670","new_quantity":"0"},{"side":"offer","event_time":"2026-07-15T03:40:05.994796Z","price_level":"64762.01","new_quantity":"0"}]}]}
{"channel":"market_trades","timestamp":"2026-07-15T03:40:06.084400205Z","sequence_num":56,"events":[{"type":"update","trades":[{"product_id":"BTC-USD","trade_id":"1056309404","price":"64561.91","size":"0.00000094","time":"2026-07-15T03:40:06.011898Z","side":"BUY"}]}]}
{"channel":"market_trades","timestamp":"2026-07-15T03:40:06.283691938Z","sequence_num":57,"events":[{"type":"update","trades":[{"product_id":"BTC-USD","trade_id":"1056309405","price":"64558.24","size":"0.000018","time":"2026-07-15T03:40:06.165538Z","side":"BUY"}]}]}
