{"channel":"l2_data","timestamp":"2026-07-16T20:28:52.106115326Z","sequence_num":0,"events":[{"type":"snapshot","product_id":"BTC-USD","updates":[{"side":"bid","event_time":"2026-07-16T20:28:51.491341Z","price_level":"64144.57","new_quantity":"0.01997296"},{"side":"bid","event_time":"2026-07-16T20:28:51.491341Z","price_level":"64144.22","new_quantity":"0.00469904"},{"side":"bid","event_time":"2026-07-16T20:28:51.491341Z","price_level":"64143.28","new_quantity":"0.00779505"},{"side":"bid","event_time":"2026-07-16T20:28:51.491341Z","price_level":"64142.96","new_quantity":"0.00545642"},{"side":"bid","event_time":"2026-07-16T20:28:51.491341Z","price_level":"64142.94","new_quantity":"0.000018"},{"side":"bid","event_time":"2026-07-16T20:28:51.491341Z","price_level":"64142.28","new_quantity":"0.12472272"},{"side":"bid","event_time":"2026-07-16T20:28:51.491341Z","price_level":"64141.34","new_quantity":"0.001545"},{"side":"bid","event_time":"2026-07-16T20:28:51.491341Z","price_level":"64141.01","new_quantity":"0.02"},{"side":"bid","event_time":"2026-07-16T20:28:51.491341Z","price_level":"64141","new_quantity":"0.12472521"},{"side":"bid","event_time":"2026-07-16T20:28:51.491341Z","price_level":"64140.8","new_quantity":"0.00682053"},{"side":"bid","event_time":"2026-07-16T20:28:51.491341Z","price_level":"64140.65","new_quantity":"0.0002588"},{"side":"bid","event_time":"2026-07-16T20:28:51.491341Z","price_level":"64140","new_quantity":"0.01"},{"side":"bid","event_time":"2026-07-16T20:28:51.491341Z","price_level":"64139.76","new_quantity":"0.00779548"},{"side":"bid","event_time":"2026-07-16T20:28:51.491341Z","price_level":"64138.78","new_quantity":"0.02"},{"side":"bid","event_time":"2026-07-16T20:28:51.491341Z","price_level":"64138.77","new_quantity":"0.000018"},{"side":"bid","event_time":"2026-07-16T20:28:51.491341Z","price_level":"64138.16","new_quantity":"0.00779567"},{"side":"bid","event_time":"2026-07-16T20:28:51.491341Z","price_level":"64138.11","new_quantity":"0.001545"},{"side":"bid","event_time":"2026-07-16T20:28:51.491341Z","price_level":"64137.79","new_quantity":"0.00004952"},{"side":"bid","event_time":"2026-07-16T20:28:51.491341Z","price_level":"64137.6","new_quantity":"0.00033322"},{"side":"bid","event_time":"2026-07-16T20:28:51.491341Z","price_level":"64137.37","new_quantity":"0.31190852"},{"side":"bid","event_time":"2026-07-16T20:28:51.491341Z","price_level":"64137.34","new_quantity":"0.04691558"},{"side":"bid","event_time":"2026-07-16T20:28:51.491341Z","price_level":"64137.31","new_quantity":"0.00065878"},{"side":"bid","event_time":"2026-07-16T20:28:51.491341Z","price_level":"64136.69","new_quantity":"0.01559221"},{"side":"bid","event_time":"2026-07-16T20:28:51.491341Z","price_level":"64136.15","new_quantity":"0.04539533"},{"side":"bid","event_time":"2026-07-16T20:28:51.491341Z","price_level":"64135.34","new_quantity":"0.31190852"},{"side":"bid","event_time":"2026-07-16T20:28:51.491341Z","price_level":"64135","new_quantity":"0.01"},{"side":"bid","event_time":"2026-07-16T20:28:51.491341Z","price_level":"64134.94","new_quantity":"0.00131757"},{"side":"bid","event_time":"2026-07-16T20:28:51.491341Z","price_level":"64134.88","new_quantity":"0.001545"},{"side":"bid","event_time":"2026-07-16T20:28:51.491341Z","price_level":"64134.6","new_quantity":"0.000018"},{"side":"bid","event_time":"2026-07-16T20:28:51.491341Z","price_level":"64133.71","new_quantity":"0.04356834"},{"side":"bid","event_time":"2026-07-16T20:28:51.491341Z","price_level":"64132.68","new_quantity":"0.31190852"},{"side":"bid","event_time":"2026-07-16T20:28:51.491341Z","price_level":"64132.15","new_quantity":"0.04691558"},{"side":"bid","event_time":"2026-07-16T20:28:51.491341Z","price_level":"64131.83","new_quantity":"0.00019806"},{"side":"bid","event_time":"2026-07-16T20:28:51.491341Z","price_level":"64131.81","new_quantity":"0.00077948"},{"side":"bid","event_time":"2026-07-16T20:28:51.491341Z","price_level":"64131.65","new_quantity":"0.001545"},{"side":"bid","event_time":"2026-07-16T20:28:51.491341Z","price_level":"64131.54","new_quantity":"0.0077892"},{"side":"bid","event_time":"2026-07-16T20:28:51.491341Z","price_level":"64131.53","new_quantity":"0.30095522"},{"side":"bid","event_time":"2026-07-16T20:28:51.491341Z","price_level":"64131.52","new_quantity":"0.06"},{"side":"bid","event_time":"2026-07-16T20:28:51.491341Z","price_level":"64130.87","new_quantity":"0.07365"},{"side":"bid","event_time":"2026-07-16T20:28:51.491341Z","price_level":"64130.74","new_quantity":"0.23359045"},{"side":"bid","event_time":"2026-07-16T20:28:51.491341Z","price_level":"64130.73","new_quantity":"0.31190852"},{"side":"bid","event_time":"2026-07-16T20:28:51.491341Z","price_level":"64130.43","new_quantity":"0.000018"},{"side":"bid","event_time":"2026-07-16T20:28:51.491341Z","price_level":"64130","new_quantity":"0.01"},{"side":"bid","event_time":"2026-07-16T20:28:51.491341Z","price_level":"64129.48","new_quantity":"0.04863608"},{"side":"bid","event_time":"2026-07-16T20:28:51.491341Z","price_level":"64128.64","new_quantity":"0.00010019"},{"side":"bid","event_time":"2026-07-16T20:28:51.491341Z","price_level":"64128.47","new_quantity":"0.1871425"},{"side":"bid","event_time":"2026-07-16T20:28:51.491341Z","price_level":"64128.46","new_quantity":"0.31190852"},{"side":"bid","event_time":"2026-07-16T20:28:51.491341Z","price_level":"64128.42","new_quantity":"0.001545"},{"side":"bid","event_time":"2026-07-16T20:28:51.491341Z","price_level":"64127.29","new_quantity":"0.05776458"},{"side":"bid","event_time":"2026-07-16T20:28:51.491341Z","price_level":"64126.26","new_quantity":"0.000018"},{"side":"bid","event_time":"2026-07-16T20:28:51.491341Z","price_level":"64126.02","new_quantity":"0.31190852"},{"side":"bid","event_time":"2026-07-16T20:28:51.491341Z","price_level":"64125.88","new_quantity":"0.25088636"},{"side":"bid","event_time":"2026-07-16T20:28:51.491341Z","price_level":"64125.87","new_quantity":"0.04691558"},{"side":"bid","event_time":"2026-07-16T20:28:51.491341Z","price_level":"64125.19","new_quantity":"0.001545"},{"side":"bid","event_time":"2026-07-16T20:28:51.491341Z","price_level":"64125","new_quantity":"0.01"},{"side":"bid","event_time":"2026-07-16T20:28:51.491341Z","price_level":"64124.87","new_quantity":"0.00263513"},{"side":"bid","event_time":"2026-07-16T20:28:51.491341Z","price_level":"64124.83","new_quantity":"0.05662573"},{"side":"bid","event_time":"2026-07-16T20:28:51.491341Z","price_level":"64124.02","new_quantity":"0.23359045"},{"side":"bid","event_time":"2026-07-16T20:28:51.491341Z","price_level":"64123.16","new_quantity":"0.31190852"},{"side":"bid","event_time":"2026-07-16T20:28:51.491341Z","price_level":"64122.58","new_quantity":"0.06327281"},{"side":"bid","event_time":"2026-07-16T20:28:51.491341Z","price_level":"64122.23","new_quantity":"0.01"},{"side":"bid","event_time":"2026-07-16T20:28:51.491341Z","price_level":"64122.19","new_quantity":"0.00039612"},{"side":"bid","event_time":"2026-07-16T20:28:51.491341Z","price_level":"64122.09","new_quantity":"0.000018"},{"side":"bid","event_time":"2026-07-16T20:28:51.491341Z","price_level":"64121.96","new_quantity":"0.001545"},{"side":"bid","event_time":"2026-07-16T20:28:51.491341Z","price_level":"64121.84","new_quantity":"0.00002339"},{"side":"bid","event_time":"2026-07-16T20:28:51.491341Z","price_level":"64121.69","new_quantity":"0.00583"},{"side":"bid","event_time":"2026-07-16T20:28:51.491341Z","price_level":"64121.11","new_quantity":"0.00623392"},{"side":"bid","event_time":"2026-07-16T20:28:51.491341Z","price_level":"64121","new_quantity":"1"},{"side":"bid","event_time":"2026-07-16T20:28:51.491341Z","price_level":"64120.73","new_quantity":"0.04691558"},{"side":"bid","event_time":"2026-07-16T20:28:51.491341Z","price_level":"64120","new_quantity":"0.01"},{"side":"bid","event_time":"2026-07-16T20:28:51.491341Z","price_level":"64119.31","new_quantity":"0.31190852"},{"side":"bid","event_time":"2026-07-16T20:28:51.491341Z","price_level":"64118.73","new_quantity":"0.001545"},{"side":"bid","event_time":"2026-07-16T20:28:51.491341Z","price_level":"64117.92","new_quantity":"0.000018"},{"side":"bid","event_time":"2026-07-16T20:28:51.491341Z","price_level":"64116.43","new_quantity":"0.00105226"},{"side":"bid","event_time":"2026-07-16T20:28:51.491341Z","price_level":"64115.92","new_quantity":"0.64994265"},{"side":"bid","event_time":"2026-07-16T20:28:51.491341Z","price_level":"64115.91","new_quantity":"0.65488253"},{"side":"bid","event_time":"2026-07-16T20:28:51.491341Z","price_level":"64115.53","new_quantity":"0.28365856"},{"side":"bid","event_time":"2026-07-16T20:28:51.491341Z","price_level":"64115.5","new_quantity":"0.001545"},{"side":"bid","event_time":"2026-07-16T20:28:51.491341Z","price_level":"64115.46","new_quantity":"0.31190852"},{"side":"bid","event_time":"2026-07-16T20:28:51.491341Z","price_level":"64115.39","new_quantity":"0.14"},{"side":"bid","event_time":"2026-07-16T20:28:51.491341Z","price_level":"64115.19","new_quantity":"0.23359045"},{"side":"bid","event_time":"2026-07-16T20:28:51.491341Z","price_level":"64115.17","new_quantity":"0.017453"},{"side":"bid","event_time":"2026-07-16T20:28:51.491341Z","price_level":"64115.15","new_quantity":"0.04691558"},{"side":"bid","event_time":"2026-07-16T20:28:51.491341Z","price_level":"64115","new_quantity":"0.01"},{"side":"bid","event_time":"2026-07-16T20:28:51.491341Z","price_level":"64113.75","new_quantity":"0.00015451"},{"side":"bid","event_time":"2026-07-16T20:28:51.491341Z","price_level":"64113","new_quantity":"0.0000309"},{"side":"bid","event_time":"2026-07-16T20:28:51.491341Z","price_level":"64112.28","new_quantity":"0.00077944"},{"side":"bid","event_time":"2026-07-16T20:28:51.491341Z","price_level":"64112.27","new_quantity":"0.001545"},{"side":"bid","event_time":"2026-07-16T20:28:51.491341Z","price_level":"64111.98","new_quantity":"0.00155788"},{"side":"bid","event_time":"2026-07-16T20:28:51.491341Z","price_level":"64111.61","new_quantity":"0.31190852"},{"side":"bid","event_time":"2026-07-16T20:28:51.491341Z","price_level":"64110","new_quantity":"0.01"},{"side":"bid","event_time":"2026-07-16T20:28:51.491341Z","price_level":"64109.93","new_quantity":"0.02337837"},{"side":"bid","event_time":"2026-07-16T20:28:51.491341Z","price_level":"64109.58","new_quantity":"0.000018"},{"side":"bid","event_time":"2026-07-16T20:28:51.491341Z","price_level":"64109.43","new_quantity":"0.00333225"},{"side":"bid","event_time":"2026-07-16T20:28:51.491341Z","price_level":"64109.04","new_quantity":"0.001545"},{"side":"bid","event_time":"2026-07-16T20:28:51.491341Z","price_level":"64108.37","new_quantity":"0.00128301"},{"side":"bid","event_time":"2026-07-16T20:28:51.491341Z","price_level":"64108.27","new_quantity":"0.23359045"},{"side":"bid","event_time":"2026-07-16T20:28:51.491341Z","price_level":"64107.35","new_quantity":"0.04691558"},{"side":"bid","event_time":"2026-07-16T20:28:51.491341Z","price_level":"64107.3","new_quantity":"0.00077994"},{"side":"bid","event_time":"2026-07-16T20:28:51.491341Z","price_level":"64107.23","new_quantity":"0.02990499"},{"side":"bid","event_time":"2026-07-16T20:28:51.491341Z","price_level":"64106.75","new_quantity":"0.02337837"},{"side":"bid","event_time":"2026-07-16T20:28:51.491341Z","price_level":"64106.7","new_quantity":"0.0005"},{"side":"bid","event_time":"2026-07-16T20:28:51.491341Z","price_level":"64106.09","new_quantity":"0.00159781"},{"side":"bid","event_time":"2026-07-16T20:28:51.491341Z","price_level":"64106.05","new_quantity":"0.06654956"},{"side":"bid","event_time":"2026-07-16T20:28:51.491341Z","price_level":"64105.81","new_quantity":"0.001545"},{"side":"bid","event_time":"2026-07-16T20:28:51.491341Z","price_level":"64105.58","new_quantity":"0.00778942"},{"side":"bid","event_time":"2026-07-16T20:28:51.491341Z","price_level":"64105.41","new_quantity":"0.000018"},{"side":"bid","event_time":"2026-07-16T20:28:51.491341Z","price_level":"64105","new_quantity":"0.01"},{"side":"bid","event_time":"2026-07-16T20:28:51.491341Z","price_level":"64104.97","new_quantity":"0.00050097"},{"side":"bid","event_time":"2026-07-16T20:28:51.491341Z","price_level":"64104.9","new_quantity":"0.545486"},{"side":"bid","event_time":"2026-07-16T20:28:51.491341Z","price_level":"64104.67","new_quantity":"0.03279572"},{"side":"bid","event_time":"2026-07-16T20:28:51.491341Z","price_level":"64104.26","new_quantity":"0.00013667"},{"side":"bid","event_time":"2026-07-16T20:28:51.491341Z","price_level":"64102.75","new_quantity":"0.90440368"},{"side":"bid","event_time":"2026-07-16T20:28:51.491341Z","price_level":"64102.74","new_quantity":"0.23359045"},{"side":"bid","event_time":"2026-07-16T20:28:51.491341Z","price_level":"64102.6","new_quantity":"0.0000234"},{"side":"bid","event_time":"2026-07-16T20:28:51.491341Z","price_level":"64102.58","new_quantity":"0.001545"},{"side":"bid","event_time":"2026-07-16T20:28:51.491341Z","price_level":"64102","new_quantity":"1"},{"side":"bid","event_time":"2026-07-16T20:28:51.491341Z","price_level":"64101.24","new_quantity":"0.000018"},{"side":"bid","event_time":"2026-07-16T20:28:51.491341Z","price_level":"64101","new_quantity":"1"},{"side":"bid","event_time":"2026-07-16T20:28:51.491341Z","price_level":"64100.83","new_quantity":"0.00077943"},{"side":"bid","event_time":"2026-07-16T20:28:51.491341Z","price_level":"64100.82","new_quantity":"0.02563635"},{"side":"bid","event_time":"2026-07-16T20:28:51.491341Z","price_level":"64100.79","new_quantity":"0.00013737"},{"side":"bid","event_time":"2026-07-16T20:28:51.491341Z","price_level":"64100.74","new_quantity":"0.04691558"},{"side":"bid","event_time":"2026-07-16T20:28:51.491341Z","price_level":"64100","new_quantity":"0.02100904"},{"side":"bid","event_time":"2026-07-16T20:28:51.491341Z","price_level":"64099.35","new_quantity":"0.001545"},{"side":"bid","event_time":"2026-07-16T20:28:51.491341Z","price_level":"64097.7","new_quantity":"0.00385349"},{"side":"bid","event_time":"2026-07-16T20:28:51.491341Z","price_level":"64097.07","new_quantity":"0.000018"},{"side":"bid","event_time":"2026-07-16T20:28:51.491341Z","price_level":"64096.88","new_quantity":"0.23359045"},{"side":"bid","event_time":"2026-07-16T20:28:51.491341Z","price_level":"64096.29","new_quantity":"0.55407628"},{"side":"bid","event_time":"2026-07-16T20:28:51.491341Z","price_level":"64096.12","new_quantity":"0.001545"},{"side":"bid","event_time":"2026-07-16T20:28:51.491341Z","price_level":"64094.91","new_quantity":"0.04691558"},{"side":"bid","event_time":"2026-07-16T20:28:51.491341Z","price_level":"64092.9","new_quantity":"0.000018"},{"side":"bid","event_time":"2026-07-16T20:28:51.491341Z","price_level":"64092.89","new_quantity":"0.001545"},{"side":"bid","event_time":"2026-07-16T20:28:51.491341Z","price_level":"64092.42","new_quantity":"0.00658783"},{"side":"bid","event_time":"2026-07-16T20:28:51.491341Z","price_level":"64092.2","new_quantity":"0.05"},{"side":"bid","event_time":"2026-07-16T20:28:51.491341Z","price_level":"64092.08","new_quantity":"0.02337837"},{"side":"bid","event_time":"2026-07-16T20:28:51.491341Z","price_level":"64091.05","new_quantity":"0.23359045"},{"side":"bid","event_time":"2026-07-16T20:28:51.491341Z","price_level":"64090.8","new_quantity":"0.00241625"},{"side":"bid","event_time":"2026-07-16T20:28:51.491341Z","price_level":"64089.96","new_quantity":"0.00233475"},{"side":"bid","event_time":"2026-07-16T20:28:51.491341Z","price_level":"64089.66","new_quantity":"0.001545"},{"side":"bid","event_time":"2026-07-16T20:28:51.491341Z","price_level":"64088.73","new_quantity":"0.000018"},{"side":"bid","event_time":"2026-07-16T20:28:51.491341Z","price_level":"64088.1","new_quantity":"0.29622349"},{"side":"bid","event_time":"2026-07-16T20:28:51.491341Z","price_level":"64086.81","new_quantity":"0.068643"},{"side":"bid","event_time":"2026-07-16T20:28:51.491341Z","price_level":"64086.43","new_quantity":"0.001545"},{"side":"bid","event_time":"2026-07-16T20:28:51.491341Z","price_level":"64084.56","new_quantity":"0.000018"},{"side":"bid","event_time":"2026-07-16T20:28:51.491341Z","price_level":"64083.36","new_quantity":"0.0000234"},{"side":"bid","event_time":"2026-07-16T20:28:51.491341Z","price_level":"64083.2","new_quantity":"0.001545"},{"side":"bid","event_time":"2026-07-16T20:28:51.491341Z","price_level":"64082.58","new_quantity":"1.34203703"},{"side":"bid","event_time":"2026-07-16T20:28:51.491341Z","price_level":"64082.57","new_quantity":"1.253792"},{"side":"bid","event_time":"2026-07-16T20:28:51.491341Z","price_level":"64082.17","new_quantity":"6.333844"},{"side":"offer","event_time":"2026-07-16T20:28:51.491341Z","price_level":"64144.58","new_quantity":"0.05939128"},{"side":"offer","event_time":"2026-07-16T20:28:51.491341Z","price_level":"64145.71","new_quantity":"0.02"},{"side":"offer","event_time":"2026-07-16T20:28:51.491341Z","price_level":"64145.72","new_quantity":"0.29661304"},{"side":"offer","event_time":"2026-07-16T20:28:51.491341Z","price_level":"64145.73","new_quantity":"0.23359045"},{"side":"offer","event_time":"2026-07-16T20:28:51.491341Z","price_level":"64145.87","new_quantity":"0.00779473"},{"side":"offer","event_time":"2026-07-16T20:28:51.491341Z","price_level":"64146.14","new_quantity":"0.0077951"},{"side":"offer","event_time":"2026-07-16T20:28:51.491341Z","price_level":"64146.19","new_quantity":"0.00545642"},{"side":"offer","event_time":"2026-07-16T20:28:51.491341Z","price_level":"64146.31","new_quantity":"0.01559221"},{"side":"offer","event_time":"2026-07-16T20:28:51.491341Z","price_level":"64146.73","new_quantity":"0.12471408"},{"side":"offer","event_time":"2026-07-16T20:28:51.491341Z","price_level":"64147.29","new_quantity":"0.31190852"},{"side":"offer","event_time":"2026-07-16T20:28:51.491341Z","price_level":"64147.8","new_quantity":"0.001545"},{"side":"offer","event_time":"2026-07-16T20:28:51.491341Z","price_level":"64148.35","new_quantity":"0.00682053"},{"side":"offer","event_time":"2026-07-16T20:28:51.491341Z","price_level":"64148.69","new_quantity":"0.61449886"},{"side":"offer","event_time":"2026-07-16T20:28:51.491341Z","price_level":"64149.33","new_quantity":"0.15588629"},{"side":"offer","event_time":"2026-07-16T20:28:51.491341Z","price_level":"64149.34","new_quantity":"0.31190852"},{"side":"offer","event_time":"2026-07-16T20:28:51.491341Z","price_level":"64149.37","new_quantity":"0.0012474"},{"side":"offer","event_time":"2026-07-16T20:28:51.491341Z","price_level":"64150.63","new_quantity":"0.04863608"},{"side":"offer","event_time":"2026-07-16T20:28:51.491341Z","price_level":"64150.74","new_quantity":"0.00009743"},{"side":"offer","event_time":"2026-07-16T20:28:51.491341Z","price_level":"64150.98","new_quantity":"0.04691558"},{"side":"offer","event_time":"2026-07-16T20:28:51.491341Z","price_level":"64151.02","new_quantity":"0.23359045"},{"side":"offer","event_time":"2026-07-16T20:28:51.491341Z","price_level":"64151.03","new_quantity":"0.001545"},{"side":"offer","event_time":"2026-07-16T20:28:51.491341Z","price_level":"64151.33","new_quantity":"0.31190852"},{"side":"offer","event_time":"2026-07-16T20:28:51.491341Z","price_level":"64151.67","new_quantity":"0.00896313"},{"side":"offer","event_time":"2026-07-16T20:28:51.491341Z","price_level":"64151.7","new_quantity":"0.00779403"},{"side":"offer","event_time":"2026-07-16T20:28:51.491341Z","price_level":"64152.05","new_quantity":"0.00009742"},{"side":"offer","event_time":"2026-07-16T20:28:51.491341Z","price_level":"64152.21","new_quantity":"0.21326694"},{"side":"offer","event_time":"2026-07-16T20:28:51.491341Z","price_level":"64153.28","new_quantity":"0.00896291"},{"side":"offer","event_time":"2026-07-16T20:28:51.491341Z","price_level":"64153.34","new_quantity":"0.00779383"},{"side":"offer","event_time":"2026-07-16T20:28:51.491341Z","price_level":"64153.57","new_quantity":"0.31190852"},{"side":"offer","event_time":"2026-07-16T20:28:51.491341Z","price_level":"64153.59","new_quantity":"0.00498027"},{"side":"offer","event_time":"2026-07-16T20:28:51.491341Z","price_level":"64154.26","new_quantity":"0.00232448"},{"side":"offer","event_time":"2026-07-16T20:28:51.491341Z","price_level":"64155","new_quantity":"0.01"},{"side":"offer","event_time":"2026-07-16T20:28:51.491341Z","price_level":"64155.45","new_quantity":"0.000018"},{"side":"offer","event_time":"2026-07-16T20:28:51.491341Z","price_level":"64155.64","new_quantity":"0.00778854"},{"side":"offer","event_time":"2026-07-16T20:28:51.491341Z","price_level":"64155.65","new_quantity":"0.0000582"},{"side":"offer","event_time":"2026-07-16T20:28:51.491341Z","price_level":"64156.52","new_quantity":"0.78485751"},{"side":"offer","event_time":"2026-07-16T20:28:51.491341Z","price_level":"64156.53","new_quantity":"0.65487965"},{"side":"offer","event_time":"2026-07-16T20:28:51.491341Z","price_level":"64156.7","new_quantity":"0.04691558"},{"side":"offer","event_time":"2026-07-16T20:28:51.491341Z","price_level":"64156.72","new_quantity":"0.23359045"},{"side":"offer","event_time":"2026-07-16T20:28:51.491341Z","price_level":"64157.16","new_quantity":"0.31190852"},{"side":"offer","event_time":"2026-07-16T20:28:51.491341Z","price_level":"64157.4","new_quantity":"0.06"},{"side":"offer","event_time":"2026-07-16T20:28:51.491341Z","price_level":"64157.44","new_quantity":"0.00583"},{"side":"offer","event_time":"2026-07-16T20:28:51.491341Z","price_level":"64157.49","new_quantity":"0.001545"},{"side":"offer","event_time":"2026-07-16T20:28:51.491341Z","price_level":"64158.42","new_quantity":"0.00038328"},{"side":"offer","event_time":"2026-07-16T20:28:51.491341Z","price_level":"64158.76","new_quantity":"0.00004317"},{"side":"offer","event_time":"2026-07-16T20:28:51.491341Z","price_level":"64158.99","new_quantity":"0.32704255"},{"side":"offer","event_time":"2026-07-16T20:28:51.491341Z","price_level":"64159.23","new_quantity":"0.31190852"},{"side":"offer","event_time":"2026-07-16T20:28:51.491341Z","price_level":"64159.58","new_quantity":"0.15086028"},{"side":"offer","event_time":"2026-07-16T20:28:51.491341Z","price_level":"64159.62","new_quantity":"0.000018"},{"side":"offer","event_time":"2026-07-16T20:28:51.491341Z","price_level":"64160","new_quantity":"0.01"},{"side":"offer","event_time":"2026-07-16T20:28:51.491341Z","price_level":"64160.13","new_quantity":"0.01"},{"side":"offer","event_time":"2026-07-16T20:28:51.491341Z","price_level":"64160.72","new_quantity":"0.001545"},{"side":"offer","event_time":"2026-07-16T20:28:51.491341Z","price_level":"64160.84","new_quantity":"0.06347816"},{"side":"offer","event_time":"2026-07-16T20:28:51.491341Z","price_level":"64161.48","new_quantity":"1.16531874"},{"side":"offer","event_time":"2026-07-16T20:28:51.491341Z","price_level":"64161.53","new_quantity":"0.31190852"},{"side":"offer","event_time":"2026-07-16T20:28:51.491341Z","price_level":"64162","new_quantity":"1"},{"side":"offer","event_time":"2026-07-16T20:28:51.491341Z","price_level":"64162.27","new_quantity":"0.23359045"},{"side":"offer","event_time":"2026-07-16T20:28:51.491341Z","price_level":"64162.71","new_quantity":"0.14"},{"side":"offer","event_time":"2026-07-16T20:28:51.491341Z","price_level":"64163.5","new_quantity":"0.31190852"},{"side":"offer","event_time":"2026-07-16T20:28:51.491341Z","price_level":"64163.79","new_quantity":"0.000018"},{"side":"offer","event_time":"2026-07-16T20:28:51.491341Z","price_level":"64163.95","new_quantity":"0.001545"},{"side":"offer","event_time":"2026-07-16T20:28:51.491341Z","price_level":"64164.24","new_quantity":"0.04691558"},{"side":"offer","event_time":"2026-07-16T20:28:51.491341Z","price_level":"64164.66","new_quantity":"0.06608985"},{"side":"offer","event_time":"2026-07-16T20:28:51.491341Z","price_level":"64165","new_quantity":"0.01"},{"side":"offer","event_time":"2026-07-16T20:28:51.491341Z","price_level":"64165.48","new_quantity":"0.41002751"},{"side":"offer","event_time":"2026-07-16T20:28:51.491341Z","price_level":"64165.49","new_quantity":"0.31190852"},{"side":"offer","event_time":"2026-07-16T20:28:51.491341Z","price_level":"64165.62","new_quantity":"0.0001164"},{"side":"offer","event_time":"2026-07-16T20:28:51.491341Z","price_level":"64166.42","new_quantity":"0.00076656"},{"side":"offer","event_time":"2026-07-16T20:28:51.491341Z","price_level":"64166.49","new_quantity":"0.27118767"},{"side":"offer","event_time":"2026-07-16T20:28:51.491341Z","price_level":"64167.18","new_quantity":"0.001545"},{"side":"offer","event_time":"2026-07-16T20:28:51.491341Z","price_level":"64167.45","new_quantity":"0.31190852"},{"side":"offer","event_time":"2026-07-16T20:28:51.491341Z","price_level":"64167.56","new_quantity":"0.06056825"},{"side":"offer","event_time":"2026-07-16T20:28:51.491341Z","price_level":"64167.63","new_quantity":"0.00105231"},{"side":"offer","event_time":"2026-07-16T20:28:51.491341Z","price_level":"64167.96","new_quantity":"0.000018"},{"side":"offer","event_time":"2026-07-16T20:28:51.491341Z","price_level":"64168.99","new_quantity":"0.86862925"},{"side":"offer","event_time":"2026-07-16T20:28:51.491341Z","price_level":"64169.6","new_quantity":"0.23359045"},{"side":"offer","event_time":"2026-07-16T20:28:51.491341Z","price_level":"64170","new_quantity":"1.01"},{"side":"offer","event_time":"2026-07-16T20:28:51.491341Z","price_level":"64170.15","new_quantity":"0.0002328"},{"side":"offer","event_time":"2026-07-16T20:28:51.491341Z","price_level":"64170.41","new_quantity":"0.001545"},{"side":"offer","event_time":"2026-07-16T20:28:51.491341Z","price_level":"64171.66","new_quantity":"0.00153313"},{"side":"offer","event_time":"2026-07-16T20:28:51.491341Z","price_level":"64172.13","new_quantity":"0.000018"},{"side":"offer","event_time":"2026-07-16T20:28:51.491341Z","price_level":"64172.26","new_quantity":"0.3544985"},{"side":"offer","event_time":"2026-07-16T20:28:51.491341Z","price_level":"64172.27","new_quantity":"0.04691558"},{"side":"offer","event_time":"2026-07-16T20:28:51.491341Z","price_level":"64173.64","new_quantity":"0.001545"},{"side":"offer","event_time":"2026-07-16T20:28:51.491341Z","price_level":"64174.17","new_quantity":"0.545454"},{"side":"offer","event_time":"2026-07-16T20:28:51.491341Z","price_level":"64174.52","new_quantity":"0.06659021"},{"side":"offer","event_time":"2026-07-16T20:28:51.491341Z","price_level":"64174.64","new_quantity":"0.18358366"},{"side":"offer","event_time":"2026-07-16T20:28:51.491341Z","price_level":"64174.65","new_quantity":"0.02935164"},{"side":"offer","event_time":"2026-07-16T20:28:51.491341Z","price_level":"64175","new_quantity":"0.01"},{"side":"offer","event_time":"2026-07-16T20:28:51.491341Z","price_level":"64176.09","new_quantity":"0.01558558"},{"side":"offer","event_time":"2026-07-16T20:28:51.491341Z","price_level":"64176.3","new_quantity":"0.000018"},{"side":"offer","event_time":"2026-07-16T20:28:51.491341Z","price_level":"64176.87","new_quantity":"0.001545"},{"side":"offer","event_time":"2026-07-16T20:28:51.491341Z","price_level":"64177.22","new_quantity":"0.03300523"},{"side":"offer","event_time":"2026-07-16T20:28:51.491341Z","price_level":"64177.25","new_quantity":"0.23359045"},{"side":"offer","event_time":"2026-07-16T20:28:51.491341Z","price_level":"64177.53","new_quantity":"0.6847993"},{"side":"offer","event_time":"2026-07-16T20:28:51.491341Z","price_level":"64178.04","new_quantity":"0.04691558"},{"side":"offer","event_time":"2026-07-16T20:28:51.491341Z","price_level":"64178.22","new_quantity":"0.01559019"},{"side":"offer","event_time":"2026-07-16T20:28:51.491341Z","price_level":"64179","new_quantity":"1"},{"side":"offer","event_time":"2026-07-16T20:28:51.491341Z","price_level":"64179.29","new_quantity":"0.00306626"},{"side":"offer","event_time":"2026-07-16T20:28:51.491341Z","price_level":"64179.82","new_quantity":"0.0000234"},{"side":"offer","event_time":"2026-07-16T20:28:51.491341Z","price_level":"64180","new_quantity":"0.0100309"},{"side":"offer","event_time":"2026-07-16T20:28:51.491341Z","price_level":"64180.1","new_quantity":"0.001545"},{"side":"offer","event_time":"2026-07-16T20:28:51.491341Z","price_level":"64180.47","new_quantity":"0.000018"},{"side":"offer","event_time":"2026-07-16T20:28:51.491341Z","price_level":"64180.61","new_quantity":"0.00155855"},{"side":"offer","event_time":"2026-07-16T20:28:51.491341Z","price_level":"64181.07","new_quantity":"0.02546758"},{"side":"offer","event_time":"2026-07-16T20:28:51.491341Z","price_level":"64181.11","new_quantity":"0.0004656"},{"side":"offer","event_time":"2026-07-16T20:28:51.491341Z","price_level":"64181.41","new_quantity":"0.14997895"},{"side":"offer","event_time":"2026-07-16T20:28:51.491341Z","price_level":"64182.45","new_quantity":"0.29778353"},{"side":"offer","event_time":"2026-07-16T20:28:51.491341Z","price_level":"64182.46","new_quantity":"0.23359045"},{"side":"offer","event_time":"2026-07-16T20:28:51.491341Z","price_level":"64183.26","new_quantity":"0.01558558"},{"side":"offer","event_time":"2026-07-16T20:28:51.491341Z","price_level":"64183.33","new_quantity":"0.001545"},{"side":"offer","event_time":"2026-07-16T20:28:51.491341Z","price_level":"64183.69","new_quantity":"0.0005"},{"side":"offer","event_time":"2026-07-16T20:28:51.491341Z","price_level":"64184.64","new_quantity":"0.000018"},{"side":"offer","event_time":"2026-07-16T20:28:51.491341Z","price_level":"64184.99","new_quantity":"0.00077946"},{"side":"offer","event_time":"2026-07-16T20:28:51.491341Z","price_level":"64185","new_quantity":"0.01"},{"side":"offer","event_time":"2026-07-16T20:28:51.491341Z","price_level":"64185.74","new_quantity":"0.5511457"},{"side":"offer","event_time":"2026-07-16T20:28:51.491341Z","price_level":"64186.56","new_quantity":"0.001545"},{"side":"offer","event_time":"2026-07-16T20:28:51.491341Z","price_level":"64187.4","new_quantity":"0.47901607"},{"side":"offer","event_time":"2026-07-16T20:28:51.491341Z","price_level":"64187.9","new_quantity":"0.04616944"},{"side":"offer","event_time":"2026-07-16T20:28:51.491341Z","price_level":"64188","new_quantity":"0.01"},{"side":"offer","event_time":"2026-07-16T20:28:51.491341Z","price_level":"64188.31","new_quantity":"0.04691558"},{"side":"offer","event_time":"2026-07-16T20:28:51.491341Z","price_level":"64188.81","new_quantity":"0.000018"},{"side":"offer","event_time":"2026-07-16T20:28:51.491341Z","price_level":"64189.79","new_quantity":"0.001545"},{"side":"offer","event_time":"2026-07-16T20:28:51.491341Z","price_level":"64189.94","new_quantity":"0.5"},{"side":"offer","event_time":"2026-07-16T20:28:51.491341Z","price_level":"64190","new_quantity":"0.01"},{"side":"offer","event_time":"2026-07-16T20:28:51.491341Z","price_level":"64190.34","new_quantity":"0.04276635"},{"side":"offer","event_time":"2026-07-16T20:28:51.491341Z","price_level":"64190.98","new_quantity":"0.00077942"},{"side":"offer","event_time":"2026-07-16T20:28:51.491341Z","price_level":"64190.99","new_quantity":"1.364802"},{"side":"offer","event_time":"2026-07-16T20:28:51.491341Z","price_level":"64191","new_quantity":"1"},{"side":"offer","event_time":"2026-07-16T20:28:51.491341Z","price_level":"64191.82","new_quantity":"0.23359045"},{"side":"offer","event_time":"2026-07-16T20:28:51.491341Z","price_level":"64192.98","new_quantity":"0.000018"},{"side":"offer","event_time":"2026-07-16T20:28:51.491341Z","price_level":"64193","new_quantity":"0.96732319"},{"side":"offer","event_time":"2026-07-16T20:28:51.491341Z","price_level":"64193.02","new_quantity":"0.001545"},{"side":"offer","event_time":"2026-07-16T20:28:51.491341Z","price_level":"64193.11","new_quantity":"0.0015103"},{"side":"offer","event_time":"2026-07-16T20:28:51.491341Z","price_level":"64193.71","new_quantity":"0.06919176"},{"side":"offer","event_time":"2026-07-16T20:28:51.491341Z","price_level":"64194.54","new_quantity":"0.01558558"},{"side":"offer","event_time":"2026-07-16T20:28:51.491341Z","price_level":"64195","new_quantity":"0.01"},{"side":"offer","event_time":"2026-07-16T20:28:51.491341Z","price_level":"64196.25","new_quantity":"0.001545"},{"side":"offer","event_time":"2026-07-16T20:28:51.491341Z","price_level":"64196.76","new_quantity":"0.05791521"},{"side":"offer","event_time":"2026-07-16T20:28:51.491341Z","price_level":"64196.79","new_quantity":"0.20995024"},{"side":"offer","event_time":"2026-07-16T20:28:51.491341Z","price_level":"64196.88","new_quantity":"0.04749758"},{"side":"offer","event_time":"2026-07-16T20:28:51.491341Z","price_level":"64197.14","new_quantity":"0.29622349"},{"side":"offer","event_time":"2026-07-16T20:28:51.491341Z","price_level":"64197.15","new_quantity":"0.000018"},{"side":"offer","event_time":"2026-07-16T20:28:51.491341Z","price_level":"64198.4","new_quantity":"0.01100035"},{"side":"offer","event_time":"2026-07-16T20:28:51.491341Z","price_level":"64198.72","new_quantity":"0.00383282"},{"side":"offer","event_time":"2026-07-16T20:28:51.491341Z","price_level":"64199.06","new_quantity":"0.0000234"},{"side":"offer","event_time":"2026-07-16T20:28:51.491341Z","price_level":"64199.48","new_quantity":"0.001545"},{"side":"offer","event_time":"2026-07-16T20:28:51.491341Z","price_level":"64199.59","new_quantity":"0.7308289"},{"side":"offer","event_time":"2026-07-16T20:28:51.491341Z","price_level":"64199.6","new_quantity":"0.00077805"},{"side":"offer","event_time":"2026-07-16T20:28:51.491341Z","price_level":"64200","new_quantity":"0.01"}]}]}
{"channel":"l2_data","timestamp":"2026-07-16T20:28:52.131288977Z","sequence_num":1,"events":[{"type":"update","product_id":"BTC-USD","updates":[{"side":"bid","event_time":"2026-07-16T20:28:51.552272Z","price_level":"64137.7","new_quantity":"0.00772884"},{"side":"offer","event_time":"2026-07-16T20:28:51.552272Z","price_level":"64168.33","new_quantity":"0.01997296"}]}]}
{"channel":"l2_data","timestamp":"2026-07-16T20:28:52.464711997Z","sequence_num":2,"events":[{"type":"update","product_id":"BTC-USD","updates":[{"side":"bid","event_time":"2026-07-16T20:28:51.609412Z","price_level":"64131.76","new_quantity":"0.665307"},{"side":"offer","event_time":"2026-07-16T20:28:51.609412Z","price_level":"64187.38","new_quantity":"0.47901622"},{"side":"offer","event_time":"2026-07-16T20:28:51.609412Z","price_level":"64187.39","new_quantity":"0.67844897"},{"side":"offer","event_time":"2026-07-16T20:28:51.609412Z","price_level":"64187.4","new_quantity":"0"},{"side":"offer","event_time":"2026-07-16T20:28:51.609412Z","price_level":"64206.95","new_quantity":"2.15528656"},{"side":"offer","event_time":"2026-07-16T20:28:51.609412Z","price_level":"64206.96","new_quantity":"1.31563664"},{"side":"offer","event_time":"2026-07-16T20:28:51.609412Z","price_level":"64206.97","new_quantity":"0"}]}]}
{"channel":"l2_data","timestamp":"2026-07-16T20:28:52.465428605Z","sequence_num":3,"events":[{"type":"update","product_id":"BTC-USD","updates":[{"side":"bid","event_time":"2026-07-16T20:28:51.654102Z","price_level":"64131.76","new_quantity":"0"},{"side":"offer","event_time":"2026-07-16T20:28:51.654102Z","price_level":"64187.39","new_quantity":"0"},{"side":"offer","event_time":"2026-07-16T20:28:51.654102Z","price_level":"64206.96","new_quantity":"0"}]}]}
{"channel":"l2_data","timestamp":"2026-07-16T20:28:52.466654339Z","sequence_num":4,"events":[{"type":"update","product_id":"BTC-USD","updates":[{"side":"bid","event_time":"2026-07-16T20:28:51.705267Z","price_level":"64144.57","new_quantity":"0.01997281"},{"side":"bid","event_time":"2026-07-16T20:28:51.705267Z","price_level":"64142.29","new_quantity":"0.02"},{"side":"bid","event_time":"2026-07-16T20:28:51.705267Z","price_level":"62834.18","new_quantity":"0.00583"},{"side":"bid","event_time":"2026-07-16T20:28:51.705267Z","price_level":"62833.86","new_quantity":"0"},{"side":"bid","event_time":"2026-07-16T20:28:51.705267Z","price_level":"56126.5","new_quantity":"0.01337205"},{"side":"offer","event_time":"2026-07-16T20:28:51.705267Z","price_level":"64184.99","new_quantity":"0"}]}]}
{"channel":"subscriptions","timestamp":"2026-07-16T20:28:52.466793983Z","sequence_num":5,"events":[{"subscriptions":{"level2":["BTC-USD"]}}]}
{"channel":"subscriptions","timestamp":"2026-07-16T20:28:52.466960093Z","sequence_num":6,"events":[{"subscriptions":{"heartbeats":["heartbeats"],"level2":["BTC-USD"]}}]}
{"channel":"l2_data","timestamp":"2026-07-16T20:28:52.46706088Z","sequence_num":7,"events":[{"type":"update","product_id":"BTC-USD","updates":[{"side":"offer","event_time":"2026-07-16T20:28:51.755931Z","price_level":"64168.33","new_quantity":"0"},{"side":"offer","event_time":"2026-07-16T20:28:51.755931Z","price_level":"64184.99","new_quantity":"0.00077946"}]}]}
{"channel":"l2_data","timestamp":"2026-07-16T20:28:52.467888555Z","sequence_num":8,"events":[{"type":"update","product_id":"BTC-USD","updates":[{"side":"bid","event_time":"2026-07-16T20:28:51.79575Z","price_level":"56126.5","new_quantity":"0"}]}]}
{"channel":"l2_data","timestamp":"2026-07-16T20:28:52.468262851Z","sequence_num":9,"events":[{"type":"update","product_id":"BTC-USD","updates":[{"side":"bid","event_time":"2026-07-16T20:28:51.862358Z","price_level":"64144.57","new_quantity":"0.01997276"},{"side":"bid","event_time":"2026-07-16T20:28:51.862358Z","price_level":"64137.7","new_quantity":"0"},{"side":"bid","event_time":"2026-07-16T20:28:51.862358Z","price_level":"62834.25","new_quantity":"0.00583"},{"side":"bid","event_time":"2026-07-16T20:28:51.862358Z","price_level":"62834.18","new_quantity":"0"},{"side":"offer","event_time":"2026-07-16T20:28:51.862358Z","price_level":"64168.33","new_quantity":"0.01997281"},{"side":"offer","event_time":"2026-07-16T20:28:51.862358Z","price_level":"68626.54","new_quantity":"0"}]}]}
{"channel":"l2_data","timestamp":"2026-07-16T20:28:52.469365438Z","sequence_num":10,"events":[{"type":"update","product_id":"BTC-USD","updates":[{"side":"bid","event_time":"2026-07-16T20:28:51.877973Z","price_level":"64141.35","new_quantity":"0.02"},{"side":"bid","event_time":"2026-07-16T20:28:51.877973Z","price_level":"64119.31","new_quantity":"0.31190852"}]}]}
{"channel":"l2_data","timestamp":"2026-07-16T20:28:52.469838986Z","sequence_num":11,"events":[{"type":"update","product_id":"BTC-USD","updates":[{"side":"bid","event_time":"2026-07-16T20:28:51.994719Z","price_level":"56126.5","new_quantity":"0.01337205"}]}]}
{"channel":"l2_data","timestamp":"2026-07-16T20:28:52.471797782Z","sequence_num":12,"events":[{"type":"update","product_id":"BTC-USD","updates":[{"side":"bid","event_time":"2026-07-16T20:28:52.059724Z","price_level":"64144.57","new_quantity":"0.01997269"},{"side":"bid","event_time":"2026-07-16T20:28:52.059724Z","price_level":"64142.29","new_quantity":"0"},{"side":"bid","event_time":"2026-07-16T20:28:52.059724Z","price_level":"64142.28","new_quantity":"0"},{"side":"bid","event_time":"2026-07-16T20:28:52.059724Z","price_level":"64141.56","new_quantity":"0.1247241"},{"side":"bid","event_time":"2026-07-16T20:28:52.059724Z","price_level":"64141","new_quantity":"0"},{"side":"bid","event_time":"2026-07-16T20:28:52.059724Z","price_level":"64139.76","new_quantity":"0"},{"side":"bid","event_time":"2026-07-16T20:28:52.059724Z","price_level":"64139.11","new_quantity":"0.1559111"},{"side":"bid","event_time":"2026-07-16T20:28:52.059724Z","price_level":"64138.16","new_quantity":"0"},{"side":"bid","event_time":"2026-07-16T20:28:52.059724Z","price_level":"64137.37","new_quantity":"0"},{"side":"bid","event_time":"2026-07-16T20:28:52.059724Z","price_level":"64130.74","new_quantity":"0"},{"side":"offer","event_time":"2026-07-16T20:28:52.059724Z","price_level":"64145.7","new_quantity":"0.04691558"},{"side":"offer","event_time":"2026-07-16T20:28:52.059724Z","price_level":"64146.05","new_quantity":"0.12471539"},{"side":"offer","event_time":"2026-07-16T20:28:52.059724Z","price_level":"64146.73","new_quantity":"0"},{"side":"offer","event_time":"2026-07-16T20:28:52.059724Z","price_level":"64150.74","new_quantity":"0"},{"side":"offer","event_time":"2026-07-16T20:28:52.059724Z","price_level":"64151.67","new_quantity":"0"},{"side":"offer","event_time":"2026-07-16T20:28:52.059724Z","price_level":"64151.7","new_quantity":"0"},{"side":"offer","event_time":"2026-07-16T20:28:52.059724Z","price_level":"64152.05","new_quantity":"0"},{"side":"offer","event_time":"2026-07-16T20:28:52.059724Z","price_level":"64153.28","new_quantity":"0"},{"side":"offer","event_time":"2026-07-16T20:28:52.059724Z","price_level":"64153.34","new_quantity":"0"},{"side":"offer","event_time":"2026-07-16T20:28:52.059724Z","price_level":"64168.33","new_quantity":"0"}]}]}
{"channel":"l2_data","timestamp":"2026-07-16T20:28:52.472577344Z","sequence_num":13,"events":[{"type":"update","product_id":"BTC-USD","updates":[{"side":"bid","event_time":"2026-07-16T20:28:52.088009Z","price_level":"64141.56","new_quantity":"0"},{"side":"bid","event_time":"2026-07-16T20:28:52.088009Z","price_level":"64140.58","new_quantity":"0.12472602"},{"side":"bid","event_time":"2026-07-16T20:28:52.088009Z","price_level":"64121","new_quantity":"0"},{"side":"bid","event_time":"2026-07-16T20:28:52.088009Z","price_level":"56126.5","new_quantity":"0"},{"side":"offer","event_time":"2026-07-16T20:28:52.088009Z","price_level":"64145.25","new_quantity":"0.31190852"},{"side":"offer","event_time":"2026-07-16T20:28:52.088009Z","price_level":"64145.26","new_quantity":"0.12471693"},{"side":"offer","event_time":"2026-07-16T20:28:52.088009Z","price_level":"64146.05","new_quantity":"0"},{"side":"offer","event_time":"2026-07-16T20:28:52.088009Z","price_level":"64167.45","new_quantity":"0"}]}]}
{"channel":"l2_data","timestamp":"2026-07-16T20:28:52.474065864Z","sequence_num":14,"events":[{"type":"update","product_id":"BTC-USD","updates":[{"side":"bid","event_time":"2026-07-16T20:28:52.149722Z","price_level":"64119","new_quantity":"1"},{"side":"offer","event_time":"2026-07-16T20:28:52.149722Z","price_level":"64145.24","new_quantity":"0.65314426"},{"side":"offer","event_time":"2026-07-16T20:28:52.149722Z","price_level":"64145.72","new_quantity":"0"},{"side":"offer","event_time":"2026-07-16T20:28:52.149722Z","price_level":"64150.63","new_quantity":"0.04873351"},{"side":"offer","event_time":"2026-07-16T20:28:52.149722Z","price_level":"64151.6","new_quantity":"0.00779404"}]}]}
{"channel":"l2_data","timestamp":"2026-07-16T20:28:52.474667511Z","sequence_num":15,"events":[{"type":"update","product_id":"BTC-USD","updates":[{"side":"bid","event_time":"2026-07-16T20:28:52.201748Z","price_level":"64141.01","new_quantity":"0"},{"side":"bid","event_time":"2026-07-16T20:28:52.201748Z","price_level":"64119","new_quantity":"0"},{"side":"offer","event_time":"2026-07-16T20:28:52.201748Z","price_level":"64145.23","new_quantity":"0.02"},{"side":"offer","event_time":"2026-07-16T20:28:52.201748Z","price_level":"64145.71","new_quantity":"0"},{"side":"offer","event_time":"2026-07-16T20:28:52.201748Z","price_level":"64168.33","new_quantity":"0.01997269"}]}]}
{"channel":"l2_data","timestamp":"2026-07-16T20:28:52.475645112Z","sequence_num":16,"events":[{"type":"update","product_id":"BTC-USD","updates":[{"side":"bid","event_time":"2026-07-16T20:28:52.231235Z","price_level":"64141.35","new_quantity":"0"},{"side":"bid","event_time":"2026-07-16T20:28:52.231235Z","price_level":"64138.78","new_quantity":"0"},{"side":"bid","event_time":"2026-07-16T20:28:52.231235Z","price_level":"64120","new_quantity":"1.01"},{"side":"bid","event_time":"2026-07-16T20:28:52.231235Z","price_level":"64118.73","new_quantity":"0.00156559"},{"side":"offer","event_time":"2026-07-16T20:28:52.231235Z","price_level":"64144.58","new_quantity":"0.14643225"},{"side":"offer","event_time":"2026-07-16T20:28:52.231235Z","price_level":"64161.48","new_quantity":"0.66384962"},{"side":"offer","event_time":"2026-07-16T20:28:52.231235Z","price_level":"64162","new_quantity":"0"}]}]}
{"channel":"l2_data","timestamp":"2026-07-16T20:28:52.476602814Z","sequence_num":17,"events":[{"type":"update","product_id":"BTC-USD","updates":[{"side":"bid","event_time":"2026-07-16T20:28:52.290692Z","price_level":"64083.54","new_quantity":"0.00854811"},{"side":"bid","event_time":"2026-07-16T20:28:52.290692Z","price_level":"56126.5","new_quantity":"0.01337205"},{"side":"offer","event_time":"2026-07-16T20:28:52.290692Z","price_level":"64158.99","new_quantity":"0.8822308"},{"side":"offer","event_time":"2026-07-16T20:28:52.290692Z","price_level":"64160","new_quantity":"1.01"},{"side":"offer","event_time":"2026-07-16T20:28:52.290692Z","price_level":"64183.42","new_quantity":"0.08573788"}]}]}
{"channel":"l2_data","timestamp":"2026-07-16T20:28:52.479602062Z","sequence_num":18,"events":[{"type":"update","product_id":"BTC-USD","updates":[{"side":"bid","event_time":"2026-07-16T20:28:52.349811Z","price_level":"64140.58","new_quantity":"0"},{"side":"bid","event_time":"2026-07-16T20:28:52.349811Z","price_level":"64139.52","new_quantity":"0.12472808"},{"side":"bid","event_time":"2026-07-16T20:28:52.349811Z","price_level":"64139.11","new_quantity":"0"},{"side":"bid","event_time":"2026-07-16T20:28:52.349811Z","price_level":"64137.7","new_quantity":"0.00928031"},{"side":"bid","event_time":"2026-07-16T20:28:52.349811Z","price_level":"64137.06","new_quantity":"0.15591607"},{"side":"bid","event_time":"2026-07-16T20:28:52.349811Z","price_level":"64136.69","new_quantity":"0"},{"side":"bid","event_time":"2026-07-16T20:28:52.349811Z","price_level":"64135.82","new_quantity":"0.01559221"},{"side":"bid","event_time":"2026-07-16T20:28:52.349811Z","price_level":"64135.34","new_quantity":"0"},{"side":"bid","event_time":"2026-07-16T20:28:52.349811Z","price_level":"64132.68","new_quantity":"0"},{"side":"bid","event_time":"2026-07-16T20:28:52.349811Z","price_level":"64131.54","new_quantity":"0"},{"side":"bid","event_time":"2026-07-16T20:28:52.349811Z","price_level":"64131.53","new_quantity":"0.0077892"},{"side":"bid","event_time":"2026-07-16T20:28:52.349811Z","price_level":"64130.88","new_quantity":"0.31190852"},{"side":"bid","event_time":"2026-07-16T20:28:52.349811Z","price_level":"64130.73","new_quantity":"0"},{"side":"bid","event_time":"2026-07-16T20:28:52.349811Z","price_level":"64128.48","new_quantity":"0.31190852"},{"side":"bid","event_time":"2026-07-16T20:28:52.349811Z","price_level":"64128.47","new_quantity":"0.21709976"},{"side":"bid","event_time":"2026-07-16T20:28:52.349811Z","price_level":"64128.46","new_quantity":"0"},{"side":"bid","event_time":"2026-07-16T20:28:52.349811Z","price_level":"64126.47","new_quantity":"0.31190852"},{"side":"bid","event_time":"2026-07-16T20:28:52.349811Z","price_level":"64126.02","new_quantity":"0"},{"side":"bid","event_time":"2026-07-16T20:28:52.349811Z","price_level":"64125.88","new_quantity":"0.36386726"},{"side":"bid","event_time":"2026-07-16T20:28:52.349811Z","price_level":"64120","new_quantity":"0.01"},{"side":"bid","event_time":"2026-07-16T20:28:52.349811Z","price_level":"64111.98","new_quantity":"0"},{"side":"bid","event_time":"2026-07-16T20:28:52.349811Z","price_level":"64107.76","new_quantity":"0.31190852"},{"side":"bid","event_time":"2026-07-16T20:28:52.349811Z","price_level":"64105.58","new_quantity":"0"},{"side":"offer","event_time":"2026-07-16T20:28:52.349811Z","price_level":"64144.58","new_quantity":"0.20339214"},{"side":"offer","event_time":"2026-07-16T20:28:52.349811Z","price_level":"64144.64","new_quantity":"0.02"},{"side":"offer","event_time":"2026-07-16T20:28:52.349811Z","price_level":"64144.65","new_quantity":"0.12471813"},{"side":"offer","event_time":"2026-07-16T20:28:52.349811Z","price_level":"64145.26","new_quantity":"0"},{"side":"offer","event_time":"2026-07-16T20:28:52.349811Z","price_level":"64145.44","new_quantity":"0.01559221"},{"side":"offer","event_time":"2026-07-16T20:28:52.349811Z","price_level":"64146.31","new_quantity":"0"},{"side":"offer","event_time":"2026-07-16T20:28:52.349811Z","price_level":"64147.37","new_quantity":"0.15589105"},{"side":"offer","event_time":"2026-07-16T20:28:52.349811Z","price_level":"64149.33","new_quantity":"0"},{"side":"offer","event_time":"2026-07-16T20:28:52.349811Z","price_level":"64156.52","new_quantity":"0.39389436"},{"side":"offer","event_time":"2026-07-16T20:28:52.349811Z","price_level":"64156.53","new_quantity":"0"},{"side":"offer","event_time":"2026-07-16T20:28:52.349811Z","price_level":"65015.61","new_quantity":"0.00583"},{"side":"offer","event_time":"2026-07-16T20:28:52.349811Z","price_level":"65015.66","new_quantity":"0.00583"},{"side":"offer","event_time":"2026-07-16T20:28:52.349811Z","price_level":"65015.91","new_quantity":"0"},{"side":"offer","event_time":"2026-07-16T20:28:52.349811Z","price_level":"65019.9","new_quantity":"0"},{"side":"offer","event_time":"2026-07-16T20:28:52.349811Z","price_level":"65230.48","new_quantity":"0.00583"},{"side":"offer","event_time":"2026-07-16T20:28:52.349811Z","price_level":"65444.02","new_quantity":"0"},{"side":"offer","event_time":"2026-07-16T20:28:52.349811Z","price_level":"65658.9","new_quantity":"0.00583"},{"side":"offer","event_time":"2026-07-16T20:28:52.349811Z","price_level":"65659.22","new_quantity":"0"},{"side":"offer","event_time":"2026-07-16T20:28:52.349811Z","price_level":"65659.23","new_quantity":"0"}]}]}
{"channel":"l2_data","timestamp":"2026-07-16T20:28:52.480575179Z","sequence_num":19,"events":[{"type":"update","product_id":"BTC-USD","updates":[{"side":"bid","event_time":"2026-07-16T20:28:52.420668Z","price_level":"64135.01","new_quantity":"0.31190852"},{"side":"bid","event_time":"2026-07-16T20:28:52.420668Z","price_level":"64132.99","new_quantity":"0.31190852"},{"side":"bid","event_time":"2026-07-16T20:28:52.420668Z","price_level":"64131.07","new_quantity":"0"},{"side":"bid","event_time":"2026-07-16T20:28:52.420668Z","price_level":"64117.01","new_quantity":"0.59859775"},{"side":"bid","event_time":"2026-07-16T20:28:52.420668Z","price_level":"64117","new_quantity":"1"},{"side":"bid","event_time":"2026-07-16T20:28:52.420668Z","price_level":"64115.92","new_quantity":"0"},{"side":"bid","event_time":"2026-07-16T20:28:52.420668Z","price_level":"64110.27","new_quantity":"0.0015579"},{"side":"bid","event_time":"2026-07-16T20:28:52.420668Z","price_level":"64103.87","new_quantity":"0.00778953"},{"side":"bid","event_time":"2026-07-16T20:28:52.420668Z","price_level":"56126.5","new_quantity":"0"},{"side":"offer","event_time":"2026-07-16T20:28:52.420668Z","price_level":"65015.66","new_quantity":"0"},{"side":"offer","event_time":"2026-07-16T20:28:52.420668Z","price_level":"65230.2","new_quantity":"0.00583"},{"side":"offer","event_time":"2026-07-16T20:28:52.420668Z","price_level":"65230.48","new_quantity":"0"},{"side":"offer","event_time":"2026-07-16T20:28:52.420668Z","price_level":"65444.64","new_quantity":"0.00583"},{"side":"offer","event_time":"2026-07-16T20:28:52.420668Z","price_level":"65445.15","new_quantity":"0"},{"side":"offer","event_time":"2026-07-16T20:28:52.420668Z","price_level":"65658.9","new_quantity":"0"}]}]}
{"channel":"l2_data","timestamp":"2026-07-16T20:28:52.489065822Z","sequence_num":20,"events":[{"type":"update","product_id":"BTC-USD","updates":[{"side":"bid","event_time":"2026-07-16T20:28:52.431903Z","price_level":"64107.76","new_quantity":"0"}]}]}
{"channel":"l2_data","timestamp":"2026-07-16T20:28:52.554740539Z","sequence_num":21,"events":[{"type":"update","product_id":"BTC-USD","updates":[{"side":"bid","event_time":"2026-07-16T20:28:52.506674Z","price_level":"64139.76","new_quantity":"0.00779548"},{"side":"bid","event_time":"2026-07-16T20:28:52.506674Z","price_level":"64138.16","new_quantity":"0.00779567"},{"side":"bid","event_time":"2026-07-16T20:28:52.506674Z","price_level":"64137.7","new_quantity":"0"},{"side":"bid","event_time":"2026-07-16T20:28:52.506674Z","price_level":"64137.35","new_quantity":"0.31190852"},{"side":"bid","event_time":"2026-07-16T20:28:52.506674Z","price_level":"64117","new_quantity":"0"},{"side":"offer","event_time":"2026-07-16T20:28:52.506674Z","price_level":"64153.18","new_quantity":"0.00896292"},{"side":"offer","event_time":"2026-07-16T20:28:52.506674Z","price_level":"65659.36","new_quantity":"0.00583"}]}]}
{"channel":"l2_data","timestamp":"2026-07-16T20:28:52.601076929Z","sequence_num":22,"events":[{"type":"update","product_id":"BTC-USD","updates":[{"side":"bid","event_time":"2026-07-16T20:28:52.556332Z","price_level":"64119","new_quantity":"1"},{"side":"offer","event_time":"2026-07-16T20:28:52.556332Z","price_level":"64151.57","new_quantity":"0.00896315"},{"side":"offer","event_time":"2026-07-16T20:28:52.556332Z","price_level":"64151.95","new_quantity":"0.00009742"},{"side":"offer","event_time":"2026-07-16T20:28:52.556332Z","price_level":"64153.23","new_quantity":"0.00779384"},{"side":"offer","event_time":"2026-07-16T20:28:52.556332Z","price_level":"65659.32","new_quantity":"0.00583"},{"side":"offer","event_time":"2026-07-16T20:28:52.556332Z","price_level":"65659.36","new_quantity":"0"}]}]}
{"channel":"l2_data","timestamp":"2026-07-16T20:28:52.630892352Z","sequence_num":23,"events":[{"type":"update","product_id":"BTC-USD","updates":[{"side":"bid","event_time":"2026-07-16T20:28:52.609698Z","price_level":"64131.37","new_quantity":"0.653986"},{"side":"bid","event_time":"2026-07-16T20:28:52.609698Z","price_level":"56126.5","new_quantity":"0.01337205"},{"side":"offer","event_time":"2026-07-16T20:28:52.609698Z","price_level":"64187.36","new_quantity":"0.47901637"},{"side":"offer","event_time":"2026-07-16T20:28:52.609698Z","price_level":"64187.37","new_quantity":"0.67844906"},{"side":"offer","event_time":"2026-07-16T20:28:52.609698Z","price_level":"64187.38","new_quantity":"0"},{"side":"offer","event_time":"2026-07-16T20:28:52.609698Z","price_level":"64206.93","new_quantity":"2.15528723"},{"side":"offer","event_time":"2026-07-16T20:28:52.609698Z","price_level":"64206.94","new_quantity":"1.31563704"},{"side":"offer","event_time":"2026-07-16T20:28:52.609698Z","price_level":"64206.95","new_quantity":"0"}]}]}
{"channel":"l2_data","timestamp":"2026-07-16T20:28:52.680944813Z","sequence_num":24,"events":[{"type":"update","product_id":"BTC-USD","updates":[{"side":"bid","event_time":"2026-07-16T20:28:52.624034Z","price_level":"64119","new_quantity":"0"},{"side":"offer","event_time":"2026-07-16T20:28:52.624034Z","price_level":"64187.37","new_quantity":"0"},{"side":"offer","event_time":"2026-07-16T20:28:52.624034Z","price_level":"64206.94","new_quantity":"0"},{"side":"offer","event_time":"2026-07-16T20:28:52.624034Z","price_level":"66131.51","new_quantity":"0.00007561"}]}]}
{"channel":"l2_data","timestamp":"2026-07-16T20:28:52.730135967Z","sequence_num":25,"events":[{"type":"update","product_id":"BTC-USD","updates":[{"side":"bid","event_time":"2026-07-16T20:28:52.696413Z","price_level":"64131.37","new_quantity":"0"},{"side":"bid","event_time":"2026-07-16T20:28:52.696413Z","price_level":"64119.32","new_quantity":"0"},{"side":"bid","event_time":"2026-07-16T20:28:52.696413Z","price_level":"64118","new_quantity":"1"},{"side":"bid","event_time":"2026-07-16T20:28:52.696413Z","price_level":"64117.02","new_quantity":"0.65488349"},{"side":"bid","event_time":"2026-07-16T20:28:52.696413Z","price_level":"64117.01","new_quantity":"0"},{"side":"bid","event_time":"2026-07-16T20:28:52.696413Z","price_level":"64115.91","new_quantity":"0"},{"side":"bid","event_time":"2026-07-16T20:28:52.696413Z","price_level":"64115.54","new_quantity":"0.59861148"},{"side":"bid","event_time":"2026-07-16T20:28:52.696413Z","price_level":"56126.5","new_quantity":"0"},{"side":"offer","event_time":"2026-07-16T20:28:52.696413Z","price_level":"64144.58","new_quantity":"0.23160111"}]}]}
{"channel":"l2_data","timestamp":"2026-07-16T20:28:52.825553677Z","sequence_num":26,"events":[{"type":"update","product_id":"BTC-USD","updates":[{"side":"bid","event_time":"2026-07-16T20:28:52.812187Z","price_level":"64119","new_quantity":"1"},{"side":"bid","event_time":"2026-07-16T20:28:52.812187Z","price_level":"64118","new_quantity":"0"}]}]}
{"channel":"l2_data","timestamp":"2026-07-16T20:28:52.8821562Z","sequence_num":27,"events":[{"type":"update","product_id":"BTC-USD","updates":[{"side":"bid","event_time":"2026-07-16T20:28:52.85453Z","price_level":"64119.49","new_quantity":"0.685714"},{"side":"bid","event_time":"2026-07-16T20:28:52.85453Z","price_level":"64117.03","new_quantity":"0.59859757"},{"side":"bid","event_time":"2026-07-16T20:28:52.85453Z","price_level":"64115.54","new_quantity":"0"},{"side":"offer","event_time":"2026-07-16T20:28:52.85453Z","price_level":"64784.86","new_quantity":"0"}]}]}
{"channel":"l2_data","timestamp":"2026-07-16T20:28:52.931393366Z","sequence_num":28,"events":[{"type":"update","product_id":"BTC-USD","updates":[{"side":"bid","event_time":"2026-07-16T20:28:52.912006Z","price_level":"64144.57","new_quantity":"0.01997267"},{"side":"bid","event_time":"2026-07-16T20:28:52.912006Z","price_level":"64137.35","new_quantity":"0"},{"side":"bid","event_time":"2026-07-16T20:28:52.912006Z","price_level":"64130.87","new_quantity":"0"},{"side":"bid","event_time":"2026-07-16T20:28:52.912006Z","price_level":"64119.49","new_quantity":"0"},{"side":"bid","event_time":"2026-07-16T20:28:52.912006Z","price_level":"64117.02","new_quantity":"0"},{"side":"bid","event_time":"2026-07-16T20:28:52.912006Z","price_level":"64115.55","new_quantity":"0.65488241"},{"side":"bid","event_time":"2026-07-16T20:28:52.912006Z","price_level":"56126.5","new_quantity":"0.01337205"},{"side":"offer","event_time":"2026-07-16T20:28:52.912006Z","price_level":"64144.58","new_quantity":"0.20188709"}]}]}
{"channel":"l2_data","timestamp":"2026-07-16T20:28:52.98092492Z","sequence_num":29,"events":[{"type":"update","product_id":"BTC-USD","updates":[{"side":"bid","event_time":"2026-07-16T20:28:52.963445Z","price_level":"64127.68","new_quantity":"0.07381"},{"side":"bid","event_time":"2026-07-16T20:28:52.963445Z","price_level":"64117.03","new_quantity":"0"},{"side":"bid","event_time":"2026-07-16T20:28:52.963445Z","price_level":"64115.56","new_quantity":"0.59861129"},{"side":"offer","event_time":"2026-07-16T20:28:52.963445Z","price_level":"64146.14","new_quantity":"0"}]}]}
{"channel":"l2_data","timestamp":"2026-07-16T20:28:53.030885445Z","sequence_num":30,"events":[{"type":"update","product_id":"BTC-USD","updates":[{"side":"bid","event_time":"2026-07-16T20:28:52.997453Z","price_level":"56126.5","new_quantity":"0"},{"side":"offer","event_time":"2026-07-16T20:28:52.997453Z","price_level":"64178.22","new_quantity":"0"},{"side":"offer","event_time":"2026-07-16T20:28:52.997453Z","price_level":"64210.29","new_quantity":"0"}]}]}
{"channel":"l2_data","timestamp":"2026-07-16T20:28:53.088734089Z","sequence_num":31,"events":[{"type":"update","product_id":"BTC-USD","updates":[{"side":"bid","event_time":"2026-07-16T20:28:53.0513Z","price_level":"64139.76","new_quantity":"0"},{"side":"bid","event_time":"2026-07-16T20:28:53.0513Z","price_level":"64138.16","new_quantity":"0"},{"side":"bid","event_time":"2026-07-16T20:28:53.0513Z","price_level":"64137.6","new_quantity":"0.00925948"},{"side":"bid","event_time":"2026-07-16T20:28:53.0513Z","price_level":"64137.35","new_quantity":"0.31190852"},{"side":"offer","event_time":"2026-07-16T20:28:53.0513Z","price_level":"64150.63","new_quantity":"0.04863608"},{"side":"offer","event_time":"2026-07-16T20:28:53.0513Z","price_level":"64151.57","new_quantity":"0"},{"side":"offer","event_time":"2026-07-16T20:28:53.0513Z","price_level":"64151.6","new_quantity":"0"},{"side":"offer","event_time":"2026-07-16T20:28:53.0513Z","price_level":"64153.18","new_quantity":"0"},{"side":"offer","event_time":"2026-07-16T20:28:53.0513Z","price_level":"64786.16","new_quantity":"0.03890047"}]}]}
{"channel":"l2_data","timestamp":"2026-07-16T20:28:53.125235262Z","sequence_num":32,"events":[{"type":"update","product_id":"BTC-USD","updates":[{"side":"bid","event_time":"2026-07-16T20:28:53.096923Z","price_level":"64131.58","new_quantity":"0.590505"}]}]}
{"channel":"heartbeats","timestamp":"2026-07-16T20:28:53.166419882Z","sequence_num":33,"events":[{"current_time":"2026-07-16 20:28:53.16294062 +0000 UTC m=+75497.317767664","heartbeat_counter":75497}]}
{"channel":"l2_data","timestamp":"2026-07-16T20:28:53.175324855Z","sequence_num":34,"events":[{"type":"update","product_id":"BTC-USD","updates":[{"side":"bid","event_time":"2026-07-16T20:28:53.150782Z","price_level":"64119","new_quantity":"0"}]}]}
{"channel":"l2_data","timestamp":"2026-07-16T20:28:53.235316747Z","sequence_num":35,"events":[{"type":"update","product_id":"BTC-USD","updates":[{"side":"bid","event_time":"2026-07-16T20:28:53.204918Z","price_level":"64144.57","new_quantity":"0.01997264"},{"side":"bid","event_time":"2026-07-16T20:28:53.204918Z","price_level":"64137.6","new_quantity":"0.00033322"},{"side":"bid","event_time":"2026-07-16T20:28:53.204918Z","price_level":"64131.58","new_quantity":"0"},{"side":"bid","event_time":"2026-07-16T20:28:53.204918Z","price_level":"64118","new_quantity":"1"},{"side":"bid","event_time":"2026-07-16T20:28:53.204918Z","price_level":"56126.5","new_quantity":"0.01337205"},{"side":"offer","event_time":"2026-07-16T20:28:53.204918Z","price_level":"64150.53","new_quantity":"0.00009743"},{"side":"offer","event_time":"2026-07-16T20:28:53.204918Z","price_level":"64151.5","new_quantity":"0.00779405"}]}]}
{"channel":"l2_data","timestamp":"2026-07-16T20:28:53.581908362Z","sequence_num":36,"events":[{"type":"update","product_id":"BTC-USD","updates":[{"side":"bid","event_time":"2026-07-16T20:28:53.303136Z","price_level":"64118","new_quantity":"0"},{"side":"bid","event_time":"2026-07-16T20:28:53.303136Z","price_level":"56126.5","new_quantity":"0"}]}]}
{"channel":"l2_data","timestamp":"2026-07-16T20:28:53.582608591Z","sequence_num":37,"events":[{"type":"update","product_id":"BTC-USD","updates":[{"side":"bid","event_time":"2026-07-16T20:28:53.349237Z","price_level":"64119","new_quantity":"1"},{"side":"offer","event_time":"2026-07-16T20:28:53.349237Z","price_level":"64156.5","new_quantity":"0.78485858"},{"side":"offer","event_time":"2026-07-16T20:28:53.349237Z","price_level":"64156.51","new_quantity":"0.65488144"},{"side":"offer","event_time":"2026-07-16T20:28:53.349237Z","price_level":"64156.52","new_quantity":"0"}]}]}
{"channel":"l2_data","timestamp":"2026-07-16T20:28:53.583114979Z","sequence_num":38,"events":[{"type":"update","product_id":"BTC-USD","updates":[{"side":"bid","event_time":"2026-07-16T20:28:53.383334Z","price_level":"64119.5","new_quantity":"0"},{"side":"bid","event_time":"2026-07-16T20:28:53.383334Z","price_level":"63501.99","new_quantity":"0"}]}]}
{"channel":"l2_data","timestamp":"2026-07-16T20:28:53.583665495Z","sequence_num":39,"events":[{"type":"update","product_id":"BTC-USD","updates":[{"side":"bid","event_time":"2026-07-16T20:28:53.500918Z","price_level":"56126.5","new_quantity":"0.01337205"}]}]}
{"channel":"l2_data","timestamp":"2026-07-16T20:28:53.583841261Z","sequence_num":40,"events":[{"type":"update","product_id":"BTC-USD","updates":[{"side":"bid","event_time":"2026-07-16T20:28:53.55995Z","price_level":"64138.16","new_quantity":"0.00779567"},{"side":"offer","event_time":"2026-07-16T20:28:53.55995Z","price_level":"64153.08","new_quantity":"0.00896294"}]}]}
{"channel":"l2_data","timestamp":"2026-07-16T20:28:53.632942255Z","sequence_num":41,"events":[{"type":"update","product_id":"BTC-USD","updates":[{"side":"bid","event_time":"2026-07-16T20:28:53.606317Z","price_level":"64139.76","new_quantity":"0.00779548"},{"side":"bid","event_time":"2026-07-16T20:28:53.606317Z","price_level":"64131.57","new_quantity":"0.710516"},{"side":"bid","event_time":"2026-07-16T20:28:53.606317Z","price_level":"63503.26","new_quantity":"0.03937456"},{"side":"bid","event_time":"2026-07-16T20:28:53.606317Z","price_level":"56126.5","new_quantity":"0"},{"side":"offer","event_time":"2026-07-16T20:28:53.606317Z","price_level":"64144.58","new_quantity":"0.20188737"},{"side":"offer","event_time":"2026-07-16T20:28:53.606317Z","price_level":"64151.47","new_quantity":"0.00896316"},{"side":"offer","event_time":"2026-07-16T20:28:53.606317Z","price_level":"64151.95","new_quantity":"0"},{"side":"offer","event_time":"2026-07-16T20:28:53.606317Z","price_level":"64153.23","new_quantity":"0"}]}]}
{"channel":"l2_data","timestamp":"2026-07-16T20:28:53.680454865Z","sequence_num":42,"events":[{"type":"update","product_id":"BTC-USD","updates":[{"side":"bid","event_time":"2026-07-16T20:28:53.650251Z","price_level":"64131.57","new_quantity":"0"},{"side":"bid","event_time":"2026-07-16T20:28:53.650251Z","price_level":"51315.66","new_quantity":"0.0002"},{"side":"offer","event_time":"2026-07-16T20:28:53.650251Z","price_level":"64151.85","new_quantity":"0.00009743"},{"side":"offer","event_time":"2026-07-16T20:28:53.650251Z","price_level":"64153.13","new_quantity":"0.00779385"},{"side":"offer","event_time":"2026-07-16T20:28:53.650251Z","price_level":"64187.34","new_quantity":"0.48135122"},{"side":"offer","event_time":"2026-07-16T20:28:53.650251Z","price_level":"64187.35","new_quantity":"0"},{"side":"offer","event_time":"2026-07-16T20:28:53.650251Z","price_level":"64187.36","new_quantity":"0"},{"side":"offer","event_time":"2026-07-16T20:28:53.650251Z","price_level":"64206.91","new_quantity":"2.1552879"},{"side":"offer","event_time":"2026-07-16T20:28:53.650251Z","price_level":"64206.92","new_quantity":"0"},{"side":"offer","event_time":"2026-07-16T20:28:53.650251Z","price_level":"64206.93","new_quantity":"0"}]}]}
{"channel":"l2_data","timestamp":"2026-07-16T20:28:53.725341667Z","sequence_num":43,"events":[{"type":"update","product_id":"BTC-USD","updates":[{"side":"bid","event_time":"2026-07-16T20:28:53.699069Z","price_level":"64115.53","new_quantity":"0"}]}]}
{"channel":"l2_data","timestamp":"2026-07-16T20:28:53.780476764Z","sequence_num":44,"events":[{"type":"update","product_id":"BTC-USD","updates":[{"side":"bid","event_time":"2026-07-16T20:28:53.716567Z","price_level":"64096.29","new_quantity":"0"},{"side":"offer","event_time":"2026-07-16T20:28:53.716567Z","price_level":"64165.48","new_quantity":"0.22444635"},{"side":"offer","event_time":"2026-07-16T20:28:53.716567Z","price_level":"64166.49","new_quantity":"0"},{"side":"offer","event_time":"2026-07-16T20:28:53.716567Z","price_level":"64185.74","new_quantity":"0"}]}]}
{"channel":"l2_data","timestamp":"2026-07-16T20:28:53.830045571Z","sequence_num":45,"events":[{"type":"update","product_id":"BTC-USD","updates":[{"side":"bid","event_time":"2026-07-16T20:28:53.799282Z","price_level":"64144.57","new_quantity":"0.01997259"},{"side":"bid","event_time":"2026-07-16T20:28:53.799282Z","price_level":"56126.5","new_quantity":"0.01337205"},{"side":"offer","event_time":"2026-07-16T20:28:53.799282Z","price_level":"64144.58","new_quantity":"0.2315608"}]}]}
{"channel":"l2_data","timestamp":"2026-07-16T20:28:53.880387964Z","sequence_num":46,"events":[{"type":"update","product_id":"BTC-USD","updates":[{"side":"bid","event_time":"2026-07-16T20:28:53.859503Z","price_level":"64131.64","new_quantity":"0.627336"},{"side":"offer","event_time":"2026-07-16T20:28:53.859503Z","price_level":"64144.58","new_quantity":"0.20184678"},{"side":"offer","event_time":"2026-07-16T20:28:53.859503Z","price_level":"64156.5","new_quantity":"0"},{"side":"offer","event_time":"2026-07-16T20:28:53.859503Z","price_level":"64156.51","new_quantity":"0"}]}]}
{"channel":"l2_data","timestamp":"2026-07-16T20:28:53.959594531Z","sequence_num":47,"events":[{"type":"update","product_id":"BTC-USD","updates":[{"side":"bid","event_time":"2026-07-16T20:28:53.896709Z","price_level":"64131.64","new_quantity":"0"},{"side":"bid","event_time":"2026-07-16T20:28:53.896709Z","price_level":"56126.5","new_quantity":"0"},{"side":"offer","event_time":"2026-07-16T20:28:53.896709Z","price_level":"64152.21","new_quantity":"0.21326694"},{"side":"offer","event_time":"2026-07-16T20:28:53.896709Z","price_level":"64153.56","new_quantity":"0"},{"side":"offer","event_time":"2026-07-16T20:28:53.896709Z","price_level":"64156.48","new_quantity":"0.78485715"},{"side":"offer","event_time":"2026-07-16T20:28:53.896709Z","price_level":"64156.49","new_quantity":"0.65487905"},{"side":"offer","event_time":"2026-07-16T20:28:53.896709Z","price_level":"64156.5","new_quantity":"0"}]}]}
{"channel":"l2_data","timestamp":"2026-07-16T20:28:53.979896178Z","sequence_num":48,"events":[{"type":"update","product_id":"BTC-USD","updates":[{"side":"bid","event_time":"2026-07-16T20:28:53.919804Z","price_level":"51315.66","new_quantity":"0"}]}]}
{"channel":"l2_data","timestamp":"2026-07-16T20:28:54.031278126Z","sequence_num":49,"events":[{"type":"update","product_id":"BTC-USD","updates":[{"side":"bid","event_time":"2026-07-16T20:28:53.983092Z","price_level":"64115.15","new_quantity":"0.32896531"},{"side":"bid","event_time":"2026-07-16T20:28:53.983092Z","price_level":"64095.91","new_quantity":"0.55049551"},{"side":"offer","event_time":"2026-07-16T20:28:53.983092Z","price_level":"64165.57","new_quantity":"0.2811817"},{"side":"offer","event_time":"2026-07-16T20:28:53.983092Z","price_level":"64184.82","new_quantity":"0.57544418"}]}]}
{"channel":"l2_data","timestamp":"2026-07-16T20:28:54.081083467Z","sequence_num":50,"events":[{"type":"update","product_id":"BTC-USD","updates":[{"side":"bid","event_time":"2026-07-16T20:28:54.03598Z","price_level":"64135.82","new_quantity":"0"},{"side":"bid","event_time":"2026-07-16T20:28:54.03598Z","price_level":"64135.29","new_quantity":"0.01559221"},{"side":"offer","event_time":"2026-07-16T20:28:54.03598Z","price_level":"64144.91","new_quantity":"0.01559221"},{"side":"offer","event_time":"2026-07-16T20:28:54.03598Z","price_level":"64145.44","new_quantity":"0"},{"side":"offer","event_time":"2026-07-16T20:28:54.03598Z","price_level":"64150.53","new_quantity":"0"},{"side":"offer","event_time":"2026-07-16T20:28:54.03598Z","price_level":"64151.5","new_quantity":"0"}]}]}
{"channel":"l2_data","timestamp":"2026-07-16T20:28:54.125588344Z","sequence_num":51,"events":[{"type":"update","product_id":"BTC-USD","updates":[{"side":"bid","event_time":"2026-07-16T20:28:54.101269Z","price_level":"64131.57","new_quantity":"0.632229"},{"side":"bid","event_time":"2026-07-16T20:28:54.101269Z","price_level":"56126.5","new_quantity":"0.01337205"}]}]}
{"channel":"heartbeats","timestamp":"2026-07-16T20:28:54.164503729Z","sequence_num":52,"events":[{"current_time":"2026-07-16 20:28:54.162885915 +0000 UTC m=+75498.317712958","heartbeat_counter":75498}]}
{"channel":"l2_data","timestamp":"2026-07-16T20:28:54.18023729Z","sequence_num":53,"events":[{"type":"update","product_id":"BTC-USD","updates":[{"side":"bid","event_time":"2026-07-16T20:28:54.1531Z","price_level":"64131.57","new_quantity":"0"},{"side":"bid","event_time":"2026-07-16T20:28:54.1531Z","price_level":"63933.08","new_quantity":"0"},{"side":"offer","event_time":"2026-07-16T20:28:54.1531Z","price_level":"64184.81","new_quantity":"0.00077947"},{"side":"offer","event_time":"2026-07-16T20:28:54.1531Z","price_level":"64184.99","new_quantity":"0"}]}]}
{"channel":"l2_data","timestamp":"2026-07-16T20:28:54.226560424Z","sequence_num":54,"events":[{"type":"update","product_id":"BTC-USD","updates":[{"side":"bid","event_time":"2026-07-16T20:28:54.192778Z","price_level":"56126.5","new_quantity":"0"}]}]}
{"channel":"l2_data","timestamp":"2026-07-16T20:28:54.279820707Z","sequence_num":55,"events":[{"type":"update","product_id":"BTC-USD","updates":[{"side":"bid","event_time":"2026-07-16T20:28:54.252283Z","price_level":"64144.57","new_quantity":"0.01997256"},{"side":"offer","event_time":"2026-07-16T20:28:54.252283Z","price_level":"64150.44","new_quantity":"0.00009743"},{"side":"offer","event_time":"2026-07-16T20:28:54.252283Z","price_level":"64151.4","new_quantity":"0.00779406"}]}]}
{"channel":"l2_data","timestamp":"2026-07-16T20:28:54.426332324Z","sequence_num":56,"events":[{"type":"update","product_id":"BTC-USD","updates":[{"side":"bid","event_time":"2026-07-16T20:28:54.393272Z","price_level":"64131.61","new_quantity":"0.588565"},{"side":"bid","event_time":"2026-07-16T20:28:54.393272Z","price_level":"56126.5","new_quantity":"0.01337205"}]}]}
{"channel":"l2_data","timestamp":"2026-07-16T20:28:54.477884282Z","sequence_num":57,"events":[{"type":"update","product_id":"BTC-USD","updates":[{"side":"bid","event_time":"2026-07-16T20:28:54.440791Z","price_level":"64144.57","new_quantity":"0.01682342"}]}]}
{"channel":"l2_data","timestamp":"2026-07-16T20:28:54.532368125Z","sequence_num":58,"events":[{"type":"update","product_id":"BTC-USD","updates":[{"side":"bid","event_time":"2026-07-16T20:28:54.50898Z","price_level":"56126.5","new_quantity":"0"},{"side":"offer","event_time":"2026-07-16T20:28:54.50898Z","price_level":"64168.33","new_quantity":"0"}]}]}
{"channel":"l2_data","timestamp":"2026-07-16T20:28:54.579641206Z","sequence_num":59,"events":[{"type":"update","product_id":"BTC-USD","updates":[{"side":"bid","event_time":"2026-07-16T20:28:54.553527Z","price_level":"64131.61","new_quantity":"0"}]}]}
{"channel":"l2_data","timestamp":"2026-07-16T20:28:54.631400192Z","sequence_num":60,"events":[{"type":"update","product_id":"BTC-USD","updates":[{"side":"bid","event_time":"2026-07-16T20:28:54.606969Z","price_level":"64138.16","new_quantity":"0"},{"side":"bid","event_time":"2026-07-16T20:28:54.606969Z","price_level":"64131.63","new_quantity":"0.610963"},{"side":"offer","event_time":"2026-07-16T20:28:54.606969Z","price_level":"64153.08","new_quantity":"0"}]}]}
{"channel":"l2_data","timestamp":"2026-07-16T20:28:54.6808345Z","sequence_num":61,"events":[{"type":"update","product_id":"BTC-USD","updates":[{"side":"bid","event_time":"2026-07-16T20:28:54.659245Z","price_level":"64139.76","new_quantity":"0.00779548"},{"side":"bid","event_time":"2026-07-16T20:28:54.659245Z","price_level":"64138.16","new_quantity":"0.00779567"},{"side":"bid","event_time":"2026-07-16T20:28:54.659245Z","price_level":"64131.63","new_quantity":"0"},{"side":"bid","event_time":"2026-07-16T20:28:54.659245Z","price_level":"64119","new_quantity":"0"},{"side":"offer","event_time":"2026-07-16T20:28:54.659245Z","price_level":"64151.38","new_quantity":"0.00896317"},{"side":"offer","event_time":"2026-07-16T20:28:54.659245Z","price_level":"64151.47","new_quantity":"0"},{"side":"offer","event_time":"2026-07-16T20:28:54.659245Z","price_level":"64151.85","new_quantity":"0"},{"side":"offer","event_time":"2026-07-16T20:28:54.659245Z","price_level":"64152.99","new_quantity":"0.00896295"},{"side":"offer","event_time":"2026-07-16T20:28:54.659245Z","price_level":"64153.13","new_quantity":"0"},{"side":"offer","event_time":"2026-07-16T20:28:54.659245Z","price_level":"64168.3","new_quantity":"0.01682342"},{"side":"offer","event_time":"2026-07-16T20:28:54.659245Z","price_level":"64187.32","new_quantity":"0.48135137"},{"side":"offer","event_time":"2026-07-16T20:28:54.659245Z","price_level":"64187.33","new_quantity":"0"},{"side":"offer","event_time":"2026-07-16T20:28:54.659245Z","price_level":"64187.34","new_quantity":"0"},{"side":"offer","event_time":"2026-07-16T20:28:54.659245Z","price_level":"64206.89","new_quantity":"2.15528857"},{"side":"offer","event_time":"2026-07-16T20:28:54.659245Z","price_level":"64206.9","new_quantity":"0"},{"side":"offer","event_time":"2026-07-16T20:28:54.659245Z","price_level":"64206.91","new_quantity":"0"}]}]}
{"channel":"l2_data","timestamp":"2026-07-16T20:28:54.730970196Z","sequence_num":62,"events":[{"type":"update","product_id":"BTC-USD","updates":[{"side":"bid","event_time":"2026-07-16T20:28:54.702484Z","price_level":"64120","new_quantity":"0.01"},{"side":"bid","event_time":"2026-07-16T20:28:54.702484Z","price_level":"64080.43","new_quantity":"0.00015605"},{"side":"bid","event_time":"2026-07-16T20:28:54.702484Z","price_level":"56126.5","new_quantity":"0.01337205"},{"side":"offer","event_time":"2026-07-16T20:28:54.702484Z","price_level":"64144.58","new_quantity":"0.19974989"},{"side":"offer","event_time":"2026-07-16T20:28:54.702484Z","price_level":"64151.75","new_quantity":"0.00009743"},{"side":"offer","event_time":"2026-07-16T20:28:54.702484Z","price_level":"64153.03","new_quantity":"0.00779386"}]}]}
{"channel":"l2_data","timestamp":"2026-07-16T20:28:54.777374449Z","sequence_num":63,"events":[{"type":"update","product_id":"BTC-USD","updates":[{"side":"bid","event_time":"2026-07-16T20:28:54.722806Z","price_level":"64119","new_quantity":"1"}]}]}
{"channel":"l2_data","timestamp":"2026-07-16T20:28:54.830438649Z","sequence_num":64,"events":[{"type":"update","product_id":"BTC-USD","updates":[{"side":"bid","event_time":"2026-07-16T20:28:54.803867Z","price_level":"56126.5","new_quantity":"0"},{"side":"offer","event_time":"2026-07-16T20:28:54.803867Z","price_level":"64168.3","new_quantity":"0"}]}]}
{"channel":"l2_data","timestamp":"2026-07-16T20:28:54.880550617Z","sequence_num":65,"events":[{"type":"update","product_id":"BTC-USD","updates":[{"side":"bid","event_time":"2026-07-16T20:28:54.859107Z","price_level":"64144.57","new_quantity":"0.01682336"},{"side":"bid","event_time":"2026-07-16T20:28:54.859107Z","price_level":"64131.61","new_quantity":"0.670375"},{"side":"bid","event_time":"2026-07-16T20:28:54.859107Z","price_level":"64115.15","new_quantity":"0.04691558"},{"side":"bid","event_time":"2026-07-16T20:28:54.859107Z","price_level":"64095.91","new_quantity":"0"},{"side":"offer","event_time":"2026-07-16T20:28:54.859107Z","price_level":"64165.57","new_quantity":"0"},{"side":"offer","event_time":"2026-07-16T20:28:54.859107Z","price_level":"64184.82","new_quantity":"0"}]}]}
{"channel":"l2_data","timestamp":"2026-07-16T20:28:54.926861203Z","sequence_num":66,"events":[{"type":"update","product_id":"BTC-USD","updates":[{"side":"bid","event_time":"2026-07-16T20:28:54.892909Z","price_level":"64131.61","new_quantity":"0"}]}]}
{"channel":"l2_data","timestamp":"2026-07-16T20:28:54.978815043Z","sequence_num":67,"events":[{"type":"update","product_id":"BTC-USD","updates":[{"side":"offer","event_time":"2026-07-16T20:28:54.957069Z","price_level":"64156.48","new_quantity":"0.39389436"},{"side":"offer","event_time":"2026-07-16T20:28:54.957069Z","price_level":"64156.49","new_quantity":"0"},{"side":"offer","event_time":"2026-07-16T20:28:54.957069Z","price_level":"64168.3","new_quantity":"0.01682342"}]}]}
{"channel":"l2_data","timestamp":"2026-07-16T20:28:55.033840297Z","sequence_num":68,"events":[{"type":"update","product_id":"BTC-USD","updates":[{"side":"bid","event_time":"2026-07-16T20:28:55.013969Z","price_level":"64137.6","new_quantity":"0.01053378"},{"side":"bid","event_time":"2026-07-16T20:28:55.013969Z","price_level":"56126.5","new_quantity":"0.01337205"},{"side":"offer","event_time":"2026-07-16T20:28:55.013969Z","price_level":"64151.4","new_quantity":"0"}]}]}
{"channel":"l2_data","timestamp":"2026-07-16T20:28:55.090995463Z","sequence_num":69,"events":[{"type":"update","product_id":"BTC-USD","updates":[{"side":"bid","event_time":"2026-07-16T20:28:55.05899Z","price_level":"64144.57","new_quantity":"0.02682336"},{"side":"bid","event_time":"2026-07-16T20:28:55.05899Z","price_level":"64139.53","new_quantity":"0.31190852"},{"side":"bid","event_time":"2026-07-16T20:28:55.05899Z","price_level":"64139.52","new_quantity":"0"},{"side":"bid","event_time":"2026-07-16T20:28:55.05899Z","price_level":"64135.93","new_quantity":"0.01559221"},{"side":"bid","event_time":"2026-07-16T20:28:55.05899Z","price_level":"64135.29","new_quantity":"0"},{"side":"bid","event_time":"2026-07-16T20:28:55.05899Z","price_level":"64131.54","new_quantity":"0.0077892"},{"side":"bid","event_time":"2026-07-16T20:28:55.05899Z","price_level":"64131.53","new_quantity":"0.25704587"},{"side":"bid","event_time":"2026-07-16T20:28:55.05899Z","price_level":"64123.26","new_quantity":"0.00583"},{"side":"bid","event_time":"2026-07-16T20:28:55.05899Z","price_level":"64111.61","new_quantity":"0"},{"side":"bid","event_time":"2026-07-16T20:28:55.05899Z","price_level":"63692.69","new_quantity":"0.00583"},{"side":"bid","event_time":"2026-07-16T20:28:55.05899Z","price_level":"63692.57","new_quantity":"0"},{"side":"bid","event_time":"2026-07-16T20:28:55.05899Z","price_level":"63263.36","new_quantity":"0.00583"},{"side":"bid","event_time":"2026-07-16T20:28:55.05899Z","price_level":"63263.3","new_quantity":"0"},{"side":"bid","event_time":"2026-07-16T20:28:55.05899Z","price_level":"63048.83","new_quantity":"0"},{"side":"bid","event_time":"2026-07-16T20:28:55.05899Z","price_level":"62834.25","new_quantity":"0"},{"side":"offer","event_time":"2026-07-16T20:28:55.05899Z","price_level":"64144.58","new_quantity":"0.15789672"},{"side":"offer","event_time":"2026-07-16T20:28:55.05899Z","price_level":"64144.65","new_quantity":"0"},{"side":"offer","event_time":"2026-07-16T20:28:55.05899Z","price_level":"64144.91","new_quantity":"0"},{"side":"offer","event_time":"2026-07-16T20:28:55.05899Z","price_level":"64145.22","new_quantity":"0.12471702"},{"side":"offer","event_time":"2026-07-16T20:28:55.05899Z","price_level":"64145.24","new_quantity":"0"},{"side":"offer","event_time":"2026-07-16T20:28:55.05899Z","price_level":"64145.25","new_quantity":"0"},{"side":"offer","event_time":"2026-07-16T20:28:55.05899Z","price_level":"64145.7","new_quantity":"0"},{"side":"offer","event_time":"2026-07-16T20:28:55.05899Z","price_level":"64145.73","new_quantity":"0"},{"side":"offer","event_time":"2026-07-16T20:28:55.05899Z","price_level":"64147.29","new_quantity":"0"},{"side":"offer","event_time":"2026-07-16T20:28:55.05899Z","price_level":"64148.69","new_quantity":"0"},{"side":"offer","event_time":"2026-07-16T20:28:55.05899Z","price_level":"64149.34","new_quantity":"0"},{"side":"offer","event_time":"2026-07-16T20:28:55.05899Z","price_level":"64149.37","new_quantity":"0"},{"side":"offer","event_time":"2026-07-16T20:28:55.05899Z","price_level":"64150.44","new_quantity":"0"},{"side":"offer","event_time":"2026-07-16T20:28:55.05899Z","price_level":"64150.63","new_quantity":"0"},{"side":"offer","event_time":"2026-07-16T20:28:55.05899Z","price_level":"64150.98","new_quantity":"0"},{"side":"offer","event_time":"2026-07-16T20:28:55.05899Z","price_level":"64151.33","new_quantity":"0"},{"side":"offer","event_time":"2026-07-16T20:28:55.05899Z","price_level":"64152.21","new_quantity":"0"},{"side":"offer","event_time":"2026-07-16T20:28:55.05899Z","price_level":"64152.98","new_quantity":"0"},{"side":"offer","event_time":"2026-07-16T20:28:55.05899Z","price_level":"64153.57","new_quantity":"0"},{"side":"offer","event_time":"2026-07-16T20:28:55.05899Z","price_level":"64156.48","new_quantity":"0"},{"side":"offer","event_time":"2026-07-16T20:28:55.05899Z","price_level":"64156.53","new_quantity":"0.31190852"},{"side":"offer","event_time":"2026-07-16T20:28:55.05899Z","price_level":"64157.16","new_quantity":"0"},{"side":"offer","event_time":"2026-07-16T20:28:55.05899Z","price_level":"64158.45","new_quantity":"0.32706832"},{"side":"offer","event_time":"2026-07-16T20:28:55.05899Z","price_level":"64158.46","new_quantity":"0.31190852"},{"side":"offer","event_time":"2026-07-16T20:28:55.05899Z","price_level":"64158.99","new_quantity":"0"},{"side":"offer","event_time":"2026-07-16T20:28:55.05899Z","price_level":"64159.23","new_quantity":"0"},{"side":"offer","event_time":"2026-07-16T20:28:55.05899Z","price_level":"64160","new_quantity":"0.01"},{"side":"offer","event_time":"2026-07-16T20:28:55.05899Z","price_level":"64168.98","new_quantity":"0.31190852"},{"side":"offer","event_time":"2026-07-16T20:28:55.05899Z","price_level":"64172.83","new_quantity":"0.31190852"},{"side":"offer","event_time":"2026-07-16T20:28:55.05899Z","price_level":"64189.94","new_quantity":"0"},{"side":"offer","event_time":"2026-07-16T20:28:55.05899Z","price_level":"64197.14","new_quantity":"0"}]}]}
{"channel":"heartbeats","timestamp":"2026-07-16T20:28:55.168165496Z","sequence_num":70,"events":[{"current_time":"2026-07-16 20:28:55.162887564 +0000 UTC m=+75499.317714619","heartbeat_counter":75499}]}
{"channel":"l2_data","timestamp":"2026-07-16T20:28:55.192827494Z","sequence_num":71,"events":[{"type":"update","product_id":"BTC-USD","updates":[{"side":"bid","event_time":"2026-07-16T20:28:55.101468Z","price_level":"64141.55","new_quantity":"0.12472413"},{"side":"bid","event_time":"2026-07-16T20:28:55.101468Z","price_level":"64139.53","new_quantity":"0"},{"side":"bid","event_time":"2026-07-16T20:28:55.101468Z","price_level":"64137.27","new_quantity":"0"},{"side":"bid","event_time":"2026-07-16T20:28:55.101468Z","price_level":"64137.06","new_quantity":"0"},{"side":"bid","event_time":"2026-07-16T20:28:55.101468Z","price_level":"64123.48","new_quantity":"0.00583"},{"side":"bid","event_time":"2026-07-16T20:28:55.101468Z","price_level":"64123.26","new_quantity":"0"},{"side":"bid","event_time":"2026-07-16T20:28:55.101468Z","price_level":"64121.69","new_quantity":"0"},{"side":"bid","event_time":"2026-07-16T20:28:55.101468Z","price_level":"64119.32","new_quantity":"0.65487201"},{"side":"bid","event_time":"2026-07-16T20:28:55.101468Z","price_level":"64119","new_quantity":"0"},{"side":"bid","event_time":"2026-07-16T20:28:55.101468Z","price_level":"64115.55","new_quantity":"0"},{"side":"bid","event_time":"2026-07-16T20:28:55.101468Z","price_level":"63908.38","new_quantity":"0.00583"},{"side":"bid","event_time":"2026-07-16T20:28:55.101468Z","price_level":"63907.15","new_quantity":"0"},{"side":"bid","event_time":"2026-07-16T20:28:55.101468Z","price_level":"63693.36","new_quantity":"0.00583"},{"side":"bid","event_time":"2026-07-16T20:28:55.101468Z","price_level":"63692.69","new_quantity":"0"},{"side":"bid","event_time":"2026-07-16T20:28:55.101468Z","price_level":"63478.05","new_quantity":"0"},{"side":"bid","event_time":"2026-07-16T20:28:55.101468Z","price_level":"63477.83","new_quantity":"0.00583"},{"side":"bid","event_time":"2026-07-16T20:28:55.101468Z","price_level":"63263.4","new_quantity":"0.00583"},{"side":"bid","event_time":"2026-07-16T20:28:55.101468Z","price_level":"63263.36","new_quantity":"0"},{"side":"bid","event_time":"2026-07-16T20:28:55.101468Z","price_level":"63048.97","new_quantity":"0.00583"},{"side":"bid","event_time":"2026-07-16T20:28:55.101468Z","price_level":"62834.54","new_quantity":"0.00583"},{"side":"bid","event_time":"2026-07-16T20:28:55.101468Z","price_level":"56126.5","new_quantity":"0"},{"side":"offer","event_time":"2026-07-16T20:28:55.101468Z","price_level":"64144.58","new_quantity":"0.18717769"},{"side":"offer","event_time":"2026-07-16T20:28:55.101468Z","price_level":"64145.22","new_quantity":"0"},{"side":"offer","event_time":"2026-07-16T20:28:55.101468Z","price_level":"64146.03","new_quantity":"0.12471544"},{"side":"offer","event_time":"2026-07-16T20:28:55.101468Z","price_level":"64147.28","new_quantity":"0.31190852"},{"side":"offer","event_time":"2026-07-16T20:28:55.101468Z","price_level":"64149.34","new_quantity":"0.31190852"},{"side":"offer","event_time":"2026-07-16T20:28:55.101468Z","price_level":"64151.01","new_quantity":"0.04691558"},{"side":"offer","event_time":"2026-07-16T20:28:55.101468Z","price_level":"64152.32","new_quantity":"0.31190852"},{"side":"offer","event_time":"2026-07-16T20:28:55.101468Z","price_level":"64154.56","new_quantity":"0.19217939"},{"side":"offer","event_time":"2026-07-16T20:28:55.101468Z","price_level":"64154.57","new_quantity":"0.31190852"},{"side":"offer","event_time":"2026-07-16T20:28:55.101468Z","price_level":"64156.52","new_quantity":"0.39389436"},{"side":"offer","event_time":"2026-07-16T20:28:55.101468Z","price_level":"64158.45","new_quantity":"0.88225328"},{"side":"offer","event_time":"2026-07-16T20:28:55.101468Z","price_level":"64160","new_quantity":"1.01"},{"side":"offer","event_time":"2026-07-16T20:28:55.101468Z","price_level":"64172.83","new_quantity":"0"},{"side":"offer","event_time":"2026-07-16T20:28:55.101468Z","price_level":"64286.22","new_quantity":"0.5"}]}]}
{"channel":"l2_data","timestamp":"2026-07-16T20:28:55.23502013Z","sequence_num":72,"events":[{"type":"update","product_id":"BTC-USD","updates":[{"side":"bid","event_time":"2026-07-16T20:28:55.169947Z","price_level":"64141.55","new_quantity":"0"},{"side":"bid","event_time":"2026-07-16T20:28:55.169947Z","price_level":"64140.43","new_quantity":"0.12472631"},{"side":"bid","event_time":"2026-07-16T20:28:55.169947Z","price_level":"64138.42","new_quantity":"0.15591276"},{"side":"bid","event_time":"2026-07-16T20:28:55.169947Z","price_level":"64137.6","new_quantity":"0.00033322"},{"side":"bid","event_time":"2026-07-16T20:28:55.169947Z","price_level":"64133.11","new_quantity":"0"},{"side":"bid","event_time":"2026-07-16T20:28:55.169947Z","price_level":"64130.87","new_quantity":"0.07385"},{"side":"bid","event_time":"2026-07-16T20:28:55.169947Z","price_level":"64120","new_quantity":"1.01"},{"side":"bid","event_time":"2026-07-16T20:28:55.169947Z","price_level":"64119.32","new_quantity":"0"},{"side":"bid","event_time":"2026-07-16T20:28:55.169947Z","price_level":"64115.58","new_quantity":"0.5986111"},{"side":"bid","event_time":"2026-07-16T20:28:55.169947Z","price_level":"64115.57","new_quantity":"0.65487895"},{"side":"bid","event_time":"2026-07-16T20:28:55.169947Z","price_level":"64115.56","new_quantity":"0"},{"side":"bid","event_time":"2026-07-16T20:28:55.169947Z","price_level":"64115.14","new_quantity":"0.27466478"},{"side":"bid","event_time":"2026-07-16T20:28:55.169947Z","price_level":"64095.91","new_quantity":"0.56356577"},{"side":"offer","event_time":"2026-07-16T20:28:55.169947Z","price_level":"64146.02","new_quantity":"0.17577378"},{"side":"offer","event_time":"2026-07-16T20:28:55.169947Z","price_level":"64146.03","new_quantity":"0"},{"side":"offer","event_time":"2026-07-16T20:28:55.169947Z","price_level":"64147.28","new_quantity":"0"},{"side":"offer","event_time":"2026-07-16T20:28:55.169947Z","price_level":"64149.33","new_quantity":"0.36000303"},{"side":"offer","event_time":"2026-07-16T20:28:55.169947Z","price_level":"64152.31","new_quantity":"0.39275352"},{"side":"offer","event_time":"2026-07-16T20:28:55.169947Z","price_level":"64154.56","new_quantity":"0"},{"side":"offer","event_time":"2026-07-16T20:28:55.169947Z","price_level":"64165.48","new_quantity":"0.35985163"},{"side":"offer","event_time":"2026-07-16T20:28:55.169947Z","price_level":"64165.58","new_quantity":"0.27487488"},{"side":"offer","event_time":"2026-07-16T20:28:55.169947Z","price_level":"64168.3","new_quantity":"0"},{"side":"offer","event_time":"2026-07-16T20:28:55.169947Z","price_level":"64184.81","new_quantity":"0"},{"side":"offer","event_time":"2026-07-16T20:28:55.169947Z","price_level":"64184.82","new_quantity":"0.55239383"},{"side":"offer","event_time":"2026-07-16T20:28:55.169947Z","price_level":"64184.99","new_quantity":"0.00077946"}]}]}
{"channel":"l2_data","timestamp":"2026-07-16T20:28:55.253012228Z","sequence_num":73,"events":[{"type":"update","product_id":"BTC-USD","updates":[{"side":"bid","event_time":"2026-07-16T20:28:55.202187Z","price_level":"64120","new_quantity":"0.01"},{"side":"offer","event_time":"2026-07-16T20:28:55.202187Z","price_level":"64145.07","new_quantity":"0.33182181"},{"side":"offer","event_time":"2026-07-16T20:28:55.202187Z","price_level":"64145.08","new_quantity":"0.23359045"},{"side":"offer","event_time":"2026-07-16T20:28:55.202187Z","price_level":"64145.09","new_quantity":"0"},{"side":"offer","event_time":"2026-07-16T20:28:55.202187Z","price_level":"64145.1","new_quantity":"0.12471724"},{"side":"offer","event_time":"2026-07-16T20:28:55.202187Z","price_level":"64145.55","new_quantity":"0.01559177"},{"side":"offer","event_time":"2026-07-16T20:28:55.202187Z","price_level":"64146.02","new_quantity":"0"},{"side":"offer","event_time":"2026-07-16T20:28:55.202187Z","price_level":"64197.13","new_quantity":"0.29624365"}]}]}
{"channel":"l2_data","timestamp":"2026-07-16T20:28:55.295149747Z","sequence_num":74,"events":[{"type":"update","product_id":"BTC-USD","updates":[{"side":"bid","event_time":"2026-07-16T20:28:55.241667Z","price_level":"64127.68","new_quantity":"0"},{"side":"bid","event_time":"2026-07-16T20:28:55.241667Z","price_level":"64116","new_quantity":"1"},{"side":"offer","event_time":"2026-07-16T20:28:55.241667Z","price_level":"64151.27","new_quantity":"0.0012474"},{"side":"offer","event_time":"2026-07-16T20:28:55.241667Z","price_level":"64228.69","new_quantity":"0"}]}]}
{"channel":"l2_data","timestamp":"2026-07-16T20:28:55.341844413Z","sequence_num":75,"events":[{"type":"update","product_id":"BTC-USD","updates":[{"side":"bid","event_time":"2026-07-16T20:28:55.297612Z","price_level":"64144.57","new_quantity":"0.0268233"},{"side":"bid","event_time":"2026-07-16T20:28:55.297612Z","price_level":"64117.01","new_quantity":"0.59859775"},{"side":"bid","event_time":"2026-07-16T20:28:55.297612Z","price_level":"64117","new_quantity":"1"},{"side":"bid","event_time":"2026-07-16T20:28:55.297612Z","price_level":"64116","new_quantity":"0"},{"side":"bid","event_time":"2026-07-16T20:28:55.297612Z","price_level":"64115.58","new_quantity":"0"},{"side":"bid","event_time":"2026-07-16T20:28:55.297612Z","price_level":"56126.5","new_quantity":"0.01337205"},{"side":"offer","event_time":"2026-07-16T20:28:55.297612Z","price_level":"64145.06","new_quantity":"0.02"},{"side":"offer","event_time":"2026-07-16T20:28:55.297612Z","price_level":"64168.39","new_quantity":"0.02682336"}]}]}
{"channel":"l2_data","timestamp":"2026-07-16T20:28:55.411225922Z","sequence_num":76,"events":[{"type":"update","product_id":"BTC-USD","updates":[{"side":"bid","event_time":"2026-07-16T20:28:55.354084Z","price_level":"64119.58","new_quantity":"0.598735"},{"side":"bid","event_time":"2026-07-16T20:28:55.354084Z","price_level":"64117","new_quantity":"0"},{"side":"offer","event_time":"2026-07-16T20:28:55.354084Z","price_level":"64144.64","new_quantity":"0"},{"side":"offer","event_time":"2026-07-16T20:28:55.354084Z","price_level":"64145.07","new_quantity":"0.48491671"},{"side":"offer","event_time":"2026-07-16T20:28:55.354084Z","price_level":"64145.23","new_quantity":"0"},{"side":"offer","event_time":"2026-07-16T20:28:55.354084Z","price_level":"64147.36","new_quantity":"0.31190852"},{"side":"offer","event_time":"2026-07-16T20:28:55.354084Z","price_level":"64150.35","new_quantity":"0.00009743"},{"side":"offer","event_time":"2026-07-16T20:28:55.354084Z","price_level":"64151.31","new_quantity":"0.00779407"},{"side":"offer","event_time":"2026-07-16T20:28:55.354084Z","price_level":"64189.94","new_quantity":"0.5"},{"side":"offer","event_time":"2026-07-16T20:28:55.354084Z","price_level":"64286.22","new_quantity":"0"}]}]}
{"channel":"l2_data","timestamp":"2026-07-16T20:28:55.685067185Z","sequence_num":77,"events":[{"type":"update","product_id":"BTC-USD","updates":[{"side":"bid","event_time":"2026-07-16T20:28:55.600353Z","price_level":"64131.96","new_quantity":"0.648795"},{"side":"bid","event_time":"2026-07-16T20:28:55.600353Z","price_level":"64119.58","new_quantity":"0"},{"side":"bid","event_time":"2026-07-16T20:28:55.600353Z","price_level":"64119","new_quantity":"1"},{"side":"bid","event_time":"2026-07-16T20:28:55.600353Z","price_level":"64117.01","new_quantity":"0"},{"side":"bid","event_time":"2026-07-16T20:28:55.600353Z","price_level":"64115.58","new_quantity":"0.5986111"},{"side":"bid","event_time":"2026-07-16T20:28:55.600353Z","price_level":"56126.5","new_quantity":"0.01337205"},{"side":"offer","event_time":"2026-07-16T20:28:55.600353Z","price_level":"64150.97","new_quantity":"0.0486477"},{"side":"offer","event_time":"2026-07-16T20:28:55.600353Z","price_level":"64168.39","new_quantity":"0.0268233"},{"side":"offer","event_time":"2026-07-16T20:28:55.600353Z","price_level":"64228.77","new_quantity":"0.05256455"}]}]}
{"channel":"l2_data","timestamp":"2026-07-16T20:28:55.748944678Z","sequence_num":78,"events":[{"type":"update","product_id":"BTC-USD","updates":[{"side":"bid","event_time":"2026-07-16T20:28:55.705364Z","price_level":"64139.76","new_quantity":"0"},{"side":"bid","event_time":"2026-07-16T20:28:55.705364Z","price_level":"64138.16","new_quantity":"0.00779567"},{"side":"bid","event_time":"2026-07-16T20:28:55.705364Z","price_level":"64131.96","new_quantity":"0"},{"side":"bid","event_time":"2026-07-16T20:28:55.705364Z","price_level":"56126.5","new_quantity":"0"},{"side":"offer","event_time":"2026-07-16T20:28:55.705364Z","price_level":"64151.38","new_quantity":"0"},{"side":"offer","event_time":"2026-07-16T20:28:55.705364Z","price_level":"64152.9","new_quantity":"0.00896296"},{"side":"offer","event_time":"2026-07-16T20:28:55.705364Z","price_level":"64152.99","new_quantity":"0"},{"side":"offer","event_time":"2026-07-16T20:28:55.705364Z","price_level":"64168.39","new_quantity":"0"},{"side":"offer","event_time":"2026-07-16T20:28:55.705364Z","price_level":"64187.3","new_quantity":"0.48135152"},{"side":"offer","event_time":"2026-07-16T20:28:55.705364Z","price_level":"64187.31","new_quantity":"0"},{"side":"offer","event_time":"2026-07-16T20:28:55.705364Z","price_level":"64187.32","new_quantity":"0"},{"side":"offer","event_time":"2026-07-16T20:28:55.705364Z","price_level":"64206.87","new_quantity":"2.15528924"},{"side":"offer","event_time":"2026-07-16T20:28:55.705364Z","price_level":"64206.88","new_quantity":"0"},{"side":"offer","event_time":"2026-07-16T20:28:55.705364Z","price_level":"64206.89","new_quantity":"0"}]}]}
{"channel":"l2_data","timestamp":"2026-07-16T20:28:55.806232232Z","sequence_num":79,"events":[{"type":"update","product_id":"BTC-USD","updates":[{"side":"bid","event_time":"2026-07-16T20:28:55.744571Z","price_level":"64139.76","new_quantity":"0.00779548"},{"side":"offer","event_time":"2026-07-16T20:28:55.744571Z","price_level":"64151.29","new_quantity":"0.00896319"},{"side":"offer","event_time":"2026-07-16T20:28:55.744571Z","price_level":"64151.66","new_quantity":"0.00009743"},{"side":"offer","event_time":"2026-07-16T20:28:55.744571Z","price_level":"64151.75","new_quantity":"0"},{"side":"offer","event_time":"2026-07-16T20:28:55.744571Z","price_level":"64152.94","new_quantity":"0.00779388"},{"side":"offer","event_time":"2026-07-16T20:28:55.744571Z","price_level":"64153.03","new_quantity":"0"}]}]}
{"channel":"l2_data","timestamp":"2026-07-16T20:28:55.831217648Z","sequence_num":80,"events":[{"type":"update","product_id":"BTC-USD","updates":[{"side":"bid","event_time":"2026-07-16T20:28:55.807467Z","price_level":"64144.57","new_quantity":"0.02682324"}]}]}
{"channel":"l2_data","timestamp":"2026-07-16T20:28:55.877321166Z","sequence_num":81,"events":[{"type":"update","product_id":"BTC-USD","updates":[{"side":"offer","event_time":"2026-07-16T20:28:55.856082Z","price_level":"64168.39","new_quantity":"0.0268233"}]}]}
{"channel":"l2_data","timestamp":"2026-07-16T20:28:55.926698867Z","sequence_num":82,"events":[{"type":"update","product_id":"BTC-USD","updates":[{"side":"bid","event_time":"2026-07-16T20:28:55.898738Z","price_level":"64144.57","new_quantity":"0.02682313"},{"side":"bid","event_time":"2026-07-16T20:28:55.898738Z","price_level":"64119.6","new_quantity":"0"},{"side":"bid","event_time":"2026-07-16T20:28:55.898738Z","price_level":"56126.5","new_quantity":"0.01337205"}]}]}
{"channel":"l2_data","timestamp":"2026-07-16T20:28:55.976183256Z","sequence_num":83,"events":[{"type":"update","product_id":"BTC-USD","updates":[{"side":"bid","event_time":"2026-07-16T20:28:55.952514Z","price_level":"64119","new_quantity":"0"}]}]}
{"channel":"l2_data","timestamp":"2026-07-16T20:28:56.026782038Z","sequence_num":84,"events":[{"type":"update","product_id":"BTC-USD","updates":[{"side":"bid","event_time":"2026-07-16T20:28:56.001413Z","price_level":"64137.6","new_quantity":"0.01048749"},{"side":"bid","event_time":"2026-07-16T20:28:56.001413Z","price_level":"64120","new_quantity":"1.01"},{"side":"bid","event_time":"2026-07-16T20:28:56.001413Z","price_level":"56126.5","new_quantity":"0"}]}]}
{"channel":"l2_data","timestamp":"2026-07-16T20:28:56.081988066Z","sequence_num":85,"events":[{"type":"update","product_id":"BTC-USD","updates":[{"side":"offer","event_time":"2026-07-16T20:28:56.01996Z","price_level":"64150.35","new_quantity":"0"},{"side":"offer","event_time":"2026-07-16T20:28:56.01996Z","price_level":"64151.31","new_quantity":"0"},{"side":"offer","event_time":"2026-07-16T20:28:56.01996Z","price_level":"64168.39","new_quantity":"0"}]}]}
{"channel":"l2_data","timestamp":"2026-07-16T20:28:56.130223406Z","sequence_num":86,"events":[{"type":"update","product_id":"BTC-USD","updates":[{"side":"bid","event_time":"2026-07-16T20:28:56.100543Z","price_level":"64132.03","new_quantity":"0.656197"},{"side":"bid","event_time":"2026-07-16T20:28:56.100543Z","price_level":"57730.11","new_quantity":"0.00034643"},{"side":"offer","event_time":"2026-07-16T20:28:56.100543Z","price_level":"64144.58","new_quantity":"0.19964981"}]}]}
{"channel":"heartbeats","timestamp":"2026-07-16T20:28:56.164306858Z","sequence_num":87,"events":[{"current_time":"2026-07-16 20:28:56.1628857 +0000 UTC m=+75500.317712755","heartbeat_counter":75500}]}
{"channel":"l2_data","timestamp":"2026-07-16T20:28:56.22996004Z","sequence_num":88,"events":[{"type":"update","product_id":"BTC-USD","updates":[{"side":"bid","event_time":"2026-07-16T20:28:56.203797Z","price_level":"64132.03","new_quantity":"0"},{"side":"bid","event_time":"2026-07-16T20:28:56.203797Z","price_level":"56126.5","new_quantity":"0.01337205"},{"side":"offer","event_time":"2026-07-16T20:28:56.203797Z","price_level":"64168.39","new_quantity":"0.02682313"},{"side":"offer","event_time":"2026-07-16T20:28:56.203797Z","price_level":"64184.81","new_quantity":"0.00077946"},{"side":"offer","event_time":"2026-07-16T20:28:56.203797Z","price_level":"64184.99","new_quantity":"0"}]}]}
{"channel":"l2_data","timestamp":"2026-07-16T20:28:56.274718494Z","sequence_num":89,"events":[{"type":"update","product_id":"BTC-USD","updates":[{"side":"bid","event_time":"2026-07-16T20:28:56.225045Z","price_level":"64039.38","new_quantity":"0"}]}]}
{"channel":"l2_data","timestamp":"2026-07-16T20:28:56.330485356Z","sequence_num":90,"events":[{"type":"update","product_id":"BTC-USD","updates":[{"side":"bid","event_time":"2026-07-16T20:28:56.310899Z","price_level":"64144.57","new_quantity":"0.02682303"},{"side":"bid","event_time":"2026-07-16T20:28:56.310899Z","price_level":"64120","new_quantity":"0.01"},{"side":"bid","event_time":"2026-07-16T20:28:56.310899Z","price_level":"56126.5","new_quantity":"0"},{"side":"offer","event_time":"2026-07-16T20:28:56.310899Z","price_level":"64168.39","new_quantity":"0"}]}]}
{"channel":"l2_data","timestamp":"2026-07-16T20:28:56.381905089Z","sequence_num":91,"events":[{"type":"update","product_id":"BTC-USD","updates":[{"side":"bid","event_time":"2026-07-16T20:28:56.356579Z","price_level":"64132.01","new_quantity":"0.625951"},{"side":"bid","event_time":"2026-07-16T20:28:56.356579Z","price_level":"64119","new_quantity":"1"},{"side":"offer","event_time":"2026-07-16T20:28:56.356579Z","price_level":"64150.26","new_quantity":"0.00009743"},{"side":"offer","event_time":"2026-07-16T20:28:56.356579Z","price_level":"64151.22","new_quantity":"0.00779408"}]}]}
{"channel":"l2_data","timestamp":"2026-07-16T20:28:56.425514819Z","sequence_num":92,"events":[{"type":"update","product_id":"BTC-USD","updates":[{"side":"bid","event_time":"2026-07-16T20:28:56.36803Z","price_level":"64132.01","new_quantity":"0"}]}]}
{"channel":"l2_data","timestamp":"2026-07-16T20:28:56.47821407Z","sequence_num":93,"events":[{"type":"update","product_id":"BTC-USD","updates":[{"side":"bid","event_time":"2026-07-16T20:28:56.458846Z","price_level":"64036.36","new_quantity":"0.09380964"}]}]}
{"channel":"l2_data","timestamp":"2026-07-16T20:28:56.53117853Z","sequence_num":94,"events":[{"type":"update","product_id":"BTC-USD","updates":[{"side":"bid","event_time":"2026-07-16T20:28:56.494498Z","price_level":"64137.6","new_quantity":"0.00033322"},{"side":"bid","event_time":"2026-07-16T20:28:56.494498Z","price_level":"56126.5","new_quantity":"0.01337205"},{"side":"offer","event_time":"2026-07-16T20:28:56.494498Z","price_level":"64152.31","new_quantity":"0.73350454"},{"side":"offer","event_time":"2026-07-16T20:28:56.494498Z","price_level":"64154.56","new_quantity":"0.65488067"},{"side":"offer","event_time":"2026-07-16T20:28:56.494498Z","price_level":"64168.39","new_quantity":"0.02682303"}]}]}
{"channel":"l2_data","timestamp":"2026-07-16T20:28:56.625876195Z","sequence_num":95,"events":[{"type":"update","product_id":"BTC-USD","updates":[{"side":"bid","event_time":"2026-07-16T20:28:56.604385Z","price_level":"64131.97","new_quantity":"0"},{"side":"bid","event_time":"2026-07-16T20:28:56.604385Z","price_level":"56126.5","new_quantity":"0"}]}]}
{"channel":"l2_data","timestamp":"2026-07-16T20:28:56.676730347Z","sequence_num":96,"events":[{"type":"update","product_id":"BTC-USD","updates":[{"side":"offer","event_time":"2026-07-16T20:28:56.623384Z","price_level":"64168.39","new_quantity":"0"}]}]}
{"channel":"l2_data","timestamp":"2026-07-16T20:28:56.726837756Z","sequence_num":97,"events":[{"type":"update","product_id":"BTC-USD","updates":[{"side":"offer","event_time":"2026-07-16T20:28:56.67773Z","price_level":"64144.58","new_quantity":"0.19781952"}]}]}
{"channel":"l2_data","timestamp":"2026-07-16T20:28:56.780501041Z","sequence_num":98,"events":[{"type":"update","product_id":"BTC-USD","updates":[{"side":"bid","event_time":"2026-07-16T20:28:56.753941Z","price_level":"64139.76","new_quantity":"0"},{"side":"bid","event_time":"2026-07-16T20:28:56.753941Z","price_level":"64138.16","new_quantity":"0"},{"side":"offer","event_time":"2026-07-16T20:28:56.753941Z","price_level":"64151.29","new_quantity":"0"},{"side":"offer","event_time":"2026-07-16T20:28:56.753941Z","price_level":"64152.9","new_quantity":"0"},{"side":"offer","event_time":"2026-07-16T20:28:56.753941Z","price_level":"64187.28","new_quantity":"0.41447"},{"side":"offer","event_time":"2026-07-16T20:28:56.753941Z","price_level":"64187.3","new_quantity":"0"},{"side":"offer","event_time":"2026-07-16T20:28:56.753941Z","price_level":"64206.85","new_quantity":"2.15528991"},{"side":"offer","event_time":"2026-07-16T20:28:56.753941Z","price_level":"64206.87","new_quantity":"0"}]}]}
{"channel":"l2_data","timestamp":"2026-07-16T20:28:56.831407912Z","sequence_num":99,"events":[{"type":"update","product_id":"BTC-USD","updates":[{"side":"bid","event_time":"2026-07-16T20:28:56.807847Z","price_level":"64139.76","new_quantity":"0.00779548"},{"side":"bid","event_time":"2026-07-16T20:28:56.807847Z","price_level":"64138.16","new_quantity":"0.00779567"},{"side":"bid","event_time":"2026-07-16T20:28:56.807847Z","price_level":"56126.5","new_quantity":"0.01337205"},{"side":"offer","event_time":"2026-07-16T20:28:56.807847Z","price_level":"64151.2","new_quantity":"0.0089632"},{"side":"offer","event_time":"2026-07-16T20:28:56.807847Z","price_level":"64151.66","new_quantity":"0"},{"side":"offer","event_time":"2026-07-16T20:28:56.807847Z","price_level":"64152.81","new_quantity":"0.00896297"},{"side":"offer","event_time":"2026-07-16T20:28:56.807847Z","price_level":"64152.85","new_quantity":"0.00779389"},{"side":"offer","event_time":"2026-07-16T20:28:56.807847Z","price_level":"64152.94","new_quantity":"0"},{"side":"offer","event_time":"2026-07-16T20:28:56.807847Z","price_level":"64168.39","new_quantity":"0.02682303"}]}]}
{"channel":"l2_data","timestamp":"2026-07-16T20:28:56.879080891Z","sequence_num":100,"events":[{"type":"update","product_id":"BTC-USD","updates":[{"side":"bid","event_time":"2026-07-16T20:28:56.85499Z","price_level":"64092.9","new_quantity":"0.00003864"},{"side":"offer","event_time":"2026-07-16T20:28:56.85499Z","price_level":"64151.57","new_quantity":"0.00009743"}]}]}
{"channel":"l2_data","timestamp":"2026-07-16T20:28:56.925003793Z","sequence_num":101,"events":[{"type":"update","product_id":"BTC-USD","updates":[{"side":"bid","event_time":"2026-07-16T20:28:56.903151Z","price_level":"64120","new_quantity":"1.01"},{"side":"bid","event_time":"2026-07-16T20:28:56.903151Z","price_level":"64119","new_quantity":"0"},{"side":"bid","event_time":"2026-07-16T20:28:56.903151Z","price_level":"56126.5","new_quantity":"0"}]}]}
{"channel":"l2_data","timestamp":"2026-07-16T20:28:56.982663764Z","sequence_num":102,"events":[{"type":"update","product_id":"BTC-USD","updates":[{"side":"bid","event_time":"2026-07-16T20:28:56.960849Z","price_level":"64137.6","new_quantity":"0.00841016"},{"side":"offer","event_time":"2026-07-16T20:28:56.960849Z","price_level":"64159.58","new_quantity":"0"},{"side":"offer","event_time":"2026-07-16T20:28:56.960849Z","price_level":"64168.39","new_quantity":"0"}]}]}
{"channel":"l2_data","timestamp":"2026-07-16T20:28:57.026535807Z","sequence_num":103,"events":[{"type":"update","product_id":"BTC-USD","updates":[{"side":"offer","event_time":"2026-07-16T20:28:57.01364Z","price_level":"64151.22","new_quantity":"0"}]}]}
{"channel":"l2_data","timestamp":"2026-07-16T20:28:57.081821068Z","sequence_num":104,"events":[{"type":"update","product_id":"BTC-USD","updates":[{"side":"offer","event_time":"2026-07-16T20:28:57.017987Z","price_level":"64150.26","new_quantity":"0"}]}]}
{"channel":"l2_data","timestamp":"2026-07-16T20:28:57.130250446Z","sequence_num":105,"events":[{"type":"update","product_id":"BTC-USD","updates":[{"side":"bid","event_time":"2026-07-16T20:28:57.101843Z","price_level":"64137.6","new_quantity":"0.00033322"},{"side":"bid","event_time":"2026-07-16T20:28:57.101843Z","price_level":"64132.03","new_quantity":"0.61259"},{"side":"bid","event_time":"2026-07-16T20:28:57.101843Z","price_level":"56126.5","new_quantity":"0.01337205"},{"side":"offer","event_time":"2026-07-16T20:28:57.101843Z","price_level":"64168.39","new_quantity":"0.02682303"}]}]}
{"channel":"heartbeats","timestamp":"2026-07-16T20:28:57.163413071Z","sequence_num":106,"events":[{"current_time":"2026-07-16 20:28:57.162947589 +0000 UTC m=+75501.317774636","heartbeat_counter":75501}]}
{"channel":"l2_data","timestamp":"2026-07-16T20:28:57.180058536Z","sequence_num":107,"events":[{"type":"update","product_id":"BTC-USD","updates":[{"side":"bid","event_time":"2026-07-16T20:28:57.142489Z","price_level":"64144.57","new_quantity":"0.02682296"},{"side":"bid","event_time":"2026-07-16T20:28:57.142489Z","price_level":"57730.11","new_quantity":"0"},{"side":"offer","event_time":"2026-07-16T20:28:57.142489Z","price_level":"64157.36","new_quantity":"0.14456045"}]}]}
{"channel":"l2_data","timestamp":"2026-07-16T20:28:57.225400579Z","sequence_num":108,"events":[{"type":"update","product_id":"BTC-USD","updates":[{"side":"bid","event_time":"2026-07-16T20:28:57.194771Z","price_level":"64132.03","new_quantity":"0"},{"side":"bid","event_time":"2026-07-16T20:28:57.194771Z","price_level":"56126.5","new_quantity":"0"}]}]}
{"channel":"l2_data","timestamp":"2026-07-16T20:28:57.27688503Z","sequence_num":109,"events":[{"type":"update","product_id":"BTC-USD","updates":[{"side":"offer","event_time":"2026-07-16T20:28:57.234873Z","price_level":"64168.39","new_quantity":"0"}]}]}
{"channel":"l2_data","timestamp":"2026-07-16T20:28:57.384119276Z","sequence_num":110,"events":[{"type":"update","product_id":"BTC-USD","updates":[{"side":"bid","event_time":"2026-07-16T20:28:57.330285Z","price_level":"64140.44","new_quantity":"0.31190852"},{"side":"bid","event_time":"2026-07-16T20:28:57.330285Z","price_level":"64140.43","new_quantity":"0"},{"side":"bid","event_time":"2026-07-16T20:28:57.330285Z","price_level":"63477.83","new_quantity":"0"},{"side":"bid","event_time":"2026-07-16T20:28:57.330285Z","price_level":"63263.4","new_quantity":"0"},{"side":"bid","event_time":"2026-07-16T20:28:57.330285Z","price_level":"63048.97","new_quantity":"0"},{"side":"bid","event_time":"2026-07-16T20:28:57.330285Z","price_level":"62834.54","new_quantity":"0"},{"side":"offer","event_time":"2026-07-16T20:28:57.330285Z","price_level":"64144.58","new_quantity":"0.14864555"},{"side":"offer","event_time":"2026-07-16T20:28:57.330285Z","price_level":"64145.07","new_quantity":"0"},{"side":"offer","event_time":"2026-07-16T20:28:57.330285Z","price_level":"64145.08","new_quantity":"0"},{"side":"offer","event_time":"2026-07-16T20:28:57.330285Z","price_level":"64145.1","new_quantity":"0"},{"side":"offer","event_time":"2026-07-16T20:28:57.330285Z","price_level":"64147.36","new_quantity":"0"},{"side":"offer","event_time":"2026-07-16T20:28:57.330285Z","price_level":"64149.33","new_quantity":"0.20358104"},{"side":"offer","event_time":"2026-07-16T20:28:57.330285Z","price_level":"64149.34","new_quantity":"0"},{"side":"offer","event_time":"2026-07-16T20:28:57.330285Z","price_level":"64158.45","new_quantity":"0.23700473"},{"side":"offer","event_time":"2026-07-16T20:28:57.330285Z","price_level":"64160","new_quantity":"0.01"}]}]}
{"channel":"l2_data","timestamp":"2026-07-16T20:28:57.450822146Z","sequence_num":111,"events":[{"type":"update","product_id":"BTC-USD","updates":[{"side":"bid","event_time":"2026-07-16T20:28:57.407629Z","price_level":"64132.36","new_quantity":"0"},{"side":"bid","event_time":"2026-07-16T20:28:57.407629Z","price_level":"64121","new_quantity":"1"},{"side":"bid","event_time":"2026-07-16T20:28:57.407629Z","price_level":"64120","new_quantity":"0.01"},{"side":"bid","event_time":"2026-07-16T20:28:57.407629Z","price_level":"63478.59","new_quantity":"0.00583"},{"side":"bid","event_time":"2026-07-16T20:28:57.407629Z","price_level":"63264.04","new_quantity":"0.00583"},{"side":"bid","event_time":"2026-07-16T20:28:57.407629Z","price_level":"63049.6","new_quantity":"0.00583"},{"side":"bid","event_time":"2026-07-16T20:28:57.407629Z","price_level":"62834.86","new_quantity":"0.00583"},{"side":"bid","event_time":"2026-07-16T20:28:57.407629Z","price_level":"56126.5","new_quantity":"0.01337205"},{"side":"offer","event_time":"2026-07-16T20:28:57.407629Z","price_level":"64145.07","new_quantity":"0.29750793"},{"side":"offer","event_time":"2026-07-16T20:28:57.407629Z","price_level":"64145.55","new_quantity":"0"},{"side":"offer","event_time":"2026-07-16T20:28:57.407629Z","price_level":"64145.78","new_quantity":"0.23359045"},{"side":"offer","event_time":"2026-07-16T20:28:57.407629Z","price_level":"64145.79","new_quantity":"0.1247159"},{"side":"offer","event_time":"2026-07-16T20:28:57.407629Z","price_level":"64149.33","new_quantity":"0.3458977"},{"side":"offer","event_time":"2026-07-16T20:28:57.407629Z","price_level":"64149.53","new_quantity":"0.01997"},{"side":"offer","event_time":"2026-07-16T20:28:57.407629Z","price_level":"64150.18","new_quantity":"0.00009743"},{"side":"offer","event_time":"2026-07-16T20:28:57.407629Z","price_level":"64150.19","new_quantity":"0.31190852"},{"side":"offer","event_time":"2026-07-16T20:28:57.407629Z","price_level":"64150.97","new_quantity":"0"},{"side":"offer","event_time":"2026-07-16T20:28:57.407629Z","price_level":"64151.14","new_quantity":"0.00779409"},{"side":"offer","event_time":"2026-07-16T20:28:57.407629Z","price_level":"64151.27","new_quantity":"0"},{"side":"offer","event_time":"2026-07-16T20:28:57.407629Z","price_level":"64152.31","new_quantity":"0.39275352"},{"side":"offer","event_time":"2026-07-16T20:28:57.407629Z","price_level":"64154.56","new_quantity":"0"},{"side":"offer","event_time":"2026-07-16T20:28:57.407629Z","price_level":"64156.5","new_quantity":"0.87115758"},{"side":"offer","event_time":"2026-07-16T20:28:57.407629Z","price_level":"64156.51","new_quantity":"0.65487542"},{"side":"offer","event_time":"2026-07-16T20:28:57.407629Z","price_level":"64156.52","new_quantity":"0"},{"side":"offer","event_time":"2026-07-16T20:28:57.407629Z","price_level":"64161.48","new_quantity":"0.66384962"},{"side":"offer","event_time":"2026-07-16T20:28:57.407629Z","price_level":"64168.41","new_quantity":"0.02682296"}]}]}
{"channel":"l2_data","timestamp":"2026-07-16T20:28:57.482882868Z","sequence_num":112,"events":[{"type":"update","product_id":"BTC-USD","updates":[{"side":"offer","event_time":"2026-07-16T20:28:57.442644Z","price_level":"64144.58","new_quantity":"0.14790318"},{"side":"offer","event_time":"2026-07-16T20:28:57.442644Z","price_level":"64158.45","new_quantity":"0.80370414"},{"side":"offer","event_time":"2026-07-16T20:28:57.442644Z","price_level":"64160","new_quantity":"1.01"}]}]}
{"channel":"l2_data","timestamp":"2026-07-16T20:28:57.532204195Z","sequence_num":113,"events":[{"type":"update","product_id":"BTC-USD","updates":[{"side":"bid","event_time":"2026-07-16T20:28:57.508497Z","price_level":"64140.45","new_quantity":"0.02"},{"side":"bid","event_time":"2026-07-16T20:28:57.508497Z","price_level":"64024.78","new_quantity":"0"},{"side":"bid","event_time":"2026-07-16T20:28:57.508497Z","price_level":"64018.45","new_quantity":"0.233784"},{"side":"bid","event_time":"2026-07-16T20:28:57.508497Z","price_level":"56126.5","new_quantity":"0"},{"side":"offer","event_time":"2026-07-16T20:28:57.508497Z","price_level":"64145.07","new_quantity":"0.46805459"},{"side":"offer","event_time":"2026-07-16T20:28:57.508497Z","price_level":"64145.55","new_quantity":"0.01559176"},{"side":"offer","event_time":"2026-07-16T20:28:57.508497Z","price_level":"64148.2","new_quantity":"0.31190852"},{"side":"offer","event_time":"2026-07-16T20:28:57.508497Z","price_level":"64150.92","new_quantity":"0.0012474"}]}]}
{"channel":"l2_data","timestamp":"2026-07-16T20:28:57.59209138Z","sequence_num":114,"events":[{"type":"update","product_id":"BTC-USD","updates":[{"side":"bid","event_time":"2026-07-16T20:28:57.554086Z","price_level":"64144.57","new_quantity":"0.02682292"},{"side":"bid","event_time":"2026-07-16T20:28:57.554086Z","price_level":"64141.75","new_quantity":"0.12472374"},{"side":"offer","event_time":"2026-07-16T20:28:57.554086Z","price_level":"64168.41","new_quantity":"0"}]}]}
{"channel":"l2_data","timestamp":"2026-07-16T20:28:57.628794475Z","sequence_num":115,"events":[{"type":"update","product_id":"BTC-USD","updates":[{"side":"bid","event_time":"2026-07-16T20:28:57.603679Z","price_level":"64144.57","new_quantity":"0.02682288"},{"side":"bid","event_time":"2026-07-16T20:28:57.603679Z","price_level":"64140.45","new_quantity":"0"},{"side":"bid","event_time":"2026-07-16T20:28:57.603679Z","price_level":"64132.14","new_quantity":"0.602223"}]}]}
{"channel":"l2_data","timestamp":"2026-07-16T20:28:57.683902839Z","sequence_num":116,"events":[{"type":"update","product_id":"BTC-USD","updates":[{"side":"bid","event_time":"2026-07-16T20:28:57.645875Z","price_level":"64136.68","new_quantity":"0.01559176"},{"side":"bid","event_time":"2026-07-16T20:28:57.645875Z","price_level":"64135.93","new_quantity":"0"},{"side":"bid","event_time":"2026-07-16T20:28:57.645875Z","price_level":"64132.14","new_quantity":"0"},{"side":"offer","event_time":"2026-07-16T20:28:57.645875Z","price_level":"64145.55","new_quantity":"0"},{"side":"offer","event_time":"2026-07-16T20:28:57.645875Z","price_level":"64146.3","new_quantity":"0.01559176"}]}]}
{"channel":"l2_data","timestamp":"2026-07-16T20:28:57.729806716Z","sequence_num":117,"events":[{"type":"update","product_id":"BTC-USD","updates":[{"side":"bid","event_time":"2026-07-16T20:28:57.702146Z","price_level":"56126.5","new_quantity":"0.01337205"},{"side":"offer","event_time":"2026-07-16T20:28:57.702146Z","price_level":"64168.41","new_quantity":"0.02682292"}]}]}
{"channel":"l2_data","timestamp":"2026-07-16T20:28:57.830702481Z","sequence_num":118,"events":[{"type":"update","product_id":"BTC-USD","updates":[{"side":"bid","event_time":"2026-07-16T20:28:57.803919Z","price_level":"64138.16","new_quantity":"0"},{"side":"bid","event_time":"2026-07-16T20:28:57.803919Z","price_level":"64137.6","new_quantity":"0.01046078"},{"side":"bid","event_time":"2026-07-16T20:28:57.803919Z","price_level":"56126.5","new_quantity":"0"},{"side":"offer","event_time":"2026-07-16T20:28:57.803919Z","price_level":"64152.81","new_quantity":"0"},{"side":"offer","event_time":"2026-07-16T20:28:57.803919Z","price_level":"64187.26","new_quantity":"0.48135182"},{"side":"offer","event_time":"2026-07-16T20:28:57.803919Z","price_level":"64187.27","new_quantity":"0"},{"side":"offer","event_time":"2026-07-16T20:28:57.803919Z","price_level":"64187.28","new_quantity":"0"},{"side":"offer","event_time":"2026-07-16T20:28:57.803919Z","price_level":"64206.83","new_quantity":"2.15529058"},{"side":"offer","event_time":"2026-07-16T20:28:57.803919Z","price_level":"64206.84","new_quantity":"0"},{"side":"offer","event_time":"2026-07-16T20:28:57.803919Z","price_level":"64206.85","new_quantity":"0"}]}]}
{"channel":"l2_data","timestamp":"2026-07-16T20:28:57.881141661Z","sequence_num":119,"events":[{"type":"update","product_id":"BTC-USD","updates":[{"side":"bid","event_time":"2026-07-16T20:28:57.854398Z","price_level":"64139.76","new_quantity":"0.00779548"},{"side":"bid","event_time":"2026-07-16T20:28:57.854398Z","price_level":"64138.16","new_quantity":"0.00779567"},{"side":"offer","event_time":"2026-07-16T20:28:57.854398Z","price_level":"64151.12","new_quantity":"0.00896321"},{"side":"offer","event_time":"2026-07-16T20:28:57.854398Z","price_level":"64151.2","new_quantity":"0"},{"side":"offer","event_time":"2026-07-16T20:28:57.854398Z","price_level":"64152.73","new_quantity":"0.00896299"}]}]}
{"channel":"l2_data","timestamp":"2026-07-16T20:28:57.930178295Z","sequence_num":120,"events":[{"type":"update","product_id":"BTC-USD","updates":[{"side":"offer","event_time":"2026-07-16T20:28:57.900016Z","price_level":"64151.57","new_quantity":"0"},{"side":"offer","event_time":"2026-07-16T20:28:57.900016Z","price_level":"64152.77","new_quantity":"0.0077939"},{"side":"offer","event_time":"2026-07-16T20:28:57.900016Z","price_level":"64152.85","new_quantity":"0"},{"side":"offer","event_time":"2026-07-16T20:28:57.900016Z","price_level":"64168.41","new_quantity":"0"}]}]}
{"channel":"l2_data","timestamp":"2026-07-16T20:28:57.979455665Z","sequence_num":121,"events":[{"type":"update","product_id":"BTC-USD","updates":[{"side":"offer","event_time":"2026-07-16T20:28:57.908766Z","price_level":"64151.49","new_quantity":"0.00009743"}]}]}
{"channel":"l2_data","timestamp":"2026-07-16T20:28:58.024977188Z","sequence_num":122,"events":[{"type":"update","product_id":"BTC-USD","updates":[{"side":"bid","event_time":"2026-07-16T20:28:57.991875Z","price_level":"56126.5","new_quantity":"0.01337205"}]}]}
{"channel":"l2_data","timestamp":"2026-07-16T20:28:58.081685332Z","sequence_num":123,"events":[{"type":"update","product_id":"BTC-USD","updates":[{"side":"offer","event_time":"2026-07-16T20:28:58.024628Z","price_level":"64150.18","new_quantity":"0"},{"side":"offer","event_time":"2026-07-16T20:28:58.024628Z","price_level":"64151.14","new_quantity":"0"},{"side":"offer","event_time":"2026-07-16T20:28:58.024628Z","price_level":"64168.41","new_quantity":"0.02682288"}]}]}
{"channel":"l2_data","timestamp":"2026-07-16T20:28:58.12592714Z","sequence_num":124,"events":[{"type":"update","product_id":"BTC-USD","updates":[{"side":"bid","event_time":"2026-07-16T20:28:58.100516Z","price_level":"64132.17","new_quantity":"0.662707"},{"side":"bid","event_time":"2026-07-16T20:28:58.100516Z","price_level":"56126.5","new_quantity":"0"}]}]}
{"channel":"heartbeats","timestamp":"2026-07-16T20:28:58.167600561Z","sequence_num":125,"events":[{"current_time":"2026-07-16 20:28:58.162884286 +0000 UTC m=+75502.317711339","heartbeat_counter":75502}]}
{"channel":"l2_data","timestamp":"2026-07-16T20:28:58.18069893Z","sequence_num":126,"events":[{"type":"update","product_id":"BTC-USD","updates":[{"side":"bid","event_time":"2026-07-16T20:28:58.157114Z","price_level":"64132.17","new_quantity":"0"},{"side":"bid","event_time":"2026-07-16T20:28:58.157114Z","price_level":"63264.14","new_quantity":"0.00583"},{"side":"bid","event_time":"2026-07-16T20:28:58.157114Z","price_level":"62834.86","new_quantity":"0"},{"side":"offer","event_time":"2026-07-16T20:28:58.157114Z","price_level":"64144.58","new_quantity":"0.05248846"},{"side":"offer","event_time":"2026-07-16T20:28:58.157114Z","price_level":"64145.05","new_quantity":"0.02928097"},{"side":"offer","event_time":"2026-07-16T20:28:58.157114Z","price_level":"64145.06","new_quantity":"0.01640495"},{"side":"offer","event_time":"2026-07-16T20:28:58.157114Z","price_level":"64145.79","new_quantity":"0"},{"side":"offer","event_time":"2026-07-16T20:28:58.157114Z","price_level":"64145.87","new_quantity":"0"}]}]}
{"channel":"l2_data","timestamp":"2026-07-16T20:28:58.230274475Z","sequence_num":127,"events":[{"type":"update","product_id":"BTC-USD","updates":[{"side":"bid","event_time":"2026-07-16T20:28:58.185902Z","price_level":"64144.57","new_quantity":"0.01355161"},{"side":"bid","event_time":"2026-07-16T20:28:58.185902Z","price_level":"64134.07","new_quantity":"0.07387"},{"side":"bid","event_time":"2026-07-16T20:28:58.185902Z","price_level":"63693.72","new_quantity":"0.00583"},{"side":"bid","event_time":"2026-07-16T20:28:58.185902Z","price_level":"63693.36","new_quantity":"0"},{"side":"bid","event_time":"2026-07-16T20:28:58.185902Z","price_level":"63479.01","new_quantity":"0.00583"},{"side":"bid","event_time":"2026-07-16T20:28:58.185902Z","price_level":"63478.59","new_quantity":"0"},{"side":"bid","event_time":"2026-07-16T20:28:58.185902Z","price_level":"63264.04","new_quantity":"0"},{"side":"bid","event_time":"2026-07-16T20:28:58.185902Z","price_level":"63049.6","new_quantity":"0"},{"side":"bid","event_time":"2026-07-16T20:28:58.185902Z","price_level":"63049.37","new_quantity":"0.00583"},{"side":"bid","event_time":"2026-07-16T20:28:58.185902Z","price_level":"62834.89","new_quantity":"0.00583"},{"side":"bid","event_time":"2026-07-16T20:28:58.185902Z","price_level":"62834.42","new_quantity":"0"},{"side":"offer","event_time":"2026-07-16T20:28:58.185902Z","price_level":"64144.58","new_quantity":"0.08703204"},{"side":"offer","event_time":"2026-07-16T20:28:58.185902Z","price_level":"64145.04","new_quantity":"0.02"},{"side":"offer","event_time":"2026-07-16T20:28:58.185902Z","price_level":"64145.05","new_quantity":"0.03473737"},{"side":"offer","event_time":"2026-07-16T20:28:58.185902Z","price_level":"64146.19","new_quantity":"0"},{"side":"offer","event_time":"2026-07-16T20:28:58.185902Z","price_level":"64146.66","new_quantity":"0.0054564"},{"side":"offer","event_time":"2026-07-16T20:28:58.185902Z","price_level":"64146.67","new_quantity":"0.1247142"},{"side":"offer","event_time":"2026-07-16T20:28:58.185902Z","price_level":"64168.41","new_quantity":"0"}]}]}
{"channel":"l2_data","timestamp":"2026-07-16T20:28:58.279236251Z","sequence_num":128,"events":[{"type":"update","product_id":"BTC-USD","updates":[{"side":"bid","event_time":"2026-07-16T20:28:58.230083Z","price_level":"64144.57","new_quantity":"0.01355155"},{"side":"bid","event_time":"2026-07-16T20:28:58.230083Z","price_level":"64130.87","new_quantity":"0"},{"side":"offer","event_time":"2026-07-16T20:28:58.230083Z","price_level":"64144.58","new_quantity":"0.09248846"},{"side":"offer","event_time":"2026-07-16T20:28:58.230083Z","price_level":"64145.05","new_quantity":"0"},{"side":"offer","event_time":"2026-07-16T20:28:58.230083Z","price_level":"64146.19","new_quantity":"0.00545642"},{"side":"offer","event_time":"2026-07-16T20:28:58.230083Z","price_level":"64146.66","new_quantity":"0"}]}]}
{"channel":"l2_data","timestamp":"2026-07-16T20:28:58.338552841Z","sequence_num":129,"events":[{"type":"update","product_id":"BTC-USD","updates":[{"side":"bid","event_time":"2026-07-16T20:28:58.295068Z","price_level":"64144.57","new_quantity":"0.03098929"},{"side":"bid","event_time":"2026-07-16T20:28:58.295068Z","price_level":"64086.82","new_quantity":"1.34194824"},{"side":"bid","event_time":"2026-07-16T20:28:58.295068Z","price_level":"64082.58","new_quantity":"0"},{"side":"bid","event_time":"2026-07-16T20:28:58.295068Z","price_level":"62834.94","new_quantity":"0.00583"},{"side":"bid","event_time":"2026-07-16T20:28:58.295068Z","price_level":"62834.89","new_quantity":"0"},{"side":"bid","event_time":"2026-07-16T20:28:58.295068Z","price_level":"56126.5","new_quantity":"0.01337205"},{"side":"offer","event_time":"2026-07-16T20:28:58.295068Z","price_level":"64144.58","new_quantity":"0.09190205"}]}]}
{"channel":"l2_data","timestamp":"2026-07-16T20:28:58.390083702Z","sequence_num":130,"events":[{"type":"update","product_id":"BTC-USD","updates":[{"side":"bid","event_time":"2026-07-16T20:28:58.349723Z","price_level":"64119.32","new_quantity":"0"},{"side":"bid","event_time":"2026-07-16T20:28:58.349723Z","price_level":"64115.6","new_quantity":"0.59861092"},{"side":"bid","event_time":"2026-07-16T20:28:58.349723Z","price_level":"64115.59","new_quantity":"0.65488212"},{"side":"bid","event_time":"2026-07-16T20:28:58.349723Z","price_level":"64115.58","new_quantity":"0"},{"side":"bid","event_time":"2026-07-16T20:28:58.349723Z","price_level":"64115.57","new_quantity":"0"},{"side":"bid","event_time":"2026-07-16T20:28:58.349723Z","price_level":"63049.42","new_quantity":"0.00583"},{"side":"bid","event_time":"2026-07-16T20:28:58.349723Z","price_level":"62834.94","new_quantity":"0"},{"side":"offer","event_time":"2026-07-16T20:28:58.349723Z","price_level":"64145.04","new_quantity":"0"},{"side":"offer","event_time":"2026-07-16T20:28:58.349723Z","price_level":"64168.3","new_quantity":"0.01355161"}]}]}
{"channel":"l2_data","timestamp":"2026-07-16T20:28:58.448324289Z","sequence_num":131,"events":[{"type":"update","product_id":"BTC-USD","updates":[{"side":"bid","event_time":"2026-07-16T20:28:58.399789Z","price_level":"64119.66","new_quantity":"0"},{"side":"bid","event_time":"2026-07-16T20:28:58.399789Z","price_level":"63049.37","new_quantity":"0"},{"side":"bid","event_time":"2026-07-16T20:28:58.399789Z","price_level":"56126.5","new_quantity":"0"},{"side":"offer","event_time":"2026-07-16T20:28:58.399789Z","price_level":"64151.55","new_quantity":"0.0486477"}]}]}
{"channel":"l2_data","timestamp":"2026-07-16T20:28:58.497574863Z","sequence_num":132,"events":[{"type":"update","product_id":"BTC-USD","updates":[{"side":"bid","event_time":"2026-07-16T20:28:58.456994Z","price_level":"64137.6","new_quantity":"0.00033322"},{"side":"offer","event_time":"2026-07-16T20:28:58.456994Z","price_level":"64150.1","new_quantity":"0.00009743"},{"side":"offer","event_time":"2026-07-16T20:28:58.456994Z","price_level":"64151.06","new_quantity":"0.0077941"}]}]}
{"channel":"l2_data","timestamp":"2026-07-16T20:28:58.532770086Z","sequence_num":133,"events":[{"type":"update","product_id":"BTC-USD","updates":[{"side":"offer","event_time":"2026-07-16T20:28:58.491641Z","price_level":"64145.87","new_quantity":"0.00779473"},{"side":"offer","event_time":"2026-07-16T20:28:58.491641Z","price_level":"64168.3","new_quantity":"0"}]}]}
{"channel":"l2_data","timestamp":"2026-07-16T20:28:58.592971045Z","sequence_num":134,"events":[{"type":"update","product_id":"BTC-USD","updates":[{"side":"bid","event_time":"2026-07-16T20:28:58.529519Z","price_level":"64144.57","new_quantity":"0.03098924"},{"side":"offer","event_time":"2026-07-16T20:28:58.529519Z","price_level":"64145.75","new_quantity":"0.12471598"},{"side":"offer","event_time":"2026-07-16T20:28:58.529519Z","price_level":"64146.67","new_quantity":"0"}]}]}
{"channel":"l2_data","timestamp":"2026-07-16T20:28:58.629178344Z","sequence_num":135,"events":[{"type":"update","product_id":"BTC-USD","updates":[{"side":"bid","event_time":"2026-07-16T20:28:58.600727Z","price_level":"64132.13","new_quantity":"0.597529"},{"side":"bid","event_time":"2026-07-16T20:28:58.600727Z","price_level":"56126.5","new_quantity":"0.01337205"}]}]}
{"channel":"l2_data","timestamp":"2026-07-16T20:28:58.691286654Z","sequence_num":136,"events":[{"type":"update","product_id":"BTC-USD","updates":[{"side":"bid","event_time":"2026-07-16T20:28:58.644416Z","price_level":"64144.57","new_quantity":"0.03098919"},{"side":"offer","event_time":"2026-07-16T20:28:58.644416Z","price_level":"64168.44","new_quantity":"0.03098929"}]}]}
{"channel":"l2_data","timestamp":"2026-07-16T20:28:58.741958305Z","sequence_num":137,"events":[{"type":"update","product_id":"BTC-USD","updates":[{"side":"bid","event_time":"2026-07-16T20:28:58.686579Z","price_level":"64144.57","new_quantity":"0.0434612"},{"side":"bid","event_time":"2026-07-16T20:28:58.686579Z","price_level":"64132.13","new_quantity":"0"},{"side":"bid","event_time":"2026-07-16T20:28:58.686579Z","price_level":"62834.87","new_quantity":"0.00583"},{"side":"bid","event_time":"2026-07-16T20:28:58.686579Z","price_level":"56126.5","new_quantity":"0.00980617"},{"side":"offer","event_time":"2026-07-16T20:28:58.686579Z","price_level":"64144.58","new_quantity":"0.08997326"}]}]}
{"channel":"l2_data","timestamp":"2026-07-16T20:28:58.791457032Z","sequence_num":138,"events":[{"type":"update","product_id":"BTC-USD","updates":[{"side":"bid","event_time":"2026-07-16T20:28:58.742179Z","price_level":"56126.5","new_quantity":"0"},{"side":"offer","event_time":"2026-07-16T20:28:58.742179Z","price_level":"64157.36","new_quantity":"0"},{"side":"offer","event_time":"2026-07-16T20:28:58.742179Z","price_level":"64158.45","new_quantity":"0.23700473"},{"side":"offer","event_time":"2026-07-16T20:28:58.742179Z","price_level":"64160","new_quantity":"0.01"},{"side":"offer","event_time":"2026-07-16T20:28:58.742179Z","price_level":"64162","new_quantity":"1"}]}]}
{"channel":"l2_data","timestamp":"2026-07-16T20:28:58.836390833Z","sequence_num":139,"events":[{"type":"update","product_id":"BTC-USD","updates":[{"side":"offer","event_time":"2026-07-16T20:28:58.808776Z","price_level":"64161.48","new_quantity":"1.17597776"},{"side":"offer","event_time":"2026-07-16T20:28:58.808776Z","price_level":"64168.44","new_quantity":"0"},{"side":"offer","event_time":"2026-07-16T20:28:58.808776Z","price_level":"64187.24","new_quantity":"0.48135197"},{"side":"offer","event_time":"2026-07-16T20:28:58.808776Z","price_level":"64187.25","new_quantity":"0"},{"side":"offer","event_time":"2026-07-16T20:28:58.808776Z","price_level":"64187.26","new_quantity":"0"},{"side":"offer","event_time":"2026-07-16T20:28:58.808776Z","price_level":"64206.81","new_quantity":"2.00186906"},{"side":"offer","event_time":"2026-07-16T20:28:58.808776Z","price_level":"64206.82","new_quantity":"0"},{"side":"offer","event_time":"2026-07-16T20:28:58.808776Z","price_level":"64206.83","new_quantity":"0"}]}]}
{"channel":"l2_data","timestamp":"2026-07-16T20:28:58.883501477Z","sequence_num":140,"events":[{"type":"update","product_id":"BTC-USD","updates":[{"side":"offer","event_time":"2026-07-16T20:28:58.854638Z","price_level":"64157.36","new_quantity":"0.09571393"}]}]}
{"channel":"l2_data","timestamp":"2026-07-16T20:28:58.930710781Z","sequence_num":141,"events":[{"type":"update","product_id":"BTC-USD","updates":[{"side":"bid","event_time":"2026-07-16T20:28:58.909122Z","price_level":"64139.76","new_quantity":"0"},{"side":"bid","event_time":"2026-07-16T20:28:58.909122Z","price_level":"64138.16","new_quantity":"0.00779567"},{"side":"bid","event_time":"2026-07-16T20:28:58.909122Z","price_level":"56126.5","new_quantity":"0.01337205"},{"side":"offer","event_time":"2026-07-16T20:28:58.909122Z","price_level":"64151.04","new_quantity":"0.00896322"},{"side":"offer","event_time":"2026-07-16T20:28:58.909122Z","price_level":"64151.12","new_quantity":"0"},{"side":"offer","event_time":"2026-07-16T20:28:58.909122Z","price_level":"64152.65","new_quantity":"0.008963"},{"side":"offer","event_time":"2026-07-16T20:28:58.909122Z","price_level":"64152.73","new_quantity":"0"}]}]}
{"channel":"l2_data","timestamp":"2026-07-16T20:28:58.981398622Z","sequence_num":142,"events":[{"type":"update","product_id":"BTC-USD","updates":[{"side":"bid","event_time":"2026-07-16T20:28:58.958875Z","price_level":"64141.75","new_quantity":"0"},{"side":"bid","event_time":"2026-07-16T20:28:58.958875Z","price_level":"64141.12","new_quantity":"0.12472497"},{"side":"bid","event_time":"2026-07-16T20:28:58.958875Z","price_level":"64139.76","new_quantity":"0.00779548"},{"side":"offer","event_time":"2026-07-16T20:28:58.958875Z","price_level":"64151.49","new_quantity":"0"},{"side":"offer","event_time":"2026-07-16T20:28:58.958875Z","price_level":"64152.77","new_quantity":"0"},{"side":"offer","event_time":"2026-07-16T20:28:58.958875Z","price_level":"64168.55","new_quantity":"0.0434612"}]}]}
{"channel":"l2_data","timestamp":"2026-07-16T20:28:59.031921835Z","sequence_num":143,"events":[{"type":"update","product_id":"BTC-USD","updates":[{"side":"bid","event_time":"2026-07-16T20:28:58.993973Z","price_level":"56126.5","new_quantity":"0"},{"side":"offer","event_time":"2026-07-16T20:28:58.993973Z","price_level":"64151.4","new_quantity":"0.00009743"},{"side":"offer","event_time":"2026-07-16T20:28:58.993973Z","price_level":"64152.69","new_quantity":"0.00779391"}]}]}
{"channel":"l2_data","timestamp":"2026-07-16T20:28:59.08243783Z","sequence_num":144,"events":[{"type":"update","product_id":"BTC-USD","updates":[{"side":"offer","event_time":"2026-07-16T20:28:59.020273Z","price_level":"64150.1","new_quantity":"0"},{"side":"offer","event_time":"2026-07-16T20:28:59.020273Z","price_level":"64151.06","new_quantity":"0"}]}]}
{"channel":"l2_data","timestamp":"2026-07-16T20:28:59.124774292Z","sequence_num":145,"events":[{"type":"update","product_id":"BTC-USD","updates":[{"side":"bid","event_time":"2026-07-16T20:28:59.100631Z","price_level":"64132.16","new_quantity":"0.64414"}]}]}
{"channel":"heartbeats","timestamp":"2026-07-16T20:28:59.168652099Z","sequence_num":146,"events":[{"current_time":"2026-07-16 20:28:59.162903805 +0000 UTC m=+75503.317730841","heartbeat_counter":75503}]}
{"channel":"l2_data","timestamp":"2026-07-16T20:28:59.176801915Z","sequence_num":147,"events":[{"type":"update","product_id":"BTC-USD","updates":[{"side":"offer","event_time":"2026-07-16T20:28:59.113491Z","price_level":"64168.55","new_quantity":"0"}]}]}
{"channel":"l2_data","timestamp":"2026-07-16T20:28:59.229618682Z","sequence_num":148,"events":[{"type":"update","product_id":"BTC-USD","updates":[{"side":"bid","event_time":"2026-07-16T20:28:59.193122Z","price_level":"64132.16","new_quantity":"0"},{"side":"bid","event_time":"2026-07-16T20:28:59.193122Z","price_level":"56126.5","new_quantity":"0.01337205"},{"side":"offer","event_time":"2026-07-16T20:28:59.193122Z","price_level":"64161.48","new_quantity":"0.66384962"},{"side":"offer","event_time":"2026-07-16T20:28:59.193122Z","price_level":"64162","new_quantity":"0"}]}]}
{"channel":"l2_data","timestamp":"2026-07-16T20:28:59.277101039Z","sequence_num":149,"events":[{"type":"update","product_id":"BTC-USD","updates":[{"side":"offer","event_time":"2026-07-16T20:28:59.226564Z","price_level":"64158.45","new_quantity":"0.80370414"},{"side":"offer","event_time":"2026-07-16T20:28:59.226564Z","price_level":"64160","new_quantity":"1.01"}]}]}
{"channel":"l2_data","timestamp":"2026-07-16T20:28:59.331049984Z","sequence_num":150,"events":[{"type":"update","product_id":"BTC-USD","updates":[{"side":"bid","event_time":"2026-07-16T20:28:59.293233Z","price_level":"64144.57","new_quantity":"0.04346117"},{"side":"bid","event_time":"2026-07-16T20:28:59.293233Z","price_level":"56126.5","new_quantity":"0"},{"side":"offer","event_time":"2026-07-16T20:28:59.293233Z","price_level":"64168.55","new_quantity":"0.0434612"}]}]}
{"channel":"l2_data","timestamp":"2026-07-16T20:28:59.380597554Z","sequence_num":151,"events":[{"type":"update","product_id":"BTC-USD","updates":[{"side":"bid","event_time":"2026-07-16T20:28:59.354241Z","price_level":"64141.12","new_quantity":"0"},{"side":"bid","event_time":"2026-07-16T20:28:59.354241Z","price_level":"64140.54","new_quantity":"0.12472609"},{"side":"bid","event_time":"2026-07-16T20:28:59.354241Z","price_level":"64121","new_quantity":"0"},{"side":"bid","event_time":"2026-07-16T20:28:59.354241Z","price_level":"64119.67","new_quantity":"0.648416"},{"side":"offer","event_time":"2026-07-16T20:28:59.354241Z","price_level":"64145.18","new_quantity":"0.1247171"},{"side":"offer","event_time":"2026-07-16T20:28:59.354241Z","price_level":"64145.75","new_quantity":"0"}]}]}
{"channel":"l2_data","timestamp":"2026-07-16T20:28:59.425392771Z","sequence_num":152,"events":[{"type":"update","product_id":"BTC-USD","updates":[{"side":"bid","event_time":"2026-07-16T20:28:59.362968Z","price_level":"64120","new_quantity":"1.01"},{"side":"bid","event_time":"2026-07-16T20:28:59.362968Z","price_level":"64119.67","new_quantity":"0"}]}]}
{"channel":"l2_data","timestamp":"2026-07-16T20:28:59.534716537Z","sequence_num":153,"events":[{"type":"update","product_id":"BTC-USD","updates":[{"side":"bid","event_time":"2026-07-16T20:28:59.503319Z","price_level":"64120","new_quantity":"0.01"},{"side":"bid","event_time":"2026-07-16T20:28:59.503319Z","price_level":"56126.5","new_quantity":"0.01337205"},{"side":"offer","event_time":"2026-07-16T20:28:59.503319Z","price_level":"64150.03","new_quantity":"0.00009743"},{"side":"offer","event_time":"2026-07-16T20:28:59.503319Z","price_level":"64150.99","new_quantity":"0.00779411"}]}]}
{"channel":"l2_data","timestamp":"2026-07-16T20:28:59.575567517Z","sequence_num":154,"events":[{"type":"update","product_id":"BTC-USD","updates":[{"side":"bid","event_time":"2026-07-16T20:28:59.51084Z","price_level":"64121","new_quantity":"1"}]}]}
{"channel":"l2_data","timestamp":"2026-07-16T20:28:59.630156746Z","sequence_num":155,"events":[{"type":"update","product_id":"BTC-USD","updates":[{"side":"bid","event_time":"2026-07-16T20:28:59.600845Z","price_level":"64137.6","new_quantity":"0.00806183"},{"side":"bid","event_time":"2026-07-16T20:28:59.600845Z","price_level":"64136.68","new_quantity":"0"},{"side":"bid","event_time":"2026-07-16T20:28:59.600845Z","price_level":"64135.91","new_quantity":"0.01559176"},{"side":"bid","event_time":"2026-07-16T20:28:59.600845Z","price_level":"64132.11","new_quantity":"0.596746"},{"side":"bid","event_time":"2026-07-16T20:28:59.600845Z","price_level":"56126.5","new_quantity":"0"},{"side":"offer","event_time":"2026-07-16T20:28:59.600845Z","price_level":"64145.53","new_quantity":"0.01559176"},{"side":"offer","event_time":"2026-07-16T20:28:59.600845Z","price_level":"64146.3","new_quantity":"0"}]}]}
{"channel":"l2_data","timestamp":"2026-07-16T20:28:59.674589491Z","sequence_num":156,"events":[{"type":"update","product_id":"BTC-USD","updates":[{"side":"bid","event_time":"2026-07-16T20:28:59.642964Z","price_level":"64132.11","new_quantity":"0"}]}]}
{"channel":"l2_data","timestamp":"2026-07-16T20:28:59.724988134Z","sequence_num":157,"events":[{"type":"update","product_id":"BTC-USD","updates":[{"side":"bid","event_time":"2026-07-16T20:28:59.669964Z","price_level":"64144.57","new_quantity":"0.04346108"}]}]}
{"channel":"l2_data","timestamp":"2026-07-16T20:28:59.776165596Z","sequence_num":158,"events":[{"type":"update","product_id":"BTC-USD","updates":[{"side":"offer","event_time":"2026-07-16T20:28:59.748267Z","price_level":"64144.58","new_quantity":"0.11925423"}]}]}
{"channel":"l2_data","timestamp":"2026-07-16T20:28:59.824448923Z","sequence_num":159,"events":[{"type":"update","product_id":"BTC-USD","updates":[{"side":"bid","event_time":"2026-07-16T20:28:59.796877Z","price_level":"64121","new_quantity":"0"},{"side":"bid","event_time":"2026-07-16T20:28:59.796877Z","price_level":"56126.5","new_quantity":"0.01337205"}]}]}
{"channel":"l2_data","timestamp":"2026-07-16T20:28:59.880527836Z","sequence_num":160,"events":[{"type":"update","product_id":"BTC-USD","updates":[{"side":"bid","event_time":"2026-07-16T20:28:59.834993Z","price_level":"64120","new_quantity":"1.01"},{"side":"offer","event_time":"2026-07-16T20:28:59.834993Z","price_level":"64187.22","new_quantity":"0.48135212"},{"side":"offer","event_time":"2026-07-16T20:28:59.834993Z","price_level":"64187.23","new_quantity":"0"},{"side":"offer","event_time":"2026-07-16T20:28:59.834993Z","price_level":"64187.24","new_quantity":"0"},{"side":"offer","event_time":"2026-07-16T20:28:59.834993Z","price_level":"64206.79","new_quantity":"2.00186968"},{"side":"offer","event_time":"2026-07-16T20:28:59.834993Z","price_level":"64206.8","new_quantity":"0"},{"side":"offer","event_time":"2026-07-16T20:28:59.834993Z","price_level":"64206.81","new_quantity":"0"}]}]}
{"channel":"l2_data","timestamp":"2026-07-16T20:28:59.925962957Z","sequence_num":161,"events":[{"type":"update","product_id":"BTC-USD","updates":[{"side":"bid","event_time":"2026-07-16T20:28:59.892284Z","price_level":"64119.67","new_quantity":"0"},{"side":"bid","event_time":"2026-07-16T20:28:59.892284Z","price_level":"56126.5","new_quantity":"0"}]}]}
{"channel":"l2_data","timestamp":"2026-07-16T20:28:59.98595139Z","sequence_num":162,"events":[{"type":"update","product_id":"BTC-USD","updates":[{"side":"bid","event_time":"2026-07-16T20:28:59.966022Z","price_level":"64139.76","new_quantity":"0"},{"side":"bid","event_time":"2026-07-16T20:28:59.966022Z","price_level":"64138.16","new_quantity":"0.00779567"},{"side":"offer","event_time":"2026-07-16T20:28:59.966022Z","price_level":"64151.04","new_quantity":"0"},{"side":"offer","event_time":"2026-07-16T20:28:59.966022Z","price_level":"64152.57","new_quantity":"0.00896301"},{"side":"offer","event_time":"2026-07-16T20:28:59.966022Z","price_level":"64152.65","new_quantity":"0"}]}]}
{"channel":"l2_data","timestamp":"2026-07-16T20:29:00.031660541Z","sequence_num":163,"events":[{"type":"update","product_id":"BTC-USD","updates":[{"side":"bid","event_time":"2026-07-16T20:28:59.982927Z","price_level":"64139.76","new_quantity":"0.00779548"},{"side":"offer","event_time":"2026-07-16T20:28:59.982927Z","price_level":"64150.97","new_quantity":"0.00896323"}]}]}
{"channel":"l2_data","timestamp":"2026-07-16T20:29:00.083058701Z","sequence_num":164,"events":[{"type":"update","product_id":"BTC-USD","updates":[{"side":"bid","event_time":"2026-07-16T20:29:00.060585Z","price_level":"64144.57","new_quantity":"0.03346108"},{"side":"bid","event_time":"2026-07-16T20:29:00.060585Z","price_level":"64140.44","new_quantity":"0"},{"side":"bid","event_time":"2026-07-16T20:29:00.060585Z","price_level":"64134.07","new_quantity":"0"},{"side":"offer","event_time":"2026-07-16T20:29:00.060585Z","price_level":"64150.03","new_quantity":"0"},{"side":"offer","event_time":"2026-07-16T20:29:00.060585Z","price_level":"64150.99","new_quantity":"0"},{"side":"offer","event_time":"2026-07-16T20:29:00.060585Z","price_level":"64151.33","new_quantity":"0.00009743"},{"side":"offer","event_time":"2026-07-16T20:29:00.060585Z","price_level":"64151.4","new_quantity":"0"},{"side":"offer","event_time":"2026-07-16T20:29:00.060585Z","price_level":"64152.61","new_quantity":"0.00779392"},{"side":"offer","event_time":"2026-07-16T20:29:00.060585Z","price_level":"64152.69","new_quantity":"0"}]}]}
{"channel":"l2_data","timestamp":"2026-07-16T20:29:00.125024722Z","sequence_num":165,"events":[{"type":"update","product_id":"BTC-USD","updates":[{"side":"bid","event_time":"2026-07-16T20:29:00.101068Z","price_level":"64132.01","new_quantity":"0.683555"},{"side":"bid","event_time":"2026-07-16T20:29:00.101068Z","price_level":"64130.87","new_quantity":"0.0739"},{"side":"bid","event_time":"2026-07-16T20:29:00.101068Z","price_level":"56126.5","new_quantity":"0.01337205"}]}]}
{"channel":"heartbeats","timestamp":"2026-07-16T20:29:00.169002919Z","sequence_num":166,"events":[{"current_time":"2026-07-16 20:29:00.162948321 +0000 UTC m=+75504.317775359","heartbeat_counter":75504}]}
{"channel":"l2_data","timestamp":"2026-07-16T20:29:00.174582149Z","sequence_num":167,"events":[{"type":"update","product_id":"BTC-USD","updates":[{"side":"bid","event_time":"2026-07-16T20:29:00.154067Z","price_level":"51315.66","new_quantity":"0.0002"}]}]}
{"channel":"l2_data","timestamp":"2026-07-16T20:29:00.229469148Z","sequence_num":168,"events":[{"type":"update","product_id":"BTC-USD","updates":[{"side":"bid","event_time":"2026-07-16T20:29:00.19976Z","price_level":"64095.91","new_quantity":"0"},{"side":"bid","event_time":"2026-07-16T20:29:00.19976Z","price_level":"56126.5","new_quantity":"0"},{"side":"offer","event_time":"2026-07-16T20:29:00.19976Z","price_level":"64165.48","new_quantity":"0.22444635"},{"side":"offer","event_time":"2026-07-16T20:29:00.19976Z","price_level":"64165.58","new_quantity":"0"}]}]}
{"channel":"l2_data","timestamp":"2026-07-16T20:29:00.278748118Z","sequence_num":169,"events":[{"type":"update","product_id":"BTC-USD","updates":[{"side":"bid","event_time":"2026-07-16T20:29:00.24827Z","price_level":"64144.57","new_quantity":"0.02098907"},{"side":"bid","event_time":"2026-07-16T20:29:00.24827Z","price_level":"64140.54","new_quantity":"0"},{"side":"bid","event_time":"2026-07-16T20:29:00.24827Z","price_level":"64139.76","new_quantity":"0.13252309"},{"side":"bid","event_time":"2026-07-16T20:29:00.24827Z","price_level":"64132.01","new_quantity":"0"},{"side":"bid","event_time":"2026-07-16T20:29:00.24827Z","price_level":"64115.14","new_quantity":"0"},{"side":"offer","event_time":"2026-07-16T20:29:00.24827Z","price_level":"64144.58","new_quantity":"0.24397248"},{"side":"offer","event_time":"2026-07-16T20:29:00.24827Z","price_level":"64145.18","new_quantity":"0"},{"side":"offer","event_time":"2026-07-16T20:29:00.24827Z","price_level":"64184.82","new_quantity":"0"}]}]}
{"channel":"l2_data","timestamp":"2026-07-16T20:29:00.329129752Z","sequence_num":170,"events":[{"type":"update","product_id":"BTC-USD","updates":[{"side":"offer","event_time":"2026-07-16T20:29:00.30606Z","price_level":"64144.58","new_quantity":"0.29585899"}]}]}
{"channel":"l2_data","timestamp":"2026-07-16T20:29:00.376049434Z","sequence_num":171,"events":[{"type":"update","product_id":"BTC-USD","updates":[{"side":"bid","event_time":"2026-07-16T20:29:00.34785Z","price_level":"64144.57","new_quantity":"0.020989"},{"side":"bid","event_time":"2026-07-16T20:29:00.34785Z","price_level":"64131.93","new_quantity":"0.63755"},{"side":"bid","event_time":"2026-07-16T20:29:00.34785Z","price_level":"64120","new_quantity":"0.01"}]}]}
{"channel":"l2_data","timestamp":"2026-07-16T20:29:00.432095355Z","sequence_num":172,"events":[{"type":"update","product_id":"BTC-USD","updates":[{"side":"bid","event_time":"2026-07-16T20:29:00.405947Z","price_level":"64144.57","new_quantity":"0.02098893"},{"side":"bid","event_time":"2026-07-16T20:29:00.405947Z","price_level":"64131.93","new_quantity":"0"},{"side":"bid","event_time":"2026-07-16T20:29:00.405947Z","price_level":"64117.01","new_quantity":"0.63211207"},{"side":"bid","event_time":"2026-07-16T20:29:00.405947Z","price_level":"64117","new_quantity":"1"},{"side":"bid","event_time":"2026-07-16T20:29:00.405947Z","price_level":"64115.6","new_quantity":"0"},{"side":"bid","event_time":"2026-07-16T20:29:00.405947Z","price_level":"56126.5","new_quantity":"0.01337205"},{"side":"offer","event_time":"2026-07-16T20:29:00.405947Z","price_level":"64184.81","new_quantity":"0"},{"side":"offer","event_time":"2026-07-16T20:29:00.405947Z","price_level":"64184.99","new_quantity":"0.00077946"}]}]}
{"channel":"l2_data","timestamp":"2026-07-16T20:29:00.476318805Z","sequence_num":173,"events":[{"type":"update","product_id":"BTC-USD","updates":[{"side":"bid","event_time":"2026-07-16T20:29:00.458Z","price_level":"64115.4","new_quantity":"0.27717965"},{"side":"bid","event_time":"2026-07-16T20:29:00.458Z","price_level":"51315.66","new_quantity":"0"}]}]}
{"channel":"l2_data","timestamp":"2026-07-16T20:29:00.532586331Z","sequence_num":174,"events":[{"type":"update","product_id":"BTC-USD","updates":[{"side":"bid","event_time":"2026-07-16T20:29:00.492548Z","price_level":"64117.01","new_quantity":"0"},{"side":"bid","event_time":"2026-07-16T20:29:00.492548Z","price_level":"64117","new_quantity":"0"},{"side":"bid","event_time":"2026-07-16T20:29:00.492548Z","price_level":"64115.6","new_quantity":"0.63212598"},{"side":"bid","event_time":"2026-07-16T20:29:00.492548Z","price_level":"64096.16","new_quantity":"0.56681067"},{"side":"bid","event_time":"2026-07-16T20:29:00.492548Z","price_level":"56126.5","new_quantity":"0"},{"side":"offer","event_time":"2026-07-16T20:29:00.492548Z","price_level":"64165.48","new_quantity":"0.36079099"},{"side":"offer","event_time":"2026-07-16T20:29:00.492548Z","price_level":"64165.92","new_quantity":"0.27644834"},{"side":"offer","event_time":"2026-07-16T20:29:00.492548Z","price_level":"64185.17","new_quantity":"0.55909495"}]}]}
{"channel":"l2_data","timestamp":"2026-07-16T20:29:00.585561774Z","sequence_num":175,"events":[{"type":"update","product_id":"BTC-USD","updates":[{"side":"bid","event_time":"2026-07-16T20:29:00.559502Z","price_level":"64137.6","new_quantity":"0.00033322"},{"side":"bid","event_time":"2026-07-16T20:29:00.559502Z","price_level":"64120","new_quantity":"0.01"},{"side":"offer","event_time":"2026-07-16T20:29:00.559502Z","price_level":"64149.95","new_quantity":"0.00009743"},{"side":"offer","event_time":"2026-07-16T20:29:00.559502Z","price_level":"64150.92","new_quantity":"0.00904152"}]}]}
{"channel":"l2_data","timestamp":"2026-07-16T20:29:00.626119915Z","sequence_num":176,"events":[{"type":"update","product_id":"BTC-USD","updates":[{"side":"bid","event_time":"2026-07-16T20:29:00.600398Z","price_level":"64142.96","new_quantity":"0.00584149"},{"side":"bid","event_time":"2026-07-16T20:29:00.600398Z","price_level":"64117.01","new_quantity":"0.63211207"},{"side":"bid","event_time":"2026-07-16T20:29:00.600398Z","price_level":"64117","new_quantity":"1"},{"side":"bid","event_time":"2026-07-16T20:29:00.600398Z","price_level":"64115.6","new_quantity":"0"}]}]}
{"channel":"l2_data","timestamp":"2026-07-16T20:29:00.674656906Z","sequence_num":177,"events":[{"type":"update","product_id":"BTC-USD","updates":[{"side":"bid","event_time":"2026-07-16T20:29:00.652712Z","price_level":"64131.91","new_quantity":"0"}]}]}
{"channel":"l2_data","timestamp":"2026-07-16T20:29:00.731886457Z","sequence_num":178,"events":[{"type":"update","product_id":"BTC-USD","updates":[{"side":"bid","event_time":"2026-07-16T20:29:00.690347Z","price_level":"64117","new_quantity":"0"},{"side":"bid","event_time":"2026-07-16T20:29:00.690347Z","price_level":"56126.5","new_quantity":"0.01337205"},{"side":"offer","event_time":"2026-07-16T20:29:00.690347Z","price_level":"64144.58","new_quantity":"0.2937457"}]}]}
{"channel":"l2_data","timestamp":"2026-07-16T20:29:00.77538337Z","sequence_num":179,"events":[{"type":"update","product_id":"BTC-USD","updates":[{"side":"bid","event_time":"2026-07-16T20:29:00.734339Z","price_level":"64119","new_quantity":"1"},{"side":"bid","event_time":"2026-07-16T20:29:00.734339Z","price_level":"64117.01","new_quantity":"0.65487681"},{"side":"bid","event_time":"2026-07-16T20:29:00.734339Z","price_level":"64115.6","new_quantity":"0.63212598"},{"side":"bid","event_time":"2026-07-16T20:29:00.734339Z","price_level":"64115.59","new_quantity":"0"}]}]}
{"channel":"l2_data","timestamp":"2026-07-16T20:29:00.830873171Z","sequence_num":180,"events":[{"type":"update","product_id":"BTC-USD","updates":[{"side":"bid","event_time":"2026-07-16T20:29:00.808377Z","price_level":"56126.5","new_quantity":"0"},{"side":"offer","event_time":"2026-07-16T20:29:00.808377Z","price_level":"65659.24","new_quantity":"0.00583"},{"side":"offer","event_time":"2026-07-16T20:29:00.808377Z","price_level":"65659.32","new_quantity":"0"}]}]}
{"channel":"l2_data","timestamp":"2026-07-16T20:29:00.876124729Z","sequence_num":181,"events":[{"type":"update","product_id":"BTC-USD","updates":[{"side":"bid","event_time":"2026-07-16T20:29:00.835929Z","price_level":"64119","new_quantity":"0"}]}]}
{"channel":"l2_data","timestamp":"2026-07-16T20:29:00.931470823Z","sequence_num":182,"events":[{"type":"update","product_id":"BTC-USD","updates":[{"side":"bid","event_time":"2026-07-16T20:29:00.892381Z","price_level":"64131.96","new_quantity":"0"},{"side":"bid","event_time":"2026-07-16T20:29:00.892381Z","price_level":"64118","new_quantity":"1"},{"side":"bid","event_time":"2026-07-16T20:29:00.892381Z","price_level":"64117.02","new_quantity":"0.63211198"},{"side":"bid","event_time":"2026-07-16T20:29:00.892381Z","price_level":"64117.01","new_quantity":"0"},{"side":"bid","event_time":"2026-07-16T20:29:00.892381Z","price_level":"64115.61","new_quantity":"0.65488078"},{"side":"bid","event_time":"2026-07-16T20:29:00.892381Z","price_level":"64115.6","new_quantity":"0"},{"side":"offer","event_time":"2026-07-16T20:29:00.892381Z","price_level":"64187.2","new_quantity":"0.48135227"},{"side":"offer","event_time":"2026-07-16T20:29:00.892381Z","price_level":"64187.22","new_quantity":"0"},{"side":"offer","event_time":"2026-07-16T20:29:00.892381Z","price_level":"64206.77","new_quantity":"2.0018703"},{"side":"offer","event_time":"2026-07-16T20:29:00.892381Z","price_level":"64206.79","new_quantity":"0"}]}]}
{"channel":"l2_data","timestamp":"2026-07-16T20:29:01.028906379Z","sequence_num":183,"events":[{"type":"update","product_id":"BTC-USD","updates":[{"side":"bid","event_time":"2026-07-16T20:29:00.997989Z","price_level":"64144.57","new_quantity":"0.02098884"},{"side":"bid","event_time":"2026-07-16T20:29:00.997989Z","price_level":"64118","new_quantity":"0"},{"side":"bid","event_time":"2026-07-16T20:29:00.997989Z","price_level":"64117.02","new_quantity":"0"},{"side":"bid","event_time":"2026-07-16T20:29:00.997989Z","price_level":"64115.62","new_quantity":"0.63212578"},{"side":"bid","event_time":"2026-07-16T20:29:00.997989Z","price_level":"56126.5","new_quantity":"0.01337205"}]}]}
{"channel":"l2_data","timestamp":"2026-07-16T20:29:01.083887682Z","sequence_num":184,"events":[{"type":"update","product_id":"BTC-USD","updates":[{"side":"bid","event_time":"2026-07-16T20:29:01.051026Z","price_level":"64139.76","new_quantity":"0.13252309"},{"side":"bid","event_time":"2026-07-16T20:29:01.051026Z","price_level":"64138.16","new_quantity":"0.00779567"},{"side":"bid","event_time":"2026-07-16T20:29:01.051026Z","price_level":"64119","new_quantity":"1"},{"side":"offer","event_time":"2026-07-16T20:29:01.051026Z","price_level":"64150.89","new_quantity":"0.00896324"},{"side":"offer","event_time":"2026-07-16T20:29:01.051026Z","price_level":"64150.97","new_quantity":"0"},{"side":"offer","event_time":"2026-07-16T20:29:01.051026Z","price_level":"64151.33","new_quantity":"0"},{"side":"offer","event_time":"2026-07-16T20:29:01.051026Z","price_level":"64152.57","new_quantity":"0"},{"side":"offer","event_time":"2026-07-16T20:29:01.051026Z","price_level":"64152.61","new_quantity":"0"}]}]}
{"channel":"l2_data","timestamp":"2026-07-16T20:29:01.1301462Z","sequence_num":185,"events":[{"type":"update","product_id":"BTC-USD","updates":[{"side":"bid","event_time":"2026-07-16T20:29:01.096206Z","price_level":"64119","new_quantity":"0"},{"side":"bid","event_time":"2026-07-16T20:29:01.096206Z","price_level":"56126.5","new_quantity":"0"},{"side":"offer","event_time":"2026-07-16T20:29:01.096206Z","price_level":"64144.58","new_quantity":"0.3380657"},{"side":"offer","event_time":"2026-07-16T20:29:01.096206Z","price_level":"64152.5","new_quantity":"0.00896302"}]}]}
{"channel":"heartbeats","timestamp":"2026-07-16T20:29:01.168774895Z","sequence_num":186,"events":[{"current_time":"2026-07-16 20:29:01.162919176 +0000 UTC m=+75505.317746212","heartbeat_counter":75505}]}
{"channel":"l2_data","timestamp":"2026-07-16T20:29:01.196301941Z","sequence_num":187,"events":[{"type":"update","product_id":"BTC-USD","updates":[{"side":"bid","event_time":"2026-07-16T20:29:01.149857Z","price_level":"64137.6","new_quantity":"0.00891982"},{"side":"bid","event_time":"2026-07-16T20:29:01.149857Z","price_level":"64135.91","new_quantity":"0"},{"side":"bid","event_time":"2026-07-16T20:29:01.149857Z","price_level":"64135.21","new_quantity":"0.01559176"},{"side":"bid","event_time":"2026-07-16T20:29:01.149857Z","price_level":"64132.01","new_quantity":"0"},{"side":"bid","event_time":"2026-07-16T20:29:01.149857Z","price_level":"64118.01","new_quantity":"0.63210222"},{"side":"bid","event_time":"2026-07-16T20:29:01.149857Z","price_level":"64118","new_quantity":"1"},{"side":"bid","event_time":"2026-07-16T20:29:01.149857Z","price_level":"64115.62","new_quantity":"0"},{"side":"offer","event_time":"2026-07-16T20:29:01.149857Z","price_level":"64144.83","new_quantity":"0.03359176"},{"side":"offer","event_time":"2026-07-16T20:29:01.149857Z","price_level":"64145.53","new_quantity":"0"},{"side":"offer","event_time":"2026-07-16T20:29:01.149857Z","price_level":"64145.8","new_quantity":"0.018"},{"side":"offer","event_time":"2026-07-16T20:29:01.149857Z","price_level":"64151.25","new_quantity":"0.00009743"},{"side":"offer","event_time":"2026-07-16T20:29:01.149857Z","price_level":"64152.54","new_quantity":"0.00779392"}]}]}
{"channel":"l2_data","timestamp":"2026-07-16T20:29:01.279648393Z","sequence_num":188,"events":[{"type":"update","product_id":"BTC-USD","updates":[{"side":"bid","event_time":"2026-07-16T20:29:01.252859Z","price_level":"64118","new_quantity":"0"},{"side":"bid","event_time":"2026-07-16T20:29:01.252859Z","price_level":"64113","new_quantity":"1.0000309"}]}]}
{"channel":"l2_data","timestamp":"2026-07-16T20:29:01.348401224Z","sequence_num":189,"events":[{"type":"update","product_id":"BTC-USD","updates":[{"side":"bid","event_time":"2026-07-16T20:29:01.301102Z","price_level":"64144.57","new_quantity":"0.02098884"},{"side":"bid","event_time":"2026-07-16T20:29:01.301102Z","price_level":"64137.6","new_quantity":"0.00033322"},{"side":"bid","event_time":"2026-07-16T20:29:01.301102Z","price_level":"64137.35","new_quantity":"0"},{"side":"bid","event_time":"2026-07-16T20:29:01.301102Z","price_level":"64135.01","new_quantity":"0"},{"side":"bid","event_time":"2026-07-16T20:29:01.301102Z","price_level":"64132.99","new_quantity":"0"},{"side":"bid","event_time":"2026-07-16T20:29:01.301102Z","price_level":"64131.54","new_quantity":"0"},{"side":"bid","event_time":"2026-07-16T20:29:01.301102Z","price_level":"64131.53","new_quantity":"0.0077892"},{"side":"bid","event_time":"2026-07-16T20:29:01.301102Z","price_level":"64130.88","new_quantity":"0"},{"side":"bid","event_time":"2026-07-16T20:29:01.301102Z","price_level":"64128.5","new_quantity":"0.37950264"},{"side":"bid","event_time":"2026-07-16T20:29:01.301102Z","price_level":"64128.49","new_quantity":"0.31190852"},{"side":"bid","event_time":"2026-07-16T20:29:01.301102Z","price_level":"64128.48","new_quantity":"0"},{"side":"bid","event_time":"2026-07-16T20:29:01.301102Z","price_level":"64128.47","new_quantity":"0"},{"side":"bid","event_time":"2026-07-16T20:29:01.301102Z","price_level":"64126.48","new_quantity":"0.31190852"},{"side":"bid","event_time":"2026-07-16T20:29:01.301102Z","price_level":"64126.47","new_quantity":"0"},{"side":"bid","event_time":"2026-07-16T20:29:01.301102Z","price_level":"64122.59","new_quantity":"0.04281271"},{"side":"bid","event_time":"2026-07-16T20:29:01.301102Z","price_level":"64118.01","new_quantity":"0"},{"side":"bid","event_time":"2026-07-16T20:29:01.301102Z","price_level":"64115.62","new_quantity":"0.63212578"},{"side":"bid","event_time":"2026-07-16T20:29:01.301102Z","price_level":"64113.01","new_quantity":"0.31190852"},{"side":"bid","event_time":"2026-07-16T20:29:01.301102Z","price_level":"64112","new_quantity":"1"},{"side":"bid","event_time":"2026-07-16T20:29:01.301102Z","price_level":"56126.5","new_quantity":"0.01337205"},{"side":"offer","event_time":"2026-07-16T20:29:01.301102Z","price_level":"64145.06","new_quantity":"0"},{"side":"offer","event_time":"2026-07-16T20:29:01.301102Z","price_level":"65659.17","new_quantity":"0.00583"},{"side":"offer","event_time":"2026-07-16T20:29:01.301102Z","price_level":"65659.24","new_quantity":"0"}]}]}
{"channel":"l2_data","timestamp":"2026-07-16T20:29:01.382039737Z","sequence_num":190,"events":[{"type":"update","product_id":"BTC-USD","updates":[{"side":"bid","event_time":"2026-07-16T20:29:01.352225Z","price_level":"64144.57","new_quantity":"0.02098876"},{"side":"bid","event_time":"2026-07-16T20:29:01.352225Z","price_level":"64131.44","new_quantity":"0.68743"},{"side":"bid","event_time":"2026-07-16T20:29:01.352225Z","price_level":"64131.42","new_quantity":"0.31190852"}]}]}
{"channel":"l2_data","timestamp":"2026-07-16T20:29:01.430139201Z","sequence_num":191,"events":[{"type":"update","product_id":"BTC-USD","updates":[{"side":"bid","event_time":"2026-07-16T20:29:01.386545Z","price_level":"64133.36","new_quantity":"0.31190852"},{"side":"bid","event_time":"2026-07-16T20:29:01.386545Z","price_level":"64131.44","new_quantity":"0"},{"side":"bid","event_time":"2026-07-16T20:29:01.386545Z","price_level":"64112","new_quantity":"0"},{"side":"bid","event_time":"2026-07-16T20:29:01.386545Z","price_level":"56126.5","new_quantity":"0.0089147"}]}]}
{"channel":"l2_data","timestamp":"2026-07-16T20:29:01.490325338Z","sequence_num":192,"events":[{"type":"update","product_id":"BTC-USD","updates":[{"side":"bid","event_time":"2026-07-16T20:29:01.423507Z","price_level":"64139.76","new_quantity":"0.00779548"},{"side":"bid","event_time":"2026-07-16T20:29:01.423507Z","price_level":"64139.17","new_quantity":"0.12472875"},{"side":"bid","event_time":"2026-07-16T20:29:01.423507Z","price_level":"64138.42","new_quantity":"0"},{"side":"bid","event_time":"2026-07-16T20:29:01.423507Z","price_level":"64137.34","new_quantity":"0"},{"side":"bid","event_time":"2026-07-16T20:29:01.423507Z","price_level":"64136.44","new_quantity":"0.31190852"},{"side":"bid","event_time":"2026-07-16T20:29:01.423507Z","price_level":"64136.43","new_quantity":"0.1559176"},{"side":"bid","event_time":"2026-07-16T20:29:01.423507Z","price_level":"64125.89","new_quantity":"0.23359045"},{"side":"bid","event_time":"2026-07-16T20:29:01.423507Z","price_level":"64125.88","new_quantity":"0.07356275"},{"side":"bid","event_time":"2026-07-16T20:29:01.423507Z","price_level":"64124.02","new_quantity":"0"},{"side":"bid","event_time":"2026-07-16T20:29:01.423507Z","price_level":"64120.45","new_quantity":"0.23359045"},{"side":"bid","event_time":"2026-07-16T20:29:01.423507Z","price_level":"64118.01","new_quantity":"0.63210222"},{"side":"bid","event_time":"2026-07-16T20:29:01.423507Z","price_level":"64118","new_quantity":"1"},{"side":"bid","event_time":"2026-07-16T20:29:01.423507Z","price_level":"64115.62","new_quantity":"0"},{"side":"bid","event_time":"2026-07-16T20:29:01.423507Z","price_level":"64113.01","new_quantity":"0.31268796"},{"side":"bid","event_time":"2026-07-16T20:29:01.423507Z","price_level":"64112.28","new_quantity":"0"},{"side":"bid","event_time":"2026-07-16T20:29:01.423507Z","price_level":"56126.5","new_quantity":"0"}]}]}
{"channel":"l2_data","timestamp":"2026-07-16T20:29:01.5373921Z","sequence_num":193,"events":[{"type":"update","product_id":"BTC-USD","updates":[{"side":"bid","event_time":"2026-07-16T20:29:01.475401Z","price_level":"64144.57","new_quantity":"0.02098871"}]}]}
{"channel":"l2_data","timestamp":"2026-07-16T20:29:01.661604005Z","sequence_num":194,"events":[{"type":"update","product_id":"BTC-USD","updates":[{"side":"bid","event_time":"2026-07-16T20:29:01.602659Z","price_level":"64131.63","new_quantity":"0.594842"},{"side":"bid","event_time":"2026-07-16T20:29:01.602659Z","price_level":"56126.5","new_quantity":"0.01337205"},{"side":"offer","event_time":"2026-07-16T20:29:01.602659Z","price_level":"64149.95","new_quantity":"0"},{"side":"offer","event_time":"2026-07-16T20:29:01.602659Z","price_level":"64150.92","new_quantity":"0.0012474"}]}]}
{"channel":"l2_data","timestamp":"2026-07-16T20:29:01.698688539Z","sequence_num":195,"events":[{"type":"update","product_id":"BTC-USD","updates":[{"side":"bid","event_time":"2026-07-16T20:29:01.647067Z","price_level":"64131.63","new_quantity":"0"},{"side":"offer","event_time":"2026-07-16T20:29:01.647067Z","price_level":"64149.88","new_quantity":"0.00009743"},{"side":"offer","event_time":"2026-07-16T20:29:01.647067Z","price_level":"64150.85","new_quantity":"0.00779413"}]}]}
{"channel":"l2_data","timestamp":"2026-07-16T20:29:01.733619612Z","sequence_num":196,"events":[{"type":"update","product_id":"BTC-USD","updates":[{"side":"bid","event_time":"2026-07-16T20:29:01.694735Z","price_level":"56126.5","new_quantity":"0"}]}]}
{"channel":"l2_data","timestamp":"2026-07-16T20:29:01.780461736Z","sequence_num":197,"events":[{"type":"update","product_id":"BTC-USD","updates":[{"side":"bid","event_time":"2026-07-16T20:29:01.755762Z","price_level":"64137.6","new_quantity":"0.00766858"},{"side":"bid","event_time":"2026-07-16T20:29:01.755762Z","price_level":"64136.44","new_quantity":"0.31190852"}]}]}
{"channel":"l2_data","timestamp":"2026-07-16T20:29:01.876579832Z","sequence_num":198,"events":[{"type":"update","product_id":"BTC-USD","updates":[{"side":"bid","event_time":"2026-07-16T20:29:01.853304Z","price_level":"64131.64","new_quantity":"0.709495"}]}]}
{"channel":"l2_data","timestamp":"2026-07-16T20:29:01.931863017Z","sequence_num":199,"events":[{"type":"update","product_id":"BTC-USD","updates":[{"side":"bid","event_time":"2026-07-16T20:29:01.896116Z","price_level":"64136.44","new_quantity":"0"},{"side":"bid","event_time":"2026-07-16T20:29:01.896116Z","price_level":"64131.64","new_quantity":"0"},{"side":"bid","event_time":"2026-07-16T20:29:01.896116Z","price_level":"64118.03","new_quantity":"0.63210202"},{"side":"bid","event_time":"2026-07-16T20:29:01.896116Z","price_level":"64118.02","new_quantity":"0"},{"side":"bid","event_time":"2026-07-16T20:29:01.896116Z","price_level":"64118.01","new_quantity":"0"},{"side":"bid","event_time":"2026-07-16T20:29:01.896116Z","price_level":"64115.61","new_quantity":"0"},{"side":"bid","event_time":"2026-07-16T20:29:01.896116Z","price_level":"64115.47","new_quantity":"0.6548891"},{"side":"bid","event_time":"2026-07-16T20:29:01.896116Z","price_level":"63503.26","new_quantity":"0"},{"side":"bid","event_time":"2026-07-16T20:29:01.896116Z","price_level":"56126.5","new_quantity":"0.01337205"},{"side":"offer","event_time":"2026-07-16T20:29:01.896116Z","price_level":"64187.18","new_quantity":"0.48135242"},{"side":"offer","event_time":"2026-07-16T20:29:01.896116Z","price_level":"64187.19","new_quantity":"0"},{"side":"offer","event_time":"2026-07-16T20:29:01.896116Z","price_level":"64187.2","new_quantity":"0"},{"side":"offer","event_time":"2026-07-16T20:29:01.896116Z","price_level":"64206.75","new_quantity":"2.00187093"},{"side":"offer","event_time":"2026-07-16T20:29:01.896116Z","price_level":"64206.76","new_quantity":"0"},{"side":"offer","event_time":"2026-07-16T20:29:01.896116Z","price_level":"64206.77","new_quantity":"0"}]}]}
{"channel":"l2_data","timestamp":"2026-07-16T20:29:01.981291474Z","sequence_num":200,"events":[{"type":"update","product_id":"BTC-USD","updates":[{"side":"bid","event_time":"2026-07-16T20:29:01.951726Z","price_level":"64136.44","new_quantity":"0.31190852"},{"side":"offer","event_time":"2026-07-16T20:29:01.951726Z","price_level":"64144.58","new_quantity":"0.33690816"}]}]}
{"channel":"l2_data","timestamp":"2026-07-16T20:29:02.025250982Z","sequence_num":201,"events":[{"type":"update","product_id":"BTC-USD","updates":[{"side":"bid","event_time":"2026-07-16T20:29:01.99169Z","price_level":"56126.5","new_quantity":"0"}]}]}
{"channel":"l2_data","timestamp":"2026-07-16T20:29:02.080766783Z","sequence_num":202,"events":[{"type":"update","product_id":"BTC-USD","updates":[{"side":"bid","event_time":"2026-07-16T20:29:02.048774Z","price_level":"64144.57","new_quantity":"0.02098857"},{"side":"bid","event_time":"2026-07-16T20:29:02.048774Z","price_level":"64139.76","new_quantity":"0"},{"side":"bid","event_time":"2026-07-16T20:29:02.048774Z","price_level":"64138.16","new_quantity":"0"},{"side":"bid","event_time":"2026-07-16T20:29:02.048774Z","price_level":"64135.21","new_quantity":"0"},{"side":"bid","event_time":"2026-07-16T20:29:02.048774Z","price_level":"64134.96","new_quantity":"0.01559176"},{"side":"bid","event_time":"2026-07-16T20:29:02.048774Z","price_level":"64118.03","new_quantity":"0"},{"side":"bid","event_time":"2026-07-16T20:29:02.048774Z","price_level":"64118","new_quantity":"0"},{"side":"bid","event_time":"2026-07-16T20:29:02.048774Z","price_level":"64115.48","new_quantity":"0.63212716"},{"side":"offer","event_time":"2026-07-16T20:29:02.048774Z","price_level":"64144.58","new_quantity":"0.35249992"},{"side":"offer","event_time":"2026-07-16T20:29:02.048774Z","price_level":"64144.83","new_quantity":"0.018"},{"side":"offer","event_time":"2026-07-16T20:29:02.048774Z","price_level":"64150.89","new_quantity":"0"},{"side":"offer","event_time":"2026-07-16T20:29:02.048774Z","price_level":"64151.25","new_quantity":"0"},{"side":"offer","event_time":"2026-07-16T20:29:02.048774Z","price_level":"64152.5","new_quantity":"0"},{"side":"offer","event_time":"2026-07-16T20:29:02.048774Z","price_level":"64152.54","new_quantity":"0"}]}]}
{"channel":"l2_data","timestamp":"2026-07-16T20:29:02.133675185Z","sequence_num":203,"events":[{"type":"update","product_id":"BTC-USD","updates":[{"side":"bid","event_time":"2026-07-16T20:29:02.106011Z","price_level":"64138.16","new_quantity":"0.00779567"},{"side":"bid","event_time":"2026-07-16T20:29:02.106011Z","price_level":"64114","new_quantity":"1"},{"side":"bid","event_time":"2026-07-16T20:29:02.106011Z","price_level":"63501.99","new_quantity":"0.03937535"},{"side":"offer","event_time":"2026-07-16T20:29:02.106011Z","price_level":"64152.43","new_quantity":"0.00896303"}]}]}
{"channel":"heartbeats","timestamp":"2026-07-16T20:29:02.167805069Z","sequence_num":204,"events":[{"current_time":"2026-07-16 20:29:02.163014554 +0000 UTC m=+75506.317841598","heartbeat_counter":75506}]}
{"channel":"l2_data","timestamp":"2026-07-16T20:29:02.18220601Z","sequence_num":205,"events":[{"type":"update","product_id":"BTC-USD","updates":[{"side":"bid","event_time":"2026-07-16T20:29:02.120417Z","price_level":"64139.76","new_quantity":"0.00779548"},{"side":"bid","event_time":"2026-07-16T20:29:02.120417Z","price_level":"64137.6","new_quantity":"0.00033322"},{"side":"offer","event_time":"2026-07-16T20:29:02.120417Z","price_level":"64150.83","new_quantity":"0.00896325"}]}]}
{"channel":"l2_data","timestamp":"2026-07-16T20:29:02.230529609Z","sequence_num":206,"events":[{"type":"update","product_id":"BTC-USD","updates":[{"side":"bid","event_time":"2026-07-16T20:29:02.192836Z","price_level":"64113","new_quantity":"0.0000309"},{"side":"bid","event_time":"2026-07-16T20:29:02.192836Z","price_level":"56126.5","new_quantity":"0.01337205"},{"side":"offer","event_time":"2026-07-16T20:29:02.192836Z","price_level":"64151.19","new_quantity":"0.00009743"},{"side":"offer","event_time":"2026-07-16T20:29:02.192836Z","price_level":"64152.47","new_quantity":"0.00779393"}]}]}
{"channel":"l2_data","timestamp":"2026-07-16T20:29:02.276033636Z","sequence_num":207,"events":[{"type":"update","product_id":"BTC-USD","updates":[{"side":"bid","event_time":"2026-07-16T20:29:02.231361Z","price_level":"64119","new_quantity":"1"}]}]}
{"channel":"l2_data","timestamp":"2026-07-16T20:29:02.33005644Z","sequence_num":208,"events":[{"type":"update","product_id":"BTC-USD","updates":[{"side":"bid","event_time":"2026-07-16T20:29:02.290343Z","price_level":"56126.5","new_quantity":"0"},{"side":"offer","event_time":"2026-07-16T20:29:02.290343Z","price_level":"64249.44","new_quantity":"0.233785"},{"side":"offer","event_time":"2026-07-16T20:29:02.290343Z","price_level":"64255.65","new_quantity":"0"}]}]}
{"channel":"l2_data","timestamp":"2026-07-16T20:29:02.378776126Z","sequence_num":209,"events":[{"type":"update","product_id":"BTC-USD","updates":[{"side":"bid","event_time":"2026-07-16T20:29:02.352012Z","price_level":"64144.57","new_quantity":"0.02098852"},{"side":"bid","event_time":"2026-07-16T20:29:02.352012Z","price_level":"64131.73","new_quantity":"0.610729"}]}]}
{"channel":"l2_data","timestamp":"2026-07-16T20:29:02.430102341Z","sequence_num":210,"events":[{"type":"update","product_id":"BTC-USD","updates":[{"side":"bid","event_time":"2026-07-16T20:29:02.394603Z","price_level":"64131.73","new_quantity":"0"},{"side":"offer","event_time":"2026-07-16T20:29:02.394603Z","price_level":"64786.16","new_quantity":"0"}]}]}
{"channel":"l2_data","timestamp":"2026-07-16T20:29:02.474638563Z","sequence_num":211,"events":[{"type":"update","product_id":"BTC-USD","updates":[{"side":"bid","event_time":"2026-07-16T20:29:02.422702Z","price_level":"64113.02","new_quantity":"0.00077944"},{"side":"bid","event_time":"2026-07-16T20:29:02.422702Z","price_level":"64113.01","new_quantity":"0.31190852"}]}]}
{"channel":"l2_data","timestamp":"2026-07-16T20:29:02.525219542Z","sequence_num":212,"events":[{"type":"update","product_id":"BTC-USD","updates":[{"side":"bid","event_time":"2026-07-16T20:29:02.493046Z","price_level":"64144.57","new_quantity":"0.02098837"},{"side":"bid","event_time":"2026-07-16T20:29:02.493046Z","price_level":"56126.5","new_quantity":"0.01337205"}]}]}
{"channel":"l2_data","timestamp":"2026-07-16T20:29:02.577100435Z","sequence_num":213,"events":[{"type":"update","product_id":"BTC-USD","updates":[{"side":"bid","event_time":"2026-07-16T20:29:02.544279Z","price_level":"64144.57","new_quantity":"0.02098833"}]}]}
{"channel":"l2_data","timestamp":"2026-07-16T20:29:02.6253794Z","sequence_num":214,"events":[{"type":"update","product_id":"BTC-USD","updates":[{"side":"bid","event_time":"2026-07-16T20:29:02.604115Z","price_level":"64131.8","new_quantity":"0.665139"},{"side":"bid","event_time":"2026-07-16T20:29:02.604115Z","price_level":"56126.5","new_quantity":"0"}]}]}
{"channel":"l2_data","timestamp":"2026-07-16T20:29:02.679493338Z","sequence_num":215,"events":[{"type":"update","product_id":"BTC-USD","updates":[{"side":"bid","event_time":"2026-07-16T20:29:02.630176Z","price_level":"64137.6","new_quantity":"0.00718819"},{"side":"bid","event_time":"2026-07-16T20:29:02.630176Z","price_level":"64131.8","new_quantity":"0"},{"side":"offer","event_time":"2026-07-16T20:29:02.630176Z","price_level":"64784.86","new_quantity":"0.03890047"}]}]}
{"channel":"l2_data","timestamp":"2026-07-16T20:29:02.726714155Z","sequence_num":216,"events":[{"type":"update","product_id":"BTC-USD","updates":[{"side":"offer","event_time":"2026-07-16T20:29:02.678727Z","price_level":"64144.58","new_quantity":"0.35071573"}]}]}
{"channel":"l2_data","timestamp":"2026-07-16T20:29:02.779209233Z","sequence_num":217,"events":[{"type":"update","product_id":"BTC-USD","updates":[{"side":"bid","event_time":"2026-07-16T20:29:02.754948Z","price_level":"64136.44","new_quantity":"0"},{"side":"bid","event_time":"2026-07-16T20:29:02.754948Z","price_level":"64125.89","new_quantity":"0"},{"side":"offer","event_time":"2026-07-16T20:29:02.754948Z","price_level":"64145.77","new_quantity":"0.04691558"},{"side":"offer","event_time":"2026-07-16T20:29:02.754948Z","price_level":"64149.82","new_quantity":"0.00009743"},{"side":"offer","event_time":"2026-07-16T20:29:02.754948Z","price_level":"64149.88","new_quantity":"0"},{"side":"offer","event_time":"2026-07-16T20:29:02.754948Z","price_level":"64150.78","new_quantity":"0.00779414"},{"side":"offer","event_time":"2026-07-16T20:29:02.754948Z","price_level":"64150.85","new_quantity":"0"}]}]}
{"channel":"l2_data","timestamp":"2026-07-16T20:29:02.829371131Z","sequence_num":218,"events":[{"type":"update","product_id":"BTC-USD","updates":[{"side":"bid","event_time":"2026-07-16T20:29:02.803254Z","price_level":"64144.57","new_quantity":"0.00355059"},{"side":"bid","event_time":"2026-07-16T20:29:02.803254Z","price_level":"64142.96","new_quantity":"0.00038507"},{"side":"bid","event_time":"2026-07-16T20:29:02.803254Z","price_level":"64140.8","new_quantity":"0"},{"side":"bid","event_time":"2026-07-16T20:29:02.803254Z","price_level":"64139.17","new_quantity":"0"},{"side":"bid","event_time":"2026-07-16T20:29:02.803254Z","price_level":"64131.81","new_quantity":"0"},{"side":"bid","event_time":"2026-07-16T20:29:02.803254Z","price_level":"64131.52","new_quantity":"0.02"},{"side":"bid","event_time":"2026-07-16T20:29:02.803254Z","price_level":"64130.87","new_quantity":"0"},{"side":"bid","event_time":"2026-07-16T20:29:02.803254Z","price_level":"64128.72","new_quantity":"0.00077948"},{"side":"bid","event_time":"2026-07-16T20:29:02.803254Z","price_level":"64126.49","new_quantity":"0.23359045"},{"side":"bid","event_time":"2026-07-16T20:29:02.803254Z","price_level":"64119.32","new_quantity":"0.65486786"},{"side":"bid","event_time":"2026-07-16T20:29:02.803254Z","price_level":"64119","new_quantity":"0"},{"side":"bid","event_time":"2026-07-16T20:29:02.803254Z","price_level":"64115.47","new_quantity":"0"},{"side":"bid","event_time":"2026-07-16T20:29:02.803254Z","price_level":"64107.23","new_quantity":"0"},{"side":"bid","event_time":"2026-07-16T20:29:02.803254Z","price_level":"64104.67","new_quantity":"0"},{"side":"bid","event_time":"2026-07-16T20:29:02.803254Z","price_level":"64100.82","new_quantity":"0"},{"side":"bid","event_time":"2026-07-16T20:29:02.803254Z","price_level":"64086.82","new_quantity":"0"},{"side":"bid","event_time":"2026-07-16T20:29:02.803254Z","price_level":"64083.54","new_quantity":"0"},{"side":"bid","event_time":"2026-07-16T20:29:02.803254Z","price_level":"64082.58","new_quantity":"1.39427604"},{"side":"bid","event_time":"2026-07-16T20:29:02.803254Z","price_level":"56126.5","new_quantity":"0.01337205"},{"side":"offer","event_time":"2026-07-16T20:29:02.803254Z","price_level":"64145.06","new_quantity":"0.31190852"},{"side":"offer","event_time":"2026-07-16T20:29:02.803254Z","price_level":"64168.98","new_quantity":"0"},{"side":"offer","event_time":"2026-07-16T20:29:02.803254Z","price_level":"64204.91","new_quantity":"2.0019283"},{"side":"offer","event_time":"2026-07-16T20:29:02.803254Z","price_level":"64204.92","new_quantity":"1.40176187"},{"side":"offer","event_time":"2026-07-16T20:29:02.803254Z","price_level":"64206.75","new_quantity":"0"},{"side":"offer","event_time":"2026-07-16T20:29:02.803254Z","price_level":"64424.79","new_quantity":"0"},{"side":"offer","event_time":"2026-07-16T20:29:02.803254Z","price_level":"65015.52","new_quantity":"0.00583"},{"side":"offer","event_time":"2026-07-16T20:29:02.803254Z","price_level":"65015.61","new_quantity":"0"},{"side":"offer","event_time":"2026-07-16T20:29:02.803254Z","price_level":"65230.04","new_quantity":"0"},{"side":"offer","event_time":"2026-07-16T20:29:02.803254Z","price_level":"65230.16","new_quantity":"0.00583"},{"side":"offer","event_time":"2026-07-16T20:29:02.803254Z","price_level":"65230.2","new_quantity":"0"},{"side":"offer","event_time":"2026-07-16T20:29:02.803254Z","price_level":"65444.64","new_quantity":"0"},{"side":"offer","event_time":"2026-07-16T20:29:02.803254Z","price_level":"65659.17","new_quantity":"0"}]}]}
{"channel":"l2_data","timestamp":"2026-07-16T20:29:02.880680659Z","sequence_num":219,"events":[{"type":"update","product_id":"BTC-USD","updates":[{"side":"bid","event_time":"2026-07-16T20:29:02.854656Z","price_level":"64137.92","new_quantity":"0.12473119"},{"side":"bid","event_time":"2026-07-16T20:29:02.854656Z","price_level":"64128.5","new_quantity":"0.45306539"},{"side":"bid","event_time":"2026-07-16T20:29:02.854656Z","price_level":"64127.67","new_quantity":"0.07396"},{"side":"bid","event_time":"2026-07-16T20:29:02.854656Z","price_level":"64119.32","new_quantity":"0"},{"side":"bid","event_time":"2026-07-16T20:29:02.854656Z","price_level":"64115.5","new_quantity":"0.63367196"},{"side":"bid","event_time":"2026-07-16T20:29:02.854656Z","price_level":"64115.49","new_quantity":"0.65488689"},{"side":"bid","event_time":"2026-07-16T20:29:02.854656Z","price_level":"64115.48","new_quantity":"0"},{"side":"bid","event_time":"2026-07-16T20:29:02.854656Z","price_level":"64115","new_quantity":"1.01"},{"side":"bid","event_time":"2026-07-16T20:29:02.854656Z","price_level":"64114","new_quantity":"0"},{"side":"offer","event_time":"2026-07-16T20:29:02.854656Z","price_level":"64144.58","new_quantity":"0.38042975"},{"side":"offer","event_time":"2026-07-16T20:29:02.854656Z","price_level":"64156.51","new_quantity":"0"},{"side":"offer","event_time":"2026-07-16T20:29:02.854656Z","price_level":"65230.03","new_quantity":"0.00583"},{"side":"offer","event_time":"2026-07-16T20:29:02.854656Z","price_level":"65230.14","new_quantity":"0"},{"side":"offer","event_time":"2026-07-16T20:29:02.854656Z","price_level":"65230.15","new_quantity":"0"},{"side":"offer","event_time":"2026-07-16T20:29:02.854656Z","price_level":"65230.16","new_quantity":"0"},{"side":"offer","event_time":"2026-07-16T20:29:02.854656Z","price_level":"65444.53","new_quantity":"0.00583"},{"side":"offer","event_time":"2026-07-16T20:29:02.854656Z","price_level":"65444.56","new_quantity":"0"},{"side":"offer","event_time":"2026-07-16T20:29:02.854656Z","price_level":"65445.01","new_quantity":"0"},{"side":"offer","event_time":"2026-07-16T20:29:02.854656Z","price_level":"65659.14","new_quantity":"0.00583"}]}]}
{"channel":"l2_data","timestamp":"2026-07-16T20:29:02.936135485Z","sequence_num":220,"events":[{"type":"update","product_id":"BTC-USD","updates":[{"side":"bid","event_time":"2026-07-16T20:29:02.907982Z","price_level":"64137.93","new_quantity":"0.04691558"},{"side":"bid","event_time":"2026-07-16T20:29:02.907982Z","price_level":"64136.44","new_quantity":"0.31190852"},{"side":"bid","event_time":"2026-07-16T20:29:02.907982Z","price_level":"64121.11","new_quantity":"0"},{"side":"bid","event_time":"2026-07-16T20:29:02.907982Z","price_level":"64115","new_quantity":"0.01"},{"side":"bid","event_time":"2026-07-16T20:29:02.907982Z","price_level":"56126.5","new_quantity":"0"},{"side":"offer","event_time":"2026-07-16T20:29:02.907982Z","price_level":"64155.19","new_quantity":"0.0001164"},{"side":"offer","event_time":"2026-07-16T20:29:02.907982Z","price_level":"64156.5","new_quantity":"0.45103558"},{"side":"offer","event_time":"2026-07-16T20:29:02.907982Z","price_level":"64165.62","new_quantity":"0"},{"side":"offer","event_time":"2026-07-16T20:29:02.907982Z","price_level":"64187.16","new_quantity":"0.48135257"},{"side":"offer","event_time":"2026-07-16T20:29:02.907982Z","price_level":"64187.18","new_quantity":"0"},{"side":"offer","event_time":"2026-07-16T20:29:02.907982Z","price_level":"64207.14","new_quantity":"0.02893097"}]}]}
{"channel":"l2_data","timestamp":"2026-07-16T20:29:02.978437113Z","sequence_num":221,"events":[{"type":"update","product_id":"BTC-USD","updates":[{"side":"bid","event_time":"2026-07-16T20:29:02.956554Z","price_level":"64137.6","new_quantity":"0.00033322"},{"side":"bid","event_time":"2026-07-16T20:29:02.956554Z","price_level":"64127.82","new_quantity":"0.04"},{"side":"bid","event_time":"2026-07-16T20:29:02.956554Z","price_level":"64117.01","new_quantity":"0.63211207"},{"side":"bid","event_time":"2026-07-16T20:29:02.956554Z","price_level":"64117","new_quantity":"1"},{"side":"bid","event_time":"2026-07-16T20:29:02.956554Z","price_level":"64115.5","new_quantity":"0.001545"},{"side":"bid","event_time":"2026-07-16T20:29:02.956554Z","price_level":"64100.83","new_quantity":"0"},{"side":"bid","event_time":"2026-07-16T20:29:02.956554Z","price_level":"64100.75","new_quantity":"0.00077945"},{"side":"bid","event_time":"2026-07-16T20:29:02.956554Z","price_level":"63501.99","new_quantity":"0"}]}]}
{"channel":"l2_data","timestamp":"2026-07-16T20:29:03.086569055Z","sequence_num":222,"events":[{"type":"update","product_id":"BTC-USD","updates":[{"side":"bid","event_time":"2026-07-16T20:29:03.054805Z","price_level":"64139.76","new_quantity":"0"},{"side":"bid","event_time":"2026-07-16T20:29:03.054805Z","price_level":"64138.16","new_quantity":"0"},{"side":"bid","event_time":"2026-07-16T20:29:03.054805Z","price_level":"64120.81","new_quantity":"0.00779505"},{"side":"bid","event_time":"2026-07-16T20:29:03.054805Z","price_level":"64117","new_quantity":"0"},{"side":"offer","event_time":"2026-07-16T20:29:03.054805Z","price_level":"64150.83","new_quantity":"0"},{"side":"offer","event_time":"2026-07-16T20:29:03.054805Z","price_level":"64151.19","new_quantity":"0"},{"side":"offer","event_time":"2026-07-16T20:29:03.054805Z","price_level":"64152.43","new_quantity":"0"},{"side":"offer","event_time":"2026-07-16T20:29:03.054805Z","price_level":"64152.47","new_quantity":"0"}]}]}
{"channel":"l2_data","timestamp":"2026-07-16T20:29:03.126432208Z","sequence_num":223,"events":[{"type":"update","product_id":"BTC-USD","updates":[{"side":"bid","event_time":"2026-07-16T20:29:03.098189Z","price_level":"64144.57","new_quantity":"0.00355055"},{"side":"bid","event_time":"2026-07-16T20:29:03.098189Z","price_level":"64118","new_quantity":"1"},{"side":"bid","event_time":"2026-07-16T20:29:03.098189Z","price_level":"64117.01","new_quantity":"0"},{"side":"bid","event_time":"2026-07-16T20:29:03.098189Z","price_level":"64115.5","new_quantity":"0.63367196"},{"side":"bid","event_time":"2026-07-16T20:29:03.098189Z","price_level":"56126.5","new_quantity":"0.01337205"}]}]}
{"channel":"heartbeats","timestamp":"2026-07-16T20:29:03.171328741Z","sequence_num":224,"events":[{"current_time":"2026-07-16 20:29:03.162881365 +0000 UTC m=+75507.317708401","heartbeat_counter":75507}]}
{"channel":"l2_data","timestamp":"2026-07-16T20:29:03.204521491Z","sequence_num":225,"events":[{"type":"update","product_id":"BTC-USD","updates":[{"side":"bid","event_time":"2026-07-16T20:29:03.15467Z","price_level":"64138.16","new_quantity":"0.00779567"},{"side":"bid","event_time":"2026-07-16T20:29:03.15467Z","price_level":"64131.16","new_quantity":"0"}]}]}
{"channel":"l2_data","timestamp":"2026-07-16T20:29:03.23139817Z","sequence_num":226,"events":[{"type":"update","product_id":"BTC-USD","updates":[{"side":"bid","event_time":"2026-07-16T20:29:03.210875Z","price_level":"64144.57","new_quantity":"0.0027239"},{"side":"bid","event_time":"2026-07-16T20:29:03.210875Z","price_level":"64139.76","new_quantity":"0.00779548"},{"side":"bid","event_time":"2026-07-16T20:29:03.210875Z","price_level":"64118.73","new_quantity":"0.001545"},{"side":"bid","event_time":"2026-07-16T20:29:03.210875Z","price_level":"64066.68","new_quantity":"0"},{"side":"bid","event_time":"2026-07-16T20:29:03.210875Z","price_level":"64059.08","new_quantity":"2.14478378"},{"side":"bid","event_time":"2026-07-16T20:29:03.210875Z","price_level":"63500.6","new_quantity":"0.03937621"},{"side":"bid","event_time":"2026-07-16T20:29:03.210875Z","price_level":"56126.5","new_quantity":"0"},{"side":"offer","event_time":"2026-07-16T20:29:03.210875Z","price_level":"64150.76","new_quantity":"0.00896326"},{"side":"offer","event_time":"2026-07-16T20:29:03.210875Z","price_level":"64152.37","new_quantity":"0.00896304"},{"side":"offer","event_time":"2026-07-16T20:29:03.210875Z","price_level":"64157.39","new_quantity":"0.00583"},{"side":"offer","event_time":"2026-07-16T20:29:03.210875Z","price_level":"64181.06","new_quantity":"0.32027682"},{"side":"offer","event_time":"2026-07-16T20:29:03.210875Z","price_level":"64182.45","new_quantity":"0"},{"side":"offer","event_time":"2026-07-16T20:29:03.210875Z","price_level":"64185.16","new_quantity":"0.48572001"},{"side":"offer","event_time":"2026-07-16T20:29:03.210875Z","price_level":"64187.16","new_quantity":"0"},{"side":"offer","event_time":"2026-07-16T20:29:03.210875Z","price_level":"64202.07","new_quantity":"2.00201685"},{"side":"offer","event_time":"2026-07-16T20:29:03.210875Z","price_level":"64204.91","new_quantity":"0"},{"side":"offer","event_time":"2026-07-16T20:29:03.210875Z","price_level":"64586.5","new_quantity":"0.00583"},{"side":"offer","event_time":"2026-07-16T20:29:03.210875Z","price_level":"64586.51","new_quantity":"0"},{"side":"offer","event_time":"2026-07-16T20:29:03.210875Z","price_level":"65444.53","new_quantity":"0"},{"side":"offer","event_time":"2026-07-16T20:29:03.210875Z","price_level":"65659.14","new_quantity":"0"}]}]}
{"channel":"l2_data","timestamp":"2026-07-16T20:29:03.274792042Z","sequence_num":227,"events":[{"type":"update","product_id":"BTC-USD","updates":[{"side":"bid","event_time":"2026-07-16T20:29:03.238171Z","price_level":"64144.57","new_quantity":"0.00277766"},{"side":"bid","event_time":"2026-07-16T20:29:03.238171Z","price_level":"64092.9","new_quantity":"0.000018"}]}]}
{"channel":"l2_data","timestamp":"2026-07-16T20:29:03.329559827Z","sequence_num":228,"events":[{"type":"update","product_id":"BTC-USD","updates":[{"side":"bid","event_time":"2026-07-16T20:29:03.297405Z","price_level":"64107","new_quantity":"0.02888947"},{"side":"bid","event_time":"2026-07-16T20:29:03.297405Z","price_level":"64104.44","new_quantity":"0.03371656"},{"side":"bid","event_time":"2026-07-16T20:29:03.297405Z","price_level":"64100.59","new_quantity":"0.02482272"},{"side":"offer","event_time":"2026-07-16T20:29:03.297405Z","price_level":"64151.12","new_quantity":"0.00009743"},{"side":"offer","event_time":"2026-07-16T20:29:03.297405Z","price_level":"64152.4","new_quantity":"0.00779394"}]}]}
{"channel":"l2_data","timestamp":"2026-07-16T20:29:03.425943562Z","sequence_num":229,"events":[{"type":"update","product_id":"BTC-USD","updates":[{"side":"bid","event_time":"2026-07-16T20:29:03.404438Z","price_level":"64144.57","new_quantity":"0.00277764"},{"side":"bid","event_time":"2026-07-16T20:29:03.404438Z","price_level":"64137.6","new_quantity":"0.00807444"},{"side":"bid","event_time":"2026-07-16T20:29:03.404438Z","price_level":"64131.26","new_quantity":"0.69717"},{"side":"bid","event_time":"2026-07-16T20:29:03.404438Z","price_level":"64119.32","new_quantity":"0.65487428"},{"side":"bid","event_time":"2026-07-16T20:29:03.404438Z","price_level":"64115.49","new_quantity":"0"},{"side":"bid","event_time":"2026-07-16T20:29:03.404438Z","price_level":"56126.5","new_quantity":"0.01337205"}]}]}
{"channel":"l2_data","timestamp":"2026-07-16T20:29:03.479422264Z","sequence_num":230,"events":[{"type":"update","product_id":"BTC-USD","updates":[{"side":"bid","event_time":"2026-07-16T20:29:03.460255Z","price_level":"64131.26","new_quantity":"0"},{"side":"offer","event_time":"2026-07-16T20:29:03.460255Z","price_level":"64784.86","new_quantity":"0"}]}]}
{"channel":"l2_data","timestamp":"2026-07-16T20:29:03.524871913Z","sequence_num":231,"events":[{"type":"update","product_id":"BTC-USD","updates":[{"side":"bid","event_time":"2026-07-16T20:29:03.49319Z","price_level":"56126.5","new_quantity":"0"}]}]}
{"channel":"l2_data","timestamp":"2026-07-16T20:29:03.577004694Z","sequence_num":232,"events":[{"type":"update","product_id":"BTC-USD","updates":[{"side":"bid","event_time":"2026-07-16T20:29:03.548555Z","price_level":"64137.6","new_quantity":"0.00033322"},{"side":"bid","event_time":"2026-07-16T20:29:03.548555Z","price_level":"64119.32","new_quantity":"0"},{"side":"bid","event_time":"2026-07-16T20:29:03.548555Z","price_level":"64115.52","new_quantity":"0.63212676"},{"side":"bid","event_time":"2026-07-16T20:29:03.548555Z","price_level":"64115.51","new_quantity":"0.65488898"},{"side":"bid","event_time":"2026-07-16T20:29:03.548555Z","price_level":"64115.5","new_quantity":"0.001545"}]}]}
{"channel":"l2_data","timestamp":"2026-07-16T20:29:03.625236593Z","sequence_num":233,"events":[{"type":"update","product_id":"BTC-USD","updates":[{"side":"bid","event_time":"2026-07-16T20:29:03.60938Z","price_level":"64144.57","new_quantity":"0.00277758"},{"side":"bid","event_time":"2026-07-16T20:29:03.60938Z","price_level":"64131.28","new_quantity":"0.655869"}]}]}
{"channel":"l2_data","timestamp":"2026-07-16T20:29:03.679652746Z","sequence_num":234,"events":[{"type":"update","product_id":"BTC-USD","updates":[{"side":"bid","event_time":"2026-07-16T20:29:03.658788Z","price_level":"64131.28","new_quantity":"0"},{"side":"offer","event_time":"2026-07-16T20:29:03.658788Z","price_level":"64168.55","new_quantity":"0"}]}]}
{"channel":"l2_data","timestamp":"2026-07-16T20:29:04.036037975Z","sequence_num":235,"events":[{"type":"update","product_id":"BTC-USD","updates":[{"side":"bid","event_time":"2026-07-16T20:29:03.691386Z","price_level":"56126.5","new_quantity":"0.01337205"},{"side":"offer","event_time":"2026-07-16T20:29:03.691386Z","price_level":"64783.45","new_quantity":"0.03890047"}]}]}
{"channel":"l2_data","timestamp":"2026-07-16T20:29:04.037089721Z","sequence_num":236,"events":[{"type":"update","product_id":"BTC-USD","updates":[{"side":"bid","event_time":"2026-07-16T20:29:03.807646Z","price_level":"56126.5","new_quantity":"0"},{"side":"offer","event_time":"2026-07-16T20:29:03.807646Z","price_level":"64149.76","new_quantity":"0.00009743"},{"side":"offer","event_time":"2026-07-16T20:29:03.807646Z","price_level":"64149.82","new_quantity":"0"},{"side":"offer","event_time":"2026-07-16T20:29:03.807646Z","price_level":"64150.72","new_quantity":"0.00779415"},{"side":"offer","event_time":"2026-07-16T20:29:03.807646Z","price_level":"64150.78","new_quantity":"0"},{"side":"offer","event_time":"2026-07-16T20:29:03.807646Z","price_level":"64167.88","new_quantity":"0.00779505"}]}]}
{"channel":"l2_data","timestamp":"2026-07-16T20:29:04.037591008Z","sequence_num":237,"events":[{"type":"update","product_id":"BTC-USD","updates":[{"side":"bid","event_time":"2026-07-16T20:29:03.836984Z","price_level":"64130.88","new_quantity":"0.07396"},{"side":"offer","event_time":"2026-07-16T20:29:03.836984Z","price_level":"64144.58","new_quantity":"0.37891476"},{"side":"offer","event_time":"2026-07-16T20:29:03.836984Z","price_level":"64157.44","new_quantity":"0"},{"side":"offer","event_time":"2026-07-16T20:29:03.836984Z","price_level":"65444.65","new_quantity":"0.00583"}]}]}
{"channel":"l2_data","timestamp":"2026-07-16T20:29:04.038130367Z","sequence_num":238,"events":[{"type":"update","product_id":"BTC-USD","updates":[{"side":"bid","event_time":"2026-07-16T20:29:03.899764Z","price_level":"64131.48","new_quantity":"0"},{"side":"bid","event_time":"2026-07-16T20:29:03.899764Z","price_level":"63200","new_quantity":"8.37215713"},{"side":"offer","event_time":"2026-07-16T20:29:03.899764Z","price_level":"64185.14","new_quantity":"0.48572016"},{"side":"offer","event_time":"2026-07-16T20:29:03.899764Z","price_level":"64185.15","new_quantity":"0"},{"side":"offer","event_time":"2026-07-16T20:29:03.899764Z","price_level":"64185.16","new_quantity":"0"},{"side":"offer","event_time":"2026-07-16T20:29:03.899764Z","price_level":"64204.91","new_quantity":"0.83778495"},{"side":"offer","event_time":"2026-07-16T20:29:03.899764Z","price_level":"65229.95","new_quantity":"0.00583"}]}]}
{"channel":"l2_data","timestamp":"2026-07-16T20:29:04.039162935Z","sequence_num":239,"events":[{"type":"update","product_id":"BTC-USD","updates":[{"side":"bid","event_time":"2026-07-16T20:29:03.941473Z","price_level":"64127.67","new_quantity":"0"},{"side":"offer","event_time":"2026-07-16T20:29:03.941473Z","price_level":"64167.88","new_quantity":"0"}]}]}
{"channel":"l2_data","timestamp":"2026-07-16T20:29:04.039763499Z","sequence_num":240,"events":[{"type":"update","product_id":"BTC-USD","updates":[{"side":"bid","event_time":"2026-07-16T20:29:03.989034Z","price_level":"63500.6","new_quantity":"0"},{"side":"bid","event_time":"2026-07-16T20:29:03.989034Z","price_level":"56126.5","new_quantity":"0.01337205"}]}]}
{"channel":"l2_data","timestamp":"2026-07-16T20:29:04.084176988Z","sequence_num":241,"events":[{"type":"update","product_id":"BTC-USD","updates":[{"side":"bid","event_time":"2026-07-16T20:29:04.060499Z","price_level":"64139.76","new_quantity":"0"},{"side":"bid","event_time":"2026-07-16T20:29:04.060499Z","price_level":"64138.61","new_quantity":"0.12472986"},{"side":"bid","event_time":"2026-07-16T20:29:04.060499Z","price_level":"64138.16","new_quantity":"0"},{"side":"bid","event_time":"2026-07-16T20:29:04.060499Z","price_level":"64137.92","new_quantity":"0"},{"side":"offer","event_time":"2026-07-16T20:29:04.060499Z","price_level":"64150.76","new_quantity":"0"},{"side":"offer","event_time":"2026-07-16T20:29:04.060499Z","price_level":"64151.12","new_quantity":"0"},{"side":"offer","event_time":"2026-07-16T20:29:04.060499Z","price_level":"64152.37","new_quantity":"0"},{"side":"offer","event_time":"2026-07-16T20:29:04.060499Z","price_level":"64152.4","new_quantity":"0"},{"side":"offer","event_time":"2026-07-16T20:29:04.060499Z","price_level":"65015.48","new_quantity":"0.00583"},{"side":"offer","event_time":"2026-07-16T20:29:04.060499Z","price_level":"65230.03","new_quantity":"0"},{"side":"offer","event_time":"2026-07-16T20:29:04.060499Z","price_level":"65444.65","new_quantity":"0"}]}]}
