{"channel":"l2_data","timestamp":"2026-07-15T03:40:09.233367294Z","sequence_num":136,"events":[{"type":"update","product_id":"BTC-USD","updates":[{"side":"bid","event_time":"2026-07-15T03:40:09.195768Z","price_level":"64589.4","new_quantity":"0.22007132"},{"side":"bid","event_time":"2026-07-15T03:40:09.195768Z","price_level":"64585.5","new_quantity":"0"},{"side":"bid","event_time":"2026-07-15T03:40:09.195768Z","price_level":"64561.05","new_quantity":"0.0391649"},{"side":"bid","event_time":"2026-07-15T03:40:09.195768Z","price_level":"64560.16","new_quantity":"0"},{"side":"bid","event_time":"2026-07-15T03:40:09.195768Z","price_level":"64557.02","new_quantity":"0"},{"side":"bid","event_time":"2026-07-15T03:40:09.195768Z","price_level":"64556.16","new_quantity":"0"},{"side":"bid","event_time":"2026-07-15T03:40:09.195768Z","price_level":"64555.29","new_quantity":"0.93159157"},{"side":"bid","event_time":"2026-07-15T03:40:09.195768Z","price_level":"64554.11","new_quantity":"0"},{"side":"bid","event_time":"2026-07-15T03:40:09.195768Z","price_level":"64551.54","new_quantity":"0.43032523"},{"side":"bid","event_time":"2026-07-15T03:40:09.195768Z","price_level":"64551.53","new_quantity":"0.64001592"},{"side":"bid","event_time":"2026-07-15T03:40:09.195768Z","price_level":"64551.52","new_quantity":"0"},{"side":"bid","event_time":"2026-07-15T03:40:09.195768Z","price_level":"64551.51","new_quantity":"0"},{"side":"bid","event_time":"2026-07-15T03:40:09.195768Z","price_level":"64550.34","new_quantity":"0"},{"side":"bid","event_time":"2026-07-15T03:40:09.195768Z","price_level":"64542.11","new_quantity":"0"},{"side":"bid","event_time":"2026-07-15T03:40:09.195768Z","price_level":"64531.46","new_quantity":"0"},{"side":"bid","event_time":"2026-07-15T03:40:09.195768Z","price_level":"64522.31","new_quantity":"1.9654341"},{"side":"bid","event_time":"2026-07-15T03:40:09.195768Z","price_level":"64522.3","new_quantity":"1.40033652"},{"side":"bid","event_time":"2026-07-15T03:40:09.195768Z","price_level":"64522.29","new_quantity":"0"},{"side":"bid","event_time":"2026-07-15T03:40:09.195768Z","price_level":"64522.28","new_quantity":"0"},{"side":"bid","event_time":"2026-07-15T03:40:09.195768Z","price_level":"64520.68","new_quantity":"0"},{"side":"bid","event_time":"2026-07-15T03:40:09.195768Z","price_level":"64500","new_quantity":"0.11110077"},{"side":"bid","event_time":"2026-07-15T03:40:09.195768Z","price_level":"64356.05","new_quantity":"0.00583"},{"side":"bid","event_time":"2026-07-15T03:40:09.195768Z","price_level":"64355.67","new_quantity":"0"},{"side":"bid","event_time":"2026-07-15T03:40:09.195768Z","price_level":"64348.86","new_quantity":"0"},{"side":"bid","event_time":"2026-07-15T03:40:09.195768Z","price_level":"64140.88","new_quantity":"0.00583"},{"side":"bid","event_time":"2026-07-15T03:40:09.195768Z","price_level":"63069.09","new_quantity":"0"},{"side":"offer","event_time":"2026-07-15T03:40:09.195768Z","price_level":"64589.41","new_quantity":"0.01354553"},{"side":"offer","event_time":"2026-07-15T03:40:09.195768Z","price_level":"64592","new_quantity":"0"},{"side":"offer","event_time":"2026-07-15T03:40:09.195768Z","price_level":"64592.5","new_quantity":"0"},{"side":"offer","event_time":"2026-07-15T03:40:09.195768Z","price_level":"64593.78","new_quantity":"0"},{"side":"offer","event_time":"2026-07-15T03:40:09.195768Z","price_level":"64593.79","new_quantity":"0.12976178"},{"side":"offer","event_time":"2026-07-15T03:40:09.195768Z","price_level":"64593.8","new_quantity":"0"},{"side":"offer","event_time":"2026-07-15T03:40:09.195768Z","price_level":"64597.36","new_quantity":"0"},{"side":"offer","event_time":"2026-07-15T03:40:09.195768Z","price_level":"64597.37","new_quantity":"0.00772597"},{"side":"offer","event_time":"2026-07-15T03:40:09.195768Z","price_level":"64603.25","new_quantity":"0.21855577"},{"side":"offer","event_time":"2026-07-15T03:40:09.195768Z","price_level":"64603.26","new_quantity":"0.179558"},{"side":"offer","event_time":"2026-07-15T03:40:09.195768Z","price_level":"64613.25","new_quantity":"0.97392352"},{"side":"offer","event_time":"2026-07-15T03:40:09.195768Z","price_level":"64615.5","new_quantity":"1"},{"side":"offer","event_time":"2026-07-15T03:40:09.195768Z","price_level":"64644.7","new_quantity":"1.12951234"},{"side":"offer","event_time":"2026-07-15T03:40:09.195768Z","price_level":"64644.71","new_quantity":"1.41876207"},{"side":"offer","event_time":"2026-07-15T03:40:09.195768Z","price_level":"64644.72","new_quantity":"0.45858961"},{"side":"offer","event_time":"2026-07-15T03:40:09.195768Z","price_level":"64644.73","new_quantity":"0"},{"side":"offer","event_time":"2026-07-15T03:40:09.195768Z","price_level":"64644.74","new_quantity":"0"},{"side":"offer","event_time":"2026-07-15T03:40:09.195768Z","price_level":"64647.31","new_quantity":"0.01846839"},{"side":"offer","event_time":"2026-07-15T03:40:09.195768Z","price_level":"64647.32","new_quantity":"0"},{"side":"offer","event_time":"2026-07-15T03:40:09.195768Z","price_level":"64648.75","new_quantity":"1.2866016"},{"side":"offer","event_time":"2026-07-15T03:40:09.195768Z","price_level":"64648.76","new_quantity":"2.08919841"},{"side":"offer","event_time":"2026-07-15T03:40:09.195768Z","price_level":"64648.77","new_quantity":"0"},{"side":"offer","event_time":"2026-07-15T03:40:09.195768Z","price_level":"64651.72","new_quantity":"0"},{"side":"offer","event_time":"2026-07-15T03:40:09.195768Z","price_level":"64651.73","new_quantity":"0.0015533"},{"side":"offer","event_time":"2026-07-15T03:40:09.195768Z","price_level":"64654.25","new_quantity":"0.83103585"},{"side":"offer","event_time":"2026-07-15T03:40:09.195768Z","price_level":"64841.99","new_quantity":"0.01987674"},{"side":"offer","event_time":"2026-07-15T03:40:09.195768Z","price_level":"65899.6","new_quantity":"0.00583"},{"side":"offer","event_time":"2026-07-15T03:40:09.195768Z","price_level":"65899.96","new_quantity":"0"},{"side":"offer","event_time":"2026-07-15T03:40:09.195768Z","price_level":"65900.53","new_quantity":"0"}]}]}
{"channel":"l2_data","timestamp":"2026-07-15T03:40:09.283586587Z","sequence_num":137,"events":[{"type":"update","product_id":"BTC-USD","updates":[{"side":"bid","event_time":"2026-07-15T03:40:09.237588Z","price_level":"64589.02","new_quantity":"0.12386005"},{"side":"bid","event_time":"2026-07-15T03:40:09.237588Z","price_level":"64588.01","new_quantity":"0.04816084"},{"side":"bid","event_time":"2026-07-15T03:40:09.237588Z","price_level":"64587","new_quantity":"1"},{"side":"bid","event_time":"2026-07-15T03:40:09.237588Z","price_level":"64586.68","new_quantity":"0"},{"side":"bid","event_time":"2026-07-15T03:40:09.237588Z","price_level":"64586.67","new_quantity":"0"},{"side":"bid","event_time":"2026-07-15T03:40:09.237588Z","price_level":"64571.68","new_quantity":"0.00583"},{"side":"bid","event_time":"2026-07-15T03:40:09.237588Z","price_level":"64571.05","new_quantity":"0.00030314"},{"side":"bid","event_time":"2026-07-15T03:40:09.237588Z","price_level":"64570.74","new_quantity":"0"},{"side":"bid","event_time":"2026-07-15T03:40:09.237588Z","price_level":"64568.97","new_quantity":"0.00060628"},{"side":"bid","event_time":"2026-07-15T03:40:09.237588Z","price_level":"64564.8","new_quantity":"0.00121256"},{"side":"bid","event_time":"2026-07-15T03:40:09.237588Z","price_level":"64556.46","new_quantity":"0.00242512"},{"side":"bid","event_time":"2026-07-15T03:40:09.237588Z","price_level":"64548.2","new_quantity":"0.269289"},{"side":"bid","event_time":"2026-07-15T03:40:09.237588Z","price_level":"64548.19","new_quantity":"0.448725"},{"side":"bid","event_time":"2026-07-15T03:40:09.237588Z","price_level":"64546.03","new_quantity":"0.0030314"},{"side":"bid","event_time":"2026-07-15T03:40:09.237588Z","price_level":"64517.35","new_quantity":"0.0304507"},{"side":"bid","event_time":"2026-07-15T03:40:09.237588Z","price_level":"64516.48","new_quantity":"0"},{"side":"bid","event_time":"2026-07-15T03:40:09.237588Z","price_level":"64506.15","new_quantity":"3.49306232"},{"side":"bid","event_time":"2026-07-15T03:40:09.237588Z","price_level":"64505","new_quantity":"3"},{"side":"bid","event_time":"2026-07-15T03:40:09.237588Z","price_level":"64356.74","new_quantity":"0.00583"},{"side":"bid","event_time":"2026-07-15T03:40:09.237588Z","price_level":"64356.62","new_quantity":"0.00583"},{"side":"bid","event_time":"2026-07-15T03:40:09.237588Z","price_level":"64356.54","new_quantity":"0"},{"side":"bid","event_time":"2026-07-15T03:40:09.237588Z","price_level":"64356.05","new_quantity":"0"},{"side":"bid","event_time":"2026-07-15T03:40:09.237588Z","price_level":"64142.08","new_quantity":"0.00583"},{"side":"bid","event_time":"2026-07-15T03:40:09.237588Z","price_level":"64141.36","new_quantity":"0"},{"side":"bid","event_time":"2026-07-15T03:40:09.237588Z","price_level":"64140.88","new_quantity":"0"},{"side":"bid","event_time":"2026-07-15T03:40:09.237588Z","price_level":"64134.04","new_quantity":"0"},{"side":"bid","event_time":"2026-07-15T03:40:09.237588Z","price_level":"63284.59","new_quantity":"0.00583"},{"side":"bid","event_time":"2026-07-15T03:40:09.237588Z","price_level":"63284.39","new_quantity":"0"},{"side":"bid","event_time":"2026-07-15T03:40:09.237588Z","price_level":"63284.09","new_quantity":"0"},{"side":"offer","event_time":"2026-07-15T03:40:09.237588Z","price_level":"64592.51","new_quantity":"0.01726217"},{"side":"offer","event_time":"2026-07-15T03:40:09.237588Z","price_level":"64593.18","new_quantity":"0.00159977"},{"side":"offer","event_time":"2026-07-15T03:40:09.237588Z","price_level":"64593.79","new_quantity":"0"},{"side":"offer","event_time":"2026-07-15T03:40:09.237588Z","price_level":"64596.21","new_quantity":"0.12378505"},{"side":"offer","event_time":"2026-07-15T03:40:09.237588Z","price_level":"64597.38","new_quantity":"0"},{"side":"offer","event_time":"2026-07-15T03:40:09.237588Z","price_level":"64597.39","new_quantity":"0.18060038"},{"side":"offer","event_time":"2026-07-15T03:40:09.237588Z","price_level":"64597.8","new_quantity":"0"},{"side":"offer","event_time":"2026-07-15T03:40:09.237588Z","price_level":"64599.2","new_quantity":"0.15477586"},{"side":"offer","event_time":"2026-07-15T03:40:09.237588Z","price_level":"64601.69","new_quantity":"0.04656107"},{"side":"offer","event_time":"2026-07-15T03:40:09.237588Z","price_level":"64603.26","new_quantity":"0"},{"side":"offer","event_time":"2026-07-15T03:40:09.237588Z","price_level":"64603.91","new_quantity":"0.00038328"},{"side":"offer","event_time":"2026-07-15T03:40:09.237588Z","price_level":"64604.61","new_quantity":"0.179558"},{"side":"offer","event_time":"2026-07-15T03:40:09.237588Z","price_level":"64605.98","new_quantity":"0"},{"side":"offer","event_time":"2026-07-15T03:40:09.237588Z","price_level":"64606.95","new_quantity":"0.00076656"},{"side":"offer","event_time":"2026-07-15T03:40:09.237588Z","price_level":"64613.79","new_quantity":"0.00583"},{"side":"offer","event_time":"2026-07-15T03:40:09.237588Z","price_level":"64820.6","new_quantity":"0"},{"side":"offer","event_time":"2026-07-15T03:40:09.237588Z","price_level":"64828.33","new_quantity":"0.00583"},{"side":"offer","event_time":"2026-07-15T03:40:09.237588Z","price_level":"64828.68","new_quantity":"0"},{"side":"offer","event_time":"2026-07-15T03:40:09.237588Z","price_level":"65035.42","new_quantity":"0"},{"side":"offer","event_time":"2026-07-15T03:40:09.237588Z","price_level":"65043.19","new_quantity":"0.00583"},{"side":"offer","event_time":"2026-07-15T03:40:09.237588Z","price_level":"65463.89","new_quantity":"0"},{"side":"offer","event_time":"2026-07-15T03:40:09.237588Z","price_level":"65471.51","new_quantity":"0.00583"},{"side":"offer","event_time":"2026-07-15T03:40:09.237588Z","price_level":"65679.03","new_quantity":"0"},{"side":"offer","event_time":"2026-07-15T03:40:09.237588Z","price_level":"65686.37","new_quantity":"0.00583"},{"side":"offer","event_time":"2026-07-15T03:40:09.237588Z","price_level":"65899.6","new_quantity":"0"},{"side":"offer","event_time":"2026-07-15T03:40:09.237588Z","price_level":"65900.91","new_quantity":"0.00583"}]}]}
{"channel":"l2_data","timestamp":"2026-07-15T03:40:09.33339572Z","sequence_num":138,"events":[{"type":"update","product_id":"BTC-USD","updates":[{"side":"bid","event_time":"2026-07-15T03:40:09.297091Z","price_level":"64589.02","new_quantity":"0"},{"side":"bid","event_time":"2026-07-15T03:40:09.297091Z","price_level":"64587.98","new_quantity":"0.12386203"},{"side":"bid","event_time":"2026-07-15T03:40:09.297091Z","price_level":"64587","new_quantity":"0"},{"side":"bid","event_time":"2026-07-15T03:40:09.297091Z","price_level":"64585.5","new_quantity":"1"},{"side":"bid","event_time":"2026-07-15T03:40:09.297091Z","price_level":"64559.23","new_quantity":"0.00077403"},{"side":"bid","event_time":"2026-07-15T03:40:09.297091Z","price_level":"64556.17","new_quantity":"0"},{"side":"bid","event_time":"2026-07-15T03:40:09.297091Z","price_level":"64551.56","new_quantity":"0.38208938"},{"side":"bid","event_time":"2026-07-15T03:40:09.297091Z","price_level":"64551.55","new_quantity":"0.64001572"},{"side":"bid","event_time":"2026-07-15T03:40:09.297091Z","price_level":"64551.54","new_quantity":"0"},{"side":"bid","event_time":"2026-07-15T03:40:09.297091Z","price_level":"64551.53","new_quantity":"0"},{"side":"bid","event_time":"2026-07-15T03:40:09.297091Z","price_level":"64550.21","new_quantity":"0.04719266"},{"side":"bid","event_time":"2026-07-15T03:40:09.297091Z","price_level":"64522.33","new_quantity":"1.69759338"},{"side":"bid","event_time":"2026-07-15T03:40:09.297091Z","price_level":"64522.32","new_quantity":"1.40033609"},{"side":"bid","event_time":"2026-07-15T03:40:09.297091Z","price_level":"64522.31","new_quantity":"0"},{"side":"bid","event_time":"2026-07-15T03:40:09.297091Z","price_level":"64522.3","new_quantity":"0"},{"side":"bid","event_time":"2026-07-15T03:40:09.297091Z","price_level":"64462.97","new_quantity":"0.00030964"},{"side":"bid","event_time":"2026-07-15T03:40:09.297091Z","price_level":"64324.64","new_quantity":"0"},{"side":"bid","event_time":"2026-07-15T03:40:09.297091Z","price_level":"56515.73","new_quantity":"0.0132912"},{"side":"offer","event_time":"2026-07-15T03:40:09.297091Z","price_level":"64596.2","new_quantity":"0.10514292"},{"side":"offer","event_time":"2026-07-15T03:40:09.297091Z","price_level":"64597.37","new_quantity":"0"},{"side":"offer","event_time":"2026-07-15T03:40:09.297091Z","price_level":"64597.38","new_quantity":"0.00772597"},{"side":"offer","event_time":"2026-07-15T03:40:09.297091Z","price_level":"64597.39","new_quantity":"0.18060162"},{"side":"offer","event_time":"2026-07-15T03:40:09.297091Z","price_level":"64598.13","new_quantity":"0.12384261"},{"side":"offer","event_time":"2026-07-15T03:40:09.297091Z","price_level":"64599.2","new_quantity":"0.03093532"},{"side":"offer","event_time":"2026-07-15T03:40:09.297091Z","price_level":"64603.25","new_quantity":"0.10810795"},{"side":"offer","event_time":"2026-07-15T03:40:09.297091Z","price_level":"64603.88","new_quantity":"0.0015533"},{"side":"offer","event_time":"2026-07-15T03:40:09.297091Z","price_level":"64604.61","new_quantity":"0"},{"side":"offer","event_time":"2026-07-15T03:40:09.297091Z","price_level":"64605.34","new_quantity":"0.00096647"},{"side":"offer","event_time":"2026-07-15T03:40:09.297091Z","price_level":"64605.42","new_quantity":"0"},{"side":"offer","event_time":"2026-07-15T03:40:09.297091Z","price_level":"64613.25","new_quantity":"0.37688543"},{"side":"offer","event_time":"2026-07-15T03:40:09.297091Z","price_level":"64615.13","new_quantity":"0.14"},{"side":"offer","event_time":"2026-07-15T03:40:09.297091Z","price_level":"64615.5","new_quantity":"0"},{"side":"offer","event_time":"2026-07-15T03:40:09.297091Z","price_level":"64644.68","new_quantity":"1.1295126"},{"side":"offer","event_time":"2026-07-15T03:40:09.297091Z","price_level":"64644.69","new_quantity":"1.41876251"},{"side":"offer","event_time":"2026-07-15T03:40:09.297091Z","price_level":"64644.7","new_quantity":"0"},{"side":"offer","event_time":"2026-07-15T03:40:09.297091Z","price_level":"64644.71","new_quantity":"0"}]}]}
{"channel":"l2_data","timestamp":"2026-07-15T03:40:09.381694438Z","sequence_num":139,"events":[{"type":"update","product_id":"BTC-USD","updates":[{"side":"bid","event_time":"2026-07-15T03:40:09.318579Z","price_level":"64581.56","new_quantity":"0.02543037"},{"side":"bid","event_time":"2026-07-15T03:40:09.318579Z","price_level":"64356.62","new_quantity":"0"},{"side":"bid","event_time":"2026-07-15T03:40:09.318579Z","price_level":"63926.45","new_quantity":"0.00583"},{"side":"bid","event_time":"2026-07-15T03:40:09.318579Z","price_level":"63926.39","new_quantity":"0.00583"},{"side":"bid","event_time":"2026-07-15T03:40:09.318579Z","price_level":"63919.43","new_quantity":"0"},{"side":"offer","event_time":"2026-07-15T03:40:09.318579Z","price_level":"64612.96","new_quantity":"0.00583"},{"side":"offer","event_time":"2026-07-15T03:40:09.318579Z","price_level":"64613.25","new_quantity":"1.04904403"},{"side":"offer","event_time":"2026-07-15T03:40:09.318579Z","price_level":"64615.5","new_quantity":"1"},{"side":"offer","event_time":"2026-07-15T03:40:09.318579Z","price_level":"64629.52","new_quantity":"0.00077402"},{"side":"offer","event_time":"2026-07-15T03:40:09.318579Z","price_level":"64631.47","new_quantity":"0"},{"side":"offer","event_time":"2026-07-15T03:40:09.318579Z","price_level":"64805.22","new_quantity":"0"},{"side":"offer","event_time":"2026-07-15T03:40:09.318579Z","price_level":"65249.38","new_quantity":"0"},{"side":"offer","event_time":"2026-07-15T03:40:09.318579Z","price_level":"65470.68","new_quantity":"0.00583"},{"side":"offer","event_time":"2026-07-15T03:40:09.318579Z","price_level":"65686.37","new_quantity":"0"},{"side":"offer","event_time":"2026-07-15T03:40:09.318579Z","price_level":"65900.91","new_quantity":"0"}]}]}
{"channel":"l2_data","timestamp":"2026-07-15T03:40:09.432608467Z","sequence_num":140,"events":[{"type":"update","product_id":"BTC-USD","updates":[{"side":"bid","event_time":"2026-07-15T03:40:09.393155Z","price_level":"64561.15","new_quantity":"0"},{"side":"bid","event_time":"2026-07-15T03:40:09.393155Z","price_level":"64561.14","new_quantity":"0"},{"side":"bid","event_time":"2026-07-15T03:40:09.393155Z","price_level":"64561.05","new_quantity":"0"},{"side":"bid","event_time":"2026-07-15T03:40:09.393155Z","price_level":"64551.58","new_quantity":"0.38208927"},{"side":"bid","event_time":"2026-07-15T03:40:09.393155Z","price_level":"64551.57","new_quantity":"0.64001552"},{"side":"bid","event_time":"2026-07-15T03:40:09.393155Z","price_level":"64551.56","new_quantity":"0"},{"side":"bid","event_time":"2026-07-15T03:40:09.393155Z","price_level":"64551.55","new_quantity":"0"},{"side":"bid","event_time":"2026-07-15T03:40:09.393155Z","price_level":"56515.73","new_quantity":"0"},{"side":"offer","event_time":"2026-07-15T03:40:09.393155Z","price_level":"64592.51","new_quantity":"0"},{"side":"offer","event_time":"2026-07-15T03:40:09.393155Z","price_level":"64597.38","new_quantity":"0"},{"side":"offer","event_time":"2026-07-15T03:40:09.393155Z","price_level":"64597.39","new_quantity":"0.18060026"},{"side":"offer","event_time":"2026-07-15T03:40:09.393155Z","price_level":"64597.49","new_quantity":"0.00772597"},{"side":"offer","event_time":"2026-07-15T03:40:09.393155Z","price_level":"64598.13","new_quantity":"0"},{"side":"offer","event_time":"2026-07-15T03:40:09.393155Z","price_level":"64599.32","new_quantity":"0.12384033"},{"side":"offer","event_time":"2026-07-15T03:40:09.393155Z","price_level":"64605.22","new_quantity":"0.00096647"},{"side":"offer","event_time":"2026-07-15T03:40:09.393155Z","price_level":"64605.34","new_quantity":"0"},{"side":"offer","event_time":"2026-07-15T03:40:09.393155Z","price_level":"64615.13","new_quantity":"0.06"},{"side":"offer","event_time":"2026-07-15T03:40:09.393155Z","price_level":"64841.99","new_quantity":"0"}]}]}
{"channel":"l2_data","timestamp":"2026-07-15T03:40:09.483088183Z","sequence_num":141,"events":[{"type":"update","product_id":"BTC-USD","updates":[{"side":"bid","event_time":"2026-07-15T03:40:09.430939Z","price_level":"64588.02","new_quantity":"0.00159977"},{"side":"bid","event_time":"2026-07-15T03:40:09.430939Z","price_level":"64588.01","new_quantity":"0.04656107"},{"side":"bid","event_time":"2026-07-15T03:40:09.430939Z","price_level":"64561.15","new_quantity":"0.039627"},{"side":"bid","event_time":"2026-07-15T03:40:09.430939Z","price_level":"64522.35","new_quantity":"1.69759312"},{"side":"bid","event_time":"2026-07-15T03:40:09.430939Z","price_level":"64522.34","new_quantity":"1.40033565"},{"side":"bid","event_time":"2026-07-15T03:40:09.430939Z","price_level":"64522.33","new_quantity":"0"},{"side":"bid","event_time":"2026-07-15T03:40:09.430939Z","price_level":"64522.32","new_quantity":"0"},{"side":"bid","event_time":"2026-07-15T03:40:09.430939Z","price_level":"63926.39","new_quantity":"0"},{"side":"offer","event_time":"2026-07-15T03:40:09.430939Z","price_level":"64589.41","new_quantity":"0.01380517"},{"side":"offer","event_time":"2026-07-15T03:40:09.430939Z","price_level":"64596.19","new_quantity":"0.04656107"},{"side":"offer","event_time":"2026-07-15T03:40:09.430939Z","price_level":"64605.14","new_quantity":"0.00096647"},{"side":"offer","event_time":"2026-07-15T03:40:09.430939Z","price_level":"64605.22","new_quantity":"0"},{"side":"offer","event_time":"2026-07-15T03:40:09.430939Z","price_level":"64613.79","new_quantity":"0"},{"side":"offer","event_time":"2026-07-15T03:40:09.430939Z","price_level":"64623.81","new_quantity":"0.00114825"},{"side":"offer","event_time":"2026-07-15T03:40:09.430939Z","price_level":"64644.66","new_quantity":"1.13046027"},{"side":"offer","event_time":"2026-07-15T03:40:09.430939Z","price_level":"64644.67","new_quantity":"1.42034989"},{"side":"offer","event_time":"2026-07-15T03:40:09.430939Z","price_level":"64644.68","new_quantity":"0"},{"side":"offer","event_time":"2026-07-15T03:40:09.430939Z","price_level":"64644.69","new_quantity":"0"},{"side":"offer","event_time":"2026-07-15T03:40:09.430939Z","price_level":"64657.23","new_quantity":"0.01615943"},{"side":"offer","event_time":"2026-07-15T03:40:09.430939Z","price_level":"64672.43","new_quantity":"0"},{"side":"offer","event_time":"2026-07-15T03:40:09.430939Z","price_level":"64685.5","new_quantity":"0"},{"side":"offer","event_time":"2026-07-15T03:40:09.430939Z","price_level":"64830.55","new_quantity":"0.86099061"},{"side":"offer","event_time":"2026-07-15T03:40:09.430939Z","price_level":"65471.51","new_quantity":"0"}]}]}
{"channel":"l2_data","timestamp":"2026-07-15T03:40:09.532537544Z","sequence_num":142,"events":[{"type":"update","product_id":"BTC-USD","updates":[{"side":"bid","event_time":"2026-07-15T03:40:09.50459Z","price_level":"64585.51","new_quantity":"0.68376699"},{"side":"bid","event_time":"2026-07-15T03:40:09.50459Z","price_level":"64583.82","new_quantity":"0.19506197"},{"side":"bid","event_time":"2026-07-15T03:40:09.50459Z","price_level":"64581.56","new_quantity":"0"},{"side":"bid","event_time":"2026-07-15T03:40:09.50459Z","price_level":"64551.6","new_quantity":"0.38208915"},{"side":"bid","event_time":"2026-07-15T03:40:09.50459Z","price_level":"64551.59","new_quantity":"0.64001532"},{"side":"bid","event_time":"2026-07-15T03:40:09.50459Z","price_level":"64551.58","new_quantity":"0"},{"side":"bid","event_time":"2026-07-15T03:40:09.50459Z","price_level":"64551.57","new_quantity":"0"},{"side":"bid","event_time":"2026-07-15T03:40:09.50459Z","price_level":"64522.37","new_quantity":"1.69759286"},{"side":"bid","event_time":"2026-07-15T03:40:09.50459Z","price_level":"64522.36","new_quantity":"1.40033522"},{"side":"bid","event_time":"2026-07-15T03:40:09.50459Z","price_level":"64522.35","new_quantity":"0"},{"side":"bid","event_time":"2026-07-15T03:40:09.50459Z","price_level":"64522.34","new_quantity":"0"},{"side":"offer","event_time":"2026-07-15T03:40:09.50459Z","price_level":"64589.41","new_quantity":"0.01404483"},{"side":"offer","event_time":"2026-07-15T03:40:09.50459Z","price_level":"64597.39","new_quantity":"0.18521367"},{"side":"offer","event_time":"2026-07-15T03:40:09.50459Z","price_level":"64598.43","new_quantity":"0.12384203"},{"side":"offer","event_time":"2026-07-15T03:40:09.50459Z","price_level":"64599.32","new_quantity":"0"},{"side":"offer","event_time":"2026-07-15T03:40:09.50459Z","price_level":"64610","new_quantity":"0.72495031"},{"side":"offer","event_time":"2026-07-15T03:40:09.50459Z","price_level":"64610.75","new_quantity":"0.04351175"},{"side":"offer","event_time":"2026-07-15T03:40:09.50459Z","price_level":"64611","new_quantity":"1"},{"side":"offer","event_time":"2026-07-15T03:40:09.50459Z","price_level":"64613.25","new_quantity":"0.37688543"},{"side":"offer","event_time":"2026-07-15T03:40:09.50459Z","price_level":"64615.5","new_quantity":"0"},{"side":"offer","event_time":"2026-07-15T03:40:09.50459Z","price_level":"64644.64","new_quantity":"1.13046053"},{"side":"offer","event_time":"2026-07-15T03:40:09.50459Z","price_level":"64644.65","new_quantity":"1.41876339"},{"side":"offer","event_time":"2026-07-15T03:40:09.50459Z","price_level":"64644.66","new_quantity":"0"},{"side":"offer","event_time":"2026-07-15T03:40:09.50459Z","price_level":"64644.67","new_quantity":"0.00158694"},{"side":"offer","event_time":"2026-07-15T03:40:09.50459Z","price_level":"64995.57","new_quantity":"0.01061683"}]}]}
{"channel":"l2_data","timestamp":"2026-07-15T03:40:09.58169212Z","sequence_num":143,"events":[{"type":"update","product_id":"BTC-USD","updates":[{"side":"bid","event_time":"2026-07-15T03:40:09.547089Z","price_level":"64548.9","new_quantity":"0.00154699"},{"side":"bid","event_time":"2026-07-15T03:40:09.547089Z","price_level":"64542.45","new_quantity":"0.00773495"},{"side":"bid","event_time":"2026-07-15T03:40:09.547089Z","price_level":"63939.87","new_quantity":"0.03910587"},{"side":"bid","event_time":"2026-07-15T03:40:09.547089Z","price_level":"51671.52","new_quantity":"0.0002"},{"side":"offer","event_time":"2026-07-15T03:40:09.547089Z","price_level":"64592","new_quantity":"0.0232"},{"side":"offer","event_time":"2026-07-15T03:40:09.547089Z","price_level":"64592.61","new_quantity":"0.01354553"},{"side":"offer","event_time":"2026-07-15T03:40:09.547089Z","price_level":"64593.98","new_quantity":"0.23145842"},{"side":"offer","event_time":"2026-07-15T03:40:09.547089Z","price_level":"64593.99","new_quantity":"0.12378505"},{"side":"offer","event_time":"2026-07-15T03:40:09.547089Z","price_level":"64596.2","new_quantity":"0"},{"side":"offer","event_time":"2026-07-15T03:40:09.547089Z","price_level":"64604.96","new_quantity":"0.00096647"},{"side":"offer","event_time":"2026-07-15T03:40:09.547089Z","price_level":"64605.14","new_quantity":"0"},{"side":"offer","event_time":"2026-07-15T03:40:09.547089Z","price_level":"64615.13","new_quantity":"0.14"}]}]}
{"channel":"l2_data","timestamp":"2026-07-15T03:40:09.631436796Z","sequence_num":144,"events":[{"type":"update","product_id":"BTC-USD","updates":[{"side":"bid","event_time":"2026-07-15T03:40:09.587699Z","price_level":"64584.04","new_quantity":"0"},{"side":"bid","event_time":"2026-07-15T03:40:09.587699Z","price_level":"64551.62","new_quantity":"0.38208903"},{"side":"bid","event_time":"2026-07-15T03:40:09.587699Z","price_level":"64551.61","new_quantity":"0.64001512"},{"side":"bid","event_time":"2026-07-15T03:40:09.587699Z","price_level":"64551.6","new_quantity":"0"},{"side":"bid","event_time":"2026-07-15T03:40:09.587699Z","price_level":"64551.59","new_quantity":"0"},{"side":"bid","event_time":"2026-07-15T03:40:09.587699Z","price_level":"64409.61","new_quantity":"0.902084"},{"side":"bid","event_time":"2026-07-15T03:40:09.587699Z","price_level":"56515.73","new_quantity":"0.0132912"},{"side":"offer","event_time":"2026-07-15T03:40:09.587699Z","price_level":"64604.87","new_quantity":"0.00096647"},{"side":"offer","event_time":"2026-07-15T03:40:09.587699Z","price_level":"64604.96","new_quantity":"0"},{"side":"offer","event_time":"2026-07-15T03:40:09.587699Z","price_level":"64794.82","new_quantity":"0.790405"},{"side":"offer","event_time":"2026-07-15T03:40:09.587699Z","price_level":"64995.57","new_quantity":"0"}]}]}
{"channel":"l2_data","timestamp":"2026-07-15T03:40:09.681697415Z","sequence_num":145,"events":[{"type":"update","product_id":"BTC-USD","updates":[{"side":"bid","event_time":"2026-07-15T03:40:09.629839Z","price_level":"64589.4","new_quantity":"0.22007128"},{"side":"bid","event_time":"2026-07-15T03:40:09.629839Z","price_level":"64561.15","new_quantity":"0.41011317"},{"side":"bid","event_time":"2026-07-15T03:40:09.629839Z","price_level":"64560.45","new_quantity":"0.66000132"},{"side":"bid","event_time":"2026-07-15T03:40:09.629839Z","price_level":"64522.39","new_quantity":"1.6975926"},{"side":"bid","event_time":"2026-07-15T03:40:09.629839Z","price_level":"64522.38","new_quantity":"1.40033479"},{"side":"bid","event_time":"2026-07-15T03:40:09.629839Z","price_level":"64522.37","new_quantity":"0"},{"side":"bid","event_time":"2026-07-15T03:40:09.629839Z","price_level":"64522.36","new_quantity":"0"},{"side":"offer","event_time":"2026-07-15T03:40:09.629839Z","price_level":"64604.77","new_quantity":"0.00096647"},{"side":"offer","event_time":"2026-07-15T03:40:09.629839Z","price_level":"64604.87","new_quantity":"0"},{"side":"offer","event_time":"2026-07-15T03:40:09.629839Z","price_level":"64644.62","new_quantity":"1.13046079"},{"side":"offer","event_time":"2026-07-15T03:40:09.629839Z","price_level":"64644.63","new_quantity":"1.41876383"},{"side":"offer","event_time":"2026-07-15T03:40:09.629839Z","price_level":"64644.64","new_quantity":"0"},{"side":"offer","event_time":"2026-07-15T03:40:09.629839Z","price_level":"64644.65","new_quantity":"0"}]}]}
{"channel":"market_trades","timestamp":"2026-07-15T03:40:09.685641247Z","sequence_num":146,"events":[{"type":"update","trades":[{"product_id":"BTC-USD","trade_id":"1056309453","price":"64589.4","size":"0.00000004","time":"2026-07-15T03:40:09.626148Z","side":"BUY"}]}]}
{"channel":"l2_data","timestamp":"2026-07-15T03:40:09.732094471Z","sequence_num":147,"events":[{"type":"update","product_id":"BTC-USD","updates":[{"side":"bid","event_time":"2026-07-15T03:40:09.681234Z","price_level":"64588.03","new_quantity":"0.00159977"},{"side":"bid","event_time":"2026-07-15T03:40:09.681234Z","price_level":"64588.02","new_quantity":"0.02"},{"side":"bid","event_time":"2026-07-15T03:40:09.681234Z","price_level":"64585.52","new_quantity":"0.03093532"},{"side":"bid","event_time":"2026-07-15T03:40:09.681234Z","price_level":"64561.15","new_quantity":"0.039627"},{"side":"bid","event_time":"2026-07-15T03:40:09.681234Z","price_level":"64560.45","new_quantity":"0.03093532"},{"side":"bid","event_time":"2026-07-15T03:40:09.681234Z","price_level":"64551.64","new_quantity":"0.38390032"},{"side":"bid","event_time":"2026-07-15T03:40:09.681234Z","price_level":"64551.63","new_quantity":"0.64304912"},{"side":"bid","event_time":"2026-07-15T03:40:09.681234Z","price_level":"64551.62","new_quantity":"0"},{"side":"bid","event_time":"2026-07-15T03:40:09.681234Z","price_level":"64551.61","new_quantity":"0"},{"side":"bid","event_time":"2026-07-15T03:40:09.681234Z","price_level":"64548.21","new_quantity":"0.00077403"},{"side":"bid","event_time":"2026-07-15T03:40:09.681234Z","price_level":"64546.61","new_quantity":"0"},{"side":"bid","event_time":"2026-07-15T03:40:09.681234Z","price_level":"56515.73","new_quantity":"0"},{"side":"offer","event_time":"2026-07-15T03:40:09.681234Z","price_level":"64592.61","new_quantity":"0"},{"side":"offer","event_time":"2026-07-15T03:40:09.681234Z","price_level":"64604.62","new_quantity":"0.02275547"},{"side":"offer","event_time":"2026-07-15T03:40:09.681234Z","price_level":"64604.77","new_quantity":"0"},{"side":"offer","event_time":"2026-07-15T03:40:09.681234Z","price_level":"64610","new_quantity":"0.12954907"},{"side":"offer","event_time":"2026-07-15T03:40:09.681234Z","price_level":"64611","new_quantity":"0"},{"side":"offer","event_time":"2026-07-15T03:40:09.681234Z","price_level":"64654.1","new_quantity":"1.64271287"},{"side":"offer","event_time":"2026-07-15T03:40:09.681234Z","price_level":"64654.11","new_quantity":"1.359593"},{"side":"offer","event_time":"2026-07-15T03:40:09.681234Z","price_level":"64654.25","new_quantity":"0"},{"side":"offer","event_time":"2026-07-15T03:40:09.681234Z","price_level":"64669.41","new_quantity":"5.978745"}]}]}
{"channel":"l2_data","timestamp":"2026-07-15T03:40:09.793287726Z","sequence_num":148,"events":[{"type":"update","product_id":"BTC-USD","updates":[{"side":"bid","event_time":"2026-07-15T03:40:09.730568Z","price_level":"64576.64","new_quantity":"0.19119859"},{"side":"bid","event_time":"2026-07-15T03:40:09.730568Z","price_level":"64522.41","new_quantity":"1.6719228"},{"side":"bid","event_time":"2026-07-15T03:40:09.730568Z","price_level":"64522.4","new_quantity":"1.40033435"},{"side":"bid","event_time":"2026-07-15T03:40:09.730568Z","price_level":"64522.39","new_quantity":"0"},{"side":"bid","event_time":"2026-07-15T03:40:09.730568Z","price_level":"64522.38","new_quantity":"0"},{"side":"bid","event_time":"2026-07-15T03:40:09.730568Z","price_level":"64520.12","new_quantity":"0"},{"side":"offer","event_time":"2026-07-15T03:40:09.730568Z","price_level":"64602.4","new_quantity":"0.000018"},{"side":"offer","event_time":"2026-07-15T03:40:09.730568Z","price_level":"64604.54","new_quantity":"0.00096647"},{"side":"offer","event_time":"2026-07-15T03:40:09.730568Z","price_level":"64604.62","new_quantity":"0.021789"},{"side":"offer","event_time":"2026-07-15T03:40:09.730568Z","price_level":"64610","new_quantity":"0.72495031"},{"side":"offer","event_time":"2026-07-15T03:40:09.730568Z","price_level":"64612.5","new_quantity":"1"},{"side":"offer","event_time":"2026-07-15T03:40:09.730568Z","price_level":"64618.22","new_quantity":"0.04441741"},{"side":"offer","event_time":"2026-07-15T03:40:09.730568Z","price_level":"64644.6","new_quantity":"1.13046106"},{"side":"offer","event_time":"2026-07-15T03:40:09.730568Z","price_level":"64644.61","new_quantity":"1.41876427"},{"side":"offer","event_time":"2026-07-15T03:40:09.730568Z","price_level":"64644.62","new_quantity":"0"},{"side":"offer","event_time":"2026-07-15T03:40:09.730568Z","price_level":"64644.63","new_quantity":"0"}]}]}
{"channel":"l2_data","timestamp":"2026-07-15T03:40:09.841443816Z","sequence_num":149,"events":[{"type":"update","product_id":"BTC-USD","updates":[{"side":"bid","event_time":"2026-07-15T03:40:09.806338Z","price_level":"64589.4","new_quantity":"0.22007124"},{"side":"bid","event_time":"2026-07-15T03:40:09.806338Z","price_level":"64588.01","new_quantity":"0.06656107"},{"side":"bid","event_time":"2026-07-15T03:40:09.806338Z","price_level":"64575.54","new_quantity":"0.00077412"},{"side":"bid","event_time":"2026-07-15T03:40:09.806338Z","price_level":"64574.77","new_quantity":"0"},{"side":"bid","event_time":"2026-07-15T03:40:09.806338Z","price_level":"64551.66","new_quantity":"0.38390021"},{"side":"bid","event_time":"2026-07-15T03:40:09.806338Z","price_level":"64551.65","new_quantity":"0.64001473"},{"side":"bid","event_time":"2026-07-15T03:40:09.806338Z","price_level":"64551.64","new_quantity":"0"},{"side":"bid","event_time":"2026-07-15T03:40:09.806338Z","price_level":"64551.63","new_quantity":"0.00303419"},{"side":"bid","event_time":"2026-07-15T03:40:09.806338Z","price_level":"64546.09","new_quantity":"0.00158694"},{"side":"bid","event_time":"2026-07-15T03:40:09.806338Z","price_level":"64536.16","new_quantity":"0"},{"side":"bid","event_time":"2026-07-15T03:40:09.806338Z","price_level":"64517.35","new_quantity":"0"},{"side":"bid","event_time":"2026-07-15T03:40:09.806338Z","price_level":"64516.75","new_quantity":"0"},{"side":"bid","event_time":"2026-07-15T03:40:09.806338Z","price_level":"64490.16","new_quantity":"0.01085313"},{"side":"offer","event_time":"2026-07-15T03:40:09.806338Z","price_level":"64592","new_quantity":"0"},{"side":"offer","event_time":"2026-07-15T03:40:09.806338Z","price_level":"64593.18","new_quantity":"0"},{"side":"offer","event_time":"2026-07-15T03:40:09.806338Z","price_level":"64593.97","new_quantity":"0.00159977"},{"side":"offer","event_time":"2026-07-15T03:40:09.806338Z","price_level":"64604.32","new_quantity":"0.00096647"},{"side":"offer","event_time":"2026-07-15T03:40:09.806338Z","price_level":"64604.42","new_quantity":"0"},{"side":"offer","event_time":"2026-07-15T03:40:09.806338Z","price_level":"64604.54","new_quantity":"0"},{"side":"offer","event_time":"2026-07-15T03:40:09.806338Z","price_level":"64614.74","new_quantity":"0.06795"},{"side":"offer","event_time":"2026-07-15T03:40:09.806338Z","price_level":"64615.13","new_quantity":"0.02"}]}]}
{"channel":"market_trades","timestamp":"2026-07-15T03:40:09.883249233Z","sequence_num":150,"events":[{"type":"update","trades":[{"product_id":"BTC-USD","trade_id":"1056309454","price":"64589.4","size":"0.00000004","time":"2026-07-15T03:40:09.775385Z","side":"BUY"}]}]}
{"channel":"l2_data","timestamp":"2026-07-15T03:40:09.899712133Z","sequence_num":151,"events":[{"type":"update","product_id":"BTC-USD","updates":[{"side":"bid","event_time":"2026-07-15T03:40:09.852816Z","price_level":"64522.43","new_quantity":"1.67192255"},{"side":"bid","event_time":"2026-07-15T03:40:09.852816Z","price_level":"64522.42","new_quantity":"1.40033392"},{"side":"bid","event_time":"2026-07-15T03:40:09.852816Z","price_level":"64522.41","new_quantity":"0"},{"side":"bid","event_time":"2026-07-15T03:40:09.852816Z","price_level":"64522.4","new_quantity":"0"},{"side":"bid","event_time":"2026-07-15T03:40:09.852816Z","price_level":"51671.52","new_quantity":"0"},{"side":"offer","event_time":"2026-07-15T03:40:09.852816Z","price_level":"64592.64","new_quantity":"0.01404483"},{"side":"offer","event_time":"2026-07-15T03:40:09.852816Z","price_level":"64604.32","new_quantity":"0"},{"side":"offer","event_time":"2026-07-15T03:40:09.852816Z","price_level":"64610","new_quantity":"0.12954907"},{"side":"offer","event_time":"2026-07-15T03:40:09.852816Z","price_level":"64612.5","new_quantity":"0"},{"side":"offer","event_time":"2026-07-15T03:40:09.852816Z","price_level":"64615.11","new_quantity":"0"},{"side":"offer","event_time":"2026-07-15T03:40:09.852816Z","price_level":"64644.58","new_quantity":"1.13046132"},{"side":"offer","event_time":"2026-07-15T03:40:09.852816Z","price_level":"64644.59","new_quantity":"1.41876471"},{"side":"offer","event_time":"2026-07-15T03:40:09.852816Z","price_level":"64644.6","new_quantity":"0"},{"side":"offer","event_time":"2026-07-15T03:40:09.852816Z","price_level":"64644.61","new_quantity":"0"}]}]}
{"channel":"l2_data","timestamp":"2026-07-15T03:40:09.972062903Z","sequence_num":152,"events":[{"type":"update","product_id":"BTC-USD","updates":[{"side":"bid","event_time":"2026-07-15T03:40:09.897876Z","price_level":"64585.8","new_quantity":"0.04644684"},{"side":"bid","event_time":"2026-07-15T03:40:09.897876Z","price_level":"64580.49","new_quantity":"0.0483189"},{"side":"bid","event_time":"2026-07-15T03:40:09.897876Z","price_level":"64561.15","new_quantity":"0.37498688"},{"side":"bid","event_time":"2026-07-15T03:40:09.897876Z","price_level":"64560.9","new_quantity":"0.570228"},{"side":"bid","event_time":"2026-07-15T03:40:09.897876Z","price_level":"64551.68","new_quantity":"0.38390009"},{"side":"bid","event_time":"2026-07-15T03:40:09.897876Z","price_level":"64551.67","new_quantity":"0.64001453"},{"side":"bid","event_time":"2026-07-15T03:40:09.897876Z","price_level":"64551.66","new_quantity":"0"},{"side":"bid","event_time":"2026-07-15T03:40:09.897876Z","price_level":"64551.65","new_quantity":"0"},{"side":"bid","event_time":"2026-07-15T03:40:09.897876Z","price_level":"64536.47","new_quantity":"0.20724859"},{"side":"bid","event_time":"2026-07-15T03:40:09.897876Z","price_level":"64535.74","new_quantity":"0.26319879"},{"side":"bid","event_time":"2026-07-15T03:40:09.897876Z","price_level":"56515.73","new_quantity":"0.0132912"},{"side":"offer","event_time":"2026-07-15T03:40:09.897876Z","price_level":"64592","new_quantity":"0.0232"},{"side":"offer","event_time":"2026-07-15T03:40:09.897876Z","price_level":"64595.48","new_quantity":"0.04644684"},{"side":"offer","event_time":"2026-07-15T03:40:09.897876Z","price_level":"64602.57","new_quantity":"0.00096647"},{"side":"offer","event_time":"2026-07-15T03:40:09.897876Z","price_level":"64610","new_quantity":"0.72541246"},{"side":"offer","event_time":"2026-07-15T03:40:09.897876Z","price_level":"64611","new_quantity":"1"},{"side":"offer","event_time":"2026-07-15T03:40:09.897876Z","price_level":"64612.26","new_quantity":"0.00077412"},{"side":"offer","event_time":"2026-07-15T03:40:09.897876Z","price_level":"64644.72","new_quantity":"0"},{"side":"offer","event_time":"2026-07-15T03:40:09.897876Z","price_level":"64645.53","new_quantity":"0.17560881"},{"side":"offer","event_time":"2026-07-15T03:40:09.897876Z","price_level":"64645.54","new_quantity":"0.26319879"},{"side":"offer","event_time":"2026-07-15T03:40:09.897876Z","price_level":"64647.31","new_quantity":"0"},{"side":"offer","event_time":"2026-07-15T03:40:09.897876Z","price_level":"64647.51","new_quantity":"0.45856981"}]}]}
{"channel":"l2_data","timestamp":"2026-07-15T03:40:10.056970032Z","sequence_num":153,"events":[{"type":"update","product_id":"BTC-USD","updates":[{"side":"bid","event_time":"2026-07-15T03:40:09.989748Z","price_level":"64589.4","new_quantity":"0.20007105"},{"side":"bid","event_time":"2026-07-15T03:40:09.989748Z","price_level":"64588.04","new_quantity":"0.02"},{"side":"bid","event_time":"2026-07-15T03:40:09.989748Z","price_level":"64561.15","new_quantity":"0.039627"},{"side":"bid","event_time":"2026-07-15T03:40:09.989748Z","price_level":"64560.9","new_quantity":"0"},{"side":"bid","event_time":"2026-07-15T03:40:09.989748Z","price_level":"64522.45","new_quantity":"1.67192228"},{"side":"bid","event_time":"2026-07-15T03:40:09.989748Z","price_level":"64522.44","new_quantity":"1.40033348"},{"side":"bid","event_time":"2026-07-15T03:40:09.989748Z","price_level":"64522.43","new_quantity":"0"},{"side":"bid","event_time":"2026-07-15T03:40:09.989748Z","price_level":"64522.42","new_quantity":"0"},{"side":"bid","event_time":"2026-07-15T03:40:09.989748Z","price_level":"64454.86","new_quantity":"0.04364"},{"side":"bid","event_time":"2026-07-15T03:40:09.989748Z","price_level":"56515.73","new_quantity":"0"},{"side":"offer","event_time":"2026-07-15T03:40:09.989748Z","price_level":"64591.88","new_quantity":"0.00159977"},{"side":"offer","event_time":"2026-07-15T03:40:09.989748Z","price_level":"64593.97","new_quantity":"0.02"},{"side":"offer","event_time":"2026-07-15T03:40:09.989748Z","price_level":"64597.35","new_quantity":"0.20071369"},{"side":"offer","event_time":"2026-07-15T03:40:09.989748Z","price_level":"64597.36","new_quantity":"0.12384407"},{"side":"offer","event_time":"2026-07-15T03:40:09.989748Z","price_level":"64597.39","new_quantity":"0"},{"side":"offer","event_time":"2026-07-15T03:40:09.989748Z","price_level":"64598.43","new_quantity":"0"},{"side":"offer","event_time":"2026-07-15T03:40:09.989748Z","price_level":"64602.28","new_quantity":"0.00096647"},{"side":"offer","event_time":"2026-07-15T03:40:09.989748Z","price_level":"64602.41","new_quantity":"0"},{"side":"offer","event_time":"2026-07-15T03:40:09.989748Z","price_level":"64602.57","new_quantity":"0"},{"side":"offer","event_time":"2026-07-15T03:40:09.989748Z","price_level":"64615.13","new_quantity":"0.14"},{"side":"offer","event_time":"2026-07-15T03:40:09.989748Z","price_level":"64641.4","new_quantity":"0.01615943"},{"side":"offer","event_time":"2026-07-15T03:40:09.989748Z","price_level":"64644.56","new_quantity":"0.85668358"},{"side":"offer","event_time":"2026-07-15T03:40:09.989748Z","price_level":"64644.57","new_quantity":"1.41876514"},{"side":"offer","event_time":"2026-07-15T03:40:09.989748Z","price_level":"64644.58","new_quantity":"0"},{"side":"offer","event_time":"2026-07-15T03:40:09.989748Z","price_level":"64644.59","new_quantity":"0"},{"side":"offer","event_time":"2026-07-15T03:40:09.989748Z","price_level":"64645.53","new_quantity":"0.42692375"},{"side":"offer","event_time":"2026-07-15T03:40:09.989748Z","price_level":"64657.23","new_quantity":"0"},{"side":"offer","event_time":"2026-07-15T03:40:09.989748Z","price_level":"64816.89","new_quantity":"0.01111578"},{"side":"offer","event_time":"2026-07-15T03:40:09.989748Z","price_level":"64857.13","new_quantity":"0.15973945"}]}]}
{"channel":"l2_data","timestamp":"2026-07-15T03:40:10.08427895Z","sequence_num":154,"events":[{"type":"update","product_id":"BTC-USD","updates":[{"side":"offer","event_time":"2026-07-15T03:40:10.041106Z","price_level":"64602.28","new_quantity":"0"}]}]}
{"channel":"market_trades","timestamp":"2026-07-15T03:40:10.084459137Z","sequence_num":155,"events":[{"type":"update","trades":[{"product_id":"BTC-USD","trade_id":"1056309455","price":"64589.4","size":"0.00000019","time":"2026-07-15T03:40:09.972802Z","side":"BUY"}]}]}
{"channel":"l2_data","timestamp":"2026-07-15T03:40:10.140699096Z","sequence_num":156,"events":[{"type":"update","product_id":"BTC-USD","updates":[{"side":"bid","event_time":"2026-07-15T03:40:10.099596Z","price_level":"64589.4","new_quantity":"0.25486962"},{"side":"bid","event_time":"2026-07-15T03:40:10.099596Z","price_level":"64587.99","new_quantity":"0.02"},{"side":"bid","event_time":"2026-07-15T03:40:10.099596Z","price_level":"64562.38","new_quantity":"0"},{"side":"bid","event_time":"2026-07-15T03:40:10.099596Z","price_level":"64551.7","new_quantity":"0.38389997"},{"side":"bid","event_time":"2026-07-15T03:40:10.099596Z","price_level":"64551.69","new_quantity":"0.64001433"},{"side":"bid","event_time":"2026-07-15T03:40:10.099596Z","price_level":"64551.68","new_quantity":"0"},{"side":"bid","event_time":"2026-07-15T03:40:10.099596Z","price_level":"64551.67","new_quantity":"0"},{"side":"bid","event_time":"2026-07-15T03:40:10.099596Z","price_level":"64522.47","new_quantity":"1.67192203"},{"side":"bid","event_time":"2026-07-15T03:40:10.099596Z","price_level":"64522.46","new_quantity":"1.40033305"},{"side":"bid","event_time":"2026-07-15T03:40:10.099596Z","price_level":"64522.45","new_quantity":"0"},{"side":"bid","event_time":"2026-07-15T03:40:10.099596Z","price_level":"64522.44","new_quantity":"0"},{"side":"offer","event_time":"2026-07-15T03:40:10.099596Z","price_level":"64592","new_quantity":"0"},{"side":"offer","event_time":"2026-07-15T03:40:10.099596Z","price_level":"64593.98","new_quantity":"0.15749055"},{"side":"offer","event_time":"2026-07-15T03:40:10.099596Z","price_level":"64593.99","new_quantity":"0"},{"side":"offer","event_time":"2026-07-15T03:40:10.099596Z","price_level":"64596.19","new_quantity":"0"},{"side":"offer","event_time":"2026-07-15T03:40:10.099596Z","price_level":"64601.95","new_quantity":"0.00096647"},{"side":"offer","event_time":"2026-07-15T03:40:10.099596Z","price_level":"64602.13","new_quantity":"0"},{"side":"offer","event_time":"2026-07-15T03:40:10.099596Z","price_level":"64610.01","new_quantity":"0"},{"side":"offer","event_time":"2026-07-15T03:40:10.099596Z","price_level":"64615.13","new_quantity":"0"},{"side":"offer","event_time":"2026-07-15T03:40:10.099596Z","price_level":"64644.54","new_quantity":"0.85668384"},{"side":"offer","event_time":"2026-07-15T03:40:10.099596Z","price_level":"64644.55","new_quantity":"1.41876558"},{"side":"offer","event_time":"2026-07-15T03:40:10.099596Z","price_level":"64644.56","new_quantity":"0"},{"side":"offer","event_time":"2026-07-15T03:40:10.099596Z","price_level":"64644.57","new_quantity":"0"},{"side":"offer","event_time":"2026-07-15T03:40:10.099596Z","price_level":"64645.51","new_quantity":"0.44938342"},{"side":"offer","event_time":"2026-07-15T03:40:10.099596Z","price_level":"64645.52","new_quantity":"0.45858393"},{"side":"offer","event_time":"2026-07-15T03:40:10.099596Z","price_level":"64645.53","new_quantity":"0"},{"side":"offer","event_time":"2026-07-15T03:40:10.099596Z","price_level":"64647.51","new_quantity":"0"}]}]}
{"channel":"market_trades","timestamp":"2026-07-15T03:40:10.183055896Z","sequence_num":157,"events":[{"type":"update","trades":[{"product_id":"BTC-USD","trade_id":"1056309456","price":"64589.41","size":"0.00154135","time":"2026-07-15T03:40:10.146075Z","side":"SELL"}]}]}
{"channel":"l2_data","timestamp":"2026-07-15T03:40:10.193392863Z","sequence_num":158,"events":[{"type":"update","product_id":"BTC-USD","updates":[{"side":"bid","event_time":"2026-07-15T03:40:10.147257Z","price_level":"64589.4","new_quantity":"0.25486962"},{"side":"bid","event_time":"2026-07-15T03:40:10.147257Z","price_level":"64587.98","new_quantity":"0"},{"side":"bid","event_time":"2026-07-15T03:40:10.147257Z","price_level":"64587.68","new_quantity":"0.04644684"},{"side":"bid","event_time":"2026-07-15T03:40:10.147257Z","price_level":"64586.71","new_quantity":"0"},{"side":"bid","event_time":"2026-07-15T03:40:10.147257Z","price_level":"64586.62","new_quantity":"0.29925805"},{"side":"bid","event_time":"2026-07-15T03:40:10.147257Z","price_level":"64585.8","new_quantity":"0"},{"side":"bid","event_time":"2026-07-15T03:40:10.147257Z","price_level":"64585.51","new_quantity":"0"},{"side":"bid","event_time":"2026-07-15T03:40:10.147257Z","price_level":"64585.5","new_quantity":"0"},{"side":"bid","event_time":"2026-07-15T03:40:10.147257Z","price_level":"64585.41","new_quantity":"0.1548337"},{"side":"bid","event_time":"2026-07-15T03:40:10.147257Z","price_level":"64583.82","new_quantity":"0.10262395"},{"side":"bid","event_time":"2026-07-15T03:40:10.147257Z","price_level":"64583.81","new_quantity":"0"},{"side":"bid","event_time":"2026-07-15T03:40:10.147257Z","price_level":"64575.57","new_quantity":"0"},{"side":"bid","event_time":"2026-07-15T03:40:10.147257Z","price_level":"64561.15","new_quantity":"0.039627"},{"side":"bid","event_time":"2026-07-15T03:40:10.147257Z","price_level":"64560.06","new_quantity":"0"},{"side":"bid","event_time":"2026-07-15T03:40:10.147257Z","price_level":"64557.08","new_quantity":"0.60478529"},{"side":"bid","event_time":"2026-07-15T03:40:10.147257Z","price_level":"64557.07","new_quantity":"0.93156588"},{"side":"bid","event_time":"2026-07-15T03:40:10.147257Z","price_level":"64557.06","new_quantity":"0"},{"side":"bid","event_time":"2026-07-15T03:40:10.147257Z","price_level":"64555.29","new_quantity":"0"},{"side":"bid","event_time":"2026-07-15T03:40:10.147257Z","price_level":"64544.44","new_quantity":"0.04243939"},{"side":"bid","event_time":"2026-07-15T03:40:10.147257Z","price_level":"64541.37","new_quantity":"0.01710028"},{"side":"bid","event_time":"2026-07-15T03:40:10.147257Z","price_level":"64541.36","new_quantity":"0.02704919"},{"side":"bid","event_time":"2026-07-15T03:40:10.147257Z","price_level":"64506.15","new_quantity":"0.40450894"},{"side":"bid","event_time":"2026-07-15T03:40:10.147257Z","price_level":"64457.58","new_quantity":"0.00030964"},{"side":"bid","event_time":"2026-07-15T03:40:10.147257Z","price_level":"64142.27","new_quantity":"0.00583"},{"side":"bid","event_time":"2026-07-15T03:40:10.147257Z","price_level":"63070.12","new_quantity":"0.00583"},{"side":"offer","event_time":"2026-07-15T03:40:10.147257Z","price_level":"64591.88","new_quantity":"0"},{"side":"offer","event_time":"2026-07-15T03:40:10.147257Z","price_level":"64591.89","new_quantity":"0"},{"side":"offer","event_time":"2026-07-15T03:40:10.147257Z","price_level":"64592.64","new_quantity":"0"},{"side":"offer","event_time":"2026-07-15T03:40:10.147257Z","price_level":"64593.97","new_quantity":"0"},{"side":"offer","event_time":"2026-07-15T03:40:10.147257Z","price_level":"64593.98","new_quantity":"0"},{"side":"offer","event_time":"2026-07-15T03:40:10.147257Z","price_level":"64595.48","new_quantity":"0"},{"side":"offer","event_time":"2026-07-15T03:40:10.147257Z","price_level":"64596.18","new_quantity":"0.00772597"},{"side":"offer","event_time":"2026-07-15T03:40:10.147257Z","price_level":"64596.19","new_quantity":"0.00159977"},{"side":"offer","event_time":"2026-07-15T03:40:10.147257Z","price_level":"64596.2","new_quantity":"0.13287169"},{"side":"offer","event_time":"2026-07-15T03:40:10.147257Z","price_level":"64596.21","new_quantity":"0.17034612"},{"side":"offer","event_time":"2026-07-15T03:40:10.147257Z","price_level":"64596.39","new_quantity":"0"},{"side":"offer","event_time":"2026-07-15T03:40:10.147257Z","price_level":"64597.35","new_quantity":"0.18450241"},{"side":"offer","event_time":"2026-07-15T03:40:10.147257Z","price_level":"64597.36","new_quantity":"0.04644684"},{"side":"offer","event_time":"2026-07-15T03:40:10.147257Z","price_level":"64597.49","new_quantity":"0"},{"side":"offer","event_time":"2026-07-15T03:40:10.147257Z","price_level":"64598.88","new_quantity":"0"},{"side":"offer","event_time":"2026-07-15T03:40:10.147257Z","price_level":"64599.87","new_quantity":"0.12383927"},{"side":"offer","event_time":"2026-07-15T03:40:10.147257Z","price_level":"64601.84","new_quantity":"0.00096647"},{"side":"offer","event_time":"2026-07-15T03:40:10.147257Z","price_level":"64601.95","new_quantity":"0"},{"side":"offer","event_time":"2026-07-15T03:40:10.147257Z","price_level":"64610","new_quantity":"0.09375753"},{"side":"offer","event_time":"2026-07-15T03:40:10.147257Z","price_level":"64610.75","new_quantity":"0"},{"side":"offer","event_time":"2026-07-15T03:40:10.147257Z","price_level":"64611","new_quantity":"0"},{"side":"offer","event_time":"2026-07-15T03:40:10.147257Z","price_level":"64614.74","new_quantity":"0"},{"side":"offer","event_time":"2026-07-15T03:40:10.147257Z","price_level":"64615.25","new_quantity":"0"},{"side":"offer","event_time":"2026-07-15T03:40:10.147257Z","price_level":"64615.65","new_quantity":"0"},{"side":"offer","event_time":"2026-07-15T03:40:10.147257Z","price_level":"64617","new_quantity":"1"},{"side":"offer","event_time":"2026-07-15T03:40:10.147257Z","price_level":"64618.22","new_quantity":"0"},{"side":"offer","event_time":"2026-07-15T03:40:10.147257Z","price_level":"64619.46","new_quantity":"0.02782677"},{"side":"offer","event_time":"2026-07-15T03:40:10.147257Z","price_level":"64621.67","new_quantity":"0"},{"side":"offer","event_time":"2026-07-15T03:40:10.147257Z","price_level":"64626.25","new_quantity":"0.46154767"},{"side":"offer","event_time":"2026-07-15T03:40:10.147257Z","price_level":"64626.26","new_quantity":"0.62907727"},{"side":"offer","event_time":"2026-07-15T03:40:10.147257Z","price_level":"64626.27","new_quantity":"0"},{"side":"offer","event_time":"2026-07-15T03:40:10.147257Z","price_level":"64629.52","new_quantity":"0"},{"side":"offer","event_time":"2026-07-15T03:40:10.147257Z","price_level":"64629.53","new_quantity":"0"},{"side":"offer","event_time":"2026-07-15T03:40:10.147257Z","price_level":"64634.08","new_quantity":"0"},{"side":"offer","event_time":"2026-07-15T03:40:10.147257Z","price_level":"64634.09","new_quantity":"0"},{"side":"offer","event_time":"2026-07-15T03:40:10.147257Z","price_level":"64644.75","new_quantity":"0"},{"side":"offer","event_time":"2026-07-15T03:40:10.147257Z","price_level":"64714.52","new_quantity":"0.00030964"},{"side":"offer","event_time":"2026-07-15T03:40:10.147257Z","price_level":"65257.7","new_quantity":"0.00583"},{"side":"offer","event_time":"2026-07-15T03:40:10.147257Z","price_level":"65686.56","new_quantity":"0.00590821"}]}]}
{"channel":"l2_data","timestamp":"2026-07-15T03:40:10.239750768Z","sequence_num":159,"events":[{"type":"update","product_id":"BTC-USD","updates":[{"side":"bid","event_time":"2026-07-15T03:40:10.167311Z","price_level":"64588.05","new_quantity":"0.00154134"},{"side":"bid","event_time":"2026-07-15T03:40:10.167311Z","price_level":"64588.03","new_quantity":"0"},{"side":"bid","event_time":"2026-07-15T03:40:10.167311Z","price_level":"64551.71","new_quantity":"0.64001413"},{"side":"bid","event_time":"2026-07-15T03:40:10.167311Z","price_level":"64551.7","new_quantity":"0"},{"side":"bid","event_time":"2026-07-15T03:40:10.167311Z","price_level":"64551.69","new_quantity":"0"},{"side":"bid","event_time":"2026-07-15T03:40:10.167311Z","price_level":"64522.48","new_quantity":"1.40033261"},{"side":"bid","event_time":"2026-07-15T03:40:10.167311Z","price_level":"64522.47","new_quantity":"0"},{"side":"bid","event_time":"2026-07-15T03:40:10.167311Z","price_level":"64522.46","new_quantity":"0"},{"side":"bid","event_time":"2026-07-15T03:40:10.167311Z","price_level":"64142.08","new_quantity":"0"},{"side":"bid","event_time":"2026-07-15T03:40:10.167311Z","price_level":"56515.73","new_quantity":"0.0132912"},{"side":"offer","event_time":"2026-07-15T03:40:10.167311Z","price_level":"64589.41","new_quantity":"0.01250348"},{"side":"offer","event_time":"2026-07-15T03:40:10.167311Z","price_level":"64593.97","new_quantity":"0.01648432"},{"side":"offer","event_time":"2026-07-15T03:40:10.167311Z","price_level":"64616.4","new_quantity":"0.68027846"},{"side":"offer","event_time":"2026-07-15T03:40:10.167311Z","price_level":"64629.52","new_quantity":"0.00077399"},{"side":"offer","event_time":"2026-07-15T03:40:10.167311Z","price_level":"64644.52","new_quantity":"0.84795072"},{"side":"offer","event_time":"2026-07-15T03:40:10.167311Z","price_level":"64644.53","new_quantity":"1.41876602"},{"side":"offer","event_time":"2026-07-15T03:40:10.167311Z","price_level":"64644.54","new_quantity":"0"},{"side":"offer","event_time":"2026-07-15T03:40:10.167311Z","price_level":"64644.55","new_quantity":"0"},{"side":"offer","event_time":"2026-07-15T03:40:10.167311Z","price_level":"64746.64","new_quantity":"0"}]}]}
{"channel":"l2_data","timestamp":"2026-07-15T03:40:10.297785592Z","sequence_num":160,"events":[{"type":"update","product_id":"BTC-USD","updates":[{"side":"bid","event_time":"2026-07-15T03:40:10.248148Z","price_level":"64589.28","new_quantity":"0.12385954"},{"side":"bid","event_time":"2026-07-15T03:40:10.248148Z","price_level":"64587","new_quantity":"0"},{"side":"bid","event_time":"2026-07-15T03:40:10.248148Z","price_level":"64586.62","new_quantity":"0.02"},{"side":"bid","event_time":"2026-07-15T03:40:10.248148Z","price_level":"64572.13","new_quantity":"0.00583"},{"side":"bid","event_time":"2026-07-15T03:40:10.248148Z","price_level":"64572.05","new_quantity":"0"},{"side":"bid","event_time":"2026-07-15T03:40:10.248148Z","price_level":"64571.69","new_quantity":"0"},{"side":"bid","event_time":"2026-07-15T03:40:10.248148Z","price_level":"64571.68","new_quantity":"0"},{"side":"bid","event_time":"2026-07-15T03:40:10.248148Z","price_level":"64557.09","new_quantity":"0.93156559"},{"side":"bid","event_time":"2026-07-15T03:40:10.248148Z","price_level":"64557.08","new_quantity":"0"},{"side":"bid","event_time":"2026-07-15T03:40:10.248148Z","price_level":"64557.07","new_quantity":"0"},{"side":"bid","event_time":"2026-07-15T03:40:10.248148Z","price_level":"64357.33","new_quantity":"0.00583"},{"side":"bid","event_time":"2026-07-15T03:40:10.248148Z","price_level":"64357.19","new_quantity":"0.00583"},{"side":"bid","event_time":"2026-07-15T03:40:10.248148Z","price_level":"64356.74","new_quantity":"0"},{"side":"bid","event_time":"2026-07-15T03:40:10.248148Z","price_level":"64142.74","new_quantity":"0.00583"},{"side":"bid","event_time":"2026-07-15T03:40:10.248148Z","price_level":"64142.27","new_quantity":"0"},{"side":"bid","event_time":"2026-07-15T03:40:10.248148Z","price_level":"63285.47","new_quantity":"0"},{"side":"bid","event_time":"2026-07-15T03:40:10.248148Z","price_level":"63285.18","new_quantity":"0.00583"},{"side":"bid","event_time":"2026-07-15T03:40:10.248148Z","price_level":"63285.11","new_quantity":"0"},{"side":"bid","event_time":"2026-07-15T03:40:10.248148Z","price_level":"63284.59","new_quantity":"0"},{"side":"bid","event_time":"2026-07-15T03:40:10.248148Z","price_level":"63070.12","new_quantity":"0"},{"side":"offer","event_time":"2026-07-15T03:40:10.248148Z","price_level":"64599.87","new_quantity":"0"},{"side":"offer","event_time":"2026-07-15T03:40:10.248148Z","price_level":"64600.16","new_quantity":"0.16750097"},{"side":"offer","event_time":"2026-07-15T03:40:10.248148Z","price_level":"64600.72","new_quantity":"0.12383763"},{"side":"offer","event_time":"2026-07-15T03:40:10.248148Z","price_level":"64601.7","new_quantity":"0"},{"side":"offer","event_time":"2026-07-15T03:40:10.248148Z","price_level":"64601.71","new_quantity":"0.00096647"},{"side":"offer","event_time":"2026-07-15T03:40:10.248148Z","price_level":"64601.84","new_quantity":"0"},{"side":"offer","event_time":"2026-07-15T03:40:10.248148Z","price_level":"64603.25","new_quantity":"0"},{"side":"offer","event_time":"2026-07-15T03:40:10.248148Z","price_level":"64603.88","new_quantity":"0.0015533"},{"side":"offer","event_time":"2026-07-15T03:40:10.248148Z","price_level":"64604.42","new_quantity":"0.15478817"},{"side":"offer","event_time":"2026-07-15T03:40:10.248148Z","price_level":"64618.63","new_quantity":"0.02"},{"side":"offer","event_time":"2026-07-15T03:40:10.248148Z","price_level":"64618.73","new_quantity":"0.04"},{"side":"offer","event_time":"2026-07-15T03:40:10.248148Z","price_level":"64618.93","new_quantity":"0.08"},{"side":"offer","event_time":"2026-07-15T03:40:10.248148Z","price_level":"64626.23","new_quantity":"0.46154779"},{"side":"offer","event_time":"2026-07-15T03:40:10.248148Z","price_level":"64626.24","new_quantity":"0.62907746"},{"side":"offer","event_time":"2026-07-15T03:40:10.248148Z","price_level":"64626.25","new_quantity":"0"},{"side":"offer","event_time":"2026-07-15T03:40:10.248148Z","price_level":"64626.26","new_quantity":"0"},{"side":"offer","event_time":"2026-07-15T03:40:10.248148Z","price_level":"64762.8","new_quantity":"0.01149846"},{"side":"offer","event_time":"2026-07-15T03:40:10.248148Z","price_level":"65901.46","new_quantity":"0.00583"},{"side":"offer","event_time":"2026-07-15T03:40:10.248148Z","price_level":"65901.48","new_quantity":"0"},{"side":"offer","event_time":"2026-07-15T03:40:10.248148Z","price_level":"65901.55","new_quantity":"0"}]}]}
{"channel":"l2_data","timestamp":"2026-07-15T03:40:10.344388171Z","sequence_num":161,"events":[{"type":"update","product_id":"BTC-USD","updates":[{"side":"bid","event_time":"2026-07-15T03:40:10.289768Z","price_level":"64589.29","new_quantity":"0.02"},{"side":"bid","event_time":"2026-07-15T03:40:10.289768Z","price_level":"64588.04","new_quantity":"0"},{"side":"bid","event_time":"2026-07-15T03:40:10.289768Z","price_level":"64585.51","new_quantity":"0.76426271"},{"side":"bid","event_time":"2026-07-15T03:40:10.289768Z","price_level":"64585.5","new_quantity":"1"},{"side":"bid","event_time":"2026-07-15T03:40:10.289768Z","price_level":"64584.53","new_quantity":"0.06"},{"side":"bid","event_time":"2026-07-15T03:40:10.289768Z","price_level":"64582.72","new_quantity":"0.00849921"},{"side":"bid","event_time":"2026-07-15T03:40:10.289768Z","price_level":"64572.28","new_quantity":"0.00583"},{"side":"bid","event_time":"2026-07-15T03:40:10.289768Z","price_level":"64572.13","new_quantity":"0"},{"side":"bid","event_time":"2026-07-15T03:40:10.289768Z","price_level":"64357.52","new_quantity":"0.00583"},{"side":"bid","event_time":"2026-07-15T03:40:10.289768Z","price_level":"64357.33","new_quantity":"0"},{"side":"bid","event_time":"2026-07-15T03:40:10.289768Z","price_level":"64357.19","new_quantity":"0"},{"side":"bid","event_time":"2026-07-15T03:40:10.289768Z","price_level":"63285.18","new_quantity":"0"},{"side":"bid","event_time":"2026-07-15T03:40:10.289768Z","price_level":"56515.73","new_quantity":"0"},{"side":"offer","event_time":"2026-07-15T03:40:10.289768Z","price_level":"64593.73","new_quantity":"0.01404483"},{"side":"offer","event_time":"2026-07-15T03:40:10.289768Z","price_level":"64601.55","new_quantity":"0"},{"side":"offer","event_time":"2026-07-15T03:40:10.289768Z","price_level":"64601.71","new_quantity":"0"},{"side":"offer","event_time":"2026-07-15T03:40:10.289768Z","price_level":"64603.25","new_quantity":"0.19992757"},{"side":"offer","event_time":"2026-07-15T03:40:10.289768Z","price_level":"64603.88","new_quantity":"0.0015533"},{"side":"offer","event_time":"2026-07-15T03:40:10.289768Z","price_level":"64616.4","new_quantity":"0.17871981"},{"side":"offer","event_time":"2026-07-15T03:40:10.289768Z","price_level":"64617","new_quantity":"0"},{"side":"offer","event_time":"2026-07-15T03:40:10.289768Z","price_level":"64618.05","new_quantity":"0.06"},{"side":"offer","event_time":"2026-07-15T03:40:10.289768Z","price_level":"64629.52","new_quantity":"0"},{"side":"offer","event_time":"2026-07-15T03:40:10.289768Z","price_level":"64632.58","new_quantity":"0.000774"},{"side":"offer","event_time":"2026-07-15T03:40:10.289768Z","price_level":"64644.5","new_quantity":"0.84795098"},{"side":"offer","event_time":"2026-07-15T03:40:10.289768Z","price_level":"64644.51","new_quantity":"1.41876646"},{"side":"offer","event_time":"2026-07-15T03:40:10.289768Z","price_level":"64644.52","new_quantity":"0"},{"side":"offer","event_time":"2026-07-15T03:40:10.289768Z","price_level":"64644.53","new_quantity":"0"},{"side":"offer","event_time":"2026-07-15T03:40:10.289768Z","price_level":"64650.89","new_quantity":"0.000774"},{"side":"offer","event_time":"2026-07-15T03:40:10.289768Z","price_level":"64650.92","new_quantity":"0"}]}]}
{"channel":"l2_data","timestamp":"2026-07-15T03:40:10.381341225Z","sequence_num":162,"events":[{"type":"update","product_id":"BTC-USD","updates":[{"side":"bid","event_time":"2026-07-15T03:40:10.348234Z","price_level":"64589.3","new_quantity":"0.00154134"},{"side":"bid","event_time":"2026-07-15T03:40:10.348234Z","price_level":"64588.13","new_quantity":"0.04644684"},{"side":"bid","event_time":"2026-07-15T03:40:10.348234Z","price_level":"64588.05","new_quantity":"0"},{"side":"bid","event_time":"2026-07-15T03:40:10.348234Z","price_level":"64587.68","new_quantity":"0"},{"side":"bid","event_time":"2026-07-15T03:40:10.348234Z","price_level":"64585.51","new_quantity":"0"},{"side":"bid","event_time":"2026-07-15T03:40:10.348234Z","price_level":"64585.5","new_quantity":"0"},{"side":"bid","event_time":"2026-07-15T03:40:10.348234Z","price_level":"64584.28","new_quantity":"0.02528898"},{"side":"bid","event_time":"2026-07-15T03:40:10.348234Z","price_level":"64573.76","new_quantity":"0.00583"},{"side":"bid","event_time":"2026-07-15T03:40:10.348234Z","price_level":"64573.6","new_quantity":"0.00772597"},{"side":"bid","event_time":"2026-07-15T03:40:10.348234Z","price_level":"64573.54","new_quantity":"0"},{"side":"bid","event_time":"2026-07-15T03:40:10.348234Z","price_level":"64572.87","new_quantity":"0"},{"side":"bid","event_time":"2026-07-15T03:40:10.348234Z","price_level":"64572.85","new_quantity":"0"},{"side":"bid","event_time":"2026-07-15T03:40:10.348234Z","price_level":"64572.38","new_quantity":"0"},{"side":"bid","event_time":"2026-07-15T03:40:10.348234Z","price_level":"64572.28","new_quantity":"0"},{"side":"bid","event_time":"2026-07-15T03:40:10.348234Z","price_level":"64567.49","new_quantity":"0"},{"side":"bid","event_time":"2026-07-15T03:40:10.348234Z","price_level":"64567.48","new_quantity":"0"},{"side":"bid","event_time":"2026-07-15T03:40:10.348234Z","price_level":"64564.43","new_quantity":"0.02423914"},{"side":"bid","event_time":"2026-07-15T03:40:10.348234Z","price_level":"64557.11","new_quantity":"0.93156531"},{"side":"bid","event_time":"2026-07-15T03:40:10.348234Z","price_level":"64557.1","new_quantity":"0"},{"side":"bid","event_time":"2026-07-15T03:40:10.348234Z","price_level":"64557.09","new_quantity":"0"},{"side":"bid","event_time":"2026-07-15T03:40:10.348234Z","price_level":"64551.73","new_quantity":"0.64001393"},{"side":"bid","event_time":"2026-07-15T03:40:10.348234Z","price_level":"64551.71","new_quantity":"0"},{"side":"bid","event_time":"2026-07-15T03:40:10.348234Z","price_level":"64544.18","new_quantity":"0"},{"side":"bid","event_time":"2026-07-15T03:40:10.348234Z","price_level":"64535.45","new_quantity":"0"},{"side":"bid","event_time":"2026-07-15T03:40:10.348234Z","price_level":"64522.5","new_quantity":"1.40033218"},{"side":"bid","event_time":"2026-07-15T03:40:10.348234Z","price_level":"64522.48","new_quantity":"0"},{"side":"bid","event_time":"2026-07-15T03:40:10.348234Z","price_level":"64512.52","new_quantity":"0"},{"side":"bid","event_time":"2026-07-15T03:40:10.348234Z","price_level":"64506.15","new_quantity":"0"},{"side":"bid","event_time":"2026-07-15T03:40:10.348234Z","price_level":"64506.1","new_quantity":"0"},{"side":"bid","event_time":"2026-07-15T03:40:10.348234Z","price_level":"64501.23","new_quantity":"0.00757849"},{"side":"bid","event_time":"2026-07-15T03:40:10.348234Z","price_level":"64485.51","new_quantity":"0"},{"side":"bid","event_time":"2026-07-15T03:40:10.348234Z","price_level":"64358.94","new_quantity":"0.00583"},{"side":"bid","event_time":"2026-07-15T03:40:10.348234Z","price_level":"64358.07","new_quantity":"0.00583"},{"side":"bid","event_time":"2026-07-15T03:40:10.348234Z","price_level":"64357.52","new_quantity":"0"},{"side":"bid","event_time":"2026-07-15T03:40:10.348234Z","price_level":"64143.54","new_quantity":"0.00583"},{"side":"bid","event_time":"2026-07-15T03:40:10.348234Z","price_level":"64142.74","new_quantity":"0"},{"side":"bid","event_time":"2026-07-15T03:40:10.348234Z","price_level":"63286.79","new_quantity":"0.00583"},{"side":"bid","event_time":"2026-07-15T03:40:10.348234Z","price_level":"63285.8","new_quantity":"0"},{"side":"offer","event_time":"2026-07-15T03:40:10.348234Z","price_level":"64589.41","new_quantity":"0.00002348"},{"side":"offer","event_time":"2026-07-15T03:40:10.348234Z","price_level":"64591.12","new_quantity":"0"},{"side":"offer","event_time":"2026-07-15T03:40:10.348234Z","price_level":"64593.18","new_quantity":"0.00159977"},{"side":"offer","event_time":"2026-07-15T03:40:10.348234Z","price_level":"64594.31","new_quantity":"0"},{"side":"offer","event_time":"2026-07-15T03:40:10.348234Z","price_level":"64596.18","new_quantity":"0"},{"side":"offer","event_time":"2026-07-15T03:40:10.348234Z","price_level":"64596.19","new_quantity":"0.00772597"},{"side":"offer","event_time":"2026-07-15T03:40:10.348234Z","price_level":"64597.35","new_quantity":"0.12677878"},{"side":"offer","event_time":"2026-07-15T03:40:10.348234Z","price_level":"64597.36","new_quantity":"0"},{"side":"offer","event_time":"2026-07-15T03:40:10.348234Z","price_level":"64597.81","new_quantity":"0.04644684"},{"side":"offer","event_time":"2026-07-15T03:40:10.348234Z","price_level":"64601.38","new_quantity":"0"},{"side":"offer","event_time":"2026-07-15T03:40:10.348234Z","price_level":"64601.45","new_quantity":"0"},{"side":"offer","event_time":"2026-07-15T03:40:10.348234Z","price_level":"64602.55","new_quantity":"0.00096647"},{"side":"offer","event_time":"2026-07-15T03:40:10.348234Z","price_level":"64613.25","new_quantity":"0.37688543"},{"side":"offer","event_time":"2026-07-15T03:40:10.348234Z","price_level":"64613.29","new_quantity":"0.02752508"},{"side":"offer","event_time":"2026-07-15T03:40:10.348234Z","price_level":"64614","new_quantity":"0"},{"side":"offer","event_time":"2026-07-15T03:40:10.348234Z","price_level":"64622.78","new_quantity":"0.01615943"},{"side":"offer","event_time":"2026-07-15T03:40:10.348234Z","price_level":"64626.21","new_quantity":"0.46310121"},{"side":"offer","event_time":"2026-07-15T03:40:10.348234Z","price_level":"64626.22","new_quantity":"0.62907766"},{"side":"offer","event_time":"2026-07-15T03:40:10.348234Z","price_level":"64626.23","new_quantity":"0"},{"side":"offer","event_time":"2026-07-15T03:40:10.348234Z","price_level":"64626.24","new_quantity":"0"},{"side":"offer","event_time":"2026-07-15T03:40:10.348234Z","price_level":"64637.31","new_quantity":"0.01615943"},{"side":"offer","event_time":"2026-07-15T03:40:10.348234Z","price_level":"64664.94","new_quantity":"1.01683138"},{"side":"offer","event_time":"2026-07-15T03:40:10.348234Z","price_level":"64665.43","new_quantity":"0"},{"side":"offer","event_time":"2026-07-15T03:40:10.348234Z","price_level":"64665.86","new_quantity":"0"},{"side":"offer","event_time":"2026-07-15T03:40:10.348234Z","price_level":"64670.88","new_quantity":"0"},{"side":"offer","event_time":"2026-07-15T03:40:10.348234Z","price_level":"64672.54","new_quantity":"0"},{"side":"offer","event_time":"2026-07-15T03:40:10.348234Z","price_level":"64685.06","new_quantity":"10.476162"}]}]}
{"channel":"market_trades","timestamp":"2026-07-15T03:40:10.382223208Z","sequence_num":163,"events":[{"type":"update","trades":[{"product_id":"BTC-USD","trade_id":"1056309460","price":"64589.41","size":"0.00021618","time":"2026-07-15T03:40:10.327888Z","side":"SELL"},{"product_id":"BTC-USD","trade_id":"1056309459","price":"64589.41","size":"0.00025964","time":"2026-07-15T03:40:10.327888Z","side":"SELL"},{"product_id":"BTC-USD","trade_id":"1056309458","price":"64589.41","size":"0.00072037","time":"2026-07-15T03:40:10.327888Z","side":"SELL"},{"product_id":"BTC-USD","trade_id":"1056309457","price":"64589.41","size":"0.01128381","time":"2026-07-15T03:40:10.327888Z","side":"SELL"}]}]}
{"channel":"l2_data","timestamp":"2026-07-15T03:40:10.432249638Z","sequence_num":164,"events":[{"type":"update","product_id":"BTC-USD","updates":[{"side":"bid","event_time":"2026-07-15T03:40:10.384256Z","price_level":"64588.13","new_quantity":"0"},{"side":"bid","event_time":"2026-07-15T03:40:10.384256Z","price_level":"64587.24","new_quantity":"0.04644684"},{"side":"bid","event_time":"2026-07-15T03:40:10.384256Z","price_level":"64572.96","new_quantity":"0.000018"},{"side":"bid","event_time":"2026-07-15T03:40:10.384256Z","price_level":"64564.73","new_quantity":"0"},{"side":"bid","event_time":"2026-07-15T03:40:10.384256Z","price_level":"64486.3","new_quantity":"0"},{"side":"bid","event_time":"2026-07-15T03:40:10.384256Z","price_level":"64486.27","new_quantity":"0"},{"side":"offer","event_time":"2026-07-15T03:40:10.384256Z","price_level":"64596.92","new_quantity":"0.04644684"},{"side":"offer","event_time":"2026-07-15T03:40:10.384256Z","price_level":"64597.81","new_quantity":"0"},{"side":"offer","event_time":"2026-07-15T03:40:10.384256Z","price_level":"64606.08","new_quantity":"0.000018"},{"side":"offer","event_time":"2026-07-15T03:40:10.384256Z","price_level":"64618.05","new_quantity":"0"},{"side":"offer","event_time":"2026-07-15T03:40:10.384256Z","price_level":"64644.48","new_quantity":"0.84795124"},{"side":"offer","event_time":"2026-07-15T03:40:10.384256Z","price_level":"64644.49","new_quantity":"1.4187669"},{"side":"offer","event_time":"2026-07-15T03:40:10.384256Z","price_level":"64644.5","new_quantity":"0"},{"side":"offer","event_time":"2026-07-15T03:40:10.384256Z","price_level":"64644.51","new_quantity":"0"}]}]}
{"channel":"market_trades","timestamp":"2026-07-15T03:40:10.69861218Z","sequence_num":165,"events":[{"type":"update","trades":[{"product_id":"BTC-USD","trade_id":"1056309461","price":"64589.4","size":"0.00000004","time":"2026-07-15T03:40:10.642568Z","side":"BUY"}]}]}
{"channel":"l2_data","timestamp":"2026-07-15T03:40:10.69911533Z","sequence_num":166,"events":[{"type":"update","product_id":"BTC-USD","updates":[{"side":"bid","event_time":"2026-07-15T03:40:10.440261Z","price_level":"64588.51","new_quantity":"0.10981762"},{"side":"bid","event_time":"2026-07-15T03:40:10.440261Z","price_level":"64588.5","new_quantity":"0"},{"side":"bid","event_time":"2026-07-15T03:40:10.440261Z","price_level":"64586.62","new_quantity":"0.35017557"},{"side":"bid","event_time":"2026-07-15T03:40:10.440261Z","price_level":"64573.77","new_quantity":"0.00772597"},{"side":"bid","event_time":"2026-07-15T03:40:10.440261Z","price_level":"64573.6","new_quantity":"0"},{"side":"offer","event_time":"2026-07-15T03:40:10.440261Z","price_level":"64589.41","new_quantity":"0.00006621"},{"side":"offer","event_time":"2026-07-15T03:40:10.440261Z","price_level":"64593.73","new_quantity":"0"},{"side":"offer","event_time":"2026-07-15T03:40:10.440261Z","price_level":"64602.46","new_quantity":"0"},{"side":"offer","event_time":"2026-07-15T03:40:10.440261Z","price_level":"64602.55","new_quantity":"0"},{"side":"offer","event_time":"2026-07-15T03:40:10.440261Z","price_level":"64613.25","new_quantity":"0.37688543"},{"side":"offer","event_time":"2026-07-15T03:40:10.440261Z","price_level":"64615.5","new_quantity":"0"},{"side":"offer","event_time":"2026-07-15T03:40:10.440261Z","price_level":"64622.76","new_quantity":"0.38685016"},{"side":"offer","event_time":"2026-07-15T03:40:10.440261Z","price_level":"64622.77","new_quantity":"0.62911124"},{"side":"offer","event_time":"2026-07-15T03:40:10.440261Z","price_level":"64626.21","new_quantity":"0.0015533"},{"side":"offer","event_time":"2026-07-15T03:40:10.440261Z","price_level":"64626.22","new_quantity":"0"},{"side":"offer","event_time":"2026-07-15T03:40:10.440261Z","price_level":"64626.38","new_quantity":"0.08598854"}]}]}
{"channel":"l2_data","timestamp":"2026-07-15T03:40:10.700414083Z","sequence_num":167,"events":[{"type":"update","product_id":"BTC-USD","updates":[{"side":"bid","event_time":"2026-07-15T03:40:10.508721Z","price_level":"64589.31","new_quantity":"0.00159977"},{"side":"bid","event_time":"2026-07-15T03:40:10.508721Z","price_level":"64589.3","new_quantity":"0.12378505"},{"side":"bid","event_time":"2026-07-15T03:40:10.508721Z","price_level":"64586.62","new_quantity":"0.88986575"},{"side":"bid","event_time":"2026-07-15T03:40:10.508721Z","price_level":"64585.5","new_quantity":"1"},{"side":"bid","event_time":"2026-07-15T03:40:10.508721Z","price_level":"64584.28","new_quantity":"0"},{"side":"bid","event_time":"2026-07-15T03:40:10.508721Z","price_level":"64582.72","new_quantity":"0"},{"side":"bid","event_time":"2026-07-15T03:40:10.508721Z","price_level":"64570.51","new_quantity":"0.30493023"},{"side":"bid","event_time":"2026-07-15T03:40:10.508721Z","price_level":"64570.27","new_quantity":"0.14"},{"side":"bid","event_time":"2026-07-15T03:40:10.508721Z","price_level":"64566.02","new_quantity":"0.07555089"},{"side":"bid","event_time":"2026-07-15T03:40:10.508721Z","price_level":"64564.44","new_quantity":"0.04382969"},{"side":"bid","event_time":"2026-07-15T03:40:10.508721Z","price_level":"64563.66","new_quantity":"0"},{"side":"bid","event_time":"2026-07-15T03:40:10.508721Z","price_level":"64563.63","new_quantity":"0"},{"side":"bid","event_time":"2026-07-15T03:40:10.508721Z","price_level":"64358.07","new_quantity":"0"},{"side":"bid","event_time":"2026-07-15T03:40:10.508721Z","price_level":"63929.01","new_quantity":"0.00583"},{"side":"bid","event_time":"2026-07-15T03:40:10.508721Z","price_level":"56515.73","new_quantity":"0.0132912"},{"side":"offer","event_time":"2026-07-15T03:40:10.508721Z","price_level":"64589.41","new_quantity":"0.00006636"},{"side":"offer","event_time":"2026-07-15T03:40:10.508721Z","price_level":"64602.25","new_quantity":"0.00096647"},{"side":"offer","event_time":"2026-07-15T03:40:10.508721Z","price_level":"64602.36","new_quantity":"0"},{"side":"offer","event_time":"2026-07-15T03:40:10.508721Z","price_level":"64618.05","new_quantity":"0.02"},{"side":"offer","event_time":"2026-07-15T03:40:10.508721Z","price_level":"64619.05","new_quantity":"0.04"},{"side":"offer","event_time":"2026-07-15T03:40:10.508721Z","price_level":"64619.46","new_quantity":"0.02782677"},{"side":"offer","event_time":"2026-07-15T03:40:10.508721Z","price_level":"64620","new_quantity":"0"},{"side":"offer","event_time":"2026-07-15T03:40:10.508721Z","price_level":"64632.58","new_quantity":"0"},{"side":"offer","event_time":"2026-07-15T03:40:10.508721Z","price_level":"64644.46","new_quantity":"0.84795151"},{"side":"offer","event_time":"2026-07-15T03:40:10.508721Z","price_level":"64644.47","new_quantity":"1.41876734"},{"side":"offer","event_time":"2026-07-15T03:40:10.508721Z","price_level":"64644.48","new_quantity":"0"},{"side":"offer","event_time":"2026-07-15T03:40:10.508721Z","price_level":"64644.49","new_quantity":"0"},{"side":"offer","event_time":"2026-07-15T03:40:10.508721Z","price_level":"64816.89","new_quantity":"0"}]}]}
{"channel":"l2_data","timestamp":"2026-07-15T03:40:10.70077119Z","sequence_num":168,"events":[{"type":"update","product_id":"BTC-USD","updates":[{"side":"bid","event_time":"2026-07-15T03:40:10.564012Z","price_level":"64589.32","new_quantity":"0.02"},{"side":"bid","event_time":"2026-07-15T03:40:10.564012Z","price_level":"64588.51","new_quantity":"0.08208886"},{"side":"bid","event_time":"2026-07-15T03:40:10.564012Z","price_level":"64587.81","new_quantity":"0.04644684"},{"side":"bid","event_time":"2026-07-15T03:40:10.564012Z","price_level":"64587.24","new_quantity":"0"},{"side":"bid","event_time":"2026-07-15T03:40:10.564012Z","price_level":"56515.73","new_quantity":"0"},{"side":"offer","event_time":"2026-07-15T03:40:10.564012Z","price_level":"64596.92","new_quantity":"0"},{"side":"offer","event_time":"2026-07-15T03:40:10.564012Z","price_level":"64597.49","new_quantity":"0.04644684"},{"side":"offer","event_time":"2026-07-15T03:40:10.564012Z","price_level":"64616.4","new_quantity":"0.17871981"},{"side":"offer","event_time":"2026-07-15T03:40:10.564012Z","price_level":"64618.5","new_quantity":"0.00306626"},{"side":"offer","event_time":"2026-07-15T03:40:10.564012Z","price_level":"64622.74","new_quantity":"0.38685028"},{"side":"offer","event_time":"2026-07-15T03:40:10.564012Z","price_level":"64622.75","new_quantity":"0.62911144"},{"side":"offer","event_time":"2026-07-15T03:40:10.564012Z","price_level":"64622.76","new_quantity":"0"},{"side":"offer","event_time":"2026-07-15T03:40:10.564012Z","price_level":"64622.77","new_quantity":"0"},{"side":"offer","event_time":"2026-07-15T03:40:10.564012Z","price_level":"64626.63","new_quantity":"0.01615943"},{"side":"offer","event_time":"2026-07-15T03:40:10.564012Z","price_level":"64641.4","new_quantity":"0"}]}]}
{"channel":"l2_data","timestamp":"2026-07-15T03:40:10.701620752Z","sequence_num":169,"events":[{"type":"update","product_id":"BTC-USD","updates":[{"side":"bid","event_time":"2026-07-15T03:40:10.603434Z","price_level":"64586.62","new_quantity":"0.35017557"},{"side":"bid","event_time":"2026-07-15T03:40:10.603434Z","price_level":"64585.5","new_quantity":"0"},{"side":"bid","event_time":"2026-07-15T03:40:10.603434Z","price_level":"64143.81","new_quantity":"0.00583"},{"side":"bid","event_time":"2026-07-15T03:40:10.603434Z","price_level":"64143.54","new_quantity":"0"},{"side":"bid","event_time":"2026-07-15T03:40:10.603434Z","price_level":"63926.45","new_quantity":"0"},{"side":"bid","event_time":"2026-07-15T03:40:10.603434Z","price_level":"63714.26","new_quantity":"0.00583"},{"side":"offer","event_time":"2026-07-15T03:40:10.603434Z","price_level":"64594.9","new_quantity":"0.00619314"},{"side":"offer","event_time":"2026-07-15T03:40:10.603434Z","price_level":"64597.35","new_quantity":"0.20761885"},{"side":"offer","event_time":"2026-07-15T03:40:10.603434Z","price_level":"64599.8","new_quantity":"0.1238394"},{"side":"offer","event_time":"2026-07-15T03:40:10.603434Z","price_level":"64600.16","new_quantity":"0.07541592"},{"side":"offer","event_time":"2026-07-15T03:40:10.603434Z","price_level":"64600.72","new_quantity":"0"},{"side":"offer","event_time":"2026-07-15T03:40:10.603434Z","price_level":"64602.15","new_quantity":"0.00096647"},{"side":"offer","event_time":"2026-07-15T03:40:10.603434Z","price_level":"64602.25","new_quantity":"0"},{"side":"offer","event_time":"2026-07-15T03:40:10.603434Z","price_level":"64613.25","new_quantity":"0.37688543"},{"side":"offer","event_time":"2026-07-15T03:40:10.603434Z","price_level":"64644.44","new_quantity":"0.84795177"},{"side":"offer","event_time":"2026-07-15T03:40:10.603434Z","price_level":"64644.45","new_quantity":"1.41876778"},{"side":"offer","event_time":"2026-07-15T03:40:10.603434Z","price_level":"64644.46","new_quantity":"0"},{"side":"offer","event_time":"2026-07-15T03:40:10.603434Z","price_level":"64644.47","new_quantity":"0"}]}]}
{"channel":"l2_data","timestamp":"2026-07-15T03:40:10.702729479Z","sequence_num":170,"events":[{"type":"update","product_id":"BTC-USD","updates":[{"side":"bid","event_time":"2026-07-15T03:40:10.662931Z","price_level":"64589.4","new_quantity":"0.25486958"},{"side":"bid","event_time":"2026-07-15T03:40:10.662931Z","price_level":"64589.31","new_quantity":"0.02159977"},{"side":"bid","event_time":"2026-07-15T03:40:10.662931Z","price_level":"64587.99","new_quantity":"0"},{"side":"bid","event_time":"2026-07-15T03:40:10.662931Z","price_level":"64587.01","new_quantity":"0.92401805"},{"side":"bid","event_time":"2026-07-15T03:40:10.662931Z","price_level":"64587","new_quantity":"1"},{"side":"bid","event_time":"2026-07-15T03:40:10.662931Z","price_level":"64586.62","new_quantity":"0"},{"side":"bid","event_time":"2026-07-15T03:40:10.662931Z","price_level":"64578.04","new_quantity":"0.00077412"},{"side":"bid","event_time":"2026-07-15T03:40:10.662931Z","price_level":"64575.54","new_quantity":"0"},{"side":"bid","event_time":"2026-07-15T03:40:10.662931Z","price_level":"64564.44","new_quantity":"0.04382969"},{"side":"bid","event_time":"2026-07-15T03:40:10.662931Z","price_level":"63070.94","new_quantity":"0.00583"},{"side":"offer","event_time":"2026-07-15T03:40:10.662931Z","price_level":"64593.18","new_quantity":"0"},{"side":"offer","event_time":"2026-07-15T03:40:10.662931Z","price_level":"64596.16","new_quantity":"0.00159977"},{"side":"offer","event_time":"2026-07-15T03:40:10.662931Z","price_level":"64596.17","new_quantity":"0.00772597"},{"side":"offer","event_time":"2026-07-15T03:40:10.662931Z","price_level":"64596.18","new_quantity":"0.02"},{"side":"offer","event_time":"2026-07-15T03:40:10.662931Z","price_level":"64596.19","new_quantity":"0"},{"side":"offer","event_time":"2026-07-15T03:40:10.662931Z","price_level":"64601.95","new_quantity":"0.00096647"},{"side":"offer","event_time":"2026-07-15T03:40:10.662931Z","price_level":"64602.15","new_quantity":"0"},{"side":"offer","event_time":"2026-07-15T03:40:10.662931Z","price_level":"64613.25","new_quantity":"0.94213384"},{"side":"offer","event_time":"2026-07-15T03:40:10.662931Z","price_level":"64614","new_quantity":"1"},{"side":"offer","event_time":"2026-07-15T03:40:10.662931Z","price_level":"64622.72","new_quantity":"0.38685039"},{"side":"offer","event_time":"2026-07-15T03:40:10.662931Z","price_level":"64622.73","new_quantity":"0.62911163"},{"side":"offer","event_time":"2026-07-15T03:40:10.662931Z","price_level":"64622.74","new_quantity":"0"},{"side":"offer","event_time":"2026-07-15T03:40:10.662931Z","price_level":"64622.75","new_quantity":"0"},{"side":"offer","event_time":"2026-07-15T03:40:10.662931Z","price_level":"64632.58","new_quantity":"0.000774"},{"side":"offer","event_time":"2026-07-15T03:40:10.662931Z","price_level":"64654.92","new_quantity":"0.0015533"},{"side":"offer","event_time":"2026-07-15T03:40:10.662931Z","price_level":"64658.11","new_quantity":"0.0015533"},{"side":"offer","event_time":"2026-07-15T03:40:10.662931Z","price_level":"64673.58","new_quantity":"0.01331"},{"side":"offer","event_time":"2026-07-15T03:40:10.662931Z","price_level":"64996.84","new_quantity":"0.01061683"}]}]}
{"channel":"l2_data","timestamp":"2026-07-15T03:40:10.730779205Z","sequence_num":171,"events":[{"type":"update","product_id":"BTC-USD","updates":[{"side":"bid","event_time":"2026-07-15T03:40:10.685357Z","price_level":"64589.4","new_quantity":"0.25539452"},{"side":"offer","event_time":"2026-07-15T03:40:10.685357Z","price_level":"64601.86","new_quantity":"0.00096647"},{"side":"offer","event_time":"2026-07-15T03:40:10.685357Z","price_level":"64601.95","new_quantity":"0"},{"side":"offer","event_time":"2026-07-15T03:40:10.685357Z","price_level":"64644.42","new_quantity":"0.84795203"},{"side":"offer","event_time":"2026-07-15T03:40:10.685357Z","price_level":"64644.43","new_quantity":"1.41876822"},{"side":"offer","event_time":"2026-07-15T03:40:10.685357Z","price_level":"64644.44","new_quantity":"0"},{"side":"offer","event_time":"2026-07-15T03:40:10.685357Z","price_level":"64644.45","new_quantity":"0"}]}]}
{"channel":"l2_data","timestamp":"2026-07-15T03:40:10.784195213Z","sequence_num":172,"events":[{"type":"update","product_id":"BTC-USD","updates":[{"side":"bid","event_time":"2026-07-15T03:40:10.743128Z","price_level":"64589.4","new_quantity":"0.25539447"},{"side":"bid","event_time":"2026-07-15T03:40:10.743128Z","price_level":"64589.33","new_quantity":"0.00159977"},{"side":"bid","event_time":"2026-07-15T03:40:10.743128Z","price_level":"64589.31","new_quantity":"0.02"},{"side":"bid","event_time":"2026-07-15T03:40:10.743128Z","price_level":"64589.29","new_quantity":"0"},{"side":"bid","event_time":"2026-07-15T03:40:10.743128Z","price_level":"64588.01","new_quantity":"0.04656107"},{"side":"bid","event_time":"2026-07-15T03:40:10.743128Z","price_level":"64587.01","new_quantity":"0.31507805"},{"side":"bid","event_time":"2026-07-15T03:40:10.743128Z","price_level":"64587","new_quantity":"0"},{"side":"offer","event_time":"2026-07-15T03:40:10.743128Z","price_level":"64594.9","new_quantity":"0"},{"side":"offer","event_time":"2026-07-15T03:40:10.743128Z","price_level":"64596.15","new_quantity":"0.00772597"},{"side":"offer","event_time":"2026-07-15T03:40:10.743128Z","price_level":"64596.17","new_quantity":"0"},{"side":"offer","event_time":"2026-07-15T03:40:10.743128Z","price_level":"64601.79","new_quantity":"0.00096647"},{"side":"offer","event_time":"2026-07-15T03:40:10.743128Z","price_level":"64601.86","new_quantity":"0"},{"side":"offer","event_time":"2026-07-15T03:40:10.743128Z","price_level":"64622.71","new_quantity":"0.62911183"},{"side":"offer","event_time":"2026-07-15T03:40:10.743128Z","price_level":"64622.73","new_quantity":"0"}]}]}
{"channel":"market_trades","timestamp":"2026-07-15T03:40:10.78691611Z","sequence_num":173,"events":[{"type":"update","trades":[{"product_id":"BTC-USD","trade_id":"1056309462","price":"64589.4","size":"0.00000005","time":"2026-07-15T03:40:10.739478Z","side":"BUY"}]}]}
{"channel":"l2_data","timestamp":"2026-07-15T03:40:10.831356202Z","sequence_num":174,"events":[{"type":"update","product_id":"BTC-USD","updates":[{"side":"bid","event_time":"2026-07-15T03:40:10.795269Z","price_level":"64589.34","new_quantity":"0.02"},{"side":"bid","event_time":"2026-07-15T03:40:10.795269Z","price_level":"64587.01","new_quantity":"0.87179594"},{"side":"bid","event_time":"2026-07-15T03:40:10.795269Z","price_level":"64587","new_quantity":"1"},{"side":"bid","event_time":"2026-07-15T03:40:10.795269Z","price_level":"63674.3","new_quantity":"0"},{"side":"bid","event_time":"2026-07-15T03:40:10.795269Z","price_level":"56515.73","new_quantity":"0.0132912"},{"side":"offer","event_time":"2026-07-15T03:40:10.795269Z","price_level":"64596.14","new_quantity":"0.02"},{"side":"offer","event_time":"2026-07-15T03:40:10.795269Z","price_level":"64596.18","new_quantity":"0"},{"side":"offer","event_time":"2026-07-15T03:40:10.795269Z","price_level":"64597.35","new_quantity":"0.12677878"},{"side":"offer","event_time":"2026-07-15T03:40:10.795269Z","price_level":"64599.8","new_quantity":"0"},{"side":"offer","event_time":"2026-07-15T03:40:10.795269Z","price_level":"64600.16","new_quantity":"0.16750021"},{"side":"offer","event_time":"2026-07-15T03:40:10.795269Z","price_level":"64601.39","new_quantity":"0.12383635"},{"side":"offer","event_time":"2026-07-15T03:40:10.795269Z","price_level":"64601.72","new_quantity":"0"},{"side":"offer","event_time":"2026-07-15T03:40:10.795269Z","price_level":"64601.79","new_quantity":"0"},{"side":"offer","event_time":"2026-07-15T03:40:10.795269Z","price_level":"64613.25","new_quantity":"0.94213384"},{"side":"offer","event_time":"2026-07-15T03:40:10.795269Z","price_level":"64614","new_quantity":"0"},{"side":"offer","event_time":"2026-07-15T03:40:10.795269Z","price_level":"64615.5","new_quantity":"1"},{"side":"offer","event_time":"2026-07-15T03:40:10.795269Z","price_level":"64622.7","new_quantity":"0.38685051"},{"side":"offer","event_time":"2026-07-15T03:40:10.795269Z","price_level":"64622.72","new_quantity":"0"},{"side":"offer","event_time":"2026-07-15T03:40:10.795269Z","price_level":"64632.58","new_quantity":"0"},{"side":"offer","event_time":"2026-07-15T03:40:10.795269Z","price_level":"64644.4","new_quantity":"0.84795229"},{"side":"offer","event_time":"2026-07-15T03:40:10.795269Z","price_level":"64644.41","new_quantity":"1.41876866"},{"side":"offer","event_time":"2026-07-15T03:40:10.795269Z","price_level":"64644.42","new_quantity":"0"},{"side":"offer","event_time":"2026-07-15T03:40:10.795269Z","price_level":"64644.43","new_quantity":"0"}]}]}
{"channel":"l2_data","timestamp":"2026-07-15T03:40:10.882233008Z","sequence_num":175,"events":[{"type":"update","product_id":"BTC-USD","updates":[{"side":"bid","event_time":"2026-07-15T03:40:10.846132Z","price_level":"64560.87","new_quantity":"0.02720082"},{"side":"bid","event_time":"2026-07-15T03:40:10.846132Z","price_level":"64557.13","new_quantity":"0.93156502"},{"side":"bid","event_time":"2026-07-15T03:40:10.846132Z","price_level":"64557.11","new_quantity":"0"},{"side":"bid","event_time":"2026-07-15T03:40:10.846132Z","price_level":"64552.53","new_quantity":"0.01955381"},{"side":"bid","event_time":"2026-07-15T03:40:10.846132Z","price_level":"64551.74","new_quantity":"0.38389973"},{"side":"bid","event_time":"2026-07-15T03:40:10.846132Z","price_level":"64537.31","new_quantity":"0.01460548"},{"side":"bid","event_time":"2026-07-15T03:40:10.846132Z","price_level":"64522.52","new_quantity":"1.40033175"},{"side":"bid","event_time":"2026-07-15T03:40:10.846132Z","price_level":"64522.5","new_quantity":"0"},{"side":"offer","event_time":"2026-07-15T03:40:10.846132Z","price_level":"64596.12","new_quantity":"0.00159977"},{"side":"offer","event_time":"2026-07-15T03:40:10.846132Z","price_level":"64596.13","new_quantity":"0.00772597"},{"side":"offer","event_time":"2026-07-15T03:40:10.846132Z","price_level":"64596.15","new_quantity":"0"},{"side":"offer","event_time":"2026-07-15T03:40:10.846132Z","price_level":"64596.16","new_quantity":"0"},{"side":"offer","event_time":"2026-07-15T03:40:10.846132Z","price_level":"64600.01","new_quantity":"0.17714355"},{"side":"offer","event_time":"2026-07-15T03:40:10.846132Z","price_level":"64600.02","new_quantity":"0.12383898"},{"side":"offer","event_time":"2026-07-15T03:40:10.846132Z","price_level":"64600.16","new_quantity":"0"},{"side":"offer","event_time":"2026-07-15T03:40:10.846132Z","price_level":"64601.39","new_quantity":"0"},{"side":"offer","event_time":"2026-07-15T03:40:10.846132Z","price_level":"64601.62","new_quantity":"0.00096647"},{"side":"offer","event_time":"2026-07-15T03:40:10.846132Z","price_level":"64632.01","new_quantity":"0.01875296"},{"side":"offer","event_time":"2026-07-15T03:40:10.846132Z","price_level":"64632.58","new_quantity":"0.00077399"},{"side":"offer","event_time":"2026-07-15T03:40:10.846132Z","price_level":"64635.63","new_quantity":"0.06732074"},{"side":"offer","event_time":"2026-07-15T03:40:10.846132Z","price_level":"64636.57","new_quantity":"0.02744345"},{"side":"offer","event_time":"2026-07-15T03:40:10.846132Z","price_level":"64647.23","new_quantity":"0.01475019"}]}]}
{"channel":"l2_data","timestamp":"2026-07-15T03:40:10.931749687Z","sequence_num":176,"events":[{"type":"update","product_id":"BTC-USD","updates":[{"side":"bid","event_time":"2026-07-15T03:40:10.891678Z","price_level":"64559.33","new_quantity":"0.04486881"},{"side":"bid","event_time":"2026-07-15T03:40:10.891678Z","price_level":"64551.75","new_quantity":"0.64001374"},{"side":"bid","event_time":"2026-07-15T03:40:10.891678Z","price_level":"64551.74","new_quantity":"0"},{"side":"bid","event_time":"2026-07-15T03:40:10.891678Z","price_level":"64551.73","new_quantity":"0"},{"side":"bid","event_time":"2026-07-15T03:40:10.891678Z","price_level":"64542.35","new_quantity":"0"},{"side":"bid","event_time":"2026-07-15T03:40:10.891678Z","price_level":"56515.73","new_quantity":"0"},{"side":"offer","event_time":"2026-07-15T03:40:10.891678Z","price_level":"64594.99","new_quantity":"0.01648432"},{"side":"offer","event_time":"2026-07-15T03:40:10.891678Z","price_level":"64596.11","new_quantity":"0.00772597"},{"side":"offer","event_time":"2026-07-15T03:40:10.891678Z","price_level":"64596.13","new_quantity":"0"},{"side":"offer","event_time":"2026-07-15T03:40:10.891678Z","price_level":"64601.62","new_quantity":"0"},{"side":"offer","event_time":"2026-07-15T03:40:10.891678Z","price_level":"64613.29","new_quantity":"0"},{"side":"offer","event_time":"2026-07-15T03:40:10.891678Z","price_level":"64622.68","new_quantity":"0.38685063"},{"side":"offer","event_time":"2026-07-15T03:40:10.891678Z","price_level":"64622.69","new_quantity":"0.62911202"},{"side":"offer","event_time":"2026-07-15T03:40:10.891678Z","price_level":"64622.7","new_quantity":"0"},{"side":"offer","event_time":"2026-07-15T03:40:10.891678Z","price_level":"64622.71","new_quantity":"0"},{"side":"offer","event_time":"2026-07-15T03:40:10.891678Z","price_level":"64644.39","new_quantity":"1.4187691"},{"side":"offer","event_time":"2026-07-15T03:40:10.891678Z","price_level":"64644.41","new_quantity":"0"}]}]}
{"channel":"l2_data","timestamp":"2026-07-15T03:40:10.981623767Z","sequence_num":177,"events":[{"type":"update","product_id":"BTC-USD","updates":[{"side":"bid","event_time":"2026-07-15T03:40:10.950414Z","price_level":"64560.87","new_quantity":"0"},{"side":"bid","event_time":"2026-07-15T03:40:10.950414Z","price_level":"64559.33","new_quantity":"0"},{"side":"bid","event_time":"2026-07-15T03:40:10.950414Z","price_level":"64544.44","new_quantity":"0"},{"side":"offer","event_time":"2026-07-15T03:40:10.950414Z","price_level":"64596.14","new_quantity":"0"},{"side":"offer","event_time":"2026-07-15T03:40:10.950414Z","price_level":"64602.11","new_quantity":"0.00096647"},{"side":"offer","event_time":"2026-07-15T03:40:10.950414Z","price_level":"64613.25","new_quantity":"0.94227826"},{"side":"offer","event_time":"2026-07-15T03:40:10.950414Z","price_level":"64613.29","new_quantity":"0.02776698"},{"side":"offer","event_time":"2026-07-15T03:40:10.950414Z","price_level":"64614","new_quantity":"1"},{"side":"offer","event_time":"2026-07-15T03:40:10.950414Z","price_level":"64615.5","new_quantity":"0"},{"side":"offer","event_time":"2026-07-15T03:40:10.950414Z","price_level":"64644.38","new_quantity":"0.84795256"},{"side":"offer","event_time":"2026-07-15T03:40:10.950414Z","price_level":"64644.4","new_quantity":"0"}]}]}
{"channel":"l2_data","timestamp":"2026-07-15T03:40:11.081179229Z","sequence_num":178,"events":[{"type":"update","product_id":"BTC-USD","updates":[{"side":"bid","event_time":"2026-07-15T03:40:11.04615Z","price_level":"64589.35","new_quantity":"0.00159977"},{"side":"bid","event_time":"2026-07-15T03:40:11.04615Z","price_level":"64589.33","new_quantity":"0"},{"side":"bid","event_time":"2026-07-15T03:40:11.04615Z","price_level":"64565.6","new_quantity":"0.0015713"},{"side":"bid","event_time":"2026-07-15T03:40:11.04615Z","price_level":"64557.16","new_quantity":"0.60478461"},{"side":"bid","event_time":"2026-07-15T03:40:11.04615Z","price_level":"64557.15","new_quantity":"0.93156473"},{"side":"bid","event_time":"2026-07-15T03:40:11.04615Z","price_level":"64557.13","new_quantity":"0"},{"side":"bid","event_time":"2026-07-15T03:40:11.04615Z","price_level":"64552.54","new_quantity":"0.6400059"},{"side":"bid","event_time":"2026-07-15T03:40:11.04615Z","price_level":"64551.75","new_quantity":"0"},{"side":"offer","event_time":"2026-07-15T03:40:11.04615Z","price_level":"64594.99","new_quantity":"0"},{"side":"offer","event_time":"2026-07-15T03:40:11.04615Z","price_level":"64601.9","new_quantity":"0.00096647"},{"side":"offer","event_time":"2026-07-15T03:40:11.04615Z","price_level":"64602.11","new_quantity":"0"},{"side":"offer","event_time":"2026-07-15T03:40:11.04615Z","price_level":"64622.66","new_quantity":"0.38789599"},{"side":"offer","event_time":"2026-07-15T03:40:11.04615Z","price_level":"64622.67","new_quantity":"0.62911222"},{"side":"offer","event_time":"2026-07-15T03:40:11.04615Z","price_level":"64622.68","new_quantity":"0"},{"side":"offer","event_time":"2026-07-15T03:40:11.04615Z","price_level":"64622.69","new_quantity":"0"},{"side":"offer","event_time":"2026-07-15T03:40:11.04615Z","price_level":"64644.36","new_quantity":"0.84795281"},{"side":"offer","event_time":"2026-07-15T03:40:11.04615Z","price_level":"64644.37","new_quantity":"1.41876953"},{"side":"offer","event_time":"2026-07-15T03:40:11.04615Z","price_level":"64644.38","new_quantity":"0"},{"side":"offer","event_time":"2026-07-15T03:40:11.04615Z","price_level":"64644.39","new_quantity":"0"}]}]}
{"channel":"l2_data","timestamp":"2026-07-15T03:40:11.131928119Z","sequence_num":179,"events":[{"type":"update","product_id":"BTC-USD","updates":[{"side":"bid","event_time":"2026-07-15T03:40:11.106007Z","price_level":"64589.4","new_quantity":"0.20059576"},{"side":"bid","event_time":"2026-07-15T03:40:11.106007Z","price_level":"64587.01","new_quantity":"0.31507805"},{"side":"bid","event_time":"2026-07-15T03:40:11.106007Z","price_level":"64587","new_quantity":"0"},{"side":"bid","event_time":"2026-07-15T03:40:11.106007Z","price_level":"64585.5","new_quantity":"1"},{"side":"bid","event_time":"2026-07-15T03:40:11.106007Z","price_level":"56515.73","new_quantity":"0.0132912"},{"side":"bid","event_time":"2026-07-15T03:40:11.106007Z","price_level":"51671.52","new_quantity":"0.0002"},{"side":"offer","event_time":"2026-07-15T03:40:11.106007Z","price_level":"64589.41","new_quantity":"0.02023199"},{"side":"offer","event_time":"2026-07-15T03:40:11.106007Z","price_level":"64592","new_quantity":"0.0232"},{"side":"offer","event_time":"2026-07-15T03:40:11.106007Z","price_level":"64601.75","new_quantity":"0.00096647"},{"side":"offer","event_time":"2026-07-15T03:40:11.106007Z","price_level":"64601.9","new_quantity":"0"},{"side":"offer","event_time":"2026-07-15T03:40:11.106007Z","price_level":"64609.76","new_quantity":"0.000018"},{"side":"offer","event_time":"2026-07-15T03:40:11.106007Z","price_level":"64645.49","new_quantity":"0.47130813"},{"side":"offer","event_time":"2026-07-15T03:40:11.106007Z","price_level":"64645.5","new_quantity":"0.48055856"},{"side":"offer","event_time":"2026-07-15T03:40:11.106007Z","price_level":"64645.51","new_quantity":"0"},{"side":"offer","event_time":"2026-07-15T03:40:11.106007Z","price_level":"64645.52","new_quantity":"0"},{"side":"offer","event_time":"2026-07-15T03:40:11.106007Z","price_level":"64648.73","new_quantity":"1.28660194"},{"side":"offer","event_time":"2026-07-15T03:40:11.106007Z","price_level":"64648.74","new_quantity":"2.08919905"},{"side":"offer","event_time":"2026-07-15T03:40:11.106007Z","price_level":"64648.75","new_quantity":"0"},{"side":"offer","event_time":"2026-07-15T03:40:11.106007Z","price_level":"64648.76","new_quantity":"0"},{"side":"offer","event_time":"2026-07-15T03:40:11.106007Z","price_level":"64658.11","new_quantity":"0"},{"side":"offer","event_time":"2026-07-15T03:40:11.106007Z","price_level":"64799.99","new_quantity":"0.00586242"},{"side":"offer","event_time":"2026-07-15T03:40:11.106007Z","price_level":"65470.68","new_quantity":"0"}]}]}
{"channel":"market_trades","timestamp":"2026-07-15T03:40:11.184966387Z","sequence_num":180,"events":[{"type":"update","trades":[{"product_id":"BTC-USD","trade_id":"1056309463","price":"64589.4","size":"0.00000014","time":"2026-07-15T03:40:11.055508Z","side":"BUY"}]}]}
{"channel":"l2_data","timestamp":"2026-07-15T03:40:11.40632417Z","sequence_num":181,"events":[{"type":"update","product_id":"BTC-USD","updates":[{"side":"bid","event_time":"2026-07-15T03:40:11.160894Z","price_level":"64589.34","new_quantity":"0"},{"side":"bid","event_time":"2026-07-15T03:40:11.160894Z","price_level":"64589.28","new_quantity":"0"},{"side":"bid","event_time":"2026-07-15T03:40:11.160894Z","price_level":"64588.21","new_quantity":"0.12386159"},{"side":"bid","event_time":"2026-07-15T03:40:11.160894Z","price_level":"64587.81","new_quantity":"0"},{"side":"bid","event_time":"2026-07-15T03:40:11.160894Z","price_level":"64587.01","new_quantity":"0.87179594"},{"side":"bid","event_time":"2026-07-15T03:40:11.160894Z","price_level":"64586.52","new_quantity":"0.04644684"},{"side":"bid","event_time":"2026-07-15T03:40:11.160894Z","price_level":"64564.44","new_quantity":"0.04382969"},{"side":"bid","event_time":"2026-07-15T03:40:11.160894Z","price_level":"64562.52","new_quantity":"0"},{"side":"bid","event_time":"2026-07-15T03:40:11.160894Z","price_level":"64557.15","new_quantity":"0"},{"side":"bid","event_time":"2026-07-15T03:40:11.160894Z","price_level":"64555.29","new_quantity":"0.91112101"},{"side":"bid","event_time":"2026-07-15T03:40:11.160894Z","price_level":"64552.54","new_quantity":"0"},{"side":"bid","event_time":"2026-07-15T03:40:11.160894Z","price_level":"64550.23","new_quantity":"0.43021348"},{"side":"bid","event_time":"2026-07-15T03:40:11.160894Z","price_level":"64550.22","new_quantity":"0.64002891"},{"side":"bid","event_time":"2026-07-15T03:40:11.160894Z","price_level":"64550.21","new_quantity":"0"},{"side":"bid","event_time":"2026-07-15T03:40:11.160894Z","price_level":"64522.53","new_quantity":"0.83599805"},{"side":"bid","event_time":"2026-07-15T03:40:11.160894Z","price_level":"64521.18","new_quantity":"0.8359232"},{"side":"bid","event_time":"2026-07-15T03:40:11.160894Z","price_level":"64505.88","new_quantity":"2.3415809"},{"side":"bid","event_time":"2026-07-15T03:40:11.160894Z","price_level":"64462.97","new_quantity":"0"},{"side":"offer","event_time":"2026-07-15T03:40:11.160894Z","price_level":"64596.19","new_quantity":"0.02"},{"side":"offer","event_time":"2026-07-15T03:40:11.160894Z","price_level":"64596.2","new_quantity":"0.17931853"},{"side":"offer","event_time":"2026-07-15T03:40:11.160894Z","price_level":"64597.35","new_quantity":"0.20762122"},{"side":"offer","event_time":"2026-07-15T03:40:11.160894Z","price_level":"64597.49","new_quantity":"0"},{"side":"offer","event_time":"2026-07-15T03:40:11.160894Z","price_level":"64597.72","new_quantity":"0.12384338"},{"side":"offer","event_time":"2026-07-15T03:40:11.160894Z","price_level":"64599.02","new_quantity":"0"},{"side":"offer","event_time":"2026-07-15T03:40:11.160894Z","price_level":"64603.25","new_quantity":"0.10752978"},{"side":"offer","event_time":"2026-07-15T03:40:11.160894Z","price_level":"64604.42","new_quantity":"0"},{"side":"offer","event_time":"2026-07-15T03:40:11.160894Z","price_level":"64619.46","new_quantity":"0.4007823"},{"side":"offer","event_time":"2026-07-15T03:40:11.160894Z","price_level":"64621.67","new_quantity":"0.62912195"},{"side":"offer","event_time":"2026-07-15T03:40:11.160894Z","price_level":"64622.66","new_quantity":"0.00104524"},{"side":"offer","event_time":"2026-07-15T03:40:11.160894Z","price_level":"64622.67","new_quantity":"0"},{"side":"offer","event_time":"2026-07-15T03:40:11.160894Z","price_level":"64644.34","new_quantity":"0.84795308"},{"side":"offer","event_time":"2026-07-15T03:40:11.160894Z","price_level":"64644.35","new_quantity":"1.41876997"},{"side":"offer","event_time":"2026-07-15T03:40:11.160894Z","price_level":"64644.36","new_quantity":"0"},{"side":"offer","event_time":"2026-07-15T03:40:11.160894Z","price_level":"64644.37","new_quantity":"0"}]}]}
{"channel":"l2_data","timestamp":"2026-07-15T03:40:11.40765092Z","sequence_num":182,"events":[{"type":"update","product_id":"BTC-USD","updates":[{"side":"bid","event_time":"2026-07-15T03:40:11.178216Z","price_level":"56515.73","new_quantity":"0"},{"side":"offer","event_time":"2026-07-15T03:40:11.178216Z","price_level":"64596.09","new_quantity":"0.00772597"},{"side":"offer","event_time":"2026-07-15T03:40:11.178216Z","price_level":"64596.1","new_quantity":"0.00159977"},{"side":"offer","event_time":"2026-07-15T03:40:11.178216Z","price_level":"64596.11","new_quantity":"0"},{"side":"offer","event_time":"2026-07-15T03:40:11.178216Z","price_level":"64596.12","new_quantity":"0"},{"side":"offer","event_time":"2026-07-15T03:40:11.178216Z","price_level":"64644.33","new_quantity":"0.48056726"},{"side":"offer","event_time":"2026-07-15T03:40:11.178216Z","price_level":"64645.49","new_quantity":"0.18441467"},{"side":"offer","event_time":"2026-07-15T03:40:11.178216Z","price_level":"64645.5","new_quantity":"0"}]}]}
{"channel":"l2_data","timestamp":"2026-07-15T03:40:11.408713727Z","sequence_num":183,"events":[{"type":"update","product_id":"BTC-USD","updates":[{"side":"bid","event_time":"2026-07-15T03:40:11.253962Z","price_level":"64589.4","new_quantity":"0.18059576"},{"side":"bid","event_time":"2026-07-15T03:40:11.253962Z","price_level":"64589.32","new_quantity":"0"},{"side":"bid","event_time":"2026-07-15T03:40:11.253962Z","price_level":"64589.31","new_quantity":"0"},{"side":"bid","event_time":"2026-07-15T03:40:11.253962Z","price_level":"64588.02","new_quantity":"0"},{"side":"bid","event_time":"2026-07-15T03:40:11.253962Z","price_level":"64587.01","new_quantity":"0.31507805"},{"side":"bid","event_time":"2026-07-15T03:40:11.253962Z","price_level":"64587","new_quantity":"1"},{"side":"bid","event_time":"2026-07-15T03:40:11.253962Z","price_level":"64585.5","new_quantity":"0"},{"side":"bid","event_time":"2026-07-15T03:40:11.253962Z","price_level":"64550.25","new_quantity":"0.43021336"},{"side":"bid","event_time":"2026-07-15T03:40:11.253962Z","price_level":"64550.24","new_quantity":"0.64002871"},{"side":"bid","event_time":"2026-07-15T03:40:11.253962Z","price_level":"64550.23","new_quantity":"0"},{"side":"bid","event_time":"2026-07-15T03:40:11.253962Z","price_level":"64550.22","new_quantity":"0"},{"side":"bid","event_time":"2026-07-15T03:40:11.253962Z","price_level":"63497.94","new_quantity":"0.00583"},{"side":"offer","event_time":"2026-07-15T03:40:11.253962Z","price_level":"64591.12","new_quantity":"0.0015533"},{"side":"offer","event_time":"2026-07-15T03:40:11.253962Z","price_level":"64594.31","new_quantity":"0.0015533"},{"side":"offer","event_time":"2026-07-15T03:40:11.253962Z","price_level":"64594.99","new_quantity":"0.01648432"},{"side":"offer","event_time":"2026-07-15T03:40:11.253962Z","price_level":"64601.5","new_quantity":"0.00096647"},{"side":"offer","event_time":"2026-07-15T03:40:11.253962Z","price_level":"64601.58","new_quantity":"0"},{"side":"offer","event_time":"2026-07-15T03:40:11.253962Z","price_level":"64601.75","new_quantity":"0"},{"side":"offer","event_time":"2026-07-15T03:40:11.253962Z","price_level":"64612.86","new_quantity":"0.00583"},{"side":"offer","event_time":"2026-07-15T03:40:11.253962Z","price_level":"64612.91","new_quantity":"0.00583"},{"side":"offer","event_time":"2026-07-15T03:40:11.253962Z","price_level":"64612.96","new_quantity":"0"},{"side":"offer","event_time":"2026-07-15T03:40:11.253962Z","price_level":"64644.31","new_quantity":"1.13485212"},{"side":"offer","event_time":"2026-07-15T03:40:11.253962Z","price_level":"64644.32","new_quantity":"1.41877063"},{"side":"offer","event_time":"2026-07-15T03:40:11.253962Z","price_level":"64644.34","new_quantity":"0"},{"side":"offer","event_time":"2026-07-15T03:40:11.253962Z","price_level":"64644.35","new_quantity":"0"},{"side":"offer","event_time":"2026-07-15T03:40:11.253962Z","price_level":"64648.71","new_quantity":"1.28660233"},{"side":"offer","event_time":"2026-07-15T03:40:11.253962Z","price_level":"64648.72","new_quantity":"2.0891997"},{"side":"offer","event_time":"2026-07-15T03:40:11.253962Z","price_level":"64648.73","new_quantity":"0"},{"side":"offer","event_time":"2026-07-15T03:40:11.253962Z","price_level":"64648.74","new_quantity":"0"},{"side":"offer","event_time":"2026-07-15T03:40:11.253962Z","price_level":"64654.92","new_quantity":"0"},{"side":"offer","event_time":"2026-07-15T03:40:11.253962Z","price_level":"64827.65","new_quantity":"0.00583"},{"side":"offer","event_time":"2026-07-15T03:40:11.253962Z","price_level":"64828.33","new_quantity":"0"},{"side":"offer","event_time":"2026-07-15T03:40:11.253962Z","price_level":"65685.01","new_quantity":"0.00583"},{"side":"offer","event_time":"2026-07-15T03:40:11.253962Z","price_level":"65685.06","new_quantity":"0"},{"side":"offer","event_time":"2026-07-15T03:40:11.253962Z","price_level":"65685.37","new_quantity":"0"},{"side":"offer","event_time":"2026-07-15T03:40:11.253962Z","price_level":"65686.56","new_quantity":"0.00007821"},{"side":"offer","event_time":"2026-07-15T03:40:11.253962Z","price_level":"65901.46","new_quantity":"0"}]}]}
{"channel":"l2_data","timestamp":"2026-07-15T03:40:11.409617162Z","sequence_num":184,"events":[{"type":"update","product_id":"BTC-USD","updates":[{"side":"bid","event_time":"2026-07-15T03:40:11.301584Z","price_level":"64589.4","new_quantity":"0.24106888"},{"side":"bid","event_time":"2026-07-15T03:40:11.301584Z","price_level":"64587.01","new_quantity":"0.8995247"},{"side":"bid","event_time":"2026-07-15T03:40:11.301584Z","price_level":"64585.28","new_quantity":"0.03022787"},{"side":"bid","event_time":"2026-07-15T03:40:11.301584Z","price_level":"64505.88","new_quantity":"2.65474752"},{"side":"bid","event_time":"2026-07-15T03:40:11.301584Z","price_level":"64463.27","new_quantity":"0.00030964"},{"side":"bid","event_time":"2026-07-15T03:40:11.301584Z","price_level":"63286.79","new_quantity":"0"},{"side":"bid","event_time":"2026-07-15T03:40:11.301584Z","price_level":"63070.94","new_quantity":"0"},{"side":"offer","event_time":"2026-07-15T03:40:11.301584Z","price_level":"64593.96","new_quantity":"0.00159977"},{"side":"offer","event_time":"2026-07-15T03:40:11.301584Z","price_level":"64593.99","new_quantity":"0.12378505"},{"side":"offer","event_time":"2026-07-15T03:40:11.301584Z","price_level":"64596.09","new_quantity":"0"},{"side":"offer","event_time":"2026-07-15T03:40:11.301584Z","price_level":"64596.1","new_quantity":"0"},{"side":"offer","event_time":"2026-07-15T03:40:11.301584Z","price_level":"64596.18","new_quantity":"0.00772597"},{"side":"offer","event_time":"2026-07-15T03:40:11.301584Z","price_level":"64601.3","new_quantity":"0.00096647"},{"side":"offer","event_time":"2026-07-15T03:40:11.301584Z","price_level":"64601.5","new_quantity":"0"},{"side":"offer","event_time":"2026-07-15T03:40:11.301584Z","price_level":"64612.91","new_quantity":"0"},{"side":"offer","event_time":"2026-07-15T03:40:11.301584Z","price_level":"64644.3","new_quantity":"0.48056748"},{"side":"offer","event_time":"2026-07-15T03:40:11.301584Z","price_level":"64644.31","new_quantity":"0.84795347"},{"side":"offer","event_time":"2026-07-15T03:40:11.301584Z","price_level":"64644.33","new_quantity":"0"},{"side":"offer","event_time":"2026-07-15T03:40:11.301584Z","price_level":"64648.69","new_quantity":"1.28660271"},{"side":"offer","event_time":"2026-07-15T03:40:11.301584Z","price_level":"64648.7","new_quantity":"2.08920034"},{"side":"offer","event_time":"2026-07-15T03:40:11.301584Z","price_level":"64648.71","new_quantity":"0"},{"side":"offer","event_time":"2026-07-15T03:40:11.301584Z","price_level":"64648.72","new_quantity":"0"},{"side":"offer","event_time":"2026-07-15T03:40:11.301584Z","price_level":"64827.38","new_quantity":"0.00583"},{"side":"offer","event_time":"2026-07-15T03:40:11.301584Z","price_level":"64827.65","new_quantity":"0"}]}]}
{"channel":"l2_data","timestamp":"2026-07-15T03:40:11.411305646Z","sequence_num":185,"events":[{"type":"update","product_id":"BTC-USD","updates":[{"side":"bid","event_time":"2026-07-15T03:40:11.355627Z","price_level":"64585.22","new_quantity":"0.00849921"},{"side":"bid","event_time":"2026-07-15T03:40:11.355627Z","price_level":"64550.27","new_quantity":"0.43021324"},{"side":"bid","event_time":"2026-07-15T03:40:11.355627Z","price_level":"64550.26","new_quantity":"0.64002851"},{"side":"bid","event_time":"2026-07-15T03:40:11.355627Z","price_level":"64550.25","new_quantity":"0"},{"side":"bid","event_time":"2026-07-15T03:40:11.355627Z","price_level":"64550.24","new_quantity":"0"},{"side":"bid","event_time":"2026-07-15T03:40:11.355627Z","price_level":"63497.99","new_quantity":"0.00583"},{"side":"bid","event_time":"2026-07-15T03:40:11.355627Z","price_level":"63497.94","new_quantity":"0"},{"side":"bid","event_time":"2026-07-15T03:40:11.355627Z","price_level":"63283.36","new_quantity":"0.00583"},{"side":"bid","event_time":"2026-07-15T03:40:11.355627Z","price_level":"51671.52","new_quantity":"0"},{"side":"offer","event_time":"2026-07-15T03:40:11.355627Z","price_level":"64589.41","new_quantity":"0.02059217"},{"side":"offer","event_time":"2026-07-15T03:40:11.355627Z","price_level":"64593.96","new_quantity":"0.00159977"},{"side":"offer","event_time":"2026-07-15T03:40:11.355627Z","price_level":"64596.19","new_quantity":"0"},{"side":"offer","event_time":"2026-07-15T03:40:11.355627Z","price_level":"64644.28","new_quantity":"1.13485265"},{"side":"offer","event_time":"2026-07-15T03:40:11.355627Z","price_level":"64644.29","new_quantity":"1.41877129"},{"side":"offer","event_time":"2026-07-15T03:40:11.355627Z","price_level":"64644.31","new_quantity":"0"},{"side":"offer","event_time":"2026-07-15T03:40:11.355627Z","price_level":"64644.32","new_quantity":"0"},{"side":"offer","event_time":"2026-07-15T03:40:11.355627Z","price_level":"65042.08","new_quantity":"0.00583"},{"side":"offer","event_time":"2026-07-15T03:40:11.355627Z","price_level":"65042.28","new_quantity":"0.00583"},{"side":"offer","event_time":"2026-07-15T03:40:11.355627Z","price_level":"65043.19","new_quantity":"0"}]}]}
{"channel":"l2_data","timestamp":"2026-07-15T03:40:11.433626784Z","sequence_num":186,"events":[{"type":"update","product_id":"BTC-USD","updates":[{"side":"bid","event_time":"2026-07-15T03:40:11.404641Z","price_level":"64550.27","new_quantity":"0.43021324"},{"side":"bid","event_time":"2026-07-15T03:40:11.404641Z","price_level":"63939.87","new_quantity":"0"},{"side":"bid","event_time":"2026-07-15T03:40:11.404641Z","price_level":"63498.01","new_quantity":"0.00583"},{"side":"bid","event_time":"2026-07-15T03:40:11.404641Z","price_level":"63497.99","new_quantity":"0"},{"side":"bid","event_time":"2026-07-15T03:40:11.404641Z","price_level":"63068.77","new_quantity":"0.00583"},{"side":"bid","event_time":"2026-07-15T03:40:11.404641Z","price_level":"56515.73","new_quantity":"0.0132912"},{"side":"offer","event_time":"2026-07-15T03:40:11.404641Z","price_level":"64596.18","new_quantity":"0"},{"side":"offer","event_time":"2026-07-15T03:40:11.404641Z","price_level":"64596.19","new_quantity":"0.00772597"},{"side":"offer","event_time":"2026-07-15T03:40:11.404641Z","price_level":"64644.27","new_quantity":"0.4805677"},{"side":"offer","event_time":"2026-07-15T03:40:11.404641Z","price_level":"64644.28","new_quantity":"0.84795386"},{"side":"offer","event_time":"2026-07-15T03:40:11.404641Z","price_level":"64644.3","new_quantity":"0"},{"side":"offer","event_time":"2026-07-15T03:40:11.404641Z","price_level":"64648.67","new_quantity":"1.2866031"},{"side":"offer","event_time":"2026-07-15T03:40:11.404641Z","price_level":"64648.68","new_quantity":"2.08920099"},{"side":"offer","event_time":"2026-07-15T03:40:11.404641Z","price_level":"64648.69","new_quantity":"0"},{"side":"offer","event_time":"2026-07-15T03:40:11.404641Z","price_level":"64648.7","new_quantity":"0"},{"side":"offer","event_time":"2026-07-15T03:40:11.404641Z","price_level":"65041.82","new_quantity":"0.00583"},{"side":"offer","event_time":"2026-07-15T03:40:11.404641Z","price_level":"65041.88","new_quantity":"0.00583"},{"side":"offer","event_time":"2026-07-15T03:40:11.404641Z","price_level":"65042.08","new_quantity":"0"},{"side":"offer","event_time":"2026-07-15T03:40:11.404641Z","price_level":"65042.28","new_quantity":"0"},{"side":"offer","event_time":"2026-07-15T03:40:11.404641Z","price_level":"65256.73","new_quantity":"0.00583"},{"side":"offer","event_time":"2026-07-15T03:40:11.404641Z","price_level":"65257.7","new_quantity":"0"},{"side":"offer","event_time":"2026-07-15T03:40:11.404641Z","price_level":"65685.01","new_quantity":"0"},{"side":"offer","event_time":"2026-07-15T03:40:11.404641Z","price_level":"65685.11","new_quantity":"0.00583"}]}]}
{"channel":"l2_data","timestamp":"2026-07-15T03:40:11.481516894Z","sequence_num":187,"events":[{"type":"update","product_id":"BTC-USD","updates":[{"side":"bid","event_time":"2026-07-15T03:40:11.44998Z","price_level":"64571.56","new_quantity":"0.033919"},{"side":"bid","event_time":"2026-07-15T03:40:11.44998Z","price_level":"64561.15","new_quantity":"0.01987167"},{"side":"bid","event_time":"2026-07-15T03:40:11.44998Z","price_level":"64560.56","new_quantity":"0"},{"side":"bid","event_time":"2026-07-15T03:40:11.44998Z","price_level":"64553.82","new_quantity":"0.05387948"},{"side":"bid","event_time":"2026-07-15T03:40:11.44998Z","price_level":"64553.81","new_quantity":"0.06610908"},{"side":"bid","event_time":"2026-07-15T03:40:11.44998Z","price_level":"64550.28","new_quantity":"0.64002831"},{"side":"bid","event_time":"2026-07-15T03:40:11.44998Z","price_level":"64550.27","new_quantity":"0"},{"side":"bid","event_time":"2026-07-15T03:40:11.44998Z","price_level":"64550.26","new_quantity":"0"},{"side":"bid","event_time":"2026-07-15T03:40:11.44998Z","price_level":"63498.04","new_quantity":"0.00583"},{"side":"bid","event_time":"2026-07-15T03:40:11.44998Z","price_level":"63498.01","new_quantity":"0"},{"side":"bid","event_time":"2026-07-15T03:40:11.44998Z","price_level":"63283.48","new_quantity":"0.00583"},{"side":"bid","event_time":"2026-07-15T03:40:11.44998Z","price_level":"63283.36","new_quantity":"0"},{"side":"bid","event_time":"2026-07-15T03:40:11.44998Z","price_level":"63068.77","new_quantity":"0"},{"side":"offer","event_time":"2026-07-15T03:40:11.44998Z","price_level":"64644.26","new_quantity":"1.41877195"},{"side":"offer","event_time":"2026-07-15T03:40:11.44998Z","price_level":"64644.28","new_quantity":"0"},{"side":"offer","event_time":"2026-07-15T03:40:11.44998Z","price_level":"64644.29","new_quantity":"0"},{"side":"offer","event_time":"2026-07-15T03:40:11.44998Z","price_level":"65041.88","new_quantity":"0"},{"side":"offer","event_time":"2026-07-15T03:40:11.44998Z","price_level":"65256.6","new_quantity":"0.00583"},{"side":"offer","event_time":"2026-07-15T03:40:11.44998Z","price_level":"65256.63","new_quantity":"0.00583"},{"side":"offer","event_time":"2026-07-15T03:40:11.44998Z","price_level":"65256.73","new_quantity":"0"},{"side":"offer","event_time":"2026-07-15T03:40:11.44998Z","price_level":"65471.19","new_quantity":"0.00583"},{"side":"offer","event_time":"2026-07-15T03:40:11.44998Z","price_level":"65685.11","new_quantity":"0"}]}]}
{"channel":"market_trades","timestamp":"2026-07-15T03:40:11.484499868Z","sequence_num":188,"events":[{"type":"update","trades":[{"product_id":"BTC-USD","trade_id":"1056309464","price":"64589.41","size":"0.00001533","time":"2026-07-15T03:40:11.45154Z","side":"SELL"}]}]}
{"channel":"l2_data","timestamp":"2026-07-15T03:40:11.532118903Z","sequence_num":189,"events":[{"type":"update","product_id":"BTC-USD","updates":[{"side":"bid","event_time":"2026-07-15T03:40:11.510848Z","price_level":"64589.4","new_quantity":"0.26106888"},{"side":"bid","event_time":"2026-07-15T03:40:11.510848Z","price_level":"64567.75","new_quantity":"0"},{"side":"bid","event_time":"2026-07-15T03:40:11.510848Z","price_level":"64557.02","new_quantity":"0.9110966"},{"side":"bid","event_time":"2026-07-15T03:40:11.510848Z","price_level":"64555.29","new_quantity":"0"},{"side":"bid","event_time":"2026-07-15T03:40:11.510848Z","price_level":"64522.54","new_quantity":"1.40033131"},{"side":"bid","event_time":"2026-07-15T03:40:11.510848Z","price_level":"64522.53","new_quantity":"0"},{"side":"bid","event_time":"2026-07-15T03:40:11.510848Z","price_level":"64522.52","new_quantity":"0"},{"side":"bid","event_time":"2026-07-15T03:40:11.510848Z","price_level":"63498.51","new_quantity":"0.00583"},{"side":"bid","event_time":"2026-07-15T03:40:11.510848Z","price_level":"63498.12","new_quantity":"0"},{"side":"bid","event_time":"2026-07-15T03:40:11.510848Z","price_level":"63498.04","new_quantity":"0"},{"side":"bid","event_time":"2026-07-15T03:40:11.510848Z","price_level":"63283.48","new_quantity":"0"},{"side":"bid","event_time":"2026-07-15T03:40:11.510848Z","price_level":"56515.73","new_quantity":"0"},{"side":"offer","event_time":"2026-07-15T03:40:11.510848Z","price_level":"64589.41","new_quantity":"0.02011701"},{"side":"offer","event_time":"2026-07-15T03:40:11.510848Z","price_level":"64600.92","new_quantity":"0.00096647"},{"side":"offer","event_time":"2026-07-15T03:40:11.510848Z","price_level":"64601","new_quantity":"0"},{"side":"offer","event_time":"2026-07-15T03:40:11.510848Z","price_level":"64601.12","new_quantity":"0"},{"side":"offer","event_time":"2026-07-15T03:40:11.510848Z","price_level":"64601.3","new_quantity":"0"},{"side":"offer","event_time":"2026-07-15T03:40:11.510848Z","price_level":"64644.25","new_quantity":"0.48056785"},{"side":"offer","event_time":"2026-07-15T03:40:11.510848Z","price_level":"64644.27","new_quantity":"0"},{"side":"offer","event_time":"2026-07-15T03:40:11.510848Z","price_level":"64648.66","new_quantity":"2.08920164"},{"side":"offer","event_time":"2026-07-15T03:40:11.510848Z","price_level":"64648.67","new_quantity":"0"},{"side":"offer","event_time":"2026-07-15T03:40:11.510848Z","price_level":"64648.68","new_quantity":"0"},{"side":"offer","event_time":"2026-07-15T03:40:11.510848Z","price_level":"65256.63","new_quantity":"0"},{"side":"offer","event_time":"2026-07-15T03:40:11.510848Z","price_level":"65685.7","new_quantity":"0.00583"},{"side":"offer","event_time":"2026-07-15T03:40:11.510848Z","price_level":"65900.18","new_quantity":"0.00583"}]}]}
{"channel":"l2_data","timestamp":"2026-07-15T03:40:11.581153396Z","sequence_num":190,"events":[{"type":"update","product_id":"BTC-USD","updates":[{"side":"bid","event_time":"2026-07-15T03:40:11.558761Z","price_level":"64586.52","new_quantity":"0"},{"side":"bid","event_time":"2026-07-15T03:40:11.558761Z","price_level":"64585.64","new_quantity":"0.04644684"},{"side":"bid","event_time":"2026-07-15T03:40:11.558761Z","price_level":"64585.22","new_quantity":"0"},{"side":"bid","event_time":"2026-07-15T03:40:11.558761Z","price_level":"64552.54","new_quantity":"0.6400059"},{"side":"bid","event_time":"2026-07-15T03:40:11.558761Z","price_level":"64550.28","new_quantity":"0"},{"side":"offer","event_time":"2026-07-15T03:40:11.558761Z","price_level":"64589.41","new_quantity":"0.02011716"},{"side":"offer","event_time":"2026-07-15T03:40:11.558761Z","price_level":"64593.95","new_quantity":"0.00159977"},{"side":"offer","event_time":"2026-07-15T03:40:11.558761Z","price_level":"64593.96","new_quantity":"0.02"},{"side":"offer","event_time":"2026-07-15T03:40:11.558761Z","price_level":"64595.32","new_quantity":"0.04644684"},{"side":"offer","event_time":"2026-07-15T03:40:11.558761Z","price_level":"64596.2","new_quantity":"0.13287169"},{"side":"offer","event_time":"2026-07-15T03:40:11.558761Z","price_level":"64644.24","new_quantity":"1.41877239"},{"side":"offer","event_time":"2026-07-15T03:40:11.558761Z","price_level":"64644.26","new_quantity":"0"}]}]}
{"channel":"market_trades","timestamp":"2026-07-15T03:40:11.584720475Z","sequence_num":191,"events":[{"type":"update","trades":[{"product_id":"BTC-USD","trade_id":"1056309468","price":"64589.41","size":"0.0004088","time":"2026-07-15T03:40:11.494341Z","side":"SELL"},{"product_id":"BTC-USD","trade_id":"1056309467","price":"64589.41","size":"0.00000015","time":"2026-07-15T03:40:11.494341Z","side":"SELL"},{"product_id":"BTC-USD","trade_id":"1056309466","price":"64589.41","size":"0.00004273","time":"2026-07-15T03:40:11.494341Z","side":"SELL"},{"product_id":"BTC-USD","trade_id":"1056309465","price":"64589.41","size":"0.00000815","time":"2026-07-15T03:40:11.494341Z","side":"SELL"}]}]}
{"channel":"l2_data","timestamp":"2026-07-15T03:40:11.627463863Z","sequence_num":192,"events":[{"type":"update","product_id":"BTC-USD","updates":[{"side":"bid","event_time":"2026-07-15T03:40:11.607554Z","price_level":"64589.4","new_quantity":"0.24106888"},{"side":"bid","event_time":"2026-07-15T03:40:11.607554Z","price_level":"64561.72","new_quantity":"0.568311"},{"side":"bid","event_time":"2026-07-15T03:40:11.607554Z","price_level":"63283.54","new_quantity":"0.00583"}]}]}
{"channel":"market_trades","timestamp":"2026-07-15T03:40:11.683329616Z","sequence_num":193,"events":[{"type":"update","trades":[{"product_id":"BTC-USD","trade_id":"1056309469","price":"64589.4","size":"0.00000005","time":"2026-07-15T03:40:11.657256Z","side":"BUY"}]}]}
{"channel":"l2_data","timestamp":"2026-07-15T03:40:11.729206118Z","sequence_num":194,"events":[{"type":"update","product_id":"BTC-USD","updates":[{"side":"bid","event_time":"2026-07-15T03:40:11.657577Z","price_level":"64571.9","new_quantity":"0.02057684"},{"side":"bid","event_time":"2026-07-15T03:40:11.657577Z","price_level":"64561.72","new_quantity":"0"},{"side":"bid","event_time":"2026-07-15T03:40:11.657577Z","price_level":"63283.95","new_quantity":"0.00583"},{"side":"bid","event_time":"2026-07-15T03:40:11.657577Z","price_level":"63283.54","new_quantity":"0"},{"side":"offer","event_time":"2026-07-15T03:40:11.657577Z","price_level":"64600.67","new_quantity":"0.00096647"},{"side":"offer","event_time":"2026-07-15T03:40:11.657577Z","price_level":"64600.77","new_quantity":"0"},{"side":"offer","event_time":"2026-07-15T03:40:11.657577Z","price_level":"64600.92","new_quantity":"0"},{"side":"offer","event_time":"2026-07-15T03:40:11.657577Z","price_level":"64675.8","new_quantity":"0.15973945"},{"side":"offer","event_time":"2026-07-15T03:40:11.657577Z","price_level":"64857.13","new_quantity":"0"},{"side":"offer","event_time":"2026-07-15T03:40:11.657577Z","price_level":"65471.12","new_quantity":"0.00583"},{"side":"offer","event_time":"2026-07-15T03:40:11.657577Z","price_level":"65471.19","new_quantity":"0"},{"side":"offer","event_time":"2026-07-15T03:40:11.657577Z","price_level":"65900.18","new_quantity":"0"}]}]}
{"channel":"l2_data","timestamp":"2026-07-15T03:40:11.733149855Z","sequence_num":195,"events":[{"type":"update","product_id":"BTC-USD","updates":[{"side":"bid","event_time":"2026-07-15T03:40:11.666344Z","price_level":"64589.4","new_quantity":"0.24106883"},{"side":"bid","event_time":"2026-07-15T03:40:11.666344Z","price_level":"56515.73","new_quantity":"0.0132912"}]}]}
{"channel":"l2_data","timestamp":"2026-07-15T03:40:11.782659423Z","sequence_num":196,"events":[{"type":"update","product_id":"BTC-USD","updates":[{"side":"bid","event_time":"2026-07-15T03:40:11.738174Z","price_level":"64558.24","new_quantity":"0.000018"},{"side":"bid","event_time":"2026-07-15T03:40:11.738174Z","price_level":"64557.17","new_quantity":"0.91109448"},{"side":"bid","event_time":"2026-07-15T03:40:11.738174Z","price_level":"64557.16","new_quantity":"0"},{"side":"bid","event_time":"2026-07-15T03:40:11.738174Z","price_level":"64557.02","new_quantity":"0"},{"side":"bid","event_time":"2026-07-15T03:40:11.738174Z","price_level":"64553.83","new_quantity":"0.63999311"},{"side":"bid","event_time":"2026-07-15T03:40:11.738174Z","price_level":"64552.54","new_quantity":"0"},{"side":"bid","event_time":"2026-07-15T03:40:11.738174Z","price_level":"63941.12","new_quantity":"0.03910511"},{"side":"offer","event_time":"2026-07-15T03:40:11.738174Z","price_level":"64592","new_quantity":"0"},{"side":"offer","event_time":"2026-07-15T03:40:11.738174Z","price_level":"64594.99","new_quantity":"0"},{"side":"offer","event_time":"2026-07-15T03:40:11.738174Z","price_level":"64597.35","new_quantity":"0.12677878"},{"side":"offer","event_time":"2026-07-15T03:40:11.738174Z","price_level":"64597.72","new_quantity":"0"},{"side":"offer","event_time":"2026-07-15T03:40:11.738174Z","price_level":"64600.01","new_quantity":"0.24690702"},{"side":"offer","event_time":"2026-07-15T03:40:11.738174Z","price_level":"64600.54","new_quantity":"0.00096647"},{"side":"offer","event_time":"2026-07-15T03:40:11.738174Z","price_level":"64600.67","new_quantity":"0"},{"side":"offer","event_time":"2026-07-15T03:40:11.738174Z","price_level":"64602.76","new_quantity":"0.15479216"},{"side":"offer","event_time":"2026-07-15T03:40:11.738174Z","price_level":"64613.44","new_quantity":"0.000018"},{"side":"offer","event_time":"2026-07-15T03:40:11.738174Z","price_level":"64621.67","new_quantity":"0"},{"side":"offer","event_time":"2026-07-15T03:40:11.738174Z","price_level":"64622.78","new_quantity":"0"},{"side":"offer","event_time":"2026-07-15T03:40:11.738174Z","price_level":"64626.37","new_quantity":"0.6290762"},{"side":"offer","event_time":"2026-07-15T03:40:11.738174Z","price_level":"64626.63","new_quantity":"0"},{"side":"offer","event_time":"2026-07-15T03:40:11.738174Z","price_level":"64637.31","new_quantity":"0"},{"side":"offer","event_time":"2026-07-15T03:40:11.738174Z","price_level":"64644.25","new_quantity":"0"},{"side":"offer","event_time":"2026-07-15T03:40:11.738174Z","price_level":"64647.22","new_quantity":"0.48054577"},{"side":"offer","event_time":"2026-07-15T03:40:11.738174Z","price_level":"64648.66","new_quantity":"0"},{"side":"offer","event_time":"2026-07-15T03:40:11.738174Z","price_level":"64650.9","new_quantity":"0"},{"side":"offer","event_time":"2026-07-15T03:40:11.738174Z","price_level":"64654.09","new_quantity":"2.08902618"},{"side":"offer","event_time":"2026-07-15T03:40:11.738174Z","price_level":"64675.8","new_quantity":"0"}]}]}
{"channel":"market_trades","timestamp":"2026-07-15T03:40:11.78485046Z","sequence_num":197,"events":[{"type":"update","trades":[{"product_id":"BTC-USD","trade_id":"1056309471","price":"64589.4","size":"0.00000002","time":"2026-07-15T03:40:11.746541Z","side":"BUY"},{"product_id":"BTC-USD","trade_id":"1056309470","price":"64589.41","size":"0.00015328","time":"2026-07-15T03:40:11.743272Z","side":"SELL"}]}]}
{"channel":"l2_data","timestamp":"2026-07-15T03:40:11.830876288Z","sequence_num":198,"events":[{"type":"update","product_id":"BTC-USD","updates":[{"side":"bid","event_time":"2026-07-15T03:40:11.807292Z","price_level":"64589.4","new_quantity":"0.38492814"},{"side":"bid","event_time":"2026-07-15T03:40:11.807292Z","price_level":"64588.51","new_quantity":"0"},{"side":"bid","event_time":"2026-07-15T03:40:11.807292Z","price_level":"64588.21","new_quantity":"0"},{"side":"bid","event_time":"2026-07-15T03:40:11.807292Z","price_level":"64588.02","new_quantity":"0.02"},{"side":"bid","event_time":"2026-07-15T03:40:11.807292Z","price_level":"56515.73","new_quantity":"0"},{"side":"offer","event_time":"2026-07-15T03:40:11.807292Z","price_level":"64589.41","new_quantity":"0.01996388"},{"side":"offer","event_time":"2026-07-15T03:40:11.807292Z","price_level":"64593.96","new_quantity":"0"},{"side":"offer","event_time":"2026-07-15T03:40:11.807292Z","price_level":"64600.46","new_quantity":"0.00096647"},{"side":"offer","event_time":"2026-07-15T03:40:11.807292Z","price_level":"64600.54","new_quantity":"0"},{"side":"offer","event_time":"2026-07-15T03:40:11.807292Z","price_level":"64613.25","new_quantity":"0.37688543"},{"side":"offer","event_time":"2026-07-15T03:40:11.807292Z","price_level":"64614","new_quantity":"0"},{"side":"offer","event_time":"2026-07-15T03:40:11.807292Z","price_level":"64615.5","new_quantity":"1"},{"side":"offer","event_time":"2026-07-15T03:40:11.807292Z","price_level":"64619.46","new_quantity":"0.02782677"},{"side":"offer","event_time":"2026-07-15T03:40:11.807292Z","price_level":"64632","new_quantity":"0.000774"},{"side":"offer","event_time":"2026-07-15T03:40:11.807292Z","price_level":"64632.58","new_quantity":"0"}]}]}
{"channel":"l2_data","timestamp":"2026-07-15T03:40:11.881312849Z","sequence_num":199,"events":[{"type":"update","product_id":"BTC-USD","updates":[{"side":"bid","event_time":"2026-07-15T03:40:11.850021Z","price_level":"64587.01","new_quantity":"0.31507805"},{"side":"bid","event_time":"2026-07-15T03:40:11.850021Z","price_level":"64587","new_quantity":"0"},{"side":"bid","event_time":"2026-07-15T03:40:11.850021Z","price_level":"64586.99","new_quantity":"0.04644684"},{"side":"bid","event_time":"2026-07-15T03:40:11.850021Z","price_level":"64585.64","new_quantity":"0"},{"side":"bid","event_time":"2026-07-15T03:40:11.850021Z","price_level":"64557.19","new_quantity":"0.9110942"},{"side":"bid","event_time":"2026-07-15T03:40:11.850021Z","price_level":"64557.18","new_quantity":"0"},{"side":"bid","event_time":"2026-07-15T03:40:11.850021Z","price_level":"64557.17","new_quantity":"0"},{"side":"bid","event_time":"2026-07-15T03:40:11.850021Z","price_level":"64522.56","new_quantity":"1.40033088"},{"side":"bid","event_time":"2026-07-15T03:40:11.850021Z","price_level":"64522.55","new_quantity":"0"},{"side":"bid","event_time":"2026-07-15T03:40:11.850021Z","price_level":"64522.54","new_quantity":"0"},{"side":"bid","event_time":"2026-07-15T03:40:11.850021Z","price_level":"64505.88","new_quantity":"3.13673661"},{"side":"offer","event_time":"2026-07-15T03:40:11.850021Z","price_level":"64595.04","new_quantity":"0.02011716"},{"side":"offer","event_time":"2026-07-15T03:40:11.850021Z","price_level":"64595.32","new_quantity":"0"},{"side":"offer","event_time":"2026-07-15T03:40:11.850021Z","price_level":"64596.67","new_quantity":"0.04644684"},{"side":"offer","event_time":"2026-07-15T03:40:11.850021Z","price_level":"64600.02","new_quantity":"0"},{"side":"offer","event_time":"2026-07-15T03:40:11.850021Z","price_level":"64600.38","new_quantity":"0.00096647"},{"side":"offer","event_time":"2026-07-15T03:40:11.850021Z","price_level":"64600.46","new_quantity":"0"},{"side":"offer","event_time":"2026-07-15T03:40:11.850021Z","price_level":"64601.51","new_quantity":"0.12383611"},{"side":"offer","event_time":"2026-07-15T03:40:11.850021Z","price_level":"64615.5","new_quantity":"0"}]}]}
{"channel":"l2_data","timestamp":"2026-07-15T03:40:11.932927604Z","sequence_num":200,"events":[{"type":"update","product_id":"BTC-USD","updates":[{"side":"bid","event_time":"2026-07-15T03:40:11.908417Z","price_level":"64588.51","new_quantity":"0.65520886"},{"side":"bid","event_time":"2026-07-15T03:40:11.908417Z","price_level":"64588.5","new_quantity":"1"},{"side":"bid","event_time":"2026-07-15T03:40:11.908417Z","price_level":"64562.97","new_quantity":"0.04656107"},{"side":"offer","event_time":"2026-07-15T03:40:11.908417Z","price_level":"64600.24","new_quantity":"0.00096647"},{"side":"offer","event_time":"2026-07-15T03:40:11.908417Z","price_level":"64600.31","new_quantity":"0"},{"side":"offer","event_time":"2026-07-15T03:40:11.908417Z","price_level":"64600.38","new_quantity":"0"},{"side":"offer","event_time":"2026-07-15T03:40:11.908417Z","price_level":"64618.05","new_quantity":"0"},{"side":"offer","event_time":"2026-07-15T03:40:11.908417Z","price_level":"64619.46","new_quantity":"0.6221965"},{"side":"offer","event_time":"2026-07-15T03:40:11.908417Z","price_level":"64620","new_quantity":"1"},{"side":"offer","event_time":"2026-07-15T03:40:11.908417Z","price_level":"64650.89","new_quantity":"0"},{"side":"offer","event_time":"2026-07-15T03:40:11.908417Z","price_level":"64651.34","new_quantity":"0.00077398"}]}]}
