{"channel":"l2_data","timestamp":"2026-07-16T20:29:04.13055645Z","sequence_num":242,"events":[{"type":"update","product_id":"BTC-USD","updates":[{"side":"bid","event_time":"2026-07-16T20:29:04.108538Z","price_level":"64131.55","new_quantity":"0.0077892"},{"side":"bid","event_time":"2026-07-16T20:29:04.108538Z","price_level":"64131.54","new_quantity":"0.620692"},{"side":"bid","event_time":"2026-07-16T20:29:04.108538Z","price_level":"64131.53","new_quantity":"0"},{"side":"bid","event_time":"2026-07-16T20:29:04.108538Z","price_level":"56126.5","new_quantity":"0"},{"side":"offer","event_time":"2026-07-16T20:29:04.108538Z","price_level":"64144.58","new_quantity":"0.37832333"},{"side":"offer","event_time":"2026-07-16T20:29:04.108538Z","price_level":"64167.88","new_quantity":"0.00779505"},{"side":"offer","event_time":"2026-07-16T20:29:04.108538Z","price_level":"65015.52","new_quantity":"0"},{"side":"offer","event_time":"2026-07-16T20:29:04.108538Z","price_level":"65444.73","new_quantity":"0.00583"}]}]}
{"channel":"heartbeats","timestamp":"2026-07-16T20:29:04.168463456Z","sequence_num":243,"events":[{"current_time":"2026-07-16 20:29:04.16302027 +0000 UTC m=+75508.317847309","heartbeat_counter":75508}]}
{"channel":"l2_data","timestamp":"2026-07-16T20:29:04.19089483Z","sequence_num":244,"events":[{"type":"update","product_id":"BTC-USD","updates":[{"side":"bid","event_time":"2026-07-16T20:29:04.134061Z","price_level":"64144.57","new_quantity":"0.00277738"},{"side":"bid","event_time":"2026-07-16T20:29:04.134061Z","price_level":"64131.55","new_quantity":"0"},{"side":"bid","event_time":"2026-07-16T20:29:04.134061Z","price_level":"64131.54","new_quantity":"0"},{"side":"bid","event_time":"2026-07-16T20:29:04.134061Z","price_level":"64131.53","new_quantity":"0.0077892"},{"side":"offer","event_time":"2026-07-16T20:29:04.134061Z","price_level":"64144.58","new_quantity":"0.34860931"}]}]}
{"channel":"l2_data","timestamp":"2026-07-16T20:29:04.512975659Z","sequence_num":245,"events":[{"type":"update","product_id":"BTC-USD","updates":[{"side":"bid","event_time":"2026-07-16T20:29:04.241131Z","price_level":"64139.76","new_quantity":"0.00779548"},{"side":"bid","event_time":"2026-07-16T20:29:04.241131Z","price_level":"64138.16","new_quantity":"0.00779567"},{"side":"bid","event_time":"2026-07-16T20:29:04.241131Z","price_level":"63501.88","new_quantity":"0.03937542"},{"side":"offer","event_time":"2026-07-16T20:29:04.241131Z","price_level":"64150.7","new_quantity":"0.00896327"},{"side":"offer","event_time":"2026-07-16T20:29:04.241131Z","price_level":"64152.31","new_quantity":"0.40171656"},{"side":"offer","event_time":"2026-07-16T20:29:04.241131Z","price_level":"64167.88","new_quantity":"0"}]}]}
{"channel":"l2_data","timestamp":"2026-07-16T20:29:04.812083576Z","sequence_num":246,"events":[{"type":"update","product_id":"BTC-USD","updates":[{"side":"bid","event_time":"2026-07-16T20:29:04.295293Z","price_level":"56126.5","new_quantity":"0.01337205"},{"side":"offer","event_time":"2026-07-16T20:29:04.295293Z","price_level":"64152.31","new_quantity":"0.73246415"},{"side":"offer","event_time":"2026-07-16T20:29:04.295293Z","price_level":"64154.56","new_quantity":"0.65488134"}]}]}
{"channel":"l2_data","timestamp":"2026-07-16T20:29:04.812887933Z","sequence_num":247,"events":[{"type":"update","product_id":"BTC-USD","updates":[{"side":"offer","event_time":"2026-07-16T20:29:04.350309Z","price_level":"64151.05","new_quantity":"0.00009743"},{"side":"offer","event_time":"2026-07-16T20:29:04.350309Z","price_level":"64152.34","new_quantity":"0.00779395"}]}]}
{"channel":"l2_data","timestamp":"2026-07-16T20:29:04.813596661Z","sequence_num":248,"events":[{"type":"update","product_id":"BTC-USD","updates":[{"side":"bid","event_time":"2026-07-16T20:29:04.388695Z","price_level":"64131.49","new_quantity":"0.712224"},{"side":"bid","event_time":"2026-07-16T20:29:04.388695Z","price_level":"56126.5","new_quantity":"0"},{"side":"offer","event_time":"2026-07-16T20:29:04.388695Z","price_level":"64167.88","new_quantity":"0.00779505"}]}]}
{"channel":"l2_data","timestamp":"2026-07-16T20:29:04.81412656Z","sequence_num":249,"events":[{"type":"update","product_id":"BTC-USD","updates":[{"side":"bid","event_time":"2026-07-16T20:29:04.507377Z","price_level":"64144.57","new_quantity":"0.00277734"},{"side":"bid","event_time":"2026-07-16T20:29:04.507377Z","price_level":"64138","new_quantity":"0.00734448"},{"side":"bid","event_time":"2026-07-16T20:29:04.507377Z","price_level":"64131.49","new_quantity":"0"},{"side":"bid","event_time":"2026-07-16T20:29:04.507377Z","price_level":"64119.32","new_quantity":"0.65487407"},{"side":"bid","event_time":"2026-07-16T20:29:04.507377Z","price_level":"64118.73","new_quantity":"0.00156676"},{"side":"bid","event_time":"2026-07-16T20:29:04.507377Z","price_level":"64115.51","new_quantity":"0"},{"side":"offer","event_time":"2026-07-16T20:29:04.507377Z","price_level":"64152.31","new_quantity":"0.40171656"},{"side":"offer","event_time":"2026-07-16T20:29:04.507377Z","price_level":"64154.56","new_quantity":"0"},{"side":"offer","event_time":"2026-07-16T20:29:04.507377Z","price_level":"64156.48","new_quantity":"0.8419954"},{"side":"offer","event_time":"2026-07-16T20:29:04.507377Z","price_level":"64156.49","new_quantity":"0.65487407"},{"side":"offer","event_time":"2026-07-16T20:29:04.507377Z","price_level":"64156.5","new_quantity":"0"},{"side":"offer","event_time":"2026-07-16T20:29:04.507377Z","price_level":"64783.45","new_quantity":"0"}]}]}
{"channel":"l2_data","timestamp":"2026-07-16T20:29:04.815101057Z","sequence_num":250,"events":[{"type":"update","product_id":"BTC-USD","updates":[{"side":"bid","event_time":"2026-07-16T20:29:04.598199Z","price_level":"64138","new_quantity":"0"},{"side":"bid","event_time":"2026-07-16T20:29:04.598199Z","price_level":"64131.51","new_quantity":"0.686805"},{"side":"bid","event_time":"2026-07-16T20:29:04.598199Z","price_level":"64119.32","new_quantity":"0"},{"side":"bid","event_time":"2026-07-16T20:29:04.598199Z","price_level":"64118.01","new_quantity":"0.65488128"},{"side":"bid","event_time":"2026-07-16T20:29:04.598199Z","price_level":"62603","new_quantity":"0"},{"side":"bid","event_time":"2026-07-16T20:29:04.598199Z","price_level":"56126.5","new_quantity":"0.01337205"},{"side":"offer","event_time":"2026-07-16T20:29:04.598199Z","price_level":"64167.88","new_quantity":"0"}]}]}
{"channel":"l2_data","timestamp":"2026-07-16T20:29:04.816358876Z","sequence_num":251,"events":[{"type":"update","product_id":"BTC-USD","updates":[{"side":"bid","event_time":"2026-07-16T20:29:04.662795Z","price_level":"64144.57","new_quantity":"0.00277729"},{"side":"bid","event_time":"2026-07-16T20:29:04.662795Z","price_level":"64131.51","new_quantity":"0"},{"side":"offer","event_time":"2026-07-16T20:29:04.662795Z","price_level":"64144.58","new_quantity":"0.3483136"},{"side":"offer","event_time":"2026-07-16T20:29:04.662795Z","price_level":"64144.83","new_quantity":"0"},{"side":"offer","event_time":"2026-07-16T20:29:04.662795Z","price_level":"64145.8","new_quantity":"0"},{"side":"offer","event_time":"2026-07-16T20:29:04.662795Z","price_level":"65659.46","new_quantity":"0.00583"}]}]}
{"channel":"l2_data","timestamp":"2026-07-16T20:29:04.816597457Z","sequence_num":252,"events":[{"type":"update","product_id":"BTC-USD","updates":[{"side":"bid","event_time":"2026-07-16T20:29:04.689788Z","price_level":"64082.18","new_quantity":"0.00858241"},{"side":"bid","event_time":"2026-07-16T20:29:04.689788Z","price_level":"56126.5","new_quantity":"0"}]}]}
{"channel":"l2_data","timestamp":"2026-07-16T20:29:04.817503261Z","sequence_num":253,"events":[{"type":"update","product_id":"BTC-USD","updates":[{"side":"bid","event_time":"2026-07-16T20:29:04.758977Z","price_level":"64130.88","new_quantity":"0"},{"side":"offer","event_time":"2026-07-16T20:29:04.758977Z","price_level":"64167.88","new_quantity":"0.00779505"},{"side":"offer","event_time":"2026-07-16T20:29:04.758977Z","price_level":"64784.09","new_quantity":"0.03890047"},{"side":"offer","event_time":"2026-07-16T20:29:04.758977Z","price_level":"65659.46","new_quantity":"0"}]}]}
{"channel":"l2_data","timestamp":"2026-07-16T20:29:04.830753726Z","sequence_num":254,"events":[{"type":"update","product_id":"BTC-USD","updates":[{"side":"bid","event_time":"2026-07-16T20:29:04.793648Z","price_level":"64138.61","new_quantity":"0"},{"side":"bid","event_time":"2026-07-16T20:29:04.793648Z","price_level":"64136.43","new_quantity":"0"},{"side":"bid","event_time":"2026-07-16T20:29:04.793648Z","price_level":"64132.39","new_quantity":"0.12474194"},{"side":"bid","event_time":"2026-07-16T20:29:04.793648Z","price_level":"64129.96","new_quantity":"0.15593335"},{"side":"bid","event_time":"2026-07-16T20:29:04.793648Z","price_level":"64127.67","new_quantity":"0.07395"},{"side":"bid","event_time":"2026-07-16T20:29:04.793648Z","price_level":"64118.01","new_quantity":"0"},{"side":"bid","event_time":"2026-07-16T20:29:04.793648Z","price_level":"64115.54","new_quantity":"0.63212657"},{"side":"bid","event_time":"2026-07-16T20:29:04.793648Z","price_level":"64115.53","new_quantity":"0.65489178"},{"side":"bid","event_time":"2026-07-16T20:29:04.793648Z","price_level":"64115.52","new_quantity":"0"},{"side":"offer","event_time":"2026-07-16T20:29:04.793648Z","price_level":"64152.29","new_quantity":"0.78373052"},{"side":"offer","event_time":"2026-07-16T20:29:04.793648Z","price_level":"64152.3","new_quantity":"0.65490266"},{"side":"offer","event_time":"2026-07-16T20:29:04.793648Z","price_level":"64152.31","new_quantity":"0.00896304"},{"side":"offer","event_time":"2026-07-16T20:29:04.793648Z","price_level":"64156.48","new_quantity":"0.45103558"},{"side":"offer","event_time":"2026-07-16T20:29:04.793648Z","price_level":"64156.49","new_quantity":"0"},{"side":"offer","event_time":"2026-07-16T20:29:04.793648Z","price_level":"64371.95","new_quantity":"0.00583"},{"side":"offer","event_time":"2026-07-16T20:29:04.793648Z","price_level":"64372.07","new_quantity":"0"},{"side":"offer","event_time":"2026-07-16T20:29:04.793648Z","price_level":"65444.73","new_quantity":"0"}]}]}
{"channel":"l2_data","timestamp":"2026-07-16T20:29:04.880115295Z","sequence_num":255,"events":[{"type":"update","product_id":"BTC-USD","updates":[{"side":"bid","event_time":"2026-07-16T20:29:04.849799Z","price_level":"64133.16","new_quantity":"0.12474045"},{"side":"bid","event_time":"2026-07-16T20:29:04.849799Z","price_level":"64132.39","new_quantity":"0"},{"side":"bid","event_time":"2026-07-16T20:29:04.849799Z","price_level":"64129.96","new_quantity":"0"},{"side":"offer","event_time":"2026-07-16T20:29:04.849799Z","price_level":"64144.58","new_quantity":"0.34709435"},{"side":"offer","event_time":"2026-07-16T20:29:04.849799Z","price_level":"64150.72","new_quantity":"0"},{"side":"offer","event_time":"2026-07-16T20:29:04.849799Z","price_level":"64152.29","new_quantity":"0.73351493"},{"side":"offer","event_time":"2026-07-16T20:29:04.849799Z","price_level":"64152.3","new_quantity":"0"},{"side":"offer","event_time":"2026-07-16T20:29:04.849799Z","price_level":"64154.56","new_quantity":"0.65489795"},{"side":"offer","event_time":"2026-07-16T20:29:04.849799Z","price_level":"64371.83","new_quantity":"0.00583"},{"side":"offer","event_time":"2026-07-16T20:29:04.849799Z","price_level":"64371.95","new_quantity":"0"},{"side":"offer","event_time":"2026-07-16T20:29:04.849799Z","price_level":"64586.32","new_quantity":"0.00583"},{"side":"offer","event_time":"2026-07-16T20:29:04.849799Z","price_level":"64586.5","new_quantity":"0"},{"side":"offer","event_time":"2026-07-16T20:29:04.849799Z","price_level":"64800.78","new_quantity":"0.00583"},{"side":"offer","event_time":"2026-07-16T20:29:04.849799Z","price_level":"64800.95","new_quantity":"0"},{"side":"offer","event_time":"2026-07-16T20:29:04.849799Z","price_level":"65229.95","new_quantity":"0"},{"side":"offer","event_time":"2026-07-16T20:29:04.849799Z","price_level":"65230.12","new_quantity":"0.00583"},{"side":"offer","event_time":"2026-07-16T20:29:04.849799Z","price_level":"65444.07","new_quantity":"0.00583"},{"side":"offer","event_time":"2026-07-16T20:29:04.849799Z","price_level":"65659.04","new_quantity":"0.00583"}]}]}
{"channel":"l2_data","timestamp":"2026-07-16T20:29:04.931026865Z","sequence_num":256,"events":[{"type":"update","product_id":"BTC-USD","updates":[{"side":"bid","event_time":"2026-07-16T20:29:04.88933Z","price_level":"56126.5","new_quantity":"0.01337205"},{"side":"offer","event_time":"2026-07-16T20:29:04.88933Z","price_level":"64144.58","new_quantity":"0.37680837"},{"side":"offer","event_time":"2026-07-16T20:29:04.88933Z","price_level":"64149.69","new_quantity":"0.00009743"},{"side":"offer","event_time":"2026-07-16T20:29:04.88933Z","price_level":"64149.76","new_quantity":"0"},{"side":"offer","event_time":"2026-07-16T20:29:04.88933Z","price_level":"64150.66","new_quantity":"0.00779415"},{"side":"offer","event_time":"2026-07-16T20:29:04.88933Z","price_level":"64167.88","new_quantity":"0"}]}]}
{"channel":"l2_data","timestamp":"2026-07-16T20:29:04.977090583Z","sequence_num":257,"events":[{"type":"update","product_id":"BTC-USD","updates":[{"side":"offer","event_time":"2026-07-16T20:29:04.949465Z","price_level":"65015.24","new_quantity":"0.00583"},{"side":"offer","event_time":"2026-07-16T20:29:04.949465Z","price_level":"65015.48","new_quantity":"0"},{"side":"offer","event_time":"2026-07-16T20:29:04.949465Z","price_level":"65444.07","new_quantity":"0"},{"side":"offer","event_time":"2026-07-16T20:29:04.949465Z","price_level":"65444.56","new_quantity":"0.00583"},{"side":"offer","event_time":"2026-07-16T20:29:04.949465Z","price_level":"65659.04","new_quantity":"0"}]}]}
{"channel":"l2_data","timestamp":"2026-07-16T20:29:05.029780266Z","sequence_num":258,"events":[{"type":"update","product_id":"BTC-USD","updates":[{"side":"bid","event_time":"2026-07-16T20:29:05.005097Z","price_level":"64138.2","new_quantity":"0.00431049"},{"side":"bid","event_time":"2026-07-16T20:29:05.005097Z","price_level":"56126.5","new_quantity":"0"},{"side":"offer","event_time":"2026-07-16T20:29:05.005097Z","price_level":"64185.13","new_quantity":"0.62467699"}]}]}
{"channel":"l2_data","timestamp":"2026-07-16T20:29:05.081000089Z","sequence_num":259,"events":[{"type":"update","product_id":"BTC-USD","updates":[{"side":"bid","event_time":"2026-07-16T20:29:05.04461Z","price_level":"64143.28","new_quantity":"0.00779505"},{"side":"bid","event_time":"2026-07-16T20:29:05.04461Z","price_level":"64139.76","new_quantity":"0"},{"side":"bid","event_time":"2026-07-16T20:29:05.04461Z","price_level":"64138.16","new_quantity":"0"},{"side":"bid","event_time":"2026-07-16T20:29:05.04461Z","price_level":"64137.68","new_quantity":"0.12473165"},{"side":"bid","event_time":"2026-07-16T20:29:05.04461Z","price_level":"64133.16","new_quantity":"0"},{"side":"bid","event_time":"2026-07-16T20:29:05.04461Z","price_level":"64130.87","new_quantity":"0.07398"},{"side":"bid","event_time":"2026-07-16T20:29:05.04461Z","price_level":"63501.88","new_quantity":"0"},{"side":"offer","event_time":"2026-07-16T20:29:05.04461Z","price_level":"64144.58","new_quantity":"0.3459406"},{"side":"offer","event_time":"2026-07-16T20:29:05.04461Z","price_level":"64150.7","new_quantity":"0"},{"side":"offer","event_time":"2026-07-16T20:29:05.04461Z","price_level":"64151.05","new_quantity":"0"},{"side":"offer","event_time":"2026-07-16T20:29:05.04461Z","price_level":"64152.31","new_quantity":"0"},{"side":"offer","event_time":"2026-07-16T20:29:05.04461Z","price_level":"64152.34","new_quantity":"0"},{"side":"offer","event_time":"2026-07-16T20:29:05.04461Z","price_level":"64167.88","new_quantity":"0.00779505"},{"side":"offer","event_time":"2026-07-16T20:29:05.04461Z","price_level":"64185.12","new_quantity":"0.48572031"},{"side":"offer","event_time":"2026-07-16T20:29:05.04461Z","price_level":"64185.13","new_quantity":"0"},{"side":"offer","event_time":"2026-07-16T20:29:05.04461Z","price_level":"64185.14","new_quantity":"0"},{"side":"offer","event_time":"2026-07-16T20:29:05.04461Z","price_level":"65659.25","new_quantity":"0.00583"}]}]}
{"channel":"l2_data","timestamp":"2026-07-16T20:29:05.129674908Z","sequence_num":260,"events":[{"type":"update","product_id":"BTC-USD","updates":[{"side":"bid","event_time":"2026-07-16T20:29:05.103211Z","price_level":"64131.57","new_quantity":"0.585719"},{"side":"offer","event_time":"2026-07-16T20:29:05.103211Z","price_level":"65230.08","new_quantity":"0.00583"},{"side":"offer","event_time":"2026-07-16T20:29:05.103211Z","price_level":"65230.12","new_quantity":"0"},{"side":"offer","event_time":"2026-07-16T20:29:05.103211Z","price_level":"65659.25","new_quantity":"0"}]}]}
{"channel":"heartbeats","timestamp":"2026-07-16T20:29:05.171583075Z","sequence_num":261,"events":[{"current_time":"2026-07-16 20:29:05.163028411 +0000 UTC m=+75509.317855448","heartbeat_counter":75509}]}
{"channel":"l2_data","timestamp":"2026-07-16T20:29:05.174565543Z","sequence_num":262,"events":[{"type":"update","product_id":"BTC-USD","updates":[{"side":"bid","event_time":"2026-07-16T20:29:05.153784Z","price_level":"64138.2","new_quantity":"0"},{"side":"bid","event_time":"2026-07-16T20:29:05.153784Z","price_level":"64131.57","new_quantity":"0"},{"side":"bid","event_time":"2026-07-16T20:29:05.153784Z","price_level":"64127.67","new_quantity":"0"}]}]}
{"channel":"l2_data","timestamp":"2026-07-16T20:29:05.229364152Z","sequence_num":263,"events":[{"type":"update","product_id":"BTC-USD","updates":[{"side":"bid","event_time":"2026-07-16T20:29:05.189083Z","price_level":"64138.34","new_quantity":"0.12473037"},{"side":"bid","event_time":"2026-07-16T20:29:05.189083Z","price_level":"64137.68","new_quantity":"0"},{"side":"bid","event_time":"2026-07-16T20:29:05.189083Z","price_level":"56126.5","new_quantity":"0.01337205"},{"side":"offer","event_time":"2026-07-16T20:29:05.189083Z","price_level":"64167.88","new_quantity":"0"},{"side":"offer","event_time":"2026-07-16T20:29:05.189083Z","price_level":"65660.17","new_quantity":"0.00583"}]}]}
{"channel":"l2_data","timestamp":"2026-07-16T20:29:05.28184264Z","sequence_num":264,"events":[{"type":"update","product_id":"BTC-USD","updates":[{"side":"offer","event_time":"2026-07-16T20:29:05.234201Z","price_level":"64144.58","new_quantity":"0.33829234"}]}]}
{"channel":"l2_data","timestamp":"2026-07-16T20:29:05.330153189Z","sequence_num":265,"events":[{"type":"update","product_id":"BTC-USD","updates":[{"side":"bid","event_time":"2026-07-16T20:29:05.301319Z","price_level":"64139.76","new_quantity":"0.00779548"},{"side":"bid","event_time":"2026-07-16T20:29:05.301319Z","price_level":"64138.16","new_quantity":"0.00779567"},{"side":"bid","event_time":"2026-07-16T20:29:05.301319Z","price_level":"63501.24","new_quantity":"0.03937582"},{"side":"bid","event_time":"2026-07-16T20:29:05.301319Z","price_level":"56126.5","new_quantity":"0"},{"side":"offer","event_time":"2026-07-16T20:29:05.301319Z","price_level":"64150.64","new_quantity":"0.00896328"},{"side":"offer","event_time":"2026-07-16T20:29:05.301319Z","price_level":"64152.25","new_quantity":"0.00896305"}]}]}
{"channel":"l2_data","timestamp":"2026-07-16T20:29:05.380069031Z","sequence_num":266,"events":[{"type":"update","product_id":"BTC-USD","updates":[{"side":"bid","event_time":"2026-07-16T20:29:05.35251Z","price_level":"64131.64","new_quantity":"0.608033"},{"side":"offer","event_time":"2026-07-16T20:29:05.35251Z","price_level":"64144.58","new_quantity":"0.33753484"},{"side":"offer","event_time":"2026-07-16T20:29:05.35251Z","price_level":"64167.88","new_quantity":"0.00779505"}]}]}
{"channel":"l2_data","timestamp":"2026-07-16T20:29:05.427986618Z","sequence_num":267,"events":[{"type":"update","product_id":"BTC-USD","updates":[{"side":"offer","event_time":"2026-07-16T20:29:05.39848Z","price_level":"64150.99","new_quantity":"0.00009743"},{"side":"offer","event_time":"2026-07-16T20:29:05.39848Z","price_level":"64152.28","new_quantity":"0.00779396"}]}]}
{"channel":"l2_data","timestamp":"2026-07-16T20:29:05.475519319Z","sequence_num":268,"events":[{"type":"update","product_id":"BTC-USD","updates":[{"side":"bid","event_time":"2026-07-16T20:29:05.436447Z","price_level":"64144.57","new_quantity":"0.00277712"}]}]}
{"channel":"l2_data","timestamp":"2026-07-16T20:29:05.528914422Z","sequence_num":269,"events":[{"type":"update","product_id":"BTC-USD","updates":[{"side":"bid","event_time":"2026-07-16T20:29:05.506282Z","price_level":"64144.57","new_quantity":"0.00277709"},{"side":"bid","event_time":"2026-07-16T20:29:05.506282Z","price_level":"64131.64","new_quantity":"0"},{"side":"bid","event_time":"2026-07-16T20:29:05.506282Z","price_level":"56126.5","new_quantity":"0.01337205"},{"side":"offer","event_time":"2026-07-16T20:29:05.506282Z","price_level":"64152.29","new_quantity":"0.39275363"},{"side":"offer","event_time":"2026-07-16T20:29:05.506282Z","price_level":"64154.56","new_quantity":"0"},{"side":"offer","event_time":"2026-07-16T20:29:05.506282Z","price_level":"64156.46","new_quantity":"0.84198916"},{"side":"offer","event_time":"2026-07-16T20:29:05.506282Z","price_level":"64156.47","new_quantity":"0.65486362"},{"side":"offer","event_time":"2026-07-16T20:29:05.506282Z","price_level":"64156.48","new_quantity":"0"},{"side":"offer","event_time":"2026-07-16T20:29:05.506282Z","price_level":"65660.15","new_quantity":"0.00583"},{"side":"offer","event_time":"2026-07-16T20:29:05.506282Z","price_level":"65660.17","new_quantity":"0"}]}]}
{"channel":"l2_data","timestamp":"2026-07-16T20:29:05.576337721Z","sequence_num":270,"events":[{"type":"update","product_id":"BTC-USD","updates":[{"side":"bid","event_time":"2026-07-16T20:29:05.516585Z","price_level":"64134.84","new_quantity":"0.12473719"}]}]}
{"channel":"l2_data","timestamp":"2026-07-16T20:29:05.624748504Z","sequence_num":271,"events":[{"type":"update","product_id":"BTC-USD","updates":[{"side":"bid","event_time":"2026-07-16T20:29:05.598201Z","price_level":"56126.5","new_quantity":"0"}]}]}
{"channel":"l2_data","timestamp":"2026-07-16T20:29:05.675050091Z","sequence_num":272,"events":[{"type":"update","product_id":"BTC-USD","updates":[{"side":"bid","event_time":"2026-07-16T20:29:05.629943Z","price_level":"64138.78","new_quantity":"0.02"}]}]}
{"channel":"l2_data","timestamp":"2026-07-16T20:29:05.726481655Z","sequence_num":273,"events":[{"type":"update","product_id":"BTC-USD","updates":[{"side":"offer","event_time":"2026-07-16T20:29:05.686511Z","price_level":"64144.58","new_quantity":"0.33707182"},{"side":"offer","event_time":"2026-07-16T20:29:05.686511Z","price_level":"64167.88","new_quantity":"0"}]}]}
{"channel":"l2_data","timestamp":"2026-07-16T20:29:05.885500786Z","sequence_num":274,"events":[{"type":"update","product_id":"BTC-USD","updates":[{"side":"bid","event_time":"2026-07-16T20:29:05.720535Z","price_level":"64144.57","new_quantity":"0.00277706"}]}]}
{"channel":"l2_data","timestamp":"2026-07-16T20:29:05.930475023Z","sequence_num":275,"events":[{"type":"update","product_id":"BTC-USD","updates":[{"side":"bid","event_time":"2026-07-16T20:29:05.889365Z","price_level":"64138.78","new_quantity":"0"},{"side":"bid","event_time":"2026-07-16T20:29:05.889365Z","price_level":"64131.63","new_quantity":"0"},{"side":"bid","event_time":"2026-07-16T20:29:05.889365Z","price_level":"56126.5","new_quantity":"0"},{"side":"offer","event_time":"2026-07-16T20:29:05.889365Z","price_level":"64167.88","new_quantity":"0.00779505"}]}]}
{"channel":"l2_data","timestamp":"2026-07-16T20:29:05.978276237Z","sequence_num":276,"events":[{"type":"update","product_id":"BTC-USD","updates":[{"side":"offer","event_time":"2026-07-16T20:29:05.951775Z","price_level":"64144.58","new_quantity":"0.33616847"},{"side":"offer","event_time":"2026-07-16T20:29:05.951775Z","price_level":"64149.69","new_quantity":"0"},{"side":"offer","event_time":"2026-07-16T20:29:05.951775Z","price_level":"64150.66","new_quantity":"0"},{"side":"offer","event_time":"2026-07-16T20:29:05.951775Z","price_level":"64156.57","new_quantity":"0.00180004"}]}]}
{"channel":"l2_data","timestamp":"2026-07-16T20:29:06.027124774Z","sequence_num":277,"events":[{"type":"update","product_id":"BTC-USD","updates":[{"side":"offer","event_time":"2026-07-16T20:29:05.999398Z","price_level":"64149.64","new_quantity":"0.00009743"},{"side":"offer","event_time":"2026-07-16T20:29:05.999398Z","price_level":"64150.6","new_quantity":"0.00779416"}]}]}
{"channel":"l2_data","timestamp":"2026-07-16T20:29:06.082289172Z","sequence_num":278,"events":[{"type":"update","product_id":"BTC-USD","updates":[{"side":"bid","event_time":"2026-07-16T20:29:06.049729Z","price_level":"64144.57","new_quantity":"0.00486967"},{"side":"bid","event_time":"2026-07-16T20:29:06.049729Z","price_level":"64139.76","new_quantity":"0"},{"side":"bid","event_time":"2026-07-16T20:29:06.049729Z","price_level":"64138.35","new_quantity":"0"},{"side":"bid","event_time":"2026-07-16T20:29:06.049729Z","price_level":"64138.2","new_quantity":"0.00346059"},{"side":"bid","event_time":"2026-07-16T20:29:06.049729Z","price_level":"64138.16","new_quantity":"0"},{"side":"bid","event_time":"2026-07-16T20:29:06.049729Z","price_level":"64064.43","new_quantity":"2.14460467"},{"side":"bid","event_time":"2026-07-16T20:29:06.049729Z","price_level":"64059.08","new_quantity":"0"},{"side":"offer","event_time":"2026-07-16T20:29:06.049729Z","price_level":"64150.64","new_quantity":"0"},{"side":"offer","event_time":"2026-07-16T20:29:06.049729Z","price_level":"64150.99","new_quantity":"0"},{"side":"offer","event_time":"2026-07-16T20:29:06.049729Z","price_level":"64152.25","new_quantity":"0"},{"side":"offer","event_time":"2026-07-16T20:29:06.049729Z","price_level":"64152.28","new_quantity":"0"},{"side":"offer","event_time":"2026-07-16T20:29:06.049729Z","price_level":"64185.1","new_quantity":"0.48572046"},{"side":"offer","event_time":"2026-07-16T20:29:06.049729Z","price_level":"64185.12","new_quantity":"0"}]}]}
{"channel":"l2_data","timestamp":"2026-07-16T20:29:06.134533212Z","sequence_num":279,"events":[{"type":"update","product_id":"BTC-USD","updates":[{"side":"bid","event_time":"2026-07-16T20:29:06.075551Z","price_level":"64144.57","new_quantity":"0"},{"side":"bid","event_time":"2026-07-16T20:29:06.075551Z","price_level":"64144.22","new_quantity":"0"},{"side":"bid","event_time":"2026-07-16T20:29:06.075551Z","price_level":"64143.28","new_quantity":"0"},{"side":"bid","event_time":"2026-07-16T20:29:06.075551Z","price_level":"64142.96","new_quantity":"0"},{"side":"bid","event_time":"2026-07-16T20:29:06.075551Z","price_level":"64142.94","new_quantity":"0"},{"side":"bid","event_time":"2026-07-16T20:29:06.075551Z","price_level":"64141.34","new_quantity":"0.177305"},{"side":"bid","event_time":"2026-07-16T20:29:06.075551Z","price_level":"64138.34","new_quantity":"0"},{"side":"bid","event_time":"2026-07-16T20:29:06.075551Z","price_level":"64138.11","new_quantity":"0"},{"side":"bid","event_time":"2026-07-16T20:29:06.075551Z","price_level":"64137.93","new_quantity":"0"},{"side":"bid","event_time":"2026-07-16T20:29:06.075551Z","price_level":"64136.44","new_quantity":"0"},{"side":"bid","event_time":"2026-07-16T20:29:06.075551Z","price_level":"64134.96","new_quantity":"0"},{"side":"bid","event_time":"2026-07-16T20:29:06.075551Z","price_level":"64134.65","new_quantity":"0.01559176"},{"side":"bid","event_time":"2026-07-16T20:29:06.075551Z","price_level":"64133.37","new_quantity":"0.31190852"},{"side":"bid","event_time":"2026-07-16T20:29:06.075551Z","price_level":"64133.36","new_quantity":"0"},{"side":"bid","event_time":"2026-07-16T20:29:06.075551Z","price_level":"64131.9","new_quantity":"0.15592862"},{"side":"bid","event_time":"2026-07-16T20:29:06.075551Z","price_level":"64131.53","new_quantity":"0"},{"side":"bid","event_time":"2026-07-16T20:29:06.075551Z","price_level":"64131.52","new_quantity":"0"},{"side":"bid","event_time":"2026-07-16T20:29:06.075551Z","price_level":"64130.87","new_quantity":"0"},{"side":"bid","event_time":"2026-07-16T20:29:06.075551Z","price_level":"64128.73","new_quantity":"0.0077892"},{"side":"bid","event_time":"2026-07-16T20:29:06.075551Z","price_level":"64126.49","new_quantity":"0"},{"side":"bid","event_time":"2026-07-16T20:29:06.075551Z","price_level":"64123.48","new_quantity":"0"},{"side":"bid","event_time":"2026-07-16T20:29:06.075551Z","price_level":"64115.72","new_quantity":"0.00583"},{"side":"bid","event_time":"2026-07-16T20:29:06.075551Z","price_level":"64115.71","new_quantity":"0.00583"},{"side":"bid","event_time":"2026-07-16T20:29:06.075551Z","price_level":"64115.54","new_quantity":"0"},{"side":"bid","event_time":"2026-07-16T20:29:06.075551Z","price_level":"64115.39","new_quantity":"0"},{"side":"bid","event_time":"2026-07-16T20:29:06.075551Z","price_level":"64113.02","new_quantity":"0.63293085"},{"side":"bid","event_time":"2026-07-16T20:29:06.075551Z","price_level":"64107","new_quantity":"0"},{"side":"bid","event_time":"2026-07-16T20:29:06.075551Z","price_level":"64104.44","new_quantity":"0"},{"side":"bid","event_time":"2026-07-16T20:29:06.075551Z","price_level":"64100.59","new_quantity":"0"},{"side":"bid","event_time":"2026-07-16T20:29:06.075551Z","price_level":"64082.18","new_quantity":"0"},{"side":"bid","event_time":"2026-07-16T20:29:06.075551Z","price_level":"63908.38","new_quantity":"0"},{"side":"bid","event_time":"2026-07-16T20:29:06.075551Z","price_level":"63049.42","new_quantity":"0"},{"side":"bid","event_time":"2026-07-16T20:29:06.075551Z","price_level":"63043.56","new_quantity":"0.00583"},{"side":"bid","event_time":"2026-07-16T20:29:06.075551Z","price_level":"62834.87","new_quantity":"0"},{"side":"offer","event_time":"2026-07-16T20:29:06.075551Z","price_level":"64142.4","new_quantity":"0.31190852"},{"side":"offer","event_time":"2026-07-16T20:29:06.075551Z","price_level":"64143.16","new_quantity":"0.04961402"},{"side":"offer","event_time":"2026-07-16T20:29:06.075551Z","price_level":"64143.29","new_quantity":"0.12472076"},{"side":"offer","event_time":"2026-07-16T20:29:06.075551Z","price_level":"64144.57","new_quantity":"0.12514711"},{"side":"offer","event_time":"2026-07-16T20:29:06.075551Z","price_level":"64144.58","new_quantity":"0.20287894"},{"side":"offer","event_time":"2026-07-16T20:29:06.075551Z","price_level":"64145.07","new_quantity":"0"},{"side":"offer","event_time":"2026-07-16T20:29:06.075551Z","price_level":"64145.77","new_quantity":"0.47855058"},{"side":"offer","event_time":"2026-07-16T20:29:06.075551Z","price_level":"64147.37","new_quantity":"0"},{"side":"offer","event_time":"2026-07-16T20:29:06.075551Z","price_level":"64151.55","new_quantity":"0"},{"side":"offer","event_time":"2026-07-16T20:29:06.075551Z","price_level":"64152.28","new_quantity":"0.0077892"},{"side":"offer","event_time":"2026-07-16T20:29:06.075551Z","price_level":"64152.3","new_quantity":"0.06167671"},{"side":"offer","event_time":"2026-07-16T20:29:06.075551Z","price_level":"64154.26","new_quantity":"0.001545"},{"side":"offer","event_time":"2026-07-16T20:29:06.075551Z","price_level":"64155.64","new_quantity":"0"},{"side":"offer","event_time":"2026-07-16T20:29:06.075551Z","price_level":"64156.15","new_quantity":"0.00583"},{"side":"offer","event_time":"2026-07-16T20:29:06.075551Z","price_level":"64156.46","new_quantity":"0.48969501"},{"side":"offer","event_time":"2026-07-16T20:29:06.075551Z","price_level":"64156.47","new_quantity":"0"},{"side":"offer","event_time":"2026-07-16T20:29:06.075551Z","price_level":"64157.39","new_quantity":"0"},{"side":"offer","event_time":"2026-07-16T20:29:06.075551Z","price_level":"64157.86","new_quantity":"0.06295613"},{"side":"offer","event_time":"2026-07-16T20:29:06.075551Z","price_level":"64158.45","new_quantity":"1.32825274"},{"side":"offer","event_time":"2026-07-16T20:29:06.075551Z","price_level":"64159","new_quantity":"1"},{"side":"offer","event_time":"2026-07-16T20:29:06.075551Z","price_level":"64160.84","new_quantity":"0"},{"side":"offer","event_time":"2026-07-16T20:29:06.075551Z","price_level":"64162.71","new_quantity":"0.02"},{"side":"offer","event_time":"2026-07-16T20:29:06.075551Z","price_level":"64165.48","new_quantity":"0.22444635"},{"side":"offer","event_time":"2026-07-16T20:29:06.075551Z","price_level":"64165.49","new_quantity":"0"},{"side":"offer","event_time":"2026-07-16T20:29:06.075551Z","price_level":"64167.56","new_quantity":"0"},{"side":"offer","event_time":"2026-07-16T20:29:06.075551Z","price_level":"64193","new_quantity":"0.96572545"},{"side":"offer","event_time":"2026-07-16T20:29:06.075551Z","price_level":"65229.96","new_quantity":"0.00583"},{"side":"offer","event_time":"2026-07-16T20:29:06.075551Z","price_level":"65230.08","new_quantity":"0"},{"side":"offer","event_time":"2026-07-16T20:29:06.075551Z","price_level":"65444.56","new_quantity":"0"},{"side":"offer","event_time":"2026-07-16T20:29:06.075551Z","price_level":"65659.68","new_quantity":"0"},{"side":"offer","event_time":"2026-07-16T20:29:06.075551Z","price_level":"65660.15","new_quantity":"0"}]}]}
{"channel":"heartbeats","timestamp":"2026-07-16T20:29:06.169730898Z","sequence_num":280,"events":[{"current_time":"2026-07-16 20:29:06.162885103 +0000 UTC m=+75510.317712162","heartbeat_counter":75510}]}
{"channel":"l2_data","timestamp":"2026-07-16T20:29:06.186106568Z","sequence_num":281,"events":[{"type":"update","product_id":"BTC-USD","updates":[{"side":"bid","event_time":"2026-07-16T20:29:06.123577Z","price_level":"64141.34","new_quantity":"0"},{"side":"bid","event_time":"2026-07-16T20:29:06.123577Z","price_level":"64140.65","new_quantity":"0.0102588"},{"side":"bid","event_time":"2026-07-16T20:29:06.123577Z","price_level":"64140","new_quantity":"0"},{"side":"bid","event_time":"2026-07-16T20:29:06.123577Z","price_level":"64136.15","new_quantity":"0"},{"side":"bid","event_time":"2026-07-16T20:29:06.123577Z","price_level":"64134.94","new_quantity":"0"},{"side":"bid","event_time":"2026-07-16T20:29:06.123577Z","price_level":"64134.84","new_quantity":"0"},{"side":"bid","event_time":"2026-07-16T20:29:06.123577Z","price_level":"64134.65","new_quantity":"0"},{"side":"bid","event_time":"2026-07-16T20:29:06.123577Z","price_level":"64133.8","new_quantity":"0.04553452"},{"side":"bid","event_time":"2026-07-16T20:29:06.123577Z","price_level":"64133.71","new_quantity":"0"},{"side":"bid","event_time":"2026-07-16T20:29:06.123577Z","price_level":"64133.55","new_quantity":"0"},{"side":"bid","event_time":"2026-07-16T20:29:06.123577Z","price_level":"64133.37","new_quantity":"0"},{"side":"bid","event_time":"2026-07-16T20:29:06.123577Z","price_level":"64132.29","new_quantity":"0.12474214"},{"side":"bid","event_time":"2026-07-16T20:29:06.123577Z","price_level":"64132.15","new_quantity":"0"},{"side":"bid","event_time":"2026-07-16T20:29:06.123577Z","price_level":"64131.9","new_quantity":"0"},{"side":"bid","event_time":"2026-07-16T20:29:06.123577Z","price_level":"64131.83","new_quantity":"0"},{"side":"bid","event_time":"2026-07-16T20:29:06.123577Z","price_level":"64131.43","new_quantity":"0.3588241"},{"side":"bid","event_time":"2026-07-16T20:29:06.123577Z","price_level":"64131.42","new_quantity":"0"},{"side":"bid","event_time":"2026-07-16T20:29:06.123577Z","price_level":"64129.93","new_quantity":"0.01559176"},{"side":"bid","event_time":"2026-07-16T20:29:06.123577Z","price_level":"64129.48","new_quantity":"0"},{"side":"bid","event_time":"2026-07-16T20:29:06.123577Z","price_level":"64128.73","new_quantity":"0"},{"side":"bid","event_time":"2026-07-16T20:29:06.123577Z","price_level":"64128.51","new_quantity":"0.31190852"},{"side":"bid","event_time":"2026-07-16T20:29:06.123577Z","price_level":"64128.5","new_quantity":"0"},{"side":"bid","event_time":"2026-07-16T20:29:06.123577Z","price_level":"64128.49","new_quantity":"0"},{"side":"bid","event_time":"2026-07-16T20:29:06.123577Z","price_level":"64127.82","new_quantity":"0"},{"side":"bid","event_time":"2026-07-16T20:29:06.123577Z","price_level":"64127.76","new_quantity":"0"},{"side":"bid","event_time":"2026-07-16T20:29:06.123577Z","price_level":"64127.29","new_quantity":"0"},{"side":"bid","event_time":"2026-07-16T20:29:06.123577Z","price_level":"64126.48","new_quantity":"0"},{"side":"bid","event_time":"2026-07-16T20:29:06.123577Z","price_level":"64125.88","new_quantity":"0"},{"side":"bid","event_time":"2026-07-16T20:29:06.123577Z","price_level":"64125.87","new_quantity":"0"},{"side":"bid","event_time":"2026-07-16T20:29:06.123577Z","price_level":"64125.28","new_quantity":"0.0486477"},{"side":"bid","event_time":"2026-07-16T20:29:06.123577Z","price_level":"64124.94","new_quantity":"0.07399"},{"side":"bid","event_time":"2026-07-16T20:29:06.123577Z","price_level":"64124.87","new_quantity":"0"},{"side":"bid","event_time":"2026-07-16T20:29:06.123577Z","price_level":"64123.18","new_quantity":"0.18620939"},{"side":"bid","event_time":"2026-07-16T20:29:06.123577Z","price_level":"64123.17","new_quantity":"0.31190852"},{"side":"bid","event_time":"2026-07-16T20:29:06.123577Z","price_level":"64123.16","new_quantity":"0"},{"side":"bid","event_time":"2026-07-16T20:29:06.123577Z","price_level":"64122.61","new_quantity":"0.20194544"},{"side":"bid","event_time":"2026-07-16T20:29:06.123577Z","price_level":"64122.6","new_quantity":"0.23359045"},{"side":"bid","event_time":"2026-07-16T20:29:06.123577Z","price_level":"64122.59","new_quantity":"0"},{"side":"bid","event_time":"2026-07-16T20:29:06.123577Z","price_level":"64121.16","new_quantity":"0.04691558"},{"side":"bid","event_time":"2026-07-16T20:29:06.123577Z","price_level":"64120.81","new_quantity":"0"},{"side":"bid","event_time":"2026-07-16T20:29:06.123577Z","price_level":"64120.73","new_quantity":"0"},{"side":"bid","event_time":"2026-07-16T20:29:06.123577Z","price_level":"64120.45","new_quantity":"0"},{"side":"bid","event_time":"2026-07-16T20:29:06.123577Z","price_level":"64119.33","new_quantity":"0.18715549"},{"side":"bid","event_time":"2026-07-16T20:29:06.123577Z","price_level":"64119.32","new_quantity":"0.31190852"},{"side":"bid","event_time":"2026-07-16T20:29:06.123577Z","price_level":"64119.31","new_quantity":"0"},{"side":"bid","event_time":"2026-07-16T20:29:06.123577Z","price_level":"64118.73","new_quantity":"0.001545"},{"side":"bid","event_time":"2026-07-16T20:29:06.123577Z","price_level":"64118","new_quantity":"0"},{"side":"bid","event_time":"2026-07-16T20:29:06.123577Z","price_level":"64116.06","new_quantity":"0.00583"},{"side":"bid","event_time":"2026-07-16T20:29:06.123577Z","price_level":"64115.72","new_quantity":"0"},{"side":"bid","event_time":"2026-07-16T20:29:06.123577Z","price_level":"64115.71","new_quantity":"0"},{"side":"bid","event_time":"2026-07-16T20:29:06.123577Z","price_level":"64115.54","new_quantity":"0.59241455"},{"side":"bid","event_time":"2026-07-16T20:29:06.123577Z","price_level":"64115.53","new_quantity":"0"},{"side":"bid","event_time":"2026-07-16T20:29:06.123577Z","price_level":"64115.46","new_quantity":"0"},{"side":"bid","event_time":"2026-07-16T20:29:06.123577Z","price_level":"64115.19","new_quantity":"0"},{"side":"bid","event_time":"2026-07-16T20:29:06.123577Z","price_level":"64115.15","new_quantity":"0"},{"side":"bid","event_time":"2026-07-16T20:29:06.123577Z","price_level":"64113.02","new_quantity":"1.28785015"},{"side":"bid","event_time":"2026-07-16T20:29:06.123577Z","price_level":"64110.27","new_quantity":"0"},{"side":"bid","event_time":"2026-07-16T20:29:06.123577Z","price_level":"64108.66","new_quantity":"0.31190852"},{"side":"bid","event_time":"2026-07-16T20:29:06.123577Z","price_level":"64108.27","new_quantity":"0"},{"side":"bid","event_time":"2026-07-16T20:29:06.123577Z","price_level":"64106.97","new_quantity":"0.00155799"},{"side":"bid","event_time":"2026-07-16T20:29:06.123577Z","price_level":"64104.91","new_quantity":"0.31190852"},{"side":"bid","event_time":"2026-07-16T20:29:06.123577Z","price_level":"64103.87","new_quantity":"0"},{"side":"bid","event_time":"2026-07-16T20:29:06.123577Z","price_level":"64102.75","new_quantity":"0.23359045"},{"side":"bid","event_time":"2026-07-16T20:29:06.123577Z","price_level":"64102.74","new_quantity":"0"},{"side":"bid","event_time":"2026-07-16T20:29:06.123577Z","price_level":"64102","new_quantity":"0"},{"side":"bid","event_time":"2026-07-16T20:29:06.123577Z","price_level":"64101","new_quantity":"0"},{"side":"bid","event_time":"2026-07-16T20:29:06.123577Z","price_level":"64100.56","new_quantity":"0.00778997"},{"side":"bid","event_time":"2026-07-16T20:29:06.123577Z","price_level":"64099","new_quantity":"1"},{"side":"bid","event_time":"2026-07-16T20:29:06.123577Z","price_level":"64098","new_quantity":"1"},{"side":"bid","event_time":"2026-07-16T20:29:06.123577Z","price_level":"64096.9","new_quantity":"0.23359045"},{"side":"bid","event_time":"2026-07-16T20:29:06.123577Z","price_level":"64096.89","new_quantity":"0.98264611"},{"side":"bid","event_time":"2026-07-16T20:29:06.123577Z","price_level":"64096.88","new_quantity":"0"},{"side":"bid","event_time":"2026-07-16T20:29:06.123577Z","price_level":"64092.42","new_quantity":"0"},{"side":"bid","event_time":"2026-07-16T20:29:06.123577Z","price_level":"64088.1","new_quantity":"0"},{"side":"bid","event_time":"2026-07-16T20:29:06.123577Z","price_level":"64084.64","new_quantity":"0.04691558"},{"side":"bid","event_time":"2026-07-16T20:29:06.123577Z","price_level":"64082.58","new_quantity":"0"},{"side":"bid","event_time":"2026-07-16T20:29:06.123577Z","price_level":"64082.17","new_quantity":"6.6300875"},{"side":"bid","event_time":"2026-07-16T20:29:06.123577Z","price_level":"64080.09","new_quantity":"0.00858269"},{"side":"bid","event_time":"2026-07-16T20:29:06.123577Z","price_level":"64079.71","new_quantity":"1.39433849"},{"side":"bid","event_time":"2026-07-16T20:29:06.123577Z","price_level":"64074.37","new_quantity":"0.04691558"},{"side":"bid","event_time":"2026-07-16T20:29:06.123577Z","price_level":"64070.12","new_quantity":"0.23359045"},{"side":"bid","event_time":"2026-07-16T20:29:06.123577Z","price_level":"64059.85","new_quantity":"0.23359045"},{"side":"bid","event_time":"2026-07-16T20:29:06.123577Z","price_level":"64050.01","new_quantity":"0.23359045"},{"side":"bid","event_time":"2026-07-16T20:29:06.123577Z","price_level":"64029.94","new_quantity":"0"},{"side":"bid","event_time":"2026-07-16T20:29:06.123577Z","price_level":"63900.87","new_quantity":"0.00583"},{"side":"bid","event_time":"2026-07-16T20:29:06.123577Z","price_level":"63693.72","new_quantity":"0"},{"side":"bid","event_time":"2026-07-16T20:29:06.123577Z","price_level":"63686.26","new_quantity":"0.00583"},{"side":"bid","event_time":"2026-07-16T20:29:06.123577Z","price_level":"63479.01","new_quantity":"0"},{"side":"bid","event_time":"2026-07-16T20:29:06.123577Z","price_level":"63471.63","new_quantity":"0.00703"},{"side":"bid","event_time":"2026-07-16T20:29:06.123577Z","price_level":"63264.14","new_quantity":"0"},{"side":"bid","event_time":"2026-07-16T20:29:06.123577Z","price_level":"63256.57","new_quantity":"0.00583"},{"side":"bid","event_time":"2026-07-16T20:29:06.123577Z","price_level":"63043.56","new_quantity":"0"},{"side":"bid","event_time":"2026-07-16T20:29:06.123577Z","price_level":"63042.09","new_quantity":"0.00583"},{"side":"bid","event_time":"2026-07-16T20:29:06.123577Z","price_level":"62827.02","new_quantity":"0.00583"},{"side":"bid","event_time":"2026-07-16T20:29:06.123577Z","price_level":"56123.68","new_quantity":"0"},{"side":"offer","event_time":"2026-07-16T20:29:06.123577Z","price_level":"64140.66","new_quantity":"1.2097528"},{"side":"offer","event_time":"2026-07-16T20:29:06.123577Z","price_level":"64141.34","new_quantity":"0.47716956"},{"side":"offer","event_time":"2026-07-16T20:29:06.123577Z","price_level":"64141.35","new_quantity":"0.03388978"},{"side":"offer","event_time":"2026-07-16T20:29:06.123577Z","price_level":"64141.36","new_quantity":"0"},{"side":"offer","event_time":"2026-07-16T20:29:06.123577Z","price_level":"64141.37","new_quantity":"0"},{"side":"offer","event_time":"2026-07-16T20:29:06.123577Z","price_level":"64141.4","new_quantity":"0.00234565"},{"side":"offer","event_time":"2026-07-16T20:29:06.123577Z","price_level":"64142.39","new_quantity":"0"},{"side":"offer","event_time":"2026-07-16T20:29:06.123577Z","price_level":"64142.4","new_quantity":"0.02"},{"side":"offer","event_time":"2026-07-16T20:29:06.123577Z","price_level":"64142.96","new_quantity":"0.00545669"},{"side":"offer","event_time":"2026-07-16T20:29:06.123577Z","price_level":"64143.16","new_quantity":"0"},{"side":"offer","event_time":"2026-07-16T20:29:06.123577Z","price_level":"64143.29","new_quantity":"0"},{"side":"offer","event_time":"2026-07-16T20:29:06.123577Z","price_level":"64143.55","new_quantity":"0.0486477"},{"side":"offer","event_time":"2026-07-16T20:29:06.123577Z","price_level":"64144.57","new_quantity":"0.04"},{"side":"offer","event_time":"2026-07-16T20:29:06.123577Z","price_level":"64144.58","new_quantity":"0.12471825"},{"side":"offer","event_time":"2026-07-16T20:29:06.123577Z","price_level":"64145.12","new_quantity":"0.00682087"},{"side":"offer","event_time":"2026-07-16T20:29:06.123577Z","price_level":"64145.76","new_quantity":"0.04691558"},{"side":"offer","event_time":"2026-07-16T20:29:06.123577Z","price_level":"64145.77","new_quantity":"0.431635"},{"side":"offer","event_time":"2026-07-16T20:29:06.123577Z","price_level":"64145.87","new_quantity":"0"},{"side":"offer","event_time":"2026-07-16T20:29:06.123577Z","price_level":"64146.19","new_quantity":"0"},{"side":"offer","event_time":"2026-07-16T20:29:06.123577Z","price_level":"64148.35","new_quantity":"0"},{"side":"offer","event_time":"2026-07-16T20:29:06.123577Z","price_level":"64150.92","new_quantity":"0"},{"side":"offer","event_time":"2026-07-16T20:29:06.123577Z","price_level":"64151.28","new_quantity":"0.000018"},{"side":"offer","event_time":"2026-07-16T20:29:06.123577Z","price_level":"64151.69","new_quantity":"0.0007795"},{"side":"offer","event_time":"2026-07-16T20:29:06.123577Z","price_level":"64153.22","new_quantity":"0.00583"},{"side":"offer","event_time":"2026-07-16T20:29:06.123577Z","price_level":"64154.69","new_quantity":"0"},{"side":"offer","event_time":"2026-07-16T20:29:06.123577Z","price_level":"64156.15","new_quantity":"0"},{"side":"offer","event_time":"2026-07-16T20:29:06.123577Z","price_level":"64160.58","new_quantity":"0.00002339"},{"side":"offer","event_time":"2026-07-16T20:29:06.123577Z","price_level":"64162.71","new_quantity":"0"},{"side":"offer","event_time":"2026-07-16T20:29:06.123577Z","price_level":"64166.42","new_quantity":"0"},{"side":"offer","event_time":"2026-07-16T20:29:06.123577Z","price_level":"64170.15","new_quantity":"0"},{"side":"offer","event_time":"2026-07-16T20:29:06.123577Z","price_level":"64171.66","new_quantity":"0"},{"side":"offer","event_time":"2026-07-16T20:29:06.123577Z","price_level":"64178.99","new_quantity":"0.32027682"},{"side":"offer","event_time":"2026-07-16T20:29:06.123577Z","price_level":"64181.03","new_quantity":"0.50796006"},{"side":"offer","event_time":"2026-07-16T20:29:06.123577Z","price_level":"64181.04","new_quantity":"0.48575119"},{"side":"offer","event_time":"2026-07-16T20:29:06.123577Z","price_level":"64181.05","new_quantity":"0"},{"side":"offer","event_time":"2026-07-16T20:29:06.123577Z","price_level":"64181.06","new_quantity":"0"},{"side":"offer","event_time":"2026-07-16T20:29:06.123577Z","price_level":"64181.11","new_quantity":"0"},{"side":"offer","event_time":"2026-07-16T20:29:06.123577Z","price_level":"64181.41","new_quantity":"0"},{"side":"offer","event_time":"2026-07-16T20:29:06.123577Z","price_level":"64185.09","new_quantity":"0"},{"side":"offer","event_time":"2026-07-16T20:29:06.123577Z","price_level":"64185.1","new_quantity":"0"},{"side":"offer","event_time":"2026-07-16T20:29:06.123577Z","price_level":"64185.16","new_quantity":"0.33470205"},{"side":"offer","event_time":"2026-07-16T20:29:06.123577Z","price_level":"64187.9","new_quantity":"0"},{"side":"offer","event_time":"2026-07-16T20:29:06.123577Z","price_level":"64189.93","new_quantity":"0.33000151"},{"side":"offer","event_time":"2026-07-16T20:29:06.123577Z","price_level":"64189.94","new_quantity":"0"},{"side":"offer","event_time":"2026-07-16T20:29:06.123577Z","price_level":"64191.2","new_quantity":"0.2962435"},{"side":"offer","event_time":"2026-07-16T20:29:06.123577Z","price_level":"64196.74","new_quantity":"0.45528083"},{"side":"offer","event_time":"2026-07-16T20:29:06.123577Z","price_level":"64196.75","new_quantity":"0.70469925"},{"side":"offer","event_time":"2026-07-16T20:29:06.123577Z","price_level":"64196.79","new_quantity":"1.23984345"},{"side":"offer","event_time":"2026-07-16T20:29:06.123577Z","price_level":"64196.88","new_quantity":"0.04691558"},{"side":"offer","event_time":"2026-07-16T20:29:06.123577Z","price_level":"64197.13","new_quantity":"0"},{"side":"offer","event_time":"2026-07-16T20:29:06.123577Z","price_level":"64198.72","new_quantity":"0"},{"side":"offer","event_time":"2026-07-16T20:29:06.123577Z","price_level":"64199.58","new_quantity":"2.0020945"},{"side":"offer","event_time":"2026-07-16T20:29:06.123577Z","price_level":"64199.59","new_quantity":"0"},{"side":"offer","event_time":"2026-07-16T20:29:06.123577Z","price_level":"64202.07","new_quantity":"0"},{"side":"offer","event_time":"2026-07-16T20:29:06.123577Z","price_level":"64226.24","new_quantity":"0"},{"side":"offer","event_time":"2026-07-16T20:29:06.123577Z","price_level":"64250","new_quantity":"0"},{"side":"offer","event_time":"2026-07-16T20:29:06.123577Z","price_level":"64369.68","new_quantity":"0.00583"},{"side":"offer","event_time":"2026-07-16T20:29:06.123577Z","price_level":"64371.83","new_quantity":"0"},{"side":"offer","event_time":"2026-07-16T20:29:06.123577Z","price_level":"64586.32","new_quantity":"0"},{"side":"offer","event_time":"2026-07-16T20:29:06.123577Z","price_level":"64796.51","new_quantity":"0.00583"},{"side":"offer","event_time":"2026-07-16T20:29:06.123577Z","price_level":"64797.98","new_quantity":"0"},{"side":"offer","event_time":"2026-07-16T20:29:06.123577Z","price_level":"64800.78","new_quantity":"0"},{"side":"offer","event_time":"2026-07-16T20:29:06.123577Z","price_level":"65015.24","new_quantity":"0"},{"side":"offer","event_time":"2026-07-16T20:29:06.123577Z","price_level":"65225.37","new_quantity":"0.00583"},{"side":"offer","event_time":"2026-07-16T20:29:06.123577Z","price_level":"65229.96","new_quantity":"0"},{"side":"offer","event_time":"2026-07-16T20:29:06.123577Z","price_level":"65439.8","new_quantity":"0.00583"},{"side":"offer","event_time":"2026-07-16T20:29:06.123577Z","price_level":"65654.25","new_quantity":"0.00583"}]}]}
{"channel":"l2_data","timestamp":"2026-07-16T20:29:06.234342608Z","sequence_num":282,"events":[{"type":"update","product_id":"BTC-USD","updates":[{"side":"bid","event_time":"2026-07-16T20:29:06.193257Z","price_level":"64140.65","new_quantity":"0.0002588"},{"side":"bid","event_time":"2026-07-16T20:29:06.193257Z","price_level":"64138.2","new_quantity":"0"},{"side":"bid","event_time":"2026-07-16T20:29:06.193257Z","price_level":"64137.79","new_quantity":"0"},{"side":"bid","event_time":"2026-07-16T20:29:06.193257Z","price_level":"64137.31","new_quantity":"0"},{"side":"bid","event_time":"2026-07-16T20:29:06.193257Z","price_level":"64133.8","new_quantity":"0"},{"side":"bid","event_time":"2026-07-16T20:29:06.193257Z","price_level":"64133.57","new_quantity":"0"},{"side":"bid","event_time":"2026-07-16T20:29:06.193257Z","price_level":"64129.93","new_quantity":"0"},{"side":"bid","event_time":"2026-07-16T20:29:06.193257Z","price_level":"64129.21","new_quantity":"0"},{"side":"bid","event_time":"2026-07-16T20:29:06.193257Z","price_level":"64128.72","new_quantity":"0"},{"side":"bid","event_time":"2026-07-16T20:29:06.193257Z","price_level":"64126.95","new_quantity":"0.0000501"},{"side":"bid","event_time":"2026-07-16T20:29:06.193257Z","price_level":"64126.28","new_quantity":"0.00066645"},{"side":"bid","event_time":"2026-07-16T20:29:06.193257Z","price_level":"64125.29","new_quantity":"0.0077892"},{"side":"bid","event_time":"2026-07-16T20:29:06.193257Z","price_level":"64124.94","new_quantity":"0"},{"side":"bid","event_time":"2026-07-16T20:29:06.193257Z","price_level":"64123.77","new_quantity":"0.28003159"},{"side":"bid","event_time":"2026-07-16T20:29:06.193257Z","price_level":"64123.76","new_quantity":"0.07399"},{"side":"bid","event_time":"2026-07-16T20:29:06.193257Z","price_level":"64123.19","new_quantity":"0.23359045"},{"side":"bid","event_time":"2026-07-16T20:29:06.193257Z","price_level":"64123.18","new_quantity":"0"},{"side":"bid","event_time":"2026-07-16T20:29:06.193257Z","price_level":"64122.61","new_quantity":"0.07890603"},{"side":"bid","event_time":"2026-07-16T20:29:06.193257Z","price_level":"64122.6","new_quantity":"0"},{"side":"bid","event_time":"2026-07-16T20:29:06.193257Z","price_level":"64122.19","new_quantity":"0"},{"side":"bid","event_time":"2026-07-16T20:29:06.193257Z","price_level":"64122.12","new_quantity":"0.0013329"},{"side":"bid","event_time":"2026-07-16T20:29:06.193257Z","price_level":"64120.81","new_quantity":"0.00020039"},{"side":"bid","event_time":"2026-07-16T20:29:06.193257Z","price_level":"64117.55","new_quantity":"0"},{"side":"bid","event_time":"2026-07-16T20:29:06.193257Z","price_level":"64113.02","new_quantity":"0.65836454"},{"side":"bid","event_time":"2026-07-16T20:29:06.193257Z","price_level":"64113","new_quantity":"0.0000309"},{"side":"bid","event_time":"2026-07-16T20:29:06.193257Z","price_level":"64110.62","new_quantity":"0.00040078"},{"side":"bid","event_time":"2026-07-16T20:29:06.193257Z","price_level":"64109.94","new_quantity":"0.63218178"},{"side":"bid","event_time":"2026-07-16T20:29:06.193257Z","price_level":"64106.97","new_quantity":"0"},{"side":"bid","event_time":"2026-07-16T20:29:06.193257Z","price_level":"64106.09","new_quantity":"0"},{"side":"bid","event_time":"2026-07-16T20:29:06.193257Z","price_level":"64100.56","new_quantity":"0"},{"side":"bid","event_time":"2026-07-16T20:29:06.193257Z","price_level":"64095.6","new_quantity":"0.00159803"},{"side":"bid","event_time":"2026-07-16T20:29:06.193257Z","price_level":"64090.8","new_quantity":"0"},{"side":"bid","event_time":"2026-07-16T20:29:06.193257Z","price_level":"64080.09","new_quantity":"0"},{"side":"bid","event_time":"2026-07-16T20:29:06.193257Z","price_level":"64078.88","new_quantity":"0.00666449"},{"side":"bid","event_time":"2026-07-16T20:29:06.193257Z","price_level":"64075.88","new_quantity":"0.00241653"},{"side":"bid","event_time":"2026-07-16T20:29:06.193257Z","price_level":"64064.43","new_quantity":"0"},{"side":"bid","event_time":"2026-07-16T20:29:06.193257Z","price_level":"64060.94","new_quantity":"0"},{"side":"bid","event_time":"2026-07-16T20:29:06.193257Z","price_level":"64053.29","new_quantity":"2.14497766"},{"side":"bid","event_time":"2026-07-16T20:29:06.193257Z","price_level":"64048.66","new_quantity":"0.00125243"},{"side":"bid","event_time":"2026-07-16T20:29:06.193257Z","price_level":"64040","new_quantity":"0.00016778"},{"side":"bid","event_time":"2026-07-16T20:29:06.193257Z","price_level":"64020","new_quantity":"2.00012075"},{"side":"bid","event_time":"2026-07-16T20:29:06.193257Z","price_level":"64016.3","new_quantity":"0.00999674"},{"side":"offer","event_time":"2026-07-16T20:29:06.193257Z","price_level":"64140.66","new_quantity":"1.23832318"},{"side":"offer","event_time":"2026-07-16T20:29:06.193257Z","price_level":"64141.34","new_quantity":"0.44863647"},{"side":"offer","event_time":"2026-07-16T20:29:06.193257Z","price_level":"64141.35","new_quantity":"0"},{"side":"offer","event_time":"2026-07-16T20:29:06.193257Z","price_level":"64141.4","new_quantity":"0"},{"side":"offer","event_time":"2026-07-16T20:29:06.193257Z","price_level":"64141.63","new_quantity":"0.02099946"},{"side":"offer","event_time":"2026-07-16T20:29:06.193257Z","price_level":"64142.27","new_quantity":"0.00545675"},{"side":"offer","event_time":"2026-07-16T20:29:06.193257Z","price_level":"64142.59","new_quantity":"0.31190852"},{"side":"offer","event_time":"2026-07-16T20:29:06.193257Z","price_level":"64142.96","new_quantity":"0"},{"side":"offer","event_time":"2026-07-16T20:29:06.193257Z","price_level":"64149.32","new_quantity":"0.0077892"},{"side":"offer","event_time":"2026-07-16T20:29:06.193257Z","price_level":"64152.28","new_quantity":"0"},{"side":"offer","event_time":"2026-07-16T20:29:06.193257Z","price_level":"64153.98","new_quantity":"0.00076656"},{"side":"offer","event_time":"2026-07-16T20:29:06.193257Z","price_level":"64157.76","new_quantity":"0.0002328"},{"side":"offer","event_time":"2026-07-16T20:29:06.193257Z","price_level":"64159.02","new_quantity":"0.00153313"},{"side":"offer","event_time":"2026-07-16T20:29:06.193257Z","price_level":"64165.48","new_quantity":"0.16659025"},{"side":"offer","event_time":"2026-07-16T20:29:06.193257Z","price_level":"64167.88","new_quantity":"0"},{"side":"offer","event_time":"2026-07-16T20:29:06.193257Z","price_level":"64169.38","new_quantity":"0.0004656"},{"side":"offer","event_time":"2026-07-16T20:29:06.193257Z","price_level":"64173.63","new_quantity":"0.04636754"},{"side":"offer","event_time":"2026-07-16T20:29:06.193257Z","price_level":"64174.64","new_quantity":"0.38681575"},{"side":"offer","event_time":"2026-07-16T20:29:06.193257Z","price_level":"64176.08","new_quantity":"0.32027682"},{"side":"offer","event_time":"2026-07-16T20:29:06.193257Z","price_level":"64177.36","new_quantity":"0.04387444"},{"side":"offer","event_time":"2026-07-16T20:29:06.193257Z","price_level":"64178.99","new_quantity":"0"},{"side":"offer","event_time":"2026-07-16T20:29:06.193257Z","price_level":"64184.29","new_quantity":"0.000582"},{"side":"offer","event_time":"2026-07-16T20:29:06.193257Z","price_level":"64185.11","new_quantity":"0.63320205"},{"side":"offer","event_time":"2026-07-16T20:29:06.193257Z","price_level":"64185.12","new_quantity":"0.5"},{"side":"offer","event_time":"2026-07-16T20:29:06.193257Z","price_level":"64185.16","new_quantity":"0"},{"side":"offer","event_time":"2026-07-16T20:29:06.193257Z","price_level":"64186.04","new_quantity":"0.00383282"},{"side":"offer","event_time":"2026-07-16T20:29:06.193257Z","price_level":"64188.3","new_quantity":"0.06044322"},{"side":"offer","event_time":"2026-07-16T20:29:06.193257Z","price_level":"64189.93","new_quantity":"0"},{"side":"offer","event_time":"2026-07-16T20:29:06.193257Z","price_level":"64192.99","new_quantity":"0.70474053"},{"side":"offer","event_time":"2026-07-16T20:29:06.193257Z","price_level":"64193.7","new_quantity":"1.27561107"},{"side":"offer","event_time":"2026-07-16T20:29:06.193257Z","price_level":"64196.73","new_quantity":"2.00218338"},{"side":"offer","event_time":"2026-07-16T20:29:06.193257Z","price_level":"64196.74","new_quantity":"0"},{"side":"offer","event_time":"2026-07-16T20:29:06.193257Z","price_level":"64196.75","new_quantity":"0"},{"side":"offer","event_time":"2026-07-16T20:29:06.193257Z","price_level":"64196.79","new_quantity":"0"},{"side":"offer","event_time":"2026-07-16T20:29:06.193257Z","price_level":"64196.87","new_quantity":"0.04195739"},{"side":"offer","event_time":"2026-07-16T20:29:06.193257Z","price_level":"64199.58","new_quantity":"0"},{"side":"offer","event_time":"2026-07-16T20:29:06.193257Z","price_level":"64214.11","new_quantity":"0.001164"},{"side":"offer","event_time":"2026-07-16T20:29:06.193257Z","price_level":"64230","new_quantity":"3"}]}]}
{"channel":"l2_data","timestamp":"2026-07-16T20:29:06.279713034Z","sequence_num":283,"events":[{"type":"update","product_id":"BTC-USD","updates":[{"side":"bid","event_time":"2026-07-16T20:29:06.236635Z","price_level":"64130.07","new_quantity":"0.01559176"},{"side":"bid","event_time":"2026-07-16T20:29:06.236635Z","price_level":"64127.22","new_quantity":"0.02"},{"side":"bid","event_time":"2026-07-16T20:29:06.236635Z","price_level":"64116.43","new_quantity":"0"},{"side":"bid","event_time":"2026-07-16T20:29:06.236635Z","price_level":"64113.02","new_quantity":"0.6575851"},{"side":"bid","event_time":"2026-07-16T20:29:06.236635Z","price_level":"64112.79","new_quantity":"0.06"},{"side":"bid","event_time":"2026-07-16T20:29:06.236635Z","price_level":"64112.69","new_quantity":"0.08"},{"side":"bid","event_time":"2026-07-16T20:29:06.236635Z","price_level":"64110.69","new_quantity":"0.00105237"},{"side":"bid","event_time":"2026-07-16T20:29:06.236635Z","price_level":"64109.44","new_quantity":"0.00077949"},{"side":"bid","event_time":"2026-07-16T20:29:06.236635Z","price_level":"64103.56","new_quantity":"0.02882938"},{"side":"bid","event_time":"2026-07-16T20:29:06.236635Z","price_level":"64100.99","new_quantity":"0.03410536"},{"side":"bid","event_time":"2026-07-16T20:29:06.236635Z","price_level":"64100.75","new_quantity":"0"},{"side":"bid","event_time":"2026-07-16T20:29:06.236635Z","price_level":"64097.14","new_quantity":"0.02587613"},{"side":"bid","event_time":"2026-07-16T20:29:06.236635Z","price_level":"64096.89","new_quantity":"0.98264611"},{"side":"bid","event_time":"2026-07-16T20:29:06.236635Z","price_level":"64078.09","new_quantity":"0.00858295"},{"side":"offer","event_time":"2026-07-16T20:29:06.236635Z","price_level":"64140.66","new_quantity":"1.29520746"},{"side":"offer","event_time":"2026-07-16T20:29:06.236635Z","price_level":"64149.53","new_quantity":"0"},{"side":"offer","event_time":"2026-07-16T20:29:06.236635Z","price_level":"64160.11","new_quantity":"0.14"},{"side":"offer","event_time":"2026-07-16T20:29:06.236635Z","price_level":"64178.99","new_quantity":"0.48576671"},{"side":"offer","event_time":"2026-07-16T20:29:06.236635Z","price_level":"64181.03","new_quantity":"0.2179666"},{"side":"offer","event_time":"2026-07-16T20:29:06.236635Z","price_level":"64181.04","new_quantity":"0"},{"side":"offer","event_time":"2026-07-16T20:29:06.236635Z","price_level":"64181.05","new_quantity":"0.00077953"},{"side":"offer","event_time":"2026-07-16T20:29:06.236635Z","price_level":"64184.99","new_quantity":"0"},{"side":"offer","event_time":"2026-07-16T20:29:06.236635Z","price_level":"64187.89","new_quantity":"0.00077949"},{"side":"offer","event_time":"2026-07-16T20:29:06.236635Z","price_level":"64190.98","new_quantity":"0"},{"side":"offer","event_time":"2026-07-16T20:29:06.236635Z","price_level":"64199.58","new_quantity":"0.00077949"},{"side":"offer","event_time":"2026-07-16T20:29:06.236635Z","price_level":"64203.6","new_quantity":"0"}]}]}
{"channel":"l2_data","timestamp":"2026-07-16T20:29:06.331497031Z","sequence_num":284,"events":[{"type":"update","product_id":"BTC-USD","updates":[{"side":"bid","event_time":"2026-07-16T20:29:06.285977Z","price_level":"64140.65","new_quantity":"0.00028734"},{"side":"bid","event_time":"2026-07-16T20:29:06.285977Z","price_level":"64127.22","new_quantity":"0.06"},{"side":"bid","event_time":"2026-07-16T20:29:06.285977Z","price_level":"64126.96","new_quantity":"0.07399"},{"side":"bid","event_time":"2026-07-16T20:29:06.285977Z","price_level":"64117.68","new_quantity":"0.00623417"},{"side":"bid","event_time":"2026-07-16T20:29:06.285977Z","price_level":"64115.17","new_quantity":"0"},{"side":"bid","event_time":"2026-07-16T20:29:06.285977Z","price_level":"64108","new_quantity":"1"},{"side":"bid","event_time":"2026-07-16T20:29:06.285977Z","price_level":"64106.05","new_quantity":"0"},{"side":"bid","event_time":"2026-07-16T20:29:06.285977Z","price_level":"64104.07","new_quantity":"0.017454"},{"side":"offer","event_time":"2026-07-16T20:29:06.285977Z","price_level":"64140.66","new_quantity":"1.31457311"},{"side":"offer","event_time":"2026-07-16T20:29:06.285977Z","price_level":"64164.72","new_quantity":"0.00623417"}]}]}
{"channel":"l2_data","timestamp":"2026-07-16T20:29:06.381077347Z","sequence_num":285,"events":[{"type":"update","product_id":"BTC-USD","updates":[{"side":"bid","event_time":"2026-07-16T20:29:06.331582Z","price_level":"64134.24","new_quantity":"0.00779615"},{"side":"bid","event_time":"2026-07-16T20:29:06.331582Z","price_level":"64126.96","new_quantity":"0"},{"side":"bid","event_time":"2026-07-16T20:29:06.331582Z","price_level":"64113.02","new_quantity":"0.0026658"},{"side":"bid","event_time":"2026-07-16T20:29:06.331582Z","price_level":"64108","new_quantity":"0"},{"side":"offer","event_time":"2026-07-16T20:29:06.331582Z","price_level":"64140.66","new_quantity":"1.25768883"},{"side":"offer","event_time":"2026-07-16T20:29:06.331582Z","price_level":"64152.19","new_quantity":"0.00896306"}]}]}
{"channel":"l2_data","timestamp":"2026-07-16T20:29:06.432134757Z","sequence_num":286,"events":[{"type":"update","product_id":"BTC-USD","updates":[{"side":"bid","event_time":"2026-07-16T20:29:06.397685Z","price_level":"64139.19","new_quantity":"0.00779555"},{"side":"bid","event_time":"2026-07-16T20:29:06.397685Z","price_level":"64135.84","new_quantity":"0.00779595"},{"side":"bid","event_time":"2026-07-16T20:29:06.397685Z","price_level":"64126.95","new_quantity":"0.0000501"},{"side":"bid","event_time":"2026-07-16T20:29:06.397685Z","price_level":"64113","new_quantity":"1.0000309"},{"side":"bid","event_time":"2026-07-16T20:29:06.397685Z","price_level":"64097.15","new_quantity":"0.98264213"},{"side":"bid","event_time":"2026-07-16T20:29:06.397685Z","price_level":"64096.91","new_quantity":"0.00077948"},{"side":"bid","event_time":"2026-07-16T20:29:06.397685Z","price_level":"64096.89","new_quantity":"0"},{"side":"bid","event_time":"2026-07-16T20:29:06.397685Z","price_level":"56123.07","new_quantity":"0.01337205"},{"side":"offer","event_time":"2026-07-16T20:29:06.397685Z","price_level":"64141.95","new_quantity":"0.00779521"},{"side":"offer","event_time":"2026-07-16T20:29:06.397685Z","price_level":"64143.66","new_quantity":"0.0012474"},{"side":"offer","event_time":"2026-07-16T20:29:06.397685Z","price_level":"64150.58","new_quantity":"0.00896329"},{"side":"offer","event_time":"2026-07-16T20:29:06.397685Z","price_level":"64178.99","new_quantity":"0"},{"side":"offer","event_time":"2026-07-16T20:29:06.397685Z","price_level":"64181.01","new_quantity":"0.50778154"},{"side":"offer","event_time":"2026-07-16T20:29:06.397685Z","price_level":"64181.02","new_quantity":"0.48575134"},{"side":"offer","event_time":"2026-07-16T20:29:06.397685Z","price_level":"64181.03","new_quantity":"0.00159799"}]}]}
{"channel":"l2_data","timestamp":"2026-07-16T20:29:06.752137364Z","sequence_num":287,"events":[{"type":"update","product_id":"BTC-USD","updates":[{"side":"bid","event_time":"2026-07-16T20:29:06.450091Z","price_level":"64117.68","new_quantity":"0"},{"side":"offer","event_time":"2026-07-16T20:29:06.450091Z","price_level":"64150.9","new_quantity":"0.00009743"},{"side":"offer","event_time":"2026-07-16T20:29:06.450091Z","price_level":"64152.18","new_quantity":"0.00779397"}]}]}
{"channel":"l2_data","timestamp":"2026-07-16T20:29:07.055464857Z","sequence_num":288,"events":[{"type":"update","product_id":"BTC-USD","updates":[{"side":"bid","event_time":"2026-07-16T20:29:06.49804Z","price_level":"64140.65","new_quantity":"0"},{"side":"bid","event_time":"2026-07-16T20:29:06.49804Z","price_level":"64139.19","new_quantity":"0"},{"side":"bid","event_time":"2026-07-16T20:29:06.49804Z","price_level":"64130.32","new_quantity":"0.12474598"},{"side":"bid","event_time":"2026-07-16T20:29:06.49804Z","price_level":"64130.07","new_quantity":"0"},{"side":"bid","event_time":"2026-07-16T20:29:06.49804Z","price_level":"64113.02","new_quantity":"0.65758774"},{"side":"bid","event_time":"2026-07-16T20:29:06.49804Z","price_level":"64076.74","new_quantity":"0.001545"},{"side":"bid","event_time":"2026-07-16T20:29:06.49804Z","price_level":"64073.51","new_quantity":"0.001545"},{"side":"bid","event_time":"2026-07-16T20:29:06.49804Z","price_level":"56123.07","new_quantity":"0"},{"side":"offer","event_time":"2026-07-16T20:29:06.49804Z","price_level":"64139.2","new_quantity":"1.47225925"},{"side":"offer","event_time":"2026-07-16T20:29:06.49804Z","price_level":"64139.67","new_quantity":"0.00234569"},{"side":"offer","event_time":"2026-07-16T20:29:06.49804Z","price_level":"64140.65","new_quantity":"0.28546816"},{"side":"offer","event_time":"2026-07-16T20:29:06.49804Z","price_level":"64140.66","new_quantity":"0.16575633"},{"side":"offer","event_time":"2026-07-16T20:29:06.49804Z","price_level":"64141.34","new_quantity":"0.0773"},{"side":"offer","event_time":"2026-07-16T20:29:06.49804Z","price_level":"64141.95","new_quantity":"0"},{"side":"offer","event_time":"2026-07-16T20:29:06.49804Z","price_level":"64142.58","new_quantity":"0.504615"},{"side":"offer","event_time":"2026-07-16T20:29:06.49804Z","price_level":"64144.58","new_quantity":"0"},{"side":"offer","event_time":"2026-07-16T20:29:06.49804Z","price_level":"64153.07","new_quantity":"0.00583"},{"side":"offer","event_time":"2026-07-16T20:29:06.49804Z","price_level":"64153.22","new_quantity":"0"},{"side":"offer","event_time":"2026-07-16T20:29:06.49804Z","price_level":"64157.36","new_quantity":"0"},{"side":"offer","event_time":"2026-07-16T20:29:06.49804Z","price_level":"64161.48","new_quantity":"0.39406024"},{"side":"offer","event_time":"2026-07-16T20:29:06.49804Z","price_level":"64163.5","new_quantity":"0"},{"side":"offer","event_time":"2026-07-16T20:29:06.49804Z","price_level":"64180.99","new_quantity":"0.50778163"},{"side":"offer","event_time":"2026-07-16T20:29:06.49804Z","price_level":"64181","new_quantity":"0.48575149"},{"side":"offer","event_time":"2026-07-16T20:29:06.49804Z","price_level":"64181.01","new_quantity":"0"},{"side":"offer","event_time":"2026-07-16T20:29:06.49804Z","price_level":"64181.02","new_quantity":"0"},{"side":"offer","event_time":"2026-07-16T20:29:06.49804Z","price_level":"64200","new_quantity":"0"},{"side":"offer","event_time":"2026-07-16T20:29:06.49804Z","price_level":"64210.3","new_quantity":"0"}]}]}
{"channel":"heartbeats","timestamp":"2026-07-16T20:29:07.170427662Z","sequence_num":289,"events":[{"current_time":"2026-07-16 20:29:07.163195258 +0000 UTC m=+75511.318022303","heartbeat_counter":75511}]}
{"channel":"l2_data","timestamp":"2026-07-16T20:29:07.378914442Z","sequence_num":290,"events":[{"type":"update","product_id":"BTC-USD","updates":[{"side":"bid","event_time":"2026-07-16T20:29:06.635091Z","price_level":"64138.77","new_quantity":"0.00001795"},{"side":"bid","event_time":"2026-07-16T20:29:06.635091Z","price_level":"64137.6","new_quantity":"0"},{"side":"bid","event_time":"2026-07-16T20:29:06.635091Z","price_level":"64131.43","new_quantity":"0.04691558"},{"side":"bid","event_time":"2026-07-16T20:29:06.635091Z","price_level":"64130.33","new_quantity":"0.31190852"},{"side":"bid","event_time":"2026-07-16T20:29:06.635091Z","price_level":"64129.96","new_quantity":"0.0450192"},{"side":"bid","event_time":"2026-07-16T20:29:06.635091Z","price_level":"64129.17","new_quantity":"0"},{"side":"bid","event_time":"2026-07-16T20:29:06.635091Z","price_level":"64129.04","new_quantity":"0"},{"side":"bid","event_time":"2026-07-16T20:29:06.635091Z","price_level":"64128.51","new_quantity":"0"},{"side":"bid","event_time":"2026-07-16T20:29:06.635091Z","price_level":"64128.17","new_quantity":"0.01559176"},{"side":"bid","event_time":"2026-07-16T20:29:06.635091Z","price_level":"64128.08","new_quantity":"0"},{"side":"bid","event_time":"2026-07-16T20:29:06.635091Z","price_level":"64127.86","new_quantity":"0"},{"side":"bid","event_time":"2026-07-16T20:29:06.635091Z","price_level":"64127.25","new_quantity":"0.31190852"},{"side":"bid","event_time":"2026-07-16T20:29:06.635091Z","price_level":"64127.22","new_quantity":"0"},{"side":"bid","event_time":"2026-07-16T20:29:06.635091Z","price_level":"64126.75","new_quantity":"0.00033322"},{"side":"bid","event_time":"2026-07-16T20:29:06.635091Z","price_level":"64125.3","new_quantity":"0.31969772"},{"side":"bid","event_time":"2026-07-16T20:29:06.635091Z","price_level":"64125.29","new_quantity":"0"},{"side":"bid","event_time":"2026-07-16T20:29:06.635091Z","price_level":"64125.28","new_quantity":"0"},{"side":"bid","event_time":"2026-07-16T20:29:06.635091Z","price_level":"64124.87","new_quantity":"0.64062"},{"side":"bid","event_time":"2026-07-16T20:29:06.635091Z","price_level":"64123.19","new_quantity":"0"},{"side":"bid","event_time":"2026-07-16T20:29:06.635091Z","price_level":"64117.48","new_quantity":"0.00779555"},{"side":"bid","event_time":"2026-07-16T20:29:06.635091Z","price_level":"64115.4","new_quantity":"0"},{"side":"bid","event_time":"2026-07-16T20:29:06.635091Z","price_level":"64113.02","new_quantity":"0.0026658"},{"side":"bid","event_time":"2026-07-16T20:29:06.635091Z","price_level":"64113","new_quantity":"1.0000309"},{"side":"bid","event_time":"2026-07-16T20:29:06.635091Z","price_level":"64112.79","new_quantity":"0"},{"side":"bid","event_time":"2026-07-16T20:29:06.635091Z","price_level":"64112.69","new_quantity":"0"},{"side":"bid","event_time":"2026-07-16T20:29:06.635091Z","price_level":"64109.97","new_quantity":"0.23359045"},{"side":"bid","event_time":"2026-07-16T20:29:06.635091Z","price_level":"64109.96","new_quantity":"0.63218159"},{"side":"bid","event_time":"2026-07-16T20:29:06.635091Z","price_level":"64109.95","new_quantity":"0.6549466"},{"side":"bid","event_time":"2026-07-16T20:29:06.635091Z","price_level":"64109.94","new_quantity":"0"},{"side":"bid","event_time":"2026-07-16T20:29:06.635091Z","price_level":"64107.3","new_quantity":"0"},{"side":"bid","event_time":"2026-07-16T20:29:06.635091Z","price_level":"64105.45","new_quantity":"0.06612848"},{"side":"bid","event_time":"2026-07-16T20:29:06.635091Z","price_level":"64103.56","new_quantity":"0"},{"side":"bid","event_time":"2026-07-16T20:29:06.635091Z","price_level":"64100.99","new_quantity":"0"},{"side":"bid","event_time":"2026-07-16T20:29:06.635091Z","price_level":"64097.14","new_quantity":"0"},{"side":"bid","event_time":"2026-07-16T20:29:06.635091Z","price_level":"64096.16","new_quantity":"0"},{"side":"bid","event_time":"2026-07-16T20:29:06.635091Z","price_level":"64095.73","new_quantity":"0.5"},{"side":"bid","event_time":"2026-07-16T20:29:06.635091Z","price_level":"64082.17","new_quantity":"0"},{"side":"bid","event_time":"2026-07-16T20:29:06.635091Z","price_level":"64076.56","new_quantity":"0.2962435"},{"side":"bid","event_time":"2026-07-16T20:29:06.635091Z","price_level":"64072.32","new_quantity":"0"},{"side":"bid","event_time":"2026-07-16T20:29:06.635091Z","price_level":"64065.15","new_quantity":"6.169987"},{"side":"bid","event_time":"2026-07-16T20:29:06.635091Z","price_level":"64055.93","new_quantity":"0.001871"},{"side":"bid","event_time":"2026-07-16T20:29:06.635091Z","price_level":"64043.5","new_quantity":"0"},{"side":"offer","event_time":"2026-07-16T20:29:06.635091Z","price_level":"64138.78","new_quantity":"0.34349424"},{"side":"offer","event_time":"2026-07-16T20:29:06.635091Z","price_level":"64139.17","new_quantity":"0.04691558"},{"side":"offer","event_time":"2026-07-16T20:29:06.635091Z","price_level":"64139.18","new_quantity":"0.12472875"},{"side":"offer","event_time":"2026-07-16T20:29:06.635091Z","price_level":"64139.19","new_quantity":"0"},{"side":"offer","event_time":"2026-07-16T20:29:06.635091Z","price_level":"64139.2","new_quantity":"0.23397835"},{"side":"offer","event_time":"2026-07-16T20:29:06.635091Z","price_level":"64139.67","new_quantity":"0"},{"side":"offer","event_time":"2026-07-16T20:29:06.635091Z","price_level":"64139.74","new_quantity":"0.00234569"},{"side":"offer","event_time":"2026-07-16T20:29:06.635091Z","price_level":"64140.39","new_quantity":"0.00545691"},{"side":"offer","event_time":"2026-07-16T20:29:06.635091Z","price_level":"64140.65","new_quantity":"0"},{"side":"offer","event_time":"2026-07-16T20:29:06.635091Z","price_level":"64142.27","new_quantity":"0"},{"side":"offer","event_time":"2026-07-16T20:29:06.635091Z","price_level":"64142.4","new_quantity":"0"},{"side":"offer","event_time":"2026-07-16T20:29:06.635091Z","price_level":"64142.55","new_quantity":"0.00682114"},{"side":"offer","event_time":"2026-07-16T20:29:06.635091Z","price_level":"64144.57","new_quantity":"0.02"},{"side":"offer","event_time":"2026-07-16T20:29:06.635091Z","price_level":"64145.12","new_quantity":"0"},{"side":"offer","event_time":"2026-07-16T20:29:06.635091Z","price_level":"64152.29","new_quantity":"0.96983072"},{"side":"offer","event_time":"2026-07-16T20:29:06.635091Z","price_level":"64155","new_quantity":"1.01"},{"side":"offer","event_time":"2026-07-16T20:29:06.635091Z","price_level":"64155.46","new_quantity":"0.33"},{"side":"offer","event_time":"2026-07-16T20:29:06.635091Z","price_level":"64158.76","new_quantity":"0"},{"side":"offer","event_time":"2026-07-16T20:29:06.635091Z","price_level":"64160.11","new_quantity":"0"},{"side":"offer","event_time":"2026-07-16T20:29:06.635091Z","price_level":"64165.48","new_quantity":"0"},{"side":"offer","event_time":"2026-07-16T20:29:06.635091Z","price_level":"64165.92","new_quantity":"0"},{"side":"offer","event_time":"2026-07-16T20:29:06.635091Z","price_level":"64168.44","new_quantity":"0.00306626"},{"side":"offer","event_time":"2026-07-16T20:29:06.635091Z","price_level":"64177.22","new_quantity":"0"},{"side":"offer","event_time":"2026-07-16T20:29:06.635091Z","price_level":"64179.29","new_quantity":"0"},{"side":"offer","event_time":"2026-07-16T20:29:06.635091Z","price_level":"64180.97","new_quantity":"0.50748322"},{"side":"offer","event_time":"2026-07-16T20:29:06.635091Z","price_level":"64180.98","new_quantity":"0.48575164"},{"side":"offer","event_time":"2026-07-16T20:29:06.635091Z","price_level":"64180.99","new_quantity":"0"},{"side":"offer","event_time":"2026-07-16T20:29:06.635091Z","price_level":"64181","new_quantity":"0"},{"side":"offer","event_time":"2026-07-16T20:29:06.635091Z","price_level":"64183.69","new_quantity":"0"},{"side":"offer","event_time":"2026-07-16T20:29:06.635091Z","price_level":"64185.11","new_quantity":"0.43999483"},{"side":"offer","event_time":"2026-07-16T20:29:06.635091Z","price_level":"64185.17","new_quantity":"0"},{"side":"offer","event_time":"2026-07-16T20:29:06.635091Z","price_level":"64185.58","new_quantity":"0.2962435"},{"side":"offer","event_time":"2026-07-16T20:29:06.635091Z","price_level":"64191","new_quantity":"0"},{"side":"offer","event_time":"2026-07-16T20:29:06.635091Z","price_level":"64191.2","new_quantity":"0"},{"side":"offer","event_time":"2026-07-16T20:29:06.635091Z","price_level":"64294.01","new_quantity":"0.001746"},{"side":"offer","event_time":"2026-07-16T20:29:06.635091Z","price_level":"64307.02","new_quantity":"0"},{"side":"offer","event_time":"2026-07-16T20:29:06.635091Z","price_level":"64400.8","new_quantity":"0.3"},{"side":"offer","event_time":"2026-07-16T20:29:06.635091Z","price_level":"64780","new_quantity":"1.8"}]}]}
{"channel":"l2_data","timestamp":"2026-07-16T20:29:07.380981257Z","sequence_num":291,"events":[{"type":"update","product_id":"BTC-USD","updates":[{"side":"bid","event_time":"2026-07-16T20:29:06.699558Z","price_level":"64138.77","new_quantity":"0.00001784"},{"side":"bid","event_time":"2026-07-16T20:29:06.699558Z","price_level":"64134.72","new_quantity":"0.00779609"},{"side":"bid","event_time":"2026-07-16T20:29:06.699558Z","price_level":"64132.29","new_quantity":"0"},{"side":"bid","event_time":"2026-07-16T20:29:06.699558Z","price_level":"64131.65","new_quantity":"0.12628839"},{"side":"bid","event_time":"2026-07-16T20:29:06.699558Z","price_level":"64125.52","new_quantity":"0.06"},{"side":"bid","event_time":"2026-07-16T20:29:06.699558Z","price_level":"64124.87","new_quantity":"0"},{"side":"bid","event_time":"2026-07-16T20:29:06.699558Z","price_level":"64113","new_quantity":"0.0000309"},{"side":"bid","event_time":"2026-07-16T20:29:06.699558Z","price_level":"64109.44","new_quantity":"0"},{"side":"bid","event_time":"2026-07-16T20:29:06.699558Z","price_level":"64108.89","new_quantity":"0.14"},{"side":"bid","event_time":"2026-07-16T20:29:06.699558Z","price_level":"64106","new_quantity":"1"},{"side":"bid","event_time":"2026-07-16T20:29:06.699558Z","price_level":"64105.45","new_quantity":"0"},{"side":"bid","event_time":"2026-07-16T20:29:06.699558Z","price_level":"64105","new_quantity":"1.01"},{"side":"bid","event_time":"2026-07-16T20:29:06.699558Z","price_level":"64096.91","new_quantity":"0"},{"side":"bid","event_time":"2026-07-16T20:29:06.699558Z","price_level":"64094.92","new_quantity":"0.0007795"},{"side":"bid","event_time":"2026-07-16T20:29:06.699558Z","price_level":"64070.4","new_quantity":"0"},{"side":"bid","event_time":"2026-07-16T20:29:06.699558Z","price_level":"64036.36","new_quantity":"0"},{"side":"bid","event_time":"2026-07-16T20:29:06.699558Z","price_level":"63987.24","new_quantity":"0"},{"side":"bid","event_time":"2026-07-16T20:29:06.699558Z","price_level":"56121.43","new_quantity":"0.01337205"},{"side":"bid","event_time":"2026-07-16T20:29:06.699558Z","price_level":"51315.66","new_quantity":"0.0002"},{"side":"offer","event_time":"2026-07-16T20:29:06.699558Z","price_level":"64139.16","new_quantity":"0.31190852"},{"side":"offer","event_time":"2026-07-16T20:29:06.699558Z","price_level":"64139.74","new_quantity":"0"},{"side":"offer","event_time":"2026-07-16T20:29:06.699558Z","price_level":"64139.81","new_quantity":"0.0023457"},{"side":"offer","event_time":"2026-07-16T20:29:06.699558Z","price_level":"64140.07","new_quantity":"0.00779544"},{"side":"offer","event_time":"2026-07-16T20:29:06.699558Z","price_level":"64147.65","new_quantity":"0.00038328"},{"side":"offer","event_time":"2026-07-16T20:29:06.699558Z","price_level":"64156.22","new_quantity":"0.14"},{"side":"offer","event_time":"2026-07-16T20:29:06.699558Z","price_level":"64158.42","new_quantity":"0"},{"side":"offer","event_time":"2026-07-16T20:29:06.699558Z","price_level":"64179.99","new_quantity":"0.00077955"},{"side":"offer","event_time":"2026-07-16T20:29:06.699558Z","price_level":"64180.95","new_quantity":"0.50701794"},{"side":"offer","event_time":"2026-07-16T20:29:06.699558Z","price_level":"64180.96","new_quantity":"0.4857518"},{"side":"offer","event_time":"2026-07-16T20:29:06.699558Z","price_level":"64180.97","new_quantity":"0"},{"side":"offer","event_time":"2026-07-16T20:29:06.699558Z","price_level":"64180.98","new_quantity":"0"},{"side":"offer","event_time":"2026-07-16T20:29:06.699558Z","price_level":"64181.05","new_quantity":"0"},{"side":"offer","event_time":"2026-07-16T20:29:06.699558Z","price_level":"64185.1","new_quantity":"0.0007795"},{"side":"offer","event_time":"2026-07-16T20:29:06.699558Z","price_level":"64187.89","new_quantity":"0"},{"side":"offer","event_time":"2026-07-16T20:29:06.699558Z","price_level":"64228.77","new_quantity":"0"},{"side":"offer","event_time":"2026-07-16T20:29:06.699558Z","price_level":"64232.23","new_quantity":"0"},{"side":"offer","event_time":"2026-07-16T20:29:06.699558Z","price_level":"64784.09","new_quantity":"0"}]}]}
{"channel":"l2_data","timestamp":"2026-07-16T20:29:07.384022301Z","sequence_num":292,"events":[{"type":"update","product_id":"BTC-USD","updates":[{"side":"bid","event_time":"2026-07-16T20:29:06.745784Z","price_level":"64128.17","new_quantity":"0"},{"side":"bid","event_time":"2026-07-16T20:29:06.745784Z","price_level":"64128.15","new_quantity":"0.01559176"},{"side":"bid","event_time":"2026-07-16T20:29:06.745784Z","price_level":"64117.48","new_quantity":"0"},{"side":"bid","event_time":"2026-07-16T20:29:06.745784Z","price_level":"64109.98","new_quantity":"0.63218139"},{"side":"bid","event_time":"2026-07-16T20:29:06.745784Z","price_level":"64109.96","new_quantity":"0"}]}]}
{"channel":"l2_data","timestamp":"2026-07-16T20:29:07.385264459Z","sequence_num":293,"events":[{"type":"update","product_id":"BTC-USD","updates":[{"side":"bid","event_time":"2026-07-16T20:29:06.805278Z","price_level":"64131.65","new_quantity":"0.001545"},{"side":"bid","event_time":"2026-07-16T20:29:06.805278Z","price_level":"64131.04","new_quantity":"0.02"},{"side":"bid","event_time":"2026-07-16T20:29:06.805278Z","price_level":"64131.03","new_quantity":"0.12474459"},{"side":"bid","event_time":"2026-07-16T20:29:06.805278Z","price_level":"64130.44","new_quantity":"0"},{"side":"bid","event_time":"2026-07-16T20:29:06.805278Z","price_level":"64128.59","new_quantity":"0.01559176"},{"side":"bid","event_time":"2026-07-16T20:29:06.805278Z","price_level":"64128.15","new_quantity":"0"},{"side":"bid","event_time":"2026-07-16T20:29:06.805278Z","price_level":"64127.3","new_quantity":"0"},{"side":"bid","event_time":"2026-07-16T20:29:06.805278Z","price_level":"64107.36","new_quantity":"0.0007795"},{"side":"bid","event_time":"2026-07-16T20:29:06.805278Z","price_level":"64105.13","new_quantity":"0.06923874"},{"side":"bid","event_time":"2026-07-16T20:29:06.805278Z","price_level":"64098","new_quantity":"0"},{"side":"bid","event_time":"2026-07-16T20:29:06.805278Z","price_level":"56121.43","new_quantity":"0"},{"side":"offer","event_time":"2026-07-16T20:29:06.805278Z","price_level":"64141.34","new_quantity":"0"},{"side":"offer","event_time":"2026-07-16T20:29:06.805278Z","price_level":"64144.57","new_quantity":"0"},{"side":"offer","event_time":"2026-07-16T20:29:06.805278Z","price_level":"64180.93","new_quantity":"0.50701803"},{"side":"offer","event_time":"2026-07-16T20:29:06.805278Z","price_level":"64180.94","new_quantity":"0.48575195"},{"side":"offer","event_time":"2026-07-16T20:29:06.805278Z","price_level":"64180.95","new_quantity":"0"},{"side":"offer","event_time":"2026-07-16T20:29:06.805278Z","price_level":"64180.96","new_quantity":"0"}]}]}
{"channel":"l2_data","timestamp":"2026-07-16T20:29:07.386183818Z","sequence_num":294,"events":[{"type":"update","product_id":"BTC-USD","updates":[{"side":"bid","event_time":"2026-07-16T20:29:06.858299Z","price_level":"64138.77","new_quantity":"0.00001768"},{"side":"bid","event_time":"2026-07-16T20:29:06.858299Z","price_level":"64128.59","new_quantity":"0"},{"side":"bid","event_time":"2026-07-16T20:29:06.858299Z","price_level":"64128.58","new_quantity":"0.01559176"},{"side":"bid","event_time":"2026-07-16T20:29:06.858299Z","price_level":"64114.96","new_quantity":"0.01"},{"side":"bid","event_time":"2026-07-16T20:29:06.858299Z","price_level":"64111","new_quantity":"1"},{"side":"offer","event_time":"2026-07-16T20:29:06.858299Z","price_level":"64152.79","new_quantity":"0.06713135"},{"side":"offer","event_time":"2026-07-16T20:29:06.858299Z","price_level":"64177.27","new_quantity":"0.0005"},{"side":"offer","event_time":"2026-07-16T20:29:06.858299Z","price_level":"64779.97","new_quantity":"0.03890047"}]}]}
{"channel":"l2_data","timestamp":"2026-07-16T20:29:07.387872469Z","sequence_num":295,"events":[{"type":"update","product_id":"BTC-USD","updates":[{"side":"bid","event_time":"2026-07-16T20:29:06.901472Z","price_level":"64134.72","new_quantity":"0"},{"side":"bid","event_time":"2026-07-16T20:29:06.901472Z","price_level":"64131.62","new_quantity":"0"},{"side":"bid","event_time":"2026-07-16T20:29:06.901472Z","price_level":"64131.03","new_quantity":"0"},{"side":"bid","event_time":"2026-07-16T20:29:06.901472Z","price_level":"64128.28","new_quantity":"0.07399"},{"side":"bid","event_time":"2026-07-16T20:29:06.901472Z","price_level":"64111.01","new_quantity":"0.63217123"},{"side":"bid","event_time":"2026-07-16T20:29:06.901472Z","price_level":"64111","new_quantity":"0"},{"side":"bid","event_time":"2026-07-16T20:29:06.901472Z","price_level":"64109.98","new_quantity":"0"},{"side":"bid","event_time":"2026-07-16T20:29:06.901472Z","price_level":"64108.8","new_quantity":"0.2836043"},{"side":"bid","event_time":"2026-07-16T20:29:06.901472Z","price_level":"64089.57","new_quantity":"0.55147581"},{"side":"offer","event_time":"2026-07-16T20:29:06.901472Z","price_level":"64138.78","new_quantity":"0.31312588"},{"side":"offer","event_time":"2026-07-16T20:29:06.901472Z","price_level":"64139.16","new_quantity":"0"},{"side":"offer","event_time":"2026-07-16T20:29:06.901472Z","price_level":"64139.17","new_quantity":"0"},{"side":"offer","event_time":"2026-07-16T20:29:06.901472Z","price_level":"64139.66","new_quantity":"0.0023457"},{"side":"offer","event_time":"2026-07-16T20:29:06.901472Z","price_level":"64139.81","new_quantity":"0"},{"side":"offer","event_time":"2026-07-16T20:29:06.901472Z","price_level":"64142.58","new_quantity":"0.21599676"},{"side":"offer","event_time":"2026-07-16T20:29:06.901472Z","price_level":"64142.59","new_quantity":"0"},{"side":"offer","event_time":"2026-07-16T20:29:06.901472Z","price_level":"64145.76","new_quantity":"0"},{"side":"offer","event_time":"2026-07-16T20:29:06.901472Z","price_level":"64152.79","new_quantity":"0"},{"side":"offer","event_time":"2026-07-16T20:29:06.901472Z","price_level":"64159.53","new_quantity":"0.27666204"},{"side":"offer","event_time":"2026-07-16T20:29:06.901472Z","price_level":"64178.77","new_quantity":"0.54597964"},{"side":"offer","event_time":"2026-07-16T20:29:06.901472Z","price_level":"64180.91","new_quantity":"0.50701812"},{"side":"offer","event_time":"2026-07-16T20:29:06.901472Z","price_level":"64180.92","new_quantity":"0.4857521"},{"side":"offer","event_time":"2026-07-16T20:29:06.901472Z","price_level":"64180.93","new_quantity":"0"},{"side":"offer","event_time":"2026-07-16T20:29:06.901472Z","price_level":"64180.94","new_quantity":"0"}]}]}
{"channel":"l2_data","timestamp":"2026-07-16T20:29:07.389628808Z","sequence_num":296,"events":[{"type":"update","product_id":"BTC-USD","updates":[{"side":"bid","event_time":"2026-07-16T20:29:06.915506Z","price_level":"64128.59","new_quantity":"0.01559176"},{"side":"bid","event_time":"2026-07-16T20:29:06.915506Z","price_level":"64128.58","new_quantity":"0"},{"side":"bid","event_time":"2026-07-16T20:29:06.915506Z","price_level":"59501","new_quantity":"0.0254157"},{"side":"offer","event_time":"2026-07-16T20:29:06.915506Z","price_level":"64145.05","new_quantity":"0.04691558"}]}]}
{"channel":"l2_data","timestamp":"2026-07-16T20:29:07.390143004Z","sequence_num":297,"events":[{"type":"update","product_id":"BTC-USD","updates":[{"side":"bid","event_time":"2026-07-16T20:29:06.983995Z","price_level":"64134.72","new_quantity":"0.00779609"},{"side":"bid","event_time":"2026-07-16T20:29:06.983995Z","price_level":"64133.04","new_quantity":"0.12474068"},{"side":"bid","event_time":"2026-07-16T20:29:06.983995Z","price_level":"64131.43","new_quantity":"0"},{"side":"bid","event_time":"2026-07-16T20:29:06.983995Z","price_level":"64130.35","new_quantity":"0.31190852"},{"side":"bid","event_time":"2026-07-16T20:29:06.983995Z","price_level":"64130.34","new_quantity":"0.04691558"},{"side":"bid","event_time":"2026-07-16T20:29:06.983995Z","price_level":"64130.33","new_quantity":"0"},{"side":"bid","event_time":"2026-07-16T20:29:06.983995Z","price_level":"64129.16","new_quantity":"0.01559176"},{"side":"bid","event_time":"2026-07-16T20:29:06.983995Z","price_level":"64128.59","new_quantity":"0"},{"side":"bid","event_time":"2026-07-16T20:29:06.983995Z","price_level":"64128.28","new_quantity":"0"},{"side":"bid","event_time":"2026-07-16T20:29:06.983995Z","price_level":"64123.77","new_quantity":"0.18620939"},{"side":"bid","event_time":"2026-07-16T20:29:06.983995Z","price_level":"64123.76","new_quantity":"0"},{"side":"bid","event_time":"2026-07-16T20:29:06.983995Z","price_level":"64114","new_quantity":"0"},{"side":"bid","event_time":"2026-07-16T20:29:06.983995Z","price_level":"64029.84","new_quantity":"0.08913867"},{"side":"bid","event_time":"2026-07-16T20:29:06.983995Z","price_level":"51315.66","new_quantity":"0"},{"side":"offer","event_time":"2026-07-16T20:29:06.983995Z","price_level":"64138.78","new_quantity":"0.25595253"},{"side":"offer","event_time":"2026-07-16T20:29:06.983995Z","price_level":"64141","new_quantity":"0.31190852"},{"side":"offer","event_time":"2026-07-16T20:29:06.983995Z","price_level":"64142.58","new_quantity":"0.40259999"},{"side":"offer","event_time":"2026-07-16T20:29:06.983995Z","price_level":"64142.99","new_quantity":"0.31190852"},{"side":"offer","event_time":"2026-07-16T20:29:06.983995Z","price_level":"64149.64","new_quantity":"0"},{"side":"offer","event_time":"2026-07-16T20:29:06.983995Z","price_level":"64150.6","new_quantity":"0"},{"side":"offer","event_time":"2026-07-16T20:29:06.983995Z","price_level":"64222.22","new_quantity":"0.04833263"}]}]}
{"channel":"l2_data","timestamp":"2026-07-16T20:29:07.394104953Z","sequence_num":298,"events":[{"type":"update","product_id":"BTC-USD","updates":[{"side":"bid","event_time":"2026-07-16T20:29:07.045639Z","price_level":"64135.84","new_quantity":"0"},{"side":"bid","event_time":"2026-07-16T20:29:07.045639Z","price_level":"64134.88","new_quantity":"0"},{"side":"bid","event_time":"2026-07-16T20:29:07.045639Z","price_level":"64134.72","new_quantity":"0"},{"side":"bid","event_time":"2026-07-16T20:29:07.045639Z","price_level":"64134.24","new_quantity":"0"},{"side":"bid","event_time":"2026-07-16T20:29:07.045639Z","price_level":"64129.96","new_quantity":"0"},{"side":"bid","event_time":"2026-07-16T20:29:07.045639Z","price_level":"64129.17","new_quantity":"0.01559176"},{"side":"bid","event_time":"2026-07-16T20:29:07.045639Z","price_level":"64129.16","new_quantity":"0"},{"side":"bid","event_time":"2026-07-16T20:29:07.045639Z","price_level":"64125.08","new_quantity":"0.07399"},{"side":"bid","event_time":"2026-07-16T20:29:07.045639Z","price_level":"64113","new_quantity":"1.0000309"},{"side":"bid","event_time":"2026-07-16T20:29:07.045639Z","price_level":"64111.01","new_quantity":"0"},{"side":"bid","event_time":"2026-07-16T20:29:07.045639Z","price_level":"64108.9","new_quantity":"0.63219204"},{"side":"bid","event_time":"2026-07-16T20:29:07.045639Z","price_level":"64097.15","new_quantity":"0"},{"side":"bid","event_time":"2026-07-16T20:29:07.045639Z","price_level":"64094.92","new_quantity":"0.98345581"},{"side":"bid","event_time":"2026-07-16T20:29:07.045639Z","price_level":"64053.74","new_quantity":"0.01061683"},{"side":"bid","event_time":"2026-07-16T20:29:07.045639Z","price_level":"56121.43","new_quantity":"0.01337205"},{"side":"offer","event_time":"2026-07-16T20:29:07.045639Z","price_level":"64149.43","new_quantity":"0.00009743"},{"side":"offer","event_time":"2026-07-16T20:29:07.045639Z","price_level":"64150","new_quantity":"0.01"},{"side":"offer","event_time":"2026-07-16T20:29:07.045639Z","price_level":"64150.39","new_quantity":"0.00779418"},{"side":"offer","event_time":"2026-07-16T20:29:07.045639Z","price_level":"64150.58","new_quantity":"0"},{"side":"offer","event_time":"2026-07-16T20:29:07.045639Z","price_level":"64150.9","new_quantity":"0"},{"side":"offer","event_time":"2026-07-16T20:29:07.045639Z","price_level":"64152.18","new_quantity":"0"},{"side":"offer","event_time":"2026-07-16T20:29:07.045639Z","price_level":"64152.19","new_quantity":"0"},{"side":"offer","event_time":"2026-07-16T20:29:07.045639Z","price_level":"64178.76","new_quantity":"0.00077953"},{"side":"offer","event_time":"2026-07-16T20:29:07.045639Z","price_level":"64179.99","new_quantity":"0"},{"side":"offer","event_time":"2026-07-16T20:29:07.045639Z","price_level":"64180.89","new_quantity":"0.50701821"},{"side":"offer","event_time":"2026-07-16T20:29:07.045639Z","price_level":"64180.9","new_quantity":"0.48575225"},{"side":"offer","event_time":"2026-07-16T20:29:07.045639Z","price_level":"64180.91","new_quantity":"0"},{"side":"offer","event_time":"2026-07-16T20:29:07.045639Z","price_level":"64180.92","new_quantity":"0"}]}]}
{"channel":"l2_data","timestamp":"2026-07-16T20:29:07.395766224Z","sequence_num":299,"events":[{"type":"update","product_id":"BTC-USD","updates":[{"side":"bid","event_time":"2026-07-16T20:29:07.094384Z","price_level":"64114.01","new_quantity":"0.654929"},{"side":"bid","event_time":"2026-07-16T20:29:07.094384Z","price_level":"64109.95","new_quantity":"0"},{"side":"bid","event_time":"2026-07-16T20:29:07.094384Z","price_level":"56121.43","new_quantity":"0"},{"side":"offer","event_time":"2026-07-16T20:29:07.094384Z","price_level":"64161.48","new_quantity":"0.66934749"},{"side":"offer","event_time":"2026-07-16T20:29:07.094384Z","price_level":"64162.61","new_quantity":"0.545506"},{"side":"offer","event_time":"2026-07-16T20:29:07.094384Z","price_level":"64172.26","new_quantity":"0.05238146"},{"side":"offer","event_time":"2026-07-16T20:29:07.094384Z","price_level":"64174.17","new_quantity":"0"},{"side":"offer","event_time":"2026-07-16T20:29:07.094384Z","price_level":"64177.53","new_quantity":"1.16174333"},{"side":"offer","event_time":"2026-07-16T20:29:07.094384Z","price_level":"64178.76","new_quantity":"0.48654798"},{"side":"offer","event_time":"2026-07-16T20:29:07.094384Z","price_level":"64180.89","new_quantity":"0"},{"side":"offer","event_time":"2026-07-16T20:29:07.094384Z","price_level":"64180.9","new_quantity":"0"},{"side":"offer","event_time":"2026-07-16T20:29:07.094384Z","price_level":"64182.45","new_quantity":"0.20086597"}]}]}
{"channel":"l2_data","timestamp":"2026-07-16T20:29:07.396526553Z","sequence_num":300,"events":[{"type":"update","product_id":"BTC-USD","updates":[{"side":"bid","event_time":"2026-07-16T20:29:07.150254Z","price_level":"64124.45","new_quantity":"0"},{"side":"bid","event_time":"2026-07-16T20:29:07.150254Z","price_level":"64114","new_quantity":"1"},{"side":"bid","event_time":"2026-07-16T20:29:07.150254Z","price_level":"64113","new_quantity":"0.0000309"},{"side":"bid","event_time":"2026-07-16T20:29:07.150254Z","price_level":"64103.08","new_quantity":"0.00155807"},{"side":"bid","event_time":"2026-07-16T20:29:07.150254Z","price_level":"64100.61","new_quantity":"0.02930041"},{"side":"bid","event_time":"2026-07-16T20:29:07.150254Z","price_level":"64098.04","new_quantity":"0.03405689"},{"side":"bid","event_time":"2026-07-16T20:29:07.150254Z","price_level":"64096.68","new_quantity":"0.00779036"},{"side":"bid","event_time":"2026-07-16T20:29:07.150254Z","price_level":"64094.19","new_quantity":"0.02558323"},{"side":"bid","event_time":"2026-07-16T20:29:07.150254Z","price_level":"64070.28","new_quantity":"0.001545"},{"side":"bid","event_time":"2026-07-16T20:29:07.150254Z","price_level":"63738.5","new_quantity":"0"},{"side":"bid","event_time":"2026-07-16T20:29:07.150254Z","price_level":"62827.17","new_quantity":"0.00583"},{"side":"bid","event_time":"2026-07-16T20:29:07.150254Z","price_level":"62827.02","new_quantity":"0"},{"side":"offer","event_time":"2026-07-16T20:29:07.150254Z","price_level":"64163.03","new_quantity":"0.03416395"},{"side":"offer","event_time":"2026-07-16T20:29:07.150254Z","price_level":"64368.58","new_quantity":"0.00583"},{"side":"offer","event_time":"2026-07-16T20:29:07.150254Z","price_level":"65011.87","new_quantity":"0.00583"}]}]}
{"channel":"l2_data","timestamp":"2026-07-16T20:29:07.397975196Z","sequence_num":301,"events":[{"type":"update","product_id":"BTC-USD","updates":[{"side":"bid","event_time":"2026-07-16T20:29:07.198212Z","price_level":"63501.24","new_quantity":"0"},{"side":"bid","event_time":"2026-07-16T20:29:07.198212Z","price_level":"62827.38","new_quantity":"0.00583"},{"side":"bid","event_time":"2026-07-16T20:29:07.198212Z","price_level":"62827.17","new_quantity":"0"},{"side":"offer","event_time":"2026-07-16T20:29:07.198212Z","price_level":"64138.78","new_quantity":"0.13742687"},{"side":"offer","event_time":"2026-07-16T20:29:07.198212Z","price_level":"64139.57","new_quantity":"0.0023457"},{"side":"offer","event_time":"2026-07-16T20:29:07.198212Z","price_level":"64139.66","new_quantity":"0"},{"side":"offer","event_time":"2026-07-16T20:29:07.198212Z","price_level":"64149.19","new_quantity":"0.00077955"},{"side":"offer","event_time":"2026-07-16T20:29:07.198212Z","price_level":"64151.69","new_quantity":"0"},{"side":"offer","event_time":"2026-07-16T20:29:07.198212Z","price_level":"64368.34","new_quantity":"0.00583"},{"side":"offer","event_time":"2026-07-16T20:29:07.198212Z","price_level":"64368.58","new_quantity":"0"},{"side":"offer","event_time":"2026-07-16T20:29:07.198212Z","price_level":"64369.68","new_quantity":"0"},{"side":"offer","event_time":"2026-07-16T20:29:07.198212Z","price_level":"64583.26","new_quantity":"0.00583"},{"side":"offer","event_time":"2026-07-16T20:29:07.198212Z","price_level":"65011.63","new_quantity":"0.00583"},{"side":"offer","event_time":"2026-07-16T20:29:07.198212Z","price_level":"65011.87","new_quantity":"0"},{"side":"offer","event_time":"2026-07-16T20:29:07.198212Z","price_level":"65225.37","new_quantity":"0"},{"side":"offer","event_time":"2026-07-16T20:29:07.198212Z","price_level":"65226.55","new_quantity":"0.00583"},{"side":"offer","event_time":"2026-07-16T20:29:07.198212Z","price_level":"65439.8","new_quantity":"0"},{"side":"offer","event_time":"2026-07-16T20:29:07.198212Z","price_level":"65654.25","new_quantity":"0"}]}]}
{"channel":"l2_data","timestamp":"2026-07-16T20:29:07.40066751Z","sequence_num":302,"events":[{"type":"update","product_id":"BTC-USD","updates":[{"side":"bid","event_time":"2026-07-16T20:29:07.235049Z","price_level":"64037.64","new_quantity":"0.00813366"},{"side":"bid","event_time":"2026-07-16T20:29:07.235049Z","price_level":"62827.46","new_quantity":"0.00583"},{"side":"bid","event_time":"2026-07-16T20:29:07.235049Z","price_level":"62827.38","new_quantity":"0"},{"side":"offer","event_time":"2026-07-16T20:29:07.235049Z","price_level":"64149.18","new_quantity":"0.0077892"},{"side":"offer","event_time":"2026-07-16T20:29:07.235049Z","price_level":"64149.32","new_quantity":"0"},{"side":"offer","event_time":"2026-07-16T20:29:07.235049Z","price_level":"64164.72","new_quantity":"0"},{"side":"offer","event_time":"2026-07-16T20:29:07.235049Z","price_level":"64368.31","new_quantity":"0.00583"},{"side":"offer","event_time":"2026-07-16T20:29:07.235049Z","price_level":"64368.33","new_quantity":"0"},{"side":"offer","event_time":"2026-07-16T20:29:07.235049Z","price_level":"64368.34","new_quantity":"0"},{"side":"offer","event_time":"2026-07-16T20:29:07.235049Z","price_level":"64582.82","new_quantity":"0.00583"},{"side":"offer","event_time":"2026-07-16T20:29:07.235049Z","price_level":"64796.51","new_quantity":"0"},{"side":"offer","event_time":"2026-07-16T20:29:07.235049Z","price_level":"64797.77","new_quantity":"0.00583"},{"side":"offer","event_time":"2026-07-16T20:29:07.235049Z","price_level":"65011.6","new_quantity":"0"},{"side":"offer","event_time":"2026-07-16T20:29:07.235049Z","price_level":"65011.62","new_quantity":"0"},{"side":"offer","event_time":"2026-07-16T20:29:07.235049Z","price_level":"65011.63","new_quantity":"0"},{"side":"offer","event_time":"2026-07-16T20:29:07.235049Z","price_level":"65226.11","new_quantity":"0.00583"},{"side":"offer","event_time":"2026-07-16T20:29:07.235049Z","price_level":"65226.55","new_quantity":"0"},{"side":"offer","event_time":"2026-07-16T20:29:07.235049Z","price_level":"65226.63","new_quantity":"0.00583"}]}]}
{"channel":"l2_data","timestamp":"2026-07-16T20:29:07.401113331Z","sequence_num":303,"events":[{"type":"update","product_id":"BTC-USD","updates":[{"side":"bid","event_time":"2026-07-16T20:29:07.295177Z","price_level":"64133.93","new_quantity":"0.00779619"},{"side":"bid","event_time":"2026-07-16T20:29:07.295177Z","price_level":"64129.17","new_quantity":"0"},{"side":"bid","event_time":"2026-07-16T20:29:07.295177Z","price_level":"64128.99","new_quantity":"0.01559176"},{"side":"bid","event_time":"2026-07-16T20:29:07.295177Z","price_level":"64114","new_quantity":"0"},{"side":"bid","event_time":"2026-07-16T20:29:07.295177Z","price_level":"56121.43","new_quantity":"0.01337205"},{"side":"offer","event_time":"2026-07-16T20:29:07.295177Z","price_level":"64139.17","new_quantity":"0.04691558"},{"side":"offer","event_time":"2026-07-16T20:29:07.295177Z","price_level":"65655.3","new_quantity":"0.00583"}]}]}
{"channel":"l2_data","timestamp":"2026-07-16T20:29:07.404025215Z","sequence_num":304,"events":[{"type":"update","product_id":"BTC-USD","updates":[{"side":"bid","event_time":"2026-07-16T20:29:07.360295Z","price_level":"64133.04","new_quantity":"0"},{"side":"bid","event_time":"2026-07-16T20:29:07.360295Z","price_level":"64132.06","new_quantity":"0.12474258"},{"side":"bid","event_time":"2026-07-16T20:29:07.360295Z","price_level":"64130.36","new_quantity":"0.02"},{"side":"bid","event_time":"2026-07-16T20:29:07.360295Z","price_level":"64129","new_quantity":"0.01559176"},{"side":"bid","event_time":"2026-07-16T20:29:07.360295Z","price_level":"64128.99","new_quantity":"0"},{"side":"bid","event_time":"2026-07-16T20:29:07.360295Z","price_level":"64125.08","new_quantity":"0"},{"side":"bid","event_time":"2026-07-16T20:29:07.360295Z","price_level":"64124.54","new_quantity":"0.685687"},{"side":"bid","event_time":"2026-07-16T20:29:07.360295Z","price_level":"64114.01","new_quantity":"0"},{"side":"bid","event_time":"2026-07-16T20:29:07.360295Z","price_level":"64112","new_quantity":"0"},{"side":"bid","event_time":"2026-07-16T20:29:07.360295Z","price_level":"64109.98","new_quantity":"0.65494159"},{"side":"bid","event_time":"2026-07-16T20:29:07.360295Z","price_level":"64105","new_quantity":"0.01"},{"side":"bid","event_time":"2026-07-16T20:29:07.360295Z","price_level":"64100.61","new_quantity":"0"},{"side":"bid","event_time":"2026-07-16T20:29:07.360295Z","price_level":"64098.04","new_quantity":"0"},{"side":"bid","event_time":"2026-07-16T20:29:07.360295Z","price_level":"64094.19","new_quantity":"0"},{"side":"bid","event_time":"2026-07-16T20:29:07.360295Z","price_level":"64079.71","new_quantity":"0"},{"side":"bid","event_time":"2026-07-16T20:29:07.360295Z","price_level":"64078.09","new_quantity":"0"},{"side":"bid","event_time":"2026-07-16T20:29:07.360295Z","price_level":"64076.57","new_quantity":"1.39440682"},{"side":"bid","event_time":"2026-07-16T20:29:07.360295Z","price_level":"64053.74","new_quantity":"0"},{"side":"bid","event_time":"2026-07-16T20:29:07.360295Z","price_level":"63980.45","new_quantity":"0.00270508"},{"side":"offer","event_time":"2026-07-16T20:29:07.360295Z","price_level":"64138.78","new_quantity":"0.16774089"},{"side":"offer","event_time":"2026-07-16T20:29:07.360295Z","price_level":"64139.16","new_quantity":"0.02"},{"side":"offer","event_time":"2026-07-16T20:29:07.360295Z","price_level":"64139.57","new_quantity":"0"},{"side":"offer","event_time":"2026-07-16T20:29:07.360295Z","price_level":"64153.06","new_quantity":"0.06879151"},{"side":"offer","event_time":"2026-07-16T20:29:07.360295Z","price_level":"64162.06","new_quantity":"0.01"},{"side":"offer","event_time":"2026-07-16T20:29:07.360295Z","price_level":"64167.63","new_quantity":"0"},{"side":"offer","event_time":"2026-07-16T20:29:07.360295Z","price_level":"64174.5","new_quantity":"0.43063529"},{"side":"offer","event_time":"2026-07-16T20:29:07.360295Z","price_level":"64174.51","new_quantity":"0.32027682"},{"side":"offer","event_time":"2026-07-16T20:29:07.360295Z","price_level":"64174.64","new_quantity":"0"},{"side":"offer","event_time":"2026-07-16T20:29:07.360295Z","price_level":"64176.08","new_quantity":"0"},{"side":"offer","event_time":"2026-07-16T20:29:07.360295Z","price_level":"64178.03","new_quantity":"0.48577397"},{"side":"offer","event_time":"2026-07-16T20:29:07.360295Z","price_level":"64178.76","new_quantity":"0.00077953"},{"side":"offer","event_time":"2026-07-16T20:29:07.360295Z","price_level":"64191.81","new_quantity":"0.70475348"},{"side":"offer","event_time":"2026-07-16T20:29:07.360295Z","price_level":"64192.99","new_quantity":"0"},{"side":"offer","event_time":"2026-07-16T20:29:07.360295Z","price_level":"64194.53","new_quantity":"2.002252"},{"side":"offer","event_time":"2026-07-16T20:29:07.360295Z","price_level":"64196.73","new_quantity":"0"},{"side":"offer","event_time":"2026-07-16T20:29:07.360295Z","price_level":"64367.64","new_quantity":"0.00583"},{"side":"offer","event_time":"2026-07-16T20:29:07.360295Z","price_level":"64583.26","new_quantity":"0"},{"side":"offer","event_time":"2026-07-16T20:29:07.360295Z","price_level":"65225.36","new_quantity":"0.00583"},{"side":"offer","event_time":"2026-07-16T20:29:07.360295Z","price_level":"65226.63","new_quantity":"0"},{"side":"offer","event_time":"2026-07-16T20:29:07.360295Z","price_level":"65654.22","new_quantity":"0.00583"},{"side":"offer","event_time":"2026-07-16T20:29:07.360295Z","price_level":"65655.3","new_quantity":"0"}]}]}
{"channel":"l2_data","timestamp":"2026-07-16T20:29:07.444583015Z","sequence_num":305,"events":[{"type":"update","product_id":"BTC-USD","updates":[{"side":"bid","event_time":"2026-07-16T20:29:07.410949Z","price_level":"64133.96","new_quantity":"0.00779618"},{"side":"bid","event_time":"2026-07-16T20:29:07.410949Z","price_level":"64132.36","new_quantity":"0.00779638"},{"side":"bid","event_time":"2026-07-16T20:29:07.410949Z","price_level":"64131.04","new_quantity":"0"},{"side":"bid","event_time":"2026-07-16T20:29:07.410949Z","price_level":"64130.44","new_quantity":"0.02"},{"side":"bid","event_time":"2026-07-16T20:29:07.410949Z","price_level":"64124.54","new_quantity":"0"},{"side":"bid","event_time":"2026-07-16T20:29:07.410949Z","price_level":"64122.61","new_quantity":"0.11366897"},{"side":"bid","event_time":"2026-07-16T20:29:07.410949Z","price_level":"64121.88","new_quantity":"0.07399"},{"side":"bid","event_time":"2026-07-16T20:29:07.410949Z","price_level":"64114.96","new_quantity":"0"},{"side":"bid","event_time":"2026-07-16T20:29:07.410949Z","price_level":"64114.01","new_quantity":"0"},{"side":"bid","event_time":"2026-07-16T20:29:07.410949Z","price_level":"64110","new_quantity":"1.01"},{"side":"bid","event_time":"2026-07-16T20:29:07.410949Z","price_level":"64109.98","new_quantity":"0.65493992"},{"side":"bid","event_time":"2026-07-16T20:29:07.410949Z","price_level":"64106","new_quantity":"0"},{"side":"bid","event_time":"2026-07-16T20:29:07.410949Z","price_level":"64103.08","new_quantity":"0"},{"side":"bid","event_time":"2026-07-16T20:29:07.410949Z","price_level":"64100.92","new_quantity":"0.00155812"},{"side":"bid","event_time":"2026-07-16T20:29:07.410949Z","price_level":"64096.68","new_quantity":"0"},{"side":"bid","event_time":"2026-07-16T20:29:07.410949Z","price_level":"64094.52","new_quantity":"0.00779062"},{"side":"bid","event_time":"2026-07-16T20:29:07.410949Z","price_level":"64051.74","new_quantity":"0.01061683"},{"side":"bid","event_time":"2026-07-16T20:29:07.410949Z","price_level":"63497.83","new_quantity":"0.03937793"},{"side":"bid","event_time":"2026-07-16T20:29:07.410949Z","price_level":"56121.43","new_quantity":"0"},{"side":"offer","event_time":"2026-07-16T20:29:07.410949Z","price_level":"64138.78","new_quantity":"0.1693149"},{"side":"offer","event_time":"2026-07-16T20:29:07.410949Z","price_level":"64139.17","new_quantity":"0.06691558"},{"side":"offer","event_time":"2026-07-16T20:29:07.410949Z","price_level":"64150.29","new_quantity":"0.00896333"},{"side":"offer","event_time":"2026-07-16T20:29:07.410949Z","price_level":"64151.9","new_quantity":"0.0089631"},{"side":"offer","event_time":"2026-07-16T20:29:07.410949Z","price_level":"64152.18","new_quantity":"0.00583"},{"side":"offer","event_time":"2026-07-16T20:29:07.410949Z","price_level":"64152.5","new_quantity":"0.00583"},{"side":"offer","event_time":"2026-07-16T20:29:07.410949Z","price_level":"64153.07","new_quantity":"0"},{"side":"offer","event_time":"2026-07-16T20:29:07.410949Z","price_level":"64161.39","new_quantity":"0.0010524"},{"side":"offer","event_time":"2026-07-16T20:29:07.410949Z","price_level":"64368.31","new_quantity":"0"},{"side":"offer","event_time":"2026-07-16T20:29:07.410949Z","price_level":"65224.33","new_quantity":"0.00583"},{"side":"offer","event_time":"2026-07-16T20:29:07.410949Z","price_level":"65224.65","new_quantity":"0.00583"},{"side":"offer","event_time":"2026-07-16T20:29:07.410949Z","price_level":"65225.36","new_quantity":"0"},{"side":"offer","event_time":"2026-07-16T20:29:07.410949Z","price_level":"65226.11","new_quantity":"0"},{"side":"offer","event_time":"2026-07-16T20:29:07.410949Z","price_level":"65653.58","new_quantity":"0"},{"side":"offer","event_time":"2026-07-16T20:29:07.410949Z","price_level":"65654.22","new_quantity":"0"}]}]}
{"channel":"l2_data","timestamp":"2026-07-16T20:29:07.486155146Z","sequence_num":306,"events":[{"type":"update","product_id":"BTC-USD","updates":[{"side":"bid","event_time":"2026-07-16T20:29:07.455271Z","price_level":"64129.01","new_quantity":"0.01559176"},{"side":"bid","event_time":"2026-07-16T20:29:07.455271Z","price_level":"64129","new_quantity":"0"},{"side":"bid","event_time":"2026-07-16T20:29:07.455271Z","price_level":"64110","new_quantity":"0.01"},{"side":"bid","event_time":"2026-07-16T20:29:07.455271Z","price_level":"64109.94","new_quantity":"0.63218178"},{"side":"bid","event_time":"2026-07-16T20:29:07.455271Z","price_level":"64108.9","new_quantity":"0"},{"side":"bid","event_time":"2026-07-16T20:29:07.455271Z","price_level":"64095.74","new_quantity":"0.98266374"},{"side":"bid","event_time":"2026-07-16T20:29:07.455271Z","price_level":"64094.92","new_quantity":"0.0007795"},{"side":"bid","event_time":"2026-07-16T20:29:07.455271Z","price_level":"64077.94","new_quantity":"1.394377"},{"side":"bid","event_time":"2026-07-16T20:29:07.455271Z","price_level":"64076.57","new_quantity":"0"},{"side":"bid","event_time":"2026-07-16T20:29:07.455271Z","price_level":"64029.84","new_quantity":"0"},{"side":"offer","event_time":"2026-07-16T20:29:07.455271Z","price_level":"64145.77","new_quantity":"0.66263048"},{"side":"offer","event_time":"2026-07-16T20:29:07.455271Z","price_level":"64148.19","new_quantity":"0.65494154"},{"side":"offer","event_time":"2026-07-16T20:29:07.455271Z","price_level":"64152.16","new_quantity":"0.00583"},{"side":"offer","event_time":"2026-07-16T20:29:07.455271Z","price_level":"64152.5","new_quantity":"0"},{"side":"offer","event_time":"2026-07-16T20:29:07.455271Z","price_level":"64174.51","new_quantity":"0"},{"side":"offer","event_time":"2026-07-16T20:29:07.455271Z","price_level":"64177.24","new_quantity":"0.32027682"},{"side":"offer","event_time":"2026-07-16T20:29:07.455271Z","price_level":"65224.31","new_quantity":"0.00583"},{"side":"offer","event_time":"2026-07-16T20:29:07.455271Z","price_level":"65224.65","new_quantity":"0"}]}]}
{"channel":"l2_data","timestamp":"2026-07-16T20:29:07.531865514Z","sequence_num":307,"events":[{"type":"update","product_id":"BTC-USD","updates":[{"side":"bid","event_time":"2026-07-16T20:29:07.489057Z","price_level":"64129.01","new_quantity":"0"},{"side":"bid","event_time":"2026-07-16T20:29:07.489057Z","price_level":"64128.73","new_quantity":"0.01559176"},{"side":"bid","event_time":"2026-07-16T20:29:07.489057Z","price_level":"64121.14","new_quantity":"0.0486477"},{"side":"bid","event_time":"2026-07-16T20:29:07.489057Z","price_level":"64111","new_quantity":"1"},{"side":"offer","event_time":"2026-07-16T20:29:07.489057Z","price_level":"64151.89","new_quantity":"0.007794"}]}]}
{"channel":"l2_data","timestamp":"2026-07-16T20:29:07.583725809Z","sequence_num":308,"events":[{"type":"update","product_id":"BTC-USD","updates":[{"side":"bid","event_time":"2026-07-16T20:29:07.542372Z","price_level":"64138.77","new_quantity":"0.00235615"},{"side":"bid","event_time":"2026-07-16T20:29:07.542372Z","price_level":"64133.93","new_quantity":"0"},{"side":"bid","event_time":"2026-07-16T20:29:07.542372Z","price_level":"64114.47","new_quantity":"0.01"},{"side":"offer","event_time":"2026-07-16T20:29:07.542372Z","price_level":"64138.78","new_quantity":"0.95853051"},{"side":"offer","event_time":"2026-07-16T20:29:07.542372Z","price_level":"64139.16","new_quantity":"0"},{"side":"offer","event_time":"2026-07-16T20:29:07.542372Z","price_level":"64139.17","new_quantity":"0.58667796"},{"side":"offer","event_time":"2026-07-16T20:29:07.542372Z","price_level":"64150.6","new_quantity":"0.00009743"},{"side":"offer","event_time":"2026-07-16T20:29:07.542372Z","price_level":"64152.18","new_quantity":"0"},{"side":"offer","event_time":"2026-07-16T20:29:07.542372Z","price_level":"64366.9","new_quantity":"0.00583"},{"side":"offer","event_time":"2026-07-16T20:29:07.542372Z","price_level":"64367.64","new_quantity":"0"},{"side":"offer","event_time":"2026-07-16T20:29:07.542372Z","price_level":"64581.34","new_quantity":"0.00583"},{"side":"offer","event_time":"2026-07-16T20:29:07.542372Z","price_level":"64581.39","new_quantity":"0.00583"},{"side":"offer","event_time":"2026-07-16T20:29:07.542372Z","price_level":"64581.97","new_quantity":"0"},{"side":"offer","event_time":"2026-07-16T20:29:07.542372Z","price_level":"64582.82","new_quantity":"0"},{"side":"offer","event_time":"2026-07-16T20:29:07.542372Z","price_level":"65224.33","new_quantity":"0"},{"side":"offer","event_time":"2026-07-16T20:29:07.542372Z","price_level":"65439.05","new_quantity":"0"},{"side":"offer","event_time":"2026-07-16T20:29:07.542372Z","price_level":"65439.06","new_quantity":"0.00583"},{"side":"offer","event_time":"2026-07-16T20:29:07.542372Z","price_level":"65653.48","new_quantity":"0"}]}]}
{"channel":"l2_data","timestamp":"2026-07-16T20:29:07.631968375Z","sequence_num":309,"events":[{"type":"update","product_id":"BTC-USD","updates":[{"side":"bid","event_time":"2026-07-16T20:29:07.602508Z","price_level":"64138.77","new_quantity":"0.00235605"},{"side":"bid","event_time":"2026-07-16T20:29:07.602508Z","price_level":"64137.48","new_quantity":"0.00779575"},{"side":"bid","event_time":"2026-07-16T20:29:07.602508Z","price_level":"64132.74","new_quantity":"0.12474126"},{"side":"bid","event_time":"2026-07-16T20:29:07.602508Z","price_level":"64132.06","new_quantity":"0"},{"side":"bid","event_time":"2026-07-16T20:29:07.602508Z","price_level":"64128.74","new_quantity":"0.01559176"},{"side":"bid","event_time":"2026-07-16T20:29:07.602508Z","price_level":"64128.73","new_quantity":"0"},{"side":"bid","event_time":"2026-07-16T20:29:07.602508Z","price_level":"64123.73","new_quantity":"0.66055"},{"side":"bid","event_time":"2026-07-16T20:29:07.602508Z","price_level":"64111","new_quantity":"0"},{"side":"bid","event_time":"2026-07-16T20:29:07.602508Z","price_level":"64109.99","new_quantity":"0.63218129"},{"side":"bid","event_time":"2026-07-16T20:29:07.602508Z","price_level":"64109.94","new_quantity":"0"},{"side":"bid","event_time":"2026-07-16T20:29:07.602508Z","price_level":"64091.82","new_quantity":"0.00078013"},{"side":"bid","event_time":"2026-07-16T20:29:07.602508Z","price_level":"56121.43","new_quantity":"0.01337205"},{"side":"offer","event_time":"2026-07-16T20:29:07.602508Z","price_level":"64174.64","new_quantity":"0.32027682"},{"side":"offer","event_time":"2026-07-16T20:29:07.602508Z","price_level":"64177.24","new_quantity":"0"},{"side":"offer","event_time":"2026-07-16T20:29:07.602508Z","price_level":"64178.03","new_quantity":"0"},{"side":"offer","event_time":"2026-07-16T20:29:07.602508Z","price_level":"64181.05","new_quantity":"0.50606349"},{"side":"offer","event_time":"2026-07-16T20:29:07.602508Z","price_level":"64181.06","new_quantity":"0.48575104"},{"side":"offer","event_time":"2026-07-16T20:29:07.602508Z","price_level":"64182.45","new_quantity":"0"},{"side":"offer","event_time":"2026-07-16T20:29:07.602508Z","price_level":"64366.88","new_quantity":"0.00583"},{"side":"offer","event_time":"2026-07-16T20:29:07.602508Z","price_level":"64581.39","new_quantity":"0"},{"side":"offer","event_time":"2026-07-16T20:29:07.602508Z","price_level":"65439.03","new_quantity":"0.00583"},{"side":"offer","event_time":"2026-07-16T20:29:07.602508Z","price_level":"65439.06","new_quantity":"0"}]}]}
{"channel":"l2_data","timestamp":"2026-07-16T20:29:07.679856541Z","sequence_num":310,"events":[{"type":"update","product_id":"BTC-USD","updates":[{"side":"bid","event_time":"2026-07-16T20:29:07.654468Z","price_level":"64138.77","new_quantity":"0.00421289"},{"side":"bid","event_time":"2026-07-16T20:29:07.654468Z","price_level":"64135","new_quantity":"0.01054835"},{"side":"bid","event_time":"2026-07-16T20:29:07.654468Z","price_level":"64128.75","new_quantity":"0.01559176"},{"side":"bid","event_time":"2026-07-16T20:29:07.654468Z","price_level":"64128.74","new_quantity":"0"},{"side":"bid","event_time":"2026-07-16T20:29:07.654468Z","price_level":"64123.73","new_quantity":"0"},{"side":"bid","event_time":"2026-07-16T20:29:07.654468Z","price_level":"64112","new_quantity":"1"},{"side":"offer","event_time":"2026-07-16T20:29:07.654468Z","price_level":"64198.39","new_quantity":"0.00077949"},{"side":"offer","event_time":"2026-07-16T20:29:07.654468Z","price_level":"64199.58","new_quantity":"0"},{"side":"offer","event_time":"2026-07-16T20:29:07.654468Z","price_level":"64366.9","new_quantity":"0"},{"side":"offer","event_time":"2026-07-16T20:29:07.654468Z","price_level":"64795.79","new_quantity":"0.00583"},{"side":"offer","event_time":"2026-07-16T20:29:07.654468Z","price_level":"64795.8","new_quantity":"0.00583"},{"side":"offer","event_time":"2026-07-16T20:29:07.654468Z","price_level":"64797.77","new_quantity":"0"}]}]}
{"channel":"l2_data","timestamp":"2026-07-16T20:29:07.72968845Z","sequence_num":311,"events":[{"type":"update","product_id":"BTC-USD","updates":[{"side":"bid","event_time":"2026-07-16T20:29:07.69088Z","price_level":"64029.84","new_quantity":"0.05022197"},{"side":"bid","event_time":"2026-07-16T20:29:07.69088Z","price_level":"56121.43","new_quantity":"0"},{"side":"offer","event_time":"2026-07-16T20:29:07.69088Z","price_level":"64174.64","new_quantity":"0"},{"side":"offer","event_time":"2026-07-16T20:29:07.69088Z","price_level":"64177.24","new_quantity":"0.32027682"},{"side":"offer","event_time":"2026-07-16T20:29:07.69088Z","price_level":"64184.99","new_quantity":"0.00077949"},{"side":"offer","event_time":"2026-07-16T20:29:07.69088Z","price_level":"64185.1","new_quantity":"0"},{"side":"offer","event_time":"2026-07-16T20:29:07.69088Z","price_level":"64779.97","new_quantity":"0"}]}]}
{"channel":"l2_data","timestamp":"2026-07-16T20:29:07.780000227Z","sequence_num":312,"events":[{"type":"update","product_id":"BTC-USD","updates":[{"side":"bid","event_time":"2026-07-16T20:29:07.74608Z","price_level":"64138","new_quantity":"0.00486636"},{"side":"bid","event_time":"2026-07-16T20:29:07.74608Z","price_level":"64128.76","new_quantity":"0.01559176"},{"side":"bid","event_time":"2026-07-16T20:29:07.74608Z","price_level":"64128.75","new_quantity":"0"},{"side":"offer","event_time":"2026-07-16T20:29:07.74608Z","price_level":"64155.46","new_quantity":"0"},{"side":"offer","event_time":"2026-07-16T20:29:07.74608Z","price_level":"64181.03","new_quantity":"0.50766156"},{"side":"offer","event_time":"2026-07-16T20:29:07.74608Z","price_level":"64181.04","new_quantity":"0.48575119"},{"side":"offer","event_time":"2026-07-16T20:29:07.74608Z","price_level":"64181.05","new_quantity":"0"},{"side":"offer","event_time":"2026-07-16T20:29:07.74608Z","price_level":"64181.06","new_quantity":"0"}]}]}
{"channel":"l2_data","timestamp":"2026-07-16T20:29:07.835568212Z","sequence_num":313,"events":[{"type":"update","product_id":"BTC-USD","updates":[{"side":"bid","event_time":"2026-07-16T20:29:07.803797Z","price_level":"64138.77","new_quantity":"0.00421286"},{"side":"bid","event_time":"2026-07-16T20:29:07.803797Z","price_level":"64132.75","new_quantity":"0.02"},{"side":"bid","event_time":"2026-07-16T20:29:07.803797Z","price_level":"64076.1","new_quantity":"0.00858322"},{"side":"offer","event_time":"2026-07-16T20:29:07.803797Z","price_level":"64139.17","new_quantity":"0.56667796"},{"side":"offer","event_time":"2026-07-16T20:29:07.803797Z","price_level":"64795.78","new_quantity":"0.00583"},{"side":"offer","event_time":"2026-07-16T20:29:07.803797Z","price_level":"64795.79","new_quantity":"0"},{"side":"offer","event_time":"2026-07-16T20:29:07.803797Z","price_level":"64795.8","new_quantity":"0"}]}]}
{"channel":"l2_data","timestamp":"2026-07-16T20:29:07.881002329Z","sequence_num":314,"events":[{"type":"update","product_id":"BTC-USD","updates":[{"side":"bid","event_time":"2026-07-16T20:29:07.856383Z","price_level":"64137.48","new_quantity":"0.00826346"},{"side":"bid","event_time":"2026-07-16T20:29:07.856383Z","price_level":"64135","new_quantity":"0.01"},{"side":"bid","event_time":"2026-07-16T20:29:07.856383Z","price_level":"64129.17","new_quantity":"0.01559176"},{"side":"bid","event_time":"2026-07-16T20:29:07.856383Z","price_level":"64128.87","new_quantity":"0"},{"side":"bid","event_time":"2026-07-16T20:29:07.856383Z","price_level":"64128.76","new_quantity":"0"},{"side":"bid","event_time":"2026-07-16T20:29:07.856383Z","price_level":"64124.27","new_quantity":"0"},{"side":"bid","event_time":"2026-07-16T20:29:07.856383Z","price_level":"64100.27","new_quantity":"0.02940038"},{"side":"bid","event_time":"2026-07-16T20:29:07.856383Z","price_level":"64097.71","new_quantity":"0.03362335"},{"side":"bid","event_time":"2026-07-16T20:29:07.856383Z","price_level":"64067.2","new_quantity":"0.01080895"},{"side":"offer","event_time":"2026-07-16T20:29:07.856383Z","price_level":"64181.01","new_quantity":"0.50701766"},{"side":"offer","event_time":"2026-07-16T20:29:07.856383Z","price_level":"64181.02","new_quantity":"0.48575134"},{"side":"offer","event_time":"2026-07-16T20:29:07.856383Z","price_level":"64181.03","new_quantity":"0.00159799"},{"side":"offer","event_time":"2026-07-16T20:29:07.856383Z","price_level":"64181.04","new_quantity":"0"}]}]}
{"channel":"l2_data","timestamp":"2026-07-16T20:29:07.930228269Z","sequence_num":315,"events":[{"type":"update","product_id":"BTC-USD","updates":[{"side":"bid","event_time":"2026-07-16T20:29:07.898442Z","price_level":"64138","new_quantity":"0"},{"side":"bid","event_time":"2026-07-16T20:29:07.898442Z","price_level":"64112","new_quantity":"0"},{"side":"bid","event_time":"2026-07-16T20:29:07.898442Z","price_level":"64093.86","new_quantity":"0.02511434"},{"side":"bid","event_time":"2026-07-16T20:29:07.898442Z","price_level":"64051.74","new_quantity":"0"},{"side":"bid","event_time":"2026-07-16T20:29:07.898442Z","price_level":"63731.07","new_quantity":"0.01061683"},{"side":"bid","event_time":"2026-07-16T20:29:07.898442Z","price_level":"56121.43","new_quantity":"0.01337205"},{"side":"offer","event_time":"2026-07-16T20:29:07.898442Z","price_level":"64778.6","new_quantity":"0.03890047"}]}]}
{"channel":"l2_data","timestamp":"2026-07-16T20:29:07.980572217Z","sequence_num":316,"events":[{"type":"update","product_id":"BTC-USD","updates":[{"side":"bid","event_time":"2026-07-16T20:29:07.947739Z","price_level":"64113","new_quantity":"1.0000309"},{"side":"bid","event_time":"2026-07-16T20:29:07.947739Z","price_level":"64029.84","new_quantity":"0.08914319"},{"side":"offer","event_time":"2026-07-16T20:29:07.947739Z","price_level":"64152.97","new_quantity":"0.26866371"},{"side":"offer","event_time":"2026-07-16T20:29:07.947739Z","price_level":"64176.08","new_quantity":"0.32027682"},{"side":"offer","event_time":"2026-07-16T20:29:07.947739Z","price_level":"64177.24","new_quantity":"0"},{"side":"offer","event_time":"2026-07-16T20:29:07.947739Z","price_level":"64180.99","new_quantity":"0.50701775"},{"side":"offer","event_time":"2026-07-16T20:29:07.947739Z","price_level":"64181","new_quantity":"0.48575149"},{"side":"offer","event_time":"2026-07-16T20:29:07.947739Z","price_level":"64181.01","new_quantity":"0"},{"side":"offer","event_time":"2026-07-16T20:29:07.947739Z","price_level":"64181.02","new_quantity":"0"}]}]}
{"channel":"l2_data","timestamp":"2026-07-16T20:29:08.032122826Z","sequence_num":317,"events":[{"type":"update","product_id":"BTC-USD","updates":[{"side":"bid","event_time":"2026-07-16T20:29:07.989891Z","price_level":"64125.08","new_quantity":"0.07399"},{"side":"bid","event_time":"2026-07-16T20:29:07.989891Z","price_level":"56121.43","new_quantity":"0"},{"side":"offer","event_time":"2026-07-16T20:29:07.989891Z","price_level":"64139.17","new_quantity":"0.38046858"},{"side":"offer","event_time":"2026-07-16T20:29:07.989891Z","price_level":"64141","new_quantity":"0"},{"side":"offer","event_time":"2026-07-16T20:29:07.989891Z","price_level":"64142.58","new_quantity":"0.05779598"},{"side":"offer","event_time":"2026-07-16T20:29:07.989891Z","price_level":"64142.99","new_quantity":"0"},{"side":"offer","event_time":"2026-07-16T20:29:07.989891Z","price_level":"64145.06","new_quantity":"0"},{"side":"offer","event_time":"2026-07-16T20:29:07.989891Z","price_level":"64152.29","new_quantity":"0.57081098"},{"side":"offer","event_time":"2026-07-16T20:29:07.989891Z","price_level":"64155","new_quantity":"0.01"},{"side":"offer","event_time":"2026-07-16T20:29:07.989891Z","price_level":"64780","new_quantity":"0.3"}]}]}
{"channel":"l2_data","timestamp":"2026-07-16T20:29:08.085162876Z","sequence_num":318,"events":[{"type":"update","product_id":"BTC-USD","updates":[{"side":"bid","event_time":"2026-07-16T20:29:08.061031Z","price_level":"64133.96","new_quantity":"0"},{"side":"bid","event_time":"2026-07-16T20:29:08.061031Z","price_level":"64132.36","new_quantity":"0"},{"side":"bid","event_time":"2026-07-16T20:29:08.061031Z","price_level":"64126.58","new_quantity":"0.04281099"},{"side":"bid","event_time":"2026-07-16T20:29:08.061031Z","price_level":"64121.88","new_quantity":"0"},{"side":"bid","event_time":"2026-07-16T20:29:08.061031Z","price_level":"64120.16","new_quantity":"0.05825191"},{"side":"bid","event_time":"2026-07-16T20:29:08.061031Z","price_level":"64095","new_quantity":"0.01"},{"side":"bid","event_time":"2026-07-16T20:29:08.061031Z","price_level":"64090","new_quantity":"0.01"},{"side":"offer","event_time":"2026-07-16T20:29:08.061031Z","price_level":"64142.58","new_quantity":"0.23661626"},{"side":"offer","event_time":"2026-07-16T20:29:08.061031Z","price_level":"64142.93","new_quantity":"0.31190852"},{"side":"offer","event_time":"2026-07-16T20:29:08.061031Z","price_level":"64145.66","new_quantity":"0.31190852"},{"side":"offer","event_time":"2026-07-16T20:29:08.061031Z","price_level":"64149.43","new_quantity":"0"},{"side":"offer","event_time":"2026-07-16T20:29:08.061031Z","price_level":"64150.29","new_quantity":"0"},{"side":"offer","event_time":"2026-07-16T20:29:08.061031Z","price_level":"64150.39","new_quantity":"0"},{"side":"offer","event_time":"2026-07-16T20:29:08.061031Z","price_level":"64150.6","new_quantity":"0"},{"side":"offer","event_time":"2026-07-16T20:29:08.061031Z","price_level":"64151.89","new_quantity":"0"},{"side":"offer","event_time":"2026-07-16T20:29:08.061031Z","price_level":"64151.9","new_quantity":"0"},{"side":"offer","event_time":"2026-07-16T20:29:08.061031Z","price_level":"64155.99","new_quantity":"1.10979227"},{"side":"offer","event_time":"2026-07-16T20:29:08.061031Z","price_level":"64156","new_quantity":"1"},{"side":"offer","event_time":"2026-07-16T20:29:08.061031Z","price_level":"64156.46","new_quantity":"0"},{"side":"offer","event_time":"2026-07-16T20:29:08.061031Z","price_level":"64180.97","new_quantity":"0.50701784"},{"side":"offer","event_time":"2026-07-16T20:29:08.061031Z","price_level":"64180.98","new_quantity":"0.48575164"},{"side":"offer","event_time":"2026-07-16T20:29:08.061031Z","price_level":"64180.99","new_quantity":"0"},{"side":"offer","event_time":"2026-07-16T20:29:08.061031Z","price_level":"64181","new_quantity":"0"}]}]}
{"channel":"l2_data","timestamp":"2026-07-16T20:29:08.129956578Z","sequence_num":319,"events":[{"type":"update","product_id":"BTC-USD","updates":[{"side":"bid","event_time":"2026-07-16T20:29:08.099934Z","price_level":"64129.96","new_quantity":"0"},{"side":"bid","event_time":"2026-07-16T20:29:08.099934Z","price_level":"64113","new_quantity":"0.0000309"},{"side":"offer","event_time":"2026-07-16T20:29:08.099934Z","price_level":"64139.17","new_quantity":"0.52403387"},{"side":"offer","event_time":"2026-07-16T20:29:08.099934Z","price_level":"64140.87","new_quantity":"0.31190852"},{"side":"offer","event_time":"2026-07-16T20:29:08.099934Z","price_level":"64149.11","new_quantity":"0.0077892"},{"side":"offer","event_time":"2026-07-16T20:29:08.099934Z","price_level":"64149.12","new_quantity":"0.00009743"},{"side":"offer","event_time":"2026-07-16T20:29:08.099934Z","price_level":"64149.18","new_quantity":"0"},{"side":"offer","event_time":"2026-07-16T20:29:08.099934Z","price_level":"64150.08","new_quantity":"0.00779422"}]}]}
{"channel":"heartbeats","timestamp":"2026-07-16T20:29:08.169232789Z","sequence_num":320,"events":[{"current_time":"2026-07-16 20:29:08.162901893 +0000 UTC m=+75512.317728942","heartbeat_counter":75512}]}
{"channel":"l2_data","timestamp":"2026-07-16T20:29:08.175028877Z","sequence_num":321,"events":[{"type":"update","product_id":"BTC-USD","updates":[{"side":"bid","event_time":"2026-07-16T20:29:08.136369Z","price_level":"64124.08","new_quantity":"0.654221"},{"side":"bid","event_time":"2026-07-16T20:29:08.136369Z","price_level":"64112","new_quantity":"1"}]}]}
{"channel":"l2_data","timestamp":"2026-07-16T20:29:08.229742114Z","sequence_num":322,"events":[{"type":"update","product_id":"BTC-USD","updates":[{"side":"bid","event_time":"2026-07-16T20:29:08.212881Z","price_level":"64124.08","new_quantity":"0"},{"side":"bid","event_time":"2026-07-16T20:29:08.212881Z","price_level":"56121.43","new_quantity":"0.01337205"},{"side":"offer","event_time":"2026-07-16T20:29:08.212881Z","price_level":"64180.95","new_quantity":"0.50701794"},{"side":"offer","event_time":"2026-07-16T20:29:08.212881Z","price_level":"64180.96","new_quantity":"0.4857518"},{"side":"offer","event_time":"2026-07-16T20:29:08.212881Z","price_level":"64180.97","new_quantity":"0"},{"side":"offer","event_time":"2026-07-16T20:29:08.212881Z","price_level":"64180.98","new_quantity":"0"}]}]}
{"channel":"l2_data","timestamp":"2026-07-16T20:29:08.27510643Z","sequence_num":323,"events":[{"type":"update","product_id":"BTC-USD","updates":[{"side":"bid","event_time":"2026-07-16T20:29:08.245765Z","price_level":"64112","new_quantity":"0"},{"side":"bid","event_time":"2026-07-16T20:29:08.245765Z","price_level":"63497.83","new_quantity":"0"}]}]}
{"channel":"l2_data","timestamp":"2026-07-16T20:29:08.331474334Z","sequence_num":324,"events":[{"type":"update","product_id":"BTC-USD","updates":[{"side":"bid","event_time":"2026-07-16T20:29:08.306503Z","price_level":"64113","new_quantity":"1.0000309"},{"side":"bid","event_time":"2026-07-16T20:29:08.306503Z","price_level":"56121.43","new_quantity":"0"},{"side":"offer","event_time":"2026-07-16T20:29:08.306503Z","price_level":"64138.78","new_quantity":"0.95777301"},{"side":"offer","event_time":"2026-07-16T20:29:08.306503Z","price_level":"64180.93","new_quantity":"0.50701803"},{"side":"offer","event_time":"2026-07-16T20:29:08.306503Z","price_level":"64180.94","new_quantity":"0.48575195"},{"side":"offer","event_time":"2026-07-16T20:29:08.306503Z","price_level":"64180.95","new_quantity":"0"},{"side":"offer","event_time":"2026-07-16T20:29:08.306503Z","price_level":"64180.96","new_quantity":"0"},{"side":"offer","event_time":"2026-07-16T20:29:08.306503Z","price_level":"65010.68","new_quantity":"0.00583"},{"side":"offer","event_time":"2026-07-16T20:29:08.306503Z","price_level":"65011.13","new_quantity":"0.00583"},{"side":"offer","event_time":"2026-07-16T20:29:08.306503Z","price_level":"65224.31","new_quantity":"0"}]}]}
{"channel":"l2_data","timestamp":"2026-07-16T20:29:08.380152165Z","sequence_num":325,"events":[{"type":"update","product_id":"BTC-USD","updates":[{"side":"bid","event_time":"2026-07-16T20:29:08.355285Z","price_level":"64114","new_quantity":"1"},{"side":"bid","event_time":"2026-07-16T20:29:08.355285Z","price_level":"64113","new_quantity":"0.0000309"},{"side":"offer","event_time":"2026-07-16T20:29:08.355285Z","price_level":"64162.06","new_quantity":"0"},{"side":"offer","event_time":"2026-07-16T20:29:08.355285Z","price_level":"65011.13","new_quantity":"0"},{"side":"offer","event_time":"2026-07-16T20:29:08.355285Z","price_level":"65225.74","new_quantity":"0.00583"}]}]}
{"channel":"l2_data","timestamp":"2026-07-16T20:29:08.510740423Z","sequence_num":326,"events":[{"type":"update","product_id":"BTC-USD","updates":[{"side":"bid","event_time":"2026-07-16T20:29:08.40123Z","price_level":"64131.66","new_quantity":"0.02"},{"side":"bid","event_time":"2026-07-16T20:29:08.40123Z","price_level":"64114","new_quantity":"0"},{"side":"bid","event_time":"2026-07-16T20:29:08.40123Z","price_level":"64112.07","new_quantity":"0"},{"side":"offer","event_time":"2026-07-16T20:29:08.40123Z","price_level":"64145.77","new_quantity":"0.431635"},{"side":"offer","event_time":"2026-07-16T20:29:08.40123Z","price_level":"64148.19","new_quantity":"0"},{"side":"offer","event_time":"2026-07-16T20:29:08.40123Z","price_level":"64149.32","new_quantity":"0.65493967"},{"side":"offer","event_time":"2026-07-16T20:29:08.40123Z","price_level":"64149.33","new_quantity":"0"},{"side":"offer","event_time":"2026-07-16T20:29:08.40123Z","price_level":"64180.92","new_quantity":"0.4857521"},{"side":"offer","event_time":"2026-07-16T20:29:08.40123Z","price_level":"64180.93","new_quantity":"0"},{"side":"offer","event_time":"2026-07-16T20:29:08.40123Z","price_level":"64180.94","new_quantity":"0"}]}]}
{"channel":"l2_data","timestamp":"2026-07-16T20:29:08.51385975Z","sequence_num":327,"events":[{"type":"update","product_id":"BTC-USD","updates":[{"side":"offer","event_time":"2026-07-16T20:29:08.410233Z","price_level":"64149.31","new_quantity":"0.75622673"},{"side":"offer","event_time":"2026-07-16T20:29:08.410233Z","price_level":"64180.91","new_quantity":"0.50701812"}]}]}
{"channel":"l2_data","timestamp":"2026-07-16T20:29:08.534403503Z","sequence_num":328,"events":[{"type":"update","product_id":"BTC-USD","updates":[{"side":"bid","event_time":"2026-07-16T20:29:08.497411Z","price_level":"64133.96","new_quantity":"0.00779618"},{"side":"bid","event_time":"2026-07-16T20:29:08.497411Z","price_level":"64132.36","new_quantity":"0.00779638"},{"side":"bid","event_time":"2026-07-16T20:29:08.497411Z","price_level":"64112","new_quantity":"1"},{"side":"bid","event_time":"2026-07-16T20:29:08.497411Z","price_level":"63495.85","new_quantity":"0.03937916"},{"side":"bid","event_time":"2026-07-16T20:29:08.497411Z","price_level":"56121.43","new_quantity":"0.01337205"},{"side":"offer","event_time":"2026-07-16T20:29:08.497411Z","price_level":"64149.98","new_quantity":"0.00896337"},{"side":"offer","event_time":"2026-07-16T20:29:08.497411Z","price_level":"64151.59","new_quantity":"0.00896314"},{"side":"offer","event_time":"2026-07-16T20:29:08.497411Z","price_level":"64161.57","new_quantity":"0.01"}]}]}
{"channel":"l2_data","timestamp":"2026-07-16T20:29:08.582128824Z","sequence_num":329,"events":[{"type":"update","product_id":"BTC-USD","updates":[{"side":"bid","event_time":"2026-07-16T20:29:08.561594Z","price_level":"64130.34","new_quantity":"0"},{"side":"bid","event_time":"2026-07-16T20:29:08.561594Z","price_level":"64112","new_quantity":"0"},{"side":"offer","event_time":"2026-07-16T20:29:08.561594Z","price_level":"64150.3","new_quantity":"0.00009743"},{"side":"offer","event_time":"2026-07-16T20:29:08.561594Z","price_level":"64151.58","new_quantity":"0.00779404"},{"side":"offer","event_time":"2026-07-16T20:29:08.561594Z","price_level":"64180.89","new_quantity":"0.50701821"},{"side":"offer","event_time":"2026-07-16T20:29:08.561594Z","price_level":"64180.9","new_quantity":"0.48575225"},{"side":"offer","event_time":"2026-07-16T20:29:08.561594Z","price_level":"64180.91","new_quantity":"0"},{"side":"offer","event_time":"2026-07-16T20:29:08.561594Z","price_level":"64180.92","new_quantity":"0"},{"side":"offer","event_time":"2026-07-16T20:29:08.561594Z","price_level":"65225.7","new_quantity":"0.00583"},{"side":"offer","event_time":"2026-07-16T20:29:08.561594Z","price_level":"65439.03","new_quantity":"0"}]}]}
{"channel":"l2_data","timestamp":"2026-07-16T20:29:08.632144815Z","sequence_num":330,"events":[{"type":"update","product_id":"BTC-USD","updates":[{"side":"bid","event_time":"2026-07-16T20:29:08.608503Z","price_level":"64132.74","new_quantity":"0"},{"side":"bid","event_time":"2026-07-16T20:29:08.608503Z","price_level":"64132.05","new_quantity":"0.12474261"},{"side":"bid","event_time":"2026-07-16T20:29:08.608503Z","price_level":"64130.35","new_quantity":"0"},{"side":"bid","event_time":"2026-07-16T20:29:08.608503Z","price_level":"64127.26","new_quantity":"0.04691558"},{"side":"bid","event_time":"2026-07-16T20:29:08.608503Z","price_level":"64127.25","new_quantity":"0"},{"side":"bid","event_time":"2026-07-16T20:29:08.608503Z","price_level":"64125.3","new_quantity":"0"},{"side":"bid","event_time":"2026-07-16T20:29:08.608503Z","price_level":"64125.2","new_quantity":"0.0077892"},{"side":"bid","event_time":"2026-07-16T20:29:08.608503Z","price_level":"64124.1","new_quantity":"0"},{"side":"bid","event_time":"2026-07-16T20:29:08.608503Z","price_level":"64123.77","new_quantity":"0"},{"side":"bid","event_time":"2026-07-16T20:29:08.608503Z","price_level":"64123.17","new_quantity":"0"},{"side":"bid","event_time":"2026-07-16T20:29:08.608503Z","price_level":"64119.33","new_quantity":"0"},{"side":"bid","event_time":"2026-07-16T20:29:08.608503Z","price_level":"64119.32","new_quantity":"0"},{"side":"bid","event_time":"2026-07-16T20:29:08.608503Z","price_level":"64117.58","new_quantity":"0.31190852"},{"side":"bid","event_time":"2026-07-16T20:29:08.608503Z","price_level":"64115.55","new_quantity":"0.3541012"},{"side":"bid","event_time":"2026-07-16T20:29:08.608503Z","price_level":"64115.34","new_quantity":"0"},{"side":"bid","event_time":"2026-07-16T20:29:08.608503Z","price_level":"64110.01","new_quantity":"0.63218109"},{"side":"bid","event_time":"2026-07-16T20:29:08.608503Z","price_level":"64110","new_quantity":"1.01"},{"side":"bid","event_time":"2026-07-16T20:29:08.608503Z","price_level":"64109.99","new_quantity":"0"},{"side":"bid","event_time":"2026-07-16T20:29:08.608503Z","price_level":"64109.43","new_quantity":"0"},{"side":"bid","event_time":"2026-07-16T20:29:08.608503Z","price_level":"64101.06","new_quantity":"0.31190852"},{"side":"bid","event_time":"2026-07-16T20:29:08.608503Z","price_level":"64099.01","new_quantity":"0.31190852"},{"side":"bid","event_time":"2026-07-16T20:29:08.608503Z","price_level":"64059.27","new_quantity":"0"},{"side":"bid","event_time":"2026-07-16T20:29:08.608503Z","price_level":"56121.43","new_quantity":"0"},{"side":"offer","event_time":"2026-07-16T20:29:08.608503Z","price_level":"64151.94","new_quantity":"0.00583"},{"side":"offer","event_time":"2026-07-16T20:29:08.608503Z","price_level":"64155.99","new_quantity":"0.51279227"},{"side":"offer","event_time":"2026-07-16T20:29:08.608503Z","price_level":"64156","new_quantity":"0"},{"side":"offer","event_time":"2026-07-16T20:29:08.608503Z","price_level":"64366.63","new_quantity":"0.00583"},{"side":"offer","event_time":"2026-07-16T20:29:08.608503Z","price_level":"64366.88","new_quantity":"0"},{"side":"offer","event_time":"2026-07-16T20:29:08.608503Z","price_level":"65225.74","new_quantity":"0"}]}]}
{"channel":"l2_data","timestamp":"2026-07-16T20:29:08.680908112Z","sequence_num":331,"events":[{"type":"update","product_id":"BTC-USD","updates":[{"side":"bid","event_time":"2026-07-16T20:29:08.645058Z","price_level":"64138.77","new_quantity":"0.00421282"},{"side":"bid","event_time":"2026-07-16T20:29:08.645058Z","price_level":"64123.89","new_quantity":"0.31190852"},{"side":"bid","event_time":"2026-07-16T20:29:08.645058Z","price_level":"64122.61","new_quantity":"0.31508102"},{"side":"bid","event_time":"2026-07-16T20:29:08.645058Z","price_level":"64121.84","new_quantity":"0.31193191"},{"side":"bid","event_time":"2026-07-16T20:29:08.645058Z","price_level":"64119.53","new_quantity":"0.31190852"},{"side":"bid","event_time":"2026-07-16T20:29:08.645058Z","price_level":"64117.59","new_quantity":"0.18620939"},{"side":"bid","event_time":"2026-07-16T20:29:08.645058Z","price_level":"64098.15","new_quantity":"0.00333225"},{"side":"bid","event_time":"2026-07-16T20:29:08.645058Z","price_level":"64046.95","new_quantity":"0.00833061"},{"side":"offer","event_time":"2026-07-16T20:29:08.645058Z","price_level":"64152.16","new_quantity":"0"},{"side":"offer","event_time":"2026-07-16T20:29:08.645058Z","price_level":"64155.99","new_quantity":"1.04423279"},{"side":"offer","event_time":"2026-07-16T20:29:08.645058Z","price_level":"64156","new_quantity":"1"},{"side":"offer","event_time":"2026-07-16T20:29:08.645058Z","price_level":"64581.15","new_quantity":"0.00583"}]}]}
{"channel":"l2_data","timestamp":"2026-07-16T20:29:08.731849932Z","sequence_num":332,"events":[{"type":"update","product_id":"BTC-USD","updates":[{"side":"bid","event_time":"2026-07-16T20:29:08.683389Z","price_level":"64130.36","new_quantity":"0"},{"side":"bid","event_time":"2026-07-16T20:29:08.683389Z","price_level":"64130.33","new_quantity":"0.02"},{"side":"bid","event_time":"2026-07-16T20:29:08.683389Z","price_level":"64125.96","new_quantity":"0.31190852"},{"side":"bid","event_time":"2026-07-16T20:29:08.683389Z","price_level":"64099.01","new_quantity":"0"},{"side":"bid","event_time":"2026-07-16T20:29:08.683389Z","price_level":"64095.01","new_quantity":"0.00077951"},{"side":"bid","event_time":"2026-07-16T20:29:08.683389Z","price_level":"64094.92","new_quantity":"0"},{"side":"offer","event_time":"2026-07-16T20:29:08.683389Z","price_level":"64180.87","new_quantity":"0.5070183"},{"side":"offer","event_time":"2026-07-16T20:29:08.683389Z","price_level":"64180.88","new_quantity":"0.4857524"},{"side":"offer","event_time":"2026-07-16T20:29:08.683389Z","price_level":"64180.89","new_quantity":"0"},{"side":"offer","event_time":"2026-07-16T20:29:08.683389Z","price_level":"64180.9","new_quantity":"0"}]}]}
{"channel":"l2_data","timestamp":"2026-07-16T20:29:08.779476807Z","sequence_num":333,"events":[{"type":"update","product_id":"BTC-USD","updates":[{"side":"bid","event_time":"2026-07-16T20:29:08.758124Z","price_level":"64138.77","new_quantity":"0.00421241"},{"side":"bid","event_time":"2026-07-16T20:29:08.758124Z","price_level":"64138","new_quantity":"0.0041607"},{"side":"bid","event_time":"2026-07-16T20:29:08.758124Z","price_level":"64130.34","new_quantity":"0.31190852"},{"side":"bid","event_time":"2026-07-16T20:29:08.758124Z","price_level":"64127.95","new_quantity":"0.31190852"},{"side":"bid","event_time":"2026-07-16T20:29:08.758124Z","price_level":"64121.85","new_quantity":"0.23359045"},{"side":"bid","event_time":"2026-07-16T20:29:08.758124Z","price_level":"64110","new_quantity":"0.01"},{"side":"bid","event_time":"2026-07-16T20:29:08.758124Z","price_level":"64104.91","new_quantity":"0"},{"side":"bid","event_time":"2026-07-16T20:29:08.758124Z","price_level":"64101.06","new_quantity":"0"},{"side":"offer","event_time":"2026-07-16T20:29:08.758124Z","price_level":"64155.99","new_quantity":"0.51279227"},{"side":"offer","event_time":"2026-07-16T20:29:08.758124Z","price_level":"64156","new_quantity":"0"},{"side":"offer","event_time":"2026-07-16T20:29:08.758124Z","price_level":"64180.86","new_quantity":"0.48575255"},{"side":"offer","event_time":"2026-07-16T20:29:08.758124Z","price_level":"64180.88","new_quantity":"0"}]}]}
{"channel":"l2_data","timestamp":"2026-07-16T20:29:08.831461752Z","sequence_num":334,"events":[{"type":"update","product_id":"BTC-USD","updates":[{"side":"bid","event_time":"2026-07-16T20:29:08.792497Z","price_level":"64132.75","new_quantity":"0"},{"side":"bid","event_time":"2026-07-16T20:29:08.792497Z","price_level":"64132.06","new_quantity":"0.02"},{"side":"bid","event_time":"2026-07-16T20:29:08.792497Z","price_level":"64130.33","new_quantity":"0"},{"side":"bid","event_time":"2026-07-16T20:29:08.792497Z","price_level":"64112","new_quantity":"1"},{"side":"bid","event_time":"2026-07-16T20:29:08.792497Z","price_level":"56121.43","new_quantity":"0.01337205"},{"side":"offer","event_time":"2026-07-16T20:29:08.792497Z","price_level":"64152.29","new_quantity":"1.1450467"},{"side":"offer","event_time":"2026-07-16T20:29:08.792497Z","price_level":"64155","new_quantity":"1.01"},{"side":"offer","event_time":"2026-07-16T20:29:08.792497Z","price_level":"64180.85","new_quantity":"0.50701839"},{"side":"offer","event_time":"2026-07-16T20:29:08.792497Z","price_level":"64180.87","new_quantity":"0"},{"side":"offer","event_time":"2026-07-16T20:29:08.792497Z","price_level":"64366.53","new_quantity":"0.00583"},{"side":"offer","event_time":"2026-07-16T20:29:08.792497Z","price_level":"64581.34","new_quantity":"0"},{"side":"offer","event_time":"2026-07-16T20:29:08.792497Z","price_level":"64780","new_quantity":"1.8"},{"side":"offer","event_time":"2026-07-16T20:29:08.792497Z","price_level":"65653.11","new_quantity":"0.00583"}]}]}
{"channel":"l2_data","timestamp":"2026-07-16T20:29:08.876659801Z","sequence_num":335,"events":[{"type":"update","product_id":"BTC-USD","updates":[{"side":"offer","event_time":"2026-07-16T20:29:08.858538Z","price_level":"64161.57","new_quantity":"0"}]}]}
{"channel":"l2_data","timestamp":"2026-07-16T20:29:08.930474566Z","sequence_num":336,"events":[{"type":"update","product_id":"BTC-USD","updates":[{"side":"bid","event_time":"2026-07-16T20:29:08.902279Z","price_level":"64138.77","new_quantity":"0.00421238"},{"side":"bid","event_time":"2026-07-16T20:29:08.902279Z","price_level":"64124.09","new_quantity":"0"},{"side":"bid","event_time":"2026-07-16T20:29:08.902279Z","price_level":"56121.43","new_quantity":"0"},{"side":"offer","event_time":"2026-07-16T20:29:08.902279Z","price_level":"64180.83","new_quantity":"0.50701848"},{"side":"offer","event_time":"2026-07-16T20:29:08.902279Z","price_level":"64180.84","new_quantity":"0.4857527"},{"side":"offer","event_time":"2026-07-16T20:29:08.902279Z","price_level":"64180.85","new_quantity":"0"},{"side":"offer","event_time":"2026-07-16T20:29:08.902279Z","price_level":"64180.86","new_quantity":"0"},{"side":"offer","event_time":"2026-07-16T20:29:08.902279Z","price_level":"64366.52","new_quantity":"0.00583"},{"side":"offer","event_time":"2026-07-16T20:29:08.902279Z","price_level":"64366.63","new_quantity":"0"},{"side":"offer","event_time":"2026-07-16T20:29:08.902279Z","price_level":"65653.11","new_quantity":"0"}]}]}
{"channel":"heartbeats","timestamp":"2026-07-16T20:29:09.165550541Z","sequence_num":337,"events":[{"current_time":"2026-07-16 20:29:09.162888867 +0000 UTC m=+75513.317715925","heartbeat_counter":75513}]}
{"channel":"l2_data","timestamp":"2026-07-16T20:29:09.245816163Z","sequence_num":338,"events":[{"type":"update","product_id":"BTC-USD","updates":[{"side":"bid","event_time":"2026-07-16T20:29:08.913297Z","price_level":"64138","new_quantity":"0"}]}]}
{"channel":"l2_data","timestamp":"2026-07-16T20:29:09.246196937Z","sequence_num":339,"events":[{"type":"update","product_id":"BTC-USD","updates":[{"side":"bid","event_time":"2026-07-16T20:29:08.99401Z","price_level":"64130.35","new_quantity":"0.02"},{"side":"offer","event_time":"2026-07-16T20:29:08.99401Z","price_level":"64152.29","new_quantity":"0.57081098"},{"side":"offer","event_time":"2026-07-16T20:29:08.99401Z","price_level":"64155","new_quantity":"0.01"},{"side":"offer","event_time":"2026-07-16T20:29:08.99401Z","price_level":"64180.81","new_quantity":"0.50701857"},{"side":"offer","event_time":"2026-07-16T20:29:08.99401Z","price_level":"64180.82","new_quantity":"0.48575286"},{"side":"offer","event_time":"2026-07-16T20:29:08.99401Z","price_level":"64180.83","new_quantity":"0"},{"side":"offer","event_time":"2026-07-16T20:29:08.99401Z","price_level":"64180.84","new_quantity":"0"}]}]}
{"channel":"l2_data","timestamp":"2026-07-16T20:29:09.246877699Z","sequence_num":340,"events":[{"type":"update","product_id":"BTC-USD","updates":[{"side":"bid","event_time":"2026-07-16T20:29:09.038003Z","price_level":"64133.96","new_quantity":"0"},{"side":"bid","event_time":"2026-07-16T20:29:09.038003Z","price_level":"64132.36","new_quantity":"0"},{"side":"offer","event_time":"2026-07-16T20:29:09.038003Z","price_level":"64149.11","new_quantity":"0"},{"side":"offer","event_time":"2026-07-16T20:29:09.038003Z","price_level":"64149.12","new_quantity":"0"},{"side":"offer","event_time":"2026-07-16T20:29:09.038003Z","price_level":"64149.18","new_quantity":"0.0077892"},{"side":"offer","event_time":"2026-07-16T20:29:09.038003Z","price_level":"64149.98","new_quantity":"0"},{"side":"offer","event_time":"2026-07-16T20:29:09.038003Z","price_level":"64150.08","new_quantity":"0"},{"side":"offer","event_time":"2026-07-16T20:29:09.038003Z","price_level":"64151.59","new_quantity":"0"},{"side":"offer","event_time":"2026-07-16T20:29:09.038003Z","price_level":"64155.99","new_quantity":"1.04423279"},{"side":"offer","event_time":"2026-07-16T20:29:09.038003Z","price_level":"64156","new_quantity":"1"},{"side":"offer","event_time":"2026-07-16T20:29:09.038003Z","price_level":"64161.55","new_quantity":"0.00826346"}]}]}
{"channel":"l2_data","timestamp":"2026-07-16T20:29:09.248023181Z","sequence_num":341,"events":[{"type":"update","product_id":"BTC-USD","updates":[{"side":"bid","event_time":"2026-07-16T20:29:09.106292Z","price_level":"64124.11","new_quantity":"0.714049"},{"side":"bid","event_time":"2026-07-16T20:29:09.106292Z","price_level":"56121.43","new_quantity":"0.01337205"},{"side":"offer","event_time":"2026-07-16T20:29:09.106292Z","price_level":"64180.79","new_quantity":"0.50701866"},{"side":"offer","event_time":"2026-07-16T20:29:09.106292Z","price_level":"64180.8","new_quantity":"0.48575301"},{"side":"offer","event_time":"2026-07-16T20:29:09.106292Z","price_level":"64180.81","new_quantity":"0"},{"side":"offer","event_time":"2026-07-16T20:29:09.106292Z","price_level":"64180.82","new_quantity":"0"}]}]}
{"channel":"l2_data","timestamp":"2026-07-16T20:29:09.248369985Z","sequence_num":342,"events":[{"type":"update","product_id":"BTC-USD","updates":[{"side":"bid","event_time":"2026-07-16T20:29:09.159311Z","price_level":"64124.11","new_quantity":"0"},{"side":"offer","event_time":"2026-07-16T20:29:09.159311Z","price_level":"64138.78","new_quantity":"1.01027978"},{"side":"offer","event_time":"2026-07-16T20:29:09.159311Z","price_level":"64148.82","new_quantity":"0.0077892"},{"side":"offer","event_time":"2026-07-16T20:29:09.159311Z","price_level":"64148.83","new_quantity":"0.00009743"},{"side":"offer","event_time":"2026-07-16T20:29:09.159311Z","price_level":"64149.18","new_quantity":"0"},{"side":"offer","event_time":"2026-07-16T20:29:09.159311Z","price_level":"64149.79","new_quantity":"0.00779426"},{"side":"offer","event_time":"2026-07-16T20:29:09.159311Z","price_level":"64155.99","new_quantity":"0.51279227"},{"side":"offer","event_time":"2026-07-16T20:29:09.159311Z","price_level":"64156","new_quantity":"0"},{"side":"offer","event_time":"2026-07-16T20:29:09.159311Z","price_level":"64161.55","new_quantity":"0"},{"side":"offer","event_time":"2026-07-16T20:29:09.159311Z","price_level":"64366.45","new_quantity":"0.00583"},{"side":"offer","event_time":"2026-07-16T20:29:09.159311Z","price_level":"64366.47","new_quantity":"0.00583"},{"side":"offer","event_time":"2026-07-16T20:29:09.159311Z","price_level":"64366.52","new_quantity":"0"},{"side":"offer","event_time":"2026-07-16T20:29:09.159311Z","price_level":"64366.53","new_quantity":"0"},{"side":"offer","event_time":"2026-07-16T20:29:09.159311Z","price_level":"65010.57","new_quantity":"0.00583"},{"side":"offer","event_time":"2026-07-16T20:29:09.159311Z","price_level":"65010.68","new_quantity":"0"},{"side":"offer","event_time":"2026-07-16T20:29:09.159311Z","price_level":"65225.7","new_quantity":"0"}]}]}
{"channel":"l2_data","timestamp":"2026-07-16T20:29:09.24920891Z","sequence_num":343,"events":[{"type":"update","product_id":"BTC-USD","updates":[{"side":"bid","event_time":"2026-07-16T20:29:09.199157Z","price_level":"56121.43","new_quantity":"0"},{"side":"offer","event_time":"2026-07-16T20:29:09.199157Z","price_level":"64152.29","new_quantity":"1.1450467"},{"side":"offer","event_time":"2026-07-16T20:29:09.199157Z","price_level":"64155","new_quantity":"1.01"}]}]}
{"channel":"l2_data","timestamp":"2026-07-16T20:29:09.330786417Z","sequence_num":344,"events":[{"type":"update","product_id":"BTC-USD","updates":[{"side":"bid","event_time":"2026-07-16T20:29:09.295881Z","price_level":"64138.77","new_quantity":"0.00414925"},{"side":"offer","event_time":"2026-07-16T20:29:09.295881Z","price_level":"64180.78","new_quantity":"0.48575316"},{"side":"offer","event_time":"2026-07-16T20:29:09.295881Z","price_level":"64180.79","new_quantity":"0"},{"side":"offer","event_time":"2026-07-16T20:29:09.295881Z","price_level":"64180.8","new_quantity":"0"},{"side":"offer","event_time":"2026-07-16T20:29:09.295881Z","price_level":"64366.47","new_quantity":"0"},{"side":"offer","event_time":"2026-07-16T20:29:09.295881Z","price_level":"64580.97","new_quantity":"0.00583"},{"side":"offer","event_time":"2026-07-16T20:29:09.295881Z","price_level":"64581.01","new_quantity":"0.00583"},{"side":"offer","event_time":"2026-07-16T20:29:09.295881Z","price_level":"64581.15","new_quantity":"0"}]}]}
{"channel":"l2_data","timestamp":"2026-07-16T20:29:09.380718976Z","sequence_num":345,"events":[{"type":"update","product_id":"BTC-USD","updates":[{"side":"bid","event_time":"2026-07-16T20:29:09.355246Z","price_level":"64124.11","new_quantity":"0"},{"side":"offer","event_time":"2026-07-16T20:29:09.355246Z","price_level":"64161.57","new_quantity":"0.01"}]}]}
{"channel":"l2_data","timestamp":"2026-07-16T20:29:09.425446672Z","sequence_num":346,"events":[{"type":"update","product_id":"BTC-USD","updates":[{"side":"bid","event_time":"2026-07-16T20:29:09.391855Z","price_level":"64138","new_quantity":"0.00479324"},{"side":"bid","event_time":"2026-07-16T20:29:09.391855Z","price_level":"56121.43","new_quantity":"0.01337205"}]}]}
{"channel":"l2_data","timestamp":"2026-07-16T20:29:09.476945317Z","sequence_num":347,"events":[{"type":"update","product_id":"BTC-USD","updates":[{"side":"offer","event_time":"2026-07-16T20:29:09.457473Z","price_level":"64161.57","new_quantity":"0"}]}]}
{"channel":"l2_data","timestamp":"2026-07-16T20:29:09.530691616Z","sequence_num":348,"events":[{"type":"update","product_id":"BTC-USD","updates":[{"side":"bid","event_time":"2026-07-16T20:29:09.491774Z","price_level":"64132.36","new_quantity":"0.00779638"},{"side":"bid","event_time":"2026-07-16T20:29:09.491774Z","price_level":"64112","new_quantity":"0"},{"side":"bid","event_time":"2026-07-16T20:29:09.491774Z","price_level":"56121.43","new_quantity":"0"},{"side":"offer","event_time":"2026-07-16T20:29:09.491774Z","price_level":"64151.3","new_quantity":"0.00896318"}]}]}
{"channel":"l2_data","timestamp":"2026-07-16T20:29:09.581653959Z","sequence_num":349,"events":[{"type":"update","product_id":"BTC-USD","updates":[{"side":"bid","event_time":"2026-07-16T20:29:09.541034Z","price_level":"64138","new_quantity":"0"},{"side":"bid","event_time":"2026-07-16T20:29:09.541034Z","price_level":"64133.96","new_quantity":"0.00779618"},{"side":"bid","event_time":"2026-07-16T20:29:09.541034Z","price_level":"64125.52","new_quantity":"0"},{"side":"bid","event_time":"2026-07-16T20:29:09.541034Z","price_level":"64108","new_quantity":"1"},{"side":"offer","event_time":"2026-07-16T20:29:09.541034Z","price_level":"64149.7","new_quantity":"0.00896341"}]}]}
{"channel":"l2_data","timestamp":"2026-07-16T20:29:09.650050761Z","sequence_num":350,"events":[{"type":"update","product_id":"BTC-USD","updates":[{"side":"bid","event_time":"2026-07-16T20:29:09.596258Z","price_level":"64124.19","new_quantity":"0.61885"},{"side":"offer","event_time":"2026-07-16T20:29:09.596258Z","price_level":"64150.3","new_quantity":"0"},{"side":"offer","event_time":"2026-07-16T20:29:09.596258Z","price_level":"64151.58","new_quantity":"0"}]}]}
{"channel":"l2_data","timestamp":"2026-07-16T20:29:09.691829414Z","sequence_num":351,"events":[{"type":"update","product_id":"BTC-USD","updates":[{"side":"bid","event_time":"2026-07-16T20:29:09.651442Z","price_level":"64124.19","new_quantity":"0"},{"side":"bid","event_time":"2026-07-16T20:29:09.651442Z","price_level":"64110","new_quantity":"1.01"},{"side":"bid","event_time":"2026-07-16T20:29:09.651442Z","price_level":"64108","new_quantity":"0"},{"side":"offer","event_time":"2026-07-16T20:29:09.651442Z","price_level":"64150.01","new_quantity":"0.00009743"},{"side":"offer","event_time":"2026-07-16T20:29:09.651442Z","price_level":"64151.3","new_quantity":"0.01675725"},{"side":"offer","event_time":"2026-07-16T20:29:09.651442Z","price_level":"64161.55","new_quantity":"0.00826346"}]}]}
{"channel":"l2_data","timestamp":"2026-07-16T20:29:09.740731591Z","sequence_num":352,"events":[{"type":"update","product_id":"BTC-USD","updates":[{"side":"bid","event_time":"2026-07-16T20:29:09.705475Z","price_level":"64132.74","new_quantity":"0.04691558"},{"side":"bid","event_time":"2026-07-16T20:29:09.705475Z","price_level":"64132.73","new_quantity":"0.12474129"},{"side":"bid","event_time":"2026-07-16T20:29:09.705475Z","price_level":"64132.05","new_quantity":"0"},{"side":"bid","event_time":"2026-07-16T20:29:09.705475Z","price_level":"64125.52","new_quantity":"0.06"},{"side":"bid","event_time":"2026-07-16T20:29:09.705475Z","price_level":"64125.08","new_quantity":"0"},{"side":"bid","event_time":"2026-07-16T20:29:09.705475Z","price_level":"64122.61","new_quantity":"0.46792065"},{"side":"bid","event_time":"2026-07-16T20:29:09.705475Z","price_level":"64121.88","new_quantity":"0.07406"},{"side":"bid","event_time":"2026-07-16T20:29:09.705475Z","price_level":"56121.43","new_quantity":"0.01337205"},{"side":"offer","event_time":"2026-07-16T20:29:09.705475Z","price_level":"64152.29","new_quantity":"0.57081098"},{"side":"offer","event_time":"2026-07-16T20:29:09.705475Z","price_level":"64155","new_quantity":"0.01"},{"side":"offer","event_time":"2026-07-16T20:29:09.705475Z","price_level":"64366.42","new_quantity":"0.00583"},{"side":"offer","event_time":"2026-07-16T20:29:09.705475Z","price_level":"64581.01","new_quantity":"0"},{"side":"offer","event_time":"2026-07-16T20:29:09.705475Z","price_level":"65438.57","new_quantity":"0.00583"}]}]}
{"channel":"l2_data","timestamp":"2026-07-16T20:29:09.794762794Z","sequence_num":353,"events":[{"type":"update","product_id":"BTC-USD","updates":[{"side":"bid","event_time":"2026-07-16T20:29:09.755988Z","price_level":"64138.77","new_quantity":"0.00414908"},{"side":"bid","event_time":"2026-07-16T20:29:09.755988Z","price_level":"64132.74","new_quantity":"0.06691558"},{"side":"bid","event_time":"2026-07-16T20:29:09.755988Z","price_level":"64132.06","new_quantity":"0"},{"side":"bid","event_time":"2026-07-16T20:29:09.755988Z","price_level":"64110","new_quantity":"0.01"},{"side":"offer","event_time":"2026-07-16T20:29:09.755988Z","price_level":"64151.93","new_quantity":"0.00583"},{"side":"offer","event_time":"2026-07-16T20:29:09.755988Z","price_level":"64156","new_quantity":"1"},{"side":"offer","event_time":"2026-07-16T20:29:09.755988Z","price_level":"64161.55","new_quantity":"0"},{"side":"offer","event_time":"2026-07-16T20:29:09.755988Z","price_level":"64366.45","new_quantity":"0"},{"side":"offer","event_time":"2026-07-16T20:29:09.755988Z","price_level":"64780","new_quantity":"0.3"},{"side":"offer","event_time":"2026-07-16T20:29:09.755988Z","price_level":"65438.51","new_quantity":"0.00583"},{"side":"offer","event_time":"2026-07-16T20:29:09.755988Z","price_level":"65438.57","new_quantity":"0"}]}]}
{"channel":"l2_data","timestamp":"2026-07-16T20:29:09.844572829Z","sequence_num":354,"events":[{"type":"update","product_id":"BTC-USD","updates":[{"side":"bid","event_time":"2026-07-16T20:29:09.807584Z","price_level":"64138.77","new_quantity":"0.00414888"},{"side":"bid","event_time":"2026-07-16T20:29:09.807584Z","price_level":"64111","new_quantity":"1"},{"side":"bid","event_time":"2026-07-16T20:29:09.807584Z","price_level":"56121.43","new_quantity":"0"},{"side":"offer","event_time":"2026-07-16T20:29:09.807584Z","price_level":"64291.31","new_quantity":"0"},{"side":"offer","event_time":"2026-07-16T20:29:09.807584Z","price_level":"64780","new_quantity":"1.8"}]}]}
{"channel":"l2_data","timestamp":"2026-07-16T20:29:09.881144532Z","sequence_num":355,"events":[{"type":"update","product_id":"BTC-USD","updates":[{"side":"bid","event_time":"2026-07-16T20:29:09.858547Z","price_level":"64124.37","new_quantity":"0.617024"},{"side":"bid","event_time":"2026-07-16T20:29:09.858547Z","price_level":"64111","new_quantity":"0"},{"side":"bid","event_time":"2026-07-16T20:29:09.858547Z","price_level":"63988.76","new_quantity":"0"}]}]}
{"channel":"l2_data","timestamp":"2026-07-16T20:29:09.945727818Z","sequence_num":356,"events":[{"type":"update","product_id":"BTC-USD","updates":[{"side":"bid","event_time":"2026-07-16T20:29:09.909366Z","price_level":"64132.75","new_quantity":"0.02"},{"side":"bid","event_time":"2026-07-16T20:29:09.909366Z","price_level":"64124.37","new_quantity":"0"},{"side":"bid","event_time":"2026-07-16T20:29:09.909366Z","price_level":"64112","new_quantity":"1"},{"side":"offer","event_time":"2026-07-16T20:29:09.909366Z","price_level":"64161.57","new_quantity":"0.01"}]}]}
{"channel":"l2_data","timestamp":"2026-07-16T20:29:09.99539162Z","sequence_num":357,"events":[{"type":"update","product_id":"BTC-USD","updates":[{"side":"bid","event_time":"2026-07-16T20:29:09.957754Z","price_level":"64138","new_quantity":"0.00382428"}]}]}
{"channel":"l2_data","timestamp":"2026-07-16T20:29:10.055278879Z","sequence_num":358,"events":[{"type":"update","product_id":"BTC-USD","updates":[{"side":"bid","event_time":"2026-07-16T20:29:09.999836Z","price_level":"64138.77","new_quantity":"0.00414872"},{"side":"bid","event_time":"2026-07-16T20:29:09.999836Z","price_level":"64132.74","new_quantity":"0.04691558"},{"side":"bid","event_time":"2026-07-16T20:29:09.999836Z","price_level":"64132.73","new_quantity":"0"},{"side":"bid","event_time":"2026-07-16T20:29:09.999836Z","price_level":"64131.66","new_quantity":"0"},{"side":"bid","event_time":"2026-07-16T20:29:09.999836Z","price_level":"64128.1","new_quantity":"0.15593786"},{"side":"bid","event_time":"2026-07-16T20:29:09.999836Z","price_level":"64125.52","new_quantity":"0"},{"side":"bid","event_time":"2026-07-16T20:29:09.999836Z","price_level":"64112","new_quantity":"0"},{"side":"bid","event_time":"2026-07-16T20:29:09.999836Z","price_level":"63983.27","new_quantity":"3.01570621"},{"side":"bid","event_time":"2026-07-16T20:29:09.999836Z","price_level":"56121.43","new_quantity":"0.01337205"},{"side":"offer","event_time":"2026-07-16T20:29:09.999836Z","price_level":"64138.78","new_quantity":"1.04099978"},{"side":"offer","event_time":"2026-07-16T20:29:09.999836Z","price_level":"64151.51","new_quantity":"0.00583"},{"side":"offer","event_time":"2026-07-16T20:29:09.999836Z","price_level":"64151.53","new_quantity":"0.00583"},{"side":"offer","event_time":"2026-07-16T20:29:09.999836Z","price_level":"64151.82","new_quantity":"0"},{"side":"offer","event_time":"2026-07-16T20:29:09.999836Z","price_level":"64151.93","new_quantity":"0"},{"side":"offer","event_time":"2026-07-16T20:29:09.999836Z","price_level":"64151.94","new_quantity":"0"},{"side":"offer","event_time":"2026-07-16T20:29:09.999836Z","price_level":"64153.06","new_quantity":"0"},{"side":"offer","event_time":"2026-07-16T20:29:09.999836Z","price_level":"64284.41","new_quantity":"2.2369426"},{"side":"offer","event_time":"2026-07-16T20:29:09.999836Z","price_level":"64366.4","new_quantity":"0.00583"},{"side":"offer","event_time":"2026-07-16T20:29:09.999836Z","price_level":"64366.42","new_quantity":"0"},{"side":"offer","event_time":"2026-07-16T20:29:09.999836Z","price_level":"64780","new_quantity":"0.3"},{"side":"offer","event_time":"2026-07-16T20:29:09.999836Z","price_level":"64795.68","new_quantity":"0.00583"},{"side":"offer","event_time":"2026-07-16T20:29:09.999836Z","price_level":"64795.78","new_quantity":"0"},{"side":"offer","event_time":"2026-07-16T20:29:09.999836Z","price_level":"65438.09","new_quantity":"0.00583"},{"side":"offer","event_time":"2026-07-16T20:29:09.999836Z","price_level":"65438.4","new_quantity":"0"},{"side":"offer","event_time":"2026-07-16T20:29:09.999836Z","price_level":"65438.51","new_quantity":"0"}]}]}
{"channel":"heartbeats","timestamp":"2026-07-16T20:29:10.165093476Z","sequence_num":359,"events":[{"current_time":"2026-07-16 20:29:10.162896366 +0000 UTC m=+75514.317723410","heartbeat_counter":75514}]}
{"channel":"l2_data","timestamp":"2026-07-16T20:29:10.378281839Z","sequence_num":360,"events":[{"type":"update","product_id":"BTC-USD","updates":[{"side":"bid","event_time":"2026-07-16T20:29:10.045347Z","price_level":"64138.77","new_quantity":"0.00309758"},{"side":"bid","event_time":"2026-07-16T20:29:10.045347Z","price_level":"64132.36","new_quantity":"0"},{"side":"bid","event_time":"2026-07-16T20:29:10.045347Z","price_level":"64129.17","new_quantity":"0"},{"side":"bid","event_time":"2026-07-16T20:29:10.045347Z","price_level":"64128.58","new_quantity":"0.01559176"},{"side":"bid","event_time":"2026-07-16T20:29:10.045347Z","price_level":"64121.88","new_quantity":"0"},{"side":"bid","event_time":"2026-07-16T20:29:10.045347Z","price_level":"64118.68","new_quantity":"0.07411"},{"side":"bid","event_time":"2026-07-16T20:29:10.045347Z","price_level":"64108","new_quantity":"1"},{"side":"offer","event_time":"2026-07-16T20:29:10.045347Z","price_level":"64138.78","new_quantity":"1.04099978"},{"side":"offer","event_time":"2026-07-16T20:29:10.045347Z","price_level":"64148.82","new_quantity":"0"},{"side":"offer","event_time":"2026-07-16T20:29:10.045347Z","price_level":"64148.83","new_quantity":"0"},{"side":"offer","event_time":"2026-07-16T20:29:10.045347Z","price_level":"64149.18","new_quantity":"0.0077892"},{"side":"offer","event_time":"2026-07-16T20:29:10.045347Z","price_level":"64149.79","new_quantity":"0"},{"side":"offer","event_time":"2026-07-16T20:29:10.045347Z","price_level":"64151.3","new_quantity":"0.00779407"},{"side":"offer","event_time":"2026-07-16T20:29:10.045347Z","price_level":"64151.39","new_quantity":"0.00583"},{"side":"offer","event_time":"2026-07-16T20:29:10.045347Z","price_level":"64151.51","new_quantity":"0"},{"side":"offer","event_time":"2026-07-16T20:29:10.045347Z","price_level":"64151.53","new_quantity":"0"},{"side":"offer","event_time":"2026-07-16T20:29:10.045347Z","price_level":"64155.99","new_quantity":"0.51279227"},{"side":"offer","event_time":"2026-07-16T20:29:10.045347Z","price_level":"64156","new_quantity":"0"},{"side":"offer","event_time":"2026-07-16T20:29:10.045347Z","price_level":"64365.95","new_quantity":"0.00583"},{"side":"offer","event_time":"2026-07-16T20:29:10.045347Z","price_level":"64365.96","new_quantity":"0.00583"},{"side":"offer","event_time":"2026-07-16T20:29:10.045347Z","price_level":"64366.4","new_quantity":"0"},{"side":"offer","event_time":"2026-07-16T20:29:10.045347Z","price_level":"64580.69","new_quantity":"0.00583"},{"side":"offer","event_time":"2026-07-16T20:29:10.045347Z","price_level":"64580.97","new_quantity":"0"},{"side":"offer","event_time":"2026-07-16T20:29:10.045347Z","price_level":"64795.29","new_quantity":"0.00583"},{"side":"offer","event_time":"2026-07-16T20:29:10.045347Z","price_level":"64795.68","new_quantity":"0"},{"side":"offer","event_time":"2026-07-16T20:29:10.045347Z","price_level":"65010.57","new_quantity":"0"},{"side":"offer","event_time":"2026-07-16T20:29:10.045347Z","price_level":"65223.67","new_quantity":"0.00583"},{"side":"offer","event_time":"2026-07-16T20:29:10.045347Z","price_level":"65438.09","new_quantity":"0"},{"side":"offer","event_time":"2026-07-16T20:29:10.045347Z","price_level":"65438.1","new_quantity":"0.00583"}]}]}
{"channel":"l2_data","timestamp":"2026-07-16T20:29:10.380889766Z","sequence_num":361,"events":[{"type":"update","product_id":"BTC-USD","updates":[{"side":"offer","event_time":"2026-07-16T20:29:10.064988Z","price_level":"64152.29","new_quantity":"1.10397817"},{"side":"offer","event_time":"2026-07-16T20:29:10.064988Z","price_level":"64155","new_quantity":"1.01"},{"side":"offer","event_time":"2026-07-16T20:29:10.064988Z","price_level":"64780","new_quantity":"1.8"}]}]}
{"channel":"l2_data","timestamp":"2026-07-16T20:29:10.381677349Z","sequence_num":362,"events":[{"type":"update","product_id":"BTC-USD","updates":[{"side":"bid","event_time":"2026-07-16T20:29:10.155747Z","price_level":"64138","new_quantity":"0"},{"side":"bid","event_time":"2026-07-16T20:29:10.155747Z","price_level":"64128.59","new_quantity":"0.01559176"},{"side":"bid","event_time":"2026-07-16T20:29:10.155747Z","price_level":"64128.58","new_quantity":"0"},{"side":"bid","event_time":"2026-07-16T20:29:10.155747Z","price_level":"64124.62","new_quantity":"0.02"},{"side":"bid","event_time":"2026-07-16T20:29:10.155747Z","price_level":"64121.66","new_quantity":"0.00077955"},{"side":"bid","event_time":"2026-07-16T20:29:10.155747Z","price_level":"64121.32","new_quantity":"0.04"},{"side":"bid","event_time":"2026-07-16T20:29:10.155747Z","price_level":"64108","new_quantity":"0"},{"side":"bid","event_time":"2026-07-16T20:29:10.155747Z","price_level":"56121.43","new_quantity":"0"},{"side":"offer","event_time":"2026-07-16T20:29:10.155747Z","price_level":"64153.12","new_quantity":"0.06765895"},{"side":"offer","event_time":"2026-07-16T20:29:10.155747Z","price_level":"64365.96","new_quantity":"0"},{"side":"offer","event_time":"2026-07-16T20:29:10.155747Z","price_level":"64580.66","new_quantity":"0.00583"},{"side":"offer","event_time":"2026-07-16T20:29:10.155747Z","price_level":"65652.83","new_quantity":"0.00583"}]}]}
{"channel":"l2_data","timestamp":"2026-07-16T20:29:10.382946287Z","sequence_num":363,"events":[{"type":"update","product_id":"BTC-USD","updates":[{"side":"bid","event_time":"2026-07-16T20:29:10.192706Z","price_level":"64131.09","new_quantity":"0.12474448"},{"side":"bid","event_time":"2026-07-16T20:29:10.192706Z","price_level":"64130.32","new_quantity":"0"},{"side":"bid","event_time":"2026-07-16T20:29:10.192706Z","price_level":"64121.88","new_quantity":"0.07411"},{"side":"bid","event_time":"2026-07-16T20:29:10.192706Z","price_level":"64110","new_quantity":"1.01"},{"side":"offer","event_time":"2026-07-16T20:29:10.192706Z","price_level":"64148.55","new_quantity":"0.00009743"},{"side":"offer","event_time":"2026-07-16T20:29:10.192706Z","price_level":"64149.51","new_quantity":"0.00779429"}]}]}
{"channel":"l2_data","timestamp":"2026-07-16T20:29:10.383081384Z","sequence_num":364,"events":[{"type":"update","product_id":"BTC-USD","updates":[{"side":"bid","event_time":"2026-07-16T20:29:10.249307Z","price_level":"64132.75","new_quantity":"0"},{"side":"bid","event_time":"2026-07-16T20:29:10.249307Z","price_level":"64118.68","new_quantity":"0"},{"side":"offer","event_time":"2026-07-16T20:29:10.249307Z","price_level":"64580.69","new_quantity":"0"},{"side":"offer","event_time":"2026-07-16T20:29:10.249307Z","price_level":"65009.85","new_quantity":"0.00583"},{"side":"offer","event_time":"2026-07-16T20:29:10.249307Z","price_level":"65652.83","new_quantity":"0"},{"side":"offer","event_time":"2026-07-16T20:29:10.249307Z","price_level":"65653.17","new_quantity":"0.00583"}]}]}
{"channel":"l2_data","timestamp":"2026-07-16T20:29:10.383885992Z","sequence_num":365,"events":[{"type":"update","product_id":"BTC-USD","updates":[{"side":"bid","event_time":"2026-07-16T20:29:10.296124Z","price_level":"64128.59","new_quantity":"0"},{"side":"bid","event_time":"2026-07-16T20:29:10.296124Z","price_level":"64127.22","new_quantity":"0.01559176"},{"side":"bid","event_time":"2026-07-16T20:29:10.296124Z","price_level":"56121.43","new_quantity":"0.01337205"}]}]}
{"channel":"l2_data","timestamp":"2026-07-16T20:29:10.384663868Z","sequence_num":366,"events":[{"type":"update","product_id":"BTC-USD","updates":[{"side":"bid","event_time":"2026-07-16T20:29:10.345399Z","price_level":"64131.1","new_quantity":"0.02"},{"side":"bid","event_time":"2026-07-16T20:29:10.345399Z","price_level":"64124.24","new_quantity":"0.615396"}]}]}
{"channel":"l2_data","timestamp":"2026-07-16T20:29:10.430117261Z","sequence_num":367,"events":[{"type":"update","product_id":"BTC-USD","updates":[{"side":"bid","event_time":"2026-07-16T20:29:10.392835Z","price_level":"64127.24","new_quantity":"0.01559176"},{"side":"bid","event_time":"2026-07-16T20:29:10.392835Z","price_level":"64127.22","new_quantity":"0"},{"side":"bid","event_time":"2026-07-16T20:29:10.392835Z","price_level":"56121.43","new_quantity":"0"},{"side":"offer","event_time":"2026-07-16T20:29:10.392835Z","price_level":"65009.82","new_quantity":"0.00583"},{"side":"offer","event_time":"2026-07-16T20:29:10.392835Z","price_level":"65223.67","new_quantity":"0"},{"side":"offer","event_time":"2026-07-16T20:29:10.392835Z","price_level":"65653.13","new_quantity":"0.00583"},{"side":"offer","event_time":"2026-07-16T20:29:10.392835Z","price_level":"65653.17","new_quantity":"0"}]}]}
{"channel":"l2_data","timestamp":"2026-07-16T20:29:10.483875592Z","sequence_num":368,"events":[{"type":"update","product_id":"BTC-USD","updates":[{"side":"bid","event_time":"2026-07-16T20:29:10.4554Z","price_level":"64138.77","new_quantity":"0.00001758"},{"side":"bid","event_time":"2026-07-16T20:29:10.4554Z","price_level":"64137.48","new_quantity":"0.00046771"},{"side":"bid","event_time":"2026-07-16T20:29:10.4554Z","price_level":"64132.74","new_quantity":"0"},{"side":"bid","event_time":"2026-07-16T20:29:10.4554Z","price_level":"64131.1","new_quantity":"0"},{"side":"bid","event_time":"2026-07-16T20:29:10.4554Z","price_level":"64131.09","new_quantity":"0"},{"side":"bid","event_time":"2026-07-16T20:29:10.4554Z","price_level":"64130.44","new_quantity":"0"},{"side":"bid","event_time":"2026-07-16T20:29:10.4554Z","price_level":"64130.35","new_quantity":"0"},{"side":"bid","event_time":"2026-07-16T20:29:10.4554Z","price_level":"64130.34","new_quantity":"0"},{"side":"bid","event_time":"2026-07-16T20:29:10.4554Z","price_level":"64128.58","new_quantity":"0"},{"side":"bid","event_time":"2026-07-16T20:29:10.4554Z","price_level":"64128.1","new_quantity":"0"},{"side":"bid","event_time":"2026-07-16T20:29:10.4554Z","price_level":"64127.95","new_quantity":"0"},{"side":"bid","event_time":"2026-07-16T20:29:10.4554Z","price_level":"64127.26","new_quantity":"0"},{"side":"bid","event_time":"2026-07-16T20:29:10.4554Z","price_level":"64127.24","new_quantity":"0"},{"side":"bid","event_time":"2026-07-16T20:29:10.4554Z","price_level":"64125.96","new_quantity":"0"},{"side":"bid","event_time":"2026-07-16T20:29:10.4554Z","price_level":"64124.24","new_quantity":"0"},{"side":"bid","event_time":"2026-07-16T20:29:10.4554Z","price_level":"64121.88","new_quantity":"0"},{"side":"bid","event_time":"2026-07-16T20:29:10.4554Z","price_level":"64121.85","new_quantity":"0"},{"side":"bid","event_time":"2026-07-16T20:29:10.4554Z","price_level":"64115.54","new_quantity":"0.3588241"},{"side":"bid","event_time":"2026-07-16T20:29:10.4554Z","price_level":"64108.89","new_quantity":"0"},{"side":"bid","event_time":"2026-07-16T20:29:10.4554Z","price_level":"63977.5","new_quantity":"0"},{"side":"bid","event_time":"2026-07-16T20:29:10.4554Z","price_level":"63965","new_quantity":"0"},{"side":"offer","event_time":"2026-07-16T20:29:10.4554Z","price_level":"64138.78","new_quantity":"0.964374"},{"side":"offer","event_time":"2026-07-16T20:29:10.4554Z","price_level":"64139.17","new_quantity":"0.38046858"},{"side":"offer","event_time":"2026-07-16T20:29:10.4554Z","price_level":"64140.87","new_quantity":"0"},{"side":"offer","event_time":"2026-07-16T20:29:10.4554Z","price_level":"64150.54","new_quantity":"0.00583"},{"side":"offer","event_time":"2026-07-16T20:29:10.4554Z","price_level":"64151.39","new_quantity":"0"},{"side":"offer","event_time":"2026-07-16T20:29:10.4554Z","price_level":"64152.29","new_quantity":"0.57081098"},{"side":"offer","event_time":"2026-07-16T20:29:10.4554Z","price_level":"64155","new_quantity":"0.01"},{"side":"offer","event_time":"2026-07-16T20:29:10.4554Z","price_level":"64341","new_quantity":"0"},{"side":"offer","event_time":"2026-07-16T20:29:10.4554Z","price_level":"64580.39","new_quantity":"0.00583"},{"side":"offer","event_time":"2026-07-16T20:29:10.4554Z","price_level":"64580.66","new_quantity":"0"},{"side":"offer","event_time":"2026-07-16T20:29:10.4554Z","price_level":"64795.1","new_quantity":"0.00583"},{"side":"offer","event_time":"2026-07-16T20:29:10.4554Z","price_level":"64795.29","new_quantity":"0"},{"side":"offer","event_time":"2026-07-16T20:29:10.4554Z","price_level":"65009.85","new_quantity":"0"},{"side":"offer","event_time":"2026-07-16T20:29:10.4554Z","price_level":"65438.1","new_quantity":"0"},{"side":"offer","event_time":"2026-07-16T20:29:10.4554Z","price_level":"65653.13","new_quantity":"0"}]}]}
{"channel":"l2_data","timestamp":"2026-07-16T20:29:10.809043985Z","sequence_num":369,"events":[{"type":"update","product_id":"BTC-USD","updates":[{"side":"bid","event_time":"2026-07-16T20:29:10.490635Z","price_level":"64138.77","new_quantity":"0"},{"side":"bid","event_time":"2026-07-16T20:29:10.490635Z","price_level":"64137.48","new_quantity":"0"},{"side":"bid","event_time":"2026-07-16T20:29:10.490635Z","price_level":"64135","new_quantity":"0.01"},{"side":"bid","event_time":"2026-07-16T20:29:10.490635Z","price_level":"64128.85","new_quantity":"0.12474883"},{"side":"bid","event_time":"2026-07-16T20:29:10.490635Z","price_level":"64127.88","new_quantity":"0"},{"side":"bid","event_time":"2026-07-16T20:29:10.490635Z","price_level":"64126.84","new_quantity":"0.04691558"},{"side":"bid","event_time":"2026-07-16T20:29:10.490635Z","price_level":"64126.58","new_quantity":"0"},{"side":"bid","event_time":"2026-07-16T20:29:10.490635Z","price_level":"64125.97","new_quantity":"0.31190852"},{"side":"bid","event_time":"2026-07-16T20:29:10.490635Z","price_level":"64125.96","new_quantity":"0.15594307"},{"side":"bid","event_time":"2026-07-16T20:29:10.490635Z","price_level":"64125.4","new_quantity":"0.01559176"},{"side":"bid","event_time":"2026-07-16T20:29:10.490635Z","price_level":"64125.2","new_quantity":"0"},{"side":"bid","event_time":"2026-07-16T20:29:10.490635Z","price_level":"64124.83","new_quantity":"0"},{"side":"bid","event_time":"2026-07-16T20:29:10.490635Z","price_level":"64124.62","new_quantity":"0"},{"side":"bid","event_time":"2026-07-16T20:29:10.490635Z","price_level":"64122.61","new_quantity":"0"},{"side":"bid","event_time":"2026-07-16T20:29:10.490635Z","price_level":"64121.66","new_quantity":"0"},{"side":"bid","event_time":"2026-07-16T20:29:10.490635Z","price_level":"64121.32","new_quantity":"0"},{"side":"bid","event_time":"2026-07-16T20:29:10.490635Z","price_level":"64120.82","new_quantity":"0.0077892"},{"side":"bid","event_time":"2026-07-16T20:29:10.490635Z","price_level":"64120.16","new_quantity":"0"},{"side":"bid","event_time":"2026-07-16T20:29:10.490635Z","price_level":"64115.56","new_quantity":"0.23359045"},{"side":"bid","event_time":"2026-07-16T20:29:10.490635Z","price_level":"64115.55","new_quantity":"0.2271726"},{"side":"bid","event_time":"2026-07-16T20:29:10.490635Z","price_level":"64114.47","new_quantity":"0"},{"side":"bid","event_time":"2026-07-16T20:29:10.490635Z","price_level":"64113.02","new_quantity":"0.05720446"},{"side":"bid","event_time":"2026-07-16T20:29:10.490635Z","price_level":"64110.01","new_quantity":"0"},{"side":"bid","event_time":"2026-07-16T20:29:10.490635Z","price_level":"64110","new_quantity":"0.01"},{"side":"bid","event_time":"2026-07-16T20:29:10.490635Z","price_level":"64109.98","new_quantity":"0"},{"side":"bid","event_time":"2026-07-16T20:29:10.490635Z","price_level":"64108.9","new_quantity":"0.65497375"},{"side":"bid","event_time":"2026-07-16T20:29:10.490635Z","price_level":"64107.36","new_quantity":"0.59666681"},{"side":"bid","event_time":"2026-07-16T20:29:10.490635Z","price_level":"64105.13","new_quantity":"0"},{"side":"bid","event_time":"2026-07-16T20:29:10.490635Z","price_level":"64100.27","new_quantity":"0"},{"side":"bid","event_time":"2026-07-16T20:29:10.490635Z","price_level":"64099","new_quantity":"0"},{"side":"bid","event_time":"2026-07-16T20:29:10.490635Z","price_level":"64097.71","new_quantity":"0"},{"side":"bid","event_time":"2026-07-16T20:29:10.490635Z","price_level":"64095.74","new_quantity":"0"},{"side":"bid","event_time":"2026-07-16T20:29:10.490635Z","price_level":"64093.86","new_quantity":"0"},{"side":"bid","event_time":"2026-07-16T20:29:10.490635Z","price_level":"64092.21","new_quantity":"0.98271786"},{"side":"bid","event_time":"2026-07-16T20:29:10.490635Z","price_level":"64079.52","new_quantity":"0"},{"side":"bid","event_time":"2026-07-16T20:29:10.490635Z","price_level":"64077.94","new_quantity":"0"},{"side":"bid","event_time":"2026-07-16T20:29:10.490635Z","price_level":"64076.1","new_quantity":"0"},{"side":"bid","event_time":"2026-07-16T20:29:10.490635Z","price_level":"64075.2","new_quantity":"0.00858334"},{"side":"bid","event_time":"2026-07-16T20:29:10.490635Z","price_level":"64074.38","new_quantity":"1.41586844"},{"side":"bid","event_time":"2026-07-16T20:29:10.490635Z","price_level":"64069.05","new_quantity":"0"},{"side":"bid","event_time":"2026-07-16T20:29:10.490635Z","price_level":"64049.05","new_quantity":"10.668587"},{"side":"bid","event_time":"2026-07-16T20:29:10.490635Z","price_level":"63980.45","new_quantity":"0"},{"side":"bid","event_time":"2026-07-16T20:29:10.490635Z","price_level":"63862.2","new_quantity":"1.40928435"},{"side":"offer","event_time":"2026-07-16T20:29:10.490635Z","price_level":"64135.01","new_quantity":"0.92543125"},{"side":"offer","event_time":"2026-07-16T20:29:10.490635Z","price_level":"64135.66","new_quantity":"0.00234573"},{"side":"offer","event_time":"2026-07-16T20:29:10.490635Z","price_level":"64137.47","new_quantity":"0.15591512"},{"side":"offer","event_time":"2026-07-16T20:29:10.490635Z","price_level":"64137.48","new_quantity":"0.29789919"},{"side":"offer","event_time":"2026-07-16T20:29:10.490635Z","price_level":"64137.49","new_quantity":"0.35190852"},{"side":"offer","event_time":"2026-07-16T20:29:10.490635Z","price_level":"64138.77","new_quantity":"0.00545697"},{"side":"offer","event_time":"2026-07-16T20:29:10.490635Z","price_level":"64138.78","new_quantity":"0.02"},{"side":"offer","event_time":"2026-07-16T20:29:10.490635Z","price_level":"64139.17","new_quantity":"0.04691558"},{"side":"offer","event_time":"2026-07-16T20:29:10.490635Z","price_level":"64139.18","new_quantity":"0"},{"side":"offer","event_time":"2026-07-16T20:29:10.490635Z","price_level":"64139.19","new_quantity":"0.44529932"},{"side":"offer","event_time":"2026-07-16T20:29:10.490635Z","price_level":"64139.59","new_quantity":"0.0486477"},{"side":"offer","event_time":"2026-07-16T20:29:10.490635Z","price_level":"64140.07","new_quantity":"0"},{"side":"offer","event_time":"2026-07-16T20:29:10.490635Z","price_level":"64140.66","new_quantity":"0.04103046"},{"side":"offer","event_time":"2026-07-16T20:29:10.490635Z","price_level":"64140.71","new_quantity":"0.31190852"},{"side":"offer","event_time":"2026-07-16T20:29:10.490635Z","price_level":"64143.55","new_quantity":"0"},{"side":"offer","event_time":"2026-07-16T20:29:10.490635Z","price_level":"64143.66","new_quantity":"0"},{"side":"offer","event_time":"2026-07-16T20:29:10.490635Z","price_level":"64145.28","new_quantity":"0.00077958"},{"side":"offer","event_time":"2026-07-16T20:29:10.490635Z","price_level":"64147.11","new_quantity":"0.000018"},{"side":"offer","event_time":"2026-07-16T20:29:10.490635Z","price_level":"64149.18","new_quantity":"0"},{"side":"offer","event_time":"2026-07-16T20:29:10.490635Z","price_level":"64149.19","new_quantity":"0"},{"side":"offer","event_time":"2026-07-16T20:29:10.490635Z","price_level":"64149.3","new_quantity":"0"},{"side":"offer","event_time":"2026-07-16T20:29:10.490635Z","price_level":"64149.31","new_quantity":"0.37877068"},{"side":"offer","event_time":"2026-07-16T20:29:10.490635Z","price_level":"64149.32","new_quantity":"0"},{"side":"offer","event_time":"2026-07-16T20:29:10.490635Z","price_level":"64150.38","new_quantity":"0.00583"},{"side":"offer","event_time":"2026-07-16T20:29:10.490635Z","price_level":"64150.54","new_quantity":"0"},{"side":"offer","event_time":"2026-07-16T20:29:10.490635Z","price_level":"64154","new_quantity":"1"},{"side":"offer","event_time":"2026-07-16T20:29:10.490635Z","price_level":"64155.65","new_quantity":"0"},{"side":"offer","event_time":"2026-07-16T20:29:10.490635Z","price_level":"64156.22","new_quantity":"0"},{"side":"offer","event_time":"2026-07-16T20:29:10.490635Z","price_level":"64157.4","new_quantity":"0"},{"side":"offer","event_time":"2026-07-16T20:29:10.490635Z","price_level":"64161.53","new_quantity":"0"},{"side":"offer","event_time":"2026-07-16T20:29:10.490635Z","price_level":"64174.49","new_quantity":"0.32027682"},{"side":"offer","event_time":"2026-07-16T20:29:10.490635Z","price_level":"64174.5","new_quantity":"0"},{"side":"offer","event_time":"2026-07-16T20:29:10.490635Z","price_level":"64176.08","new_quantity":"0"},{"side":"offer","event_time":"2026-07-16T20:29:10.490635Z","price_level":"64178.03","new_quantity":"0.48577397"},{"side":"offer","event_time":"2026-07-16T20:29:10.490635Z","price_level":"64180.78","new_quantity":"0"},{"side":"offer","event_time":"2026-07-16T20:29:10.490635Z","price_level":"64184.55","new_quantity":"0.5"},{"side":"offer","event_time":"2026-07-16T20:29:10.490635Z","price_level":"64185.11","new_quantity":"0.13828427"},{"side":"offer","event_time":"2026-07-16T20:29:10.490635Z","price_level":"64185.12","new_quantity":"0"},{"side":"offer","event_time":"2026-07-16T20:29:10.490635Z","price_level":"64190.33","new_quantity":"0.73075241"},{"side":"offer","event_time":"2026-07-16T20:29:10.490635Z","price_level":"64190.99","new_quantity":"0"},{"side":"offer","event_time":"2026-07-16T20:29:10.490635Z","price_level":"64191.81","new_quantity":"0"},{"side":"offer","event_time":"2026-07-16T20:29:10.490635Z","price_level":"64192.99","new_quantity":"2.12503586"},{"side":"offer","event_time":"2026-07-16T20:29:10.490635Z","price_level":"64193.7","new_quantity":"0.09207982"},{"side":"offer","event_time":"2026-07-16T20:29:10.490635Z","price_level":"64194.53","new_quantity":"0"},{"side":"offer","event_time":"2026-07-16T20:29:10.490635Z","price_level":"64195","new_quantity":"0"},{"side":"offer","event_time":"2026-07-16T20:29:10.490635Z","price_level":"64247.31","new_quantity":"0.001455"},{"side":"offer","event_time":"2026-07-16T20:29:10.490635Z","price_level":"64259.43","new_quantity":"0"},{"side":"offer","event_time":"2026-07-16T20:29:10.490635Z","price_level":"65436.96","new_quantity":"0.00583"}]}]}
{"channel":"l2_data","timestamp":"2026-07-16T20:29:10.8149224Z","sequence_num":370,"events":[{"type":"update","product_id":"BTC-USD","updates":[{"side":"bid","event_time":"2026-07-16T20:29:10.548632Z","price_level":"64132.36","new_quantity":"0.00779638"},{"side":"bid","event_time":"2026-07-16T20:29:10.548632Z","price_level":"64126.96","new_quantity":"0.02"},{"side":"bid","event_time":"2026-07-16T20:29:10.548632Z","price_level":"64125.4","new_quantity":"0"},{"side":"bid","event_time":"2026-07-16T20:29:10.548632Z","price_level":"64124.04","new_quantity":"0.01559176"},{"side":"bid","event_time":"2026-07-16T20:29:10.548632Z","price_level":"64123.32","new_quantity":"0"},{"side":"bid","event_time":"2026-07-16T20:29:10.548632Z","price_level":"64120.82","new_quantity":"0"},{"side":"bid","event_time":"2026-07-16T20:29:10.548632Z","price_level":"64119.54","new_quantity":"0.41534709"},{"side":"bid","event_time":"2026-07-16T20:29:10.548632Z","price_level":"64118.26","new_quantity":"0.07411"},{"side":"bid","event_time":"2026-07-16T20:29:10.548632Z","price_level":"64117.59","new_quantity":"0"},{"side":"bid","event_time":"2026-07-16T20:29:10.548632Z","price_level":"64108.9","new_quantity":"0"},{"side":"bid","event_time":"2026-07-16T20:29:10.548632Z","price_level":"64106.7","new_quantity":"0"},{"side":"bid","event_time":"2026-07-16T20:29:10.548632Z","price_level":"64104.91","new_quantity":"0.65500539"},{"side":"bid","event_time":"2026-07-16T20:29:10.548632Z","price_level":"64091","new_quantity":"1"},{"side":"bid","event_time":"2026-07-16T20:29:10.548632Z","price_level":"64090","new_quantity":"1.01"},{"side":"bid","event_time":"2026-07-16T20:29:10.548632Z","price_level":"64087","new_quantity":"1"},{"side":"bid","event_time":"2026-07-16T20:29:10.548632Z","price_level":"64086","new_quantity":"1"},{"side":"bid","event_time":"2026-07-16T20:29:10.548632Z","price_level":"64022.44","new_quantity":"0"},{"side":"offer","event_time":"2026-07-16T20:29:10.548632Z","price_level":"64135.01","new_quantity":"1.05016811"},{"side":"offer","event_time":"2026-07-16T20:29:10.548632Z","price_level":"64137.48","new_quantity":"0.2133472"},{"side":"offer","event_time":"2026-07-16T20:29:10.548632Z","price_level":"64137.49","new_quantity":"0.33190852"},{"side":"offer","event_time":"2026-07-16T20:29:10.548632Z","price_level":"64138.78","new_quantity":"0"},{"side":"offer","event_time":"2026-07-16T20:29:10.548632Z","price_level":"64144.88","new_quantity":"0.0000582"},{"side":"offer","event_time":"2026-07-16T20:29:10.548632Z","price_level":"64151.03","new_quantity":"0.01050822"},{"side":"offer","event_time":"2026-07-16T20:29:10.548632Z","price_level":"64161.57","new_quantity":"0"},{"side":"offer","event_time":"2026-07-16T20:29:10.548632Z","price_level":"64292.3","new_quantity":"0.01149846"},{"side":"offer","event_time":"2026-07-16T20:29:10.548632Z","price_level":"64305.45","new_quantity":"0"}]}]}
{"channel":"l2_data","timestamp":"2026-07-16T20:29:10.816647047Z","sequence_num":371,"events":[{"type":"update","product_id":"BTC-USD","updates":[{"side":"bid","event_time":"2026-07-16T20:29:10.600276Z","price_level":"64133.96","new_quantity":"0"},{"side":"bid","event_time":"2026-07-16T20:29:10.600276Z","price_level":"64130.19","new_quantity":"0.00779664"},{"side":"bid","event_time":"2026-07-16T20:29:10.600276Z","price_level":"64128.85","new_quantity":"0"},{"side":"bid","event_time":"2026-07-16T20:29:10.600276Z","price_level":"64127.8","new_quantity":"0.12475088"},{"side":"bid","event_time":"2026-07-16T20:29:10.600276Z","price_level":"64126.79","new_quantity":"0"},{"side":"bid","event_time":"2026-07-16T20:29:10.600276Z","price_level":"64124.04","new_quantity":"0"},{"side":"bid","event_time":"2026-07-16T20:29:10.600276Z","price_level":"64124.02","new_quantity":"0.01559176"},{"side":"bid","event_time":"2026-07-16T20:29:10.600276Z","price_level":"64120.01","new_quantity":"0.0077892"},{"side":"bid","event_time":"2026-07-16T20:29:10.600276Z","price_level":"64109.08","new_quantity":"0.06059674"},{"side":"bid","event_time":"2026-07-16T20:29:10.600276Z","price_level":"64109","new_quantity":"1"},{"side":"bid","event_time":"2026-07-16T20:29:10.600276Z","price_level":"64108.67","new_quantity":"0.65498281"},{"side":"bid","event_time":"2026-07-16T20:29:10.600276Z","price_level":"64104.91","new_quantity":"0"},{"side":"bid","event_time":"2026-07-16T20:29:10.600276Z","price_level":"64104.2","new_quantity":"0.14"},{"side":"bid","event_time":"2026-07-16T20:29:10.600276Z","price_level":"64086","new_quantity":"0"},{"side":"bid","event_time":"2026-07-16T20:29:10.600276Z","price_level":"64009.54","new_quantity":"0.00150292"},{"side":"bid","event_time":"2026-07-16T20:29:10.600276Z","price_level":"56118.13","new_quantity":"0.01337205"},{"side":"offer","event_time":"2026-07-16T20:29:10.600276Z","price_level":"64144.87","new_quantity":"0.0077892"},{"side":"offer","event_time":"2026-07-16T20:29:10.600276Z","price_level":"64145.64","new_quantity":"0.90412295"},{"side":"offer","event_time":"2026-07-16T20:29:10.600276Z","price_level":"64145.65","new_quantity":"0.65499261"},{"side":"offer","event_time":"2026-07-16T20:29:10.600276Z","price_level":"64145.77","new_quantity":"0"},{"side":"offer","event_time":"2026-07-16T20:29:10.600276Z","price_level":"64149.42","new_quantity":"0.00896345"},{"side":"offer","event_time":"2026-07-16T20:29:10.600276Z","price_level":"64149.7","new_quantity":"0"},{"side":"offer","event_time":"2026-07-16T20:29:10.600276Z","price_level":"64151.52","new_quantity":"0.04"},{"side":"offer","event_time":"2026-07-16T20:29:10.600276Z","price_level":"64173.62","new_quantity":"0.32027682"},{"side":"offer","event_time":"2026-07-16T20:29:10.600276Z","price_level":"64174.49","new_quantity":"0"},{"side":"offer","event_time":"2026-07-16T20:29:10.600276Z","price_level":"64177.24","new_quantity":"0.48577995"},{"side":"offer","event_time":"2026-07-16T20:29:10.600276Z","price_level":"64178.03","new_quantity":"0"}]}]}
{"channel":"l2_data","timestamp":"2026-07-16T20:29:10.818770429Z","sequence_num":372,"events":[{"type":"update","product_id":"BTC-USD","updates":[{"side":"bid","event_time":"2026-07-16T20:29:10.649052Z","price_level":"64127.8","new_quantity":"0"},{"side":"bid","event_time":"2026-07-16T20:29:10.649052Z","price_level":"64124.73","new_quantity":"0.01559176"},{"side":"bid","event_time":"2026-07-16T20:29:10.649052Z","price_level":"64124.02","new_quantity":"0"},{"side":"bid","event_time":"2026-07-16T20:29:10.649052Z","price_level":"64123.62","new_quantity":"0.04"},{"side":"bid","event_time":"2026-07-16T20:29:10.649052Z","price_level":"64121.28","new_quantity":"0"},{"side":"bid","event_time":"2026-07-16T20:29:10.649052Z","price_level":"64119.22","new_quantity":"0.02"},{"side":"bid","event_time":"2026-07-16T20:29:10.649052Z","price_level":"64117.4","new_quantity":"0.05823955"},{"side":"bid","event_time":"2026-07-16T20:29:10.649052Z","price_level":"64111.36","new_quantity":"0.01"},{"side":"bid","event_time":"2026-07-16T20:29:10.649052Z","price_level":"64109.08","new_quantity":"0"},{"side":"bid","event_time":"2026-07-16T20:29:10.649052Z","price_level":"64109","new_quantity":"0"},{"side":"bid","event_time":"2026-07-16T20:29:10.649052Z","price_level":"64107.36","new_quantity":"0.59588731"},{"side":"bid","event_time":"2026-07-16T20:29:10.649052Z","price_level":"64102.76","new_quantity":"0.00077954"},{"side":"bid","event_time":"2026-07-16T20:29:10.649052Z","price_level":"64095.01","new_quantity":"0"},{"side":"bid","event_time":"2026-07-16T20:29:10.649052Z","price_level":"64092.9","new_quantity":"0.000018"},{"side":"offer","event_time":"2026-07-16T20:29:10.649052Z","price_level":"64139.99","new_quantity":"0.0012474"},{"side":"offer","event_time":"2026-07-16T20:29:10.649052Z","price_level":"64149.49","new_quantity":"0.06"},{"side":"offer","event_time":"2026-07-16T20:29:10.649052Z","price_level":"64150.01","new_quantity":"0"},{"side":"offer","event_time":"2026-07-16T20:29:10.649052Z","price_level":"64151.3","new_quantity":"0"},{"side":"offer","event_time":"2026-07-16T20:29:10.649052Z","price_level":"64151.52","new_quantity":"0.14"},{"side":"offer","event_time":"2026-07-16T20:29:10.649052Z","price_level":"64158.46","new_quantity":"0.32190852"},{"side":"offer","event_time":"2026-07-16T20:29:10.649052Z","price_level":"64174.99","new_quantity":"0.00077958"},{"side":"offer","event_time":"2026-07-16T20:29:10.649052Z","price_level":"64178.76","new_quantity":"0"},{"side":"offer","event_time":"2026-07-16T20:29:10.649052Z","price_level":"64183.25","new_quantity":"0.00077954"},{"side":"offer","event_time":"2026-07-16T20:29:10.649052Z","price_level":"64184.99","new_quantity":"0"},{"side":"offer","event_time":"2026-07-16T20:29:10.649052Z","price_level":"64193.69","new_quantity":"0.00077954"},{"side":"offer","event_time":"2026-07-16T20:29:10.649052Z","price_level":"64198.39","new_quantity":"0"}]}]}
