{"channel":"l2_data","timestamp":"2026-07-15T03:40:04.181141677Z","sequence_num":0,"events":[{"type":"snapshot","product_id":"BTC-USD","updates":[{"side":"bid","event_time":"2026-07-15T03:40:03.803292Z","price_level":"64614.65","new_quantity":"0.21871304"},{"side":"bid","event_time":"2026-07-15T03:40:03.803292Z","price_level":"64614","new_quantity":"0.0257"},{"side":"bid","event_time":"2026-07-15T03:40:03.803292Z","price_level":"64613.64","new_quantity":"0.12381286"},{"side":"bid","event_time":"2026-07-15T03:40:03.803292Z","price_level":"64613.44","new_quantity":"0.00015074"},{"side":"bid","event_time":"2026-07-15T03:40:03.803292Z","price_level":"64613.35","new_quantity":"0.00773834"},{"side":"bid","event_time":"2026-07-15T03:40:03.803292Z","price_level":"64613.03","new_quantity":"0.00773818"},{"side":"bid","event_time":"2026-07-15T03:40:03.803292Z","price_level":"64612.59","new_quantity":"0.12378505"},{"side":"bid","event_time":"2026-07-15T03:40:03.803292Z","price_level":"64612","new_quantity":"0.0257"},{"side":"bid","event_time":"2026-07-15T03:40:03.803292Z","price_level":"64611.01","new_quantity":"0.78489268"},{"side":"bid","event_time":"2026-07-15T03:40:03.803292Z","price_level":"64611","new_quantity":"1"},{"side":"bid","event_time":"2026-07-15T03:40:03.803292Z","price_level":"64610.85","new_quantity":"0.00967272"},{"side":"bid","event_time":"2026-07-15T03:40:03.803292Z","price_level":"64610.46","new_quantity":"0.15477369"},{"side":"bid","event_time":"2026-07-15T03:40:03.803292Z","price_level":"64610.42","new_quantity":"0.12378505"},{"side":"bid","event_time":"2026-07-15T03:40:03.803292Z","price_level":"64610.41","new_quantity":"0.04656107"},{"side":"bid","event_time":"2026-07-15T03:40:03.803292Z","price_level":"64610.26","new_quantity":"0.0015533"},{"side":"bid","event_time":"2026-07-15T03:40:03.803292Z","price_level":"64610","new_quantity":"0.0245"},{"side":"bid","event_time":"2026-07-15T03:40:03.803292Z","price_level":"64609.76","new_quantity":"0.000018"},{"side":"bid","event_time":"2026-07-15T03:40:03.803292Z","price_level":"64609.51","new_quantity":"0.17147844"},{"side":"bid","event_time":"2026-07-15T03:40:03.803292Z","price_level":"64609.37","new_quantity":"0.06"},{"side":"bid","event_time":"2026-07-15T03:40:03.803292Z","price_level":"64609.33","new_quantity":"0.00003"},{"side":"bid","event_time":"2026-07-15T03:40:03.803292Z","price_level":"64609.13","new_quantity":"0.04642788"},{"side":"bid","event_time":"2026-07-15T03:40:03.803292Z","price_level":"64608.2","new_quantity":"0.03093532"},{"side":"bid","event_time":"2026-07-15T03:40:03.803292Z","price_level":"64608.02","new_quantity":"0.12378505"},{"side":"bid","event_time":"2026-07-15T03:40:03.803292Z","price_level":"64608","new_quantity":"0.0245"},{"side":"bid","event_time":"2026-07-15T03:40:03.803292Z","price_level":"64607.07","new_quantity":"0.0015533"},{"side":"bid","event_time":"2026-07-15T03:40:03.803292Z","price_level":"64606.08","new_quantity":"0.000018"},{"side":"bid","event_time":"2026-07-15T03:40:03.803292Z","price_level":"64605.01","new_quantity":"0.13265443"},{"side":"bid","event_time":"2026-07-15T03:40:03.803292Z","price_level":"64604.72","new_quantity":"0.12378505"},{"side":"bid","event_time":"2026-07-15T03:40:03.803292Z","price_level":"64604.3","new_quantity":"0.05"},{"side":"bid","event_time":"2026-07-15T03:40:03.803292Z","price_level":"64603.88","new_quantity":"0.0015533"},{"side":"bid","event_time":"2026-07-15T03:40:03.803292Z","price_level":"64603.57","new_quantity":"0.00030231"},{"side":"bid","event_time":"2026-07-15T03:40:03.803292Z","price_level":"64603.51","new_quantity":"0.04656107"},{"side":"bid","event_time":"2026-07-15T03:40:03.803292Z","price_level":"64603.14","new_quantity":"0.0482796"},{"side":"bid","event_time":"2026-07-15T03:40:03.803292Z","price_level":"64602.72","new_quantity":"0.16828866"},{"side":"bid","event_time":"2026-07-15T03:40:03.803292Z","price_level":"64602.71","new_quantity":"0.12378505"},{"side":"bid","event_time":"2026-07-15T03:40:03.803292Z","price_level":"64602.4","new_quantity":"0.000018"},{"side":"bid","event_time":"2026-07-15T03:40:03.803292Z","price_level":"64601.71","new_quantity":"0.00772597"},{"side":"bid","event_time":"2026-07-15T03:40:03.803292Z","price_level":"64601.7","new_quantity":"0.03093532"},{"side":"bid","event_time":"2026-07-15T03:40:03.803292Z","price_level":"64601.61","new_quantity":"0.00120923"},{"side":"bid","event_time":"2026-07-15T03:40:03.803292Z","price_level":"64601.49","new_quantity":"0.00060461"},{"side":"bid","event_time":"2026-07-15T03:40:03.803292Z","price_level":"64601.03","new_quantity":"0.00077381"},{"side":"bid","event_time":"2026-07-15T03:40:03.803292Z","price_level":"64600.69","new_quantity":"0.0015533"},{"side":"bid","event_time":"2026-07-15T03:40:03.803292Z","price_level":"64600.42","new_quantity":"0.12378505"},{"side":"bid","event_time":"2026-07-15T03:40:03.803292Z","price_level":"64599.77","new_quantity":"0.10788454"},{"side":"bid","event_time":"2026-07-15T03:40:03.803292Z","price_level":"64599.19","new_quantity":"0.00583"},{"side":"bid","event_time":"2026-07-15T03:40:03.803292Z","price_level":"64598.72","new_quantity":"0.000018"},{"side":"bid","event_time":"2026-07-15T03:40:03.803292Z","price_level":"64598.32","new_quantity":"0.12378505"},{"side":"bid","event_time":"2026-07-15T03:40:03.803292Z","price_level":"64598.15","new_quantity":"0.0328187"},{"side":"bid","event_time":"2026-07-15T03:40:03.803292Z","price_level":"64598.11","new_quantity":"0.00002319"},{"side":"bid","event_time":"2026-07-15T03:40:03.803292Z","price_level":"64597.82","new_quantity":"0.036066"},{"side":"bid","event_time":"2026-07-15T03:40:03.803292Z","price_level":"64597.5","new_quantity":"0.0015533"},{"side":"bid","event_time":"2026-07-15T03:40:03.803292Z","price_level":"64597.36","new_quantity":"0.04656107"},{"side":"bid","event_time":"2026-07-15T03:40:03.803292Z","price_level":"64596.6","new_quantity":"0.00115403"},{"side":"bid","event_time":"2026-07-15T03:40:03.803292Z","price_level":"64596.56","new_quantity":"0.13133873"},{"side":"bid","event_time":"2026-07-15T03:40:03.803292Z","price_level":"64596.55","new_quantity":"0.14"},{"side":"bid","event_time":"2026-07-15T03:40:03.803292Z","price_level":"64595.77","new_quantity":"0.02423914"},{"side":"bid","event_time":"2026-07-15T03:40:03.803292Z","price_level":"64595.04","new_quantity":"0.000018"},{"side":"bid","event_time":"2026-07-15T03:40:03.803292Z","price_level":"64594.31","new_quantity":"0.05574073"},{"side":"bid","event_time":"2026-07-15T03:40:03.803292Z","price_level":"64593.29","new_quantity":"0.00241846"},{"side":"bid","event_time":"2026-07-15T03:40:03.803292Z","price_level":"64592.77","new_quantity":"0.12379885"},{"side":"bid","event_time":"2026-07-15T03:40:03.803292Z","price_level":"64592.76","new_quantity":"0.12378505"},{"side":"bid","event_time":"2026-07-15T03:40:03.803292Z","price_level":"64592.52","new_quantity":"0.00154636"},{"side":"bid","event_time":"2026-07-15T03:40:03.803292Z","price_level":"64592","new_quantity":"0.00003194"},{"side":"bid","event_time":"2026-07-15T03:40:03.803292Z","price_level":"64591.87","new_quantity":"0.00104465"},{"side":"bid","event_time":"2026-07-15T03:40:03.803292Z","price_level":"64591.8","new_quantity":"0.05"},{"side":"bid","event_time":"2026-07-15T03:40:03.803292Z","price_level":"64591.36","new_quantity":"0.000018"},{"side":"bid","event_time":"2026-07-15T03:40:03.803292Z","price_level":"64591.12","new_quantity":"0.0015533"},{"side":"bid","event_time":"2026-07-15T03:40:03.803292Z","price_level":"64590.92","new_quantity":"0.03093532"},{"side":"bid","event_time":"2026-07-15T03:40:03.803292Z","price_level":"64590.12","new_quantity":"0.02771255"},{"side":"bid","event_time":"2026-07-15T03:40:03.803292Z","price_level":"64588.89","new_quantity":"0.10078747"},{"side":"bid","event_time":"2026-07-15T03:40:03.803292Z","price_level":"64588.88","new_quantity":"0.12378505"},{"side":"bid","event_time":"2026-07-15T03:40:03.803292Z","price_level":"64587.93","new_quantity":"0.00157587"},{"side":"bid","event_time":"2026-07-15T03:40:03.803292Z","price_level":"64587.68","new_quantity":"0.000018"},{"side":"bid","event_time":"2026-07-15T03:40:03.803292Z","price_level":"64587.11","new_quantity":"0.04344432"},{"side":"bid","event_time":"2026-07-15T03:40:03.803292Z","price_level":"64586.49","new_quantity":"0.10480084"},{"side":"bid","event_time":"2026-07-15T03:40:03.803292Z","price_level":"64586.48","new_quantity":"0.04656107"},{"side":"bid","event_time":"2026-07-15T03:40:03.803292Z","price_level":"64586.07","new_quantity":"0.0077318"},{"side":"bid","event_time":"2026-07-15T03:40:03.803292Z","price_level":"64585.39","new_quantity":"0.01907164"},{"side":"bid","event_time":"2026-07-15T03:40:03.803292Z","price_level":"64585","new_quantity":"0.12378505"},{"side":"bid","event_time":"2026-07-15T03:40:03.803292Z","price_level":"64584.75","new_quantity":"0.00077367"},{"side":"bid","event_time":"2026-07-15T03:40:03.803292Z","price_level":"64584.74","new_quantity":"0.0015533"},{"side":"bid","event_time":"2026-07-15T03:40:03.803292Z","price_level":"64584.49","new_quantity":"0.03093532"},{"side":"bid","event_time":"2026-07-15T03:40:03.803292Z","price_level":"64584","new_quantity":"0.06891902"},{"side":"bid","event_time":"2026-07-15T03:40:03.803292Z","price_level":"64583.25","new_quantity":"0.00120367"},{"side":"bid","event_time":"2026-07-15T03:40:03.803292Z","price_level":"64581.55","new_quantity":"0.0015533"},{"side":"bid","event_time":"2026-07-15T03:40:03.803292Z","price_level":"64581.14","new_quantity":"0.55292907"},{"side":"bid","event_time":"2026-07-15T03:40:03.803292Z","price_level":"64581.13","new_quantity":"0.88325265"},{"side":"bid","event_time":"2026-07-15T03:40:03.803292Z","price_level":"64580.64","new_quantity":"0.0429267"},{"side":"bid","event_time":"2026-07-15T03:40:03.803292Z","price_level":"64580.47","new_quantity":"0.04656107"},{"side":"bid","event_time":"2026-07-15T03:40:03.803292Z","price_level":"64580.32","new_quantity":"0.000018"},{"side":"bid","event_time":"2026-07-15T03:40:03.803292Z","price_level":"64579.32","new_quantity":"0.60950483"},{"side":"bid","event_time":"2026-07-15T03:40:03.803292Z","price_level":"64579.31","new_quantity":"0.02684277"},{"side":"bid","event_time":"2026-07-15T03:40:03.803292Z","price_level":"64578.7","new_quantity":"0.00002319"},{"side":"bid","event_time":"2026-07-15T03:40:03.803292Z","price_level":"64578.37","new_quantity":"0.00302307"},{"side":"bid","event_time":"2026-07-15T03:40:03.803292Z","price_level":"64578.36","new_quantity":"0.0015533"},{"side":"bid","event_time":"2026-07-15T03:40:03.803292Z","price_level":"64577.84","new_quantity":"0.44862"},{"side":"bid","event_time":"2026-07-15T03:40:03.803292Z","price_level":"64577.52","new_quantity":"0.03093532"},{"side":"bid","event_time":"2026-07-15T03:40:03.803292Z","price_level":"64577.25","new_quantity":"0.21359684"},{"side":"bid","event_time":"2026-07-15T03:40:03.803292Z","price_level":"64577.24","new_quantity":"0.32906259"},{"side":"bid","event_time":"2026-07-15T03:40:03.803292Z","price_level":"64576.64","new_quantity":"0.000018"},{"side":"bid","event_time":"2026-07-15T03:40:03.803292Z","price_level":"64576.17","new_quantity":"0.02423914"},{"side":"bid","event_time":"2026-07-15T03:40:03.803292Z","price_level":"64575.17","new_quantity":"0.0015533"},{"side":"bid","event_time":"2026-07-15T03:40:03.803292Z","price_level":"64574.67","new_quantity":"0.0005"},{"side":"bid","event_time":"2026-07-15T03:40:03.803292Z","price_level":"64572.96","new_quantity":"0.000018"},{"side":"bid","event_time":"2026-07-15T03:40:03.803292Z","price_level":"64571.99","new_quantity":"0.00077372"},{"side":"bid","event_time":"2026-07-15T03:40:03.803292Z","price_level":"64571.98","new_quantity":"0.0015533"},{"side":"bid","event_time":"2026-07-15T03:40:03.803292Z","price_level":"64571.35","new_quantity":"0.01846839"},{"side":"bid","event_time":"2026-07-15T03:40:03.803292Z","price_level":"64571.34","new_quantity":"0.03093532"},{"side":"bid","event_time":"2026-07-15T03:40:03.803292Z","price_level":"64570.21","new_quantity":"0.00158635"},{"side":"bid","event_time":"2026-07-15T03:40:03.803292Z","price_level":"64570.13","new_quantity":"0.02873502"},{"side":"bid","event_time":"2026-07-15T03:40:03.803292Z","price_level":"64570.12","new_quantity":"0.04656107"},{"side":"bid","event_time":"2026-07-15T03:40:03.803292Z","price_level":"64569.29","new_quantity":"0.01463398"},{"side":"bid","event_time":"2026-07-15T03:40:03.803292Z","price_level":"64569.28","new_quantity":"0.000018"},{"side":"bid","event_time":"2026-07-15T03:40:03.803292Z","price_level":"64568.79","new_quantity":"0.0015533"},{"side":"bid","event_time":"2026-07-15T03:40:03.803292Z","price_level":"64567.63","new_quantity":"0.06134308"},{"side":"bid","event_time":"2026-07-15T03:40:03.803292Z","price_level":"64567.62","new_quantity":"0.06784712"},{"side":"bid","event_time":"2026-07-15T03:40:03.803292Z","price_level":"64565.6","new_quantity":"0.0015713"},{"side":"bid","event_time":"2026-07-15T03:40:03.803292Z","price_level":"64565.02","new_quantity":"0.03093532"},{"side":"bid","event_time":"2026-07-15T03:40:03.803292Z","price_level":"64562.41","new_quantity":"0.0015533"},{"side":"bid","event_time":"2026-07-15T03:40:03.803292Z","price_level":"64561.92","new_quantity":"0.00003847"},{"side":"bid","event_time":"2026-07-15T03:40:03.803292Z","price_level":"64561.91","new_quantity":"0.00000094"},{"side":"bid","event_time":"2026-07-15T03:40:03.803292Z","price_level":"64560.7","new_quantity":"0.2076429"},{"side":"bid","event_time":"2026-07-15T03:40:03.803292Z","price_level":"64560.69","new_quantity":"0.26305242"},{"side":"bid","event_time":"2026-07-15T03:40:03.803292Z","price_level":"64560.22","new_quantity":"0.00077447"},{"side":"bid","event_time":"2026-07-15T03:40:03.803292Z","price_level":"64559.78","new_quantity":"0.04656107"},{"side":"bid","event_time":"2026-07-15T03:40:03.803292Z","price_level":"64559.29","new_quantity":"0.0000232"},{"side":"bid","event_time":"2026-07-15T03:40:03.803292Z","price_level":"64559.23","new_quantity":"0.01158896"},{"side":"bid","event_time":"2026-07-15T03:40:03.803292Z","price_level":"64559.22","new_quantity":"0.0015533"},{"side":"bid","event_time":"2026-07-15T03:40:03.803292Z","price_level":"64558.87","new_quantity":"0.02423914"},{"side":"bid","event_time":"2026-07-15T03:40:03.803292Z","price_level":"64558.24","new_quantity":"0.000018"},{"side":"bid","event_time":"2026-07-15T03:40:03.803292Z","price_level":"64556.13","new_quantity":"0.83322637"},{"side":"bid","event_time":"2026-07-15T03:40:03.803292Z","price_level":"64556.12","new_quantity":"1.39413577"},{"side":"bid","event_time":"2026-07-15T03:40:03.803292Z","price_level":"64556.03","new_quantity":"0.0015533"},{"side":"bid","event_time":"2026-07-15T03:40:03.803292Z","price_level":"64554.67","new_quantity":"0.03093532"},{"side":"bid","event_time":"2026-07-15T03:40:03.803292Z","price_level":"64554.56","new_quantity":"0.000018"},{"side":"bid","event_time":"2026-07-15T03:40:03.803292Z","price_level":"64553.15","new_quantity":"0.00510402"},{"side":"bid","event_time":"2026-07-15T03:40:03.803292Z","price_level":"64552.84","new_quantity":"0.0015533"},{"side":"bid","event_time":"2026-07-15T03:40:03.803292Z","price_level":"64551.76","new_quantity":"0.04656107"},{"side":"bid","event_time":"2026-07-15T03:40:03.803292Z","price_level":"64551.75","new_quantity":"0.80415016"},{"side":"bid","event_time":"2026-07-15T03:40:03.803292Z","price_level":"64551.74","new_quantity":"1.343951"},{"side":"bid","event_time":"2026-07-15T03:40:03.803292Z","price_level":"64551.63","new_quantity":"0.00303419"},{"side":"bid","event_time":"2026-07-15T03:40:03.803292Z","price_level":"64551.33","new_quantity":"0.00604614"},{"side":"bid","event_time":"2026-07-15T03:40:03.803292Z","price_level":"64549.65","new_quantity":"0.0015533"},{"side":"bid","event_time":"2026-07-15T03:40:03.803292Z","price_level":"64548.96","new_quantity":"0.00239888"},{"side":"bid","event_time":"2026-07-15T03:40:03.803292Z","price_level":"64548.37","new_quantity":"1.34887025"},{"side":"bid","event_time":"2026-07-15T03:40:03.803292Z","price_level":"64548.24","new_quantity":"0.06567585"},{"side":"bid","event_time":"2026-07-15T03:40:03.803292Z","price_level":"64548.03","new_quantity":"0.232019"},{"side":"bid","event_time":"2026-07-15T03:40:03.803292Z","price_level":"64543","new_quantity":"0.04656107"},{"side":"bid","event_time":"2026-07-15T03:40:03.803292Z","price_level":"64542.98","new_quantity":"0.83357722"},{"side":"bid","event_time":"2026-07-15T03:40:03.803292Z","price_level":"64542.97","new_quantity":"1.39441975"},{"side":"offer","event_time":"2026-07-15T03:40:03.803292Z","price_level":"64614.66","new_quantity":"0.0328187"},{"side":"offer","event_time":"2026-07-15T03:40:03.803292Z","price_level":"64615.96","new_quantity":"0.00773803"},{"side":"offer","event_time":"2026-07-15T03:40:03.803292Z","price_level":"64616.27","new_quantity":"0.00773825"},{"side":"offer","event_time":"2026-07-15T03:40:03.803292Z","price_level":"64616.64","new_quantity":"0.0015533"},{"side":"offer","event_time":"2026-07-15T03:40:03.803292Z","price_level":"64617.8","new_quantity":"0.00319954"},{"side":"offer","event_time":"2026-07-15T03:40:03.803292Z","price_level":"64617.81","new_quantity":"0.02"},{"side":"offer","event_time":"2026-07-15T03:40:03.803292Z","price_level":"64617.82","new_quantity":"0.09674061"},{"side":"offer","event_time":"2026-07-15T03:40:03.803292Z","price_level":"64617.89","new_quantity":"0.02"},{"side":"offer","event_time":"2026-07-15T03:40:03.803292Z","price_level":"64617.9","new_quantity":"0.00024389"},{"side":"offer","event_time":"2026-07-15T03:40:03.803292Z","price_level":"64617.99","new_quantity":"0.02"},{"side":"offer","event_time":"2026-07-15T03:40:03.803292Z","price_level":"64618","new_quantity":"0.0257"},{"side":"offer","event_time":"2026-07-15T03:40:03.803292Z","price_level":"64618.44","new_quantity":"0.02"},{"side":"offer","event_time":"2026-07-15T03:40:03.803292Z","price_level":"64618.45","new_quantity":"0.00967281"},{"side":"offer","event_time":"2026-07-15T03:40:03.803292Z","price_level":"64618.82","new_quantity":"0.04642788"},{"side":"offer","event_time":"2026-07-15T03:40:03.803292Z","price_level":"64619.41","new_quantity":"0.32469231"},{"side":"offer","event_time":"2026-07-15T03:40:03.803292Z","price_level":"64619.74","new_quantity":"0.12380119"},{"side":"offer","event_time":"2026-07-15T03:40:03.803292Z","price_level":"64619.83","new_quantity":"0.0015533"},{"side":"offer","event_time":"2026-07-15T03:40:03.803292Z","price_level":"64620","new_quantity":"0.0245"},{"side":"offer","event_time":"2026-07-15T03:40:03.803292Z","price_level":"64620.35","new_quantity":"0.022692"},{"side":"offer","event_time":"2026-07-15T03:40:03.803292Z","price_level":"64620.81","new_quantity":"0.01621876"},{"side":"offer","event_time":"2026-07-15T03:40:03.803292Z","price_level":"64621.68","new_quantity":"0.04656107"},{"side":"offer","event_time":"2026-07-15T03:40:03.803292Z","price_level":"64621.79","new_quantity":"0.00773825"},{"side":"offer","event_time":"2026-07-15T03:40:03.803292Z","price_level":"64622","new_quantity":"0.0245"},{"side":"offer","event_time":"2026-07-15T03:40:03.803292Z","price_level":"64622.05","new_quantity":"0.12378505"},{"side":"offer","event_time":"2026-07-15T03:40:03.803292Z","price_level":"64622.22","new_quantity":"0.0733"},{"side":"offer","event_time":"2026-07-15T03:40:03.803292Z","price_level":"64622.67","new_quantity":"0.21808511"},{"side":"offer","event_time":"2026-07-15T03:40:03.803292Z","price_level":"64622.68","new_quantity":"0.15474445"},{"side":"offer","event_time":"2026-07-15T03:40:03.803292Z","price_level":"64623.02","new_quantity":"0.0015533"},{"side":"offer","event_time":"2026-07-15T03:40:03.803292Z","price_level":"64623.19","new_quantity":"0.0482796"},{"side":"offer","event_time":"2026-07-15T03:40:03.803292Z","price_level":"64623.99","new_quantity":"0.12378505"},{"side":"offer","event_time":"2026-07-15T03:40:03.803292Z","price_level":"64624","new_quantity":"0.0245"},{"side":"offer","event_time":"2026-07-15T03:40:03.803292Z","price_level":"64624.13","new_quantity":"0.01647578"},{"side":"offer","event_time":"2026-07-15T03:40:03.803292Z","price_level":"64624.14","new_quantity":"0.00076656"},{"side":"offer","event_time":"2026-07-15T03:40:03.803292Z","price_level":"64624.36","new_quantity":"0.00077381"},{"side":"offer","event_time":"2026-07-15T03:40:03.803292Z","price_level":"64624.47","new_quantity":"0.00772597"},{"side":"offer","event_time":"2026-07-15T03:40:03.803292Z","price_level":"64624.48","new_quantity":"0.000018"},{"side":"offer","event_time":"2026-07-15T03:40:03.803292Z","price_level":"64625.5","new_quantity":"0.00304952"},{"side":"offer","event_time":"2026-07-15T03:40:03.803292Z","price_level":"64625.97","new_quantity":"0.26071119"},{"side":"offer","event_time":"2026-07-15T03:40:03.803292Z","price_level":"64625.98","new_quantity":"0.12378505"},{"side":"offer","event_time":"2026-07-15T03:40:03.803292Z","price_level":"64626","new_quantity":"0.0245"},{"side":"offer","event_time":"2026-07-15T03:40:03.803292Z","price_level":"64626.21","new_quantity":"0.0015533"},{"side":"offer","event_time":"2026-07-15T03:40:03.803292Z","price_level":"64626.65","new_quantity":"0.00038328"},{"side":"offer","event_time":"2026-07-15T03:40:03.803292Z","price_level":"64628","new_quantity":"0.0245"},{"side":"offer","event_time":"2026-07-15T03:40:03.803292Z","price_level":"64628.16","new_quantity":"0.000018"},{"side":"offer","event_time":"2026-07-15T03:40:03.803292Z","price_level":"64628.31","new_quantity":"0.12378505"},{"side":"offer","event_time":"2026-07-15T03:40:03.803292Z","price_level":"64628.32","new_quantity":"0.04656107"},{"side":"offer","event_time":"2026-07-15T03:40:03.803292Z","price_level":"64628.4","new_quantity":"0.03093532"},{"side":"offer","event_time":"2026-07-15T03:40:03.803292Z","price_level":"64628.41","new_quantity":"0.06068109"},{"side":"offer","event_time":"2026-07-15T03:40:03.803292Z","price_level":"64629.07","new_quantity":"0.15634154"},{"side":"offer","event_time":"2026-07-15T03:40:03.803292Z","price_level":"64629.09","new_quantity":"0.05103005"},{"side":"offer","event_time":"2026-07-15T03:40:03.803292Z","price_level":"64629.4","new_quantity":"0.0015533"},{"side":"offer","event_time":"2026-07-15T03:40:03.803292Z","price_level":"64630","new_quantity":"0.0222"},{"side":"offer","event_time":"2026-07-15T03:40:03.803292Z","price_level":"64630.35","new_quantity":"0.01554874"},{"side":"offer","event_time":"2026-07-15T03:40:03.803292Z","price_level":"64630.87","new_quantity":"0.01971422"},{"side":"offer","event_time":"2026-07-15T03:40:03.803292Z","price_level":"64631.48","new_quantity":"0.12378505"},{"side":"offer","event_time":"2026-07-15T03:40:03.803292Z","price_level":"64631.84","new_quantity":"0.000018"},{"side":"offer","event_time":"2026-07-15T03:40:03.803292Z","price_level":"64632","new_quantity":"0.0222"},{"side":"offer","event_time":"2026-07-15T03:40:03.803292Z","price_level":"64632.59","new_quantity":"0.0015533"},{"side":"offer","event_time":"2026-07-15T03:40:03.803292Z","price_level":"64633.57","new_quantity":"0.03093532"},{"side":"offer","event_time":"2026-07-15T03:40:03.803292Z","price_level":"64633.58","new_quantity":"0.13690968"},{"side":"offer","event_time":"2026-07-15T03:40:03.803292Z","price_level":"64633.59","new_quantity":"0.12378505"},{"side":"offer","event_time":"2026-07-15T03:40:03.803292Z","price_level":"64633.63","new_quantity":"0.04656107"},{"side":"offer","event_time":"2026-07-15T03:40:03.803292Z","price_level":"64634","new_quantity":"0.0222"},{"side":"offer","event_time":"2026-07-15T03:40:03.803292Z","price_level":"64635.52","new_quantity":"0.000018"},{"side":"offer","event_time":"2026-07-15T03:40:03.803292Z","price_level":"64635.58","new_quantity":"0.16190624"},{"side":"offer","event_time":"2026-07-15T03:40:03.803292Z","price_level":"64635.59","new_quantity":"0.12378505"},{"side":"offer","event_time":"2026-07-15T03:40:03.803292Z","price_level":"64635.66","new_quantity":"0.00583"},{"side":"offer","event_time":"2026-07-15T03:40:03.803292Z","price_level":"64635.78","new_quantity":"0.0015533"},{"side":"offer","event_time":"2026-07-15T03:40:03.803292Z","price_level":"64637.06","new_quantity":"0.01947531"},{"side":"offer","event_time":"2026-07-15T03:40:03.803292Z","price_level":"64637.44","new_quantity":"0.00104465"},{"side":"offer","event_time":"2026-07-15T03:40:03.803292Z","price_level":"64637.59","new_quantity":"0.00153313"},{"side":"offer","event_time":"2026-07-15T03:40:03.803292Z","price_level":"64637.78","new_quantity":"0.00002322"},{"side":"offer","event_time":"2026-07-15T03:40:03.803292Z","price_level":"64638.71","new_quantity":"0.12378505"},{"side":"offer","event_time":"2026-07-15T03:40:03.803292Z","price_level":"64638.8","new_quantity":"0.07749639"},{"side":"offer","event_time":"2026-07-15T03:40:03.803292Z","price_level":"64638.97","new_quantity":"0.0015533"},{"side":"offer","event_time":"2026-07-15T03:40:03.803292Z","price_level":"64638.98","new_quantity":"0.04416045"},{"side":"offer","event_time":"2026-07-15T03:40:03.803292Z","price_level":"64639.2","new_quantity":"0.000018"},{"side":"offer","event_time":"2026-07-15T03:40:03.803292Z","price_level":"64639.5","new_quantity":"1"},{"side":"offer","event_time":"2026-07-15T03:40:03.803292Z","price_level":"64639.85","new_quantity":"0.00592"},{"side":"offer","event_time":"2026-07-15T03:40:03.803292Z","price_level":"64640.87","new_quantity":"0.02782749"},{"side":"offer","event_time":"2026-07-15T03:40:03.803292Z","price_level":"64641.44","new_quantity":"0.0194789"},{"side":"offer","event_time":"2026-07-15T03:40:03.803292Z","price_level":"64641.45","new_quantity":"0.06715226"},{"side":"offer","event_time":"2026-07-15T03:40:03.803292Z","price_level":"64641.99","new_quantity":"0.02930088"},{"side":"offer","event_time":"2026-07-15T03:40:03.803292Z","price_level":"64642.16","new_quantity":"0.0015533"},{"side":"offer","event_time":"2026-07-15T03:40:03.803292Z","price_level":"64642.88","new_quantity":"0.000018"},{"side":"offer","event_time":"2026-07-15T03:40:03.803292Z","price_level":"64643.97","new_quantity":"0.03093532"},{"side":"offer","event_time":"2026-07-15T03:40:03.803292Z","price_level":"64643.99","new_quantity":"0.04656107"},{"side":"offer","event_time":"2026-07-15T03:40:03.803292Z","price_level":"64644.23","new_quantity":"0.14"},{"side":"offer","event_time":"2026-07-15T03:40:03.803292Z","price_level":"64645.34","new_quantity":"0.6382099"},{"side":"offer","event_time":"2026-07-15T03:40:03.803292Z","price_level":"64645.35","new_quantity":"0.0015533"},{"side":"offer","event_time":"2026-07-15T03:40:03.803292Z","price_level":"64645.45","new_quantity":"0.04423948"},{"side":"offer","event_time":"2026-07-15T03:40:03.803292Z","price_level":"64645.66","new_quantity":"0.02"},{"side":"offer","event_time":"2026-07-15T03:40:03.803292Z","price_level":"64646.56","new_quantity":"0.000018"},{"side":"offer","event_time":"2026-07-15T03:40:03.803292Z","price_level":"64646.76","new_quantity":"0.04"},{"side":"offer","event_time":"2026-07-15T03:40:03.803292Z","price_level":"64647.42","new_quantity":"0.448614"},{"side":"offer","event_time":"2026-07-15T03:40:03.803292Z","price_level":"64648.54","new_quantity":"0.0015533"},{"side":"offer","event_time":"2026-07-15T03:40:03.803292Z","price_level":"64649.14","new_quantity":"0.03093532"},{"side":"offer","event_time":"2026-07-15T03:40:03.803292Z","price_level":"64649.87","new_quantity":"0.00306626"},{"side":"offer","event_time":"2026-07-15T03:40:03.803292Z","price_level":"64650.24","new_quantity":"0.000018"},{"side":"offer","event_time":"2026-07-15T03:40:03.803292Z","price_level":"64650.48","new_quantity":"0.04656107"},{"side":"offer","event_time":"2026-07-15T03:40:03.803292Z","price_level":"64651.73","new_quantity":"0.0015533"},{"side":"offer","event_time":"2026-07-15T03:40:03.803292Z","price_level":"64651.83","new_quantity":"0.06640642"},{"side":"offer","event_time":"2026-07-15T03:40:03.803292Z","price_level":"64653.92","new_quantity":"0.000018"},{"side":"offer","event_time":"2026-07-15T03:40:03.803292Z","price_level":"64653.98","new_quantity":"0.02724954"},{"side":"offer","event_time":"2026-07-15T03:40:03.803292Z","price_level":"64654.52","new_quantity":"0.0194418"},{"side":"offer","event_time":"2026-07-15T03:40:03.803292Z","price_level":"64654.64","new_quantity":"0.01615943"},{"side":"offer","event_time":"2026-07-15T03:40:03.803292Z","price_level":"64654.91","new_quantity":"0.00077371"},{"side":"offer","event_time":"2026-07-15T03:40:03.803292Z","price_level":"64654.92","new_quantity":"0.0015533"},{"side":"offer","event_time":"2026-07-15T03:40:03.803292Z","price_level":"64655.82","new_quantity":"0.03093532"},{"side":"offer","event_time":"2026-07-15T03:40:03.803292Z","price_level":"64657","new_quantity":"0.00003194"},{"side":"offer","event_time":"2026-07-15T03:40:03.803292Z","price_level":"64657.19","new_quantity":"0.00002321"},{"side":"offer","event_time":"2026-07-15T03:40:03.803292Z","price_level":"64657.29","new_quantity":"0.00158635"},{"side":"offer","event_time":"2026-07-15T03:40:03.803292Z","price_level":"64657.6","new_quantity":"0.000018"},{"side":"offer","event_time":"2026-07-15T03:40:03.803292Z","price_level":"64658.11","new_quantity":"0.0015533"},{"side":"offer","event_time":"2026-07-15T03:40:03.803292Z","price_level":"64661.11","new_quantity":"0.02873502"},{"side":"offer","event_time":"2026-07-15T03:40:03.803292Z","price_level":"64661.12","new_quantity":"0.04656107"},{"side":"offer","event_time":"2026-07-15T03:40:03.803292Z","price_level":"64661.28","new_quantity":"0.000018"},{"side":"offer","event_time":"2026-07-15T03:40:03.803292Z","price_level":"64661.3","new_quantity":"0.0015533"},{"side":"offer","event_time":"2026-07-15T03:40:03.803292Z","price_level":"64661.7","new_quantity":"0.00383282"},{"side":"offer","event_time":"2026-07-15T03:40:03.803292Z","price_level":"64661.86","new_quantity":"0.02642582"},{"side":"offer","event_time":"2026-07-15T03:40:03.803292Z","price_level":"64662.69","new_quantity":"0.06630774"},{"side":"offer","event_time":"2026-07-15T03:40:03.803292Z","price_level":"64664.48","new_quantity":"0.00077367"},{"side":"offer","event_time":"2026-07-15T03:40:03.803292Z","price_level":"64664.49","new_quantity":"0.0015533"},{"side":"offer","event_time":"2026-07-15T03:40:03.803292Z","price_level":"64664.96","new_quantity":"0.000018"},{"side":"offer","event_time":"2026-07-15T03:40:03.803292Z","price_level":"64665.13","new_quantity":"0.00780353"},{"side":"offer","event_time":"2026-07-15T03:40:03.803292Z","price_level":"64667.23","new_quantity":"1.91741638"},{"side":"offer","event_time":"2026-07-15T03:40:03.803292Z","price_level":"64667.68","new_quantity":"0.0015533"},{"side":"offer","event_time":"2026-07-15T03:40:03.803292Z","price_level":"64667.86","new_quantity":"0.03093532"},{"side":"offer","event_time":"2026-07-15T03:40:03.803292Z","price_level":"64668.22","new_quantity":"0.05767656"},{"side":"offer","event_time":"2026-07-15T03:40:03.803292Z","price_level":"64668.23","new_quantity":"0.04656107"},{"side":"offer","event_time":"2026-07-15T03:40:03.803292Z","price_level":"64668.45","new_quantity":"0.01615943"},{"side":"offer","event_time":"2026-07-15T03:40:03.803292Z","price_level":"64668.64","new_quantity":"0.000018"},{"side":"offer","event_time":"2026-07-15T03:40:03.803292Z","price_level":"64669.82","new_quantity":"0.01615943"},{"side":"offer","event_time":"2026-07-15T03:40:03.803292Z","price_level":"64670.53","new_quantity":"0.26305242"},{"side":"offer","event_time":"2026-07-15T03:40:03.803292Z","price_level":"64670.87","new_quantity":"0.0015533"},{"side":"offer","event_time":"2026-07-15T03:40:03.803292Z","price_level":"64671.76","new_quantity":"2.02549184"},{"side":"offer","event_time":"2026-07-15T03:40:03.803292Z","price_level":"64671.87","new_quantity":"0.0145874"},{"side":"offer","event_time":"2026-07-15T03:40:03.803292Z","price_level":"64672.32","new_quantity":"0.000018"},{"side":"offer","event_time":"2026-07-15T03:40:03.803292Z","price_level":"64672.43","new_quantity":"0.00114825"},{"side":"offer","event_time":"2026-07-15T03:40:03.803292Z","price_level":"64673.17","new_quantity":"0.0680824"},{"side":"offer","event_time":"2026-07-15T03:40:03.803292Z","price_level":"64673.82","new_quantity":"0.04656107"},{"side":"offer","event_time":"2026-07-15T03:40:03.803292Z","price_level":"64674.06","new_quantity":"0.0015533"},{"side":"offer","event_time":"2026-07-15T03:40:03.803292Z","price_level":"64675.95","new_quantity":"0.00077374"},{"side":"offer","event_time":"2026-07-15T03:40:03.803292Z","price_level":"64675.96","new_quantity":"0.01615943"},{"side":"offer","event_time":"2026-07-15T03:40:03.803292Z","price_level":"64675.99","new_quantity":"0.0001111"},{"side":"offer","event_time":"2026-07-15T03:40:03.803292Z","price_level":"64676","new_quantity":"0.000018"},{"side":"offer","event_time":"2026-07-15T03:40:03.803292Z","price_level":"64676.6","new_quantity":"0.00002321"},{"side":"offer","event_time":"2026-07-15T03:40:03.803292Z","price_level":"64677.25","new_quantity":"0.0015533"},{"side":"offer","event_time":"2026-07-15T03:40:03.803292Z","price_level":"64677.54","new_quantity":"0.03093532"},{"side":"offer","event_time":"2026-07-15T03:40:03.803292Z","price_level":"64679.68","new_quantity":"0.000018"}]}]}
{"channel":"l2_data","timestamp":"2026-07-15T03:40:04.204764235Z","sequence_num":1,"events":[{"type":"update","product_id":"BTC-USD","updates":[{"side":"bid","event_time":"2026-07-15T03:40:03.853063Z","price_level":"64614.65","new_quantity":"0.210225"},{"side":"bid","event_time":"2026-07-15T03:40:03.853063Z","price_level":"64586.49","new_quantity":"0.16530195"},{"side":"bid","event_time":"2026-07-15T03:40:03.853063Z","price_level":"64548.39","new_quantity":"1.34886983"},{"side":"bid","event_time":"2026-07-15T03:40:03.853063Z","price_level":"64548.37","new_quantity":"0"},{"side":"bid","event_time":"2026-07-15T03:40:03.853063Z","price_level":"51691.72","new_quantity":"0"},{"side":"offer","event_time":"2026-07-15T03:40:03.853063Z","price_level":"64614.66","new_quantity":"0.0327306"},{"side":"offer","event_time":"2026-07-15T03:40:03.853063Z","price_level":"64619.41","new_quantity":"0.20808449"},{"side":"offer","event_time":"2026-07-15T03:40:03.853063Z","price_level":"64622.22","new_quantity":"0"},{"side":"offer","event_time":"2026-07-15T03:40:03.853063Z","price_level":"64645.32","new_quantity":"0.6382101"},{"side":"offer","event_time":"2026-07-15T03:40:03.853063Z","price_level":"64645.34","new_quantity":"0"},{"side":"offer","event_time":"2026-07-15T03:40:03.853063Z","price_level":"64671.74","new_quantity":"2.02549247"},{"side":"offer","event_time":"2026-07-15T03:40:03.853063Z","price_level":"64671.76","new_quantity":"0"}]}]}
{"channel":"l2_data","timestamp":"2026-07-15T03:40:04.205921564Z","sequence_num":2,"events":[{"type":"update","product_id":"BTC-USD","updates":[{"side":"bid","event_time":"2026-07-15T03:40:03.910918Z","price_level":"64604.95","new_quantity":"0.00077381"},{"side":"bid","event_time":"2026-07-15T03:40:03.910918Z","price_level":"64601.03","new_quantity":"0"},{"side":"bid","event_time":"2026-07-15T03:40:03.910918Z","price_level":"64589.32","new_quantity":"0"},{"side":"bid","event_time":"2026-07-15T03:40:03.910918Z","price_level":"56537.82","new_quantity":"0.0132912"},{"side":"offer","event_time":"2026-07-15T03:40:03.910918Z","price_level":"64614.66","new_quantity":"0.03187704"},{"side":"offer","event_time":"2026-07-15T03:40:03.910918Z","price_level":"64617.03","new_quantity":"0.00085356"},{"side":"offer","event_time":"2026-07-15T03:40:03.910918Z","price_level":"64618.81","new_quantity":"0.02"},{"side":"offer","event_time":"2026-07-15T03:40:03.910918Z","price_level":"64625.45","new_quantity":"0.07332"}]}]}
{"channel":"l2_data","timestamp":"2026-07-15T03:40:04.206847512Z","sequence_num":3,"events":[{"type":"update","product_id":"BTC-USD","updates":[{"side":"bid","event_time":"2026-07-15T03:40:03.974679Z","price_level":"56537.82","new_quantity":"0"}]}]}
{"channel":"subscriptions","timestamp":"2026-07-15T03:40:04.207177713Z","sequence_num":4,"events":[{"subscriptions":{"level2":["BTC-USD"]}}]}
{"channel":"l2_data","timestamp":"2026-07-15T03:40:04.207312618Z","sequence_num":5,"events":[{"type":"update","product_id":"BTC-USD","updates":[{"side":"bid","event_time":"2026-07-15T03:40:04.027333Z","price_level":"64614.65","new_quantity":"0.173925"},{"side":"bid","event_time":"2026-07-15T03:40:04.027333Z","price_level":"64614","new_quantity":"0"},{"side":"bid","event_time":"2026-07-15T03:40:04.027333Z","price_level":"64611","new_quantity":"0"},{"side":"offer","event_time":"2026-07-15T03:40:04.027333Z","price_level":"64617.78","new_quantity":"0.18449041"},{"side":"offer","event_time":"2026-07-15T03:40:04.027333Z","price_level":"64617.79","new_quantity":"0.12378505"},{"side":"offer","event_time":"2026-07-15T03:40:04.027333Z","price_level":"64617.8","new_quantity":"0"},{"side":"offer","event_time":"2026-07-15T03:40:04.027333Z","price_level":"64617.82","new_quantity":"0"},{"side":"offer","event_time":"2026-07-15T03:40:04.027333Z","price_level":"64619.41","new_quantity":"0.29940059"},{"side":"offer","event_time":"2026-07-15T03:40:04.027333Z","price_level":"64619.73","new_quantity":"0.12378505"},{"side":"offer","event_time":"2026-07-15T03:40:04.027333Z","price_level":"64621.99","new_quantity":"0.03093532"},{"side":"offer","event_time":"2026-07-15T03:40:04.027333Z","price_level":"64747.19","new_quantity":"0"}]}]}
{"channel":"market_trades","timestamp":"2026-07-15T03:40:04.207568942Z","sequence_num":6,"events":[{"type":"snapshot","trades":[{"product_id":"BTC-USD","trade_id":"1056309363","price":"64614.66","size":"0.0000881","time":"2026-07-15T03:40:03.837421Z","side":"SELL"},{"product_id":"BTC-USD","trade_id":"1056309362","price":"64614.65","size":"0.00000018","time":"2026-07-15T03:40:03.505205Z","side":"BUY"},{"product_id":"BTC-USD","trade_id":"1056309361","price":"64614.65","size":"0.00000002","time":"2026-07-15T03:40:03.503879Z","side":"BUY"},{"product_id":"BTC-USD","trade_id":"1056309360","price":"64614.65","size":"0.0000001","time":"2026-07-15T03:40:02.815214Z","side":"BUY"},{"product_id":"BTC-USD","trade_id":"1056309359","price":"64614.66","size":"0.00000814","time":"2026-07-15T03:40:02.775302Z","side":"SELL"},{"product_id":"BTC-USD","trade_id":"1056309358","price":"64614.65","size":"0.00000003","time":"2026-07-15T03:40:02.4369Z","side":"BUY"},{"product_id":"BTC-USD","trade_id":"1056309357","price":"64614.65","size":"0.00000002","time":"2026-07-15T03:40:02.435976Z","side":"BUY"},{"product_id":"BTC-USD","trade_id":"1056309356","price":"64614.65","size":"0.00000002","time":"2026-07-15T03:40:01.773151Z","side":"BUY"},{"product_id":"BTC-USD","trade_id":"1056309355","price":"64614.65","size":"0.00000003","time":"2026-07-15T03:40:01.429667Z","side":"BUY"},{"product_id":"BTC-USD","trade_id":"1056309354","price":"64614.65","size":"0.00000002","time":"2026-07-15T03:40:01.347609Z","side":"BUY"},{"product_id":"BTC-USD","trade_id":"1056309353","price":"64614.65","size":"0.00000009","time":"2026-07-15T03:40:00.754155Z","side":"BUY"},{"product_id":"BTC-USD","trade_id":"1056309352","price":"64614.65","size":"0.00000006","time":"2026-07-15T03:40:00.308012Z","side":"BUY"},{"product_id":"BTC-USD","trade_id":"1056309351","price":"64614.65","size":"0.00000001","time":"2026-07-15T03:40:00.248427Z","side":"BUY"},{"product_id":"BTC-USD","trade_id":"1056309350","price":"64614.65","size":"0.00000003","time":"2026-07-15T03:40:00.10821Z","side":"BUY"},{"product_id":"BTC-USD","trade_id":"1056309349","price":"64614.65","size":"0.00000004","time":"2026-07-15T03:39:59.705719Z","side":"BUY"},{"product_id":"BTC-USD","trade_id":"1056309348","price":"64614.65","size":"0.00000004","time":"2026-07-15T03:39:59.287552Z","side":"BUY"},{"product_id":"BTC-USD","trade_id":"1056309347","price":"64614.65","size":"0.00000015","time":"2026-07-15T03:39:59.137201Z","side":"BUY"},{"product_id":"BTC-USD","trade_id":"1056309346","price":"64614.66","size":"0.00049147","time":"2026-07-15T03:39:58.758549Z","side":"SELL"},{"product_id":"BTC-USD","trade_id":"1056309345","price":"64614.66","size":"0.00023941","time":"2026-07-15T03:39:58.758549Z","side":"SELL"},{"product_id":"BTC-USD","trade_id":"1056309344","price":"64614.66","size":"0.00071841","time":"2026-07-15T03:39:58.758549Z","side":"SELL"},{"product_id":"BTC-USD","trade_id":"1056309343","price":"64614.66","size":"0.00003002","time":"2026-07-15T03:39:58.758549Z","side":"SELL"},{"product_id":"BTC-USD","trade_id":"1056309342","price":"64614.66","size":"0.00005989","time":"2026-07-15T03:39:58.758549Z","side":"SELL"},{"product_id":"BTC-USD","trade_id":"1056309341","price":"64614.66","size":"0.00168522","time":"2026-07-15T03:39:58.754277Z","side":"SELL"},{"product_id":"BTC-USD","trade_id":"1056309340","price":"64614.65","size":"0.00000017","time":"2026-07-15T03:39:58.668073Z","side":"BUY"},{"product_id":"BTC-USD","trade_id":"1056309339","price":"64614.65","size":"0.00000007","time":"2026-07-15T03:39:58.251293Z","side":"BUY"},{"product_id":"BTC-USD","trade_id":"1056309338","price":"64614.65","size":"0.00000038","time":"2026-07-15T03:39:58.079537Z","side":"BUY"},{"product_id":"BTC-USD","trade_id":"1056309337","price":"64614.65","size":"0.00000011","time":"2026-07-15T03:39:57.611888Z","side":"BUY"},{"product_id":"BTC-USD","trade_id":"1056309336","price":"64614.65","size":"0.00000006","time":"2026-07-15T03:39:57.244624Z","side":"BUY"},{"product_id":"BTC-USD","trade_id":"1056309335","price":"64614.66","size":"0.00022015","time":"2026-07-15T03:39:56.871326Z","side":"SELL"},{"product_id":"BTC-USD","trade_id":"1056309334","price":"64614.65","size":"0.00000003","time":"2026-07-15T03:39:56.836637Z","side":"BUY"},{"product_id":"BTC-USD","trade_id":"1056309333","price":"64614.65","size":"0.00000008","time":"2026-07-15T03:39:56.57226Z","side":"BUY"},{"product_id":"BTC-USD","trade_id":"1056309332","price":"64614.65","size":"0.00000007","time":"2026-07-15T03:39:55.791975Z","side":"BUY"},{"product_id":"BTC-USD","trade_id":"1056309331","price":"64614.65","size":"0.00000001","time":"2026-07-15T03:39:55.696855Z","side":"BUY"},{"product_id":"BTC-USD","trade_id":"1056309330","price":"64614.65","size":"0.00000003","time":"2026-07-15T03:39:55.550871Z","side":"BUY"},{"product_id":"BTC-USD","trade_id":"1056309329","price":"64614.66","size":"0.00107241","time":"2026-07-15T03:39:55.19847Z","side":"SELL"},{"product_id":"BTC-USD","trade_id":"1056309328","price":"64614.65","size":"0.00000011","time":"2026-07-15T03:39:54.906449Z","side":"BUY"},{"product_id":"BTC-USD","trade_id":"1056309327","price":"64614.65","size":"0.00000003","time":"2026-07-15T03:39:54.816979Z","side":"BUY"},{"product_id":"BTC-USD","trade_id":"1056309326","price":"64614.66","size":"0.00011894","time":"2026-07-15T03:39:54.767731Z","side":"SELL"},{"product_id":"BTC-USD","trade_id":"1056309325","price":"64614.66","size":"0.00011994","time":"2026-07-15T03:39:54.767731Z","side":"SELL"},{"product_id":"BTC-USD","trade_id":"1056309324","price":"64614.66","size":"0.0001221","time":"2026-07-15T03:39:54.767731Z","side":"SELL"},{"product_id":"BTC-USD","trade_id":"1056309323","price":"64614.65","size":"0.00000003","time":"2026-07-15T03:39:54.506036Z","side":"BUY"},{"product_id":"BTC-USD","trade_id":"1056309322","price":"64614.65","size":"0.00000007","time":"2026-07-15T03:39:53.876431Z","side":"BUY"},{"product_id":"BTC-USD","trade_id":"1056309321","price":"64614.65","size":"0.00000003","time":"2026-07-15T03:39:53.821708Z","side":"BUY"},{"product_id":"BTC-USD","trade_id":"1056309320","price":"64613.45","size":"0.00023957","time":"2026-07-15T03:39:53.558627Z","side":"SELL"},{"product_id":"BTC-USD","trade_id":"1056309319","price":"64613.45","size":"0.01298992","time":"2026-07-15T03:39:53.558627Z","side":"SELL"},{"product_id":"BTC-USD","trade_id":"1056309318","price":"64613.45","size":"0.00026693","time":"2026-07-15T03:39:53.558627Z","side":"SELL"},{"product_id":"BTC-USD","trade_id":"1056309317","price":"64613.44","size":"0.00000004","time":"2026-07-15T03:39:53.403971Z","side":"BUY"},{"product_id":"BTC-USD","trade_id":"1056309316","price":"64613.44","size":"0.00000009","time":"2026-07-15T03:39:52.804659Z","side":"BUY"},{"product_id":"BTC-USD","trade_id":"1056309315","price":"64613.44","size":"0.00000003","time":"2026-07-15T03:39:52.789406Z","side":"BUY"},{"product_id":"BTC-USD","trade_id":"1056309314","price":"64613.45","size":"0.00045165","time":"2026-07-15T03:39:52.580116Z","side":"SELL"},{"product_id":"BTC-USD","trade_id":"1056309313","price":"64613.45","size":"0.00003048","time":"2026-07-15T03:39:52.580116Z","side":"SELL"},{"product_id":"BTC-USD","trade_id":"1056309312","price":"64613.45","size":"0.00006097","time":"2026-07-15T03:39:52.580116Z","side":"SELL"},{"product_id":"BTC-USD","trade_id":"1056309311","price":"64613.44","size":"0.00464284","time":"2026-07-15T03:39:52.575768Z","side":"BUY"},{"product_id":"BTC-USD","trade_id":"1056309310","price":"64613.44","size":"0.00000003","time":"2026-07-15T03:39:52.382518Z","side":"BUY"},{"product_id":"BTC-USD","trade_id":"1056309309","price":"64613.44","size":"0.00000001","time":"2026-07-15T03:39:51.901568Z","side":"BUY"},{"product_id":"BTC-USD","trade_id":"1056309308","price":"64613.44","size":"0.00000003","time":"2026-07-15T03:39:51.778346Z","side":"BUY"},{"product_id":"BTC-USD","trade_id":"1056309307","price":"64613.44","size":"0.00000005","time":"2026-07-15T03:39:51.753929Z","side":"BUY"},{"product_id":"BTC-USD","trade_id":"1056309306","price":"64613.45","size":"0.00022018","time":"2026-07-15T03:39:51.674656Z","side":"SELL"},{"product_id":"BTC-USD","trade_id":"1056309305","price":"64613.44","size":"0.00000004","time":"2026-07-15T03:39:51.254912Z","side":"BUY"},{"product_id":"BTC-USD","trade_id":"1056309304","price":"64613.44","size":"0.00057498","time":"2026-07-15T03:39:51.213125Z","side":"BUY"},{"product_id":"BTC-USD","trade_id":"1056309303","price":"64613.44","size":"0.000018","time":"2026-07-15T03:39:51.213125Z","side":"BUY"},{"product_id":"BTC-USD","trade_id":"1056309302","price":"64613.44","size":"0.0001885","time":"2026-07-15T03:39:51.213125Z","side":"BUY"},{"product_id":"BTC-USD","trade_id":"1056309301","price":"64613.44","size":"0.0000001","time":"2026-07-15T03:39:50.739507Z","side":"BUY"},{"product_id":"BTC-USD","trade_id":"1056309300","price":"64613.44","size":"0.00000004","time":"2026-07-15T03:39:50.719279Z","side":"BUY"},{"product_id":"BTC-USD","trade_id":"1056309299","price":"64613.44","size":"0.00000002","time":"2026-07-15T03:39:49.779685Z","side":"BUY"},{"product_id":"BTC-USD","trade_id":"1056309298","price":"64614.65","size":"0.00773818","time":"2026-07-15T03:39:49.745065Z","side":"BUY"},{"product_id":"BTC-USD","trade_id":"1056309297","price":"64614.65","size":"0.02366004","time":"2026-07-15T03:39:49.745065Z","side":"BUY"},{"product_id":"BTC-USD","trade_id":"1056309296","price":"64614.65","size":"0.09999992","time":"2026-07-15T03:39:49.745065Z","side":"BUY"},{"product_id":"BTC-USD","trade_id":"1056309295","price":"64614.65","size":"0.00000005","time":"2026-07-15T03:39:49.730736Z","side":"BUY"},{"product_id":"BTC-USD","trade_id":"1056309294","price":"64614.65","size":"0.00000003","time":"2026-07-15T03:39:49.728324Z","side":"BUY"},{"product_id":"BTC-USD","trade_id":"1056309293","price":"64614.65","size":"0.00007707","time":"2026-07-15T03:39:49.484105Z","side":"BUY"},{"product_id":"BTC-USD","trade_id":"1056309292","price":"64614.65","size":"0.00000003","time":"2026-07-15T03:39:48.709704Z","side":"BUY"},{"product_id":"BTC-USD","trade_id":"1056309291","price":"64616.27","size":"0.00000015","time":"2026-07-15T03:39:48.701252Z","side":"BUY"},{"product_id":"BTC-USD","trade_id":"1056309290","price":"64617.89","size":"0.00000014","time":"2026-07-15T03:39:48.689761Z","side":"BUY"},{"product_id":"BTC-USD","trade_id":"1056309289","price":"64620.64","size":"0.0000273","time":"2026-07-15T03:39:48.228606Z","side":"BUY"},{"product_id":"BTC-USD","trade_id":"1056309288","price":"64620.64","size":"0.0101536","time":"2026-07-15T03:39:48.228606Z","side":"BUY"},{"product_id":"BTC-USD","trade_id":"1056309287","price":"64620.64","size":"0.0096928","time":"2026-07-15T03:39:48.228606Z","side":"BUY"},{"product_id":"BTC-USD","trade_id":"1056309286","price":"64620.64","size":"0.00212346","time":"2026-07-15T03:39:48.228606Z","side":"BUY"},{"product_id":"BTC-USD","trade_id":"1056309285","price":"64620.8","size":"0.02552609","time":"2026-07-15T03:39:48.180933Z","side":"BUY"},{"product_id":"BTC-USD","trade_id":"1056309284","price":"64620.8","size":"0.0100969","time":"2026-07-15T03:39:48.180933Z","side":"BUY"},{"product_id":"BTC-USD","trade_id":"1056309283","price":"64620.8","size":"0.00003849","time":"2026-07-15T03:39:48.180933Z","side":"BUY"},{"product_id":"BTC-USD","trade_id":"1056309282","price":"64620.8","size":"0.00000001","time":"2026-07-15T03:39:48.053901Z","side":"BUY"},{"product_id":"BTC-USD","trade_id":"1056309281","price":"64620.8","size":"0.00000003","time":"2026-07-15T03:39:47.705115Z","side":"BUY"},{"product_id":"BTC-USD","trade_id":"1056309280","price":"64620.8","size":"0.00000009","time":"2026-07-15T03:39:47.656642Z","side":"BUY"},{"product_id":"BTC-USD","trade_id":"1056309279","price":"64620.8","size":"0.00000004","time":"2026-07-15T03:39:47.503202Z","side":"BUY"},{"product_id":"BTC-USD","trade_id":"1056309278","price":"64620.8","size":"0.00000003","time":"2026-07-15T03:39:46.620162Z","side":"BUY"},{"product_id":"BTC-USD","trade_id":"1056309277","price":"64620.8","size":"0.00000006","time":"2026-07-15T03:39:46.468549Z","side":"BUY"},{"product_id":"BTC-USD","trade_id":"1056309276","price":"64620.8","size":"0.00000011","time":"2026-07-15T03:39:46.364951Z","side":"BUY"},{"product_id":"BTC-USD","trade_id":"1056309275","price":"64620.81","size":"0.01547256","time":"2026-07-15T03:39:46.327378Z","side":"SELL"},{"product_id":"BTC-USD","trade_id":"1056309274","price":"64620.8","size":"0.00000004","time":"2026-07-15T03:39:45.537595Z","side":"BUY"},{"product_id":"BTC-USD","trade_id":"1056309273","price":"64620.8","size":"0.00000012","time":"2026-07-15T03:39:45.440269Z","side":"BUY"},{"product_id":"BTC-USD","trade_id":"1056309272","price":"64620.8","size":"0.00000006","time":"2026-07-15T03:39:45.298775Z","side":"BUY"},{"product_id":"BTC-USD","trade_id":"1056309271","price":"64620.8","size":"0.00000007","time":"2026-07-15T03:39:44.479697Z","side":"BUY"},{"product_id":"BTC-USD","trade_id":"1056309270","price":"64620.8","size":"0.00000006","time":"2026-07-15T03:39:44.3776Z","side":"BUY"},{"product_id":"BTC-USD","trade_id":"1056309269","price":"64620.8","size":"0.00000004","time":"2026-07-15T03:39:44.317647Z","side":"BUY"},{"product_id":"BTC-USD","trade_id":"1056309268","price":"64620.81","size":"0.00014936","time":"2026-07-15T03:39:44.293662Z","side":"SELL"},{"product_id":"BTC-USD","trade_id":"1056309267","price":"64620.8","size":"0.00000001","time":"2026-07-15T03:39:43.700177Z","side":"BUY"},{"product_id":"BTC-USD","trade_id":"1056309266","price":"64620.8","size":"0.00000008","time":"2026-07-15T03:39:43.438182Z","side":"BUY"},{"product_id":"BTC-USD","trade_id":"1056309265","price":"64620.8","size":"0.00000003","time":"2026-07-15T03:39:43.312955Z","side":"BUY"},{"product_id":"BTC-USD","trade_id":"1056309264","price":"64620.8","size":"0.00000011","time":"2026-07-15T03:39:43.281139Z","side":"BUY"}]}]}
{"channel":"subscriptions","timestamp":"2026-07-15T03:40:04.207679834Z","sequence_num":7,"events":[{"subscriptions":{"level2":["BTC-USD"],"market_trades":["BTC-USD"]}}]}
{"channel":"l2_data","timestamp":"2026-07-15T03:40:04.213609872Z","sequence_num":8,"events":[{"type":"update","product_id":"BTC-USD","updates":[{"side":"bid","event_time":"2026-07-15T03:40:04.102632Z","price_level":"64614.65","new_quantity":"0.02228485"},{"side":"bid","event_time":"2026-07-15T03:40:04.102632Z","price_level":"64613.64","new_quantity":"0"},{"side":"bid","event_time":"2026-07-15T03:40:04.102632Z","price_level":"64613.03","new_quantity":"0"},{"side":"bid","event_time":"2026-07-15T03:40:04.102632Z","price_level":"64612.59","new_quantity":"0"},{"side":"bid","event_time":"2026-07-15T03:40:04.102632Z","price_level":"64612","new_quantity":"0.0257"},{"side":"bid","event_time":"2026-07-15T03:40:04.102632Z","price_level":"64611.01","new_quantity":"0"},{"side":"bid","event_time":"2026-07-15T03:40:04.102632Z","price_level":"64610.85","new_quantity":"0"},{"side":"bid","event_time":"2026-07-15T03:40:04.102632Z","price_level":"64610.46","new_quantity":"0"},{"side":"bid","event_time":"2026-07-15T03:40:04.102632Z","price_level":"64610.42","new_quantity":"0"},{"side":"bid","event_time":"2026-07-15T03:40:04.102632Z","price_level":"64610.41","new_quantity":"0"},{"side":"bid","event_time":"2026-07-15T03:40:04.102632Z","price_level":"64610.26","new_quantity":"0"},{"side":"bid","event_time":"2026-07-15T03:40:04.102632Z","price_level":"64609.51","new_quantity":"0"},{"side":"bid","event_time":"2026-07-15T03:40:04.102632Z","price_level":"64609.38","new_quantity":"0.07749639"},{"side":"bid","event_time":"2026-07-15T03:40:04.102632Z","price_level":"64609.37","new_quantity":"0"},{"side":"bid","event_time":"2026-07-15T03:40:04.102632Z","price_level":"64609.13","new_quantity":"0"},{"side":"bid","event_time":"2026-07-15T03:40:04.102632Z","price_level":"64608.2","new_quantity":"0"},{"side":"bid","event_time":"2026-07-15T03:40:04.102632Z","price_level":"64608.02","new_quantity":"0"},{"side":"bid","event_time":"2026-07-15T03:40:04.102632Z","price_level":"64607.82","new_quantity":"0.15478001"},{"side":"bid","event_time":"2026-07-15T03:40:04.102632Z","price_level":"64607.4","new_quantity":"0.12378505"},{"side":"bid","event_time":"2026-07-15T03:40:04.102632Z","price_level":"64607.07","new_quantity":"0"},{"side":"bid","event_time":"2026-07-15T03:40:04.102632Z","price_level":"64605.01","new_quantity":"0"},{"side":"bid","event_time":"2026-07-15T03:40:04.102632Z","price_level":"64604.72","new_quantity":"0"},{"side":"bid","event_time":"2026-07-15T03:40:04.102632Z","price_level":"64603.88","new_quantity":"0"},{"side":"bid","event_time":"2026-07-15T03:40:04.102632Z","price_level":"64603.52","new_quantity":"0.12378505"},{"side":"bid","event_time":"2026-07-15T03:40:04.102632Z","price_level":"64603.51","new_quantity":"0"},{"side":"bid","event_time":"2026-07-15T03:40:04.102632Z","price_level":"64603.15","new_quantity":"0.09451565"},{"side":"bid","event_time":"2026-07-15T03:40:04.102632Z","price_level":"64602.82","new_quantity":"0.035385"},{"side":"bid","event_time":"2026-07-15T03:40:04.102632Z","price_level":"64602.73","new_quantity":"0.07749639"},{"side":"bid","event_time":"2026-07-15T03:40:04.102632Z","price_level":"64602.72","new_quantity":"0"},{"side":"bid","event_time":"2026-07-15T03:40:04.102632Z","price_level":"64602.71","new_quantity":"0"},{"side":"bid","event_time":"2026-07-15T03:40:04.102632Z","price_level":"64602.02","new_quantity":"0"},{"side":"bid","event_time":"2026-07-15T03:40:04.102632Z","price_level":"64602.01","new_quantity":"0"},{"side":"bid","event_time":"2026-07-15T03:40:04.102632Z","price_level":"64601.71","new_quantity":"0"},{"side":"bid","event_time":"2026-07-15T03:40:04.102632Z","price_level":"64601.7","new_quantity":"0"},{"side":"bid","event_time":"2026-07-15T03:40:04.102632Z","price_level":"64600.69","new_quantity":"0"},{"side":"bid","event_time":"2026-07-15T03:40:04.102632Z","price_level":"64600.42","new_quantity":"0"},{"side":"bid","event_time":"2026-07-15T03:40:04.102632Z","price_level":"64599.19","new_quantity":"0"},{"side":"bid","event_time":"2026-07-15T03:40:04.102632Z","price_level":"64598.15","new_quantity":"0"},{"side":"bid","event_time":"2026-07-15T03:40:04.102632Z","price_level":"64597.5","new_quantity":"0"},{"side":"bid","event_time":"2026-07-15T03:40:04.102632Z","price_level":"64597.36","new_quantity":"0"},{"side":"bid","event_time":"2026-07-15T03:40:04.102632Z","price_level":"64596.93","new_quantity":"0.03093532"},{"side":"bid","event_time":"2026-07-15T03:40:04.102632Z","price_level":"64596.56","new_quantity":"0.05877141"},{"side":"bid","event_time":"2026-07-15T03:40:04.102632Z","price_level":"64596.55","new_quantity":"0"},{"side":"bid","event_time":"2026-07-15T03:40:04.102632Z","price_level":"64594.31","new_quantity":"0.05418743"},{"side":"bid","event_time":"2026-07-15T03:40:04.102632Z","price_level":"64593.17","new_quantity":"0.00583"},{"side":"bid","event_time":"2026-07-15T03:40:04.102632Z","price_level":"64592.78","new_quantity":"0.04656107"},{"side":"bid","event_time":"2026-07-15T03:40:04.102632Z","price_level":"64592.72","new_quantity":"0"},{"side":"bid","event_time":"2026-07-15T03:40:04.102632Z","price_level":"64592.52","new_quantity":"0"},{"side":"bid","event_time":"2026-07-15T03:40:04.102632Z","price_level":"64591.12","new_quantity":"0"},{"side":"bid","event_time":"2026-07-15T03:40:04.102632Z","price_level":"64590.92","new_quantity":"0"},{"side":"bid","event_time":"2026-07-15T03:40:04.102632Z","price_level":"64590.9","new_quantity":"0.00154637"},{"side":"bid","event_time":"2026-07-15T03:40:04.102632Z","price_level":"64587.93","new_quantity":"0"},{"side":"bid","event_time":"2026-07-15T03:40:04.102632Z","price_level":"64587.68","new_quantity":"0.00006329"},{"side":"bid","event_time":"2026-07-15T03:40:04.102632Z","price_level":"64586.07","new_quantity":"0"},{"side":"bid","event_time":"2026-07-15T03:40:04.102632Z","price_level":"64584.74","new_quantity":"0"},{"side":"bid","event_time":"2026-07-15T03:40:04.102632Z","price_level":"64584.45","new_quantity":"0.0077319"},{"side":"bid","event_time":"2026-07-15T03:40:04.102632Z","price_level":"64581.55","new_quantity":"0"},{"side":"bid","event_time":"2026-07-15T03:40:04.102632Z","price_level":"64578.36","new_quantity":"0"},{"side":"bid","event_time":"2026-07-15T03:40:04.102632Z","price_level":"64576.5","new_quantity":"1"},{"side":"bid","event_time":"2026-07-15T03:40:04.102632Z","price_level":"64561.92","new_quantity":"0.000018"},{"side":"bid","event_time":"2026-07-15T03:40:04.102632Z","price_level":"64560.7","new_quantity":"0"},{"side":"bid","event_time":"2026-07-15T03:40:04.102632Z","price_level":"64560.69","new_quantity":"0"},{"side":"bid","event_time":"2026-07-15T03:40:04.102632Z","price_level":"64555.14","new_quantity":"0.26308864"},{"side":"bid","event_time":"2026-07-15T03:40:04.102632Z","price_level":"64533.88","new_quantity":"0"},{"side":"bid","event_time":"2026-07-15T03:40:04.102632Z","price_level":"64384.57","new_quantity":"0"},{"side":"bid","event_time":"2026-07-15T03:40:04.102632Z","price_level":"64377.53","new_quantity":"0.00583"},{"side":"bid","event_time":"2026-07-15T03:40:04.102632Z","price_level":"64210.79","new_quantity":"0.01061683"},{"side":"bid","event_time":"2026-07-15T03:40:04.102632Z","price_level":"64169.79","new_quantity":"0"},{"side":"bid","event_time":"2026-07-15T03:40:04.102632Z","price_level":"63311.42","new_quantity":"0"},{"side":"bid","event_time":"2026-07-15T03:40:04.102632Z","price_level":"63306.59","new_quantity":"0.00583"},{"side":"bid","event_time":"2026-07-15T03:40:04.102632Z","price_level":"63306.14","new_quantity":"0"},{"side":"bid","event_time":"2026-07-15T03:40:04.102632Z","price_level":"63096.46","new_quantity":"0"},{"side":"offer","event_time":"2026-07-15T03:40:04.102632Z","price_level":"64614.66","new_quantity":"0.09198127"},{"side":"offer","event_time":"2026-07-15T03:40:04.102632Z","price_level":"64614.9","new_quantity":"0.04642741"},{"side":"offer","event_time":"2026-07-15T03:40:04.102632Z","price_level":"64616","new_quantity":"0.0257"},{"side":"offer","event_time":"2026-07-15T03:40:04.102632Z","price_level":"64616.5","new_quantity":"0.174351"},{"side":"offer","event_time":"2026-07-15T03:40:04.102632Z","price_level":"64616.64","new_quantity":"0"},{"side":"offer","event_time":"2026-07-15T03:40:04.102632Z","price_level":"64616.7","new_quantity":"0"},{"side":"offer","event_time":"2026-07-15T03:40:04.102632Z","price_level":"64617.77","new_quantity":"0.00319954"},{"side":"offer","event_time":"2026-07-15T03:40:04.102632Z","price_level":"64617.78","new_quantity":"0"},{"side":"offer","event_time":"2026-07-15T03:40:04.102632Z","price_level":"64617.79","new_quantity":"0"},{"side":"offer","event_time":"2026-07-15T03:40:04.102632Z","price_level":"64617.91","new_quantity":"0"},{"side":"offer","event_time":"2026-07-15T03:40:04.102632Z","price_level":"64618","new_quantity":"0.14950452"},{"side":"offer","event_time":"2026-07-15T03:40:04.102632Z","price_level":"64618.82","new_quantity":"0"},{"side":"offer","event_time":"2026-07-15T03:40:04.102632Z","price_level":"64619.72","new_quantity":"0.12378505"},{"side":"offer","event_time":"2026-07-15T03:40:04.102632Z","price_level":"64619.73","new_quantity":"0"},{"side":"offer","event_time":"2026-07-15T03:40:04.102632Z","price_level":"64619.83","new_quantity":"0"},{"side":"offer","event_time":"2026-07-15T03:40:04.102632Z","price_level":"64621.99","new_quantity":"0"},{"side":"offer","event_time":"2026-07-15T03:40:04.102632Z","price_level":"64622.22","new_quantity":"0.07332"},{"side":"offer","event_time":"2026-07-15T03:40:04.102632Z","price_level":"64622.68","new_quantity":"0"},{"side":"offer","event_time":"2026-07-15T03:40:04.102632Z","price_level":"64623.02","new_quantity":"0"},{"side":"offer","event_time":"2026-07-15T03:40:04.102632Z","price_level":"64623.18","new_quantity":"0.00772597"},{"side":"offer","event_time":"2026-07-15T03:40:04.102632Z","price_level":"64624.47","new_quantity":"0"},{"side":"offer","event_time":"2026-07-15T03:40:04.102632Z","price_level":"64626.21","new_quantity":"0"},{"side":"offer","event_time":"2026-07-15T03:40:04.102632Z","price_level":"64629.4","new_quantity":"0"},{"side":"offer","event_time":"2026-07-15T03:40:04.102632Z","price_level":"64632.59","new_quantity":"0"},{"side":"offer","event_time":"2026-07-15T03:40:04.102632Z","price_level":"64633.78","new_quantity":"0.00583"},{"side":"offer","event_time":"2026-07-15T03:40:04.102632Z","price_level":"64635.52","new_quantity":"0.000018"},{"side":"offer","event_time":"2026-07-15T03:40:04.102632Z","price_level":"64635.66","new_quantity":"0"},{"side":"offer","event_time":"2026-07-15T03:40:04.102632Z","price_level":"64635.78","new_quantity":"0"},{"side":"offer","event_time":"2026-07-15T03:40:04.102632Z","price_level":"64638.97","new_quantity":"0"},{"side":"offer","event_time":"2026-07-15T03:40:04.102632Z","price_level":"64639.5","new_quantity":"0"},{"side":"offer","event_time":"2026-07-15T03:40:04.102632Z","price_level":"64642.16","new_quantity":"0"},{"side":"offer","event_time":"2026-07-15T03:40:04.102632Z","price_level":"64644.23","new_quantity":"0"},{"side":"offer","event_time":"2026-07-15T03:40:04.102632Z","price_level":"64645.35","new_quantity":"0"},{"side":"offer","event_time":"2026-07-15T03:40:04.102632Z","price_level":"64648.54","new_quantity":"0"},{"side":"offer","event_time":"2026-07-15T03:40:04.102632Z","price_level":"64651.73","new_quantity":"0"},{"side":"offer","event_time":"2026-07-15T03:40:04.102632Z","price_level":"64654.92","new_quantity":"0"},{"side":"offer","event_time":"2026-07-15T03:40:04.102632Z","price_level":"64658.11","new_quantity":"0"},{"side":"offer","event_time":"2026-07-15T03:40:04.102632Z","price_level":"64660.5","new_quantity":"1"},{"side":"offer","event_time":"2026-07-15T03:40:04.102632Z","price_level":"64664.96","new_quantity":"0.45846407"},{"side":"offer","event_time":"2026-07-15T03:40:04.102632Z","price_level":"64664.97","new_quantity":"0.26308864"},{"side":"offer","event_time":"2026-07-15T03:40:04.102632Z","price_level":"64667.23","new_quantity":"1.43072124"},{"side":"offer","event_time":"2026-07-15T03:40:04.102632Z","price_level":"64670.53","new_quantity":"0"},{"side":"offer","event_time":"2026-07-15T03:40:04.102632Z","price_level":"64701.9","new_quantity":"0.01061683"},{"side":"offer","event_time":"2026-07-15T03:40:04.102632Z","price_level":"64849.18","new_quantity":"0.00583"},{"side":"offer","event_time":"2026-07-15T03:40:04.102632Z","price_level":"64850.49","new_quantity":"0"},{"side":"offer","event_time":"2026-07-15T03:40:04.102632Z","price_level":"65064.81","new_quantity":"0.00583"},{"side":"offer","event_time":"2026-07-15T03:40:04.102632Z","price_level":"65064.88","new_quantity":"0"},{"side":"offer","event_time":"2026-07-15T03:40:04.102632Z","price_level":"65064.95","new_quantity":"0"},{"side":"offer","event_time":"2026-07-15T03:40:04.102632Z","price_level":"65279.38","new_quantity":"0.00583"},{"side":"offer","event_time":"2026-07-15T03:40:04.102632Z","price_level":"65279.46","new_quantity":"0"},{"side":"offer","event_time":"2026-07-15T03:40:04.102632Z","price_level":"65493.02","new_quantity":"0"},{"side":"offer","event_time":"2026-07-15T03:40:04.102632Z","price_level":"65493.96","new_quantity":"0"},{"side":"offer","event_time":"2026-07-15T03:40:04.102632Z","price_level":"65494.18","new_quantity":"0.00583"},{"side":"offer","event_time":"2026-07-15T03:40:04.102632Z","price_level":"65708.17","new_quantity":"0"},{"side":"offer","event_time":"2026-07-15T03:40:04.102632Z","price_level":"65708.52","new_quantity":"0"},{"side":"offer","event_time":"2026-07-15T03:40:04.102632Z","price_level":"65708.61","new_quantity":"0.00583"},{"side":"offer","event_time":"2026-07-15T03:40:04.102632Z","price_level":"65922.99","new_quantity":"0"}]}]}
{"channel":"l2_data","timestamp":"2026-07-15T03:40:04.215243664Z","sequence_num":9,"events":[{"type":"update","product_id":"BTC-USD","updates":[{"side":"bid","event_time":"2026-07-15T03:40:04.14218Z","price_level":"64611.49","new_quantity":"0.12381698"},{"side":"bid","event_time":"2026-07-15T03:40:04.14218Z","price_level":"64610.6","new_quantity":"0"},{"side":"bid","event_time":"2026-07-15T03:40:04.14218Z","price_level":"64609.39","new_quantity":"0.12378505"},{"side":"bid","event_time":"2026-07-15T03:40:04.14218Z","price_level":"64604.31","new_quantity":"0.10393015"},{"side":"bid","event_time":"2026-07-15T03:40:04.14218Z","price_level":"64603.62","new_quantity":"0.03537608"},{"side":"bid","event_time":"2026-07-15T03:40:04.14218Z","price_level":"64602.82","new_quantity":"0"},{"side":"bid","event_time":"2026-07-15T03:40:04.14218Z","price_level":"64596.94","new_quantity":"0.00772597"},{"side":"bid","event_time":"2026-07-15T03:40:04.14218Z","price_level":"64586.71","new_quantity":"0"},{"side":"bid","event_time":"2026-07-15T03:40:04.14218Z","price_level":"64576.5","new_quantity":"0"},{"side":"bid","event_time":"2026-07-15T03:40:04.14218Z","price_level":"64533.88","new_quantity":"0.01061683"},{"side":"offer","event_time":"2026-07-15T03:40:04.14218Z","price_level":"64614.89","new_quantity":"0.00319954"},{"side":"offer","event_time":"2026-07-15T03:40:04.14218Z","price_level":"64617.77","new_quantity":"0"},{"side":"offer","event_time":"2026-07-15T03:40:04.14218Z","price_level":"64621.79","new_quantity":"0"},{"side":"offer","event_time":"2026-07-15T03:40:04.14218Z","price_level":"64622.66","new_quantity":"0.03093532"},{"side":"offer","event_time":"2026-07-15T03:40:04.14218Z","price_level":"64622.67","new_quantity":"0.13454845"},{"side":"offer","event_time":"2026-07-15T03:40:04.14218Z","price_level":"64625.45","new_quantity":"0"},{"side":"offer","event_time":"2026-07-15T03:40:04.14218Z","price_level":"64660.5","new_quantity":"0"},{"side":"offer","event_time":"2026-07-15T03:40:04.14218Z","price_level":"65024.99","new_quantity":"0"}]}]}
{"channel":"l2_data","timestamp":"2026-07-15T03:40:04.233583929Z","sequence_num":10,"events":[{"type":"update","product_id":"BTC-USD","updates":[{"side":"bid","event_time":"2026-07-15T03:40:04.187142Z","price_level":"64610.26","new_quantity":"0.0015533"},{"side":"bid","event_time":"2026-07-15T03:40:04.187142Z","price_level":"64609.5","new_quantity":"0.06"},{"side":"bid","event_time":"2026-07-15T03:40:04.187142Z","price_level":"64607.07","new_quantity":"0.0015533"},{"side":"bid","event_time":"2026-07-15T03:40:04.187142Z","price_level":"64606.5","new_quantity":"1"},{"side":"bid","event_time":"2026-07-15T03:40:04.187142Z","price_level":"64606.05","new_quantity":"0.04642741"},{"side":"bid","event_time":"2026-07-15T03:40:04.187142Z","price_level":"64603.88","new_quantity":"0.0015533"},{"side":"bid","event_time":"2026-07-15T03:40:04.187142Z","price_level":"64603.62","new_quantity":"0"},{"side":"bid","event_time":"2026-07-15T03:40:04.187142Z","price_level":"64600.69","new_quantity":"0.0015533"},{"side":"bid","event_time":"2026-07-15T03:40:04.187142Z","price_level":"64597.5","new_quantity":"0.0015533"},{"side":"bid","event_time":"2026-07-15T03:40:04.187142Z","price_level":"64594.31","new_quantity":"0.05574073"},{"side":"bid","event_time":"2026-07-15T03:40:04.187142Z","price_level":"64591.96","new_quantity":"0.14"},{"side":"bid","event_time":"2026-07-15T03:40:04.187142Z","price_level":"64591.12","new_quantity":"0.0015533"},{"side":"bid","event_time":"2026-07-15T03:40:04.187142Z","price_level":"64587.93","new_quantity":"0.0015533"},{"side":"bid","event_time":"2026-07-15T03:40:04.187142Z","price_level":"64584.74","new_quantity":"0.0015533"},{"side":"bid","event_time":"2026-07-15T03:40:04.187142Z","price_level":"64581.55","new_quantity":"0.0015533"},{"side":"bid","event_time":"2026-07-15T03:40:04.187142Z","price_level":"64578.36","new_quantity":"0.0015533"},{"side":"bid","event_time":"2026-07-15T03:40:04.187142Z","price_level":"56537.82","new_quantity":"0.0132912"},{"side":"offer","event_time":"2026-07-15T03:40:04.187142Z","price_level":"64614.66","new_quantity":"0.06463127"},{"side":"offer","event_time":"2026-07-15T03:40:04.187142Z","price_level":"64614.9","new_quantity":"0"},{"side":"offer","event_time":"2026-07-15T03:40:04.187142Z","price_level":"64615.74","new_quantity":"0.04642741"},{"side":"offer","event_time":"2026-07-15T03:40:04.187142Z","price_level":"64616.64","new_quantity":"0.0015533"},{"side":"offer","event_time":"2026-07-15T03:40:04.187142Z","price_level":"64619.83","new_quantity":"0.0015533"},{"side":"offer","event_time":"2026-07-15T03:40:04.187142Z","price_level":"64623.01","new_quantity":"0.00772597"},{"side":"offer","event_time":"2026-07-15T03:40:04.187142Z","price_level":"64623.02","new_quantity":"0.0015533"},{"side":"offer","event_time":"2026-07-15T03:40:04.187142Z","price_level":"64623.18","new_quantity":"0"},{"side":"offer","event_time":"2026-07-15T03:40:04.187142Z","price_level":"64626.21","new_quantity":"0.0015533"},{"side":"offer","event_time":"2026-07-15T03:40:04.187142Z","price_level":"64629.4","new_quantity":"0.0015533"},{"side":"offer","event_time":"2026-07-15T03:40:04.187142Z","price_level":"64632.59","new_quantity":"0.0015533"},{"side":"offer","event_time":"2026-07-15T03:40:04.187142Z","price_level":"64635.78","new_quantity":"0.0015533"},{"side":"offer","event_time":"2026-07-15T03:40:04.187142Z","price_level":"64638.97","new_quantity":"0.0015533"},{"side":"offer","event_time":"2026-07-15T03:40:04.187142Z","price_level":"64639.63","new_quantity":"0.14"},{"side":"offer","event_time":"2026-07-15T03:40:04.187142Z","price_level":"64641","new_quantity":"1"},{"side":"offer","event_time":"2026-07-15T03:40:04.187142Z","price_level":"64642.16","new_quantity":"0.0015533"},{"side":"offer","event_time":"2026-07-15T03:40:04.187142Z","price_level":"64645.35","new_quantity":"0.0015533"},{"side":"offer","event_time":"2026-07-15T03:40:04.187142Z","price_level":"64648.54","new_quantity":"0.0015533"},{"side":"offer","event_time":"2026-07-15T03:40:04.187142Z","price_level":"64651.73","new_quantity":"0.0015533"},{"side":"offer","event_time":"2026-07-15T03:40:04.187142Z","price_level":"64654.91","new_quantity":"0"},{"side":"offer","event_time":"2026-07-15T03:40:04.187142Z","price_level":"64654.92","new_quantity":"0.0015533"},{"side":"offer","event_time":"2026-07-15T03:40:04.187142Z","price_level":"64658.11","new_quantity":"0.0015533"},{"side":"offer","event_time":"2026-07-15T03:40:04.187142Z","price_level":"64743.17","new_quantity":"0.04441"}]}]}
{"channel":"l2_data","timestamp":"2026-07-15T03:40:04.280319447Z","sequence_num":11,"events":[{"type":"update","product_id":"BTC-USD","updates":[{"side":"bid","event_time":"2026-07-15T03:40:04.234353Z","price_level":"64609.5","new_quantity":"1.06"},{"side":"bid","event_time":"2026-07-15T03:40:04.234353Z","price_level":"64606.5","new_quantity":"0"},{"side":"bid","event_time":"2026-07-15T03:40:04.234353Z","price_level":"64595.94","new_quantity":"0.02228485"},{"side":"bid","event_time":"2026-07-15T03:40:04.234353Z","price_level":"64584.75","new_quantity":"0"},{"side":"bid","event_time":"2026-07-15T03:40:04.234353Z","price_level":"64584.5","new_quantity":"0.00077372"},{"side":"bid","event_time":"2026-07-15T03:40:04.234353Z","price_level":"64210.79","new_quantity":"0"},{"side":"offer","event_time":"2026-07-15T03:40:04.234353Z","price_level":"64641","new_quantity":"0"},{"side":"offer","event_time":"2026-07-15T03:40:04.234353Z","price_level":"64655.81","new_quantity":"0.00077371"}]}]}
{"channel":"l2_data","timestamp":"2026-07-15T03:40:04.332128575Z","sequence_num":12,"events":[{"type":"update","product_id":"BTC-USD","updates":[{"side":"bid","event_time":"2026-07-15T03:40:04.281491Z","price_level":"56537.82","new_quantity":"0"}]}]}
{"channel":"l2_data","timestamp":"2026-07-15T03:40:04.381492796Z","sequence_num":13,"events":[{"type":"update","product_id":"BTC-USD","updates":[{"side":"bid","event_time":"2026-07-15T03:40:04.331838Z","price_level":"64612","new_quantity":"0"},{"side":"bid","event_time":"2026-07-15T03:40:04.331838Z","price_level":"64611.49","new_quantity":"0"},{"side":"bid","event_time":"2026-07-15T03:40:04.331838Z","price_level":"64610.33","new_quantity":"0"},{"side":"bid","event_time":"2026-07-15T03:40:04.331838Z","price_level":"64610.26","new_quantity":"0"},{"side":"bid","event_time":"2026-07-15T03:40:04.331838Z","price_level":"64610","new_quantity":"0"},{"side":"bid","event_time":"2026-07-15T03:40:04.331838Z","price_level":"64609.5","new_quantity":"0"},{"side":"bid","event_time":"2026-07-15T03:40:04.331838Z","price_level":"64609.39","new_quantity":"0"},{"side":"bid","event_time":"2026-07-15T03:40:04.331838Z","price_level":"64609.38","new_quantity":"0"},{"side":"bid","event_time":"2026-07-15T03:40:04.331838Z","price_level":"64608.01","new_quantity":"0.04656107"},{"side":"bid","event_time":"2026-07-15T03:40:04.331838Z","price_level":"64607.82","new_quantity":"0"},{"side":"bid","event_time":"2026-07-15T03:40:04.331838Z","price_level":"64607.4","new_quantity":"0"},{"side":"bid","event_time":"2026-07-15T03:40:04.331838Z","price_level":"64607.07","new_quantity":"0"},{"side":"bid","event_time":"2026-07-15T03:40:04.331838Z","price_level":"64606.05","new_quantity":"0"},{"side":"bid","event_time":"2026-07-15T03:40:04.331838Z","price_level":"64605.6","new_quantity":"0.15478533"},{"side":"bid","event_time":"2026-07-15T03:40:04.331838Z","price_level":"64605.03","new_quantity":"0.04642741"},{"side":"bid","event_time":"2026-07-15T03:40:04.331838Z","price_level":"64603.88","new_quantity":"0"},{"side":"bid","event_time":"2026-07-15T03:40:04.331838Z","price_level":"64601.7","new_quantity":"0"},{"side":"bid","event_time":"2026-07-15T03:40:04.331838Z","price_level":"64600.69","new_quantity":"0"},{"side":"bid","event_time":"2026-07-15T03:40:04.331838Z","price_level":"64597.5","new_quantity":"0"},{"side":"bid","event_time":"2026-07-15T03:40:04.331838Z","price_level":"64594.31","new_quantity":"0.05418743"},{"side":"bid","event_time":"2026-07-15T03:40:04.331838Z","price_level":"64591.12","new_quantity":"0"},{"side":"bid","event_time":"2026-07-15T03:40:04.331838Z","price_level":"64590.9","new_quantity":"0"},{"side":"bid","event_time":"2026-07-15T03:40:04.331838Z","price_level":"64588.75","new_quantity":"0.00154642"},{"side":"bid","event_time":"2026-07-15T03:40:04.331838Z","price_level":"64587.93","new_quantity":"0"},{"side":"bid","event_time":"2026-07-15T03:40:04.331838Z","price_level":"64584.74","new_quantity":"0"},{"side":"bid","event_time":"2026-07-15T03:40:04.331838Z","price_level":"64584.45","new_quantity":"0"},{"side":"bid","event_time":"2026-07-15T03:40:04.331838Z","price_level":"64582.5","new_quantity":"1"},{"side":"bid","event_time":"2026-07-15T03:40:04.331838Z","price_level":"64582.3","new_quantity":"0.00773215"},{"side":"bid","event_time":"2026-07-15T03:40:04.331838Z","price_level":"64581.15","new_quantity":"0.12378505"},{"side":"offer","event_time":"2026-07-15T03:40:04.331838Z","price_level":"64614.66","new_quantity":"0.18296725"},{"side":"offer","event_time":"2026-07-15T03:40:04.331838Z","price_level":"64615.27","new_quantity":"0.12380974"},{"side":"offer","event_time":"2026-07-15T03:40:04.331838Z","price_level":"64615.74","new_quantity":"0"},{"side":"offer","event_time":"2026-07-15T03:40:04.331838Z","price_level":"64616.5","new_quantity":"0"},{"side":"offer","event_time":"2026-07-15T03:40:04.331838Z","price_level":"64616.99","new_quantity":"0.16867648"},{"side":"offer","event_time":"2026-07-15T03:40:04.331838Z","price_level":"64617","new_quantity":"0.12378505"},{"side":"offer","event_time":"2026-07-15T03:40:04.331838Z","price_level":"64618","new_quantity":"0.0257"},{"side":"offer","event_time":"2026-07-15T03:40:04.331838Z","price_level":"64619.1","new_quantity":"0.02228485"},{"side":"offer","event_time":"2026-07-15T03:40:04.331838Z","price_level":"64619.74","new_quantity":"0"},{"side":"offer","event_time":"2026-07-15T03:40:04.331838Z","price_level":"64636.5","new_quantity":"1"},{"side":"offer","event_time":"2026-07-15T03:40:04.331838Z","price_level":"64655.81","new_quantity":"0"}]}]}
{"channel":"market_trades","timestamp":"2026-07-15T03:40:04.386235033Z","sequence_num":14,"events":[{"type":"update","trades":[{"product_id":"BTC-USD","trade_id":"1056309368","price":"64613.35","size":"0.00773834","time":"2026-07-15T03:40:04.352752Z","side":"BUY"},{"product_id":"BTC-USD","trade_id":"1056309367","price":"64613.44","size":"0.00015074","time":"2026-07-15T03:40:04.352752Z","side":"BUY"},{"product_id":"BTC-USD","trade_id":"1056309366","price":"64614.65","size":"0.00912219","time":"2026-07-15T03:40:04.352752Z","side":"BUY"},{"product_id":"BTC-USD","trade_id":"1056309365","price":"64614.65","size":"0.01313855","time":"2026-07-15T03:40:04.352752Z","side":"BUY"},{"product_id":"BTC-USD","trade_id":"1056309364","price":"64614.65","size":"0.00002411","time":"2026-07-15T03:40:04.352752Z","side":"BUY"}]}]}
{"channel":"l2_data","timestamp":"2026-07-15T03:40:04.446531702Z","sequence_num":15,"events":[{"type":"update","product_id":"BTC-USD","updates":[{"side":"bid","event_time":"2026-07-15T03:40:04.373668Z","price_level":"64614.65","new_quantity":"0"},{"side":"bid","event_time":"2026-07-15T03:40:04.373668Z","price_level":"64613.44","new_quantity":"0"},{"side":"bid","event_time":"2026-07-15T03:40:04.373668Z","price_level":"64613.35","new_quantity":"0"},{"side":"bid","event_time":"2026-07-15T03:40:04.373668Z","price_level":"64608.01","new_quantity":"0"},{"side":"bid","event_time":"2026-07-15T03:40:04.373668Z","price_level":"64608","new_quantity":"0"},{"side":"bid","event_time":"2026-07-15T03:40:04.373668Z","price_level":"64607.63","new_quantity":"0"},{"side":"bid","event_time":"2026-07-15T03:40:04.373668Z","price_level":"64606","new_quantity":"0.0257"},{"side":"bid","event_time":"2026-07-15T03:40:04.373668Z","price_level":"64605.6","new_quantity":"0"},{"side":"bid","event_time":"2026-07-15T03:40:04.373668Z","price_level":"64605.03","new_quantity":"0"},{"side":"bid","event_time":"2026-07-15T03:40:04.373668Z","price_level":"64604.97","new_quantity":"0"},{"side":"bid","event_time":"2026-07-15T03:40:04.373668Z","price_level":"64604.31","new_quantity":"0"},{"side":"bid","event_time":"2026-07-15T03:40:04.373668Z","price_level":"64603.52","new_quantity":"0"},{"side":"bid","event_time":"2026-07-15T03:40:04.373668Z","price_level":"64603.15","new_quantity":"0"},{"side":"bid","event_time":"2026-07-15T03:40:04.373668Z","price_level":"64603.14","new_quantity":"0"},{"side":"bid","event_time":"2026-07-15T03:40:04.373668Z","price_level":"64602.73","new_quantity":"0"},{"side":"bid","event_time":"2026-07-15T03:40:04.373668Z","price_level":"64599.77","new_quantity":"0"},{"side":"bid","event_time":"2026-07-15T03:40:04.373668Z","price_level":"64599.69","new_quantity":"0.04656107"},{"side":"bid","event_time":"2026-07-15T03:40:04.373668Z","price_level":"64598.43","new_quantity":"0.03093532"},{"side":"bid","event_time":"2026-07-15T03:40:04.373668Z","price_level":"64598.42","new_quantity":"0.048285"},{"side":"bid","event_time":"2026-07-15T03:40:04.373668Z","price_level":"64597.82","new_quantity":"0"},{"side":"bid","event_time":"2026-07-15T03:40:04.373668Z","price_level":"64596.94","new_quantity":"0"},{"side":"bid","event_time":"2026-07-15T03:40:04.373668Z","price_level":"64596.93","new_quantity":"0"},{"side":"bid","event_time":"2026-07-15T03:40:04.373668Z","price_level":"64592.79","new_quantity":"0.03093532"},{"side":"bid","event_time":"2026-07-15T03:40:04.373668Z","price_level":"64592.77","new_quantity":"0.12379885"},{"side":"bid","event_time":"2026-07-15T03:40:04.373668Z","price_level":"64591.96","new_quantity":"0"},{"side":"bid","event_time":"2026-07-15T03:40:04.373668Z","price_level":"64590.12","new_quantity":"0"},{"side":"bid","event_time":"2026-07-15T03:40:04.373668Z","price_level":"64586.49","new_quantity":"0"},{"side":"bid","event_time":"2026-07-15T03:40:04.373668Z","price_level":"64585.4","new_quantity":"0.1453604"},{"side":"bid","event_time":"2026-07-15T03:40:04.373668Z","price_level":"64585.39","new_quantity":"0"},{"side":"bid","event_time":"2026-07-15T03:40:04.373668Z","price_level":"64584","new_quantity":"0.000018"},{"side":"bid","event_time":"2026-07-15T03:40:04.373668Z","price_level":"64582.5","new_quantity":"0"},{"side":"bid","event_time":"2026-07-15T03:40:04.373668Z","price_level":"64581.55","new_quantity":"0"},{"side":"bid","event_time":"2026-07-15T03:40:04.373668Z","price_level":"64581.16","new_quantity":"0.09952691"},{"side":"bid","event_time":"2026-07-15T03:40:04.373668Z","price_level":"64581.14","new_quantity":"0"},{"side":"bid","event_time":"2026-07-15T03:40:04.373668Z","price_level":"64581.13","new_quantity":"0"},{"side":"bid","event_time":"2026-07-15T03:40:04.373668Z","price_level":"64579.33","new_quantity":"0.88567242"},{"side":"bid","event_time":"2026-07-15T03:40:04.373668Z","price_level":"64579.32","new_quantity":"0"},{"side":"bid","event_time":"2026-07-15T03:40:04.373668Z","price_level":"64578.36","new_quantity":"0"},{"side":"bid","event_time":"2026-07-15T03:40:04.373668Z","price_level":"64577.85","new_quantity":"1.05505117"},{"side":"bid","event_time":"2026-07-15T03:40:04.373668Z","price_level":"64577.25","new_quantity":"0.54874184"},{"side":"bid","event_time":"2026-07-15T03:40:04.373668Z","price_level":"64576.18","new_quantity":"0.60953447"},{"side":"bid","event_time":"2026-07-15T03:40:04.373668Z","price_level":"64559.79","new_quantity":"0.05013825"},{"side":"bid","event_time":"2026-07-15T03:40:04.373668Z","price_level":"64556.13","new_quantity":"0"},{"side":"bid","event_time":"2026-07-15T03:40:04.373668Z","price_level":"64556.12","new_quantity":"0"},{"side":"bid","event_time":"2026-07-15T03:40:04.373668Z","price_level":"64553.15","new_quantity":"0"},{"side":"bid","event_time":"2026-07-15T03:40:04.373668Z","price_level":"64551.34","new_quantity":"0.01060344"},{"side":"bid","event_time":"2026-07-15T03:40:04.373668Z","price_level":"64551.17","new_quantity":"0.00510417"},{"side":"bid","event_time":"2026-07-15T03:40:04.373668Z","price_level":"64550.88","new_quantity":"0.000018"},{"side":"bid","event_time":"2026-07-15T03:40:04.373668Z","price_level":"64548.39","new_quantity":"0"},{"side":"bid","event_time":"2026-07-15T03:40:04.373668Z","price_level":"64548.25","new_quantity":"0.17772383"},{"side":"bid","event_time":"2026-07-15T03:40:04.373668Z","price_level":"64543.02","new_quantity":"1.66671659"},{"side":"bid","event_time":"2026-07-15T03:40:04.373668Z","price_level":"64543.01","new_quantity":"1.34898226"},{"side":"bid","event_time":"2026-07-15T03:40:04.373668Z","price_level":"64542.98","new_quantity":"0"},{"side":"bid","event_time":"2026-07-15T03:40:04.373668Z","price_level":"64535.01","new_quantity":"1.12835208"},{"side":"bid","event_time":"2026-07-15T03:40:04.373668Z","price_level":"64533.58","new_quantity":"0"},{"side":"bid","event_time":"2026-07-15T03:40:04.373668Z","price_level":"64529.17","new_quantity":"2.15415413"},{"side":"bid","event_time":"2026-07-15T03:40:04.373668Z","price_level":"64337.07","new_quantity":"1.39888243"},{"side":"offer","event_time":"2026-07-15T03:40:04.373668Z","price_level":"64609.77","new_quantity":"0.43224481"},{"side":"offer","event_time":"2026-07-15T03:40:04.373668Z","price_level":"64609.99","new_quantity":"0.0306858"},{"side":"offer","event_time":"2026-07-15T03:40:04.373668Z","price_level":"64610","new_quantity":"0.0257"},{"side":"offer","event_time":"2026-07-15T03:40:04.373668Z","price_level":"64610.01","new_quantity":"0.04227974"},{"side":"offer","event_time":"2026-07-15T03:40:04.373668Z","price_level":"64612","new_quantity":"0.0257"},{"side":"offer","event_time":"2026-07-15T03:40:04.373668Z","price_level":"64613.44","new_quantity":"0.14207229"},{"side":"offer","event_time":"2026-07-15T03:40:04.373668Z","price_level":"64613.45","new_quantity":"0.02"},{"side":"offer","event_time":"2026-07-15T03:40:04.373668Z","price_level":"64614","new_quantity":"0.0257"},{"side":"offer","event_time":"2026-07-15T03:40:04.373668Z","price_level":"64614.65","new_quantity":"0.15152352"},{"side":"offer","event_time":"2026-07-15T03:40:04.373668Z","price_level":"64614.66","new_quantity":"0.01185397"},{"side":"offer","event_time":"2026-07-15T03:40:04.373668Z","price_level":"64614.89","new_quantity":"0"},{"side":"offer","event_time":"2026-07-15T03:40:04.373668Z","price_level":"64615.27","new_quantity":"0"},{"side":"offer","event_time":"2026-07-15T03:40:04.373668Z","price_level":"64615.96","new_quantity":"0"},{"side":"offer","event_time":"2026-07-15T03:40:04.373668Z","price_level":"64616.64","new_quantity":"0"},{"side":"offer","event_time":"2026-07-15T03:40:04.373668Z","price_level":"64616.99","new_quantity":"0.11186166"},{"side":"offer","event_time":"2026-07-15T03:40:04.373668Z","price_level":"64617.03","new_quantity":"0"},{"side":"offer","event_time":"2026-07-15T03:40:04.373668Z","price_level":"64617.52","new_quantity":"0"},{"side":"offer","event_time":"2026-07-15T03:40:04.373668Z","price_level":"64617.81","new_quantity":"0"},{"side":"offer","event_time":"2026-07-15T03:40:04.373668Z","price_level":"64617.99","new_quantity":"0"},{"side":"offer","event_time":"2026-07-15T03:40:04.373668Z","price_level":"64618.44","new_quantity":"0"},{"side":"offer","event_time":"2026-07-15T03:40:04.373668Z","price_level":"64618.81","new_quantity":"0"},{"side":"offer","event_time":"2026-07-15T03:40:04.373668Z","price_level":"64619.83","new_quantity":"0"},{"side":"offer","event_time":"2026-07-15T03:40:04.373668Z","price_level":"64620.8","new_quantity":"0.000018"},{"side":"offer","event_time":"2026-07-15T03:40:04.373668Z","price_level":"64623.01","new_quantity":"0"},{"side":"offer","event_time":"2026-07-15T03:40:04.373668Z","price_level":"64623.02","new_quantity":"0"},{"side":"offer","event_time":"2026-07-15T03:40:04.373668Z","price_level":"64623.18","new_quantity":"0.00772597"},{"side":"offer","event_time":"2026-07-15T03:40:04.373668Z","price_level":"64623.19","new_quantity":"0"},{"side":"offer","event_time":"2026-07-15T03:40:04.373668Z","price_level":"64626.21","new_quantity":"0"},{"side":"offer","event_time":"2026-07-15T03:40:04.373668Z","price_level":"64629.4","new_quantity":"0"},{"side":"offer","event_time":"2026-07-15T03:40:04.373668Z","price_level":"64630.35","new_quantity":"0.00190186"},{"side":"offer","event_time":"2026-07-15T03:40:04.373668Z","price_level":"64630.87","new_quantity":"0.01073572"},{"side":"offer","event_time":"2026-07-15T03:40:04.373668Z","price_level":"64632","new_quantity":"0"},{"side":"offer","event_time":"2026-07-15T03:40:04.373668Z","price_level":"64632.59","new_quantity":"0"},{"side":"offer","event_time":"2026-07-15T03:40:04.373668Z","price_level":"64634","new_quantity":"0"},{"side":"offer","event_time":"2026-07-15T03:40:04.373668Z","price_level":"64635.58","new_quantity":"0.08800655"},{"side":"offer","event_time":"2026-07-15T03:40:04.373668Z","price_level":"64635.78","new_quantity":"0"},{"side":"offer","event_time":"2026-07-15T03:40:04.373668Z","price_level":"64636.5","new_quantity":"0"},{"side":"offer","event_time":"2026-07-15T03:40:04.373668Z","price_level":"64638.71","new_quantity":"0"},{"side":"offer","event_time":"2026-07-15T03:40:04.373668Z","price_level":"64638.79","new_quantity":"0.22901325"},{"side":"offer","event_time":"2026-07-15T03:40:04.373668Z","price_level":"64638.97","new_quantity":"0"},{"side":"offer","event_time":"2026-07-15T03:40:04.373668Z","price_level":"64641.99","new_quantity":"0"},{"side":"offer","event_time":"2026-07-15T03:40:04.373668Z","price_level":"64642.16","new_quantity":"0"},{"side":"offer","event_time":"2026-07-15T03:40:04.373668Z","price_level":"64643.95","new_quantity":"0.42728479"},{"side":"offer","event_time":"2026-07-15T03:40:04.373668Z","price_level":"64643.96","new_quantity":"0.63822353"},{"side":"offer","event_time":"2026-07-15T03:40:04.373668Z","price_level":"64645.32","new_quantity":"0"},{"side":"offer","event_time":"2026-07-15T03:40:04.373668Z","price_level":"64645.35","new_quantity":"0"},{"side":"offer","event_time":"2026-07-15T03:40:04.373668Z","price_level":"64645.66","new_quantity":"0"},{"side":"offer","event_time":"2026-07-15T03:40:04.373668Z","price_level":"64646.76","new_quantity":"0"},{"side":"offer","event_time":"2026-07-15T03:40:04.373668Z","price_level":"64647.41","new_quantity":"0.26782256"},{"side":"offer","event_time":"2026-07-15T03:40:04.373668Z","price_level":"64648.54","new_quantity":"0"},{"side":"offer","event_time":"2026-07-15T03:40:04.373668Z","price_level":"64649.13","new_quantity":"0.04810665"},{"side":"offer","event_time":"2026-07-15T03:40:04.373668Z","price_level":"64651.73","new_quantity":"0"},{"side":"offer","event_time":"2026-07-15T03:40:04.373668Z","price_level":"64651.82","new_quantity":"0.07763921"},{"side":"offer","event_time":"2026-07-15T03:40:04.373668Z","price_level":"64654.91","new_quantity":"0.00077373"},{"side":"offer","event_time":"2026-07-15T03:40:04.373668Z","price_level":"64654.92","new_quantity":"0"},{"side":"offer","event_time":"2026-07-15T03:40:04.373668Z","price_level":"64655.81","new_quantity":"0.02038643"},{"side":"offer","event_time":"2026-07-15T03:40:04.373668Z","price_level":"64662.67","new_quantity":"0.31467687"},{"side":"offer","event_time":"2026-07-15T03:40:04.373668Z","price_level":"64662.68","new_quantity":"0.45846223"},{"side":"offer","event_time":"2026-07-15T03:40:04.373668Z","price_level":"64664.94","new_quantity":"1.01683138"},{"side":"offer","event_time":"2026-07-15T03:40:04.373668Z","price_level":"64664.95","new_quantity":"1.43077168"},{"side":"offer","event_time":"2026-07-15T03:40:04.373668Z","price_level":"64664.96","new_quantity":"0.000018"},{"side":"offer","event_time":"2026-07-15T03:40:04.373668Z","price_level":"64667.23","new_quantity":"0"},{"side":"offer","event_time":"2026-07-15T03:40:04.373668Z","price_level":"64669.81","new_quantity":"2.02555291"},{"side":"offer","event_time":"2026-07-15T03:40:04.373668Z","price_level":"64671.74","new_quantity":"0"}]}]}
{"channel":"market_trades","timestamp":"2026-07-15T03:40:04.497894159Z","sequence_num":16,"events":[{"type":"update","trades":[{"product_id":"BTC-USD","trade_id":"1056309373","price":"64604.3","size":"0.05","time":"2026-07-15T03:40:04.440422Z","side":"BUY"},{"product_id":"BTC-USD","trade_id":"1056309372","price":"64606.08","size":"0.000018","time":"2026-07-15T03:40:04.43819Z","side":"BUY"},{"product_id":"BTC-USD","trade_id":"1056309371","price":"64609.33","size":"0.00003","time":"2026-07-15T03:40:04.437331Z","side":"BUY"},{"product_id":"BTC-USD","trade_id":"1056309370","price":"64609.76","size":"0.00004759","time":"2026-07-15T03:40:04.437331Z","side":"BUY"},{"product_id":"BTC-USD","trade_id":"1056309369","price":"64609.76","size":"0.000018","time":"2026-07-15T03:40:04.437331Z","side":"BUY"}]}]}
{"channel":"l2_data","timestamp":"2026-07-15T03:40:04.538275626Z","sequence_num":17,"events":[{"type":"update","product_id":"BTC-USD","updates":[{"side":"bid","event_time":"2026-07-15T03:40:04.421012Z","price_level":"64609.76","new_quantity":"0.00006559"},{"side":"bid","event_time":"2026-07-15T03:40:04.421012Z","price_level":"64606","new_quantity":"0"},{"side":"bid","event_time":"2026-07-15T03:40:04.421012Z","price_level":"64604.37","new_quantity":"0"},{"side":"bid","event_time":"2026-07-15T03:40:04.421012Z","price_level":"64604.01","new_quantity":"0"},{"side":"bid","event_time":"2026-07-15T03:40:04.421012Z","price_level":"64604","new_quantity":"0.0257"},{"side":"bid","event_time":"2026-07-15T03:40:04.421012Z","price_level":"64603.57","new_quantity":"0.00030231"},{"side":"bid","event_time":"2026-07-15T03:40:04.421012Z","price_level":"64601.61","new_quantity":"0"},{"side":"bid","event_time":"2026-07-15T03:40:04.421012Z","price_level":"64600.1","new_quantity":"0.1663973"},{"side":"bid","event_time":"2026-07-15T03:40:04.421012Z","price_level":"64600.09","new_quantity":"0.07749639"},{"side":"bid","event_time":"2026-07-15T03:40:04.421012Z","price_level":"64600.08","new_quantity":"0.04642741"},{"side":"bid","event_time":"2026-07-15T03:40:04.421012Z","price_level":"64600.04","new_quantity":"0.15479864"},{"side":"bid","event_time":"2026-07-15T03:40:04.421012Z","price_level":"64599.69","new_quantity":"0"},{"side":"bid","event_time":"2026-07-15T03:40:04.421012Z","price_level":"64598.43","new_quantity":"0"},{"side":"bid","event_time":"2026-07-15T03:40:04.421012Z","price_level":"64598.42","new_quantity":"0"},{"side":"bid","event_time":"2026-07-15T03:40:04.421012Z","price_level":"64598.32","new_quantity":"0"},{"side":"bid","event_time":"2026-07-15T03:40:04.421012Z","price_level":"64596.6","new_quantity":"0"},{"side":"bid","event_time":"2026-07-15T03:40:04.421012Z","price_level":"64595.94","new_quantity":"0"},{"side":"bid","event_time":"2026-07-15T03:40:04.421012Z","price_level":"64593.29","new_quantity":"0"},{"side":"bid","event_time":"2026-07-15T03:40:04.421012Z","price_level":"64592.8","new_quantity":"0.07676882"},{"side":"bid","event_time":"2026-07-15T03:40:04.421012Z","price_level":"64592.77","new_quantity":"0"},{"side":"bid","event_time":"2026-07-15T03:40:04.421012Z","price_level":"64592.76","new_quantity":"0"},{"side":"bid","event_time":"2026-07-15T03:40:04.421012Z","price_level":"64590.76","new_quantity":"0.12378505"},{"side":"bid","event_time":"2026-07-15T03:40:04.421012Z","price_level":"64588.89","new_quantity":"0"},{"side":"bid","event_time":"2026-07-15T03:40:04.421012Z","price_level":"64588.88","new_quantity":"0"},{"side":"bid","event_time":"2026-07-15T03:40:04.421012Z","price_level":"64588.75","new_quantity":"0"},{"side":"bid","event_time":"2026-07-15T03:40:04.421012Z","price_level":"64587.75","new_quantity":"0.00120923"},{"side":"bid","event_time":"2026-07-15T03:40:04.421012Z","price_level":"64587.68","new_quantity":"0.000018"},{"side":"bid","event_time":"2026-07-15T03:40:04.421012Z","price_level":"64587.11","new_quantity":"0"},{"side":"bid","event_time":"2026-07-15T03:40:04.421012Z","price_level":"64586.49","new_quantity":"0.046738"},{"side":"bid","event_time":"2026-07-15T03:40:04.421012Z","price_level":"64585.4","new_quantity":"0"},{"side":"bid","event_time":"2026-07-15T03:40:04.421012Z","price_level":"64585.3","new_quantity":"0.12378505"},{"side":"bid","event_time":"2026-07-15T03:40:04.421012Z","price_level":"64585","new_quantity":"0"},{"side":"bid","event_time":"2026-07-15T03:40:04.421012Z","price_level":"64583.17","new_quantity":"0.16911404"},{"side":"bid","event_time":"2026-07-15T03:40:04.421012Z","price_level":"64583.16","new_quantity":"0.12378505"},{"side":"bid","event_time":"2026-07-15T03:40:04.421012Z","price_level":"64582.52","new_quantity":"0.035703"},{"side":"bid","event_time":"2026-07-15T03:40:04.421012Z","price_level":"64582.3","new_quantity":"0"},{"side":"bid","event_time":"2026-07-15T03:40:04.421012Z","price_level":"64581.16","new_quantity":"0"},{"side":"bid","event_time":"2026-07-15T03:40:04.421012Z","price_level":"64580.64","new_quantity":"0"},{"side":"bid","event_time":"2026-07-15T03:40:04.421012Z","price_level":"64579.43","new_quantity":"0.00241846"},{"side":"bid","event_time":"2026-07-15T03:40:04.421012Z","price_level":"64577.25","new_quantity":"1.10289421"},{"side":"bid","event_time":"2026-07-15T03:40:04.421012Z","price_level":"64575","new_quantity":"1"},{"side":"bid","event_time":"2026-07-15T03:40:04.421012Z","price_level":"64573.98","new_quantity":"0.09376804"},{"side":"bid","event_time":"2026-07-15T03:40:04.421012Z","price_level":"64573.97","new_quantity":"0.12378505"},{"side":"bid","event_time":"2026-07-15T03:40:04.421012Z","price_level":"64571.35","new_quantity":"0"},{"side":"bid","event_time":"2026-07-15T03:40:04.421012Z","price_level":"64570.13","new_quantity":"0.10769747"},{"side":"bid","event_time":"2026-07-15T03:40:04.421012Z","price_level":"64570.09","new_quantity":"0.12378505"},{"side":"bid","event_time":"2026-07-15T03:40:04.421012Z","price_level":"64567.63","new_quantity":"0.12596827"},{"side":"bid","event_time":"2026-07-15T03:40:04.421012Z","price_level":"64566.21","new_quantity":"0.12378505"},{"side":"bid","event_time":"2026-07-15T03:40:04.421012Z","price_level":"64562.33","new_quantity":"0.12378505"},{"side":"bid","event_time":"2026-07-15T03:40:04.421012Z","price_level":"64559.23","new_quantity":"0"},{"side":"bid","event_time":"2026-07-15T03:40:04.421012Z","price_level":"64556.14","new_quantity":"0.01158896"},{"side":"bid","event_time":"2026-07-15T03:40:04.421012Z","price_level":"64556.13","new_quantity":"0"},{"side":"bid","event_time":"2026-07-15T03:40:04.421012Z","price_level":"64555.14","new_quantity":"0"},{"side":"bid","event_time":"2026-07-15T03:40:04.421012Z","price_level":"64551.34","new_quantity":"0"},{"side":"bid","event_time":"2026-07-15T03:40:04.421012Z","price_level":"64551.17","new_quantity":"0"},{"side":"bid","event_time":"2026-07-15T03:40:04.421012Z","price_level":"64550.29","new_quantity":"0"},{"side":"bid","event_time":"2026-07-15T03:40:04.421012Z","price_level":"64549","new_quantity":"0.15849605"},{"side":"bid","event_time":"2026-07-15T03:40:04.421012Z","price_level":"64548.99","new_quantity":"0.26308864"},{"side":"bid","event_time":"2026-07-15T03:40:04.421012Z","price_level":"64535.01","new_quantity":"0.01879625"},{"side":"bid","event_time":"2026-07-15T03:40:04.421012Z","price_level":"64535","new_quantity":"0"},{"side":"bid","event_time":"2026-07-15T03:40:04.421012Z","price_level":"64504.41","new_quantity":"0"},{"side":"bid","event_time":"2026-07-15T03:40:04.421012Z","price_level":"64485.86","new_quantity":"0.232053"},{"side":"offer","event_time":"2026-07-15T03:40:04.421012Z","price_level":"64609.77","new_quantity":"0.22137018"},{"side":"offer","event_time":"2026-07-15T03:40:04.421012Z","price_level":"64609.99","new_quantity":"0"},{"side":"offer","event_time":"2026-07-15T03:40:04.421012Z","price_level":"64610","new_quantity":"0.13501535"},{"side":"offer","event_time":"2026-07-15T03:40:04.421012Z","price_level":"64610.37","new_quantity":"0.12381913"},{"side":"offer","event_time":"2026-07-15T03:40:04.421012Z","price_level":"64610.44","new_quantity":"0"},{"side":"offer","event_time":"2026-07-15T03:40:04.421012Z","price_level":"64611.82","new_quantity":"0"},{"side":"offer","event_time":"2026-07-15T03:40:04.421012Z","price_level":"64613.44","new_quantity":"0.13832916"},{"side":"offer","event_time":"2026-07-15T03:40:04.421012Z","price_level":"64613.45","new_quantity":"0"},{"side":"offer","event_time":"2026-07-15T03:40:04.421012Z","price_level":"64614.41","new_quantity":"0.12378505"},{"side":"offer","event_time":"2026-07-15T03:40:04.421012Z","price_level":"64614.64","new_quantity":"0.00319954"},{"side":"offer","event_time":"2026-07-15T03:40:04.421012Z","price_level":"64614.65","new_quantity":"0.00773847"},{"side":"offer","event_time":"2026-07-15T03:40:04.421012Z","price_level":"64614.7","new_quantity":"0.00085358"},{"side":"offer","event_time":"2026-07-15T03:40:04.421012Z","price_level":"64614.75","new_quantity":"0.048285"},{"side":"offer","event_time":"2026-07-15T03:40:04.421012Z","price_level":"64616.54","new_quantity":"0.23807862"},{"side":"offer","event_time":"2026-07-15T03:40:04.421012Z","price_level":"64616.55","new_quantity":"0.12378505"},{"side":"offer","event_time":"2026-07-15T03:40:04.421012Z","price_level":"64616.99","new_quantity":"0"},{"side":"offer","event_time":"2026-07-15T03:40:04.421012Z","price_level":"64617","new_quantity":"0"},{"side":"offer","event_time":"2026-07-15T03:40:04.421012Z","price_level":"64618.18","new_quantity":"0.07332"},{"side":"offer","event_time":"2026-07-15T03:40:04.421012Z","price_level":"64618.53","new_quantity":"0.12378505"},{"side":"offer","event_time":"2026-07-15T03:40:04.421012Z","price_level":"64619.09","new_quantity":"0.00772597"},{"side":"offer","event_time":"2026-07-15T03:40:04.421012Z","price_level":"64619.41","new_quantity":"0.20808449"},{"side":"offer","event_time":"2026-07-15T03:40:04.421012Z","price_level":"64619.72","new_quantity":"0"},{"side":"offer","event_time":"2026-07-15T03:40:04.421012Z","price_level":"64623.18","new_quantity":"0"},{"side":"offer","event_time":"2026-07-15T03:40:04.421012Z","price_level":"64639.63","new_quantity":"0"},{"side":"offer","event_time":"2026-07-15T03:40:04.421012Z","price_level":"64655.81","new_quantity":"0.61478006"},{"side":"offer","event_time":"2026-07-15T03:40:04.421012Z","price_level":"64656","new_quantity":"1"},{"side":"offer","event_time":"2026-07-15T03:40:04.421012Z","price_level":"64658.8","new_quantity":"0.18579894"},{"side":"offer","event_time":"2026-07-15T03:40:04.421012Z","price_level":"64658.81","new_quantity":"0.26308864"},{"side":"offer","event_time":"2026-07-15T03:40:04.421012Z","price_level":"64661.11","new_quantity":"0"},{"side":"offer","event_time":"2026-07-15T03:40:04.421012Z","price_level":"64664.97","new_quantity":"0"},{"side":"offer","event_time":"2026-07-15T03:40:04.421012Z","price_level":"64668.22","new_quantity":"1.24991064"},{"side":"offer","event_time":"2026-07-15T03:40:04.421012Z","price_level":"64673.16","new_quantity":"0.06936947"},{"side":"offer","event_time":"2026-07-15T03:40:04.421012Z","price_level":"64677.53","new_quantity":"0.01847913"},{"side":"offer","event_time":"2026-07-15T03:40:04.421012Z","price_level":"64681.29","new_quantity":"0"},{"side":"offer","event_time":"2026-07-15T03:40:04.421012Z","price_level":"64684.02","new_quantity":"0"},{"side":"offer","event_time":"2026-07-15T03:40:04.421012Z","price_level":"64720","new_quantity":"0"}]}]}
{"channel":"l2_data","timestamp":"2026-07-15T03:40:04.557034543Z","sequence_num":18,"events":[{"type":"update","product_id":"BTC-USD","updates":[{"side":"bid","event_time":"2026-07-15T03:40:04.47551Z","price_level":"64609.76","new_quantity":"0"},{"side":"bid","event_time":"2026-07-15T03:40:04.47551Z","price_level":"64609.33","new_quantity":"0"},{"side":"bid","event_time":"2026-07-15T03:40:04.47551Z","price_level":"64606.08","new_quantity":"0"},{"side":"bid","event_time":"2026-07-15T03:40:04.47551Z","price_level":"64604.95","new_quantity":"0"},{"side":"bid","event_time":"2026-07-15T03:40:04.47551Z","price_level":"64604.3","new_quantity":"0"},{"side":"bid","event_time":"2026-07-15T03:40:04.47551Z","price_level":"64604","new_quantity":"0"},{"side":"bid","event_time":"2026-07-15T03:40:04.47551Z","price_level":"64603.57","new_quantity":"0.00000231"},{"side":"bid","event_time":"2026-07-15T03:40:04.47551Z","price_level":"64602.97","new_quantity":"0"},{"side":"bid","event_time":"2026-07-15T03:40:04.47551Z","price_level":"64600.1","new_quantity":"0"},{"side":"bid","event_time":"2026-07-15T03:40:04.47551Z","price_level":"64600.09","new_quantity":"0"},{"side":"bid","event_time":"2026-07-15T03:40:04.47551Z","price_level":"64600.08","new_quantity":"0"},{"side":"bid","event_time":"2026-07-15T03:40:04.47551Z","price_level":"64600.04","new_quantity":"0"},{"side":"bid","event_time":"2026-07-15T03:40:04.47551Z","price_level":"64598","new_quantity":"0.0257"},{"side":"bid","event_time":"2026-07-15T03:40:04.47551Z","price_level":"64597.24","new_quantity":"0"},{"side":"bid","event_time":"2026-07-15T03:40:04.47551Z","price_level":"64596.56","new_quantity":"0"},{"side":"bid","event_time":"2026-07-15T03:40:04.47551Z","price_level":"64595.77","new_quantity":"0"},{"side":"bid","event_time":"2026-07-15T03:40:04.47551Z","price_level":"64593.17","new_quantity":"0"},{"side":"bid","event_time":"2026-07-15T03:40:04.47551Z","price_level":"64592.84","new_quantity":"0.04656107"},{"side":"bid","event_time":"2026-07-15T03:40:04.47551Z","price_level":"64592.81","new_quantity":"0"},{"side":"bid","event_time":"2026-07-15T03:40:04.47551Z","price_level":"64592.8","new_quantity":"0"},{"side":"bid","event_time":"2026-07-15T03:40:04.47551Z","price_level":"64592.79","new_quantity":"0"},{"side":"bid","event_time":"2026-07-15T03:40:04.47551Z","price_level":"64592.78","new_quantity":"0"},{"side":"bid","event_time":"2026-07-15T03:40:04.47551Z","price_level":"64591.87","new_quantity":"0"},{"side":"bid","event_time":"2026-07-15T03:40:04.47551Z","price_level":"64591.81","new_quantity":"0.03093532"},{"side":"bid","event_time":"2026-07-15T03:40:04.47551Z","price_level":"64590.76","new_quantity":"0"},{"side":"bid","event_time":"2026-07-15T03:40:04.47551Z","price_level":"64588.37","new_quantity":"0"},{"side":"bid","event_time":"2026-07-15T03:40:04.47551Z","price_level":"64586.51","new_quantity":"0.046738"},{"side":"bid","event_time":"2026-07-15T03:40:04.47551Z","price_level":"64586.5","new_quantity":"0.03093532"},{"side":"bid","event_time":"2026-07-15T03:40:04.47551Z","price_level":"64586.49","new_quantity":"0"},{"side":"bid","event_time":"2026-07-15T03:40:04.47551Z","price_level":"64585.3","new_quantity":"0"},{"side":"bid","event_time":"2026-07-15T03:40:04.47551Z","price_level":"64585.13","new_quantity":"0"},{"side":"bid","event_time":"2026-07-15T03:40:04.47551Z","price_level":"64584.49","new_quantity":"0"},{"side":"bid","event_time":"2026-07-15T03:40:04.47551Z","price_level":"64583.19","new_quantity":"0.04429771"},{"side":"bid","event_time":"2026-07-15T03:40:04.47551Z","price_level":"64583.18","new_quantity":"0"},{"side":"bid","event_time":"2026-07-15T03:40:04.47551Z","price_level":"64583.17","new_quantity":"0"},{"side":"bid","event_time":"2026-07-15T03:40:04.47551Z","price_level":"64583.16","new_quantity":"0"},{"side":"bid","event_time":"2026-07-15T03:40:04.47551Z","price_level":"64582.52","new_quantity":"0"},{"side":"bid","event_time":"2026-07-15T03:40:04.47551Z","price_level":"64581.15","new_quantity":"0"},{"side":"bid","event_time":"2026-07-15T03:40:04.47551Z","price_level":"64580.91","new_quantity":"0.12378505"},{"side":"bid","event_time":"2026-07-15T03:40:04.47551Z","price_level":"64579.89","new_quantity":"0.04405038"},{"side":"bid","event_time":"2026-07-15T03:40:04.47551Z","price_level":"64577.84","new_quantity":"0"},{"side":"bid","event_time":"2026-07-15T03:40:04.47551Z","price_level":"64577.25","new_quantity":"0.57512246"},{"side":"bid","event_time":"2026-07-15T03:40:04.47551Z","price_level":"64575.17","new_quantity":"0"},{"side":"bid","event_time":"2026-07-15T03:40:04.47551Z","price_level":"64575","new_quantity":"0"},{"side":"bid","event_time":"2026-07-15T03:40:04.47551Z","price_level":"64574.26","new_quantity":"0.035489"},{"side":"bid","event_time":"2026-07-15T03:40:04.47551Z","price_level":"64573.43","new_quantity":"0.04306735"},{"side":"bid","event_time":"2026-07-15T03:40:04.47551Z","price_level":"64571.98","new_quantity":"0"},{"side":"bid","event_time":"2026-07-15T03:40:04.47551Z","price_level":"64568.79","new_quantity":"0"},{"side":"bid","event_time":"2026-07-15T03:40:04.47551Z","price_level":"64565.6","new_quantity":"0.000018"},{"side":"bid","event_time":"2026-07-15T03:40:04.47551Z","price_level":"64562.41","new_quantity":"0"},{"side":"bid","event_time":"2026-07-15T03:40:04.47551Z","price_level":"64562.34","new_quantity":"0.07391098"},{"side":"bid","event_time":"2026-07-15T03:40:04.47551Z","price_level":"64562.33","new_quantity":"0.12378505"},{"side":"bid","event_time":"2026-07-15T03:40:04.47551Z","price_level":"64560.22","new_quantity":"0"},{"side":"bid","event_time":"2026-07-15T03:40:04.47551Z","price_level":"64559.79","new_quantity":"0.11070924"},{"side":"bid","event_time":"2026-07-15T03:40:04.47551Z","price_level":"64558.45","new_quantity":"0.12378505"},{"side":"bid","event_time":"2026-07-15T03:40:04.47551Z","price_level":"64558.19","new_quantity":"0.448637"},{"side":"bid","event_time":"2026-07-15T03:40:04.47551Z","price_level":"64554.15","new_quantity":"0.02423914"},{"side":"bid","event_time":"2026-07-15T03:40:04.47551Z","price_level":"64544.33","new_quantity":"0.03093532"},{"side":"bid","event_time":"2026-07-15T03:40:04.47551Z","price_level":"64535.01","new_quantity":"0"},{"side":"bid","event_time":"2026-07-15T03:40:04.47551Z","price_level":"64533.88","new_quantity":"0"},{"side":"bid","event_time":"2026-07-15T03:40:04.47551Z","price_level":"64533.57","new_quantity":"0"},{"side":"bid","event_time":"2026-07-15T03:40:04.47551Z","price_level":"64529.18","new_quantity":"1.61565454"},{"side":"bid","event_time":"2026-07-15T03:40:04.47551Z","price_level":"64526.97","new_quantity":"0"},{"side":"bid","event_time":"2026-07-15T03:40:04.47551Z","price_level":"64501.77","new_quantity":"0"},{"side":"offer","event_time":"2026-07-15T03:40:04.47551Z","price_level":"64603.58","new_quantity":"0.22983228"},{"side":"offer","event_time":"2026-07-15T03:40:04.47551Z","price_level":"64604","new_quantity":"0.0257"},{"side":"offer","event_time":"2026-07-15T03:40:04.47551Z","price_level":"64604.3","new_quantity":"0.0803498"},{"side":"offer","event_time":"2026-07-15T03:40:04.47551Z","price_level":"64604.31","new_quantity":"0.0953162"},{"side":"offer","event_time":"2026-07-15T03:40:04.47551Z","price_level":"64606","new_quantity":"0.0257"},{"side":"offer","event_time":"2026-07-15T03:40:04.47551Z","price_level":"64606.08","new_quantity":"0.00773935"},{"side":"offer","event_time":"2026-07-15T03:40:04.47551Z","price_level":"64606.09","new_quantity":"0"},{"side":"offer","event_time":"2026-07-15T03:40:04.47551Z","price_level":"64606.52","new_quantity":"0.10031798"},{"side":"offer","event_time":"2026-07-15T03:40:04.47551Z","price_level":"64606.72","new_quantity":"0.12382613"},{"side":"offer","event_time":"2026-07-15T03:40:04.47551Z","price_level":"64607.7","new_quantity":"0.00773935"},{"side":"offer","event_time":"2026-07-15T03:40:04.47551Z","price_level":"64608","new_quantity":"0.0257"},{"side":"offer","event_time":"2026-07-15T03:40:04.47551Z","price_level":"64609.02","new_quantity":"0"},{"side":"offer","event_time":"2026-07-15T03:40:04.47551Z","price_level":"64609.03","new_quantity":"0"},{"side":"offer","event_time":"2026-07-15T03:40:04.47551Z","price_level":"64609.34","new_quantity":"0"},{"side":"offer","event_time":"2026-07-15T03:40:04.47551Z","price_level":"64609.76","new_quantity":"0.14378505"},{"side":"offer","event_time":"2026-07-15T03:40:04.47551Z","price_level":"64609.77","new_quantity":"0"},{"side":"offer","event_time":"2026-07-15T03:40:04.47551Z","price_level":"64609.88","new_quantity":"0.00967419"},{"side":"offer","event_time":"2026-07-15T03:40:04.47551Z","price_level":"64610","new_quantity":"0.0257"},{"side":"offer","event_time":"2026-07-15T03:40:04.47551Z","price_level":"64610.37","new_quantity":"0"},{"side":"offer","event_time":"2026-07-15T03:40:04.47551Z","price_level":"64612.23","new_quantity":"0.12378505"},{"side":"offer","event_time":"2026-07-15T03:40:04.47551Z","price_level":"64613.07","new_quantity":"0.22144494"},{"side":"offer","event_time":"2026-07-15T03:40:04.47551Z","price_level":"64613.08","new_quantity":"0"},{"side":"offer","event_time":"2026-07-15T03:40:04.47551Z","price_level":"64613.43","new_quantity":"0.04656107"},{"side":"offer","event_time":"2026-07-15T03:40:04.47551Z","price_level":"64613.44","new_quantity":"0"},{"side":"offer","event_time":"2026-07-15T03:40:04.47551Z","price_level":"64614.64","new_quantity":"0"},{"side":"offer","event_time":"2026-07-15T03:40:04.47551Z","price_level":"64614.65","new_quantity":"0"},{"side":"offer","event_time":"2026-07-15T03:40:04.47551Z","price_level":"64614.7","new_quantity":"0"},{"side":"offer","event_time":"2026-07-15T03:40:04.47551Z","price_level":"64616.27","new_quantity":"0"},{"side":"offer","event_time":"2026-07-15T03:40:04.47551Z","price_level":"64616.53","new_quantity":"0.03093532"},{"side":"offer","event_time":"2026-07-15T03:40:04.47551Z","price_level":"64616.74","new_quantity":"0.00077393"},{"side":"offer","event_time":"2026-07-15T03:40:04.47551Z","price_level":"64617.89","new_quantity":"0"},{"side":"offer","event_time":"2026-07-15T03:40:04.47551Z","price_level":"64618.2","new_quantity":"0.06226334"},{"side":"offer","event_time":"2026-07-15T03:40:04.47551Z","price_level":"64618.45","new_quantity":"0"},{"side":"offer","event_time":"2026-07-15T03:40:04.47551Z","price_level":"64619.41","new_quantity":"0.1541901"},{"side":"offer","event_time":"2026-07-15T03:40:04.47551Z","price_level":"64621.92","new_quantity":"0"},{"side":"offer","event_time":"2026-07-15T03:40:04.47551Z","price_level":"64622.22","new_quantity":"0"},{"side":"offer","event_time":"2026-07-15T03:40:04.47551Z","price_level":"64622.67","new_quantity":"0.10065116"},{"side":"offer","event_time":"2026-07-15T03:40:04.47551Z","price_level":"64624.36","new_quantity":"0"},{"side":"offer","event_time":"2026-07-15T03:40:04.47551Z","price_level":"64625.33","new_quantity":"0.02773705"},{"side":"offer","event_time":"2026-07-15T03:40:04.47551Z","price_level":"64628","new_quantity":"0"},{"side":"offer","event_time":"2026-07-15T03:40:04.47551Z","price_level":"64628.41","new_quantity":"0"},{"side":"offer","event_time":"2026-07-15T03:40:04.47551Z","price_level":"64629.07","new_quantity":"0.07896179"},{"side":"offer","event_time":"2026-07-15T03:40:04.47551Z","price_level":"64630","new_quantity":"0"},{"side":"offer","event_time":"2026-07-15T03:40:04.47551Z","price_level":"64630.74","new_quantity":"0.00104481"},{"side":"offer","event_time":"2026-07-15T03:40:04.47551Z","price_level":"64633.56","new_quantity":"0.0497566"},{"side":"offer","event_time":"2026-07-15T03:40:04.47551Z","price_level":"64633.58","new_quantity":"0"},{"side":"offer","event_time":"2026-07-15T03:40:04.47551Z","price_level":"64633.59","new_quantity":"0"},{"side":"offer","event_time":"2026-07-15T03:40:04.47551Z","price_level":"64635.58","new_quantity":"0"},{"side":"offer","event_time":"2026-07-15T03:40:04.47551Z","price_level":"64635.59","new_quantity":"0"},{"side":"offer","event_time":"2026-07-15T03:40:04.47551Z","price_level":"64637.44","new_quantity":"0"},{"side":"offer","event_time":"2026-07-15T03:40:04.47551Z","price_level":"64638.79","new_quantity":"0.12435868"},{"side":"offer","event_time":"2026-07-15T03:40:04.47551Z","price_level":"64639.85","new_quantity":"0"},{"side":"offer","event_time":"2026-07-15T03:40:04.47551Z","price_level":"64640.87","new_quantity":"0"},{"side":"offer","event_time":"2026-07-15T03:40:04.47551Z","price_level":"64653.98","new_quantity":"0"},{"side":"offer","event_time":"2026-07-15T03:40:04.47551Z","price_level":"64655.81","new_quantity":"0.02038643"},{"side":"offer","event_time":"2026-07-15T03:40:04.47551Z","price_level":"64656","new_quantity":"0"},{"side":"offer","event_time":"2026-07-15T03:40:04.47551Z","price_level":"64657.29","new_quantity":"0"},{"side":"offer","event_time":"2026-07-15T03:40:04.47551Z","price_level":"64666.17","new_quantity":"0.0023992"},{"side":"offer","event_time":"2026-07-15T03:40:04.47551Z","price_level":"64667.38","new_quantity":"1.39173727"},{"side":"offer","event_time":"2026-07-15T03:40:04.47551Z","price_level":"64670.99","new_quantity":"0.00077242"},{"side":"offer","event_time":"2026-07-15T03:40:04.47551Z","price_level":"64674.06","new_quantity":"0"},{"side":"offer","event_time":"2026-07-15T03:40:04.47551Z","price_level":"64677.25","new_quantity":"0"},{"side":"offer","event_time":"2026-07-15T03:40:04.47551Z","price_level":"64677.54","new_quantity":"0"},{"side":"offer","event_time":"2026-07-15T03:40:04.47551Z","price_level":"64685.16","new_quantity":"0"},{"side":"offer","event_time":"2026-07-15T03:40:04.47551Z","price_level":"64689.22","new_quantity":"0"},{"side":"offer","event_time":"2026-07-15T03:40:04.47551Z","price_level":"64692.51","new_quantity":"0"},{"side":"offer","event_time":"2026-07-15T03:40:04.47551Z","price_level":"64897.64","new_quantity":"0"}]}]}
{"channel":"market_trades","timestamp":"2026-07-15T03:40:04.593259851Z","sequence_num":19,"events":[{"type":"update","trades":[{"product_id":"BTC-USD","trade_id":"1056309374","price":"64603.57","size":"0.0003","time":"2026-07-15T03:40:04.446617Z","side":"BUY"}]}]}
{"channel":"l2_data","timestamp":"2026-07-15T03:40:04.593650174Z","sequence_num":20,"events":[{"type":"update","product_id":"BTC-USD","updates":[{"side":"bid","event_time":"2026-07-15T03:40:04.491634Z","price_level":"64603.57","new_quantity":"0"},{"side":"bid","event_time":"2026-07-15T03:40:04.491634Z","price_level":"64601.49","new_quantity":"0"},{"side":"bid","event_time":"2026-07-15T03:40:04.491634Z","price_level":"64598","new_quantity":"0"},{"side":"bid","event_time":"2026-07-15T03:40:04.491634Z","price_level":"64583.19","new_quantity":"0"},{"side":"bid","event_time":"2026-07-15T03:40:04.491634Z","price_level":"64580.92","new_quantity":"0.07389967"},{"side":"bid","event_time":"2026-07-15T03:40:04.491634Z","price_level":"64579.89","new_quantity":"0"},{"side":"bid","event_time":"2026-07-15T03:40:04.491634Z","price_level":"64579.31","new_quantity":"0"},{"side":"bid","event_time":"2026-07-15T03:40:04.491634Z","price_level":"64578.37","new_quantity":"0"},{"side":"bid","event_time":"2026-07-15T03:40:04.491634Z","price_level":"64576.18","new_quantity":"0"},{"side":"bid","event_time":"2026-07-15T03:40:04.491634Z","price_level":"64573.43","new_quantity":"0"},{"side":"bid","event_time":"2026-07-15T03:40:04.491634Z","price_level":"64565.03","new_quantity":"0.60963973"},{"side":"bid","event_time":"2026-07-15T03:40:04.491634Z","price_level":"64559.79","new_quantity":"0"},{"side":"bid","event_time":"2026-07-15T03:40:04.491634Z","price_level":"64534.02","new_quantity":"0"},{"side":"bid","event_time":"2026-07-15T03:40:04.491634Z","price_level":"64528.22","new_quantity":"0"},{"side":"bid","event_time":"2026-07-15T03:40:04.491634Z","price_level":"64515","new_quantity":"3"},{"side":"bid","event_time":"2026-07-15T03:40:04.491634Z","price_level":"64502.81","new_quantity":"0"},{"side":"offer","event_time":"2026-07-15T03:40:04.491634Z","price_level":"64602.41","new_quantity":"0.13523"},{"side":"offer","event_time":"2026-07-15T03:40:04.491634Z","price_level":"64602.58","new_quantity":"0.0334"},{"side":"offer","event_time":"2026-07-15T03:40:04.491634Z","price_level":"64603.57","new_quantity":"0.0676662"},{"side":"offer","event_time":"2026-07-15T03:40:04.491634Z","price_level":"64603.58","new_quantity":"0.64201296"},{"side":"offer","event_time":"2026-07-15T03:40:04.491634Z","price_level":"64604.3","new_quantity":"0.12749727"},{"side":"offer","event_time":"2026-07-15T03:40:04.491634Z","price_level":"64604.31","new_quantity":"0"},{"side":"offer","event_time":"2026-07-15T03:40:04.491634Z","price_level":"64606.08","new_quantity":"0"},{"side":"offer","event_time":"2026-07-15T03:40:04.491634Z","price_level":"64606.51","new_quantity":"0.12378505"},{"side":"offer","event_time":"2026-07-15T03:40:04.491634Z","price_level":"64606.52","new_quantity":"0.08181012"},{"side":"offer","event_time":"2026-07-15T03:40:04.491634Z","price_level":"64607.7","new_quantity":"0"},{"side":"offer","event_time":"2026-07-15T03:40:04.491634Z","price_level":"64609.75","new_quantity":"0.22305842"},{"side":"offer","event_time":"2026-07-15T03:40:04.491634Z","price_level":"64609.88","new_quantity":"0"},{"side":"offer","event_time":"2026-07-15T03:40:04.491634Z","price_level":"64614.75","new_quantity":"0"},{"side":"offer","event_time":"2026-07-15T03:40:04.491634Z","price_level":"64626","new_quantity":"0"},{"side":"offer","event_time":"2026-07-15T03:40:04.491634Z","price_level":"64627.87","new_quantity":"0.00592"},{"side":"offer","event_time":"2026-07-15T03:40:04.491634Z","price_level":"64631.48","new_quantity":"0"},{"side":"offer","event_time":"2026-07-15T03:40:04.491634Z","price_level":"64637.59","new_quantity":"0"},{"side":"offer","event_time":"2026-07-15T03:40:04.491634Z","price_level":"64646.46","new_quantity":"0.00158656"},{"side":"offer","event_time":"2026-07-15T03:40:04.491634Z","price_level":"64649.87","new_quantity":"0"},{"side":"offer","event_time":"2026-07-15T03:40:04.491634Z","price_level":"64650.47","new_quantity":"1.43109214"},{"side":"offer","event_time":"2026-07-15T03:40:04.491634Z","price_level":"64654.52","new_quantity":"0"},{"side":"offer","event_time":"2026-07-15T03:40:04.491634Z","price_level":"64661.86","new_quantity":"0"},{"side":"offer","event_time":"2026-07-15T03:40:04.491634Z","price_level":"64664.94","new_quantity":"1.56063473"},{"side":"offer","event_time":"2026-07-15T03:40:04.491634Z","price_level":"64664.95","new_quantity":"0"},{"side":"offer","event_time":"2026-07-15T03:40:04.491634Z","price_level":"64677.53","new_quantity":"0"},{"side":"offer","event_time":"2026-07-15T03:40:04.491634Z","price_level":"64694.59","new_quantity":"0"},{"side":"offer","event_time":"2026-07-15T03:40:04.491634Z","price_level":"64698.58","new_quantity":"0"},{"side":"offer","event_time":"2026-07-15T03:40:04.491634Z","price_level":"64716.66","new_quantity":"0"},{"side":"offer","event_time":"2026-07-15T03:40:04.491634Z","price_level":"64738.51","new_quantity":"0"}]}]}
{"channel":"l2_data","timestamp":"2026-07-15T03:40:04.65328786Z","sequence_num":21,"events":[{"type":"update","product_id":"BTC-USD","updates":[{"side":"bid","event_time":"2026-07-15T03:40:04.606031Z","price_level":"64598.11","new_quantity":"0"},{"side":"bid","event_time":"2026-07-15T03:40:04.606031Z","price_level":"64579.33","new_quantity":"0.60182114"},{"side":"bid","event_time":"2026-07-15T03:40:04.606031Z","price_level":"64577.85","new_quantity":"0.12378505"},{"side":"bid","event_time":"2026-07-15T03:40:04.606031Z","price_level":"64567.64","new_quantity":"0.93141338"},{"side":"bid","event_time":"2026-07-15T03:40:04.606031Z","price_level":"64559.79","new_quantity":"0.37080165"},{"side":"bid","event_time":"2026-07-15T03:40:04.606031Z","price_level":"64551.74","new_quantity":"0"},{"side":"bid","event_time":"2026-07-15T03:40:04.606031Z","price_level":"64548.99","new_quantity":"0"},{"side":"bid","event_time":"2026-07-15T03:40:04.606031Z","price_level":"64543.01","new_quantity":"0"},{"side":"bid","event_time":"2026-07-15T03:40:04.606031Z","price_level":"64542.97","new_quantity":"0"},{"side":"bid","event_time":"2026-07-15T03:40:04.606031Z","price_level":"64542.65","new_quantity":"0.26312993"},{"side":"bid","event_time":"2026-07-15T03:40:04.606031Z","price_level":"64542.52","new_quantity":"0"},{"side":"bid","event_time":"2026-07-15T03:40:04.606031Z","price_level":"64538.46","new_quantity":"0"},{"side":"bid","event_time":"2026-07-15T03:40:04.606031Z","price_level":"64536.45","new_quantity":"1.34911938"},{"side":"bid","event_time":"2026-07-15T03:40:04.606031Z","price_level":"64529.17","new_quantity":"0"},{"side":"bid","event_time":"2026-07-15T03:40:04.606031Z","price_level":"64525.18","new_quantity":"0.001857"},{"side":"bid","event_time":"2026-07-15T03:40:04.606031Z","price_level":"64515.95","new_quantity":"2.15459554"},{"side":"bid","event_time":"2026-07-15T03:40:04.606031Z","price_level":"64508.38","new_quantity":"9.62753"},{"side":"bid","event_time":"2026-07-15T03:40:04.606031Z","price_level":"64481.65","new_quantity":"0.00002322"},{"side":"bid","event_time":"2026-07-15T03:40:04.606031Z","price_level":"64324.23","new_quantity":"1.39916166"},{"side":"bid","event_time":"2026-07-15T03:40:04.606031Z","price_level":"56528.13","new_quantity":"0.0132912"},{"side":"offer","event_time":"2026-07-15T03:40:04.606031Z","price_level":"64603.58","new_quantity":"0.75900493"},{"side":"offer","event_time":"2026-07-15T03:40:04.606031Z","price_level":"64604.29","new_quantity":"0.12147516"},{"side":"offer","event_time":"2026-07-15T03:40:04.606031Z","price_level":"64604.3","new_quantity":"0"},{"side":"offer","event_time":"2026-07-15T03:40:04.606031Z","price_level":"64605.2","new_quantity":"0.0077395"},{"side":"offer","event_time":"2026-07-15T03:40:04.606031Z","price_level":"64605.68","new_quantity":"0.00085369"},{"side":"offer","event_time":"2026-07-15T03:40:04.606031Z","price_level":"64607.38","new_quantity":"0.00967438"},{"side":"offer","event_time":"2026-07-15T03:40:04.606031Z","price_level":"64609.75","new_quantity":"0.25399374"},{"side":"offer","event_time":"2026-07-15T03:40:04.606031Z","price_level":"64633.55","new_quantity":"0.63832632"},{"side":"offer","event_time":"2026-07-15T03:40:04.606031Z","price_level":"64643.96","new_quantity":"0"},{"side":"offer","event_time":"2026-07-15T03:40:04.606031Z","price_level":"64651.81","new_quantity":"0.45853931"},{"side":"offer","event_time":"2026-07-15T03:40:04.606031Z","price_level":"64652.46","new_quantity":"0.26312993"},{"side":"offer","event_time":"2026-07-15T03:40:04.606031Z","price_level":"64658.79","new_quantity":"2.02589814"},{"side":"offer","event_time":"2026-07-15T03:40:04.606031Z","price_level":"64658.81","new_quantity":"0"},{"side":"offer","event_time":"2026-07-15T03:40:04.606031Z","price_level":"64662.68","new_quantity":"0"},{"side":"offer","event_time":"2026-07-15T03:40:04.606031Z","price_level":"64666.66","new_quantity":"1.247833"},{"side":"offer","event_time":"2026-07-15T03:40:04.606031Z","price_level":"64669.81","new_quantity":"0"},{"side":"offer","event_time":"2026-07-15T03:40:04.606031Z","price_level":"64681.96","new_quantity":"5.630031"},{"side":"offer","event_time":"2026-07-15T03:40:04.606031Z","price_level":"64738.89","new_quantity":"0"}]}]}
{"channel":"market_trades","timestamp":"2026-07-15T03:40:04.688183138Z","sequence_num":22,"events":[{"type":"update","trades":[{"product_id":"BTC-USD","trade_id":"1056309377","price":"64595.04","size":"0.00000002","time":"2026-07-15T03:40:04.530568Z","side":"BUY"},{"product_id":"BTC-USD","trade_id":"1056309376","price":"64598.72","size":"0.000018","time":"2026-07-15T03:40:04.529743Z","side":"BUY"},{"product_id":"BTC-USD","trade_id":"1056309375","price":"64602.4","size":"0.000018","time":"2026-07-15T03:40:04.501188Z","side":"BUY"}]}]}
{"channel":"l2_data","timestamp":"2026-07-15T03:40:04.695728726Z","sequence_num":23,"events":[{"type":"update","product_id":"BTC-USD","updates":[{"side":"bid","event_time":"2026-07-15T03:40:04.638965Z","price_level":"64602.4","new_quantity":"0"},{"side":"bid","event_time":"2026-07-15T03:40:04.638965Z","price_level":"64592.85","new_quantity":"0.04656107"},{"side":"bid","event_time":"2026-07-15T03:40:04.638965Z","price_level":"64592.84","new_quantity":"0"},{"side":"bid","event_time":"2026-07-15T03:40:04.638965Z","price_level":"64591.81","new_quantity":"0"},{"side":"bid","event_time":"2026-07-15T03:40:04.638965Z","price_level":"64590.26","new_quantity":"0.12385767"},{"side":"bid","event_time":"2026-07-15T03:40:04.638965Z","price_level":"64588.27","new_quantity":"0.15482686"},{"side":"bid","event_time":"2026-07-15T03:40:04.638965Z","price_level":"64587.46","new_quantity":"0.00029931"},{"side":"bid","event_time":"2026-07-15T03:40:04.638965Z","price_level":"64585.41","new_quantity":"0.00059861"},{"side":"bid","event_time":"2026-07-15T03:40:04.638965Z","price_level":"64584.5","new_quantity":"0"},{"side":"bid","event_time":"2026-07-15T03:40:04.638965Z","price_level":"64582.86","new_quantity":"0"},{"side":"bid","event_time":"2026-07-15T03:40:04.638965Z","price_level":"64580.27","new_quantity":"0.06"},{"side":"bid","event_time":"2026-07-15T03:40:04.638965Z","price_level":"64579.67","new_quantity":"0.08"},{"side":"bid","event_time":"2026-07-15T03:40:04.638965Z","price_level":"64579.33","new_quantity":"0.60259505"},{"side":"bid","event_time":"2026-07-15T03:40:04.638965Z","price_level":"64578.04","new_quantity":"0.02782336"},{"side":"bid","event_time":"2026-07-15T03:40:04.638965Z","price_level":"64577.25","new_quantity":"0.23241731"},{"side":"bid","event_time":"2026-07-15T03:40:04.638965Z","price_level":"64574.67","new_quantity":"0"},{"side":"bid","event_time":"2026-07-15T03:40:04.638965Z","price_level":"64574.26","new_quantity":"0"},{"side":"bid","event_time":"2026-07-15T03:40:04.638965Z","price_level":"64571.99","new_quantity":"0"},{"side":"bid","event_time":"2026-07-15T03:40:04.638965Z","price_level":"64570.21","new_quantity":"0"},{"side":"bid","event_time":"2026-07-15T03:40:04.638965Z","price_level":"64568.8","new_quantity":"0.00077391"},{"side":"bid","event_time":"2026-07-15T03:40:04.638965Z","price_level":"64567.63","new_quantity":"0.48073366"},{"side":"bid","event_time":"2026-07-15T03:40:04.638965Z","price_level":"64562.76","new_quantity":"0.00299307"},{"side":"bid","event_time":"2026-07-15T03:40:04.638965Z","price_level":"64560","new_quantity":"1"},{"side":"bid","event_time":"2026-07-15T03:40:04.638965Z","price_level":"64556.03","new_quantity":"0.04302674"},{"side":"bid","event_time":"2026-07-15T03:40:04.638965Z","price_level":"64548.03","new_quantity":"0"},{"side":"bid","event_time":"2026-07-15T03:40:04.638965Z","price_level":"64541.73","new_quantity":"0"},{"side":"bid","event_time":"2026-07-15T03:40:04.638965Z","price_level":"64536.43","new_quantity":"0"},{"side":"bid","event_time":"2026-07-15T03:40:04.638965Z","price_level":"64516.43","new_quantity":"0.00748267"},{"side":"bid","event_time":"2026-07-15T03:40:04.638965Z","price_level":"64515.57","new_quantity":"0"},{"side":"bid","event_time":"2026-07-15T03:40:04.638965Z","price_level":"64506.59","new_quantity":"0"},{"side":"bid","event_time":"2026-07-15T03:40:04.638965Z","price_level":"64502.91","new_quantity":"0"},{"side":"bid","event_time":"2026-07-15T03:40:04.638965Z","price_level":"64485.54","new_quantity":"0.00897921"},{"side":"bid","event_time":"2026-07-15T03:40:04.638965Z","price_level":"64481.84","new_quantity":"11.402352"},{"side":"bid","event_time":"2026-07-15T03:40:04.638965Z","price_level":"56528.13","new_quantity":"0"},{"side":"offer","event_time":"2026-07-15T03:40:04.638965Z","price_level":"64601.41","new_quantity":"0.0334"},{"side":"offer","event_time":"2026-07-15T03:40:04.638965Z","price_level":"64602.41","new_quantity":"0.72443489"},{"side":"offer","event_time":"2026-07-15T03:40:04.638965Z","price_level":"64602.58","new_quantity":"0"},{"side":"offer","event_time":"2026-07-15T03:40:04.638965Z","price_level":"64603.56","new_quantity":"0.17034612"},{"side":"offer","event_time":"2026-07-15T03:40:04.638965Z","price_level":"64603.57","new_quantity":"0.19335116"},{"side":"offer","event_time":"2026-07-15T03:40:04.638965Z","price_level":"64603.58","new_quantity":"0.13169144"},{"side":"offer","event_time":"2026-07-15T03:40:04.638965Z","price_level":"64604.29","new_quantity":"0"},{"side":"offer","event_time":"2026-07-15T03:40:04.638965Z","price_level":"64604.3","new_quantity":"0"},{"side":"offer","event_time":"2026-07-15T03:40:04.638965Z","price_level":"64605.61","new_quantity":"0.048285"},{"side":"offer","event_time":"2026-07-15T03:40:04.638965Z","price_level":"64605.68","new_quantity":"0"},{"side":"offer","event_time":"2026-07-15T03:40:04.638965Z","price_level":"64606.5","new_quantity":"0.16367642"},{"side":"offer","event_time":"2026-07-15T03:40:04.638965Z","price_level":"64606.52","new_quantity":"0"},{"side":"offer","event_time":"2026-07-15T03:40:04.638965Z","price_level":"64606.69","new_quantity":"0.022717"},{"side":"offer","event_time":"2026-07-15T03:40:04.638965Z","price_level":"64609.74","new_quantity":"0.03093532"},{"side":"offer","event_time":"2026-07-15T03:40:04.638965Z","price_level":"64609.75","new_quantity":"0.22305842"},{"side":"offer","event_time":"2026-07-15T03:40:04.638965Z","price_level":"64611.97","new_quantity":"0.07332"},{"side":"offer","event_time":"2026-07-15T03:40:04.638965Z","price_level":"64612.84","new_quantity":"0.05552282"},{"side":"offer","event_time":"2026-07-15T03:40:04.638965Z","price_level":"64613.07","new_quantity":"0.13945925"},{"side":"offer","event_time":"2026-07-15T03:40:04.638965Z","price_level":"64619.1","new_quantity":"0"},{"side":"offer","event_time":"2026-07-15T03:40:04.638965Z","price_level":"64620.35","new_quantity":"0"},{"side":"offer","event_time":"2026-07-15T03:40:04.638965Z","price_level":"64620.81","new_quantity":"0.01591375"},{"side":"offer","event_time":"2026-07-15T03:40:04.638965Z","price_level":"64621.09","new_quantity":"0.00153313"},{"side":"offer","event_time":"2026-07-15T03:40:04.638965Z","price_level":"64624.85","new_quantity":"0.06"},{"side":"offer","event_time":"2026-07-15T03:40:04.638965Z","price_level":"64625.5","new_quantity":"0"},{"side":"offer","event_time":"2026-07-15T03:40:04.638965Z","price_level":"64626.65","new_quantity":"0"},{"side":"offer","event_time":"2026-07-15T03:40:04.638965Z","price_level":"64628.31","new_quantity":"0"},{"side":"offer","event_time":"2026-07-15T03:40:04.638965Z","price_level":"64629.07","new_quantity":"0.03864407"},{"side":"offer","event_time":"2026-07-15T03:40:04.638965Z","price_level":"64629.09","new_quantity":"0"},{"side":"offer","event_time":"2026-07-15T03:40:04.638965Z","price_level":"64630.35","new_quantity":"0"},{"side":"offer","event_time":"2026-07-15T03:40:04.638965Z","price_level":"64630.87","new_quantity":"0"},{"side":"offer","event_time":"2026-07-15T03:40:04.638965Z","price_level":"64633.44","new_quantity":"0.00306626"},{"side":"offer","event_time":"2026-07-15T03:40:04.638965Z","price_level":"64635.18","new_quantity":"0.01615943"},{"side":"offer","event_time":"2026-07-15T03:40:04.638965Z","price_level":"64638.98","new_quantity":"0"},{"side":"offer","event_time":"2026-07-15T03:40:04.638965Z","price_level":"64641.63","new_quantity":"0.01615943"},{"side":"offer","event_time":"2026-07-15T03:40:04.638965Z","price_level":"64644.09","new_quantity":"0.00780353"},{"side":"offer","event_time":"2026-07-15T03:40:04.638965Z","price_level":"64649.13","new_quantity":"0.89448776"},{"side":"offer","event_time":"2026-07-15T03:40:04.638965Z","price_level":"64649.86","new_quantity":"0.00077387"},{"side":"offer","event_time":"2026-07-15T03:40:04.638965Z","price_level":"64651.82","new_quantity":"0.04976448"},{"side":"offer","event_time":"2026-07-15T03:40:04.638965Z","price_level":"64654.64","new_quantity":"0"},{"side":"offer","event_time":"2026-07-15T03:40:04.638965Z","price_level":"64654.91","new_quantity":"0"},{"side":"offer","event_time":"2026-07-15T03:40:04.638965Z","price_level":"64661.1","new_quantity":"0.00077391"},{"side":"offer","event_time":"2026-07-15T03:40:04.638965Z","price_level":"64661.7","new_quantity":"0"},{"side":"offer","event_time":"2026-07-15T03:40:04.638965Z","price_level":"64664.48","new_quantity":"0"},{"side":"offer","event_time":"2026-07-15T03:40:04.638965Z","price_level":"64664.94","new_quantity":"1.01683138"},{"side":"offer","event_time":"2026-07-15T03:40:04.638965Z","price_level":"64665.13","new_quantity":"0"},{"side":"offer","event_time":"2026-07-15T03:40:04.638965Z","price_level":"64670.86","new_quantity":"0.00077391"},{"side":"offer","event_time":"2026-07-15T03:40:04.638965Z","price_level":"64671.87","new_quantity":"0"},{"side":"offer","event_time":"2026-07-15T03:40:04.638965Z","price_level":"64673.82","new_quantity":"0"},{"side":"offer","event_time":"2026-07-15T03:40:04.638965Z","price_level":"64675.95","new_quantity":"0"},{"side":"offer","event_time":"2026-07-15T03:40:04.638965Z","price_level":"64675.96","new_quantity":"0"},{"side":"offer","event_time":"2026-07-15T03:40:04.638965Z","price_level":"64681.47","new_quantity":"0.00766564"},{"side":"offer","event_time":"2026-07-15T03:40:04.638965Z","price_level":"64694.44","new_quantity":"0"},{"side":"offer","event_time":"2026-07-15T03:40:04.638965Z","price_level":"64710","new_quantity":"3"},{"side":"offer","event_time":"2026-07-15T03:40:04.638965Z","price_level":"64721.65","new_quantity":"0.00958205"},{"side":"offer","event_time":"2026-07-15T03:40:04.638965Z","price_level":"64733.73","new_quantity":"0"},{"side":"offer","event_time":"2026-07-15T03:40:04.638965Z","price_level":"64740.13","new_quantity":"0"},{"side":"offer","event_time":"2026-07-15T03:40:04.638965Z","price_level":"64785.55","new_quantity":"0"}]}]}
{"channel":"l2_data","timestamp":"2026-07-15T03:40:04.747572839Z","sequence_num":24,"events":[{"type":"update","product_id":"BTC-USD","updates":[{"side":"bid","event_time":"2026-07-15T03:40:04.693708Z","price_level":"64598.72","new_quantity":"0"},{"side":"bid","event_time":"2026-07-15T03:40:04.693708Z","price_level":"64595.04","new_quantity":"0.00001792"},{"side":"bid","event_time":"2026-07-15T03:40:04.693708Z","price_level":"64594.31","new_quantity":"0"},{"side":"bid","event_time":"2026-07-15T03:40:04.693708Z","price_level":"64592.85","new_quantity":"0"},{"side":"bid","event_time":"2026-07-15T03:40:04.693708Z","price_level":"64592","new_quantity":"0"},{"side":"bid","event_time":"2026-07-15T03:40:04.693708Z","price_level":"64591.12","new_quantity":"0"},{"side":"bid","event_time":"2026-07-15T03:40:04.693708Z","price_level":"64590.26","new_quantity":"0"},{"side":"bid","event_time":"2026-07-15T03:40:04.693708Z","price_level":"64588.27","new_quantity":"0"},{"side":"bid","event_time":"2026-07-15T03:40:04.693708Z","price_level":"64587.93","new_quantity":"0"},{"side":"bid","event_time":"2026-07-15T03:40:04.693708Z","price_level":"64587.75","new_quantity":"0"},{"side":"bid","event_time":"2026-07-15T03:40:04.693708Z","price_level":"64587.53","new_quantity":"0"},{"side":"bid","event_time":"2026-07-15T03:40:04.693708Z","price_level":"64587.28","new_quantity":"0.00619236"},{"side":"bid","event_time":"2026-07-15T03:40:04.693708Z","price_level":"64586.52","new_quantity":"0"},{"side":"bid","event_time":"2026-07-15T03:40:04.693708Z","price_level":"64586.51","new_quantity":"0"},{"side":"bid","event_time":"2026-07-15T03:40:04.693708Z","price_level":"64586.5","new_quantity":"0"},{"side":"bid","event_time":"2026-07-15T03:40:04.693708Z","price_level":"64586.48","new_quantity":"0"},{"side":"bid","event_time":"2026-07-15T03:40:04.693708Z","price_level":"64585.6","new_quantity":"0.15483326"},{"side":"bid","event_time":"2026-07-15T03:40:04.693708Z","price_level":"64584.74","new_quantity":"0"},{"side":"bid","event_time":"2026-07-15T03:40:04.693708Z","price_level":"64584.7","new_quantity":"0.04"},{"side":"bid","event_time":"2026-07-15T03:40:04.693708Z","price_level":"64583.62","new_quantity":"0"},{"side":"bid","event_time":"2026-07-15T03:40:04.693708Z","price_level":"64582.87","new_quantity":"0.04656107"},{"side":"bid","event_time":"2026-07-15T03:40:04.693708Z","price_level":"64582.85","new_quantity":"0.12378505"},{"side":"bid","event_time":"2026-07-15T03:40:04.693708Z","price_level":"64582.78","new_quantity":"0"},{"side":"bid","event_time":"2026-07-15T03:40:04.693708Z","price_level":"64581.66","new_quantity":"0"},{"side":"bid","event_time":"2026-07-15T03:40:04.693708Z","price_level":"64581.58","new_quantity":"0.048285"},{"side":"bid","event_time":"2026-07-15T03:40:04.693708Z","price_level":"64581.55","new_quantity":"0"},{"side":"bid","event_time":"2026-07-15T03:40:04.693708Z","price_level":"64580.93","new_quantity":"0.03093532"},{"side":"bid","event_time":"2026-07-15T03:40:04.693708Z","price_level":"64580.92","new_quantity":"0"},{"side":"bid","event_time":"2026-07-15T03:40:04.693708Z","price_level":"64580.91","new_quantity":"0"},{"side":"bid","event_time":"2026-07-15T03:40:04.693708Z","price_level":"64580.47","new_quantity":"0"},{"side":"bid","event_time":"2026-07-15T03:40:04.693708Z","price_level":"64580.27","new_quantity":"0"},{"side":"bid","event_time":"2026-07-15T03:40:04.693708Z","price_level":"64579.67","new_quantity":"0"},{"side":"bid","event_time":"2026-07-15T03:40:04.693708Z","price_level":"64579.43","new_quantity":"0"},{"side":"bid","event_time":"2026-07-15T03:40:04.693708Z","price_level":"64579.34","new_quantity":"0.12378505"},{"side":"bid","event_time":"2026-07-15T03:40:04.693708Z","price_level":"64579.33","new_quantity":"0.09238191"},{"side":"bid","event_time":"2026-07-15T03:40:04.693708Z","price_level":"64578.36","new_quantity":"0"},{"side":"bid","event_time":"2026-07-15T03:40:04.693708Z","price_level":"64578.04","new_quantity":"0"},{"side":"bid","event_time":"2026-07-15T03:40:04.693708Z","price_level":"64577.86","new_quantity":"0"},{"side":"bid","event_time":"2026-07-15T03:40:04.693708Z","price_level":"64577.85","new_quantity":"0"},{"side":"bid","event_time":"2026-07-15T03:40:04.693708Z","price_level":"64577.52","new_quantity":"0"},{"side":"bid","event_time":"2026-07-15T03:40:04.693708Z","price_level":"64577.26","new_quantity":"0.04656107"},{"side":"bid","event_time":"2026-07-15T03:40:04.693708Z","price_level":"64576.22","new_quantity":"0.12378505"},{"side":"bid","event_time":"2026-07-15T03:40:04.693708Z","price_level":"64575.17","new_quantity":"0"},{"side":"bid","event_time":"2026-07-15T03:40:04.693708Z","price_level":"64575.01","new_quantity":"0.05088628"},{"side":"bid","event_time":"2026-07-15T03:40:04.693708Z","price_level":"64573.97","new_quantity":"0.12378505"},{"side":"bid","event_time":"2026-07-15T03:40:04.693708Z","price_level":"64573.76","new_quantity":"0.00119723"},{"side":"bid","event_time":"2026-07-15T03:40:04.693708Z","price_level":"64571.98","new_quantity":"0"},{"side":"bid","event_time":"2026-07-15T03:40:04.693708Z","price_level":"64571.34","new_quantity":"0"},{"side":"bid","event_time":"2026-07-15T03:40:04.693708Z","price_level":"64570.59","new_quantity":"0.03093532"},{"side":"bid","event_time":"2026-07-15T03:40:04.693708Z","price_level":"64570.09","new_quantity":"0.12378505"},{"side":"bid","event_time":"2026-07-15T03:40:04.693708Z","price_level":"64570","new_quantity":"0.00003194"},{"side":"bid","event_time":"2026-07-15T03:40:04.693708Z","price_level":"64569.29","new_quantity":"0"},{"side":"bid","event_time":"2026-07-15T03:40:04.693708Z","price_level":"64568.8","new_quantity":"0"},{"side":"bid","event_time":"2026-07-15T03:40:04.693708Z","price_level":"64568.79","new_quantity":"0"},{"side":"bid","event_time":"2026-07-15T03:40:04.693708Z","price_level":"64567.65","new_quantity":"1.05289224"},{"side":"bid","event_time":"2026-07-15T03:40:04.693708Z","price_level":"64567.64","new_quantity":"0"},{"side":"bid","event_time":"2026-07-15T03:40:04.693708Z","price_level":"64567.63","new_quantity":"0"},{"side":"bid","event_time":"2026-07-15T03:40:04.693708Z","price_level":"64566.59","new_quantity":"0.597439"},{"side":"bid","event_time":"2026-07-15T03:40:04.693708Z","price_level":"64565.6","new_quantity":"0.000018"},{"side":"bid","event_time":"2026-07-15T03:40:04.693708Z","price_level":"64565.53","new_quantity":"0.00239446"},{"side":"bid","event_time":"2026-07-15T03:40:04.693708Z","price_level":"64565.03","new_quantity":"0"},{"side":"bid","event_time":"2026-07-15T03:40:04.693708Z","price_level":"64564.91","new_quantity":"0"},{"side":"bid","event_time":"2026-07-15T03:40:04.693708Z","price_level":"64564.5","new_quantity":"0"},{"side":"bid","event_time":"2026-07-15T03:40:04.693708Z","price_level":"64562.41","new_quantity":"0"},{"side":"bid","event_time":"2026-07-15T03:40:04.693708Z","price_level":"64562.35","new_quantity":"0.9314897"},{"side":"bid","event_time":"2026-07-15T03:40:04.693708Z","price_level":"64560","new_quantity":"0"},{"side":"bid","event_time":"2026-07-15T03:40:04.693708Z","price_level":"64559.79","new_quantity":"0.60968922"},{"side":"bid","event_time":"2026-07-15T03:40:04.693708Z","price_level":"64556.03","new_quantity":"0.0015533"},{"side":"bid","event_time":"2026-07-15T03:40:04.693708Z","price_level":"64554.57","new_quantity":"0.12378505"},{"side":"bid","event_time":"2026-07-15T03:40:04.693708Z","price_level":"64551.75","new_quantity":"0"},{"side":"bid","event_time":"2026-07-15T03:40:04.693708Z","price_level":"64551.33","new_quantity":"0"},{"side":"bid","event_time":"2026-07-15T03:40:04.693708Z","price_level":"64549","new_quantity":"0"},{"side":"bid","event_time":"2026-07-15T03:40:04.693708Z","price_level":"64548.96","new_quantity":"0"},{"side":"bid","event_time":"2026-07-15T03:40:04.693708Z","price_level":"64546.46","new_quantity":"0.0015533"},{"side":"bid","event_time":"2026-07-15T03:40:04.693708Z","price_level":"64543.27","new_quantity":"0.0015533"},{"side":"bid","event_time":"2026-07-15T03:40:04.693708Z","price_level":"64543.02","new_quantity":"0"},{"side":"bid","event_time":"2026-07-15T03:40:04.693708Z","price_level":"64542.65","new_quantity":"0"},{"side":"bid","event_time":"2026-07-15T03:40:04.693708Z","price_level":"64540.08","new_quantity":"0.0015533"},{"side":"bid","event_time":"2026-07-15T03:40:04.693708Z","price_level":"64536.95","new_quantity":"0.26312993"},{"side":"bid","event_time":"2026-07-15T03:40:04.693708Z","price_level":"64536.89","new_quantity":"0.0015533"},{"side":"bid","event_time":"2026-07-15T03:40:04.693708Z","price_level":"64536.46","new_quantity":"0.07749639"},{"side":"bid","event_time":"2026-07-15T03:40:04.693708Z","price_level":"64536.45","new_quantity":"0"},{"side":"bid","event_time":"2026-07-15T03:40:04.693708Z","price_level":"64536.44","new_quantity":"0"},{"side":"bid","event_time":"2026-07-15T03:40:04.693708Z","price_level":"64533.7","new_quantity":"0.0015533"},{"side":"bid","event_time":"2026-07-15T03:40:04.693708Z","price_level":"64530.51","new_quantity":"0.0015533"},{"side":"bid","event_time":"2026-07-15T03:40:04.693708Z","price_level":"64529.98","new_quantity":"0.03093532"},{"side":"bid","event_time":"2026-07-15T03:40:04.693708Z","price_level":"64529.18","new_quantity":"0"},{"side":"bid","event_time":"2026-07-15T03:40:04.693708Z","price_level":"64522.04","new_quantity":"0.06057538"},{"side":"bid","event_time":"2026-07-15T03:40:04.693708Z","price_level":"64519.75","new_quantity":"0.232053"},{"side":"bid","event_time":"2026-07-15T03:40:04.693708Z","price_level":"64337.6","new_quantity":"0"},{"side":"bid","event_time":"2026-07-15T03:40:04.693708Z","price_level":"64265.81","new_quantity":"0"},{"side":"bid","event_time":"2026-07-15T03:40:04.693708Z","price_level":"64147.51","new_quantity":"0"},{"side":"bid","event_time":"2026-07-15T03:40:04.693708Z","price_level":"63958.4","new_quantity":"1.5"},{"side":"bid","event_time":"2026-07-15T03:40:04.693708Z","price_level":"63579.2","new_quantity":"7"},{"side":"offer","event_time":"2026-07-15T03:40:04.693708Z","price_level":"64602.41","new_quantity":"1.3153508"},{"side":"offer","event_time":"2026-07-15T03:40:04.693708Z","price_level":"64603.56","new_quantity":"0.20128144"},{"side":"offer","event_time":"2026-07-15T03:40:04.693708Z","price_level":"64603.58","new_quantity":"0.13169144"},{"side":"offer","event_time":"2026-07-15T03:40:04.693708Z","price_level":"64603.99","new_quantity":"0.00772597"},{"side":"offer","event_time":"2026-07-15T03:40:04.693708Z","price_level":"64605.61","new_quantity":"0"},{"side":"offer","event_time":"2026-07-15T03:40:04.693708Z","price_level":"64607.07","new_quantity":"0.0015533"},{"side":"offer","event_time":"2026-07-15T03:40:04.693708Z","price_level":"64610.26","new_quantity":"0.0015533"},{"side":"offer","event_time":"2026-07-15T03:40:04.693708Z","price_level":"64613.45","new_quantity":"0.0015533"},{"side":"offer","event_time":"2026-07-15T03:40:04.693708Z","price_level":"64616.64","new_quantity":"0.0015533"},{"side":"offer","event_time":"2026-07-15T03:40:04.693708Z","price_level":"64616.74","new_quantity":"0"},{"side":"offer","event_time":"2026-07-15T03:40:04.693708Z","price_level":"64618.18","new_quantity":"0"},{"side":"offer","event_time":"2026-07-15T03:40:04.693708Z","price_level":"64619.09","new_quantity":"0"},{"side":"offer","event_time":"2026-07-15T03:40:04.693708Z","price_level":"64619.83","new_quantity":"0.0015533"},{"side":"offer","event_time":"2026-07-15T03:40:04.693708Z","price_level":"64621.38","new_quantity":"0.04297119"},{"side":"offer","event_time":"2026-07-15T03:40:04.693708Z","price_level":"64622.67","new_quantity":"0.70134213"},{"side":"offer","event_time":"2026-07-15T03:40:04.693708Z","price_level":"64623.02","new_quantity":"0.0015533"},{"side":"offer","event_time":"2026-07-15T03:40:04.693708Z","price_level":"64624.14","new_quantity":"0"},{"side":"offer","event_time":"2026-07-15T03:40:04.693708Z","price_level":"64625.83","new_quantity":"0"},{"side":"offer","event_time":"2026-07-15T03:40:04.693708Z","price_level":"64626.21","new_quantity":"0.0015533"},{"side":"offer","event_time":"2026-07-15T03:40:04.693708Z","price_level":"64629.4","new_quantity":"0.0015533"},{"side":"offer","event_time":"2026-07-15T03:40:04.693708Z","price_level":"64631.83","new_quantity":"0.02689535"},{"side":"offer","event_time":"2026-07-15T03:40:04.693708Z","price_level":"64632.59","new_quantity":"0.0015533"},{"side":"offer","event_time":"2026-07-15T03:40:04.693708Z","price_level":"64633.54","new_quantity":"0.43083741"},{"side":"offer","event_time":"2026-07-15T03:40:04.693708Z","price_level":"64633.55","new_quantity":"0"},{"side":"offer","event_time":"2026-07-15T03:40:04.693708Z","price_level":"64633.56","new_quantity":"0"},{"side":"offer","event_time":"2026-07-15T03:40:04.693708Z","price_level":"64634.42","new_quantity":"0.0187135"},{"side":"offer","event_time":"2026-07-15T03:40:04.693708Z","price_level":"64635.78","new_quantity":"0.0015533"},{"side":"offer","event_time":"2026-07-15T03:40:04.693708Z","price_level":"64636","new_quantity":"0.00003194"},{"side":"offer","event_time":"2026-07-15T03:40:04.693708Z","price_level":"64638.97","new_quantity":"0.0015533"},{"side":"offer","event_time":"2026-07-15T03:40:04.693708Z","price_level":"64642.16","new_quantity":"0.0015533"},{"side":"offer","event_time":"2026-07-15T03:40:04.693708Z","price_level":"64643.95","new_quantity":"0.04626534"},{"side":"offer","event_time":"2026-07-15T03:40:04.693708Z","price_level":"64645.35","new_quantity":"0.0015533"},{"side":"offer","event_time":"2026-07-15T03:40:04.693708Z","price_level":"64646.75","new_quantity":"0.26312993"},{"side":"offer","event_time":"2026-07-15T03:40:04.693708Z","price_level":"64648.54","new_quantity":"0.0015533"},{"side":"offer","event_time":"2026-07-15T03:40:04.693708Z","price_level":"64649.86","new_quantity":"0"},{"side":"offer","event_time":"2026-07-15T03:40:04.693708Z","price_level":"64650","new_quantity":"0"},{"side":"offer","event_time":"2026-07-15T03:40:04.693708Z","price_level":"64651.73","new_quantity":"0.0015533"},{"side":"offer","event_time":"2026-07-15T03:40:04.693708Z","price_level":"64651.8","new_quantity":"0.32351244"},{"side":"offer","event_time":"2026-07-15T03:40:04.693708Z","price_level":"64651.81","new_quantity":"0"},{"side":"offer","event_time":"2026-07-15T03:40:04.693708Z","price_level":"64651.82","new_quantity":"0"},{"side":"offer","event_time":"2026-07-15T03:40:04.693708Z","price_level":"64652.46","new_quantity":"0"},{"side":"offer","event_time":"2026-07-15T03:40:04.693708Z","price_level":"64654.92","new_quantity":"0.0015533"},{"side":"offer","event_time":"2026-07-15T03:40:04.693708Z","price_level":"64657","new_quantity":"0"},{"side":"offer","event_time":"2026-07-15T03:40:04.693708Z","price_level":"64658.78","new_quantity":"1.39526013"},{"side":"offer","event_time":"2026-07-15T03:40:04.693708Z","price_level":"64658.79","new_quantity":"0"},{"side":"offer","event_time":"2026-07-15T03:40:04.693708Z","price_level":"64658.8","new_quantity":"0"},{"side":"offer","event_time":"2026-07-15T03:40:04.693708Z","price_level":"64661.1","new_quantity":"0"},{"side":"offer","event_time":"2026-07-15T03:40:04.693708Z","price_level":"64662.67","new_quantity":"0"},{"side":"offer","event_time":"2026-07-15T03:40:04.693708Z","price_level":"64662.68","new_quantity":"0.04097492"},{"side":"offer","event_time":"2026-07-15T03:40:04.693708Z","price_level":"64664.94","new_quantity":"1.45285266"},{"side":"offer","event_time":"2026-07-15T03:40:04.693708Z","price_level":"64667.86","new_quantity":"0"},{"side":"offer","event_time":"2026-07-15T03:40:04.693708Z","price_level":"64668.22","new_quantity":"0.05767656"},{"side":"offer","event_time":"2026-07-15T03:40:04.693708Z","price_level":"64670.86","new_quantity":"0"},{"side":"offer","event_time":"2026-07-15T03:40:04.693708Z","price_level":"64670.87","new_quantity":"0"},{"side":"offer","event_time":"2026-07-15T03:40:04.693708Z","price_level":"64705","new_quantity":"3"},{"side":"offer","event_time":"2026-07-15T03:40:04.693708Z","price_level":"64707.06","new_quantity":"0"},{"side":"offer","event_time":"2026-07-15T03:40:04.693708Z","price_level":"64709.41","new_quantity":"0"},{"side":"offer","event_time":"2026-07-15T03:40:04.693708Z","price_level":"64710","new_quantity":"0"}]}]}
{"channel":"market_trades","timestamp":"2026-07-15T03:40:04.784335013Z","sequence_num":25,"events":[{"type":"update","trades":[{"product_id":"BTC-USD","trade_id":"1056309379","price":"64595.04","size":"0.00001792","time":"2026-07-15T03:40:04.646636Z","side":"BUY"},{"product_id":"BTC-USD","trade_id":"1056309378","price":"64595.04","size":"0.00000006","time":"2026-07-15T03:40:04.592989Z","side":"BUY"}]}]}
{"channel":"l2_data","timestamp":"2026-07-15T03:40:04.796280293Z","sequence_num":26,"events":[{"type":"update","product_id":"BTC-USD","updates":[{"side":"bid","event_time":"2026-07-15T03:40:04.754225Z","price_level":"64595.04","new_quantity":"0"},{"side":"bid","event_time":"2026-07-15T03:40:04.754225Z","price_level":"64592.85","new_quantity":"0"},{"side":"bid","event_time":"2026-07-15T03:40:04.754225Z","price_level":"64591.68","new_quantity":"0.00774094"},{"side":"bid","event_time":"2026-07-15T03:40:04.754225Z","price_level":"64590","new_quantity":"0.0257"},{"side":"bid","event_time":"2026-07-15T03:40:04.754225Z","price_level":"64587.28","new_quantity":"0"},{"side":"bid","event_time":"2026-07-15T03:40:04.754225Z","price_level":"64586.71","new_quantity":"0.04656107"},{"side":"bid","event_time":"2026-07-15T03:40:04.754225Z","price_level":"64586.52","new_quantity":"0"},{"side":"bid","event_time":"2026-07-15T03:40:04.754225Z","price_level":"64585.6","new_quantity":"0"},{"side":"bid","event_time":"2026-07-15T03:40:04.754225Z","price_level":"64584.82","new_quantity":"0"},{"side":"bid","event_time":"2026-07-15T03:40:04.754225Z","price_level":"64584.81","new_quantity":"0"},{"side":"bid","event_time":"2026-07-15T03:40:04.754225Z","price_level":"64584.7","new_quantity":"0"},{"side":"bid","event_time":"2026-07-15T03:40:04.754225Z","price_level":"64584.41","new_quantity":"0"},{"side":"bid","event_time":"2026-07-15T03:40:04.754225Z","price_level":"64582.87","new_quantity":"0"},{"side":"bid","event_time":"2026-07-15T03:40:04.754225Z","price_level":"64582.85","new_quantity":"0"},{"side":"bid","event_time":"2026-07-15T03:40:04.754225Z","price_level":"64581.95","new_quantity":"0"},{"side":"bid","event_time":"2026-07-15T03:40:04.754225Z","price_level":"64581.58","new_quantity":"0"},{"side":"bid","event_time":"2026-07-15T03:40:04.754225Z","price_level":"64580.93","new_quantity":"0"},{"side":"bid","event_time":"2026-07-15T03:40:04.754225Z","price_level":"64579.35","new_quantity":"0.03093532"},{"side":"bid","event_time":"2026-07-15T03:40:04.754225Z","price_level":"64579.34","new_quantity":"0"},{"side":"bid","event_time":"2026-07-15T03:40:04.754225Z","price_level":"64579.33","new_quantity":"0"},{"side":"bid","event_time":"2026-07-15T03:40:04.754225Z","price_level":"64576.47","new_quantity":"0.048285"},{"side":"bid","event_time":"2026-07-15T03:40:04.754225Z","price_level":"64576.22","new_quantity":"0"},{"side":"bid","event_time":"2026-07-15T03:40:04.754225Z","price_level":"64573.98","new_quantity":"0"},{"side":"bid","event_time":"2026-07-15T03:40:04.754225Z","price_level":"64573.97","new_quantity":"0"},{"side":"bid","event_time":"2026-07-15T03:40:04.754225Z","price_level":"64572.16","new_quantity":"0.05814958"},{"side":"bid","event_time":"2026-07-15T03:40:04.754225Z","price_level":"64572","new_quantity":"0.00077398"},{"side":"bid","event_time":"2026-07-15T03:40:04.754225Z","price_level":"64570.13","new_quantity":"0.02873502"},{"side":"bid","event_time":"2026-07-15T03:40:04.754225Z","price_level":"64570.09","new_quantity":"0"},{"side":"bid","event_time":"2026-07-15T03:40:04.754225Z","price_level":"64567.76","new_quantity":"0"},{"side":"bid","event_time":"2026-07-15T03:40:04.754225Z","price_level":"64567.65","new_quantity":"0"},{"side":"bid","event_time":"2026-07-15T03:40:04.754225Z","price_level":"64567.62","new_quantity":"0"},{"side":"bid","event_time":"2026-07-15T03:40:04.754225Z","price_level":"64566.59","new_quantity":"0"},{"side":"bid","event_time":"2026-07-15T03:40:04.754225Z","price_level":"64566.52","new_quantity":"0"},{"side":"bid","event_time":"2026-07-15T03:40:04.754225Z","price_level":"64566.29","new_quantity":"0.02799072"},{"side":"bid","event_time":"2026-07-15T03:40:04.754225Z","price_level":"64566.21","new_quantity":"0"},{"side":"bid","event_time":"2026-07-15T03:40:04.754225Z","price_level":"64562.33","new_quantity":"0"},{"side":"bid","event_time":"2026-07-15T03:40:04.754225Z","price_level":"64560.27","new_quantity":"0.035069"},{"side":"bid","event_time":"2026-07-15T03:40:04.754225Z","price_level":"64559.79","new_quantity":"0.61046321"},{"side":"bid","event_time":"2026-07-15T03:40:04.754225Z","price_level":"64559.22","new_quantity":"0"},{"side":"bid","event_time":"2026-07-15T03:40:04.754225Z","price_level":"64558.54","new_quantity":"0.12378505"},{"side":"bid","event_time":"2026-07-15T03:40:04.754225Z","price_level":"64558.45","new_quantity":"0"},{"side":"bid","event_time":"2026-07-15T03:40:04.754225Z","price_level":"64557.81","new_quantity":"0.01447927"},{"side":"bid","event_time":"2026-07-15T03:40:04.754225Z","price_level":"64556.56","new_quantity":"0.12378505"},{"side":"bid","event_time":"2026-07-15T03:40:04.754225Z","price_level":"64556.14","new_quantity":"0"},{"side":"bid","event_time":"2026-07-15T03:40:04.754225Z","price_level":"64556.03","new_quantity":"0"},{"side":"bid","event_time":"2026-07-15T03:40:04.754225Z","price_level":"64554.68","new_quantity":"0"},{"side":"bid","event_time":"2026-07-15T03:40:04.754225Z","price_level":"64554.58","new_quantity":"0.12378505"},{"side":"bid","event_time":"2026-07-15T03:40:04.754225Z","price_level":"64554.57","new_quantity":"0"},{"side":"bid","event_time":"2026-07-15T03:40:04.754225Z","price_level":"64550.8","new_quantity":"0.12378505"},{"side":"bid","event_time":"2026-07-15T03:40:04.754225Z","price_level":"64548.25","new_quantity":"0"},{"side":"bid","event_time":"2026-07-15T03:40:04.754225Z","price_level":"64546.92","new_quantity":"0.12378505"},{"side":"bid","event_time":"2026-07-15T03:40:04.754225Z","price_level":"64543.04","new_quantity":"0.12378505"},{"side":"bid","event_time":"2026-07-15T03:40:04.754225Z","price_level":"64539.16","new_quantity":"0.12378505"},{"side":"bid","event_time":"2026-07-15T03:40:04.754225Z","price_level":"64536.96","new_quantity":"0.01158896"},{"side":"bid","event_time":"2026-07-15T03:40:04.754225Z","price_level":"64536.95","new_quantity":"0"},{"side":"bid","event_time":"2026-07-15T03:40:04.754225Z","price_level":"64536.46","new_quantity":"0.20128144"},{"side":"bid","event_time":"2026-07-15T03:40:04.754225Z","price_level":"64534.05","new_quantity":"0"},{"side":"bid","event_time":"2026-07-15T03:40:04.754225Z","price_level":"64533.17","new_quantity":"0.00598614"},{"side":"bid","event_time":"2026-07-15T03:40:04.754225Z","price_level":"64529.98","new_quantity":"1.38018997"},{"side":"bid","event_time":"2026-07-15T03:40:04.754225Z","price_level":"64529.64","new_quantity":"0"},{"side":"bid","event_time":"2026-07-15T03:40:04.754225Z","price_level":"64522.03","new_quantity":"0"},{"side":"bid","event_time":"2026-07-15T03:40:04.754225Z","price_level":"64515.95","new_quantity":"0"},{"side":"bid","event_time":"2026-07-15T03:40:04.754225Z","price_level":"64515","new_quantity":"0"},{"side":"bid","event_time":"2026-07-15T03:40:04.754225Z","price_level":"64510.01","new_quantity":"2.15479393"},{"side":"bid","event_time":"2026-07-15T03:40:04.754225Z","price_level":"64502.56","new_quantity":"0.02317792"},{"side":"bid","event_time":"2026-07-15T03:40:04.754225Z","price_level":"64489.27","new_quantity":"0"},{"side":"bid","event_time":"2026-07-15T03:40:04.754225Z","price_level":"64463.81","new_quantity":"0.03476688"},{"side":"bid","event_time":"2026-07-15T03:40:04.754225Z","price_level":"64368.35","new_quantity":"0"},{"side":"bid","event_time":"2026-07-15T03:40:04.754225Z","price_level":"63969.46","new_quantity":"0"},{"side":"offer","event_time":"2026-07-15T03:40:04.754225Z","price_level":"64591.81","new_quantity":"0.09082696"},{"side":"offer","event_time":"2026-07-15T03:40:04.754225Z","price_level":"64595.05","new_quantity":"0.07376472"},{"side":"offer","event_time":"2026-07-15T03:40:04.754225Z","price_level":"64595.78","new_quantity":"0.12378505"},{"side":"offer","event_time":"2026-07-15T03:40:04.754225Z","price_level":"64596","new_quantity":"0.0257"},{"side":"offer","event_time":"2026-07-15T03:40:04.754225Z","price_level":"64597.75","new_quantity":"0"},{"side":"offer","event_time":"2026-07-15T03:40:04.754225Z","price_level":"64598.18","new_quantity":"0.00512"},{"side":"offer","event_time":"2026-07-15T03:40:04.754225Z","price_level":"64598.73","new_quantity":"0.15110505"},{"side":"offer","event_time":"2026-07-15T03:40:04.754225Z","price_level":"64599.9","new_quantity":"0"},{"side":"offer","event_time":"2026-07-15T03:40:04.754225Z","price_level":"64600","new_quantity":"0.0257"},{"side":"offer","event_time":"2026-07-15T03:40:04.754225Z","price_level":"64600.26","new_quantity":"0.00100836"},{"side":"offer","event_time":"2026-07-15T03:40:04.754225Z","price_level":"64600.67","new_quantity":"0.12378505"},{"side":"offer","event_time":"2026-07-15T03:40:04.754225Z","price_level":"64601.4","new_quantity":"0.13590072"},{"side":"offer","event_time":"2026-07-15T03:40:04.754225Z","price_level":"64601.41","new_quantity":"0.2871762"},{"side":"offer","event_time":"2026-07-15T03:40:04.754225Z","price_level":"64601.7","new_quantity":"0"},{"side":"offer","event_time":"2026-07-15T03:40:04.754225Z","price_level":"64602","new_quantity":"0.0257"},{"side":"offer","event_time":"2026-07-15T03:40:04.754225Z","price_level":"64602.4","new_quantity":"0.23909985"},{"side":"offer","event_time":"2026-07-15T03:40:04.754225Z","price_level":"64602.41","new_quantity":"0"},{"side":"offer","event_time":"2026-07-15T03:40:04.754225Z","price_level":"64602.71","new_quantity":"0.00773961"},{"side":"offer","event_time":"2026-07-15T03:40:04.754225Z","price_level":"64602.95","new_quantity":"0.00038328"},{"side":"offer","event_time":"2026-07-15T03:40:04.754225Z","price_level":"64603.02","new_quantity":"0.00774015"},{"side":"offer","event_time":"2026-07-15T03:40:04.754225Z","price_level":"64603.55","new_quantity":"0.24758721"},{"side":"offer","event_time":"2026-07-15T03:40:04.754225Z","price_level":"64603.56","new_quantity":"0.17034612"},{"side":"offer","event_time":"2026-07-15T03:40:04.754225Z","price_level":"64603.57","new_quantity":"0"},{"side":"offer","event_time":"2026-07-15T03:40:04.754225Z","price_level":"64603.58","new_quantity":"0.0001198"},{"side":"offer","event_time":"2026-07-15T03:40:04.754225Z","price_level":"64603.99","new_quantity":"0"},{"side":"offer","event_time":"2026-07-15T03:40:04.754225Z","price_level":"64604.02","new_quantity":"0"},{"side":"offer","event_time":"2026-07-15T03:40:04.754225Z","price_level":"64604.46","new_quantity":"0.06267034"},{"side":"offer","event_time":"2026-07-15T03:40:04.754225Z","price_level":"64604.91","new_quantity":"0"},{"side":"offer","event_time":"2026-07-15T03:40:04.754225Z","price_level":"64605.2","new_quantity":"0.00967518"},{"side":"offer","event_time":"2026-07-15T03:40:04.754225Z","price_level":"64606.04","new_quantity":"0.00076656"},{"side":"offer","event_time":"2026-07-15T03:40:04.754225Z","price_level":"64606.2","new_quantity":"0"},{"side":"offer","event_time":"2026-07-15T03:40:04.754225Z","price_level":"64606.62","new_quantity":"0.0278468"},{"side":"offer","event_time":"2026-07-15T03:40:04.754225Z","price_level":"64606.72","new_quantity":"0"},{"side":"offer","event_time":"2026-07-15T03:40:04.754225Z","price_level":"64607.38","new_quantity":"0"},{"side":"offer","event_time":"2026-07-15T03:40:04.754225Z","price_level":"64609.79","new_quantity":"0.00077401"},{"side":"offer","event_time":"2026-07-15T03:40:04.754225Z","price_level":"64610","new_quantity":"0.09902"},{"side":"offer","event_time":"2026-07-15T03:40:04.754225Z","price_level":"64611.96","new_quantity":"0"},{"side":"offer","event_time":"2026-07-15T03:40:04.754225Z","price_level":"64612.84","new_quantity":"0"},{"side":"offer","event_time":"2026-07-15T03:40:04.754225Z","price_level":"64615.5","new_quantity":"0"},{"side":"offer","event_time":"2026-07-15T03:40:04.754225Z","price_level":"64616.54","new_quantity":"0.7679485"},{"side":"offer","event_time":"2026-07-15T03:40:04.754225Z","price_level":"64618.67","new_quantity":"0.448637"},{"side":"offer","event_time":"2026-07-15T03:40:04.754225Z","price_level":"64619.87","new_quantity":"0.00592"},{"side":"offer","event_time":"2026-07-15T03:40:04.754225Z","price_level":"64622","new_quantity":"0"},{"side":"offer","event_time":"2026-07-15T03:40:04.754225Z","price_level":"64622.05","new_quantity":"0"},{"side":"offer","event_time":"2026-07-15T03:40:04.754225Z","price_level":"64622.59","new_quantity":"0.00104492"},{"side":"offer","event_time":"2026-07-15T03:40:04.754225Z","price_level":"64622.67","new_quantity":"0"},{"side":"offer","event_time":"2026-07-15T03:40:04.754225Z","price_level":"64623.98","new_quantity":"0.21500013"},{"side":"offer","event_time":"2026-07-15T03:40:04.754225Z","price_level":"64623.99","new_quantity":"0"},{"side":"offer","event_time":"2026-07-15T03:40:04.754225Z","price_level":"64624","new_quantity":"0"},{"side":"offer","event_time":"2026-07-15T03:40:04.754225Z","price_level":"64624.46","new_quantity":"0.04340985"},{"side":"offer","event_time":"2026-07-15T03:40:04.754225Z","price_level":"64624.85","new_quantity":"0"},{"side":"offer","event_time":"2026-07-15T03:40:04.754225Z","price_level":"64625.33","new_quantity":"0"},{"side":"offer","event_time":"2026-07-15T03:40:04.754225Z","price_level":"64625.97","new_quantity":"0.12371001"},{"side":"offer","event_time":"2026-07-15T03:40:04.754225Z","price_level":"64625.98","new_quantity":"0"},{"side":"offer","event_time":"2026-07-15T03:40:04.754225Z","price_level":"64629.06","new_quantity":"0.49634033"},{"side":"offer","event_time":"2026-07-15T03:40:04.754225Z","price_level":"64629.07","new_quantity":"0"},{"side":"offer","event_time":"2026-07-15T03:40:04.754225Z","price_level":"64629.2","new_quantity":"0.01615943"},{"side":"offer","event_time":"2026-07-15T03:40:04.754225Z","price_level":"64630.74","new_quantity":"0"},{"side":"offer","event_time":"2026-07-15T03:40:04.754225Z","price_level":"64633.54","new_quantity":"0.05940378"},{"side":"offer","event_time":"2026-07-15T03:40:04.754225Z","price_level":"64636.29","new_quantity":"0.01457031"},{"side":"offer","event_time":"2026-07-15T03:40:04.754225Z","price_level":"64640.45","new_quantity":"0.00383282"},{"side":"offer","event_time":"2026-07-15T03:40:04.754225Z","price_level":"64643.94","new_quantity":"0.000774"},{"side":"offer","event_time":"2026-07-15T03:40:04.754225Z","price_level":"64645.45","new_quantity":"0"},{"side":"offer","event_time":"2026-07-15T03:40:04.754225Z","price_level":"64646.74","new_quantity":"0.42491113"},{"side":"offer","event_time":"2026-07-15T03:40:04.754225Z","price_level":"64646.75","new_quantity":"0"},{"side":"offer","event_time":"2026-07-15T03:40:04.754225Z","price_level":"64647.41","new_quantity":"0"},{"side":"offer","event_time":"2026-07-15T03:40:04.754225Z","price_level":"64647.42","new_quantity":"0"},{"side":"offer","event_time":"2026-07-15T03:40:04.754225Z","price_level":"64649.13","new_quantity":"0.9011001"},{"side":"offer","event_time":"2026-07-15T03:40:04.754225Z","price_level":"64649.99","new_quantity":"1.43110276"},{"side":"offer","event_time":"2026-07-15T03:40:04.754225Z","price_level":"64650.46","new_quantity":"0.19150589"},{"side":"offer","event_time":"2026-07-15T03:40:04.754225Z","price_level":"64650.47","new_quantity":"0"},{"side":"offer","event_time":"2026-07-15T03:40:04.754225Z","price_level":"64651.8","new_quantity":"0.03965538"},{"side":"offer","event_time":"2026-07-15T03:40:04.754225Z","price_level":"64654.26","new_quantity":"1.39201985"},{"side":"offer","event_time":"2026-07-15T03:40:04.754225Z","price_level":"64654.63","new_quantity":"0.00077399"},{"side":"offer","event_time":"2026-07-15T03:40:04.754225Z","price_level":"64655.8","new_quantity":"1.41200301"},{"side":"offer","event_time":"2026-07-15T03:40:04.754225Z","price_level":"64655.82","new_quantity":"0"},{"side":"offer","event_time":"2026-07-15T03:40:04.754225Z","price_level":"64658.78","new_quantity":"0.02919705"},{"side":"offer","event_time":"2026-07-15T03:40:04.754225Z","price_level":"64664.47","new_quantity":"0.00077398"},{"side":"offer","event_time":"2026-07-15T03:40:04.754225Z","price_level":"64668.45","new_quantity":"0"},{"side":"offer","event_time":"2026-07-15T03:40:04.754225Z","price_level":"64669.82","new_quantity":"0"},{"side":"offer","event_time":"2026-07-15T03:40:04.754225Z","price_level":"64673.16","new_quantity":"0.04064519"},{"side":"offer","event_time":"2026-07-15T03:40:04.754225Z","price_level":"64673.17","new_quantity":"0"},{"side":"offer","event_time":"2026-07-15T03:40:04.754225Z","price_level":"64676.1","new_quantity":"0.01331"},{"side":"offer","event_time":"2026-07-15T03:40:04.754225Z","price_level":"64682.47","new_quantity":"0.00348306"},{"side":"offer","event_time":"2026-07-15T03:40:04.754225Z","price_level":"64685.5","new_quantity":"0.15973945"},{"side":"offer","event_time":"2026-07-15T03:40:04.754225Z","price_level":"64705","new_quantity":"0"},{"side":"offer","event_time":"2026-07-15T03:40:04.754225Z","price_level":"64748.74","new_quantity":"0"},{"side":"offer","event_time":"2026-07-15T03:40:04.754225Z","price_level":"64750.83","new_quantity":"0"},{"side":"offer","event_time":"2026-07-15T03:40:04.754225Z","price_level":"64760.98","new_quantity":"0.01149846"},{"side":"offer","event_time":"2026-07-15T03:40:04.754225Z","price_level":"64761.22","new_quantity":"11.837405"},{"side":"offer","event_time":"2026-07-15T03:40:04.754225Z","price_level":"64817.79","new_quantity":"0"},{"side":"offer","event_time":"2026-07-15T03:40:04.754225Z","price_level":"64829.91","new_quantity":"0"},{"side":"offer","event_time":"2026-07-15T03:40:04.754225Z","price_level":"64870.28","new_quantity":"0"},{"side":"offer","event_time":"2026-07-15T03:40:04.754225Z","price_level":"64887.52","new_quantity":"0"}]}]}
{"channel":"l2_data","timestamp":"2026-07-15T03:40:04.845281299Z","sequence_num":27,"events":[{"type":"update","product_id":"BTC-USD","updates":[{"side":"bid","event_time":"2026-07-15T03:40:04.791466Z","price_level":"64591.8","new_quantity":"0"},{"side":"bid","event_time":"2026-07-15T03:40:04.791466Z","price_level":"64591.68","new_quantity":"0"},{"side":"bid","event_time":"2026-07-15T03:40:04.791466Z","price_level":"64590","new_quantity":"0"},{"side":"bid","event_time":"2026-07-15T03:40:04.791466Z","price_level":"64587.46","new_quantity":"0"},{"side":"bid","event_time":"2026-07-15T03:40:04.791466Z","price_level":"64586","new_quantity":"0.0257"},{"side":"bid","event_time":"2026-07-15T03:40:04.791466Z","price_level":"64585.41","new_quantity":"0"},{"side":"bid","event_time":"2026-07-15T03:40:04.791466Z","price_level":"64579.49","new_quantity":"0.04644472"},{"side":"bid","event_time":"2026-07-15T03:40:04.791466Z","price_level":"64579.35","new_quantity":"0"},{"side":"bid","event_time":"2026-07-15T03:40:04.791466Z","price_level":"64577.27","new_quantity":"0.03093532"},{"side":"bid","event_time":"2026-07-15T03:40:04.791466Z","price_level":"64576.47","new_quantity":"0"},{"side":"bid","event_time":"2026-07-15T03:40:04.791466Z","price_level":"64576.17","new_quantity":"0"},{"side":"bid","event_time":"2026-07-15T03:40:04.791466Z","price_level":"64575.01","new_quantity":"0"},{"side":"bid","event_time":"2026-07-15T03:40:04.791466Z","price_level":"64573.68","new_quantity":"0.048285"},{"side":"bid","event_time":"2026-07-15T03:40:04.791466Z","price_level":"64570.13","new_quantity":"0.12454965"},{"side":"bid","event_time":"2026-07-15T03:40:04.791466Z","price_level":"64569.65","new_quantity":"0.12378505"},{"side":"bid","event_time":"2026-07-15T03:40:04.791466Z","price_level":"64567.63","new_quantity":"0.11486927"},{"side":"bid","event_time":"2026-07-15T03:40:04.791466Z","price_level":"64566.29","new_quantity":"0"},{"side":"bid","event_time":"2026-07-15T03:40:04.791466Z","price_level":"64566.23","new_quantity":"0.12378505"},{"side":"bid","event_time":"2026-07-15T03:40:04.791466Z","price_level":"64563.47","new_quantity":"0.12378505"},{"side":"bid","event_time":"2026-07-15T03:40:04.791466Z","price_level":"64562.76","new_quantity":"0"},{"side":"bid","event_time":"2026-07-15T03:40:04.791466Z","price_level":"64562.36","new_quantity":"0.63001033"},{"side":"bid","event_time":"2026-07-15T03:40:04.791466Z","price_level":"64562.35","new_quantity":"0"},{"side":"bid","event_time":"2026-07-15T03:40:04.791466Z","price_level":"64562.34","new_quantity":"0"},{"side":"bid","event_time":"2026-07-15T03:40:04.791466Z","price_level":"64561.14","new_quantity":"0.12378505"},{"side":"bid","event_time":"2026-07-15T03:40:04.791466Z","price_level":"64559.8","new_quantity":"1.68046656"},{"side":"bid","event_time":"2026-07-15T03:40:04.791466Z","price_level":"64559.79","new_quantity":"0.00077399"},{"side":"bid","event_time":"2026-07-15T03:40:04.791466Z","price_level":"64557.81","new_quantity":"0"},{"side":"bid","event_time":"2026-07-15T03:40:04.791466Z","price_level":"64555.73","new_quantity":"0.04359169"},{"side":"bid","event_time":"2026-07-15T03:40:04.791466Z","price_level":"64554.69","new_quantity":"0.06722519"},{"side":"bid","event_time":"2026-07-15T03:40:04.791466Z","price_level":"64554.68","new_quantity":"0.60973748"},{"side":"bid","event_time":"2026-07-15T03:40:04.791466Z","price_level":"64552.5","new_quantity":"1"},{"side":"bid","event_time":"2026-07-15T03:40:04.791466Z","price_level":"64548.25","new_quantity":"0.0401358"},{"side":"bid","event_time":"2026-07-15T03:40:04.791466Z","price_level":"64544.34","new_quantity":"0.04719266"},{"side":"bid","event_time":"2026-07-15T03:40:04.791466Z","price_level":"64539.16","new_quantity":"0"},{"side":"bid","event_time":"2026-07-15T03:40:04.791466Z","price_level":"64536.96","new_quantity":"0.21587019"},{"side":"bid","event_time":"2026-07-15T03:40:04.791466Z","price_level":"64536.46","new_quantity":"0.07749639"},{"side":"bid","event_time":"2026-07-15T03:40:04.791466Z","price_level":"64529.99","new_quantity":"1.86949494"},{"side":"bid","event_time":"2026-07-15T03:40:04.791466Z","price_level":"64529.58","new_quantity":"0.26318673"},{"side":"bid","event_time":"2026-07-15T03:40:04.791466Z","price_level":"64527.21","new_quantity":"0.00510607"},{"side":"bid","event_time":"2026-07-15T03:40:04.791466Z","price_level":"64524.11","new_quantity":"0"},{"side":"bid","event_time":"2026-07-15T03:40:04.791466Z","price_level":"64516.43","new_quantity":"0"},{"side":"bid","event_time":"2026-07-15T03:40:04.791466Z","price_level":"64508.39","new_quantity":"5.51055376"},{"side":"bid","event_time":"2026-07-15T03:40:04.791466Z","price_level":"64503.1","new_quantity":"0.00348306"},{"side":"bid","event_time":"2026-07-15T03:40:04.791466Z","price_level":"64495","new_quantity":"3"},{"side":"bid","event_time":"2026-07-15T03:40:04.791466Z","price_level":"64485.54","new_quantity":"0"},{"side":"bid","event_time":"2026-07-15T03:40:04.791466Z","price_level":"64444.94","new_quantity":"0"},{"side":"offer","event_time":"2026-07-15T03:40:04.791466Z","price_level":"64591.81","new_quantity":"0.21922793"},{"side":"offer","event_time":"2026-07-15T03:40:04.791466Z","price_level":"64592","new_quantity":"0.0257"},{"side":"offer","event_time":"2026-07-15T03:40:04.791466Z","price_level":"64592.56","new_quantity":"0.12378505"},{"side":"offer","event_time":"2026-07-15T03:40:04.791466Z","price_level":"64593.53","new_quantity":"0.09472972"},{"side":"offer","event_time":"2026-07-15T03:40:04.791466Z","price_level":"64594.05","new_quantity":"0.0334"},{"side":"offer","event_time":"2026-07-15T03:40:04.791466Z","price_level":"64595.04","new_quantity":"0.07450692"},{"side":"offer","event_time":"2026-07-15T03:40:04.791466Z","price_level":"64595.05","new_quantity":"0.32941497"},{"side":"offer","event_time":"2026-07-15T03:40:04.791466Z","price_level":"64596.66","new_quantity":"0.00774072"},{"side":"offer","event_time":"2026-07-15T03:40:04.791466Z","price_level":"64597.28","new_quantity":"0.03093532"},{"side":"offer","event_time":"2026-07-15T03:40:04.791466Z","price_level":"64597.59","new_quantity":"0.04656107"},{"side":"offer","event_time":"2026-07-15T03:40:04.791466Z","price_level":"64598.18","new_quantity":"0"},{"side":"offer","event_time":"2026-07-15T03:40:04.791466Z","price_level":"64598.73","new_quantity":"0.14378505"},{"side":"offer","event_time":"2026-07-15T03:40:04.791466Z","price_level":"64600.26","new_quantity":"0"},{"side":"offer","event_time":"2026-07-15T03:40:04.791466Z","price_level":"64600.66","new_quantity":"0.35648161"},{"side":"offer","event_time":"2026-07-15T03:40:04.791466Z","price_level":"64601.35","new_quantity":"0"},{"side":"offer","event_time":"2026-07-15T03:40:04.791466Z","price_level":"64601.4","new_quantity":"0"},{"side":"offer","event_time":"2026-07-15T03:40:04.791466Z","price_level":"64601.41","new_quantity":"0"},{"side":"offer","event_time":"2026-07-15T03:40:04.791466Z","price_level":"64602.4","new_quantity":"0"},{"side":"offer","event_time":"2026-07-15T03:40:04.791466Z","price_level":"64602.71","new_quantity":"0"},{"side":"offer","event_time":"2026-07-15T03:40:04.791466Z","price_level":"64603.02","new_quantity":"0"},{"side":"offer","event_time":"2026-07-15T03:40:04.791466Z","price_level":"64605.2","new_quantity":"0"},{"side":"offer","event_time":"2026-07-15T03:40:04.791466Z","price_level":"64609.75","new_quantity":"0.3087671"},{"side":"offer","event_time":"2026-07-15T03:40:04.791466Z","price_level":"64609.76","new_quantity":"0.12378505"},{"side":"offer","event_time":"2026-07-15T03:40:04.791466Z","price_level":"64611","new_quantity":"1"},{"side":"offer","event_time":"2026-07-15T03:40:04.791466Z","price_level":"64613.07","new_quantity":"0.71955698"},{"side":"offer","event_time":"2026-07-15T03:40:04.791466Z","price_level":"64616.54","new_quantity":"0.43878479"},{"side":"offer","event_time":"2026-07-15T03:40:04.791466Z","price_level":"64618","new_quantity":"0"},{"side":"offer","event_time":"2026-07-15T03:40:04.791466Z","price_level":"64618.37","new_quantity":"0.00002323"},{"side":"offer","event_time":"2026-07-15T03:40:04.791466Z","price_level":"64618.53","new_quantity":"0"},{"side":"offer","event_time":"2026-07-15T03:40:04.791466Z","price_level":"64619.41","new_quantity":"0.09759185"},{"side":"offer","event_time":"2026-07-15T03:40:04.791466Z","price_level":"64620","new_quantity":"0"},{"side":"offer","event_time":"2026-07-15T03:40:04.791466Z","price_level":"64621.09","new_quantity":"0"},{"side":"offer","event_time":"2026-07-15T03:40:04.791466Z","price_level":"64623.98","new_quantity":"0"},{"side":"offer","event_time":"2026-07-15T03:40:04.791466Z","price_level":"64625.97","new_quantity":"0.40513642"},{"side":"offer","event_time":"2026-07-15T03:40:04.791466Z","price_level":"64629.19","new_quantity":"0.02726552"},{"side":"offer","event_time":"2026-07-15T03:40:04.791466Z","price_level":"64631.82","new_quantity":"0"},{"side":"offer","event_time":"2026-07-15T03:40:04.791466Z","price_level":"64633.44","new_quantity":"0"},{"side":"offer","event_time":"2026-07-15T03:40:04.791466Z","price_level":"64636.28","new_quantity":"0.0203391"},{"side":"offer","event_time":"2026-07-15T03:40:04.791466Z","price_level":"64639.37","new_quantity":"0.26318673"},{"side":"offer","event_time":"2026-07-15T03:40:04.791466Z","price_level":"64646.74","new_quantity":"0.15708857"},{"side":"offer","event_time":"2026-07-15T03:40:04.791466Z","price_level":"64655.79","new_quantity":"0.86238611"},{"side":"offer","event_time":"2026-07-15T03:40:04.791466Z","price_level":"64655.81","new_quantity":"0"},{"side":"offer","event_time":"2026-07-15T03:40:04.791466Z","price_level":"64664.49","new_quantity":"0"},{"side":"offer","event_time":"2026-07-15T03:40:04.791466Z","price_level":"64667.68","new_quantity":"0"},{"side":"offer","event_time":"2026-07-15T03:40:04.791466Z","price_level":"64668.22","new_quantity":"0"},{"side":"offer","event_time":"2026-07-15T03:40:04.791466Z","price_level":"64668.23","new_quantity":"0"},{"side":"offer","event_time":"2026-07-15T03:40:04.791466Z","price_level":"64673.16","new_quantity":"0"},{"side":"offer","event_time":"2026-07-15T03:40:04.791466Z","price_level":"64681.47","new_quantity":"0"},{"side":"offer","event_time":"2026-07-15T03:40:04.791466Z","price_level":"64700","new_quantity":"0.00394126"},{"side":"offer","event_time":"2026-07-15T03:40:04.791466Z","price_level":"64721.65","new_quantity":"0"}]}]}
{"channel":"market_trades","timestamp":"2026-07-15T03:40:04.887688752Z","sequence_num":28,"events":[{"type":"update","trades":[{"product_id":"BTC-USD","trade_id":"1056309382","price":"64591.36","size":"0.00001772","time":"2026-07-15T03:40:04.774458Z","side":"BUY"},{"product_id":"BTC-USD","trade_id":"1056309381","price":"64591.36","size":"0.00000028","time":"2026-07-15T03:40:04.732494Z","side":"BUY"},{"product_id":"BTC-USD","trade_id":"1056309380","price":"64591.8","size":"0.05","time":"2026-07-15T03:40:04.681276Z","side":"BUY"}]}]}
{"channel":"l2_data","timestamp":"2026-07-15T03:40:04.912010131Z","sequence_num":29,"events":[{"type":"update","product_id":"BTC-USD","updates":[{"side":"bid","event_time":"2026-07-15T03:40:04.81394Z","price_level":"64591.36","new_quantity":"0.00001772"},{"side":"bid","event_time":"2026-07-15T03:40:04.81394Z","price_level":"64586.71","new_quantity":"0"},{"side":"bid","event_time":"2026-07-15T03:40:04.81394Z","price_level":"64584.42","new_quantity":"0.04656107"},{"side":"bid","event_time":"2026-07-15T03:40:04.81394Z","price_level":"64583.26","new_quantity":"0.02"},{"side":"bid","event_time":"2026-07-15T03:40:04.81394Z","price_level":"64579.49","new_quantity":"0"},{"side":"bid","event_time":"2026-07-15T03:40:04.81394Z","price_level":"64577.97","new_quantity":"0.04644472"},{"side":"bid","event_time":"2026-07-15T03:40:04.81394Z","price_level":"64577.27","new_quantity":"0.03093532"},{"side":"bid","event_time":"2026-07-15T03:40:04.81394Z","price_level":"64573.66","new_quantity":"0.12378505"},{"side":"bid","event_time":"2026-07-15T03:40:04.81394Z","price_level":"64571.62","new_quantity":"0.12378505"},{"side":"bid","event_time":"2026-07-15T03:40:04.81394Z","price_level":"64571.23","new_quantity":"0.03093532"},{"side":"bid","event_time":"2026-07-15T03:40:04.81394Z","price_level":"64570.59","new_quantity":"0"},{"side":"bid","event_time":"2026-07-15T03:40:04.81394Z","price_level":"64570.13","new_quantity":"0"},{"side":"bid","event_time":"2026-07-15T03:40:04.81394Z","price_level":"64567.63","new_quantity":"0"},{"side":"bid","event_time":"2026-07-15T03:40:04.81394Z","price_level":"64555.73","new_quantity":"0"},{"side":"bid","event_time":"2026-07-15T03:40:04.81394Z","price_level":"64553.04","new_quantity":"0.0005"},{"side":"bid","event_time":"2026-07-15T03:40:04.81394Z","price_level":"64552.5","new_quantity":"0"},{"side":"bid","event_time":"2026-07-15T03:40:04.81394Z","price_level":"64546.92","new_quantity":"0"},{"side":"bid","event_time":"2026-07-15T03:40:04.81394Z","price_level":"64543.04","new_quantity":"0"},{"side":"bid","event_time":"2026-07-15T03:40:04.81394Z","price_level":"64536.96","new_quantity":"0.01158896"},{"side":"bid","event_time":"2026-07-15T03:40:04.81394Z","price_level":"64529.98","new_quantity":"0.03093532"},{"side":"bid","event_time":"2026-07-15T03:40:04.81394Z","price_level":"64522.05","new_quantity":"1.34942048"},{"side":"bid","event_time":"2026-07-15T03:40:04.81394Z","price_level":"64499.17","new_quantity":"0.04985013"},{"side":"offer","event_time":"2026-07-15T03:40:04.81394Z","price_level":"64591.37","new_quantity":"0.10557483"},{"side":"offer","event_time":"2026-07-15T03:40:04.81394Z","price_level":"64591.8","new_quantity":"0.07450714"},{"side":"offer","event_time":"2026-07-15T03:40:04.81394Z","price_level":"64591.81","new_quantity":"0.41333162"},{"side":"offer","event_time":"2026-07-15T03:40:04.81394Z","price_level":"64593.42","new_quantity":"0.00774094"},{"side":"offer","event_time":"2026-07-15T03:40:04.81394Z","price_level":"64593.53","new_quantity":"0.048285"},{"side":"offer","event_time":"2026-07-15T03:40:04.81394Z","price_level":"64594","new_quantity":"0.0257"},{"side":"offer","event_time":"2026-07-15T03:40:04.81394Z","price_level":"64594.05","new_quantity":"0"},{"side":"offer","event_time":"2026-07-15T03:40:04.81394Z","price_level":"64595.02","new_quantity":"0.1548107"},{"side":"offer","event_time":"2026-07-15T03:40:04.81394Z","price_level":"64595.04","new_quantity":"0"},{"side":"offer","event_time":"2026-07-15T03:40:04.81394Z","price_level":"64595.05","new_quantity":"0"},{"side":"offer","event_time":"2026-07-15T03:40:04.81394Z","price_level":"64596.66","new_quantity":"0"},{"side":"offer","event_time":"2026-07-15T03:40:04.81394Z","price_level":"64606.5","new_quantity":"0.10373194"},{"side":"offer","event_time":"2026-07-15T03:40:04.81394Z","price_level":"64606.69","new_quantity":"0"},{"side":"offer","event_time":"2026-07-15T03:40:04.81394Z","price_level":"64607.73","new_quantity":"0.05850425"},{"side":"offer","event_time":"2026-07-15T03:40:04.81394Z","price_level":"64611","new_quantity":"0"},{"side":"offer","event_time":"2026-07-15T03:40:04.81394Z","price_level":"64611.97","new_quantity":"0"},{"side":"offer","event_time":"2026-07-15T03:40:04.81394Z","price_level":"64613.07","new_quantity":"0.13945925"},{"side":"offer","event_time":"2026-07-15T03:40:04.81394Z","price_level":"64614","new_quantity":"0"},{"side":"offer","event_time":"2026-07-15T03:40:04.81394Z","price_level":"64616","new_quantity":"0"},{"side":"offer","event_time":"2026-07-15T03:40:04.81394Z","price_level":"64618.2","new_quantity":"0"},{"side":"offer","event_time":"2026-07-15T03:40:04.81394Z","price_level":"64622.65","new_quantity":"0.5514985"},{"side":"offer","event_time":"2026-07-15T03:40:04.81394Z","price_level":"64629.06","new_quantity":"0"},{"side":"offer","event_time":"2026-07-15T03:40:04.81394Z","price_level":"64638.79","new_quantity":"0.25208105"},{"side":"offer","event_time":"2026-07-15T03:40:04.81394Z","price_level":"64643.94","new_quantity":"0.19227989"},{"side":"offer","event_time":"2026-07-15T03:40:04.81394Z","price_level":"64646.74","new_quantity":"0"},{"side":"offer","event_time":"2026-07-15T03:40:04.81394Z","price_level":"64649.98","new_quantity":"1.41200301"},{"side":"offer","event_time":"2026-07-15T03:40:04.81394Z","price_level":"64650.46","new_quantity":"0"},{"side":"offer","event_time":"2026-07-15T03:40:04.81394Z","price_level":"64651.8","new_quantity":"0.86608344"},{"side":"offer","event_time":"2026-07-15T03:40:04.81394Z","price_level":"64655.8","new_quantity":"0"},{"side":"offer","event_time":"2026-07-15T03:40:04.81394Z","price_level":"64661.3","new_quantity":"0"},{"side":"offer","event_time":"2026-07-15T03:40:04.81394Z","price_level":"64695","new_quantity":"3"},{"side":"offer","event_time":"2026-07-15T03:40:04.81394Z","price_level":"64710.9","new_quantity":"0.00309066"},{"side":"offer","event_time":"2026-07-15T03:40:04.81394Z","price_level":"64743.57","new_quantity":"0"}]}]}
