{"channel":"l2_data","timestamp":"2026-07-16T20:29:23.741865754Z","sequence_num":635,"events":[{"type":"update","product_id":"BTC-USD","updates":[{"side":"bid","event_time":"2026-07-16T20:29:23.708582Z","price_level":"64130.68","new_quantity":"0"},{"side":"bid","event_time":"2026-07-16T20:29:23.708582Z","price_level":"64129.32","new_quantity":"0.02"},{"side":"bid","event_time":"2026-07-16T20:29:23.708582Z","price_level":"64129.31","new_quantity":"0.12474794"},{"side":"bid","event_time":"2026-07-16T20:29:23.708582Z","price_level":"64127.37","new_quantity":"0.15593964"},{"side":"bid","event_time":"2026-07-16T20:29:23.708582Z","price_level":"64122.59","new_quantity":"0.0077892"},{"side":"bid","event_time":"2026-07-16T20:29:23.708582Z","price_level":"64118.74","new_quantity":"0"},{"side":"bid","event_time":"2026-07-16T20:29:23.708582Z","price_level":"64112.43","new_quantity":"0.00583"},{"side":"bid","event_time":"2026-07-16T20:29:23.708582Z","price_level":"64112.33","new_quantity":"0"},{"side":"bid","event_time":"2026-07-16T20:29:23.708582Z","price_level":"64112.04","new_quantity":"0"},{"side":"bid","event_time":"2026-07-16T20:29:23.708582Z","price_level":"64026.31","new_quantity":"0"},{"side":"bid","event_time":"2026-07-16T20:29:23.708582Z","price_level":"63897.95","new_quantity":"0.00583"},{"side":"bid","event_time":"2026-07-16T20:29:23.708582Z","price_level":"63897.9","new_quantity":"0.00583"},{"side":"bid","event_time":"2026-07-16T20:29:23.708582Z","price_level":"63897.48","new_quantity":"0"},{"side":"bid","event_time":"2026-07-16T20:29:23.708582Z","price_level":"63682.58","new_quantity":"0"},{"side":"bid","event_time":"2026-07-16T20:29:23.708582Z","price_level":"63254.71","new_quantity":"0.00583"},{"side":"bid","event_time":"2026-07-16T20:29:23.708582Z","price_level":"63254.61","new_quantity":"0"},{"side":"bid","event_time":"2026-07-16T20:29:23.708582Z","price_level":"63254.31","new_quantity":"0"},{"side":"bid","event_time":"2026-07-16T20:29:23.708582Z","price_level":"63040.23","new_quantity":"0.00583"},{"side":"bid","event_time":"2026-07-16T20:29:23.708582Z","price_level":"63039.71","new_quantity":"0"},{"side":"bid","event_time":"2026-07-16T20:29:23.708582Z","price_level":"62825.28","new_quantity":"0"},{"side":"offer","event_time":"2026-07-16T20:29:23.708582Z","price_level":"64135.01","new_quantity":"1.0985617"},{"side":"offer","event_time":"2026-07-16T20:29:23.708582Z","price_level":"64137.18","new_quantity":"0.28428554"},{"side":"offer","event_time":"2026-07-16T20:29:23.708582Z","price_level":"64137.19","new_quantity":"0.31190852"},{"side":"offer","event_time":"2026-07-16T20:29:23.708582Z","price_level":"64137.46","new_quantity":"0"},{"side":"offer","event_time":"2026-07-16T20:29:23.708582Z","price_level":"64144.47","new_quantity":"0"},{"side":"offer","event_time":"2026-07-16T20:29:23.708582Z","price_level":"64144.48","new_quantity":"0.00009744"},{"side":"offer","event_time":"2026-07-16T20:29:23.708582Z","price_level":"64144.56","new_quantity":"0.0077892"},{"side":"offer","event_time":"2026-07-16T20:29:23.708582Z","price_level":"64158.46","new_quantity":"0"},{"side":"offer","event_time":"2026-07-16T20:29:23.708582Z","price_level":"64219.63","new_quantity":"0"}]}]}
{"channel":"l2_data","timestamp":"2026-07-16T20:29:23.789713282Z","sequence_num":636,"events":[{"type":"update","product_id":"BTC-USD","updates":[{"side":"bid","event_time":"2026-07-16T20:29:23.75032Z","price_level":"64129.9","new_quantity":"0.12474678"},{"side":"bid","event_time":"2026-07-16T20:29:23.75032Z","price_level":"64129.31","new_quantity":"0"},{"side":"bid","event_time":"2026-07-16T20:29:23.75032Z","price_level":"64125.4","new_quantity":"0"},{"side":"bid","event_time":"2026-07-16T20:29:23.75032Z","price_level":"64125.39","new_quantity":"0.01559475"},{"side":"bid","event_time":"2026-07-16T20:29:23.75032Z","price_level":"63897.9","new_quantity":"0"},{"side":"bid","event_time":"2026-07-16T20:29:23.75032Z","price_level":"63468.35","new_quantity":"0.00583"},{"side":"bid","event_time":"2026-07-16T20:29:23.75032Z","price_level":"63468.34","new_quantity":"0"},{"side":"bid","event_time":"2026-07-16T20:29:23.75032Z","price_level":"63254.71","new_quantity":"0"},{"side":"bid","event_time":"2026-07-16T20:29:23.75032Z","price_level":"63253.48","new_quantity":"0.00583"},{"side":"offer","event_time":"2026-07-16T20:29:23.75032Z","price_level":"64147.97","new_quantity":"0"}]}]}
{"channel":"l2_data","timestamp":"2026-07-16T20:29:23.840108538Z","sequence_num":637,"events":[{"type":"update","product_id":"BTC-USD","updates":[{"side":"bid","event_time":"2026-07-16T20:29:23.821196Z","price_level":"64135","new_quantity":"0.01797937"},{"side":"bid","event_time":"2026-07-16T20:29:23.821196Z","price_level":"64130.69","new_quantity":"0"},{"side":"bid","event_time":"2026-07-16T20:29:23.821196Z","price_level":"64129.91","new_quantity":"0.02"},{"side":"bid","event_time":"2026-07-16T20:29:23.821196Z","price_level":"63468.35","new_quantity":"0"},{"side":"bid","event_time":"2026-07-16T20:29:23.821196Z","price_level":"56118.13","new_quantity":"0.01337205"}]}]}
{"channel":"l2_data","timestamp":"2026-07-16T20:29:23.894418741Z","sequence_num":638,"events":[{"type":"update","product_id":"BTC-USD","updates":[{"side":"bid","event_time":"2026-07-16T20:29:23.846675Z","price_level":"64125.39","new_quantity":"0"},{"side":"bid","event_time":"2026-07-16T20:29:23.846675Z","price_level":"64125.37","new_quantity":"0.01559475"},{"side":"bid","event_time":"2026-07-16T20:29:23.846675Z","price_level":"63683.09","new_quantity":"0.00583"},{"side":"bid","event_time":"2026-07-16T20:29:23.846675Z","price_level":"63468.5","new_quantity":"0.00583"},{"side":"bid","event_time":"2026-07-16T20:29:23.846675Z","price_level":"63253.48","new_quantity":"0"},{"side":"bid","event_time":"2026-07-16T20:29:23.846675Z","price_level":"63040.23","new_quantity":"0"},{"side":"offer","event_time":"2026-07-16T20:29:23.846675Z","price_level":"64135.01","new_quantity":"1.0784527"},{"side":"offer","event_time":"2026-07-16T20:29:23.846675Z","price_level":"64140.14","new_quantity":"0.02016"}]}]}
{"channel":"l2_data","timestamp":"2026-07-16T20:29:23.950105689Z","sequence_num":639,"events":[{"type":"update","product_id":"BTC-USD","updates":[{"side":"bid","event_time":"2026-07-16T20:29:23.910083Z","price_level":"64028.75","new_quantity":"0.09382291"},{"side":"bid","event_time":"2026-07-16T20:29:23.910083Z","price_level":"56118.13","new_quantity":"0"},{"side":"offer","event_time":"2026-07-16T20:29:23.910083Z","price_level":"64147.97","new_quantity":"0.33"},{"side":"offer","event_time":"2026-07-16T20:29:23.910083Z","price_level":"64221.13","new_quantity":"0.04833345"}]}]}
{"channel":"l2_data","timestamp":"2026-07-16T20:29:23.981840134Z","sequence_num":640,"events":[{"type":"update","product_id":"BTC-USD","updates":[{"side":"bid","event_time":"2026-07-16T20:29:23.947216Z","price_level":"64125.37","new_quantity":"0"},{"side":"bid","event_time":"2026-07-16T20:29:23.947216Z","price_level":"64125.36","new_quantity":"0.01559475"}]}]}
{"channel":"l2_data","timestamp":"2026-07-16T20:29:24.02924927Z","sequence_num":641,"events":[{"type":"update","product_id":"BTC-USD","updates":[{"side":"bid","event_time":"2026-07-16T20:29:24.003442Z","price_level":"64129.91","new_quantity":"0"},{"side":"bid","event_time":"2026-07-16T20:29:24.003442Z","price_level":"64129.9","new_quantity":"0"},{"side":"bid","event_time":"2026-07-16T20:29:24.003442Z","price_level":"64128.61","new_quantity":"0"},{"side":"bid","event_time":"2026-07-16T20:29:24.003442Z","price_level":"64128.55","new_quantity":"0.12474941"}]}]}
{"channel":"l2_data","timestamp":"2026-07-16T20:29:24.095948299Z","sequence_num":642,"events":[{"type":"update","product_id":"BTC-USD","updates":[{"side":"bid","event_time":"2026-07-16T20:29:24.02346Z","price_level":"64130.19","new_quantity":"0"},{"side":"bid","event_time":"2026-07-16T20:29:24.02346Z","price_level":"64128.59","new_quantity":"0"},{"side":"bid","event_time":"2026-07-16T20:29:24.02346Z","price_level":"64125.4","new_quantity":"0.01559475"},{"side":"bid","event_time":"2026-07-16T20:29:24.02346Z","price_level":"64125.36","new_quantity":"0"},{"side":"offer","event_time":"2026-07-16T20:29:24.02346Z","price_level":"64144.48","new_quantity":"0"},{"side":"offer","event_time":"2026-07-16T20:29:24.02346Z","price_level":"64145.34","new_quantity":"0"},{"side":"offer","event_time":"2026-07-16T20:29:24.02346Z","price_level":"64145.45","new_quantity":"0"},{"side":"offer","event_time":"2026-07-16T20:29:24.02346Z","price_level":"64145.66","new_quantity":"0.31190852"},{"side":"offer","event_time":"2026-07-16T20:29:24.02346Z","price_level":"64146.95","new_quantity":"0"}]}]}
{"channel":"l2_data","timestamp":"2026-07-16T20:29:24.129805541Z","sequence_num":643,"events":[{"type":"update","product_id":"BTC-USD","updates":[{"side":"bid","event_time":"2026-07-16T20:29:24.100478Z","price_level":"56118.13","new_quantity":"0.01337205"}]}]}
{"channel":"heartbeats","timestamp":"2026-07-16T20:29:24.164292728Z","sequence_num":644,"events":[{"current_time":"2026-07-16 20:29:24.163064565 +0000 UTC m=+75528.317891601","heartbeat_counter":75528}]}
{"channel":"l2_data","timestamp":"2026-07-16T20:29:24.190765112Z","sequence_num":645,"events":[{"type":"update","product_id":"BTC-USD","updates":[{"side":"bid","event_time":"2026-07-16T20:29:24.145468Z","price_level":"64121.54","new_quantity":"0.617965"},{"side":"offer","event_time":"2026-07-16T20:29:24.145468Z","price_level":"64145.19","new_quantity":"0.00779482"}]}]}
{"channel":"l2_data","timestamp":"2026-07-16T20:29:24.24098745Z","sequence_num":646,"events":[{"type":"update","product_id":"BTC-USD","updates":[{"side":"bid","event_time":"2026-07-16T20:29:24.187058Z","price_level":"64135","new_quantity":"0.02106986"},{"side":"bid","event_time":"2026-07-16T20:29:24.187058Z","price_level":"64130.01","new_quantity":"0.02"},{"side":"bid","event_time":"2026-07-16T20:29:24.187058Z","price_level":"64129.32","new_quantity":"0"},{"side":"bid","event_time":"2026-07-16T20:29:24.187058Z","price_level":"64128.61","new_quantity":"0.02"},{"side":"bid","event_time":"2026-07-16T20:29:24.187058Z","price_level":"64121.54","new_quantity":"0"},{"side":"bid","event_time":"2026-07-16T20:29:24.187058Z","price_level":"64083.36","new_quantity":"0.00004398"},{"side":"bid","event_time":"2026-07-16T20:29:24.187058Z","price_level":"63683.04","new_quantity":"0"},{"side":"bid","event_time":"2026-07-16T20:29:24.187058Z","price_level":"63253.56","new_quantity":"0.00583"},{"side":"bid","event_time":"2026-07-16T20:29:24.187058Z","price_level":"63039.13","new_quantity":"0.00583"},{"side":"bid","event_time":"2026-07-16T20:29:24.187058Z","price_level":"56118.13","new_quantity":"0"},{"side":"offer","event_time":"2026-07-16T20:29:24.187058Z","price_level":"64144.23","new_quantity":"0.00009744"}]}]}
{"channel":"l2_data","timestamp":"2026-07-16T20:29:24.329995006Z","sequence_num":647,"events":[{"type":"update","product_id":"BTC-USD","updates":[{"side":"bid","event_time":"2026-07-16T20:29:24.314401Z","price_level":"64135","new_quantity":"0.01797929"},{"side":"bid","event_time":"2026-07-16T20:29:24.314401Z","price_level":"64129.69","new_quantity":"0.1247472"},{"side":"bid","event_time":"2026-07-16T20:29:24.314401Z","price_level":"64128.55","new_quantity":"0"},{"side":"offer","event_time":"2026-07-16T20:29:24.314401Z","price_level":"64182.45","new_quantity":"0.15045997"}]}]}
{"channel":"l2_data","timestamp":"2026-07-16T20:29:24.803312147Z","sequence_num":648,"events":[{"type":"update","product_id":"BTC-USD","updates":[{"side":"bid","event_time":"2026-07-16T20:29:24.353591Z","price_level":"64135","new_quantity":"0.01797926"},{"side":"bid","event_time":"2026-07-16T20:29:24.353591Z","price_level":"64129.7","new_quantity":"0.02"},{"side":"bid","event_time":"2026-07-16T20:29:24.353591Z","price_level":"64128.59","new_quantity":"0.00779683"},{"side":"bid","event_time":"2026-07-16T20:29:24.353591Z","price_level":"64121.61","new_quantity":"0.670583"},{"side":"bid","event_time":"2026-07-16T20:29:24.353591Z","price_level":"62823.86","new_quantity":"0.00583"},{"side":"offer","event_time":"2026-07-16T20:29:24.353591Z","price_level":"64146.7","new_quantity":"0.00896383"}]}]}
{"channel":"l2_data","timestamp":"2026-07-16T20:29:24.804288309Z","sequence_num":649,"events":[{"type":"update","product_id":"BTC-USD","updates":[{"side":"bid","event_time":"2026-07-16T20:29:24.395258Z","price_level":"56118.13","new_quantity":"0.01337205"}]}]}
{"channel":"l2_data","timestamp":"2026-07-16T20:29:24.805496952Z","sequence_num":650,"events":[{"type":"update","product_id":"BTC-USD","updates":[{"side":"offer","event_time":"2026-07-16T20:29:24.44675Z","price_level":"64182.44","new_quantity":"0.00077956"},{"side":"offer","event_time":"2026-07-16T20:29:24.44675Z","price_level":"64182.45","new_quantity":"0.14968045"}]}]}
{"channel":"l2_data","timestamp":"2026-07-16T20:29:24.806103164Z","sequence_num":651,"events":[{"type":"update","product_id":"BTC-USD","updates":[{"side":"bid","event_time":"2026-07-16T20:29:24.494614Z","price_level":"56118.13","new_quantity":"0"}]}]}
{"channel":"l2_data","timestamp":"2026-07-16T20:29:24.806637497Z","sequence_num":652,"events":[{"type":"update","product_id":"BTC-USD","updates":[{"side":"bid","event_time":"2026-07-16T20:29:24.535276Z","price_level":"64121.61","new_quantity":"0"},{"side":"bid","event_time":"2026-07-16T20:29:24.535276Z","price_level":"62824.38","new_quantity":"0.00583"},{"side":"bid","event_time":"2026-07-16T20:29:24.535276Z","price_level":"62823.86","new_quantity":"0"},{"side":"offer","event_time":"2026-07-16T20:29:24.535276Z","price_level":"64145.41","new_quantity":"0.00009743"},{"side":"offer","event_time":"2026-07-16T20:29:24.535276Z","price_level":"64146.7","new_quantity":"0.01675846"}]}]}
{"channel":"l2_data","timestamp":"2026-07-16T20:29:24.806995833Z","sequence_num":653,"events":[{"type":"update","product_id":"BTC-USD","updates":[{"side":"bid","event_time":"2026-07-16T20:29:24.606797Z","price_level":"64130.19","new_quantity":"0.00779664"},{"side":"bid","event_time":"2026-07-16T20:29:24.606797Z","price_level":"64121.59","new_quantity":"0.703411"},{"side":"offer","event_time":"2026-07-16T20:29:24.606797Z","price_level":"64145.09","new_quantity":"0.00896405"},{"side":"offer","event_time":"2026-07-16T20:29:24.606797Z","price_level":"64777.23","new_quantity":"0"}]}]}
{"channel":"l2_data","timestamp":"2026-07-16T20:29:24.807896831Z","sequence_num":654,"events":[{"type":"update","product_id":"BTC-USD","updates":[{"side":"bid","event_time":"2026-07-16T20:29:24.63283Z","price_level":"64121.59","new_quantity":"0"}]}]}
{"channel":"l2_data","timestamp":"2026-07-16T20:29:24.808844155Z","sequence_num":655,"events":[{"type":"update","product_id":"BTC-USD","updates":[{"side":"bid","event_time":"2026-07-16T20:29:24.693485Z","price_level":"56118.13","new_quantity":"0.01337205"},{"side":"offer","event_time":"2026-07-16T20:29:24.693485Z","price_level":"64173.87","new_quantity":"0.32027682"},{"side":"offer","event_time":"2026-07-16T20:29:24.693485Z","price_level":"64173.88","new_quantity":"0"},{"side":"offer","event_time":"2026-07-16T20:29:24.693485Z","price_level":"64173.89","new_quantity":"0"}]}]}
{"channel":"l2_data","timestamp":"2026-07-16T20:29:24.829900881Z","sequence_num":656,"events":[{"type":"update","product_id":"BTC-USD","updates":[{"side":"bid","event_time":"2026-07-16T20:29:24.793912Z","price_level":"63253.73","new_quantity":"0.00583"},{"side":"bid","event_time":"2026-07-16T20:29:24.793912Z","price_level":"62824.38","new_quantity":"0"},{"side":"bid","event_time":"2026-07-16T20:29:24.793912Z","price_level":"56118.13","new_quantity":"0"},{"side":"offer","event_time":"2026-07-16T20:29:24.793912Z","price_level":"64135.01","new_quantity":"1.07777905"},{"side":"offer","event_time":"2026-07-16T20:29:24.793912Z","price_level":"64776.58","new_quantity":"0.03890047"}]}]}
{"channel":"l2_data","timestamp":"2026-07-16T20:29:24.879741324Z","sequence_num":657,"events":[{"type":"update","product_id":"BTC-USD","updates":[{"side":"bid","event_time":"2026-07-16T20:29:24.849653Z","price_level":"64135","new_quantity":"0.01797922"},{"side":"bid","event_time":"2026-07-16T20:29:24.849653Z","price_level":"64125.4","new_quantity":"0"},{"side":"bid","event_time":"2026-07-16T20:29:24.849653Z","price_level":"64125.39","new_quantity":"0.01559475"},{"side":"bid","event_time":"2026-07-16T20:29:24.849653Z","price_level":"64121.65","new_quantity":"0.614814"},{"side":"offer","event_time":"2026-07-16T20:29:24.849653Z","price_level":"64139.13","new_quantity":"0.92259155"},{"side":"offer","event_time":"2026-07-16T20:29:24.849653Z","price_level":"64141.24","new_quantity":"0.6550193"}]}]}
{"channel":"l2_data","timestamp":"2026-07-16T20:29:24.926225934Z","sequence_num":658,"events":[{"type":"update","product_id":"BTC-USD","updates":[{"side":"bid","event_time":"2026-07-16T20:29:24.873692Z","price_level":"64121.65","new_quantity":"0"}]}]}
{"channel":"l2_data","timestamp":"2026-07-16T20:29:24.9782461Z","sequence_num":659,"events":[{"type":"update","product_id":"BTC-USD","updates":[{"side":"bid","event_time":"2026-07-16T20:29:24.932482Z","price_level":"64125.39","new_quantity":"0"},{"side":"bid","event_time":"2026-07-16T20:29:24.932482Z","price_level":"64125.38","new_quantity":"0.01559475"}]}]}
{"channel":"l2_data","timestamp":"2026-07-16T20:29:25.025557857Z","sequence_num":660,"events":[{"type":"update","product_id":"BTC-USD","updates":[{"side":"bid","event_time":"2026-07-16T20:29:24.999847Z","price_level":"56118.13","new_quantity":"0.01337205"}]}]}
{"channel":"l2_data","timestamp":"2026-07-16T20:29:25.082914007Z","sequence_num":661,"events":[{"type":"update","product_id":"BTC-USD","updates":[{"side":"bid","event_time":"2026-07-16T20:29:25.02817Z","price_level":"64135","new_quantity":"0.02094965"},{"side":"bid","event_time":"2026-07-16T20:29:25.02817Z","price_level":"64128.59","new_quantity":"0"},{"side":"bid","event_time":"2026-07-16T20:29:25.02817Z","price_level":"64125.38","new_quantity":"0"},{"side":"bid","event_time":"2026-07-16T20:29:25.02817Z","price_level":"64125.37","new_quantity":"0.01559475"},{"side":"bid","event_time":"2026-07-16T20:29:25.02817Z","price_level":"63253.75","new_quantity":"0.00583"},{"side":"bid","event_time":"2026-07-16T20:29:25.02817Z","price_level":"63253.73","new_quantity":"0"},{"side":"bid","event_time":"2026-07-16T20:29:25.02817Z","price_level":"63253.56","new_quantity":"0"},{"side":"bid","event_time":"2026-07-16T20:29:25.02817Z","price_level":"63039.13","new_quantity":"0"},{"side":"offer","event_time":"2026-07-16T20:29:25.02817Z","price_level":"64135.01","new_quantity":"1.07748329"},{"side":"offer","event_time":"2026-07-16T20:29:25.02817Z","price_level":"64144.23","new_quantity":"0"},{"side":"offer","event_time":"2026-07-16T20:29:25.02817Z","price_level":"64145.19","new_quantity":"0"},{"side":"offer","event_time":"2026-07-16T20:29:25.02817Z","price_level":"64146.7","new_quantity":"0.00779463"}]}]}
{"channel":"l2_data","timestamp":"2026-07-16T20:29:25.125392107Z","sequence_num":662,"events":[{"type":"update","product_id":"BTC-USD","updates":[{"side":"bid","event_time":"2026-07-16T20:29:25.105207Z","price_level":"64121.66","new_quantity":"0"},{"side":"bid","event_time":"2026-07-16T20:29:25.105207Z","price_level":"63494.51","new_quantity":"0"},{"side":"bid","event_time":"2026-07-16T20:29:25.105207Z","price_level":"56118.13","new_quantity":"0"}]}]}
{"channel":"heartbeats","timestamp":"2026-07-16T20:29:25.169336421Z","sequence_num":663,"events":[{"current_time":"2026-07-16 20:29:25.162900487 +0000 UTC m=+75529.317727533","heartbeat_counter":75529}]}
{"channel":"l2_data","timestamp":"2026-07-16T20:29:25.176940371Z","sequence_num":664,"events":[{"type":"update","product_id":"BTC-USD","updates":[{"side":"bid","event_time":"2026-07-16T20:29:25.161068Z","price_level":"64135","new_quantity":"0.01797922"},{"side":"bid","event_time":"2026-07-16T20:29:25.161068Z","price_level":"63039.12","new_quantity":"0.00583"},{"side":"bid","event_time":"2026-07-16T20:29:25.161068Z","price_level":"62824.69","new_quantity":"0.00583"}]}]}
{"channel":"l2_data","timestamp":"2026-07-16T20:29:25.276720068Z","sequence_num":665,"events":[{"type":"update","product_id":"BTC-USD","updates":[{"side":"offer","event_time":"2026-07-16T20:29:25.243301Z","price_level":"64143.99","new_quantity":"0.00009744"},{"side":"offer","event_time":"2026-07-16T20:29:25.243301Z","price_level":"64144.95","new_quantity":"0.00779485"}]}]}
{"channel":"l2_data","timestamp":"2026-07-16T20:29:25.325130146Z","sequence_num":666,"events":[{"type":"update","product_id":"BTC-USD","updates":[{"side":"bid","event_time":"2026-07-16T20:29:25.302054Z","price_level":"56118.13","new_quantity":"0.01337205"}]}]}
{"channel":"l2_data","timestamp":"2026-07-16T20:29:25.379470894Z","sequence_num":667,"events":[{"type":"update","product_id":"BTC-USD","updates":[{"side":"bid","event_time":"2026-07-16T20:29:25.354641Z","price_level":"64135","new_quantity":"0.01797917"},{"side":"bid","event_time":"2026-07-16T20:29:25.354641Z","price_level":"64125.37","new_quantity":"0"},{"side":"bid","event_time":"2026-07-16T20:29:25.354641Z","price_level":"64125.35","new_quantity":"0.01559475"},{"side":"bid","event_time":"2026-07-16T20:29:25.354641Z","price_level":"64121.59","new_quantity":"0.631282"},{"side":"bid","event_time":"2026-07-16T20:29:25.354641Z","price_level":"63493.87","new_quantity":"0.03938039"},{"side":"offer","event_time":"2026-07-16T20:29:25.354641Z","price_level":"64173.86","new_quantity":"0.23992856"},{"side":"offer","event_time":"2026-07-16T20:29:25.354641Z","price_level":"64191.68","new_quantity":"0.6963642"},{"side":"offer","event_time":"2026-07-16T20:29:25.354641Z","price_level":"64191.7","new_quantity":"0"}]}]}
{"channel":"l2_data","timestamp":"2026-07-16T20:29:25.425172876Z","sequence_num":668,"events":[{"type":"update","product_id":"BTC-USD","updates":[{"side":"bid","event_time":"2026-07-16T20:29:25.39324Z","price_level":"64121.59","new_quantity":"0"},{"side":"bid","event_time":"2026-07-16T20:29:25.39324Z","price_level":"56118.13","new_quantity":"0"}]}]}
{"channel":"l2_data","timestamp":"2026-07-16T20:29:25.483871954Z","sequence_num":669,"events":[{"type":"update","product_id":"BTC-USD","updates":[{"side":"bid","event_time":"2026-07-16T20:29:25.454945Z","price_level":"64135","new_quantity":"0.0179791"},{"side":"bid","event_time":"2026-07-16T20:29:25.454945Z","price_level":"64128.59","new_quantity":"0.00779683"},{"side":"offer","event_time":"2026-07-16T20:29:25.454945Z","price_level":"64146.46","new_quantity":"0.00896386"}]}]}
{"channel":"l2_data","timestamp":"2026-07-16T20:29:25.525599965Z","sequence_num":670,"events":[{"type":"update","product_id":"BTC-USD","updates":[{"side":"bid","event_time":"2026-07-16T20:29:25.492247Z","price_level":"64125.35","new_quantity":"0"},{"side":"bid","event_time":"2026-07-16T20:29:25.492247Z","price_level":"64125.34","new_quantity":"0.01559475"}]}]}
{"channel":"l2_data","timestamp":"2026-07-16T20:29:25.5877499Z","sequence_num":671,"events":[{"type":"update","product_id":"BTC-USD","updates":[{"side":"bid","event_time":"2026-07-16T20:29:25.546025Z","price_level":"64135","new_quantity":"0.02159555"},{"side":"bid","event_time":"2026-07-16T20:29:25.546025Z","price_level":"63039.21","new_quantity":"0.00583"},{"side":"bid","event_time":"2026-07-16T20:29:25.546025Z","price_level":"62824.69","new_quantity":"0"}]}]}
{"channel":"l2_data","timestamp":"2026-07-16T20:29:25.629541509Z","sequence_num":672,"events":[{"type":"update","product_id":"BTC-USD","updates":[{"side":"bid","event_time":"2026-07-16T20:29:25.601242Z","price_level":"64125.37","new_quantity":"0.01559475"},{"side":"bid","event_time":"2026-07-16T20:29:25.601242Z","price_level":"64125.34","new_quantity":"0"},{"side":"bid","event_time":"2026-07-16T20:29:25.601242Z","price_level":"64125.33","new_quantity":"0"},{"side":"bid","event_time":"2026-07-16T20:29:25.601242Z","price_level":"64121.79","new_quantity":"0.664641"},{"side":"bid","event_time":"2026-07-16T20:29:25.601242Z","price_level":"56118.13","new_quantity":"0.01337205"},{"side":"offer","event_time":"2026-07-16T20:29:25.601242Z","price_level":"64145.17","new_quantity":"0.00009744"},{"side":"offer","event_time":"2026-07-16T20:29:25.601242Z","price_level":"64145.41","new_quantity":"0"},{"side":"offer","event_time":"2026-07-16T20:29:25.601242Z","price_level":"64146.46","new_quantity":"0.01675852"},{"side":"offer","event_time":"2026-07-16T20:29:25.601242Z","price_level":"64146.7","new_quantity":"0"}]}]}
{"channel":"l2_data","timestamp":"2026-07-16T20:29:25.684497037Z","sequence_num":673,"events":[{"type":"update","product_id":"BTC-USD","updates":[{"side":"bid","event_time":"2026-07-16T20:29:25.644318Z","price_level":"64125.37","new_quantity":"0"},{"side":"bid","event_time":"2026-07-16T20:29:25.644318Z","price_level":"64125.36","new_quantity":"0.01559475"},{"side":"bid","event_time":"2026-07-16T20:29:25.644318Z","price_level":"64121.79","new_quantity":"0"},{"side":"offer","event_time":"2026-07-16T20:29:25.644318Z","price_level":"64145.09","new_quantity":"0"}]}]}
{"channel":"l2_data","timestamp":"2026-07-16T20:29:25.73024253Z","sequence_num":674,"events":[{"type":"update","product_id":"BTC-USD","updates":[{"side":"bid","event_time":"2026-07-16T20:29:25.68979Z","price_level":"64130.19","new_quantity":"0.00779664"},{"side":"bid","event_time":"2026-07-16T20:29:25.68979Z","price_level":"63253.85","new_quantity":"0.00583"},{"side":"bid","event_time":"2026-07-16T20:29:25.68979Z","price_level":"63039.12","new_quantity":"0"},{"side":"bid","event_time":"2026-07-16T20:29:25.68979Z","price_level":"56118.13","new_quantity":"0"},{"side":"offer","event_time":"2026-07-16T20:29:25.68979Z","price_level":"64135.01","new_quantity":"1.07569078"},{"side":"offer","event_time":"2026-07-16T20:29:25.68979Z","price_level":"64144.86","new_quantity":"0.00896409"}]}]}
{"channel":"l2_data","timestamp":"2026-07-16T20:29:25.774955074Z","sequence_num":675,"events":[{"type":"update","product_id":"BTC-USD","updates":[{"side":"bid","event_time":"2026-07-16T20:29:25.744615Z","price_level":"64125.36","new_quantity":"0"},{"side":"bid","event_time":"2026-07-16T20:29:25.744615Z","price_level":"64125.35","new_quantity":"0.01559475"}]}]}
{"channel":"l2_data","timestamp":"2026-07-16T20:29:25.841815873Z","sequence_num":676,"events":[{"type":"update","product_id":"BTC-USD","updates":[{"side":"bid","event_time":"2026-07-16T20:29:25.776079Z","price_level":"63468.54","new_quantity":"0.00583"},{"side":"bid","event_time":"2026-07-16T20:29:25.776079Z","price_level":"63253.75","new_quantity":"0"},{"side":"bid","event_time":"2026-07-16T20:29:25.776079Z","price_level":"63039.21","new_quantity":"0"},{"side":"offer","event_time":"2026-07-16T20:29:25.776079Z","price_level":"64135.01","new_quantity":"1.07490353"}]}]}
{"channel":"l2_data","timestamp":"2026-07-16T20:29:25.877779356Z","sequence_num":677,"events":[{"type":"update","product_id":"BTC-USD","updates":[{"side":"bid","event_time":"2026-07-16T20:29:25.838843Z","price_level":"64125.35","new_quantity":"0"},{"side":"bid","event_time":"2026-07-16T20:29:25.838843Z","price_level":"64125.34","new_quantity":"0.01559475"}]}]}
{"channel":"l2_data","timestamp":"2026-07-16T20:29:25.936689965Z","sequence_num":678,"events":[{"type":"update","product_id":"BTC-USD","updates":[{"side":"bid","event_time":"2026-07-16T20:29:25.896643Z","price_level":"64135","new_quantity":"0.02159543"},{"side":"bid","event_time":"2026-07-16T20:29:25.896643Z","price_level":"64121.77","new_quantity":"0"},{"side":"bid","event_time":"2026-07-16T20:29:25.896643Z","price_level":"64028.75","new_quantity":"0"},{"side":"bid","event_time":"2026-07-16T20:29:25.896643Z","price_level":"56118.13","new_quantity":"0.01337205"}]}]}
{"channel":"l2_data","timestamp":"2026-07-16T20:29:25.982036022Z","sequence_num":679,"events":[{"type":"update","product_id":"BTC-USD","updates":[{"side":"bid","event_time":"2026-07-16T20:29:25.93231Z","price_level":"64125.34","new_quantity":"0"},{"side":"bid","event_time":"2026-07-16T20:29:25.93231Z","price_level":"64125.33","new_quantity":"0.01559475"}]}]}
{"channel":"l2_data","timestamp":"2026-07-16T20:29:26.031060632Z","sequence_num":680,"events":[{"type":"update","product_id":"BTC-USD","updates":[{"side":"bid","event_time":"2026-07-16T20:29:25.989535Z","price_level":"63468.57","new_quantity":"0.00583"},{"side":"bid","event_time":"2026-07-16T20:29:25.989535Z","price_level":"63468.5","new_quantity":"0"},{"side":"bid","event_time":"2026-07-16T20:29:25.989535Z","price_level":"56118.13","new_quantity":"0"},{"side":"offer","event_time":"2026-07-16T20:29:25.989535Z","price_level":"64135.01","new_quantity":"1.0733744"}]}]}
{"channel":"l2_data","timestamp":"2026-07-16T20:29:26.081533859Z","sequence_num":681,"events":[{"type":"update","product_id":"BTC-USD","updates":[{"side":"bid","event_time":"2026-07-16T20:29:26.049208Z","price_level":"64128.59","new_quantity":"0"},{"side":"bid","event_time":"2026-07-16T20:29:26.049208Z","price_level":"64125.33","new_quantity":"0"},{"side":"bid","event_time":"2026-07-16T20:29:26.049208Z","price_level":"64125.32","new_quantity":"0.01559475"},{"side":"offer","event_time":"2026-07-16T20:29:26.049208Z","price_level":"64135.01","new_quantity":"1.07041652"},{"side":"offer","event_time":"2026-07-16T20:29:26.049208Z","price_level":"64143.99","new_quantity":"0"},{"side":"offer","event_time":"2026-07-16T20:29:26.049208Z","price_level":"64144.95","new_quantity":"0"},{"side":"offer","event_time":"2026-07-16T20:29:26.049208Z","price_level":"64146.46","new_quantity":"0.00779466"}]}]}
{"channel":"l2_data","timestamp":"2026-07-16T20:29:26.125135126Z","sequence_num":682,"events":[{"type":"update","product_id":"BTC-USD","updates":[{"side":"bid","event_time":"2026-07-16T20:29:26.104421Z","price_level":"64121.78","new_quantity":"0.642695"},{"side":"bid","event_time":"2026-07-16T20:29:26.104421Z","price_level":"64026.74","new_quantity":"0.08183455"},{"side":"bid","event_time":"2026-07-16T20:29:26.104421Z","price_level":"63468.61","new_quantity":"0.00583"},{"side":"bid","event_time":"2026-07-16T20:29:26.104421Z","price_level":"63468.54","new_quantity":"0"}]}]}
{"channel":"heartbeats","timestamp":"2026-07-16T20:29:26.165851363Z","sequence_num":683,"events":[{"current_time":"2026-07-16 20:29:26.162904398 +0000 UTC m=+75530.317731445","heartbeat_counter":75530}]}
{"channel":"l2_data","timestamp":"2026-07-16T20:29:26.175767076Z","sequence_num":684,"events":[{"type":"update","product_id":"BTC-USD","updates":[{"side":"bid","event_time":"2026-07-16T20:29:26.132872Z","price_level":"64135","new_quantity":"0.01797898"},{"side":"bid","event_time":"2026-07-16T20:29:26.132872Z","price_level":"63468.57","new_quantity":"0"},{"side":"bid","event_time":"2026-07-16T20:29:26.132872Z","price_level":"63038.82","new_quantity":"0.00583"},{"side":"bid","event_time":"2026-07-16T20:29:26.132872Z","price_level":"51308","new_quantity":"0.0002"}]}]}
{"channel":"l2_data","timestamp":"2026-07-16T20:29:26.229751749Z","sequence_num":685,"events":[{"type":"update","product_id":"BTC-USD","updates":[{"side":"bid","event_time":"2026-07-16T20:29:26.192035Z","price_level":"64121.78","new_quantity":"0"},{"side":"bid","event_time":"2026-07-16T20:29:26.192035Z","price_level":"56118.13","new_quantity":"0.01337205"},{"side":"offer","event_time":"2026-07-16T20:29:26.192035Z","price_level":"64173.85","new_quantity":"0.32027682"},{"side":"offer","event_time":"2026-07-16T20:29:26.192035Z","price_level":"64173.86","new_quantity":"0"},{"side":"offer","event_time":"2026-07-16T20:29:26.192035Z","price_level":"64173.87","new_quantity":"0"}]}]}
{"channel":"l2_data","timestamp":"2026-07-16T20:29:26.329466161Z","sequence_num":686,"events":[{"type":"update","product_id":"BTC-USD","updates":[{"side":"bid","event_time":"2026-07-16T20:29:26.295216Z","price_level":"56118.13","new_quantity":"0"},{"side":"bid","event_time":"2026-07-16T20:29:26.295216Z","price_level":"51308","new_quantity":"0"},{"side":"offer","event_time":"2026-07-16T20:29:26.295216Z","price_level":"64143.76","new_quantity":"0.00009744"},{"side":"offer","event_time":"2026-07-16T20:29:26.295216Z","price_level":"64144.72","new_quantity":"0.00779487"}]}]}
{"channel":"l2_data","timestamp":"2026-07-16T20:29:26.379865423Z","sequence_num":687,"events":[{"type":"update","product_id":"BTC-USD","updates":[{"side":"bid","event_time":"2026-07-16T20:29:26.360078Z","price_level":"64125.32","new_quantity":"0"},{"side":"bid","event_time":"2026-07-16T20:29:26.360078Z","price_level":"64125.31","new_quantity":"0"},{"side":"bid","event_time":"2026-07-16T20:29:26.360078Z","price_level":"64121.72","new_quantity":"0"},{"side":"offer","event_time":"2026-07-16T20:29:26.360078Z","price_level":"64173.84","new_quantity":"0.23992856"},{"side":"offer","event_time":"2026-07-16T20:29:26.360078Z","price_level":"64191.66","new_quantity":"0.69636442"},{"side":"offer","event_time":"2026-07-16T20:29:26.360078Z","price_level":"64191.67","new_quantity":"0"},{"side":"offer","event_time":"2026-07-16T20:29:26.360078Z","price_level":"64191.68","new_quantity":"0"}]}]}
{"channel":"l2_data","timestamp":"2026-07-16T20:29:26.42518335Z","sequence_num":688,"events":[{"type":"update","product_id":"BTC-USD","updates":[{"side":"bid","event_time":"2026-07-16T20:29:26.367037Z","price_level":"64125.3","new_quantity":"0.01559475"}]}]}
{"channel":"l2_data","timestamp":"2026-07-16T20:29:26.475191492Z","sequence_num":689,"events":[{"type":"update","product_id":"BTC-USD","updates":[{"side":"bid","event_time":"2026-07-16T20:29:26.430674Z","price_level":"64135","new_quantity":"0.01797895"}]}]}
{"channel":"l2_data","timestamp":"2026-07-16T20:29:26.530005953Z","sequence_num":690,"events":[{"type":"update","product_id":"BTC-USD","updates":[{"side":"bid","event_time":"2026-07-16T20:29:26.496799Z","price_level":"64135","new_quantity":"0.02078149"},{"side":"bid","event_time":"2026-07-16T20:29:26.496799Z","price_level":"64128.59","new_quantity":"0.00779683"},{"side":"bid","event_time":"2026-07-16T20:29:26.496799Z","price_level":"64125.3","new_quantity":"0"},{"side":"bid","event_time":"2026-07-16T20:29:26.496799Z","price_level":"64125.29","new_quantity":"0.01559475"},{"side":"bid","event_time":"2026-07-16T20:29:26.496799Z","price_level":"63039.4","new_quantity":"0.00583"},{"side":"bid","event_time":"2026-07-16T20:29:26.496799Z","price_level":"56118.13","new_quantity":"0.01337205"},{"side":"offer","event_time":"2026-07-16T20:29:26.496799Z","price_level":"64146.23","new_quantity":"0.00896389"}]}]}
{"channel":"l2_data","timestamp":"2026-07-16T20:29:26.580888212Z","sequence_num":691,"events":[{"type":"update","product_id":"BTC-USD","updates":[{"side":"offer","event_time":"2026-07-16T20:29:26.523577Z","price_level":"64256.27","new_quantity":"0"}]}]}
{"channel":"l2_data","timestamp":"2026-07-16T20:29:26.624798293Z","sequence_num":692,"events":[{"type":"update","product_id":"BTC-USD","updates":[{"side":"bid","event_time":"2026-07-16T20:29:26.600837Z","price_level":"64125.29","new_quantity":"0"},{"side":"bid","event_time":"2026-07-16T20:29:26.600837Z","price_level":"64125.28","new_quantity":"0.01559475"},{"side":"bid","event_time":"2026-07-16T20:29:26.600837Z","price_level":"64121.76","new_quantity":"0.646616"},{"side":"bid","event_time":"2026-07-16T20:29:26.600837Z","price_level":"56118.13","new_quantity":"0"}]}]}
{"channel":"l2_data","timestamp":"2026-07-16T20:29:26.680070103Z","sequence_num":693,"events":[{"type":"update","product_id":"BTC-USD","updates":[{"side":"bid","event_time":"2026-07-16T20:29:26.650617Z","price_level":"64135","new_quantity":"0.01797895"},{"side":"bid","event_time":"2026-07-16T20:29:26.650617Z","price_level":"64130.01","new_quantity":"0"},{"side":"bid","event_time":"2026-07-16T20:29:26.650617Z","price_level":"64121.76","new_quantity":"0"},{"side":"bid","event_time":"2026-07-16T20:29:26.650617Z","price_level":"63038.82","new_quantity":"0"},{"side":"offer","event_time":"2026-07-16T20:29:26.650617Z","price_level":"64145.17","new_quantity":"0"},{"side":"offer","event_time":"2026-07-16T20:29:26.650617Z","price_level":"64146.46","new_quantity":"0"}]}]}
{"channel":"l2_data","timestamp":"2026-07-16T20:29:26.730277647Z","sequence_num":694,"events":[{"type":"update","product_id":"BTC-USD","updates":[{"side":"bid","event_time":"2026-07-16T20:29:26.70849Z","price_level":"64129.7","new_quantity":"0"},{"side":"bid","event_time":"2026-07-16T20:29:26.70849Z","price_level":"62824.88","new_quantity":"0.00583"},{"side":"bid","event_time":"2026-07-16T20:29:26.70849Z","price_level":"62824.31","new_quantity":"0"},{"side":"offer","event_time":"2026-07-16T20:29:26.70849Z","price_level":"64144.95","new_quantity":"0.00009744"},{"side":"offer","event_time":"2026-07-16T20:29:26.70849Z","price_level":"64146.23","new_quantity":"0.01675858"}]}]}
{"channel":"l2_data","timestamp":"2026-07-16T20:29:26.779916334Z","sequence_num":695,"events":[{"type":"update","product_id":"BTC-USD","updates":[{"side":"bid","event_time":"2026-07-16T20:29:26.745716Z","price_level":"64130.19","new_quantity":"0.00779664"},{"side":"bid","event_time":"2026-07-16T20:29:26.745716Z","price_level":"64125.28","new_quantity":"0"},{"side":"bid","event_time":"2026-07-16T20:29:26.745716Z","price_level":"64125.27","new_quantity":"0.01559475"},{"side":"bid","event_time":"2026-07-16T20:29:26.745716Z","price_level":"62824.92","new_quantity":"0.00583"},{"side":"bid","event_time":"2026-07-16T20:29:26.745716Z","price_level":"62824.88","new_quantity":"0"},{"side":"offer","event_time":"2026-07-16T20:29:26.745716Z","price_level":"64144.63","new_quantity":"0.00896412"},{"side":"offer","event_time":"2026-07-16T20:29:26.745716Z","price_level":"64144.86","new_quantity":"0"}]}]}
{"channel":"l2_data","timestamp":"2026-07-16T20:29:26.824654024Z","sequence_num":696,"events":[{"type":"update","product_id":"BTC-USD","updates":[{"side":"bid","event_time":"2026-07-16T20:29:26.795052Z","price_level":"64129.7","new_quantity":"0.02"},{"side":"bid","event_time":"2026-07-16T20:29:26.795052Z","price_level":"56118.13","new_quantity":"0.01337205"}]}]}
{"channel":"l2_data","timestamp":"2026-07-16T20:29:26.884558172Z","sequence_num":697,"events":[{"type":"update","product_id":"BTC-USD","updates":[{"side":"bid","event_time":"2026-07-16T20:29:26.858905Z","price_level":"64129.69","new_quantity":"0"},{"side":"bid","event_time":"2026-07-16T20:29:26.858905Z","price_level":"64128.66","new_quantity":"0.1247492"},{"side":"bid","event_time":"2026-07-16T20:29:26.858905Z","price_level":"64121.68","new_quantity":"0.656956"},{"side":"bid","event_time":"2026-07-16T20:29:26.858905Z","price_level":"64110","new_quantity":"0.01"}]}]}
{"channel":"l2_data","timestamp":"2026-07-16T20:29:26.928511128Z","sequence_num":698,"events":[{"type":"update","product_id":"BTC-USD","updates":[{"side":"bid","event_time":"2026-07-16T20:29:26.907421Z","price_level":"64135","new_quantity":"0.0179789"},{"side":"bid","event_time":"2026-07-16T20:29:26.907421Z","price_level":"64125.27","new_quantity":"0"},{"side":"bid","event_time":"2026-07-16T20:29:26.907421Z","price_level":"64125.26","new_quantity":"0.01559475"},{"side":"bid","event_time":"2026-07-16T20:29:26.907421Z","price_level":"64121.68","new_quantity":"0"},{"side":"bid","event_time":"2026-07-16T20:29:26.907421Z","price_level":"64109","new_quantity":"1"},{"side":"bid","event_time":"2026-07-16T20:29:26.907421Z","price_level":"56118.13","new_quantity":"0"}]}]}
{"channel":"l2_data","timestamp":"2026-07-16T20:29:26.994058558Z","sequence_num":699,"events":[{"type":"update","product_id":"BTC-USD","updates":[{"side":"bid","event_time":"2026-07-16T20:29:26.958345Z","price_level":"64125.26","new_quantity":"0"},{"side":"bid","event_time":"2026-07-16T20:29:26.958345Z","price_level":"64125.25","new_quantity":"0.01559475"}]}]}
{"channel":"l2_data","timestamp":"2026-07-16T20:29:27.032245444Z","sequence_num":700,"events":[{"type":"update","product_id":"BTC-USD","updates":[{"side":"bid","event_time":"2026-07-16T20:29:27.010802Z","price_level":"64129.7","new_quantity":"0"},{"side":"bid","event_time":"2026-07-16T20:29:27.010802Z","price_level":"64128.67","new_quantity":"0.02"},{"side":"bid","event_time":"2026-07-16T20:29:27.010802Z","price_level":"64128.66","new_quantity":"0"},{"side":"bid","event_time":"2026-07-16T20:29:27.010802Z","price_level":"64128.6","new_quantity":"0"},{"side":"bid","event_time":"2026-07-16T20:29:27.010802Z","price_level":"64127.99","new_quantity":"0.1247505"},{"side":"bid","event_time":"2026-07-16T20:29:27.010802Z","price_level":"64109","new_quantity":"0"}]}]}
{"channel":"l2_data","timestamp":"2026-07-16T20:29:27.106708123Z","sequence_num":701,"events":[{"type":"update","product_id":"BTC-USD","updates":[{"side":"bid","event_time":"2026-07-16T20:29:27.052952Z","price_level":"64135","new_quantity":"0.00054035"},{"side":"bid","event_time":"2026-07-16T20:29:27.052952Z","price_level":"64133.39","new_quantity":"0"},{"side":"bid","event_time":"2026-07-16T20:29:27.052952Z","price_level":"64131.23","new_quantity":"0"},{"side":"bid","event_time":"2026-07-16T20:29:27.052952Z","price_level":"64128.67","new_quantity":"0"},{"side":"bid","event_time":"2026-07-16T20:29:27.052952Z","price_level":"64128.61","new_quantity":"0"},{"side":"bid","event_time":"2026-07-16T20:29:27.052952Z","price_level":"64128.59","new_quantity":"0"},{"side":"bid","event_time":"2026-07-16T20:29:27.052952Z","price_level":"64127.99","new_quantity":"0"},{"side":"bid","event_time":"2026-07-16T20:29:27.052952Z","price_level":"64127.37","new_quantity":"0"},{"side":"bid","event_time":"2026-07-16T20:29:27.052952Z","price_level":"64126.86","new_quantity":"0"},{"side":"bid","event_time":"2026-07-16T20:29:27.052952Z","price_level":"64126.77","new_quantity":"0"},{"side":"bid","event_time":"2026-07-16T20:29:27.052952Z","price_level":"64125.87","new_quantity":"0"},{"side":"bid","event_time":"2026-07-16T20:29:27.052952Z","price_level":"64125.86","new_quantity":"0"},{"side":"bid","event_time":"2026-07-16T20:29:27.052952Z","price_level":"64125.76","new_quantity":"0.12475484"},{"side":"bid","event_time":"2026-07-16T20:29:27.052952Z","price_level":"64125.29","new_quantity":"0"},{"side":"bid","event_time":"2026-07-16T20:29:27.052952Z","price_level":"64125.25","new_quantity":"0"},{"side":"bid","event_time":"2026-07-16T20:29:27.052952Z","price_level":"64124.1","new_quantity":"0"},{"side":"bid","event_time":"2026-07-16T20:29:27.052952Z","price_level":"64123.84","new_quantity":"0"},{"side":"bid","event_time":"2026-07-16T20:29:27.052952Z","price_level":"64123.39","new_quantity":"0.01559475"},{"side":"bid","event_time":"2026-07-16T20:29:27.052952Z","price_level":"64123.27","new_quantity":"0"},{"side":"bid","event_time":"2026-07-16T20:29:27.052952Z","price_level":"64122.59","new_quantity":"0.04691558"},{"side":"bid","event_time":"2026-07-16T20:29:27.052952Z","price_level":"64121.84","new_quantity":"0.00002339"},{"side":"bid","event_time":"2026-07-16T20:29:27.052952Z","price_level":"64121.3","new_quantity":"0"},{"side":"bid","event_time":"2026-07-16T20:29:27.052952Z","price_level":"64121.16","new_quantity":"0"},{"side":"bid","event_time":"2026-07-16T20:29:27.052952Z","price_level":"64120.95","new_quantity":"0"},{"side":"bid","event_time":"2026-07-16T20:29:27.052952Z","price_level":"64119.54","new_quantity":"0.28171126"},{"side":"bid","event_time":"2026-07-16T20:29:27.052952Z","price_level":"64119.53","new_quantity":"0"},{"side":"bid","event_time":"2026-07-16T20:29:27.052952Z","price_level":"64118.74","new_quantity":"0.0077892"},{"side":"bid","event_time":"2026-07-16T20:29:27.052952Z","price_level":"64118.43","new_quantity":"0.0007796"},{"side":"bid","event_time":"2026-07-16T20:29:27.052952Z","price_level":"64116.86","new_quantity":"0"},{"side":"bid","event_time":"2026-07-16T20:29:27.052952Z","price_level":"64115.57","new_quantity":"0"},{"side":"bid","event_time":"2026-07-16T20:29:27.052952Z","price_level":"64113.32","new_quantity":"0"},{"side":"bid","event_time":"2026-07-16T20:29:27.052952Z","price_level":"64112.4","new_quantity":"0.00155977"},{"side":"bid","event_time":"2026-07-16T20:29:27.052952Z","price_level":"64108.01","new_quantity":"0"},{"side":"bid","event_time":"2026-07-16T20:29:27.052952Z","price_level":"64104.81","new_quantity":"0.31190852"},{"side":"bid","event_time":"2026-07-16T20:29:27.052952Z","price_level":"64104.22","new_quantity":"0.64750777"},{"side":"bid","event_time":"2026-07-16T20:29:27.052952Z","price_level":"64102.76","new_quantity":"0.31268809"},{"side":"bid","event_time":"2026-07-16T20:29:27.052952Z","price_level":"64101.65","new_quantity":"0"},{"side":"bid","event_time":"2026-07-16T20:29:27.052952Z","price_level":"64099.17","new_quantity":"0"},{"side":"bid","event_time":"2026-07-16T20:29:27.052952Z","price_level":"64098.91","new_quantity":"0.31190852"},{"side":"bid","event_time":"2026-07-16T20:29:27.052952Z","price_level":"64098.84","new_quantity":"0.00155819"},{"side":"bid","event_time":"2026-07-16T20:29:27.052952Z","price_level":"64096.61","new_quantity":"0"},{"side":"bid","event_time":"2026-07-16T20:29:27.052952Z","price_level":"64095.25","new_quantity":"0"},{"side":"bid","event_time":"2026-07-16T20:29:27.052952Z","price_level":"64094.04","new_quantity":"0"},{"side":"bid","event_time":"2026-07-16T20:29:27.052952Z","price_level":"64092.43","new_quantity":"0.00779098"},{"side":"bid","event_time":"2026-07-16T20:29:27.052952Z","price_level":"64090.2","new_quantity":"0"},{"side":"bid","event_time":"2026-07-16T20:29:27.052952Z","price_level":"64074.1","new_quantity":"0"},{"side":"offer","event_time":"2026-07-16T20:29:27.052952Z","price_level":"64135.01","new_quantity":"1.12597249"},{"side":"offer","event_time":"2026-07-16T20:29:27.052952Z","price_level":"64139.99","new_quantity":"0"},{"side":"offer","event_time":"2026-07-16T20:29:27.052952Z","price_level":"64142.49","new_quantity":"0.0077892"},{"side":"offer","event_time":"2026-07-16T20:29:27.052952Z","price_level":"64143.76","new_quantity":"0"},{"side":"offer","event_time":"2026-07-16T20:29:27.052952Z","price_level":"64144.56","new_quantity":"0"},{"side":"offer","event_time":"2026-07-16T20:29:27.052952Z","price_level":"64144.72","new_quantity":"0"},{"side":"offer","event_time":"2026-07-16T20:29:27.052952Z","price_level":"64146.23","new_quantity":"0.00779469"},{"side":"offer","event_time":"2026-07-16T20:29:27.052952Z","price_level":"64151","new_quantity":"1"},{"side":"offer","event_time":"2026-07-16T20:29:27.052952Z","price_level":"64151.99","new_quantity":"0.45995538"},{"side":"offer","event_time":"2026-07-16T20:29:27.052952Z","price_level":"64152","new_quantity":"0"},{"side":"offer","event_time":"2026-07-16T20:29:27.052952Z","price_level":"64172.26","new_quantity":"0.32027682"},{"side":"offer","event_time":"2026-07-16T20:29:27.052952Z","price_level":"64173.84","new_quantity":"0"},{"side":"offer","event_time":"2026-07-16T20:29:27.052952Z","price_level":"64173.85","new_quantity":"0"},{"side":"offer","event_time":"2026-07-16T20:29:27.052952Z","price_level":"64176.08","new_quantity":"0.48065828"},{"side":"offer","event_time":"2026-07-16T20:29:27.052952Z","price_level":"64177.52","new_quantity":"0"},{"side":"offer","event_time":"2026-07-16T20:29:27.052952Z","price_level":"64190.33","new_quantity":"0.69637885"},{"side":"offer","event_time":"2026-07-16T20:29:27.052952Z","price_level":"64191.65","new_quantity":"0.99573861"},{"side":"offer","event_time":"2026-07-16T20:29:27.052952Z","price_level":"64191.66","new_quantity":"0"},{"side":"offer","event_time":"2026-07-16T20:29:27.052952Z","price_level":"64193.7","new_quantity":"0"},{"side":"offer","event_time":"2026-07-16T20:29:27.052952Z","price_level":"64194.53","new_quantity":"0"},{"side":"offer","event_time":"2026-07-16T20:29:27.052952Z","price_level":"65649.31","new_quantity":"0.00583"},{"side":"offer","event_time":"2026-07-16T20:29:27.052952Z","price_level":"65649.43","new_quantity":"0"}]}]}
{"channel":"l2_data","timestamp":"2026-07-16T20:29:27.161408878Z","sequence_num":702,"events":[{"type":"update","product_id":"BTC-USD","updates":[{"side":"bid","event_time":"2026-07-16T20:29:27.115484Z","price_level":"64123.39","new_quantity":"0"},{"side":"bid","event_time":"2026-07-16T20:29:27.115484Z","price_level":"64122.72","new_quantity":"0.01559475"},{"side":"bid","event_time":"2026-07-16T20:29:27.115484Z","price_level":"64122.6","new_quantity":"0.31190852"},{"side":"bid","event_time":"2026-07-16T20:29:27.115484Z","price_level":"64119.82","new_quantity":"0.635841"},{"side":"bid","event_time":"2026-07-16T20:29:27.115484Z","price_level":"64119.55","new_quantity":"0.31190852"},{"side":"bid","event_time":"2026-07-16T20:29:27.115484Z","price_level":"64118.1","new_quantity":"0.07447"},{"side":"bid","event_time":"2026-07-16T20:29:27.115484Z","price_level":"64115.56","new_quantity":"0.23359045"},{"side":"bid","event_time":"2026-07-16T20:29:27.115484Z","price_level":"64112.4","new_quantity":"0"},{"side":"bid","event_time":"2026-07-16T20:29:27.115484Z","price_level":"64110.69","new_quantity":"0.00105237"},{"side":"bid","event_time":"2026-07-16T20:29:27.115484Z","price_level":"64104.21","new_quantity":"0"},{"side":"bid","event_time":"2026-07-16T20:29:27.115484Z","price_level":"64103","new_quantity":"1"},{"side":"bid","event_time":"2026-07-16T20:29:27.115484Z","price_level":"64102.01","new_quantity":"0.65504587"},{"side":"bid","event_time":"2026-07-16T20:29:27.115484Z","price_level":"64102","new_quantity":"0"},{"side":"bid","event_time":"2026-07-16T20:29:27.115484Z","price_level":"64064","new_quantity":"0"},{"side":"bid","event_time":"2026-07-16T20:29:27.115484Z","price_level":"64037.64","new_quantity":"0"},{"side":"bid","event_time":"2026-07-16T20:29:27.115484Z","price_level":"64026.74","new_quantity":"0"},{"side":"bid","event_time":"2026-07-16T20:29:27.115484Z","price_level":"56118.13","new_quantity":"0.01337205"},{"side":"offer","event_time":"2026-07-16T20:29:27.115484Z","price_level":"64149.31","new_quantity":"0.6366932"},{"side":"offer","event_time":"2026-07-16T20:29:27.115484Z","price_level":"64151","new_quantity":"1"}]}]}
{"channel":"heartbeats","timestamp":"2026-07-16T20:29:27.163881077Z","sequence_num":703,"events":[{"current_time":"2026-07-16 20:29:27.162906127 +0000 UTC m=+75531.317733181","heartbeat_counter":75531}]}
{"channel":"l2_data","timestamp":"2026-07-16T20:29:27.207664189Z","sequence_num":704,"events":[{"type":"update","product_id":"BTC-USD","updates":[{"side":"bid","event_time":"2026-07-16T20:29:27.170561Z","price_level":"64135","new_quantity":"0.00393629"},{"side":"bid","event_time":"2026-07-16T20:29:27.170561Z","price_level":"64122.72","new_quantity":"0"},{"side":"bid","event_time":"2026-07-16T20:29:27.170561Z","price_level":"64122.7","new_quantity":"0.01559475"},{"side":"bid","event_time":"2026-07-16T20:29:27.170561Z","price_level":"64119.82","new_quantity":"0"},{"side":"bid","event_time":"2026-07-16T20:29:27.170561Z","price_level":"64104.82","new_quantity":"0.64750171"},{"side":"bid","event_time":"2026-07-16T20:29:27.170561Z","price_level":"64104.22","new_quantity":"0"},{"side":"offer","event_time":"2026-07-16T20:29:27.170561Z","price_level":"64149.31","new_quantity":"0.99557463"},{"side":"offer","event_time":"2026-07-16T20:29:27.170561Z","price_level":"64193.69","new_quantity":"0"}]}]}
{"channel":"l2_data","timestamp":"2026-07-16T20:29:27.241131667Z","sequence_num":705,"events":[{"type":"update","product_id":"BTC-USD","updates":[{"side":"bid","event_time":"2026-07-16T20:29:27.206229Z","price_level":"64103","new_quantity":"0"},{"side":"bid","event_time":"2026-07-16T20:29:27.206229Z","price_level":"63493.87","new_quantity":"0"},{"side":"bid","event_time":"2026-07-16T20:29:27.206229Z","price_level":"56118.13","new_quantity":"0"},{"side":"offer","event_time":"2026-07-16T20:29:27.206229Z","price_level":"64136.86","new_quantity":"0.0012474"},{"side":"offer","event_time":"2026-07-16T20:29:27.206229Z","price_level":"64193.7","new_quantity":"0.00077959"},{"side":"offer","event_time":"2026-07-16T20:29:27.206229Z","price_level":"64221.13","new_quantity":"0"},{"side":"offer","event_time":"2026-07-16T20:29:27.206229Z","price_level":"64244.71","new_quantity":"0.00813406"}]}]}
{"channel":"l2_data","timestamp":"2026-07-16T20:29:27.280604483Z","sequence_num":706,"events":[{"type":"update","product_id":"BTC-USD","updates":[{"side":"bid","event_time":"2026-07-16T20:29:27.244403Z","price_level":"64110.69","new_quantity":"0"},{"side":"bid","event_time":"2026-07-16T20:29:27.244403Z","price_level":"64110.03","new_quantity":"0.00779621"},{"side":"bid","event_time":"2026-07-16T20:29:27.244403Z","price_level":"64107","new_quantity":"1"},{"side":"bid","event_time":"2026-07-16T20:29:27.244403Z","price_level":"64104.95","new_quantity":"0.00105246"},{"side":"bid","event_time":"2026-07-16T20:29:27.244403Z","price_level":"64104.82","new_quantity":"1.30252015"},{"side":"bid","event_time":"2026-07-16T20:29:27.244403Z","price_level":"64102.01","new_quantity":"0"}]}]}
{"channel":"l2_data","timestamp":"2026-07-16T20:29:27.329584951Z","sequence_num":707,"events":[{"type":"update","product_id":"BTC-USD","updates":[{"side":"bid","event_time":"2026-07-16T20:29:27.308787Z","price_level":"64135","new_quantity":"0.00054035"},{"side":"bid","event_time":"2026-07-16T20:29:27.308787Z","price_level":"64126.76","new_quantity":"0.02"},{"side":"bid","event_time":"2026-07-16T20:29:27.308787Z","price_level":"64126.38","new_quantity":"0.12475363"},{"side":"bid","event_time":"2026-07-16T20:29:27.308787Z","price_level":"64125.76","new_quantity":"0"},{"side":"bid","event_time":"2026-07-16T20:29:27.308787Z","price_level":"64123.28","new_quantity":"0.15594958"},{"side":"bid","event_time":"2026-07-16T20:29:27.308787Z","price_level":"64107","new_quantity":"0"}]}]}
{"channel":"l2_data","timestamp":"2026-07-16T20:29:27.391383773Z","sequence_num":708,"events":[{"type":"update","product_id":"BTC-USD","updates":[{"side":"bid","event_time":"2026-07-16T20:29:27.35153Z","price_level":"64122.7","new_quantity":"0"},{"side":"bid","event_time":"2026-07-16T20:29:27.35153Z","price_level":"64122.68","new_quantity":"0.01559475"},{"side":"bid","event_time":"2026-07-16T20:29:27.35153Z","price_level":"64108","new_quantity":"1"},{"side":"bid","event_time":"2026-07-16T20:29:27.35153Z","price_level":"64098.15","new_quantity":"0.070555"},{"side":"bid","event_time":"2026-07-16T20:29:27.35153Z","price_level":"64023.26","new_quantity":"0.08914816"},{"side":"offer","event_time":"2026-07-16T20:29:27.35153Z","price_level":"64143.53","new_quantity":"0.00009744"},{"side":"offer","event_time":"2026-07-16T20:29:27.35153Z","price_level":"64144.5","new_quantity":"0.0077949"},{"side":"offer","event_time":"2026-07-16T20:29:27.35153Z","price_level":"64172.24","new_quantity":"0.32027682"},{"side":"offer","event_time":"2026-07-16T20:29:27.35153Z","price_level":"64172.25","new_quantity":"0"},{"side":"offer","event_time":"2026-07-16T20:29:27.35153Z","price_level":"64172.26","new_quantity":"0"},{"side":"offer","event_time":"2026-07-16T20:29:27.35153Z","price_level":"64191.63","new_quantity":"2.18765485"},{"side":"offer","event_time":"2026-07-16T20:29:27.35153Z","price_level":"64191.64","new_quantity":"0"},{"side":"offer","event_time":"2026-07-16T20:29:27.35153Z","price_level":"64191.65","new_quantity":"0"}]}]}
{"channel":"l2_data","timestamp":"2026-07-16T20:29:27.460547365Z","sequence_num":709,"events":[{"type":"update","product_id":"BTC-USD","updates":[{"side":"bid","event_time":"2026-07-16T20:29:27.406554Z","price_level":"64123.48","new_quantity":"0.01559475"},{"side":"bid","event_time":"2026-07-16T20:29:27.406554Z","price_level":"64122.68","new_quantity":"0"},{"side":"bid","event_time":"2026-07-16T20:29:27.406554Z","price_level":"64120.07","new_quantity":"0"},{"side":"bid","event_time":"2026-07-16T20:29:27.406554Z","price_level":"64109","new_quantity":"1"},{"side":"bid","event_time":"2026-07-16T20:29:27.406554Z","price_level":"64108","new_quantity":"0"},{"side":"bid","event_time":"2026-07-16T20:29:27.406554Z","price_level":"56118.13","new_quantity":"0.01337205"}]}]}
{"channel":"l2_data","timestamp":"2026-07-16T20:29:27.493210167Z","sequence_num":710,"events":[{"type":"update","product_id":"BTC-USD","updates":[{"side":"bid","event_time":"2026-07-16T20:29:27.450241Z","price_level":"64135","new_quantity":"0.00054028"},{"side":"offer","event_time":"2026-07-16T20:29:27.450241Z","price_level":"64215.63","new_quantity":"0.0483376"}]}]}
{"channel":"l2_data","timestamp":"2026-07-16T20:29:27.525027286Z","sequence_num":711,"events":[{"type":"update","product_id":"BTC-USD","updates":[{"side":"bid","event_time":"2026-07-16T20:29:27.500802Z","price_level":"64123.49","new_quantity":"0.01559475"},{"side":"bid","event_time":"2026-07-16T20:29:27.500802Z","price_level":"64123.48","new_quantity":"0"},{"side":"bid","event_time":"2026-07-16T20:29:27.500802Z","price_level":"64018.45","new_quantity":"0"},{"side":"bid","event_time":"2026-07-16T20:29:27.500802Z","price_level":"64005.02","new_quantity":"0.233822"},{"side":"bid","event_time":"2026-07-16T20:29:27.500802Z","price_level":"63491.89","new_quantity":"0.03938161"},{"side":"bid","event_time":"2026-07-16T20:29:27.500802Z","price_level":"56118.13","new_quantity":"0"}]}]}
{"channel":"l2_data","timestamp":"2026-07-16T20:29:27.581159968Z","sequence_num":712,"events":[{"type":"update","product_id":"BTC-USD","updates":[{"side":"bid","event_time":"2026-07-16T20:29:27.561755Z","price_level":"64128.59","new_quantity":"0.00779683"},{"side":"bid","event_time":"2026-07-16T20:29:27.561755Z","price_level":"64126.97","new_quantity":"0.12475249"},{"side":"bid","event_time":"2026-07-16T20:29:27.561755Z","price_level":"64126.38","new_quantity":"0"},{"side":"offer","event_time":"2026-07-16T20:29:27.561755Z","price_level":"64146.02","new_quantity":"0.00896392"}]}]}
{"channel":"l2_data","timestamp":"2026-07-16T20:29:27.625553422Z","sequence_num":713,"events":[{"type":"update","product_id":"BTC-USD","updates":[{"side":"bid","event_time":"2026-07-16T20:29:27.605258Z","price_level":"64126.98","new_quantity":"0.02"},{"side":"bid","event_time":"2026-07-16T20:29:27.605258Z","price_level":"64123.51","new_quantity":"0.01559475"},{"side":"bid","event_time":"2026-07-16T20:29:27.605258Z","price_level":"64123.49","new_quantity":"0"},{"side":"bid","event_time":"2026-07-16T20:29:27.605258Z","price_level":"64120.15","new_quantity":"0"},{"side":"bid","event_time":"2026-07-16T20:29:27.605258Z","price_level":"64095.5","new_quantity":"0.02984294"},{"side":"bid","event_time":"2026-07-16T20:29:27.605258Z","price_level":"64092.93","new_quantity":"0.03258819"},{"side":"bid","event_time":"2026-07-16T20:29:27.605258Z","price_level":"64089.08","new_quantity":"0.02536215"}]}]}
{"channel":"l2_data","timestamp":"2026-07-16T20:29:27.674954806Z","sequence_num":714,"events":[{"type":"update","product_id":"BTC-USD","updates":[{"side":"bid","event_time":"2026-07-16T20:29:27.628262Z","price_level":"51308","new_quantity":"0.0002"}]}]}
{"channel":"l2_data","timestamp":"2026-07-16T20:29:27.731016252Z","sequence_num":715,"events":[{"type":"update","product_id":"BTC-USD","updates":[{"side":"bid","event_time":"2026-07-16T20:29:27.710824Z","price_level":"56118.13","new_quantity":"0.01337205"},{"side":"offer","event_time":"2026-07-16T20:29:27.710824Z","price_level":"64135.01","new_quantity":"1.12360533"},{"side":"offer","event_time":"2026-07-16T20:29:27.710824Z","price_level":"64146.23","new_quantity":"0"}]}]}
{"channel":"l2_data","timestamp":"2026-07-16T20:29:27.779946823Z","sequence_num":716,"events":[{"type":"update","product_id":"BTC-USD","updates":[{"side":"bid","event_time":"2026-07-16T20:29:27.741372Z","price_level":"64123.51","new_quantity":"0"},{"side":"bid","event_time":"2026-07-16T20:29:27.741372Z","price_level":"64122.6","new_quantity":"0.32750327"},{"side":"offer","event_time":"2026-07-16T20:29:27.741372Z","price_level":"64144.73","new_quantity":"0.00009744"},{"side":"offer","event_time":"2026-07-16T20:29:27.741372Z","price_level":"64144.95","new_quantity":"0"},{"side":"offer","event_time":"2026-07-16T20:29:27.741372Z","price_level":"64146.01","new_quantity":"0.00779472"},{"side":"offer","event_time":"2026-07-16T20:29:27.741372Z","price_level":"64776.58","new_quantity":"0"}]}]}
{"channel":"l2_data","timestamp":"2026-07-16T20:29:27.830940123Z","sequence_num":717,"events":[{"type":"update","product_id":"BTC-USD","updates":[{"side":"bid","event_time":"2026-07-16T20:29:27.810311Z","price_level":"64130.19","new_quantity":"0.00779664"},{"side":"bid","event_time":"2026-07-16T20:29:27.810311Z","price_level":"64122.6","new_quantity":"0.31190852"},{"side":"bid","event_time":"2026-07-16T20:29:27.810311Z","price_level":"64094.05","new_quantity":"0"},{"side":"bid","event_time":"2026-07-16T20:29:27.810311Z","price_level":"64091.06","new_quantity":"0.92251282"},{"side":"bid","event_time":"2026-07-16T20:29:27.810311Z","price_level":"64076.57","new_quantity":"0"},{"side":"bid","event_time":"2026-07-16T20:29:27.810311Z","price_level":"64076.56","new_quantity":"0"},{"side":"bid","event_time":"2026-07-16T20:29:27.810311Z","price_level":"64070.13","new_quantity":"1.43548444"},{"side":"bid","event_time":"2026-07-16T20:29:27.810311Z","price_level":"56118.13","new_quantity":"0"},{"side":"offer","event_time":"2026-07-16T20:29:27.810311Z","price_level":"64139.59","new_quantity":"0"},{"side":"offer","event_time":"2026-07-16T20:29:27.810311Z","price_level":"64144.41","new_quantity":"0.00896415"},{"side":"offer","event_time":"2026-07-16T20:29:27.810311Z","price_level":"64144.63","new_quantity":"0"},{"side":"offer","event_time":"2026-07-16T20:29:27.810311Z","price_level":"64174.34","new_quantity":"0.48067132"},{"side":"offer","event_time":"2026-07-16T20:29:27.810311Z","price_level":"64176.08","new_quantity":"0"},{"side":"offer","event_time":"2026-07-16T20:29:27.810311Z","price_level":"64185.58","new_quantity":"0"},{"side":"offer","event_time":"2026-07-16T20:29:27.810311Z","price_level":"64188.29","new_quantity":"0.69640098"},{"side":"offer","event_time":"2026-07-16T20:29:27.810311Z","price_level":"64190.33","new_quantity":"0"}]}]}
{"channel":"l2_data","timestamp":"2026-07-16T20:29:27.880058093Z","sequence_num":718,"events":[{"type":"update","product_id":"BTC-USD","updates":[{"side":"bid","event_time":"2026-07-16T20:29:27.83772Z","price_level":"64122.4","new_quantity":"0.01559475"},{"side":"bid","event_time":"2026-07-16T20:29:27.83772Z","price_level":"64122.38","new_quantity":"0"},{"side":"bid","event_time":"2026-07-16T20:29:27.83772Z","price_level":"64071.09","new_quantity":"0.29630017"},{"side":"offer","event_time":"2026-07-16T20:29:27.83772Z","price_level":"64180.1","new_quantity":"0.29784517"},{"side":"offer","event_time":"2026-07-16T20:29:27.83772Z","price_level":"64185.11","new_quantity":"0"}]}]}
{"channel":"l2_data","timestamp":"2026-07-16T20:29:27.925409966Z","sequence_num":719,"events":[{"type":"update","product_id":"BTC-USD","updates":[{"side":"bid","event_time":"2026-07-16T20:29:27.901308Z","price_level":"64120.27","new_quantity":"0"},{"side":"bid","event_time":"2026-07-16T20:29:27.901308Z","price_level":"64092.21","new_quantity":"0.92171675"},{"side":"bid","event_time":"2026-07-16T20:29:27.901308Z","price_level":"64091.06","new_quantity":"0.00077953"},{"side":"bid","event_time":"2026-07-16T20:29:27.901308Z","price_level":"64074.38","new_quantity":"1.43538923"},{"side":"bid","event_time":"2026-07-16T20:29:27.901308Z","price_level":"64070.13","new_quantity":"0"}]}]}
{"channel":"l2_data","timestamp":"2026-07-16T20:29:27.980260057Z","sequence_num":720,"events":[{"type":"update","product_id":"BTC-USD","updates":[{"side":"bid","event_time":"2026-07-16T20:29:27.945046Z","price_level":"64122.42","new_quantity":"0.01559475"},{"side":"bid","event_time":"2026-07-16T20:29:27.945046Z","price_level":"64122.4","new_quantity":"0"},{"side":"bid","event_time":"2026-07-16T20:29:27.945046Z","price_level":"64091.07","new_quantity":"0.00077958"},{"side":"bid","event_time":"2026-07-16T20:29:27.945046Z","price_level":"64091.06","new_quantity":"0"},{"side":"bid","event_time":"2026-07-16T20:29:27.945046Z","price_level":"51308","new_quantity":"0"},{"side":"offer","event_time":"2026-07-16T20:29:27.945046Z","price_level":"64775.21","new_quantity":"0.03890047"}]}]}
{"channel":"l2_data","timestamp":"2026-07-16T20:29:28.025622178Z","sequence_num":721,"events":[{"type":"update","product_id":"BTC-USD","updates":[{"side":"bid","event_time":"2026-07-16T20:29:27.993418Z","price_level":"64122.43","new_quantity":"0.01559475"},{"side":"bid","event_time":"2026-07-16T20:29:27.993418Z","price_level":"64122.42","new_quantity":"0"},{"side":"bid","event_time":"2026-07-16T20:29:27.993418Z","price_level":"56118.13","new_quantity":"0.01337205"}]}]}
{"channel":"l2_data","timestamp":"2026-07-16T20:29:28.089122623Z","sequence_num":722,"events":[{"type":"update","product_id":"BTC-USD","updates":[{"side":"bid","event_time":"2026-07-16T20:29:28.019521Z","price_level":"64123.54","new_quantity":"0.01559475"},{"side":"bid","event_time":"2026-07-16T20:29:28.019521Z","price_level":"64122.43","new_quantity":"0"},{"side":"bid","event_time":"2026-07-16T20:29:28.019521Z","price_level":"64060.8","new_quantity":"0.01113732"},{"side":"offer","event_time":"2026-07-16T20:29:28.019521Z","price_level":"64143.53","new_quantity":"0"},{"side":"offer","event_time":"2026-07-16T20:29:28.019521Z","price_level":"64144.5","new_quantity":"0"}]}]}
{"channel":"l2_data","timestamp":"2026-07-16T20:29:28.129725138Z","sequence_num":723,"events":[{"type":"update","product_id":"BTC-USD","updates":[{"side":"bid","event_time":"2026-07-16T20:29:28.109953Z","price_level":"64120.31","new_quantity":"0.6129"},{"side":"bid","event_time":"2026-07-16T20:29:28.109953Z","price_level":"64109","new_quantity":"0"},{"side":"bid","event_time":"2026-07-16T20:29:28.109953Z","price_level":"56118.13","new_quantity":"0"},{"side":"offer","event_time":"2026-07-16T20:29:28.109953Z","price_level":"64157.99","new_quantity":"0"}]}]}
{"channel":"heartbeats","timestamp":"2026-07-16T20:29:28.165925825Z","sequence_num":724,"events":[{"current_time":"2026-07-16 20:29:28.162994725 +0000 UTC m=+75532.317821770","heartbeat_counter":75532}]}
{"channel":"l2_data","timestamp":"2026-07-16T20:29:28.175546007Z","sequence_num":725,"events":[{"type":"update","product_id":"BTC-USD","updates":[{"side":"bid","event_time":"2026-07-16T20:29:28.152455Z","price_level":"64123.54","new_quantity":"0"},{"side":"bid","event_time":"2026-07-16T20:29:28.152455Z","price_level":"64123.53","new_quantity":"0.01559475"},{"side":"bid","event_time":"2026-07-16T20:29:28.152455Z","price_level":"64120.31","new_quantity":"0"},{"side":"bid","event_time":"2026-07-16T20:29:28.152455Z","price_level":"64110","new_quantity":"1.01"}]}]}
{"channel":"l2_data","timestamp":"2026-07-16T20:29:28.224893253Z","sequence_num":726,"events":[{"type":"update","product_id":"BTC-USD","updates":[{"side":"bid","event_time":"2026-07-16T20:29:28.209313Z","price_level":"64135","new_quantity":"0.00406092"},{"side":"bid","event_time":"2026-07-16T20:29:28.209313Z","price_level":"64124.54","new_quantity":"0.31190852"},{"side":"bid","event_time":"2026-07-16T20:29:28.209313Z","price_level":"64102.77","new_quantity":"0.00077958"},{"side":"bid","event_time":"2026-07-16T20:29:28.209313Z","price_level":"64102.76","new_quantity":"0.31190852"},{"side":"bid","event_time":"2026-07-16T20:29:28.209313Z","price_level":"64033.55","new_quantity":"0.00813406"}]}]}
{"channel":"l2_data","timestamp":"2026-07-16T20:29:28.279784271Z","sequence_num":727,"events":[{"type":"update","product_id":"BTC-USD","updates":[{"side":"bid","event_time":"2026-07-16T20:29:28.258641Z","price_level":"63491.89","new_quantity":"0"},{"side":"offer","event_time":"2026-07-16T20:29:28.258641Z","price_level":"64157.1","new_quantity":"0.00779621"}]}]}
{"channel":"l2_data","timestamp":"2026-07-16T20:29:28.325393911Z","sequence_num":728,"events":[{"type":"update","product_id":"BTC-USD","updates":[{"side":"bid","event_time":"2026-07-16T20:29:28.29255Z","price_level":"56118.13","new_quantity":"0.01337205"}]}]}
{"channel":"l2_data","timestamp":"2026-07-16T20:29:28.384364316Z","sequence_num":729,"events":[{"type":"update","product_id":"BTC-USD","updates":[{"side":"bid","event_time":"2026-07-16T20:29:28.36285Z","price_level":"64123.53","new_quantity":"0"},{"side":"bid","event_time":"2026-07-16T20:29:28.36285Z","price_level":"64123.52","new_quantity":"0.01559475"},{"side":"bid","event_time":"2026-07-16T20:29:28.36285Z","price_level":"64120.47","new_quantity":"0"},{"side":"bid","event_time":"2026-07-16T20:29:28.36285Z","price_level":"64110","new_quantity":"0.01"},{"side":"bid","event_time":"2026-07-16T20:29:28.36285Z","price_level":"64109","new_quantity":"1"},{"side":"offer","event_time":"2026-07-16T20:29:28.36285Z","price_level":"64172.22","new_quantity":"0.32027682"},{"side":"offer","event_time":"2026-07-16T20:29:28.36285Z","price_level":"64172.23","new_quantity":"0"},{"side":"offer","event_time":"2026-07-16T20:29:28.36285Z","price_level":"64172.24","new_quantity":"0"},{"side":"offer","event_time":"2026-07-16T20:29:28.36285Z","price_level":"64191.61","new_quantity":"2.18765553"},{"side":"offer","event_time":"2026-07-16T20:29:28.36285Z","price_level":"64191.62","new_quantity":"0"},{"side":"offer","event_time":"2026-07-16T20:29:28.36285Z","price_level":"64191.63","new_quantity":"0"}]}]}
{"channel":"l2_data","timestamp":"2026-07-16T20:29:28.43117671Z","sequence_num":730,"events":[{"type":"update","product_id":"BTC-USD","updates":[{"side":"bid","event_time":"2026-07-16T20:29:28.411411Z","price_level":"64135","new_quantity":"0.00406067"},{"side":"bid","event_time":"2026-07-16T20:29:28.411411Z","price_level":"56118.13","new_quantity":"0"},{"side":"offer","event_time":"2026-07-16T20:29:28.411411Z","price_level":"64143.32","new_quantity":"0.00009744"},{"side":"offer","event_time":"2026-07-16T20:29:28.411411Z","price_level":"64144.28","new_quantity":"0.00779493"},{"side":"offer","event_time":"2026-07-16T20:29:28.411411Z","price_level":"64157.1","new_quantity":"0"}]}]}
{"channel":"l2_data","timestamp":"2026-07-16T20:29:28.479488339Z","sequence_num":731,"events":[{"type":"update","product_id":"BTC-USD","updates":[{"side":"bid","event_time":"2026-07-16T20:29:28.459044Z","price_level":"64135","new_quantity":"0.00054003"},{"side":"bid","event_time":"2026-07-16T20:29:28.459044Z","price_level":"64109","new_quantity":"0"},{"side":"offer","event_time":"2026-07-16T20:29:28.459044Z","price_level":"64149.31","new_quantity":"0.6366932"},{"side":"offer","event_time":"2026-07-16T20:29:28.459044Z","price_level":"64151","new_quantity":"0"}]}]}
{"channel":"l2_data","timestamp":"2026-07-16T20:29:28.530168056Z","sequence_num":732,"events":[{"type":"update","product_id":"BTC-USD","updates":[{"side":"bid","event_time":"2026-07-16T20:29:28.502874Z","price_level":"64135","new_quantity":"0.0005399"},{"side":"bid","event_time":"2026-07-16T20:29:28.502874Z","price_level":"64123.52","new_quantity":"0"},{"side":"bid","event_time":"2026-07-16T20:29:28.502874Z","price_level":"64123.51","new_quantity":"0.01559475"},{"side":"bid","event_time":"2026-07-16T20:29:28.502874Z","price_level":"64110","new_quantity":"1.01"},{"side":"bid","event_time":"2026-07-16T20:29:28.502874Z","price_level":"63492.53","new_quantity":"0.03938122"},{"side":"offer","event_time":"2026-07-16T20:29:28.502874Z","price_level":"64149.31","new_quantity":"0.99557463"},{"side":"offer","event_time":"2026-07-16T20:29:28.502874Z","price_level":"64150","new_quantity":"1.01"}]}]}
{"channel":"l2_data","timestamp":"2026-07-16T20:29:28.581103162Z","sequence_num":733,"events":[{"type":"update","product_id":"BTC-USD","updates":[{"side":"offer","event_time":"2026-07-16T20:29:28.560778Z","price_level":"64157.1","new_quantity":"0.00779621"}]}]}
{"channel":"l2_data","timestamp":"2026-07-16T20:29:28.633755762Z","sequence_num":734,"events":[{"type":"update","product_id":"BTC-USD","updates":[{"side":"bid","event_time":"2026-07-16T20:29:28.604393Z","price_level":"64135","new_quantity":"0"},{"side":"bid","event_time":"2026-07-16T20:29:28.604393Z","price_level":"64134.6","new_quantity":"0"},{"side":"bid","event_time":"2026-07-16T20:29:28.604393Z","price_level":"64133.71","new_quantity":"0"},{"side":"bid","event_time":"2026-07-16T20:29:28.604393Z","price_level":"64131.65","new_quantity":"0.01"},{"side":"bid","event_time":"2026-07-16T20:29:28.604393Z","price_level":"64130.43","new_quantity":"0.000018"},{"side":"bid","event_time":"2026-07-16T20:29:28.604393Z","price_level":"64130","new_quantity":"0"},{"side":"bid","event_time":"2026-07-16T20:29:28.604393Z","price_level":"64128.59","new_quantity":"0"},{"side":"bid","event_time":"2026-07-16T20:29:28.604393Z","price_level":"64127.58","new_quantity":"0"},{"side":"bid","event_time":"2026-07-16T20:29:28.604393Z","price_level":"64127.57","new_quantity":"0.12475133"},{"side":"bid","event_time":"2026-07-16T20:29:28.604393Z","price_level":"64126.98","new_quantity":"0"},{"side":"bid","event_time":"2026-07-16T20:29:28.604393Z","price_level":"64126.97","new_quantity":"0"},{"side":"bid","event_time":"2026-07-16T20:29:28.604393Z","price_level":"64126.76","new_quantity":"0"},{"side":"bid","event_time":"2026-07-16T20:29:28.604393Z","price_level":"64123.51","new_quantity":"0"},{"side":"bid","event_time":"2026-07-16T20:29:28.604393Z","price_level":"64122.05","new_quantity":"0.01559475"},{"side":"bid","event_time":"2026-07-16T20:29:28.604393Z","price_level":"64119.37","new_quantity":"0.669255"},{"side":"bid","event_time":"2026-07-16T20:29:28.604393Z","price_level":"64104.82","new_quantity":"0.65501844"},{"side":"bid","event_time":"2026-07-16T20:29:28.604393Z","price_level":"64102.77","new_quantity":"0.648302"},{"side":"bid","event_time":"2026-07-16T20:29:28.604393Z","price_level":"64092.21","new_quantity":"0"},{"side":"bid","event_time":"2026-07-16T20:29:28.604393Z","price_level":"64089.09","new_quantity":"0.92176162"},{"side":"bid","event_time":"2026-07-16T20:29:28.604393Z","price_level":"64083.36","new_quantity":"0.0000234"},{"side":"bid","event_time":"2026-07-16T20:29:28.604393Z","price_level":"64074.38","new_quantity":"0"},{"side":"bid","event_time":"2026-07-16T20:29:28.604393Z","price_level":"64072.13","new_quantity":"0.10973501"},{"side":"bid","event_time":"2026-07-16T20:29:28.604393Z","price_level":"64071.1","new_quantity":"1.43546271"},{"side":"bid","event_time":"2026-07-16T20:29:28.604393Z","price_level":"64063.71","new_quantity":"0.000018"},{"side":"bid","event_time":"2026-07-16T20:29:28.604393Z","price_level":"64047.75","new_quantity":"0.01061683"},{"side":"offer","event_time":"2026-07-16T20:29:28.604393Z","price_level":"64131.66","new_quantity":"0.07488097"},{"side":"offer","event_time":"2026-07-16T20:29:28.604393Z","price_level":"64132.71","new_quantity":"0.0266"},{"side":"offer","event_time":"2026-07-16T20:29:28.604393Z","price_level":"64132.72","new_quantity":"0.0089"},{"side":"offer","event_time":"2026-07-16T20:29:28.604393Z","price_level":"64133.71","new_quantity":"0.4869314"},{"side":"offer","event_time":"2026-07-16T20:29:28.604393Z","price_level":"64133.72","new_quantity":"0.56804273"},{"side":"offer","event_time":"2026-07-16T20:29:28.604393Z","price_level":"64135","new_quantity":"0.00545729"},{"side":"offer","event_time":"2026-07-16T20:29:28.604393Z","price_level":"64135.01","new_quantity":"0.12499553"},{"side":"offer","event_time":"2026-07-16T20:29:28.604393Z","price_level":"64136.3","new_quantity":"0"},{"side":"offer","event_time":"2026-07-16T20:29:28.604393Z","price_level":"64136.99","new_quantity":"0.0486477"},{"side":"offer","event_time":"2026-07-16T20:29:28.604393Z","price_level":"64137.18","new_quantity":"0.19120421"},{"side":"offer","event_time":"2026-07-16T20:29:28.604393Z","price_level":"64137.47","new_quantity":"0"},{"side":"offer","event_time":"2026-07-16T20:29:28.604393Z","price_level":"64140.14","new_quantity":"0"},{"side":"offer","event_time":"2026-07-16T20:29:28.604393Z","price_level":"64140.66","new_quantity":"0"},{"side":"offer","event_time":"2026-07-16T20:29:28.604393Z","price_level":"64142.94","new_quantity":"0.000018"},{"side":"offer","event_time":"2026-07-16T20:29:28.604393Z","price_level":"64146.02","new_quantity":"0"},{"side":"offer","event_time":"2026-07-16T20:29:28.604393Z","price_level":"64149.31","new_quantity":"0.6366932"},{"side":"offer","event_time":"2026-07-16T20:29:28.604393Z","price_level":"64150","new_quantity":"0.01"},{"side":"offer","event_time":"2026-07-16T20:29:28.604393Z","price_level":"64155.99","new_quantity":"0"},{"side":"offer","event_time":"2026-07-16T20:29:28.604393Z","price_level":"64156.53","new_quantity":"0"},{"side":"offer","event_time":"2026-07-16T20:29:28.604393Z","price_level":"64169.99","new_quantity":"0.32027682"},{"side":"offer","event_time":"2026-07-16T20:29:28.604393Z","price_level":"64172.22","new_quantity":"0"},{"side":"offer","event_time":"2026-07-16T20:29:28.604393Z","price_level":"64173.62","new_quantity":"0.48067671"},{"side":"offer","event_time":"2026-07-16T20:29:28.604393Z","price_level":"64174.34","new_quantity":"0"},{"side":"offer","event_time":"2026-07-16T20:29:28.604393Z","price_level":"64190.33","new_quantity":"2.13045644"},{"side":"offer","event_time":"2026-07-16T20:29:28.604393Z","price_level":"64191.61","new_quantity":"0"},{"side":"offer","event_time":"2026-07-16T20:29:28.604393Z","price_level":"64202.08","new_quantity":"0"},{"side":"offer","event_time":"2026-07-16T20:29:28.604393Z","price_level":"64202.09","new_quantity":"0"},{"side":"offer","event_time":"2026-07-16T20:29:28.604393Z","price_level":"64226.34","new_quantity":"0"},{"side":"offer","event_time":"2026-07-16T20:29:28.604393Z","price_level":"65005.89","new_quantity":"0.00583"},{"side":"offer","event_time":"2026-07-16T20:29:28.604393Z","price_level":"65005.97","new_quantity":"0"},{"side":"offer","event_time":"2026-07-16T20:29:28.604393Z","price_level":"65219.45","new_quantity":"0"},{"side":"offer","event_time":"2026-07-16T20:29:28.604393Z","price_level":"65220.51","new_quantity":"0.00583"},{"side":"offer","event_time":"2026-07-16T20:29:28.604393Z","price_level":"65220.77","new_quantity":"0"},{"side":"offer","event_time":"2026-07-16T20:29:28.604393Z","price_level":"65434.75","new_quantity":"0"},{"side":"offer","event_time":"2026-07-16T20:29:28.604393Z","price_level":"65434.83","new_quantity":"0"},{"side":"offer","event_time":"2026-07-16T20:29:28.604393Z","price_level":"65649.31","new_quantity":"0"}]}]}
{"channel":"l2_data","timestamp":"2026-07-16T20:29:28.682171253Z","sequence_num":735,"events":[{"type":"update","product_id":"BTC-USD","updates":[{"side":"bid","event_time":"2026-07-16T20:29:28.660549Z","price_level":"64128.59","new_quantity":"0.00779683"},{"side":"bid","event_time":"2026-07-16T20:29:28.660549Z","price_level":"64126.27","new_quantity":"0.02"},{"side":"bid","event_time":"2026-07-16T20:29:28.660549Z","price_level":"64119.37","new_quantity":"0"},{"side":"bid","event_time":"2026-07-16T20:29:28.660549Z","price_level":"64116.04","new_quantity":"0.05805156"},{"side":"bid","event_time":"2026-07-16T20:29:28.660549Z","price_level":"64109.04","new_quantity":"0.001545"},{"side":"bid","event_time":"2026-07-16T20:29:28.660549Z","price_level":"64047.75","new_quantity":"0"},{"side":"offer","event_time":"2026-07-16T20:29:28.660549Z","price_level":"64131.66","new_quantity":"0.09591626"},{"side":"offer","event_time":"2026-07-16T20:29:28.660549Z","price_level":"64132.44","new_quantity":"0.00234579"},{"side":"offer","event_time":"2026-07-16T20:29:28.660549Z","price_level":"64132.71","new_quantity":"0"},{"side":"offer","event_time":"2026-07-16T20:29:28.660549Z","price_level":"64132.72","new_quantity":"0"},{"side":"offer","event_time":"2026-07-16T20:29:28.660549Z","price_level":"64133.26","new_quantity":"0.02"},{"side":"offer","event_time":"2026-07-16T20:29:28.660549Z","price_level":"64133.27","new_quantity":"0.00545752"},{"side":"offer","event_time":"2026-07-16T20:29:28.660549Z","price_level":"64133.7","new_quantity":"0.02"},{"side":"offer","event_time":"2026-07-16T20:29:28.660549Z","price_level":"64133.72","new_quantity":"0.56569697"},{"side":"offer","event_time":"2026-07-16T20:29:28.660549Z","price_level":"64135","new_quantity":"0"},{"side":"offer","event_time":"2026-07-16T20:29:28.660549Z","price_level":"64135.43","new_quantity":"0.0068219"},{"side":"offer","event_time":"2026-07-16T20:29:28.660549Z","price_level":"64136.62","new_quantity":"0"},{"side":"offer","event_time":"2026-07-16T20:29:28.660549Z","price_level":"64138.78","new_quantity":"0"},{"side":"offer","event_time":"2026-07-16T20:29:28.660549Z","price_level":"64142.05","new_quantity":"0.0077892"},{"side":"offer","event_time":"2026-07-16T20:29:28.660549Z","price_level":"64142.06","new_quantity":"0.00077964"},{"side":"offer","event_time":"2026-07-16T20:29:28.660549Z","price_level":"64142.49","new_quantity":"0"},{"side":"offer","event_time":"2026-07-16T20:29:28.660549Z","price_level":"64145.28","new_quantity":"0"},{"side":"offer","event_time":"2026-07-16T20:29:28.660549Z","price_level":"64145.81","new_quantity":"0.00896395"},{"side":"offer","event_time":"2026-07-16T20:29:28.660549Z","price_level":"64149.31","new_quantity":"0.99557463"},{"side":"offer","event_time":"2026-07-16T20:29:28.660549Z","price_level":"64150","new_quantity":"1.01"},{"side":"offer","event_time":"2026-07-16T20:29:28.660549Z","price_level":"64155.05","new_quantity":"0.00105252"},{"side":"offer","event_time":"2026-07-16T20:29:28.660549Z","price_level":"64161.39","new_quantity":"0"},{"side":"offer","event_time":"2026-07-16T20:29:28.660549Z","price_level":"64177.27","new_quantity":"0"},{"side":"offer","event_time":"2026-07-16T20:29:28.660549Z","price_level":"64214.21","new_quantity":"0.0035084"},{"side":"offer","event_time":"2026-07-16T20:29:28.660549Z","price_level":"64235.35","new_quantity":"0"},{"side":"offer","event_time":"2026-07-16T20:29:28.660549Z","price_level":"65220.41","new_quantity":"0.00583"},{"side":"offer","event_time":"2026-07-16T20:29:28.660549Z","price_level":"65220.45","new_quantity":"0.00583"},{"side":"offer","event_time":"2026-07-16T20:29:28.660549Z","price_level":"65220.51","new_quantity":"0"},{"side":"offer","event_time":"2026-07-16T20:29:28.660549Z","price_level":"65435.24","new_quantity":"0.00583"}]}]}
{"channel":"l2_data","timestamp":"2026-07-16T20:29:28.72966888Z","sequence_num":736,"events":[{"type":"update","product_id":"BTC-USD","updates":[{"side":"bid","event_time":"2026-07-16T20:29:28.702901Z","price_level":"64116.04","new_quantity":"0"},{"side":"bid","event_time":"2026-07-16T20:29:28.702901Z","price_level":"64072.14","new_quantity":"1.43543941"},{"side":"bid","event_time":"2026-07-16T20:29:28.702901Z","price_level":"64071.1","new_quantity":"0"},{"side":"bid","event_time":"2026-07-16T20:29:28.702901Z","price_level":"63730.17","new_quantity":"0"},{"side":"offer","event_time":"2026-07-16T20:29:28.702901Z","price_level":"64169.59","new_quantity":"0.32027682"},{"side":"offer","event_time":"2026-07-16T20:29:28.702901Z","price_level":"64169.99","new_quantity":"0"},{"side":"offer","event_time":"2026-07-16T20:29:28.702901Z","price_level":"65220.45","new_quantity":"0"}]}]}
{"channel":"l2_data","timestamp":"2026-07-16T20:29:28.780800065Z","sequence_num":737,"events":[{"type":"update","product_id":"BTC-USD","updates":[{"side":"bid","event_time":"2026-07-16T20:29:28.756742Z","price_level":"64131.65","new_quantity":"0.01005954"},{"side":"bid","event_time":"2026-07-16T20:29:28.756742Z","price_level":"64126.29","new_quantity":"0.02"},{"side":"bid","event_time":"2026-07-16T20:29:28.756742Z","price_level":"64122.2","new_quantity":"0.04256694"},{"side":"bid","event_time":"2026-07-16T20:29:28.756742Z","price_level":"64110.03","new_quantity":"0"},{"side":"bid","event_time":"2026-07-16T20:29:28.756742Z","price_level":"64102.77","new_quantity":"0.64752242"},{"side":"bid","event_time":"2026-07-16T20:29:28.756742Z","price_level":"64100.75","new_quantity":"0.00077958"},{"side":"bid","event_time":"2026-07-16T20:29:28.756742Z","price_level":"64091.07","new_quantity":"0"},{"side":"bid","event_time":"2026-07-16T20:29:28.756742Z","price_level":"64090.43","new_quantity":"0"},{"side":"bid","event_time":"2026-07-16T20:29:28.756742Z","price_level":"64067.05","new_quantity":"0.001545"},{"side":"bid","event_time":"2026-07-16T20:29:28.756742Z","price_level":"63727.09","new_quantity":"0.01061683"},{"side":"offer","event_time":"2026-07-16T20:29:28.756742Z","price_level":"64157.1","new_quantity":"0"},{"side":"offer","event_time":"2026-07-16T20:29:28.756742Z","price_level":"64174.33","new_quantity":"0"},{"side":"offer","event_time":"2026-07-16T20:29:28.756742Z","price_level":"64174.99","new_quantity":"0"},{"side":"offer","event_time":"2026-07-16T20:29:28.756742Z","price_level":"64180.6","new_quantity":"0"},{"side":"offer","event_time":"2026-07-16T20:29:28.756742Z","price_level":"64182.44","new_quantity":"0"},{"side":"offer","event_time":"2026-07-16T20:29:28.756742Z","price_level":"64192.99","new_quantity":"0"},{"side":"offer","event_time":"2026-07-16T20:29:28.756742Z","price_level":"64193.7","new_quantity":"0"}]}]}
{"channel":"l2_data","timestamp":"2026-07-16T20:29:28.826604294Z","sequence_num":738,"events":[{"type":"update","product_id":"BTC-USD","updates":[{"side":"offer","event_time":"2026-07-16T20:29:28.802403Z","price_level":"64132.43","new_quantity":"0.02"},{"side":"offer","event_time":"2026-07-16T20:29:28.802403Z","price_level":"64144.52","new_quantity":"0.00009744"},{"side":"offer","event_time":"2026-07-16T20:29:28.802403Z","price_level":"64144.73","new_quantity":"0"},{"side":"offer","event_time":"2026-07-16T20:29:28.802403Z","price_level":"64145.81","new_quantity":"0.01675869"},{"side":"offer","event_time":"2026-07-16T20:29:28.802403Z","price_level":"64146.01","new_quantity":"0"}]}]}
{"channel":"l2_data","timestamp":"2026-07-16T20:29:28.892271221Z","sequence_num":739,"events":[{"type":"update","product_id":"BTC-USD","updates":[{"side":"bid","event_time":"2026-07-16T20:29:28.859868Z","price_level":"64130.19","new_quantity":"0"},{"side":"bid","event_time":"2026-07-16T20:29:28.859868Z","price_level":"64047.75","new_quantity":"0.01061683"},{"side":"offer","event_time":"2026-07-16T20:29:28.859868Z","price_level":"64133.7","new_quantity":"0.06691558"},{"side":"offer","event_time":"2026-07-16T20:29:28.859868Z","price_level":"64144.41","new_quantity":"0"},{"side":"offer","event_time":"2026-07-16T20:29:28.859868Z","price_level":"64156.99","new_quantity":"0.01"},{"side":"offer","event_time":"2026-07-16T20:29:28.859868Z","price_level":"64179.94","new_quantity":"0.5"},{"side":"offer","event_time":"2026-07-16T20:29:28.859868Z","price_level":"64184.55","new_quantity":"0"},{"side":"offer","event_time":"2026-07-16T20:29:28.859868Z","price_level":"64207.14","new_quantity":"0"},{"side":"offer","event_time":"2026-07-16T20:29:28.859868Z","price_level":"64207.15","new_quantity":"0"}]}]}
{"channel":"l2_data","timestamp":"2026-07-16T20:29:28.932021096Z","sequence_num":740,"events":[{"type":"update","product_id":"BTC-USD","updates":[{"side":"bid","event_time":"2026-07-16T20:29:28.906185Z","price_level":"64130.36","new_quantity":"0.00779662"},{"side":"bid","event_time":"2026-07-16T20:29:28.906185Z","price_level":"64127.58","new_quantity":"0.02"},{"side":"bid","event_time":"2026-07-16T20:29:28.906185Z","price_level":"64126.84","new_quantity":"0.00779705"},{"side":"bid","event_time":"2026-07-16T20:29:28.906185Z","price_level":"64109.9","new_quantity":"0.01"},{"side":"bid","event_time":"2026-07-16T20:29:28.906185Z","price_level":"64086.82","new_quantity":"0.00077958"},{"side":"bid","event_time":"2026-07-16T20:29:28.906185Z","price_level":"64047.75","new_quantity":"0"},{"side":"bid","event_time":"2026-07-16T20:29:28.906185Z","price_level":"56115.2","new_quantity":"0.01337205"},{"side":"offer","event_time":"2026-07-16T20:29:28.906185Z","price_level":"64132.28","new_quantity":"0.00234579"},{"side":"offer","event_time":"2026-07-16T20:29:28.906185Z","price_level":"64132.44","new_quantity":"0"},{"side":"offer","event_time":"2026-07-16T20:29:28.906185Z","price_level":"64132.95","new_quantity":"0.0077963"},{"side":"offer","event_time":"2026-07-16T20:29:28.906185Z","price_level":"64133.69","new_quantity":"0.02"},{"side":"offer","event_time":"2026-07-16T20:29:28.906185Z","price_level":"64144.2","new_quantity":"0.00896418"},{"side":"offer","event_time":"2026-07-16T20:29:28.906185Z","price_level":"64170.14","new_quantity":"0.0005"},{"side":"offer","event_time":"2026-07-16T20:29:28.906185Z","price_level":"64172.26","new_quantity":"0.00077962"},{"side":"offer","event_time":"2026-07-16T20:29:28.906185Z","price_level":"64178.03","new_quantity":"0.00077958"},{"side":"offer","event_time":"2026-07-16T20:29:28.906185Z","price_level":"64190.32","new_quantity":"0.00077958"}]}]}
{"channel":"l2_data","timestamp":"2026-07-16T20:29:28.980532047Z","sequence_num":741,"events":[{"type":"update","product_id":"BTC-USD","updates":[{"side":"bid","event_time":"2026-07-16T20:29:28.949912Z","price_level":"63727.09","new_quantity":"0"},{"side":"offer","event_time":"2026-07-16T20:29:28.949912Z","price_level":"64131.66","new_quantity":"0.09572393"},{"side":"offer","event_time":"2026-07-16T20:29:28.949912Z","price_level":"64132.27","new_quantity":"0"},{"side":"offer","event_time":"2026-07-16T20:29:28.949912Z","price_level":"64132.43","new_quantity":"0"},{"side":"offer","event_time":"2026-07-16T20:29:28.949912Z","price_level":"65650.84","new_quantity":"0.00583"}]}]}
{"channel":"heartbeats","timestamp":"2026-07-16T20:29:29.165062778Z","sequence_num":742,"events":[{"current_time":"2026-07-16 20:29:29.162987017 +0000 UTC m=+75533.317814061","heartbeat_counter":75533}]}
{"channel":"l2_data","timestamp":"2026-07-16T20:29:29.29642281Z","sequence_num":743,"events":[{"type":"update","product_id":"BTC-USD","updates":[{"side":"bid","event_time":"2026-07-16T20:29:28.999524Z","price_level":"64103.75","new_quantity":"0"},{"side":"bid","event_time":"2026-07-16T20:29:28.999524Z","price_level":"64084.51","new_quantity":"0"},{"side":"bid","event_time":"2026-07-16T20:29:28.999524Z","price_level":"63727.09","new_quantity":"0.01061683"},{"side":"bid","event_time":"2026-07-16T20:29:28.999524Z","price_level":"56115.2","new_quantity":"0"},{"side":"offer","event_time":"2026-07-16T20:29:28.999524Z","price_level":"64174.35","new_quantity":"0"},{"side":"offer","event_time":"2026-07-16T20:29:28.999524Z","price_level":"64174.41","new_quantity":"0"}]}]}
{"channel":"l2_data","timestamp":"2026-07-16T20:29:29.297686158Z","sequence_num":744,"events":[{"type":"update","product_id":"BTC-USD","updates":[{"side":"bid","event_time":"2026-07-16T20:29:29.041659Z","price_level":"64126.85","new_quantity":"0.02"},{"side":"bid","event_time":"2026-07-16T20:29:29.041659Z","price_level":"64115.86","new_quantity":"0.05814968"},{"side":"bid","event_time":"2026-07-16T20:29:29.041659Z","price_level":"64085","new_quantity":"0.01"},{"side":"offer","event_time":"2026-07-16T20:29:29.041659Z","price_level":"64143.32","new_quantity":"0"},{"side":"offer","event_time":"2026-07-16T20:29:29.041659Z","price_level":"64144.28","new_quantity":"0"},{"side":"offer","event_time":"2026-07-16T20:29:29.041659Z","price_level":"64156.99","new_quantity":"0"}]}]}
{"channel":"l2_data","timestamp":"2026-07-16T20:29:29.298607455Z","sequence_num":745,"events":[{"type":"update","product_id":"BTC-USD","updates":[{"side":"bid","event_time":"2026-07-16T20:29:29.100731Z","price_level":"64125.22","new_quantity":"0.15594488"},{"side":"bid","event_time":"2026-07-16T20:29:29.100731Z","price_level":"64123.28","new_quantity":"0"},{"side":"bid","event_time":"2026-07-16T20:29:29.100731Z","price_level":"64120.22","new_quantity":"0.698525"},{"side":"offer","event_time":"2026-07-16T20:29:29.100731Z","price_level":"64132.17","new_quantity":"0.12474239"},{"side":"offer","event_time":"2026-07-16T20:29:29.100731Z","price_level":"64171.21","new_quantity":"0.00159827"},{"side":"offer","event_time":"2026-07-16T20:29:29.100731Z","price_level":"64181.03","new_quantity":"0"}]}]}
{"channel":"l2_data","timestamp":"2026-07-16T20:29:29.299238267Z","sequence_num":746,"events":[{"type":"update","product_id":"BTC-USD","updates":[{"side":"bid","event_time":"2026-07-16T20:29:29.154672Z","price_level":"64130.43","new_quantity":"0.00042465"},{"side":"bid","event_time":"2026-07-16T20:29:29.154672Z","price_level":"64120.22","new_quantity":"0"},{"side":"offer","event_time":"2026-07-16T20:29:29.154672Z","price_level":"64132.21","new_quantity":"0.00234579"},{"side":"offer","event_time":"2026-07-16T20:29:29.154672Z","price_level":"64132.28","new_quantity":"0"},{"side":"offer","event_time":"2026-07-16T20:29:29.154672Z","price_level":"64139.13","new_quantity":"0.59566397"},{"side":"offer","event_time":"2026-07-16T20:29:29.154672Z","price_level":"64141.24","new_quantity":"0"}]}]}
{"channel":"l2_data","timestamp":"2026-07-16T20:29:29.300089804Z","sequence_num":747,"events":[{"type":"update","product_id":"BTC-USD","updates":[{"side":"bid","event_time":"2026-07-16T20:29:29.192864Z","price_level":"64131.65","new_quantity":"0.0136689"},{"side":"bid","event_time":"2026-07-16T20:29:29.192864Z","price_level":"64110","new_quantity":"0.01"},{"side":"bid","event_time":"2026-07-16T20:29:29.192864Z","price_level":"56115.2","new_quantity":"0.01337205"},{"side":"offer","event_time":"2026-07-16T20:29:29.192864Z","price_level":"64156.99","new_quantity":"0.01005954"},{"side":"offer","event_time":"2026-07-16T20:29:29.192864Z","price_level":"65650.02","new_quantity":"0.00583"},{"side":"offer","event_time":"2026-07-16T20:29:29.192864Z","price_level":"65650.61","new_quantity":"0"},{"side":"offer","event_time":"2026-07-16T20:29:29.192864Z","price_level":"65650.84","new_quantity":"0"}]}]}
{"channel":"l2_data","timestamp":"2026-07-16T20:29:29.301488213Z","sequence_num":748,"events":[{"type":"update","product_id":"BTC-USD","updates":[{"side":"bid","event_time":"2026-07-16T20:29:29.257086Z","price_level":"64108","new_quantity":"1"},{"side":"bid","event_time":"2026-07-16T20:29:29.257086Z","price_level":"64103.3","new_quantity":"0.64751707"},{"side":"bid","event_time":"2026-07-16T20:29:29.257086Z","price_level":"64103.29","new_quantity":"0.27706596"},{"side":"bid","event_time":"2026-07-16T20:29:29.257086Z","price_level":"64102.77","new_quantity":"0"},{"side":"bid","event_time":"2026-07-16T20:29:29.257086Z","price_level":"64084.06","new_quantity":"0.5453417"},{"side":"offer","event_time":"2026-07-16T20:29:29.257086Z","price_level":"64172.92","new_quantity":"0.48068195"},{"side":"offer","event_time":"2026-07-16T20:29:29.257086Z","price_level":"64172.93","new_quantity":"0.55235753"},{"side":"offer","event_time":"2026-07-16T20:29:29.257086Z","price_level":"64173.62","new_quantity":"0"}]}]}
{"channel":"l2_data","timestamp":"2026-07-16T20:29:29.329352838Z","sequence_num":749,"events":[{"type":"update","product_id":"BTC-USD","updates":[{"side":"bid","event_time":"2026-07-16T20:29:29.30627Z","price_level":"56115.2","new_quantity":"0"},{"side":"offer","event_time":"2026-07-16T20:29:29.30627Z","price_level":"64156.99","new_quantity":"0"}]}]}
{"channel":"l2_data","timestamp":"2026-07-16T20:29:29.376736321Z","sequence_num":750,"events":[{"type":"update","product_id":"BTC-USD","updates":[{"side":"bid","event_time":"2026-07-16T20:29:29.353271Z","price_level":"64120.33","new_quantity":"0.618146"},{"side":"bid","event_time":"2026-07-16T20:29:29.353271Z","price_level":"64108","new_quantity":"0"}]}]}
{"channel":"l2_data","timestamp":"2026-07-16T20:29:29.430346803Z","sequence_num":751,"events":[{"type":"update","product_id":"BTC-USD","updates":[{"side":"bid","event_time":"2026-07-16T20:29:29.374412Z","price_level":"64120.33","new_quantity":"0"},{"side":"bid","event_time":"2026-07-16T20:29:29.374412Z","price_level":"64110","new_quantity":"1.01"},{"side":"offer","event_time":"2026-07-16T20:29:29.374412Z","price_level":"64132.14","new_quantity":"0.00234579"},{"side":"offer","event_time":"2026-07-16T20:29:29.374412Z","price_level":"64132.21","new_quantity":"0"},{"side":"offer","event_time":"2026-07-16T20:29:29.374412Z","price_level":"64155.16","new_quantity":"0.37287373"},{"side":"offer","event_time":"2026-07-16T20:29:29.374412Z","price_level":"64177.53","new_quantity":"1.02118095"}]}]}
{"channel":"l2_data","timestamp":"2026-07-16T20:29:29.481918952Z","sequence_num":752,"events":[{"type":"update","product_id":"BTC-USD","updates":[{"side":"bid","event_time":"2026-07-16T20:29:29.460132Z","price_level":"64131.65","new_quantity":"0.01163582"},{"side":"bid","event_time":"2026-07-16T20:29:29.460132Z","price_level":"64109.9","new_quantity":"0"},{"side":"offer","event_time":"2026-07-16T20:29:29.460132Z","price_level":"64131.66","new_quantity":"0.09108011"},{"side":"offer","event_time":"2026-07-16T20:29:29.460132Z","price_level":"64143.01","new_quantity":"0.00009744"},{"side":"offer","event_time":"2026-07-16T20:29:29.460132Z","price_level":"64143.97","new_quantity":"0.00779497"},{"side":"offer","event_time":"2026-07-16T20:29:29.460132Z","price_level":"64151.21","new_quantity":"0.0136689"},{"side":"offer","event_time":"2026-07-16T20:29:29.460132Z","price_level":"64155.16","new_quantity":"0"},{"side":"offer","event_time":"2026-07-16T20:29:29.460132Z","price_level":"64155.17","new_quantity":"0"}]}]}
{"channel":"l2_data","timestamp":"2026-07-16T20:29:29.525040811Z","sequence_num":753,"events":[{"type":"update","product_id":"BTC-USD","updates":[{"side":"bid","event_time":"2026-07-16T20:29:29.504779Z","price_level":"64131.65","new_quantity":"0.01163577"},{"side":"bid","event_time":"2026-07-16T20:29:29.504779Z","price_level":"64126.76","new_quantity":"0.02"},{"side":"bid","event_time":"2026-07-16T20:29:29.504779Z","price_level":"56115.2","new_quantity":"0.01337205"}]}]}
{"channel":"l2_data","timestamp":"2026-07-16T20:29:29.580843066Z","sequence_num":754,"events":[{"type":"update","product_id":"BTC-USD","updates":[{"side":"bid","event_time":"2026-07-16T20:29:29.536071Z","price_level":"64131.65","new_quantity":"0.01163556"},{"side":"offer","event_time":"2026-07-16T20:29:29.536071Z","price_level":"64139.13","new_quantity":"0.87334679"},{"side":"offer","event_time":"2026-07-16T20:29:29.536071Z","price_level":"64141.24","new_quantity":"0.655018"}]}]}
{"channel":"l2_data","timestamp":"2026-07-16T20:29:29.629815289Z","sequence_num":755,"events":[{"type":"update","product_id":"BTC-USD","updates":[{"side":"bid","event_time":"2026-07-16T20:29:29.608166Z","price_level":"64131.65","new_quantity":"0.02433062"},{"side":"bid","event_time":"2026-07-16T20:29:29.608166Z","price_level":"64120.31","new_quantity":"0.674253"},{"side":"bid","event_time":"2026-07-16T20:29:29.608166Z","price_level":"56115.2","new_quantity":"0"},{"side":"offer","event_time":"2026-07-16T20:29:29.608166Z","price_level":"64151.21","new_quantity":"0"}]}]}
{"channel":"l2_data","timestamp":"2026-07-16T20:29:29.679363282Z","sequence_num":756,"events":[{"type":"update","product_id":"BTC-USD","updates":[{"side":"bid","event_time":"2026-07-16T20:29:29.652815Z","price_level":"64120.31","new_quantity":"0"},{"side":"offer","event_time":"2026-07-16T20:29:29.652815Z","price_level":"64132.16","new_quantity":"0.02"}]}]}
{"channel":"l2_data","timestamp":"2026-07-16T20:29:29.730023001Z","sequence_num":757,"events":[{"type":"update","product_id":"BTC-USD","updates":[{"side":"bid","event_time":"2026-07-16T20:29:29.689596Z","price_level":"64128.59","new_quantity":"0"},{"side":"bid","event_time":"2026-07-16T20:29:29.689596Z","price_level":"64125.24","new_quantity":"0.00779724"},{"side":"offer","event_time":"2026-07-16T20:29:29.689596Z","price_level":"64132.14","new_quantity":"0"},{"side":"offer","event_time":"2026-07-16T20:29:29.689596Z","price_level":"64145.49","new_quantity":"0.008964"},{"side":"offer","event_time":"2026-07-16T20:29:29.689596Z","price_level":"64145.81","new_quantity":"0.00779474"}]}]}
{"channel":"l2_data","timestamp":"2026-07-16T20:29:29.782646978Z","sequence_num":758,"events":[{"type":"update","product_id":"BTC-USD","updates":[{"side":"bid","event_time":"2026-07-16T20:29:29.754863Z","price_level":"64115.59","new_quantity":"0.02433062"},{"side":"bid","event_time":"2026-07-16T20:29:29.754863Z","price_level":"64100.75","new_quantity":"0"},{"side":"bid","event_time":"2026-07-16T20:29:29.754863Z","price_level":"64100.01","new_quantity":"0.00077958"},{"side":"offer","event_time":"2026-07-16T20:29:29.754863Z","price_level":"64132.07","new_quantity":"0.00234579"},{"side":"offer","event_time":"2026-07-16T20:29:29.754863Z","price_level":"64153.69","new_quantity":"0.27203908"}]}]}
{"channel":"l2_data","timestamp":"2026-07-16T20:29:29.843498966Z","sequence_num":759,"events":[{"type":"update","product_id":"BTC-USD","updates":[{"side":"bid","event_time":"2026-07-16T20:29:29.795107Z","price_level":"56115.2","new_quantity":"0.01248058"},{"side":"offer","event_time":"2026-07-16T20:29:29.795107Z","price_level":"64151.3","new_quantity":"0.02433062"}]}]}
{"channel":"l2_data","timestamp":"2026-07-16T20:29:29.892314914Z","sequence_num":760,"events":[{"type":"update","product_id":"BTC-USD","updates":[{"side":"bid","event_time":"2026-07-16T20:29:29.86231Z","price_level":"56115.2","new_quantity":"0.01337205"},{"side":"offer","event_time":"2026-07-16T20:29:29.86231Z","price_level":"64132.06","new_quantity":"0.02"},{"side":"offer","event_time":"2026-07-16T20:29:29.86231Z","price_level":"64144.17","new_quantity":"0.00009744"},{"side":"offer","event_time":"2026-07-16T20:29:29.86231Z","price_level":"64144.52","new_quantity":"0"},{"side":"offer","event_time":"2026-07-16T20:29:29.86231Z","price_level":"64145.46","new_quantity":"0.00779478"},{"side":"offer","event_time":"2026-07-16T20:29:29.86231Z","price_level":"64145.81","new_quantity":"0"}]}]}
{"channel":"l2_data","timestamp":"2026-07-16T20:29:29.95362667Z","sequence_num":761,"events":[{"type":"update","product_id":"BTC-USD","updates":[{"side":"bid","event_time":"2026-07-16T20:29:29.913638Z","price_level":"64126.85","new_quantity":"0"},{"side":"bid","event_time":"2026-07-16T20:29:29.913638Z","price_level":"64126.84","new_quantity":"0"},{"side":"bid","event_time":"2026-07-16T20:29:29.913638Z","price_level":"64125.25","new_quantity":"0.02"},{"side":"bid","event_time":"2026-07-16T20:29:29.913638Z","price_level":"64107.96","new_quantity":"0"},{"side":"bid","event_time":"2026-07-16T20:29:29.913638Z","price_level":"56115.2","new_quantity":"0"},{"side":"offer","event_time":"2026-07-16T20:29:29.913638Z","price_level":"64132.94","new_quantity":"0.02"},{"side":"offer","event_time":"2026-07-16T20:29:29.913638Z","price_level":"64144.2","new_quantity":"0"}]}]}
{"channel":"l2_data","timestamp":"2026-07-16T20:29:30.00384652Z","sequence_num":762,"events":[{"type":"update","product_id":"BTC-USD","updates":[{"side":"bid","event_time":"2026-07-16T20:29:29.972182Z","price_level":"64126.84","new_quantity":"0.00779705"},{"side":"offer","event_time":"2026-07-16T20:29:29.972182Z","price_level":"64143.85","new_quantity":"0.00896423"},{"side":"offer","event_time":"2026-07-16T20:29:29.972182Z","price_level":"64151.3","new_quantity":"0"}]}]}
{"channel":"l2_data","timestamp":"2026-07-16T20:29:30.09751338Z","sequence_num":763,"events":[{"type":"update","product_id":"BTC-USD","updates":[{"side":"bid","event_time":"2026-07-16T20:29:30.052316Z","price_level":"64072.13","new_quantity":"0"},{"side":"bid","event_time":"2026-07-16T20:29:30.052316Z","price_level":"64072.12","new_quantity":"0.0046051"},{"side":"offer","event_time":"2026-07-16T20:29:30.052316Z","price_level":"64143.01","new_quantity":"0"},{"side":"offer","event_time":"2026-07-16T20:29:30.052316Z","price_level":"64143.97","new_quantity":"0"}]}]}
{"channel":"l2_data","timestamp":"2026-07-16T20:29:30.144273205Z","sequence_num":764,"events":[{"type":"update","product_id":"BTC-USD","updates":[{"side":"bid","event_time":"2026-07-16T20:29:30.101032Z","price_level":"64120.24","new_quantity":"0.644423"},{"side":"bid","event_time":"2026-07-16T20:29:30.101032Z","price_level":"64103.29","new_quantity":"0"},{"side":"bid","event_time":"2026-07-16T20:29:30.101032Z","price_level":"64084.06","new_quantity":"0"},{"side":"bid","event_time":"2026-07-16T20:29:30.101032Z","price_level":"56115.2","new_quantity":"0.01337205"},{"side":"offer","event_time":"2026-07-16T20:29:30.101032Z","price_level":"64153.69","new_quantity":"0"},{"side":"offer","event_time":"2026-07-16T20:29:30.101032Z","price_level":"64172.93","new_quantity":"0"}]}]}
{"channel":"heartbeats","timestamp":"2026-07-16T20:29:30.171685384Z","sequence_num":765,"events":[{"current_time":"2026-07-16 20:29:30.162919788 +0000 UTC m=+75534.317746823","heartbeat_counter":75534}]}
{"channel":"l2_data","timestamp":"2026-07-16T20:29:30.178358559Z","sequence_num":766,"events":[{"type":"update","product_id":"BTC-USD","updates":[{"side":"bid","event_time":"2026-07-16T20:29:30.119817Z","price_level":"64120.24","new_quantity":"0"}]}]}
{"channel":"l2_data","timestamp":"2026-07-16T20:29:30.239397751Z","sequence_num":767,"events":[{"type":"update","product_id":"BTC-USD","updates":[{"side":"bid","event_time":"2026-07-16T20:29:30.190472Z","price_level":"64131.65","new_quantity":"0.02696897"},{"side":"bid","event_time":"2026-07-16T20:29:30.190472Z","price_level":"64104.83","new_quantity":"0.64366589"},{"side":"bid","event_time":"2026-07-16T20:29:30.190472Z","price_level":"64103.3","new_quantity":"0"},{"side":"bid","event_time":"2026-07-16T20:29:30.190472Z","price_level":"64091.06","new_quantity":"0.92173329"},{"side":"bid","event_time":"2026-07-16T20:29:30.190472Z","price_level":"64089.09","new_quantity":"0"},{"side":"bid","event_time":"2026-07-16T20:29:30.190472Z","price_level":"56115.2","new_quantity":"0"},{"side":"offer","event_time":"2026-07-16T20:29:30.190472Z","price_level":"64151.3","new_quantity":"0.02433062"},{"side":"offer","event_time":"2026-07-16T20:29:30.190472Z","price_level":"64169.59","new_quantity":"0"}]}]}
{"channel":"l2_data","timestamp":"2026-07-16T20:29:30.282710275Z","sequence_num":768,"events":[{"type":"update","product_id":"BTC-USD","updates":[{"side":"offer","event_time":"2026-07-16T20:29:30.257892Z","price_level":"64131.66","new_quantity":"0.08886178"},{"side":"offer","event_time":"2026-07-16T20:29:30.257892Z","price_level":"64131.98","new_quantity":"0.00234579"},{"side":"offer","event_time":"2026-07-16T20:29:30.257892Z","price_level":"64132.07","new_quantity":"0"},{"side":"offer","event_time":"2026-07-16T20:29:30.257892Z","price_level":"64149.31","new_quantity":"0.6366932"},{"side":"offer","event_time":"2026-07-16T20:29:30.257892Z","price_level":"64150","new_quantity":"0.01"},{"side":"offer","event_time":"2026-07-16T20:29:30.257892Z","price_level":"64151","new_quantity":"1"}]}]}
{"channel":"l2_data","timestamp":"2026-07-16T20:29:30.340986189Z","sequence_num":769,"events":[{"type":"update","product_id":"BTC-USD","updates":[{"side":"bid","event_time":"2026-07-16T20:29:30.304246Z","price_level":"64131.65","new_quantity":"0.02682225"},{"side":"offer","event_time":"2026-07-16T20:29:30.304246Z","price_level":"64131.97","new_quantity":"0.02"},{"side":"offer","event_time":"2026-07-16T20:29:30.304246Z","price_level":"64132.06","new_quantity":"0"}]}]}
{"channel":"l2_data","timestamp":"2026-07-16T20:29:30.380796697Z","sequence_num":770,"events":[{"type":"update","product_id":"BTC-USD","updates":[{"side":"bid","event_time":"2026-07-16T20:29:30.340241Z","price_level":"64131.65","new_quantity":"0.01170923"},{"side":"bid","event_time":"2026-07-16T20:29:30.340241Z","price_level":"64128.14","new_quantity":"0.12475021"},{"side":"bid","event_time":"2026-07-16T20:29:30.340241Z","price_level":"64127.57","new_quantity":"0"},{"side":"bid","event_time":"2026-07-16T20:29:30.340241Z","price_level":"64104.83","new_quantity":"0"},{"side":"bid","event_time":"2026-07-16T20:29:30.340241Z","price_level":"64103.29","new_quantity":"0.28033918"},{"side":"bid","event_time":"2026-07-16T20:29:30.340241Z","price_level":"64102.77","new_quantity":"0.64368658"},{"side":"bid","event_time":"2026-07-16T20:29:30.340241Z","price_level":"64091.06","new_quantity":"0"},{"side":"bid","event_time":"2026-07-16T20:29:30.340241Z","price_level":"64089.09","new_quantity":"0.92176162"},{"side":"bid","event_time":"2026-07-16T20:29:30.340241Z","price_level":"64084.06","new_quantity":"0.56953489"},{"side":"bid","event_time":"2026-07-16T20:29:30.340241Z","price_level":"64047.75","new_quantity":"0.01061683"},{"side":"offer","event_time":"2026-07-16T20:29:30.340241Z","price_level":"64132.17","new_quantity":"0"},{"side":"offer","event_time":"2026-07-16T20:29:30.340241Z","price_level":"64132.75","new_quantity":"0.12474126"},{"side":"offer","event_time":"2026-07-16T20:29:30.340241Z","price_level":"64151.3","new_quantity":"0"},{"side":"offer","event_time":"2026-07-16T20:29:30.340241Z","price_level":"64153.69","new_quantity":"0.27005947"},{"side":"offer","event_time":"2026-07-16T20:29:30.340241Z","price_level":"64172.26","new_quantity":"0.48146652"},{"side":"offer","event_time":"2026-07-16T20:29:30.340241Z","price_level":"64172.92","new_quantity":"0"},{"side":"offer","event_time":"2026-07-16T20:29:30.340241Z","price_level":"64172.93","new_quantity":"0.52877324"}]}]}
{"channel":"l2_data","timestamp":"2026-07-16T20:29:30.43109795Z","sequence_num":771,"events":[{"type":"update","product_id":"BTC-USD","updates":[{"side":"bid","event_time":"2026-07-16T20:29:30.400047Z","price_level":"64128.15","new_quantity":"0.02"},{"side":"bid","event_time":"2026-07-16T20:29:30.400047Z","price_level":"64047.75","new_quantity":"0"},{"side":"bid","event_time":"2026-07-16T20:29:30.400047Z","price_level":"56115.2","new_quantity":"0.01337205"},{"side":"offer","event_time":"2026-07-16T20:29:30.400047Z","price_level":"64149.31","new_quantity":"0.99557463"},{"side":"offer","event_time":"2026-07-16T20:29:30.400047Z","price_level":"64172.25","new_quantity":"0.70844883"},{"side":"offer","event_time":"2026-07-16T20:29:30.400047Z","price_level":"64192.99","new_quantity":"0.57836211"}]}]}
{"channel":"l2_data","timestamp":"2026-07-16T20:29:30.484766507Z","sequence_num":772,"events":[{"type":"update","product_id":"BTC-USD","updates":[{"side":"bid","event_time":"2026-07-16T20:29:30.443784Z","price_level":"64103.3","new_quantity":"0.64368125"},{"side":"bid","event_time":"2026-07-16T20:29:30.443784Z","price_level":"64102.77","new_quantity":"0"},{"side":"bid","event_time":"2026-07-16T20:29:30.443784Z","price_level":"63727.09","new_quantity":"0"},{"side":"offer","event_time":"2026-07-16T20:29:30.443784Z","price_level":"64132.16","new_quantity":"0"},{"side":"offer","event_time":"2026-07-16T20:29:30.443784Z","price_level":"64132.74","new_quantity":"0"},{"side":"offer","event_time":"2026-07-16T20:29:30.443784Z","price_level":"64168.98","new_quantity":"0.30070529"}]}]}
{"channel":"l2_data","timestamp":"2026-07-16T20:29:30.530191388Z","sequence_num":773,"events":[{"type":"update","product_id":"BTC-USD","updates":[{"side":"bid","event_time":"2026-07-16T20:29:30.495819Z","price_level":"56115.2","new_quantity":"0"},{"side":"offer","event_time":"2026-07-16T20:29:30.495819Z","price_level":"64142.67","new_quantity":"0.00009744"},{"side":"offer","event_time":"2026-07-16T20:29:30.495819Z","price_level":"64143.63","new_quantity":"0.00779501"},{"side":"offer","event_time":"2026-07-16T20:29:30.495819Z","price_level":"64151.2","new_quantity":"0.01170923"},{"side":"offer","event_time":"2026-07-16T20:29:30.495819Z","price_level":"64172.25","new_quantity":"0.70922844"},{"side":"offer","event_time":"2026-07-16T20:29:30.495819Z","price_level":"64172.26","new_quantity":"0.4806869"}]}]}
{"channel":"l2_data","timestamp":"2026-07-16T20:29:30.580644903Z","sequence_num":774,"events":[{"type":"update","product_id":"BTC-USD","updates":[{"side":"bid","event_time":"2026-07-16T20:29:30.523246Z","price_level":"64127.58","new_quantity":"0"},{"side":"bid","event_time":"2026-07-16T20:29:30.523246Z","price_level":"63727.09","new_quantity":"0.01061683"},{"side":"offer","event_time":"2026-07-16T20:29:30.523246Z","price_level":"64132.74","new_quantity":"0.02"}]}]}
{"channel":"l2_data","timestamp":"2026-07-16T20:29:30.629724007Z","sequence_num":775,"events":[{"type":"update","product_id":"BTC-USD","updates":[{"side":"bid","event_time":"2026-07-16T20:29:30.60135Z","price_level":"64131.65","new_quantity":"0.01170913"},{"side":"bid","event_time":"2026-07-16T20:29:30.60135Z","price_level":"64120.3","new_quantity":"0.711006"},{"side":"offer","event_time":"2026-07-16T20:29:30.60135Z","price_level":"64131.91","new_quantity":"0.00234579"},{"side":"offer","event_time":"2026-07-16T20:29:30.60135Z","price_level":"64131.97","new_quantity":"0"},{"side":"offer","event_time":"2026-07-16T20:29:30.60135Z","price_level":"64131.98","new_quantity":"0"}]}]}
{"channel":"l2_data","timestamp":"2026-07-16T20:29:30.679115649Z","sequence_num":776,"events":[{"type":"update","product_id":"BTC-USD","updates":[{"side":"bid","event_time":"2026-07-16T20:29:30.641048Z","price_level":"64120.3","new_quantity":"0"},{"side":"offer","event_time":"2026-07-16T20:29:30.641048Z","price_level":"64131.9","new_quantity":"0.02"}]}]}
{"channel":"l2_data","timestamp":"2026-07-16T20:29:30.730932561Z","sequence_num":777,"events":[{"type":"update","product_id":"BTC-USD","updates":[{"side":"bid","event_time":"2026-07-16T20:29:30.691747Z","price_level":"56115.2","new_quantity":"0.01337205"},{"side":"offer","event_time":"2026-07-16T20:29:30.691747Z","price_level":"64151.2","new_quantity":"0"}]}]}
{"channel":"l2_data","timestamp":"2026-07-16T20:29:30.781126647Z","sequence_num":778,"events":[{"type":"update","product_id":"BTC-USD","updates":[{"side":"bid","event_time":"2026-07-16T20:29:30.75588Z","price_level":"64125.25","new_quantity":"0"},{"side":"bid","event_time":"2026-07-16T20:29:30.75588Z","price_level":"64125.24","new_quantity":"0.00779724"},{"side":"offer","event_time":"2026-07-16T20:29:30.75588Z","price_level":"64131.66","new_quantity":"0.08701468"},{"side":"offer","event_time":"2026-07-16T20:29:30.75588Z","price_level":"64145.15","new_quantity":"0.00896404"},{"side":"offer","event_time":"2026-07-16T20:29:30.75588Z","price_level":"64145.49","new_quantity":"0"}]}]}
{"channel":"l2_data","timestamp":"2026-07-16T20:29:30.829715883Z","sequence_num":779,"events":[{"type":"update","product_id":"BTC-USD","updates":[{"side":"bid","event_time":"2026-07-16T20:29:30.807182Z","price_level":"56115.2","new_quantity":"0"},{"side":"offer","event_time":"2026-07-16T20:29:30.807182Z","price_level":"64151.21","new_quantity":"0.01170913"}]}]}
{"channel":"l2_data","timestamp":"2026-07-16T20:29:30.930524731Z","sequence_num":780,"events":[{"type":"update","product_id":"BTC-USD","updates":[{"side":"bid","event_time":"2026-07-16T20:29:30.895289Z","price_level":"64128.15","new_quantity":"0"},{"side":"bid","event_time":"2026-07-16T20:29:30.895289Z","price_level":"64128.14","new_quantity":"0"},{"side":"bid","event_time":"2026-07-16T20:29:30.895289Z","price_level":"64126.9","new_quantity":"0.02"},{"side":"bid","event_time":"2026-07-16T20:29:30.895289Z","price_level":"64126.89","new_quantity":"0.12475265"},{"side":"bid","event_time":"2026-07-16T20:29:30.895289Z","price_level":"64120.26","new_quantity":"0.713469"},{"side":"offer","event_time":"2026-07-16T20:29:30.895289Z","price_level":"64131.81","new_quantity":"0.00234579"},{"side":"offer","event_time":"2026-07-16T20:29:30.895289Z","price_level":"64131.91","new_quantity":"0"},{"side":"offer","event_time":"2026-07-16T20:29:30.895289Z","price_level":"64144.17","new_quantity":"0"},{"side":"offer","event_time":"2026-07-16T20:29:30.895289Z","price_level":"64145.46","new_quantity":"0"},{"side":"offer","event_time":"2026-07-16T20:29:30.895289Z","price_level":"64172.24","new_quantity":"0.48068705"},{"side":"offer","event_time":"2026-07-16T20:29:30.895289Z","price_level":"64172.25","new_quantity":"0.00077961"},{"side":"offer","event_time":"2026-07-16T20:29:30.895289Z","price_level":"64172.26","new_quantity":"0"},{"side":"offer","event_time":"2026-07-16T20:29:30.895289Z","price_level":"64187.99","new_quantity":"0.67585349"},{"side":"offer","event_time":"2026-07-16T20:29:30.895289Z","price_level":"64188.28","new_quantity":"2.13052448"},{"side":"offer","event_time":"2026-07-16T20:29:30.895289Z","price_level":"64188.29","new_quantity":"0"},{"side":"offer","event_time":"2026-07-16T20:29:30.895289Z","price_level":"64190.33","new_quantity":"0"}]}]}
{"channel":"heartbeats","timestamp":"2026-07-16T20:29:31.16407131Z","sequence_num":781,"events":[{"current_time":"2026-07-16 20:29:31.162919428 +0000 UTC m=+75535.317746472","heartbeat_counter":75535}]}
{"channel":"l2_data","timestamp":"2026-07-16T20:29:31.223939932Z","sequence_num":782,"events":[{"type":"update","product_id":"BTC-USD","updates":[{"side":"bid","event_time":"2026-07-16T20:29:30.958585Z","price_level":"64131.65","new_quantity":"0.01170824"},{"side":"bid","event_time":"2026-07-16T20:29:30.958585Z","price_level":"64120.26","new_quantity":"0"},{"side":"offer","event_time":"2026-07-16T20:29:30.958585Z","price_level":"64131.8","new_quantity":"0"},{"side":"offer","event_time":"2026-07-16T20:29:30.958585Z","price_level":"64131.9","new_quantity":"0"},{"side":"offer","event_time":"2026-07-16T20:29:30.958585Z","price_level":"64143.84","new_quantity":"0.00009744"},{"side":"offer","event_time":"2026-07-16T20:29:30.958585Z","price_level":"64145.12","new_quantity":"0.00779482"},{"side":"offer","event_time":"2026-07-16T20:29:30.958585Z","price_level":"64151.21","new_quantity":"0"}]}]}
{"channel":"l2_data","timestamp":"2026-07-16T20:29:31.224733826Z","sequence_num":783,"events":[{"type":"update","product_id":"BTC-USD","updates":[{"side":"bid","event_time":"2026-07-16T20:29:30.99771Z","price_level":"64126.84","new_quantity":"0.00779705"},{"side":"bid","event_time":"2026-07-16T20:29:30.99771Z","price_level":"56115.2","new_quantity":"0.01337205"},{"side":"offer","event_time":"2026-07-16T20:29:30.99771Z","price_level":"64143.52","new_quantity":"0.00896427"},{"side":"offer","event_time":"2026-07-16T20:29:30.99771Z","price_level":"64143.85","new_quantity":"0"}]}]}
{"channel":"l2_data","timestamp":"2026-07-16T20:29:31.225246395Z","sequence_num":784,"events":[{"type":"update","product_id":"BTC-USD","updates":[{"side":"bid","event_time":"2026-07-16T20:29:31.039771Z","price_level":"64124.91","new_quantity":"0.04676038"},{"side":"offer","event_time":"2026-07-16T20:29:31.039771Z","price_level":"64131.8","new_quantity":"0.02"},{"side":"offer","event_time":"2026-07-16T20:29:31.039771Z","price_level":"64142.67","new_quantity":"0"},{"side":"offer","event_time":"2026-07-16T20:29:31.039771Z","price_level":"64143.63","new_quantity":"0"},{"side":"offer","event_time":"2026-07-16T20:29:31.039771Z","price_level":"64190.32","new_quantity":"0"},{"side":"offer","event_time":"2026-07-16T20:29:31.039771Z","price_level":"64190.33","new_quantity":"0.00077958"}]}]}
{"channel":"l2_data","timestamp":"2026-07-16T20:29:31.225374906Z","sequence_num":785,"events":[{"type":"update","product_id":"BTC-USD","updates":[{"side":"bid","event_time":"2026-07-16T20:29:31.102849Z","price_level":"64120.24","new_quantity":"0.700702"},{"side":"bid","event_time":"2026-07-16T20:29:31.102849Z","price_level":"56115.2","new_quantity":"0"}]}]}
{"channel":"l2_data","timestamp":"2026-07-16T20:29:31.225876273Z","sequence_num":786,"events":[{"type":"update","product_id":"BTC-USD","updates":[{"side":"bid","event_time":"2026-07-16T20:29:31.142989Z","price_level":"64120.24","new_quantity":"0"},{"side":"offer","event_time":"2026-07-16T20:29:31.142989Z","price_level":"64151.21","new_quantity":"0.01170824"}]}]}
{"channel":"l2_data","timestamp":"2026-07-16T20:29:31.226186833Z","sequence_num":787,"events":[{"type":"update","product_id":"BTC-USD","updates":[{"side":"bid","event_time":"2026-07-16T20:29:31.179771Z","price_level":"64131.65","new_quantity":"0.01440546"}]}]}
{"channel":"l2_data","timestamp":"2026-07-16T20:29:31.276185682Z","sequence_num":788,"events":[{"type":"update","product_id":"BTC-USD","updates":[{"side":"offer","event_time":"2026-07-16T20:29:31.261352Z","price_level":"64151.21","new_quantity":"0"}]}]}
{"channel":"l2_data","timestamp":"2026-07-16T20:29:31.324762148Z","sequence_num":789,"events":[{"type":"update","product_id":"BTC-USD","updates":[{"side":"bid","event_time":"2026-07-16T20:29:31.295131Z","price_level":"56115.2","new_quantity":"0.01337205"}]}]}
{"channel":"l2_data","timestamp":"2026-07-16T20:29:31.625359973Z","sequence_num":790,"events":[{"type":"update","product_id":"BTC-USD","updates":[{"side":"bid","event_time":"2026-07-16T20:29:31.344407Z","price_level":"64131.65","new_quantity":"0.01170824"},{"side":"offer","event_time":"2026-07-16T20:29:31.344407Z","price_level":"64131.66","new_quantity":"0.08315563"},{"side":"offer","event_time":"2026-07-16T20:29:31.344407Z","price_level":"64131.73","new_quantity":"0.00234579"},{"side":"offer","event_time":"2026-07-16T20:29:31.344407Z","price_level":"64131.81","new_quantity":"0"},{"side":"offer","event_time":"2026-07-16T20:29:31.344407Z","price_level":"65649.93","new_quantity":"0.00583"},{"side":"offer","event_time":"2026-07-16T20:29:31.344407Z","price_level":"65650.02","new_quantity":"0"}]}]}
{"channel":"l2_data","timestamp":"2026-07-16T20:29:31.626158055Z","sequence_num":791,"events":[{"type":"update","product_id":"BTC-USD","updates":[{"side":"bid","event_time":"2026-07-16T20:29:31.40839Z","price_level":"64107.97","new_quantity":"0"},{"side":"bid","event_time":"2026-07-16T20:29:31.40839Z","price_level":"56115.2","new_quantity":"0"},{"side":"offer","event_time":"2026-07-16T20:29:31.40839Z","price_level":"64151.23","new_quantity":"0.01440546"},{"side":"offer","event_time":"2026-07-16T20:29:31.40839Z","price_level":"64156.71","new_quantity":"0.17809965"},{"side":"offer","event_time":"2026-07-16T20:29:31.40839Z","price_level":"64174.64","new_quantity":"0.23391903"},{"side":"offer","event_time":"2026-07-16T20:29:31.40839Z","price_level":"64193.9","new_quantity":"0.21229546"}]}]}
{"channel":"l2_data","timestamp":"2026-07-16T20:29:31.627017671Z","sequence_num":792,"events":[{"type":"update","product_id":"BTC-USD","updates":[{"side":"bid","event_time":"2026-07-16T20:29:31.46057Z","price_level":"64110","new_quantity":"0.01"},{"side":"bid","event_time":"2026-07-16T20:29:31.46057Z","price_level":"64079.7","new_quantity":"0"},{"side":"bid","event_time":"2026-07-16T20:29:31.46057Z","price_level":"63952.6","new_quantity":"0"},{"side":"offer","event_time":"2026-07-16T20:29:31.46057Z","price_level":"64328.4","new_quantity":"0"}]}]}
{"channel":"l2_data","timestamp":"2026-07-16T20:29:31.627931358Z","sequence_num":793,"events":[{"type":"update","product_id":"BTC-USD","updates":[{"side":"bid","event_time":"2026-07-16T20:29:31.508611Z","price_level":"64109","new_quantity":"1"},{"side":"offer","event_time":"2026-07-16T20:29:31.508611Z","price_level":"64131.72","new_quantity":"0.02"},{"side":"offer","event_time":"2026-07-16T20:29:31.508611Z","price_level":"64131.8","new_quantity":"0"},{"side":"offer","event_time":"2026-07-16T20:29:31.508611Z","price_level":"64172.23","new_quantity":"0.00077961"},{"side":"offer","event_time":"2026-07-16T20:29:31.508611Z","price_level":"64172.25","new_quantity":"0"}]}]}
{"channel":"l2_data","timestamp":"2026-07-16T20:29:31.628345753Z","sequence_num":794,"events":[{"type":"update","product_id":"BTC-USD","updates":[{"side":"offer","event_time":"2026-07-16T20:29:31.566296Z","price_level":"64142.34","new_quantity":"0.00009744"},{"side":"offer","event_time":"2026-07-16T20:29:31.566296Z","price_level":"64143.31","new_quantity":"0.00779505"},{"side":"offer","event_time":"2026-07-16T20:29:31.566296Z","price_level":"64147.97","new_quantity":"0"},{"side":"offer","event_time":"2026-07-16T20:29:31.566296Z","price_level":"64151.23","new_quantity":"0"}]}]}
{"channel":"l2_data","timestamp":"2026-07-16T20:29:31.628694688Z","sequence_num":795,"events":[{"type":"update","product_id":"BTC-USD","updates":[{"side":"bid","event_time":"2026-07-16T20:29:31.612928Z","price_level":"64120.25","new_quantity":"0"},{"side":"bid","event_time":"2026-07-16T20:29:31.612928Z","price_level":"64109","new_quantity":"0"},{"side":"bid","event_time":"2026-07-16T20:29:31.612928Z","price_level":"56115.2","new_quantity":"0.01337205"}]}]}
{"channel":"l2_data","timestamp":"2026-07-16T20:29:31.67494741Z","sequence_num":796,"events":[{"type":"update","product_id":"BTC-USD","updates":[{"side":"bid","event_time":"2026-07-16T20:29:31.648438Z","price_level":"64131.65","new_quantity":"0.0117082"},{"side":"bid","event_time":"2026-07-16T20:29:31.648438Z","price_level":"64110","new_quantity":"1.01"}]}]}
{"channel":"l2_data","timestamp":"2026-07-16T20:29:31.72483983Z","sequence_num":797,"events":[{"type":"update","product_id":"BTC-USD","updates":[{"side":"bid","event_time":"2026-07-16T20:29:31.707759Z","price_level":"64131.65","new_quantity":"0.01170816"},{"side":"bid","event_time":"2026-07-16T20:29:31.707759Z","price_level":"56115.2","new_quantity":"0"}]}]}
{"channel":"l2_data","timestamp":"2026-07-16T20:29:31.829475071Z","sequence_num":798,"events":[{"type":"update","product_id":"BTC-USD","updates":[{"side":"offer","event_time":"2026-07-16T20:29:31.739038Z","price_level":"64148.13","new_quantity":"0.33"},{"side":"offer","event_time":"2026-07-16T20:29:31.739038Z","price_level":"64151.21","new_quantity":"0.01170824"}]}]}
{"channel":"l2_data","timestamp":"2026-07-16T20:29:31.831941235Z","sequence_num":799,"events":[{"type":"update","product_id":"BTC-USD","updates":[{"side":"bid","event_time":"2026-07-16T20:29:31.77249Z","price_level":"64125.24","new_quantity":"0"}]}]}
