{"channel":"l2_data","timestamp":"2026-07-15T03:40:06.324251098Z","sequence_num":58,"events":[{"type":"update","product_id":"BTC-USD","updates":[{"side":"bid","event_time":"2026-07-15T03:40:06.0333Z","price_level":"64561.91","new_quantity":"0"},{"side":"bid","event_time":"2026-07-15T03:40:06.0333Z","price_level":"64556.4","new_quantity":"0"},{"side":"bid","event_time":"2026-07-15T03:40:06.0333Z","price_level":"64556","new_quantity":"0"},{"side":"bid","event_time":"2026-07-15T03:40:06.0333Z","price_level":"64554","new_quantity":"0.0245"},{"side":"bid","event_time":"2026-07-15T03:40:06.0333Z","price_level":"64553.9","new_quantity":"0.0334"},{"side":"bid","event_time":"2026-07-15T03:40:06.0333Z","price_level":"64552.9","new_quantity":"0.12392935"},{"side":"bid","event_time":"2026-07-15T03:40:06.0333Z","price_level":"64549.5","new_quantity":"1"},{"side":"bid","event_time":"2026-07-15T03:40:06.0333Z","price_level":"64548.28","new_quantity":"0"},{"side":"bid","event_time":"2026-07-15T03:40:06.0333Z","price_level":"64548.07","new_quantity":"0.02"},{"side":"bid","event_time":"2026-07-15T03:40:06.0333Z","price_level":"64547.97","new_quantity":"0.04"},{"side":"bid","event_time":"2026-07-15T03:40:06.0333Z","price_level":"64545.95","new_quantity":"0.07389967"},{"side":"bid","event_time":"2026-07-15T03:40:06.0333Z","price_level":"64545.94","new_quantity":"0.12378505"},{"side":"bid","event_time":"2026-07-15T03:40:06.0333Z","price_level":"64544.66","new_quantity":"0"},{"side":"bid","event_time":"2026-07-15T03:40:06.0333Z","price_level":"64544.34","new_quantity":"0.12034371"},{"side":"bid","event_time":"2026-07-15T03:40:06.0333Z","price_level":"64543.36","new_quantity":"0.12378505"},{"side":"bid","event_time":"2026-07-15T03:40:06.0333Z","price_level":"64541.39","new_quantity":"0.15279372"},{"side":"bid","event_time":"2026-07-15T03:40:06.0333Z","price_level":"64539.89","new_quantity":"0.00772597"},{"side":"bid","event_time":"2026-07-15T03:40:06.0333Z","price_level":"64538.58","new_quantity":"0.1982924"},{"side":"bid","event_time":"2026-07-15T03:40:06.0333Z","price_level":"64538","new_quantity":"0.14"},{"side":"bid","event_time":"2026-07-15T03:40:06.0333Z","price_level":"64535.31","new_quantity":"0.14853316"},{"side":"bid","event_time":"2026-07-15T03:40:06.0333Z","price_level":"64533.07","new_quantity":"0.00119723"},{"side":"bid","event_time":"2026-07-15T03:40:06.0333Z","price_level":"64531.35","new_quantity":"0.12650098"},{"side":"bid","event_time":"2026-07-15T03:40:06.0333Z","price_level":"64530.43","new_quantity":"0"},{"side":"bid","event_time":"2026-07-15T03:40:06.0333Z","price_level":"64527.76","new_quantity":"0.00077442"},{"side":"bid","event_time":"2026-07-15T03:40:06.0333Z","price_level":"64526.26","new_quantity":"0"},{"side":"bid","event_time":"2026-07-15T03:40:06.0333Z","price_level":"64526.14","new_quantity":"0.58420846"},{"side":"bid","event_time":"2026-07-15T03:40:06.0333Z","price_level":"64524.84","new_quantity":"0.00239446"},{"side":"bid","event_time":"2026-07-15T03:40:06.0333Z","price_level":"64524.7","new_quantity":"0.07482699"},{"side":"bid","event_time":"2026-07-15T03:40:06.0333Z","price_level":"64522.09","new_quantity":"0.7253469"},{"side":"bid","event_time":"2026-07-15T03:40:06.0333Z","price_level":"64520.81","new_quantity":"0"},{"side":"bid","event_time":"2026-07-15T03:40:06.0333Z","price_level":"64520.32","new_quantity":"0"},{"side":"bid","event_time":"2026-07-15T03:40:06.0333Z","price_level":"64516.88","new_quantity":"0.00299307"},{"side":"bid","event_time":"2026-07-15T03:40:06.0333Z","price_level":"64516.49","new_quantity":"0.04626534"},{"side":"bid","event_time":"2026-07-15T03:40:06.0333Z","price_level":"64509.68","new_quantity":"0.01449449"},{"side":"bid","event_time":"2026-07-15T03:40:06.0333Z","price_level":"64506.15","new_quantity":"0.08670458"},{"side":"bid","event_time":"2026-07-15T03:40:06.0333Z","price_level":"64504.4","new_quantity":"0"},{"side":"bid","event_time":"2026-07-15T03:40:06.0333Z","price_level":"64498.91","new_quantity":"0.16023087"},{"side":"bid","event_time":"2026-07-15T03:40:06.0333Z","price_level":"64498.9","new_quantity":"0.26328496"},{"side":"bid","event_time":"2026-07-15T03:40:06.0333Z","price_level":"64490.99","new_quantity":"0.94453017"},{"side":"bid","event_time":"2026-07-15T03:40:06.0333Z","price_level":"64488.8","new_quantity":"0"},{"side":"bid","event_time":"2026-07-15T03:40:06.0333Z","price_level":"64486.28","new_quantity":"0.0406119"},{"side":"bid","event_time":"2026-07-15T03:40:06.0333Z","price_level":"64484.17","new_quantity":"0"},{"side":"bid","event_time":"2026-07-15T03:40:06.0333Z","price_level":"64480.02","new_quantity":"3.07801049"},{"side":"bid","event_time":"2026-07-15T03:40:06.0333Z","price_level":"64476.25","new_quantity":"0.86310138"},{"side":"bid","event_time":"2026-07-15T03:40:06.0333Z","price_level":"64470.02","new_quantity":"0.02291591"},{"side":"bid","event_time":"2026-07-15T03:40:06.0333Z","price_level":"64467.83","new_quantity":"0.00748267"},{"side":"bid","event_time":"2026-07-15T03:40:06.0333Z","price_level":"64462.96","new_quantity":"0.83351579"},{"side":"bid","event_time":"2026-07-15T03:40:06.0333Z","price_level":"64453.3","new_quantity":"0"},{"side":"bid","event_time":"2026-07-15T03:40:06.0333Z","price_level":"64452.41","new_quantity":"0.02068214"},{"side":"bid","event_time":"2026-07-15T03:40:06.0333Z","price_level":"64436.96","new_quantity":"0.00897921"},{"side":"bid","event_time":"2026-07-15T03:40:06.0333Z","price_level":"56491.68","new_quantity":"0"},{"side":"offer","event_time":"2026-07-15T03:40:06.0333Z","price_level":"64558.25","new_quantity":"0.23492812"},{"side":"offer","event_time":"2026-07-15T03:40:06.0333Z","price_level":"64558.84","new_quantity":"0.03093532"},{"side":"offer","event_time":"2026-07-15T03:40:06.0333Z","price_level":"64560","new_quantity":"0.0245"},{"side":"offer","event_time":"2026-07-15T03:40:06.0333Z","price_level":"64560.91","new_quantity":"0.0199398"},{"side":"offer","event_time":"2026-07-15T03:40:06.0333Z","price_level":"64561.11","new_quantity":"0.12378505"},{"side":"offer","event_time":"2026-07-15T03:40:06.0333Z","price_level":"64561.52","new_quantity":"0.09475722"},{"side":"offer","event_time":"2026-07-15T03:40:06.0333Z","price_level":"64561.91","new_quantity":"0.00774472"},{"side":"offer","event_time":"2026-07-15T03:40:06.0333Z","price_level":"64561.92","new_quantity":"0.15160624"},{"side":"offer","event_time":"2026-07-15T03:40:06.0333Z","price_level":"64563.34","new_quantity":"0"},{"side":"offer","event_time":"2026-07-15T03:40:06.0333Z","price_level":"64563.86","new_quantity":"0.12378505"},{"side":"offer","event_time":"2026-07-15T03:40:06.0333Z","price_level":"64565.59","new_quantity":"0"},{"side":"offer","event_time":"2026-07-15T03:40:06.0333Z","price_level":"64565.6","new_quantity":"0"},{"side":"offer","event_time":"2026-07-15T03:40:06.0333Z","price_level":"64567.22","new_quantity":"0"},{"side":"offer","event_time":"2026-07-15T03:40:06.0333Z","price_level":"64569.4","new_quantity":"0"},{"side":"offer","event_time":"2026-07-15T03:40:06.0333Z","price_level":"64574.59","new_quantity":"0"},{"side":"offer","event_time":"2026-07-15T03:40:06.0333Z","price_level":"64574.89","new_quantity":"0"},{"side":"offer","event_time":"2026-07-15T03:40:06.0333Z","price_level":"64575.12","new_quantity":"0.00100882"},{"side":"offer","event_time":"2026-07-15T03:40:06.0333Z","price_level":"64576.78","new_quantity":"0.00153313"},{"side":"offer","event_time":"2026-07-15T03:40:06.0333Z","price_level":"64581.95","new_quantity":"0.60916562"},{"side":"offer","event_time":"2026-07-15T03:40:06.0333Z","price_level":"64582","new_quantity":"0"},{"side":"offer","event_time":"2026-07-15T03:40:06.0333Z","price_level":"64582.5","new_quantity":"1"},{"side":"offer","event_time":"2026-07-15T03:40:06.0333Z","price_level":"64583.85","new_quantity":"0.2222488"},{"side":"offer","event_time":"2026-07-15T03:40:06.0333Z","price_level":"64585.63","new_quantity":"0.14"},{"side":"offer","event_time":"2026-07-15T03:40:06.0333Z","price_level":"64587.66","new_quantity":"0.76775677"},{"side":"offer","event_time":"2026-07-15T03:40:06.0333Z","price_level":"64589.12","new_quantity":"0.00306626"},{"side":"offer","event_time":"2026-07-15T03:40:06.0333Z","price_level":"64589.32","new_quantity":"0.63876344"},{"side":"offer","event_time":"2026-07-15T03:40:06.0333Z","price_level":"64591.33","new_quantity":"0.12184441"},{"side":"offer","event_time":"2026-07-15T03:40:06.0333Z","price_level":"64591.77","new_quantity":"0"},{"side":"offer","event_time":"2026-07-15T03:40:06.0333Z","price_level":"64593.54","new_quantity":"0.01846839"},{"side":"offer","event_time":"2026-07-15T03:40:06.0333Z","price_level":"64595.01","new_quantity":"0.03093532"},{"side":"offer","event_time":"2026-07-15T03:40:06.0333Z","price_level":"64604.66","new_quantity":"0.00383282"},{"side":"offer","event_time":"2026-07-15T03:40:06.0333Z","price_level":"64606.47","new_quantity":"0.20075217"},{"side":"offer","event_time":"2026-07-15T03:40:06.0333Z","price_level":"64608.64","new_quantity":"0.26328496"},{"side":"offer","event_time":"2026-07-15T03:40:06.0333Z","price_level":"64613.39","new_quantity":"0.45881197"},{"side":"offer","event_time":"2026-07-15T03:40:06.0333Z","price_level":"64613.4","new_quantity":"1.3216493"},{"side":"offer","event_time":"2026-07-15T03:40:06.0333Z","price_level":"64613.41","new_quantity":"1.43191296"},{"side":"offer","event_time":"2026-07-15T03:40:06.0333Z","price_level":"64613.42","new_quantity":"0"},{"side":"offer","event_time":"2026-07-15T03:40:06.0333Z","price_level":"64614.15","new_quantity":"0"},{"side":"offer","event_time":"2026-07-15T03:40:06.0333Z","price_level":"64615.49","new_quantity":"0"},{"side":"offer","event_time":"2026-07-15T03:40:06.0333Z","price_level":"64616.51","new_quantity":"0"},{"side":"offer","event_time":"2026-07-15T03:40:06.0333Z","price_level":"64616.52","new_quantity":"0.01940957"},{"side":"offer","event_time":"2026-07-15T03:40:06.0333Z","price_level":"64618.33","new_quantity":"0"},{"side":"offer","event_time":"2026-07-15T03:40:06.0333Z","price_level":"64622.64","new_quantity":"0"},{"side":"offer","event_time":"2026-07-15T03:40:06.0333Z","price_level":"64622.66","new_quantity":"0"},{"side":"offer","event_time":"2026-07-15T03:40:06.0333Z","price_level":"64626.6","new_quantity":"0.232057"},{"side":"offer","event_time":"2026-07-15T03:40:06.0333Z","price_level":"64629.4","new_quantity":"0"},{"side":"offer","event_time":"2026-07-15T03:40:06.0333Z","price_level":"64636.78","new_quantity":"0.00766564"},{"side":"offer","event_time":"2026-07-15T03:40:06.0333Z","price_level":"64651.83","new_quantity":"0"},{"side":"offer","event_time":"2026-07-15T03:40:06.0333Z","price_level":"64651.93","new_quantity":"0"},{"side":"offer","event_time":"2026-07-15T03:40:06.0333Z","price_level":"64665","new_quantity":"3"},{"side":"offer","event_time":"2026-07-15T03:40:06.0333Z","price_level":"64668.75","new_quantity":"0"},{"side":"offer","event_time":"2026-07-15T03:40:06.0333Z","price_level":"64683.26","new_quantity":"0"}]}]}
{"channel":"l2_data","timestamp":"2026-07-15T03:40:06.327142287Z","sequence_num":59,"events":[{"type":"update","product_id":"BTC-USD","updates":[{"side":"bid","event_time":"2026-07-15T03:40:06.090257Z","price_level":"64554.8","new_quantity":"0.0334"},{"side":"bid","event_time":"2026-07-15T03:40:06.090257Z","price_level":"64554.07","new_quantity":"0.1239271"},{"side":"bid","event_time":"2026-07-15T03:40:06.090257Z","price_level":"64553.9","new_quantity":"0"},{"side":"bid","event_time":"2026-07-15T03:40:06.090257Z","price_level":"64552.9","new_quantity":"0"},{"side":"bid","event_time":"2026-07-15T03:40:06.090257Z","price_level":"64551","new_quantity":"1"},{"side":"bid","event_time":"2026-07-15T03:40:06.090257Z","price_level":"64549.5","new_quantity":"0"},{"side":"bid","event_time":"2026-07-15T03:40:06.090257Z","price_level":"64549.08","new_quantity":"0.12378505"},{"side":"bid","event_time":"2026-07-15T03:40:06.090257Z","price_level":"64544.33","new_quantity":"0"},{"side":"bid","event_time":"2026-07-15T03:40:06.090257Z","price_level":"64543.37","new_quantity":"0.03093532"},{"side":"bid","event_time":"2026-07-15T03:40:06.090257Z","price_level":"64538.58","new_quantity":"0.11425009"},{"side":"bid","event_time":"2026-07-15T03:40:06.090257Z","price_level":"64538","new_quantity":"0"},{"side":"bid","event_time":"2026-07-15T03:40:06.090257Z","price_level":"64537.87","new_quantity":"0"},{"side":"bid","event_time":"2026-07-15T03:40:06.090257Z","price_level":"64535.34","new_quantity":"0.00077444"},{"side":"bid","event_time":"2026-07-15T03:40:06.090257Z","price_level":"64533.3","new_quantity":"0.00583"},{"side":"bid","event_time":"2026-07-15T03:40:06.090257Z","price_level":"64532.86","new_quantity":"0"},{"side":"bid","event_time":"2026-07-15T03:40:06.090257Z","price_level":"64532.02","new_quantity":"0.04613992"},{"side":"bid","event_time":"2026-07-15T03:40:06.090257Z","price_level":"64528.58","new_quantity":"0.11124868"},{"side":"bid","event_time":"2026-07-15T03:40:06.090257Z","price_level":"64526.14","new_quantity":"0"},{"side":"bid","event_time":"2026-07-15T03:40:06.090257Z","price_level":"64526.13","new_quantity":"0"},{"side":"bid","event_time":"2026-07-15T03:40:06.090257Z","price_level":"64524.7","new_quantity":"0"},{"side":"bid","event_time":"2026-07-15T03:40:06.090257Z","price_level":"64524.69","new_quantity":"0"},{"side":"bid","event_time":"2026-07-15T03:40:06.090257Z","price_level":"64522.09","new_quantity":"1.11517147"},{"side":"bid","event_time":"2026-07-15T03:40:06.090257Z","price_level":"64522.08","new_quantity":"0"},{"side":"bid","event_time":"2026-07-15T03:40:06.090257Z","price_level":"64520.69","new_quantity":"0.93209115"},{"side":"bid","event_time":"2026-07-15T03:40:06.090257Z","price_level":"64516.51","new_quantity":"0.41049404"},{"side":"bid","event_time":"2026-07-15T03:40:06.090257Z","price_level":"64516.5","new_quantity":"0.61009831"},{"side":"bid","event_time":"2026-07-15T03:40:06.090257Z","price_level":"64516.49","new_quantity":"0"},{"side":"bid","event_time":"2026-07-15T03:40:06.090257Z","price_level":"64509.68","new_quantity":"0"},{"side":"bid","event_time":"2026-07-15T03:40:06.090257Z","price_level":"64509.42","new_quantity":"0.00154793"},{"side":"bid","event_time":"2026-07-15T03:40:06.090257Z","price_level":"64502.98","new_quantity":"0.00773969"},{"side":"bid","event_time":"2026-07-15T03:40:06.090257Z","price_level":"64480.02","new_quantity":"1.791"},{"side":"bid","event_time":"2026-07-15T03:40:06.090257Z","price_level":"64480.01","new_quantity":"0"},{"side":"bid","event_time":"2026-07-15T03:40:06.090257Z","price_level":"64463.81","new_quantity":"2.15633823"},{"side":"bid","event_time":"2026-07-15T03:40:06.090257Z","price_level":"64344.02","new_quantity":"0"},{"side":"bid","event_time":"2026-07-15T03:40:06.090257Z","price_level":"64318.73","new_quantity":"0.00583"},{"side":"bid","event_time":"2026-07-15T03:40:06.090257Z","price_level":"64129.46","new_quantity":"0"},{"side":"bid","event_time":"2026-07-15T03:40:06.090257Z","price_level":"63246.72","new_quantity":"0.00583"},{"side":"bid","event_time":"2026-07-15T03:40:06.090257Z","price_level":"63246.28","new_quantity":"0"},{"side":"bid","event_time":"2026-07-15T03:40:06.090257Z","price_level":"63031.85","new_quantity":"0"},{"side":"offer","event_time":"2026-07-15T03:40:06.090257Z","price_level":"64558.25","new_quantity":"0.29041034"},{"side":"offer","event_time":"2026-07-15T03:40:06.090257Z","price_level":"64558.83","new_quantity":"0.03309489"},{"side":"offer","event_time":"2026-07-15T03:40:06.090257Z","price_level":"64560.91","new_quantity":"0"},{"side":"offer","event_time":"2026-07-15T03:40:06.090257Z","price_level":"64561.11","new_quantity":"0"},{"side":"offer","event_time":"2026-07-15T03:40:06.090257Z","price_level":"64561.51","new_quantity":"0.05365546"},{"side":"offer","event_time":"2026-07-15T03:40:06.090257Z","price_level":"64561.52","new_quantity":"0.048285"},{"side":"offer","event_time":"2026-07-15T03:40:06.090257Z","price_level":"64561.91","new_quantity":"0.00934543"},{"side":"offer","event_time":"2026-07-15T03:40:06.090257Z","price_level":"64561.92","new_quantity":"0"},{"side":"offer","event_time":"2026-07-15T03:40:06.090257Z","price_level":"64563.35","new_quantity":"0"},{"side":"offer","event_time":"2026-07-15T03:40:06.090257Z","price_level":"64563.53","new_quantity":"0.00774472"},{"side":"offer","event_time":"2026-07-15T03:40:06.090257Z","price_level":"64563.86","new_quantity":"0"},{"side":"offer","event_time":"2026-07-15T03:40:06.090257Z","price_level":"64564.52","new_quantity":"0.32053484"},{"side":"offer","event_time":"2026-07-15T03:40:06.090257Z","price_level":"64564.53","new_quantity":"0.12378505"},{"side":"offer","event_time":"2026-07-15T03:40:06.090257Z","price_level":"64564.54","new_quantity":"0.12390703"},{"side":"offer","event_time":"2026-07-15T03:40:06.090257Z","price_level":"64564.59","new_quantity":"0"},{"side":"offer","event_time":"2026-07-15T03:40:06.090257Z","price_level":"64564.6","new_quantity":"0"},{"side":"offer","event_time":"2026-07-15T03:40:06.090257Z","price_level":"64565.71","new_quantity":"0.0096809"},{"side":"offer","event_time":"2026-07-15T03:40:06.090257Z","price_level":"64565.81","new_quantity":"0.07326"},{"side":"offer","event_time":"2026-07-15T03:40:06.090257Z","price_level":"64565.87","new_quantity":"0"},{"side":"offer","event_time":"2026-07-15T03:40:06.090257Z","price_level":"64569.57","new_quantity":"0.00772597"},{"side":"offer","event_time":"2026-07-15T03:40:06.090257Z","price_level":"64569.99","new_quantity":"0"},{"side":"offer","event_time":"2026-07-15T03:40:06.090257Z","price_level":"64571.21","new_quantity":"0.16188495"},{"side":"offer","event_time":"2026-07-15T03:40:06.090257Z","price_level":"64573.16","new_quantity":"0"},{"side":"offer","event_time":"2026-07-15T03:40:06.090257Z","price_level":"64575.12","new_quantity":"0"},{"side":"offer","event_time":"2026-07-15T03:40:06.090257Z","price_level":"64575.52","new_quantity":"0"},{"side":"offer","event_time":"2026-07-15T03:40:06.090257Z","price_level":"64575.94","new_quantity":"0.00583"},{"side":"offer","event_time":"2026-07-15T03:40:06.090257Z","price_level":"64576.11","new_quantity":"0"},{"side":"offer","event_time":"2026-07-15T03:40:06.090257Z","price_level":"64576.85","new_quantity":"0"},{"side":"offer","event_time":"2026-07-15T03:40:06.090257Z","price_level":"64579.55","new_quantity":"0.00002324"},{"side":"offer","event_time":"2026-07-15T03:40:06.090257Z","price_level":"64600.37","new_quantity":"0"},{"side":"offer","event_time":"2026-07-15T03:40:06.090257Z","price_level":"64606.47","new_quantity":"1.03632096"},{"side":"offer","event_time":"2026-07-15T03:40:06.090257Z","price_level":"64608.63","new_quantity":"1.4320189"},{"side":"offer","event_time":"2026-07-15T03:40:06.090257Z","price_level":"64613.38","new_quantity":"0.30962504"},{"side":"offer","event_time":"2026-07-15T03:40:06.090257Z","price_level":"64613.4","new_quantity":"0"},{"side":"offer","event_time":"2026-07-15T03:40:06.090257Z","price_level":"64613.41","new_quantity":"0"},{"side":"offer","event_time":"2026-07-15T03:40:06.090257Z","price_level":"64628.13","new_quantity":"2.10892643"},{"side":"offer","event_time":"2026-07-15T03:40:06.090257Z","price_level":"64628.14","new_quantity":"2.02685892"},{"side":"offer","event_time":"2026-07-15T03:40:06.090257Z","price_level":"64628.26","new_quantity":"0"},{"side":"offer","event_time":"2026-07-15T03:40:06.090257Z","price_level":"64676.28","new_quantity":"0.00958205"},{"side":"offer","event_time":"2026-07-15T03:40:06.090257Z","price_level":"64690.62","new_quantity":"0"},{"side":"offer","event_time":"2026-07-15T03:40:06.090257Z","price_level":"64788.55","new_quantity":"0.00304658"},{"side":"offer","event_time":"2026-07-15T03:40:06.090257Z","price_level":"64790.42","new_quantity":"0.00583"},{"side":"offer","event_time":"2026-07-15T03:40:06.090257Z","price_level":"64812.47","new_quantity":"0"},{"side":"offer","event_time":"2026-07-15T03:40:06.090257Z","price_level":"64814.95","new_quantity":"0"},{"side":"offer","event_time":"2026-07-15T03:40:06.090257Z","price_level":"65005.27","new_quantity":"0.00583"},{"side":"offer","event_time":"2026-07-15T03:40:06.090257Z","price_level":"65494.18","new_quantity":"0"},{"side":"offer","event_time":"2026-07-15T03:40:06.090257Z","price_level":"65648.14","new_quantity":"0.00583"},{"side":"offer","event_time":"2026-07-15T03:40:06.090257Z","price_level":"65708.61","new_quantity":"0"},{"side":"offer","event_time":"2026-07-15T03:40:06.090257Z","price_level":"65863.14","new_quantity":"0.00583"}]}]}
{"channel":"l2_data","timestamp":"2026-07-15T03:40:06.331862733Z","sequence_num":60,"events":[{"type":"update","product_id":"BTC-USD","updates":[{"side":"bid","event_time":"2026-07-15T03:40:06.142195Z","price_level":"64554.07","new_quantity":"0"},{"side":"bid","event_time":"2026-07-15T03:40:06.142195Z","price_level":"64553.16","new_quantity":"0.12392885"},{"side":"bid","event_time":"2026-07-15T03:40:06.142195Z","price_level":"64547.98","new_quantity":"0.12553434"},{"side":"bid","event_time":"2026-07-15T03:40:06.142195Z","price_level":"64547.72","new_quantity":"0"},{"side":"bid","event_time":"2026-07-15T03:40:06.142195Z","price_level":"64546.87","new_quantity":"0.04647222"},{"side":"bid","event_time":"2026-07-15T03:40:06.142195Z","price_level":"64545.95","new_quantity":"0"},{"side":"bid","event_time":"2026-07-15T03:40:06.142195Z","price_level":"64539.89","new_quantity":"0"},{"side":"bid","event_time":"2026-07-15T03:40:06.142195Z","price_level":"64539.44","new_quantity":"0"},{"side":"bid","event_time":"2026-07-15T03:40:06.142195Z","price_level":"64535.34","new_quantity":"0"},{"side":"bid","event_time":"2026-07-15T03:40:06.142195Z","price_level":"64533.37","new_quantity":"0.00583"},{"side":"bid","event_time":"2026-07-15T03:40:06.142195Z","price_level":"64533.3","new_quantity":"0"},{"side":"bid","event_time":"2026-07-15T03:40:06.142195Z","price_level":"64531.09","new_quantity":"0"},{"side":"bid","event_time":"2026-07-15T03:40:06.142195Z","price_level":"64530.53","new_quantity":"0"},{"side":"bid","event_time":"2026-07-15T03:40:06.142195Z","price_level":"64528.58","new_quantity":"0.11124868"},{"side":"bid","event_time":"2026-07-15T03:40:06.142195Z","price_level":"64528.56","new_quantity":"0"},{"side":"bid","event_time":"2026-07-15T03:40:06.142195Z","price_level":"64523.6","new_quantity":"0"},{"side":"bid","event_time":"2026-07-15T03:40:06.142195Z","price_level":"64522.11","new_quantity":"0.84369629"},{"side":"bid","event_time":"2026-07-15T03:40:06.142195Z","price_level":"64522.1","new_quantity":"0.93207078"},{"side":"bid","event_time":"2026-07-15T03:40:06.142195Z","price_level":"64522.09","new_quantity":"0"},{"side":"bid","event_time":"2026-07-15T03:40:06.142195Z","price_level":"64520.69","new_quantity":"0"},{"side":"bid","event_time":"2026-07-15T03:40:06.142195Z","price_level":"64509.42","new_quantity":"0"},{"side":"bid","event_time":"2026-07-15T03:40:06.142195Z","price_level":"64502.98","new_quantity":"0"},{"side":"bid","event_time":"2026-07-15T03:40:06.142195Z","price_level":"64497.17","new_quantity":"0"},{"side":"bid","event_time":"2026-07-15T03:40:06.142195Z","price_level":"64495.18","new_quantity":"0"},{"side":"bid","event_time":"2026-07-15T03:40:06.142195Z","price_level":"64475.02","new_quantity":"0"},{"side":"bid","event_time":"2026-07-15T03:40:06.142195Z","price_level":"64470.02","new_quantity":"0.19902646"},{"side":"bid","event_time":"2026-07-15T03:40:06.142195Z","price_level":"64468.29","new_quantity":"0.2999"},{"side":"bid","event_time":"2026-07-15T03:40:06.142195Z","price_level":"64454.87","new_quantity":"0.02623794"},{"side":"bid","event_time":"2026-07-15T03:40:06.142195Z","price_level":"64451.4","new_quantity":"0.05"},{"side":"bid","event_time":"2026-07-15T03:40:06.142195Z","price_level":"64428.08","new_quantity":"0"},{"side":"bid","event_time":"2026-07-15T03:40:06.142195Z","price_level":"64104.25","new_quantity":"0.00583"},{"side":"bid","event_time":"2026-07-15T03:40:06.142195Z","price_level":"63246.79","new_quantity":"0.00583"},{"side":"bid","event_time":"2026-07-15T03:40:06.142195Z","price_level":"63246.72","new_quantity":"0"},{"side":"bid","event_time":"2026-07-15T03:40:06.142195Z","price_level":"63032.07","new_quantity":"0.00583"},{"side":"offer","event_time":"2026-07-15T03:40:06.142195Z","price_level":"64558.25","new_quantity":"0.40458124"},{"side":"offer","event_time":"2026-07-15T03:40:06.142195Z","price_level":"64561.51","new_quantity":"0.12069539"},{"side":"offer","event_time":"2026-07-15T03:40:06.142195Z","price_level":"64562.57","new_quantity":"0.12378505"},{"side":"offer","event_time":"2026-07-15T03:40:06.142195Z","price_level":"64565.02","new_quantity":"0.00772597"},{"side":"offer","event_time":"2026-07-15T03:40:06.142195Z","price_level":"64569.57","new_quantity":"0"},{"side":"offer","event_time":"2026-07-15T03:40:06.142195Z","price_level":"64569.58","new_quantity":"0"},{"side":"offer","event_time":"2026-07-15T03:40:06.142195Z","price_level":"64571.98","new_quantity":"0.00100882"},{"side":"offer","event_time":"2026-07-15T03:40:06.142195Z","price_level":"64573.84","new_quantity":"0"},{"side":"offer","event_time":"2026-07-15T03:40:06.142195Z","price_level":"64575.57","new_quantity":"0"},{"side":"offer","event_time":"2026-07-15T03:40:06.142195Z","price_level":"64587.64","new_quantity":"0.82211457"},{"side":"offer","event_time":"2026-07-15T03:40:06.142195Z","price_level":"64587.65","new_quantity":"0.63877996"},{"side":"offer","event_time":"2026-07-15T03:40:06.142195Z","price_level":"64587.66","new_quantity":"0"},{"side":"offer","event_time":"2026-07-15T03:40:06.142195Z","price_level":"64587.79","new_quantity":"0.06637877"},{"side":"offer","event_time":"2026-07-15T03:40:06.142195Z","price_level":"64589.32","new_quantity":"0"},{"side":"offer","event_time":"2026-07-15T03:40:06.142195Z","price_level":"64599.81","new_quantity":"0.01902998"},{"side":"offer","event_time":"2026-07-15T03:40:06.142195Z","price_level":"64603.26","new_quantity":"0.10616991"},{"side":"offer","event_time":"2026-07-15T03:40:06.142195Z","price_level":"64605.75","new_quantity":"0.02670441"},{"side":"offer","event_time":"2026-07-15T03:40:06.142195Z","price_level":"64607.17","new_quantity":"0.06773069"},{"side":"offer","event_time":"2026-07-15T03:40:06.142195Z","price_level":"64609.73","new_quantity":"0.32050153"},{"side":"offer","event_time":"2026-07-15T03:40:06.142195Z","price_level":"64611.13","new_quantity":"0.45882802"},{"side":"offer","event_time":"2026-07-15T03:40:06.142195Z","price_level":"64613.38","new_quantity":"0"},{"side":"offer","event_time":"2026-07-15T03:40:06.142195Z","price_level":"64613.39","new_quantity":"0"},{"side":"offer","event_time":"2026-07-15T03:40:06.142195Z","price_level":"64613.42","new_quantity":"0.0357143"},{"side":"offer","event_time":"2026-07-15T03:40:06.142195Z","price_level":"64624.79","new_quantity":"0.00077445"},{"side":"offer","event_time":"2026-07-15T03:40:06.142195Z","price_level":"64633.62","new_quantity":"0"},{"side":"offer","event_time":"2026-07-15T03:40:06.142195Z","price_level":"65005.19","new_quantity":"0.00583"},{"side":"offer","event_time":"2026-07-15T03:40:06.142195Z","price_level":"65005.22","new_quantity":"0.00583"},{"side":"offer","event_time":"2026-07-15T03:40:06.142195Z","price_level":"65005.27","new_quantity":"0"},{"side":"offer","event_time":"2026-07-15T03:40:06.142195Z","price_level":"65064.81","new_quantity":"0"},{"side":"offer","event_time":"2026-07-15T03:40:06.142195Z","price_level":"65863.14","new_quantity":"0"}]}]}
{"channel":"l2_data","timestamp":"2026-07-15T03:40:06.335402924Z","sequence_num":61,"events":[{"type":"update","product_id":"BTC-USD","updates":[{"side":"bid","event_time":"2026-07-15T03:40:06.194545Z","price_level":"64558.24","new_quantity":"0"},{"side":"bid","event_time":"2026-07-15T03:40:06.194545Z","price_level":"64554.8","new_quantity":"0"},{"side":"bid","event_time":"2026-07-15T03:40:06.194545Z","price_level":"64554.56","new_quantity":"0.000018"},{"side":"bid","event_time":"2026-07-15T03:40:06.194545Z","price_level":"64554","new_quantity":"0"},{"side":"bid","event_time":"2026-07-15T03:40:06.194545Z","price_level":"64553.16","new_quantity":"0"},{"side":"bid","event_time":"2026-07-15T03:40:06.194545Z","price_level":"64552.26","new_quantity":"0.0334"},{"side":"bid","event_time":"2026-07-15T03:40:06.194545Z","price_level":"64552.09","new_quantity":"0.1239309"},{"side":"bid","event_time":"2026-07-15T03:40:06.194545Z","price_level":"64552","new_quantity":"0.0245"},{"side":"bid","event_time":"2026-07-15T03:40:06.194545Z","price_level":"64546.87","new_quantity":"0"},{"side":"bid","event_time":"2026-07-15T03:40:06.194545Z","price_level":"64544.89","new_quantity":"0.04647222"},{"side":"bid","event_time":"2026-07-15T03:40:06.194545Z","price_level":"64539.82","new_quantity":"0.048285"},{"side":"bid","event_time":"2026-07-15T03:40:06.194545Z","price_level":"64527.77","new_quantity":"0.00077447"},{"side":"bid","event_time":"2026-07-15T03:40:06.194545Z","price_level":"64520.44","new_quantity":"0.04244214"},{"side":"bid","event_time":"2026-07-15T03:40:06.194545Z","price_level":"64516.53","new_quantity":"0.41049392"},{"side":"bid","event_time":"2026-07-15T03:40:06.194545Z","price_level":"64516.52","new_quantity":"0.61009812"},{"side":"bid","event_time":"2026-07-15T03:40:06.194545Z","price_level":"64516.51","new_quantity":"0"},{"side":"bid","event_time":"2026-07-15T03:40:06.194545Z","price_level":"64516.5","new_quantity":"0"},{"side":"bid","event_time":"2026-07-15T03:40:06.194545Z","price_level":"64507.96","new_quantity":"0.00154797"},{"side":"bid","event_time":"2026-07-15T03:40:06.194545Z","price_level":"64501.52","new_quantity":"0.00773986"},{"side":"bid","event_time":"2026-07-15T03:40:06.194545Z","price_level":"64493.18","new_quantity":"0.00510876"},{"side":"bid","event_time":"2026-07-15T03:40:06.194545Z","price_level":"64490.99","new_quantity":"0.13853803"},{"side":"bid","event_time":"2026-07-15T03:40:06.194545Z","price_level":"64490.98","new_quantity":"0"},{"side":"bid","event_time":"2026-07-15T03:40:06.194545Z","price_level":"64486.3","new_quantity":"0.84666267"},{"side":"bid","event_time":"2026-07-15T03:40:06.194545Z","price_level":"64486.29","new_quantity":"1.35016878"},{"side":"bid","event_time":"2026-07-15T03:40:06.194545Z","price_level":"64486.28","new_quantity":"0"},{"side":"bid","event_time":"2026-07-15T03:40:06.194545Z","price_level":"64384.5","new_quantity":"0"},{"side":"bid","event_time":"2026-07-15T03:40:06.194545Z","price_level":"64318.84","new_quantity":"0.00583"},{"side":"bid","event_time":"2026-07-15T03:40:06.194545Z","price_level":"64318.73","new_quantity":"0"},{"side":"bid","event_time":"2026-07-15T03:40:06.194545Z","price_level":"63914.57","new_quantity":"0"},{"side":"bid","event_time":"2026-07-15T03:40:06.194545Z","price_level":"63889.28","new_quantity":"0.00583"},{"side":"bid","event_time":"2026-07-15T03:40:06.194545Z","price_level":"63889.23","new_quantity":"0"},{"side":"bid","event_time":"2026-07-15T03:40:06.194545Z","price_level":"63699.94","new_quantity":"0"},{"side":"bid","event_time":"2026-07-15T03:40:06.194545Z","price_level":"63674.3","new_quantity":"0.00583"},{"side":"bid","event_time":"2026-07-15T03:40:06.194545Z","price_level":"63485.51","new_quantity":"0"},{"side":"bid","event_time":"2026-07-15T03:40:06.194545Z","price_level":"63459.76","new_quantity":"0.00583"},{"side":"bid","event_time":"2026-07-15T03:40:06.194545Z","price_level":"63246.79","new_quantity":"0"},{"side":"bid","event_time":"2026-07-15T03:40:06.194545Z","price_level":"63032.07","new_quantity":"0"},{"side":"offer","event_time":"2026-07-15T03:40:06.194545Z","price_level":"64554.57","new_quantity":"0.32920017"},{"side":"offer","event_time":"2026-07-15T03:40:06.194545Z","price_level":"64555.99","new_quantity":"0.029253"},{"side":"offer","event_time":"2026-07-15T03:40:06.194545Z","price_level":"64556","new_quantity":"0.0245"},{"side":"offer","event_time":"2026-07-15T03:40:06.194545Z","price_level":"64558","new_quantity":"0.0245"},{"side":"offer","event_time":"2026-07-15T03:40:06.194545Z","price_level":"64558.22","new_quantity":"0.19014196"},{"side":"offer","event_time":"2026-07-15T03:40:06.194545Z","price_level":"64558.23","new_quantity":"0.12378505"},{"side":"offer","event_time":"2026-07-15T03:40:06.194545Z","price_level":"64558.24","new_quantity":"0.00774516"},{"side":"offer","event_time":"2026-07-15T03:40:06.194545Z","price_level":"64558.25","new_quantity":"0"},{"side":"offer","event_time":"2026-07-15T03:40:06.194545Z","price_level":"64558.83","new_quantity":"0"},{"side":"offer","event_time":"2026-07-15T03:40:06.194545Z","price_level":"64559.86","new_quantity":"0.00774516"},{"side":"offer","event_time":"2026-07-15T03:40:06.194545Z","price_level":"64560.38","new_quantity":"0.12378505"},{"side":"offer","event_time":"2026-07-15T03:40:06.194545Z","price_level":"64561.51","new_quantity":"0.12313215"},{"side":"offer","event_time":"2026-07-15T03:40:06.194545Z","price_level":"64561.91","new_quantity":"0"},{"side":"offer","event_time":"2026-07-15T03:40:06.194545Z","price_level":"64562.04","new_quantity":"0.00968145"},{"side":"offer","event_time":"2026-07-15T03:40:06.194545Z","price_level":"64563.53","new_quantity":"0"},{"side":"offer","event_time":"2026-07-15T03:40:06.194545Z","price_level":"64564.51","new_quantity":"0.00772597"},{"side":"offer","event_time":"2026-07-15T03:40:06.194545Z","price_level":"64564.54","new_quantity":"0"},{"side":"offer","event_time":"2026-07-15T03:40:06.194545Z","price_level":"64565.02","new_quantity":"0"},{"side":"offer","event_time":"2026-07-15T03:40:06.194545Z","price_level":"64565.71","new_quantity":"0"},{"side":"offer","event_time":"2026-07-15T03:40:06.194545Z","price_level":"64571.98","new_quantity":"0"},{"side":"offer","event_time":"2026-07-15T03:40:06.194545Z","price_level":"64572.3","new_quantity":"0"},{"side":"offer","event_time":"2026-07-15T03:40:06.194545Z","price_level":"64572.39","new_quantity":"0.00100887"},{"side":"offer","event_time":"2026-07-15T03:40:06.194545Z","price_level":"64575.07","new_quantity":"0.00583"},{"side":"offer","event_time":"2026-07-15T03:40:06.194545Z","price_level":"64575.27","new_quantity":"0"},{"side":"offer","event_time":"2026-07-15T03:40:06.194545Z","price_level":"64575.42","new_quantity":"0.00038328"},{"side":"offer","event_time":"2026-07-15T03:40:06.194545Z","price_level":"64575.44","new_quantity":"0.05676143"},{"side":"offer","event_time":"2026-07-15T03:40:06.194545Z","price_level":"64575.94","new_quantity":"0"},{"side":"offer","event_time":"2026-07-15T03:40:06.194545Z","price_level":"64578","new_quantity":"0"},{"side":"offer","event_time":"2026-07-15T03:40:06.194545Z","price_level":"64585.8","new_quantity":"0"},{"side":"offer","event_time":"2026-07-15T03:40:06.194545Z","price_level":"64591.32","new_quantity":"0.0278077"},{"side":"offer","event_time":"2026-07-15T03:40:06.194545Z","price_level":"64591.33","new_quantity":"0.04656107"},{"side":"offer","event_time":"2026-07-15T03:40:06.194545Z","price_level":"64591.78","new_quantity":"0"},{"side":"offer","event_time":"2026-07-15T03:40:06.194545Z","price_level":"64607.16","new_quantity":"1.43205148"},{"side":"offer","event_time":"2026-07-15T03:40:06.194545Z","price_level":"64608.63","new_quantity":"0"},{"side":"offer","event_time":"2026-07-15T03:40:06.194545Z","price_level":"64609.33","new_quantity":"0"},{"side":"offer","event_time":"2026-07-15T03:40:06.194545Z","price_level":"64613.4","new_quantity":"1.24602493"},{"side":"offer","event_time":"2026-07-15T03:40:06.194545Z","price_level":"64613.41","new_quantity":"2.02732099"},{"side":"offer","event_time":"2026-07-15T03:40:06.194545Z","price_level":"64613.42","new_quantity":"0"},{"side":"offer","event_time":"2026-07-15T03:40:06.194545Z","price_level":"64620.81","new_quantity":"0"},{"side":"offer","event_time":"2026-07-15T03:40:06.194545Z","price_level":"64626.21","new_quantity":"0"},{"side":"offer","event_time":"2026-07-15T03:40:06.194545Z","price_level":"64628.13","new_quantity":"0.89889166"},{"side":"offer","event_time":"2026-07-15T03:40:06.194545Z","price_level":"64628.14","new_quantity":"0"},{"side":"offer","event_time":"2026-07-15T03:40:06.194545Z","price_level":"65004.91","new_quantity":"0.00583"},{"side":"offer","event_time":"2026-07-15T03:40:06.194545Z","price_level":"65005.19","new_quantity":"0"},{"side":"offer","event_time":"2026-07-15T03:40:06.194545Z","price_level":"65005.22","new_quantity":"0"},{"side":"offer","event_time":"2026-07-15T03:40:06.194545Z","price_level":"65219.82","new_quantity":"0.00583"},{"side":"offer","event_time":"2026-07-15T03:40:06.194545Z","price_level":"65279.38","new_quantity":"0"},{"side":"offer","event_time":"2026-07-15T03:40:06.194545Z","price_level":"65362.23","new_quantity":"0"},{"side":"offer","event_time":"2026-07-15T03:40:06.194545Z","price_level":"65647.42","new_quantity":"0"},{"side":"offer","event_time":"2026-07-15T03:40:06.194545Z","price_level":"65648.14","new_quantity":"0"}]}]}
{"channel":"l2_data","timestamp":"2026-07-15T03:40:06.3374513Z","sequence_num":62,"events":[{"type":"update","product_id":"BTC-USD","updates":[{"side":"bid","event_time":"2026-07-15T03:40:06.23636Z","price_level":"64549.08","new_quantity":"0"},{"side":"bid","event_time":"2026-07-15T03:40:06.23636Z","price_level":"64548.28","new_quantity":"0.12378505"},{"side":"bid","event_time":"2026-07-15T03:40:06.23636Z","price_level":"64538.59","new_quantity":"0.00772597"},{"side":"bid","event_time":"2026-07-15T03:40:06.23636Z","price_level":"64535.6","new_quantity":"0.02"},{"side":"bid","event_time":"2026-07-15T03:40:06.23636Z","price_level":"64535.5","new_quantity":"0.04"},{"side":"bid","event_time":"2026-07-15T03:40:06.23636Z","price_level":"64534","new_quantity":"0.08"},{"side":"bid","event_time":"2026-07-15T03:40:06.23636Z","price_level":"64527.82","new_quantity":"0.04337005"},{"side":"bid","event_time":"2026-07-15T03:40:06.23636Z","price_level":"64527.76","new_quantity":"0"},{"side":"bid","event_time":"2026-07-15T03:40:06.23636Z","price_level":"64525.03","new_quantity":"0"},{"side":"bid","event_time":"2026-07-15T03:40:06.23636Z","price_level":"64522.11","new_quantity":"0.31258799"},{"side":"bid","event_time":"2026-07-15T03:40:06.23636Z","price_level":"64522.1","new_quantity":"0"},{"side":"bid","event_time":"2026-07-15T03:40:06.23636Z","price_level":"64516.55","new_quantity":"0.96698813"},{"side":"bid","event_time":"2026-07-15T03:40:06.23636Z","price_level":"64516.54","new_quantity":"0.9321511"},{"side":"bid","event_time":"2026-07-15T03:40:06.23636Z","price_level":"64516.53","new_quantity":"0"},{"side":"offer","event_time":"2026-07-15T03:40:06.23636Z","price_level":"64562.13","new_quantity":"0.07326"},{"side":"offer","event_time":"2026-07-15T03:40:06.23636Z","price_level":"64572.39","new_quantity":"0"},{"side":"offer","event_time":"2026-07-15T03:40:06.23636Z","price_level":"64572.55","new_quantity":"0"},{"side":"offer","event_time":"2026-07-15T03:40:06.23636Z","price_level":"64572.63","new_quantity":"0.00100887"},{"side":"offer","event_time":"2026-07-15T03:40:06.23636Z","price_level":"64583.85","new_quantity":"0.56071009"},{"side":"offer","event_time":"2026-07-15T03:40:06.23636Z","price_level":"64584.23","new_quantity":"0.63881378"},{"side":"offer","event_time":"2026-07-15T03:40:06.23636Z","price_level":"64587.64","new_quantity":"0.44457106"},{"side":"offer","event_time":"2026-07-15T03:40:06.23636Z","price_level":"64587.65","new_quantity":"0"},{"side":"offer","event_time":"2026-07-15T03:40:06.23636Z","price_level":"64589.33","new_quantity":"0"},{"side":"offer","event_time":"2026-07-15T03:40:06.23636Z","price_level":"64608.63","new_quantity":"0.45884577"},{"side":"offer","event_time":"2026-07-15T03:40:06.23636Z","price_level":"64609.73","new_quantity":"0.05447275"},{"side":"offer","event_time":"2026-07-15T03:40:06.23636Z","price_level":"64611.13","new_quantity":"0"},{"side":"offer","event_time":"2026-07-15T03:40:06.23636Z","price_level":"64616.52","new_quantity":"0.01940957"},{"side":"offer","event_time":"2026-07-15T03:40:06.23636Z","price_level":"64622.63","new_quantity":"0"},{"side":"offer","event_time":"2026-07-15T03:40:06.23636Z","price_level":"64654.55","new_quantity":"0.04800935"}]}]}
{"channel":"l2_data","timestamp":"2026-07-15T03:40:06.338752867Z","sequence_num":63,"events":[{"type":"update","product_id":"BTC-USD","updates":[{"side":"bid","event_time":"2026-07-15T03:40:06.285601Z","price_level":"64551.01","new_quantity":"0.12378505"},{"side":"bid","event_time":"2026-07-15T03:40:06.285601Z","price_level":"64538.98","new_quantity":"0.00772597"},{"side":"bid","event_time":"2026-07-15T03:40:06.285601Z","price_level":"64538.97","new_quantity":"0.0334"},{"side":"bid","event_time":"2026-07-15T03:40:06.285601Z","price_level":"64538.59","new_quantity":"0"},{"side":"bid","event_time":"2026-07-15T03:40:06.285601Z","price_level":"64535.6","new_quantity":"0"},{"side":"bid","event_time":"2026-07-15T03:40:06.285601Z","price_level":"64535.5","new_quantity":"0"},{"side":"bid","event_time":"2026-07-15T03:40:06.285601Z","price_level":"64534","new_quantity":"0"},{"side":"bid","event_time":"2026-07-15T03:40:06.285601Z","price_level":"64528.67","new_quantity":"0.05703988"},{"side":"bid","event_time":"2026-07-15T03:40:06.285601Z","price_level":"64528.58","new_quantity":"0"},{"side":"bid","event_time":"2026-07-15T03:40:06.285601Z","price_level":"64528.57","new_quantity":"0"},{"side":"bid","event_time":"2026-07-15T03:40:06.285601Z","price_level":"64527.82","new_quantity":"0"},{"side":"bid","event_time":"2026-07-15T03:40:06.285601Z","price_level":"64520.44","new_quantity":"0"},{"side":"bid","event_time":"2026-07-15T03:40:06.285601Z","price_level":"64516.55","new_quantity":"0.60275955"},{"side":"bid","event_time":"2026-07-15T03:40:06.285601Z","price_level":"64516.52","new_quantity":"0"},{"side":"bid","event_time":"2026-07-15T03:40:06.285601Z","price_level":"64512.53","new_quantity":"0.65641868"},{"side":"bid","event_time":"2026-07-15T03:40:06.285601Z","price_level":"64512.52","new_quantity":"0.61013595"},{"side":"bid","event_time":"2026-07-15T03:40:06.285601Z","price_level":"64512.51","new_quantity":"0"},{"side":"bid","event_time":"2026-07-15T03:40:06.285601Z","price_level":"64507.96","new_quantity":"0"},{"side":"bid","event_time":"2026-07-15T03:40:06.285601Z","price_level":"64506.1","new_quantity":"0.01505932"},{"side":"bid","event_time":"2026-07-15T03:40:06.285601Z","price_level":"64501.52","new_quantity":"0"},{"side":"bid","event_time":"2026-07-15T03:40:06.285601Z","price_level":"64486.32","new_quantity":"0.84666242"},{"side":"bid","event_time":"2026-07-15T03:40:06.285601Z","price_level":"64486.31","new_quantity":"1.35016836"},{"side":"bid","event_time":"2026-07-15T03:40:06.285601Z","price_level":"64486.3","new_quantity":"0"},{"side":"bid","event_time":"2026-07-15T03:40:06.285601Z","price_level":"64486.29","new_quantity":"0"},{"side":"bid","event_time":"2026-07-15T03:40:06.285601Z","price_level":"64476.85","new_quantity":"0.00808054"},{"side":"bid","event_time":"2026-07-15T03:40:06.285601Z","price_level":"64438.9","new_quantity":"0.05"},{"side":"bid","event_time":"2026-07-15T03:40:06.285601Z","price_level":"64363.41","new_quantity":"0"},{"side":"bid","event_time":"2026-07-15T03:40:06.285601Z","price_level":"64298.73","new_quantity":"0"},{"side":"bid","event_time":"2026-07-15T03:40:06.285601Z","price_level":"56485.24","new_quantity":"0.0132912"},{"side":"offer","event_time":"2026-07-15T03:40:06.285601Z","price_level":"64554.57","new_quantity":"0.27085605"},{"side":"offer","event_time":"2026-07-15T03:40:06.285601Z","price_level":"64555.99","new_quantity":"0.1003678"},{"side":"offer","event_time":"2026-07-15T03:40:06.285601Z","price_level":"64557.98","new_quantity":"0.12378505"},{"side":"offer","event_time":"2026-07-15T03:40:06.285601Z","price_level":"64557.99","new_quantity":"0.00159977"},{"side":"offer","event_time":"2026-07-15T03:40:06.285601Z","price_level":"64558.22","new_quantity":"0.11624228"},{"side":"offer","event_time":"2026-07-15T03:40:06.285601Z","price_level":"64558.23","new_quantity":"0"},{"side":"offer","event_time":"2026-07-15T03:40:06.285601Z","price_level":"64560.37","new_quantity":"0.04656107"},{"side":"offer","event_time":"2026-07-15T03:40:06.285601Z","price_level":"64561.51","new_quantity":"0.22509899"},{"side":"offer","event_time":"2026-07-15T03:40:06.285601Z","price_level":"64564.24","new_quantity":"0.00772597"},{"side":"offer","event_time":"2026-07-15T03:40:06.285601Z","price_level":"64564.25","new_quantity":"0.12390759"},{"side":"offer","event_time":"2026-07-15T03:40:06.285601Z","price_level":"64564.51","new_quantity":"0"},{"side":"offer","event_time":"2026-07-15T03:40:06.285601Z","price_level":"64572.63","new_quantity":"0"},{"side":"offer","event_time":"2026-07-15T03:40:06.285601Z","price_level":"64572.72","new_quantity":"0.00100887"},{"side":"offer","event_time":"2026-07-15T03:40:06.285601Z","price_level":"64581.95","new_quantity":"0"},{"side":"offer","event_time":"2026-07-15T03:40:06.285601Z","price_level":"64582.5","new_quantity":"0"},{"side":"offer","event_time":"2026-07-15T03:40:06.285601Z","price_level":"64587.79","new_quantity":"0"},{"side":"offer","event_time":"2026-07-15T03:40:06.285601Z","price_level":"64613.39","new_quantity":"2.02732161"},{"side":"offer","event_time":"2026-07-15T03:40:06.285601Z","price_level":"64613.41","new_quantity":"0"},{"side":"offer","event_time":"2026-07-15T03:40:06.285601Z","price_level":"64628.32","new_quantity":"0"},{"side":"offer","event_time":"2026-07-15T03:40:06.285601Z","price_level":"64665","new_quantity":"0"}]}]}
{"channel":"l2_data","timestamp":"2026-07-15T03:40:06.383582944Z","sequence_num":64,"events":[{"type":"update","product_id":"BTC-USD","updates":[{"side":"bid","event_time":"2026-07-15T03:40:06.343593Z","price_level":"64561.52","new_quantity":"0.1013662"},{"side":"bid","event_time":"2026-07-15T03:40:06.343593Z","price_level":"64561.51","new_quantity":"0.1324662"},{"side":"bid","event_time":"2026-07-15T03:40:06.343593Z","price_level":"64558.23","new_quantity":"0.10789"},{"side":"bid","event_time":"2026-07-15T03:40:06.343593Z","price_level":"64558.02","new_quantity":"0.12378505"},{"side":"bid","event_time":"2026-07-15T03:40:06.343593Z","price_level":"64558.01","new_quantity":"0.00159977"},{"side":"bid","event_time":"2026-07-15T03:40:06.343593Z","price_level":"64558","new_quantity":"0.0245"},{"side":"bid","event_time":"2026-07-15T03:40:06.343593Z","price_level":"64557.16","new_quantity":"0.04656107"},{"side":"bid","event_time":"2026-07-15T03:40:06.343593Z","price_level":"64556","new_quantity":"0.18828505"},{"side":"bid","event_time":"2026-07-15T03:40:06.343593Z","price_level":"64555.12","new_quantity":"0.15490637"},{"side":"bid","event_time":"2026-07-15T03:40:06.343593Z","price_level":"64554.57","new_quantity":"0.04"},{"side":"bid","event_time":"2026-07-15T03:40:06.343593Z","price_level":"64554.56","new_quantity":"0.000018"},{"side":"bid","event_time":"2026-07-15T03:40:06.343593Z","price_level":"64554.01","new_quantity":"0.10504964"},{"side":"bid","event_time":"2026-07-15T03:40:06.343593Z","price_level":"64554","new_quantity":"0.0245"},{"side":"bid","event_time":"2026-07-15T03:40:06.343593Z","price_level":"64553.42","new_quantity":"0"},{"side":"bid","event_time":"2026-07-15T03:40:06.343593Z","price_level":"64552.26","new_quantity":"0"},{"side":"bid","event_time":"2026-07-15T03:40:06.343593Z","price_level":"64552.09","new_quantity":"0"},{"side":"bid","event_time":"2026-07-15T03:40:06.343593Z","price_level":"64551.84","new_quantity":"0.04647362"},{"side":"bid","event_time":"2026-07-15T03:40:06.343593Z","price_level":"64551.02","new_quantity":"0.13297214"},{"side":"bid","event_time":"2026-07-15T03:40:06.343593Z","price_level":"64551","new_quantity":"0"},{"side":"bid","event_time":"2026-07-15T03:40:06.343593Z","price_level":"64549.07","new_quantity":"0"},{"side":"bid","event_time":"2026-07-15T03:40:06.343593Z","price_level":"64548.96","new_quantity":"0.03093532"},{"side":"bid","event_time":"2026-07-15T03:40:06.343593Z","price_level":"64548.07","new_quantity":"0"},{"side":"bid","event_time":"2026-07-15T03:40:06.343593Z","price_level":"64547.97","new_quantity":"0"},{"side":"bid","event_time":"2026-07-15T03:40:06.343593Z","price_level":"64546.83","new_quantity":"0.104497"},{"side":"bid","event_time":"2026-07-15T03:40:06.343593Z","price_level":"64544.89","new_quantity":"0"},{"side":"bid","event_time":"2026-07-15T03:40:06.343593Z","price_level":"64543.01","new_quantity":"0.091151"},{"side":"bid","event_time":"2026-07-15T03:40:06.343593Z","price_level":"64541.41","new_quantity":"0.0431272"},{"side":"bid","event_time":"2026-07-15T03:40:06.343593Z","price_level":"64539.82","new_quantity":"0"},{"side":"bid","event_time":"2026-07-15T03:40:06.343593Z","price_level":"64535.31","new_quantity":"0.078114"},{"side":"bid","event_time":"2026-07-15T03:40:06.343593Z","price_level":"64533.31","new_quantity":"0"},{"side":"bid","event_time":"2026-07-15T03:40:06.343593Z","price_level":"64532.02","new_quantity":"0"},{"side":"bid","event_time":"2026-07-15T03:40:06.343593Z","price_level":"64531.35","new_quantity":"0.05230281"},{"side":"bid","event_time":"2026-07-15T03:40:06.343593Z","price_level":"64531.34","new_quantity":"0"},{"side":"bid","event_time":"2026-07-15T03:40:06.343593Z","price_level":"64528.55","new_quantity":"0.02769058"},{"side":"bid","event_time":"2026-07-15T03:40:06.343593Z","price_level":"64527.77","new_quantity":"0"},{"side":"bid","event_time":"2026-07-15T03:40:06.343593Z","price_level":"64524.14","new_quantity":"0.00077439"},{"side":"bid","event_time":"2026-07-15T03:40:06.343593Z","price_level":"64521.31","new_quantity":"0.01907721"},{"side":"bid","event_time":"2026-07-15T03:40:06.343593Z","price_level":"64520.63","new_quantity":"0.06774415"},{"side":"bid","event_time":"2026-07-15T03:40:06.343593Z","price_level":"64520.12","new_quantity":"0.04299755"},{"side":"bid","event_time":"2026-07-15T03:40:06.343593Z","price_level":"64516.75","new_quantity":"0.02676706"},{"side":"bid","event_time":"2026-07-15T03:40:06.343593Z","price_level":"64470.02","new_quantity":"1.46375534"},{"side":"bid","event_time":"2026-07-15T03:40:06.343593Z","price_level":"64468.3","new_quantity":"2.15618805"},{"side":"bid","event_time":"2026-07-15T03:40:06.343593Z","price_level":"64464.92","new_quantity":"0.02423914"},{"side":"bid","event_time":"2026-07-15T03:40:06.343593Z","price_level":"64463.81","new_quantity":"0"},{"side":"bid","event_time":"2026-07-15T03:40:06.343593Z","price_level":"64458.67","new_quantity":"0.04988029"},{"side":"bid","event_time":"2026-07-15T03:40:06.343593Z","price_level":"64444.93","new_quantity":"0.00268993"},{"side":"bid","event_time":"2026-07-15T03:40:06.343593Z","price_level":"56485.24","new_quantity":"0"},{"side":"offer","event_time":"2026-07-15T03:40:06.343593Z","price_level":"64554.57","new_quantity":"0"},{"side":"offer","event_time":"2026-07-15T03:40:06.343593Z","price_level":"64555.99","new_quantity":"0"},{"side":"offer","event_time":"2026-07-15T03:40:06.343593Z","price_level":"64556","new_quantity":"0"},{"side":"offer","event_time":"2026-07-15T03:40:06.343593Z","price_level":"64557.98","new_quantity":"0"},{"side":"offer","event_time":"2026-07-15T03:40:06.343593Z","price_level":"64557.99","new_quantity":"0"},{"side":"offer","event_time":"2026-07-15T03:40:06.343593Z","price_level":"64558","new_quantity":"0"},{"side":"offer","event_time":"2026-07-15T03:40:06.343593Z","price_level":"64558.22","new_quantity":"0"},{"side":"offer","event_time":"2026-07-15T03:40:06.343593Z","price_level":"64558.24","new_quantity":"0"},{"side":"offer","event_time":"2026-07-15T03:40:06.343593Z","price_level":"64558.84","new_quantity":"0"},{"side":"offer","event_time":"2026-07-15T03:40:06.343593Z","price_level":"64559.86","new_quantity":"0"},{"side":"offer","event_time":"2026-07-15T03:40:06.343593Z","price_level":"64560","new_quantity":"0"},{"side":"offer","event_time":"2026-07-15T03:40:06.343593Z","price_level":"64560.37","new_quantity":"0"},{"side":"offer","event_time":"2026-07-15T03:40:06.343593Z","price_level":"64560.38","new_quantity":"0"},{"side":"offer","event_time":"2026-07-15T03:40:06.343593Z","price_level":"64561.51","new_quantity":"0"},{"side":"offer","event_time":"2026-07-15T03:40:06.343593Z","price_level":"64561.52","new_quantity":"0"},{"side":"offer","event_time":"2026-07-15T03:40:06.343593Z","price_level":"64562","new_quantity":"0"},{"side":"offer","event_time":"2026-07-15T03:40:06.343593Z","price_level":"64562.04","new_quantity":"0"},{"side":"offer","event_time":"2026-07-15T03:40:06.343593Z","price_level":"64562.13","new_quantity":"0"},{"side":"offer","event_time":"2026-07-15T03:40:06.343593Z","price_level":"64562.57","new_quantity":"0"},{"side":"offer","event_time":"2026-07-15T03:40:06.343593Z","price_level":"64563.13","new_quantity":"0"},{"side":"offer","event_time":"2026-07-15T03:40:06.343593Z","price_level":"64564.24","new_quantity":"0"},{"side":"offer","event_time":"2026-07-15T03:40:06.343593Z","price_level":"64564.25","new_quantity":"0"},{"side":"offer","event_time":"2026-07-15T03:40:06.343593Z","price_level":"64564.51","new_quantity":"0"},{"side":"offer","event_time":"2026-07-15T03:40:06.343593Z","price_level":"64564.52","new_quantity":"0.03393414"},{"side":"offer","event_time":"2026-07-15T03:40:06.343593Z","price_level":"64564.53","new_quantity":"0"},{"side":"offer","event_time":"2026-07-15T03:40:06.343593Z","price_level":"64565.31","new_quantity":"0"},{"side":"offer","event_time":"2026-07-15T03:40:06.343593Z","price_level":"64565.81","new_quantity":"0"},{"side":"offer","event_time":"2026-07-15T03:40:06.343593Z","price_level":"64565.86","new_quantity":"0"},{"side":"offer","event_time":"2026-07-15T03:40:06.343593Z","price_level":"64565.88","new_quantity":"0"},{"side":"offer","event_time":"2026-07-15T03:40:06.343593Z","price_level":"64566.15","new_quantity":"0"},{"side":"offer","event_time":"2026-07-15T03:40:06.343593Z","price_level":"64566.92","new_quantity":"0.00968081"},{"side":"offer","event_time":"2026-07-15T03:40:06.343593Z","price_level":"64568.26","new_quantity":"0"},{"side":"offer","event_time":"2026-07-15T03:40:06.343593Z","price_level":"64568.27","new_quantity":"0"},{"side":"offer","event_time":"2026-07-15T03:40:06.343593Z","price_level":"64568.54","new_quantity":"0"},{"side":"offer","event_time":"2026-07-15T03:40:06.343593Z","price_level":"64571.19","new_quantity":"0.02985528"},{"side":"offer","event_time":"2026-07-15T03:40:06.343593Z","price_level":"64571.2","new_quantity":"0.03093532"},{"side":"offer","event_time":"2026-07-15T03:40:06.343593Z","price_level":"64571.21","new_quantity":"0"},{"side":"offer","event_time":"2026-07-15T03:40:06.343593Z","price_level":"64571.22","new_quantity":"0"},{"side":"offer","event_time":"2026-07-15T03:40:06.343593Z","price_level":"64572.72","new_quantity":"0"},{"side":"offer","event_time":"2026-07-15T03:40:06.343593Z","price_level":"64573","new_quantity":"0"},{"side":"offer","event_time":"2026-07-15T03:40:06.343593Z","price_level":"64573.07","new_quantity":"0"},{"side":"offer","event_time":"2026-07-15T03:40:06.343593Z","price_level":"64575.06","new_quantity":"0.00100881"},{"side":"offer","event_time":"2026-07-15T03:40:06.343593Z","price_level":"64575.07","new_quantity":"0"},{"side":"offer","event_time":"2026-07-15T03:40:06.343593Z","price_level":"64575.09","new_quantity":"0.04965717"},{"side":"offer","event_time":"2026-07-15T03:40:06.343593Z","price_level":"64575.1","new_quantity":"0"},{"side":"offer","event_time":"2026-07-15T03:40:06.343593Z","price_level":"64575.29","new_quantity":"0.1238864"},{"side":"offer","event_time":"2026-07-15T03:40:06.343593Z","price_level":"64575.43","new_quantity":"0.04656107"},{"side":"offer","event_time":"2026-07-15T03:40:06.343593Z","price_level":"64575.69","new_quantity":"0"},{"side":"offer","event_time":"2026-07-15T03:40:06.343593Z","price_level":"64575.99","new_quantity":"0"},{"side":"offer","event_time":"2026-07-15T03:40:06.343593Z","price_level":"64576.61","new_quantity":"0"},{"side":"offer","event_time":"2026-07-15T03:40:06.343593Z","price_level":"64576.62","new_quantity":"0"},{"side":"offer","event_time":"2026-07-15T03:40:06.343593Z","price_level":"64576.63","new_quantity":"0"},{"side":"offer","event_time":"2026-07-15T03:40:06.343593Z","price_level":"64578.6","new_quantity":"0.0352925"},{"side":"offer","event_time":"2026-07-15T03:40:06.343593Z","price_level":"64578.61","new_quantity":"0.03093532"},{"side":"offer","event_time":"2026-07-15T03:40:06.343593Z","price_level":"64579.67","new_quantity":"0"},{"side":"offer","event_time":"2026-07-15T03:40:06.343593Z","price_level":"64579.68","new_quantity":"0"},{"side":"offer","event_time":"2026-07-15T03:40:06.343593Z","price_level":"64579.69","new_quantity":"0"},{"side":"offer","event_time":"2026-07-15T03:40:06.343593Z","price_level":"64580.49","new_quantity":"0"},{"side":"offer","event_time":"2026-07-15T03:40:06.343593Z","price_level":"64582.47","new_quantity":"0.04626534"},{"side":"offer","event_time":"2026-07-15T03:40:06.343593Z","price_level":"64582.48","new_quantity":"0.04656107"},{"side":"offer","event_time":"2026-07-15T03:40:06.343593Z","price_level":"64582.49","new_quantity":"0"},{"side":"offer","event_time":"2026-07-15T03:40:06.343593Z","price_level":"64582.5","new_quantity":"0"},{"side":"offer","event_time":"2026-07-15T03:40:06.343593Z","price_level":"64583.84","new_quantity":"0.03093532"},{"side":"offer","event_time":"2026-07-15T03:40:06.343593Z","price_level":"64583.86","new_quantity":"0"},{"side":"offer","event_time":"2026-07-15T03:40:06.343593Z","price_level":"64584.23","new_quantity":"0"},{"side":"offer","event_time":"2026-07-15T03:40:06.343593Z","price_level":"64584.24","new_quantity":"0"},{"side":"offer","event_time":"2026-07-15T03:40:06.343593Z","price_level":"64584.25","new_quantity":"0"},{"side":"offer","event_time":"2026-07-15T03:40:06.343593Z","price_level":"64585.63","new_quantity":"0"},{"side":"offer","event_time":"2026-07-15T03:40:06.343593Z","price_level":"64587.63","new_quantity":"0.12378505"},{"side":"offer","event_time":"2026-07-15T03:40:06.343593Z","price_level":"64587.64","new_quantity":"0.31257488"},{"side":"offer","event_time":"2026-07-15T03:40:06.343593Z","price_level":"64587.67","new_quantity":"0"},{"side":"offer","event_time":"2026-07-15T03:40:06.343593Z","price_level":"64588.14","new_quantity":"0.04656107"},{"side":"offer","event_time":"2026-07-15T03:40:06.343593Z","price_level":"64589.76","new_quantity":"0"},{"side":"offer","event_time":"2026-07-15T03:40:06.343593Z","price_level":"64591.32","new_quantity":"0.09815222"},{"side":"offer","event_time":"2026-07-15T03:40:06.343593Z","price_level":"64591.33","new_quantity":"0"},{"side":"offer","event_time":"2026-07-15T03:40:06.343593Z","price_level":"64591.55","new_quantity":"0.12378505"},{"side":"offer","event_time":"2026-07-15T03:40:06.343593Z","price_level":"64593.54","new_quantity":"0"},{"side":"offer","event_time":"2026-07-15T03:40:06.343593Z","price_level":"64594.16","new_quantity":"0.63871558"},{"side":"offer","event_time":"2026-07-15T03:40:06.343593Z","price_level":"64594.17","new_quantity":"0.03093532"},{"side":"offer","event_time":"2026-07-15T03:40:06.343593Z","price_level":"64595.01","new_quantity":"0"},{"side":"offer","event_time":"2026-07-15T03:40:06.343593Z","price_level":"64595.42","new_quantity":"0.07389967"},{"side":"offer","event_time":"2026-07-15T03:40:06.343593Z","price_level":"64595.43","new_quantity":"0.12378505"},{"side":"offer","event_time":"2026-07-15T03:40:06.343593Z","price_level":"64597.49","new_quantity":"0.10951584"},{"side":"offer","event_time":"2026-07-15T03:40:06.343593Z","price_level":"64599.31","new_quantity":"0.12378505"},{"side":"offer","event_time":"2026-07-15T03:40:06.343593Z","price_level":"64599.81","new_quantity":"0"},{"side":"offer","event_time":"2026-07-15T03:40:06.343593Z","price_level":"64603.18","new_quantity":"0.07389967"},{"side":"offer","event_time":"2026-07-15T03:40:06.343593Z","price_level":"64603.19","new_quantity":"0.12378505"},{"side":"offer","event_time":"2026-07-15T03:40:06.343593Z","price_level":"64603.26","new_quantity":"0.95711953"},{"side":"offer","event_time":"2026-07-15T03:40:06.343593Z","price_level":"64605.73","new_quantity":"0.12378505"},{"side":"offer","event_time":"2026-07-15T03:40:06.343593Z","price_level":"64605.74","new_quantity":"1.43208296"},{"side":"offer","event_time":"2026-07-15T03:40:06.343593Z","price_level":"64606.47","new_quantity":"0"},{"side":"offer","event_time":"2026-07-15T03:40:06.343593Z","price_level":"64607.16","new_quantity":"0"},{"side":"offer","event_time":"2026-07-15T03:40:06.343593Z","price_level":"64608.62","new_quantity":"0.48054008"},{"side":"offer","event_time":"2026-07-15T03:40:06.343593Z","price_level":"64613.38","new_quantity":"1.2460253"},{"side":"offer","event_time":"2026-07-15T03:40:06.343593Z","price_level":"64613.4","new_quantity":"0"},{"side":"offer","event_time":"2026-07-15T03:40:06.343593Z","price_level":"64616.64","new_quantity":"0"},{"side":"offer","event_time":"2026-07-15T03:40:06.343593Z","price_level":"64619.41","new_quantity":"0.0278077"},{"side":"offer","event_time":"2026-07-15T03:40:06.343593Z","price_level":"64619.83","new_quantity":"0"},{"side":"offer","event_time":"2026-07-15T03:40:06.343593Z","price_level":"64623.02","new_quantity":"0"},{"side":"offer","event_time":"2026-07-15T03:40:06.343593Z","price_level":"64626.86","new_quantity":"0.03093532"},{"side":"offer","event_time":"2026-07-15T03:40:06.343593Z","price_level":"64628.12","new_quantity":"0.04656107"},{"side":"offer","event_time":"2026-07-15T03:40:06.343593Z","price_level":"64636.28","new_quantity":"0.04066243"},{"side":"offer","event_time":"2026-07-15T03:40:06.343593Z","price_level":"64637.19","new_quantity":"0.03093532"},{"side":"offer","event_time":"2026-07-15T03:40:06.343593Z","price_level":"64665","new_quantity":"3"},{"side":"offer","event_time":"2026-07-15T03:40:06.343593Z","price_level":"64701.9","new_quantity":"0"}]}]}
{"channel":"market_trades","timestamp":"2026-07-15T03:40:06.390624633Z","sequence_num":65,"events":[{"type":"update","trades":[{"product_id":"BTC-USD","trade_id":"1056309414","price":"64561.52","size":"0.048285","time":"2026-07-15T03:40:06.312534Z","side":"SELL"},{"product_id":"BTC-USD","trade_id":"1056309413","price":"64558.24","size":"0.0077","time":"2026-07-15T03:40:06.310399Z","side":"SELL"},{"product_id":"BTC-USD","trade_id":"1056309412","price":"64559.86","size":"0.00774516","time":"2026-07-15T03:40:06.303414Z","side":"SELL"},{"product_id":"BTC-USD","trade_id":"1056309411","price":"64558.84","size":"0.03093532","time":"2026-07-15T03:40:06.302479Z","side":"SELL"},{"product_id":"BTC-USD","trade_id":"1056309410","price":"64558.24","size":"0.00774516","time":"2026-07-15T03:40:06.302203Z","side":"SELL"},{"product_id":"BTC-USD","trade_id":"1056309409","price":"64557.99","size":"0.00159977","time":"2026-07-15T03:40:06.302203Z","side":"SELL"},{"product_id":"BTC-USD","trade_id":"1056309408","price":"64554.57","size":"0.00939446","time":"2026-07-15T03:40:06.301415Z","side":"SELL"},{"product_id":"BTC-USD","trade_id":"1056309407","price":"64554.57","size":"0.03707776","time":"2026-07-15T03:40:06.301389Z","side":"SELL"},{"product_id":"BTC-USD","trade_id":"1056309406","price":"64554.57","size":"0.02608","time":"2026-07-15T03:40:06.301389Z","side":"SELL"}]}]}
{"channel":"l2_data","timestamp":"2026-07-15T03:40:06.446431726Z","sequence_num":66,"events":[{"type":"update","product_id":"BTC-USD","updates":[{"side":"bid","event_time":"2026-07-15T03:40:06.400165Z","price_level":"64563.11","new_quantity":"0.14210197"},{"side":"bid","event_time":"2026-07-15T03:40:06.400165Z","price_level":"64563.02","new_quantity":"0"},{"side":"bid","event_time":"2026-07-15T03:40:06.400165Z","price_level":"64562.03","new_quantity":"0"},{"side":"bid","event_time":"2026-07-15T03:40:06.400165Z","price_level":"64562.02","new_quantity":"0"},{"side":"bid","event_time":"2026-07-15T03:40:06.400165Z","price_level":"64561.52","new_quantity":"0"},{"side":"bid","event_time":"2026-07-15T03:40:06.400165Z","price_level":"64561.51","new_quantity":"0"},{"side":"bid","event_time":"2026-07-15T03:40:06.400165Z","price_level":"64558.23","new_quantity":"0"},{"side":"bid","event_time":"2026-07-15T03:40:06.400165Z","price_level":"64558.02","new_quantity":"0"},{"side":"bid","event_time":"2026-07-15T03:40:06.400165Z","price_level":"64558.01","new_quantity":"0"},{"side":"bid","event_time":"2026-07-15T03:40:06.400165Z","price_level":"64557.19","new_quantity":"0.08477184"},{"side":"bid","event_time":"2026-07-15T03:40:06.400165Z","price_level":"64557.17","new_quantity":"0"},{"side":"bid","event_time":"2026-07-15T03:40:06.400165Z","price_level":"64556.32","new_quantity":"0"},{"side":"bid","event_time":"2026-07-15T03:40:06.400165Z","price_level":"64556","new_quantity":"0.0645"},{"side":"bid","event_time":"2026-07-15T03:40:06.400165Z","price_level":"64555.13","new_quantity":"0.03093532"},{"side":"bid","event_time":"2026-07-15T03:40:06.400165Z","price_level":"64555.12","new_quantity":"0"},{"side":"bid","event_time":"2026-07-15T03:40:06.400165Z","price_level":"64554.58","new_quantity":"0.12182892"},{"side":"bid","event_time":"2026-07-15T03:40:06.400165Z","price_level":"64554.01","new_quantity":"0"},{"side":"bid","event_time":"2026-07-15T03:40:06.400165Z","price_level":"64553.84","new_quantity":"0.12378505"},{"side":"bid","event_time":"2026-07-15T03:40:06.400165Z","price_level":"64551.84","new_quantity":"0"},{"side":"bid","event_time":"2026-07-15T03:40:06.400165Z","price_level":"64551.02","new_quantity":"0.14152708"},{"side":"bid","event_time":"2026-07-15T03:40:06.400165Z","price_level":"64551.01","new_quantity":"0"},{"side":"bid","event_time":"2026-07-15T03:40:06.400165Z","price_level":"64549.96","new_quantity":"0.12378505"},{"side":"bid","event_time":"2026-07-15T03:40:06.400165Z","price_level":"64548.29","new_quantity":"0.1597501"},{"side":"bid","event_time":"2026-07-15T03:40:06.400165Z","price_level":"64548.28","new_quantity":"0"},{"side":"bid","event_time":"2026-07-15T03:40:06.400165Z","price_level":"64547.98","new_quantity":"0"},{"side":"bid","event_time":"2026-07-15T03:40:06.400165Z","price_level":"64547.21","new_quantity":"0.00772597"},{"side":"bid","event_time":"2026-07-15T03:40:06.400165Z","price_level":"64544.34","new_quantity":"0.23643855"},{"side":"bid","event_time":"2026-07-15T03:40:06.400165Z","price_level":"64544.09","new_quantity":"0.14"},{"side":"bid","event_time":"2026-07-15T03:40:06.400165Z","price_level":"64541.39","new_quantity":"0.15279372"},{"side":"bid","event_time":"2026-07-15T03:40:06.400165Z","price_level":"64540.81","new_quantity":"0"},{"side":"bid","event_time":"2026-07-15T03:40:06.400165Z","price_level":"64538.98","new_quantity":"0"},{"side":"bid","event_time":"2026-07-15T03:40:06.400165Z","price_level":"64528.69","new_quantity":"1.16914355"},{"side":"bid","event_time":"2026-07-15T03:40:06.400165Z","price_level":"64528.68","new_quantity":"0.93197573"},{"side":"bid","event_time":"2026-07-15T03:40:06.400165Z","price_level":"64528.67","new_quantity":"0"},{"side":"bid","event_time":"2026-07-15T03:40:06.400165Z","price_level":"64527.75","new_quantity":"0.60999194"},{"side":"bid","event_time":"2026-07-15T03:40:06.400165Z","price_level":"64527.59","new_quantity":"0.04441421"},{"side":"bid","event_time":"2026-07-15T03:40:06.400165Z","price_level":"64527","new_quantity":"1"},{"side":"bid","event_time":"2026-07-15T03:40:06.400165Z","price_level":"64516.76","new_quantity":"0.06224528"},{"side":"bid","event_time":"2026-07-15T03:40:06.400165Z","price_level":"64516.55","new_quantity":"0"},{"side":"bid","event_time":"2026-07-15T03:40:06.400165Z","price_level":"64516.54","new_quantity":"0"},{"side":"bid","event_time":"2026-07-15T03:40:06.400165Z","price_level":"64512.53","new_quantity":"0.41243792"},{"side":"bid","event_time":"2026-07-15T03:40:06.400165Z","price_level":"64512.52","new_quantity":"0.00077437"},{"side":"bid","event_time":"2026-07-15T03:40:06.400165Z","price_level":"64511.39","new_quantity":"0.2633505"},{"side":"bid","event_time":"2026-07-15T03:40:06.400165Z","price_level":"64506.15","new_quantity":"0.08670458"},{"side":"bid","event_time":"2026-07-15T03:40:06.400165Z","price_level":"64504.95","new_quantity":"0"},{"side":"bid","event_time":"2026-07-15T03:40:06.400165Z","price_level":"64498.91","new_quantity":"0"},{"side":"bid","event_time":"2026-07-15T03:40:06.400165Z","price_level":"64498.9","new_quantity":"0"},{"side":"bid","event_time":"2026-07-15T03:40:06.400165Z","price_level":"64491.01","new_quantity":"0.94452993"},{"side":"bid","event_time":"2026-07-15T03:40:06.400165Z","price_level":"64491","new_quantity":"1.35007018"},{"side":"bid","event_time":"2026-07-15T03:40:06.400165Z","price_level":"64490.99","new_quantity":"0"},{"side":"bid","event_time":"2026-07-15T03:40:06.400165Z","price_level":"64486.32","new_quantity":"0"},{"side":"bid","event_time":"2026-07-15T03:40:06.400165Z","price_level":"64486.31","new_quantity":"0"},{"side":"bid","event_time":"2026-07-15T03:40:06.400165Z","price_level":"64486.28","new_quantity":"0.0406119"},{"side":"bid","event_time":"2026-07-15T03:40:06.400165Z","price_level":"64470.02","new_quantity":"1.07108099"},{"side":"bid","event_time":"2026-07-15T03:40:06.400165Z","price_level":"64462.96","new_quantity":"0"},{"side":"bid","event_time":"2026-07-15T03:40:06.400165Z","price_level":"64363.2","new_quantity":"0.000018"},{"side":"offer","event_time":"2026-07-15T03:40:06.400165Z","price_level":"64563.12","new_quantity":"0.00790216"},{"side":"offer","event_time":"2026-07-15T03:40:06.400165Z","price_level":"64564.52","new_quantity":"0"},{"side":"offer","event_time":"2026-07-15T03:40:06.400165Z","price_level":"64564.74","new_quantity":"0.00774465"},{"side":"offer","event_time":"2026-07-15T03:40:06.400165Z","price_level":"64565.03","new_quantity":"0"},{"side":"offer","event_time":"2026-07-15T03:40:06.400165Z","price_level":"64566","new_quantity":"0"},{"side":"offer","event_time":"2026-07-15T03:40:06.400165Z","price_level":"64571.2","new_quantity":"0"},{"side":"offer","event_time":"2026-07-15T03:40:06.400165Z","price_level":"64572.96","new_quantity":"0.000018"},{"side":"offer","event_time":"2026-07-15T03:40:06.400165Z","price_level":"64573.99","new_quantity":"0.00772597"},{"side":"offer","event_time":"2026-07-15T03:40:06.400165Z","price_level":"64575.06","new_quantity":"0"},{"side":"offer","event_time":"2026-07-15T03:40:06.400165Z","price_level":"64575.09","new_quantity":"0.14150995"},{"side":"offer","event_time":"2026-07-15T03:40:06.400165Z","price_level":"64575.29","new_quantity":"0"},{"side":"offer","event_time":"2026-07-15T03:40:06.400165Z","price_level":"64575.42","new_quantity":"0.00038328"},{"side":"offer","event_time":"2026-07-15T03:40:06.400165Z","price_level":"64575.88","new_quantity":"0.00100879"},{"side":"offer","event_time":"2026-07-15T03:40:06.400165Z","price_level":"64577.03","new_quantity":"0.03093532"},{"side":"offer","event_time":"2026-07-15T03:40:06.400165Z","price_level":"64577.04","new_quantity":"0.12388305"},{"side":"offer","event_time":"2026-07-15T03:40:06.400165Z","price_level":"64577.72","new_quantity":"0.11066259"},{"side":"offer","event_time":"2026-07-15T03:40:06.400165Z","price_level":"64578.5","new_quantity":"0.00159977"},{"side":"offer","event_time":"2026-07-15T03:40:06.400165Z","price_level":"64578.58","new_quantity":"0"},{"side":"offer","event_time":"2026-07-15T03:40:06.400165Z","price_level":"64578.6","new_quantity":"0"},{"side":"offer","event_time":"2026-07-15T03:40:06.400165Z","price_level":"64578.61","new_quantity":"0"},{"side":"offer","event_time":"2026-07-15T03:40:06.400165Z","price_level":"64580.11","new_quantity":"0.15484643"},{"side":"offer","event_time":"2026-07-15T03:40:06.400165Z","price_level":"64581.16","new_quantity":"0.19406469"},{"side":"offer","event_time":"2026-07-15T03:40:06.400165Z","price_level":"64581.17","new_quantity":"0.12378505"},{"side":"offer","event_time":"2026-07-15T03:40:06.400165Z","price_level":"64582.47","new_quantity":"0"},{"side":"offer","event_time":"2026-07-15T03:40:06.400165Z","price_level":"64583.2","new_quantity":"0.12378505"},{"side":"offer","event_time":"2026-07-15T03:40:06.400165Z","price_level":"64583.85","new_quantity":"0"},{"side":"offer","event_time":"2026-07-15T03:40:06.400165Z","price_level":"64586.85","new_quantity":"0"},{"side":"offer","event_time":"2026-07-15T03:40:06.400165Z","price_level":"64587.63","new_quantity":"0"},{"side":"offer","event_time":"2026-07-15T03:40:06.400165Z","price_level":"64587.64","new_quantity":"0.13715805"},{"side":"offer","event_time":"2026-07-15T03:40:06.400165Z","price_level":"64588.29","new_quantity":"0.12378505"},{"side":"offer","event_time":"2026-07-15T03:40:06.400165Z","price_level":"64589.59","new_quantity":"0"},{"side":"offer","event_time":"2026-07-15T03:40:06.400165Z","price_level":"64591.3","new_quantity":"0.1836301"},{"side":"offer","event_time":"2026-07-15T03:40:06.400165Z","price_level":"64591.31","new_quantity":"0.12378505"},{"side":"offer","event_time":"2026-07-15T03:40:06.400165Z","price_level":"64591.32","new_quantity":"0"},{"side":"offer","event_time":"2026-07-15T03:40:06.400165Z","price_level":"64591.55","new_quantity":"0"},{"side":"offer","event_time":"2026-07-15T03:40:06.400165Z","price_level":"64591.73","new_quantity":"0.02"},{"side":"offer","event_time":"2026-07-15T03:40:06.400165Z","price_level":"64593.46","new_quantity":"0.12378505"},{"side":"offer","event_time":"2026-07-15T03:40:06.400165Z","price_level":"64594.15","new_quantity":"0.47368126"},{"side":"offer","event_time":"2026-07-15T03:40:06.400165Z","price_level":"64595","new_quantity":"0.0007743"},{"side":"offer","event_time":"2026-07-15T03:40:06.400165Z","price_level":"64595.42","new_quantity":"0"},{"side":"offer","event_time":"2026-07-15T03:40:06.400165Z","price_level":"64603.26","new_quantity":"0"},{"side":"offer","event_time":"2026-07-15T03:40:06.400165Z","price_level":"64603.38","new_quantity":"0.14840162"},{"side":"offer","event_time":"2026-07-15T03:40:06.400165Z","price_level":"64604.65","new_quantity":"0.00077437"},{"side":"offer","event_time":"2026-07-15T03:40:06.400165Z","price_level":"64605.74","new_quantity":"0"},{"side":"offer","event_time":"2026-07-15T03:40:06.400165Z","price_level":"64605.75","new_quantity":"0"},{"side":"offer","event_time":"2026-07-15T03:40:06.400165Z","price_level":"64607.16","new_quantity":"0.15227409"},{"side":"offer","event_time":"2026-07-15T03:40:06.400165Z","price_level":"64608.61","new_quantity":"0.12378505"},{"side":"offer","event_time":"2026-07-15T03:40:06.400165Z","price_level":"64608.62","new_quantity":"0"},{"side":"offer","event_time":"2026-07-15T03:40:06.400165Z","price_level":"64608.63","new_quantity":"0"},{"side":"offer","event_time":"2026-07-15T03:40:06.400165Z","price_level":"64608.64","new_quantity":"0"},{"side":"offer","event_time":"2026-07-15T03:40:06.400165Z","price_level":"64613.38","new_quantity":"0.0357143"},{"side":"offer","event_time":"2026-07-15T03:40:06.400165Z","price_level":"64613.39","new_quantity":"0"},{"side":"offer","event_time":"2026-07-15T03:40:06.400165Z","price_level":"64614.7","new_quantity":"0"},{"side":"offer","event_time":"2026-07-15T03:40:06.400165Z","price_level":"64616.5","new_quantity":"0.87329328"},{"side":"offer","event_time":"2026-07-15T03:40:06.400165Z","price_level":"64616.51","new_quantity":"1.43184427"},{"side":"offer","event_time":"2026-07-15T03:40:06.400165Z","price_level":"64616.52","new_quantity":"0"},{"side":"offer","event_time":"2026-07-15T03:40:06.400165Z","price_level":"64619.39","new_quantity":"1.61532921"},{"side":"offer","event_time":"2026-07-15T03:40:06.400165Z","price_level":"64619.4","new_quantity":"0.4587693"},{"side":"offer","event_time":"2026-07-15T03:40:06.400165Z","price_level":"64619.41","new_quantity":"0"},{"side":"offer","event_time":"2026-07-15T03:40:06.400165Z","price_level":"64621.15","new_quantity":"0.2633505"},{"side":"offer","event_time":"2026-07-15T03:40:06.400165Z","price_level":"64621.67","new_quantity":"2.02706185"},{"side":"offer","event_time":"2026-07-15T03:40:06.400165Z","price_level":"64628.13","new_quantity":"0.89889166"},{"side":"offer","event_time":"2026-07-15T03:40:06.400165Z","price_level":"64629","new_quantity":"0"},{"side":"offer","event_time":"2026-07-15T03:40:06.400165Z","price_level":"64665","new_quantity":"0"},{"side":"offer","event_time":"2026-07-15T03:40:06.400165Z","price_level":"64683.36","new_quantity":"0"}]}]}
{"channel":"l2_data","timestamp":"2026-07-15T03:40:06.487169738Z","sequence_num":67,"events":[{"type":"update","product_id":"BTC-USD","updates":[{"side":"bid","event_time":"2026-07-15T03:40:06.438633Z","price_level":"64564.93","new_quantity":"0.0334"},{"side":"bid","event_time":"2026-07-15T03:40:06.438633Z","price_level":"64564.74","new_quantity":"0.00159977"},{"side":"bid","event_time":"2026-07-15T03:40:06.438633Z","price_level":"64564.23","new_quantity":"0.04647362"},{"side":"bid","event_time":"2026-07-15T03:40:06.438633Z","price_level":"64563.11","new_quantity":"0.10789"},{"side":"bid","event_time":"2026-07-15T03:40:06.438633Z","price_level":"64562","new_quantity":"0.0245"},{"side":"bid","event_time":"2026-07-15T03:40:06.438633Z","price_level":"64560","new_quantity":"0.0245"},{"side":"bid","event_time":"2026-07-15T03:40:06.438633Z","price_level":"64557.77","new_quantity":"0.12378505"},{"side":"bid","event_time":"2026-07-15T03:40:06.438633Z","price_level":"64557.19","new_quantity":"0.20371199"},{"side":"bid","event_time":"2026-07-15T03:40:06.438633Z","price_level":"64556.57","new_quantity":"0"},{"side":"bid","event_time":"2026-07-15T03:40:06.438633Z","price_level":"64555.81","new_quantity":"0.12378505"},{"side":"bid","event_time":"2026-07-15T03:40:06.438633Z","price_level":"64549.76","new_quantity":"0.04697585"},{"side":"bid","event_time":"2026-07-15T03:40:06.438633Z","price_level":"64541.41","new_quantity":"0"},{"side":"bid","event_time":"2026-07-15T03:40:06.438633Z","price_level":"64531.36","new_quantity":"0.93193703"},{"side":"bid","event_time":"2026-07-15T03:40:06.438633Z","price_level":"64528.68","new_quantity":"0"},{"side":"bid","event_time":"2026-07-15T03:40:06.438633Z","price_level":"64527","new_quantity":"0"},{"side":"bid","event_time":"2026-07-15T03:40:06.438633Z","price_level":"64476.81","new_quantity":"0.01061683"},{"side":"bid","event_time":"2026-07-15T03:40:06.438633Z","price_level":"64476.27","new_quantity":"1.9535526"},{"side":"bid","event_time":"2026-07-15T03:40:06.438633Z","price_level":"64476.26","new_quantity":"2.15592185"},{"side":"bid","event_time":"2026-07-15T03:40:06.438633Z","price_level":"64476.25","new_quantity":"0"},{"side":"bid","event_time":"2026-07-15T03:40:06.438633Z","price_level":"64470.02","new_quantity":"0"},{"side":"bid","event_time":"2026-07-15T03:40:06.438633Z","price_level":"64468.3","new_quantity":"0"},{"side":"offer","event_time":"2026-07-15T03:40:06.438633Z","price_level":"64563.12","new_quantity":"0"},{"side":"offer","event_time":"2026-07-15T03:40:06.438633Z","price_level":"64564.74","new_quantity":"0"},{"side":"offer","event_time":"2026-07-15T03:40:06.438633Z","price_level":"64566.9","new_quantity":"0.01140846"},{"side":"offer","event_time":"2026-07-15T03:40:06.438633Z","price_level":"64566.91","new_quantity":"0.00774413"},{"side":"offer","event_time":"2026-07-15T03:40:06.438633Z","price_level":"64566.92","new_quantity":"0"},{"side":"offer","event_time":"2026-07-15T03:40:06.438633Z","price_level":"64567.99","new_quantity":"0.0396553"},{"side":"offer","event_time":"2026-07-15T03:40:06.438633Z","price_level":"64568","new_quantity":"0.0245"},{"side":"offer","event_time":"2026-07-15T03:40:06.438633Z","price_level":"64568.52","new_quantity":"0"},{"side":"offer","event_time":"2026-07-15T03:40:06.438633Z","price_level":"64568.53","new_quantity":"0.00774413"},{"side":"offer","event_time":"2026-07-15T03:40:06.438633Z","price_level":"64569.97","new_quantity":"0"},{"side":"offer","event_time":"2026-07-15T03:40:06.438633Z","price_level":"64569.98","new_quantity":"0"},{"side":"offer","event_time":"2026-07-15T03:40:06.438633Z","price_level":"64569.99","new_quantity":"0"},{"side":"offer","event_time":"2026-07-15T03:40:06.438633Z","price_level":"64570.71","new_quantity":"0.00968016"},{"side":"offer","event_time":"2026-07-15T03:40:06.438633Z","price_level":"64572.95","new_quantity":"0.00772597"},{"side":"offer","event_time":"2026-07-15T03:40:06.438633Z","price_level":"64573.99","new_quantity":"0"},{"side":"offer","event_time":"2026-07-15T03:40:06.438633Z","price_level":"64575.09","new_quantity":"0.22635134"},{"side":"offer","event_time":"2026-07-15T03:40:06.438633Z","price_level":"64575.31","new_quantity":"0.12388637"},{"side":"offer","event_time":"2026-07-15T03:40:06.438633Z","price_level":"64575.81","new_quantity":"0.00100876"},{"side":"offer","event_time":"2026-07-15T03:40:06.438633Z","price_level":"64575.88","new_quantity":"0"},{"side":"offer","event_time":"2026-07-15T03:40:06.438633Z","price_level":"64577.71","new_quantity":"0.00159977"},{"side":"offer","event_time":"2026-07-15T03:40:06.438633Z","price_level":"64577.72","new_quantity":"0.01728175"},{"side":"offer","event_time":"2026-07-15T03:40:06.438633Z","price_level":"64578.5","new_quantity":"0"},{"side":"offer","event_time":"2026-07-15T03:40:06.438633Z","price_level":"64580.11","new_quantity":"0"},{"side":"offer","event_time":"2026-07-15T03:40:06.438633Z","price_level":"64591.97","new_quantity":"0.06637877"},{"side":"offer","event_time":"2026-07-15T03:40:06.438633Z","price_level":"64594.15","new_quantity":"0"},{"side":"offer","event_time":"2026-07-15T03:40:06.438633Z","price_level":"64594.16","new_quantity":"0"},{"side":"offer","event_time":"2026-07-15T03:40:06.438633Z","price_level":"64594.99","new_quantity":"0.07436193"},{"side":"offer","event_time":"2026-07-15T03:40:06.438633Z","price_level":"64597.47","new_quantity":"0.4830041"},{"side":"offer","event_time":"2026-07-15T03:40:06.438633Z","price_level":"64597.48","new_quantity":"0.63868275"},{"side":"offer","event_time":"2026-07-15T03:40:06.438633Z","price_level":"64597.49","new_quantity":"0"},{"side":"offer","event_time":"2026-07-15T03:40:06.438633Z","price_level":"64604.84","new_quantity":"0.0608935"},{"side":"offer","event_time":"2026-07-15T03:40:06.438633Z","price_level":"64616.5","new_quantity":"1.35864446"},{"side":"offer","event_time":"2026-07-15T03:40:06.438633Z","price_level":"64618.5","new_quantity":"1"},{"side":"offer","event_time":"2026-07-15T03:40:06.438633Z","price_level":"64621.15","new_quantity":"0"},{"side":"offer","event_time":"2026-07-15T03:40:06.438633Z","price_level":"64685","new_quantity":"3"},{"side":"offer","event_time":"2026-07-15T03:40:06.438633Z","price_level":"64816.9","new_quantity":"0.05"},{"side":"offer","event_time":"2026-07-15T03:40:06.438633Z","price_level":"65222.4","new_quantity":"0.3"}]}]}
{"channel":"market_trades","timestamp":"2026-07-15T03:40:06.529545522Z","sequence_num":68,"events":[{"type":"update","trades":[{"product_id":"BTC-USD","trade_id":"1056309420","price":"64564.74","size":"0.00774465","time":"2026-07-15T03:40:06.398603Z","side":"SELL"},{"product_id":"BTC-USD","trade_id":"1056309419","price":"64563.12","size":"0.00774465","time":"2026-07-15T03:40:06.398603Z","side":"SELL"},{"product_id":"BTC-USD","trade_id":"1056309418","price":"64563.12","size":"0.00015751","time":"2026-07-15T03:40:06.398603Z","side":"SELL"},{"product_id":"BTC-USD","trade_id":"1056309417","price":"64563.12","size":"0.01","time":"2026-07-15T03:40:06.389858Z","side":"SELL"},{"product_id":"BTC-USD","trade_id":"1056309416","price":"64563.12","size":"0.00225535","time":"2026-07-15T03:40:06.383965Z","side":"SELL"},{"product_id":"BTC-USD","trade_id":"1056309415","price":"64563.12","size":"0.00774465","time":"2026-07-15T03:40:06.383965Z","side":"SELL"}]}]}
{"channel":"l2_data","timestamp":"2026-07-15T03:40:06.533173055Z","sequence_num":69,"events":[{"type":"update","product_id":"BTC-USD","updates":[{"side":"bid","event_time":"2026-07-15T03:40:06.496438Z","price_level":"64564","new_quantity":"0.0245"},{"side":"bid","event_time":"2026-07-15T03:40:06.496438Z","price_level":"64563.12","new_quantity":"0.04656107"},{"side":"bid","event_time":"2026-07-15T03:40:06.496438Z","price_level":"64561.51","new_quantity":"0.62793532"},{"side":"bid","event_time":"2026-07-15T03:40:06.496438Z","price_level":"64561.5","new_quantity":"1"},{"side":"bid","event_time":"2026-07-15T03:40:06.496438Z","price_level":"64560.01","new_quantity":"0.0385065"},{"side":"bid","event_time":"2026-07-15T03:40:06.496438Z","price_level":"64559.17","new_quantity":"0.06"},{"side":"bid","event_time":"2026-07-15T03:40:06.496438Z","price_level":"64548.29","new_quantity":"0.07852282"},{"side":"bid","event_time":"2026-07-15T03:40:06.496438Z","price_level":"64546.83","new_quantity":"0"},{"side":"bid","event_time":"2026-07-15T03:40:06.496438Z","price_level":"64543.01","new_quantity":"0"},{"side":"bid","event_time":"2026-07-15T03:40:06.496438Z","price_level":"64531.37","new_quantity":"0.60866921"},{"side":"bid","event_time":"2026-07-15T03:40:06.496438Z","price_level":"64531.35","new_quantity":"0"},{"side":"bid","event_time":"2026-07-15T03:40:06.496438Z","price_level":"64528.71","new_quantity":"0.46408241"},{"side":"bid","event_time":"2026-07-15T03:40:06.496438Z","price_level":"64528.7","new_quantity":"0.60998296"},{"side":"bid","event_time":"2026-07-15T03:40:06.496438Z","price_level":"64528.69","new_quantity":"0"},{"side":"bid","event_time":"2026-07-15T03:40:06.496438Z","price_level":"64527.75","new_quantity":"0"},{"side":"bid","event_time":"2026-07-15T03:40:06.496438Z","price_level":"64526.19","new_quantity":"0.0005"},{"side":"bid","event_time":"2026-07-15T03:40:06.496438Z","price_level":"64491.03","new_quantity":"0.94452968"},{"side":"bid","event_time":"2026-07-15T03:40:06.496438Z","price_level":"64491.02","new_quantity":"1.35006976"},{"side":"bid","event_time":"2026-07-15T03:40:06.496438Z","price_level":"64491.01","new_quantity":"0"},{"side":"bid","event_time":"2026-07-15T03:40:06.496438Z","price_level":"64491","new_quantity":"0"},{"side":"bid","event_time":"2026-07-15T03:40:06.496438Z","price_level":"64489.27","new_quantity":"1.5456695"},{"side":"bid","event_time":"2026-07-15T03:40:06.496438Z","price_level":"64488.15","new_quantity":"1.371572"},{"side":"bid","event_time":"2026-07-15T03:40:06.496438Z","price_level":"64476.27","new_quantity":"1.3051657"},{"side":"bid","event_time":"2026-07-15T03:40:06.496438Z","price_level":"64472.86","new_quantity":"5.107734"},{"side":"bid","event_time":"2026-07-15T03:40:06.496438Z","price_level":"64468.3","new_quantity":"0.18350745"},{"side":"bid","event_time":"2026-07-15T03:40:06.496438Z","price_level":"64462.96","new_quantity":"0.09314135"},{"side":"bid","event_time":"2026-07-15T03:40:06.496438Z","price_level":"64457.94","new_quantity":"11.711026"},{"side":"bid","event_time":"2026-07-15T03:40:06.496438Z","price_level":"64438.44","new_quantity":"12.008406"},{"side":"offer","event_time":"2026-07-15T03:40:06.496438Z","price_level":"64566.9","new_quantity":"0.02403908"},{"side":"offer","event_time":"2026-07-15T03:40:06.496438Z","price_level":"64567.99","new_quantity":"0.0250288"},{"side":"offer","event_time":"2026-07-15T03:40:06.496438Z","price_level":"64568","new_quantity":"0"},{"side":"offer","event_time":"2026-07-15T03:40:06.496438Z","price_level":"64574.17","new_quantity":"0.022498"},{"side":"offer","event_time":"2026-07-15T03:40:06.496438Z","price_level":"64575.72","new_quantity":"0.00100876"},{"side":"offer","event_time":"2026-07-15T03:40:06.496438Z","price_level":"64575.81","new_quantity":"0"},{"side":"offer","event_time":"2026-07-15T03:40:06.496438Z","price_level":"64587.31","new_quantity":"0.05906191"},{"side":"offer","event_time":"2026-07-15T03:40:06.496438Z","price_level":"64591.3","new_quantity":"0.25948148"},{"side":"offer","event_time":"2026-07-15T03:40:06.496438Z","price_level":"64591.73","new_quantity":"0.16"},{"side":"offer","event_time":"2026-07-15T03:40:06.496438Z","price_level":"64594.8","new_quantity":"0.34220777"},{"side":"offer","event_time":"2026-07-15T03:40:06.496438Z","price_level":"64594.81","new_quantity":"0.448653"},{"side":"offer","event_time":"2026-07-15T03:40:06.496438Z","price_level":"64594.99","new_quantity":"0"},{"side":"offer","event_time":"2026-07-15T03:40:06.496438Z","price_level":"64595","new_quantity":"0"},{"side":"offer","event_time":"2026-07-15T03:40:06.496438Z","price_level":"64597.47","new_quantity":"1.01825298"},{"side":"offer","event_time":"2026-07-15T03:40:06.496438Z","price_level":"64597.5","new_quantity":"1"},{"side":"offer","event_time":"2026-07-15T03:40:06.496438Z","price_level":"64604.65","new_quantity":"0"},{"side":"offer","event_time":"2026-07-15T03:40:06.496438Z","price_level":"64604.84","new_quantity":"0"},{"side":"offer","event_time":"2026-07-15T03:40:06.496438Z","price_level":"64608.61","new_quantity":"0.12378505"},{"side":"offer","event_time":"2026-07-15T03:40:06.496438Z","price_level":"64614.66","new_quantity":"0.01164444"},{"side":"offer","event_time":"2026-07-15T03:40:06.496438Z","price_level":"64616.5","new_quantity":"0.87329328"},{"side":"offer","event_time":"2026-07-15T03:40:06.496438Z","price_level":"64616.51","new_quantity":"0"},{"side":"offer","event_time":"2026-07-15T03:40:06.496438Z","price_level":"64618.5","new_quantity":"0"},{"side":"offer","event_time":"2026-07-15T03:40:06.496438Z","price_level":"64619.38","new_quantity":"1.43178067"},{"side":"offer","event_time":"2026-07-15T03:40:06.496438Z","price_level":"64619.39","new_quantity":"0.30169298"},{"side":"offer","event_time":"2026-07-15T03:40:06.496438Z","price_level":"64621.67","new_quantity":"0"},{"side":"offer","event_time":"2026-07-15T03:40:06.496438Z","price_level":"64626.58","new_quantity":"2.30357739"},{"side":"offer","event_time":"2026-07-15T03:40:06.496438Z","price_level":"64626.59","new_quantity":"2.0899151"},{"side":"offer","event_time":"2026-07-15T03:40:06.496438Z","price_level":"64628.13","new_quantity":"0"},{"side":"offer","event_time":"2026-07-15T03:40:06.496438Z","price_level":"64654.55","new_quantity":"0"},{"side":"offer","event_time":"2026-07-15T03:40:06.496438Z","price_level":"64685","new_quantity":"0"},{"side":"offer","event_time":"2026-07-15T03:40:06.496438Z","price_level":"64967.49","new_quantity":"0.01061683"}]}]}
{"channel":"l2_data","timestamp":"2026-07-15T03:40:06.58140707Z","sequence_num":70,"events":[{"type":"update","product_id":"BTC-USD","updates":[{"side":"bid","event_time":"2026-07-15T03:40:06.54526Z","price_level":"64564.23","new_quantity":"0"},{"side":"bid","event_time":"2026-07-15T03:40:06.54526Z","price_level":"64563.15","new_quantity":"0.04647362"},{"side":"bid","event_time":"2026-07-15T03:40:06.54526Z","price_level":"64531.39","new_quantity":"0.60866904"},{"side":"bid","event_time":"2026-07-15T03:40:06.54526Z","price_level":"64531.38","new_quantity":"0.93193674"},{"side":"bid","event_time":"2026-07-15T03:40:06.54526Z","price_level":"64531.37","new_quantity":"0"},{"side":"bid","event_time":"2026-07-15T03:40:06.54526Z","price_level":"64531.36","new_quantity":"0"},{"side":"bid","event_time":"2026-07-15T03:40:06.54526Z","price_level":"64476.28","new_quantity":"2.07570637"},{"side":"bid","event_time":"2026-07-15T03:40:06.54526Z","price_level":"64476.27","new_quantity":"0.83333012"},{"side":"bid","event_time":"2026-07-15T03:40:06.54526Z","price_level":"64476.26","new_quantity":"0"},{"side":"bid","event_time":"2026-07-15T03:40:06.54526Z","price_level":"64472.87","new_quantity":"0.10504284"},{"side":"offer","event_time":"2026-07-15T03:40:06.54526Z","price_level":"64571.19","new_quantity":"0.05780396"},{"side":"offer","event_time":"2026-07-15T03:40:06.54526Z","price_level":"64572.82","new_quantity":"0.00772597"},{"side":"offer","event_time":"2026-07-15T03:40:06.54526Z","price_level":"64572.83","new_quantity":"0.04647362"},{"side":"offer","event_time":"2026-07-15T03:40:06.54526Z","price_level":"64572.95","new_quantity":"0"},{"side":"offer","event_time":"2026-07-15T03:40:06.54526Z","price_level":"64575.65","new_quantity":"0.00100876"},{"side":"offer","event_time":"2026-07-15T03:40:06.54526Z","price_level":"64575.72","new_quantity":"0"},{"side":"offer","event_time":"2026-07-15T03:40:06.54526Z","price_level":"64591.73","new_quantity":"0.2"},{"side":"offer","event_time":"2026-07-15T03:40:06.54526Z","price_level":"64597.45","new_quantity":"0.48300422"},{"side":"offer","event_time":"2026-07-15T03:40:06.54526Z","price_level":"64597.46","new_quantity":"0.63868295"},{"side":"offer","event_time":"2026-07-15T03:40:06.54526Z","price_level":"64597.47","new_quantity":"0"},{"side":"offer","event_time":"2026-07-15T03:40:06.54526Z","price_level":"64597.48","new_quantity":"0"},{"side":"offer","event_time":"2026-07-15T03:40:06.54526Z","price_level":"64597.5","new_quantity":"0"},{"side":"offer","event_time":"2026-07-15T03:40:06.54526Z","price_level":"64619.39","new_quantity":"0.42034237"},{"side":"offer","event_time":"2026-07-15T03:40:06.54526Z","price_level":"64621.15","new_quantity":"0.2633505"},{"side":"offer","event_time":"2026-07-15T03:40:06.54526Z","price_level":"64680","new_quantity":"0"},{"side":"offer","event_time":"2026-07-15T03:40:06.54526Z","price_level":"64805.22","new_quantity":"0.86101853"},{"side":"offer","event_time":"2026-07-15T03:40:06.54526Z","price_level":"65222.4","new_quantity":"1.8"}]}]}
{"channel":"l2_data","timestamp":"2026-07-15T03:40:06.630645883Z","sequence_num":71,"events":[{"type":"update","product_id":"BTC-USD","updates":[{"side":"bid","event_time":"2026-07-15T03:40:06.602288Z","price_level":"64564.94","new_quantity":"0.0044"},{"side":"bid","event_time":"2026-07-15T03:40:06.602288Z","price_level":"64564.93","new_quantity":"0"},{"side":"bid","event_time":"2026-07-15T03:40:06.602288Z","price_level":"64563.11","new_quantity":"0"},{"side":"bid","event_time":"2026-07-15T03:40:06.602288Z","price_level":"64557.84","new_quantity":"0.0483189"},{"side":"bid","event_time":"2026-07-15T03:40:06.602288Z","price_level":"64537.44","new_quantity":"0.00077433"},{"side":"bid","event_time":"2026-07-15T03:40:06.602288Z","price_level":"64528.73","new_quantity":"0.4640823"},{"side":"bid","event_time":"2026-07-15T03:40:06.602288Z","price_level":"64528.72","new_quantity":"0.60998278"},{"side":"bid","event_time":"2026-07-15T03:40:06.602288Z","price_level":"64528.71","new_quantity":"0"},{"side":"bid","event_time":"2026-07-15T03:40:06.602288Z","price_level":"64528.7","new_quantity":"0"},{"side":"bid","event_time":"2026-07-15T03:40:06.602288Z","price_level":"64524.14","new_quantity":"0"},{"side":"bid","event_time":"2026-07-15T03:40:06.602288Z","price_level":"64517.34","new_quantity":"0.02423914"},{"side":"bid","event_time":"2026-07-15T03:40:06.602288Z","price_level":"64491.05","new_quantity":"0.94452942"},{"side":"bid","event_time":"2026-07-15T03:40:06.602288Z","price_level":"64491.04","new_quantity":"1.35006934"},{"side":"bid","event_time":"2026-07-15T03:40:06.602288Z","price_level":"64491.03","new_quantity":"0"},{"side":"bid","event_time":"2026-07-15T03:40:06.602288Z","price_level":"64491.02","new_quantity":"0"},{"side":"bid","event_time":"2026-07-15T03:40:06.602288Z","price_level":"64458.67","new_quantity":"0"},{"side":"bid","event_time":"2026-07-15T03:40:06.602288Z","price_level":"56495.18","new_quantity":"0"},{"side":"bid","event_time":"2026-07-15T03:40:06.602288Z","price_level":"51655.42","new_quantity":"0.0002"},{"side":"offer","event_time":"2026-07-15T03:40:06.602288Z","price_level":"64566.87","new_quantity":"0.00215423"},{"side":"offer","event_time":"2026-07-15T03:40:06.602288Z","price_level":"64566.88","new_quantity":"0.00774402"},{"side":"offer","event_time":"2026-07-15T03:40:06.602288Z","price_level":"64566.89","new_quantity":"0"},{"side":"offer","event_time":"2026-07-15T03:40:06.602288Z","price_level":"64566.9","new_quantity":"0.01263062"},{"side":"offer","event_time":"2026-07-15T03:40:06.602288Z","price_level":"64566.91","new_quantity":"0"},{"side":"offer","event_time":"2026-07-15T03:40:06.602288Z","price_level":"64575.34","new_quantity":"0.00100875"},{"side":"offer","event_time":"2026-07-15T03:40:06.602288Z","price_level":"64575.43","new_quantity":"0.04656107"},{"side":"offer","event_time":"2026-07-15T03:40:06.602288Z","price_level":"64575.65","new_quantity":"0"},{"side":"offer","event_time":"2026-07-15T03:40:06.602288Z","price_level":"64577.72","new_quantity":"0.0439187"},{"side":"offer","event_time":"2026-07-15T03:40:06.602288Z","price_level":"64578.15","new_quantity":"0.0483189"},{"side":"offer","event_time":"2026-07-15T03:40:06.602288Z","price_level":"64587.64","new_quantity":"0.72589566"},{"side":"offer","event_time":"2026-07-15T03:40:06.602288Z","price_level":"64588.5","new_quantity":"1"},{"side":"offer","event_time":"2026-07-15T03:40:06.602288Z","price_level":"64626.56","new_quantity":"2.30357778"},{"side":"offer","event_time":"2026-07-15T03:40:06.602288Z","price_level":"64626.57","new_quantity":"2.08991575"},{"side":"offer","event_time":"2026-07-15T03:40:06.602288Z","price_level":"64626.58","new_quantity":"0"},{"side":"offer","event_time":"2026-07-15T03:40:06.602288Z","price_level":"64626.59","new_quantity":"0"},{"side":"offer","event_time":"2026-07-15T03:40:06.602288Z","price_level":"64829.4","new_quantity":"0.05"},{"side":"offer","event_time":"2026-07-15T03:40:06.602288Z","price_level":"64871.54","new_quantity":"0"}]}]}
{"channel":"l2_data","timestamp":"2026-07-15T03:40:06.680941789Z","sequence_num":72,"events":[{"type":"update","product_id":"BTC-USD","updates":[{"side":"bid","event_time":"2026-07-15T03:40:06.646249Z","price_level":"64538.97","new_quantity":"0"},{"side":"bid","event_time":"2026-07-15T03:40:06.646249Z","price_level":"64538.58","new_quantity":"0.11425009"},{"side":"bid","event_time":"2026-07-15T03:40:06.646249Z","price_level":"64522.92","new_quantity":"0.00154761"},{"side":"bid","event_time":"2026-07-15T03:40:06.646249Z","price_level":"64516.47","new_quantity":"0.00773807"},{"side":"offer","event_time":"2026-07-15T03:40:06.646249Z","price_level":"64565.87","new_quantity":"0.0334"},{"side":"offer","event_time":"2026-07-15T03:40:06.646249Z","price_level":"64566.87","new_quantity":"0"},{"side":"offer","event_time":"2026-07-15T03:40:06.646249Z","price_level":"64568","new_quantity":"0.0245"},{"side":"offer","event_time":"2026-07-15T03:40:06.646249Z","price_level":"64571.19","new_quantity":"0.12819227"},{"side":"offer","event_time":"2026-07-15T03:40:06.646249Z","price_level":"64574.14","new_quantity":"0.1238886"},{"side":"offer","event_time":"2026-07-15T03:40:06.646249Z","price_level":"64575.31","new_quantity":"0"},{"side":"offer","event_time":"2026-07-15T03:40:06.646249Z","price_level":"64587.64","new_quantity":"0.14643104"},{"side":"offer","event_time":"2026-07-15T03:40:06.646249Z","price_level":"64588.5","new_quantity":"0"},{"side":"offer","event_time":"2026-07-15T03:40:06.646249Z","price_level":"64597.44","new_quantity":"0.63868315"},{"side":"offer","event_time":"2026-07-15T03:40:06.646249Z","price_level":"64597.46","new_quantity":"0"},{"side":"offer","event_time":"2026-07-15T03:40:06.646249Z","price_level":"64607.15","new_quantity":"0.00077427"},{"side":"offer","event_time":"2026-07-15T03:40:06.646249Z","price_level":"64613.37","new_quantity":"0.00077433"},{"side":"offer","event_time":"2026-07-15T03:40:06.646249Z","price_level":"64644.68","new_quantity":"0.01061683"},{"side":"offer","event_time":"2026-07-15T03:40:06.646249Z","price_level":"64675","new_quantity":"3"}]}]}
{"channel":"market_trades","timestamp":"2026-07-15T03:40:06.719062676Z","sequence_num":73,"events":[{"type":"update","trades":[{"product_id":"BTC-USD","trade_id":"1056309421","price":"64564.93","size":"0.00000009","time":"2026-07-15T03:40:06.58357Z","side":"BUY"}]}]}
{"channel":"l2_data","timestamp":"2026-07-15T03:40:06.735784302Z","sequence_num":74,"events":[{"type":"update","product_id":"BTC-USD","updates":[{"side":"bid","event_time":"2026-07-15T03:40:06.683858Z","price_level":"64564.94","new_quantity":"0.00439994"},{"side":"bid","event_time":"2026-07-15T03:40:06.683858Z","price_level":"64564.74","new_quantity":"0"},{"side":"bid","event_time":"2026-07-15T03:40:06.683858Z","price_level":"64563.15","new_quantity":"0"},{"side":"bid","event_time":"2026-07-15T03:40:06.683858Z","price_level":"64563.12","new_quantity":"0"},{"side":"bid","event_time":"2026-07-15T03:40:06.683858Z","price_level":"64562.01","new_quantity":"0.00159977"},{"side":"bid","event_time":"2026-07-15T03:40:06.683858Z","price_level":"64561.51","new_quantity":"0.597"},{"side":"bid","event_time":"2026-07-15T03:40:06.683858Z","price_level":"64561.35","new_quantity":"0.04647362"},{"side":"bid","event_time":"2026-07-15T03:40:06.683858Z","price_level":"64531.41","new_quantity":"0.60866887"},{"side":"bid","event_time":"2026-07-15T03:40:06.683858Z","price_level":"64531.4","new_quantity":"0.93193645"},{"side":"bid","event_time":"2026-07-15T03:40:06.683858Z","price_level":"64531.39","new_quantity":"0"},{"side":"bid","event_time":"2026-07-15T03:40:06.683858Z","price_level":"64531.38","new_quantity":"0"},{"side":"offer","event_time":"2026-07-15T03:40:06.683858Z","price_level":"64565.85","new_quantity":"0.0334"},{"side":"offer","event_time":"2026-07-15T03:40:06.683858Z","price_level":"64565.87","new_quantity":"0"},{"side":"offer","event_time":"2026-07-15T03:40:06.683858Z","price_level":"64566.85","new_quantity":"0.00425423"},{"side":"offer","event_time":"2026-07-15T03:40:06.683858Z","price_level":"64566.86","new_quantity":"0.00774402"},{"side":"offer","event_time":"2026-07-15T03:40:06.683858Z","price_level":"64566.87","new_quantity":"0"},{"side":"offer","event_time":"2026-07-15T03:40:06.683858Z","price_level":"64566.88","new_quantity":"0"},{"side":"offer","event_time":"2026-07-15T03:40:06.683858Z","price_level":"64567.99","new_quantity":"0.13313739"},{"side":"offer","event_time":"2026-07-15T03:40:06.683858Z","price_level":"64569.98","new_quantity":"0.12378505"},{"side":"offer","event_time":"2026-07-15T03:40:06.683858Z","price_level":"64569.99","new_quantity":"0.04656107"},{"side":"offer","event_time":"2026-07-15T03:40:06.683858Z","price_level":"64571.03","new_quantity":"0.04647362"},{"side":"offer","event_time":"2026-07-15T03:40:06.683858Z","price_level":"64572.82","new_quantity":"0"},{"side":"offer","event_time":"2026-07-15T03:40:06.683858Z","price_level":"64572.83","new_quantity":"0"},{"side":"offer","event_time":"2026-07-15T03:40:06.683858Z","price_level":"64572.95","new_quantity":"0.00772597"},{"side":"offer","event_time":"2026-07-15T03:40:06.683858Z","price_level":"64575.03","new_quantity":"0.00100875"},{"side":"offer","event_time":"2026-07-15T03:40:06.683858Z","price_level":"64575.34","new_quantity":"0"},{"side":"offer","event_time":"2026-07-15T03:40:06.683858Z","price_level":"64586.99","new_quantity":"0.597"},{"side":"offer","event_time":"2026-07-15T03:40:06.683858Z","price_level":"64587","new_quantity":"1"},{"side":"offer","event_time":"2026-07-15T03:40:06.683858Z","price_level":"64597.43","new_quantity":"0.48300434"},{"side":"offer","event_time":"2026-07-15T03:40:06.683858Z","price_level":"64597.45","new_quantity":"0"},{"side":"offer","event_time":"2026-07-15T03:40:06.683858Z","price_level":"64607.16","new_quantity":"0.08986325"},{"side":"offer","event_time":"2026-07-15T03:40:06.683858Z","price_level":"64608.61","new_quantity":"0"},{"side":"offer","event_time":"2026-07-15T03:40:06.683858Z","price_level":"64619.36","new_quantity":"1.43178112"},{"side":"offer","event_time":"2026-07-15T03:40:06.683858Z","price_level":"64619.37","new_quantity":"0.45876951"},{"side":"offer","event_time":"2026-07-15T03:40:06.683858Z","price_level":"64619.38","new_quantity":"0"},{"side":"offer","event_time":"2026-07-15T03:40:06.683858Z","price_level":"64619.39","new_quantity":"0.16985886"},{"side":"offer","event_time":"2026-07-15T03:40:06.683858Z","price_level":"64619.4","new_quantity":"0"},{"side":"offer","event_time":"2026-07-15T03:40:06.683858Z","price_level":"64644.68","new_quantity":"0.01061683"},{"side":"offer","event_time":"2026-07-15T03:40:06.683858Z","price_level":"64664.1","new_quantity":"0.04985237"}]}]}
{"channel":"market_trades","timestamp":"2026-07-15T03:40:06.786049847Z","sequence_num":75,"events":[{"type":"update","trades":[{"product_id":"BTC-USD","trade_id":"1056309422","price":"64564.94","size":"0.00000006","time":"2026-07-15T03:40:06.661373Z","side":"BUY"}]}]}
{"channel":"l2_data","timestamp":"2026-07-15T03:40:06.833738999Z","sequence_num":76,"events":[{"type":"update","product_id":"BTC-USD","updates":[{"side":"bid","event_time":"2026-07-15T03:40:06.789126Z","price_level":"64564.94","new_quantity":"0"},{"side":"bid","event_time":"2026-07-15T03:40:06.789126Z","price_level":"64564","new_quantity":"0"},{"side":"bid","event_time":"2026-07-15T03:40:06.789126Z","price_level":"64561.51","new_quantity":"0"},{"side":"bid","event_time":"2026-07-15T03:40:06.789126Z","price_level":"64561.5","new_quantity":"0"},{"side":"bid","event_time":"2026-07-15T03:40:06.789126Z","price_level":"64561.35","new_quantity":"0"},{"side":"bid","event_time":"2026-07-15T03:40:06.789126Z","price_level":"64560.01","new_quantity":"0"},{"side":"bid","event_time":"2026-07-15T03:40:06.789126Z","price_level":"64559.17","new_quantity":"0"},{"side":"bid","event_time":"2026-07-15T03:40:06.789126Z","price_level":"64557.84","new_quantity":"0"},{"side":"bid","event_time":"2026-07-15T03:40:06.789126Z","price_level":"64557.79","new_quantity":"0.12391996"},{"side":"bid","event_time":"2026-07-15T03:40:06.789126Z","price_level":"64557.77","new_quantity":"0"},{"side":"bid","event_time":"2026-07-15T03:40:06.789126Z","price_level":"64557.54","new_quantity":"0.04647362"},{"side":"bid","event_time":"2026-07-15T03:40:06.789126Z","price_level":"64557.32","new_quantity":"0.12378505"},{"side":"bid","event_time":"2026-07-15T03:40:06.789126Z","price_level":"64557.19","new_quantity":"0"},{"side":"bid","event_time":"2026-07-15T03:40:06.789126Z","price_level":"64557.16","new_quantity":"0"},{"side":"bid","event_time":"2026-07-15T03:40:06.789126Z","price_level":"64557","new_quantity":"1"},{"side":"bid","event_time":"2026-07-15T03:40:06.789126Z","price_level":"64556","new_quantity":"0.0245"},{"side":"bid","event_time":"2026-07-15T03:40:06.789126Z","price_level":"64555.81","new_quantity":"0"},{"side":"bid","event_time":"2026-07-15T03:40:06.789126Z","price_level":"64555.27","new_quantity":"0.12378505"},{"side":"bid","event_time":"2026-07-15T03:40:06.789126Z","price_level":"64555.13","new_quantity":"0"},{"side":"bid","event_time":"2026-07-15T03:40:06.789126Z","price_level":"64554.57","new_quantity":"0"},{"side":"bid","event_time":"2026-07-15T03:40:06.789126Z","price_level":"64553.84","new_quantity":"0"},{"side":"bid","event_time":"2026-07-15T03:40:06.789126Z","price_level":"64552.07","new_quantity":"0.0483189"},{"side":"bid","event_time":"2026-07-15T03:40:06.789126Z","price_level":"64551.39","new_quantity":"0.12378505"},{"side":"bid","event_time":"2026-07-15T03:40:06.789126Z","price_level":"64549.96","new_quantity":"0"},{"side":"bid","event_time":"2026-07-15T03:40:06.789126Z","price_level":"64548.96","new_quantity":"0"},{"side":"bid","event_time":"2026-07-15T03:40:06.789126Z","price_level":"64548.74","new_quantity":"0.03093532"},{"side":"bid","event_time":"2026-07-15T03:40:06.789126Z","price_level":"64547.51","new_quantity":"0.12378505"},{"side":"bid","event_time":"2026-07-15T03:40:06.789126Z","price_level":"64547.21","new_quantity":"0"},{"side":"bid","event_time":"2026-07-15T03:40:06.789126Z","price_level":"64545.95","new_quantity":"0.00772597"},{"side":"bid","event_time":"2026-07-15T03:40:06.789126Z","price_level":"64545.94","new_quantity":"0"},{"side":"bid","event_time":"2026-07-15T03:40:06.789126Z","price_level":"64544.09","new_quantity":"0.02"},{"side":"bid","event_time":"2026-07-15T03:40:06.789126Z","price_level":"64536.04","new_quantity":"0.032663"},{"side":"bid","event_time":"2026-07-15T03:40:06.789126Z","price_level":"64528.72","new_quantity":"0"},{"side":"bid","event_time":"2026-07-15T03:40:06.789126Z","price_level":"64528.66","new_quantity":"0"},{"side":"bid","event_time":"2026-07-15T03:40:06.789126Z","price_level":"64526.13","new_quantity":"0.61000726"},{"side":"bid","event_time":"2026-07-15T03:40:06.789126Z","price_level":"64524.85","new_quantity":"0.00077434"},{"side":"bid","event_time":"2026-07-15T03:40:06.789126Z","price_level":"64512.52","new_quantity":"0"},{"side":"bid","event_time":"2026-07-15T03:40:06.789126Z","price_level":"64491.06","new_quantity":"1.35006892"},{"side":"bid","event_time":"2026-07-15T03:40:06.789126Z","price_level":"64491.04","new_quantity":"0"},{"side":"bid","event_time":"2026-07-15T03:40:06.789126Z","price_level":"64472.87","new_quantity":"0.74055005"},{"side":"bid","event_time":"2026-07-15T03:40:06.789126Z","price_level":"64443.45","new_quantity":"0.00310349"},{"side":"offer","event_time":"2026-07-15T03:40:06.789126Z","price_level":"64564.95","new_quantity":"0.08175423"},{"side":"offer","event_time":"2026-07-15T03:40:06.789126Z","price_level":"64565.84","new_quantity":"0.05210346"},{"side":"offer","event_time":"2026-07-15T03:40:06.789126Z","price_level":"64565.85","new_quantity":"0"},{"side":"offer","event_time":"2026-07-15T03:40:06.789126Z","price_level":"64566","new_quantity":"0.0245"},{"side":"offer","event_time":"2026-07-15T03:40:06.789126Z","price_level":"64566.85","new_quantity":"0"},{"side":"offer","event_time":"2026-07-15T03:40:06.789126Z","price_level":"64567.22","new_quantity":"0.04647362"},{"side":"offer","event_time":"2026-07-15T03:40:06.789126Z","price_level":"64567.98","new_quantity":"0.12378505"},{"side":"offer","event_time":"2026-07-15T03:40:06.789126Z","price_level":"64569.18","new_quantity":"0.12389812"},{"side":"offer","event_time":"2026-07-15T03:40:06.789126Z","price_level":"64569.97","new_quantity":"0.00772597"},{"side":"offer","event_time":"2026-07-15T03:40:06.789126Z","price_level":"64571.03","new_quantity":"0"},{"side":"offer","event_time":"2026-07-15T03:40:06.789126Z","price_level":"64571.18","new_quantity":"0.03093532"},{"side":"offer","event_time":"2026-07-15T03:40:06.789126Z","price_level":"64572.95","new_quantity":"0"},{"side":"offer","event_time":"2026-07-15T03:40:06.789126Z","price_level":"64574.14","new_quantity":"0"},{"side":"offer","event_time":"2026-07-15T03:40:06.789126Z","price_level":"64574.29","new_quantity":"0.1548604"},{"side":"offer","event_time":"2026-07-15T03:40:06.789126Z","price_level":"64575.03","new_quantity":"0"},{"side":"offer","event_time":"2026-07-15T03:40:06.789126Z","price_level":"64577.04","new_quantity":"0"},{"side":"offer","event_time":"2026-07-15T03:40:06.789126Z","price_level":"64577.72","new_quantity":"0.01728175"},{"side":"offer","event_time":"2026-07-15T03:40:06.789126Z","price_level":"64578.15","new_quantity":"0"},{"side":"offer","event_time":"2026-07-15T03:40:06.789126Z","price_level":"64578.81","new_quantity":"0.06070816"},{"side":"offer","event_time":"2026-07-15T03:40:06.789126Z","price_level":"64586.99","new_quantity":"0"},{"side":"offer","event_time":"2026-07-15T03:40:06.789126Z","price_level":"64587","new_quantity":"1"},{"side":"offer","event_time":"2026-07-15T03:40:06.789126Z","price_level":"64587.31","new_quantity":"0"},{"side":"offer","event_time":"2026-07-15T03:40:06.789126Z","price_level":"64597.42","new_quantity":"0.63868334"},{"side":"offer","event_time":"2026-07-15T03:40:06.789126Z","price_level":"64597.44","new_quantity":"0"},{"side":"offer","event_time":"2026-07-15T03:40:06.789126Z","price_level":"64605.73","new_quantity":"0"},{"side":"offer","event_time":"2026-07-15T03:40:06.789126Z","price_level":"64616.49","new_quantity":"1.43184471"},{"side":"offer","event_time":"2026-07-15T03:40:06.789126Z","price_level":"64619.35","new_quantity":"0.45876965"},{"side":"offer","event_time":"2026-07-15T03:40:06.789126Z","price_level":"64619.36","new_quantity":"0"},{"side":"offer","event_time":"2026-07-15T03:40:06.789126Z","price_level":"64619.37","new_quantity":"0"},{"side":"offer","event_time":"2026-07-15T03:40:06.789126Z","price_level":"64626.41","new_quantity":"0.01615943"},{"side":"offer","event_time":"2026-07-15T03:40:06.789126Z","price_level":"64626.55","new_quantity":"2.08991639"},{"side":"offer","event_time":"2026-07-15T03:40:06.789126Z","price_level":"64626.57","new_quantity":"0"},{"side":"offer","event_time":"2026-07-15T03:40:06.789126Z","price_level":"64644.68","new_quantity":"0.01061683"},{"side":"offer","event_time":"2026-07-15T03:40:06.789126Z","price_level":"64670","new_quantity":"3"},{"side":"offer","event_time":"2026-07-15T03:40:06.789126Z","price_level":"64675","new_quantity":"0"},{"side":"offer","event_time":"2026-07-15T03:40:06.789126Z","price_level":"64967.49","new_quantity":"0"}]}]}
{"channel":"l2_data","timestamp":"2026-07-15T03:40:06.883950516Z","sequence_num":77,"events":[{"type":"update","product_id":"BTC-USD","updates":[{"side":"bid","event_time":"2026-07-15T03:40:06.840005Z","price_level":"64562.38","new_quantity":"0.00159977"},{"side":"bid","event_time":"2026-07-15T03:40:06.840005Z","price_level":"64562.01","new_quantity":"0"},{"side":"bid","event_time":"2026-07-15T03:40:06.840005Z","price_level":"64562","new_quantity":"0"},{"side":"bid","event_time":"2026-07-15T03:40:06.840005Z","price_level":"64560.14","new_quantity":"0.04656107"},{"side":"bid","event_time":"2026-07-15T03:40:06.840005Z","price_level":"64557.79","new_quantity":"0"},{"side":"bid","event_time":"2026-07-15T03:40:06.840005Z","price_level":"64557.54","new_quantity":"0"},{"side":"bid","event_time":"2026-07-15T03:40:06.840005Z","price_level":"64556.45","new_quantity":"0.12392253"},{"side":"bid","event_time":"2026-07-15T03:40:06.840005Z","price_level":"64556.01","new_quantity":"0.08852617"},{"side":"bid","event_time":"2026-07-15T03:40:06.840005Z","price_level":"64555.28","new_quantity":"0.03093532"},{"side":"bid","event_time":"2026-07-15T03:40:06.840005Z","price_level":"64554.58","new_quantity":"0.11958398"},{"side":"bid","event_time":"2026-07-15T03:40:06.840005Z","price_level":"64553.29","new_quantity":"0.15491076"},{"side":"bid","event_time":"2026-07-15T03:40:06.840005Z","price_level":"64552.07","new_quantity":"0"},{"side":"bid","event_time":"2026-07-15T03:40:06.840005Z","price_level":"64551.4","new_quantity":"0.17948511"},{"side":"bid","event_time":"2026-07-15T03:40:06.840005Z","price_level":"64551.02","new_quantity":"0"},{"side":"bid","event_time":"2026-07-15T03:40:06.840005Z","price_level":"64548.46","new_quantity":"0.0483189"},{"side":"bid","event_time":"2026-07-15T03:40:06.840005Z","price_level":"64548.29","new_quantity":"0"},{"side":"bid","event_time":"2026-07-15T03:40:06.840005Z","price_level":"64547.52","new_quantity":"0.07852282"},{"side":"bid","event_time":"2026-07-15T03:40:06.840005Z","price_level":"64545.95","new_quantity":"0"},{"side":"bid","event_time":"2026-07-15T03:40:06.840005Z","price_level":"64544.35","new_quantity":"0.00772597"},{"side":"bid","event_time":"2026-07-15T03:40:06.840005Z","price_level":"64544.34","new_quantity":"0.13228371"},{"side":"bid","event_time":"2026-07-15T03:40:06.840005Z","price_level":"64531.41","new_quantity":"0.05230281"},{"side":"bid","event_time":"2026-07-15T03:40:06.840005Z","price_level":"64531.4","new_quantity":"0"},{"side":"bid","event_time":"2026-07-15T03:40:06.840005Z","price_level":"64528.75","new_quantity":"1.00079506"},{"side":"bid","event_time":"2026-07-15T03:40:06.840005Z","price_level":"64528.74","new_quantity":"0.93197487"},{"side":"bid","event_time":"2026-07-15T03:40:06.840005Z","price_level":"64528.73","new_quantity":"0"},{"side":"bid","event_time":"2026-07-15T03:40:06.840005Z","price_level":"64522.92","new_quantity":"0"},{"side":"bid","event_time":"2026-07-15T03:40:06.840005Z","price_level":"64516.47","new_quantity":"0"},{"side":"bid","event_time":"2026-07-15T03:40:06.840005Z","price_level":"64512.53","new_quantity":"0.29262981"},{"side":"bid","event_time":"2026-07-15T03:40:06.840005Z","price_level":"64511.39","new_quantity":"0"},{"side":"bid","event_time":"2026-07-15T03:40:06.840005Z","price_level":"64491.07","new_quantity":"0.94452917"},{"side":"bid","event_time":"2026-07-15T03:40:06.840005Z","price_level":"64491.05","new_quantity":"0"},{"side":"bid","event_time":"2026-07-15T03:40:06.840005Z","price_level":"64476.81","new_quantity":"0.01061683"},{"side":"bid","event_time":"2026-07-15T03:40:06.840005Z","price_level":"64476.28","new_quantity":"0"},{"side":"bid","event_time":"2026-07-15T03:40:06.840005Z","price_level":"64472.87","new_quantity":"1.1521481"},{"side":"bid","event_time":"2026-07-15T03:40:06.840005Z","price_level":"64470.39","new_quantity":"0.04802155"},{"side":"bid","event_time":"2026-07-15T03:40:06.840005Z","price_level":"64470.02","new_quantity":"2.07590792"},{"side":"bid","event_time":"2026-07-15T03:40:06.840005Z","price_level":"64154","new_quantity":"0.01061683"},{"side":"bid","event_time":"2026-07-15T03:40:06.840005Z","price_level":"51655.42","new_quantity":"0"},{"side":"offer","event_time":"2026-07-15T03:40:06.840005Z","price_level":"64562.39","new_quantity":"0.02825423"},{"side":"offer","event_time":"2026-07-15T03:40:06.840005Z","price_level":"64562.98","new_quantity":"0.01627078"},{"side":"offer","event_time":"2026-07-15T03:40:06.840005Z","price_level":"64563","new_quantity":"0"},{"side":"offer","event_time":"2026-07-15T03:40:06.840005Z","price_level":"64563.99","new_quantity":"0"},{"side":"offer","event_time":"2026-07-15T03:40:06.840005Z","price_level":"64564","new_quantity":"0.0245"},{"side":"offer","event_time":"2026-07-15T03:40:06.840005Z","price_level":"64564.93","new_quantity":"0.02679016"},{"side":"offer","event_time":"2026-07-15T03:40:06.840005Z","price_level":"64564.95","new_quantity":"0"},{"side":"offer","event_time":"2026-07-15T03:40:06.840005Z","price_level":"64565.84","new_quantity":"0"},{"side":"offer","event_time":"2026-07-15T03:40:06.840005Z","price_level":"64567.22","new_quantity":"0"},{"side":"offer","event_time":"2026-07-15T03:40:06.840005Z","price_level":"64567.97","new_quantity":"0.32267757"},{"side":"offer","event_time":"2026-07-15T03:40:06.840005Z","price_level":"64567.99","new_quantity":"0"},{"side":"offer","event_time":"2026-07-15T03:40:06.840005Z","price_level":"64568.09","new_quantity":"0.12390021"},{"side":"offer","event_time":"2026-07-15T03:40:06.840005Z","price_level":"64569.12","new_quantity":"0.0483189"},{"side":"offer","event_time":"2026-07-15T03:40:06.840005Z","price_level":"64571.17","new_quantity":"0.14378604"},{"side":"offer","event_time":"2026-07-15T03:40:06.840005Z","price_level":"64571.19","new_quantity":"0"},{"side":"offer","event_time":"2026-07-15T03:40:06.840005Z","price_level":"64573.86","new_quantity":"0.12378505"},{"side":"offer","event_time":"2026-07-15T03:40:06.840005Z","price_level":"64574.25","new_quantity":"0.00098675"},{"side":"offer","event_time":"2026-07-15T03:40:06.840005Z","price_level":"64574.28","new_quantity":"0.09651161"},{"side":"offer","event_time":"2026-07-15T03:40:06.840005Z","price_level":"64574.29","new_quantity":"0"},{"side":"offer","event_time":"2026-07-15T03:40:06.840005Z","price_level":"64574.43","new_quantity":"0"},{"side":"offer","event_time":"2026-07-15T03:40:06.840005Z","price_level":"64575.09","new_quantity":"0"},{"side":"offer","event_time":"2026-07-15T03:40:06.840005Z","price_level":"64577.72","new_quantity":"0.12086367"},{"side":"offer","event_time":"2026-07-15T03:40:06.840005Z","price_level":"64577.74","new_quantity":"0.12378505"},{"side":"offer","event_time":"2026-07-15T03:40:06.840005Z","price_level":"64586.99","new_quantity":"0"},{"side":"offer","event_time":"2026-07-15T03:40:06.840005Z","price_level":"64587","new_quantity":"0"},{"side":"offer","event_time":"2026-07-15T03:40:06.840005Z","price_level":"64597.41","new_quantity":"0.48300446"},{"side":"offer","event_time":"2026-07-15T03:40:06.840005Z","price_level":"64597.43","new_quantity":"0"},{"side":"offer","event_time":"2026-07-15T03:40:06.840005Z","price_level":"64599.31","new_quantity":"0"},{"side":"offer","event_time":"2026-07-15T03:40:06.840005Z","price_level":"64603.18","new_quantity":"0"},{"side":"offer","event_time":"2026-07-15T03:40:06.840005Z","price_level":"64603.19","new_quantity":"0"},{"side":"offer","event_time":"2026-07-15T03:40:06.840005Z","price_level":"64603.38","new_quantity":"0.07403964"},{"side":"offer","event_time":"2026-07-15T03:40:06.840005Z","price_level":"64616.48","new_quantity":"1.14717903"},{"side":"offer","event_time":"2026-07-15T03:40:06.840005Z","price_level":"64616.5","new_quantity":"0"},{"side":"offer","event_time":"2026-07-15T03:40:06.840005Z","price_level":"64619.39","new_quantity":"0.0278077"},{"side":"offer","event_time":"2026-07-15T03:40:06.840005Z","price_level":"64621.15","new_quantity":"0"},{"side":"offer","event_time":"2026-07-15T03:40:06.840005Z","price_level":"64626.54","new_quantity":"2.30357816"},{"side":"offer","event_time":"2026-07-15T03:40:06.840005Z","price_level":"64626.56","new_quantity":"0"},{"side":"offer","event_time":"2026-07-15T03:40:06.840005Z","price_level":"64701.3","new_quantity":"0.05"}]}]}
{"channel":"l2_data","timestamp":"2026-07-15T03:40:06.935568629Z","sequence_num":78,"events":[{"type":"update","product_id":"BTC-USD","updates":[{"side":"bid","event_time":"2026-07-15T03:40:06.885804Z","price_level":"64562.38","new_quantity":"0.00212471"},{"side":"bid","event_time":"2026-07-15T03:40:06.885804Z","price_level":"64560.14","new_quantity":"0"},{"side":"bid","event_time":"2026-07-15T03:40:06.885804Z","price_level":"64557.32","new_quantity":"0"},{"side":"bid","event_time":"2026-07-15T03:40:06.885804Z","price_level":"64557.01","new_quantity":"0.04656107"},{"side":"bid","event_time":"2026-07-15T03:40:06.885804Z","price_level":"64556.01","new_quantity":"0"},{"side":"bid","event_time":"2026-07-15T03:40:06.885804Z","price_level":"64555.27","new_quantity":"0"},{"side":"bid","event_time":"2026-07-15T03:40:06.885804Z","price_level":"64551.39","new_quantity":"0"},{"side":"bid","event_time":"2026-07-15T03:40:06.885804Z","price_level":"64549.58","new_quantity":"0.12378505"},{"side":"bid","event_time":"2026-07-15T03:40:06.885804Z","price_level":"64548.46","new_quantity":"0"},{"side":"bid","event_time":"2026-07-15T03:40:06.885804Z","price_level":"64544.09","new_quantity":"0"},{"side":"bid","event_time":"2026-07-15T03:40:06.885804Z","price_level":"64531.94","new_quantity":"0.42039927"},{"side":"bid","event_time":"2026-07-15T03:40:06.885804Z","price_level":"64531.93","new_quantity":"0.616577"},{"side":"bid","event_time":"2026-07-15T03:40:06.885804Z","price_level":"64531.41","new_quantity":"0"},{"side":"bid","event_time":"2026-07-15T03:40:06.885804Z","price_level":"64528.75","new_quantity":"0.63662073"},{"side":"bid","event_time":"2026-07-15T03:40:06.885804Z","price_level":"64528.74","new_quantity":"0"},{"side":"bid","event_time":"2026-07-15T03:40:06.885804Z","price_level":"64526.14","new_quantity":"0.93201242"},{"side":"bid","event_time":"2026-07-15T03:40:06.885804Z","price_level":"64526.13","new_quantity":"0"},{"side":"bid","event_time":"2026-07-15T03:40:06.885804Z","price_level":"64522.13","new_quantity":"0.72894889"},{"side":"bid","event_time":"2026-07-15T03:40:06.885804Z","price_level":"64522.12","new_quantity":"0.61004517"},{"side":"bid","event_time":"2026-07-15T03:40:06.885804Z","price_level":"64522.11","new_quantity":"0"},{"side":"bid","event_time":"2026-07-15T03:40:06.885804Z","price_level":"64500.47","new_quantity":"0.00077518"},{"side":"bid","event_time":"2026-07-15T03:40:06.885804Z","price_level":"64491.09","new_quantity":"0.94452892"},{"side":"bid","event_time":"2026-07-15T03:40:06.885804Z","price_level":"64491.08","new_quantity":"1.3500685"},{"side":"bid","event_time":"2026-07-15T03:40:06.885804Z","price_level":"64491.07","new_quantity":"0"},{"side":"bid","event_time":"2026-07-15T03:40:06.885804Z","price_level":"64491.06","new_quantity":"0"},{"side":"bid","event_time":"2026-07-15T03:40:06.885804Z","price_level":"64481.08","new_quantity":"0"},{"side":"bid","event_time":"2026-07-15T03:40:06.885804Z","price_level":"56492.09","new_quantity":"0.0132912"},{"side":"offer","event_time":"2026-07-15T03:40:06.885804Z","price_level":"64562.39","new_quantity":"0.03080846"},{"side":"offer","event_time":"2026-07-15T03:40:06.885804Z","price_level":"64569.12","new_quantity":"0"},{"side":"offer","event_time":"2026-07-15T03:40:06.885804Z","price_level":"64574.17","new_quantity":"0.02348475"},{"side":"offer","event_time":"2026-07-15T03:40:06.885804Z","price_level":"64574.25","new_quantity":"0"},{"side":"offer","event_time":"2026-07-15T03:40:06.885804Z","price_level":"64585.49","new_quantity":"0.597"},{"side":"offer","event_time":"2026-07-15T03:40:06.885804Z","price_level":"64585.5","new_quantity":"0"},{"side":"offer","event_time":"2026-07-15T03:40:06.885804Z","price_level":"64591.3","new_quantity":"0.65498142"},{"side":"offer","event_time":"2026-07-15T03:40:06.885804Z","price_level":"64593.45","new_quantity":"0.6387226"},{"side":"offer","event_time":"2026-07-15T03:40:06.885804Z","price_level":"64597.41","new_quantity":"0.02781083"},{"side":"offer","event_time":"2026-07-15T03:40:06.885804Z","price_level":"64597.42","new_quantity":"0"},{"side":"offer","event_time":"2026-07-15T03:40:06.885804Z","price_level":"64606.11","new_quantity":"0.01884451"},{"side":"offer","event_time":"2026-07-15T03:40:06.885804Z","price_level":"64610.66","new_quantity":"0.02740643"},{"side":"offer","event_time":"2026-07-15T03:40:06.885804Z","price_level":"64613.36","new_quantity":"0.4455053"},{"side":"offer","event_time":"2026-07-15T03:40:06.885804Z","price_level":"64613.37","new_quantity":"0.68644695"},{"side":"offer","event_time":"2026-07-15T03:40:06.885804Z","price_level":"64613.38","new_quantity":"0"},{"side":"offer","event_time":"2026-07-15T03:40:06.885804Z","price_level":"64616.46","new_quantity":"0.29237994"},{"side":"offer","event_time":"2026-07-15T03:40:06.885804Z","price_level":"64616.47","new_quantity":"0.4587901"},{"side":"offer","event_time":"2026-07-15T03:40:06.885804Z","price_level":"64616.48","new_quantity":"0"},{"side":"offer","event_time":"2026-07-15T03:40:06.885804Z","price_level":"64616.49","new_quantity":"0"},{"side":"offer","event_time":"2026-07-15T03:40:06.885804Z","price_level":"64619.35","new_quantity":"0"},{"side":"offer","event_time":"2026-07-15T03:40:06.885804Z","price_level":"64619.39","new_quantity":"1.27202685"},{"side":"offer","event_time":"2026-07-15T03:40:06.885804Z","price_level":"64621.67","new_quantity":"2.09007422"},{"side":"offer","event_time":"2026-07-15T03:40:06.885804Z","price_level":"64626.54","new_quantity":"1.05589807"},{"side":"offer","event_time":"2026-07-15T03:40:06.885804Z","price_level":"64626.55","new_quantity":"0"}]}]}
{"channel":"l2_data","timestamp":"2026-07-15T03:40:06.999000665Z","sequence_num":79,"events":[{"type":"update","product_id":"BTC-USD","updates":[{"side":"bid","event_time":"2026-07-15T03:40:06.935775Z","price_level":"64555.57","new_quantity":"0.06"},{"side":"bid","event_time":"2026-07-15T03:40:06.935775Z","price_level":"64554.58","new_quantity":"0"},{"side":"bid","event_time":"2026-07-15T03:40:06.935775Z","price_level":"64553.59","new_quantity":"0.12378505"},{"side":"bid","event_time":"2026-07-15T03:40:06.935775Z","price_level":"64553.3","new_quantity":"0.18281931"},{"side":"bid","event_time":"2026-07-15T03:40:06.935775Z","price_level":"64551.64","new_quantity":"0.12378505"},{"side":"bid","event_time":"2026-07-15T03:40:06.935775Z","price_level":"64542","new_quantity":"0.04"},{"side":"bid","event_time":"2026-07-15T03:40:06.935775Z","price_level":"64540.4","new_quantity":"0.08"},{"side":"bid","event_time":"2026-07-15T03:40:06.935775Z","price_level":"64537.44","new_quantity":"0"},{"side":"bid","event_time":"2026-07-15T03:40:06.935775Z","price_level":"64533.38","new_quantity":"0.00077441"},{"side":"bid","event_time":"2026-07-15T03:40:06.935775Z","price_level":"64531.94","new_quantity":"0.05230281"},{"side":"bid","event_time":"2026-07-15T03:40:06.935775Z","price_level":"64531.93","new_quantity":"0"},{"side":"bid","event_time":"2026-07-15T03:40:06.935775Z","price_level":"64470.4","new_quantity":"2.07589568"},{"side":"bid","event_time":"2026-07-15T03:40:06.935775Z","price_level":"64470.02","new_quantity":"0"},{"side":"bid","event_time":"2026-07-15T03:40:06.935775Z","price_level":"64365.12","new_quantity":"0.00030976"},{"side":"bid","event_time":"2026-07-15T03:40:06.935775Z","price_level":"64355.86","new_quantity":"0"},{"side":"bid","event_time":"2026-07-15T03:40:06.935775Z","price_level":"64300.51","new_quantity":"0.00030976"},{"side":"bid","event_time":"2026-07-15T03:40:06.935775Z","price_level":"64235.9","new_quantity":"0.00030976"},{"side":"bid","event_time":"2026-07-15T03:40:06.935775Z","price_level":"64154","new_quantity":"0"},{"side":"bid","event_time":"2026-07-15T03:40:06.935775Z","price_level":"64131.25","new_quantity":"0.04831322"},{"side":"offer","event_time":"2026-07-15T03:40:06.935775Z","price_level":"64585.49","new_quantity":"0.597"},{"side":"offer","event_time":"2026-07-15T03:40:06.935775Z","price_level":"64585.5","new_quantity":"1"},{"side":"offer","event_time":"2026-07-15T03:40:06.935775Z","price_level":"64603.26","new_quantity":"0.11150953"},{"side":"offer","event_time":"2026-07-15T03:40:06.935775Z","price_level":"64603.38","new_quantity":"0"},{"side":"offer","event_time":"2026-07-15T03:40:06.935775Z","price_level":"64603.53","new_quantity":"0.00077434"},{"side":"offer","event_time":"2026-07-15T03:40:06.935775Z","price_level":"64607.15","new_quantity":"0"},{"side":"offer","event_time":"2026-07-15T03:40:06.935775Z","price_level":"64816.92","new_quantity":"0"},{"side":"offer","event_time":"2026-07-15T03:40:06.935775Z","price_level":"65235.75","new_quantity":"0.02588"}]}]}
{"channel":"l2_data","timestamp":"2026-07-15T03:40:07.034585016Z","sequence_num":80,"events":[{"type":"update","product_id":"BTC-USD","updates":[{"side":"bid","event_time":"2026-07-15T03:40:06.984806Z","price_level":"64562.38","new_quantity":"0.00052494"},{"side":"bid","event_time":"2026-07-15T03:40:06.984806Z","price_level":"64558.01","new_quantity":"0.00159977"},{"side":"bid","event_time":"2026-07-15T03:40:06.984806Z","price_level":"64557.02","new_quantity":"0.12378505"},{"side":"bid","event_time":"2026-07-15T03:40:06.984806Z","price_level":"64524.85","new_quantity":"0"},{"side":"bid","event_time":"2026-07-15T03:40:06.984806Z","price_level":"64520.95","new_quantity":"0.0007744"},{"side":"bid","event_time":"2026-07-15T03:40:06.984806Z","price_level":"56492.09","new_quantity":"0"}]}]}
{"channel":"l2_data","timestamp":"2026-07-15T03:40:07.092250345Z","sequence_num":81,"events":[{"type":"update","product_id":"BTC-USD","updates":[{"side":"bid","event_time":"2026-07-15T03:40:07.028989Z","price_level":"64557.03","new_quantity":"0.02"},{"side":"bid","event_time":"2026-07-15T03:40:07.028989Z","price_level":"64542","new_quantity":"0.06"},{"side":"bid","event_time":"2026-07-15T03:40:07.028989Z","price_level":"64522.15","new_quantity":"0.72941109"},{"side":"bid","event_time":"2026-07-15T03:40:07.028989Z","price_level":"64522.14","new_quantity":"0.61004498"},{"side":"bid","event_time":"2026-07-15T03:40:07.028989Z","price_level":"64522.13","new_quantity":"0"},{"side":"bid","event_time":"2026-07-15T03:40:07.028989Z","price_level":"64522.12","new_quantity":"0"},{"side":"bid","event_time":"2026-07-15T03:40:07.028989Z","price_level":"64491.11","new_quantity":"0.94452867"},{"side":"bid","event_time":"2026-07-15T03:40:07.028989Z","price_level":"64491.1","new_quantity":"1.35006808"},{"side":"bid","event_time":"2026-07-15T03:40:07.028989Z","price_level":"64491.09","new_quantity":"0"},{"side":"bid","event_time":"2026-07-15T03:40:07.028989Z","price_level":"64491.08","new_quantity":"0"},{"side":"offer","event_time":"2026-07-15T03:40:07.028989Z","price_level":"64567.96","new_quantity":"0.02"},{"side":"offer","event_time":"2026-07-15T03:40:07.028989Z","price_level":"64574.17","new_quantity":"0.022498"},{"side":"offer","event_time":"2026-07-15T03:40:07.028989Z","price_level":"64580.51","new_quantity":"0.00098675"},{"side":"offer","event_time":"2026-07-15T03:40:07.028989Z","price_level":"64583.99","new_quantity":"0"},{"side":"offer","event_time":"2026-07-15T03:40:07.028989Z","price_level":"64590.34","new_quantity":"0.0007744"},{"side":"offer","event_time":"2026-07-15T03:40:07.028989Z","price_level":"64596.25","new_quantity":"0.01647578"},{"side":"offer","event_time":"2026-07-15T03:40:07.028989Z","price_level":"64597.06","new_quantity":"0"},{"side":"offer","event_time":"2026-07-15T03:40:07.028989Z","price_level":"64603.42","new_quantity":"0.00104544"},{"side":"offer","event_time":"2026-07-15T03:40:07.028989Z","price_level":"64611.14","new_quantity":"0"},{"side":"offer","event_time":"2026-07-15T03:40:07.028989Z","price_level":"64613.34","new_quantity":"0.4455053"},{"side":"offer","event_time":"2026-07-15T03:40:07.028989Z","price_level":"64613.35","new_quantity":"0.68567262"},{"side":"offer","event_time":"2026-07-15T03:40:07.028989Z","price_level":"64613.36","new_quantity":"0"},{"side":"offer","event_time":"2026-07-15T03:40:07.028989Z","price_level":"64613.37","new_quantity":"0.00077433"},{"side":"offer","event_time":"2026-07-15T03:40:07.028989Z","price_level":"64616.44","new_quantity":"0.29238003"},{"side":"offer","event_time":"2026-07-15T03:40:07.028989Z","price_level":"64616.45","new_quantity":"0.45879024"},{"side":"offer","event_time":"2026-07-15T03:40:07.028989Z","price_level":"64616.46","new_quantity":"0"},{"side":"offer","event_time":"2026-07-15T03:40:07.028989Z","price_level":"64616.47","new_quantity":"0"}]}]}
{"channel":"l2_data","timestamp":"2026-07-15T03:40:07.141168379Z","sequence_num":82,"events":[{"type":"update","product_id":"BTC-USD","updates":[{"side":"bid","event_time":"2026-07-15T03:40:07.087267Z","price_level":"64559.22","new_quantity":"0.0015533"},{"side":"bid","event_time":"2026-07-15T03:40:07.087267Z","price_level":"64557.02","new_quantity":"0.14378505"},{"side":"bid","event_time":"2026-07-15T03:40:07.087267Z","price_level":"64556.03","new_quantity":"0.0015533"},{"side":"bid","event_time":"2026-07-15T03:40:07.087267Z","price_level":"64555.57","new_quantity":"0.02"},{"side":"bid","event_time":"2026-07-15T03:40:07.087267Z","price_level":"64552.84","new_quantity":"0.0015533"},{"side":"bid","event_time":"2026-07-15T03:40:07.087267Z","price_level":"64549.65","new_quantity":"0.0015533"},{"side":"bid","event_time":"2026-07-15T03:40:07.087267Z","price_level":"64546.46","new_quantity":"0.0015533"},{"side":"bid","event_time":"2026-07-15T03:40:07.087267Z","price_level":"64543.52","new_quantity":"0.000018"},{"side":"bid","event_time":"2026-07-15T03:40:07.087267Z","price_level":"64543.27","new_quantity":"0.0015533"},{"side":"bid","event_time":"2026-07-15T03:40:07.087267Z","price_level":"64540.08","new_quantity":"0.0015533"},{"side":"bid","event_time":"2026-07-15T03:40:07.087267Z","price_level":"64536.89","new_quantity":"0.0015533"},{"side":"bid","event_time":"2026-07-15T03:40:07.087267Z","price_level":"64533.7","new_quantity":"0.0015533"},{"side":"bid","event_time":"2026-07-15T03:40:07.087267Z","price_level":"64533.38","new_quantity":"0"},{"side":"bid","event_time":"2026-07-15T03:40:07.087267Z","price_level":"64531.95","new_quantity":"0.0007744"},{"side":"bid","event_time":"2026-07-15T03:40:07.087267Z","price_level":"64530.51","new_quantity":"0.0015533"},{"side":"bid","event_time":"2026-07-15T03:40:07.087267Z","price_level":"64527.32","new_quantity":"0.0015533"},{"side":"bid","event_time":"2026-07-15T03:40:07.087267Z","price_level":"64511.37","new_quantity":"0.0015533"},{"side":"bid","event_time":"2026-07-15T03:40:07.087267Z","price_level":"64508.18","new_quantity":"0.0015533"},{"side":"bid","event_time":"2026-07-15T03:40:07.087267Z","price_level":"64504.99","new_quantity":"0.0015533"},{"side":"bid","event_time":"2026-07-15T03:40:07.087267Z","price_level":"64501.8","new_quantity":"0.0015533"},{"side":"bid","event_time":"2026-07-15T03:40:07.087267Z","price_level":"64498.61","new_quantity":"0.0015533"},{"side":"bid","event_time":"2026-07-15T03:40:07.087267Z","price_level":"64319.72","new_quantity":"0.01"},{"side":"offer","event_time":"2026-07-15T03:40:07.087267Z","price_level":"64565.6","new_quantity":"0.0015533"},{"side":"offer","event_time":"2026-07-15T03:40:07.087267Z","price_level":"64568.79","new_quantity":"0.0015533"},{"side":"offer","event_time":"2026-07-15T03:40:07.087267Z","price_level":"64571.98","new_quantity":"0.0015533"},{"side":"offer","event_time":"2026-07-15T03:40:07.087267Z","price_level":"64575.17","new_quantity":"0.0015533"},{"side":"offer","event_time":"2026-07-15T03:40:07.087267Z","price_level":"64576.64","new_quantity":"0.000018"},{"side":"offer","event_time":"2026-07-15T03:40:07.087267Z","price_level":"64578.36","new_quantity":"0.0015533"},{"side":"offer","event_time":"2026-07-15T03:40:07.087267Z","price_level":"64581.55","new_quantity":"0.0015533"},{"side":"offer","event_time":"2026-07-15T03:40:07.087267Z","price_level":"64584.74","new_quantity":"0.0015533"},{"side":"offer","event_time":"2026-07-15T03:40:07.087267Z","price_level":"64587.93","new_quantity":"0.0015533"},{"side":"offer","event_time":"2026-07-15T03:40:07.087267Z","price_level":"64591.12","new_quantity":"0.0015533"},{"side":"offer","event_time":"2026-07-15T03:40:07.087267Z","price_level":"64594.31","new_quantity":"0.0015533"},{"side":"offer","event_time":"2026-07-15T03:40:07.087267Z","price_level":"64597.5","new_quantity":"0.0015533"},{"side":"offer","event_time":"2026-07-15T03:40:07.087267Z","price_level":"64600.69","new_quantity":"0.0015533"},{"side":"offer","event_time":"2026-07-15T03:40:07.087267Z","price_level":"64603.88","new_quantity":"0.0015533"},{"side":"offer","event_time":"2026-07-15T03:40:07.087267Z","price_level":"64607.07","new_quantity":"0.0015533"},{"side":"offer","event_time":"2026-07-15T03:40:07.087267Z","price_level":"64610.26","new_quantity":"0.0015533"},{"side":"offer","event_time":"2026-07-15T03:40:07.087267Z","price_level":"64613.45","new_quantity":"0.0015533"},{"side":"offer","event_time":"2026-07-15T03:40:07.087267Z","price_level":"64616.64","new_quantity":"0.0015533"},{"side":"offer","event_time":"2026-07-15T03:40:07.087267Z","price_level":"64619.83","new_quantity":"0.0015533"},{"side":"offer","event_time":"2026-07-15T03:40:07.087267Z","price_level":"64623.02","new_quantity":"0.0015533"},{"side":"offer","event_time":"2026-07-15T03:40:07.087267Z","price_level":"64626.21","new_quantity":"0.0015533"},{"side":"offer","event_time":"2026-07-15T03:40:07.087267Z","price_level":"64641.63","new_quantity":"0"},{"side":"offer","event_time":"2026-07-15T03:40:07.087267Z","price_level":"64644.68","new_quantity":"0"},{"side":"offer","event_time":"2026-07-15T03:40:07.087267Z","price_level":"64679.68","new_quantity":"0"},{"side":"offer","event_time":"2026-07-15T03:40:07.087267Z","price_level":"64785.3","new_quantity":"0.01"},{"side":"offer","event_time":"2026-07-15T03:40:07.087267Z","price_level":"64967.49","new_quantity":"0.01061683"}]}]}
{"channel":"l2_data","timestamp":"2026-07-15T03:40:07.194257068Z","sequence_num":83,"events":[{"type":"update","product_id":"BTC-USD","updates":[{"side":"bid","event_time":"2026-07-15T03:40:07.139003Z","price_level":"64564.15","new_quantity":"0.12378505"},{"side":"bid","event_time":"2026-07-15T03:40:07.139003Z","price_level":"64564.01","new_quantity":"0.09986626"},{"side":"bid","event_time":"2026-07-15T03:40:07.139003Z","price_level":"64564","new_quantity":"0.09231203"},{"side":"bid","event_time":"2026-07-15T03:40:07.139003Z","price_level":"64562.98","new_quantity":"0.09996626"},{"side":"bid","event_time":"2026-07-15T03:40:07.139003Z","price_level":"64562.97","new_quantity":"0.11932733"},{"side":"bid","event_time":"2026-07-15T03:40:07.139003Z","price_level":"64562.38","new_quantity":"0.00052494"},{"side":"bid","event_time":"2026-07-15T03:40:07.139003Z","price_level":"64562","new_quantity":"0.0232"},{"side":"bid","event_time":"2026-07-15T03:40:07.139003Z","price_level":"64560.45","new_quantity":"0.03093532"},{"side":"bid","event_time":"2026-07-15T03:40:07.139003Z","price_level":"64560.44","new_quantity":"0.12378505"},{"side":"bid","event_time":"2026-07-15T03:40:07.139003Z","price_level":"64558.07","new_quantity":"0.12391942"},{"side":"bid","event_time":"2026-07-15T03:40:07.139003Z","price_level":"64558.01","new_quantity":"0"},{"side":"bid","event_time":"2026-07-15T03:40:07.139003Z","price_level":"64557.03","new_quantity":"0.25358059"},{"side":"bid","event_time":"2026-07-15T03:40:07.139003Z","price_level":"64557.01","new_quantity":"0.04656107"},{"side":"bid","event_time":"2026-07-15T03:40:07.139003Z","price_level":"64557","new_quantity":"0"},{"side":"bid","event_time":"2026-07-15T03:40:07.139003Z","price_level":"64553.6","new_quantity":"0.16516458"},{"side":"bid","event_time":"2026-07-15T03:40:07.139003Z","price_level":"64553.3","new_quantity":"0"},{"side":"bid","event_time":"2026-07-15T03:40:07.139003Z","price_level":"64553.29","new_quantity":"0"},{"side":"bid","event_time":"2026-07-15T03:40:07.139003Z","price_level":"64551.94","new_quantity":"0.0483189"},{"side":"bid","event_time":"2026-07-15T03:40:07.139003Z","price_level":"64546.47","new_quantity":"0.00772597"},{"side":"bid","event_time":"2026-07-15T03:40:07.139003Z","price_level":"64544.35","new_quantity":"0"},{"side":"bid","event_time":"2026-07-15T03:40:07.139003Z","price_level":"64543.14","new_quantity":"0.00583"},{"side":"bid","event_time":"2026-07-15T03:40:07.139003Z","price_level":"64542","new_quantity":"0"},{"side":"bid","event_time":"2026-07-15T03:40:07.139003Z","price_level":"64540.4","new_quantity":"0"},{"side":"bid","event_time":"2026-07-15T03:40:07.139003Z","price_level":"64538.85","new_quantity":"0"},{"side":"bid","event_time":"2026-07-15T03:40:07.139003Z","price_level":"64538.58","new_quantity":"0.06669248"},{"side":"bid","event_time":"2026-07-15T03:40:07.139003Z","price_level":"64537.43","new_quantity":"0"},{"side":"bid","event_time":"2026-07-15T03:40:07.139003Z","price_level":"64535.31","new_quantity":"0"},{"side":"bid","event_time":"2026-07-15T03:40:07.139003Z","price_level":"64535.3","new_quantity":"0"},{"side":"bid","event_time":"2026-07-15T03:40:07.139003Z","price_level":"64533.83","new_quantity":"0"},{"side":"bid","event_time":"2026-07-15T03:40:07.139003Z","price_level":"64533.37","new_quantity":"0"},{"side":"bid","event_time":"2026-07-15T03:40:07.139003Z","price_level":"64527.75","new_quantity":"0.93198917"},{"side":"bid","event_time":"2026-07-15T03:40:07.139003Z","price_level":"64526.14","new_quantity":"0"},{"side":"bid","event_time":"2026-07-15T03:40:07.139003Z","price_level":"64522.17","new_quantity":"0.72941098"},{"side":"bid","event_time":"2026-07-15T03:40:07.139003Z","price_level":"64522.16","new_quantity":"0.61004479"},{"side":"bid","event_time":"2026-07-15T03:40:07.139003Z","price_level":"64522.15","new_quantity":"0"},{"side":"bid","event_time":"2026-07-15T03:40:07.139003Z","price_level":"64522.14","new_quantity":"0"},{"side":"bid","event_time":"2026-07-15T03:40:07.139003Z","price_level":"64518.8","new_quantity":"0.00154771"},{"side":"bid","event_time":"2026-07-15T03:40:07.139003Z","price_level":"64512.36","new_quantity":"0.00773856"},{"side":"bid","event_time":"2026-07-15T03:40:07.139003Z","price_level":"64491.13","new_quantity":"0.94452842"},{"side":"bid","event_time":"2026-07-15T03:40:07.139003Z","price_level":"64491.12","new_quantity":"1.35006766"},{"side":"bid","event_time":"2026-07-15T03:40:07.139003Z","price_level":"64491.11","new_quantity":"0"},{"side":"bid","event_time":"2026-07-15T03:40:07.139003Z","price_level":"64491.1","new_quantity":"0"},{"side":"bid","event_time":"2026-07-15T03:40:07.139003Z","price_level":"64472.88","new_quantity":"2.07581583"},{"side":"bid","event_time":"2026-07-15T03:40:07.139003Z","price_level":"64470.4","new_quantity":"0"},{"side":"bid","event_time":"2026-07-15T03:40:07.139003Z","price_level":"63459.76","new_quantity":"0"},{"side":"bid","event_time":"2026-07-15T03:40:07.139003Z","price_level":"63037.84","new_quantity":"0"},{"side":"offer","event_time":"2026-07-15T03:40:07.139003Z","price_level":"64562.39","new_quantity":"0"},{"side":"offer","event_time":"2026-07-15T03:40:07.139003Z","price_level":"64562.98","new_quantity":"0"},{"side":"offer","event_time":"2026-07-15T03:40:07.139003Z","price_level":"64564","new_quantity":"0"},{"side":"offer","event_time":"2026-07-15T03:40:07.139003Z","price_level":"64564.93","new_quantity":"0"},{"side":"offer","event_time":"2026-07-15T03:40:07.139003Z","price_level":"64565.6","new_quantity":"0"},{"side":"offer","event_time":"2026-07-15T03:40:07.139003Z","price_level":"64566","new_quantity":"0"},{"side":"offer","event_time":"2026-07-15T03:40:07.139003Z","price_level":"64567.96","new_quantity":"0"},{"side":"offer","event_time":"2026-07-15T03:40:07.139003Z","price_level":"64567.97","new_quantity":"0"},{"side":"offer","event_time":"2026-07-15T03:40:07.139003Z","price_level":"64567.98","new_quantity":"0"},{"side":"offer","event_time":"2026-07-15T03:40:07.139003Z","price_level":"64568","new_quantity":"0"},{"side":"offer","event_time":"2026-07-15T03:40:07.139003Z","price_level":"64568.09","new_quantity":"0"},{"side":"offer","event_time":"2026-07-15T03:40:07.139003Z","price_level":"64568.79","new_quantity":"0"},{"side":"offer","event_time":"2026-07-15T03:40:07.139003Z","price_level":"64569.18","new_quantity":"0"},{"side":"offer","event_time":"2026-07-15T03:40:07.139003Z","price_level":"64569.97","new_quantity":"0"},{"side":"offer","event_time":"2026-07-15T03:40:07.139003Z","price_level":"64569.98","new_quantity":"0"},{"side":"offer","event_time":"2026-07-15T03:40:07.139003Z","price_level":"64569.99","new_quantity":"0.00772597"},{"side":"offer","event_time":"2026-07-15T03:40:07.139003Z","price_level":"64571.17","new_quantity":"0.09739859"},{"side":"offer","event_time":"2026-07-15T03:40:07.139003Z","price_level":"64571.18","new_quantity":"0"},{"side":"offer","event_time":"2026-07-15T03:40:07.139003Z","price_level":"64571.98","new_quantity":"0"},{"side":"offer","event_time":"2026-07-15T03:40:07.139003Z","price_level":"64572.38","new_quantity":"0.0483189"},{"side":"offer","event_time":"2026-07-15T03:40:07.139003Z","price_level":"64573.86","new_quantity":"0"},{"side":"offer","event_time":"2026-07-15T03:40:07.139003Z","price_level":"64574.28","new_quantity":"0.05059524"},{"side":"offer","event_time":"2026-07-15T03:40:07.139003Z","price_level":"64575.17","new_quantity":"0"},{"side":"offer","event_time":"2026-07-15T03:40:07.139003Z","price_level":"64575.43","new_quantity":"0"},{"side":"offer","event_time":"2026-07-15T03:40:07.139003Z","price_level":"64577.03","new_quantity":"0"},{"side":"offer","event_time":"2026-07-15T03:40:07.139003Z","price_level":"64577.74","new_quantity":"0"},{"side":"offer","event_time":"2026-07-15T03:40:07.139003Z","price_level":"64578.36","new_quantity":"0"},{"side":"offer","event_time":"2026-07-15T03:40:07.139003Z","price_level":"64578.8","new_quantity":"0.179558"},{"side":"offer","event_time":"2026-07-15T03:40:07.139003Z","price_level":"64579.88","new_quantity":"0"},{"side":"offer","event_time":"2026-07-15T03:40:07.139003Z","price_level":"64580.51","new_quantity":"0"},{"side":"offer","event_time":"2026-07-15T03:40:07.139003Z","price_level":"64581.17","new_quantity":"0"},{"side":"offer","event_time":"2026-07-15T03:40:07.139003Z","price_level":"64581.55","new_quantity":"0"},{"side":"offer","event_time":"2026-07-15T03:40:07.139003Z","price_level":"64581.82","new_quantity":"0.00583"},{"side":"offer","event_time":"2026-07-15T03:40:07.139003Z","price_level":"64582.09","new_quantity":"0"},{"side":"offer","event_time":"2026-07-15T03:40:07.139003Z","price_level":"64582.11","new_quantity":"0"},{"side":"offer","event_time":"2026-07-15T03:40:07.139003Z","price_level":"64582.48","new_quantity":"0"},{"side":"offer","event_time":"2026-07-15T03:40:07.139003Z","price_level":"64583.2","new_quantity":"0"},{"side":"offer","event_time":"2026-07-15T03:40:07.139003Z","price_level":"64583.84","new_quantity":"0"},{"side":"offer","event_time":"2026-07-15T03:40:07.139003Z","price_level":"64584.74","new_quantity":"0"},{"side":"offer","event_time":"2026-07-15T03:40:07.139003Z","price_level":"64585.49","new_quantity":"0"},{"side":"offer","event_time":"2026-07-15T03:40:07.139003Z","price_level":"64585.5","new_quantity":"0"},{"side":"offer","event_time":"2026-07-15T03:40:07.139003Z","price_level":"64587.93","new_quantity":"0"},{"side":"offer","event_time":"2026-07-15T03:40:07.139003Z","price_level":"64588.14","new_quantity":"0"},{"side":"offer","event_time":"2026-07-15T03:40:07.139003Z","price_level":"64588.29","new_quantity":"0"},{"side":"offer","event_time":"2026-07-15T03:40:07.139003Z","price_level":"64591.12","new_quantity":"0"},{"side":"offer","event_time":"2026-07-15T03:40:07.139003Z","price_level":"64591.3","new_quantity":"0.30683822"},{"side":"offer","event_time":"2026-07-15T03:40:07.139003Z","price_level":"64591.31","new_quantity":"0"},{"side":"offer","event_time":"2026-07-15T03:40:07.139003Z","price_level":"64591.73","new_quantity":"0.08"},{"side":"offer","event_time":"2026-07-15T03:40:07.139003Z","price_level":"64593.45","new_quantity":"0"},{"side":"offer","event_time":"2026-07-15T03:40:07.139003Z","price_level":"64593.46","new_quantity":"0"},{"side":"offer","event_time":"2026-07-15T03:40:07.139003Z","price_level":"64594.17","new_quantity":"0"},{"side":"offer","event_time":"2026-07-15T03:40:07.139003Z","price_level":"64594.31","new_quantity":"0"},{"side":"offer","event_time":"2026-07-15T03:40:07.139003Z","price_level":"64594.8","new_quantity":"0.67930069"},{"side":"offer","event_time":"2026-07-15T03:40:07.139003Z","price_level":"64595.42","new_quantity":"0.63870312"},{"side":"offer","event_time":"2026-07-15T03:40:07.139003Z","price_level":"64595.43","new_quantity":"0"},{"side":"offer","event_time":"2026-07-15T03:40:07.139003Z","price_level":"64596.25","new_quantity":"0"},{"side":"offer","event_time":"2026-07-15T03:40:07.139003Z","price_level":"64597.5","new_quantity":"0"},{"side":"offer","event_time":"2026-07-15T03:40:07.139003Z","price_level":"64597.96","new_quantity":"0"},{"side":"offer","event_time":"2026-07-15T03:40:07.139003Z","price_level":"64600.69","new_quantity":"0"},{"side":"offer","event_time":"2026-07-15T03:40:07.139003Z","price_level":"64603.54","new_quantity":"0"},{"side":"offer","event_time":"2026-07-15T03:40:07.139003Z","price_level":"64603.56","new_quantity":"0"},{"side":"offer","event_time":"2026-07-15T03:40:07.139003Z","price_level":"64603.88","new_quantity":"0"},{"side":"offer","event_time":"2026-07-15T03:40:07.139003Z","price_level":"64607.07","new_quantity":"0"},{"side":"offer","event_time":"2026-07-15T03:40:07.139003Z","price_level":"64609.74","new_quantity":"0"},{"side":"offer","event_time":"2026-07-15T03:40:07.139003Z","price_level":"64610.26","new_quantity":"0"},{"side":"offer","event_time":"2026-07-15T03:40:07.139003Z","price_level":"64613.32","new_quantity":"0.4560798"},{"side":"offer","event_time":"2026-07-15T03:40:07.139003Z","price_level":"64613.33","new_quantity":"0.68567262"},{"side":"offer","event_time":"2026-07-15T03:40:07.139003Z","price_level":"64613.34","new_quantity":"0"},{"side":"offer","event_time":"2026-07-15T03:40:07.139003Z","price_level":"64613.35","new_quantity":"0"},{"side":"offer","event_time":"2026-07-15T03:40:07.139003Z","price_level":"64613.43","new_quantity":"0"},{"side":"offer","event_time":"2026-07-15T03:40:07.139003Z","price_level":"64613.45","new_quantity":"0"},{"side":"offer","event_time":"2026-07-15T03:40:07.139003Z","price_level":"64615.6","new_quantity":"0.01615943"},{"side":"offer","event_time":"2026-07-15T03:40:07.139003Z","price_level":"64616.42","new_quantity":"0.29330743"},{"side":"offer","event_time":"2026-07-15T03:40:07.139003Z","price_level":"64616.43","new_quantity":"0.45879038"},{"side":"offer","event_time":"2026-07-15T03:40:07.139003Z","price_level":"64616.44","new_quantity":"0"},{"side":"offer","event_time":"2026-07-15T03:40:07.139003Z","price_level":"64616.45","new_quantity":"0"},{"side":"offer","event_time":"2026-07-15T03:40:07.139003Z","price_level":"64616.53","new_quantity":"0"},{"side":"offer","event_time":"2026-07-15T03:40:07.139003Z","price_level":"64616.64","new_quantity":"0"},{"side":"offer","event_time":"2026-07-15T03:40:07.139003Z","price_level":"64619.83","new_quantity":"0"},{"side":"offer","event_time":"2026-07-15T03:40:07.139003Z","price_level":"64621.67","new_quantity":"0"},{"side":"offer","event_time":"2026-07-15T03:40:07.139003Z","price_level":"64623.02","new_quantity":"0"},{"side":"offer","event_time":"2026-07-15T03:40:07.139003Z","price_level":"64626.21","new_quantity":"0"},{"side":"offer","event_time":"2026-07-15T03:40:07.139003Z","price_level":"64626.4","new_quantity":"2.08992124"},{"side":"offer","event_time":"2026-07-15T03:40:07.139003Z","price_level":"64626.86","new_quantity":"0"},{"side":"offer","event_time":"2026-07-15T03:40:07.139003Z","price_level":"64790.42","new_quantity":"0"},{"side":"offer","event_time":"2026-07-15T03:40:07.139003Z","price_level":"64798.05","new_quantity":"0.00583"},{"side":"offer","event_time":"2026-07-15T03:40:07.139003Z","price_level":"64967.49","new_quantity":"0"},{"side":"offer","event_time":"2026-07-15T03:40:07.139003Z","price_level":"65439.54","new_quantity":"0.00583"},{"side":"offer","event_time":"2026-07-15T03:40:07.139003Z","price_level":"65439.81","new_quantity":"0"},{"side":"offer","event_time":"2026-07-15T03:40:07.139003Z","price_level":"65439.83","new_quantity":"0"}]}]}
{"channel":"l2_data","timestamp":"2026-07-15T03:40:07.241865328Z","sequence_num":84,"events":[{"type":"update","product_id":"BTC-USD","updates":[{"side":"bid","event_time":"2026-07-15T03:40:07.191236Z","price_level":"64568.51","new_quantity":"0.2023562"},{"side":"bid","event_time":"2026-07-15T03:40:07.191236Z","price_level":"64566.89","new_quantity":"0.12378505"},{"side":"bid","event_time":"2026-07-15T03:40:07.191236Z","price_level":"64566.86","new_quantity":"0.00159977"},{"side":"bid","event_time":"2026-07-15T03:40:07.191236Z","price_level":"64566.85","new_quantity":"0"},{"side":"bid","event_time":"2026-07-15T03:40:07.191236Z","price_level":"64566","new_quantity":"0.0232"},{"side":"bid","event_time":"2026-07-15T03:40:07.191236Z","price_level":"64565.66","new_quantity":"0"},{"side":"bid","event_time":"2026-07-15T03:40:07.191236Z","price_level":"64564.91","new_quantity":"0.12378505"},{"side":"bid","event_time":"2026-07-15T03:40:07.191236Z","price_level":"64564.15","new_quantity":"0"},{"side":"bid","event_time":"2026-07-15T03:40:07.191236Z","price_level":"64564.01","new_quantity":"0"},{"side":"bid","event_time":"2026-07-15T03:40:07.191236Z","price_level":"64564","new_quantity":"0.0232"},{"side":"bid","event_time":"2026-07-15T03:40:07.191236Z","price_level":"64563.65","new_quantity":"0.1548859"},{"side":"bid","event_time":"2026-07-15T03:40:07.191236Z","price_level":"64562.98","new_quantity":"0"},{"side":"bid","event_time":"2026-07-15T03:40:07.191236Z","price_level":"64562.97","new_quantity":"0.04656107"},{"side":"bid","event_time":"2026-07-15T03:40:07.191236Z","price_level":"64561.25","new_quantity":"0"},{"side":"bid","event_time":"2026-07-15T03:40:07.191236Z","price_level":"64560.45","new_quantity":"0.12038881"},{"side":"bid","event_time":"2026-07-15T03:40:07.191236Z","price_level":"64559.77","new_quantity":"0.0483189"},{"side":"bid","event_time":"2026-07-15T03:40:07.191236Z","price_level":"64559.22","new_quantity":"0"},{"side":"bid","event_time":"2026-07-15T03:40:07.191236Z","price_level":"64558.07","new_quantity":"0"},{"side":"bid","event_time":"2026-07-15T03:40:07.191236Z","price_level":"64557.03","new_quantity":"0.16765884"},{"side":"bid","event_time":"2026-07-15T03:40:07.191236Z","price_level":"64556.45","new_quantity":"0"},{"side":"bid","event_time":"2026-07-15T03:40:07.191236Z","price_level":"64556.03","new_quantity":"0"},{"side":"bid","event_time":"2026-07-15T03:40:07.191236Z","price_level":"64555.57","new_quantity":"0"},{"side":"bid","event_time":"2026-07-15T03:40:07.191236Z","price_level":"64553.39","new_quantity":"0.00583"},{"side":"bid","event_time":"2026-07-15T03:40:07.191236Z","price_level":"64552.84","new_quantity":"0"},{"side":"bid","event_time":"2026-07-15T03:40:07.191236Z","price_level":"64551.94","new_quantity":"0"},{"side":"bid","event_time":"2026-07-15T03:40:07.191236Z","price_level":"64549.65","new_quantity":"0"},{"side":"bid","event_time":"2026-07-15T03:40:07.191236Z","price_level":"64546.46","new_quantity":"0"},{"side":"bid","event_time":"2026-07-15T03:40:07.191236Z","price_level":"64543.27","new_quantity":"0"},{"side":"bid","event_time":"2026-07-15T03:40:07.191236Z","price_level":"64543.14","new_quantity":"0"},{"side":"bid","event_time":"2026-07-15T03:40:07.191236Z","price_level":"64541.39","new_quantity":"0.07520896"},{"side":"bid","event_time":"2026-07-15T03:40:07.191236Z","price_level":"64540.08","new_quantity":"0"},{"side":"bid","event_time":"2026-07-15T03:40:07.191236Z","price_level":"64539.43","new_quantity":"0"},{"side":"bid","event_time":"2026-07-15T03:40:07.191236Z","price_level":"64536.89","new_quantity":"0"},{"side":"bid","event_time":"2026-07-15T03:40:07.191236Z","price_level":"64534.51","new_quantity":"0.59866113"},{"side":"bid","event_time":"2026-07-15T03:40:07.191236Z","price_level":"64534.5","new_quantity":"1"},{"side":"bid","event_time":"2026-07-15T03:40:07.191236Z","price_level":"64530.87","new_quantity":"0.00154743"},{"side":"bid","event_time":"2026-07-15T03:40:07.191236Z","price_level":"64524.42","new_quantity":"0.00773717"},{"side":"bid","event_time":"2026-07-15T03:40:07.191236Z","price_level":"64518.8","new_quantity":"0"},{"side":"bid","event_time":"2026-07-15T03:40:07.191236Z","price_level":"64512.36","new_quantity":"0"},{"side":"bid","event_time":"2026-07-15T03:40:07.191236Z","price_level":"64498.61","new_quantity":"0"},{"side":"bid","event_time":"2026-07-15T03:40:07.191236Z","price_level":"64480.02","new_quantity":"0"},{"side":"bid","event_time":"2026-07-15T03:40:07.191236Z","price_level":"64480","new_quantity":"0"},{"side":"bid","event_time":"2026-07-15T03:40:07.191236Z","price_level":"64474.84","new_quantity":"0.00348481"},{"side":"bid","event_time":"2026-07-15T03:40:07.191236Z","price_level":"64336.59","new_quantity":"0.00583"},{"side":"bid","event_time":"2026-07-15T03:40:07.191236Z","price_level":"63955.62","new_quantity":"0"},{"side":"bid","event_time":"2026-07-15T03:40:07.191236Z","price_level":"63266.12","new_quantity":"0.00583"},{"side":"bid","event_time":"2026-07-15T03:40:07.191236Z","price_level":"63050.01","new_quantity":"0.00583"},{"side":"offer","event_time":"2026-07-15T03:40:07.191236Z","price_level":"64566.86","new_quantity":"0"},{"side":"offer","event_time":"2026-07-15T03:40:07.191236Z","price_level":"64566.9","new_quantity":"0"},{"side":"offer","event_time":"2026-07-15T03:40:07.191236Z","price_level":"64568.52","new_quantity":"0.00774381"},{"side":"offer","event_time":"2026-07-15T03:40:07.191236Z","price_level":"64568.53","new_quantity":"0"},{"side":"offer","event_time":"2026-07-15T03:40:07.191236Z","price_level":"64569.99","new_quantity":"0"},{"side":"offer","event_time":"2026-07-15T03:40:07.191236Z","price_level":"64570","new_quantity":"0"},{"side":"offer","event_time":"2026-07-15T03:40:07.191236Z","price_level":"64570.14","new_quantity":"0.00774381"},{"side":"offer","event_time":"2026-07-15T03:40:07.191236Z","price_level":"64570.71","new_quantity":"0"},{"side":"offer","event_time":"2026-07-15T03:40:07.191236Z","price_level":"64571.17","new_quantity":"0"},{"side":"offer","event_time":"2026-07-15T03:40:07.191236Z","price_level":"64572","new_quantity":"0"},{"side":"offer","event_time":"2026-07-15T03:40:07.191236Z","price_level":"64572.32","new_quantity":"0.00967976"},{"side":"offer","event_time":"2026-07-15T03:40:07.191236Z","price_level":"64572.38","new_quantity":"0"},{"side":"offer","event_time":"2026-07-15T03:40:07.191236Z","price_level":"64574.28","new_quantity":"0"},{"side":"offer","event_time":"2026-07-15T03:40:07.191236Z","price_level":"64575.4","new_quantity":"0.05428032"},{"side":"offer","event_time":"2026-07-15T03:40:07.191236Z","price_level":"64576.78","new_quantity":"0"},{"side":"offer","event_time":"2026-07-15T03:40:07.191236Z","price_level":"64577.7","new_quantity":"0.04656107"},{"side":"offer","event_time":"2026-07-15T03:40:07.191236Z","price_level":"64577.71","new_quantity":"0.00159977"},{"side":"offer","event_time":"2026-07-15T03:40:07.191236Z","price_level":"64577.72","new_quantity":"0.08902844"},{"side":"offer","event_time":"2026-07-15T03:40:07.191236Z","price_level":"64578.8","new_quantity":"0"},{"side":"offer","event_time":"2026-07-15T03:40:07.191236Z","price_level":"64578.81","new_quantity":"0"},{"side":"offer","event_time":"2026-07-15T03:40:07.191236Z","price_level":"64578.83","new_quantity":"0.12387961"},{"side":"offer","event_time":"2026-07-15T03:40:07.191236Z","price_level":"64580.72","new_quantity":"0"},{"side":"offer","event_time":"2026-07-15T03:40:07.191236Z","price_level":"64581.16","new_quantity":"0"},{"side":"offer","event_time":"2026-07-15T03:40:07.191236Z","price_level":"64581.82","new_quantity":"0"},{"side":"offer","event_time":"2026-07-15T03:40:07.191236Z","price_level":"64583.64","new_quantity":"0.02779696"},{"side":"offer","event_time":"2026-07-15T03:40:07.191236Z","price_level":"64583.65","new_quantity":"0.04656107"},{"side":"offer","event_time":"2026-07-15T03:40:07.191236Z","price_level":"64583.72","new_quantity":"0"},{"side":"offer","event_time":"2026-07-15T03:40:07.191236Z","price_level":"64583.9","new_quantity":"0"},{"side":"offer","event_time":"2026-07-15T03:40:07.191236Z","price_level":"64586.73","new_quantity":"0.12378505"},{"side":"offer","event_time":"2026-07-15T03:40:07.191236Z","price_level":"64586.85","new_quantity":"0.01846839"},{"side":"offer","event_time":"2026-07-15T03:40:07.191236Z","price_level":"64586.86","new_quantity":"0.03093532"},{"side":"offer","event_time":"2026-07-15T03:40:07.191236Z","price_level":"64587.56","new_quantity":"0.20889276"},{"side":"offer","event_time":"2026-07-15T03:40:07.191236Z","price_level":"64587.57","new_quantity":"0.179558"},{"side":"offer","event_time":"2026-07-15T03:40:07.191236Z","price_level":"64587.6","new_quantity":"0"},{"side":"offer","event_time":"2026-07-15T03:40:07.191236Z","price_level":"64587.64","new_quantity":"0"},{"side":"offer","event_time":"2026-07-15T03:40:07.191236Z","price_level":"64588.82","new_quantity":"0.12378505"},{"side":"offer","event_time":"2026-07-15T03:40:07.191236Z","price_level":"64588.83","new_quantity":"0.04656107"},{"side":"offer","event_time":"2026-07-15T03:40:07.191236Z","price_level":"64589.12","new_quantity":"0"},{"side":"offer","event_time":"2026-07-15T03:40:07.191236Z","price_level":"64589.79","new_quantity":"0"},{"side":"offer","event_time":"2026-07-15T03:40:07.191236Z","price_level":"64590.26","new_quantity":"0"},{"side":"offer","event_time":"2026-07-15T03:40:07.191236Z","price_level":"64590.34","new_quantity":"0"},{"side":"offer","event_time":"2026-07-15T03:40:07.191236Z","price_level":"64590.81","new_quantity":"0.16975899"},{"side":"offer","event_time":"2026-07-15T03:40:07.191236Z","price_level":"64590.82","new_quantity":"0.12378505"},{"side":"offer","event_time":"2026-07-15T03:40:07.191236Z","price_level":"64591.28","new_quantity":"0"},{"side":"offer","event_time":"2026-07-15T03:40:07.191236Z","price_level":"64591.3","new_quantity":"0"},{"side":"offer","event_time":"2026-07-15T03:40:07.191236Z","price_level":"64591.73","new_quantity":"0"},{"side":"offer","event_time":"2026-07-15T03:40:07.191236Z","price_level":"64591.97","new_quantity":"0"},{"side":"offer","event_time":"2026-07-15T03:40:07.191236Z","price_level":"64592.17","new_quantity":"0.03093532"},{"side":"offer","event_time":"2026-07-15T03:40:07.191236Z","price_level":"64592.79","new_quantity":"0.12378505"},{"side":"offer","event_time":"2026-07-15T03:40:07.191236Z","price_level":"64593.19","new_quantity":"0.00583"},{"side":"offer","event_time":"2026-07-15T03:40:07.191236Z","price_level":"64594.78","new_quantity":"0.04656107"},{"side":"offer","event_time":"2026-07-15T03:40:07.191236Z","price_level":"64594.79","new_quantity":"0.12378505"},{"side":"offer","event_time":"2026-07-15T03:40:07.191236Z","price_level":"64597.41","new_quantity":"0"},{"side":"offer","event_time":"2026-07-15T03:40:07.191236Z","price_level":"64599.3","new_quantity":"0.07389967"},{"side":"offer","event_time":"2026-07-15T03:40:07.191236Z","price_level":"64599.31","new_quantity":"0.12378505"},{"side":"offer","event_time":"2026-07-15T03:40:07.191236Z","price_level":"64601.94","new_quantity":"0.00077438"},{"side":"offer","event_time":"2026-07-15T03:40:07.191236Z","price_level":"64603.03","new_quantity":"0.09814285"},{"side":"offer","event_time":"2026-07-15T03:40:07.191236Z","price_level":"64603.04","new_quantity":"0.04656107"},{"side":"offer","event_time":"2026-07-15T03:40:07.191236Z","price_level":"64603.19","new_quantity":"0.12378505"},{"side":"offer","event_time":"2026-07-15T03:40:07.191236Z","price_level":"64603.26","new_quantity":"0.06586832"},{"side":"offer","event_time":"2026-07-15T03:40:07.191236Z","price_level":"64603.42","new_quantity":"0"},{"side":"offer","event_time":"2026-07-15T03:40:07.191236Z","price_level":"64603.53","new_quantity":"0"},{"side":"offer","event_time":"2026-07-15T03:40:07.191236Z","price_level":"64604.66","new_quantity":"0"},{"side":"offer","event_time":"2026-07-15T03:40:07.191236Z","price_level":"64605.12","new_quantity":"0.03093532"},{"side":"offer","event_time":"2026-07-15T03:40:07.191236Z","price_level":"64606.11","new_quantity":"0"},{"side":"offer","event_time":"2026-07-15T03:40:07.191236Z","price_level":"64607.06","new_quantity":"0.16376293"},{"side":"offer","event_time":"2026-07-15T03:40:07.191236Z","price_level":"64607.07","new_quantity":"0.12378505"},{"side":"offer","event_time":"2026-07-15T03:40:07.191236Z","price_level":"64607.16","new_quantity":"0"},{"side":"offer","event_time":"2026-07-15T03:40:07.191236Z","price_level":"64609.73","new_quantity":"0.10853808"},{"side":"offer","event_time":"2026-07-15T03:40:07.191236Z","price_level":"64610.66","new_quantity":"0"},{"side":"offer","event_time":"2026-07-15T03:40:07.191236Z","price_level":"64610.95","new_quantity":"0.12378505"},{"side":"offer","event_time":"2026-07-15T03:40:07.191236Z","price_level":"64613.3","new_quantity":"0.12378505"},{"side":"offer","event_time":"2026-07-15T03:40:07.191236Z","price_level":"64613.31","new_quantity":"0.04656107"},{"side":"offer","event_time":"2026-07-15T03:40:07.191236Z","price_level":"64613.53","new_quantity":"0"},{"side":"offer","event_time":"2026-07-15T03:40:07.191236Z","price_level":"64615.02","new_quantity":"0.00104541"},{"side":"offer","event_time":"2026-07-15T03:40:07.191236Z","price_level":"64616.41","new_quantity":"0.03093532"},{"side":"offer","event_time":"2026-07-15T03:40:07.191236Z","price_level":"64619.39","new_quantity":"0.0278077"},{"side":"offer","event_time":"2026-07-15T03:40:07.191236Z","price_level":"64626.39","new_quantity":"1.49432367"},{"side":"offer","event_time":"2026-07-15T03:40:07.191236Z","price_level":"64626.54","new_quantity":"0"},{"side":"offer","event_time":"2026-07-15T03:40:07.191236Z","price_level":"64628.15","new_quantity":"0"},{"side":"offer","event_time":"2026-07-15T03:40:07.191236Z","price_level":"64631.49","new_quantity":"0.00158748"},{"side":"offer","event_time":"2026-07-15T03:40:07.191236Z","price_level":"64633.39","new_quantity":"0"},{"side":"offer","event_time":"2026-07-15T03:40:07.191236Z","price_level":"64634.99","new_quantity":"0.60665793"},{"side":"offer","event_time":"2026-07-15T03:40:07.191236Z","price_level":"64635","new_quantity":"1"},{"side":"offer","event_time":"2026-07-15T03:40:07.191236Z","price_level":"64636.28","new_quantity":"0.06598222"},{"side":"offer","event_time":"2026-07-15T03:40:07.191236Z","price_level":"64638.45","new_quantity":"0.04656107"},{"side":"offer","event_time":"2026-07-15T03:40:07.191236Z","price_level":"64647.51","new_quantity":"0.02501589"},{"side":"offer","event_time":"2026-07-15T03:40:07.191236Z","price_level":"64647.52","new_quantity":"0.03093532"},{"side":"offer","event_time":"2026-07-15T03:40:07.191236Z","price_level":"64648.77","new_quantity":"0.0278077"},{"side":"offer","event_time":"2026-07-15T03:40:07.191236Z","price_level":"64648.78","new_quantity":"0.04656107"},{"side":"offer","event_time":"2026-07-15T03:40:07.191236Z","price_level":"64651.35","new_quantity":"0.00240058"},{"side":"offer","event_time":"2026-07-15T03:40:07.191236Z","price_level":"64657.84","new_quantity":"0.01846839"},{"side":"offer","event_time":"2026-07-15T03:40:07.191236Z","price_level":"64657.85","new_quantity":"0.03093532"},{"side":"offer","event_time":"2026-07-15T03:40:07.191236Z","price_level":"64659.11","new_quantity":"0"},{"side":"offer","event_time":"2026-07-15T03:40:07.191236Z","price_level":"64798.05","new_quantity":"0"},{"side":"offer","event_time":"2026-07-15T03:40:07.191236Z","price_level":"64807.93","new_quantity":"0.00385"},{"side":"offer","event_time":"2026-07-15T03:40:07.191236Z","price_level":"64843.2","new_quantity":"0"},{"side":"offer","event_time":"2026-07-15T03:40:07.191236Z","price_level":"64849.51","new_quantity":"1.38782853"},{"side":"offer","event_time":"2026-07-15T03:40:07.191236Z","price_level":"65222.4","new_quantity":"0.3"},{"side":"offer","event_time":"2026-07-15T03:40:07.191236Z","price_level":"65665.34","new_quantity":"0.00583"}]}]}
{"channel":"market_trades","timestamp":"2026-07-15T03:40:07.284248836Z","sequence_num":85,"events":[{"type":"update","trades":[{"product_id":"BTC-USD","trade_id":"1056309424","price":"64566.9","size":"0.01263062","time":"2026-07-15T03:40:07.148793Z","side":"SELL"},{"product_id":"BTC-USD","trade_id":"1056309423","price":"64566.86","size":"0.00774402","time":"2026-07-15T03:40:07.148793Z","side":"SELL"}]}]}
{"channel":"l2_data","timestamp":"2026-07-15T03:40:07.289977018Z","sequence_num":86,"events":[{"type":"update","product_id":"BTC-USD","updates":[{"side":"bid","event_time":"2026-07-15T03:40:07.218489Z","price_level":"64567.98","new_quantity":"0.12390042"},{"side":"bid","event_time":"2026-07-15T03:40:07.218489Z","price_level":"64566.9","new_quantity":"0.03093532"},{"side":"bid","event_time":"2026-07-15T03:40:07.218489Z","price_level":"64562.38","new_quantity":"0.04052494"},{"side":"bid","event_time":"2026-07-15T03:40:07.218489Z","price_level":"64559.77","new_quantity":"0"},{"side":"bid","event_time":"2026-07-15T03:40:07.218489Z","price_level":"64558.01","new_quantity":"0.00772597"},{"side":"bid","event_time":"2026-07-15T03:40:07.218489Z","price_level":"64546.47","new_quantity":"0"},{"side":"bid","event_time":"2026-07-15T03:40:07.218489Z","price_level":"64534.51","new_quantity":"0.92733513"},{"side":"bid","event_time":"2026-07-15T03:40:07.218489Z","price_level":"64532.37","new_quantity":"0.60994827"},{"side":"bid","event_time":"2026-07-15T03:40:07.218489Z","price_level":"64532.36","new_quantity":"0.06879819"},{"side":"bid","event_time":"2026-07-15T03:40:07.218489Z","price_level":"64522.17","new_quantity":"0.36521424"},{"side":"bid","event_time":"2026-07-15T03:40:07.218489Z","price_level":"64522.16","new_quantity":"0"},{"side":"bid","event_time":"2026-07-15T03:40:07.218489Z","price_level":"64502.58","new_quantity":"1.71014239"},{"side":"bid","event_time":"2026-07-15T03:40:07.218489Z","price_level":"64502.57","new_quantity":"1.34982801"},{"side":"bid","event_time":"2026-07-15T03:40:07.218489Z","price_level":"64502.56","new_quantity":"0"},{"side":"bid","event_time":"2026-07-15T03:40:07.218489Z","price_level":"64491.13","new_quantity":"0"},{"side":"bid","event_time":"2026-07-15T03:40:07.218489Z","price_level":"64491.12","new_quantity":"0"},{"side":"bid","event_time":"2026-07-15T03:40:07.218489Z","price_level":"64490.95","new_quantity":"0.13853803"},{"side":"bid","event_time":"2026-07-15T03:40:07.218489Z","price_level":"64486.28","new_quantity":"1.82641975"},{"side":"bid","event_time":"2026-07-15T03:40:07.218489Z","price_level":"64485","new_quantity":"3"},{"side":"bid","event_time":"2026-07-15T03:40:07.218489Z","price_level":"64336.78","new_quantity":"0.00583"},{"side":"bid","event_time":"2026-07-15T03:40:07.218489Z","price_level":"64336.59","new_quantity":"0"},{"side":"bid","event_time":"2026-07-15T03:40:07.218489Z","price_level":"64318.84","new_quantity":"0"},{"side":"bid","event_time":"2026-07-15T03:40:07.218489Z","price_level":"63050.01","new_quantity":"0"},{"side":"offer","event_time":"2026-07-15T03:40:07.218489Z","price_level":"64570.14","new_quantity":"0.00918455"},{"side":"offer","event_time":"2026-07-15T03:40:07.218489Z","price_level":"64577.7","new_quantity":"0"},{"side":"offer","event_time":"2026-07-15T03:40:07.218489Z","price_level":"64577.72","new_quantity":"0.08902719"},{"side":"offer","event_time":"2026-07-15T03:40:07.218489Z","price_level":"64578.83","new_quantity":"0"},{"side":"offer","event_time":"2026-07-15T03:40:07.218489Z","price_level":"64579.92","new_quantity":"0.12387751"},{"side":"offer","event_time":"2026-07-15T03:40:07.218489Z","price_level":"64582.67","new_quantity":"0.12023661"},{"side":"offer","event_time":"2026-07-15T03:40:07.218489Z","price_level":"64582.68","new_quantity":"0.15484028"},{"side":"offer","event_time":"2026-07-15T03:40:07.218489Z","price_level":"64583.64","new_quantity":"0"},{"side":"offer","event_time":"2026-07-15T03:40:07.218489Z","price_level":"64586.7","new_quantity":"0.12566451"},{"side":"offer","event_time":"2026-07-15T03:40:07.218489Z","price_level":"64586.71","new_quantity":"0.179558"},{"side":"offer","event_time":"2026-07-15T03:40:07.218489Z","price_level":"64586.73","new_quantity":"0"},{"side":"offer","event_time":"2026-07-15T03:40:07.218489Z","price_level":"64586.85","new_quantity":"0"},{"side":"offer","event_time":"2026-07-15T03:40:07.218489Z","price_level":"64587.56","new_quantity":"0.02779696"},{"side":"offer","event_time":"2026-07-15T03:40:07.218489Z","price_level":"64587.57","new_quantity":"0"},{"side":"offer","event_time":"2026-07-15T03:40:07.218489Z","price_level":"64588.82","new_quantity":"0"},{"side":"offer","event_time":"2026-07-15T03:40:07.218489Z","price_level":"64590.81","new_quantity":"0.02602923"},{"side":"offer","event_time":"2026-07-15T03:40:07.218489Z","price_level":"64590.82","new_quantity":"0"},{"side":"offer","event_time":"2026-07-15T03:40:07.218489Z","price_level":"64591.82","new_quantity":"0.00153313"},{"side":"offer","event_time":"2026-07-15T03:40:07.218489Z","price_level":"64591.89","new_quantity":"0.00098673"},{"side":"offer","event_time":"2026-07-15T03:40:07.218489Z","price_level":"64592.79","new_quantity":"0"},{"side":"offer","event_time":"2026-07-15T03:40:07.218489Z","price_level":"64592.88","new_quantity":"0.00583"},{"side":"offer","event_time":"2026-07-15T03:40:07.218489Z","price_level":"64593.19","new_quantity":"0"},{"side":"offer","event_time":"2026-07-15T03:40:07.218489Z","price_level":"64604.17","new_quantity":"0.00306626"},{"side":"offer","event_time":"2026-07-15T03:40:07.218489Z","price_level":"64613.29","new_quantity":"0.11938193"},{"side":"offer","event_time":"2026-07-15T03:40:07.218489Z","price_level":"64613.32","new_quantity":"0"},{"side":"offer","event_time":"2026-07-15T03:40:07.218489Z","price_level":"64613.33","new_quantity":"0"},{"side":"offer","event_time":"2026-07-15T03:40:07.218489Z","price_level":"64616.4","new_quantity":"0.01848225"},{"side":"offer","event_time":"2026-07-15T03:40:07.218489Z","price_level":"64616.42","new_quantity":"0"},{"side":"offer","event_time":"2026-07-15T03:40:07.218489Z","price_level":"64616.43","new_quantity":"0"},{"side":"offer","event_time":"2026-07-15T03:40:07.218489Z","price_level":"64620.04","new_quantity":"0.00383282"},{"side":"offer","event_time":"2026-07-15T03:40:07.218489Z","price_level":"64626.37","new_quantity":"2.33653721"},{"side":"offer","event_time":"2026-07-15T03:40:07.218489Z","price_level":"64626.38","new_quantity":"1.89034534"},{"side":"offer","event_time":"2026-07-15T03:40:07.218489Z","price_level":"64626.39","new_quantity":"0.03093532"},{"side":"offer","event_time":"2026-07-15T03:40:07.218489Z","price_level":"64634.99","new_quantity":"0"},{"side":"offer","event_time":"2026-07-15T03:40:07.218489Z","price_level":"64635","new_quantity":"0"},{"side":"offer","event_time":"2026-07-15T03:40:07.218489Z","price_level":"64636.78","new_quantity":"0"},{"side":"offer","event_time":"2026-07-15T03:40:07.218489Z","price_level":"64676.28","new_quantity":"0"},{"side":"offer","event_time":"2026-07-15T03:40:07.218489Z","price_level":"65004.91","new_quantity":"0"},{"side":"offer","event_time":"2026-07-15T03:40:07.218489Z","price_level":"65022.81","new_quantity":"0.00583"},{"side":"offer","event_time":"2026-07-15T03:40:07.218489Z","price_level":"65219.82","new_quantity":"0"},{"side":"offer","event_time":"2026-07-15T03:40:07.218489Z","price_level":"65665.03","new_quantity":"0.00583"},{"side":"offer","event_time":"2026-07-15T03:40:07.218489Z","price_level":"65665.34","new_quantity":"0"}]}]}
{"channel":"l2_data","timestamp":"2026-07-15T03:40:07.341898138Z","sequence_num":87,"events":[{"type":"update","product_id":"BTC-USD","updates":[{"side":"bid","event_time":"2026-07-15T03:40:07.273972Z","price_level":"64568.51","new_quantity":"0.25866532"},{"side":"bid","event_time":"2026-07-15T03:40:07.273972Z","price_level":"64568","new_quantity":"0.0232"},{"side":"bid","event_time":"2026-07-15T03:40:07.273972Z","price_level":"64567.5","new_quantity":"1"},{"side":"bid","event_time":"2026-07-15T03:40:07.273972Z","price_level":"64566.89","new_quantity":"0"},{"side":"bid","event_time":"2026-07-15T03:40:07.273972Z","price_level":"64566.57","new_quantity":"0"},{"side":"bid","event_time":"2026-07-15T03:40:07.273972Z","price_level":"64564.91","new_quantity":"0"},{"side":"bid","event_time":"2026-07-15T03:40:07.273972Z","price_level":"64563.66","new_quantity":"0"},{"side":"bid","event_time":"2026-07-15T03:40:07.273972Z","price_level":"64562.38","new_quantity":"0.00052494"},{"side":"bid","event_time":"2026-07-15T03:40:07.273972Z","price_level":"64561.86","new_quantity":"0.12378505"},{"side":"bid","event_time":"2026-07-15T03:40:07.273972Z","price_level":"64560.46","new_quantity":"0.10678616"},{"side":"bid","event_time":"2026-07-15T03:40:07.273972Z","price_level":"64560.45","new_quantity":"0.03093532"},{"side":"bid","event_time":"2026-07-15T03:40:07.273972Z","price_level":"64560.44","new_quantity":"0"},{"side":"bid","event_time":"2026-07-15T03:40:07.273972Z","price_level":"64559.78","new_quantity":"0.12378505"},{"side":"bid","event_time":"2026-07-15T03:40:07.273972Z","price_level":"64538.58","new_quantity":"0.61356101"},{"side":"bid","event_time":"2026-07-15T03:40:07.273972Z","price_level":"64536.47","new_quantity":"0.93186324"},{"side":"bid","event_time":"2026-07-15T03:40:07.273972Z","price_level":"64534.51","new_quantity":"0.328674"},{"side":"bid","event_time":"2026-07-15T03:40:07.273972Z","price_level":"64534.5","new_quantity":"0"},{"side":"bid","event_time":"2026-07-15T03:40:07.273972Z","price_level":"64528.75","new_quantity":"0.08115905"},{"side":"bid","event_time":"2026-07-15T03:40:07.273972Z","price_level":"64527.75","new_quantity":"0"},{"side":"bid","event_time":"2026-07-15T03:40:07.273972Z","price_level":"64476.28","new_quantity":"2.07570637"},{"side":"bid","event_time":"2026-07-15T03:40:07.273972Z","price_level":"64472.88","new_quantity":"0"},{"side":"bid","event_time":"2026-07-15T03:40:07.273972Z","price_level":"64472.87","new_quantity":"1.22627589"},{"side":"bid","event_time":"2026-07-15T03:40:07.273972Z","price_level":"58122.29","new_quantity":"0.0003441"},{"side":"offer","event_time":"2026-07-15T03:40:07.273972Z","price_level":"64574","new_quantity":"0.0232"},{"side":"offer","event_time":"2026-07-15T03:40:07.273972Z","price_level":"64574.17","new_quantity":"0"},{"side":"offer","event_time":"2026-07-15T03:40:07.273972Z","price_level":"64575.4","new_quantity":"0"},{"side":"offer","event_time":"2026-07-15T03:40:07.273972Z","price_level":"64575.43","new_quantity":"0.04852382"},{"side":"offer","event_time":"2026-07-15T03:40:07.273972Z","price_level":"64577.69","new_quantity":"0.13794639"},{"side":"offer","event_time":"2026-07-15T03:40:07.273972Z","price_level":"64577.7","new_quantity":"0.04656107"},{"side":"offer","event_time":"2026-07-15T03:40:07.273972Z","price_level":"64577.71","new_quantity":"0"},{"side":"offer","event_time":"2026-07-15T03:40:07.273972Z","price_level":"64577.72","new_quantity":"0"},{"side":"offer","event_time":"2026-07-15T03:40:07.273972Z","price_level":"64580.13","new_quantity":"0.022354"},{"side":"offer","event_time":"2026-07-15T03:40:07.273972Z","price_level":"64580.32","new_quantity":"0.00772597"},{"side":"offer","event_time":"2026-07-15T03:40:07.273972Z","price_level":"64582.57","new_quantity":"0.19413628"},{"side":"offer","event_time":"2026-07-15T03:40:07.273972Z","price_level":"64582.58","new_quantity":"0.12378505"},{"side":"offer","event_time":"2026-07-15T03:40:07.273972Z","price_level":"64582.65","new_quantity":"0"},{"side":"offer","event_time":"2026-07-15T03:40:07.273972Z","price_level":"64582.67","new_quantity":"0"},{"side":"offer","event_time":"2026-07-15T03:40:07.273972Z","price_level":"64585.7","new_quantity":"0.03093532"},{"side":"offer","event_time":"2026-07-15T03:40:07.273972Z","price_level":"64585.71","new_quantity":"0.09236806"},{"side":"offer","event_time":"2026-07-15T03:40:07.273972Z","price_level":"64585.72","new_quantity":"0.12378505"},{"side":"offer","event_time":"2026-07-15T03:40:07.273972Z","price_level":"64586.7","new_quantity":"0"},{"side":"offer","event_time":"2026-07-15T03:40:07.273972Z","price_level":"64586.71","new_quantity":"0"},{"side":"offer","event_time":"2026-07-15T03:40:07.273972Z","price_level":"64586.86","new_quantity":"0"},{"side":"offer","event_time":"2026-07-15T03:40:07.273972Z","price_level":"64587.54","new_quantity":"0.20889276"},{"side":"offer","event_time":"2026-07-15T03:40:07.273972Z","price_level":"64587.55","new_quantity":"0.179558"},{"side":"offer","event_time":"2026-07-15T03:40:07.273972Z","price_level":"64587.56","new_quantity":"0"},{"side":"offer","event_time":"2026-07-15T03:40:07.273972Z","price_level":"64588.05","new_quantity":"0.12378505"},{"side":"offer","event_time":"2026-07-15T03:40:07.273972Z","price_level":"64588.82","new_quantity":"0"},{"side":"offer","event_time":"2026-07-15T03:40:07.273972Z","price_level":"64590.63","new_quantity":"0.17126335"},{"side":"offer","event_time":"2026-07-15T03:40:07.273972Z","price_level":"64590.64","new_quantity":"0.12378505"},{"side":"offer","event_time":"2026-07-15T03:40:07.273972Z","price_level":"64590.81","new_quantity":"0"},{"side":"offer","event_time":"2026-07-15T03:40:07.273972Z","price_level":"64591.46","new_quantity":"0.00098673"},{"side":"offer","event_time":"2026-07-15T03:40:07.273972Z","price_level":"64591.69","new_quantity":"0"},{"side":"offer","event_time":"2026-07-15T03:40:07.273972Z","price_level":"64591.89","new_quantity":"0"},{"side":"offer","event_time":"2026-07-15T03:40:07.273972Z","price_level":"64592.58","new_quantity":"0.12378505"},{"side":"offer","event_time":"2026-07-15T03:40:07.273972Z","price_level":"64594.8","new_quantity":"0.34220777"},{"side":"offer","event_time":"2026-07-15T03:40:07.273972Z","price_level":"64595.42","new_quantity":"0"},{"side":"offer","event_time":"2026-07-15T03:40:07.273972Z","price_level":"64600.09","new_quantity":"0.05423473"},{"side":"offer","event_time":"2026-07-15T03:40:07.273972Z","price_level":"64603.01","new_quantity":"0.48295754"},{"side":"offer","event_time":"2026-07-15T03:40:07.273972Z","price_level":"64603.02","new_quantity":"0.63862798"},{"side":"offer","event_time":"2026-07-15T03:40:07.273972Z","price_level":"64603.03","new_quantity":"0"},{"side":"offer","event_time":"2026-07-15T03:40:07.273972Z","price_level":"64603.25","new_quantity":"0.00077424"},{"side":"offer","event_time":"2026-07-15T03:40:07.273972Z","price_level":"64613.29","new_quantity":"0.04548225"},{"side":"offer","event_time":"2026-07-15T03:40:07.273972Z","price_level":"64613.3","new_quantity":"0"},{"side":"offer","event_time":"2026-07-15T03:40:07.273972Z","price_level":"64626","new_quantity":"1"},{"side":"offer","event_time":"2026-07-15T03:40:07.273972Z","price_level":"64652.09","new_quantity":"0.00766564"},{"side":"offer","event_time":"2026-07-15T03:40:07.273972Z","price_level":"64670","new_quantity":"0"},{"side":"offer","event_time":"2026-07-15T03:40:07.273972Z","price_level":"64692.25","new_quantity":"0.00958205"},{"side":"offer","event_time":"2026-07-15T03:40:07.273972Z","price_level":"64843.2","new_quantity":"0.3"},{"side":"offer","event_time":"2026-07-15T03:40:07.273972Z","price_level":"64980.32","new_quantity":"0.01061683"}]}]}
{"channel":"l2_data","timestamp":"2026-07-15T03:40:07.400594788Z","sequence_num":88,"events":[{"type":"update","product_id":"BTC-USD","updates":[{"side":"bid","event_time":"2026-07-15T03:40:07.330658Z","price_level":"64568.51","new_quantity":"0.3023562"},{"side":"bid","event_time":"2026-07-15T03:40:07.330658Z","price_level":"64567.51","new_quantity":"0"},{"side":"bid","event_time":"2026-07-15T03:40:07.330658Z","price_level":"64565.02","new_quantity":"0"},{"side":"bid","event_time":"2026-07-15T03:40:07.330658Z","price_level":"64563.77","new_quantity":"0.02"},{"side":"bid","event_time":"2026-07-15T03:40:07.330658Z","price_level":"64562.01","new_quantity":"0.028232"},{"side":"bid","event_time":"2026-07-15T03:40:07.330658Z","price_level":"64561.86","new_quantity":"0"},{"side":"bid","event_time":"2026-07-15T03:40:07.330658Z","price_level":"64560.46","new_quantity":"0.10678616"},{"side":"bid","event_time":"2026-07-15T03:40:07.330658Z","price_level":"64559.78","new_quantity":"0"},{"side":"bid","event_time":"2026-07-15T03:40:07.330658Z","price_level":"64559.05","new_quantity":"0.12378505"},{"side":"bid","event_time":"2026-07-15T03:40:07.330658Z","price_level":"64549.19","new_quantity":"0.14"},{"side":"bid","event_time":"2026-07-15T03:40:07.330658Z","price_level":"64541.39","new_quantity":"0"},{"side":"bid","event_time":"2026-07-15T03:40:07.330658Z","price_level":"64541.38","new_quantity":"0"},{"side":"bid","event_time":"2026-07-15T03:40:07.330658Z","price_level":"64536.47","new_quantity":"0.93263749"},{"side":"bid","event_time":"2026-07-15T03:40:07.330658Z","price_level":"64531.95","new_quantity":"0"},{"side":"bid","event_time":"2026-07-15T03:40:07.330658Z","price_level":"64502.6","new_quantity":"1.71014214"},{"side":"bid","event_time":"2026-07-15T03:40:07.330658Z","price_level":"64502.59","new_quantity":"1.34982759"},{"side":"bid","event_time":"2026-07-15T03:40:07.330658Z","price_level":"64502.58","new_quantity":"0"},{"side":"bid","event_time":"2026-07-15T03:40:07.330658Z","price_level":"64502.57","new_quantity":"0"},{"side":"bid","event_time":"2026-07-15T03:40:07.330658Z","price_level":"64476.29","new_quantity":"1.90821498"},{"side":"bid","event_time":"2026-07-15T03:40:07.330658Z","price_level":"64476.27","new_quantity":"0"},{"side":"bid","event_time":"2026-07-15T03:40:07.330658Z","price_level":"64470.39","new_quantity":"0"},{"side":"bid","event_time":"2026-07-15T03:40:07.330658Z","price_level":"64091.75","new_quantity":"0.04831322"},{"side":"offer","event_time":"2026-07-15T03:40:07.330658Z","price_level":"64572","new_quantity":"0.0232"},{"side":"offer","event_time":"2026-07-15T03:40:07.330658Z","price_level":"64577.67","new_quantity":"0.12378505"},{"side":"offer","event_time":"2026-07-15T03:40:07.330658Z","price_level":"64577.68","new_quantity":"0.00159977"},{"side":"offer","event_time":"2026-07-15T03:40:07.330658Z","price_level":"64577.69","new_quantity":"0.19325483"},{"side":"offer","event_time":"2026-07-15T03:40:07.330658Z","price_level":"64580.12","new_quantity":"0.00772597"},{"side":"offer","event_time":"2026-07-15T03:40:07.330658Z","price_level":"64580.32","new_quantity":"0"},{"side":"offer","event_time":"2026-07-15T03:40:07.330658Z","price_level":"64580.51","new_quantity":"0.12378505"},{"side":"offer","event_time":"2026-07-15T03:40:07.330658Z","price_level":"64585.68","new_quantity":"0"},{"side":"offer","event_time":"2026-07-15T03:40:07.330658Z","price_level":"64585.69","new_quantity":"0"},{"side":"offer","event_time":"2026-07-15T03:40:07.330658Z","price_level":"64585.71","new_quantity":"0"},{"side":"offer","event_time":"2026-07-15T03:40:07.330658Z","price_level":"64587.54","new_quantity":"0.10169663"},{"side":"offer","event_time":"2026-07-15T03:40:07.330658Z","price_level":"64587.55","new_quantity":"0"},{"side":"offer","event_time":"2026-07-15T03:40:07.330658Z","price_level":"64588.18","new_quantity":"0.05291423"},{"side":"offer","event_time":"2026-07-15T03:40:07.330658Z","price_level":"64591.29","new_quantity":"0.00098673"},{"side":"offer","event_time":"2026-07-15T03:40:07.330658Z","price_level":"64591.46","new_quantity":"0"},{"side":"offer","event_time":"2026-07-15T03:40:07.330658Z","price_level":"64594.5","new_quantity":"1"},{"side":"offer","event_time":"2026-07-15T03:40:07.330658Z","price_level":"64594.8","new_quantity":"0"},{"side":"offer","event_time":"2026-07-15T03:40:07.330658Z","price_level":"64596.34","new_quantity":"0.02"},{"side":"offer","event_time":"2026-07-15T03:40:07.330658Z","price_level":"64596.82","new_quantity":"0.12167354"},{"side":"offer","event_time":"2026-07-15T03:40:07.330658Z","price_level":"64596.83","new_quantity":"0.14"},{"side":"offer","event_time":"2026-07-15T03:40:07.330658Z","price_level":"64597.74","new_quantity":"0.04"},{"side":"offer","event_time":"2026-07-15T03:40:07.330658Z","price_level":"64599.3","new_quantity":"0"},{"side":"offer","event_time":"2026-07-15T03:40:07.330658Z","price_level":"64600.09","new_quantity":"0"},{"side":"offer","event_time":"2026-07-15T03:40:07.330658Z","price_level":"64603.25","new_quantity":"0"},{"side":"offer","event_time":"2026-07-15T03:40:07.330658Z","price_level":"64607.06","new_quantity":"0.09032545"},{"side":"offer","event_time":"2026-07-15T03:40:07.330658Z","price_level":"64607.07","new_quantity":"0"},{"side":"offer","event_time":"2026-07-15T03:40:07.330658Z","price_level":"64607.15","new_quantity":"0"},{"side":"offer","event_time":"2026-07-15T03:40:07.330658Z","price_level":"64609.73","new_quantity":"0.025241"},{"side":"offer","event_time":"2026-07-15T03:40:07.330658Z","price_level":"64610.95","new_quantity":"0"},{"side":"offer","event_time":"2026-07-15T03:40:07.330658Z","price_level":"64613.37","new_quantity":"0"},{"side":"offer","event_time":"2026-07-15T03:40:07.330658Z","price_level":"64616.41","new_quantity":"0.03093532"},{"side":"offer","event_time":"2026-07-15T03:40:07.330658Z","price_level":"64624.79","new_quantity":"0"},{"side":"offer","event_time":"2026-07-15T03:40:07.330658Z","price_level":"64626","new_quantity":"0"},{"side":"offer","event_time":"2026-07-15T03:40:07.330658Z","price_level":"64626.35","new_quantity":"2.61085547"},{"side":"offer","event_time":"2026-07-15T03:40:07.330658Z","price_level":"64626.36","new_quantity":"1.89034592"},{"side":"offer","event_time":"2026-07-15T03:40:07.330658Z","price_level":"64626.37","new_quantity":"0"},{"side":"offer","event_time":"2026-07-15T03:40:07.330658Z","price_level":"64626.38","new_quantity":"0"},{"side":"offer","event_time":"2026-07-15T03:40:07.330658Z","price_level":"64628.11","new_quantity":"0"},{"side":"offer","event_time":"2026-07-15T03:40:07.330658Z","price_level":"64664.1","new_quantity":"0"},{"side":"offer","event_time":"2026-07-15T03:40:07.330658Z","price_level":"64690","new_quantity":"0"}]}]}
{"channel":"l2_data","timestamp":"2026-07-15T03:40:07.472313179Z","sequence_num":89,"events":[{"type":"update","product_id":"BTC-USD","updates":[{"side":"bid","event_time":"2026-07-15T03:40:07.357895Z","price_level":"64567.5","new_quantity":"0"},{"side":"bid","event_time":"2026-07-15T03:40:07.357895Z","price_level":"64563.63","new_quantity":"0.12378505"},{"side":"bid","event_time":"2026-07-15T03:40:07.357895Z","price_level":"64561.05","new_quantity":"0.18550664"},{"side":"bid","event_time":"2026-07-15T03:40:07.357895Z","price_level":"64561.04","new_quantity":"0.12378505"},{"side":"bid","event_time":"2026-07-15T03:40:07.357895Z","price_level":"64560.46","new_quantity":"0"},{"side":"bid","event_time":"2026-07-15T03:40:07.357895Z","price_level":"64543.82","new_quantity":"0.597477"},{"side":"bid","event_time":"2026-07-15T03:40:07.357895Z","price_level":"64476.31","new_quantity":"1.44936461"},{"side":"bid","event_time":"2026-07-15T03:40:07.357895Z","price_level":"64476.3","new_quantity":"2.07570573"},{"side":"bid","event_time":"2026-07-15T03:40:07.357895Z","price_level":"64476.29","new_quantity":"0"},{"side":"bid","event_time":"2026-07-15T03:40:07.357895Z","price_level":"64476.28","new_quantity":"0"},{"side":"offer","event_time":"2026-07-15T03:40:07.357895Z","price_level":"64582.57","new_quantity":"0.27651247"},{"side":"offer","event_time":"2026-07-15T03:40:07.357895Z","price_level":"64582.67","new_quantity":"0.179558"},{"side":"offer","event_time":"2026-07-15T03:40:07.357895Z","price_level":"64585.66","new_quantity":"0.09236806"},{"side":"offer","event_time":"2026-07-15T03:40:07.357895Z","price_level":"64590.94","new_quantity":"0.00098673"},{"side":"offer","event_time":"2026-07-15T03:40:07.357895Z","price_level":"64591.29","new_quantity":"0"},{"side":"offer","event_time":"2026-07-15T03:40:07.357895Z","price_level":"64594.49","new_quantity":"0.97848247"},{"side":"offer","event_time":"2026-07-15T03:40:07.357895Z","price_level":"64602.99","new_quantity":"0.48295766"},{"side":"offer","event_time":"2026-07-15T03:40:07.357895Z","price_level":"64603","new_quantity":"0.63862818"},{"side":"offer","event_time":"2026-07-15T03:40:07.357895Z","price_level":"64603.01","new_quantity":"0"},{"side":"offer","event_time":"2026-07-15T03:40:07.357895Z","price_level":"64603.02","new_quantity":"0"},{"side":"offer","event_time":"2026-07-15T03:40:07.357895Z","price_level":"64680","new_quantity":"3"}]}]}
{"channel":"l2_data","timestamp":"2026-07-15T03:40:07.524926953Z","sequence_num":90,"events":[{"type":"update","product_id":"BTC-USD","updates":[{"side":"bid","event_time":"2026-07-15T03:40:07.375993Z","price_level":"64567.99","new_quantity":"0.1072424"},{"side":"bid","event_time":"2026-07-15T03:40:07.375993Z","price_level":"64566","new_quantity":"1.0232"},{"side":"bid","event_time":"2026-07-15T03:40:07.375993Z","price_level":"64563.66","new_quantity":"0.22518181"},{"side":"bid","event_time":"2026-07-15T03:40:07.375993Z","price_level":"64551.4","new_quantity":"0.25965273"},{"side":"bid","event_time":"2026-07-15T03:40:07.375993Z","price_level":"64548.32","new_quantity":"0.032721"},{"side":"bid","event_time":"2026-07-15T03:40:07.375993Z","price_level":"64544.34","new_quantity":"0.13228371"},{"side":"bid","event_time":"2026-07-15T03:40:07.375993Z","price_level":"64543.82","new_quantity":"0"},{"side":"bid","event_time":"2026-07-15T03:40:07.375993Z","price_level":"64536.04","new_quantity":"0"},{"side":"offer","event_time":"2026-07-15T03:40:07.375993Z","price_level":"64582.55","new_quantity":"0.30133241"},{"side":"offer","event_time":"2026-07-15T03:40:07.375993Z","price_level":"64582.56","new_quantity":"0.179558"},{"side":"offer","event_time":"2026-07-15T03:40:07.375993Z","price_level":"64582.57","new_quantity":"0"},{"side":"offer","event_time":"2026-07-15T03:40:07.375993Z","price_level":"64582.67","new_quantity":"0"},{"side":"offer","event_time":"2026-07-15T03:40:07.375993Z","price_level":"64590.71","new_quantity":"0.00098673"},{"side":"offer","event_time":"2026-07-15T03:40:07.375993Z","price_level":"64590.94","new_quantity":"0"},{"side":"offer","event_time":"2026-07-15T03:40:07.375993Z","price_level":"65222.4","new_quantity":"1.8"}]}]}
{"channel":"l2_data","timestamp":"2026-07-15T03:40:07.558124933Z","sequence_num":91,"events":[{"type":"update","product_id":"BTC-USD","updates":[{"side":"bid","event_time":"2026-07-15T03:40:07.411369Z","price_level":"64568.01","new_quantity":"0.12378505"},{"side":"bid","event_time":"2026-07-15T03:40:07.411369Z","price_level":"64567.99","new_quantity":"0.69053167"},{"side":"bid","event_time":"2026-07-15T03:40:07.411369Z","price_level":"64566.01","new_quantity":"0.12378505"},{"side":"bid","event_time":"2026-07-15T03:40:07.411369Z","price_level":"64563.77","new_quantity":"0.06"},{"side":"bid","event_time":"2026-07-15T03:40:07.411369Z","price_level":"64544.34","new_quantity":"0.04645478"},{"side":"bid","event_time":"2026-07-15T03:40:07.411369Z","price_level":"64543.36","new_quantity":"0"},{"side":"bid","event_time":"2026-07-15T03:40:07.411369Z","price_level":"64502.62","new_quantity":"1.71014189"},{"side":"bid","event_time":"2026-07-15T03:40:07.411369Z","price_level":"64502.61","new_quantity":"1.34982717"},{"side":"bid","event_time":"2026-07-15T03:40:07.411369Z","price_level":"64502.6","new_quantity":"0"},{"side":"bid","event_time":"2026-07-15T03:40:07.411369Z","price_level":"64502.59","new_quantity":"0"},{"side":"offer","event_time":"2026-07-15T03:40:07.411369Z","price_level":"64572","new_quantity":"0"},{"side":"offer","event_time":"2026-07-15T03:40:07.411369Z","price_level":"64577.65","new_quantity":"0.00159977"},{"side":"offer","event_time":"2026-07-15T03:40:07.411369Z","price_level":"64577.66","new_quantity":"0.21179087"},{"side":"offer","event_time":"2026-07-15T03:40:07.411369Z","price_level":"64577.68","new_quantity":"0"},{"side":"offer","event_time":"2026-07-15T03:40:07.411369Z","price_level":"64577.69","new_quantity":"0"},{"side":"offer","event_time":"2026-07-15T03:40:07.411369Z","price_level":"64578.57","new_quantity":"0.1238801"},{"side":"offer","event_time":"2026-07-15T03:40:07.411369Z","price_level":"64579.92","new_quantity":"0"},{"side":"offer","event_time":"2026-07-15T03:40:07.411369Z","price_level":"64582.55","new_quantity":"0.19413628"},{"side":"offer","event_time":"2026-07-15T03:40:07.411369Z","price_level":"64582.56","new_quantity":"0"},{"side":"offer","event_time":"2026-07-15T03:40:07.411369Z","price_level":"64585.64","new_quantity":"0.19956419"},{"side":"offer","event_time":"2026-07-15T03:40:07.411369Z","price_level":"64585.65","new_quantity":"0.179558"},{"side":"offer","event_time":"2026-07-15T03:40:07.411369Z","price_level":"64585.66","new_quantity":"0"},{"side":"offer","event_time":"2026-07-15T03:40:07.411369Z","price_level":"64626.34","new_quantity":"1.89034651"},{"side":"offer","event_time":"2026-07-15T03:40:07.411369Z","price_level":"64626.35","new_quantity":"1.75571251"},{"side":"offer","event_time":"2026-07-15T03:40:07.411369Z","price_level":"64626.36","new_quantity":"0"}]}]}
{"channel":"market_trades","timestamp":"2026-07-15T03:40:07.585137139Z","sequence_num":92,"events":[{"type":"update","trades":[{"product_id":"BTC-USD","trade_id":"1056309425","price":"64568.51","size":"0.00001546","time":"2026-07-15T03:40:07.515988Z","side":"BUY"}]}]}
