{"channel":"l2_data","timestamp":"2026-07-15T03:40:07.660978857Z","sequence_num":93,"events":[{"type":"update","product_id":"BTC-USD","updates":[{"side":"bid","event_time":"2026-07-15T03:40:07.486279Z","price_level":"64565.6","new_quantity":"0.0015533"},{"side":"bid","event_time":"2026-07-15T03:40:07.486279Z","price_level":"64562.41","new_quantity":"0.0015533"},{"side":"bid","event_time":"2026-07-15T03:40:07.486279Z","price_level":"64562.01","new_quantity":"0"},{"side":"bid","event_time":"2026-07-15T03:40:07.486279Z","price_level":"64559.22","new_quantity":"0.0015533"},{"side":"bid","event_time":"2026-07-15T03:40:07.486279Z","price_level":"64556.03","new_quantity":"0.0015533"},{"side":"bid","event_time":"2026-07-15T03:40:07.486279Z","price_level":"64552.84","new_quantity":"0.0015533"},{"side":"bid","event_time":"2026-07-15T03:40:07.486279Z","price_level":"64549.65","new_quantity":"0.0015533"},{"side":"bid","event_time":"2026-07-15T03:40:07.486279Z","price_level":"64546.66","new_quantity":"0.02731411"},{"side":"bid","event_time":"2026-07-15T03:40:07.486279Z","price_level":"64546.46","new_quantity":"0.0015533"},{"side":"bid","event_time":"2026-07-15T03:40:07.486279Z","price_level":"64543.27","new_quantity":"0.0015533"},{"side":"bid","event_time":"2026-07-15T03:40:07.486279Z","price_level":"64540.08","new_quantity":"0.0015533"},{"side":"bid","event_time":"2026-07-15T03:40:07.486279Z","price_level":"64536.89","new_quantity":"0.0015533"},{"side":"bid","event_time":"2026-07-15T03:40:07.486279Z","price_level":"64528.55","new_quantity":"0"},{"side":"bid","event_time":"2026-07-15T03:40:07.486279Z","price_level":"64501.8","new_quantity":"0"},{"side":"bid","event_time":"2026-07-15T03:40:07.486279Z","price_level":"64486.17","new_quantity":"0.01331"},{"side":"bid","event_time":"2026-07-15T03:40:07.486279Z","price_level":"64476.32","new_quantity":"2.07570508"},{"side":"bid","event_time":"2026-07-15T03:40:07.486279Z","price_level":"64476.31","new_quantity":"0.83541055"},{"side":"bid","event_time":"2026-07-15T03:40:07.486279Z","price_level":"64476.3","new_quantity":"0"},{"side":"bid","event_time":"2026-07-15T03:40:07.486279Z","price_level":"56497.45","new_quantity":"0.0132912"},{"side":"offer","event_time":"2026-07-15T03:40:07.486279Z","price_level":"64571.98","new_quantity":"0.0015533"},{"side":"offer","event_time":"2026-07-15T03:40:07.486279Z","price_level":"64575.17","new_quantity":"0.0015533"},{"side":"offer","event_time":"2026-07-15T03:40:07.486279Z","price_level":"64578.36","new_quantity":"0.0015533"},{"side":"offer","event_time":"2026-07-15T03:40:07.486279Z","price_level":"64581.55","new_quantity":"0.0015533"},{"side":"offer","event_time":"2026-07-15T03:40:07.486279Z","price_level":"64584.74","new_quantity":"0.0015533"},{"side":"offer","event_time":"2026-07-15T03:40:07.486279Z","price_level":"64585.64","new_quantity":"0.09236806"},{"side":"offer","event_time":"2026-07-15T03:40:07.486279Z","price_level":"64585.65","new_quantity":"0"},{"side":"offer","event_time":"2026-07-15T03:40:07.486279Z","price_level":"64587.93","new_quantity":"0.0015533"},{"side":"offer","event_time":"2026-07-15T03:40:07.486279Z","price_level":"64590.3","new_quantity":"0.00098673"},{"side":"offer","event_time":"2026-07-15T03:40:07.486279Z","price_level":"64590.71","new_quantity":"0"},{"side":"offer","event_time":"2026-07-15T03:40:07.486279Z","price_level":"64591.12","new_quantity":"0.0015533"},{"side":"offer","event_time":"2026-07-15T03:40:07.486279Z","price_level":"64591.37","new_quantity":"0"},{"side":"offer","event_time":"2026-07-15T03:40:07.486279Z","price_level":"64594.31","new_quantity":"0.0015533"},{"side":"offer","event_time":"2026-07-15T03:40:07.486279Z","price_level":"64597.5","new_quantity":"0.0015533"},{"side":"offer","event_time":"2026-07-15T03:40:07.486279Z","price_level":"64600.69","new_quantity":"0.0015533"},{"side":"offer","event_time":"2026-07-15T03:40:07.486279Z","price_level":"64602.97","new_quantity":"0.48295778"},{"side":"offer","event_time":"2026-07-15T03:40:07.486279Z","price_level":"64602.98","new_quantity":"0.63862838"},{"side":"offer","event_time":"2026-07-15T03:40:07.486279Z","price_level":"64602.99","new_quantity":"0"},{"side":"offer","event_time":"2026-07-15T03:40:07.486279Z","price_level":"64603","new_quantity":"0"},{"side":"offer","event_time":"2026-07-15T03:40:07.486279Z","price_level":"64603.26","new_quantity":"0.02129778"},{"side":"offer","event_time":"2026-07-15T03:40:07.486279Z","price_level":"64603.27","new_quantity":"0"},{"side":"offer","event_time":"2026-07-15T03:40:07.486279Z","price_level":"64603.39","new_quantity":"0"},{"side":"offer","event_time":"2026-07-15T03:40:07.486279Z","price_level":"64603.88","new_quantity":"0.0015533"},{"side":"offer","event_time":"2026-07-15T03:40:07.486279Z","price_level":"64607.07","new_quantity":"0.0015533"},{"side":"offer","event_time":"2026-07-15T03:40:07.486279Z","price_level":"64608.22","new_quantity":"0.02778288"},{"side":"offer","event_time":"2026-07-15T03:40:07.486279Z","price_level":"64609.33","new_quantity":"0.0007742"},{"side":"offer","event_time":"2026-07-15T03:40:07.486279Z","price_level":"64610.26","new_quantity":"0.0015533"},{"side":"offer","event_time":"2026-07-15T03:40:07.486279Z","price_level":"64613.45","new_quantity":"0.0015533"},{"side":"offer","event_time":"2026-07-15T03:40:07.486279Z","price_level":"64616.4","new_quantity":"0.01925651"},{"side":"offer","event_time":"2026-07-15T03:40:07.486279Z","price_level":"64616.64","new_quantity":"0.0015533"},{"side":"offer","event_time":"2026-07-15T03:40:07.486279Z","price_level":"64619.83","new_quantity":"0.0015533"},{"side":"offer","event_time":"2026-07-15T03:40:07.486279Z","price_level":"64623.02","new_quantity":"0.0015533"},{"side":"offer","event_time":"2026-07-15T03:40:07.486279Z","price_level":"64623.19","new_quantity":"0.01572121"},{"side":"offer","event_time":"2026-07-15T03:40:07.486279Z","price_level":"64626.21","new_quantity":"0.0015533"},{"side":"offer","event_time":"2026-07-15T03:40:07.486279Z","price_level":"64629.19","new_quantity":"0.00077426"},{"side":"offer","event_time":"2026-07-15T03:40:07.486279Z","price_level":"64629.4","new_quantity":"0.0015533"},{"side":"offer","event_time":"2026-07-15T03:40:07.486279Z","price_level":"64632.59","new_quantity":"0.0015533"},{"side":"offer","event_time":"2026-07-15T03:40:07.486279Z","price_level":"64705.78","new_quantity":"0"}]}]}
{"channel":"l2_data","timestamp":"2026-07-15T03:40:07.669843785Z","sequence_num":94,"events":[{"type":"update","product_id":"BTC-USD","updates":[{"side":"bid","event_time":"2026-07-15T03:40:07.548743Z","price_level":"64568.51","new_quantity":"0.35966545"},{"side":"bid","event_time":"2026-07-15T03:40:07.548743Z","price_level":"64546.66","new_quantity":"0"},{"side":"bid","event_time":"2026-07-15T03:40:07.548743Z","price_level":"64534.66","new_quantity":"0.02423914"},{"side":"bid","event_time":"2026-07-15T03:40:07.548743Z","price_level":"64528.76","new_quantity":"0.00077426"},{"side":"bid","event_time":"2026-07-15T03:40:07.548743Z","price_level":"64520.95","new_quantity":"0"},{"side":"bid","event_time":"2026-07-15T03:40:07.548743Z","price_level":"64502.64","new_quantity":"1.70921432"},{"side":"bid","event_time":"2026-07-15T03:40:07.548743Z","price_level":"64502.63","new_quantity":"1.34982675"},{"side":"bid","event_time":"2026-07-15T03:40:07.548743Z","price_level":"64502.62","new_quantity":"0"},{"side":"bid","event_time":"2026-07-15T03:40:07.548743Z","price_level":"64502.61","new_quantity":"0"},{"side":"bid","event_time":"2026-07-15T03:40:07.548743Z","price_level":"64472.87","new_quantity":"0"},{"side":"bid","event_time":"2026-07-15T03:40:07.548743Z","price_level":"64471.5","new_quantity":"0.0498692"},{"side":"bid","event_time":"2026-07-15T03:40:07.548743Z","price_level":"64464.92","new_quantity":"0"},{"side":"offer","event_time":"2026-07-15T03:40:07.548743Z","price_level":"64568.52","new_quantity":"0.00846273"},{"side":"offer","event_time":"2026-07-15T03:40:07.548743Z","price_level":"64589.59","new_quantity":"0.00098672"},{"side":"offer","event_time":"2026-07-15T03:40:07.548743Z","price_level":"64589.8","new_quantity":"0"},{"side":"offer","event_time":"2026-07-15T03:40:07.548743Z","price_level":"64589.93","new_quantity":"0"},{"side":"offer","event_time":"2026-07-15T03:40:07.548743Z","price_level":"64590.3","new_quantity":"0"},{"side":"offer","event_time":"2026-07-15T03:40:07.548743Z","price_level":"64593.45","new_quantity":"0.01647578"},{"side":"offer","event_time":"2026-07-15T03:40:07.548743Z","price_level":"64594.49","new_quantity":"0.38148247"},{"side":"offer","event_time":"2026-07-15T03:40:07.548743Z","price_level":"64594.5","new_quantity":"0"},{"side":"offer","event_time":"2026-07-15T03:40:07.548743Z","price_level":"64599.28","new_quantity":"0.00077437"},{"side":"offer","event_time":"2026-07-15T03:40:07.548743Z","price_level":"64601.94","new_quantity":"0"},{"side":"offer","event_time":"2026-07-15T03:40:07.548743Z","price_level":"64602.95","new_quantity":"0.48295789"},{"side":"offer","event_time":"2026-07-15T03:40:07.548743Z","price_level":"64602.96","new_quantity":"0.63862857"},{"side":"offer","event_time":"2026-07-15T03:40:07.548743Z","price_level":"64602.97","new_quantity":"0"},{"side":"offer","event_time":"2026-07-15T03:40:07.548743Z","price_level":"64602.98","new_quantity":"0"},{"side":"offer","event_time":"2026-07-15T03:40:07.548743Z","price_level":"64614.66","new_quantity":"0.01092603"},{"side":"offer","event_time":"2026-07-15T03:40:07.548743Z","price_level":"64616.4","new_quantity":"0.01848225"},{"side":"offer","event_time":"2026-07-15T03:40:07.548743Z","price_level":"64621.67","new_quantity":"0.00077426"},{"side":"offer","event_time":"2026-07-15T03:40:07.548743Z","price_level":"64623.19","new_quantity":"0"},{"side":"offer","event_time":"2026-07-15T03:40:07.548743Z","price_level":"64626.32","new_quantity":"1.89034709"},{"side":"offer","event_time":"2026-07-15T03:40:07.548743Z","price_level":"64626.33","new_quantity":"1.78189231"},{"side":"offer","event_time":"2026-07-15T03:40:07.548743Z","price_level":"64626.34","new_quantity":"0"},{"side":"offer","event_time":"2026-07-15T03:40:07.548743Z","price_level":"64626.35","new_quantity":"0"},{"side":"offer","event_time":"2026-07-15T03:40:07.548743Z","price_level":"64627.31","new_quantity":"0.04385213"},{"side":"offer","event_time":"2026-07-15T03:40:07.548743Z","price_level":"64634.77","new_quantity":"0.03537613"},{"side":"offer","event_time":"2026-07-15T03:40:07.548743Z","price_level":"64634.78","new_quantity":"0.04307907"},{"side":"offer","event_time":"2026-07-15T03:40:07.548743Z","price_level":"64635.63","new_quantity":"0.83336837"},{"side":"offer","event_time":"2026-07-15T03:40:07.548743Z","price_level":"64635.64","new_quantity":"1.303837"},{"side":"offer","event_time":"2026-07-15T03:40:07.548743Z","price_level":"64636.28","new_quantity":"0"},{"side":"offer","event_time":"2026-07-15T03:40:07.548743Z","price_level":"64637.06","new_quantity":"0"},{"side":"offer","event_time":"2026-07-15T03:40:07.548743Z","price_level":"64650.94","new_quantity":"6.191718"},{"side":"offer","event_time":"2026-07-15T03:40:07.548743Z","price_level":"64665.21","new_quantity":"0.05163352"},{"side":"offer","event_time":"2026-07-15T03:40:07.548743Z","price_level":"64665.86","new_quantity":"10.387293"},{"side":"offer","event_time":"2026-07-15T03:40:07.548743Z","price_level":"65222.4","new_quantity":"0.3"}]}]}
{"channel":"market_trades","timestamp":"2026-07-15T03:40:07.686345763Z","sequence_num":95,"events":[{"type":"update","trades":[{"product_id":"BTC-USD","trade_id":"1056309431","price":"64572.95","size":"0.00000004","time":"2026-07-15T03:40:07.607543Z","side":"BUY"},{"product_id":"BTC-USD","trade_id":"1056309430","price":"64570.14","size":"0.00144074","time":"2026-07-15T03:40:07.567378Z","side":"SELL"},{"product_id":"BTC-USD","trade_id":"1056309429","price":"64570.14","size":"0.00774381","time":"2026-07-15T03:40:07.567378Z","side":"SELL"},{"product_id":"BTC-USD","trade_id":"1056309428","price":"64568.52","size":"0.00001273","time":"2026-07-15T03:40:07.567378Z","side":"SELL"},{"product_id":"BTC-USD","trade_id":"1056309427","price":"64568.52","size":"0.00070619","time":"2026-07-15T03:40:07.566789Z","side":"SELL"},{"product_id":"BTC-USD","trade_id":"1056309426","price":"64568.52","size":"0.00774381","time":"2026-07-15T03:40:07.566789Z","side":"SELL"}]}]}
{"channel":"l2_data","timestamp":"2026-07-15T03:40:07.708930612Z","sequence_num":96,"events":[{"type":"update","product_id":"BTC-USD","updates":[{"side":"bid","event_time":"2026-07-15T03:40:07.601742Z","price_level":"64572.95","new_quantity":"0.18120197"},{"side":"bid","event_time":"2026-07-15T03:40:07.601742Z","price_level":"64572.56","new_quantity":"0.12389161"},{"side":"bid","event_time":"2026-07-15T03:40:07.601742Z","price_level":"64572.23","new_quantity":"0.03093532"},{"side":"bid","event_time":"2026-07-15T03:40:07.601742Z","price_level":"64572.22","new_quantity":"0.12378505"},{"side":"bid","event_time":"2026-07-15T03:40:07.601742Z","price_level":"64572","new_quantity":"0.0232"},{"side":"bid","event_time":"2026-07-15T03:40:07.601742Z","price_level":"64570.29","new_quantity":"0.32311516"},{"side":"bid","event_time":"2026-07-15T03:40:07.601742Z","price_level":"64570.28","new_quantity":"0.12378505"},{"side":"bid","event_time":"2026-07-15T03:40:07.601742Z","price_level":"64570","new_quantity":"0.0232"},{"side":"bid","event_time":"2026-07-15T03:40:07.601742Z","price_level":"64568.67","new_quantity":"0.00159977"},{"side":"bid","event_time":"2026-07-15T03:40:07.601742Z","price_level":"64568.66","new_quantity":"0.04656107"},{"side":"bid","event_time":"2026-07-15T03:40:07.601742Z","price_level":"64568.52","new_quantity":"0.04"},{"side":"bid","event_time":"2026-07-15T03:40:07.601742Z","price_level":"64568.51","new_quantity":"0"},{"side":"bid","event_time":"2026-07-15T03:40:07.601742Z","price_level":"64568.02","new_quantity":"0"},{"side":"bid","event_time":"2026-07-15T03:40:07.601742Z","price_level":"64567.99","new_quantity":"0"},{"side":"bid","event_time":"2026-07-15T03:40:07.601742Z","price_level":"64566.86","new_quantity":"0"},{"side":"bid","event_time":"2026-07-15T03:40:07.601742Z","price_level":"64566.02","new_quantity":"0.08867739"},{"side":"bid","event_time":"2026-07-15T03:40:07.601742Z","price_level":"64566","new_quantity":"0.0232"},{"side":"bid","event_time":"2026-07-15T03:40:07.601742Z","price_level":"64564.93","new_quantity":"0.0483189"},{"side":"bid","event_time":"2026-07-15T03:40:07.601742Z","price_level":"64563.77","new_quantity":"0"},{"side":"bid","event_time":"2026-07-15T03:40:07.601742Z","price_level":"64563.66","new_quantity":"0.11678774"},{"side":"bid","event_time":"2026-07-15T03:40:07.601742Z","price_level":"64563.65","new_quantity":"0"},{"side":"bid","event_time":"2026-07-15T03:40:07.601742Z","price_level":"64557.92","new_quantity":"0.04398043"},{"side":"bid","event_time":"2026-07-15T03:40:07.601742Z","price_level":"64557.03","new_quantity":"0.14765884"},{"side":"bid","event_time":"2026-07-15T03:40:07.601742Z","price_level":"64557.02","new_quantity":"0.12378505"},{"side":"bid","event_time":"2026-07-15T03:40:07.601742Z","price_level":"64551.4","new_quantity":"0.09800261"},{"side":"bid","event_time":"2026-07-15T03:40:07.601742Z","price_level":"64549.76","new_quantity":"0"},{"side":"bid","event_time":"2026-07-15T03:40:07.601742Z","price_level":"64549.58","new_quantity":"0"},{"side":"bid","event_time":"2026-07-15T03:40:07.601742Z","price_level":"64549.19","new_quantity":"0"},{"side":"bid","event_time":"2026-07-15T03:40:07.601742Z","price_level":"64547.52","new_quantity":"0"},{"side":"bid","event_time":"2026-07-15T03:40:07.601742Z","price_level":"64547.51","new_quantity":"0"},{"side":"bid","event_time":"2026-07-15T03:40:07.601742Z","price_level":"64538.6","new_quantity":"0.60395897"},{"side":"bid","event_time":"2026-07-15T03:40:07.601742Z","price_level":"64538.59","new_quantity":"0.93183263"},{"side":"bid","event_time":"2026-07-15T03:40:07.601742Z","price_level":"64538.58","new_quantity":"0"},{"side":"bid","event_time":"2026-07-15T03:40:07.601742Z","price_level":"64536.47","new_quantity":"0.00077425"},{"side":"bid","event_time":"2026-07-15T03:40:07.601742Z","price_level":"64534.68","new_quantity":"0.42133056"},{"side":"bid","event_time":"2026-07-15T03:40:07.601742Z","price_level":"64534.67","new_quantity":"0.60992654"},{"side":"bid","event_time":"2026-07-15T03:40:07.601742Z","price_level":"64534.51","new_quantity":"0"},{"side":"bid","event_time":"2026-07-15T03:40:07.601742Z","price_level":"64532.37","new_quantity":"0"},{"side":"bid","event_time":"2026-07-15T03:40:07.601742Z","price_level":"64521.31","new_quantity":"0"},{"side":"bid","event_time":"2026-07-15T03:40:07.601742Z","price_level":"64506.14","new_quantity":"0.04656107"},{"side":"bid","event_time":"2026-07-15T03:40:07.601742Z","price_level":"64504.38","new_quantity":"0.001858"},{"side":"bid","event_time":"2026-07-15T03:40:07.601742Z","price_level":"64488.03","new_quantity":"0"},{"side":"bid","event_time":"2026-07-15T03:40:07.601742Z","price_level":"64486.28","new_quantity":"1.28239476"},{"side":"bid","event_time":"2026-07-15T03:40:07.601742Z","price_level":"64485.01","new_quantity":"2.07542536"},{"side":"bid","event_time":"2026-07-15T03:40:07.601742Z","price_level":"64485","new_quantity":"0"},{"side":"bid","event_time":"2026-07-15T03:40:07.601742Z","price_level":"64476.32","new_quantity":"0"},{"side":"bid","event_time":"2026-07-15T03:40:07.601742Z","price_level":"64091.75","new_quantity":"0"},{"side":"bid","event_time":"2026-07-15T03:40:07.601742Z","price_level":"56497.45","new_quantity":"0"},{"side":"offer","event_time":"2026-07-15T03:40:07.601742Z","price_level":"64568.52","new_quantity":"0"},{"side":"offer","event_time":"2026-07-15T03:40:07.601742Z","price_level":"64570.14","new_quantity":"0"},{"side":"offer","event_time":"2026-07-15T03:40:07.601742Z","price_level":"64571.98","new_quantity":"0"},{"side":"offer","event_time":"2026-07-15T03:40:07.601742Z","price_level":"64572.32","new_quantity":"0"},{"side":"offer","event_time":"2026-07-15T03:40:07.601742Z","price_level":"64573.59","new_quantity":"0.0077435"},{"side":"offer","event_time":"2026-07-15T03:40:07.601742Z","price_level":"64574","new_quantity":"0"},{"side":"offer","event_time":"2026-07-15T03:40:07.601742Z","price_level":"64575.17","new_quantity":"0"},{"side":"offer","event_time":"2026-07-15T03:40:07.601742Z","price_level":"64575.43","new_quantity":"0"},{"side":"offer","event_time":"2026-07-15T03:40:07.601742Z","price_level":"64575.44","new_quantity":"0"},{"side":"offer","event_time":"2026-07-15T03:40:07.601742Z","price_level":"64575.77","new_quantity":"0.00967938"},{"side":"offer","event_time":"2026-07-15T03:40:07.601742Z","price_level":"64576","new_quantity":"0"},{"side":"offer","event_time":"2026-07-15T03:40:07.601742Z","price_level":"64577.63","new_quantity":"0.00159977"},{"side":"offer","event_time":"2026-07-15T03:40:07.601742Z","price_level":"64577.65","new_quantity":"0"},{"side":"offer","event_time":"2026-07-15T03:40:07.601742Z","price_level":"64577.66","new_quantity":"0"},{"side":"offer","event_time":"2026-07-15T03:40:07.601742Z","price_level":"64577.67","new_quantity":"0"},{"side":"offer","event_time":"2026-07-15T03:40:07.601742Z","price_level":"64577.7","new_quantity":"0"},{"side":"offer","event_time":"2026-07-15T03:40:07.601742Z","price_level":"64577.99","new_quantity":"0.0490899"},{"side":"offer","event_time":"2026-07-15T03:40:07.601742Z","price_level":"64578","new_quantity":"0.0232"},{"side":"offer","event_time":"2026-07-15T03:40:07.601742Z","price_level":"64578.36","new_quantity":"0"},{"side":"offer","event_time":"2026-07-15T03:40:07.601742Z","price_level":"64578.57","new_quantity":"0"},{"side":"offer","event_time":"2026-07-15T03:40:07.601742Z","price_level":"64580.51","new_quantity":"0"},{"side":"offer","event_time":"2026-07-15T03:40:07.601742Z","price_level":"64581.55","new_quantity":"0"},{"side":"offer","event_time":"2026-07-15T03:40:07.601742Z","price_level":"64582.18","new_quantity":"0.02779696"},{"side":"offer","event_time":"2026-07-15T03:40:07.601742Z","price_level":"64582.55","new_quantity":"0"},{"side":"offer","event_time":"2026-07-15T03:40:07.601742Z","price_level":"64582.58","new_quantity":"0"},{"side":"offer","event_time":"2026-07-15T03:40:07.601742Z","price_level":"64582.68","new_quantity":"0"},{"side":"offer","event_time":"2026-07-15T03:40:07.601742Z","price_level":"64584.55","new_quantity":"0.12386864"},{"side":"offer","event_time":"2026-07-15T03:40:07.601742Z","price_level":"64584.74","new_quantity":"0"},{"side":"offer","event_time":"2026-07-15T03:40:07.601742Z","price_level":"64584.98","new_quantity":"0.0483189"},{"side":"offer","event_time":"2026-07-15T03:40:07.601742Z","price_level":"64585.59","new_quantity":"0.15483332"},{"side":"offer","event_time":"2026-07-15T03:40:07.601742Z","price_level":"64585.64","new_quantity":"0"},{"side":"offer","event_time":"2026-07-15T03:40:07.601742Z","price_level":"64585.7","new_quantity":"0"},{"side":"offer","event_time":"2026-07-15T03:40:07.601742Z","price_level":"64585.72","new_quantity":"0"},{"side":"offer","event_time":"2026-07-15T03:40:07.601742Z","price_level":"64587.54","new_quantity":"0.19648011"},{"side":"offer","event_time":"2026-07-15T03:40:07.601742Z","price_level":"64587.93","new_quantity":"0"},{"side":"offer","event_time":"2026-07-15T03:40:07.601742Z","price_level":"64588.18","new_quantity":"0"},{"side":"offer","event_time":"2026-07-15T03:40:07.601742Z","price_level":"64588.82","new_quantity":"0.179558"},{"side":"offer","event_time":"2026-07-15T03:40:07.601742Z","price_level":"64589.23","new_quantity":"0.0009867"},{"side":"offer","event_time":"2026-07-15T03:40:07.601742Z","price_level":"64589.59","new_quantity":"0"},{"side":"offer","event_time":"2026-07-15T03:40:07.601742Z","price_level":"64591.12","new_quantity":"0"},{"side":"offer","event_time":"2026-07-15T03:40:07.601742Z","price_level":"64593.45","new_quantity":"0"},{"side":"offer","event_time":"2026-07-15T03:40:07.601742Z","price_level":"64594.31","new_quantity":"0"},{"side":"offer","event_time":"2026-07-15T03:40:07.601742Z","price_level":"64596.34","new_quantity":"0"},{"side":"offer","event_time":"2026-07-15T03:40:07.601742Z","price_level":"64596.82","new_quantity":"0.08631584"},{"side":"offer","event_time":"2026-07-15T03:40:07.601742Z","price_level":"64596.83","new_quantity":"0"},{"side":"offer","event_time":"2026-07-15T03:40:07.601742Z","price_level":"64597.5","new_quantity":"0"},{"side":"offer","event_time":"2026-07-15T03:40:07.601742Z","price_level":"64597.74","new_quantity":"0"},{"side":"offer","event_time":"2026-07-15T03:40:07.601742Z","price_level":"64600.69","new_quantity":"0"},{"side":"offer","event_time":"2026-07-15T03:40:07.601742Z","price_level":"64603.88","new_quantity":"0"},{"side":"offer","event_time":"2026-07-15T03:40:07.601742Z","price_level":"64607.07","new_quantity":"0"},{"side":"offer","event_time":"2026-07-15T03:40:07.601742Z","price_level":"64609.33","new_quantity":"0"},{"side":"offer","event_time":"2026-07-15T03:40:07.601742Z","price_level":"64610.26","new_quantity":"0"},{"side":"offer","event_time":"2026-07-15T03:40:07.601742Z","price_level":"64613.45","new_quantity":"0"},{"side":"offer","event_time":"2026-07-15T03:40:07.601742Z","price_level":"64616.64","new_quantity":"0"},{"side":"offer","event_time":"2026-07-15T03:40:07.601742Z","price_level":"64619.83","new_quantity":"0"},{"side":"offer","event_time":"2026-07-15T03:40:07.601742Z","price_level":"64622.99","new_quantity":"0.59793807"},{"side":"offer","event_time":"2026-07-15T03:40:07.601742Z","price_level":"64623","new_quantity":"1"},{"side":"offer","event_time":"2026-07-15T03:40:07.601742Z","price_level":"64626.31","new_quantity":"1.38889069"},{"side":"offer","event_time":"2026-07-15T03:40:07.601742Z","price_level":"64626.33","new_quantity":"0"},{"side":"offer","event_time":"2026-07-15T03:40:07.601742Z","price_level":"64626.4","new_quantity":"0"},{"side":"offer","event_time":"2026-07-15T03:40:07.601742Z","price_level":"64629.19","new_quantity":"2.09060528"},{"side":"offer","event_time":"2026-07-15T03:40:07.601742Z","price_level":"64647.51","new_quantity":"0"},{"side":"offer","event_time":"2026-07-15T03:40:07.601742Z","price_level":"64648.45","new_quantity":"0"},{"side":"offer","event_time":"2026-07-15T03:40:07.601742Z","price_level":"64843.2","new_quantity":"0"}]}]}
{"channel":"l2_data","timestamp":"2026-07-15T03:40:07.74871611Z","sequence_num":97,"events":[{"type":"update","product_id":"BTC-USD","updates":[{"side":"bid","event_time":"2026-07-15T03:40:07.649662Z","price_level":"64572.95","new_quantity":"0.18120193"},{"side":"bid","event_time":"2026-07-15T03:40:07.649662Z","price_level":"64572.23","new_quantity":"0.71568539"},{"side":"bid","event_time":"2026-07-15T03:40:07.649662Z","price_level":"64572","new_quantity":"1.0232"},{"side":"bid","event_time":"2026-07-15T03:40:07.649662Z","price_level":"64558.01","new_quantity":"0"},{"side":"bid","event_time":"2026-07-15T03:40:07.649662Z","price_level":"64551.4","new_quantity":"0.09800261"},{"side":"bid","event_time":"2026-07-15T03:40:07.649662Z","price_level":"64544.18","new_quantity":"0.02752153"},{"side":"bid","event_time":"2026-07-15T03:40:07.649662Z","price_level":"64542.55","new_quantity":"0"},{"side":"bid","event_time":"2026-07-15T03:40:07.649662Z","price_level":"64540.49","new_quantity":"0"},{"side":"bid","event_time":"2026-07-15T03:40:07.649662Z","price_level":"64533.16","new_quantity":"0.00154738"},{"side":"bid","event_time":"2026-07-15T03:40:07.649662Z","price_level":"64533.07","new_quantity":"0"},{"side":"bid","event_time":"2026-07-15T03:40:07.649662Z","price_level":"64530.87","new_quantity":"0"},{"side":"bid","event_time":"2026-07-15T03:40:07.649662Z","price_level":"64526.71","new_quantity":"0.0077369"},{"side":"bid","event_time":"2026-07-15T03:40:07.649662Z","price_level":"64526.19","new_quantity":"0"},{"side":"bid","event_time":"2026-07-15T03:40:07.649662Z","price_level":"64524.84","new_quantity":"0"},{"side":"bid","event_time":"2026-07-15T03:40:07.649662Z","price_level":"64524.42","new_quantity":"0"},{"side":"bid","event_time":"2026-07-15T03:40:07.649662Z","price_level":"64516.88","new_quantity":"0"},{"side":"bid","event_time":"2026-07-15T03:40:07.649662Z","price_level":"64506.17","new_quantity":"0.92239185"},{"side":"bid","event_time":"2026-07-15T03:40:07.649662Z","price_level":"64506.16","new_quantity":"1.41227586"},{"side":"bid","event_time":"2026-07-15T03:40:07.649662Z","price_level":"64506.15","new_quantity":"0"},{"side":"bid","event_time":"2026-07-15T03:40:07.649662Z","price_level":"64502.64","new_quantity":"0"},{"side":"bid","event_time":"2026-07-15T03:40:07.649662Z","price_level":"64502.63","new_quantity":"0"},{"side":"bid","event_time":"2026-07-15T03:40:07.649662Z","price_level":"64502.56","new_quantity":"0.90336775"},{"side":"bid","event_time":"2026-07-15T03:40:07.649662Z","price_level":"64490.01","new_quantity":"2.80305098"},{"side":"bid","event_time":"2026-07-15T03:40:07.649662Z","price_level":"64490","new_quantity":"3"},{"side":"bid","event_time":"2026-07-15T03:40:07.649662Z","price_level":"64489.27","new_quantity":"0"},{"side":"bid","event_time":"2026-07-15T03:40:07.649662Z","price_level":"64467.83","new_quantity":"0"},{"side":"bid","event_time":"2026-07-15T03:40:07.649662Z","price_level":"64436.96","new_quantity":"0"},{"side":"offer","event_time":"2026-07-15T03:40:07.649662Z","price_level":"64573.59","new_quantity":"0"},{"side":"offer","event_time":"2026-07-15T03:40:07.649662Z","price_level":"64574.58","new_quantity":"0.00774317"},{"side":"offer","event_time":"2026-07-15T03:40:07.649662Z","price_level":"64575.77","new_quantity":"0"},{"side":"offer","event_time":"2026-07-15T03:40:07.649662Z","price_level":"64576.76","new_quantity":"0.00967897"},{"side":"offer","event_time":"2026-07-15T03:40:07.649662Z","price_level":"64577.99","new_quantity":"0"},{"side":"offer","event_time":"2026-07-15T03:40:07.649662Z","price_level":"64580.12","new_quantity":"0"},{"side":"offer","event_time":"2026-07-15T03:40:07.649662Z","price_level":"64583.99","new_quantity":"0.00772597"},{"side":"offer","event_time":"2026-07-15T03:40:07.649662Z","price_level":"64584.53","new_quantity":"0.12378505"},{"side":"offer","event_time":"2026-07-15T03:40:07.649662Z","price_level":"64584.54","new_quantity":"0.19523145"},{"side":"offer","event_time":"2026-07-15T03:40:07.649662Z","price_level":"64587.54","new_quantity":"0.10169663"},{"side":"offer","event_time":"2026-07-15T03:40:07.649662Z","price_level":"64588.82","new_quantity":"0"},{"side":"offer","event_time":"2026-07-15T03:40:07.649662Z","price_level":"64589.12","new_quantity":"0"},{"side":"offer","event_time":"2026-07-15T03:40:07.649662Z","price_level":"64589.23","new_quantity":"0"},{"side":"offer","event_time":"2026-07-15T03:40:07.649662Z","price_level":"64590.61","new_quantity":"0.2778704"},{"side":"offer","event_time":"2026-07-15T03:40:07.649662Z","price_level":"64590.62","new_quantity":"0.179558"},{"side":"offer","event_time":"2026-07-15T03:40:07.649662Z","price_level":"64590.63","new_quantity":"0"},{"side":"offer","event_time":"2026-07-15T03:40:07.649662Z","price_level":"64592.57","new_quantity":"0"},{"side":"offer","event_time":"2026-07-15T03:40:07.649662Z","price_level":"64602.95","new_quantity":"0"},{"side":"offer","event_time":"2026-07-15T03:40:07.649662Z","price_level":"64602.96","new_quantity":"0"},{"side":"offer","event_time":"2026-07-15T03:40:07.649662Z","price_level":"64607.04","new_quantity":"0.48768675"},{"side":"offer","event_time":"2026-07-15T03:40:07.649662Z","price_level":"64607.05","new_quantity":"0.63858814"},{"side":"offer","event_time":"2026-07-15T03:40:07.649662Z","price_level":"64607.06","new_quantity":"0"},{"side":"offer","event_time":"2026-07-15T03:40:07.649662Z","price_level":"64619.49","new_quantity":"0.01882833"},{"side":"offer","event_time":"2026-07-15T03:40:07.649662Z","price_level":"64624.04","new_quantity":"0.02672971"},{"side":"offer","event_time":"2026-07-15T03:40:07.649662Z","price_level":"64626.32","new_quantity":"1.43162692"},{"side":"offer","event_time":"2026-07-15T03:40:07.649662Z","price_level":"64629.18","new_quantity":"1.25962432"},{"side":"offer","event_time":"2026-07-15T03:40:07.649662Z","price_level":"64634.75","new_quantity":"0.30919631"},{"side":"offer","event_time":"2026-07-15T03:40:07.649662Z","price_level":"64634.76","new_quantity":"0.45866027"},{"side":"offer","event_time":"2026-07-15T03:40:07.649662Z","price_level":"64634.77","new_quantity":"0"},{"side":"offer","event_time":"2026-07-15T03:40:07.649662Z","price_level":"64647.51","new_quantity":"0.01846839"},{"side":"offer","event_time":"2026-07-15T03:40:07.649662Z","price_level":"64648.77","new_quantity":"3.72214134"},{"side":"offer","event_time":"2026-07-15T03:40:07.649662Z","price_level":"64730.94","new_quantity":"0"}]}]}
{"channel":"l2_data","timestamp":"2026-07-15T03:40:07.78272613Z","sequence_num":98,"events":[{"type":"update","product_id":"BTC-USD","updates":[{"side":"bid","event_time":"2026-07-15T03:40:07.731984Z","price_level":"64572.95","new_quantity":"0.18120189"},{"side":"bid","event_time":"2026-07-15T03:40:07.731984Z","price_level":"64572.57","new_quantity":"0.18018175"},{"side":"bid","event_time":"2026-07-15T03:40:07.731984Z","price_level":"64572.23","new_quantity":"0.03093532"},{"side":"bid","event_time":"2026-07-15T03:40:07.731984Z","price_level":"64572","new_quantity":"0.0232"},{"side":"bid","event_time":"2026-07-15T03:40:07.731984Z","price_level":"64568.52","new_quantity":"0.02"},{"side":"bid","event_time":"2026-07-15T03:40:07.731984Z","price_level":"64567.87","new_quantity":"0.02"},{"side":"bid","event_time":"2026-07-15T03:40:07.731984Z","price_level":"64564.93","new_quantity":"0"},{"side":"bid","event_time":"2026-07-15T03:40:07.731984Z","price_level":"64561.92","new_quantity":"0.000018"},{"side":"bid","event_time":"2026-07-15T03:40:07.731984Z","price_level":"64560.46","new_quantity":"0.00772597"},{"side":"bid","event_time":"2026-07-15T03:40:07.731984Z","price_level":"64556.16","new_quantity":"0.00029931"},{"side":"bid","event_time":"2026-07-15T03:40:07.731984Z","price_level":"64554.11","new_quantity":"0.00059861"},{"side":"bid","event_time":"2026-07-15T03:40:07.731984Z","price_level":"64553.6","new_quantity":"0.23110913"},{"side":"bid","event_time":"2026-07-15T03:40:07.731984Z","price_level":"64553.39","new_quantity":"0.14583"},{"side":"bid","event_time":"2026-07-15T03:40:07.731984Z","price_level":"64550.34","new_quantity":"0.00119723"},{"side":"bid","event_time":"2026-07-15T03:40:07.731984Z","price_level":"64542.11","new_quantity":"0.00239446"},{"side":"bid","event_time":"2026-07-15T03:40:07.731984Z","price_level":"64538.62","new_quantity":"0.96807478"},{"side":"bid","event_time":"2026-07-15T03:40:07.731984Z","price_level":"64538.61","new_quantity":"0.93183234"},{"side":"bid","event_time":"2026-07-15T03:40:07.731984Z","price_level":"64538.6","new_quantity":"0"},{"side":"bid","event_time":"2026-07-15T03:40:07.731984Z","price_level":"64538.59","new_quantity":"0"},{"side":"bid","event_time":"2026-07-15T03:40:07.731984Z","price_level":"64536.47","new_quantity":"0.61068377"},{"side":"bid","event_time":"2026-07-15T03:40:07.731984Z","price_level":"64534.68","new_quantity":"0"},{"side":"bid","event_time":"2026-07-15T03:40:07.731984Z","price_level":"64534.67","new_quantity":"0.05648967"},{"side":"bid","event_time":"2026-07-15T03:40:07.731984Z","price_level":"64533.16","new_quantity":"0"},{"side":"bid","event_time":"2026-07-15T03:40:07.731984Z","price_level":"64531.46","new_quantity":"0.00299307"},{"side":"bid","event_time":"2026-07-15T03:40:07.731984Z","price_level":"64528.75","new_quantity":"0.03781399"},{"side":"bid","event_time":"2026-07-15T03:40:07.731984Z","price_level":"64527.59","new_quantity":"0"},{"side":"bid","event_time":"2026-07-15T03:40:07.731984Z","price_level":"64526.71","new_quantity":"0"},{"side":"bid","event_time":"2026-07-15T03:40:07.731984Z","price_level":"64506.19","new_quantity":"0.92239158"},{"side":"bid","event_time":"2026-07-15T03:40:07.731984Z","price_level":"64506.18","new_quantity":"1.40068646"},{"side":"bid","event_time":"2026-07-15T03:40:07.731984Z","price_level":"64506.17","new_quantity":"0"},{"side":"bid","event_time":"2026-07-15T03:40:07.731984Z","price_level":"64506.16","new_quantity":"0.01158896"},{"side":"bid","event_time":"2026-07-15T03:40:07.731984Z","price_level":"64486.28","new_quantity":"0.0406119"},{"side":"bid","event_time":"2026-07-15T03:40:07.731984Z","price_level":"64485.51","new_quantity":"0.00748267"},{"side":"bid","event_time":"2026-07-15T03:40:07.731984Z","price_level":"64485.01","new_quantity":"0"},{"side":"bid","event_time":"2026-07-15T03:40:07.731984Z","price_level":"64476.82","new_quantity":"2.07568899"},{"side":"bid","event_time":"2026-07-15T03:40:07.731984Z","price_level":"64462.96","new_quantity":"0"},{"side":"bid","event_time":"2026-07-15T03:40:07.731984Z","price_level":"64454.87","new_quantity":"0"},{"side":"bid","event_time":"2026-07-15T03:40:07.731984Z","price_level":"64454.63","new_quantity":"0.00897921"},{"side":"bid","event_time":"2026-07-15T03:40:07.731984Z","price_level":"64452.41","new_quantity":"0"},{"side":"bid","event_time":"2026-07-15T03:40:07.731984Z","price_level":"64131.25","new_quantity":"0"},{"side":"offer","event_time":"2026-07-15T03:40:07.731984Z","price_level":"64572.96","new_quantity":"0.00776117"},{"side":"offer","event_time":"2026-07-15T03:40:07.731984Z","price_level":"64577.63","new_quantity":"0"},{"side":"offer","event_time":"2026-07-15T03:40:07.731984Z","price_level":"64580.32","new_quantity":"0.000018"},{"side":"offer","event_time":"2026-07-15T03:40:07.731984Z","price_level":"64583.64","new_quantity":"0.00159977"},{"side":"offer","event_time":"2026-07-15T03:40:07.731984Z","price_level":"64584.98","new_quantity":"0"},{"side":"offer","event_time":"2026-07-15T03:40:07.731984Z","price_level":"64588.92","new_quantity":"0.00098667"},{"side":"offer","event_time":"2026-07-15T03:40:07.731984Z","price_level":"64589.08","new_quantity":"0"},{"side":"offer","event_time":"2026-07-15T03:40:07.731984Z","price_level":"64590.55","new_quantity":"0.2778704"},{"side":"offer","event_time":"2026-07-15T03:40:07.731984Z","price_level":"64590.56","new_quantity":"0.179558"},{"side":"offer","event_time":"2026-07-15T03:40:07.731984Z","price_level":"64590.57","new_quantity":"0"},{"side":"offer","event_time":"2026-07-15T03:40:07.731984Z","price_level":"64590.58","new_quantity":"0"},{"side":"offer","event_time":"2026-07-15T03:40:07.731984Z","price_level":"64590.59","new_quantity":"0"},{"side":"offer","event_time":"2026-07-15T03:40:07.731984Z","price_level":"64590.6","new_quantity":"0"},{"side":"offer","event_time":"2026-07-15T03:40:07.731984Z","price_level":"64590.61","new_quantity":"0"},{"side":"offer","event_time":"2026-07-15T03:40:07.731984Z","price_level":"64590.62","new_quantity":"0"},{"side":"offer","event_time":"2026-07-15T03:40:07.731984Z","price_level":"64596.22","new_quantity":"0.05233375"},{"side":"offer","event_time":"2026-07-15T03:40:07.731984Z","price_level":"64600.44","new_quantity":"0.02"},{"side":"offer","event_time":"2026-07-15T03:40:07.731984Z","price_level":"64601.03","new_quantity":"0.14"},{"side":"offer","event_time":"2026-07-15T03:40:07.731984Z","price_level":"64601.72","new_quantity":"0.0545421"},{"side":"offer","event_time":"2026-07-15T03:40:07.731984Z","price_level":"64601.99","new_quantity":"0.6987157"},{"side":"offer","event_time":"2026-07-15T03:40:07.731984Z","price_level":"64602","new_quantity":"1.00003194"},{"side":"offer","event_time":"2026-07-15T03:40:07.731984Z","price_level":"64603.03","new_quantity":"0"},{"side":"offer","event_time":"2026-07-15T03:40:07.731984Z","price_level":"64603.26","new_quantity":"0.04152758"},{"side":"offer","event_time":"2026-07-15T03:40:07.731984Z","price_level":"64604.24","new_quantity":"0.04"},{"side":"offer","event_time":"2026-07-15T03:40:07.731984Z","price_level":"64609.33","new_quantity":"0"},{"side":"offer","event_time":"2026-07-15T03:40:07.731984Z","price_level":"64619.39","new_quantity":"0"},{"side":"offer","event_time":"2026-07-15T03:40:07.731984Z","price_level":"64619.48","new_quantity":"0.04179864"},{"side":"offer","event_time":"2026-07-15T03:40:07.731984Z","price_level":"64622.99","new_quantity":"0.0168957"},{"side":"offer","event_time":"2026-07-15T03:40:07.731984Z","price_level":"64623","new_quantity":"0"},{"side":"offer","event_time":"2026-07-15T03:40:07.731984Z","price_level":"64627.31","new_quantity":"0"},{"side":"offer","event_time":"2026-07-15T03:40:07.731984Z","price_level":"64629.18","new_quantity":"0.28583899"},{"side":"offer","event_time":"2026-07-15T03:40:07.731984Z","price_level":"64629.19","new_quantity":"0.4586998"},{"side":"offer","event_time":"2026-07-15T03:40:07.731984Z","price_level":"64631.48","new_quantity":"0.00077423"},{"side":"offer","event_time":"2026-07-15T03:40:07.731984Z","price_level":"64634.73","new_quantity":"1.5567183"},{"side":"offer","event_time":"2026-07-15T03:40:07.731984Z","price_level":"64634.74","new_quantity":"2.08965158"},{"side":"offer","event_time":"2026-07-15T03:40:07.731984Z","price_level":"64634.75","new_quantity":"0"},{"side":"offer","event_time":"2026-07-15T03:40:07.731984Z","price_level":"64634.76","new_quantity":"0"},{"side":"offer","event_time":"2026-07-15T03:40:07.731984Z","price_level":"64676","new_quantity":"0"},{"side":"offer","event_time":"2026-07-15T03:40:07.731984Z","price_level":"64746.64","new_quantity":"0.01149846"}]}]}
{"channel":"market_trades","timestamp":"2026-07-15T03:40:07.789044177Z","sequence_num":99,"events":[{"type":"update","trades":[{"product_id":"BTC-USD","trade_id":"1056309432","price":"64572.95","size":"0.00000004","time":"2026-07-15T03:40:07.71956Z","side":"BUY"}]}]}
{"channel":"l2_data","timestamp":"2026-07-15T03:40:07.832203856Z","sequence_num":100,"events":[{"type":"update","product_id":"BTC-USD","updates":[{"side":"bid","event_time":"2026-07-15T03:40:07.790308Z","price_level":"64570.51","new_quantity":"0.92298072"},{"side":"bid","event_time":"2026-07-15T03:40:07.790308Z","price_level":"64570.5","new_quantity":"1"},{"side":"bid","event_time":"2026-07-15T03:40:07.790308Z","price_level":"64570.29","new_quantity":"0"},{"side":"bid","event_time":"2026-07-15T03:40:07.790308Z","price_level":"64567.87","new_quantity":"0.06"},{"side":"bid","event_time":"2026-07-15T03:40:07.790308Z","price_level":"64543.01","new_quantity":"0.00077423"},{"side":"bid","event_time":"2026-07-15T03:40:07.790308Z","price_level":"64538.64","new_quantity":"0.55630373"},{"side":"bid","event_time":"2026-07-15T03:40:07.790308Z","price_level":"64538.63","new_quantity":"0.93183205"},{"side":"bid","event_time":"2026-07-15T03:40:07.790308Z","price_level":"64538.62","new_quantity":"0"},{"side":"bid","event_time":"2026-07-15T03:40:07.790308Z","price_level":"64538.61","new_quantity":"0"},{"side":"bid","event_time":"2026-07-15T03:40:07.790308Z","price_level":"64536.47","new_quantity":"0.60990952"},{"side":"bid","event_time":"2026-07-15T03:40:07.790308Z","price_level":"56501.34","new_quantity":"0.0132912"},{"side":"offer","event_time":"2026-07-15T03:40:07.790308Z","price_level":"64575.42","new_quantity":"0"},{"side":"offer","event_time":"2026-07-15T03:40:07.790308Z","price_level":"64578.51","new_quantity":"0"},{"side":"offer","event_time":"2026-07-15T03:40:07.790308Z","price_level":"64588.92","new_quantity":"0"},{"side":"offer","event_time":"2026-07-15T03:40:07.790308Z","price_level":"64589.41","new_quantity":"0.00038328"},{"side":"offer","event_time":"2026-07-15T03:40:07.790308Z","price_level":"64592.5","new_quantity":"0.00076656"},{"side":"offer","event_time":"2026-07-15T03:40:07.790308Z","price_level":"64603.26","new_quantity":"0.42018981"},{"side":"offer","event_time":"2026-07-15T03:40:07.790308Z","price_level":"64605.11","new_quantity":"0.63860732"},{"side":"offer","event_time":"2026-07-15T03:40:07.790308Z","price_level":"64607.04","new_quantity":"0"},{"side":"offer","event_time":"2026-07-15T03:40:07.790308Z","price_level":"64607.05","new_quantity":"0"},{"side":"offer","event_time":"2026-07-15T03:40:07.790308Z","price_level":"64607.16","new_quantity":"0.10644963"},{"side":"offer","event_time":"2026-07-15T03:40:07.790308Z","price_level":"64613.28","new_quantity":"0.00077417"},{"side":"offer","event_time":"2026-07-15T03:40:07.790308Z","price_level":"64631.48","new_quantity":"0"},{"side":"offer","event_time":"2026-07-15T03:40:07.790308Z","price_level":"64634.71","new_quantity":"1.28289851"},{"side":"offer","event_time":"2026-07-15T03:40:07.790308Z","price_level":"64634.72","new_quantity":"2.08965222"},{"side":"offer","event_time":"2026-07-15T03:40:07.790308Z","price_level":"64634.73","new_quantity":"0"},{"side":"offer","event_time":"2026-07-15T03:40:07.790308Z","price_level":"64634.74","new_quantity":"0"}]}]}
{"channel":"l2_data","timestamp":"2026-07-15T03:40:07.882013834Z","sequence_num":101,"events":[{"type":"update","product_id":"BTC-USD","updates":[{"side":"bid","event_time":"2026-07-15T03:40:07.845964Z","price_level":"64572.95","new_quantity":"0.2340159"},{"side":"bid","event_time":"2026-07-15T03:40:07.845964Z","price_level":"64570.5","new_quantity":"0"},{"side":"bid","event_time":"2026-07-15T03:40:07.845964Z","price_level":"64568.52","new_quantity":"0"},{"side":"bid","event_time":"2026-07-15T03:40:07.845964Z","price_level":"64536.5","new_quantity":"0.41038122"},{"side":"bid","event_time":"2026-07-15T03:40:07.845964Z","price_level":"64536.49","new_quantity":"0.60990934"},{"side":"bid","event_time":"2026-07-15T03:40:07.845964Z","price_level":"64536.47","new_quantity":"0"},{"side":"bid","event_time":"2026-07-15T03:40:07.845964Z","price_level":"64535.05","new_quantity":"0.00154731"},{"side":"bid","event_time":"2026-07-15T03:40:07.845964Z","price_level":"64528.61","new_quantity":"0.00773657"},{"side":"bid","event_time":"2026-07-15T03:40:07.845964Z","price_level":"64506.21","new_quantity":"0.92239133"},{"side":"bid","event_time":"2026-07-15T03:40:07.845964Z","price_level":"64506.2","new_quantity":"1.40068603"},{"side":"bid","event_time":"2026-07-15T03:40:07.845964Z","price_level":"64506.19","new_quantity":"0"},{"side":"bid","event_time":"2026-07-15T03:40:07.845964Z","price_level":"64506.18","new_quantity":"0"},{"side":"offer","event_time":"2026-07-15T03:40:07.845964Z","price_level":"64588.31","new_quantity":"0.00098667"},{"side":"offer","event_time":"2026-07-15T03:40:07.845964Z","price_level":"64588.49","new_quantity":"0"},{"side":"offer","event_time":"2026-07-15T03:40:07.845964Z","price_level":"64593.54","new_quantity":"0.06086038"},{"side":"offer","event_time":"2026-07-15T03:40:07.845964Z","price_level":"64601.02","new_quantity":"0.21785734"},{"side":"offer","event_time":"2026-07-15T03:40:07.845964Z","price_level":"64601.72","new_quantity":"0"},{"side":"offer","event_time":"2026-07-15T03:40:07.845964Z","price_level":"64601.99","new_quantity":"0"},{"side":"offer","event_time":"2026-07-15T03:40:07.845964Z","price_level":"64602","new_quantity":"0.00003194"},{"side":"offer","event_time":"2026-07-15T03:40:07.845964Z","price_level":"64603.5","new_quantity":"1"},{"side":"offer","event_time":"2026-07-15T03:40:07.845964Z","price_level":"64629.18","new_quantity":"0"},{"side":"offer","event_time":"2026-07-15T03:40:07.845964Z","price_level":"64629.19","new_quantity":"0"},{"side":"offer","event_time":"2026-07-15T03:40:07.845964Z","price_level":"64634.7","new_quantity":"0.4586607"}]}]}
{"channel":"l2_data","timestamp":"2026-07-15T03:40:07.938180162Z","sequence_num":102,"events":[{"type":"update","product_id":"BTC-USD","updates":[{"side":"bid","event_time":"2026-07-15T03:40:07.89137Z","price_level":"64572.57","new_quantity":"0.75414587"},{"side":"bid","event_time":"2026-07-15T03:40:07.89137Z","price_level":"64572","new_quantity":"1.0232"},{"side":"bid","event_time":"2026-07-15T03:40:07.89137Z","price_level":"64570.51","new_quantity":"0.31404072"},{"side":"bid","event_time":"2026-07-15T03:40:07.89137Z","price_level":"64568.67","new_quantity":"0"},{"side":"bid","event_time":"2026-07-15T03:40:07.89137Z","price_level":"64558.74","new_quantity":"0.05855738"},{"side":"bid","event_time":"2026-07-15T03:40:07.89137Z","price_level":"64551.4","new_quantity":"0.06745259"},{"side":"bid","event_time":"2026-07-15T03:40:07.89137Z","price_level":"64548.95","new_quantity":"0"},{"side":"bid","event_time":"2026-07-15T03:40:07.89137Z","price_level":"64547.23","new_quantity":"0.33929379"},{"side":"bid","event_time":"2026-07-15T03:40:07.89137Z","price_level":"64547.22","new_quantity":"0.56676"},{"side":"bid","event_time":"2026-07-15T03:40:07.89137Z","price_level":"64538.65","new_quantity":"0.93183176"},{"side":"bid","event_time":"2026-07-15T03:40:07.89137Z","price_level":"64538.63","new_quantity":"0"},{"side":"bid","event_time":"2026-07-15T03:40:07.89137Z","price_level":"64534.2","new_quantity":"0.0005"},{"side":"bid","event_time":"2026-07-15T03:40:07.89137Z","price_level":"56501.34","new_quantity":"0"},{"side":"offer","event_time":"2026-07-15T03:40:07.89137Z","price_level":"64572.96","new_quantity":"0.00001117"},{"side":"offer","event_time":"2026-07-15T03:40:07.89137Z","price_level":"64580.13","new_quantity":"0"},{"side":"offer","event_time":"2026-07-15T03:40:07.89137Z","price_level":"64582.17","new_quantity":"0"},{"side":"offer","event_time":"2026-07-15T03:40:07.89137Z","price_level":"64584.55","new_quantity":"0"},{"side":"offer","event_time":"2026-07-15T03:40:07.89137Z","price_level":"64588.31","new_quantity":"0"},{"side":"offer","event_time":"2026-07-15T03:40:07.89137Z","price_level":"64590.52","new_quantity":"0.179558"},{"side":"offer","event_time":"2026-07-15T03:40:07.89137Z","price_level":"64590.53","new_quantity":"0.22117904"},{"side":"offer","event_time":"2026-07-15T03:40:07.89137Z","price_level":"64590.54","new_quantity":"0"},{"side":"offer","event_time":"2026-07-15T03:40:07.89137Z","price_level":"64590.55","new_quantity":"0"},{"side":"offer","event_time":"2026-07-15T03:40:07.89137Z","price_level":"64590.56","new_quantity":"0"},{"side":"offer","event_time":"2026-07-15T03:40:07.89137Z","price_level":"64591.61","new_quantity":"0.021984"},{"side":"offer","event_time":"2026-07-15T03:40:07.89137Z","price_level":"64592.63","new_quantity":"0.00098667"},{"side":"offer","event_time":"2026-07-15T03:40:07.89137Z","price_level":"64599.28","new_quantity":"0"},{"side":"offer","event_time":"2026-07-15T03:40:07.89137Z","price_level":"64600.44","new_quantity":"0"},{"side":"offer","event_time":"2026-07-15T03:40:07.89137Z","price_level":"64601.02","new_quantity":"0.13799796"},{"side":"offer","event_time":"2026-07-15T03:40:07.89137Z","price_level":"64601.03","new_quantity":"0.06"},{"side":"offer","event_time":"2026-07-15T03:40:07.89137Z","price_level":"64602.53","new_quantity":"0.00077431"},{"side":"offer","event_time":"2026-07-15T03:40:07.89137Z","price_level":"64603.26","new_quantity":"0.58753002"},{"side":"offer","event_time":"2026-07-15T03:40:07.89137Z","price_level":"64604.24","new_quantity":"0"},{"side":"offer","event_time":"2026-07-15T03:40:07.89137Z","price_level":"64605.11","new_quantity":"0"},{"side":"offer","event_time":"2026-07-15T03:40:07.89137Z","price_level":"64607.14","new_quantity":"0.48768617"},{"side":"offer","event_time":"2026-07-15T03:40:07.89137Z","price_level":"64607.15","new_quantity":"0.63858716"},{"side":"offer","event_time":"2026-07-15T03:40:07.89137Z","price_level":"64607.16","new_quantity":"0"},{"side":"offer","event_time":"2026-07-15T03:40:07.89137Z","price_level":"64615.6","new_quantity":"0"},{"side":"offer","event_time":"2026-07-15T03:40:07.89137Z","price_level":"64634.68","new_quantity":"1.55718173"},{"side":"offer","event_time":"2026-07-15T03:40:07.89137Z","price_level":"64634.69","new_quantity":"2.08965319"},{"side":"offer","event_time":"2026-07-15T03:40:07.89137Z","price_level":"64634.71","new_quantity":"0"},{"side":"offer","event_time":"2026-07-15T03:40:07.89137Z","price_level":"64634.72","new_quantity":"0"},{"side":"offer","event_time":"2026-07-15T03:40:07.89137Z","price_level":"64634.76","new_quantity":"0.00077422"},{"side":"offer","event_time":"2026-07-15T03:40:07.89137Z","price_level":"64788.55","new_quantity":"0"}]}]}
{"channel":"l2_data","timestamp":"2026-07-15T03:40:07.984047062Z","sequence_num":103,"events":[{"type":"update","product_id":"BTC-USD","updates":[{"side":"bid","event_time":"2026-07-15T03:40:07.943467Z","price_level":"64576.18","new_quantity":"0.10789"},{"side":"bid","event_time":"2026-07-15T03:40:07.943467Z","price_level":"64575.02","new_quantity":"0.04646634"},{"side":"bid","event_time":"2026-07-15T03:40:07.943467Z","price_level":"64574.7","new_quantity":"0"},{"side":"bid","event_time":"2026-07-15T03:40:07.943467Z","price_level":"64574.69","new_quantity":"0.12378505"},{"side":"bid","event_time":"2026-07-15T03:40:07.943467Z","price_level":"64573.56","new_quantity":"0"},{"side":"bid","event_time":"2026-07-15T03:40:07.943467Z","price_level":"64572.97","new_quantity":"0"},{"side":"bid","event_time":"2026-07-15T03:40:07.943467Z","price_level":"64572.96","new_quantity":"0.00159977"},{"side":"bid","event_time":"2026-07-15T03:40:07.943467Z","price_level":"64572.95","new_quantity":"0.04"},{"side":"bid","event_time":"2026-07-15T03:40:07.943467Z","price_level":"64572.57","new_quantity":"0.18018175"},{"side":"bid","event_time":"2026-07-15T03:40:07.943467Z","price_level":"64572","new_quantity":"0.0232"},{"side":"bid","event_time":"2026-07-15T03:40:07.943467Z","price_level":"64568.46","new_quantity":"0.0483189"},{"side":"bid","event_time":"2026-07-15T03:40:07.943467Z","price_level":"64567.98","new_quantity":"0"},{"side":"bid","event_time":"2026-07-15T03:40:07.943467Z","price_level":"64554","new_quantity":"0"},{"side":"bid","event_time":"2026-07-15T03:40:07.943467Z","price_level":"64553.6","new_quantity":"0.09599486"},{"side":"bid","event_time":"2026-07-15T03:40:07.943467Z","price_level":"64553.59","new_quantity":"0"},{"side":"bid","event_time":"2026-07-15T03:40:07.943467Z","price_level":"64552","new_quantity":"0"},{"side":"bid","event_time":"2026-07-15T03:40:07.943467Z","price_level":"64551.64","new_quantity":"0"},{"side":"bid","event_time":"2026-07-15T03:40:07.943467Z","price_level":"64547.23","new_quantity":"0"},{"side":"bid","event_time":"2026-07-15T03:40:07.943467Z","price_level":"64547.22","new_quantity":"0"},{"side":"bid","event_time":"2026-07-15T03:40:07.943467Z","price_level":"64544.34","new_quantity":"0.08566822"},{"side":"bid","event_time":"2026-07-15T03:40:07.943467Z","price_level":"64542.35","new_quantity":"0.04368827"},{"side":"bid","event_time":"2026-07-15T03:40:07.943467Z","price_level":"64538.66","new_quantity":"0.55630356"},{"side":"bid","event_time":"2026-07-15T03:40:07.943467Z","price_level":"64538.64","new_quantity":"0"},{"side":"bid","event_time":"2026-07-15T03:40:07.943467Z","price_level":"64536.52","new_quantity":"0.41038111"},{"side":"bid","event_time":"2026-07-15T03:40:07.943467Z","price_level":"64536.51","new_quantity":"0.60990915"},{"side":"bid","event_time":"2026-07-15T03:40:07.943467Z","price_level":"64536.5","new_quantity":"0"},{"side":"bid","event_time":"2026-07-15T03:40:07.943467Z","price_level":"64536.49","new_quantity":"0"},{"side":"bid","event_time":"2026-07-15T03:40:07.943467Z","price_level":"64535.45","new_quantity":"0.01899391"},{"side":"bid","event_time":"2026-07-15T03:40:07.943467Z","price_level":"64523.52","new_quantity":"0.15719562"},{"side":"bid","event_time":"2026-07-15T03:40:07.943467Z","price_level":"64523.51","new_quantity":"0.26330924"},{"side":"bid","event_time":"2026-07-15T03:40:07.943467Z","price_level":"64515.64","new_quantity":"0.83374867"},{"side":"bid","event_time":"2026-07-15T03:40:07.943467Z","price_level":"64515.63","new_quantity":"1.39501063"},{"side":"bid","event_time":"2026-07-15T03:40:07.943467Z","price_level":"64506.23","new_quantity":"0.92146374"},{"side":"bid","event_time":"2026-07-15T03:40:07.943467Z","price_level":"64506.22","new_quantity":"1.40068559"},{"side":"bid","event_time":"2026-07-15T03:40:07.943467Z","price_level":"64506.21","new_quantity":"0"},{"side":"bid","event_time":"2026-07-15T03:40:07.943467Z","price_level":"64506.2","new_quantity":"0"},{"side":"bid","event_time":"2026-07-15T03:40:07.943467Z","price_level":"64504.99","new_quantity":"0"},{"side":"bid","event_time":"2026-07-15T03:40:07.943467Z","price_level":"64486.3","new_quantity":"0.30029057"},{"side":"bid","event_time":"2026-07-15T03:40:07.943467Z","price_level":"64486.29","new_quantity":"2.07538416"},{"side":"bid","event_time":"2026-07-15T03:40:07.943467Z","price_level":"64486.28","new_quantity":"0"},{"side":"bid","event_time":"2026-07-15T03:40:07.943467Z","price_level":"64476.82","new_quantity":"0"},{"side":"bid","event_time":"2026-07-15T03:40:07.943467Z","price_level":"64476.31","new_quantity":"0"},{"side":"bid","event_time":"2026-07-15T03:40:07.943467Z","price_level":"64382.95","new_quantity":"0.04831322"},{"side":"bid","event_time":"2026-07-15T03:40:07.943467Z","price_level":"64297.18","new_quantity":"0"},{"side":"offer","event_time":"2026-07-15T03:40:07.943467Z","price_level":"64572.96","new_quantity":"0"},{"side":"offer","event_time":"2026-07-15T03:40:07.943467Z","price_level":"64574.58","new_quantity":"0"},{"side":"offer","event_time":"2026-07-15T03:40:07.943467Z","price_level":"64576.19","new_quantity":"0.00774308"},{"side":"offer","event_time":"2026-07-15T03:40:07.943467Z","price_level":"64576.76","new_quantity":"0"},{"side":"offer","event_time":"2026-07-15T03:40:07.943467Z","price_level":"64578","new_quantity":"0"},{"side":"offer","event_time":"2026-07-15T03:40:07.943467Z","price_level":"64578.37","new_quantity":"0.00967885"},{"side":"offer","event_time":"2026-07-15T03:40:07.943467Z","price_level":"64582.15","new_quantity":"0.00159977"},{"side":"offer","event_time":"2026-07-15T03:40:07.943467Z","price_level":"64582.16","new_quantity":"0.1026517"},{"side":"offer","event_time":"2026-07-15T03:40:07.943467Z","price_level":"64582.17","new_quantity":"0.12378505"},{"side":"offer","event_time":"2026-07-15T03:40:07.943467Z","price_level":"64582.18","new_quantity":"0"},{"side":"offer","event_time":"2026-07-15T03:40:07.943467Z","price_level":"64583.24","new_quantity":"0"},{"side":"offer","event_time":"2026-07-15T03:40:07.943467Z","price_level":"64583.64","new_quantity":"0"},{"side":"offer","event_time":"2026-07-15T03:40:07.943467Z","price_level":"64584.52","new_quantity":"0.13840011"},{"side":"offer","event_time":"2026-07-15T03:40:07.943467Z","price_level":"64584.54","new_quantity":"0"},{"side":"offer","event_time":"2026-07-15T03:40:07.943467Z","price_level":"64584.7","new_quantity":"0.04646634"},{"side":"offer","event_time":"2026-07-15T03:40:07.943467Z","price_level":"64585.59","new_quantity":"0"},{"side":"offer","event_time":"2026-07-15T03:40:07.943467Z","price_level":"64585.61","new_quantity":"0.12386661"},{"side":"offer","event_time":"2026-07-15T03:40:07.943467Z","price_level":"64587.54","new_quantity":"0.18135516"},{"side":"offer","event_time":"2026-07-15T03:40:07.943467Z","price_level":"64588.34","new_quantity":"0.0483189"},{"side":"offer","event_time":"2026-07-15T03:40:07.943467Z","price_level":"64588.43","new_quantity":"0.1548265"},{"side":"offer","event_time":"2026-07-15T03:40:07.943467Z","price_level":"64590.52","new_quantity":"0"},{"side":"offer","event_time":"2026-07-15T03:40:07.943467Z","price_level":"64591.61","new_quantity":"0.021984"},{"side":"offer","event_time":"2026-07-15T03:40:07.943467Z","price_level":"64592.16","new_quantity":"0.179558"},{"side":"offer","event_time":"2026-07-15T03:40:07.943467Z","price_level":"64592.88","new_quantity":"0"},{"side":"offer","event_time":"2026-07-15T03:40:07.943467Z","price_level":"64595.91","new_quantity":"0.00592"},{"side":"offer","event_time":"2026-07-15T03:40:07.943467Z","price_level":"64596.59","new_quantity":"0.04330632"},{"side":"offer","event_time":"2026-07-15T03:40:07.943467Z","price_level":"64601.02","new_quantity":"0.10217796"},{"side":"offer","event_time":"2026-07-15T03:40:07.943467Z","price_level":"64601.03","new_quantity":"0"},{"side":"offer","event_time":"2026-07-15T03:40:07.943467Z","price_level":"64626.32","new_quantity":"0"},{"side":"offer","event_time":"2026-07-15T03:40:07.943467Z","price_level":"64628.76","new_quantity":"1.41911221"},{"side":"offer","event_time":"2026-07-15T03:40:07.943467Z","price_level":"64633.28","new_quantity":"0.45867078"},{"side":"offer","event_time":"2026-07-15T03:40:07.943467Z","price_level":"64633.29","new_quantity":"0.26330924"},{"side":"offer","event_time":"2026-07-15T03:40:07.943467Z","price_level":"64634.7","new_quantity":"0"},{"side":"offer","event_time":"2026-07-15T03:40:07.943467Z","price_level":"64634.78","new_quantity":"0"}]}]}
{"channel":"market_trades","timestamp":"2026-07-15T03:40:07.987185772Z","sequence_num":104,"events":[{"type":"update","trades":[{"product_id":"BTC-USD","trade_id":"1056309435","price":"64572.96","size":"0.00001117","time":"2026-07-15T03:40:07.891401Z","side":"SELL"},{"product_id":"BTC-USD","trade_id":"1056309434","price":"64572.96","size":"0.007732","time":"2026-07-15T03:40:07.87813Z","side":"SELL"},{"product_id":"BTC-USD","trade_id":"1056309433","price":"64572.96","size":"0.000018","time":"2026-07-15T03:40:07.87813Z","side":"SELL"}]}]}
{"channel":"l2_data","timestamp":"2026-07-15T03:40:08.031847668Z","sequence_num":105,"events":[{"type":"update","product_id":"BTC-USD","updates":[{"side":"bid","event_time":"2026-07-15T03:40:07.994866Z","price_level":"64576.18","new_quantity":"0.14100197"},{"side":"bid","event_time":"2026-07-15T03:40:07.994866Z","price_level":"64576","new_quantity":"0.06966634"},{"side":"bid","event_time":"2026-07-15T03:40:07.994866Z","price_level":"64575.02","new_quantity":"0"},{"side":"bid","event_time":"2026-07-15T03:40:07.994866Z","price_level":"64570.51","new_quantity":"0.31404072"},{"side":"bid","event_time":"2026-07-15T03:40:07.994866Z","price_level":"64561.06","new_quantity":"0.00772597"},{"side":"bid","event_time":"2026-07-15T03:40:07.994866Z","price_level":"64560.46","new_quantity":"0"},{"side":"bid","event_time":"2026-07-15T03:40:07.994866Z","price_level":"64544.35","new_quantity":"0.93174947"},{"side":"bid","event_time":"2026-07-15T03:40:07.994866Z","price_level":"64538.65","new_quantity":"0"},{"side":"bid","event_time":"2026-07-15T03:40:07.994866Z","price_level":"64508.35","new_quantity":"0.00240035"},{"side":"offer","event_time":"2026-07-15T03:40:07.994866Z","price_level":"64579.55","new_quantity":"0"},{"side":"offer","event_time":"2026-07-15T03:40:07.994866Z","price_level":"64581.99","new_quantity":"0.04260242"},{"side":"offer","event_time":"2026-07-15T03:40:07.994866Z","price_level":"64582","new_quantity":"0.0232"},{"side":"offer","event_time":"2026-07-15T03:40:07.994866Z","price_level":"64582.16","new_quantity":"0"},{"side":"offer","event_time":"2026-07-15T03:40:07.994866Z","price_level":"64582.17","new_quantity":"0"},{"side":"offer","event_time":"2026-07-15T03:40:07.994866Z","price_level":"64583.99","new_quantity":"0"},{"side":"offer","event_time":"2026-07-15T03:40:07.994866Z","price_level":"64584.52","new_quantity":"0.07389967"},{"side":"offer","event_time":"2026-07-15T03:40:07.994866Z","price_level":"64584.7","new_quantity":"0"},{"side":"offer","event_time":"2026-07-15T03:40:07.994866Z","price_level":"64585.6","new_quantity":"0"},{"side":"offer","event_time":"2026-07-15T03:40:07.994866Z","price_level":"64585.61","new_quantity":"0"},{"side":"offer","event_time":"2026-07-15T03:40:07.994866Z","price_level":"64585.68","new_quantity":"0.04646634"},{"side":"offer","event_time":"2026-07-15T03:40:07.994866Z","price_level":"64587.53","new_quantity":"0.00772597"},{"side":"offer","event_time":"2026-07-15T03:40:07.994866Z","price_level":"64587.54","new_quantity":"0.20471798"},{"side":"offer","event_time":"2026-07-15T03:40:07.994866Z","price_level":"64587.55","new_quantity":"0.12386289"},{"side":"offer","event_time":"2026-07-15T03:40:07.994866Z","price_level":"64588.43","new_quantity":"0"},{"side":"offer","event_time":"2026-07-15T03:40:07.994866Z","price_level":"64591.12","new_quantity":"0.15482005"},{"side":"offer","event_time":"2026-07-15T03:40:07.994866Z","price_level":"64591.6","new_quantity":"0"},{"side":"offer","event_time":"2026-07-15T03:40:07.994866Z","price_level":"64592.16","new_quantity":"0.179558"},{"side":"offer","event_time":"2026-07-15T03:40:07.994866Z","price_level":"64592.63","new_quantity":"0"},{"side":"offer","event_time":"2026-07-15T03:40:07.994866Z","price_level":"64596.59","new_quantity":"0"},{"side":"offer","event_time":"2026-07-15T03:40:07.994866Z","price_level":"64603.26","new_quantity":"0.0463441"},{"side":"offer","event_time":"2026-07-15T03:40:07.994866Z","price_level":"64603.5","new_quantity":"0"},{"side":"offer","event_time":"2026-07-15T03:40:07.994866Z","price_level":"64604.17","new_quantity":"0.00306626"},{"side":"offer","event_time":"2026-07-15T03:40:07.994866Z","price_level":"64607.15","new_quantity":"0"},{"side":"offer","event_time":"2026-07-15T03:40:07.994866Z","price_level":"64609.33","new_quantity":"0.63856561"}]}]}
{"channel":"l2_data","timestamp":"2026-07-15T03:40:08.08384139Z","sequence_num":106,"events":[{"type":"update","product_id":"BTC-USD","updates":[{"side":"bid","event_time":"2026-07-15T03:40:08.03493Z","price_level":"64576.18","new_quantity":"0.24636281"},{"side":"bid","event_time":"2026-07-15T03:40:08.03493Z","price_level":"64576","new_quantity":"0.0232"},{"side":"bid","event_time":"2026-07-15T03:40:08.03493Z","price_level":"64574.69","new_quantity":"0"},{"side":"bid","event_time":"2026-07-15T03:40:08.03493Z","price_level":"64573.51","new_quantity":"0.13111714"},{"side":"bid","event_time":"2026-07-15T03:40:08.03493Z","price_level":"64572.57","new_quantity":"0"},{"side":"bid","event_time":"2026-07-15T03:40:08.03493Z","price_level":"64572.22","new_quantity":"0"},{"side":"bid","event_time":"2026-07-15T03:40:08.03493Z","price_level":"64544.36","new_quantity":"0.6478618"},{"side":"bid","event_time":"2026-07-15T03:40:08.03493Z","price_level":"64544.34","new_quantity":"0"},{"side":"bid","event_time":"2026-07-15T03:40:08.03493Z","price_level":"64538.66","new_quantity":"0"},{"side":"bid","event_time":"2026-07-15T03:40:08.03493Z","price_level":"64536.54","new_quantity":"0.43978302"},{"side":"bid","event_time":"2026-07-15T03:40:08.03493Z","price_level":"64536.53","new_quantity":"0.64016467"},{"side":"bid","event_time":"2026-07-15T03:40:08.03493Z","price_level":"64536.52","new_quantity":"0"},{"side":"bid","event_time":"2026-07-15T03:40:08.03493Z","price_level":"64536.51","new_quantity":"0"},{"side":"bid","event_time":"2026-07-15T03:40:08.03493Z","price_level":"64512.53","new_quantity":"1.09184286"},{"side":"bid","event_time":"2026-07-15T03:40:08.03493Z","price_level":"64510.01","new_quantity":"1.4006033"},{"side":"bid","event_time":"2026-07-15T03:40:08.03493Z","price_level":"64506.23","new_quantity":"0"},{"side":"bid","event_time":"2026-07-15T03:40:08.03493Z","price_level":"64506.22","new_quantity":"0"},{"side":"bid","event_time":"2026-07-15T03:40:08.03493Z","price_level":"64506.15","new_quantity":"0.07833584"},{"side":"bid","event_time":"2026-07-15T03:40:08.03493Z","price_level":"64490.01","new_quantity":"3.94302168"},{"side":"bid","event_time":"2026-07-15T03:40:08.03493Z","price_level":"64488.16","new_quantity":"2.07532398"},{"side":"bid","event_time":"2026-07-15T03:40:08.03493Z","price_level":"64486.3","new_quantity":"0.0406119"},{"side":"bid","event_time":"2026-07-15T03:40:08.03493Z","price_level":"64486.29","new_quantity":"0"},{"side":"offer","event_time":"2026-07-15T03:40:08.03493Z","price_level":"64580","new_quantity":"0.0232"},{"side":"offer","event_time":"2026-07-15T03:40:08.03493Z","price_level":"64584.52","new_quantity":"0"},{"side":"offer","event_time":"2026-07-15T03:40:08.03493Z","price_level":"64584.53","new_quantity":"0"},{"side":"offer","event_time":"2026-07-15T03:40:08.03493Z","price_level":"64584.68","new_quantity":"0.10164008"},{"side":"offer","event_time":"2026-07-15T03:40:08.03493Z","price_level":"64584.69","new_quantity":"0.12378505"},{"side":"offer","event_time":"2026-07-15T03:40:08.03493Z","price_level":"64585.68","new_quantity":"0"},{"side":"offer","event_time":"2026-07-15T03:40:08.03493Z","price_level":"64585.86","new_quantity":"0.04646634"},{"side":"offer","event_time":"2026-07-15T03:40:08.03493Z","price_level":"64587.51","new_quantity":"0.20933038"},{"side":"offer","event_time":"2026-07-15T03:40:08.03493Z","price_level":"64587.52","new_quantity":"0.12378505"},{"side":"offer","event_time":"2026-07-15T03:40:08.03493Z","price_level":"64587.54","new_quantity":"0"},{"side":"offer","event_time":"2026-07-15T03:40:08.03493Z","price_level":"64588.05","new_quantity":"0"},{"side":"offer","event_time":"2026-07-15T03:40:08.03493Z","price_level":"64590.51","new_quantity":"0.34342255"},{"side":"offer","event_time":"2026-07-15T03:40:08.03493Z","price_level":"64590.52","new_quantity":"0.12378505"},{"side":"offer","event_time":"2026-07-15T03:40:08.03493Z","price_level":"64590.53","new_quantity":"0"},{"side":"offer","event_time":"2026-07-15T03:40:08.03493Z","price_level":"64590.64","new_quantity":"0"},{"side":"offer","event_time":"2026-07-15T03:40:08.03493Z","price_level":"64592.16","new_quantity":"0"},{"side":"offer","event_time":"2026-07-15T03:40:08.03493Z","price_level":"64592.58","new_quantity":"0"},{"side":"offer","event_time":"2026-07-15T03:40:08.03493Z","price_level":"64592.65","new_quantity":"0.00098666"},{"side":"offer","event_time":"2026-07-15T03:40:08.03493Z","price_level":"64592.78","new_quantity":"0.179558"},{"side":"offer","event_time":"2026-07-15T03:40:08.03493Z","price_level":"64594.48","new_quantity":"0.12378505"},{"side":"offer","event_time":"2026-07-15T03:40:08.03493Z","price_level":"64594.79","new_quantity":"0"},{"side":"offer","event_time":"2026-07-15T03:40:08.03493Z","price_level":"64603.26","new_quantity":"0.61476614"},{"side":"offer","event_time":"2026-07-15T03:40:08.03493Z","price_level":"64605","new_quantity":"1"},{"side":"offer","event_time":"2026-07-15T03:40:08.03493Z","price_level":"64605.03","new_quantity":"0.08"},{"side":"offer","event_time":"2026-07-15T03:40:08.03493Z","price_level":"64607.07","new_quantity":"0.12378505"},{"side":"offer","event_time":"2026-07-15T03:40:08.03493Z","price_level":"64609.73","new_quantity":"0.09591367"},{"side":"offer","event_time":"2026-07-15T03:40:08.03493Z","price_level":"64610.95","new_quantity":"0.12378505"},{"side":"offer","event_time":"2026-07-15T03:40:08.03493Z","price_level":"64613.29","new_quantity":"0.10302877"},{"side":"offer","event_time":"2026-07-15T03:40:08.03493Z","price_level":"64614.83","new_quantity":"0.12378505"},{"side":"offer","event_time":"2026-07-15T03:40:08.03493Z","price_level":"64626.31","new_quantity":"0.23417375"},{"side":"offer","event_time":"2026-07-15T03:40:08.03493Z","price_level":"64628.76","new_quantity":"0"},{"side":"offer","event_time":"2026-07-15T03:40:08.03493Z","price_level":"64633.25","new_quantity":"0.45867099"},{"side":"offer","event_time":"2026-07-15T03:40:08.03493Z","price_level":"64633.26","new_quantity":"2.53581604"},{"side":"offer","event_time":"2026-07-15T03:40:08.03493Z","price_level":"64633.27","new_quantity":"1.41901319"},{"side":"offer","event_time":"2026-07-15T03:40:08.03493Z","price_level":"64633.28","new_quantity":"0"},{"side":"offer","event_time":"2026-07-15T03:40:08.03493Z","price_level":"64634.68","new_quantity":"0"}]}]}
{"channel":"l2_data","timestamp":"2026-07-15T03:40:08.136132574Z","sequence_num":107,"events":[{"type":"update","product_id":"BTC-USD","updates":[{"side":"bid","event_time":"2026-07-15T03:40:08.095695Z","price_level":"64580.31","new_quantity":"0.18742939"},{"side":"bid","event_time":"2026-07-15T03:40:08.095695Z","price_level":"64580","new_quantity":"0.0232"},{"side":"bid","event_time":"2026-07-15T03:40:08.095695Z","price_level":"64579.85","new_quantity":"0.12378505"},{"side":"bid","event_time":"2026-07-15T03:40:08.095695Z","price_level":"64578.38","new_quantity":"0.03093532"},{"side":"bid","event_time":"2026-07-15T03:40:08.095695Z","price_level":"64578.36","new_quantity":"0"},{"side":"bid","event_time":"2026-07-15T03:40:08.095695Z","price_level":"64578","new_quantity":"0.0232"},{"side":"bid","event_time":"2026-07-15T03:40:08.095695Z","price_level":"64576.64","new_quantity":"0.15038976"},{"side":"bid","event_time":"2026-07-15T03:40:08.095695Z","price_level":"64576.63","new_quantity":"0.12378505"},{"side":"bid","event_time":"2026-07-15T03:40:08.095695Z","price_level":"64576.29","new_quantity":"0.04656107"},{"side":"bid","event_time":"2026-07-15T03:40:08.095695Z","price_level":"64576.19","new_quantity":"0.00933977"},{"side":"bid","event_time":"2026-07-15T03:40:08.095695Z","price_level":"64576.18","new_quantity":"0"},{"side":"bid","event_time":"2026-07-15T03:40:08.095695Z","price_level":"64574.77","new_quantity":"0.0483189"},{"side":"bid","event_time":"2026-07-15T03:40:08.095695Z","price_level":"64573.53","new_quantity":"0.11911352"},{"side":"bid","event_time":"2026-07-15T03:40:08.095695Z","price_level":"64573.52","new_quantity":"0.12378505"},{"side":"bid","event_time":"2026-07-15T03:40:08.095695Z","price_level":"64573.51","new_quantity":"0"},{"side":"bid","event_time":"2026-07-15T03:40:08.095695Z","price_level":"64572.96","new_quantity":"0"},{"side":"bid","event_time":"2026-07-15T03:40:08.095695Z","price_level":"64572.95","new_quantity":"0.02"},{"side":"bid","event_time":"2026-07-15T03:40:08.095695Z","price_level":"64572.56","new_quantity":"0"},{"side":"bid","event_time":"2026-07-15T03:40:08.095695Z","price_level":"64568.46","new_quantity":"0"},{"side":"bid","event_time":"2026-07-15T03:40:08.095695Z","price_level":"64567.87","new_quantity":"0"},{"side":"bid","event_time":"2026-07-15T03:40:08.095695Z","price_level":"64566.09","new_quantity":"0.04888853"},{"side":"bid","event_time":"2026-07-15T03:40:08.095695Z","price_level":"64562.42","new_quantity":"0.00772597"},{"side":"bid","event_time":"2026-07-15T03:40:08.095695Z","price_level":"64561.06","new_quantity":"0"},{"side":"bid","event_time":"2026-07-15T03:40:08.095695Z","price_level":"64559.29","new_quantity":"0.00002323"},{"side":"bid","event_time":"2026-07-15T03:40:08.095695Z","price_level":"64558","new_quantity":"0"},{"side":"bid","event_time":"2026-07-15T03:40:08.095695Z","price_level":"64557.92","new_quantity":"0"},{"side":"bid","event_time":"2026-07-15T03:40:08.095695Z","price_level":"64556","new_quantity":"0"},{"side":"bid","event_time":"2026-07-15T03:40:08.095695Z","price_level":"64553.6","new_quantity":"0"},{"side":"bid","event_time":"2026-07-15T03:40:08.095695Z","price_level":"64553.39","new_quantity":"0.00583"},{"side":"bid","event_time":"2026-07-15T03:40:08.095695Z","price_level":"64536.16","new_quantity":"0.00158721"},{"side":"bid","event_time":"2026-07-15T03:40:08.095695Z","price_level":"64535.05","new_quantity":"0"},{"side":"bid","event_time":"2026-07-15T03:40:08.095695Z","price_level":"64533.71","new_quantity":"0.00077417"},{"side":"bid","event_time":"2026-07-15T03:40:08.095695Z","price_level":"64531.94","new_quantity":"0.20552579"},{"side":"bid","event_time":"2026-07-15T03:40:08.095695Z","price_level":"64529.3","new_quantity":"0.26330924"},{"side":"bid","event_time":"2026-07-15T03:40:08.095695Z","price_level":"64528.76","new_quantity":"0"},{"side":"bid","event_time":"2026-07-15T03:40:08.095695Z","price_level":"64528.61","new_quantity":"0"},{"side":"bid","event_time":"2026-07-15T03:40:08.095695Z","price_level":"64523.52","new_quantity":"0"},{"side":"bid","event_time":"2026-07-15T03:40:08.095695Z","price_level":"64523.51","new_quantity":"0"},{"side":"bid","event_time":"2026-07-15T03:40:08.095695Z","price_level":"64516.76","new_quantity":"0.04377689"},{"side":"bid","event_time":"2026-07-15T03:40:08.095695Z","price_level":"64516.48","new_quantity":"0.04656107"},{"side":"bid","event_time":"2026-07-15T03:40:08.095695Z","price_level":"64511.37","new_quantity":"0"},{"side":"bid","event_time":"2026-07-15T03:40:08.095695Z","price_level":"64508.18","new_quantity":"0"},{"side":"bid","event_time":"2026-07-15T03:40:08.095695Z","price_level":"64490.01","new_quantity":"0"},{"side":"bid","event_time":"2026-07-15T03:40:08.095695Z","price_level":"64490","new_quantity":"0"},{"side":"bid","event_time":"2026-07-15T03:40:08.095695Z","price_level":"64489.27","new_quantity":"2.07213027"},{"side":"bid","event_time":"2026-07-15T03:40:08.095695Z","price_level":"64488.15","new_quantity":"0"},{"side":"bid","event_time":"2026-07-15T03:40:08.095695Z","price_level":"64401.86","new_quantity":"0.04831322"},{"side":"bid","event_time":"2026-07-15T03:40:08.095695Z","price_level":"51654.81","new_quantity":"0.0002"},{"side":"offer","event_time":"2026-07-15T03:40:08.095695Z","price_level":"64576.19","new_quantity":"0"},{"side":"offer","event_time":"2026-07-15T03:40:08.095695Z","price_level":"64576.64","new_quantity":"0"},{"side":"offer","event_time":"2026-07-15T03:40:08.095695Z","price_level":"64578.37","new_quantity":"0"},{"side":"offer","event_time":"2026-07-15T03:40:08.095695Z","price_level":"64580","new_quantity":"0"},{"side":"offer","event_time":"2026-07-15T03:40:08.095695Z","price_level":"64581.99","new_quantity":"0"},{"side":"offer","event_time":"2026-07-15T03:40:08.095695Z","price_level":"64582","new_quantity":"0"},{"side":"offer","event_time":"2026-07-15T03:40:08.095695Z","price_level":"64582.15","new_quantity":"0"},{"side":"offer","event_time":"2026-07-15T03:40:08.095695Z","price_level":"64582.17","new_quantity":"0.00967816"},{"side":"offer","event_time":"2026-07-15T03:40:08.095695Z","price_level":"64583.65","new_quantity":"0"},{"side":"offer","event_time":"2026-07-15T03:40:08.095695Z","price_level":"64584","new_quantity":"0.000018"},{"side":"offer","event_time":"2026-07-15T03:40:08.095695Z","price_level":"64584.68","new_quantity":"0"},{"side":"offer","event_time":"2026-07-15T03:40:08.095695Z","price_level":"64584.69","new_quantity":"0"},{"side":"offer","event_time":"2026-07-15T03:40:08.095695Z","price_level":"64585.86","new_quantity":"0"},{"side":"offer","event_time":"2026-07-15T03:40:08.095695Z","price_level":"64586","new_quantity":"0.0232"},{"side":"offer","event_time":"2026-07-15T03:40:08.095695Z","price_level":"64587.42","new_quantity":"0"},{"side":"offer","event_time":"2026-07-15T03:40:08.095695Z","price_level":"64587.49","new_quantity":"0.00159977"},{"side":"offer","event_time":"2026-07-15T03:40:08.095695Z","price_level":"64587.5","new_quantity":"0"},{"side":"offer","event_time":"2026-07-15T03:40:08.095695Z","price_level":"64587.51","new_quantity":"0"},{"side":"offer","event_time":"2026-07-15T03:40:08.095695Z","price_level":"64587.52","new_quantity":"0"},{"side":"offer","event_time":"2026-07-15T03:40:08.095695Z","price_level":"64587.53","new_quantity":"0"},{"side":"offer","event_time":"2026-07-15T03:40:08.095695Z","price_level":"64587.55","new_quantity":"0"},{"side":"offer","event_time":"2026-07-15T03:40:08.095695Z","price_level":"64588.19","new_quantity":"0"},{"side":"offer","event_time":"2026-07-15T03:40:08.095695Z","price_level":"64588.34","new_quantity":"0"},{"side":"offer","event_time":"2026-07-15T03:40:08.095695Z","price_level":"64588.83","new_quantity":"0"},{"side":"offer","event_time":"2026-07-15T03:40:08.095695Z","price_level":"64590.24","new_quantity":"0.04646634"},{"side":"offer","event_time":"2026-07-15T03:40:08.095695Z","price_level":"64590.43","new_quantity":"0"},{"side":"offer","event_time":"2026-07-15T03:40:08.095695Z","price_level":"64590.51","new_quantity":"0"},{"side":"offer","event_time":"2026-07-15T03:40:08.095695Z","price_level":"64590.52","new_quantity":"0"},{"side":"offer","event_time":"2026-07-15T03:40:08.095695Z","price_level":"64591.12","new_quantity":"0"},{"side":"offer","event_time":"2026-07-15T03:40:08.095695Z","price_level":"64591.61","new_quantity":"0"},{"side":"offer","event_time":"2026-07-15T03:40:08.095695Z","price_level":"64592.17","new_quantity":"0"},{"side":"offer","event_time":"2026-07-15T03:40:08.095695Z","price_level":"64592.65","new_quantity":"0"},{"side":"offer","event_time":"2026-07-15T03:40:08.095695Z","price_level":"64592.78","new_quantity":"0"},{"side":"offer","event_time":"2026-07-15T03:40:08.095695Z","price_level":"64593.54","new_quantity":"0"},{"side":"offer","event_time":"2026-07-15T03:40:08.095695Z","price_level":"64593.7","new_quantity":"0"},{"side":"offer","event_time":"2026-07-15T03:40:08.095695Z","price_level":"64593.94","new_quantity":"0"},{"side":"offer","event_time":"2026-07-15T03:40:08.095695Z","price_level":"64594.46","new_quantity":"0"},{"side":"offer","event_time":"2026-07-15T03:40:08.095695Z","price_level":"64594.47","new_quantity":"0"},{"side":"offer","event_time":"2026-07-15T03:40:08.095695Z","price_level":"64594.48","new_quantity":"0.03093532"},{"side":"offer","event_time":"2026-07-15T03:40:08.095695Z","price_level":"64595.16","new_quantity":"0.0483189"},{"side":"offer","event_time":"2026-07-15T03:40:08.095695Z","price_level":"64595.91","new_quantity":"0"},{"side":"offer","event_time":"2026-07-15T03:40:08.095695Z","price_level":"64596.82","new_quantity":"0"},{"side":"offer","event_time":"2026-07-15T03:40:08.095695Z","price_level":"64598.17","new_quantity":"0.03219451"},{"side":"offer","event_time":"2026-07-15T03:40:08.095695Z","price_level":"64598.18","new_quantity":"0.021982"},{"side":"offer","event_time":"2026-07-15T03:40:08.095695Z","price_level":"64599.31","new_quantity":"0"},{"side":"offer","event_time":"2026-07-15T03:40:08.095695Z","price_level":"64599.81","new_quantity":"0.03093532"},{"side":"offer","event_time":"2026-07-15T03:40:08.095695Z","price_level":"64599.89","new_quantity":"0.0009866"},{"side":"offer","event_time":"2026-07-15T03:40:08.095695Z","price_level":"64600.21","new_quantity":"0.17561538"},{"side":"offer","event_time":"2026-07-15T03:40:08.095695Z","price_level":"64600.22","new_quantity":"0.12378505"},{"side":"offer","event_time":"2026-07-15T03:40:08.095695Z","price_level":"64601.02","new_quantity":"0"},{"side":"offer","event_time":"2026-07-15T03:40:08.095695Z","price_level":"64602.53","new_quantity":"0"},{"side":"offer","event_time":"2026-07-15T03:40:08.095695Z","price_level":"64603.26","new_quantity":"0.12496227"},{"side":"offer","event_time":"2026-07-15T03:40:08.095695Z","price_level":"64604.16","new_quantity":"0.179558"},{"side":"offer","event_time":"2026-07-15T03:40:08.095695Z","price_level":"64605","new_quantity":"0"},{"side":"offer","event_time":"2026-07-15T03:40:08.095695Z","price_level":"64605.03","new_quantity":"0"},{"side":"offer","event_time":"2026-07-15T03:40:08.095695Z","price_level":"64607.06","new_quantity":"0.11598601"},{"side":"offer","event_time":"2026-07-15T03:40:08.095695Z","price_level":"64607.14","new_quantity":"0"},{"side":"offer","event_time":"2026-07-15T03:40:08.095695Z","price_level":"64607.17","new_quantity":"0"},{"side":"offer","event_time":"2026-07-15T03:40:08.095695Z","price_level":"64609.33","new_quantity":"0"},{"side":"offer","event_time":"2026-07-15T03:40:08.095695Z","price_level":"64609.34","new_quantity":"0"},{"side":"offer","event_time":"2026-07-15T03:40:08.095695Z","price_level":"64609.38","new_quantity":"0"},{"side":"offer","event_time":"2026-07-15T03:40:08.095695Z","price_level":"64609.58","new_quantity":"0.00077425"},{"side":"offer","event_time":"2026-07-15T03:40:08.095695Z","price_level":"64609.73","new_quantity":"0.46252648"},{"side":"offer","event_time":"2026-07-15T03:40:08.095695Z","price_level":"64610.93","new_quantity":"0.03093532"},{"side":"offer","event_time":"2026-07-15T03:40:08.095695Z","price_level":"64610.94","new_quantity":"0.62922643"},{"side":"offer","event_time":"2026-07-15T03:40:08.095695Z","price_level":"64613.28","new_quantity":"0"},{"side":"offer","event_time":"2026-07-15T03:40:08.095695Z","price_level":"64615.01","new_quantity":"0.00077415"},{"side":"offer","event_time":"2026-07-15T03:40:08.095695Z","price_level":"64615.02","new_quantity":"0"},{"side":"offer","event_time":"2026-07-15T03:40:08.095695Z","price_level":"64616.4","new_quantity":"0.09001901"},{"side":"offer","event_time":"2026-07-15T03:40:08.095695Z","price_level":"64618.71","new_quantity":"0.12378505"},{"side":"offer","event_time":"2026-07-15T03:40:08.095695Z","price_level":"64619.48","new_quantity":"0.10008878"},{"side":"offer","event_time":"2026-07-15T03:40:08.095695Z","price_level":"64619.49","new_quantity":"0"},{"side":"offer","event_time":"2026-07-15T03:40:08.095695Z","price_level":"64621.67","new_quantity":"0"},{"side":"offer","event_time":"2026-07-15T03:40:08.095695Z","price_level":"64622.59","new_quantity":"0.12378505"},{"side":"offer","event_time":"2026-07-15T03:40:08.095695Z","price_level":"64622.66","new_quantity":"0.00104524"},{"side":"offer","event_time":"2026-07-15T03:40:08.095695Z","price_level":"64622.99","new_quantity":"0"},{"side":"offer","event_time":"2026-07-15T03:40:08.095695Z","price_level":"64623.02","new_quantity":"0"},{"side":"offer","event_time":"2026-07-15T03:40:08.095695Z","price_level":"64624.04","new_quantity":"0"},{"side":"offer","event_time":"2026-07-15T03:40:08.095695Z","price_level":"64626.2","new_quantity":"0.00077417"},{"side":"offer","event_time":"2026-07-15T03:40:08.095695Z","price_level":"64626.21","new_quantity":"0"},{"side":"offer","event_time":"2026-07-15T03:40:08.095695Z","price_level":"64629.4","new_quantity":"0"},{"side":"offer","event_time":"2026-07-15T03:40:08.095695Z","price_level":"64630.49","new_quantity":"0.59795847"},{"side":"offer","event_time":"2026-07-15T03:40:08.095695Z","price_level":"64630.5","new_quantity":"1"},{"side":"offer","event_time":"2026-07-15T03:40:08.095695Z","price_level":"64633.24","new_quantity":"1.13109759"},{"side":"offer","event_time":"2026-07-15T03:40:08.095695Z","price_level":"64633.26","new_quantity":"0"},{"side":"offer","event_time":"2026-07-15T03:40:08.095695Z","price_level":"64633.29","new_quantity":"0"},{"side":"offer","event_time":"2026-07-15T03:40:08.095695Z","price_level":"64634.69","new_quantity":"0"},{"side":"offer","event_time":"2026-07-15T03:40:08.095695Z","price_level":"64634.76","new_quantity":"0"},{"side":"offer","event_time":"2026-07-15T03:40:08.095695Z","price_level":"64635.53","new_quantity":"0.01615943"},{"side":"offer","event_time":"2026-07-15T03:40:08.095695Z","price_level":"64635.63","new_quantity":"1.97427445"},{"side":"offer","event_time":"2026-07-15T03:40:08.095695Z","price_level":"64636.29","new_quantity":"0"},{"side":"offer","event_time":"2026-07-15T03:40:08.095695Z","price_level":"64637.18","new_quantity":"0.00077411"},{"side":"offer","event_time":"2026-07-15T03:40:08.095695Z","price_level":"64638.44","new_quantity":"2.08953196"},{"side":"offer","event_time":"2026-07-15T03:40:08.095695Z","price_level":"64638.77","new_quantity":"0.1977574"},{"side":"offer","event_time":"2026-07-15T03:40:08.095695Z","price_level":"64639.09","new_quantity":"0.26330924"},{"side":"offer","event_time":"2026-07-15T03:40:08.095695Z","price_level":"64641.19","new_quantity":"0"},{"side":"offer","event_time":"2026-07-15T03:40:08.095695Z","price_level":"64660.32","new_quantity":"0"},{"side":"offer","event_time":"2026-07-15T03:40:08.095695Z","price_level":"64664.94","new_quantity":"7.11195744"},{"side":"offer","event_time":"2026-07-15T03:40:08.095695Z","price_level":"64682.26","new_quantity":"0.00348413"},{"side":"offer","event_time":"2026-07-15T03:40:08.095695Z","price_level":"64862.58","new_quantity":"1.38754889"},{"side":"offer","event_time":"2026-07-15T03:40:08.095695Z","price_level":"64980.32","new_quantity":"0"}]}]}
{"channel":"l2_data","timestamp":"2026-07-15T03:40:08.18275103Z","sequence_num":108,"events":[{"type":"update","product_id":"BTC-USD","updates":[{"side":"bid","event_time":"2026-07-15T03:40:08.138632Z","price_level":"64579.5","new_quantity":"1"},{"side":"bid","event_time":"2026-07-15T03:40:08.138632Z","price_level":"64570.51","new_quantity":"0.21523711"},{"side":"bid","event_time":"2026-07-15T03:40:08.138632Z","price_level":"64568.02","new_quantity":"0.00772597"},{"side":"bid","event_time":"2026-07-15T03:40:08.138632Z","price_level":"64562.91","new_quantity":"0.00583"},{"side":"bid","event_time":"2026-07-15T03:40:08.138632Z","price_level":"64562.42","new_quantity":"0"},{"side":"bid","event_time":"2026-07-15T03:40:08.138632Z","price_level":"64557.03","new_quantity":"0.44433742"},{"side":"bid","event_time":"2026-07-15T03:40:08.138632Z","price_level":"64555.37","new_quantity":"0.572771"},{"side":"bid","event_time":"2026-07-15T03:40:08.138632Z","price_level":"64544.38","new_quantity":"0.94717374"},{"side":"bid","event_time":"2026-07-15T03:40:08.138632Z","price_level":"64544.37","new_quantity":"0.93174918"},{"side":"bid","event_time":"2026-07-15T03:40:08.138632Z","price_level":"64544.36","new_quantity":"0"},{"side":"bid","event_time":"2026-07-15T03:40:08.138632Z","price_level":"64544.35","new_quantity":"0"},{"side":"bid","event_time":"2026-07-15T03:40:08.138632Z","price_level":"64543.01","new_quantity":"0.64087463"},{"side":"bid","event_time":"2026-07-15T03:40:08.138632Z","price_level":"64542.1","new_quantity":"0.00154715"},{"side":"bid","event_time":"2026-07-15T03:40:08.138632Z","price_level":"64536.54","new_quantity":"0"},{"side":"bid","event_time":"2026-07-15T03:40:08.138632Z","price_level":"64536.53","new_quantity":"0"},{"side":"bid","event_time":"2026-07-15T03:40:08.138632Z","price_level":"64536.47","new_quantity":"0.05855227"},{"side":"bid","event_time":"2026-07-15T03:40:08.138632Z","price_level":"64535.65","new_quantity":"0.00773577"},{"side":"bid","event_time":"2026-07-15T03:40:08.138632Z","price_level":"64534.2","new_quantity":"0"},{"side":"bid","event_time":"2026-07-15T03:40:08.138632Z","price_level":"64519.16","new_quantity":"0.00598614"},{"side":"bid","event_time":"2026-07-15T03:40:08.138632Z","price_level":"64512.55","new_quantity":"1.1282949"},{"side":"bid","event_time":"2026-07-15T03:40:08.138632Z","price_level":"64512.54","new_quantity":"1.40054838"},{"side":"bid","event_time":"2026-07-15T03:40:08.138632Z","price_level":"64512.53","new_quantity":"0"},{"side":"bid","event_time":"2026-07-15T03:40:08.138632Z","price_level":"64510.01","new_quantity":"0"},{"side":"bid","event_time":"2026-07-15T03:40:08.138632Z","price_level":"64502.56","new_quantity":"2.57530024"},{"side":"bid","event_time":"2026-07-15T03:40:08.138632Z","price_level":"64502.31","new_quantity":"0"},{"side":"bid","event_time":"2026-07-15T03:40:08.138632Z","price_level":"64500","new_quantity":"3.11110077"},{"side":"bid","event_time":"2026-07-15T03:40:08.138632Z","price_level":"64489.29","new_quantity":"2.07210876"},{"side":"bid","event_time":"2026-07-15T03:40:08.138632Z","price_level":"64489.28","new_quantity":"2.07528794"},{"side":"bid","event_time":"2026-07-15T03:40:08.138632Z","price_level":"64489.27","new_quantity":"0"},{"side":"bid","event_time":"2026-07-15T03:40:08.138632Z","price_level":"64488.16","new_quantity":"0"},{"side":"bid","event_time":"2026-07-15T03:40:08.138632Z","price_level":"64471.5","new_quantity":"0"},{"side":"bid","event_time":"2026-07-15T03:40:08.138632Z","price_level":"63276.33","new_quantity":"0.00583"},{"side":"offer","event_time":"2026-07-15T03:40:08.138632Z","price_level":"64584","new_quantity":"0.023218"},{"side":"offer","event_time":"2026-07-15T03:40:08.138632Z","price_level":"64590.24","new_quantity":"0"},{"side":"offer","event_time":"2026-07-15T03:40:08.138632Z","price_level":"64590.85","new_quantity":"0.09854221"},{"side":"offer","event_time":"2026-07-15T03:40:08.138632Z","price_level":"64590.86","new_quantity":"0.04646634"},{"side":"offer","event_time":"2026-07-15T03:40:08.138632Z","price_level":"64591.82","new_quantity":"0"},{"side":"offer","event_time":"2026-07-15T03:40:08.138632Z","price_level":"64593.03","new_quantity":"0.12385237"},{"side":"offer","event_time":"2026-07-15T03:40:08.138632Z","price_level":"64594.47","new_quantity":"0.00772597"},{"side":"offer","event_time":"2026-07-15T03:40:08.138632Z","price_level":"64594.77","new_quantity":"0.12378505"},{"side":"offer","event_time":"2026-07-15T03:40:08.138632Z","price_level":"64597.43","new_quantity":"0.28032938"},{"side":"offer","event_time":"2026-07-15T03:40:08.138632Z","price_level":"64597.44","new_quantity":"0.1548049"},{"side":"offer","event_time":"2026-07-15T03:40:08.138632Z","price_level":"64597.77","new_quantity":"0.179558"},{"side":"offer","event_time":"2026-07-15T03:40:08.138632Z","price_level":"64597.78","new_quantity":"0.12378505"},{"side":"offer","event_time":"2026-07-15T03:40:08.138632Z","price_level":"64598.17","new_quantity":"0"},{"side":"offer","event_time":"2026-07-15T03:40:08.138632Z","price_level":"64600.19","new_quantity":"0.17561538"},{"side":"offer","event_time":"2026-07-15T03:40:08.138632Z","price_level":"64600.2","new_quantity":"0"},{"side":"offer","event_time":"2026-07-15T03:40:08.138632Z","price_level":"64600.21","new_quantity":"0"},{"side":"offer","event_time":"2026-07-15T03:40:08.138632Z","price_level":"64603.26","new_quantity":"0.02037046"},{"side":"offer","event_time":"2026-07-15T03:40:08.138632Z","price_level":"64604.16","new_quantity":"0"},{"side":"offer","event_time":"2026-07-15T03:40:08.138632Z","price_level":"64604.17","new_quantity":"0"},{"side":"offer","event_time":"2026-07-15T03:40:08.138632Z","price_level":"64606.15","new_quantity":"0.00153313"},{"side":"offer","event_time":"2026-07-15T03:40:08.138632Z","price_level":"64606.19","new_quantity":"0.00583"},{"side":"offer","event_time":"2026-07-15T03:40:08.138632Z","price_level":"64618.5","new_quantity":"0.00306626"},{"side":"offer","event_time":"2026-07-15T03:40:08.138632Z","price_level":"64620.04","new_quantity":"0"},{"side":"offer","event_time":"2026-07-15T03:40:08.138632Z","price_level":"64630.49","new_quantity":"0"},{"side":"offer","event_time":"2026-07-15T03:40:08.138632Z","price_level":"64630.5","new_quantity":"0"},{"side":"offer","event_time":"2026-07-15T03:40:08.138632Z","price_level":"64633.22","new_quantity":"1.14028309"},{"side":"offer","event_time":"2026-07-15T03:40:08.138632Z","price_level":"64633.23","new_quantity":"1.41901407"},{"side":"offer","event_time":"2026-07-15T03:40:08.138632Z","price_level":"64633.24","new_quantity":"0"},{"side":"offer","event_time":"2026-07-15T03:40:08.138632Z","price_level":"64633.27","new_quantity":"0"},{"side":"offer","event_time":"2026-07-15T03:40:08.138632Z","price_level":"64634.38","new_quantity":"0.00383282"},{"side":"offer","event_time":"2026-07-15T03:40:08.138632Z","price_level":"64652.09","new_quantity":"0"},{"side":"offer","event_time":"2026-07-15T03:40:08.138632Z","price_level":"64665.21","new_quantity":"0"},{"side":"offer","event_time":"2026-07-15T03:40:08.138632Z","price_level":"64680","new_quantity":"0"},{"side":"offer","event_time":"2026-07-15T03:40:08.138632Z","price_level":"65249.48","new_quantity":"0.00583"},{"side":"offer","event_time":"2026-07-15T03:40:08.138632Z","price_level":"65892.77","new_quantity":"0.00583"}]}]}
{"channel":"market_trades","timestamp":"2026-07-15T03:40:08.186107801Z","sequence_num":109,"events":[{"type":"update","trades":[{"product_id":"BTC-USD","trade_id":"1056309438","price":"64578.37","size":"0.00967","time":"2026-07-15T03:40:08.05619Z","side":"SELL"},{"product_id":"BTC-USD","trade_id":"1056309437","price":"64576.64","size":"0.000018","time":"2026-07-15T03:40:08.05301Z","side":"SELL"},{"product_id":"BTC-USD","trade_id":"1056309436","price":"64576.19","size":"0.00774308","time":"2026-07-15T03:40:08.05301Z","side":"SELL"}]}]}
{"channel":"l2_data","timestamp":"2026-07-15T03:40:08.231674253Z","sequence_num":110,"events":[{"type":"update","product_id":"BTC-USD","updates":[{"side":"bid","event_time":"2026-07-15T03:40:08.181489Z","price_level":"64563.32","new_quantity":"0.00583"},{"side":"bid","event_time":"2026-07-15T03:40:08.181489Z","price_level":"64562.91","new_quantity":"0"},{"side":"bid","event_time":"2026-07-15T03:40:08.181489Z","price_level":"64557.03","new_quantity":"0.14765884"},{"side":"bid","event_time":"2026-07-15T03:40:08.181489Z","price_level":"64555.37","new_quantity":"0"},{"side":"bid","event_time":"2026-07-15T03:40:08.181489Z","price_level":"64553.39","new_quantity":"0"},{"side":"bid","event_time":"2026-07-15T03:40:08.181489Z","price_level":"64348.59","new_quantity":"0.00583"},{"side":"bid","event_time":"2026-07-15T03:40:08.181489Z","price_level":"64336.78","new_quantity":"0"},{"side":"bid","event_time":"2026-07-15T03:40:08.181489Z","price_level":"63276.74","new_quantity":"0"},{"side":"bid","event_time":"2026-07-15T03:40:08.181489Z","price_level":"63276.33","new_quantity":"0"},{"side":"bid","event_time":"2026-07-15T03:40:08.181489Z","price_level":"63276.32","new_quantity":"0.00583"},{"side":"bid","event_time":"2026-07-15T03:40:08.181489Z","price_level":"63266.12","new_quantity":"0"},{"side":"bid","event_time":"2026-07-15T03:40:08.181489Z","price_level":"63062.31","new_quantity":"0"},{"side":"offer","event_time":"2026-07-15T03:40:08.181489Z","price_level":"64590.85","new_quantity":"0.2290877"},{"side":"offer","event_time":"2026-07-15T03:40:08.181489Z","price_level":"64590.86","new_quantity":"0"},{"side":"offer","event_time":"2026-07-15T03:40:08.181489Z","price_level":"64591.63","new_quantity":"0.12378505"},{"side":"offer","event_time":"2026-07-15T03:40:08.181489Z","price_level":"64591.64","new_quantity":"0.12385504"},{"side":"offer","event_time":"2026-07-15T03:40:08.181489Z","price_level":"64597.39","new_quantity":"0.21329031"},{"side":"offer","event_time":"2026-07-15T03:40:08.181489Z","price_level":"64597.4","new_quantity":"0.179558"},{"side":"offer","event_time":"2026-07-15T03:40:08.181489Z","price_level":"64597.41","new_quantity":"0"},{"side":"offer","event_time":"2026-07-15T03:40:08.181489Z","price_level":"64597.42","new_quantity":"0"},{"side":"offer","event_time":"2026-07-15T03:40:08.181489Z","price_level":"64597.43","new_quantity":"0"},{"side":"offer","event_time":"2026-07-15T03:40:08.181489Z","price_level":"64597.44","new_quantity":"0"},{"side":"offer","event_time":"2026-07-15T03:40:08.181489Z","price_level":"64597.77","new_quantity":"0"},{"side":"offer","event_time":"2026-07-15T03:40:08.181489Z","price_level":"64606.09","new_quantity":"0.00583"},{"side":"offer","event_time":"2026-07-15T03:40:08.181489Z","price_level":"64606.19","new_quantity":"0"},{"side":"offer","event_time":"2026-07-15T03:40:08.181489Z","price_level":"64608.14","new_quantity":"0.02"},{"side":"offer","event_time":"2026-07-15T03:40:08.181489Z","price_level":"64609.73","new_quantity":"0"},{"side":"offer","event_time":"2026-07-15T03:40:08.181489Z","price_level":"64610","new_quantity":"0.11760907"},{"side":"offer","event_time":"2026-07-15T03:40:08.181489Z","price_level":"64610.34","new_quantity":"0.04"},{"side":"offer","event_time":"2026-07-15T03:40:08.181489Z","price_level":"64610.94","new_quantity":"0"},{"side":"offer","event_time":"2026-07-15T03:40:08.181489Z","price_level":"64613.27","new_quantity":"1.01939734"},{"side":"offer","event_time":"2026-07-15T03:40:08.181489Z","price_level":"64613.28","new_quantity":"0.62920364"},{"side":"offer","event_time":"2026-07-15T03:40:08.181489Z","price_level":"64613.29","new_quantity":"0"},{"side":"offer","event_time":"2026-07-15T03:40:08.181489Z","price_level":"64614","new_quantity":"1"},{"side":"offer","event_time":"2026-07-15T03:40:08.181489Z","price_level":"64666.34","new_quantity":"0.00766564"},{"side":"offer","event_time":"2026-07-15T03:40:08.181489Z","price_level":"64700","new_quantity":"3.00394126"},{"side":"offer","event_time":"2026-07-15T03:40:08.181489Z","price_level":"64807.93","new_quantity":"0"},{"side":"offer","event_time":"2026-07-15T03:40:08.181489Z","price_level":"64820.6","new_quantity":"0.00583"},{"side":"offer","event_time":"2026-07-15T03:40:08.181489Z","price_level":"64820.66","new_quantity":"0.00583"},{"side":"offer","event_time":"2026-07-15T03:40:08.181489Z","price_level":"65022.81","new_quantity":"0"},{"side":"offer","event_time":"2026-07-15T03:40:08.181489Z","price_level":"65249.38","new_quantity":"0.00583"},{"side":"offer","event_time":"2026-07-15T03:40:08.181489Z","price_level":"65249.48","new_quantity":"0"},{"side":"offer","event_time":"2026-07-15T03:40:08.181489Z","price_level":"65439.54","new_quantity":"0"},{"side":"offer","event_time":"2026-07-15T03:40:08.181489Z","price_level":"65463.89","new_quantity":"0.00583"},{"side":"offer","event_time":"2026-07-15T03:40:08.181489Z","price_level":"65463.95","new_quantity":"0.00583"},{"side":"offer","event_time":"2026-07-15T03:40:08.181489Z","price_level":"65665.03","new_quantity":"0"},{"side":"offer","event_time":"2026-07-15T03:40:08.181489Z","price_level":"65892.77","new_quantity":"0"}]}]}
{"channel":"l2_data","timestamp":"2026-07-15T03:40:08.283913697Z","sequence_num":111,"events":[{"type":"update","product_id":"BTC-USD","updates":[{"side":"bid","event_time":"2026-07-15T03:40:08.231557Z","price_level":"64580.31","new_quantity":"0.28742939"},{"side":"bid","event_time":"2026-07-15T03:40:08.231557Z","price_level":"64578.36","new_quantity":"0.0015533"},{"side":"bid","event_time":"2026-07-15T03:40:08.231557Z","price_level":"64575.17","new_quantity":"0.0015533"},{"side":"bid","event_time":"2026-07-15T03:40:08.231557Z","price_level":"64571.98","new_quantity":"0.0015533"},{"side":"bid","event_time":"2026-07-15T03:40:08.231557Z","price_level":"64568.79","new_quantity":"0.0015533"},{"side":"bid","event_time":"2026-07-15T03:40:08.231557Z","price_level":"64561.05","new_quantity":"0.27665752"},{"side":"bid","event_time":"2026-07-15T03:40:08.231557Z","price_level":"64559.18","new_quantity":"0.14"},{"side":"bid","event_time":"2026-07-15T03:40:08.231557Z","price_level":"64549.66","new_quantity":"0.00077412"},{"side":"bid","event_time":"2026-07-15T03:40:08.231557Z","price_level":"64544.4","new_quantity":"1.03092504"},{"side":"bid","event_time":"2026-07-15T03:40:08.231557Z","price_level":"64544.39","new_quantity":"0.93174889"},{"side":"bid","event_time":"2026-07-15T03:40:08.231557Z","price_level":"64544.38","new_quantity":"0"},{"side":"bid","event_time":"2026-07-15T03:40:08.231557Z","price_level":"64544.37","new_quantity":"0"},{"side":"bid","event_time":"2026-07-15T03:40:08.231557Z","price_level":"64543.19","new_quantity":"0.06692004"},{"side":"bid","event_time":"2026-07-15T03:40:08.231557Z","price_level":"64543.01","new_quantity":"0.6401004"},{"side":"bid","event_time":"2026-07-15T03:40:08.231557Z","price_level":"64514.56","new_quantity":"0"},{"side":"bid","event_time":"2026-07-15T03:40:08.231557Z","price_level":"64512.57","new_quantity":"1.12829463"},{"side":"bid","event_time":"2026-07-15T03:40:08.231557Z","price_level":"64512.56","new_quantity":"1.40054794"},{"side":"bid","event_time":"2026-07-15T03:40:08.231557Z","price_level":"64512.55","new_quantity":"0"},{"side":"bid","event_time":"2026-07-15T03:40:08.231557Z","price_level":"64512.54","new_quantity":"0"},{"side":"bid","event_time":"2026-07-15T03:40:08.231557Z","price_level":"64489.3","new_quantity":"2.0752873"},{"side":"bid","event_time":"2026-07-15T03:40:08.231557Z","price_level":"64489.29","new_quantity":"0"},{"side":"bid","event_time":"2026-07-15T03:40:08.231557Z","price_level":"64489.28","new_quantity":"0"},{"side":"bid","event_time":"2026-07-15T03:40:08.231557Z","price_level":"64348.86","new_quantity":"0.00583"},{"side":"bid","event_time":"2026-07-15T03:40:08.231557Z","price_level":"64348.59","new_quantity":"0"},{"side":"bid","event_time":"2026-07-15T03:40:08.231557Z","price_level":"64134.04","new_quantity":"0.00583"},{"side":"bid","event_time":"2026-07-15T03:40:08.231557Z","price_level":"64104.25","new_quantity":"0"},{"side":"bid","event_time":"2026-07-15T03:40:08.231557Z","price_level":"63919.43","new_quantity":"0.00583"},{"side":"bid","event_time":"2026-07-15T03:40:08.231557Z","price_level":"63276.71","new_quantity":"0.00583"},{"side":"bid","event_time":"2026-07-15T03:40:08.231557Z","price_level":"63276.32","new_quantity":"0"},{"side":"offer","event_time":"2026-07-15T03:40:08.231557Z","price_level":"64584.74","new_quantity":"0.0015533"},{"side":"offer","event_time":"2026-07-15T03:40:08.231557Z","price_level":"64587.49","new_quantity":"0"},{"side":"offer","event_time":"2026-07-15T03:40:08.231557Z","price_level":"64587.93","new_quantity":"0.0015533"},{"side":"offer","event_time":"2026-07-15T03:40:08.231557Z","price_level":"64590.14","new_quantity":"0.00159977"},{"side":"offer","event_time":"2026-07-15T03:40:08.231557Z","price_level":"64590.15","new_quantity":"0.0277404"},{"side":"offer","event_time":"2026-07-15T03:40:08.231557Z","price_level":"64590.16","new_quantity":"0.04646634"},{"side":"offer","event_time":"2026-07-15T03:40:08.231557Z","price_level":"64591.12","new_quantity":"0.0015533"},{"side":"offer","event_time":"2026-07-15T03:40:08.231557Z","price_level":"64594.3","new_quantity":"0.00772597"},{"side":"offer","event_time":"2026-07-15T03:40:08.231557Z","price_level":"64594.31","new_quantity":"0.0015533"},{"side":"offer","event_time":"2026-07-15T03:40:08.231557Z","price_level":"64594.47","new_quantity":"0"},{"side":"offer","event_time":"2026-07-15T03:40:08.231557Z","price_level":"64596.21","new_quantity":"0.179558"},{"side":"offer","event_time":"2026-07-15T03:40:08.231557Z","price_level":"64597.39","new_quantity":"0.1070215"},{"side":"offer","event_time":"2026-07-15T03:40:08.231557Z","price_level":"64597.4","new_quantity":"0"},{"side":"offer","event_time":"2026-07-15T03:40:08.231557Z","price_level":"64597.5","new_quantity":"0.0015533"},{"side":"offer","event_time":"2026-07-15T03:40:08.231557Z","price_level":"64599.8","new_quantity":"0.0009866"},{"side":"offer","event_time":"2026-07-15T03:40:08.231557Z","price_level":"64599.89","new_quantity":"0"},{"side":"offer","event_time":"2026-07-15T03:40:08.231557Z","price_level":"64600.69","new_quantity":"0.0015533"},{"side":"offer","event_time":"2026-07-15T03:40:08.231557Z","price_level":"64603.88","new_quantity":"0.0015533"},{"side":"offer","event_time":"2026-07-15T03:40:08.231557Z","price_level":"64605.98","new_quantity":"0.00583"},{"side":"offer","event_time":"2026-07-15T03:40:08.231557Z","price_level":"64606","new_quantity":"0.00583"},{"side":"offer","event_time":"2026-07-15T03:40:08.231557Z","price_level":"64606.09","new_quantity":"0"},{"side":"offer","event_time":"2026-07-15T03:40:08.231557Z","price_level":"64607.07","new_quantity":"0.12533835"},{"side":"offer","event_time":"2026-07-15T03:40:08.231557Z","price_level":"64608.14","new_quantity":"0"},{"side":"offer","event_time":"2026-07-15T03:40:08.231557Z","price_level":"64608.16","new_quantity":"0.05660353"},{"side":"offer","event_time":"2026-07-15T03:40:08.231557Z","price_level":"64609.43","new_quantity":"0.02"},{"side":"offer","event_time":"2026-07-15T03:40:08.231557Z","price_level":"64610","new_quantity":"0.1751403"},{"side":"offer","event_time":"2026-07-15T03:40:08.231557Z","price_level":"64610.03","new_quantity":"0.12"},{"side":"offer","event_time":"2026-07-15T03:40:08.231557Z","price_level":"64610.26","new_quantity":"0.0015533"},{"side":"offer","event_time":"2026-07-15T03:40:08.231557Z","price_level":"64610.34","new_quantity":"0"},{"side":"offer","event_time":"2026-07-15T03:40:08.231557Z","price_level":"64613.27","new_quantity":"0.48431621"},{"side":"offer","event_time":"2026-07-15T03:40:08.231557Z","price_level":"64613.45","new_quantity":"0.0015533"},{"side":"offer","event_time":"2026-07-15T03:40:08.231557Z","price_level":"64613.92","new_quantity":"0.06795673"},{"side":"offer","event_time":"2026-07-15T03:40:08.231557Z","price_level":"64614","new_quantity":"0"},{"side":"offer","event_time":"2026-07-15T03:40:08.231557Z","price_level":"64615.01","new_quantity":"0"},{"side":"offer","event_time":"2026-07-15T03:40:08.231557Z","price_level":"64616.64","new_quantity":"0.0015533"},{"side":"offer","event_time":"2026-07-15T03:40:08.231557Z","price_level":"64619.83","new_quantity":"0.0015533"},{"side":"offer","event_time":"2026-07-15T03:40:08.231557Z","price_level":"64620.03","new_quantity":"0.00077408"},{"side":"offer","event_time":"2026-07-15T03:40:08.231557Z","price_level":"64623.02","new_quantity":"0.0015533"},{"side":"offer","event_time":"2026-07-15T03:40:08.231557Z","price_level":"64626.21","new_quantity":"0.0015533"},{"side":"offer","event_time":"2026-07-15T03:40:08.231557Z","price_level":"64629.4","new_quantity":"0.0015533"},{"side":"offer","event_time":"2026-07-15T03:40:08.231557Z","price_level":"64633.2","new_quantity":"1.14257154"},{"side":"offer","event_time":"2026-07-15T03:40:08.231557Z","price_level":"64633.21","new_quantity":"1.41901451"},{"side":"offer","event_time":"2026-07-15T03:40:08.231557Z","price_level":"64633.22","new_quantity":"0"},{"side":"offer","event_time":"2026-07-15T03:40:08.231557Z","price_level":"64633.23","new_quantity":"0"},{"side":"offer","event_time":"2026-07-15T03:40:08.231557Z","price_level":"64635.78","new_quantity":"0.0015533"},{"side":"offer","event_time":"2026-07-15T03:40:08.231557Z","price_level":"64637.18","new_quantity":"0"},{"side":"offer","event_time":"2026-07-15T03:40:08.231557Z","price_level":"64638.97","new_quantity":"0.0015533"},{"side":"offer","event_time":"2026-07-15T03:40:08.231557Z","price_level":"64642.16","new_quantity":"0.0015533"},{"side":"offer","event_time":"2026-07-15T03:40:08.231557Z","price_level":"64645.35","new_quantity":"0.0015533"},{"side":"offer","event_time":"2026-07-15T03:40:08.231557Z","price_level":"64700","new_quantity":"0.00394126"},{"side":"offer","event_time":"2026-07-15T03:40:08.231557Z","price_level":"64820.66","new_quantity":"0"},{"side":"offer","event_time":"2026-07-15T03:40:08.231557Z","price_level":"65035.42","new_quantity":"0.00583"},{"side":"offer","event_time":"2026-07-15T03:40:08.231557Z","price_level":"65463.95","new_quantity":"0"}]}]}
{"channel":"l2_data","timestamp":"2026-07-15T03:40:08.332464041Z","sequence_num":112,"events":[{"type":"update","product_id":"BTC-USD","updates":[{"side":"bid","event_time":"2026-07-15T03:40:08.295177Z","price_level":"64578.36","new_quantity":"0.04104252"},{"side":"bid","event_time":"2026-07-15T03:40:08.295177Z","price_level":"64576.74","new_quantity":"0.00774253"},{"side":"bid","event_time":"2026-07-15T03:40:08.295177Z","price_level":"64575.57","new_quantity":"0.06"},{"side":"bid","event_time":"2026-07-15T03:40:08.295177Z","price_level":"64574.56","new_quantity":"0.00967816"},{"side":"bid","event_time":"2026-07-15T03:40:08.295177Z","price_level":"64568.51","new_quantity":"0.03356217"},{"side":"bid","event_time":"2026-07-15T03:40:08.295177Z","price_level":"64563.72","new_quantity":"0.00583"},{"side":"bid","event_time":"2026-07-15T03:40:08.295177Z","price_level":"64563.61","new_quantity":"0.00583"},{"side":"bid","event_time":"2026-07-15T03:40:08.295177Z","price_level":"64563.32","new_quantity":"0"},{"side":"bid","event_time":"2026-07-15T03:40:08.295177Z","price_level":"64512.52","new_quantity":"0.02423914"},{"side":"bid","event_time":"2026-07-15T03:40:08.295177Z","price_level":"64324.64","new_quantity":"0.01828179"},{"side":"bid","event_time":"2026-07-15T03:40:08.295177Z","price_level":"63889.28","new_quantity":"0"},{"side":"bid","event_time":"2026-07-15T03:40:08.295177Z","price_level":"63277.14","new_quantity":"0.00583"},{"side":"bid","event_time":"2026-07-15T03:40:08.295177Z","price_level":"63276.71","new_quantity":"0"},{"side":"offer","event_time":"2026-07-15T03:40:08.295177Z","price_level":"64582.17","new_quantity":"0"},{"side":"offer","event_time":"2026-07-15T03:40:08.295177Z","price_level":"64589.64","new_quantity":"0.07485474"},{"side":"offer","event_time":"2026-07-15T03:40:08.295177Z","price_level":"64589.65","new_quantity":"0.12378505"},{"side":"offer","event_time":"2026-07-15T03:40:08.295177Z","price_level":"64589.99","new_quantity":"0.04646634"},{"side":"offer","event_time":"2026-07-15T03:40:08.295177Z","price_level":"64590.15","new_quantity":"0"},{"side":"offer","event_time":"2026-07-15T03:40:08.295177Z","price_level":"64590.16","new_quantity":"0"},{"side":"offer","event_time":"2026-07-15T03:40:08.295177Z","price_level":"64593.02","new_quantity":"0.00772597"},{"side":"offer","event_time":"2026-07-15T03:40:08.295177Z","price_level":"64594.3","new_quantity":"0"},{"side":"offer","event_time":"2026-07-15T03:40:08.295177Z","price_level":"64596.21","new_quantity":"0.179558"},{"side":"offer","event_time":"2026-07-15T03:40:08.295177Z","price_level":"64599.72","new_quantity":"0.0009866"},{"side":"offer","event_time":"2026-07-15T03:40:08.295177Z","price_level":"64599.8","new_quantity":"0"},{"side":"offer","event_time":"2026-07-15T03:40:08.295177Z","price_level":"64606","new_quantity":"0"},{"side":"offer","event_time":"2026-07-15T03:40:08.295177Z","price_level":"64607.06","new_quantity":"0.71977933"},{"side":"offer","event_time":"2026-07-15T03:40:08.295177Z","price_level":"64609.5","new_quantity":"1"},{"side":"offer","event_time":"2026-07-15T03:40:08.295177Z","price_level":"64613.25","new_quantity":"0.48478149"},{"side":"offer","event_time":"2026-07-15T03:40:08.295177Z","price_level":"64613.26","new_quantity":"0.62920384"},{"side":"offer","event_time":"2026-07-15T03:40:08.295177Z","price_level":"64613.27","new_quantity":"0"},{"side":"offer","event_time":"2026-07-15T03:40:08.295177Z","price_level":"64613.28","new_quantity":"0"},{"side":"offer","event_time":"2026-07-15T03:40:08.295177Z","price_level":"64613.92","new_quantity":"0"},{"side":"offer","event_time":"2026-07-15T03:40:08.295177Z","price_level":"64619.48","new_quantity":"0.03055813"},{"side":"offer","event_time":"2026-07-15T03:40:08.295177Z","price_level":"64622.59","new_quantity":"0"},{"side":"offer","event_time":"2026-07-15T03:40:08.295177Z","price_level":"64626.2","new_quantity":"0"},{"side":"offer","event_time":"2026-07-15T03:40:08.295177Z","price_level":"64629.19","new_quantity":"0.00077412"},{"side":"offer","event_time":"2026-07-15T03:40:08.295177Z","price_level":"64641.44","new_quantity":"0.00077412"},{"side":"offer","event_time":"2026-07-15T03:40:08.295177Z","price_level":"64695","new_quantity":"3"},{"side":"offer","event_time":"2026-07-15T03:40:08.295177Z","price_level":"65679.03","new_quantity":"0.00583"}]}]}
{"channel":"l2_data","timestamp":"2026-07-15T03:40:08.381478795Z","sequence_num":113,"events":[{"type":"update","product_id":"BTC-USD","updates":[{"side":"bid","event_time":"2026-07-15T03:40:08.336041Z","price_level":"64568.51","new_quantity":"0.04206138"},{"side":"bid","event_time":"2026-07-15T03:40:08.336041Z","price_level":"64544.42","new_quantity":"1.07041392"},{"side":"bid","event_time":"2026-07-15T03:40:08.336041Z","price_level":"64544.41","new_quantity":"0.9317486"},{"side":"bid","event_time":"2026-07-15T03:40:08.336041Z","price_level":"64544.4","new_quantity":"0"},{"side":"bid","event_time":"2026-07-15T03:40:08.336041Z","price_level":"64544.39","new_quantity":"0"},{"side":"bid","event_time":"2026-07-15T03:40:08.336041Z","price_level":"64512.59","new_quantity":"1.14276514"},{"side":"bid","event_time":"2026-07-15T03:40:08.336041Z","price_level":"64512.58","new_quantity":"1.40054751"},{"side":"bid","event_time":"2026-07-15T03:40:08.336041Z","price_level":"64512.57","new_quantity":"0"},{"side":"bid","event_time":"2026-07-15T03:40:08.336041Z","price_level":"64512.56","new_quantity":"0"},{"side":"bid","event_time":"2026-07-15T03:40:08.336041Z","price_level":"64482.63","new_quantity":"0.04986502"},{"side":"bid","event_time":"2026-07-15T03:40:08.336041Z","price_level":"58122.29","new_quantity":"0"},{"side":"offer","event_time":"2026-07-15T03:40:08.336041Z","price_level":"64589.63","new_quantity":"0.00159977"},{"side":"offer","event_time":"2026-07-15T03:40:08.336041Z","price_level":"64590.14","new_quantity":"0"},{"side":"offer","event_time":"2026-07-15T03:40:08.336041Z","price_level":"64596.21","new_quantity":"0.179558"},{"side":"offer","event_time":"2026-07-15T03:40:08.336041Z","price_level":"64599.57","new_quantity":"0.0009866"},{"side":"offer","event_time":"2026-07-15T03:40:08.336041Z","price_level":"64599.64","new_quantity":"0"},{"side":"offer","event_time":"2026-07-15T03:40:08.336041Z","price_level":"64599.72","new_quantity":"0"},{"side":"offer","event_time":"2026-07-15T03:40:08.336041Z","price_level":"64607.06","new_quantity":"0.11598601"},{"side":"offer","event_time":"2026-07-15T03:40:08.336041Z","price_level":"64609.5","new_quantity":"0"},{"side":"offer","event_time":"2026-07-15T03:40:08.336041Z","price_level":"64620.03","new_quantity":"0"},{"side":"offer","event_time":"2026-07-15T03:40:08.336041Z","price_level":"64629.19","new_quantity":"0"},{"side":"offer","event_time":"2026-07-15T03:40:08.336041Z","price_level":"64633.18","new_quantity":"1.14257181"},{"side":"offer","event_time":"2026-07-15T03:40:08.336041Z","price_level":"64633.19","new_quantity":"1.41901495"},{"side":"offer","event_time":"2026-07-15T03:40:08.336041Z","price_level":"64633.2","new_quantity":"0"},{"side":"offer","event_time":"2026-07-15T03:40:08.336041Z","price_level":"64633.21","new_quantity":"0"},{"side":"offer","event_time":"2026-07-15T03:40:08.336041Z","price_level":"64676.38","new_quantity":"0.04799067"}]}]}
{"channel":"l2_data","timestamp":"2026-07-15T03:40:08.436477002Z","sequence_num":114,"events":[{"type":"update","product_id":"BTC-USD","updates":[{"side":"bid","event_time":"2026-07-15T03:40:08.394026Z","price_level":"64580.31","new_quantity":"0.33848926"},{"side":"bid","event_time":"2026-07-15T03:40:08.394026Z","price_level":"64569.28","new_quantity":"0.000018"},{"side":"bid","event_time":"2026-07-15T03:40:08.394026Z","price_level":"64563.61","new_quantity":"0"},{"side":"bid","event_time":"2026-07-15T03:40:08.394026Z","price_level":"64560.56","new_quantity":"0.033091"},{"side":"bid","event_time":"2026-07-15T03:40:08.394026Z","price_level":"64554.65","new_quantity":"0"},{"side":"bid","event_time":"2026-07-15T03:40:08.394026Z","price_level":"64554.64","new_quantity":"0"},{"side":"bid","event_time":"2026-07-15T03:40:08.394026Z","price_level":"64551.4","new_quantity":"0.04838031"},{"side":"bid","event_time":"2026-07-15T03:40:08.394026Z","price_level":"64548.32","new_quantity":"0"},{"side":"bid","event_time":"2026-07-15T03:40:08.394026Z","price_level":"56507.78","new_quantity":"0.0132912"},{"side":"bid","event_time":"2026-07-15T03:40:08.394026Z","price_level":"51654.81","new_quantity":"0"},{"side":"offer","event_time":"2026-07-15T03:40:08.394026Z","price_level":"64587.68","new_quantity":"0.000018"},{"side":"offer","event_time":"2026-07-15T03:40:08.394026Z","price_level":"64592.49","new_quantity":"0.00772597"},{"side":"offer","event_time":"2026-07-15T03:40:08.394026Z","price_level":"64593.02","new_quantity":"0"},{"side":"offer","event_time":"2026-07-15T03:40:08.394026Z","price_level":"64596.21","new_quantity":"0"},{"side":"offer","event_time":"2026-07-15T03:40:08.394026Z","price_level":"64599.48","new_quantity":"0.0009866"},{"side":"offer","event_time":"2026-07-15T03:40:08.394026Z","price_level":"64599.57","new_quantity":"0"},{"side":"offer","event_time":"2026-07-15T03:40:08.394026Z","price_level":"64610","new_quantity":"0.80060504"},{"side":"offer","event_time":"2026-07-15T03:40:08.394026Z","price_level":"64610.34","new_quantity":"0.02"},{"side":"offer","event_time":"2026-07-15T03:40:08.394026Z","price_level":"64611","new_quantity":"1"},{"side":"offer","event_time":"2026-07-15T03:40:08.394026Z","price_level":"64611.33","new_quantity":"0.62922263"},{"side":"offer","event_time":"2026-07-15T03:40:08.394026Z","price_level":"64611.34","new_quantity":"0.04"},{"side":"offer","event_time":"2026-07-15T03:40:08.394026Z","price_level":"64613.25","new_quantity":"0.10914679"},{"side":"offer","event_time":"2026-07-15T03:40:08.394026Z","price_level":"64613.26","new_quantity":"0"},{"side":"offer","event_time":"2026-07-15T03:40:08.394026Z","price_level":"64621.67","new_quantity":"0.00077409"},{"side":"offer","event_time":"2026-07-15T03:40:08.394026Z","price_level":"64631.48","new_quantity":"0.00077412"},{"side":"offer","event_time":"2026-07-15T03:40:08.394026Z","price_level":"64814.27","new_quantity":"0.01814622"}]}]}
{"channel":"l2_data","timestamp":"2026-07-15T03:40:08.484813568Z","sequence_num":115,"events":[{"type":"update","product_id":"BTC-USD","updates":[{"side":"bid","event_time":"2026-07-15T03:40:08.439209Z","price_level":"64580.32","new_quantity":"1.14057067"},{"side":"bid","event_time":"2026-07-15T03:40:08.439209Z","price_level":"64580.31","new_quantity":"0"},{"side":"bid","event_time":"2026-07-15T03:40:08.439209Z","price_level":"64579.51","new_quantity":"0.65382117"},{"side":"bid","event_time":"2026-07-15T03:40:08.439209Z","price_level":"64578.7","new_quantity":"0.00774229"},{"side":"bid","event_time":"2026-07-15T03:40:08.439209Z","price_level":"64578.36","new_quantity":"0.0015533"},{"side":"bid","event_time":"2026-07-15T03:40:08.439209Z","price_level":"64576.74","new_quantity":"0"},{"side":"bid","event_time":"2026-07-15T03:40:08.439209Z","price_level":"64576.64","new_quantity":"0.2642075"},{"side":"bid","event_time":"2026-07-15T03:40:08.439209Z","price_level":"64576.52","new_quantity":"0.00967787"},{"side":"bid","event_time":"2026-07-15T03:40:08.439209Z","price_level":"64576.19","new_quantity":"0.12388467"},{"side":"bid","event_time":"2026-07-15T03:40:08.439209Z","price_level":"64574.56","new_quantity":"0"},{"side":"bid","event_time":"2026-07-15T03:40:08.439209Z","price_level":"64572.95","new_quantity":"0"},{"side":"bid","event_time":"2026-07-15T03:40:08.439209Z","price_level":"64559.18","new_quantity":"0"},{"side":"bid","event_time":"2026-07-15T03:40:08.439209Z","price_level":"64544.44","new_quantity":"0.9824109"},{"side":"bid","event_time":"2026-07-15T03:40:08.439209Z","price_level":"64544.43","new_quantity":"1.57183464"},{"side":"bid","event_time":"2026-07-15T03:40:08.439209Z","price_level":"64544.42","new_quantity":"0"},{"side":"bid","event_time":"2026-07-15T03:40:08.439209Z","price_level":"64544.41","new_quantity":"0"},{"side":"bid","event_time":"2026-07-15T03:40:08.439209Z","price_level":"64543.01","new_quantity":"0"},{"side":"bid","event_time":"2026-07-15T03:40:08.439209Z","price_level":"64541.56","new_quantity":"0.0005"},{"side":"bid","event_time":"2026-07-15T03:40:08.439209Z","price_level":"64516.78","new_quantity":"0.87984945"},{"side":"bid","event_time":"2026-07-15T03:40:08.439209Z","price_level":"64516.77","new_quantity":"1.40045655"},{"side":"bid","event_time":"2026-07-15T03:40:08.439209Z","price_level":"64516.76","new_quantity":"0"},{"side":"bid","event_time":"2026-07-15T03:40:08.439209Z","price_level":"64512.59","new_quantity":"0.30663828"},{"side":"bid","event_time":"2026-07-15T03:40:08.439209Z","price_level":"64512.58","new_quantity":"0"},{"side":"bid","event_time":"2026-07-15T03:40:08.439209Z","price_level":"64490.96","new_quantity":"2.07523388"},{"side":"bid","event_time":"2026-07-15T03:40:08.439209Z","price_level":"64489.3","new_quantity":"0"},{"side":"bid","event_time":"2026-07-15T03:40:08.439209Z","price_level":"64472.86","new_quantity":"0"},{"side":"offer","event_time":"2026-07-15T03:40:08.439209Z","price_level":"64580.32","new_quantity":"0"},{"side":"offer","event_time":"2026-07-15T03:40:08.439209Z","price_level":"64580.33","new_quantity":"0.00003586"},{"side":"offer","event_time":"2026-07-15T03:40:08.439209Z","price_level":"64584","new_quantity":"0.000018"},{"side":"offer","event_time":"2026-07-15T03:40:08.439209Z","price_level":"64584.74","new_quantity":"0"},{"side":"offer","event_time":"2026-07-15T03:40:08.439209Z","price_level":"64586","new_quantity":"0"},{"side":"offer","event_time":"2026-07-15T03:40:08.439209Z","price_level":"64587.93","new_quantity":"0"},{"side":"offer","event_time":"2026-07-15T03:40:08.439209Z","price_level":"64588","new_quantity":"0.0232"},{"side":"offer","event_time":"2026-07-15T03:40:08.439209Z","price_level":"64589.64","new_quantity":"0"},{"side":"offer","event_time":"2026-07-15T03:40:08.439209Z","price_level":"64589.65","new_quantity":"0"},{"side":"offer","event_time":"2026-07-15T03:40:08.439209Z","price_level":"64589.99","new_quantity":"0"},{"side":"offer","event_time":"2026-07-15T03:40:08.439209Z","price_level":"64590.75","new_quantity":"0.03374851"},{"side":"offer","event_time":"2026-07-15T03:40:08.439209Z","price_level":"64590.76","new_quantity":"0"},{"side":"offer","event_time":"2026-07-15T03:40:08.439209Z","price_level":"64590.85","new_quantity":"0"},{"side":"offer","event_time":"2026-07-15T03:40:08.439209Z","price_level":"64591.63","new_quantity":"0"},{"side":"offer","event_time":"2026-07-15T03:40:08.439209Z","price_level":"64591.64","new_quantity":"0"},{"side":"offer","event_time":"2026-07-15T03:40:08.439209Z","price_level":"64592.49","new_quantity":"0"},{"side":"offer","event_time":"2026-07-15T03:40:08.439209Z","price_level":"64593.03","new_quantity":"0"},{"side":"offer","event_time":"2026-07-15T03:40:08.439209Z","price_level":"64594.17","new_quantity":"0"},{"side":"offer","event_time":"2026-07-15T03:40:08.439209Z","price_level":"64594.49","new_quantity":"0.19899435"},{"side":"offer","event_time":"2026-07-15T03:40:08.439209Z","price_level":"64594.77","new_quantity":"0"},{"side":"offer","event_time":"2026-07-15T03:40:08.439209Z","price_level":"64594.81","new_quantity":"0"},{"side":"offer","event_time":"2026-07-15T03:40:08.439209Z","price_level":"64595.23","new_quantity":"0.12384816"},{"side":"offer","event_time":"2026-07-15T03:40:08.439209Z","price_level":"64596.15","new_quantity":"0.15480799"},{"side":"offer","event_time":"2026-07-15T03:40:08.439209Z","price_level":"64596.21","new_quantity":"0"},{"side":"offer","event_time":"2026-07-15T03:40:08.439209Z","price_level":"64597.39","new_quantity":"0.13608339"},{"side":"offer","event_time":"2026-07-15T03:40:08.439209Z","price_level":"64597.78","new_quantity":"0.179558"},{"side":"offer","event_time":"2026-07-15T03:40:08.439209Z","price_level":"64599.39","new_quantity":"0.0009866"},{"side":"offer","event_time":"2026-07-15T03:40:08.439209Z","price_level":"64599.48","new_quantity":"0"},{"side":"offer","event_time":"2026-07-15T03:40:08.439209Z","price_level":"64600.19","new_quantity":"0.02874335"},{"side":"offer","event_time":"2026-07-15T03:40:08.439209Z","price_level":"64600.22","new_quantity":"0"},{"side":"offer","event_time":"2026-07-15T03:40:08.439209Z","price_level":"64603.19","new_quantity":"0"},{"side":"offer","event_time":"2026-07-15T03:40:08.439209Z","price_level":"64609.43","new_quantity":"0"},{"side":"offer","event_time":"2026-07-15T03:40:08.439209Z","price_level":"64610.03","new_quantity":"0"},{"side":"offer","event_time":"2026-07-15T03:40:08.439209Z","price_level":"64610.34","new_quantity":"0"},{"side":"offer","event_time":"2026-07-15T03:40:08.439209Z","price_level":"64613.25","new_quantity":"0.4040463"},{"side":"offer","event_time":"2026-07-15T03:40:08.439209Z","price_level":"64613.36","new_quantity":"0.448713"},{"side":"offer","event_time":"2026-07-15T03:40:08.439209Z","price_level":"64619.48","new_quantity":"0.09919003"},{"side":"offer","event_time":"2026-07-15T03:40:08.439209Z","price_level":"64622.59","new_quantity":"0.12378505"},{"side":"offer","event_time":"2026-07-15T03:40:08.439209Z","price_level":"64622.91","new_quantity":"0"},{"side":"offer","event_time":"2026-07-15T03:40:08.439209Z","price_level":"64626.29","new_quantity":"0.18563192"},{"side":"offer","event_time":"2026-07-15T03:40:08.439209Z","price_level":"64626.3","new_quantity":"0.12378505"},{"side":"offer","event_time":"2026-07-15T03:40:08.439209Z","price_level":"64626.31","new_quantity":"0"},{"side":"offer","event_time":"2026-07-15T03:40:08.439209Z","price_level":"64626.6","new_quantity":"0"},{"side":"offer","event_time":"2026-07-15T03:40:08.439209Z","price_level":"64627.46","new_quantity":"0"},{"side":"offer","event_time":"2026-07-15T03:40:08.439209Z","price_level":"64633.18","new_quantity":"0.0215933"},{"side":"offer","event_time":"2026-07-15T03:40:08.439209Z","price_level":"64633.19","new_quantity":"0"},{"side":"offer","event_time":"2026-07-15T03:40:08.439209Z","price_level":"64633.25","new_quantity":"0"},{"side":"offer","event_time":"2026-07-15T03:40:08.439209Z","price_level":"64635.63","new_quantity":"1.84851929"},{"side":"offer","event_time":"2026-07-15T03:40:08.439209Z","price_level":"64637.18","new_quantity":"1.41892735"},{"side":"offer","event_time":"2026-07-15T03:40:08.439209Z","price_level":"64638.12","new_quantity":"0"},{"side":"offer","event_time":"2026-07-15T03:40:08.439209Z","price_level":"64638.43","new_quantity":"0.45863423"},{"side":"offer","event_time":"2026-07-15T03:40:08.439209Z","price_level":"64638.44","new_quantity":"0"},{"side":"offer","event_time":"2026-07-15T03:40:08.439209Z","price_level":"64647.49","new_quantity":"1.26574415"},{"side":"offer","event_time":"2026-07-15T03:40:08.439209Z","price_level":"64647.5","new_quantity":"2.08923913"},{"side":"offer","event_time":"2026-07-15T03:40:08.439209Z","price_level":"64647.51","new_quantity":"0"},{"side":"offer","event_time":"2026-07-15T03:40:08.439209Z","price_level":"64668.4","new_quantity":"0"},{"side":"offer","event_time":"2026-07-15T03:40:08.439209Z","price_level":"64692.25","new_quantity":"0"}]}]}
{"channel":"market_trades","timestamp":"2026-07-15T03:40:08.491931396Z","sequence_num":116,"events":[{"type":"update","trades":[{"product_id":"BTC-USD","trade_id":"1056309443","price":"64580.33","size":"0.00003586","time":"2026-07-15T03:40:08.439098Z","side":"SELL"},{"product_id":"BTC-USD","trade_id":"1056309442","price":"64580.33","size":"0.00022366","time":"2026-07-15T03:40:08.400349Z","side":"SELL"},{"product_id":"BTC-USD","trade_id":"1056309441","price":"64580.33","size":"0.00527296","time":"2026-07-15T03:40:08.400349Z","side":"SELL"},{"product_id":"BTC-USD","trade_id":"1056309440","price":"64580.33","size":"0.02262538","time":"2026-07-15T03:40:08.400349Z","side":"SELL"},{"product_id":"BTC-USD","trade_id":"1056309439","price":"64580.32","size":"0.000018","time":"2026-07-15T03:40:08.400349Z","side":"SELL"}]}]}
{"channel":"l2_data","timestamp":"2026-07-15T03:40:08.531451848Z","sequence_num":117,"events":[{"type":"update","product_id":"BTC-USD","updates":[{"side":"bid","event_time":"2026-07-15T03:40:08.495272Z","price_level":"64589.4","new_quantity":"0.10789"},{"side":"bid","event_time":"2026-07-15T03:40:08.495272Z","price_level":"64587.26","new_quantity":"0.02995423"},{"side":"bid","event_time":"2026-07-15T03:40:08.495272Z","price_level":"64587.25","new_quantity":"0.013854"},{"side":"bid","event_time":"2026-07-15T03:40:08.495272Z","price_level":"64587.23","new_quantity":"0.00320012"},{"side":"bid","event_time":"2026-07-15T03:40:08.495272Z","price_level":"64587.22","new_quantity":"0"},{"side":"bid","event_time":"2026-07-15T03:40:08.495272Z","price_level":"64584.03","new_quantity":"0.12386963"},{"side":"bid","event_time":"2026-07-15T03:40:08.495272Z","price_level":"64584","new_quantity":"0.0394883"},{"side":"bid","event_time":"2026-07-15T03:40:08.495272Z","price_level":"64583.99","new_quantity":"0"},{"side":"bid","event_time":"2026-07-15T03:40:08.495272Z","price_level":"64583.32","new_quantity":"0.12378505"},{"side":"bid","event_time":"2026-07-15T03:40:08.495272Z","price_level":"64582.81","new_quantity":"0"},{"side":"bid","event_time":"2026-07-15T03:40:08.495272Z","price_level":"64582.5","new_quantity":"1"},{"side":"bid","event_time":"2026-07-15T03:40:08.495272Z","price_level":"64582.38","new_quantity":"0.00774161"},{"side":"bid","event_time":"2026-07-15T03:40:08.495272Z","price_level":"64582.16","new_quantity":"0.04656107"},{"side":"bid","event_time":"2026-07-15T03:40:08.495272Z","price_level":"64580.36","new_quantity":"0.25453115"},{"side":"bid","event_time":"2026-07-15T03:40:08.495272Z","price_level":"64580.35","new_quantity":"0.15484584"},{"side":"bid","event_time":"2026-07-15T03:40:08.495272Z","price_level":"64580.33","new_quantity":"0"},{"side":"bid","event_time":"2026-07-15T03:40:08.495272Z","price_level":"64580.32","new_quantity":"0.02"},{"side":"bid","event_time":"2026-07-15T03:40:08.495272Z","price_level":"64580.2","new_quantity":"0.00967702"},{"side":"bid","event_time":"2026-07-15T03:40:08.495272Z","price_level":"64579.51","new_quantity":"0"},{"side":"bid","event_time":"2026-07-15T03:40:08.495272Z","price_level":"64579.5","new_quantity":"0"},{"side":"bid","event_time":"2026-07-15T03:40:08.495272Z","price_level":"64578.7","new_quantity":"0"},{"side":"bid","event_time":"2026-07-15T03:40:08.495272Z","price_level":"64576.64","new_quantity":"0.15038976"},{"side":"bid","event_time":"2026-07-15T03:40:08.495272Z","price_level":"64576.52","new_quantity":"0"},{"side":"bid","event_time":"2026-07-15T03:40:08.495272Z","price_level":"64576.19","new_quantity":"0"},{"side":"bid","event_time":"2026-07-15T03:40:08.495272Z","price_level":"64570.52","new_quantity":"0.00772597"},{"side":"bid","event_time":"2026-07-15T03:40:08.495272Z","price_level":"64568.58","new_quantity":"0.05210691"},{"side":"bid","event_time":"2026-07-15T03:40:08.495272Z","price_level":"64568.51","new_quantity":"0.00849921"},{"side":"bid","event_time":"2026-07-15T03:40:08.495272Z","price_level":"64568.02","new_quantity":"0"},{"side":"bid","event_time":"2026-07-15T03:40:08.495272Z","price_level":"64566","new_quantity":"0"},{"side":"bid","event_time":"2026-07-15T03:40:08.495272Z","price_level":"64564","new_quantity":"0"},{"side":"bid","event_time":"2026-07-15T03:40:08.495272Z","price_level":"64562","new_quantity":"0"},{"side":"bid","event_time":"2026-07-15T03:40:08.495272Z","price_level":"64561.05","new_quantity":"0.18550664"},{"side":"bid","event_time":"2026-07-15T03:40:08.495272Z","price_level":"64560","new_quantity":"0"},{"side":"bid","event_time":"2026-07-15T03:40:08.495272Z","price_level":"64558.74","new_quantity":"0"},{"side":"bid","event_time":"2026-07-15T03:40:08.495272Z","price_level":"64557.03","new_quantity":"0.04737135"},{"side":"bid","event_time":"2026-07-15T03:40:08.495272Z","price_level":"64557.02","new_quantity":"0"},{"side":"bid","event_time":"2026-07-15T03:40:08.495272Z","price_level":"64542.1","new_quantity":"0"},{"side":"bid","event_time":"2026-07-15T03:40:08.495272Z","price_level":"64535.65","new_quantity":"0"},{"side":"bid","event_time":"2026-07-15T03:40:08.495272Z","price_level":"64517.75","new_quantity":"0"},{"side":"bid","event_time":"2026-07-15T03:40:08.495272Z","price_level":"64506.15","new_quantity":"0.05053888"},{"side":"bid","event_time":"2026-07-15T03:40:08.495272Z","price_level":"64506.14","new_quantity":"0"},{"side":"bid","event_time":"2026-07-15T03:40:08.495272Z","price_level":"64495.49","new_quantity":"0.00348393"},{"side":"bid","event_time":"2026-07-15T03:40:08.495272Z","price_level":"64474.84","new_quantity":"0"},{"side":"bid","event_time":"2026-07-15T03:40:08.495272Z","price_level":"56507.78","new_quantity":"0"},{"side":"offer","event_time":"2026-07-15T03:40:08.495272Z","price_level":"64580.33","new_quantity":"0"},{"side":"offer","event_time":"2026-07-15T03:40:08.495272Z","price_level":"64584","new_quantity":"0"},{"side":"offer","event_time":"2026-07-15T03:40:08.495272Z","price_level":"64587.68","new_quantity":"0"},{"side":"offer","event_time":"2026-07-15T03:40:08.495272Z","price_level":"64588","new_quantity":"0"},{"side":"offer","event_time":"2026-07-15T03:40:08.495272Z","price_level":"64589.41","new_quantity":"0.00038328"},{"side":"offer","event_time":"2026-07-15T03:40:08.495272Z","price_level":"64589.63","new_quantity":"0"},{"side":"offer","event_time":"2026-07-15T03:40:08.495272Z","price_level":"64590.75","new_quantity":"0"},{"side":"offer","event_time":"2026-07-15T03:40:08.495272Z","price_level":"64591.8","new_quantity":"0.01648432"},{"side":"offer","event_time":"2026-07-15T03:40:08.495272Z","price_level":"64592.48","new_quantity":"0"},{"side":"offer","event_time":"2026-07-15T03:40:08.495272Z","price_level":"64592.49","new_quantity":"0"},{"side":"offer","event_time":"2026-07-15T03:40:08.495272Z","price_level":"64593.1","new_quantity":"0.04422472"},{"side":"offer","event_time":"2026-07-15T03:40:08.495272Z","price_level":"64594.39","new_quantity":"0.01648432"},{"side":"offer","event_time":"2026-07-15T03:40:08.495272Z","price_level":"64594.47","new_quantity":"0.00159977"},{"side":"offer","event_time":"2026-07-15T03:40:08.495272Z","price_level":"64594.48","new_quantity":"0.03093532"},{"side":"offer","event_time":"2026-07-15T03:40:08.495272Z","price_level":"64594.49","new_quantity":"0.21647057"},{"side":"offer","event_time":"2026-07-15T03:40:08.495272Z","price_level":"64595.09","new_quantity":"0"},{"side":"offer","event_time":"2026-07-15T03:40:08.495272Z","price_level":"64595.16","new_quantity":"0"},{"side":"offer","event_time":"2026-07-15T03:40:08.495272Z","price_level":"64595.23","new_quantity":"0"},{"side":"offer","event_time":"2026-07-15T03:40:08.495272Z","price_level":"64595.91","new_quantity":"0.12378505"},{"side":"offer","event_time":"2026-07-15T03:40:08.495272Z","price_level":"64595.92","new_quantity":"0.12384684"},{"side":"offer","event_time":"2026-07-15T03:40:08.495272Z","price_level":"64596.15","new_quantity":"0"},{"side":"offer","event_time":"2026-07-15T03:40:08.495272Z","price_level":"64597.39","new_quantity":"0.18578267"},{"side":"offer","event_time":"2026-07-15T03:40:08.495272Z","price_level":"64597.78","new_quantity":"0"},{"side":"offer","event_time":"2026-07-15T03:40:08.495272Z","price_level":"64598.09","new_quantity":"0.12378505"},{"side":"offer","event_time":"2026-07-15T03:40:08.495272Z","price_level":"64598.41","new_quantity":"0.0483189"},{"side":"offer","event_time":"2026-07-15T03:40:08.495272Z","price_level":"64599.22","new_quantity":"0.15480063"},{"side":"offer","event_time":"2026-07-15T03:40:08.495272Z","price_level":"64599.39","new_quantity":"0"},{"side":"offer","event_time":"2026-07-15T03:40:08.495272Z","price_level":"64600.16","new_quantity":"0.2843278"},{"side":"offer","event_time":"2026-07-15T03:40:08.495272Z","price_level":"64600.17","new_quantity":"0"},{"side":"offer","event_time":"2026-07-15T03:40:08.495272Z","price_level":"64600.18","new_quantity":"0.12378505"},{"side":"offer","event_time":"2026-07-15T03:40:08.495272Z","price_level":"64600.19","new_quantity":"0"},{"side":"offer","event_time":"2026-07-15T03:40:08.495272Z","price_level":"64601.08","new_quantity":"0.00098656"},{"side":"offer","event_time":"2026-07-15T03:40:08.495272Z","price_level":"64603.02","new_quantity":"0"},{"side":"offer","event_time":"2026-07-15T03:40:08.495272Z","price_level":"64603.03","new_quantity":"0.12378505"},{"side":"offer","event_time":"2026-07-15T03:40:08.495272Z","price_level":"64603.26","new_quantity":"0.09515837"},{"side":"offer","event_time":"2026-07-15T03:40:08.495272Z","price_level":"64605.09","new_quantity":"0.12378505"},{"side":"offer","event_time":"2026-07-15T03:40:08.495272Z","price_level":"64610","new_quantity":"0.11853639"},{"side":"offer","event_time":"2026-07-15T03:40:08.495272Z","price_level":"64611","new_quantity":"0"},{"side":"offer","event_time":"2026-07-15T03:40:08.495272Z","price_level":"64611.33","new_quantity":"0"},{"side":"offer","event_time":"2026-07-15T03:40:08.495272Z","price_level":"64611.34","new_quantity":"0"},{"side":"offer","event_time":"2026-07-15T03:40:08.495272Z","price_level":"64613.25","new_quantity":"0.92237193"},{"side":"offer","event_time":"2026-07-15T03:40:08.495272Z","price_level":"64615.5","new_quantity":"1"},{"side":"offer","event_time":"2026-07-15T03:40:08.495272Z","price_level":"64619.46","new_quantity":"0.47869542"},{"side":"offer","event_time":"2026-07-15T03:40:08.495272Z","price_level":"64619.47","new_quantity":"0.62914337"},{"side":"offer","event_time":"2026-07-15T03:40:08.495272Z","price_level":"64619.48","new_quantity":"0"},{"side":"offer","event_time":"2026-07-15T03:40:08.495272Z","price_level":"64626.29","new_quantity":"0.09563572"},{"side":"offer","event_time":"2026-07-15T03:40:08.495272Z","price_level":"64626.3","new_quantity":"0"},{"side":"offer","event_time":"2026-07-15T03:40:08.495272Z","price_level":"64655.74","new_quantity":"0.15705191"},{"side":"offer","event_time":"2026-07-15T03:40:08.495272Z","price_level":"64655.75","new_quantity":"0.232092"},{"side":"offer","event_time":"2026-07-15T03:40:08.495272Z","price_level":"64657.84","new_quantity":"0"},{"side":"offer","event_time":"2026-07-15T03:40:08.495272Z","price_level":"64708.18","new_quantity":"0.00958205"}]}]}
{"channel":"l2_data","timestamp":"2026-07-15T03:40:08.580826791Z","sequence_num":118,"events":[{"type":"update","product_id":"BTC-USD","updates":[{"side":"bid","event_time":"2026-07-15T03:40:08.541226Z","price_level":"64587.26","new_quantity":"0"},{"side":"bid","event_time":"2026-07-15T03:40:08.541226Z","price_level":"64587.25","new_quantity":"0.00159977"},{"side":"bid","event_time":"2026-07-15T03:40:08.541226Z","price_level":"64586","new_quantity":"0.0232"},{"side":"bid","event_time":"2026-07-15T03:40:08.541226Z","price_level":"64584.16","new_quantity":"0.04646634"},{"side":"bid","event_time":"2026-07-15T03:40:08.541226Z","price_level":"64583.32","new_quantity":"0"},{"side":"bid","event_time":"2026-07-15T03:40:08.541226Z","price_level":"64582.51","new_quantity":"0.12378505"},{"side":"bid","event_time":"2026-07-15T03:40:08.541226Z","price_level":"64568.51","new_quantity":"0"},{"side":"bid","event_time":"2026-07-15T03:40:08.541226Z","price_level":"64557.03","new_quantity":"0.59747519"},{"side":"bid","event_time":"2026-07-15T03:40:08.541226Z","price_level":"64555.29","new_quantity":"0.93159157"},{"side":"bid","event_time":"2026-07-15T03:40:08.541226Z","price_level":"64551.41","new_quantity":"0.64001711"},{"side":"bid","event_time":"2026-07-15T03:40:08.541226Z","price_level":"64551.4","new_quantity":"0"},{"side":"bid","event_time":"2026-07-15T03:40:08.541226Z","price_level":"64551","new_quantity":"0.00003194"},{"side":"bid","event_time":"2026-07-15T03:40:08.541226Z","price_level":"64544.44","new_quantity":"0"},{"side":"bid","event_time":"2026-07-15T03:40:08.541226Z","price_level":"64544.43","new_quantity":"0"},{"side":"bid","event_time":"2026-07-15T03:40:08.541226Z","price_level":"64541.56","new_quantity":"0"},{"side":"bid","event_time":"2026-07-15T03:40:08.541226Z","price_level":"64533","new_quantity":"0"},{"side":"bid","event_time":"2026-07-15T03:40:08.541226Z","price_level":"64522.18","new_quantity":"1.40033913"},{"side":"bid","event_time":"2026-07-15T03:40:08.541226Z","price_level":"64522.17","new_quantity":"0"},{"side":"bid","event_time":"2026-07-15T03:40:08.541226Z","price_level":"64521.17","new_quantity":"1.330581"},{"side":"bid","event_time":"2026-07-15T03:40:08.541226Z","price_level":"64516.78","new_quantity":"0"},{"side":"bid","event_time":"2026-07-15T03:40:08.541226Z","price_level":"64516.77","new_quantity":"0"},{"side":"bid","event_time":"2026-07-15T03:40:08.541226Z","price_level":"64506.15","new_quantity":"3.09917494"},{"side":"bid","event_time":"2026-07-15T03:40:08.541226Z","price_level":"64505.87","new_quantity":"5.117416"},{"side":"bid","event_time":"2026-07-15T03:40:08.541226Z","price_level":"64502.56","new_quantity":"0"},{"side":"bid","event_time":"2026-07-15T03:40:08.541226Z","price_level":"64500.01","new_quantity":"2.0749427"},{"side":"bid","event_time":"2026-07-15T03:40:08.541226Z","price_level":"64490.96","new_quantity":"0"},{"side":"offer","event_time":"2026-07-15T03:40:08.541226Z","price_level":"64589.41","new_quantity":"0.00277531"},{"side":"offer","event_time":"2026-07-15T03:40:08.541226Z","price_level":"64590","new_quantity":"0.0232"},{"side":"offer","event_time":"2026-07-15T03:40:08.541226Z","price_level":"64591.77","new_quantity":"0.09403959"},{"side":"offer","event_time":"2026-07-15T03:40:08.541226Z","price_level":"64591.78","new_quantity":"0.12378505"},{"side":"offer","event_time":"2026-07-15T03:40:08.541226Z","price_level":"64593.1","new_quantity":"0.01648432"},{"side":"offer","event_time":"2026-07-15T03:40:08.541226Z","price_level":"64593.82","new_quantity":"0.33870843"},{"side":"offer","event_time":"2026-07-15T03:40:08.541226Z","price_level":"64593.83","new_quantity":"0.12378505"},{"side":"offer","event_time":"2026-07-15T03:40:08.541226Z","price_level":"64593.84","new_quantity":"0.04646634"},{"side":"offer","event_time":"2026-07-15T03:40:08.541226Z","price_level":"64594.47","new_quantity":"0"},{"side":"offer","event_time":"2026-07-15T03:40:08.541226Z","price_level":"64594.49","new_quantity":"0"},{"side":"offer","event_time":"2026-07-15T03:40:08.541226Z","price_level":"64595.92","new_quantity":"0"},{"side":"offer","event_time":"2026-07-15T03:40:08.541226Z","price_level":"64600.16","new_quantity":"0.17713167"},{"side":"offer","event_time":"2026-07-15T03:40:08.541226Z","price_level":"64601.08","new_quantity":"0"},{"side":"offer","event_time":"2026-07-15T03:40:08.541226Z","price_level":"64614.66","new_quantity":"0.01068646"},{"side":"offer","event_time":"2026-07-15T03:40:08.541226Z","price_level":"64616.4","new_quantity":"0.01848225"},{"side":"offer","event_time":"2026-07-15T03:40:08.541226Z","price_level":"64618.71","new_quantity":"0"},{"side":"offer","event_time":"2026-07-15T03:40:08.541226Z","price_level":"64622.59","new_quantity":"0"},{"side":"offer","event_time":"2026-07-15T03:40:08.541226Z","price_level":"64637.18","new_quantity":"0"},{"side":"offer","event_time":"2026-07-15T03:40:08.541226Z","price_level":"64638.43","new_quantity":"0"},{"side":"offer","event_time":"2026-07-15T03:40:08.541226Z","price_level":"64647.46","new_quantity":"1.41870172"},{"side":"offer","event_time":"2026-07-15T03:40:08.541226Z","price_level":"64647.47","new_quantity":"0.29223469"},{"side":"offer","event_time":"2026-07-15T03:40:08.541226Z","price_level":"64647.48","new_quantity":"0.45857003"},{"side":"offer","event_time":"2026-07-15T03:40:08.541226Z","price_level":"64647.49","new_quantity":"0"},{"side":"offer","event_time":"2026-07-15T03:40:08.541226Z","price_level":"64647.5","new_quantity":"0"},{"side":"offer","event_time":"2026-07-15T03:40:08.541226Z","price_level":"64650.93","new_quantity":"2.08912828"}]}]}
{"channel":"market_trades","timestamp":"2026-07-15T03:40:08.584474553Z","sequence_num":119,"events":[{"type":"update","trades":[{"product_id":"BTC-USD","trade_id":"1056309446","price":"64588","size":"0.00436789","time":"2026-07-15T03:40:08.469555Z","side":"SELL"},{"product_id":"BTC-USD","trade_id":"1056309445","price":"64587.68","size":"0.000018","time":"2026-07-15T03:40:08.469555Z","side":"SELL"},{"product_id":"BTC-USD","trade_id":"1056309444","price":"64584","size":"0.000018","time":"2026-07-15T03:40:08.469555Z","side":"SELL"}]}]}
{"channel":"l2_data","timestamp":"2026-07-15T03:40:08.631153376Z","sequence_num":120,"events":[{"type":"update","product_id":"BTC-USD","updates":[{"side":"bid","event_time":"2026-07-15T03:40:08.597578Z","price_level":"64584.67","new_quantity":"0.12378505"},{"side":"bid","event_time":"2026-07-15T03:40:08.597578Z","price_level":"64576.64","new_quantity":"0.13038976"},{"side":"bid","event_time":"2026-07-15T03:40:08.597578Z","price_level":"64562.08","new_quantity":"0.14"},{"side":"bid","event_time":"2026-07-15T03:40:08.597578Z","price_level":"64561.05","new_quantity":"0"},{"side":"bid","event_time":"2026-07-15T03:40:08.597578Z","price_level":"64559.05","new_quantity":"0"},{"side":"bid","event_time":"2026-07-15T03:40:08.597578Z","price_level":"64533.71","new_quantity":"0"},{"side":"offer","event_time":"2026-07-15T03:40:08.597578Z","price_level":"64591.76","new_quantity":"0.00159977"},{"side":"offer","event_time":"2026-07-15T03:40:08.597578Z","price_level":"64593.09","new_quantity":"0.02"},{"side":"offer","event_time":"2026-07-15T03:40:08.597578Z","price_level":"64594.48","new_quantity":"0"},{"side":"offer","event_time":"2026-07-15T03:40:08.597578Z","price_level":"64594.77","new_quantity":"0.12384904"},{"side":"offer","event_time":"2026-07-15T03:40:08.597578Z","price_level":"64596.21","new_quantity":"0.00772597"},{"side":"offer","event_time":"2026-07-15T03:40:08.597578Z","price_level":"64600.87","new_quantity":"0.00098651"},{"side":"offer","event_time":"2026-07-15T03:40:08.597578Z","price_level":"64600.96","new_quantity":"0"},{"side":"offer","event_time":"2026-07-15T03:40:08.597578Z","price_level":"64602","new_quantity":"0"},{"side":"offer","event_time":"2026-07-15T03:40:08.597578Z","price_level":"64610","new_quantity":"0.17502174"},{"side":"offer","event_time":"2026-07-15T03:40:08.597578Z","price_level":"64611.34","new_quantity":"0.06"},{"side":"offer","event_time":"2026-07-15T03:40:08.597578Z","price_level":"64612.33","new_quantity":"0.02"},{"side":"offer","event_time":"2026-07-15T03:40:08.597578Z","price_level":"64612.43","new_quantity":"0.12"},{"side":"offer","event_time":"2026-07-15T03:40:08.597578Z","price_level":"64615.5","new_quantity":"0"},{"side":"offer","event_time":"2026-07-15T03:40:08.597578Z","price_level":"64619.47","new_quantity":"0"},{"side":"offer","event_time":"2026-07-15T03:40:08.597578Z","price_level":"64621.67","new_quantity":"0.62989604"},{"side":"offer","event_time":"2026-07-15T03:40:08.597578Z","price_level":"64622","new_quantity":"0.00003194"},{"side":"offer","event_time":"2026-07-15T03:40:08.597578Z","price_level":"64635.63","new_quantity":"0.83336837"},{"side":"offer","event_time":"2026-07-15T03:40:08.597578Z","price_level":"64641.44","new_quantity":"0"},{"side":"offer","event_time":"2026-07-15T03:40:08.597578Z","price_level":"64647.45","new_quantity":"1.13919962"},{"side":"offer","event_time":"2026-07-15T03:40:08.597578Z","price_level":"64647.47","new_quantity":"0"}]}]}
{"channel":"l2_data","timestamp":"2026-07-15T03:40:08.680921942Z","sequence_num":121,"events":[{"type":"update","product_id":"BTC-USD","updates":[{"side":"bid","event_time":"2026-07-15T03:40:08.649591Z","price_level":"64589.4","new_quantity":"0.14737788"},{"side":"bid","event_time":"2026-07-15T03:40:08.649591Z","price_level":"64587.78","new_quantity":"0.0077412"},{"side":"bid","event_time":"2026-07-15T03:40:08.649591Z","price_level":"64587.23","new_quantity":"0"},{"side":"bid","event_time":"2026-07-15T03:40:08.649591Z","price_level":"64585.6","new_quantity":"0.0096765"},{"side":"bid","event_time":"2026-07-15T03:40:08.649591Z","price_level":"64584.74","new_quantity":"0.0015533"},{"side":"bid","event_time":"2026-07-15T03:40:08.649591Z","price_level":"64584.16","new_quantity":"0"},{"side":"bid","event_time":"2026-07-15T03:40:08.649591Z","price_level":"64584","new_quantity":"0"},{"side":"bid","event_time":"2026-07-15T03:40:08.649591Z","price_level":"64583.58","new_quantity":"0.04646634"},{"side":"bid","event_time":"2026-07-15T03:40:08.649591Z","price_level":"64582.38","new_quantity":"0"},{"side":"bid","event_time":"2026-07-15T03:40:08.649591Z","price_level":"64581.55","new_quantity":"0.0015533"},{"side":"bid","event_time":"2026-07-15T03:40:08.649591Z","price_level":"64580.2","new_quantity":"0"},{"side":"bid","event_time":"2026-07-15T03:40:08.649591Z","price_level":"64563.66","new_quantity":"0.17159701"},{"side":"bid","event_time":"2026-07-15T03:40:08.649591Z","price_level":"64561.05","new_quantity":"0.11306458"},{"side":"bid","event_time":"2026-07-15T03:40:08.649591Z","price_level":"64557.03","new_quantity":"0"},{"side":"bid","event_time":"2026-07-15T03:40:08.649591Z","price_level":"64557.02","new_quantity":"0.04737135"},{"side":"bid","event_time":"2026-07-15T03:40:08.649591Z","price_level":"64556.31","new_quantity":"0"},{"side":"bid","event_time":"2026-07-15T03:40:08.649591Z","price_level":"64556.3","new_quantity":"0"},{"side":"bid","event_time":"2026-07-15T03:40:08.649591Z","price_level":"64556.17","new_quantity":"0.00077409"},{"side":"bid","event_time":"2026-07-15T03:40:08.649591Z","price_level":"64555.29","new_quantity":"0"},{"side":"bid","event_time":"2026-07-15T03:40:08.649591Z","price_level":"64551.44","new_quantity":"0.93164567"},{"side":"bid","event_time":"2026-07-15T03:40:08.649591Z","price_level":"64551.43","new_quantity":"1.57166419"},{"side":"bid","event_time":"2026-07-15T03:40:08.649591Z","price_level":"64551.41","new_quantity":"0"},{"side":"bid","event_time":"2026-07-15T03:40:08.649591Z","price_level":"64549.66","new_quantity":"0"},{"side":"bid","event_time":"2026-07-15T03:40:08.649591Z","price_level":"64544.96","new_quantity":"0.00154708"},{"side":"bid","event_time":"2026-07-15T03:40:08.649591Z","price_level":"64543.38","new_quantity":"0.11465532"},{"side":"bid","event_time":"2026-07-15T03:40:08.649591Z","price_level":"64541.57","new_quantity":"0.00077408"},{"side":"bid","event_time":"2026-07-15T03:40:08.649591Z","price_level":"64538.52","new_quantity":"0.00773542"},{"side":"bid","event_time":"2026-07-15T03:40:08.649591Z","price_level":"64522.21","new_quantity":"1.98279456"},{"side":"bid","event_time":"2026-07-15T03:40:08.649591Z","price_level":"64522.2","new_quantity":"1.40033869"},{"side":"bid","event_time":"2026-07-15T03:40:08.649591Z","price_level":"64522.19","new_quantity":"0"},{"side":"bid","event_time":"2026-07-15T03:40:08.649591Z","price_level":"64522.18","new_quantity":"0"},{"side":"bid","event_time":"2026-07-15T03:40:08.649591Z","price_level":"64520.94","new_quantity":"0"},{"side":"bid","event_time":"2026-07-15T03:40:08.649591Z","price_level":"64517.35","new_quantity":"0.05824766"},{"side":"bid","event_time":"2026-07-15T03:40:08.649591Z","price_level":"64502.56","new_quantity":"1.19550056"},{"side":"bid","event_time":"2026-07-15T03:40:08.649591Z","price_level":"64500.01","new_quantity":"0"},{"side":"bid","event_time":"2026-07-15T03:40:08.649591Z","price_level":"64490.96","new_quantity":"2.07523388"},{"side":"offer","event_time":"2026-07-15T03:40:08.649591Z","price_level":"64591.77","new_quantity":"0.13554762"},{"side":"offer","event_time":"2026-07-15T03:40:08.649591Z","price_level":"64592","new_quantity":"0.0232"},{"side":"offer","event_time":"2026-07-15T03:40:08.649591Z","price_level":"64593.26","new_quantity":"0.04646634"},{"side":"offer","event_time":"2026-07-15T03:40:08.649591Z","price_level":"64593.84","new_quantity":"0"},{"side":"offer","event_time":"2026-07-15T03:40:08.649591Z","price_level":"64595.9","new_quantity":"0.00772597"},{"side":"offer","event_time":"2026-07-15T03:40:08.649591Z","price_level":"64596.21","new_quantity":"0"},{"side":"offer","event_time":"2026-07-15T03:40:08.649591Z","price_level":"64600.8","new_quantity":"0.00098647"},{"side":"offer","event_time":"2026-07-15T03:40:08.649591Z","price_level":"64600.87","new_quantity":"0"},{"side":"offer","event_time":"2026-07-15T03:40:08.649591Z","price_level":"64610","new_quantity":"0.8125602"},{"side":"offer","event_time":"2026-07-15T03:40:08.649591Z","price_level":"64611","new_quantity":"1"},{"side":"offer","event_time":"2026-07-15T03:40:08.649591Z","price_level":"64613.25","new_quantity":"0.37688543"},{"side":"offer","event_time":"2026-07-15T03:40:08.649591Z","price_level":"64621.67","new_quantity":"0.62912195"},{"side":"offer","event_time":"2026-07-15T03:40:08.649591Z","price_level":"64631.48","new_quantity":"0"},{"side":"offer","event_time":"2026-07-15T03:40:08.649591Z","price_level":"64634.37","new_quantity":"0"},{"side":"offer","event_time":"2026-07-15T03:40:08.649591Z","price_level":"64644.08","new_quantity":"0"},{"side":"offer","event_time":"2026-07-15T03:40:08.649591Z","price_level":"64647.42","new_quantity":"1.13920018"},{"side":"offer","event_time":"2026-07-15T03:40:08.649591Z","price_level":"64647.43","new_quantity":"1.41870238"},{"side":"offer","event_time":"2026-07-15T03:40:08.649591Z","price_level":"64647.44","new_quantity":"0.45857031"},{"side":"offer","event_time":"2026-07-15T03:40:08.649591Z","price_level":"64647.45","new_quantity":"0"},{"side":"offer","event_time":"2026-07-15T03:40:08.649591Z","price_level":"64647.46","new_quantity":"0"},{"side":"offer","event_time":"2026-07-15T03:40:08.649591Z","price_level":"64647.48","new_quantity":"0"},{"side":"offer","event_time":"2026-07-15T03:40:08.649591Z","price_level":"64648.54","new_quantity":"0.0015533"},{"side":"offer","event_time":"2026-07-15T03:40:08.649591Z","price_level":"64648.76","new_quantity":"2.08919841"},{"side":"offer","event_time":"2026-07-15T03:40:08.649591Z","price_level":"64650.93","new_quantity":"0"},{"side":"offer","event_time":"2026-07-15T03:40:08.649591Z","price_level":"64651.73","new_quantity":"0.0015533"}]}]}
{"channel":"market_trades","timestamp":"2026-07-15T03:40:08.683841855Z","sequence_num":122,"events":[{"type":"update","trades":[{"product_id":"BTC-USD","trade_id":"1056309447","price":"64589.4","size":"0.00000002","time":"2026-07-15T03:40:08.620921Z","side":"BUY"}]}]}
{"channel":"l2_data","timestamp":"2026-07-15T03:40:08.731995157Z","sequence_num":123,"events":[{"type":"update","product_id":"BTC-USD","updates":[{"side":"bid","event_time":"2026-07-15T03:40:08.689581Z","price_level":"64588","new_quantity":"0.0232"},{"side":"bid","event_time":"2026-07-15T03:40:08.689581Z","price_level":"64586.61","new_quantity":"0.12378505"},{"side":"bid","event_time":"2026-07-15T03:40:08.689581Z","price_level":"64584.04","new_quantity":"0.02"},{"side":"bid","event_time":"2026-07-15T03:40:08.689581Z","price_level":"64583.58","new_quantity":"0"},{"side":"bid","event_time":"2026-07-15T03:40:08.689581Z","price_level":"64582.75","new_quantity":"0.04646634"},{"side":"bid","event_time":"2026-07-15T03:40:08.689581Z","price_level":"64580.32","new_quantity":"0"},{"side":"bid","event_time":"2026-07-15T03:40:08.689581Z","price_level":"64561.05","new_quantity":"0.0391649"},{"side":"bid","event_time":"2026-07-15T03:40:08.689581Z","price_level":"64561.04","new_quantity":"0"},{"side":"bid","event_time":"2026-07-15T03:40:08.689581Z","price_level":"56515.73","new_quantity":"0.0132912"},{"side":"offer","event_time":"2026-07-15T03:40:08.689581Z","price_level":"64590","new_quantity":"0"},{"side":"offer","event_time":"2026-07-15T03:40:08.689581Z","price_level":"64591.78","new_quantity":"0"},{"side":"offer","event_time":"2026-07-15T03:40:08.689581Z","price_level":"64592","new_quantity":"0"},{"side":"offer","event_time":"2026-07-15T03:40:08.689581Z","price_level":"64592.43","new_quantity":"0.04646634"},{"side":"offer","event_time":"2026-07-15T03:40:08.689581Z","price_level":"64593.09","new_quantity":"0"},{"side":"offer","event_time":"2026-07-15T03:40:08.689581Z","price_level":"64593.26","new_quantity":"0"},{"side":"offer","event_time":"2026-07-15T03:40:08.689581Z","price_level":"64593.83","new_quantity":"0"},{"side":"offer","event_time":"2026-07-15T03:40:08.689581Z","price_level":"64594.78","new_quantity":"0"},{"side":"offer","event_time":"2026-07-15T03:40:08.689581Z","price_level":"64595.91","new_quantity":"0"},{"side":"offer","event_time":"2026-07-15T03:40:08.689581Z","price_level":"64598.09","new_quantity":"0"},{"side":"offer","event_time":"2026-07-15T03:40:08.689581Z","price_level":"64599.81","new_quantity":"0"},{"side":"offer","event_time":"2026-07-15T03:40:08.689581Z","price_level":"64600.69","new_quantity":"0.00253977"},{"side":"offer","event_time":"2026-07-15T03:40:08.689581Z","price_level":"64600.8","new_quantity":"0"},{"side":"offer","event_time":"2026-07-15T03:40:08.689581Z","price_level":"64603.04","new_quantity":"0"},{"side":"offer","event_time":"2026-07-15T03:40:08.689581Z","price_level":"64605.12","new_quantity":"0"}]}]}
{"channel":"l2_data","timestamp":"2026-07-15T03:40:08.782936553Z","sequence_num":124,"events":[{"type":"update","product_id":"BTC-USD","updates":[{"side":"bid","event_time":"2026-07-15T03:40:08.743995Z","price_level":"64589.4","new_quantity":"0.14737784"},{"side":"bid","event_time":"2026-07-15T03:40:08.743995Z","price_level":"64585.26","new_quantity":"0.12386725"},{"side":"bid","event_time":"2026-07-15T03:40:08.743995Z","price_level":"64584.03","new_quantity":"0"},{"side":"bid","event_time":"2026-07-15T03:40:08.743995Z","price_level":"64583.76","new_quantity":"0"},{"side":"bid","event_time":"2026-07-15T03:40:08.743995Z","price_level":"64582.77","new_quantity":"0.04646634"},{"side":"bid","event_time":"2026-07-15T03:40:08.743995Z","price_level":"64582.75","new_quantity":"0"},{"side":"bid","event_time":"2026-07-15T03:40:08.743995Z","price_level":"64582.5","new_quantity":"0"},{"side":"bid","event_time":"2026-07-15T03:40:08.743995Z","price_level":"64582.45","new_quantity":"0.15484081"},{"side":"bid","event_time":"2026-07-15T03:40:08.743995Z","price_level":"64580.36","new_quantity":"0.12099618"},{"side":"bid","event_time":"2026-07-15T03:40:08.743995Z","price_level":"64580.35","new_quantity":"0"},{"side":"bid","event_time":"2026-07-15T03:40:08.743995Z","price_level":"64563.66","new_quantity":"0.11678774"},{"side":"bid","event_time":"2026-07-15T03:40:08.743995Z","price_level":"64562.08","new_quantity":"0"},{"side":"bid","event_time":"2026-07-15T03:40:08.743995Z","price_level":"64557.04","new_quantity":"0.60397866"},{"side":"bid","event_time":"2026-07-15T03:40:08.743995Z","price_level":"64557.03","new_quantity":"0.93156646"},{"side":"bid","event_time":"2026-07-15T03:40:08.743995Z","price_level":"64557.02","new_quantity":"0"},{"side":"bid","event_time":"2026-07-15T03:40:08.743995Z","price_level":"64551.46","new_quantity":"0.4300272"},{"side":"bid","event_time":"2026-07-15T03:40:08.743995Z","price_level":"64551.45","new_quantity":"0.64001671"},{"side":"bid","event_time":"2026-07-15T03:40:08.743995Z","price_level":"64551.44","new_quantity":"0"},{"side":"bid","event_time":"2026-07-15T03:40:08.743995Z","price_level":"64551.43","new_quantity":"0"},{"side":"bid","event_time":"2026-07-15T03:40:08.743995Z","price_level":"64523.65","new_quantity":"0.0007749"},{"side":"bid","event_time":"2026-07-15T03:40:08.743995Z","price_level":"64522.06","new_quantity":"0"},{"side":"bid","event_time":"2026-07-15T03:40:08.743995Z","price_level":"64502.56","new_quantity":"1.48495187"},{"side":"bid","event_time":"2026-07-15T03:40:08.743995Z","price_level":"64500.47","new_quantity":"0"},{"side":"bid","event_time":"2026-07-15T03:40:08.743995Z","price_level":"64500.01","new_quantity":"2.0749427"},{"side":"bid","event_time":"2026-07-15T03:40:08.743995Z","price_level":"64490.96","new_quantity":"0"},{"side":"offer","event_time":"2026-07-15T03:40:08.743995Z","price_level":"64591.12","new_quantity":"0"},{"side":"offer","event_time":"2026-07-15T03:40:08.743995Z","price_level":"64591.76","new_quantity":"0"},{"side":"offer","event_time":"2026-07-15T03:40:08.743995Z","price_level":"64591.77","new_quantity":"0"},{"side":"offer","event_time":"2026-07-15T03:40:08.743995Z","price_level":"64591.8","new_quantity":"0"},{"side":"offer","event_time":"2026-07-15T03:40:08.743995Z","price_level":"64591.99","new_quantity":"0.04204844"},{"side":"offer","event_time":"2026-07-15T03:40:08.743995Z","price_level":"64592","new_quantity":"0.0232"},{"side":"offer","event_time":"2026-07-15T03:40:08.743995Z","price_level":"64592.43","new_quantity":"0"},{"side":"offer","event_time":"2026-07-15T03:40:08.743995Z","price_level":"64592.45","new_quantity":"0.04646634"},{"side":"offer","event_time":"2026-07-15T03:40:08.743995Z","price_level":"64593.1","new_quantity":"0"},{"side":"offer","event_time":"2026-07-15T03:40:08.743995Z","price_level":"64593.44","new_quantity":"0"},{"side":"offer","event_time":"2026-07-15T03:40:08.743995Z","price_level":"64593.81","new_quantity":"0.00159977"},{"side":"offer","event_time":"2026-07-15T03:40:08.743995Z","price_level":"64593.82","new_quantity":"0.11200673"},{"side":"offer","event_time":"2026-07-15T03:40:08.743995Z","price_level":"64594","new_quantity":"0.0232"},{"side":"offer","event_time":"2026-07-15T03:40:08.743995Z","price_level":"64594.31","new_quantity":"0"},{"side":"offer","event_time":"2026-07-15T03:40:08.743995Z","price_level":"64594.39","new_quantity":"0"},{"side":"offer","event_time":"2026-07-15T03:40:08.743995Z","price_level":"64594.77","new_quantity":"0"},{"side":"offer","event_time":"2026-07-15T03:40:08.743995Z","price_level":"64595.9","new_quantity":"0"},{"side":"offer","event_time":"2026-07-15T03:40:08.743995Z","price_level":"64596.07","new_quantity":"0.12384655"},{"side":"offer","event_time":"2026-07-15T03:40:08.743995Z","price_level":"64597.38","new_quantity":"0.04656107"},{"side":"offer","event_time":"2026-07-15T03:40:08.743995Z","price_level":"64597.39","new_quantity":"0.19099789"},{"side":"offer","event_time":"2026-07-15T03:40:08.743995Z","price_level":"64597.5","new_quantity":"0"},{"side":"offer","event_time":"2026-07-15T03:40:08.743995Z","price_level":"64598.4","new_quantity":"0.00772597"},{"side":"offer","event_time":"2026-07-15T03:40:08.743995Z","price_level":"64599.21","new_quantity":"0.12378505"},{"side":"offer","event_time":"2026-07-15T03:40:08.743995Z","price_level":"64600.16","new_quantity":"0.07541592"},{"side":"offer","event_time":"2026-07-15T03:40:08.743995Z","price_level":"64600.18","new_quantity":"0"},{"side":"offer","event_time":"2026-07-15T03:40:08.743995Z","price_level":"64600.54","new_quantity":"0.00098647"},{"side":"offer","event_time":"2026-07-15T03:40:08.743995Z","price_level":"64600.62","new_quantity":"0"},{"side":"offer","event_time":"2026-07-15T03:40:08.743995Z","price_level":"64600.69","new_quantity":"0"},{"side":"offer","event_time":"2026-07-15T03:40:08.743995Z","price_level":"64603.26","new_quantity":"0.1733973"},{"side":"offer","event_time":"2026-07-15T03:40:08.743995Z","price_level":"64603.88","new_quantity":"0"},{"side":"offer","event_time":"2026-07-15T03:40:08.743995Z","price_level":"64605.07","new_quantity":"0.179558"},{"side":"offer","event_time":"2026-07-15T03:40:08.743995Z","price_level":"64605.08","new_quantity":"0.03093532"},{"side":"offer","event_time":"2026-07-15T03:40:08.743995Z","price_level":"64605.97","new_quantity":"0"},{"side":"offer","event_time":"2026-07-15T03:40:08.743995Z","price_level":"64607.07","new_quantity":"0.12378505"},{"side":"offer","event_time":"2026-07-15T03:40:08.743995Z","price_level":"64607.76","new_quantity":"0.04656107"},{"side":"offer","event_time":"2026-07-15T03:40:08.743995Z","price_level":"64608.22","new_quantity":"0"},{"side":"offer","event_time":"2026-07-15T03:40:08.743995Z","price_level":"64610","new_quantity":"0.12954907"},{"side":"offer","event_time":"2026-07-15T03:40:08.743995Z","price_level":"64610.26","new_quantity":"0"},{"side":"offer","event_time":"2026-07-15T03:40:08.743995Z","price_level":"64611","new_quantity":"0"},{"side":"offer","event_time":"2026-07-15T03:40:08.743995Z","price_level":"64611.34","new_quantity":"0"},{"side":"offer","event_time":"2026-07-15T03:40:08.743995Z","price_level":"64612.33","new_quantity":"0"},{"side":"offer","event_time":"2026-07-15T03:40:08.743995Z","price_level":"64612.43","new_quantity":"0"},{"side":"offer","event_time":"2026-07-15T03:40:08.743995Z","price_level":"64613.45","new_quantity":"0"},{"side":"offer","event_time":"2026-07-15T03:40:08.743995Z","price_level":"64616.4","new_quantity":"0.09277689"},{"side":"offer","event_time":"2026-07-15T03:40:08.743995Z","price_level":"64616.64","new_quantity":"0"},{"side":"offer","event_time":"2026-07-15T03:40:08.743995Z","price_level":"64618.71","new_quantity":"0.12378505"},{"side":"offer","event_time":"2026-07-15T03:40:08.743995Z","price_level":"64619.46","new_quantity":"0.02782677"},{"side":"offer","event_time":"2026-07-15T03:40:08.743995Z","price_level":"64619.83","new_quantity":"0"},{"side":"offer","event_time":"2026-07-15T03:40:08.743995Z","price_level":"64621.67","new_quantity":"0"},{"side":"offer","event_time":"2026-07-15T03:40:08.743995Z","price_level":"64623.02","new_quantity":"0"},{"side":"offer","event_time":"2026-07-15T03:40:08.743995Z","price_level":"64626.21","new_quantity":"0"},{"side":"offer","event_time":"2026-07-15T03:40:08.743995Z","price_level":"64626.27","new_quantity":"0.47119473"},{"side":"offer","event_time":"2026-07-15T03:40:08.743995Z","price_level":"64626.28","new_quantity":"0.62907707"},{"side":"offer","event_time":"2026-07-15T03:40:08.743995Z","price_level":"64626.29","new_quantity":"0"},{"side":"offer","event_time":"2026-07-15T03:40:08.743995Z","price_level":"64629.4","new_quantity":"0"},{"side":"offer","event_time":"2026-07-15T03:40:08.743995Z","price_level":"64632.59","new_quantity":"0"},{"side":"offer","event_time":"2026-07-15T03:40:08.743995Z","price_level":"64633.09","new_quantity":"0.0215933"},{"side":"offer","event_time":"2026-07-15T03:40:08.743995Z","price_level":"64633.18","new_quantity":"0"},{"side":"offer","event_time":"2026-07-15T03:40:08.743995Z","price_level":"64635.63","new_quantity":"0.6373625"},{"side":"offer","event_time":"2026-07-15T03:40:08.743995Z","price_level":"64635.64","new_quantity":"0"},{"side":"offer","event_time":"2026-07-15T03:40:08.743995Z","price_level":"64635.78","new_quantity":"0"},{"side":"offer","event_time":"2026-07-15T03:40:08.743995Z","price_level":"64638","new_quantity":"1"},{"side":"offer","event_time":"2026-07-15T03:40:08.743995Z","price_level":"64647.41","new_quantity":"0.45857052"},{"side":"offer","event_time":"2026-07-15T03:40:08.743995Z","price_level":"64647.44","new_quantity":"0"},{"side":"offer","event_time":"2026-07-15T03:40:08.743995Z","price_level":"64648.76","new_quantity":"0"},{"side":"offer","event_time":"2026-07-15T03:40:08.743995Z","price_level":"64648.77","new_quantity":"0.02924085"},{"side":"offer","event_time":"2026-07-15T03:40:08.743995Z","price_level":"64650.94","new_quantity":"0"},{"side":"offer","event_time":"2026-07-15T03:40:08.743995Z","price_level":"64651.78","new_quantity":"2.07823959"},{"side":"offer","event_time":"2026-07-15T03:40:08.743995Z","price_level":"64651.79","new_quantity":"2.08910049"},{"side":"offer","event_time":"2026-07-15T03:40:08.743995Z","price_level":"64651.8","new_quantity":"0"}]}]}
{"channel":"market_trades","timestamp":"2026-07-15T03:40:08.783483944Z","sequence_num":125,"events":[{"type":"update","trades":[{"product_id":"BTC-USD","trade_id":"1056309448","price":"64589.4","size":"0.00000004","time":"2026-07-15T03:40:08.717511Z","side":"BUY"}]}]}
{"channel":"l2_data","timestamp":"2026-07-15T03:40:08.832029725Z","sequence_num":126,"events":[{"type":"update","product_id":"BTC-USD","updates":[{"side":"bid","event_time":"2026-07-15T03:40:08.781208Z","price_level":"64589.4","new_quantity":"0.14739836"},{"side":"bid","event_time":"2026-07-15T03:40:08.781208Z","price_level":"64586.39","new_quantity":"0.12386509"},{"side":"bid","event_time":"2026-07-15T03:40:08.781208Z","price_level":"64585.5","new_quantity":"1"},{"side":"bid","event_time":"2026-07-15T03:40:08.781208Z","price_level":"64585.26","new_quantity":"0"},{"side":"bid","event_time":"2026-07-15T03:40:08.781208Z","price_level":"64576.64","new_quantity":"0.19118059"},{"side":"bid","event_time":"2026-07-15T03:40:08.781208Z","price_level":"64574.86","new_quantity":"0.04474025"},{"side":"bid","event_time":"2026-07-15T03:40:08.781208Z","price_level":"64566.09","new_quantity":"0"},{"side":"bid","event_time":"2026-07-15T03:40:08.781208Z","price_level":"64550.64","new_quantity":"0.0005"},{"side":"bid","event_time":"2026-07-15T03:40:08.781208Z","price_level":"64544.96","new_quantity":"0"},{"side":"bid","event_time":"2026-07-15T03:40:08.781208Z","price_level":"64538.52","new_quantity":"0"},{"side":"bid","event_time":"2026-07-15T03:40:08.781208Z","price_level":"64522.23","new_quantity":"1.96432592"},{"side":"bid","event_time":"2026-07-15T03:40:08.781208Z","price_level":"64522.22","new_quantity":"1.40033826"},{"side":"bid","event_time":"2026-07-15T03:40:08.781208Z","price_level":"64522.21","new_quantity":"0"},{"side":"bid","event_time":"2026-07-15T03:40:08.781208Z","price_level":"64522.2","new_quantity":"0"},{"side":"bid","event_time":"2026-07-15T03:40:08.781208Z","price_level":"64497.14","new_quantity":"10.961196"},{"side":"bid","event_time":"2026-07-15T03:40:08.781208Z","price_level":"64457.94","new_quantity":"0"},{"side":"bid","event_time":"2026-07-15T03:40:08.781208Z","price_level":"56515.73","new_quantity":"0"},{"side":"offer","event_time":"2026-07-15T03:40:08.781208Z","price_level":"64591.99","new_quantity":"0"},{"side":"offer","event_time":"2026-07-15T03:40:08.781208Z","price_level":"64593.82","new_quantity":"0.05493479"},{"side":"offer","event_time":"2026-07-15T03:40:08.781208Z","price_level":"64596.07","new_quantity":"0"},{"side":"offer","event_time":"2026-07-15T03:40:08.781208Z","price_level":"64597.64","new_quantity":"0.12384353"},{"side":"offer","event_time":"2026-07-15T03:40:08.781208Z","price_level":"64598.18","new_quantity":"0"},{"side":"offer","event_time":"2026-07-15T03:40:08.781208Z","price_level":"64604.62","new_quantity":"0.201347"},{"side":"offer","event_time":"2026-07-15T03:40:08.781208Z","price_level":"64605.07","new_quantity":"0"},{"side":"offer","event_time":"2026-07-15T03:40:08.781208Z","price_level":"64614.64","new_quantity":"0.06754609"},{"side":"offer","event_time":"2026-07-15T03:40:08.781208Z","price_level":"64626.41","new_quantity":"0"},{"side":"offer","event_time":"2026-07-15T03:40:08.781208Z","price_level":"64629.2","new_quantity":"0"},{"side":"offer","event_time":"2026-07-15T03:40:08.781208Z","price_level":"64631.47","new_quantity":"0.00077404"},{"side":"offer","event_time":"2026-07-15T03:40:08.781208Z","price_level":"64635.53","new_quantity":"0"},{"side":"offer","event_time":"2026-07-15T03:40:08.781208Z","price_level":"64635.63","new_quantity":"0.04627921"},{"side":"offer","event_time":"2026-07-15T03:40:08.781208Z","price_level":"64638","new_quantity":"0"},{"side":"offer","event_time":"2026-07-15T03:40:08.781208Z","price_level":"64638.96","new_quantity":"0.00077407"},{"side":"offer","event_time":"2026-07-15T03:40:08.781208Z","price_level":"64647.39","new_quantity":"1.1392007"},{"side":"offer","event_time":"2026-07-15T03:40:08.781208Z","price_level":"64647.4","new_quantity":"1.41870304"},{"side":"offer","event_time":"2026-07-15T03:40:08.781208Z","price_level":"64647.42","new_quantity":"0"},{"side":"offer","event_time":"2026-07-15T03:40:08.781208Z","price_level":"64647.43","new_quantity":"0"},{"side":"offer","event_time":"2026-07-15T03:40:08.781208Z","price_level":"64650.92","new_quantity":"0.00077407"}]}]}
{"channel":"l2_data","timestamp":"2026-07-15T03:40:08.882367657Z","sequence_num":127,"events":[{"type":"update","product_id":"BTC-USD","updates":[{"side":"bid","event_time":"2026-07-15T03:40:08.844609Z","price_level":"64589.4","new_quantity":"0.16739836"},{"side":"bid","event_time":"2026-07-15T03:40:08.844609Z","price_level":"64587.25","new_quantity":"0"},{"side":"bid","event_time":"2026-07-15T03:40:08.844609Z","price_level":"64586.62","new_quantity":"0.02159977"},{"side":"bid","event_time":"2026-07-15T03:40:08.844609Z","price_level":"64585.5","new_quantity":"0"},{"side":"bid","event_time":"2026-07-15T03:40:08.844609Z","price_level":"64584","new_quantity":"1"},{"side":"bid","event_time":"2026-07-15T03:40:08.844609Z","price_level":"64582.77","new_quantity":"0"},{"side":"bid","event_time":"2026-07-15T03:40:08.844609Z","price_level":"64567.48","new_quantity":"0.14"},{"side":"bid","event_time":"2026-07-15T03:40:08.844609Z","price_level":"64566.02","new_quantity":"0"},{"side":"bid","event_time":"2026-07-15T03:40:08.844609Z","price_level":"64557.06","new_quantity":"0.60397849"},{"side":"bid","event_time":"2026-07-15T03:40:08.844609Z","price_level":"64557.05","new_quantity":"0.93156617"},{"side":"bid","event_time":"2026-07-15T03:40:08.844609Z","price_level":"64557.04","new_quantity":"0"},{"side":"bid","event_time":"2026-07-15T03:40:08.844609Z","price_level":"64557.03","new_quantity":"0"},{"side":"bid","event_time":"2026-07-15T03:40:08.844609Z","price_level":"64551.48","new_quantity":"0.43032558"},{"side":"bid","event_time":"2026-07-15T03:40:08.844609Z","price_level":"64551.47","new_quantity":"0.64001651"},{"side":"bid","event_time":"2026-07-15T03:40:08.844609Z","price_level":"64551.46","new_quantity":"0"},{"side":"bid","event_time":"2026-07-15T03:40:08.844609Z","price_level":"64551.45","new_quantity":"0"},{"side":"bid","event_time":"2026-07-15T03:40:08.844609Z","price_level":"64546.6","new_quantity":"0.00154704"},{"side":"bid","event_time":"2026-07-15T03:40:08.844609Z","price_level":"64540.15","new_quantity":"0.00773523"},{"side":"bid","event_time":"2026-07-15T03:40:08.844609Z","price_level":"64531.94","new_quantity":"0.05230281"},{"side":"bid","event_time":"2026-07-15T03:40:08.844609Z","price_level":"64529.3","new_quantity":"0"},{"side":"bid","event_time":"2026-07-15T03:40:08.844609Z","price_level":"64520.61","new_quantity":"0.001858"},{"side":"bid","event_time":"2026-07-15T03:40:08.844609Z","price_level":"64504.38","new_quantity":"0"},{"side":"offer","event_time":"2026-07-15T03:40:08.844609Z","price_level":"64592.45","new_quantity":"0"},{"side":"offer","event_time":"2026-07-15T03:40:08.844609Z","price_level":"64593.82","new_quantity":"0.11197002"},{"side":"offer","event_time":"2026-07-15T03:40:08.844609Z","price_level":"64596.21","new_quantity":"0.12378505"},{"side":"offer","event_time":"2026-07-15T03:40:08.844609Z","price_level":"64597.37","new_quantity":"0.02"},{"side":"offer","event_time":"2026-07-15T03:40:08.844609Z","price_level":"64597.39","new_quantity":"0.26777258"},{"side":"offer","event_time":"2026-07-15T03:40:08.844609Z","price_level":"64599.2","new_quantity":"0.03093532"},{"side":"offer","event_time":"2026-07-15T03:40:08.844609Z","price_level":"64600.35","new_quantity":"0.00098647"},{"side":"offer","event_time":"2026-07-15T03:40:08.844609Z","price_level":"64600.42","new_quantity":"0"},{"side":"offer","event_time":"2026-07-15T03:40:08.844609Z","price_level":"64600.54","new_quantity":"0"},{"side":"offer","event_time":"2026-07-15T03:40:08.844609Z","price_level":"64604.62","new_quantity":"0.201347"},{"side":"offer","event_time":"2026-07-15T03:40:08.844609Z","price_level":"64605.07","new_quantity":"0"},{"side":"offer","event_time":"2026-07-15T03:40:08.844609Z","price_level":"64613.25","new_quantity":"0.96509907"},{"side":"offer","event_time":"2026-07-15T03:40:08.844609Z","price_level":"64614","new_quantity":"1"},{"side":"offer","event_time":"2026-07-15T03:40:08.844609Z","price_level":"64615.13","new_quantity":"0.14"},{"side":"offer","event_time":"2026-07-15T03:40:08.844609Z","price_level":"64619.46","new_quantity":"0.39985498"},{"side":"offer","event_time":"2026-07-15T03:40:08.844609Z","price_level":"64621.67","new_quantity":"0.62912195"},{"side":"offer","event_time":"2026-07-15T03:40:08.844609Z","price_level":"64626.27","new_quantity":"0.08598854"},{"side":"offer","event_time":"2026-07-15T03:40:08.844609Z","price_level":"64626.28","new_quantity":"0"},{"side":"offer","event_time":"2026-07-15T03:40:08.844609Z","price_level":"64633.09","new_quantity":"0"},{"side":"offer","event_time":"2026-07-15T03:40:08.844609Z","price_level":"64638.77","new_quantity":"0.04195122"},{"side":"offer","event_time":"2026-07-15T03:40:08.844609Z","price_level":"64639.09","new_quantity":"0"},{"side":"offer","event_time":"2026-07-15T03:40:08.844609Z","price_level":"64647.38","new_quantity":"0.45857074"},{"side":"offer","event_time":"2026-07-15T03:40:08.844609Z","price_level":"64647.41","new_quantity":"0"},{"side":"offer","event_time":"2026-07-15T03:40:08.844609Z","price_level":"64651.76","new_quantity":"2.07823998"},{"side":"offer","event_time":"2026-07-15T03:40:08.844609Z","price_level":"64651.77","new_quantity":"2.08910114"},{"side":"offer","event_time":"2026-07-15T03:40:08.844609Z","price_level":"64651.78","new_quantity":"0"},{"side":"offer","event_time":"2026-07-15T03:40:08.844609Z","price_level":"64651.79","new_quantity":"0"},{"side":"offer","event_time":"2026-07-15T03:40:08.844609Z","price_level":"64814.27","new_quantity":"0"}]}]}
{"channel":"l2_data","timestamp":"2026-07-15T03:40:08.938300831Z","sequence_num":128,"events":[{"type":"update","product_id":"BTC-USD","updates":[{"side":"bid","event_time":"2026-07-15T03:40:08.885398Z","price_level":"64589.4","new_quantity":"0.14739836"},{"side":"bid","event_time":"2026-07-15T03:40:08.885398Z","price_level":"64567.49","new_quantity":"0.16493538"},{"side":"bid","event_time":"2026-07-15T03:40:08.885398Z","price_level":"64561.05","new_quantity":"0.41595477"},{"side":"bid","event_time":"2026-07-15T03:40:08.885398Z","price_level":"64560.26","new_quantity":"0.639526"},{"side":"bid","event_time":"2026-07-15T03:40:08.885398Z","price_level":"64522.25","new_quantity":"1.96543488"},{"side":"bid","event_time":"2026-07-15T03:40:08.885398Z","price_level":"64522.24","new_quantity":"1.40033782"},{"side":"bid","event_time":"2026-07-15T03:40:08.885398Z","price_level":"64522.23","new_quantity":"0"},{"side":"bid","event_time":"2026-07-15T03:40:08.885398Z","price_level":"64522.22","new_quantity":"0"},{"side":"offer","event_time":"2026-07-15T03:40:08.885398Z","price_level":"64600.35","new_quantity":"0"},{"side":"offer","event_time":"2026-07-15T03:40:08.885398Z","price_level":"64601.07","new_quantity":"0.00098647"},{"side":"offer","event_time":"2026-07-15T03:40:08.885398Z","price_level":"64613.25","new_quantity":"0.37688543"},{"side":"offer","event_time":"2026-07-15T03:40:08.885398Z","price_level":"64614","new_quantity":"0"},{"side":"offer","event_time":"2026-07-15T03:40:08.885398Z","price_level":"64615.25","new_quantity":"0.02"},{"side":"offer","event_time":"2026-07-15T03:40:08.885398Z","price_level":"64615.65","new_quantity":"0.04"},{"side":"offer","event_time":"2026-07-15T03:40:08.885398Z","price_level":"64647.36","new_quantity":"1.13920123"},{"side":"offer","event_time":"2026-07-15T03:40:08.885398Z","price_level":"64647.37","new_quantity":"1.4187037"},{"side":"offer","event_time":"2026-07-15T03:40:08.885398Z","price_level":"64647.39","new_quantity":"0"},{"side":"offer","event_time":"2026-07-15T03:40:08.885398Z","price_level":"64647.4","new_quantity":"0"}]}]}
{"channel":"l2_data","timestamp":"2026-07-15T03:40:08.982602492Z","sequence_num":129,"events":[{"type":"update","product_id":"BTC-USD","updates":[{"side":"bid","event_time":"2026-07-15T03:40:08.947159Z","price_level":"64589.4","new_quantity":"0.14739827"},{"side":"bid","event_time":"2026-07-15T03:40:08.947159Z","price_level":"64584","new_quantity":"0"},{"side":"bid","event_time":"2026-07-15T03:40:08.947159Z","price_level":"64567.75","new_quantity":"0.04204844"},{"side":"bid","event_time":"2026-07-15T03:40:08.947159Z","price_level":"64561.05","new_quantity":"0.0391649"},{"side":"bid","event_time":"2026-07-15T03:40:08.947159Z","price_level":"64560.26","new_quantity":"0"},{"side":"bid","event_time":"2026-07-15T03:40:08.947159Z","price_level":"64557.05","new_quantity":"0"},{"side":"bid","event_time":"2026-07-15T03:40:08.947159Z","price_level":"64555.29","new_quantity":"0.93159157"},{"side":"bid","event_time":"2026-07-15T03:40:08.947159Z","price_level":"64551.5","new_quantity":"0.43032546"},{"side":"bid","event_time":"2026-07-15T03:40:08.947159Z","price_level":"64551.49","new_quantity":"0.64001631"},{"side":"bid","event_time":"2026-07-15T03:40:08.947159Z","price_level":"64551.48","new_quantity":"0"},{"side":"bid","event_time":"2026-07-15T03:40:08.947159Z","price_level":"64551.47","new_quantity":"0"},{"side":"bid","event_time":"2026-07-15T03:40:08.947159Z","price_level":"64482.63","new_quantity":"0"},{"side":"offer","event_time":"2026-07-15T03:40:08.947159Z","price_level":"64591.24","new_quantity":"0.04204844"},{"side":"offer","event_time":"2026-07-15T03:40:08.947159Z","price_level":"64593.78","new_quantity":"0.00159977"},{"side":"offer","event_time":"2026-07-15T03:40:08.947159Z","price_level":"64593.79","new_quantity":"0.19384806"},{"side":"offer","event_time":"2026-07-15T03:40:08.947159Z","price_level":"64593.8","new_quantity":"0.12378505"},{"side":"offer","event_time":"2026-07-15T03:40:08.947159Z","price_level":"64593.81","new_quantity":"0"},{"side":"offer","event_time":"2026-07-15T03:40:08.947159Z","price_level":"64593.82","new_quantity":"0"},{"side":"offer","event_time":"2026-07-15T03:40:08.947159Z","price_level":"64600.88","new_quantity":"0.00098647"},{"side":"offer","event_time":"2026-07-15T03:40:08.947159Z","price_level":"64600.95","new_quantity":"0"},{"side":"offer","event_time":"2026-07-15T03:40:08.947159Z","price_level":"64601.07","new_quantity":"0"},{"side":"offer","event_time":"2026-07-15T03:40:08.947159Z","price_level":"64603.26","new_quantity":"0.1098434"},{"side":"offer","event_time":"2026-07-15T03:40:08.947159Z","price_level":"64604.62","new_quantity":"0.021789"},{"side":"offer","event_time":"2026-07-15T03:40:08.947159Z","price_level":"64610","new_quantity":"0.69804647"},{"side":"offer","event_time":"2026-07-15T03:40:08.947159Z","price_level":"64612.5","new_quantity":"1"},{"side":"offer","event_time":"2026-07-15T03:40:08.947159Z","price_level":"64647.35","new_quantity":"0.45857095"},{"side":"offer","event_time":"2026-07-15T03:40:08.947159Z","price_level":"64647.38","new_quantity":"0"},{"side":"offer","event_time":"2026-07-15T03:40:08.947159Z","price_level":"64651.74","new_quantity":"2.07824037"},{"side":"offer","event_time":"2026-07-15T03:40:08.947159Z","price_level":"64651.75","new_quantity":"2.08910179"},{"side":"offer","event_time":"2026-07-15T03:40:08.947159Z","price_level":"64651.76","new_quantity":"0"},{"side":"offer","event_time":"2026-07-15T03:40:08.947159Z","price_level":"64651.77","new_quantity":"0"},{"side":"offer","event_time":"2026-07-15T03:40:08.947159Z","price_level":"64676.38","new_quantity":"0"}]}]}
{"channel":"market_trades","timestamp":"2026-07-15T03:40:08.987304945Z","sequence_num":130,"events":[{"type":"update","trades":[{"product_id":"BTC-USD","trade_id":"1056309449","price":"64589.4","size":"0.00000009","time":"2026-07-15T03:40:08.922213Z","side":"BUY"}]}]}
{"channel":"l2_data","timestamp":"2026-07-15T03:40:09.032709209Z","sequence_num":131,"events":[{"type":"update","product_id":"BTC-USD","updates":[{"side":"bid","event_time":"2026-07-15T03:40:09.003595Z","price_level":"64586.67","new_quantity":"0.12386455"},{"side":"bid","event_time":"2026-07-15T03:40:09.003595Z","price_level":"64586.39","new_quantity":"0"},{"side":"bid","event_time":"2026-07-15T03:40:09.003595Z","price_level":"64585.5","new_quantity":"1"},{"side":"bid","event_time":"2026-07-15T03:40:09.003595Z","price_level":"64582.45","new_quantity":"0"},{"side":"bid","event_time":"2026-07-15T03:40:09.003595Z","price_level":"64573.54","new_quantity":"0.00772597"},{"side":"bid","event_time":"2026-07-15T03:40:09.003595Z","price_level":"64570.52","new_quantity":"0"},{"side":"bid","event_time":"2026-07-15T03:40:09.003595Z","price_level":"64561.46","new_quantity":"0.00104506"},{"side":"bid","event_time":"2026-07-15T03:40:09.003595Z","price_level":"64546.6","new_quantity":"0"},{"side":"bid","event_time":"2026-07-15T03:40:09.003595Z","price_level":"64540.15","new_quantity":"0"},{"side":"bid","event_time":"2026-07-15T03:40:09.003595Z","price_level":"64528.75","new_quantity":"0.86563436"},{"side":"bid","event_time":"2026-07-15T03:40:09.003595Z","price_level":"64528.54","new_quantity":"1.39473168"},{"side":"bid","event_time":"2026-07-15T03:40:09.003595Z","price_level":"64525.13","new_quantity":"0.00239977"},{"side":"bid","event_time":"2026-07-15T03:40:09.003595Z","price_level":"64522.27","new_quantity":"1.96543462"},{"side":"bid","event_time":"2026-07-15T03:40:09.003595Z","price_level":"64522.26","new_quantity":"1.40033739"},{"side":"bid","event_time":"2026-07-15T03:40:09.003595Z","price_level":"64522.25","new_quantity":"0"},{"side":"bid","event_time":"2026-07-15T03:40:09.003595Z","price_level":"64522.24","new_quantity":"0"},{"side":"bid","event_time":"2026-07-15T03:40:09.003595Z","price_level":"64508.35","new_quantity":"0"},{"side":"bid","event_time":"2026-07-15T03:40:09.003595Z","price_level":"64310.36","new_quantity":"0"},{"side":"bid","event_time":"2026-07-15T03:40:09.003595Z","price_level":"56515.73","new_quantity":"0.0132912"},{"side":"offer","event_time":"2026-07-15T03:40:09.003595Z","price_level":"64597.36","new_quantity":"0.00772597"},{"side":"offer","event_time":"2026-07-15T03:40:09.003595Z","price_level":"64597.64","new_quantity":"0"},{"side":"offer","event_time":"2026-07-15T03:40:09.003595Z","price_level":"64598.4","new_quantity":"0"},{"side":"offer","event_time":"2026-07-15T03:40:09.003595Z","price_level":"64600.81","new_quantity":"0"},{"side":"offer","event_time":"2026-07-15T03:40:09.003595Z","price_level":"64600.88","new_quantity":"0"},{"side":"offer","event_time":"2026-07-15T03:40:09.003595Z","price_level":"64605.42","new_quantity":"0.00098647"},{"side":"offer","event_time":"2026-07-15T03:40:09.003595Z","price_level":"64609.58","new_quantity":"0"},{"side":"offer","event_time":"2026-07-15T03:40:09.003595Z","price_level":"64614.64","new_quantity":"0"},{"side":"offer","event_time":"2026-07-15T03:40:09.003595Z","price_level":"64615.11","new_quantity":"0.00077412"},{"side":"offer","event_time":"2026-07-15T03:40:09.003595Z","price_level":"64629.53","new_quantity":"0.01916344"},{"side":"offer","event_time":"2026-07-15T03:40:09.003595Z","price_level":"64631.49","new_quantity":"0"},{"side":"offer","event_time":"2026-07-15T03:40:09.003595Z","price_level":"64634.08","new_quantity":"0.01841301"},{"side":"offer","event_time":"2026-07-15T03:40:09.003595Z","price_level":"64634.09","new_quantity":"0.02699174"},{"side":"offer","event_time":"2026-07-15T03:40:09.003595Z","price_level":"64635.18","new_quantity":"0"},{"side":"offer","event_time":"2026-07-15T03:40:09.003595Z","price_level":"64644.67","new_quantity":"0.00158694"},{"side":"offer","event_time":"2026-07-15T03:40:09.003595Z","price_level":"64644.75","new_quantity":"0.01462879"},{"side":"offer","event_time":"2026-07-15T03:40:09.003595Z","price_level":"64647.33","new_quantity":"1.13920174"},{"side":"offer","event_time":"2026-07-15T03:40:09.003595Z","price_level":"64647.34","new_quantity":"1.41870435"},{"side":"offer","event_time":"2026-07-15T03:40:09.003595Z","price_level":"64647.36","new_quantity":"0"},{"side":"offer","event_time":"2026-07-15T03:40:09.003595Z","price_level":"64647.37","new_quantity":"0"},{"side":"offer","event_time":"2026-07-15T03:40:09.003595Z","price_level":"64670.88","new_quantity":"0.01615943"}]}]}
{"channel":"l2_data","timestamp":"2026-07-15T03:40:09.164071719Z","sequence_num":132,"events":[{"type":"update","product_id":"BTC-USD","updates":[{"side":"bid","event_time":"2026-07-15T03:40:09.038786Z","price_level":"64586.68","new_quantity":"0.00159977"},{"side":"bid","event_time":"2026-07-15T03:40:09.038786Z","price_level":"64586.62","new_quantity":"0.02"},{"side":"bid","event_time":"2026-07-15T03:40:09.038786Z","price_level":"64583.81","new_quantity":"0.15483755"},{"side":"bid","event_time":"2026-07-15T03:40:09.038786Z","price_level":"64580.32","new_quantity":"0.000018"},{"side":"bid","event_time":"2026-07-15T03:40:09.038786Z","price_level":"64551.52","new_quantity":"0.43032535"},{"side":"bid","event_time":"2026-07-15T03:40:09.038786Z","price_level":"64551.51","new_quantity":"0.64001612"},{"side":"bid","event_time":"2026-07-15T03:40:09.038786Z","price_level":"64551.5","new_quantity":"0"},{"side":"bid","event_time":"2026-07-15T03:40:09.038786Z","price_level":"64551.49","new_quantity":"0"},{"side":"offer","event_time":"2026-07-15T03:40:09.038786Z","price_level":"64591.12","new_quantity":"0.0015533"},{"side":"offer","event_time":"2026-07-15T03:40:09.038786Z","price_level":"64594.31","new_quantity":"0.0015533"},{"side":"offer","event_time":"2026-07-15T03:40:09.038786Z","price_level":"64597.39","new_quantity":"0.17966393"},{"side":"offer","event_time":"2026-07-15T03:40:09.038786Z","price_level":"64597.5","new_quantity":"0.0015533"},{"side":"offer","event_time":"2026-07-15T03:40:09.038786Z","price_level":"64597.8","new_quantity":"0.12384324"},{"side":"offer","event_time":"2026-07-15T03:40:09.038786Z","price_level":"64599.22","new_quantity":"0"},{"side":"offer","event_time":"2026-07-15T03:40:09.038786Z","price_level":"64600.16","new_quantity":"0.15667033"},{"side":"offer","event_time":"2026-07-15T03:40:09.038786Z","price_level":"64600.69","new_quantity":"0.0015533"},{"side":"offer","event_time":"2026-07-15T03:40:09.038786Z","price_level":"64601.7","new_quantity":"0.1547947"},{"side":"offer","event_time":"2026-07-15T03:40:09.038786Z","price_level":"64603.26","new_quantity":"0.1098434"},{"side":"offer","event_time":"2026-07-15T03:40:09.038786Z","price_level":"64603.88","new_quantity":"0.0015533"},{"side":"offer","event_time":"2026-07-15T03:40:09.038786Z","price_level":"64604.62","new_quantity":"0.021789"},{"side":"offer","event_time":"2026-07-15T03:40:09.038786Z","price_level":"64607.07","new_quantity":"0.12533835"},{"side":"offer","event_time":"2026-07-15T03:40:09.038786Z","price_level":"64610.26","new_quantity":"0.0015533"},{"side":"offer","event_time":"2026-07-15T03:40:09.038786Z","price_level":"64613.45","new_quantity":"0.0015533"},{"side":"offer","event_time":"2026-07-15T03:40:09.038786Z","price_level":"64616.64","new_quantity":"0.0015533"},{"side":"offer","event_time":"2026-07-15T03:40:09.038786Z","price_level":"64619.83","new_quantity":"0.0015533"},{"side":"offer","event_time":"2026-07-15T03:40:09.038786Z","price_level":"64623.02","new_quantity":"0.0015533"},{"side":"offer","event_time":"2026-07-15T03:40:09.038786Z","price_level":"64626.21","new_quantity":"0.0015533"},{"side":"offer","event_time":"2026-07-15T03:40:09.038786Z","price_level":"64629.4","new_quantity":"0.0015533"},{"side":"offer","event_time":"2026-07-15T03:40:09.038786Z","price_level":"64632.59","new_quantity":"0.0015533"},{"side":"offer","event_time":"2026-07-15T03:40:09.038786Z","price_level":"64635.78","new_quantity":"0.0015533"},{"side":"offer","event_time":"2026-07-15T03:40:09.038786Z","price_level":"64647.32","new_quantity":"0.45857116"},{"side":"offer","event_time":"2026-07-15T03:40:09.038786Z","price_level":"64647.35","new_quantity":"0"},{"side":"offer","event_time":"2026-07-15T03:40:09.038786Z","price_level":"64651.72","new_quantity":"2.07916807"},{"side":"offer","event_time":"2026-07-15T03:40:09.038786Z","price_level":"64651.73","new_quantity":"2.09065573"},{"side":"offer","event_time":"2026-07-15T03:40:09.038786Z","price_level":"64651.74","new_quantity":"0"},{"side":"offer","event_time":"2026-07-15T03:40:09.038786Z","price_level":"64651.75","new_quantity":"0"},{"side":"offer","event_time":"2026-07-15T03:40:09.038786Z","price_level":"64672.54","new_quantity":"0.01331"}]}]}
{"channel":"l2_data","timestamp":"2026-07-15T03:40:09.166268439Z","sequence_num":133,"events":[{"type":"update","product_id":"BTC-USD","updates":[{"side":"offer","event_time":"2026-07-15T03:40:09.056699Z","price_level":"64598.72","new_quantity":"0.000018"}]}]}
{"channel":"l2_data","timestamp":"2026-07-15T03:40:09.18263314Z","sequence_num":134,"events":[{"type":"update","product_id":"BTC-USD","updates":[{"side":"bid","event_time":"2026-07-15T03:40:09.137735Z","price_level":"64570.74","new_quantity":"0.00583"},{"side":"bid","event_time":"2026-07-15T03:40:09.137735Z","price_level":"64563.72","new_quantity":"0"},{"side":"bid","event_time":"2026-07-15T03:40:09.137735Z","price_level":"64561.05","new_quantity":"0.39209566"},{"side":"bid","event_time":"2026-07-15T03:40:09.137735Z","price_level":"64560.16","new_quantity":"0.599561"},{"side":"bid","event_time":"2026-07-15T03:40:09.137735Z","price_level":"64557.02","new_quantity":"0.93156661"},{"side":"bid","event_time":"2026-07-15T03:40:09.137735Z","price_level":"64555.29","new_quantity":"0"},{"side":"bid","event_time":"2026-07-15T03:40:09.137735Z","price_level":"64546.61","new_quantity":"0.00077406"},{"side":"bid","event_time":"2026-07-15T03:40:09.137735Z","price_level":"64541.57","new_quantity":"0"},{"side":"bid","event_time":"2026-07-15T03:40:09.137735Z","price_level":"64522.29","new_quantity":"1.96543437"},{"side":"bid","event_time":"2026-07-15T03:40:09.137735Z","price_level":"64522.28","new_quantity":"1.40033696"},{"side":"bid","event_time":"2026-07-15T03:40:09.137735Z","price_level":"64522.27","new_quantity":"0"},{"side":"bid","event_time":"2026-07-15T03:40:09.137735Z","price_level":"64522.26","new_quantity":"0"},{"side":"bid","event_time":"2026-07-15T03:40:09.137735Z","price_level":"64502.56","new_quantity":"0"},{"side":"bid","event_time":"2026-07-15T03:40:09.137735Z","price_level":"64490.95","new_quantity":"0"},{"side":"bid","event_time":"2026-07-15T03:40:09.137735Z","price_level":"64489.76","new_quantity":"0.04985737"},{"side":"bid","event_time":"2026-07-15T03:40:09.137735Z","price_level":"64468.3","new_quantity":"0"},{"side":"bid","event_time":"2026-07-15T03:40:09.137735Z","price_level":"64452.4","new_quantity":"0.03431578"},{"side":"bid","event_time":"2026-07-15T03:40:09.137735Z","price_level":"63284.09","new_quantity":"0.00583"},{"side":"bid","event_time":"2026-07-15T03:40:09.137735Z","price_level":"63277.14","new_quantity":"0"},{"side":"bid","event_time":"2026-07-15T03:40:09.137735Z","price_level":"56515.73","new_quantity":"0"},{"side":"offer","event_time":"2026-07-15T03:40:09.137735Z","price_level":"64589.41","new_quantity":"0.01726217"},{"side":"offer","event_time":"2026-07-15T03:40:09.137735Z","price_level":"64591.24","new_quantity":"0"},{"side":"offer","event_time":"2026-07-15T03:40:09.137735Z","price_level":"64591.89","new_quantity":"0.01648432"},{"side":"offer","event_time":"2026-07-15T03:40:09.137735Z","price_level":"64593.19","new_quantity":"0.01648432"},{"side":"offer","event_time":"2026-07-15T03:40:09.137735Z","price_level":"64594.48","new_quantity":"0.01648432"},{"side":"offer","event_time":"2026-07-15T03:40:09.137735Z","price_level":"64610","new_quantity":"0.12954907"},{"side":"offer","event_time":"2026-07-15T03:40:09.137735Z","price_level":"64612.5","new_quantity":"0"},{"side":"offer","event_time":"2026-07-15T03:40:09.137735Z","price_level":"64615.13","new_quantity":"0.02"},{"side":"offer","event_time":"2026-07-15T03:40:09.137735Z","price_level":"64644.73","new_quantity":"0.85573395"},{"side":"offer","event_time":"2026-07-15T03:40:09.137735Z","price_level":"64644.74","new_quantity":"1.41876141"},{"side":"offer","event_time":"2026-07-15T03:40:09.137735Z","price_level":"64647.31","new_quantity":"0.29223537"},{"side":"offer","event_time":"2026-07-15T03:40:09.137735Z","price_level":"64647.33","new_quantity":"0"},{"side":"offer","event_time":"2026-07-15T03:40:09.137735Z","price_level":"64647.34","new_quantity":"0"},{"side":"offer","event_time":"2026-07-15T03:40:09.137735Z","price_level":"64650.9","new_quantity":"0.01615943"},{"side":"offer","event_time":"2026-07-15T03:40:09.137735Z","price_level":"64665.43","new_quantity":"0.01615943"},{"side":"offer","event_time":"2026-07-15T03:40:09.137735Z","price_level":"64683.53","new_quantity":"0.0479877"},{"side":"offer","event_time":"2026-07-15T03:40:09.137735Z","price_level":"65900.53","new_quantity":"0.00583"}]}]}
{"channel":"market_trades","timestamp":"2026-07-15T03:40:09.185097061Z","sequence_num":135,"events":[{"type":"update","trades":[{"product_id":"BTC-USD","trade_id":"1056309452","price":"64589.41","size":"0.0016617","time":"2026-07-15T03:40:09.150399Z","side":"SELL"},{"product_id":"BTC-USD","trade_id":"1056309451","price":"64589.41","size":"0.00239203","time":"2026-07-15T03:40:09.150399Z","side":"SELL"},{"product_id":"BTC-USD","trade_id":"1056309450","price":"64589.41","size":"0.00038328","time":"2026-07-15T03:40:09.150399Z","side":"SELL"}]}]}
