{"channel":"l2_data","timestamp":"2026-07-16T20:29:10.821443317Z","sequence_num":373,"events":[{"type":"update","product_id":"BTC-USD","updates":[{"side":"bid","event_time":"2026-07-16T20:29:10.708505Z","price_level":"64135","new_quantity":"0.01083644"},{"side":"bid","event_time":"2026-07-16T20:29:10.708505Z","price_level":"64128.45","new_quantity":"0.12474961"},{"side":"bid","event_time":"2026-07-16T20:29:10.708505Z","price_level":"64123.62","new_quantity":"0"},{"side":"bid","event_time":"2026-07-16T20:29:10.708505Z","price_level":"64110","new_quantity":"1.01"},{"side":"bid","event_time":"2026-07-16T20:29:10.708505Z","price_level":"64109","new_quantity":"0"},{"side":"bid","event_time":"2026-07-16T20:29:10.708505Z","price_level":"64087","new_quantity":"0"},{"side":"bid","event_time":"2026-07-16T20:29:10.708505Z","price_level":"56118.13","new_quantity":"0"},{"side":"offer","event_time":"2026-07-16T20:29:10.708505Z","price_level":"64137.49","new_quantity":"0.31190852"},{"side":"offer","event_time":"2026-07-16T20:29:10.708505Z","price_level":"64145.64","new_quantity":"0.83849954"},{"side":"offer","event_time":"2026-07-16T20:29:10.708505Z","price_level":"64145.65","new_quantity":"0"},{"side":"offer","event_time":"2026-07-16T20:29:10.708505Z","price_level":"64148.19","new_quantity":"0.65494979"},{"side":"offer","event_time":"2026-07-16T20:29:10.708505Z","price_level":"64149.74","new_quantity":"0.00009743"},{"side":"offer","event_time":"2026-07-16T20:29:10.708505Z","price_level":"64151.02","new_quantity":"0.24138456"},{"side":"offer","event_time":"2026-07-16T20:29:10.708505Z","price_level":"64176.08","new_quantity":"0.48578873"},{"side":"offer","event_time":"2026-07-16T20:29:10.708505Z","price_level":"64177.24","new_quantity":"0"}]}]}
{"channel":"l2_data","timestamp":"2026-07-16T20:29:10.822546032Z","sequence_num":374,"events":[{"type":"update","product_id":"BTC-USD","updates":[{"side":"bid","event_time":"2026-07-16T20:29:10.746445Z","price_level":"64135","new_quantity":"0.01083623"},{"side":"bid","event_time":"2026-07-16T20:29:10.746445Z","price_level":"64128.46","new_quantity":"0.02"},{"side":"bid","event_time":"2026-07-16T20:29:10.746445Z","price_level":"64124.73","new_quantity":"0"},{"side":"bid","event_time":"2026-07-16T20:29:10.746445Z","price_level":"64124.72","new_quantity":"0.01559176"},{"side":"bid","event_time":"2026-07-16T20:29:10.746445Z","price_level":"64107.36","new_quantity":"0"},{"side":"bid","event_time":"2026-07-16T20:29:10.746445Z","price_level":"64104.91","new_quantity":"0.59591008"},{"side":"bid","event_time":"2026-07-16T20:29:10.746445Z","price_level":"64104.84","new_quantity":"0.06853315"},{"side":"offer","event_time":"2026-07-16T20:29:10.746445Z","price_level":"64138.77","new_quantity":"0"},{"side":"offer","event_time":"2026-07-16T20:29:10.746445Z","price_level":"64140.39","new_quantity":"0"},{"side":"offer","event_time":"2026-07-16T20:29:10.746445Z","price_level":"64142.55","new_quantity":"0"},{"side":"offer","event_time":"2026-07-16T20:29:10.746445Z","price_level":"64191.81","new_quantity":"2.12507492"},{"side":"offer","event_time":"2026-07-16T20:29:10.746445Z","price_level":"64192.99","new_quantity":"0"}]}]}
{"channel":"l2_data","timestamp":"2026-07-16T20:29:10.830856554Z","sequence_num":375,"events":[{"type":"update","product_id":"BTC-USD","updates":[{"side":"bid","event_time":"2026-07-16T20:29:10.803914Z","price_level":"64133.71","new_quantity":"0.00779621"},{"side":"bid","event_time":"2026-07-16T20:29:10.803914Z","price_level":"64128.65","new_quantity":"0.02"},{"side":"bid","event_time":"2026-07-16T20:29:10.803914Z","price_level":"64096.51","new_quantity":"0.0005"},{"side":"bid","event_time":"2026-07-16T20:29:10.803914Z","price_level":"64091.06","new_quantity":"0.00077953"},{"side":"offer","event_time":"2026-07-16T20:29:10.803914Z","price_level":"64135.01","new_quantity":"1.05562534"},{"side":"offer","event_time":"2026-07-16T20:29:10.803914Z","price_level":"64136.3","new_quantity":"0.0077959"},{"side":"offer","event_time":"2026-07-16T20:29:10.803914Z","price_level":"64136.62","new_quantity":"0.00545723"},{"side":"offer","event_time":"2026-07-16T20:29:10.803914Z","price_level":"64138.78","new_quantity":"0.00682154"},{"side":"offer","event_time":"2026-07-16T20:29:10.803914Z","price_level":"64158.46","new_quantity":"0.31190852"},{"side":"offer","event_time":"2026-07-16T20:29:10.803914Z","price_level":"64172.25","new_quantity":"0.32027682"},{"side":"offer","event_time":"2026-07-16T20:29:10.803914Z","price_level":"64173.62","new_quantity":"0"}]}]}
{"channel":"l2_data","timestamp":"2026-07-16T20:29:10.884570157Z","sequence_num":376,"events":[{"type":"update","product_id":"BTC-USD","updates":[{"side":"bid","event_time":"2026-07-16T20:29:10.857539Z","price_level":"64125.4","new_quantity":"0.01559176"},{"side":"bid","event_time":"2026-07-16T20:29:10.857539Z","price_level":"64124.72","new_quantity":"0"},{"side":"bid","event_time":"2026-07-16T20:29:10.857539Z","price_level":"64123.62","new_quantity":"0.04"},{"side":"bid","event_time":"2026-07-16T20:29:10.857539Z","price_level":"64121.58","new_quantity":"0.66028"},{"side":"bid","event_time":"2026-07-16T20:29:10.857539Z","price_level":"64109","new_quantity":"1"},{"side":"bid","event_time":"2026-07-16T20:29:10.857539Z","price_level":"64106.76","new_quantity":"0.59589288"},{"side":"bid","event_time":"2026-07-16T20:29:10.857539Z","price_level":"64104.91","new_quantity":"0"},{"side":"offer","event_time":"2026-07-16T20:29:10.857539Z","price_level":"64778.6","new_quantity":"0"}]}]}
{"channel":"l2_data","timestamp":"2026-07-16T20:29:10.927085783Z","sequence_num":377,"events":[{"type":"update","product_id":"BTC-USD","updates":[{"side":"bid","event_time":"2026-07-16T20:29:10.895965Z","price_level":"64121.58","new_quantity":"0"},{"side":"bid","event_time":"2026-07-16T20:29:10.895965Z","price_level":"56118.13","new_quantity":"0.01337205"}]}]}
{"channel":"l2_data","timestamp":"2026-07-16T20:29:10.980401481Z","sequence_num":378,"events":[{"type":"update","product_id":"BTC-USD","updates":[{"side":"bid","event_time":"2026-07-16T20:29:10.947008Z","price_level":"64135","new_quantity":"0.01083614"},{"side":"offer","event_time":"2026-07-16T20:29:10.947008Z","price_level":"64158.48","new_quantity":"0.01083623"}]}]}
{"channel":"l2_data","timestamp":"2026-07-16T20:29:11.032626948Z","sequence_num":379,"events":[{"type":"update","product_id":"BTC-USD","updates":[{"side":"bid","event_time":"2026-07-16T20:29:11.013578Z","price_level":"56118.13","new_quantity":"0"},{"side":"offer","event_time":"2026-07-16T20:29:11.013578Z","price_level":"64149.51","new_quantity":"0"}]}]}
{"channel":"l2_data","timestamp":"2026-07-16T20:29:11.091469778Z","sequence_num":380,"events":[{"type":"update","product_id":"BTC-USD","updates":[{"side":"bid","event_time":"2026-07-16T20:29:11.05199Z","price_level":"64096.8","new_quantity":"0.02937848"},{"side":"bid","event_time":"2026-07-16T20:29:11.05199Z","price_level":"64094.24","new_quantity":"0.0332348"},{"side":"bid","event_time":"2026-07-16T20:29:11.05199Z","price_level":"64090.39","new_quantity":"0.02522725"},{"side":"offer","event_time":"2026-07-16T20:29:11.05199Z","price_level":"64135.01","new_quantity":"1.02664437"},{"side":"offer","event_time":"2026-07-16T20:29:11.05199Z","price_level":"64145","new_quantity":"0.01"},{"side":"offer","event_time":"2026-07-16T20:29:11.05199Z","price_level":"64148.55","new_quantity":"0"},{"side":"offer","event_time":"2026-07-16T20:29:11.05199Z","price_level":"64152.29","new_quantity":"1.14437056"},{"side":"offer","event_time":"2026-07-16T20:29:11.05199Z","price_level":"64176.06","new_quantity":"0.48578888"},{"side":"offer","event_time":"2026-07-16T20:29:11.05199Z","price_level":"64176.07","new_quantity":"0"},{"side":"offer","event_time":"2026-07-16T20:29:11.05199Z","price_level":"64176.08","new_quantity":"0"},{"side":"offer","event_time":"2026-07-16T20:29:11.05199Z","price_level":"64778.34","new_quantity":"0.03890047"}]}]}
{"channel":"l2_data","timestamp":"2026-07-16T20:29:11.131960061Z","sequence_num":381,"events":[{"type":"update","product_id":"BTC-USD","updates":[{"side":"bid","event_time":"2026-07-16T20:29:11.100747Z","price_level":"64135","new_quantity":"0.0108361"},{"side":"bid","event_time":"2026-07-16T20:29:11.100747Z","price_level":"64121.7","new_quantity":"0.589349"},{"side":"offer","event_time":"2026-07-16T20:29:11.100747Z","price_level":"64158.48","new_quantity":"0"}]}]}
{"channel":"heartbeats","timestamp":"2026-07-16T20:29:11.163420698Z","sequence_num":382,"events":[{"current_time":"2026-07-16 20:29:11.162886223 +0000 UTC m=+75515.317713268","heartbeat_counter":75515}]}
{"channel":"l2_data","timestamp":"2026-07-16T20:29:11.175523549Z","sequence_num":383,"events":[{"type":"update","product_id":"BTC-USD","updates":[{"side":"bid","event_time":"2026-07-16T20:29:11.153145Z","price_level":"64128.45","new_quantity":"0"},{"side":"bid","event_time":"2026-07-16T20:29:11.153145Z","price_level":"64121.7","new_quantity":"0"}]}]}
{"channel":"l2_data","timestamp":"2026-07-16T20:29:11.229850028Z","sequence_num":384,"events":[{"type":"update","product_id":"BTC-USD","updates":[{"side":"bid","event_time":"2026-07-16T20:29:11.1938Z","price_level":"64129.36","new_quantity":"0.02"},{"side":"bid","event_time":"2026-07-16T20:29:11.1938Z","price_level":"64129.35","new_quantity":"0.12474786"},{"side":"bid","event_time":"2026-07-16T20:29:11.1938Z","price_level":"56118.13","new_quantity":"0.01337205"},{"side":"offer","event_time":"2026-07-16T20:29:11.1938Z","price_level":"64135.59","new_quantity":"0.00234575"},{"side":"offer","event_time":"2026-07-16T20:29:11.1938Z","price_level":"64135.66","new_quantity":"0"}]}]}
{"channel":"l2_data","timestamp":"2026-07-16T20:29:11.281996295Z","sequence_num":385,"events":[{"type":"update","product_id":"BTC-USD","updates":[{"side":"bid","event_time":"2026-07-16T20:29:11.245937Z","price_level":"64121.3","new_quantity":"0.07412"},{"side":"offer","event_time":"2026-07-16T20:29:11.245937Z","price_level":"64158.48","new_quantity":"0.0108361"}]}]}
{"channel":"l2_data","timestamp":"2026-07-16T20:29:11.329838154Z","sequence_num":386,"events":[{"type":"update","product_id":"BTC-USD","updates":[{"side":"bid","event_time":"2026-07-16T20:29:11.298491Z","price_level":"64125.4","new_quantity":"0"},{"side":"bid","event_time":"2026-07-16T20:29:11.298491Z","price_level":"64124.83","new_quantity":"0.01559176"},{"side":"bid","event_time":"2026-07-16T20:29:11.298491Z","price_level":"64109","new_quantity":"0"},{"side":"bid","event_time":"2026-07-16T20:29:11.298491Z","price_level":"56118.13","new_quantity":"0"},{"side":"offer","event_time":"2026-07-16T20:29:11.298491Z","price_level":"64148.21","new_quantity":"0.00009743"},{"side":"offer","event_time":"2026-07-16T20:29:11.298491Z","price_level":"64149.18","new_quantity":"0.00779433"}]}]}
{"channel":"l2_data","timestamp":"2026-07-16T20:29:11.375267954Z","sequence_num":387,"events":[{"type":"update","product_id":"BTC-USD","updates":[{"side":"bid","event_time":"2026-07-16T20:29:11.358758Z","price_level":"64124.83","new_quantity":"0"},{"side":"bid","event_time":"2026-07-16T20:29:11.358758Z","price_level":"64118.26","new_quantity":"0"}]}]}
{"channel":"l2_data","timestamp":"2026-07-16T20:29:11.429992862Z","sequence_num":388,"events":[{"type":"update","product_id":"BTC-USD","updates":[{"side":"bid","event_time":"2026-07-16T20:29:11.408323Z","price_level":"64124.82","new_quantity":"0.01559176"},{"side":"bid","event_time":"2026-07-16T20:29:11.408323Z","price_level":"64120.95","new_quantity":"0.0007796"},{"side":"bid","event_time":"2026-07-16T20:29:11.408323Z","price_level":"64108.67","new_quantity":"0"},{"side":"bid","event_time":"2026-07-16T20:29:11.408323Z","price_level":"64106.78","new_quantity":"0.5958927"},{"side":"bid","event_time":"2026-07-16T20:29:11.408323Z","price_level":"64106.77","new_quantity":"0.65498397"},{"side":"bid","event_time":"2026-07-16T20:29:11.408323Z","price_level":"64106.76","new_quantity":"0"},{"side":"bid","event_time":"2026-07-16T20:29:11.408323Z","price_level":"63495.85","new_quantity":"0"},{"side":"offer","event_time":"2026-07-16T20:29:11.408323Z","price_level":"64158.48","new_quantity":"0"},{"side":"offer","event_time":"2026-07-16T20:29:11.408323Z","price_level":"64353.5","new_quantity":"0"}]}]}
{"channel":"l2_data","timestamp":"2026-07-16T20:29:11.481500952Z","sequence_num":389,"events":[{"type":"update","product_id":"BTC-USD","updates":[{"side":"bid","event_time":"2026-07-16T20:29:11.458022Z","price_level":"64128.46","new_quantity":"0"},{"side":"bid","event_time":"2026-07-16T20:29:11.458022Z","price_level":"64125.4","new_quantity":"0.01559176"},{"side":"bid","event_time":"2026-07-16T20:29:11.458022Z","price_level":"64124.82","new_quantity":"0"},{"side":"bid","event_time":"2026-07-16T20:29:11.458022Z","price_level":"64109","new_quantity":"1"},{"side":"bid","event_time":"2026-07-16T20:29:11.458022Z","price_level":"64092.2","new_quantity":"0"},{"side":"offer","event_time":"2026-07-16T20:29:11.458022Z","price_level":"64142.58","new_quantity":"0.5861196"},{"side":"offer","event_time":"2026-07-16T20:29:11.458022Z","price_level":"64142.92","new_quantity":"0.65499535"},{"side":"offer","event_time":"2026-07-16T20:29:11.458022Z","price_level":"64145.64","new_quantity":"0.51309237"},{"side":"offer","event_time":"2026-07-16T20:29:11.458022Z","price_level":"64148.19","new_quantity":"0"}]}]}
{"channel":"l2_data","timestamp":"2026-07-16T20:29:11.529901575Z","sequence_num":390,"events":[{"type":"update","product_id":"BTC-USD","updates":[{"side":"bid","event_time":"2026-07-16T20:29:11.507145Z","price_level":"64130.2","new_quantity":"0.02"},{"side":"bid","event_time":"2026-07-16T20:29:11.507145Z","price_level":"64128.33","new_quantity":"0"},{"side":"bid","event_time":"2026-07-16T20:29:11.507145Z","price_level":"64123.27","new_quantity":"0.04216256"},{"side":"bid","event_time":"2026-07-16T20:29:11.507145Z","price_level":"64106.77","new_quantity":"0"},{"side":"bid","event_time":"2026-07-16T20:29:11.507145Z","price_level":"64104.91","new_quantity":"0.65500707"},{"side":"bid","event_time":"2026-07-16T20:29:11.507145Z","price_level":"56118.13","new_quantity":"0.01337205"},{"side":"offer","event_time":"2026-07-16T20:29:11.507145Z","price_level":"64365.35","new_quantity":"0.00583"},{"side":"offer","event_time":"2026-07-16T20:29:11.507145Z","price_level":"65651.93","new_quantity":"0.00583"}]}]}
{"channel":"l2_data","timestamp":"2026-07-16T20:29:11.586503924Z","sequence_num":391,"events":[{"type":"update","product_id":"BTC-USD","updates":[{"side":"bid","event_time":"2026-07-16T20:29:11.552519Z","price_level":"64116.86","new_quantity":"0.05674613"},{"side":"bid","event_time":"2026-07-16T20:29:11.552519Z","price_level":"64096.8","new_quantity":"0"},{"side":"bid","event_time":"2026-07-16T20:29:11.552519Z","price_level":"64094.24","new_quantity":"0"},{"side":"bid","event_time":"2026-07-16T20:29:11.552519Z","price_level":"64090.39","new_quantity":"0"},{"side":"offer","event_time":"2026-07-16T20:29:11.552519Z","price_level":"64135.52","new_quantity":"0.00234575"},{"side":"offer","event_time":"2026-07-16T20:29:11.552519Z","price_level":"64135.59","new_quantity":"0"},{"side":"offer","event_time":"2026-07-16T20:29:11.552519Z","price_level":"64151.03","new_quantity":"0.001545"},{"side":"offer","event_time":"2026-07-16T20:29:11.552519Z","price_level":"64158.48","new_quantity":"0.0108361"},{"side":"offer","event_time":"2026-07-16T20:29:11.552519Z","price_level":"64177.31","new_quantity":"0.05785906"},{"side":"offer","event_time":"2026-07-16T20:29:11.552519Z","price_level":"64365.34","new_quantity":"0.00583"},{"side":"offer","event_time":"2026-07-16T20:29:11.552519Z","price_level":"64365.95","new_quantity":"0"},{"side":"offer","event_time":"2026-07-16T20:29:11.552519Z","price_level":"65651.93","new_quantity":"0"}]}]}
{"channel":"l2_data","timestamp":"2026-07-16T20:29:11.631542266Z","sequence_num":392,"events":[{"type":"update","product_id":"BTC-USD","updates":[{"side":"bid","event_time":"2026-07-16T20:29:11.608119Z","price_level":"64132.36","new_quantity":"0"},{"side":"bid","event_time":"2026-07-16T20:29:11.608119Z","price_level":"64128.59","new_quantity":"0.00779683"},{"side":"bid","event_time":"2026-07-16T20:29:11.608119Z","price_level":"64121.57","new_quantity":"0"},{"side":"bid","event_time":"2026-07-16T20:29:11.608119Z","price_level":"64106.78","new_quantity":"0"},{"side":"bid","event_time":"2026-07-16T20:29:11.608119Z","price_level":"64104.92","new_quantity":"0.59590999"},{"side":"bid","event_time":"2026-07-16T20:29:11.608119Z","price_level":"63495.6","new_quantity":"0.03937932"},{"side":"bid","event_time":"2026-07-16T20:29:11.608119Z","price_level":"56118.13","new_quantity":"0"},{"side":"offer","event_time":"2026-07-16T20:29:11.608119Z","price_level":"64135.01","new_quantity":"1.02649002"},{"side":"offer","event_time":"2026-07-16T20:29:11.608119Z","price_level":"64150.61","new_quantity":"0.00896328"},{"side":"offer","event_time":"2026-07-16T20:29:11.608119Z","price_level":"64365.35","new_quantity":"0"},{"side":"offer","event_time":"2026-07-16T20:29:11.608119Z","price_level":"64794.94","new_quantity":"0.00583"}]}]}
{"channel":"l2_data","timestamp":"2026-07-16T20:29:11.680565082Z","sequence_num":393,"events":[{"type":"update","product_id":"BTC-USD","updates":[{"side":"bid","event_time":"2026-07-16T20:29:11.639466Z","price_level":"64130.2","new_quantity":"0"},{"side":"bid","event_time":"2026-07-16T20:29:11.639466Z","price_level":"64130.19","new_quantity":"0"},{"side":"bid","event_time":"2026-07-16T20:29:11.639466Z","price_level":"64128.43","new_quantity":"0"},{"side":"bid","event_time":"2026-07-16T20:29:11.639466Z","price_level":"64074.38","new_quantity":"0"},{"side":"bid","event_time":"2026-07-16T20:29:11.639466Z","price_level":"64070.13","new_quantity":"1.41596236"},{"side":"offer","event_time":"2026-07-16T20:29:11.639466Z","price_level":"64149.42","new_quantity":"0"},{"side":"offer","event_time":"2026-07-16T20:29:11.639466Z","price_level":"64182.45","new_quantity":"0.00077952"},{"side":"offer","event_time":"2026-07-16T20:29:11.639466Z","price_level":"64183.25","new_quantity":"0"}]}]}
{"channel":"l2_data","timestamp":"2026-07-16T20:29:11.731646069Z","sequence_num":394,"events":[{"type":"update","product_id":"BTC-USD","updates":[{"side":"bid","event_time":"2026-07-16T20:29:11.706447Z","price_level":"64135","new_quantity":"0.01504404"},{"side":"bid","event_time":"2026-07-16T20:29:11.706447Z","price_level":"64130.19","new_quantity":"0.00779664"},{"side":"offer","event_time":"2026-07-16T20:29:11.706447Z","price_level":"64149.01","new_quantity":"0.00896351"},{"side":"offer","event_time":"2026-07-16T20:29:11.706447Z","price_level":"64158.48","new_quantity":"0"},{"side":"offer","event_time":"2026-07-16T20:29:11.706447Z","price_level":"64580.06","new_quantity":"0.00583"},{"side":"offer","event_time":"2026-07-16T20:29:11.706447Z","price_level":"64795.1","new_quantity":"0"}]}]}
{"channel":"l2_data","timestamp":"2026-07-16T20:29:11.7955954Z","sequence_num":395,"events":[{"type":"update","product_id":"BTC-USD","updates":[{"side":"bid","event_time":"2026-07-16T20:29:11.750493Z","price_level":"64128.6","new_quantity":"0.02"},{"side":"bid","event_time":"2026-07-16T20:29:11.750493Z","price_level":"64074.38","new_quantity":"1.41586844"},{"side":"bid","event_time":"2026-07-16T20:29:11.750493Z","price_level":"64070.13","new_quantity":"0"},{"side":"offer","event_time":"2026-07-16T20:29:11.750493Z","price_level":"64149.32","new_quantity":"0.00009743"},{"side":"offer","event_time":"2026-07-16T20:29:11.750493Z","price_level":"64149.74","new_quantity":"0"},{"side":"offer","event_time":"2026-07-16T20:29:11.750493Z","price_level":"64150.61","new_quantity":"0.01675744"},{"side":"offer","event_time":"2026-07-16T20:29:11.750493Z","price_level":"64151.02","new_quantity":"0.23359045"}]}]}
{"channel":"l2_data","timestamp":"2026-07-16T20:29:11.829853483Z","sequence_num":396,"events":[{"type":"update","product_id":"BTC-USD","updates":[{"side":"bid","event_time":"2026-07-16T20:29:11.793969Z","price_level":"64135","new_quantity":"0.01504397"},{"side":"bid","event_time":"2026-07-16T20:29:11.793969Z","price_level":"64134.6","new_quantity":"0.00067224"},{"side":"bid","event_time":"2026-07-16T20:29:11.793969Z","price_level":"64109","new_quantity":"0"},{"side":"bid","event_time":"2026-07-16T20:29:11.793969Z","price_level":"56118.13","new_quantity":"0.01337205"},{"side":"offer","event_time":"2026-07-16T20:29:11.793969Z","price_level":"64135.44","new_quantity":"0.00234575"},{"side":"offer","event_time":"2026-07-16T20:29:11.793969Z","price_level":"64135.52","new_quantity":"0"}]}]}
{"channel":"l2_data","timestamp":"2026-07-16T20:29:11.875393497Z","sequence_num":397,"events":[{"type":"update","product_id":"BTC-USD","updates":[{"side":"bid","event_time":"2026-07-16T20:29:11.831045Z","price_level":"64135","new_quantity":"0.01083603"}]}]}
{"channel":"l2_data","timestamp":"2026-07-16T20:29:11.930501016Z","sequence_num":398,"events":[{"type":"update","product_id":"BTC-USD","updates":[{"side":"bid","event_time":"2026-07-16T20:29:11.89807Z","price_level":"64121.68","new_quantity":"0"},{"side":"bid","event_time":"2026-07-16T20:29:11.89807Z","price_level":"63977.5","new_quantity":"0.05"},{"side":"bid","event_time":"2026-07-16T20:29:11.89807Z","price_level":"56118.13","new_quantity":"0"},{"side":"offer","event_time":"2026-07-16T20:29:11.89807Z","price_level":"64158.52","new_quantity":"0.01504404"},{"side":"offer","event_time":"2026-07-16T20:29:11.89807Z","price_level":"64193.7","new_quantity":"0.24183072"},{"side":"offer","event_time":"2026-07-16T20:29:11.89807Z","price_level":"64193.91","new_quantity":"0.280558"},{"side":"offer","event_time":"2026-07-16T20:29:11.89807Z","price_level":"64210.38","new_quantity":"0"},{"side":"offer","event_time":"2026-07-16T20:29:11.89807Z","price_level":"64365.16","new_quantity":"0.00583"},{"side":"offer","event_time":"2026-07-16T20:29:11.89807Z","price_level":"64580.39","new_quantity":"0"}]}]}
{"channel":"l2_data","timestamp":"2026-07-16T20:29:12.02970603Z","sequence_num":399,"events":[{"type":"update","product_id":"BTC-USD","updates":[{"side":"bid","event_time":"2026-07-16T20:29:12.011836Z","price_level":"64135","new_quantity":"0.01083594"},{"side":"offer","event_time":"2026-07-16T20:29:12.011836Z","price_level":"64149.18","new_quantity":"0"},{"side":"offer","event_time":"2026-07-16T20:29:12.011836Z","price_level":"64158.52","new_quantity":"0"}]}]}
{"channel":"l2_data","timestamp":"2026-07-16T20:29:12.081725372Z","sequence_num":400,"events":[{"type":"update","product_id":"BTC-USD","updates":[{"side":"bid","event_time":"2026-07-16T20:29:12.043155Z","price_level":"64096.79","new_quantity":"0.02986583"},{"side":"bid","event_time":"2026-07-16T20:29:12.043155Z","price_level":"64094.23","new_quantity":"0.03358847"},{"side":"bid","event_time":"2026-07-16T20:29:12.043155Z","price_level":"64090.38","new_quantity":"0.02571152"},{"side":"bid","event_time":"2026-07-16T20:29:12.043155Z","price_level":"63965","new_quantity":"0.05"},{"side":"offer","event_time":"2026-07-16T20:29:12.043155Z","price_level":"64148.21","new_quantity":"0"},{"side":"offer","event_time":"2026-07-16T20:29:12.043155Z","price_level":"64176.04","new_quantity":"0.48578904"},{"side":"offer","event_time":"2026-07-16T20:29:12.043155Z","price_level":"64176.05","new_quantity":"0"},{"side":"offer","event_time":"2026-07-16T20:29:12.043155Z","price_level":"64176.06","new_quantity":"0"}]}]}
{"channel":"l2_data","timestamp":"2026-07-16T20:29:12.130113843Z","sequence_num":401,"events":[{"type":"update","product_id":"BTC-USD","updates":[{"side":"bid","event_time":"2026-07-16T20:29:12.100855Z","price_level":"64121.7","new_quantity":"0.670332"},{"side":"bid","event_time":"2026-07-16T20:29:12.100855Z","price_level":"56118.13","new_quantity":"0.01337205"},{"side":"offer","event_time":"2026-07-16T20:29:12.100855Z","price_level":"64135.36","new_quantity":"0.00234575"},{"side":"offer","event_time":"2026-07-16T20:29:12.100855Z","price_level":"64135.44","new_quantity":"0"}]}]}
{"channel":"heartbeats","timestamp":"2026-07-16T20:29:12.164868181Z","sequence_num":402,"events":[{"current_time":"2026-07-16 20:29:12.163297235 +0000 UTC m=+75516.318124289","heartbeat_counter":75516}]}
{"channel":"l2_data","timestamp":"2026-07-16T20:29:12.179531983Z","sequence_num":403,"events":[{"type":"update","product_id":"BTC-USD","updates":[{"side":"bid","event_time":"2026-07-16T20:29:12.155786Z","price_level":"64121.7","new_quantity":"0"},{"side":"offer","event_time":"2026-07-16T20:29:12.155786Z","price_level":"64158.48","new_quantity":"0.01083594"},{"side":"offer","event_time":"2026-07-16T20:29:12.155786Z","price_level":"64365.34","new_quantity":"0"}]}]}
{"channel":"l2_data","timestamp":"2026-07-16T20:29:12.229343086Z","sequence_num":404,"events":[{"type":"update","product_id":"BTC-USD","updates":[{"side":"bid","event_time":"2026-07-16T20:29:12.197729Z","price_level":"56118.13","new_quantity":"0"},{"side":"offer","event_time":"2026-07-16T20:29:12.197729Z","price_level":"64135.01","new_quantity":"1.02647194"},{"side":"offer","event_time":"2026-07-16T20:29:12.197729Z","price_level":"64341","new_quantity":"0.05"},{"side":"offer","event_time":"2026-07-16T20:29:12.197729Z","price_level":"64365.01","new_quantity":"0.00583"},{"side":"offer","event_time":"2026-07-16T20:29:12.197729Z","price_level":"64365.16","new_quantity":"0"},{"side":"offer","event_time":"2026-07-16T20:29:12.197729Z","price_level":"64794.58","new_quantity":"0.00583"}]}]}
{"channel":"l2_data","timestamp":"2026-07-16T20:29:12.326662571Z","sequence_num":405,"events":[{"type":"update","product_id":"BTC-USD","updates":[{"side":"offer","event_time":"2026-07-16T20:29:12.30166Z","price_level":"64147.79","new_quantity":"0.00009743"},{"side":"offer","event_time":"2026-07-16T20:29:12.30166Z","price_level":"64148.75","new_quantity":"0.00779438"},{"side":"offer","event_time":"2026-07-16T20:29:12.30166Z","price_level":"64158.48","new_quantity":"0"}]}]}
{"channel":"l2_data","timestamp":"2026-07-16T20:29:12.380461724Z","sequence_num":406,"events":[{"type":"update","product_id":"BTC-USD","updates":[{"side":"bid","event_time":"2026-07-16T20:29:12.361268Z","price_level":"64135","new_quantity":"0.01083583"},{"side":"bid","event_time":"2026-07-16T20:29:12.361268Z","price_level":"64121.6","new_quantity":"0.655864"},{"side":"offer","event_time":"2026-07-16T20:29:12.361268Z","price_level":"64353.5","new_quantity":"0.05"}]}]}
{"channel":"l2_data","timestamp":"2026-07-16T20:29:12.431573928Z","sequence_num":407,"events":[{"type":"update","product_id":"BTC-USD","updates":[{"side":"bid","event_time":"2026-07-16T20:29:12.393817Z","price_level":"64121.6","new_quantity":"0"},{"side":"bid","event_time":"2026-07-16T20:29:12.393817Z","price_level":"56118.13","new_quantity":"0.01337205"},{"side":"offer","event_time":"2026-07-16T20:29:12.393817Z","price_level":"64135.29","new_quantity":"0.00234575"},{"side":"offer","event_time":"2026-07-16T20:29:12.393817Z","price_level":"64135.36","new_quantity":"0"}]}]}
{"channel":"l2_data","timestamp":"2026-07-16T20:29:12.54124059Z","sequence_num":408,"events":[{"type":"update","product_id":"BTC-USD","updates":[{"side":"bid","event_time":"2026-07-16T20:29:12.502313Z","price_level":"64092.2","new_quantity":"0.05"},{"side":"bid","event_time":"2026-07-16T20:29:12.502313Z","price_level":"56118.13","new_quantity":"0"},{"side":"offer","event_time":"2026-07-16T20:29:12.502313Z","price_level":"64139.2","new_quantity":"0.23359045"},{"side":"offer","event_time":"2026-07-16T20:29:12.502313Z","price_level":"64158.48","new_quantity":"0.01083594"}]}]}
{"channel":"l2_data","timestamp":"2026-07-16T20:29:12.585803993Z","sequence_num":409,"events":[{"type":"update","product_id":"BTC-USD","updates":[{"side":"bid","event_time":"2026-07-16T20:29:12.523006Z","price_level":"64135","new_quantity":"0.01101747"},{"side":"bid","event_time":"2026-07-16T20:29:12.523006Z","price_level":"64126.11","new_quantity":"0.04673199"}]}]}
{"channel":"l2_data","timestamp":"2026-07-16T20:29:12.652576025Z","sequence_num":410,"events":[{"type":"update","product_id":"BTC-USD","updates":[{"side":"bid","event_time":"2026-07-16T20:29:12.61117Z","price_level":"64121.71","new_quantity":"0.625134"},{"side":"offer","event_time":"2026-07-16T20:29:12.61117Z","price_level":"64158.48","new_quantity":"0"}]}]}
{"channel":"l2_data","timestamp":"2026-07-16T20:29:12.690660402Z","sequence_num":411,"events":[{"type":"update","product_id":"BTC-USD","updates":[{"side":"bid","event_time":"2026-07-16T20:29:12.641408Z","price_level":"64128.59","new_quantity":"0"},{"side":"bid","event_time":"2026-07-16T20:29:12.641408Z","price_level":"64128.43","new_quantity":"0.02"},{"side":"offer","event_time":"2026-07-16T20:29:12.641408Z","price_level":"64150.61","new_quantity":"0.00779416"}]}]}
{"channel":"l2_data","timestamp":"2026-07-16T20:29:12.739943406Z","sequence_num":412,"events":[{"type":"update","product_id":"BTC-USD","updates":[{"side":"bid","event_time":"2026-07-16T20:29:12.691535Z","price_level":"64130.19","new_quantity":"0"},{"side":"bid","event_time":"2026-07-16T20:29:12.691535Z","price_level":"64128.59","new_quantity":"0.00779683"},{"side":"bid","event_time":"2026-07-16T20:29:12.691535Z","price_level":"64121.71","new_quantity":"0"},{"side":"bid","event_time":"2026-07-16T20:29:12.691535Z","price_level":"64074.38","new_quantity":"0"},{"side":"bid","event_time":"2026-07-16T20:29:12.691535Z","price_level":"64070.13","new_quantity":"1.41596236"},{"side":"bid","event_time":"2026-07-16T20:29:12.691535Z","price_level":"56118.13","new_quantity":"0.01337205"},{"side":"offer","event_time":"2026-07-16T20:29:12.691535Z","price_level":"64149.01","new_quantity":"0"},{"side":"offer","event_time":"2026-07-16T20:29:12.691535Z","price_level":"64150.2","new_quantity":"0.00896334"}]}]}
{"channel":"l2_data","timestamp":"2026-07-16T20:29:12.789244581Z","sequence_num":413,"events":[{"type":"update","product_id":"BTC-USD","updates":[{"side":"bid","event_time":"2026-07-16T20:29:12.756179Z","price_level":"64130.19","new_quantity":"0.00779664"},{"side":"offer","event_time":"2026-07-16T20:29:12.756179Z","price_level":"64135.22","new_quantity":"0.00234575"},{"side":"offer","event_time":"2026-07-16T20:29:12.756179Z","price_level":"64135.29","new_quantity":"0"},{"side":"offer","event_time":"2026-07-16T20:29:12.756179Z","price_level":"64148.59","new_quantity":"0.00896356"},{"side":"offer","event_time":"2026-07-16T20:29:12.756179Z","price_level":"64158.48","new_quantity":"0.01101747"}]}]}
{"channel":"l2_data","timestamp":"2026-07-16T20:29:12.839547325Z","sequence_num":414,"events":[{"type":"update","product_id":"BTC-USD","updates":[{"side":"bid","event_time":"2026-07-16T20:29:12.806981Z","price_level":"56118.13","new_quantity":"0"},{"side":"offer","event_time":"2026-07-16T20:29:12.806981Z","price_level":"64149.32","new_quantity":"0"},{"side":"offer","event_time":"2026-07-16T20:29:12.806981Z","price_level":"64150.19","new_quantity":"0.31970273"},{"side":"offer","event_time":"2026-07-16T20:29:12.806981Z","price_level":"64150.61","new_quantity":"0"}]}]}
{"channel":"l2_data","timestamp":"2026-07-16T20:29:12.888679335Z","sequence_num":415,"events":[{"type":"update","product_id":"BTC-USD","updates":[{"side":"bid","event_time":"2026-07-16T20:29:12.81777Z","price_level":"64074.38","new_quantity":"1.41586844"},{"side":"bid","event_time":"2026-07-16T20:29:12.81777Z","price_level":"64070.13","new_quantity":"0"},{"side":"offer","event_time":"2026-07-16T20:29:12.81777Z","price_level":"64148.91","new_quantity":"0.00009743"}]}]}
{"channel":"l2_data","timestamp":"2026-07-16T20:29:12.93127764Z","sequence_num":416,"events":[{"type":"update","product_id":"BTC-USD","updates":[{"side":"bid","event_time":"2026-07-16T20:29:12.892297Z","price_level":"64121.78","new_quantity":"0.588051"}]}]}
{"channel":"l2_data","timestamp":"2026-07-16T20:29:12.994041319Z","sequence_num":417,"events":[{"type":"update","product_id":"BTC-USD","updates":[{"side":"bid","event_time":"2026-07-16T20:29:12.953587Z","price_level":"64121.78","new_quantity":"0"},{"side":"offer","event_time":"2026-07-16T20:29:12.953587Z","price_level":"64158.48","new_quantity":"0"}]}]}
{"channel":"l2_data","timestamp":"2026-07-16T20:29:13.032959126Z","sequence_num":418,"events":[{"type":"update","product_id":"BTC-USD","updates":[{"side":"bid","event_time":"2026-07-16T20:29:13.011453Z","price_level":"56118.13","new_quantity":"0.01337205"},{"side":"offer","event_time":"2026-07-16T20:29:13.011453Z","price_level":"64148.75","new_quantity":"0"}]}]}
{"channel":"l2_data","timestamp":"2026-07-16T20:29:13.086775622Z","sequence_num":419,"events":[{"type":"update","product_id":"BTC-USD","updates":[{"side":"bid","event_time":"2026-07-16T20:29:13.058857Z","price_level":"64135","new_quantity":"0.01101736"},{"side":"bid","event_time":"2026-07-16T20:29:13.058857Z","price_level":"64108.8","new_quantity":"0"},{"side":"bid","event_time":"2026-07-16T20:29:13.058857Z","price_level":"64089.57","new_quantity":"0"},{"side":"offer","event_time":"2026-07-16T20:29:13.058857Z","price_level":"64135.15","new_quantity":"0.00234575"},{"side":"offer","event_time":"2026-07-16T20:29:13.058857Z","price_level":"64135.22","new_quantity":"0"},{"side":"offer","event_time":"2026-07-16T20:29:13.058857Z","price_level":"64147.79","new_quantity":"0"},{"side":"offer","event_time":"2026-07-16T20:29:13.058857Z","price_level":"64159.53","new_quantity":"0"},{"side":"offer","event_time":"2026-07-16T20:29:13.058857Z","price_level":"64176.02","new_quantity":"0.48578919"},{"side":"offer","event_time":"2026-07-16T20:29:13.058857Z","price_level":"64176.04","new_quantity":"0"},{"side":"offer","event_time":"2026-07-16T20:29:13.058857Z","price_level":"64177.53","new_quantity":"0.6847993"},{"side":"offer","event_time":"2026-07-16T20:29:13.058857Z","price_level":"64178.77","new_quantity":"0"}]}]}
{"channel":"l2_data","timestamp":"2026-07-16T20:29:13.133374671Z","sequence_num":420,"events":[{"type":"update","product_id":"BTC-USD","updates":[{"side":"bid","event_time":"2026-07-16T20:29:13.10167Z","price_level":"64121.85","new_quantity":"0.613951"},{"side":"bid","event_time":"2026-07-16T20:29:13.10167Z","price_level":"56118.13","new_quantity":"0"},{"side":"offer","event_time":"2026-07-16T20:29:13.10167Z","price_level":"64158.49","new_quantity":"0.01101747"}]}]}
{"channel":"heartbeats","timestamp":"2026-07-16T20:29:13.169805209Z","sequence_num":421,"events":[{"current_time":"2026-07-16 20:29:13.162889532 +0000 UTC m=+75517.317716571","heartbeat_counter":75517}]}
{"channel":"l2_data","timestamp":"2026-07-16T20:29:13.175144671Z","sequence_num":422,"events":[{"type":"update","product_id":"BTC-USD","updates":[{"side":"bid","event_time":"2026-07-16T20:29:13.135864Z","price_level":"64121.85","new_quantity":"0"},{"side":"bid","event_time":"2026-07-16T20:29:13.135864Z","price_level":"51308","new_quantity":"0.0002"}]}]}
{"channel":"l2_data","timestamp":"2026-07-16T20:29:13.224678929Z","sequence_num":423,"events":[{"type":"update","product_id":"BTC-USD","updates":[{"side":"bid","event_time":"2026-07-16T20:29:13.206305Z","price_level":"64104.91","new_quantity":"0"}]}]}
{"channel":"l2_data","timestamp":"2026-07-16T20:29:13.279566094Z","sequence_num":424,"events":[{"type":"update","product_id":"BTC-USD","updates":[{"side":"bid","event_time":"2026-07-16T20:29:13.214944Z","price_level":"64102.76","new_quantity":"0.65581018"},{"side":"offer","event_time":"2026-07-16T20:29:13.214944Z","price_level":"64158.49","new_quantity":"0"}]}]}
{"channel":"l2_data","timestamp":"2026-07-16T20:29:13.330756771Z","sequence_num":425,"events":[{"type":"update","product_id":"BTC-USD","updates":[{"side":"bid","event_time":"2026-07-16T20:29:13.292982Z","price_level":"64106.52","new_quantity":"0.27615442"},{"side":"bid","event_time":"2026-07-16T20:29:13.292982Z","price_level":"64087.29","new_quantity":"0.5642379"},{"side":"bid","event_time":"2026-07-16T20:29:13.292982Z","price_level":"56118.13","new_quantity":"0.01337205"},{"side":"offer","event_time":"2026-07-16T20:29:13.292982Z","price_level":"64156.5","new_quantity":"0.26861076"},{"side":"offer","event_time":"2026-07-16T20:29:13.292982Z","price_level":"64175.74","new_quantity":"0.46377061"},{"side":"offer","event_time":"2026-07-16T20:29:13.292982Z","price_level":"64175.75","new_quantity":"0.53822227"},{"side":"offer","event_time":"2026-07-16T20:29:13.292982Z","price_level":"64176.02","new_quantity":"0"}]}]}
{"channel":"l2_data","timestamp":"2026-07-16T20:29:13.375774993Z","sequence_num":426,"events":[{"type":"update","product_id":"BTC-USD","updates":[{"side":"bid","event_time":"2026-07-16T20:29:13.353902Z","price_level":"64123.62","new_quantity":"0"},{"side":"bid","event_time":"2026-07-16T20:29:13.353902Z","price_level":"64109.56","new_quantity":"0.626834"}]}]}
{"channel":"l2_data","timestamp":"2026-07-16T20:29:13.431106005Z","sequence_num":427,"events":[{"type":"update","product_id":"BTC-USD","updates":[{"side":"bid","event_time":"2026-07-16T20:29:13.397478Z","price_level":"64135","new_quantity":"0.0110173"},{"side":"bid","event_time":"2026-07-16T20:29:13.397478Z","price_level":"64129.35","new_quantity":"0"},{"side":"bid","event_time":"2026-07-16T20:29:13.397478Z","price_level":"64128.01","new_quantity":"0.31190852"},{"side":"bid","event_time":"2026-07-16T20:29:13.397478Z","price_level":"64110","new_quantity":"0.01"},{"side":"bid","event_time":"2026-07-16T20:29:13.397478Z","price_level":"64109.56","new_quantity":"0"},{"side":"bid","event_time":"2026-07-16T20:29:13.397478Z","price_level":"64102.77","new_quantity":"0.00077952"},{"side":"bid","event_time":"2026-07-16T20:29:13.397478Z","price_level":"64102.76","new_quantity":"0.65503064"},{"side":"bid","event_time":"2026-07-16T20:29:13.397478Z","price_level":"56118.13","new_quantity":"0"},{"side":"offer","event_time":"2026-07-16T20:29:13.397478Z","price_level":"64142.58","new_quantity":"0.22533829"},{"side":"offer","event_time":"2026-07-16T20:29:13.397478Z","price_level":"64142.92","new_quantity":"0"},{"side":"offer","event_time":"2026-07-16T20:29:13.397478Z","price_level":"64147.39","new_quantity":"0.00009743"},{"side":"offer","event_time":"2026-07-16T20:29:13.397478Z","price_level":"64148.35","new_quantity":"0.00779443"},{"side":"offer","event_time":"2026-07-16T20:29:13.397478Z","price_level":"64158.49","new_quantity":"0.01101736"}]}]}
{"channel":"l2_data","timestamp":"2026-07-16T20:29:13.480274716Z","sequence_num":428,"events":[{"type":"update","product_id":"BTC-USD","updates":[{"side":"bid","event_time":"2026-07-16T20:29:13.457705Z","price_level":"64129.36","new_quantity":"0"},{"side":"bid","event_time":"2026-07-16T20:29:13.457705Z","price_level":"64129.18","new_quantity":"0.12474819"},{"side":"bid","event_time":"2026-07-16T20:29:13.457705Z","price_level":"64109","new_quantity":"1"},{"side":"bid","event_time":"2026-07-16T20:29:13.457705Z","price_level":"51308","new_quantity":"0"},{"side":"offer","event_time":"2026-07-16T20:29:13.457705Z","price_level":"64135.08","new_quantity":"0.00234575"},{"side":"offer","event_time":"2026-07-16T20:29:13.457705Z","price_level":"64135.15","new_quantity":"0"}]}]}
{"channel":"l2_data","timestamp":"2026-07-16T20:29:13.530917456Z","sequence_num":429,"events":[{"type":"update","product_id":"BTC-USD","updates":[{"side":"bid","event_time":"2026-07-16T20:29:13.480042Z","price_level":"64129.19","new_quantity":"0.02"},{"side":"bid","event_time":"2026-07-16T20:29:13.480042Z","price_level":"64126.96","new_quantity":"0"},{"side":"bid","event_time":"2026-07-16T20:29:13.480042Z","price_level":"64119.22","new_quantity":"0.06"},{"side":"bid","event_time":"2026-07-16T20:29:13.480042Z","price_level":"63495.6","new_quantity":"0"}]}]}
{"channel":"l2_data","timestamp":"2026-07-16T20:29:13.581421095Z","sequence_num":430,"events":[{"type":"update","product_id":"BTC-USD","updates":[{"side":"bid","event_time":"2026-07-16T20:29:13.55672Z","price_level":"64109","new_quantity":"0"},{"side":"offer","event_time":"2026-07-16T20:29:13.55672Z","price_level":"64135.01","new_quantity":"1.02673061"},{"side":"offer","event_time":"2026-07-16T20:29:13.55672Z","price_level":"64154","new_quantity":"0"}]}]}
{"channel":"l2_data","timestamp":"2026-07-16T20:29:13.637086938Z","sequence_num":431,"events":[{"type":"update","product_id":"BTC-USD","updates":[{"side":"bid","event_time":"2026-07-16T20:29:13.601489Z","price_level":"64135","new_quantity":"0.01428259"},{"side":"bid","event_time":"2026-07-16T20:29:13.601489Z","price_level":"64128.65","new_quantity":"0"},{"side":"bid","event_time":"2026-07-16T20:29:13.601489Z","price_level":"64128.6","new_quantity":"0"},{"side":"bid","event_time":"2026-07-16T20:29:13.601489Z","price_level":"64128.43","new_quantity":"0"},{"side":"bid","event_time":"2026-07-16T20:29:13.601489Z","price_level":"64125.4","new_quantity":"0"},{"side":"bid","event_time":"2026-07-16T20:29:13.601489Z","price_level":"64125.39","new_quantity":"0.01559176"},{"side":"bid","event_time":"2026-07-16T20:29:13.601489Z","price_level":"64121.64","new_quantity":"0.679447"},{"side":"bid","event_time":"2026-07-16T20:29:13.601489Z","price_level":"64109","new_quantity":"1"},{"side":"bid","event_time":"2026-07-16T20:29:13.601489Z","price_level":"56118.13","new_quantity":"0.01337205"},{"side":"offer","event_time":"2026-07-16T20:29:13.601489Z","price_level":"64135.01","new_quantity":"1.05117542"},{"side":"offer","event_time":"2026-07-16T20:29:13.601489Z","price_level":"64150","new_quantity":"1.01583"},{"side":"offer","event_time":"2026-07-16T20:29:13.601489Z","price_level":"64150.06","new_quantity":"0.00583"},{"side":"offer","event_time":"2026-07-16T20:29:13.601489Z","price_level":"64150.38","new_quantity":"0"},{"side":"offer","event_time":"2026-07-16T20:29:13.601489Z","price_level":"64152.29","new_quantity":"0.57081098"},{"side":"offer","event_time":"2026-07-16T20:29:13.601489Z","price_level":"64794.94","new_quantity":"0"},{"side":"offer","event_time":"2026-07-16T20:29:13.601489Z","price_level":"65436.58","new_quantity":"0.00583"},{"side":"offer","event_time":"2026-07-16T20:29:13.601489Z","price_level":"65436.64","new_quantity":"0"},{"side":"offer","event_time":"2026-07-16T20:29:13.601489Z","price_level":"65436.96","new_quantity":"0"}]}]}
{"channel":"l2_data","timestamp":"2026-07-16T20:29:13.687110561Z","sequence_num":432,"events":[{"type":"update","product_id":"BTC-USD","updates":[{"side":"bid","event_time":"2026-07-16T20:29:13.623978Z","price_level":"64128.6","new_quantity":"0.02"},{"side":"offer","event_time":"2026-07-16T20:29:13.623978Z","price_level":"64149.31","new_quantity":"1.04551479"}]}]}
{"channel":"l2_data","timestamp":"2026-07-16T20:29:13.73412419Z","sequence_num":433,"events":[{"type":"update","product_id":"BTC-USD","updates":[{"side":"bid","event_time":"2026-07-16T20:29:13.70472Z","price_level":"64128.59","new_quantity":"0.00779683"},{"side":"bid","event_time":"2026-07-16T20:29:13.70472Z","price_level":"64121.64","new_quantity":"0"},{"side":"bid","event_time":"2026-07-16T20:29:13.70472Z","price_level":"64100.92","new_quantity":"0"},{"side":"bid","event_time":"2026-07-16T20:29:13.70472Z","price_level":"64099.22","new_quantity":"0.00155812"},{"side":"bid","event_time":"2026-07-16T20:29:13.70472Z","price_level":"64094.52","new_quantity":"0"},{"side":"bid","event_time":"2026-07-16T20:29:13.70472Z","price_level":"64092.81","new_quantity":"0.0077906"},{"side":"bid","event_time":"2026-07-16T20:29:13.70472Z","price_level":"56118.13","new_quantity":"0"},{"side":"offer","event_time":"2026-07-16T20:29:13.70472Z","price_level":"64135.01","new_quantity":"1.10761558"},{"side":"offer","event_time":"2026-07-16T20:29:13.70472Z","price_level":"64139.19","new_quantity":"0.72660261"},{"side":"offer","event_time":"2026-07-16T20:29:13.70472Z","price_level":"64140.7","new_quantity":"0.65502701"},{"side":"offer","event_time":"2026-07-16T20:29:13.70472Z","price_level":"64149.8","new_quantity":"0.00896339"},{"side":"offer","event_time":"2026-07-16T20:29:13.70472Z","price_level":"64150.2","new_quantity":"0"}]}]}
{"channel":"l2_data","timestamp":"2026-07-16T20:29:13.78088503Z","sequence_num":434,"events":[{"type":"update","product_id":"BTC-USD","updates":[{"side":"bid","event_time":"2026-07-16T20:29:13.743909Z","price_level":"64135","new_quantity":"0.0110173"},{"side":"bid","event_time":"2026-07-16T20:29:13.743909Z","price_level":"64125.39","new_quantity":"0"},{"side":"bid","event_time":"2026-07-16T20:29:13.743909Z","price_level":"64125.38","new_quantity":"0.01559176"},{"side":"bid","event_time":"2026-07-16T20:29:13.743909Z","price_level":"63973.17","new_quantity":"0.00270479"},{"side":"offer","event_time":"2026-07-16T20:29:13.743909Z","price_level":"65651.01","new_quantity":"0.00583"}]}]}
{"channel":"l2_data","timestamp":"2026-07-16T20:29:13.830956905Z","sequence_num":435,"events":[{"type":"update","product_id":"BTC-USD","updates":[{"side":"bid","event_time":"2026-07-16T20:29:13.772425Z","price_level":"64130.19","new_quantity":"0.00779664"},{"side":"bid","event_time":"2026-07-16T20:29:13.772425Z","price_level":"64074.38","new_quantity":"0"},{"side":"bid","event_time":"2026-07-16T20:29:13.772425Z","price_level":"64070.13","new_quantity":"1.41596236"},{"side":"bid","event_time":"2026-07-16T20:29:13.772425Z","price_level":"63496.23","new_quantity":"0.03937892"},{"side":"offer","event_time":"2026-07-16T20:29:13.772425Z","price_level":"64148.2","new_quantity":"0.32087214"},{"side":"offer","event_time":"2026-07-16T20:29:13.772425Z","price_level":"64148.59","new_quantity":"0"},{"side":"offer","event_time":"2026-07-16T20:29:13.772425Z","price_level":"64174.64","new_quantity":"0.46377856"},{"side":"offer","event_time":"2026-07-16T20:29:13.772425Z","price_level":"64175.74","new_quantity":"0"}]}]}
{"channel":"l2_data","timestamp":"2026-07-16T20:29:13.892326387Z","sequence_num":436,"events":[{"type":"update","product_id":"BTC-USD","updates":[{"side":"bid","event_time":"2026-07-16T20:29:13.861645Z","price_level":"64125.38","new_quantity":"0"},{"side":"bid","event_time":"2026-07-16T20:29:13.861645Z","price_level":"64124.81","new_quantity":"0.01559176"},{"side":"bid","event_time":"2026-07-16T20:29:13.861645Z","price_level":"64121.48","new_quantity":"0.5957"},{"side":"bid","event_time":"2026-07-16T20:29:13.861645Z","price_level":"64121.3","new_quantity":"0"},{"side":"bid","event_time":"2026-07-16T20:29:13.861645Z","price_level":"64109","new_quantity":"0"},{"side":"offer","event_time":"2026-07-16T20:29:13.861645Z","price_level":"64148.91","new_quantity":"0"},{"side":"offer","event_time":"2026-07-16T20:29:13.861645Z","price_level":"64150.19","new_quantity":"0.31190852"}]}]}
{"channel":"l2_data","timestamp":"2026-07-16T20:29:13.971938359Z","sequence_num":437,"events":[{"type":"update","product_id":"BTC-USD","updates":[{"side":"bid","event_time":"2026-07-16T20:29:13.900318Z","price_level":"64121.48","new_quantity":"0"},{"side":"bid","event_time":"2026-07-16T20:29:13.900318Z","price_level":"64118.1","new_quantity":"0.07412"},{"side":"bid","event_time":"2026-07-16T20:29:13.900318Z","price_level":"64108","new_quantity":"1"},{"side":"bid","event_time":"2026-07-16T20:29:13.900318Z","price_level":"64074.38","new_quantity":"1.41586844"},{"side":"bid","event_time":"2026-07-16T20:29:13.900318Z","price_level":"64070.13","new_quantity":"0"},{"side":"bid","event_time":"2026-07-16T20:29:13.900318Z","price_level":"56118.13","new_quantity":"0.01337205"},{"side":"offer","event_time":"2026-07-16T20:29:13.900318Z","price_level":"64135.01","new_quantity":"1.16591133"},{"side":"offer","event_time":"2026-07-16T20:29:13.900318Z","price_level":"64135.08","new_quantity":"0"},{"side":"offer","event_time":"2026-07-16T20:29:13.900318Z","price_level":"64148.51","new_quantity":"0.00009743"},{"side":"offer","event_time":"2026-07-16T20:29:13.900318Z","price_level":"64149.8","new_quantity":"0.01675765"}]}]}
{"channel":"l2_data","timestamp":"2026-07-16T20:29:13.978651313Z","sequence_num":438,"events":[{"type":"update","product_id":"BTC-USD","updates":[{"side":"bid","event_time":"2026-07-16T20:29:13.920732Z","price_level":"64128.01","new_quantity":"0"}]}]}
{"channel":"l2_data","timestamp":"2026-07-16T20:29:14.030900283Z","sequence_num":439,"events":[{"type":"update","product_id":"BTC-USD","updates":[{"side":"bid","event_time":"2026-07-16T20:29:14.009302Z","price_level":"64108","new_quantity":"0"},{"side":"bid","event_time":"2026-07-16T20:29:14.009302Z","price_level":"56118.13","new_quantity":"0"},{"side":"offer","event_time":"2026-07-16T20:29:14.009302Z","price_level":"64148.35","new_quantity":"0"},{"side":"offer","event_time":"2026-07-16T20:29:14.009302Z","price_level":"64778.34","new_quantity":"0"}]}]}
{"channel":"l2_data","timestamp":"2026-07-16T20:29:14.080956678Z","sequence_num":440,"events":[{"type":"update","product_id":"BTC-USD","updates":[{"side":"bid","event_time":"2026-07-16T20:29:14.046904Z","price_level":"64109","new_quantity":"1"},{"side":"offer","event_time":"2026-07-16T20:29:14.046904Z","price_level":"64147.39","new_quantity":"0"},{"side":"offer","event_time":"2026-07-16T20:29:14.046904Z","price_level":"64174.63","new_quantity":"0.83287743"}]}]}
{"channel":"l2_data","timestamp":"2026-07-16T20:29:14.129806441Z","sequence_num":441,"events":[{"type":"update","product_id":"BTC-USD","updates":[{"side":"bid","event_time":"2026-07-16T20:29:14.104189Z","price_level":"64121.38","new_quantity":"0.689546"},{"side":"offer","event_time":"2026-07-16T20:29:14.104189Z","price_level":"64156.5","new_quantity":"0"}]}]}
{"channel":"heartbeats","timestamp":"2026-07-16T20:29:14.163161045Z","sequence_num":442,"events":[{"current_time":"2026-07-16 20:29:14.162883691 +0000 UTC m=+75518.317710745","heartbeat_counter":75518}]}
{"channel":"l2_data","timestamp":"2026-07-16T20:29:14.179811838Z","sequence_num":443,"events":[{"type":"update","product_id":"BTC-USD","updates":[{"side":"bid","event_time":"2026-07-16T20:29:14.138746Z","price_level":"64135","new_quantity":"0.01495691"},{"side":"bid","event_time":"2026-07-16T20:29:14.138746Z","price_level":"64106.52","new_quantity":"0"},{"side":"bid","event_time":"2026-07-16T20:29:14.138746Z","price_level":"64087.29","new_quantity":"0"},{"side":"offer","event_time":"2026-07-16T20:29:14.138746Z","price_level":"64150.06","new_quantity":"0"},{"side":"offer","event_time":"2026-07-16T20:29:14.138746Z","price_level":"64174.63","new_quantity":"0"},{"side":"offer","event_time":"2026-07-16T20:29:14.138746Z","price_level":"64175.75","new_quantity":"0"},{"side":"offer","event_time":"2026-07-16T20:29:14.138746Z","price_level":"64579.81","new_quantity":"0.00583"},{"side":"offer","event_time":"2026-07-16T20:29:14.138746Z","price_level":"65651.01","new_quantity":"0"}]}]}
{"channel":"l2_data","timestamp":"2026-07-16T20:29:14.229671618Z","sequence_num":444,"events":[{"type":"update","product_id":"BTC-USD","updates":[{"side":"bid","event_time":"2026-07-16T20:29:14.209685Z","price_level":"64121.38","new_quantity":"0"},{"side":"bid","event_time":"2026-07-16T20:29:14.209685Z","price_level":"56118.13","new_quantity":"0.01337205"},{"side":"offer","event_time":"2026-07-16T20:29:14.209685Z","price_level":"64778.98","new_quantity":"0.03890047"}]}]}
{"channel":"l2_data","timestamp":"2026-07-16T20:29:14.280044642Z","sequence_num":445,"events":[{"type":"update","product_id":"BTC-USD","updates":[{"side":"bid","event_time":"2026-07-16T20:29:14.232479Z","price_level":"64135","new_quantity":"0.01495684"},{"side":"bid","event_time":"2026-07-16T20:29:14.232479Z","price_level":"64129.19","new_quantity":"0"},{"side":"bid","event_time":"2026-07-16T20:29:14.232479Z","price_level":"64128.6","new_quantity":"0"},{"side":"offer","event_time":"2026-07-16T20:29:14.232479Z","price_level":"64152.97","new_quantity":"0"}]}]}
{"channel":"l2_data","timestamp":"2026-07-16T20:29:14.33023856Z","sequence_num":446,"events":[{"type":"update","product_id":"BTC-USD","updates":[{"side":"bid","event_time":"2026-07-16T20:29:14.309679Z","price_level":"56118.13","new_quantity":"0"},{"side":"offer","event_time":"2026-07-16T20:29:14.309679Z","price_level":"64139.19","new_quantity":"0.44529932"},{"side":"offer","event_time":"2026-07-16T20:29:14.309679Z","price_level":"64140.7","new_quantity":"0"},{"side":"offer","event_time":"2026-07-16T20:29:14.309679Z","price_level":"64142.56","new_quantity":"0.61638129"},{"side":"offer","event_time":"2026-07-16T20:29:14.309679Z","price_level":"64142.57","new_quantity":"0.6550134"},{"side":"offer","event_time":"2026-07-16T20:29:14.309679Z","price_level":"64142.58","new_quantity":"0"}]}]}
{"channel":"l2_data","timestamp":"2026-07-16T20:29:14.37537403Z","sequence_num":447,"events":[{"type":"update","product_id":"BTC-USD","updates":[{"side":"bid","event_time":"2026-07-16T20:29:14.362807Z","price_level":"64121.44","new_quantity":"0.709484"},{"side":"bid","event_time":"2026-07-16T20:29:14.362807Z","price_level":"64105.51","new_quantity":"0.28147969"}]}]}
{"channel":"l2_data","timestamp":"2026-07-16T20:29:14.471192427Z","sequence_num":448,"events":[{"type":"update","product_id":"BTC-USD","updates":[{"side":"bid","event_time":"2026-07-16T20:29:14.406448Z","price_level":"64121.44","new_quantity":"0"},{"side":"bid","event_time":"2026-07-16T20:29:14.406448Z","price_level":"64105.52","new_quantity":"0.59590441"},{"side":"bid","event_time":"2026-07-16T20:29:14.406448Z","price_level":"64104.92","new_quantity":"0"},{"side":"bid","event_time":"2026-07-16T20:29:14.406448Z","price_level":"64086.28","new_quantity":"0.55095083"},{"side":"offer","event_time":"2026-07-16T20:29:14.406448Z","price_level":"64150.35","new_quantity":"0.33"},{"side":"offer","event_time":"2026-07-16T20:29:14.406448Z","price_level":"64155.12","new_quantity":"0.27697243"},{"side":"offer","event_time":"2026-07-16T20:29:14.406448Z","price_level":"64174.36","new_quantity":"0.54111091"}]}]}
{"channel":"l2_data","timestamp":"2026-07-16T20:29:14.489168411Z","sequence_num":449,"events":[{"type":"update","product_id":"BTC-USD","updates":[{"side":"bid","event_time":"2026-07-16T20:29:14.458181Z","price_level":"64135","new_quantity":"0.0149568"},{"side":"bid","event_time":"2026-07-16T20:29:14.458181Z","price_level":"64129.19","new_quantity":"0.02"},{"side":"offer","event_time":"2026-07-16T20:29:14.458181Z","price_level":"64147","new_quantity":"0.00009743"},{"side":"offer","event_time":"2026-07-16T20:29:14.458181Z","price_level":"64147.96","new_quantity":"0.00779448"}]}]}
{"channel":"l2_data","timestamp":"2026-07-16T20:29:14.534096337Z","sequence_num":450,"events":[{"type":"update","product_id":"BTC-USD","updates":[{"side":"bid","event_time":"2026-07-16T20:29:14.50838Z","price_level":"64135","new_quantity":"0.00495769"},{"side":"bid","event_time":"2026-07-16T20:29:14.50838Z","price_level":"64125.97","new_quantity":"0"},{"side":"bid","event_time":"2026-07-16T20:29:14.50838Z","price_level":"64124.92","new_quantity":"0.01559176"},{"side":"bid","event_time":"2026-07-16T20:29:14.50838Z","price_level":"64124.81","new_quantity":"0"},{"side":"bid","event_time":"2026-07-16T20:29:14.50838Z","price_level":"56118.13","new_quantity":"0.01337205"},{"side":"offer","event_time":"2026-07-16T20:29:14.50838Z","price_level":"64364.65","new_quantity":"0.00583"},{"side":"offer","event_time":"2026-07-16T20:29:14.50838Z","price_level":"64580.06","new_quantity":"0"}]}]}
{"channel":"l2_data","timestamp":"2026-07-16T20:29:14.579948726Z","sequence_num":451,"events":[{"type":"update","product_id":"BTC-USD","updates":[{"side":"bid","event_time":"2026-07-16T20:29:14.557906Z","price_level":"64135","new_quantity":"0.00101808"},{"side":"bid","event_time":"2026-07-16T20:29:14.557906Z","price_level":"64125.97","new_quantity":"0.31190852"}]}]}
{"channel":"l2_data","timestamp":"2026-07-16T20:29:14.630557589Z","sequence_num":452,"events":[{"type":"update","product_id":"BTC-USD","updates":[{"side":"bid","event_time":"2026-07-16T20:29:14.605614Z","price_level":"64121.36","new_quantity":"0.608008"},{"side":"bid","event_time":"2026-07-16T20:29:14.605614Z","price_level":"64104.97","new_quantity":"0"},{"side":"bid","event_time":"2026-07-16T20:29:14.605614Z","price_level":"56118.13","new_quantity":"0"},{"side":"offer","event_time":"2026-07-16T20:29:14.605614Z","price_level":"64364.61","new_quantity":"0.00583"},{"side":"offer","event_time":"2026-07-16T20:29:14.605614Z","price_level":"64365.01","new_quantity":"0"}]}]}
{"channel":"l2_data","timestamp":"2026-07-16T20:29:14.674732016Z","sequence_num":453,"events":[{"type":"update","product_id":"BTC-USD","updates":[{"side":"bid","event_time":"2026-07-16T20:29:14.632437Z","price_level":"64121.36","new_quantity":"0"},{"side":"bid","event_time":"2026-07-16T20:29:14.632437Z","price_level":"64093.79","new_quantity":"0.00050097"}]}]}
{"channel":"l2_data","timestamp":"2026-07-16T20:29:14.725251922Z","sequence_num":454,"events":[{"type":"update","product_id":"BTC-USD","updates":[{"side":"bid","event_time":"2026-07-16T20:29:14.693889Z","price_level":"64128.6","new_quantity":"0.02"}]}]}
{"channel":"l2_data","timestamp":"2026-07-16T20:29:14.780123763Z","sequence_num":455,"events":[{"type":"update","product_id":"BTC-USD","updates":[{"side":"bid","event_time":"2026-07-16T20:29:14.753083Z","price_level":"64135","new_quantity":"0.00020222"},{"side":"bid","event_time":"2026-07-16T20:29:14.753083Z","price_level":"64133.71","new_quantity":"0.00867133"},{"side":"bid","event_time":"2026-07-16T20:29:14.753083Z","price_level":"64129.91","new_quantity":"0.12474677"},{"side":"bid","event_time":"2026-07-16T20:29:14.753083Z","price_level":"64129.18","new_quantity":"0"},{"side":"bid","event_time":"2026-07-16T20:29:14.753083Z","price_level":"64128.59","new_quantity":"0"},{"side":"bid","event_time":"2026-07-16T20:29:14.753083Z","price_level":"64109","new_quantity":"0"},{"side":"offer","event_time":"2026-07-16T20:29:14.753083Z","price_level":"64135.01","new_quantity":"1.14421264"},{"side":"offer","event_time":"2026-07-16T20:29:14.753083Z","price_level":"64137.06","new_quantity":"0.027"},{"side":"offer","event_time":"2026-07-16T20:29:14.753083Z","price_level":"64137.46","new_quantity":"0.27094225"},{"side":"offer","event_time":"2026-07-16T20:29:14.753083Z","price_level":"64137.48","new_quantity":"0"},{"side":"offer","event_time":"2026-07-16T20:29:14.753083Z","price_level":"64137.49","new_quantity":"0"},{"side":"offer","event_time":"2026-07-16T20:29:14.753083Z","price_level":"64138.34","new_quantity":"0.31190852"},{"side":"offer","event_time":"2026-07-16T20:29:14.753083Z","price_level":"64139.17","new_quantity":"0"},{"side":"offer","event_time":"2026-07-16T20:29:14.753083Z","price_level":"64139.18","new_quantity":"0.04691558"},{"side":"offer","event_time":"2026-07-16T20:29:14.753083Z","price_level":"64149.8","new_quantity":"0.00779426"},{"side":"offer","event_time":"2026-07-16T20:29:14.753083Z","price_level":"64364.65","new_quantity":"0"},{"side":"offer","event_time":"2026-07-16T20:29:14.753083Z","price_level":"65009.1","new_quantity":"0.00583"},{"side":"offer","event_time":"2026-07-16T20:29:14.753083Z","price_level":"65009.82","new_quantity":"0"},{"side":"offer","event_time":"2026-07-16T20:29:14.753083Z","price_level":"65224.38","new_quantity":"0.00583"},{"side":"offer","event_time":"2026-07-16T20:29:14.753083Z","price_level":"65652.6","new_quantity":"0"}]}]}
{"channel":"l2_data","timestamp":"2026-07-16T20:29:14.831397862Z","sequence_num":456,"events":[{"type":"update","product_id":"BTC-USD","updates":[{"side":"bid","event_time":"2026-07-16T20:29:14.808777Z","price_level":"64128.59","new_quantity":"0.00779683"},{"side":"bid","event_time":"2026-07-16T20:29:14.808777Z","price_level":"64110","new_quantity":"1.01"},{"side":"bid","event_time":"2026-07-16T20:29:14.808777Z","price_level":"56118.13","new_quantity":"0.01337205"},{"side":"offer","event_time":"2026-07-16T20:29:14.808777Z","price_level":"64135.01","new_quantity":"1.14406478"},{"side":"offer","event_time":"2026-07-16T20:29:14.808777Z","price_level":"64142.56","new_quantity":"0.22533829"},{"side":"offer","event_time":"2026-07-16T20:29:14.808777Z","price_level":"64142.57","new_quantity":"0"},{"side":"offer","event_time":"2026-07-16T20:29:14.808777Z","price_level":"64145.62","new_quantity":"0.91418589"},{"side":"offer","event_time":"2026-07-16T20:29:14.808777Z","price_level":"64145.63","new_quantity":"0.65499292"},{"side":"offer","event_time":"2026-07-16T20:29:14.808777Z","price_level":"64145.64","new_quantity":"0"},{"side":"offer","event_time":"2026-07-16T20:29:14.808777Z","price_level":"64149.31","new_quantity":"0.6366932"},{"side":"offer","event_time":"2026-07-16T20:29:14.808777Z","price_level":"64149.42","new_quantity":"0.00896345"},{"side":"offer","event_time":"2026-07-16T20:29:14.808777Z","price_level":"64150","new_quantity":"0.01583"},{"side":"offer","event_time":"2026-07-16T20:29:14.808777Z","price_level":"64151.99","new_quantity":"1.05695538"},{"side":"offer","event_time":"2026-07-16T20:29:14.808777Z","price_level":"64152","new_quantity":"1"},{"side":"offer","event_time":"2026-07-16T20:29:14.808777Z","price_level":"64152.29","new_quantity":"0"},{"side":"offer","event_time":"2026-07-16T20:29:14.808777Z","price_level":"64158.49","new_quantity":"0"},{"side":"offer","event_time":"2026-07-16T20:29:14.808777Z","price_level":"65009.08","new_quantity":"0.00583"},{"side":"offer","event_time":"2026-07-16T20:29:14.808777Z","price_level":"65009.1","new_quantity":"0"},{"side":"offer","event_time":"2026-07-16T20:29:14.808777Z","price_level":"65224.24","new_quantity":"0.00583"},{"side":"offer","event_time":"2026-07-16T20:29:14.808777Z","price_level":"65436.58","new_quantity":"0"}]}]}
{"channel":"l2_data","timestamp":"2026-07-16T20:29:14.882092598Z","sequence_num":457,"events":[{"type":"update","product_id":"BTC-USD","updates":[{"side":"bid","event_time":"2026-07-16T20:29:14.852468Z","price_level":"64130.19","new_quantity":"0.00779664"},{"side":"bid","event_time":"2026-07-16T20:29:14.852468Z","price_level":"64129.19","new_quantity":"0"},{"side":"bid","event_time":"2026-07-16T20:29:14.852468Z","price_level":"64128.65","new_quantity":"0.02"},{"side":"bid","event_time":"2026-07-16T20:29:14.852468Z","price_level":"64121.54","new_quantity":"0.602166"},{"side":"offer","event_time":"2026-07-16T20:29:14.852468Z","price_level":"64147.82","new_quantity":"0.00896367"},{"side":"offer","event_time":"2026-07-16T20:29:14.852468Z","price_level":"64148.2","new_quantity":"0.31190852"}]}]}
{"channel":"l2_data","timestamp":"2026-07-16T20:29:14.927436659Z","sequence_num":458,"events":[{"type":"update","product_id":"BTC-USD","updates":[{"side":"bid","event_time":"2026-07-16T20:29:14.89555Z","price_level":"64121.54","new_quantity":"0"},{"side":"bid","event_time":"2026-07-16T20:29:14.89555Z","price_level":"56118.13","new_quantity":"0"}]}]}
{"channel":"l2_data","timestamp":"2026-07-16T20:29:14.985185342Z","sequence_num":459,"events":[{"type":"update","product_id":"BTC-USD","updates":[{"side":"bid","event_time":"2026-07-16T20:29:14.952779Z","price_level":"64130.74","new_quantity":"0.12474515"},{"side":"bid","event_time":"2026-07-16T20:29:14.952779Z","price_level":"64125.96","new_quantity":"0"},{"side":"bid","event_time":"2026-07-16T20:29:14.952779Z","price_level":"64121.3","new_quantity":"0.07416"},{"side":"bid","event_time":"2026-07-16T20:29:14.952779Z","price_level":"64050.84","new_quantity":"0.01061683"},{"side":"offer","event_time":"2026-07-16T20:29:14.952779Z","price_level":"64139.19","new_quantity":"0.72659786"},{"side":"offer","event_time":"2026-07-16T20:29:14.952779Z","price_level":"64140.7","new_quantity":"0.65501906"},{"side":"offer","event_time":"2026-07-16T20:29:14.952779Z","price_level":"64145.62","new_quantity":"0.52309698"},{"side":"offer","event_time":"2026-07-16T20:29:14.952779Z","price_level":"64145.63","new_quantity":"0"},{"side":"offer","event_time":"2026-07-16T20:29:14.952779Z","price_level":"64148.13","new_quantity":"0.00009743"},{"side":"offer","event_time":"2026-07-16T20:29:14.952779Z","price_level":"64148.51","new_quantity":"0"},{"side":"offer","event_time":"2026-07-16T20:29:14.952779Z","price_level":"64149.42","new_quantity":"0.01675775"},{"side":"offer","event_time":"2026-07-16T20:29:14.952779Z","price_level":"64149.8","new_quantity":"0"},{"side":"offer","event_time":"2026-07-16T20:29:14.952779Z","price_level":"64158.47","new_quantity":"0.00867133"}]}]}
{"channel":"l2_data","timestamp":"2026-07-16T20:29:15.027794494Z","sequence_num":460,"events":[{"type":"update","product_id":"BTC-USD","updates":[{"side":"offer","event_time":"2026-07-16T20:29:14.988048Z","price_level":"64139.19","new_quantity":"0.44529932"},{"side":"offer","event_time":"2026-07-16T20:29:14.988048Z","price_level":"64140.7","new_quantity":"0"},{"side":"offer","event_time":"2026-07-16T20:29:14.988048Z","price_level":"64142.54","new_quantity":"0.61638181"},{"side":"offer","event_time":"2026-07-16T20:29:14.988048Z","price_level":"64142.55","new_quantity":"0.65501427"},{"side":"offer","event_time":"2026-07-16T20:29:14.988048Z","price_level":"64142.56","new_quantity":"0"}]}]}
{"channel":"l2_data","timestamp":"2026-07-16T20:29:15.082122399Z","sequence_num":461,"events":[{"type":"update","product_id":"BTC-USD","updates":[{"side":"bid","event_time":"2026-07-16T20:29:15.059137Z","price_level":"64130.74","new_quantity":"0"},{"side":"bid","event_time":"2026-07-16T20:29:15.059137Z","price_level":"64129.92","new_quantity":"0.02"},{"side":"bid","event_time":"2026-07-16T20:29:15.059137Z","price_level":"64127.79","new_quantity":"0.15593861"},{"side":"bid","event_time":"2026-07-16T20:29:15.059137Z","price_level":"64125.4","new_quantity":"0.01559176"},{"side":"bid","event_time":"2026-07-16T20:29:15.059137Z","price_level":"64124.92","new_quantity":"0"},{"side":"bid","event_time":"2026-07-16T20:29:15.059137Z","price_level":"64118.1","new_quantity":"0"},{"side":"bid","event_time":"2026-07-16T20:29:15.059137Z","price_level":"64109.04","new_quantity":"0.00156558"},{"side":"bid","event_time":"2026-07-16T20:29:15.059137Z","price_level":"64050.84","new_quantity":"0"},{"side":"bid","event_time":"2026-07-16T20:29:15.059137Z","price_level":"63731.07","new_quantity":"0"},{"side":"offer","event_time":"2026-07-16T20:29:15.059137Z","price_level":"64147","new_quantity":"0"},{"side":"offer","event_time":"2026-07-16T20:29:15.059137Z","price_level":"64147.96","new_quantity":"0"},{"side":"offer","event_time":"2026-07-16T20:29:15.059137Z","price_level":"64174.35","new_quantity":"0.87435631"}]}]}
{"channel":"l2_data","timestamp":"2026-07-16T20:29:15.130576917Z","sequence_num":462,"events":[{"type":"update","product_id":"BTC-USD","updates":[{"side":"bid","event_time":"2026-07-16T20:29:15.105693Z","price_level":"64121.44","new_quantity":"0"},{"side":"bid","event_time":"2026-07-16T20:29:15.105693Z","price_level":"64029.84","new_quantity":"0"},{"side":"bid","event_time":"2026-07-16T20:29:15.105693Z","price_level":"56118.13","new_quantity":"0.01337205"},{"side":"offer","event_time":"2026-07-16T20:29:15.105693Z","price_level":"64158.47","new_quantity":"0"},{"side":"offer","event_time":"2026-07-16T20:29:15.105693Z","price_level":"64222.22","new_quantity":"0"}]}]}
{"channel":"heartbeats","timestamp":"2026-07-16T20:29:15.166408248Z","sequence_num":463,"events":[{"current_time":"2026-07-16 20:29:15.162888507 +0000 UTC m=+75519.317715543","heartbeat_counter":75519}]}
{"channel":"l2_data","timestamp":"2026-07-16T20:29:15.237306298Z","sequence_num":464,"events":[{"type":"update","product_id":"BTC-USD","updates":[{"side":"bid","event_time":"2026-07-16T20:29:15.190908Z","price_level":"56118.13","new_quantity":"0"}]}]}
{"channel":"l2_data","timestamp":"2026-07-16T20:29:15.294160107Z","sequence_num":465,"events":[{"type":"update","product_id":"BTC-USD","updates":[{"side":"bid","event_time":"2026-07-16T20:29:15.235198Z","price_level":"64135","new_quantity":"0.0002022"},{"side":"bid","event_time":"2026-07-16T20:29:15.235198Z","price_level":"63730.17","new_quantity":"0.01061683"},{"side":"offer","event_time":"2026-07-16T20:29:15.235198Z","price_level":"64158.48","new_quantity":"0.00867133"}]}]}
{"channel":"l2_data","timestamp":"2026-07-16T20:29:15.340077941Z","sequence_num":466,"events":[{"type":"update","product_id":"BTC-USD","updates":[{"side":"bid","event_time":"2026-07-16T20:29:15.302789Z","price_level":"64135","new_quantity":"0.00469167"},{"side":"bid","event_time":"2026-07-16T20:29:15.302789Z","price_level":"64027.25","new_quantity":"0.09382259"},{"side":"offer","event_time":"2026-07-16T20:29:15.302789Z","price_level":"64219.63","new_quantity":"0.05257225"},{"side":"offer","event_time":"2026-07-16T20:29:15.302789Z","price_level":"65009.07","new_quantity":"0.00583"},{"side":"offer","event_time":"2026-07-16T20:29:15.302789Z","price_level":"65224.38","new_quantity":"0"}]}]}
{"channel":"l2_data","timestamp":"2026-07-16T20:29:15.444795772Z","sequence_num":467,"events":[{"type":"update","product_id":"BTC-USD","updates":[{"side":"bid","event_time":"2026-07-16T20:29:15.39384Z","price_level":"64121.61","new_quantity":"0.633396"},{"side":"bid","event_time":"2026-07-16T20:29:15.39384Z","price_level":"56118.13","new_quantity":"0.01337205"},{"side":"offer","event_time":"2026-07-16T20:29:15.39384Z","price_level":"64158.48","new_quantity":"0"}]}]}
{"channel":"l2_data","timestamp":"2026-07-16T20:29:15.520770939Z","sequence_num":468,"events":[{"type":"update","product_id":"BTC-USD","updates":[{"side":"bid","event_time":"2026-07-16T20:29:15.451213Z","price_level":"64135","new_quantity":"0.0002022"},{"side":"bid","event_time":"2026-07-16T20:29:15.451213Z","price_level":"64130.2","new_quantity":"0.02"},{"side":"bid","event_time":"2026-07-16T20:29:15.451213Z","price_level":"64121.61","new_quantity":"0"},{"side":"offer","event_time":"2026-07-16T20:29:15.451213Z","price_level":"64579.49","new_quantity":"0.00583"},{"side":"offer","event_time":"2026-07-16T20:29:15.451213Z","price_level":"65009.08","new_quantity":"0"}]}]}
{"channel":"l2_data","timestamp":"2026-07-16T20:29:15.530980825Z","sequence_num":469,"events":[{"type":"update","product_id":"BTC-USD","updates":[{"side":"bid","event_time":"2026-07-16T20:29:15.485802Z","price_level":"64135","new_quantity":"0.00020215"}]}]}
{"channel":"l2_data","timestamp":"2026-07-16T20:29:15.88678803Z","sequence_num":470,"events":[{"type":"update","product_id":"BTC-USD","updates":[{"side":"bid","event_time":"2026-07-16T20:29:15.539041Z","price_level":"64130.2","new_quantity":"0"},{"side":"bid","event_time":"2026-07-16T20:29:15.539041Z","price_level":"64129.92","new_quantity":"0"},{"side":"bid","event_time":"2026-07-16T20:29:15.539041Z","price_level":"64128.65","new_quantity":"0"},{"side":"bid","event_time":"2026-07-16T20:29:15.539041Z","price_level":"56118.13","new_quantity":"0"},{"side":"offer","event_time":"2026-07-16T20:29:15.539041Z","price_level":"64158.48","new_quantity":"0.00867133"}]}]}
{"channel":"l2_data","timestamp":"2026-07-16T20:29:15.887387364Z","sequence_num":471,"events":[{"type":"update","product_id":"BTC-USD","updates":[{"side":"offer","event_time":"2026-07-16T20:29:15.585834Z","price_level":"64147.6","new_quantity":"0.00779452"}]}]}
{"channel":"l2_data","timestamp":"2026-07-16T20:29:15.888053391Z","sequence_num":472,"events":[{"type":"update","product_id":"BTC-USD","updates":[{"side":"bid","event_time":"2026-07-16T20:29:15.656711Z","price_level":"64135","new_quantity":"0.00230746"},{"side":"bid","event_time":"2026-07-16T20:29:15.656711Z","price_level":"64133.71","new_quantity":"0.00779621"},{"side":"bid","event_time":"2026-07-16T20:29:15.656711Z","price_level":"64128.65","new_quantity":"0.02"},{"side":"bid","event_time":"2026-07-16T20:29:15.656711Z","price_level":"64121.58","new_quantity":"0"},{"side":"bid","event_time":"2026-07-16T20:29:15.656711Z","price_level":"64121.3","new_quantity":"0"},{"side":"offer","event_time":"2026-07-16T20:29:15.656711Z","price_level":"64146.63","new_quantity":"0.00009743"},{"side":"offer","event_time":"2026-07-16T20:29:15.656711Z","price_level":"64579.32","new_quantity":"0.00583"},{"side":"offer","event_time":"2026-07-16T20:29:15.656711Z","price_level":"64579.81","new_quantity":"0"}]}]}
{"channel":"l2_data","timestamp":"2026-07-16T20:29:15.889640488Z","sequence_num":473,"events":[{"type":"update","product_id":"BTC-USD","updates":[{"side":"bid","event_time":"2026-07-16T20:29:15.699816Z","price_level":"64129.91","new_quantity":"0"},{"side":"bid","event_time":"2026-07-16T20:29:15.699816Z","price_level":"64128.73","new_quantity":"0"},{"side":"bid","event_time":"2026-07-16T20:29:15.699816Z","price_level":"64128.65","new_quantity":"0"},{"side":"bid","event_time":"2026-07-16T20:29:15.699816Z","price_level":"64128.6","new_quantity":"0"},{"side":"bid","event_time":"2026-07-16T20:29:15.699816Z","price_level":"64128.43","new_quantity":"0"},{"side":"bid","event_time":"2026-07-16T20:29:15.699816Z","price_level":"64128.05","new_quantity":"0"},{"side":"bid","event_time":"2026-07-16T20:29:15.699816Z","price_level":"64127.79","new_quantity":"0"},{"side":"bid","event_time":"2026-07-16T20:29:15.699816Z","price_level":"64126.24","new_quantity":"0.1247539"},{"side":"bid","event_time":"2026-07-16T20:29:15.699816Z","price_level":"64126.11","new_quantity":"0"},{"side":"bid","event_time":"2026-07-16T20:29:15.699816Z","price_level":"64125.97","new_quantity":"0"},{"side":"bid","event_time":"2026-07-16T20:29:15.699816Z","price_level":"64125.69","new_quantity":"0"},{"side":"bid","event_time":"2026-07-16T20:29:15.699816Z","price_level":"64125.4","new_quantity":"0"},{"side":"bid","event_time":"2026-07-16T20:29:15.699816Z","price_level":"64123.89","new_quantity":"0"},{"side":"bid","event_time":"2026-07-16T20:29:15.699816Z","price_level":"64123.73","new_quantity":"0.01559176"},{"side":"bid","event_time":"2026-07-16T20:29:15.699816Z","price_level":"64119.22","new_quantity":"0"},{"side":"bid","event_time":"2026-07-16T20:29:15.699816Z","price_level":"64118.1","new_quantity":"0.07418"},{"side":"bid","event_time":"2026-07-16T20:29:15.699816Z","price_level":"64116.06","new_quantity":"0"},{"side":"bid","event_time":"2026-07-16T20:29:15.699816Z","price_level":"64111.36","new_quantity":"0"},{"side":"bid","event_time":"2026-07-16T20:29:15.699816Z","price_level":"64110","new_quantity":"0.01"},{"side":"bid","event_time":"2026-07-16T20:29:15.699816Z","price_level":"64107.38","new_quantity":"0.00583"},{"side":"bid","event_time":"2026-07-16T20:29:15.699816Z","price_level":"64107.37","new_quantity":"0"},{"side":"bid","event_time":"2026-07-16T20:29:15.699816Z","price_level":"64096.79","new_quantity":"0"},{"side":"bid","event_time":"2026-07-16T20:29:15.699816Z","price_level":"64095.73","new_quantity":"0"},{"side":"bid","event_time":"2026-07-16T20:29:15.699816Z","price_level":"64094.23","new_quantity":"0"},{"side":"bid","event_time":"2026-07-16T20:29:15.699816Z","price_level":"64090.42","new_quantity":"0.5"},{"side":"bid","event_time":"2026-07-16T20:29:15.699816Z","price_level":"64090.38","new_quantity":"0"},{"side":"bid","event_time":"2026-07-16T20:29:15.699816Z","price_level":"64075.2","new_quantity":"0"},{"side":"bid","event_time":"2026-07-16T20:29:15.699816Z","price_level":"63900.87","new_quantity":"0"},{"side":"bid","event_time":"2026-07-16T20:29:15.699816Z","price_level":"63892.55","new_quantity":"0.00583"},{"side":"bid","event_time":"2026-07-16T20:29:15.699816Z","price_level":"62827.46","new_quantity":"0"},{"side":"bid","event_time":"2026-07-16T20:29:15.699816Z","price_level":"62820.37","new_quantity":"0.00583"},{"side":"bid","event_time":"2026-07-16T20:29:15.699816Z","price_level":"56118.13","new_quantity":"0.01337205"},{"side":"offer","event_time":"2026-07-16T20:29:15.699816Z","price_level":"64147.38","new_quantity":"0.00583"},{"side":"offer","event_time":"2026-07-16T20:29:15.699816Z","price_level":"64147.39","new_quantity":"0.00583"},{"side":"offer","event_time":"2026-07-16T20:29:15.699816Z","price_level":"64147.46","new_quantity":"0"},{"side":"offer","event_time":"2026-07-16T20:29:15.699816Z","price_level":"64150","new_quantity":"0.01"},{"side":"offer","event_time":"2026-07-16T20:29:15.699816Z","price_level":"64151.99","new_quantity":"0"},{"side":"offer","event_time":"2026-07-16T20:29:15.699816Z","price_level":"64152","new_quantity":"0"},{"side":"offer","event_time":"2026-07-16T20:29:15.699816Z","price_level":"64219.66","new_quantity":"0"},{"side":"offer","event_time":"2026-07-16T20:29:15.699816Z","price_level":"64361.82","new_quantity":"0.00583"},{"side":"offer","event_time":"2026-07-16T20:29:15.699816Z","price_level":"64361.85","new_quantity":"0"},{"side":"offer","event_time":"2026-07-16T20:29:15.699816Z","price_level":"64364.61","new_quantity":"0"},{"side":"offer","event_time":"2026-07-16T20:29:15.699816Z","price_level":"64579.49","new_quantity":"0"},{"side":"offer","event_time":"2026-07-16T20:29:15.699816Z","price_level":"65009.07","new_quantity":"0"},{"side":"offer","event_time":"2026-07-16T20:29:15.699816Z","price_level":"65219.53","new_quantity":"0.00583"},{"side":"offer","event_time":"2026-07-16T20:29:15.699816Z","price_level":"65219.54","new_quantity":"0.00583"},{"side":"offer","event_time":"2026-07-16T20:29:15.699816Z","price_level":"65224.24","new_quantity":"0"},{"side":"offer","event_time":"2026-07-16T20:29:15.699816Z","price_level":"65433.97","new_quantity":"0"}]}]}
{"channel":"l2_data","timestamp":"2026-07-16T20:29:15.893514736Z","sequence_num":474,"events":[{"type":"update","product_id":"BTC-USD","updates":[{"side":"bid","event_time":"2026-07-16T20:29:15.752122Z","price_level":"64128.64","new_quantity":"0"},{"side":"bid","event_time":"2026-07-16T20:29:15.752122Z","price_level":"64123.74","new_quantity":"0.01559176"},{"side":"bid","event_time":"2026-07-16T20:29:15.752122Z","price_level":"64123.73","new_quantity":"0"},{"side":"bid","event_time":"2026-07-16T20:29:15.752122Z","price_level":"64117.91","new_quantity":"0.00010019"},{"side":"bid","event_time":"2026-07-16T20:29:15.752122Z","price_level":"64105","new_quantity":"1.01"},{"side":"bid","event_time":"2026-07-16T20:29:15.752122Z","price_level":"64102.76","new_quantity":"0"},{"side":"bid","event_time":"2026-07-16T20:29:15.752122Z","price_level":"64096.91","new_quantity":"0.65505454"},{"side":"bid","event_time":"2026-07-16T20:29:15.752122Z","price_level":"62820.4","new_quantity":"0.00583"},{"side":"bid","event_time":"2026-07-16T20:29:15.752122Z","price_level":"62820.38","new_quantity":"0"},{"side":"bid","event_time":"2026-07-16T20:29:15.752122Z","price_level":"62820.37","new_quantity":"0"},{"side":"offer","event_time":"2026-07-16T20:29:15.752122Z","price_level":"64142.54","new_quantity":"0.22533829"},{"side":"offer","event_time":"2026-07-16T20:29:15.752122Z","price_level":"64142.55","new_quantity":"0"},{"side":"offer","event_time":"2026-07-16T20:29:15.752122Z","price_level":"64147.39","new_quantity":"0"},{"side":"offer","event_time":"2026-07-16T20:29:15.752122Z","price_level":"64149.31","new_quantity":"1.202589"},{"side":"offer","event_time":"2026-07-16T20:29:15.752122Z","price_level":"64150","new_quantity":"1.01"},{"side":"offer","event_time":"2026-07-16T20:29:15.752122Z","price_level":"64155.19","new_quantity":"0"},{"side":"offer","event_time":"2026-07-16T20:29:15.752122Z","price_level":"64208.29","new_quantity":"0.00766564"},{"side":"offer","event_time":"2026-07-16T20:29:15.752122Z","price_level":"64361.81","new_quantity":"0.00583"},{"side":"offer","event_time":"2026-07-16T20:29:15.752122Z","price_level":"64361.82","new_quantity":"0"},{"side":"offer","event_time":"2026-07-16T20:29:15.752122Z","price_level":"64576.25","new_quantity":"0.00583"},{"side":"offer","event_time":"2026-07-16T20:29:15.752122Z","price_level":"64576.26","new_quantity":"0"},{"side":"offer","event_time":"2026-07-16T20:29:15.752122Z","price_level":"64579.32","new_quantity":"0"},{"side":"offer","event_time":"2026-07-16T20:29:15.752122Z","price_level":"65219.54","new_quantity":"0"},{"side":"offer","event_time":"2026-07-16T20:29:15.752122Z","price_level":"65433.96","new_quantity":"0"},{"side":"offer","event_time":"2026-07-16T20:29:15.752122Z","price_level":"65433.99","new_quantity":"0"},{"side":"offer","event_time":"2026-07-16T20:29:15.752122Z","price_level":"65648.42","new_quantity":"0"}]}]}
{"channel":"l2_data","timestamp":"2026-07-16T20:29:15.895368293Z","sequence_num":475,"events":[{"type":"update","product_id":"BTC-USD","updates":[{"side":"bid","event_time":"2026-07-16T20:29:15.812868Z","price_level":"64128.59","new_quantity":"0"},{"side":"bid","event_time":"2026-07-16T20:29:15.812868Z","price_level":"64126.85","new_quantity":"0.31190852"},{"side":"bid","event_time":"2026-07-16T20:29:15.812868Z","price_level":"64126.82","new_quantity":"0.12475277"},{"side":"bid","event_time":"2026-07-16T20:29:15.812868Z","price_level":"64126.24","new_quantity":"0"},{"side":"bid","event_time":"2026-07-16T20:29:15.812868Z","price_level":"64123.83","new_quantity":"0.31190852"},{"side":"bid","event_time":"2026-07-16T20:29:15.812868Z","price_level":"64123.75","new_quantity":"0.15594845"},{"side":"bid","event_time":"2026-07-16T20:29:15.812868Z","price_level":"64120.01","new_quantity":"0"},{"side":"bid","event_time":"2026-07-16T20:29:15.812868Z","price_level":"64118.74","new_quantity":"0.0077892"},{"side":"bid","event_time":"2026-07-16T20:29:15.812868Z","price_level":"64102.76","new_quantity":"0.6550435"},{"side":"bid","event_time":"2026-07-16T20:29:15.812868Z","price_level":"64099.22","new_quantity":"0"},{"side":"bid","event_time":"2026-07-16T20:29:15.812868Z","price_level":"64097.46","new_quantity":"0.00155816"},{"side":"bid","event_time":"2026-07-16T20:29:15.812868Z","price_level":"64096.91","new_quantity":"0"},{"side":"bid","event_time":"2026-07-16T20:29:15.812868Z","price_level":"64092.81","new_quantity":"0"},{"side":"bid","event_time":"2026-07-16T20:29:15.812868Z","price_level":"64091.05","new_quantity":"0.24138127"},{"side":"bid","event_time":"2026-07-16T20:29:15.812868Z","price_level":"63686.26","new_quantity":"0"},{"side":"bid","event_time":"2026-07-16T20:29:15.812868Z","price_level":"56118.13","new_quantity":"0"},{"side":"offer","event_time":"2026-07-16T20:29:15.812868Z","price_level":"64135.01","new_quantity":"1.14262082"},{"side":"offer","event_time":"2026-07-16T20:29:15.812868Z","price_level":"64144.6","new_quantity":"0.0077892"},{"side":"offer","event_time":"2026-07-16T20:29:15.812868Z","price_level":"64144.61","new_quantity":"0.0001164"},{"side":"offer","event_time":"2026-07-16T20:29:15.812868Z","price_level":"64144.87","new_quantity":"0"},{"side":"offer","event_time":"2026-07-16T20:29:15.812868Z","price_level":"64147.26","new_quantity":"0.00583"},{"side":"offer","event_time":"2026-07-16T20:29:15.812868Z","price_level":"64147.38","new_quantity":"0"},{"side":"offer","event_time":"2026-07-16T20:29:15.812868Z","price_level":"64149.42","new_quantity":"0.0077943"},{"side":"offer","event_time":"2026-07-16T20:29:15.812868Z","price_level":"64256.65","new_quantity":"0"},{"side":"offer","event_time":"2026-07-16T20:29:15.812868Z","price_level":"65219.45","new_quantity":"0.00583"},{"side":"offer","event_time":"2026-07-16T20:29:15.812868Z","price_level":"65219.53","new_quantity":"0"}]}]}
{"channel":"l2_data","timestamp":"2026-07-16T20:29:15.896256424Z","sequence_num":476,"events":[{"type":"update","product_id":"BTC-USD","updates":[{"side":"bid","event_time":"2026-07-16T20:29:15.845607Z","price_level":"64128.59","new_quantity":"0.00779683"},{"side":"bid","event_time":"2026-07-16T20:29:15.845607Z","price_level":"64126.87","new_quantity":"0.31190852"},{"side":"bid","event_time":"2026-07-16T20:29:15.845607Z","price_level":"64126.86","new_quantity":"0.04691558"},{"side":"bid","event_time":"2026-07-16T20:29:15.845607Z","price_level":"64126.85","new_quantity":"0"},{"side":"bid","event_time":"2026-07-16T20:29:15.845607Z","price_level":"64126.84","new_quantity":"0"},{"side":"bid","event_time":"2026-07-16T20:29:15.845607Z","price_level":"64124.39","new_quantity":"0.01559176"},{"side":"bid","event_time":"2026-07-16T20:29:15.845607Z","price_level":"64123.84","new_quantity":"0.31190852"},{"side":"bid","event_time":"2026-07-16T20:29:15.845607Z","price_level":"64123.83","new_quantity":"0"},{"side":"bid","event_time":"2026-07-16T20:29:15.845607Z","price_level":"64123.74","new_quantity":"0"},{"side":"bid","event_time":"2026-07-16T20:29:15.845607Z","price_level":"64120.88","new_quantity":"0.637266"},{"side":"bid","event_time":"2026-07-16T20:29:15.845607Z","price_level":"64117.02","new_quantity":"0.06"},{"side":"bid","event_time":"2026-07-16T20:29:15.845607Z","price_level":"64115.57","new_quantity":"0.23359045"},{"side":"bid","event_time":"2026-07-16T20:29:15.845607Z","price_level":"64115.56","new_quantity":"0"},{"side":"bid","event_time":"2026-07-16T20:29:15.845607Z","price_level":"64110.92","new_quantity":"0.00779621"},{"side":"bid","event_time":"2026-07-16T20:29:15.845607Z","price_level":"64105","new_quantity":"0.01"},{"side":"bid","event_time":"2026-07-16T20:29:15.845607Z","price_level":"64027.25","new_quantity":"0"},{"side":"bid","event_time":"2026-07-16T20:29:15.845607Z","price_level":"63892.73","new_quantity":"0.00583"},{"side":"bid","event_time":"2026-07-16T20:29:15.845607Z","price_level":"63892.55","new_quantity":"0"},{"side":"bid","event_time":"2026-07-16T20:29:15.845607Z","price_level":"62820.58","new_quantity":"0.00583"},{"side":"bid","event_time":"2026-07-16T20:29:15.845607Z","price_level":"62820.4","new_quantity":"0"},{"side":"offer","event_time":"2026-07-16T20:29:15.845607Z","price_level":"64149.06","new_quantity":"0.0089635"},{"side":"offer","event_time":"2026-07-16T20:29:15.845607Z","price_level":"64244.82","new_quantity":"0.00958205"},{"side":"offer","event_time":"2026-07-16T20:29:15.845607Z","price_level":"64280.25","new_quantity":"0"}]}]}
{"channel":"l2_data","timestamp":"2026-07-16T20:29:15.931223122Z","sequence_num":477,"events":[{"type":"update","product_id":"BTC-USD","updates":[{"side":"bid","event_time":"2026-07-16T20:29:15.904737Z","price_level":"64130.19","new_quantity":"0.00779664"},{"side":"bid","event_time":"2026-07-16T20:29:15.904737Z","price_level":"64120.88","new_quantity":"0"},{"side":"bid","event_time":"2026-07-16T20:29:15.904737Z","price_level":"64104","new_quantity":"1"},{"side":"bid","event_time":"2026-07-16T20:29:15.904737Z","price_level":"64102.77","new_quantity":"0"},{"side":"bid","event_time":"2026-07-16T20:29:15.904737Z","price_level":"64102.76","new_quantity":"0.65582309"},{"side":"bid","event_time":"2026-07-16T20:29:15.904737Z","price_level":"64074.38","new_quantity":"0"},{"side":"bid","event_time":"2026-07-16T20:29:15.904737Z","price_level":"64070.13","new_quantity":"1.41596236"},{"side":"offer","event_time":"2026-07-16T20:29:15.904737Z","price_level":"64147.46","new_quantity":"0.00896372"},{"side":"offer","event_time":"2026-07-16T20:29:15.904737Z","price_level":"64147.82","new_quantity":"0"},{"side":"offer","event_time":"2026-07-16T20:29:15.904737Z","price_level":"64174.34","new_quantity":"0.46378073"},{"side":"offer","event_time":"2026-07-16T20:29:15.904737Z","price_level":"64174.35","new_quantity":"0"},{"side":"offer","event_time":"2026-07-16T20:29:15.904737Z","price_level":"64174.64","new_quantity":"0"},{"side":"offer","event_time":"2026-07-16T20:29:15.904737Z","price_level":"64188.29","new_quantity":"0.73077563"},{"side":"offer","event_time":"2026-07-16T20:29:15.904737Z","price_level":"64190.33","new_quantity":"0"}]}]}
{"channel":"l2_data","timestamp":"2026-07-16T20:29:15.975023367Z","sequence_num":478,"events":[{"type":"update","product_id":"BTC-USD","updates":[{"side":"bid","event_time":"2026-07-16T20:29:15.934122Z","price_level":"64124.41","new_quantity":"0.01559176"},{"side":"bid","event_time":"2026-07-16T20:29:15.934122Z","price_level":"64124.39","new_quantity":"0"}]}]}
{"channel":"l2_data","timestamp":"2026-07-16T20:29:16.02989188Z","sequence_num":479,"events":[{"type":"update","product_id":"BTC-USD","updates":[{"side":"bid","event_time":"2026-07-16T20:29:16.003219Z","price_level":"64135","new_quantity":"0.00628601"},{"side":"bid","event_time":"2026-07-16T20:29:16.003219Z","price_level":"64127.62","new_quantity":"0.12475123"},{"side":"bid","event_time":"2026-07-16T20:29:16.003219Z","price_level":"64126.96","new_quantity":"0.02"},{"side":"bid","event_time":"2026-07-16T20:29:16.003219Z","price_level":"64126.82","new_quantity":"0"},{"side":"bid","event_time":"2026-07-16T20:29:16.003219Z","price_level":"64104","new_quantity":"0"},{"side":"bid","event_time":"2026-07-16T20:29:16.003219Z","price_level":"64074.38","new_quantity":"1.41586844"},{"side":"bid","event_time":"2026-07-16T20:29:16.003219Z","price_level":"64070.13","new_quantity":"0"},{"side":"bid","event_time":"2026-07-16T20:29:16.003219Z","price_level":"56118.13","new_quantity":"0.01337205"},{"side":"offer","event_time":"2026-07-16T20:29:16.003219Z","price_level":"64148.13","new_quantity":"0"},{"side":"offer","event_time":"2026-07-16T20:29:16.003219Z","price_level":"64149.42","new_quantity":"0"}]}]}
{"channel":"l2_data","timestamp":"2026-07-16T20:29:16.080417102Z","sequence_num":480,"events":[{"type":"update","product_id":"BTC-USD","updates":[{"side":"bid","event_time":"2026-07-16T20:29:16.048403Z","price_level":"64124.42","new_quantity":"0.01559176"},{"side":"bid","event_time":"2026-07-16T20:29:16.048403Z","price_level":"64124.41","new_quantity":"0"},{"side":"bid","event_time":"2026-07-16T20:29:16.048403Z","price_level":"64105","new_quantity":"1.01"},{"side":"offer","event_time":"2026-07-16T20:29:16.048403Z","price_level":"64147.77","new_quantity":"0.00009743"},{"side":"offer","event_time":"2026-07-16T20:29:16.048403Z","price_level":"64149.06","new_quantity":"0.01675785"}]}]}
{"channel":"l2_data","timestamp":"2026-07-16T20:29:16.130256646Z","sequence_num":481,"events":[{"type":"update","product_id":"BTC-USD","updates":[{"side":"bid","event_time":"2026-07-16T20:29:16.103031Z","price_level":"64121.22","new_quantity":"0.589771"},{"side":"bid","event_time":"2026-07-16T20:29:16.103031Z","price_level":"64105","new_quantity":"0.01"},{"side":"bid","event_time":"2026-07-16T20:29:16.103031Z","price_level":"64026.31","new_quantity":"0.09382472"},{"side":"bid","event_time":"2026-07-16T20:29:16.103031Z","price_level":"56118.13","new_quantity":"0"},{"side":"offer","event_time":"2026-07-16T20:29:16.103031Z","price_level":"64152.31","new_quantity":"0.42313439"},{"side":"offer","event_time":"2026-07-16T20:29:16.103031Z","price_level":"64174.33","new_quantity":"0.8743576"}]}]}
{"channel":"heartbeats","timestamp":"2026-07-16T20:29:16.163770587Z","sequence_num":482,"events":[{"current_time":"2026-07-16 20:29:16.162909877 +0000 UTC m=+75520.317736922","heartbeat_counter":75520}]}
{"channel":"l2_data","timestamp":"2026-07-16T20:29:16.180587972Z","sequence_num":483,"events":[{"type":"update","product_id":"BTC-USD","updates":[{"side":"bid","event_time":"2026-07-16T20:29:16.156962Z","price_level":"64135","new_quantity":"0.00230746"},{"side":"bid","event_time":"2026-07-16T20:29:16.156962Z","price_level":"64127.62","new_quantity":"0"},{"side":"bid","event_time":"2026-07-16T20:29:16.156962Z","price_level":"64127.04","new_quantity":"0.12475235"},{"side":"bid","event_time":"2026-07-16T20:29:16.156962Z","price_level":"64126.87","new_quantity":"0"},{"side":"bid","event_time":"2026-07-16T20:29:16.156962Z","price_level":"64124.42","new_quantity":"0"},{"side":"bid","event_time":"2026-07-16T20:29:16.156962Z","price_level":"64123.29","new_quantity":"0.01559176"},{"side":"bid","event_time":"2026-07-16T20:29:16.156962Z","price_level":"64121.22","new_quantity":"0"},{"side":"bid","event_time":"2026-07-16T20:29:16.156962Z","price_level":"64102","new_quantity":"1"},{"side":"bid","event_time":"2026-07-16T20:29:16.156962Z","price_level":"64101","new_quantity":"1"},{"side":"offer","event_time":"2026-07-16T20:29:16.156962Z","price_level":"64141.34","new_quantity":"0.001545"},{"side":"offer","event_time":"2026-07-16T20:29:16.156962Z","price_level":"64144.56","new_quantity":"0.0077892"},{"side":"offer","event_time":"2026-07-16T20:29:16.156962Z","price_level":"64144.57","new_quantity":"0.001545"},{"side":"offer","event_time":"2026-07-16T20:29:16.156962Z","price_level":"64144.6","new_quantity":"0"},{"side":"offer","event_time":"2026-07-16T20:29:16.156962Z","price_level":"64205.94","new_quantity":"0"},{"side":"offer","event_time":"2026-07-16T20:29:16.156962Z","price_level":"64209.17","new_quantity":"0"},{"side":"offer","event_time":"2026-07-16T20:29:16.156962Z","price_level":"64778.98","new_quantity":"0"}]}]}
{"channel":"l2_data","timestamp":"2026-07-16T20:29:16.229790058Z","sequence_num":484,"events":[{"type":"update","product_id":"BTC-USD","updates":[{"side":"bid","event_time":"2026-07-16T20:29:16.191828Z","price_level":"64127.05","new_quantity":"0.02"},{"side":"bid","event_time":"2026-07-16T20:29:16.191828Z","price_level":"64096.61","new_quantity":"0.02900278"},{"side":"bid","event_time":"2026-07-16T20:29:16.191828Z","price_level":"64094.04","new_quantity":"0.03315483"},{"side":"bid","event_time":"2026-07-16T20:29:16.191828Z","price_level":"64090.2","new_quantity":"0.0248952"},{"side":"offer","event_time":"2026-07-16T20:29:16.191828Z","price_level":"64185.6","new_quantity":"0.01075066"}]}]}
{"channel":"l2_data","timestamp":"2026-07-16T20:29:16.274783754Z","sequence_num":485,"events":[{"type":"update","product_id":"BTC-USD","updates":[{"side":"bid","event_time":"2026-07-16T20:29:16.247548Z","price_level":"64135","new_quantity":"0.00230742"},{"side":"bid","event_time":"2026-07-16T20:29:16.247548Z","price_level":"64101","new_quantity":"0"}]}]}
{"channel":"l2_data","timestamp":"2026-07-16T20:29:16.335246578Z","sequence_num":486,"events":[{"type":"update","product_id":"BTC-USD","updates":[{"side":"bid","event_time":"2026-07-16T20:29:16.309024Z","price_level":"64105","new_quantity":"1.01"},{"side":"bid","event_time":"2026-07-16T20:29:16.309024Z","price_level":"56118.13","new_quantity":"0.01337205"},{"side":"offer","event_time":"2026-07-16T20:29:16.309024Z","price_level":"64775.93","new_quantity":"0.03890047"}]}]}
{"channel":"l2_data","timestamp":"2026-07-16T20:29:16.375199198Z","sequence_num":487,"events":[{"type":"update","product_id":"BTC-USD","updates":[{"side":"bid","event_time":"2026-07-16T20:29:16.327575Z","price_level":"64123.3","new_quantity":"0.01559176"},{"side":"bid","event_time":"2026-07-16T20:29:16.327575Z","price_level":"64123.29","new_quantity":"0"}]}]}
{"channel":"l2_data","timestamp":"2026-07-16T20:29:16.425460951Z","sequence_num":488,"events":[{"type":"update","product_id":"BTC-USD","updates":[{"side":"bid","event_time":"2026-07-16T20:29:16.403322Z","price_level":"64121.08","new_quantity":"0"},{"side":"bid","event_time":"2026-07-16T20:29:16.403322Z","price_level":"56118.13","new_quantity":"0"}]}]}
{"channel":"l2_data","timestamp":"2026-07-16T20:29:16.475319331Z","sequence_num":489,"events":[{"type":"update","product_id":"BTC-USD","updates":[{"side":"bid","event_time":"2026-07-16T20:29:16.451605Z","price_level":"64127.06","new_quantity":"0.31190852"},{"side":"bid","event_time":"2026-07-16T20:29:16.451605Z","price_level":"64127.05","new_quantity":"0"},{"side":"bid","event_time":"2026-07-16T20:29:16.451605Z","price_level":"64126.96","new_quantity":"0"}]}]}
{"channel":"l2_data","timestamp":"2026-07-16T20:29:16.524897806Z","sequence_num":490,"events":[{"type":"update","product_id":"BTC-USD","updates":[{"side":"bid","event_time":"2026-07-16T20:29:16.482844Z","price_level":"64127.07","new_quantity":"0.02"},{"side":"bid","event_time":"2026-07-16T20:29:16.482844Z","price_level":"64107.73","new_quantity":"0.00583"},{"side":"bid","event_time":"2026-07-16T20:29:16.482844Z","price_level":"64104.84","new_quantity":"0"},{"side":"bid","event_time":"2026-07-16T20:29:16.482844Z","price_level":"62821.15","new_quantity":"0.00583"},{"side":"bid","event_time":"2026-07-16T20:29:16.482844Z","price_level":"62820.58","new_quantity":"0"}]}]}
{"channel":"l2_data","timestamp":"2026-07-16T20:29:16.575620837Z","sequence_num":491,"events":[{"type":"update","product_id":"BTC-USD","updates":[{"side":"bid","event_time":"2026-07-16T20:29:16.542605Z","price_level":"64123.3","new_quantity":"0"},{"side":"bid","event_time":"2026-07-16T20:29:16.542605Z","price_level":"64123.19","new_quantity":"0.01559176"},{"side":"bid","event_time":"2026-07-16T20:29:16.542605Z","price_level":"64121.14","new_quantity":"0"}]}]}
{"channel":"l2_data","timestamp":"2026-07-16T20:29:16.625930917Z","sequence_num":492,"events":[{"type":"update","product_id":"BTC-USD","updates":[{"side":"bid","event_time":"2026-07-16T20:29:16.602622Z","price_level":"64135","new_quantity":"0.00230738"},{"side":"bid","event_time":"2026-07-16T20:29:16.602622Z","price_level":"64123.2","new_quantity":"0.01559176"},{"side":"bid","event_time":"2026-07-16T20:29:16.602622Z","price_level":"64123.19","new_quantity":"0"},{"side":"bid","event_time":"2026-07-16T20:29:16.602622Z","price_level":"64121.13","new_quantity":"0.599323"},{"side":"bid","event_time":"2026-07-16T20:29:16.602622Z","price_level":"56118.13","new_quantity":"0.01337205"}]}]}
{"channel":"l2_data","timestamp":"2026-07-16T20:29:16.679263653Z","sequence_num":493,"events":[{"type":"update","product_id":"BTC-USD","updates":[{"side":"bid","event_time":"2026-07-16T20:29:16.649962Z","price_level":"64121.13","new_quantity":"0"},{"side":"bid","event_time":"2026-07-16T20:29:16.649962Z","price_level":"63496.23","new_quantity":"0"},{"side":"offer","event_time":"2026-07-16T20:29:16.649962Z","price_level":"64146.28","new_quantity":"0.00009743"},{"side":"offer","event_time":"2026-07-16T20:29:16.649962Z","price_level":"64146.63","new_quantity":"0"},{"side":"offer","event_time":"2026-07-16T20:29:16.649962Z","price_level":"64147.25","new_quantity":"0.00779457"},{"side":"offer","event_time":"2026-07-16T20:29:16.649962Z","price_level":"64147.6","new_quantity":"0"}]}]}
{"channel":"l2_data","timestamp":"2026-07-16T20:29:16.729235643Z","sequence_num":494,"events":[{"type":"update","product_id":"BTC-USD","updates":[{"side":"bid","event_time":"2026-07-16T20:29:16.704674Z","price_level":"64135","new_quantity":"0.00548208"},{"side":"bid","event_time":"2026-07-16T20:29:16.704674Z","price_level":"64108.44","new_quantity":"0.00583"},{"side":"bid","event_time":"2026-07-16T20:29:16.704674Z","price_level":"64107.38","new_quantity":"0"},{"side":"bid","event_time":"2026-07-16T20:29:16.704674Z","price_level":"62821.15","new_quantity":"0"},{"side":"bid","event_time":"2026-07-16T20:29:16.704674Z","price_level":"56118.13","new_quantity":"0"},{"side":"offer","event_time":"2026-07-16T20:29:16.704674Z","price_level":"64315.63","new_quantity":"0.023381"},{"side":"offer","event_time":"2026-07-16T20:29:16.704674Z","price_level":"64331.82","new_quantity":"0"},{"side":"offer","event_time":"2026-07-16T20:29:16.704674Z","price_level":"64792.17","new_quantity":"0.00583"},{"side":"offer","event_time":"2026-07-16T20:29:16.704674Z","price_level":"65435.46","new_quantity":"0.00583"},{"side":"offer","event_time":"2026-07-16T20:29:16.704674Z","price_level":"65649.89","new_quantity":"0.00583"}]}]}
{"channel":"l2_data","timestamp":"2026-07-16T20:29:16.775218731Z","sequence_num":495,"events":[{"type":"update","product_id":"BTC-USD","updates":[{"side":"bid","event_time":"2026-07-16T20:29:16.738211Z","price_level":"64127.66","new_quantity":"0.02"},{"side":"bid","event_time":"2026-07-16T20:29:16.738211Z","price_level":"64127.65","new_quantity":"0.12475117"},{"side":"bid","event_time":"2026-07-16T20:29:16.738211Z","price_level":"64127.04","new_quantity":"0"}]}]}
{"channel":"l2_data","timestamp":"2026-07-16T20:29:16.829582128Z","sequence_num":496,"events":[{"type":"update","product_id":"BTC-USD","updates":[{"side":"bid","event_time":"2026-07-16T20:29:16.793175Z","price_level":"64105.01","new_quantity":"0.65502111"},{"side":"bid","event_time":"2026-07-16T20:29:16.793175Z","price_level":"64102.76","new_quantity":"0.00077959"},{"side":"offer","event_time":"2026-07-16T20:29:16.793175Z","price_level":"64139.19","new_quantity":"0.72752145"},{"side":"offer","event_time":"2026-07-16T20:29:16.793175Z","price_level":"64140.7","new_quantity":"0.65502111"}]}]}
{"channel":"l2_data","timestamp":"2026-07-16T20:29:16.885275922Z","sequence_num":497,"events":[{"type":"update","product_id":"BTC-USD","updates":[{"side":"bid","event_time":"2026-07-16T20:29:16.860456Z","price_level":"64135","new_quantity":"0.00230738"},{"side":"bid","event_time":"2026-07-16T20:29:16.860456Z","price_level":"64128.59","new_quantity":"0"},{"side":"bid","event_time":"2026-07-16T20:29:16.860456Z","price_level":"64123.21","new_quantity":"0.01559176"},{"side":"bid","event_time":"2026-07-16T20:29:16.860456Z","price_level":"64123.2","new_quantity":"0"},{"side":"bid","event_time":"2026-07-16T20:29:16.860456Z","price_level":"64121.17","new_quantity":"0"},{"side":"bid","event_time":"2026-07-16T20:29:16.860456Z","price_level":"63493.24","new_quantity":"0.03938078"},{"side":"bid","event_time":"2026-07-16T20:29:16.860456Z","price_level":"62821.37","new_quantity":"0.00583"},{"side":"offer","event_time":"2026-07-16T20:29:16.860456Z","price_level":"64135.01","new_quantity":"1.16272982"},{"side":"offer","event_time":"2026-07-16T20:29:16.860456Z","price_level":"64140.66","new_quantity":"0.02099946"},{"side":"offer","event_time":"2026-07-16T20:29:16.860456Z","price_level":"64791.68","new_quantity":"0.00583"},{"side":"offer","event_time":"2026-07-16T20:29:16.860456Z","price_level":"64794.58","new_quantity":"0"},{"side":"offer","event_time":"2026-07-16T20:29:16.860456Z","price_level":"65434.97","new_quantity":"0.00583"},{"side":"offer","event_time":"2026-07-16T20:29:16.860456Z","price_level":"65435.46","new_quantity":"0"},{"side":"offer","event_time":"2026-07-16T20:29:16.860456Z","price_level":"65649.89","new_quantity":"0"}]}]}
{"channel":"l2_data","timestamp":"2026-07-16T20:29:16.932391826Z","sequence_num":498,"events":[{"type":"update","product_id":"BTC-USD","updates":[{"side":"bid","event_time":"2026-07-16T20:29:16.902445Z","price_level":"64128.59","new_quantity":"0.00779683"},{"side":"bid","event_time":"2026-07-16T20:29:16.902445Z","price_level":"64127.66","new_quantity":"0"},{"side":"bid","event_time":"2026-07-16T20:29:16.902445Z","price_level":"64127.07","new_quantity":"0"},{"side":"bid","event_time":"2026-07-16T20:29:16.902445Z","price_level":"64107.73","new_quantity":"0"},{"side":"bid","event_time":"2026-07-16T20:29:16.902445Z","price_level":"64102.77","new_quantity":"0.00077959"},{"side":"bid","event_time":"2026-07-16T20:29:16.902445Z","price_level":"64102.76","new_quantity":"0"},{"side":"bid","event_time":"2026-07-16T20:29:16.902445Z","price_level":"63893.38","new_quantity":"0.00583"},{"side":"bid","event_time":"2026-07-16T20:29:16.902445Z","price_level":"63893.23","new_quantity":"0.00583"},{"side":"bid","event_time":"2026-07-16T20:29:16.902445Z","price_level":"63892.73","new_quantity":"0"},{"side":"bid","event_time":"2026-07-16T20:29:16.902445Z","price_level":"62821.37","new_quantity":"0"},{"side":"bid","event_time":"2026-07-16T20:29:16.902445Z","price_level":"56118.13","new_quantity":"0.01337205"},{"side":"offer","event_time":"2026-07-16T20:29:16.902445Z","price_level":"64148.72","new_quantity":"0.00896355"},{"side":"offer","event_time":"2026-07-16T20:29:16.902445Z","price_level":"64149.06","new_quantity":"0.00779435"},{"side":"offer","event_time":"2026-07-16T20:29:16.902445Z","price_level":"64791.26","new_quantity":"0.00583"},{"side":"offer","event_time":"2026-07-16T20:29:16.902445Z","price_level":"64791.68","new_quantity":"0"},{"side":"offer","event_time":"2026-07-16T20:29:16.902445Z","price_level":"64792.17","new_quantity":"0"},{"side":"offer","event_time":"2026-07-16T20:29:16.902445Z","price_level":"65005.97","new_quantity":"0.00583"},{"side":"offer","event_time":"2026-07-16T20:29:16.902445Z","price_level":"65434.83","new_quantity":"0.00583"},{"side":"offer","event_time":"2026-07-16T20:29:16.902445Z","price_level":"65434.97","new_quantity":"0"}]}]}
{"channel":"l2_data","timestamp":"2026-07-16T20:29:16.987662201Z","sequence_num":499,"events":[{"type":"update","product_id":"BTC-USD","updates":[{"side":"bid","event_time":"2026-07-16T20:29:16.955336Z","price_level":"64130.19","new_quantity":"0.00779664"},{"side":"bid","event_time":"2026-07-16T20:29:16.955336Z","price_level":"64127.66","new_quantity":"0.02"},{"side":"bid","event_time":"2026-07-16T20:29:16.955336Z","price_level":"64123.81","new_quantity":"0.01559176"},{"side":"bid","event_time":"2026-07-16T20:29:16.955336Z","price_level":"64123.8","new_quantity":"0"},{"side":"bid","event_time":"2026-07-16T20:29:16.955336Z","price_level":"64123.21","new_quantity":"0"},{"side":"bid","event_time":"2026-07-16T20:29:16.955336Z","price_level":"64104.26","new_quantity":"0.06831473"},{"side":"bid","event_time":"2026-07-16T20:29:16.955336Z","price_level":"64074.38","new_quantity":"0"},{"side":"bid","event_time":"2026-07-16T20:29:16.955336Z","price_level":"64070.13","new_quantity":"1.41596236"},{"side":"bid","event_time":"2026-07-16T20:29:16.955336Z","price_level":"63893.55","new_quantity":"0.00583"},{"side":"bid","event_time":"2026-07-16T20:29:16.955336Z","price_level":"63893.23","new_quantity":"0"},{"side":"offer","event_time":"2026-07-16T20:29:16.955336Z","price_level":"64135.01","new_quantity":"1.1620367"},{"side":"offer","event_time":"2026-07-16T20:29:16.955336Z","price_level":"64147.11","new_quantity":"0.00898177"},{"side":"offer","event_time":"2026-07-16T20:29:16.955336Z","price_level":"64147.46","new_quantity":"0"},{"side":"offer","event_time":"2026-07-16T20:29:16.955336Z","price_level":"64174.32","new_quantity":"0.46378087"},{"side":"offer","event_time":"2026-07-16T20:29:16.955336Z","price_level":"64174.33","new_quantity":"0"},{"side":"offer","event_time":"2026-07-16T20:29:16.955336Z","price_level":"64174.34","new_quantity":"0"},{"side":"offer","event_time":"2026-07-16T20:29:16.955336Z","price_level":"65649.43","new_quantity":"0.00583"}]}]}
{"channel":"l2_data","timestamp":"2026-07-16T20:29:17.031548966Z","sequence_num":500,"events":[{"type":"update","product_id":"BTC-USD","updates":[{"side":"bid","event_time":"2026-07-16T20:29:17.013186Z","price_level":"64127.06","new_quantity":"0"},{"side":"bid","event_time":"2026-07-16T20:29:17.013186Z","price_level":"56118.13","new_quantity":"0"},{"side":"offer","event_time":"2026-07-16T20:29:17.013186Z","price_level":"64149.06","new_quantity":"0"}]}]}
{"channel":"l2_data","timestamp":"2026-07-16T20:29:17.114566441Z","sequence_num":501,"events":[{"type":"update","product_id":"BTC-USD","updates":[{"side":"offer","event_time":"2026-07-16T20:29:17.018617Z","price_level":"64147.77","new_quantity":"0"}]}]}
{"channel":"l2_data","timestamp":"2026-07-16T20:29:17.132565262Z","sequence_num":502,"events":[{"type":"update","product_id":"BTC-USD","updates":[{"side":"bid","event_time":"2026-07-16T20:29:17.102383Z","price_level":"64120.98","new_quantity":"0.630826"},{"side":"bid","event_time":"2026-07-16T20:29:17.102383Z","price_level":"64074.38","new_quantity":"1.41586844"},{"side":"bid","event_time":"2026-07-16T20:29:17.102383Z","price_level":"64070.13","new_quantity":"0"},{"side":"offer","event_time":"2026-07-16T20:29:17.102383Z","price_level":"64147.43","new_quantity":"0.00009743"},{"side":"offer","event_time":"2026-07-16T20:29:17.102383Z","price_level":"64148.71","new_quantity":"0.00779439"},{"side":"offer","event_time":"2026-07-16T20:29:17.102383Z","price_level":"64174.35","new_quantity":"0.59748051"}]}]}
{"channel":"heartbeats","timestamp":"2026-07-16T20:29:17.171500781Z","sequence_num":503,"events":[{"current_time":"2026-07-16 20:29:17.16288859 +0000 UTC m=+75521.317715626","heartbeat_counter":75521}]}
{"channel":"l2_data","timestamp":"2026-07-16T20:29:17.175166461Z","sequence_num":504,"events":[{"type":"update","product_id":"BTC-USD","updates":[{"side":"bid","event_time":"2026-07-16T20:29:17.149033Z","price_level":"64123.82","new_quantity":"0.01559176"},{"side":"bid","event_time":"2026-07-16T20:29:17.149033Z","price_level":"64123.81","new_quantity":"0"},{"side":"bid","event_time":"2026-07-16T20:29:17.149033Z","price_level":"64120.98","new_quantity":"0"},{"side":"bid","event_time":"2026-07-16T20:29:17.149033Z","price_level":"64074.1","new_quantity":"0.00858349"}]}]}
{"channel":"l2_data","timestamp":"2026-07-16T20:29:17.224845371Z","sequence_num":505,"events":[{"type":"update","product_id":"BTC-USD","updates":[{"side":"bid","event_time":"2026-07-16T20:29:17.193101Z","price_level":"56118.13","new_quantity":"0.01337205"}]}]}
{"channel":"l2_data","timestamp":"2026-07-16T20:29:17.275083356Z","sequence_num":506,"events":[{"type":"update","product_id":"BTC-USD","updates":[{"side":"bid","event_time":"2026-07-16T20:29:17.247029Z","price_level":"64125.86","new_quantity":"0.04545762"}]}]}
{"channel":"l2_data","timestamp":"2026-07-16T20:29:17.326403098Z","sequence_num":507,"events":[{"type":"update","product_id":"BTC-USD","updates":[{"side":"bid","event_time":"2026-07-16T20:29:17.293123Z","price_level":"64135","new_quantity":"0.00230731"},{"side":"bid","event_time":"2026-07-16T20:29:17.293123Z","price_level":"56118.13","new_quantity":"0"}]}]}
{"channel":"l2_data","timestamp":"2026-07-16T20:29:17.383188067Z","sequence_num":508,"events":[{"type":"update","product_id":"BTC-USD","updates":[{"side":"bid","event_time":"2026-07-16T20:29:17.35167Z","price_level":"64128.34","new_quantity":"0.12474982"},{"side":"bid","event_time":"2026-07-16T20:29:17.35167Z","price_level":"64127.65","new_quantity":"0"},{"side":"bid","event_time":"2026-07-16T20:29:17.35167Z","price_level":"64125.87","new_quantity":"0.31190852"},{"side":"bid","event_time":"2026-07-16T20:29:17.35167Z","price_level":"64125.71","new_quantity":"0.15594367"},{"side":"bid","event_time":"2026-07-16T20:29:17.35167Z","price_level":"64123.75","new_quantity":"0"},{"side":"bid","event_time":"2026-07-16T20:29:17.35167Z","price_level":"64108.37","new_quantity":"0"},{"side":"bid","event_time":"2026-07-16T20:29:17.35167Z","price_level":"64105","new_quantity":"0.01"},{"side":"bid","event_time":"2026-07-16T20:29:17.35167Z","price_level":"64098.8","new_quantity":"0.00128301"},{"side":"bid","event_time":"2026-07-16T20:29:17.35167Z","price_level":"63893.97","new_quantity":"0.00583"},{"side":"bid","event_time":"2026-07-16T20:29:17.35167Z","price_level":"63893.38","new_quantity":"0"},{"side":"offer","event_time":"2026-07-16T20:29:17.35167Z","price_level":"64139.19","new_quantity":"0.44529932"},{"side":"offer","event_time":"2026-07-16T20:29:17.35167Z","price_level":"64140.7","new_quantity":"0"},{"side":"offer","event_time":"2026-07-16T20:29:17.35167Z","price_level":"64142.52","new_quantity":"0.61737246"},{"side":"offer","event_time":"2026-07-16T20:29:17.35167Z","price_level":"64142.53","new_quantity":"0.65501225"},{"side":"offer","event_time":"2026-07-16T20:29:17.35167Z","price_level":"64142.54","new_quantity":"0"},{"side":"offer","event_time":"2026-07-16T20:29:17.35167Z","price_level":"64149.31","new_quantity":"0.6366932"},{"side":"offer","event_time":"2026-07-16T20:29:17.35167Z","price_level":"64150","new_quantity":"0.01"}]}]}
{"channel":"l2_data","timestamp":"2026-07-16T20:29:17.433732822Z","sequence_num":509,"events":[{"type":"update","product_id":"BTC-USD","updates":[{"side":"bid","event_time":"2026-07-16T20:29:17.411216Z","price_level":"64135","new_quantity":"0.00228796"},{"side":"bid","event_time":"2026-07-16T20:29:17.411216Z","price_level":"64128.35","new_quantity":"0.02"},{"side":"bid","event_time":"2026-07-16T20:29:17.411216Z","price_level":"64127.66","new_quantity":"0"},{"side":"bid","event_time":"2026-07-16T20:29:17.411216Z","price_level":"64123.83","new_quantity":"0.01559176"},{"side":"bid","event_time":"2026-07-16T20:29:17.411216Z","price_level":"64123.82","new_quantity":"0"},{"side":"bid","event_time":"2026-07-16T20:29:17.411216Z","price_level":"64121.12","new_quantity":"0"},{"side":"bid","event_time":"2026-07-16T20:29:17.411216Z","price_level":"64109.04","new_quantity":"0.001545"},{"side":"bid","event_time":"2026-07-16T20:29:17.411216Z","price_level":"64108.75","new_quantity":"0.00583"},{"side":"bid","event_time":"2026-07-16T20:29:17.411216Z","price_level":"64102","new_quantity":"0"},{"side":"bid","event_time":"2026-07-16T20:29:17.411216Z","price_level":"64100","new_quantity":"1.02100904"},{"side":"bid","event_time":"2026-07-16T20:29:17.411216Z","price_level":"63893.55","new_quantity":"0"},{"side":"offer","event_time":"2026-07-16T20:29:17.411216Z","price_level":"64149.31","new_quantity":"1.19258463"},{"side":"offer","event_time":"2026-07-16T20:29:17.411216Z","price_level":"64151","new_quantity":"1"}]}]}
{"channel":"l2_data","timestamp":"2026-07-16T20:29:17.476266407Z","sequence_num":510,"events":[{"type":"update","product_id":"BTC-USD","updates":[{"side":"bid","event_time":"2026-07-16T20:29:17.417036Z","price_level":"64101","new_quantity":"1"}]}]}
{"channel":"l2_data","timestamp":"2026-07-16T20:29:17.525463334Z","sequence_num":511,"events":[{"type":"update","product_id":"BTC-USD","updates":[{"side":"bid","event_time":"2026-07-16T20:29:17.501072Z","price_level":"64135","new_quantity":"0.00231676"},{"side":"bid","event_time":"2026-07-16T20:29:17.501072Z","price_level":"56118.13","new_quantity":"0.01337205"}]}]}
{"channel":"l2_data","timestamp":"2026-07-16T20:29:17.582371093Z","sequence_num":512,"events":[{"type":"update","product_id":"BTC-USD","updates":[{"side":"bid","event_time":"2026-07-16T20:29:17.523283Z","price_level":"64100","new_quantity":"0.02100904"},{"side":"offer","event_time":"2026-07-16T20:29:17.523283Z","price_level":"64139.18","new_quantity":"0"}]}]}
{"channel":"l2_data","timestamp":"2026-07-16T20:29:17.631311502Z","sequence_num":513,"events":[{"type":"update","product_id":"BTC-USD","updates":[{"side":"bid","event_time":"2026-07-16T20:29:17.597672Z","price_level":"64135","new_quantity":"0.00231672"},{"side":"bid","event_time":"2026-07-16T20:29:17.597672Z","price_level":"64129.4","new_quantity":"0.12474777"},{"side":"bid","event_time":"2026-07-16T20:29:17.597672Z","price_level":"64128.6","new_quantity":"0.02"},{"side":"bid","event_time":"2026-07-16T20:29:17.597672Z","price_level":"64128.34","new_quantity":"0"},{"side":"bid","event_time":"2026-07-16T20:29:17.597672Z","price_level":"64123.84","new_quantity":"0.32750028"},{"side":"bid","event_time":"2026-07-16T20:29:17.597672Z","price_level":"64123.83","new_quantity":"0"},{"side":"bid","event_time":"2026-07-16T20:29:17.597672Z","price_level":"64110.72","new_quantity":"0.00583"},{"side":"bid","event_time":"2026-07-16T20:29:17.597672Z","price_level":"64110.68","new_quantity":"0.00583"},{"side":"bid","event_time":"2026-07-16T20:29:17.597672Z","price_level":"64108.75","new_quantity":"0"},{"side":"bid","event_time":"2026-07-16T20:29:17.597672Z","price_level":"64108.44","new_quantity":"0"},{"side":"bid","event_time":"2026-07-16T20:29:17.597672Z","price_level":"64106.01","new_quantity":"0.59589985"},{"side":"bid","event_time":"2026-07-16T20:29:17.597672Z","price_level":"64105.52","new_quantity":"0"},{"side":"bid","event_time":"2026-07-16T20:29:17.597672Z","price_level":"64097.46","new_quantity":"0"},{"side":"bid","event_time":"2026-07-16T20:29:17.597672Z","price_level":"64091.05","new_quantity":"0.23359045"},{"side":"bid","event_time":"2026-07-16T20:29:17.597672Z","price_level":"63679.46","new_quantity":"0.00583"},{"side":"bid","event_time":"2026-07-16T20:29:17.597672Z","price_level":"63679.19","new_quantity":"0"},{"side":"bid","event_time":"2026-07-16T20:29:17.597672Z","price_level":"63471.63","new_quantity":"0.0012"},{"side":"bid","event_time":"2026-07-16T20:29:17.597672Z","price_level":"56118.13","new_quantity":"0"},{"side":"offer","event_time":"2026-07-16T20:29:17.597672Z","price_level":"64139.17","new_quantity":"0.04691558"},{"side":"offer","event_time":"2026-07-16T20:29:17.597672Z","price_level":"64158.48","new_quantity":"0"}]}]}
{"channel":"l2_data","timestamp":"2026-07-16T20:29:17.679571443Z","sequence_num":514,"events":[{"type":"update","product_id":"BTC-USD","updates":[{"side":"bid","event_time":"2026-07-16T20:29:17.652451Z","price_level":"64129.41","new_quantity":"0.02"},{"side":"bid","event_time":"2026-07-16T20:29:17.652451Z","price_level":"64121.38","new_quantity":"0"},{"side":"bid","event_time":"2026-07-16T20:29:17.652451Z","price_level":"64108","new_quantity":"1"},{"side":"bid","event_time":"2026-07-16T20:29:17.652451Z","price_level":"64099.39","new_quantity":"0.00155816"},{"side":"bid","event_time":"2026-07-16T20:29:17.652451Z","price_level":"64092.98","new_quantity":"0.00779084"},{"side":"offer","event_time":"2026-07-16T20:29:17.652451Z","price_level":"64142.52","new_quantity":"0.22633015"},{"side":"offer","event_time":"2026-07-16T20:29:17.652451Z","price_level":"64142.53","new_quantity":"0"},{"side":"offer","event_time":"2026-07-16T20:29:17.652451Z","price_level":"64145.6","new_quantity":"0.91766645"},{"side":"offer","event_time":"2026-07-16T20:29:17.652451Z","price_level":"64145.61","new_quantity":"0.65499276"},{"side":"offer","event_time":"2026-07-16T20:29:17.652451Z","price_level":"64145.62","new_quantity":"0"}]}]}
{"channel":"l2_data","timestamp":"2026-07-16T20:29:17.731359813Z","sequence_num":515,"events":[{"type":"update","product_id":"BTC-USD","updates":[{"side":"bid","event_time":"2026-07-16T20:29:17.704176Z","price_level":"64135","new_quantity":"0.00710759"},{"side":"bid","event_time":"2026-07-16T20:29:17.704176Z","price_level":"64128.35","new_quantity":"0"},{"side":"bid","event_time":"2026-07-16T20:29:17.704176Z","price_level":"64110.74","new_quantity":"0.00583"},{"side":"bid","event_time":"2026-07-16T20:29:17.704176Z","price_level":"64110.72","new_quantity":"0"},{"side":"bid","event_time":"2026-07-16T20:29:17.704176Z","price_level":"64110.68","new_quantity":"0"},{"side":"bid","event_time":"2026-07-16T20:29:17.704176Z","price_level":"64106.76","new_quantity":"0.59589288"},{"side":"bid","event_time":"2026-07-16T20:29:17.704176Z","price_level":"64106.01","new_quantity":"0"},{"side":"bid","event_time":"2026-07-16T20:29:17.704176Z","price_level":"63896.27","new_quantity":"0.00583"},{"side":"offer","event_time":"2026-07-16T20:29:17.704176Z","price_level":"64135.01","new_quantity":"1.16001407"}]}]}
{"channel":"l2_data","timestamp":"2026-07-16T20:29:17.779494788Z","sequence_num":516,"events":[{"type":"update","product_id":"BTC-USD","updates":[{"side":"bid","event_time":"2026-07-16T20:29:17.754994Z","price_level":"64124.58","new_quantity":"0.01559176"},{"side":"bid","event_time":"2026-07-16T20:29:17.754994Z","price_level":"64123.84","new_quantity":"0.31190852"},{"side":"bid","event_time":"2026-07-16T20:29:17.754994Z","price_level":"64109","new_quantity":"1"},{"side":"bid","event_time":"2026-07-16T20:29:17.754994Z","price_level":"64108","new_quantity":"0"},{"side":"offer","event_time":"2026-07-16T20:29:17.754994Z","price_level":"64146.28","new_quantity":"0"},{"side":"offer","event_time":"2026-07-16T20:29:17.754994Z","price_level":"64147.25","new_quantity":"0"},{"side":"offer","event_time":"2026-07-16T20:29:17.754994Z","price_level":"64157.99","new_quantity":"0.00779621"}]}]}
{"channel":"l2_data","timestamp":"2026-07-16T20:29:17.830392425Z","sequence_num":517,"events":[{"type":"update","product_id":"BTC-USD","updates":[{"side":"bid","event_time":"2026-07-16T20:29:17.813047Z","price_level":"64128.43","new_quantity":"0.02"},{"side":"bid","event_time":"2026-07-16T20:29:17.813047Z","price_level":"64124.58","new_quantity":"0"},{"side":"bid","event_time":"2026-07-16T20:29:17.813047Z","price_level":"64124.45","new_quantity":"0.01559176"},{"side":"bid","event_time":"2026-07-16T20:29:17.813047Z","price_level":"56118.13","new_quantity":"0.01337205"},{"side":"offer","event_time":"2026-07-16T20:29:17.813047Z","price_level":"64145.95","new_quantity":"0.00009743"},{"side":"offer","event_time":"2026-07-16T20:29:17.813047Z","price_level":"64146.91","new_quantity":"0.00779461"}]}]}
{"channel":"l2_data","timestamp":"2026-07-16T20:29:17.930251557Z","sequence_num":518,"events":[{"type":"update","product_id":"BTC-USD","updates":[{"side":"bid","event_time":"2026-07-16T20:29:17.896047Z","price_level":"64135","new_quantity":"0.00231672"},{"side":"bid","event_time":"2026-07-16T20:29:17.896047Z","price_level":"64121.43","new_quantity":"0.59021"},{"side":"bid","event_time":"2026-07-16T20:29:17.896047Z","price_level":"64102.77","new_quantity":"0"},{"side":"bid","event_time":"2026-07-16T20:29:17.896047Z","price_level":"64102.76","new_quantity":"0.00077956"},{"side":"bid","event_time":"2026-07-16T20:29:17.896047Z","price_level":"62823.58","new_quantity":"0.00583"},{"side":"bid","event_time":"2026-07-16T20:29:17.896047Z","price_level":"56118.13","new_quantity":"0"},{"side":"offer","event_time":"2026-07-16T20:29:17.896047Z","price_level":"64157.99","new_quantity":"0"}]}]}
{"channel":"l2_data","timestamp":"2026-07-16T20:29:17.98054891Z","sequence_num":519,"events":[{"type":"update","product_id":"BTC-USD","updates":[{"side":"bid","event_time":"2026-07-16T20:29:17.957421Z","price_level":"64128.6","new_quantity":"0"},{"side":"bid","event_time":"2026-07-16T20:29:17.957421Z","price_level":"64128.59","new_quantity":"0.00779683"},{"side":"bid","event_time":"2026-07-16T20:29:17.957421Z","price_level":"64126.96","new_quantity":"0.02"},{"side":"bid","event_time":"2026-07-16T20:29:17.957421Z","price_level":"64121.43","new_quantity":"0"},{"side":"offer","event_time":"2026-07-16T20:29:17.957421Z","price_level":"64139.19","new_quantity":"0.71556054"},{"side":"offer","event_time":"2026-07-16T20:29:17.957421Z","price_level":"64140.7","new_quantity":"0.65501709"},{"side":"offer","event_time":"2026-07-16T20:29:17.957421Z","price_level":"64145.6","new_quantity":"0.52663579"},{"side":"offer","event_time":"2026-07-16T20:29:17.957421Z","price_level":"64145.61","new_quantity":"0"},{"side":"offer","event_time":"2026-07-16T20:29:17.957421Z","price_level":"64148.39","new_quantity":"0.00896359"},{"side":"offer","event_time":"2026-07-16T20:29:17.957421Z","price_level":"64148.72","new_quantity":"0"}]}]}
{"channel":"l2_data","timestamp":"2026-07-16T20:29:18.043586888Z","sequence_num":520,"events":[{"type":"update","product_id":"BTC-USD","updates":[{"side":"bid","event_time":"2026-07-16T20:29:18.002389Z","price_level":"64135","new_quantity":"0.00193774"},{"side":"bid","event_time":"2026-07-16T20:29:18.002389Z","price_level":"64130.19","new_quantity":"0"},{"side":"bid","event_time":"2026-07-16T20:29:18.002389Z","price_level":"64128.6","new_quantity":"0.02"},{"side":"bid","event_time":"2026-07-16T20:29:18.002389Z","price_level":"62823.66","new_quantity":"0.00583"},{"side":"bid","event_time":"2026-07-16T20:29:18.002389Z","price_level":"62823.58","new_quantity":"0"},{"side":"offer","event_time":"2026-07-16T20:29:18.002389Z","price_level":"64147.11","new_quantity":"0.000018"}]}]}
{"channel":"l2_data","timestamp":"2026-07-16T20:29:18.093349391Z","sequence_num":521,"events":[{"type":"update","product_id":"BTC-USD","updates":[{"side":"bid","event_time":"2026-07-16T20:29:18.042283Z","price_level":"64135","new_quantity":"0.00211938"},{"side":"bid","event_time":"2026-07-16T20:29:18.042283Z","price_level":"64130.19","new_quantity":"0.00779664"},{"side":"bid","event_time":"2026-07-16T20:29:18.042283Z","price_level":"64124.47","new_quantity":"0.01559176"},{"side":"bid","event_time":"2026-07-16T20:29:18.042283Z","price_level":"64124.45","new_quantity":"0"},{"side":"offer","event_time":"2026-07-16T20:29:18.042283Z","price_level":"64146.78","new_quantity":"0.00896382"},{"side":"offer","event_time":"2026-07-16T20:29:18.042283Z","price_level":"64147.43","new_quantity":"0"},{"side":"offer","event_time":"2026-07-16T20:29:18.042283Z","price_level":"64148.71","new_quantity":"0"},{"side":"offer","event_time":"2026-07-16T20:29:18.042283Z","price_level":"64157.99","new_quantity":"0.00779621"}]}]}
{"channel":"l2_data","timestamp":"2026-07-16T20:29:18.129998249Z","sequence_num":522,"events":[{"type":"update","product_id":"BTC-USD","updates":[{"side":"bid","event_time":"2026-07-16T20:29:18.102486Z","price_level":"64121.42","new_quantity":"0.678481"},{"side":"bid","event_time":"2026-07-16T20:29:18.102486Z","price_level":"56118.13","new_quantity":"0.01337205"}]}]}
{"channel":"heartbeats","timestamp":"2026-07-16T20:29:18.165601148Z","sequence_num":523,"events":[{"current_time":"2026-07-16 20:29:18.162901883 +0000 UTC m=+75522.317728919","heartbeat_counter":75522}]}
{"channel":"l2_data","timestamp":"2026-07-16T20:29:18.189416652Z","sequence_num":524,"events":[{"type":"update","product_id":"BTC-USD","updates":[{"side":"bid","event_time":"2026-07-16T20:29:18.150527Z","price_level":"64124.48","new_quantity":"0.01559176"},{"side":"bid","event_time":"2026-07-16T20:29:18.150527Z","price_level":"64124.47","new_quantity":"0"},{"side":"bid","event_time":"2026-07-16T20:29:18.150527Z","price_level":"64121.42","new_quantity":"0"},{"side":"offer","event_time":"2026-07-16T20:29:18.150527Z","price_level":"64172.23","new_quantity":"0.32027682"},{"side":"offer","event_time":"2026-07-16T20:29:18.150527Z","price_level":"64172.25","new_quantity":"0"},{"side":"offer","event_time":"2026-07-16T20:29:18.150527Z","price_level":"64172.26","new_quantity":"0"},{"side":"offer","event_time":"2026-07-16T20:29:18.150527Z","price_level":"64191.79","new_quantity":"2.12507558"},{"side":"offer","event_time":"2026-07-16T20:29:18.150527Z","price_level":"64191.81","new_quantity":"0"}]}]}
{"channel":"l2_data","timestamp":"2026-07-16T20:29:18.242694972Z","sequence_num":525,"events":[{"type":"update","product_id":"BTC-USD","updates":[{"side":"bid","event_time":"2026-07-16T20:29:18.208996Z","price_level":"56118.13","new_quantity":"0"},{"side":"offer","event_time":"2026-07-16T20:29:18.208996Z","price_level":"64148.38","new_quantity":"0.00779443"},{"side":"offer","event_time":"2026-07-16T20:29:18.208996Z","price_level":"64157.99","new_quantity":"0"}]}]}
{"channel":"l2_data","timestamp":"2026-07-16T20:29:18.284498341Z","sequence_num":526,"events":[{"type":"update","product_id":"BTC-USD","updates":[{"side":"offer","event_time":"2026-07-16T20:29:18.220965Z","price_level":"64147.1","new_quantity":"0.00009743"}]}]}
{"channel":"l2_data","timestamp":"2026-07-16T20:29:18.338353571Z","sequence_num":527,"events":[{"type":"update","product_id":"BTC-USD","updates":[{"side":"bid","event_time":"2026-07-16T20:29:18.296227Z","price_level":"64135","new_quantity":"0.00064097"},{"side":"offer","event_time":"2026-07-16T20:29:18.296227Z","price_level":"64135.01","new_quantity":"1.14426796"}]}]}
{"channel":"l2_data","timestamp":"2026-07-16T20:29:18.390837818Z","sequence_num":528,"events":[{"type":"update","product_id":"BTC-USD","updates":[{"side":"bid","event_time":"2026-07-16T20:29:18.353098Z","price_level":"64135","new_quantity":"0.00064091"},{"side":"bid","event_time":"2026-07-16T20:29:18.353098Z","price_level":"64124.49","new_quantity":"0.01559176"},{"side":"bid","event_time":"2026-07-16T20:29:18.353098Z","price_level":"64124.48","new_quantity":"0"},{"side":"bid","event_time":"2026-07-16T20:29:18.353098Z","price_level":"64121.37","new_quantity":"0.602697"},{"side":"offer","event_time":"2026-07-16T20:29:18.353098Z","price_level":"64135.01","new_quantity":"1.15985972"},{"side":"offer","event_time":"2026-07-16T20:29:18.353098Z","price_level":"64157.99","new_quantity":"0.00779621"}]}]}
{"channel":"l2_data","timestamp":"2026-07-16T20:29:18.440675038Z","sequence_num":529,"events":[{"type":"update","product_id":"BTC-USD","updates":[{"side":"bid","event_time":"2026-07-16T20:29:18.394746Z","price_level":"64124.5","new_quantity":"0.01559176"},{"side":"bid","event_time":"2026-07-16T20:29:18.394746Z","price_level":"64124.49","new_quantity":"0"},{"side":"bid","event_time":"2026-07-16T20:29:18.394746Z","price_level":"64121.37","new_quantity":"0"},{"side":"bid","event_time":"2026-07-16T20:29:18.394746Z","price_level":"56118.13","new_quantity":"0.01337205"}]}]}
{"channel":"l2_data","timestamp":"2026-07-16T20:29:18.540172269Z","sequence_num":530,"events":[{"type":"update","product_id":"BTC-USD","updates":[{"side":"bid","event_time":"2026-07-16T20:29:18.495431Z","price_level":"64124.51","new_quantity":"0.01559176"},{"side":"bid","event_time":"2026-07-16T20:29:18.495431Z","price_level":"64124.5","new_quantity":"0"},{"side":"bid","event_time":"2026-07-16T20:29:18.495431Z","price_level":"56118.13","new_quantity":"0"},{"side":"offer","event_time":"2026-07-16T20:29:18.495431Z","price_level":"64157.99","new_quantity":"0"}]}]}
{"channel":"l2_data","timestamp":"2026-07-16T20:29:18.625446698Z","sequence_num":531,"events":[{"type":"update","product_id":"BTC-USD","updates":[{"side":"bid","event_time":"2026-07-16T20:29:18.600965Z","price_level":"64124.52","new_quantity":"0.01559176"},{"side":"bid","event_time":"2026-07-16T20:29:18.600965Z","price_level":"64124.51","new_quantity":"0"},{"side":"bid","event_time":"2026-07-16T20:29:18.600965Z","price_level":"64121.31","new_quantity":"0.715058"}]}]}
{"channel":"l2_data","timestamp":"2026-07-16T20:29:18.680502539Z","sequence_num":532,"events":[{"type":"update","product_id":"BTC-USD","updates":[{"side":"bid","event_time":"2026-07-16T20:29:18.645627Z","price_level":"64135","new_quantity":"0.00064086"},{"side":"bid","event_time":"2026-07-16T20:29:18.645627Z","price_level":"64121.31","new_quantity":"0"},{"side":"offer","event_time":"2026-07-16T20:29:18.645627Z","price_level":"64157.99","new_quantity":"0.00779621"}]}]}
{"channel":"l2_data","timestamp":"2026-07-16T20:29:18.726070258Z","sequence_num":533,"events":[{"type":"update","product_id":"BTC-USD","updates":[{"side":"bid","event_time":"2026-07-16T20:29:18.692245Z","price_level":"56118.13","new_quantity":"0.01337205"}]}]}
{"channel":"l2_data","timestamp":"2026-07-16T20:29:18.775159811Z","sequence_num":534,"events":[{"type":"update","product_id":"BTC-USD","updates":[{"side":"bid","event_time":"2026-07-16T20:29:18.747495Z","price_level":"64124.53","new_quantity":"0.01559176"},{"side":"bid","event_time":"2026-07-16T20:29:18.747495Z","price_level":"64124.52","new_quantity":"0"}]}]}
{"channel":"l2_data","timestamp":"2026-07-16T20:29:18.830017996Z","sequence_num":535,"events":[{"type":"update","product_id":"BTC-USD","updates":[{"side":"bid","event_time":"2026-07-16T20:29:18.803812Z","price_level":"56118.13","new_quantity":"0"},{"side":"offer","event_time":"2026-07-16T20:29:18.803812Z","price_level":"64145.95","new_quantity":"0"}]}]}
{"channel":"l2_data","timestamp":"2026-07-16T20:29:18.880212682Z","sequence_num":536,"events":[{"type":"update","product_id":"BTC-USD","updates":[{"side":"bid","event_time":"2026-07-16T20:29:18.843779Z","price_level":"64124.54","new_quantity":"0.01559176"},{"side":"bid","event_time":"2026-07-16T20:29:18.843779Z","price_level":"64124.53","new_quantity":"0"},{"side":"offer","event_time":"2026-07-16T20:29:18.843779Z","price_level":"64145.63","new_quantity":"0.00009743"},{"side":"offer","event_time":"2026-07-16T20:29:18.843779Z","price_level":"64146.59","new_quantity":"0.00779465"},{"side":"offer","event_time":"2026-07-16T20:29:18.843779Z","price_level":"64146.91","new_quantity":"0"},{"side":"offer","event_time":"2026-07-16T20:29:18.843779Z","price_level":"64157.99","new_quantity":"0"}]}]}
{"channel":"l2_data","timestamp":"2026-07-16T20:29:18.932543338Z","sequence_num":537,"events":[{"type":"update","product_id":"BTC-USD","updates":[{"side":"bid","event_time":"2026-07-16T20:29:18.886037Z","price_level":"64121.27","new_quantity":"0"},{"side":"bid","event_time":"2026-07-16T20:29:18.886037Z","price_level":"64104.9","new_quantity":"0"},{"side":"offer","event_time":"2026-07-16T20:29:18.886037Z","price_level":"64149.31","new_quantity":"0.6366932"},{"side":"offer","event_time":"2026-07-16T20:29:18.886037Z","price_level":"64151","new_quantity":"0"}]}]}
{"channel":"l2_data","timestamp":"2026-07-16T20:29:18.983909817Z","sequence_num":538,"events":[{"type":"update","product_id":"BTC-USD","updates":[{"side":"bid","event_time":"2026-07-16T20:29:18.947343Z","price_level":"64129.4","new_quantity":"0"},{"side":"bid","event_time":"2026-07-16T20:29:18.947343Z","price_level":"64124.54","new_quantity":"0"},{"side":"bid","event_time":"2026-07-16T20:29:18.947343Z","price_level":"64109","new_quantity":"0"},{"side":"bid","event_time":"2026-07-16T20:29:18.947343Z","price_level":"64106","new_quantity":"1"},{"side":"bid","event_time":"2026-07-16T20:29:18.947343Z","price_level":"64086.5","new_quantity":"0.545567"},{"side":"offer","event_time":"2026-07-16T20:29:18.947343Z","price_level":"64139.19","new_quantity":"0.44529932"},{"side":"offer","event_time":"2026-07-16T20:29:18.947343Z","price_level":"64140.7","new_quantity":"0"},{"side":"offer","event_time":"2026-07-16T20:29:18.947343Z","price_level":"64149.31","new_quantity":"1.19258463"},{"side":"offer","event_time":"2026-07-16T20:29:18.947343Z","price_level":"64150","new_quantity":"1.01"}]}]}
{"channel":"l2_data","timestamp":"2026-07-16T20:29:19.034421873Z","sequence_num":539,"events":[{"type":"update","product_id":"BTC-USD","updates":[{"side":"bid","event_time":"2026-07-16T20:29:19.001557Z","price_level":"64128.59","new_quantity":"0"},{"side":"bid","event_time":"2026-07-16T20:29:19.001557Z","price_level":"64124.56","new_quantity":"0.01559475"},{"side":"bid","event_time":"2026-07-16T20:29:19.001557Z","price_level":"56118.13","new_quantity":"0.01337205"},{"side":"offer","event_time":"2026-07-16T20:29:19.001557Z","price_level":"64149.31","new_quantity":"0.6366932"},{"side":"offer","event_time":"2026-07-16T20:29:19.001557Z","price_level":"64150","new_quantity":"0.01"},{"side":"offer","event_time":"2026-07-16T20:29:19.001557Z","price_level":"64157.99","new_quantity":"0.00779621"}]}]}
{"channel":"l2_data","timestamp":"2026-07-16T20:29:19.083955677Z","sequence_num":540,"events":[{"type":"update","product_id":"BTC-USD","updates":[{"side":"bid","event_time":"2026-07-16T20:29:19.062742Z","price_level":"64130.19","new_quantity":"0.00779664"},{"side":"bid","event_time":"2026-07-16T20:29:19.062742Z","price_level":"64128.59","new_quantity":"0.00779683"},{"side":"bid","event_time":"2026-07-16T20:29:19.062742Z","price_level":"64106","new_quantity":"0"},{"side":"offer","event_time":"2026-07-16T20:29:19.062742Z","price_level":"64146.78","new_quantity":"0"},{"side":"offer","event_time":"2026-07-16T20:29:19.062742Z","price_level":"64147.1","new_quantity":"0"},{"side":"offer","event_time":"2026-07-16T20:29:19.062742Z","price_level":"64148.07","new_quantity":"0.00896364"},{"side":"offer","event_time":"2026-07-16T20:29:19.062742Z","price_level":"64148.38","new_quantity":"0"},{"side":"offer","event_time":"2026-07-16T20:29:19.062742Z","price_level":"64148.39","new_quantity":"0"},{"side":"offer","event_time":"2026-07-16T20:29:19.062742Z","price_level":"64149.31","new_quantity":"1.19258463"},{"side":"offer","event_time":"2026-07-16T20:29:19.062742Z","price_level":"64151","new_quantity":"1"}]}]}
{"channel":"l2_data","timestamp":"2026-07-16T20:29:19.131072715Z","sequence_num":541,"events":[{"type":"update","product_id":"BTC-USD","updates":[{"side":"bid","event_time":"2026-07-16T20:29:19.101572Z","price_level":"64135","new_quantity":"0.00384817"},{"side":"bid","event_time":"2026-07-16T20:29:19.101572Z","price_level":"64121.18","new_quantity":"0.62974"},{"side":"bid","event_time":"2026-07-16T20:29:19.101572Z","price_level":"64107","new_quantity":"1"},{"side":"bid","event_time":"2026-07-16T20:29:19.101572Z","price_level":"64105.01","new_quantity":"0"},{"side":"bid","event_time":"2026-07-16T20:29:19.101572Z","price_level":"64102.76","new_quantity":"0.65581465"},{"side":"bid","event_time":"2026-07-16T20:29:19.101572Z","price_level":"56118.13","new_quantity":"0"},{"side":"offer","event_time":"2026-07-16T20:29:19.101572Z","price_level":"64146.47","new_quantity":"0.00896386"}]}]}
{"channel":"heartbeats","timestamp":"2026-07-16T20:29:19.163090222Z","sequence_num":542,"events":[{"current_time":"2026-07-16 20:29:19.162920858 +0000 UTC m=+75523.317747902","heartbeat_counter":75523}]}
{"channel":"l2_data","timestamp":"2026-07-16T20:29:19.181269173Z","sequence_num":543,"events":[{"type":"update","product_id":"BTC-USD","updates":[{"side":"bid","event_time":"2026-07-16T20:29:19.150918Z","price_level":"64129.41","new_quantity":"0"},{"side":"bid","event_time":"2026-07-16T20:29:19.150918Z","price_level":"64124.57","new_quantity":"0.01559475"},{"side":"bid","event_time":"2026-07-16T20:29:19.150918Z","price_level":"64124.56","new_quantity":"0"},{"side":"bid","event_time":"2026-07-16T20:29:19.150918Z","price_level":"64121.18","new_quantity":"0"},{"side":"bid","event_time":"2026-07-16T20:29:19.150918Z","price_level":"64107","new_quantity":"0"},{"side":"offer","event_time":"2026-07-16T20:29:19.150918Z","price_level":"64149.31","new_quantity":"0.6366932"},{"side":"offer","event_time":"2026-07-16T20:29:19.150918Z","price_level":"64151","new_quantity":"0"},{"side":"offer","event_time":"2026-07-16T20:29:19.150918Z","price_level":"64172.21","new_quantity":"0.32027682"},{"side":"offer","event_time":"2026-07-16T20:29:19.150918Z","price_level":"64172.23","new_quantity":"0"},{"side":"offer","event_time":"2026-07-16T20:29:19.150918Z","price_level":"64191.77","new_quantity":"2.18765007"},{"side":"offer","event_time":"2026-07-16T20:29:19.150918Z","price_level":"64191.79","new_quantity":"0"}]}]}
{"channel":"l2_data","timestamp":"2026-07-16T20:29:19.230128184Z","sequence_num":544,"events":[{"type":"update","product_id":"BTC-USD","updates":[{"side":"bid","event_time":"2026-07-16T20:29:19.193979Z","price_level":"64124.57","new_quantity":"0"},{"side":"bid","event_time":"2026-07-16T20:29:19.193979Z","price_level":"64090","new_quantity":"0.01"},{"side":"offer","event_time":"2026-07-16T20:29:19.193979Z","price_level":"64149.31","new_quantity":"1.19258463"},{"side":"offer","event_time":"2026-07-16T20:29:19.193979Z","price_level":"64150","new_quantity":"1.01"}]}]}
{"channel":"l2_data","timestamp":"2026-07-16T20:29:19.275218576Z","sequence_num":545,"events":[{"type":"update","product_id":"BTC-USD","updates":[{"side":"bid","event_time":"2026-07-16T20:29:19.245139Z","price_level":"64135","new_quantity":"0.00064086"},{"side":"bid","event_time":"2026-07-16T20:29:19.245139Z","price_level":"64124.58","new_quantity":"0.01559475"},{"side":"bid","event_time":"2026-07-16T20:29:19.245139Z","price_level":"64104","new_quantity":"1"},{"side":"bid","event_time":"2026-07-16T20:29:19.245139Z","price_level":"64103","new_quantity":"1"},{"side":"bid","event_time":"2026-07-16T20:29:19.245139Z","price_level":"64102.77","new_quantity":"0.00077958"},{"side":"bid","event_time":"2026-07-16T20:29:19.245139Z","price_level":"64102.76","new_quantity":"0.65503509"}]}]}
{"channel":"l2_data","timestamp":"2026-07-16T20:29:19.330363635Z","sequence_num":546,"events":[{"type":"update","product_id":"BTC-USD","updates":[{"side":"bid","event_time":"2026-07-16T20:29:19.299165Z","price_level":"64104","new_quantity":"0"},{"side":"bid","event_time":"2026-07-16T20:29:19.299165Z","price_level":"56118.13","new_quantity":"0.01337205"},{"side":"offer","event_time":"2026-07-16T20:29:19.299165Z","price_level":"64146.78","new_quantity":"0.00009743"},{"side":"offer","event_time":"2026-07-16T20:29:19.299165Z","price_level":"64148.07","new_quantity":"0.01675811"},{"side":"offer","event_time":"2026-07-16T20:29:19.299165Z","price_level":"64157.99","new_quantity":"0"}]}]}
{"channel":"l2_data","timestamp":"2026-07-16T20:29:19.377801556Z","sequence_num":547,"events":[{"type":"update","product_id":"BTC-USD","updates":[{"side":"bid","event_time":"2026-07-16T20:29:19.349194Z","price_level":"64107","new_quantity":"1"}]}]}
{"channel":"l2_data","timestamp":"2026-07-16T20:29:19.4255297Z","sequence_num":548,"events":[{"type":"update","product_id":"BTC-USD","updates":[{"side":"bid","event_time":"2026-07-16T20:29:19.394068Z","price_level":"64135","new_quantity":"0.00064084"},{"side":"bid","event_time":"2026-07-16T20:29:19.394068Z","price_level":"56118.13","new_quantity":"0"}]}]}
{"channel":"l2_data","timestamp":"2026-07-16T20:29:19.478923098Z","sequence_num":549,"events":[{"type":"update","product_id":"BTC-USD","updates":[{"side":"bid","event_time":"2026-07-16T20:29:19.426703Z","price_level":"64128.6","new_quantity":"0"},{"side":"bid","event_time":"2026-07-16T20:29:19.426703Z","price_level":"64128.43","new_quantity":"0"},{"side":"bid","event_time":"2026-07-16T20:29:19.426703Z","price_level":"64125.87","new_quantity":"0"},{"side":"offer","event_time":"2026-07-16T20:29:19.426703Z","price_level":"64157.99","new_quantity":"0.00779621"}]}]}
{"channel":"l2_data","timestamp":"2026-07-16T20:29:19.524886967Z","sequence_num":550,"events":[{"type":"update","product_id":"BTC-USD","updates":[{"side":"bid","event_time":"2026-07-16T20:29:19.492641Z","price_level":"64125.87","new_quantity":"0.31190852"}]}]}
{"channel":"l2_data","timestamp":"2026-07-16T20:29:19.575480631Z","sequence_num":551,"events":[{"type":"update","product_id":"BTC-USD","updates":[{"side":"bid","event_time":"2026-07-16T20:29:19.557959Z","price_level":"64128.04","new_quantity":"0.02"},{"side":"bid","event_time":"2026-07-16T20:29:19.557959Z","price_level":"64128.03","new_quantity":"0.12475042"},{"side":"bid","event_time":"2026-07-16T20:29:19.557959Z","price_level":"64124.58","new_quantity":"0"},{"side":"bid","event_time":"2026-07-16T20:29:19.557959Z","price_level":"64124.54","new_quantity":"0.01559475"},{"side":"bid","event_time":"2026-07-16T20:29:19.557959Z","price_level":"64117.32","new_quantity":"0.0486477"},{"side":"bid","event_time":"2026-07-16T20:29:19.557959Z","price_level":"64107","new_quantity":"0"}]}]}
{"channel":"l2_data","timestamp":"2026-07-16T20:29:19.625076457Z","sequence_num":552,"events":[{"type":"update","product_id":"BTC-USD","updates":[{"side":"bid","event_time":"2026-07-16T20:29:19.613272Z","price_level":"64128.03","new_quantity":"0"},{"side":"bid","event_time":"2026-07-16T20:29:19.613272Z","price_level":"64127.41","new_quantity":"0.02"},{"side":"bid","event_time":"2026-07-16T20:29:19.613272Z","price_level":"64127.4","new_quantity":"0.12475164"},{"side":"bid","event_time":"2026-07-16T20:29:19.613272Z","price_level":"64121.18","new_quantity":"0.71268"},{"side":"bid","event_time":"2026-07-16T20:29:19.613272Z","price_level":"64103","new_quantity":"0"},{"side":"bid","event_time":"2026-07-16T20:29:19.613272Z","price_level":"56118.13","new_quantity":"0.01337205"},{"side":"bid","event_time":"2026-07-16T20:29:19.613272Z","price_level":"51308","new_quantity":"0.0002"}]}]}
{"channel":"l2_data","timestamp":"2026-07-16T20:29:19.675254368Z","sequence_num":553,"events":[{"type":"update","product_id":"BTC-USD","updates":[{"side":"bid","event_time":"2026-07-16T20:29:19.659718Z","price_level":"64135","new_quantity":"0.00448897"},{"side":"bid","event_time":"2026-07-16T20:29:19.659718Z","price_level":"64128.04","new_quantity":"0"},{"side":"bid","event_time":"2026-07-16T20:29:19.659718Z","price_level":"64121.18","new_quantity":"0"},{"side":"bid","event_time":"2026-07-16T20:29:19.659718Z","price_level":"64109.04","new_quantity":"0.00156575"},{"side":"bid","event_time":"2026-07-16T20:29:19.659718Z","price_level":"64102","new_quantity":"1"}]}]}
{"channel":"l2_data","timestamp":"2026-07-16T20:29:19.724386284Z","sequence_num":554,"events":[{"type":"update","product_id":"BTC-USD","updates":[{"side":"bid","event_time":"2026-07-16T20:29:19.688712Z","price_level":"64135","new_quantity":"0.0044889"},{"side":"bid","event_time":"2026-07-16T20:29:19.688712Z","price_level":"64101","new_quantity":"0"},{"side":"bid","event_time":"2026-07-16T20:29:19.688712Z","price_level":"64099.39","new_quantity":"0"},{"side":"bid","event_time":"2026-07-16T20:29:19.688712Z","price_level":"64097.74","new_quantity":"0.0015582"},{"side":"bid","event_time":"2026-07-16T20:29:19.688712Z","price_level":"64092.98","new_quantity":"0"},{"side":"bid","event_time":"2026-07-16T20:29:19.688712Z","price_level":"64091.33","new_quantity":"0.00779104"},{"side":"bid","event_time":"2026-07-16T20:29:19.688712Z","price_level":"56118.13","new_quantity":"0"}]}]}
{"channel":"l2_data","timestamp":"2026-07-16T20:29:19.775084079Z","sequence_num":555,"events":[{"type":"update","product_id":"BTC-USD","updates":[{"side":"bid","event_time":"2026-07-16T20:29:19.760839Z","price_level":"64124.57","new_quantity":"0.01559475"},{"side":"bid","event_time":"2026-07-16T20:29:19.760839Z","price_level":"64124.54","new_quantity":"0"},{"side":"bid","event_time":"2026-07-16T20:29:19.760839Z","price_level":"64106","new_quantity":"1"}]}]}
{"channel":"l2_data","timestamp":"2026-07-16T20:29:19.827645504Z","sequence_num":556,"events":[{"type":"update","product_id":"BTC-USD","updates":[{"side":"bid","event_time":"2026-07-16T20:29:19.809977Z","price_level":"64106","new_quantity":"0"},{"side":"bid","event_time":"2026-07-16T20:29:19.809977Z","price_level":"64102","new_quantity":"0"}]}]}
{"channel":"l2_data","timestamp":"2026-07-16T20:29:19.880971945Z","sequence_num":557,"events":[{"type":"update","product_id":"BTC-USD","updates":[{"side":"bid","event_time":"2026-07-16T20:29:19.838035Z","price_level":"64135","new_quantity":"0.00064077"},{"side":"bid","event_time":"2026-07-16T20:29:19.838035Z","price_level":"64124.58","new_quantity":"0.01559475"},{"side":"bid","event_time":"2026-07-16T20:29:19.838035Z","price_level":"64124.57","new_quantity":"0"}]}]}
{"channel":"l2_data","timestamp":"2026-07-16T20:29:19.931385149Z","sequence_num":558,"events":[{"type":"update","product_id":"BTC-USD","updates":[{"side":"bid","event_time":"2026-07-16T20:29:19.894008Z","price_level":"64127.41","new_quantity":"0"},{"side":"bid","event_time":"2026-07-16T20:29:19.894008Z","price_level":"64127.4","new_quantity":"0"},{"side":"bid","event_time":"2026-07-16T20:29:19.894008Z","price_level":"64126.96","new_quantity":"0"},{"side":"bid","event_time":"2026-07-16T20:29:19.894008Z","price_level":"64125.71","new_quantity":"0"},{"side":"bid","event_time":"2026-07-16T20:29:19.894008Z","price_level":"64125.7","new_quantity":"0.12475496"},{"side":"bid","event_time":"2026-07-16T20:29:19.894008Z","price_level":"64123.79","new_quantity":"0.15594834"},{"side":"bid","event_time":"2026-07-16T20:29:19.894008Z","price_level":"64109.16","new_quantity":"0"},{"side":"bid","event_time":"2026-07-16T20:29:19.894008Z","price_level":"64106","new_quantity":"1"},{"side":"bid","event_time":"2026-07-16T20:29:19.894008Z","price_level":"64104.26","new_quantity":"0.00013667"},{"side":"bid","event_time":"2026-07-16T20:29:19.894008Z","price_level":"64067.2","new_quantity":"0"},{"side":"bid","event_time":"2026-07-16T20:29:19.894008Z","price_level":"56118.13","new_quantity":"0.01337205"},{"side":"offer","event_time":"2026-07-16T20:29:19.894008Z","price_level":"64145.63","new_quantity":"0"},{"side":"offer","event_time":"2026-07-16T20:29:19.894008Z","price_level":"64146.59","new_quantity":"0"}]}]}
{"channel":"l2_data","timestamp":"2026-07-16T20:29:19.982889729Z","sequence_num":559,"events":[{"type":"update","product_id":"BTC-USD","updates":[{"side":"bid","event_time":"2026-07-16T20:29:19.943919Z","price_level":"64126.96","new_quantity":"0.02"},{"side":"bid","event_time":"2026-07-16T20:29:19.943919Z","price_level":"51308","new_quantity":"0"},{"side":"offer","event_time":"2026-07-16T20:29:19.943919Z","price_level":"64145.32","new_quantity":"0.00009744"},{"side":"offer","event_time":"2026-07-16T20:29:19.943919Z","price_level":"64146.28","new_quantity":"0.00779468"}]}]}
{"channel":"l2_data","timestamp":"2026-07-16T20:29:20.026533805Z","sequence_num":560,"events":[{"type":"update","product_id":"BTC-USD","updates":[{"side":"bid","event_time":"2026-07-16T20:29:19.987388Z","price_level":"64135","new_quantity":"0.00064067"},{"side":"bid","event_time":"2026-07-16T20:29:19.987388Z","price_level":"56118.13","new_quantity":"0"}]}]}
{"channel":"l2_data","timestamp":"2026-07-16T20:29:20.082091541Z","sequence_num":561,"events":[{"type":"update","product_id":"BTC-USD","updates":[{"side":"bid","event_time":"2026-07-16T20:29:20.040661Z","price_level":"64130.19","new_quantity":"0"},{"side":"bid","event_time":"2026-07-16T20:29:20.040661Z","price_level":"64128.59","new_quantity":"0"},{"side":"bid","event_time":"2026-07-16T20:29:20.040661Z","price_level":"64106.76","new_quantity":"0"},{"side":"bid","event_time":"2026-07-16T20:29:20.040661Z","price_level":"64104.21","new_quantity":"0.64750787"},{"side":"bid","event_time":"2026-07-16T20:29:20.040661Z","price_level":"64074.38","new_quantity":"0"},{"side":"bid","event_time":"2026-07-16T20:29:20.040661Z","price_level":"64070.13","new_quantity":"1.43548444"},{"side":"offer","event_time":"2026-07-16T20:29:20.040661Z","price_level":"64146.47","new_quantity":"0"},{"side":"offer","event_time":"2026-07-16T20:29:20.040661Z","price_level":"64146.78","new_quantity":"0"},{"side":"offer","event_time":"2026-07-16T20:29:20.040661Z","price_level":"64148.07","new_quantity":"0"},{"side":"offer","event_time":"2026-07-16T20:29:20.040661Z","price_level":"64183.42","new_quantity":"0"}]}]}
{"channel":"l2_data","timestamp":"2026-07-16T20:29:20.131175931Z","sequence_num":562,"events":[{"type":"update","product_id":"BTC-USD","updates":[{"side":"bid","event_time":"2026-07-16T20:29:20.095208Z","price_level":"64128.59","new_quantity":"0.00779683"},{"side":"bid","event_time":"2026-07-16T20:29:20.095208Z","price_level":"64127.36","new_quantity":"0.12475172"},{"side":"bid","event_time":"2026-07-16T20:29:20.095208Z","price_level":"64123.79","new_quantity":"0"},{"side":"bid","event_time":"2026-07-16T20:29:20.095208Z","price_level":"64074.1","new_quantity":"0"},{"side":"offer","event_time":"2026-07-16T20:29:20.095208Z","price_level":"64147.77","new_quantity":"0.00896368"}]}]}
{"channel":"heartbeats","timestamp":"2026-07-16T20:29:20.166783199Z","sequence_num":563,"events":[{"current_time":"2026-07-16 20:29:20.162910155 +0000 UTC m=+75524.317737195","heartbeat_counter":75524}]}
{"channel":"l2_data","timestamp":"2026-07-16T20:29:20.174684175Z","sequence_num":564,"events":[{"type":"update","product_id":"BTC-USD","updates":[{"side":"bid","event_time":"2026-07-16T20:29:20.102105Z","price_level":"64126.96","new_quantity":"0"},{"side":"bid","event_time":"2026-07-16T20:29:20.102105Z","price_level":"64121.07","new_quantity":"0.69318"}]}]}
{"channel":"l2_data","timestamp":"2026-07-16T20:29:20.230751385Z","sequence_num":565,"events":[{"type":"update","product_id":"BTC-USD","updates":[{"side":"bid","event_time":"2026-07-16T20:29:20.205302Z","price_level":"64130.19","new_quantity":"0.00779664"},{"side":"bid","event_time":"2026-07-16T20:29:20.205302Z","price_level":"64127.37","new_quantity":"0.02"},{"side":"bid","event_time":"2026-07-16T20:29:20.205302Z","price_level":"64121.07","new_quantity":"0"},{"side":"bid","event_time":"2026-07-16T20:29:20.205302Z","price_level":"64106.01","new_quantity":"0.64748969"},{"side":"bid","event_time":"2026-07-16T20:29:20.205302Z","price_level":"64104.21","new_quantity":"0"},{"side":"bid","event_time":"2026-07-16T20:29:20.205302Z","price_level":"64074.38","new_quantity":"1.43538923"},{"side":"bid","event_time":"2026-07-16T20:29:20.205302Z","price_level":"64070.13","new_quantity":"0"},{"side":"bid","event_time":"2026-07-16T20:29:20.205302Z","price_level":"56118.13","new_quantity":"0.01337205"},{"side":"offer","event_time":"2026-07-16T20:29:20.205302Z","price_level":"64139.19","new_quantity":"0.71556269"},{"side":"offer","event_time":"2026-07-16T20:29:20.205302Z","price_level":"64140.7","new_quantity":"0.65502069"},{"side":"offer","event_time":"2026-07-16T20:29:20.205302Z","price_level":"64146.17","new_quantity":"0.0089639"},{"side":"offer","event_time":"2026-07-16T20:29:20.205302Z","price_level":"64172.19","new_quantity":"0.32027682"},{"side":"offer","event_time":"2026-07-16T20:29:20.205302Z","price_level":"64172.2","new_quantity":"0"},{"side":"offer","event_time":"2026-07-16T20:29:20.205302Z","price_level":"64172.21","new_quantity":"0"},{"side":"offer","event_time":"2026-07-16T20:29:20.205302Z","price_level":"64191.75","new_quantity":"2.18765076"},{"side":"offer","event_time":"2026-07-16T20:29:20.205302Z","price_level":"64191.76","new_quantity":"0"},{"side":"offer","event_time":"2026-07-16T20:29:20.205302Z","price_level":"64191.77","new_quantity":"0"}]}]}
{"channel":"l2_data","timestamp":"2026-07-16T20:29:20.282575713Z","sequence_num":566,"events":[{"type":"update","product_id":"BTC-USD","updates":[{"side":"bid","event_time":"2026-07-16T20:29:20.231565Z","price_level":"64135","new_quantity":"0.01807922"},{"side":"bid","event_time":"2026-07-16T20:29:20.231565Z","price_level":"64133.39","new_quantity":"0.00545723"},{"side":"bid","event_time":"2026-07-16T20:29:20.231565Z","price_level":"64131.23","new_quantity":"0.00682154"},{"side":"bid","event_time":"2026-07-16T20:29:20.231565Z","price_level":"64094.05","new_quantity":"0.90054264"},{"side":"bid","event_time":"2026-07-16T20:29:20.231565Z","price_level":"64092.21","new_quantity":"0"},{"side":"bid","event_time":"2026-07-16T20:29:20.231565Z","price_level":"64074.1","new_quantity":"0.00858349"},{"side":"offer","event_time":"2026-07-16T20:29:20.231565Z","price_level":"64173.94","new_quantity":"0.08161357"},{"side":"offer","event_time":"2026-07-16T20:29:20.231565Z","price_level":"64174.32","new_quantity":"0"},{"side":"offer","event_time":"2026-07-16T20:29:20.231565Z","price_level":"64177.52","new_quantity":"0.46375775"},{"side":"offer","event_time":"2026-07-16T20:29:20.231565Z","price_level":"64188.29","new_quantity":"0"},{"side":"offer","event_time":"2026-07-16T20:29:20.231565Z","price_level":"64191.74","new_quantity":"0.69636355"}]}]}
{"channel":"l2_data","timestamp":"2026-07-16T20:29:20.324796472Z","sequence_num":567,"events":[{"type":"update","product_id":"BTC-USD","updates":[{"side":"bid","event_time":"2026-07-16T20:29:20.292352Z","price_level":"64135","new_quantity":"0.02201573"},{"side":"bid","event_time":"2026-07-16T20:29:20.292352Z","price_level":"56118.13","new_quantity":"0"}]}]}
{"channel":"l2_data","timestamp":"2026-07-16T20:29:20.380911694Z","sequence_num":568,"events":[{"type":"update","product_id":"BTC-USD","updates":[{"side":"bid","event_time":"2026-07-16T20:29:20.352334Z","price_level":"64121.34","new_quantity":"0.636285"},{"side":"bid","event_time":"2026-07-16T20:29:20.352334Z","price_level":"64107.36","new_quantity":"0.64747606"},{"side":"bid","event_time":"2026-07-16T20:29:20.352334Z","price_level":"64106.01","new_quantity":"0"},{"side":"bid","event_time":"2026-07-16T20:29:20.352334Z","price_level":"64076.57","new_quantity":"1.43534017"},{"side":"bid","event_time":"2026-07-16T20:29:20.352334Z","price_level":"64074.38","new_quantity":"0"},{"side":"offer","event_time":"2026-07-16T20:29:20.352334Z","price_level":"64146.48","new_quantity":"0.00009743"},{"side":"offer","event_time":"2026-07-16T20:29:20.352334Z","price_level":"64147.77","new_quantity":"0.01675818"},{"side":"offer","event_time":"2026-07-16T20:29:20.352334Z","price_level":"64172.19","new_quantity":"0"},{"side":"offer","event_time":"2026-07-16T20:29:20.352334Z","price_level":"64174.34","new_quantity":"0.32027682"},{"side":"offer","event_time":"2026-07-16T20:29:20.352334Z","price_level":"64191.75","new_quantity":"0"},{"side":"offer","event_time":"2026-07-16T20:29:20.352334Z","price_level":"64194.53","new_quantity":"2.18755602"}]}]}
{"channel":"l2_data","timestamp":"2026-07-16T20:29:20.4259426Z","sequence_num":569,"events":[{"type":"update","product_id":"BTC-USD","updates":[{"side":"bid","event_time":"2026-07-16T20:29:20.412652Z","price_level":"64135","new_quantity":"0.02201564"},{"side":"bid","event_time":"2026-07-16T20:29:20.412652Z","price_level":"64121.34","new_quantity":"0"},{"side":"bid","event_time":"2026-07-16T20:29:20.412652Z","price_level":"64106","new_quantity":"1"}]}]}
{"channel":"l2_data","timestamp":"2026-07-16T20:29:20.475414099Z","sequence_num":570,"events":[{"type":"update","product_id":"BTC-USD","updates":[{"side":"bid","event_time":"2026-07-16T20:29:20.451832Z","price_level":"64110.92","new_quantity":"0"},{"side":"bid","event_time":"2026-07-16T20:29:20.451832Z","price_level":"64106","new_quantity":"0"}]}]}
{"channel":"l2_data","timestamp":"2026-07-16T20:29:20.525093931Z","sequence_num":571,"events":[{"type":"update","product_id":"BTC-USD","updates":[{"side":"bid","event_time":"2026-07-16T20:29:20.490754Z","price_level":"64124.59","new_quantity":"0.01559475"},{"side":"bid","event_time":"2026-07-16T20:29:20.490754Z","price_level":"64124.58","new_quantity":"0"},{"side":"bid","event_time":"2026-07-16T20:29:20.490754Z","price_level":"64102","new_quantity":"1"},{"side":"bid","event_time":"2026-07-16T20:29:20.490754Z","price_level":"64101","new_quantity":"1"},{"side":"bid","event_time":"2026-07-16T20:29:20.490754Z","price_level":"56118.13","new_quantity":"0.01337205"}]}]}
{"channel":"l2_data","timestamp":"2026-07-16T20:29:20.580411419Z","sequence_num":572,"events":[{"type":"update","product_id":"BTC-USD","updates":[{"side":"bid","event_time":"2026-07-16T20:29:20.534666Z","price_level":"64101","new_quantity":"0"},{"side":"offer","event_time":"2026-07-16T20:29:20.534666Z","price_level":"64138.11","new_quantity":"0.001545"},{"side":"offer","event_time":"2026-07-16T20:29:20.534666Z","price_level":"64202.71","new_quantity":"0"}]}]}
{"channel":"l2_data","timestamp":"2026-07-16T20:29:20.624993826Z","sequence_num":573,"events":[{"type":"update","product_id":"BTC-USD","updates":[{"side":"bid","event_time":"2026-07-16T20:29:20.571933Z","price_level":"64103","new_quantity":"1"}]}]}
{"channel":"l2_data","timestamp":"2026-07-16T20:29:20.679699806Z","sequence_num":574,"events":[{"type":"update","product_id":"BTC-USD","updates":[{"side":"bid","event_time":"2026-07-16T20:29:20.653741Z","price_level":"64124.59","new_quantity":"0"},{"side":"bid","event_time":"2026-07-16T20:29:20.653741Z","price_level":"64123.92","new_quantity":"0.01559475"},{"side":"bid","event_time":"2026-07-16T20:29:20.653741Z","price_level":"64121.3","new_quantity":"0"},{"side":"bid","event_time":"2026-07-16T20:29:20.653741Z","price_level":"64110.79","new_quantity":"0.02201564"},{"side":"bid","event_time":"2026-07-16T20:29:20.653741Z","price_level":"64106","new_quantity":"1"},{"side":"bid","event_time":"2026-07-16T20:29:20.653741Z","price_level":"64105.52","new_quantity":"0.65501485"},{"side":"bid","event_time":"2026-07-16T20:29:20.653741Z","price_level":"64103","new_quantity":"0"},{"side":"bid","event_time":"2026-07-16T20:29:20.653741Z","price_level":"64102.76","new_quantity":"0"},{"side":"bid","event_time":"2026-07-16T20:29:20.653741Z","price_level":"56118.13","new_quantity":"0"},{"side":"offer","event_time":"2026-07-16T20:29:20.653741Z","price_level":"64139.19","new_quantity":"0.44529932"},{"side":"offer","event_time":"2026-07-16T20:29:20.653741Z","price_level":"64140.7","new_quantity":"0"},{"side":"offer","event_time":"2026-07-16T20:29:20.653741Z","price_level":"64142.5","new_quantity":"0.61743219"},{"side":"offer","event_time":"2026-07-16T20:29:20.653741Z","price_level":"64142.51","new_quantity":"0.65501485"},{"side":"offer","event_time":"2026-07-16T20:29:20.653741Z","price_level":"64142.52","new_quantity":"0"},{"side":"offer","event_time":"2026-07-16T20:29:20.653741Z","price_level":"64173.93","new_quantity":"0.32027682"},{"side":"offer","event_time":"2026-07-16T20:29:20.653741Z","price_level":"64174.34","new_quantity":"0"}]}]}
{"channel":"l2_data","timestamp":"2026-07-16T20:29:20.775777169Z","sequence_num":575,"events":[{"type":"update","product_id":"BTC-USD","updates":[{"side":"bid","event_time":"2026-07-16T20:29:20.759055Z","price_level":"64123.93","new_quantity":"0.01559475"},{"side":"bid","event_time":"2026-07-16T20:29:20.759055Z","price_level":"64123.92","new_quantity":"0"},{"side":"bid","event_time":"2026-07-16T20:29:20.759055Z","price_level":"64110.79","new_quantity":"0"},{"side":"bid","event_time":"2026-07-16T20:29:20.759055Z","price_level":"64103.01","new_quantity":"0.00077958"},{"side":"bid","event_time":"2026-07-16T20:29:20.759055Z","price_level":"64102.77","new_quantity":"0"}]}]}
{"channel":"l2_data","timestamp":"2026-07-16T20:29:20.830531441Z","sequence_num":576,"events":[{"type":"update","product_id":"BTC-USD","updates":[{"side":"bid","event_time":"2026-07-16T20:29:20.793311Z","price_level":"64099.17","new_quantity":"0.06846948"},{"side":"bid","event_time":"2026-07-16T20:29:20.793311Z","price_level":"56118.13","new_quantity":"0.01337205"}]}]}
{"channel":"l2_data","timestamp":"2026-07-16T20:29:20.879433776Z","sequence_num":577,"events":[{"type":"update","product_id":"BTC-USD","updates":[{"side":"bid","event_time":"2026-07-16T20:29:20.86324Z","price_level":"64123.94","new_quantity":"0.01559475"},{"side":"bid","event_time":"2026-07-16T20:29:20.86324Z","price_level":"64123.93","new_quantity":"0"},{"side":"bid","event_time":"2026-07-16T20:29:20.86324Z","price_level":"64121.28","new_quantity":"0.622025"},{"side":"bid","event_time":"2026-07-16T20:29:20.86324Z","price_level":"64105.52","new_quantity":"0"},{"side":"bid","event_time":"2026-07-16T20:29:20.86324Z","price_level":"64104.21","new_quantity":"0.65501901"}]}]}
{"channel":"l2_data","timestamp":"2026-07-16T20:29:20.929124463Z","sequence_num":578,"events":[{"type":"update","product_id":"BTC-USD","updates":[{"side":"bid","event_time":"2026-07-16T20:29:20.902723Z","price_level":"64123.94","new_quantity":"0"},{"side":"bid","event_time":"2026-07-16T20:29:20.902723Z","price_level":"64121.28","new_quantity":"0"},{"side":"bid","event_time":"2026-07-16T20:29:20.902723Z","price_level":"56118.13","new_quantity":"0"}]}]}
{"channel":"l2_data","timestamp":"2026-07-16T20:29:20.997221609Z","sequence_num":579,"events":[{"type":"update","product_id":"BTC-USD","updates":[{"side":"bid","event_time":"2026-07-16T20:29:20.965805Z","price_level":"64135","new_quantity":"0.01807913"},{"side":"bid","event_time":"2026-07-16T20:29:20.965805Z","price_level":"64123.95","new_quantity":"0.01559475"},{"side":"bid","event_time":"2026-07-16T20:29:20.965805Z","price_level":"64110.69","new_quantity":"0.02306801"},{"side":"offer","event_time":"2026-07-16T20:29:20.965805Z","price_level":"64145.32","new_quantity":"0"},{"side":"offer","event_time":"2026-07-16T20:29:20.965805Z","price_level":"64145.99","new_quantity":"0.00779472"},{"side":"offer","event_time":"2026-07-16T20:29:20.965805Z","price_level":"64146.28","new_quantity":"0"},{"side":"offer","event_time":"2026-07-16T20:29:20.965805Z","price_level":"64284.41","new_quantity":"0"}]}]}
{"channel":"l2_data","timestamp":"2026-07-16T20:29:21.039793121Z","sequence_num":580,"events":[{"type":"update","product_id":"BTC-USD","updates":[{"side":"bid","event_time":"2026-07-16T20:29:20.977507Z","price_level":"63983.27","new_quantity":"0"},{"side":"offer","event_time":"2026-07-16T20:29:20.977507Z","price_level":"64145.03","new_quantity":"0.00009744"}]}]}
{"channel":"l2_data","timestamp":"2026-07-16T20:29:21.091015598Z","sequence_num":581,"events":[{"type":"update","product_id":"BTC-USD","updates":[{"side":"bid","event_time":"2026-07-16T20:29:21.02002Z","price_level":"64130.19","new_quantity":"0"},{"side":"bid","event_time":"2026-07-16T20:29:21.02002Z","price_level":"64128.59","new_quantity":"0"},{"side":"bid","event_time":"2026-07-16T20:29:21.02002Z","price_level":"64123.96","new_quantity":"0.01559475"},{"side":"bid","event_time":"2026-07-16T20:29:21.02002Z","price_level":"64123.95","new_quantity":"0"},{"side":"offer","event_time":"2026-07-16T20:29:21.02002Z","price_level":"64146.17","new_quantity":"0"},{"side":"offer","event_time":"2026-07-16T20:29:21.02002Z","price_level":"64146.48","new_quantity":"0"},{"side":"offer","event_time":"2026-07-16T20:29:21.02002Z","price_level":"64147.77","new_quantity":"0"}]}]}
{"channel":"l2_data","timestamp":"2026-07-16T20:29:21.142122797Z","sequence_num":582,"events":[{"type":"update","product_id":"BTC-USD","updates":[{"side":"bid","event_time":"2026-07-16T20:29:21.100575Z","price_level":"64121.22","new_quantity":"0.605166"},{"side":"bid","event_time":"2026-07-16T20:29:21.100575Z","price_level":"64106","new_quantity":"0"},{"side":"bid","event_time":"2026-07-16T20:29:21.100575Z","price_level":"56118.13","new_quantity":"0.01337205"},{"side":"offer","event_time":"2026-07-16T20:29:21.100575Z","price_level":"64280.04","new_quantity":"2.2369426"}]}]}
{"channel":"heartbeats","timestamp":"2026-07-16T20:29:21.167567559Z","sequence_num":583,"events":[{"current_time":"2026-07-16 20:29:21.162880528 +0000 UTC m=+75525.317707564","heartbeat_counter":75525}]}
{"channel":"l2_data","timestamp":"2026-07-16T20:29:21.180123834Z","sequence_num":584,"events":[{"type":"update","product_id":"BTC-USD","updates":[{"side":"bid","event_time":"2026-07-16T20:29:21.151373Z","price_level":"64128.59","new_quantity":"0.00779683"},{"side":"bid","event_time":"2026-07-16T20:29:21.151373Z","price_level":"64123.97","new_quantity":"0.01559475"},{"side":"bid","event_time":"2026-07-16T20:29:21.151373Z","price_level":"64123.96","new_quantity":"0"},{"side":"bid","event_time":"2026-07-16T20:29:21.151373Z","price_level":"64121.22","new_quantity":"0"},{"side":"bid","event_time":"2026-07-16T20:29:21.151373Z","price_level":"64103","new_quantity":"1"}]}]}
{"channel":"l2_data","timestamp":"2026-07-16T20:29:21.244377495Z","sequence_num":585,"events":[{"type":"update","product_id":"BTC-USD","updates":[{"side":"bid","event_time":"2026-07-16T20:29:21.200097Z","price_level":"64135","new_quantity":"0.01807897"},{"side":"bid","event_time":"2026-07-16T20:29:21.200097Z","price_level":"64123.98","new_quantity":"0.01559475"},{"side":"bid","event_time":"2026-07-16T20:29:21.200097Z","price_level":"64123.97","new_quantity":"0"},{"side":"bid","event_time":"2026-07-16T20:29:21.200097Z","price_level":"56118.13","new_quantity":"0"},{"side":"offer","event_time":"2026-07-16T20:29:21.200097Z","price_level":"64147.49","new_quantity":"0.00896372"},{"side":"offer","event_time":"2026-07-16T20:29:21.200097Z","price_level":"64173.92","new_quantity":"0.23992856"},{"side":"offer","event_time":"2026-07-16T20:29:21.200097Z","price_level":"64193.7","new_quantity":"1.52865631"}]}]}
{"channel":"l2_data","timestamp":"2026-07-16T20:29:21.292137608Z","sequence_num":586,"events":[{"type":"update","product_id":"BTC-USD","updates":[{"side":"bid","event_time":"2026-07-16T20:29:21.258803Z","price_level":"64130.19","new_quantity":"0.00779664"},{"side":"bid","event_time":"2026-07-16T20:29:21.258803Z","price_level":"64103","new_quantity":"0"},{"side":"offer","event_time":"2026-07-16T20:29:21.258803Z","price_level":"64145.88","new_quantity":"0.00896394"}]}]}
{"channel":"l2_data","timestamp":"2026-07-16T20:29:21.32555754Z","sequence_num":587,"events":[{"type":"update","product_id":"BTC-USD","updates":[{"side":"bid","event_time":"2026-07-16T20:29:21.297253Z","price_level":"64135","new_quantity":"0.01797991"},{"side":"bid","event_time":"2026-07-16T20:29:21.297253Z","price_level":"64106","new_quantity":"1"},{"side":"bid","event_time":"2026-07-16T20:29:21.297253Z","price_level":"63978.59","new_quantity":"3.00907651"}]}]}
{"channel":"l2_data","timestamp":"2026-07-16T20:29:21.375237372Z","sequence_num":588,"events":[{"type":"update","product_id":"BTC-USD","updates":[{"side":"bid","event_time":"2026-07-16T20:29:21.352876Z","price_level":"64121.29","new_quantity":"0.59007"}]}]}
{"channel":"l2_data","timestamp":"2026-07-16T20:29:21.433515463Z","sequence_num":589,"events":[{"type":"update","product_id":"BTC-USD","updates":[{"side":"bid","event_time":"2026-07-16T20:29:21.39653Z","price_level":"56118.13","new_quantity":"0.01337205"},{"side":"offer","event_time":"2026-07-16T20:29:21.39653Z","price_level":"64146.2","new_quantity":"0.00009743"},{"side":"offer","event_time":"2026-07-16T20:29:21.39653Z","price_level":"64147.48","new_quantity":"0.00779454"},{"side":"offer","event_time":"2026-07-16T20:29:21.39653Z","price_level":"64775.93","new_quantity":"0"}]}]}
{"channel":"l2_data","timestamp":"2026-07-16T20:29:21.475635869Z","sequence_num":590,"events":[{"type":"update","product_id":"BTC-USD","updates":[{"side":"bid","event_time":"2026-07-16T20:29:21.443251Z","price_level":"64121.29","new_quantity":"0"}]}]}
{"channel":"l2_data","timestamp":"2026-07-16T20:29:21.525440433Z","sequence_num":591,"events":[{"type":"update","product_id":"BTC-USD","updates":[{"side":"bid","event_time":"2026-07-16T20:29:21.487857Z","price_level":"64135","new_quantity":"0.01797987"},{"side":"bid","event_time":"2026-07-16T20:29:21.487857Z","price_level":"64123.99","new_quantity":"0.01559475"},{"side":"bid","event_time":"2026-07-16T20:29:21.487857Z","price_level":"64123.98","new_quantity":"0"},{"side":"bid","event_time":"2026-07-16T20:29:21.487857Z","price_level":"56118.13","new_quantity":"0"}]}]}
{"channel":"l2_data","timestamp":"2026-07-16T20:29:21.579624467Z","sequence_num":592,"events":[{"type":"update","product_id":"BTC-USD","updates":[{"side":"offer","event_time":"2026-07-16T20:29:21.552256Z","price_level":"64150.35","new_quantity":"0"}]}]}
{"channel":"l2_data","timestamp":"2026-07-16T20:29:21.633098803Z","sequence_num":593,"events":[{"type":"update","product_id":"BTC-USD","updates":[{"side":"bid","event_time":"2026-07-16T20:29:21.600969Z","price_level":"64135","new_quantity":"0.02050686"},{"side":"bid","event_time":"2026-07-16T20:29:21.600969Z","price_level":"64121.31","new_quantity":"0.622934"},{"side":"offer","event_time":"2026-07-16T20:29:21.600969Z","price_level":"64777.23","new_quantity":"0.03890047"}]}]}
{"channel":"l2_data","timestamp":"2026-07-16T20:29:21.681682424Z","sequence_num":594,"events":[{"type":"update","product_id":"BTC-USD","updates":[{"side":"bid","event_time":"2026-07-16T20:29:21.65986Z","price_level":"64135","new_quantity":"0.02050675"},{"side":"bid","event_time":"2026-07-16T20:29:21.65986Z","price_level":"64124","new_quantity":"0.01559475"},{"side":"bid","event_time":"2026-07-16T20:29:21.65986Z","price_level":"64123.99","new_quantity":"0"},{"side":"bid","event_time":"2026-07-16T20:29:21.65986Z","price_level":"64121.31","new_quantity":"0"},{"side":"offer","event_time":"2026-07-16T20:29:21.65986Z","price_level":"64150","new_quantity":"0.01"}]}]}
{"channel":"l2_data","timestamp":"2026-07-16T20:29:21.730530999Z","sequence_num":595,"events":[{"type":"update","product_id":"BTC-USD","updates":[{"side":"bid","event_time":"2026-07-16T20:29:21.709116Z","price_level":"64064","new_quantity":"0.0111763"},{"side":"bid","event_time":"2026-07-16T20:29:21.709116Z","price_level":"62823.8","new_quantity":"0.00583"},{"side":"bid","event_time":"2026-07-16T20:29:21.709116Z","price_level":"62823.66","new_quantity":"0"},{"side":"bid","event_time":"2026-07-16T20:29:21.709116Z","price_level":"56118.13","new_quantity":"0.01337205"},{"side":"offer","event_time":"2026-07-16T20:29:21.709116Z","price_level":"64135.01","new_quantity":"1.1579276"},{"side":"offer","event_time":"2026-07-16T20:29:21.709116Z","price_level":"64149.31","new_quantity":"0.6366932"},{"side":"offer","event_time":"2026-07-16T20:29:21.709116Z","price_level":"64151","new_quantity":"1"}]}]}
{"channel":"l2_data","timestamp":"2026-07-16T20:29:21.780387363Z","sequence_num":596,"events":[{"type":"update","product_id":"BTC-USD","updates":[{"side":"bid","event_time":"2026-07-16T20:29:21.753189Z","price_level":"64135","new_quantity":"0.01797976"},{"side":"bid","event_time":"2026-07-16T20:29:21.753189Z","price_level":"64103.01","new_quantity":"0"},{"side":"bid","event_time":"2026-07-16T20:29:21.753189Z","price_level":"64102.76","new_quantity":"0.00077957"},{"side":"offer","event_time":"2026-07-16T20:29:21.753189Z","price_level":"64147.97","new_quantity":"0.33"},{"side":"offer","event_time":"2026-07-16T20:29:21.753189Z","price_level":"64149.31","new_quantity":"0.99557463"}]}]}
{"channel":"l2_data","timestamp":"2026-07-16T20:29:21.825263198Z","sequence_num":597,"events":[{"type":"update","product_id":"BTC-USD","updates":[{"side":"bid","event_time":"2026-07-16T20:29:21.791277Z","price_level":"56118.13","new_quantity":"0"}]}]}
{"channel":"l2_data","timestamp":"2026-07-16T20:29:21.875083664Z","sequence_num":598,"events":[{"type":"update","product_id":"BTC-USD","updates":[{"side":"bid","event_time":"2026-07-16T20:29:21.837849Z","price_level":"64124.01","new_quantity":"0.01559475"},{"side":"bid","event_time":"2026-07-16T20:29:21.837849Z","price_level":"64124","new_quantity":"0"},{"side":"bid","event_time":"2026-07-16T20:29:21.837849Z","price_level":"64106","new_quantity":"0"}]}]}
{"channel":"l2_data","timestamp":"2026-07-16T20:29:21.930956045Z","sequence_num":599,"events":[{"type":"update","product_id":"BTC-USD","updates":[{"side":"bid","event_time":"2026-07-16T20:29:21.906139Z","price_level":"64128.6","new_quantity":"0.02"},{"side":"bid","event_time":"2026-07-16T20:29:21.906139Z","price_level":"64127.96","new_quantity":"0.12475055"},{"side":"bid","event_time":"2026-07-16T20:29:21.906139Z","price_level":"64127.37","new_quantity":"0"},{"side":"bid","event_time":"2026-07-16T20:29:21.906139Z","price_level":"64127.36","new_quantity":"0"},{"side":"bid","event_time":"2026-07-16T20:29:21.906139Z","price_level":"64124.01","new_quantity":"0"},{"side":"bid","event_time":"2026-07-16T20:29:21.906139Z","price_level":"64121.3","new_quantity":"0"},{"side":"bid","event_time":"2026-07-16T20:29:21.906139Z","price_level":"64107","new_quantity":"0"},{"side":"offer","event_time":"2026-07-16T20:29:21.906139Z","price_level":"64173.91","new_quantity":"0.32027682"},{"side":"offer","event_time":"2026-07-16T20:29:21.906139Z","price_level":"64173.92","new_quantity":"0"},{"side":"offer","event_time":"2026-07-16T20:29:21.906139Z","price_level":"64173.93","new_quantity":"0"}]}]}
{"channel":"l2_data","timestamp":"2026-07-16T20:29:21.97604704Z","sequence_num":600,"events":[{"type":"update","product_id":"BTC-USD","updates":[{"side":"bid","event_time":"2026-07-16T20:29:21.957841Z","price_level":"64124.64","new_quantity":"0.01559475"},{"side":"bid","event_time":"2026-07-16T20:29:21.957841Z","price_level":"64108.01","new_quantity":"0.64746949"},{"side":"bid","event_time":"2026-07-16T20:29:21.957841Z","price_level":"64108","new_quantity":"1"},{"side":"bid","event_time":"2026-07-16T20:29:21.957841Z","price_level":"64107.36","new_quantity":"0"},{"side":"bid","event_time":"2026-07-16T20:29:21.957841Z","price_level":"64099.54","new_quantity":"0.00155818"},{"side":"bid","event_time":"2026-07-16T20:29:21.957841Z","price_level":"64097.74","new_quantity":"0"},{"side":"bid","event_time":"2026-07-16T20:29:21.957841Z","price_level":"64093.13","new_quantity":"0.00779093"},{"side":"bid","event_time":"2026-07-16T20:29:21.957841Z","price_level":"64091.33","new_quantity":"0"},{"side":"bid","event_time":"2026-07-16T20:29:21.957841Z","price_level":"63493.24","new_quantity":"0"}]}]}
{"channel":"l2_data","timestamp":"2026-07-16T20:29:22.025160418Z","sequence_num":601,"events":[{"type":"update","product_id":"BTC-USD","updates":[{"side":"bid","event_time":"2026-07-16T20:29:21.995856Z","price_level":"56118.13","new_quantity":"0.01337205"}]}]}
{"channel":"l2_data","timestamp":"2026-07-16T20:29:22.087978977Z","sequence_num":602,"events":[{"type":"update","product_id":"BTC-USD","updates":[{"side":"bid","event_time":"2026-07-16T20:29:22.032865Z","price_level":"64130.19","new_quantity":"0"},{"side":"bid","event_time":"2026-07-16T20:29:22.032865Z","price_level":"64128.59","new_quantity":"0"},{"side":"bid","event_time":"2026-07-16T20:29:22.032865Z","price_level":"64127.97","new_quantity":"0.02"},{"side":"offer","event_time":"2026-07-16T20:29:22.032865Z","price_level":"64144.75","new_quantity":"0.00009744"},{"side":"offer","event_time":"2026-07-16T20:29:22.032865Z","price_level":"64145.03","new_quantity":"0"},{"side":"offer","event_time":"2026-07-16T20:29:22.032865Z","price_level":"64145.71","new_quantity":"0.00779475"},{"side":"offer","event_time":"2026-07-16T20:29:22.032865Z","price_level":"64145.88","new_quantity":"0"},{"side":"offer","event_time":"2026-07-16T20:29:22.032865Z","price_level":"64145.99","new_quantity":"0"},{"side":"offer","event_time":"2026-07-16T20:29:22.032865Z","price_level":"64146.2","new_quantity":"0"},{"side":"offer","event_time":"2026-07-16T20:29:22.032865Z","price_level":"64147.48","new_quantity":"0"},{"side":"offer","event_time":"2026-07-16T20:29:22.032865Z","price_level":"64147.49","new_quantity":"0"}]}]}
{"channel":"l2_data","timestamp":"2026-07-16T20:29:22.124969039Z","sequence_num":603,"events":[{"type":"update","product_id":"BTC-USD","updates":[{"side":"bid","event_time":"2026-07-16T20:29:22.103051Z","price_level":"64128.6","new_quantity":"0"},{"side":"bid","event_time":"2026-07-16T20:29:22.103051Z","price_level":"64121.32","new_quantity":"0.624708"},{"side":"bid","event_time":"2026-07-16T20:29:22.103051Z","price_level":"56118.13","new_quantity":"0"}]}]}
{"channel":"heartbeats","timestamp":"2026-07-16T20:29:22.165132169Z","sequence_num":604,"events":[{"current_time":"2026-07-16 20:29:22.162950414 +0000 UTC m=+75526.317777467","heartbeat_counter":75526}]}
{"channel":"l2_data","timestamp":"2026-07-16T20:29:22.17487203Z","sequence_num":605,"events":[{"type":"update","product_id":"BTC-USD","updates":[{"side":"bid","event_time":"2026-07-16T20:29:22.149935Z","price_level":"64124.65","new_quantity":"0.01559475"},{"side":"bid","event_time":"2026-07-16T20:29:22.149935Z","price_level":"64124.64","new_quantity":"0"},{"side":"bid","event_time":"2026-07-16T20:29:22.149935Z","price_level":"64121.32","new_quantity":"0"},{"side":"bid","event_time":"2026-07-16T20:29:22.149935Z","price_level":"63494.51","new_quantity":"0.03937999"}]}]}
{"channel":"l2_data","timestamp":"2026-07-16T20:29:22.229794415Z","sequence_num":606,"events":[{"type":"update","product_id":"BTC-USD","updates":[{"side":"bid","event_time":"2026-07-16T20:29:22.188696Z","price_level":"64128.59","new_quantity":"0.00779683"},{"side":"offer","event_time":"2026-07-16T20:29:22.188696Z","price_level":"64147.21","new_quantity":"0.00896376"}]}]}
{"channel":"l2_data","timestamp":"2026-07-16T20:29:22.280631321Z","sequence_num":607,"events":[{"type":"update","product_id":"BTC-USD","updates":[{"side":"bid","event_time":"2026-07-16T20:29:22.238336Z","price_level":"64135","new_quantity":"0.01797968"},{"side":"bid","event_time":"2026-07-16T20:29:22.238336Z","price_level":"64128.6","new_quantity":"0.02"},{"side":"offer","event_time":"2026-07-16T20:29:22.238336Z","price_level":"64173.9","new_quantity":"0.23992856"},{"side":"offer","event_time":"2026-07-16T20:29:22.238336Z","price_level":"64191.72","new_quantity":"0.69636377"},{"side":"offer","event_time":"2026-07-16T20:29:22.238336Z","price_level":"64191.74","new_quantity":"0"}]}]}
{"channel":"l2_data","timestamp":"2026-07-16T20:29:22.329668625Z","sequence_num":608,"events":[{"type":"update","product_id":"BTC-USD","updates":[{"side":"bid","event_time":"2026-07-16T20:29:22.304433Z","price_level":"64135","new_quantity":"0.02170077"},{"side":"bid","event_time":"2026-07-16T20:29:22.304433Z","price_level":"64130.19","new_quantity":"0.00779664"},{"side":"bid","event_time":"2026-07-16T20:29:22.304433Z","price_level":"64111.18","new_quantity":"0.00583"},{"side":"bid","event_time":"2026-07-16T20:29:22.304433Z","price_level":"63893.97","new_quantity":"0"},{"side":"bid","event_time":"2026-07-16T20:29:22.304433Z","price_level":"62823.8","new_quantity":"0"},{"side":"bid","event_time":"2026-07-16T20:29:22.304433Z","price_level":"56118.13","new_quantity":"0.01337205"},{"side":"offer","event_time":"2026-07-16T20:29:22.304433Z","price_level":"64145.61","new_quantity":"0.00896398"}]}]}
{"channel":"l2_data","timestamp":"2026-07-16T20:29:22.375481102Z","sequence_num":609,"events":[{"type":"update","product_id":"BTC-USD","updates":[{"side":"bid","event_time":"2026-07-16T20:29:22.362512Z","price_level":"64124.65","new_quantity":"0"},{"side":"bid","event_time":"2026-07-16T20:29:22.362512Z","price_level":"64124.64","new_quantity":"0.01559475"},{"side":"bid","event_time":"2026-07-16T20:29:22.362512Z","price_level":"64121.42","new_quantity":"0.698022"}]}]}
{"channel":"l2_data","timestamp":"2026-07-16T20:29:22.425141721Z","sequence_num":610,"events":[{"type":"update","product_id":"BTC-USD","updates":[{"side":"bid","event_time":"2026-07-16T20:29:22.39088Z","price_level":"56118.13","new_quantity":"0"}]}]}
{"channel":"l2_data","timestamp":"2026-07-16T20:29:22.479899294Z","sequence_num":611,"events":[{"type":"update","product_id":"BTC-USD","updates":[{"side":"bid","event_time":"2026-07-16T20:29:22.457874Z","price_level":"64135","new_quantity":"0.01797968"},{"side":"bid","event_time":"2026-07-16T20:29:22.457874Z","price_level":"64121.42","new_quantity":"0"},{"side":"bid","event_time":"2026-07-16T20:29:22.457874Z","price_level":"64111.44","new_quantity":"0.00583"},{"side":"bid","event_time":"2026-07-16T20:29:22.457874Z","price_level":"64111.18","new_quantity":"0"},{"side":"bid","event_time":"2026-07-16T20:29:22.457874Z","price_level":"64110.74","new_quantity":"0"},{"side":"bid","event_time":"2026-07-16T20:29:22.457874Z","price_level":"63896.33","new_quantity":"0.00583"},{"side":"offer","event_time":"2026-07-16T20:29:22.457874Z","price_level":"64135.01","new_quantity":"1.15704017"},{"side":"offer","event_time":"2026-07-16T20:29:22.457874Z","price_level":"64145.92","new_quantity":"0.00009743"},{"side":"offer","event_time":"2026-07-16T20:29:22.457874Z","price_level":"64147.21","new_quantity":"0.01675833"}]}]}
{"channel":"l2_data","timestamp":"2026-07-16T20:29:22.642114078Z","sequence_num":612,"events":[{"type":"update","product_id":"BTC-USD","updates":[{"side":"bid","event_time":"2026-07-16T20:29:22.612562Z","price_level":"64121.38","new_quantity":"0.593947"},{"side":"bid","event_time":"2026-07-16T20:29:22.612562Z","price_level":"64086.28","new_quantity":"0"},{"side":"bid","event_time":"2026-07-16T20:29:22.612562Z","price_level":"56118.13","new_quantity":"0.01337205"},{"side":"offer","event_time":"2026-07-16T20:29:22.612562Z","price_level":"64155.12","new_quantity":"0"}]}]}
{"channel":"l2_data","timestamp":"2026-07-16T20:29:22.682624286Z","sequence_num":613,"events":[{"type":"update","product_id":"BTC-USD","updates":[{"side":"bid","event_time":"2026-07-16T20:29:22.638536Z","price_level":"64121.38","new_quantity":"0"},{"side":"bid","event_time":"2026-07-16T20:29:22.638536Z","price_level":"64105.51","new_quantity":"0"},{"side":"offer","event_time":"2026-07-16T20:29:22.638536Z","price_level":"64174.36","new_quantity":"0"}]}]}
{"channel":"l2_data","timestamp":"2026-07-16T20:29:22.724550712Z","sequence_num":614,"events":[{"type":"update","product_id":"BTC-USD","updates":[{"side":"bid","event_time":"2026-07-16T20:29:22.691205Z","price_level":"64064.42","new_quantity":"0"},{"side":"bid","event_time":"2026-07-16T20:29:22.691205Z","price_level":"64052.73","new_quantity":"0.280583"},{"side":"bid","event_time":"2026-07-16T20:29:22.691205Z","price_level":"56118.13","new_quantity":"0"}]}]}
{"channel":"l2_data","timestamp":"2026-07-16T20:29:22.775007168Z","sequence_num":615,"events":[{"type":"update","product_id":"BTC-USD","updates":[{"side":"bid","event_time":"2026-07-16T20:29:22.743759Z","price_level":"64124.64","new_quantity":"0"},{"side":"bid","event_time":"2026-07-16T20:29:22.743759Z","price_level":"64124.63","new_quantity":"0.01559475"}]}]}
{"channel":"l2_data","timestamp":"2026-07-16T20:29:22.8254683Z","sequence_num":616,"events":[{"type":"update","product_id":"BTC-USD","updates":[{"side":"bid","event_time":"2026-07-16T20:29:22.812051Z","price_level":"64124.63","new_quantity":"0"},{"side":"bid","event_time":"2026-07-16T20:29:22.812051Z","price_level":"64124.6","new_quantity":"0.01559475"},{"side":"bid","event_time":"2026-07-16T20:29:22.812051Z","price_level":"63896.87","new_quantity":"0.00583"},{"side":"bid","event_time":"2026-07-16T20:29:22.812051Z","price_level":"63896.27","new_quantity":"0"},{"side":"bid","event_time":"2026-07-16T20:29:22.812051Z","price_level":"62824.15","new_quantity":"0"}]}]}
{"channel":"l2_data","timestamp":"2026-07-16T20:29:22.874665099Z","sequence_num":617,"events":[{"type":"update","product_id":"BTC-USD","updates":[{"side":"bid","event_time":"2026-07-16T20:29:22.858499Z","price_level":"64121.34","new_quantity":"0"}]}]}
{"channel":"l2_data","timestamp":"2026-07-16T20:29:22.935626918Z","sequence_num":618,"events":[{"type":"update","product_id":"BTC-USD","updates":[{"side":"bid","event_time":"2026-07-16T20:29:22.907707Z","price_level":"64124.6","new_quantity":"0"},{"side":"bid","event_time":"2026-07-16T20:29:22.907707Z","price_level":"64124.59","new_quantity":"0.01559475"},{"side":"bid","event_time":"2026-07-16T20:29:22.907707Z","price_level":"64103.75","new_quantity":"0.27165243"},{"side":"bid","event_time":"2026-07-16T20:29:22.907707Z","price_level":"64084.51","new_quantity":"0.54350341"},{"side":"bid","event_time":"2026-07-16T20:29:22.907707Z","price_level":"56118.13","new_quantity":"0.01337205"},{"side":"offer","event_time":"2026-07-16T20:29:22.907707Z","price_level":"64155.17","new_quantity":"0.27752112"},{"side":"offer","event_time":"2026-07-16T20:29:22.907707Z","price_level":"64174.41","new_quantity":"0.54115806"}]}]}
{"channel":"l2_data","timestamp":"2026-07-16T20:29:22.976908545Z","sequence_num":619,"events":[{"type":"update","product_id":"BTC-USD","updates":[{"side":"bid","event_time":"2026-07-16T20:29:22.941665Z","price_level":"64108","new_quantity":"0"}]}]}
{"channel":"l2_data","timestamp":"2026-07-16T20:29:23.026251693Z","sequence_num":620,"events":[{"type":"update","product_id":"BTC-USD","updates":[{"side":"bid","event_time":"2026-07-16T20:29:22.991386Z","price_level":"64109","new_quantity":"1"},{"side":"bid","event_time":"2026-07-16T20:29:22.991386Z","price_level":"56118.13","new_quantity":"0"}]}]}
{"channel":"l2_data","timestamp":"2026-07-16T20:29:23.08834619Z","sequence_num":621,"events":[{"type":"update","product_id":"BTC-USD","updates":[{"side":"bid","event_time":"2026-07-16T20:29:23.048333Z","price_level":"64135","new_quantity":"0.02154505"},{"side":"bid","event_time":"2026-07-16T20:29:23.048333Z","price_level":"64130.19","new_quantity":"0"},{"side":"bid","event_time":"2026-07-16T20:29:23.048333Z","price_level":"64128.59","new_quantity":"0"},{"side":"bid","event_time":"2026-07-16T20:29:23.048333Z","price_level":"64128.43","new_quantity":"0.02"},{"side":"bid","event_time":"2026-07-16T20:29:23.048333Z","price_level":"62824.65","new_quantity":"0.00583"},{"side":"offer","event_time":"2026-07-16T20:29:23.048333Z","price_level":"64144.75","new_quantity":"0"},{"side":"offer","event_time":"2026-07-16T20:29:23.048333Z","price_level":"64145.61","new_quantity":"0"},{"side":"offer","event_time":"2026-07-16T20:29:23.048333Z","price_level":"64145.71","new_quantity":"0"},{"side":"offer","event_time":"2026-07-16T20:29:23.048333Z","price_level":"64145.92","new_quantity":"0"},{"side":"offer","event_time":"2026-07-16T20:29:23.048333Z","price_level":"64147.21","new_quantity":"0"}]}]}
{"channel":"l2_data","timestamp":"2026-07-16T20:29:23.1297322Z","sequence_num":622,"events":[{"type":"update","product_id":"BTC-USD","updates":[{"side":"bid","event_time":"2026-07-16T20:29:23.100419Z","price_level":"64121.47","new_quantity":"0.633969"},{"side":"offer","event_time":"2026-07-16T20:29:23.100419Z","price_level":"64144.47","new_quantity":"0.0077892"},{"side":"offer","event_time":"2026-07-16T20:29:23.100419Z","price_level":"64144.48","new_quantity":"0.00009744"},{"side":"offer","event_time":"2026-07-16T20:29:23.100419Z","price_level":"64144.56","new_quantity":"0"},{"side":"offer","event_time":"2026-07-16T20:29:23.100419Z","price_level":"64145.45","new_quantity":"0.00779479"}]}]}
{"channel":"heartbeats","timestamp":"2026-07-16T20:29:23.164516245Z","sequence_num":623,"events":[{"current_time":"2026-07-16 20:29:23.162977679 +0000 UTC m=+75527.317804732","heartbeat_counter":75527}]}
{"channel":"l2_data","timestamp":"2026-07-16T20:29:23.174805196Z","sequence_num":624,"events":[{"type":"update","product_id":"BTC-USD","updates":[{"side":"bid","event_time":"2026-07-16T20:29:23.161151Z","price_level":"64135","new_quantity":"0.02154483"},{"side":"bid","event_time":"2026-07-16T20:29:23.161151Z","price_level":"64128.6","new_quantity":"0"},{"side":"bid","event_time":"2026-07-16T20:29:23.161151Z","price_level":"64121.47","new_quantity":"0"}]}]}
{"channel":"l2_data","timestamp":"2026-07-16T20:29:23.230088934Z","sequence_num":625,"events":[{"type":"update","product_id":"BTC-USD","updates":[{"side":"bid","event_time":"2026-07-16T20:29:23.211253Z","price_level":"64124.59","new_quantity":"0"},{"side":"bid","event_time":"2026-07-16T20:29:23.211253Z","price_level":"64124.58","new_quantity":"0.01559475"},{"side":"bid","event_time":"2026-07-16T20:29:23.211253Z","price_level":"56118.13","new_quantity":"0.01337205"},{"side":"offer","event_time":"2026-07-16T20:29:23.211253Z","price_level":"64173.89","new_quantity":"0.32027682"},{"side":"offer","event_time":"2026-07-16T20:29:23.211253Z","price_level":"64173.9","new_quantity":"0"},{"side":"offer","event_time":"2026-07-16T20:29:23.211253Z","price_level":"64173.91","new_quantity":"0"}]}]}
{"channel":"l2_data","timestamp":"2026-07-16T20:29:23.280235443Z","sequence_num":626,"events":[{"type":"update","product_id":"BTC-USD","updates":[{"side":"bid","event_time":"2026-07-16T20:29:23.251441Z","price_level":"64128.59","new_quantity":"0.00779683"},{"side":"bid","event_time":"2026-07-16T20:29:23.251441Z","price_level":"64121.3","new_quantity":"0.07432"},{"side":"offer","event_time":"2026-07-16T20:29:23.251441Z","price_level":"64146.95","new_quantity":"0.00896379"},{"side":"offer","event_time":"2026-07-16T20:29:23.251441Z","price_level":"64173.88","new_quantity":"0.23992856"},{"side":"offer","event_time":"2026-07-16T20:29:23.251441Z","price_level":"64191.7","new_quantity":"0.69636398"},{"side":"offer","event_time":"2026-07-16T20:29:23.251441Z","price_level":"64191.71","new_quantity":"0"},{"side":"offer","event_time":"2026-07-16T20:29:23.251441Z","price_level":"64191.72","new_quantity":"0"}]}]}
{"channel":"l2_data","timestamp":"2026-07-16T20:29:23.325012404Z","sequence_num":627,"events":[{"type":"update","product_id":"BTC-USD","updates":[{"side":"bid","event_time":"2026-07-16T20:29:23.295153Z","price_level":"64135","new_quantity":"0.0215448"},{"side":"bid","event_time":"2026-07-16T20:29:23.295153Z","price_level":"56118.13","new_quantity":"0"}]}]}
{"channel":"l2_data","timestamp":"2026-07-16T20:29:23.375286399Z","sequence_num":628,"events":[{"type":"update","product_id":"BTC-USD","updates":[{"side":"bid","event_time":"2026-07-16T20:29:23.349865Z","price_level":"64135","new_quantity":"0.01797943"},{"side":"bid","event_time":"2026-07-16T20:29:23.349865Z","price_level":"64121.48","new_quantity":"0.691573"},{"side":"bid","event_time":"2026-07-16T20:29:23.349865Z","price_level":"63896.33","new_quantity":"0"},{"side":"bid","event_time":"2026-07-16T20:29:23.349865Z","price_level":"63681.74","new_quantity":"0.00583"},{"side":"bid","event_time":"2026-07-16T20:29:23.349865Z","price_level":"62824.65","new_quantity":"0"}]}]}
{"channel":"l2_data","timestamp":"2026-07-16T20:29:23.710891073Z","sequence_num":629,"events":[{"type":"update","product_id":"BTC-USD","updates":[{"side":"bid","event_time":"2026-07-16T20:29:23.399781Z","price_level":"64130.19","new_quantity":"0.00779664"},{"side":"bid","event_time":"2026-07-16T20:29:23.399781Z","price_level":"64121.48","new_quantity":"0"},{"side":"bid","event_time":"2026-07-16T20:29:23.399781Z","price_level":"64118.1","new_quantity":"0"},{"side":"bid","event_time":"2026-07-16T20:29:23.399781Z","price_level":"64109","new_quantity":"0"},{"side":"offer","event_time":"2026-07-16T20:29:23.399781Z","price_level":"64145.34","new_quantity":"0.00896402"}]}]}
{"channel":"l2_data","timestamp":"2026-07-16T20:29:23.711268501Z","sequence_num":630,"events":[{"type":"update","product_id":"BTC-USD","updates":[{"side":"bid","event_time":"2026-07-16T20:29:23.424983Z","price_level":"64108","new_quantity":"1"}]}]}
{"channel":"l2_data","timestamp":"2026-07-16T20:29:23.71159455Z","sequence_num":631,"events":[{"type":"update","product_id":"BTC-USD","updates":[{"side":"bid","event_time":"2026-07-16T20:29:23.49331Z","price_level":"64128.6","new_quantity":"0.31190852"},{"side":"bid","event_time":"2026-07-16T20:29:23.49331Z","price_level":"56118.13","new_quantity":"0.01337205"},{"side":"offer","event_time":"2026-07-16T20:29:23.49331Z","price_level":"64137.46","new_quantity":"0.09715379"},{"side":"offer","event_time":"2026-07-16T20:29:23.49331Z","price_level":"64138.34","new_quantity":"0"},{"side":"offer","event_time":"2026-07-16T20:29:23.49331Z","price_level":"64139.17","new_quantity":"0"},{"side":"offer","event_time":"2026-07-16T20:29:23.49331Z","price_level":"64145.66","new_quantity":"0.31200595"},{"side":"offer","event_time":"2026-07-16T20:29:23.49331Z","price_level":"64146.95","new_quantity":"0.01675839"}]}]}
{"channel":"l2_data","timestamp":"2026-07-16T20:29:23.713034833Z","sequence_num":632,"events":[{"type":"update","product_id":"BTC-USD","updates":[{"side":"bid","event_time":"2026-07-16T20:29:23.559326Z","price_level":"64130.68","new_quantity":"0.12474528"},{"side":"bid","event_time":"2026-07-16T20:29:23.559326Z","price_level":"64129.98","new_quantity":"0"},{"side":"bid","event_time":"2026-07-16T20:29:23.559326Z","price_level":"64128.63","new_quantity":"0"},{"side":"bid","event_time":"2026-07-16T20:29:23.559326Z","price_level":"64127.96","new_quantity":"0"},{"side":"bid","event_time":"2026-07-16T20:29:23.559326Z","price_level":"64125.7","new_quantity":"0"},{"side":"bid","event_time":"2026-07-16T20:29:23.559326Z","price_level":"64125.4","new_quantity":"0.01559475"},{"side":"bid","event_time":"2026-07-16T20:29:23.559326Z","price_level":"64124.58","new_quantity":"0"},{"side":"bid","event_time":"2026-07-16T20:29:23.559326Z","price_level":"64112.04","new_quantity":"0.00583"},{"side":"bid","event_time":"2026-07-16T20:29:23.559326Z","price_level":"64111.53","new_quantity":"0"},{"side":"bid","event_time":"2026-07-16T20:29:23.559326Z","price_level":"64111.44","new_quantity":"0"},{"side":"bid","event_time":"2026-07-16T20:29:23.559326Z","price_level":"64110","new_quantity":"1.01"},{"side":"bid","event_time":"2026-07-16T20:29:23.559326Z","price_level":"64108","new_quantity":"0"},{"side":"bid","event_time":"2026-07-16T20:29:23.559326Z","price_level":"63897.48","new_quantity":"0.00583"},{"side":"bid","event_time":"2026-07-16T20:29:23.559326Z","price_level":"63896.87","new_quantity":"0"},{"side":"bid","event_time":"2026-07-16T20:29:23.559326Z","price_level":"63683.04","new_quantity":"0.00583"},{"side":"bid","event_time":"2026-07-16T20:29:23.559326Z","price_level":"63682.58","new_quantity":"0.00583"},{"side":"bid","event_time":"2026-07-16T20:29:23.559326Z","price_level":"63681.74","new_quantity":"0"},{"side":"bid","event_time":"2026-07-16T20:29:23.559326Z","price_level":"63679.46","new_quantity":"0"},{"side":"bid","event_time":"2026-07-16T20:29:23.559326Z","price_level":"63256.57","new_quantity":"0"},{"side":"bid","event_time":"2026-07-16T20:29:23.559326Z","price_level":"63254.31","new_quantity":"0.00583"},{"side":"bid","event_time":"2026-07-16T20:29:23.559326Z","price_level":"63042.09","new_quantity":"0"},{"side":"offer","event_time":"2026-07-16T20:29:23.559326Z","price_level":"64139.19","new_quantity":"0.35648537"},{"side":"offer","event_time":"2026-07-16T20:29:23.559326Z","price_level":"64140.71","new_quantity":"0"},{"side":"offer","event_time":"2026-07-16T20:29:23.559326Z","price_level":"64141.25","new_quantity":"0.31190852"},{"side":"offer","event_time":"2026-07-16T20:29:23.559326Z","price_level":"64142.5","new_quantity":"0.23173984"},{"side":"offer","event_time":"2026-07-16T20:29:23.559326Z","price_level":"64142.51","new_quantity":"0"},{"side":"offer","event_time":"2026-07-16T20:29:23.559326Z","price_level":"64142.93","new_quantity":"0"},{"side":"offer","event_time":"2026-07-16T20:29:23.559326Z","price_level":"64143.34","new_quantity":"0.31190852"},{"side":"offer","event_time":"2026-07-16T20:29:23.559326Z","price_level":"64149.31","new_quantity":"0.6366932"},{"side":"offer","event_time":"2026-07-16T20:29:23.559326Z","price_level":"64151","new_quantity":"0"},{"side":"offer","event_time":"2026-07-16T20:29:23.559326Z","price_level":"64151.99","new_quantity":"1.05695538"},{"side":"offer","event_time":"2026-07-16T20:29:23.559326Z","price_level":"64152","new_quantity":"1"},{"side":"offer","event_time":"2026-07-16T20:29:23.559326Z","price_level":"64152.31","new_quantity":"0"}]}]}
{"channel":"l2_data","timestamp":"2026-07-16T20:29:23.714429674Z","sequence_num":633,"events":[{"type":"update","product_id":"BTC-USD","updates":[{"side":"bid","event_time":"2026-07-16T20:29:23.599939Z","price_level":"64128.43","new_quantity":"0"},{"side":"bid","event_time":"2026-07-16T20:29:23.599939Z","price_level":"64127.97","new_quantity":"0"},{"side":"bid","event_time":"2026-07-16T20:29:23.599939Z","price_level":"56118.13","new_quantity":"0"},{"side":"offer","event_time":"2026-07-16T20:29:23.599939Z","price_level":"64139.16","new_quantity":"0.59566397"},{"side":"offer","event_time":"2026-07-16T20:29:23.599939Z","price_level":"64139.17","new_quantity":"0.31190852"},{"side":"offer","event_time":"2026-07-16T20:29:23.599939Z","price_level":"64139.18","new_quantity":"0.04691558"},{"side":"offer","event_time":"2026-07-16T20:29:23.599939Z","price_level":"64139.19","new_quantity":"0"}]}]}
{"channel":"l2_data","timestamp":"2026-07-16T20:29:23.715784079Z","sequence_num":634,"events":[{"type":"update","product_id":"BTC-USD","updates":[{"side":"bid","event_time":"2026-07-16T20:29:23.654097Z","price_level":"64130.69","new_quantity":"0.02"},{"side":"bid","event_time":"2026-07-16T20:29:23.654097Z","price_level":"64101.65","new_quantity":"0.00155813"},{"side":"bid","event_time":"2026-07-16T20:29:23.654097Z","price_level":"64099.54","new_quantity":"0"},{"side":"bid","event_time":"2026-07-16T20:29:23.654097Z","price_level":"64095.25","new_quantity":"0.00779068"},{"side":"bid","event_time":"2026-07-16T20:29:23.654097Z","price_level":"64093.13","new_quantity":"0"},{"side":"bid","event_time":"2026-07-16T20:29:23.654097Z","price_level":"63039.71","new_quantity":"0.00583"},{"side":"bid","event_time":"2026-07-16T20:29:23.654097Z","price_level":"62825.28","new_quantity":"0.00583"},{"side":"offer","event_time":"2026-07-16T20:29:23.654097Z","price_level":"64135.01","new_quantity":"1.10060001"},{"side":"offer","event_time":"2026-07-16T20:29:23.654097Z","price_level":"64139.13","new_quantity":"0.59566397"},{"side":"offer","event_time":"2026-07-16T20:29:23.654097Z","price_level":"64139.14","new_quantity":"0.31190852"},{"side":"offer","event_time":"2026-07-16T20:29:23.654097Z","price_level":"64139.15","new_quantity":"0.04691558"},{"side":"offer","event_time":"2026-07-16T20:29:23.654097Z","price_level":"64139.16","new_quantity":"0"},{"side":"offer","event_time":"2026-07-16T20:29:23.654097Z","price_level":"64139.17","new_quantity":"0"},{"side":"offer","event_time":"2026-07-16T20:29:23.654097Z","price_level":"64139.18","new_quantity":"0"}]}]}
