{"action":"update","arg":{"instType":"SPOT","channel":"books","instId":"BTCUSDT"},"data":[{"asks":[],"bids":[["64812.5","0.026247"],["64811.57","0"],["64801.8","0.001543"],["64801.61","0"]],"ts":"1784090335607","seq":656732617933,"pseq":656732616410}],"ts":1784090335610}
{"action":"update","arg":{"instType":"SPOT","channel":"books","instId":"BTCUSDT"},"data":[{"asks":[["64823.01","0"],["64823.19","0.030884"]],"bids":[["64801.8","0"],["64801.61","0.061707"]],"ts":"1784090335702","seq":656732619235,"pseq":656732617933}],"ts":1784090335705}
{"action":"update","arg":{"instType":"SPOT","channel":"books","instId":"BTCUSDT"},"data":[{"asks":[["64815.01","2.238678"]],"bids":[["64801.8","0"],["64801.61","0.061707"]],"ts":"1784090335826","seq":656732620689,"pseq":656732619235}],"ts":1784090335830}
{"action":"update","arg":{"instType":"SPOT","channel":"books","instId":"BTCUSDT"},"data":[{"asks":[["64912.96","0.071415"],["64922.69","0.071415"],["64944.32","0"],["64954.06","0"]],"bids":[["64801.8","0"],["64801.61","0.061707"],["64798.29","0.269001"],["64797.96","0"],["64796.31","0.463259"],["64796.3","0.190723"]],"ts":"1784090335910","seq":656732621670,"pseq":656732620689}],"ts":1784090335912}
{"action":"update","arg":{"instType":"SPOT","channel":"books","instId":"BTCUSDT"},"data":[{"asks":[["64818.72","0.001691"],["64819.42","0"]],"bids":[["64802.94","0.061707"],["64801.8","0"],["64801.61","0"]],"ts":"1784090336006","seq":656732622596,"pseq":656732621670}],"ts":1784090336010}
{"action":"update","arg":{"instType":"SPOT","channel":"books","instId":"BTCUSDT"},"data":[{"asks":[["64815.01","2.238122"],["64820.8","0.426668"],["64820.81","0.463261"],["64820.82","0"],["64823.2","0"],["64827.57","0.256877"],["64829.97","0.075847"],["64840.75","0.154398"],["65074.09","0"]],"bids":[["64814.46","0"],["64805.92","0.087951"],["64805.9","0"],["64805.05","0"],["64805.04","0"],["64803.71","0"],["64802.94","0.061707"],["64796.32","0"],["64796.3","0"],["64795.01","0.030884"],["64748.32","0"],["64734.73","1.878183"],["64704.27","6.618033"],["64690.69","1.070506"],["64414.32","0.000039"],["64413.31","0.000034"],["64412.83","0.000791"]],"ts":"1784090336101","seq":656732624545,"pseq":656732622596}],"ts":1784090336104}
{"action":"update","arg":{"instType":"SPOT","channel":"books","instId":"BTCUSDT"},"data":[{"asks":[],"bids":[["64813.7","0.003882"],["64812.5","0"],["64810.88","0.026247"],["64801.6","0"],["64797.49","0.077199"],["64796.3","0.332278"],["64794.75","0"],["64794.15","0.084154"],["64785.25","0"],["64780.18","0.154399"],["64413.31","0"],["64412.83","0"]],"ts":"1784090336200","seq":656732626830,"pseq":656732624545}],"ts":1784090336203}
{"action":"update","arg":{"instType":"SPOT","channel":"books","instId":"BTCUSDT"},"data":[{"asks":[["64817.58","1.124207"],["64820.4","0.015579"],["64823.89","0"],["64831.09","0.01558"],["64850.23","0"],["64859.85","0"],["65074.09","0.000401"]],"bids":[["64807.6","0"],["64805.64","0.046319"],["64796.3","0.363163"],["64795.01","0"],["64413.31","0.000034"]],"ts":"1784090336304","seq":656732628511,"pseq":656732626830}],"ts":1784090336308}
{"action":"update","arg":{"instType":"SPOT","channel":"books","instId":"BTCUSDT"},"data":[{"asks":[["64818","0.001691"],["64818.72","0"]],"bids":[["64814.48","0.003479"],["64813.7","0"],["64807.61","0"],["64796.3","0.377038"],["64795.78","0"],["64793.69","0.001543"],["64412.83","0.000791"]],"ts":"1784090336408","seq":656732631486,"pseq":656732628511}],"ts":1784090336410}
{"action":"update","arg":{"instType":"SPOT","channel":"trade","instId":"BTCUSDT"},"data":[{"ts":"1784090336455","price":"64815","size":"0.02","side":"sell","tradeId":"1461146262558195712"}],"ts":1784090336456}
{"action":"update","arg":{"instType":"SPOT","channel":"books","instId":"BTCUSDT"},"data":[{"asks":[["64811.24","1.953293"],["64813.49","0"],["64813.99","0"],["64814.49","1.44108"],["64815","0.26"],["64815.01","0.202772"],["64816.08","0.001542"],["64816.56","0"],["64817.57","0"],["64817.58","0.74797"],["64820.64","0.07956"],["64824.6","0"],["64825","0.02"],["64827.57","0"],["64829.97","0"],["64833.95","0"],["64844.87","0"],["65074.77","0.000062"]],"bids":[["64815","0"],["64814.48","0"],["64811.23","0.005108"],["64811.2","0"],["64810.18","0"],["64808.89","0.010855"],["64805.92","0.023707"],["64805.91","0"],["64805.89","0"],["64802.94","0"],["64802.93","0.212128"],["64802.92","0"],["64801.79","0"],["64801.18","0"],["64800.95","0"],["64800","0.761877"],["64799.88","0.001543"],["64798.99","0.012908"],["64796.32","0.030885"],["64796.3","0.59707"],["64795.01","0"],["64790.49","0"],["64783.3","0"],["64780.43","0.001543"],["64771.05","0.01"],["64755.4","0"],["64732.5","0"],["64727.5","0"],["64725.01","0.001544"],["64699.6","0"],["64412.55","0.00001"],["64412.5","0.000981"],["64412","0.000036"],["64411.76","0.000011"],["64411.6","0.000051"],["64411.33","0.002071"],["64411.09","0.000706"],["64410.89","0.00002"],["64410.75","0.000941"],["64410.6","0.000048"],["64410.53","0.000014"]],"ts":"1784090336501","seq":656732634934,"pseq":656732631486}],"ts":1784090336504}
{"action":"update","arg":{"instType":"SPOT","channel":"books","instId":"BTCUSDT"},"data":[{"asks":[["64811.24","1.995707"],["64812.24","0.000772"],["64815.01","0.159586"],["64817.57","0.223774"],["65074.09","0"],["65074.77","0"]],"bids":[["64802.93","0"],["64800.84","0.338207"],["64800.83","0.061707"],["64796.32","0"],["64796.3","0"],["64795.01","0.030885"],["64771.05","0.05"],["64720.3","0"],["64700.53","0.016201"]],"ts":"1784090336611","seq":656732637457,"pseq":656732634934}],"ts":1784090336614}
{"action":"update","arg":{"instType":"SPOT","channel":"books","instId":"BTCUSDT"},"data":[{"asks":[["64815","0"],["64824.11","0.000771"],["64826.42","0"],["64832.89","0.001041"],["64837.35","0"],["65074.09","0.000401"]],"bids":[["64805.92","0.094836"],["64805.01","0.26"],["64800.85","0.061707"],["64800.83","0"],["64796.3","0.60629"],["64792.55","0.025203"],["64764.35","0"],["64763.11","0.154402"],["64656.25","0.000017"],["64410.89","0"],["64410.75","0"],["64410.6","0"],["64410.53","0"]],"ts":"1784090336712","seq":656732639859,"pseq":656732637457}],"ts":1784090336716}
{"action":"update","arg":{"instType":"SPOT","channel":"books","instId":"BTCUSDT"},"data":[{"asks":[["64822.3","0"],["64849.53","0.214877"],["64879.3","0"],["64936.3","0"],["64993.3","0"],["65050.3","0"],["65074.77","0.000062"],["65074.93","0.000016"],["65075","0.02"],["65075.19","0.001206"]],"bids":[["64796.32","0.030885"],["64795.01","0"]],"ts":"1784090336811","seq":656732642336,"pseq":656732639859}],"ts":1784090336814}
{"action":"update","arg":{"instType":"SPOT","channel":"books","instId":"BTCUSDT"},"data":[{"asks":[["64814.49","1.439537"],["64820.2","0.002145"],["64877.2","0.002143"],["64934.2","0.002141"],["64991.2","0.002139"],["65048.2","0.002137"],["65074.09","0"],["65074.77","0"],["65074.93","0"],["65075","0"],["65075.19","0"]],"bids":[["64810.88","0"],["64809.63","0.026248"],["64796.32","0"],["64795.01","0.030885"],["64778","0.000035"],["64777","0.000035"],["64776","0.000035"],["64775","0.020035"],["64774","0.000035"],["64773","0.000035"],["64772","0.000035"],["64771","0.000035"],["64770","0.020035"],["64769","0.000035"],["64768","0.000035"],["64767","0.000035"],["64766","0.000035"],["64765","0.020035"],["64414.41","0"],["64414.32","0"],["64413.31","0"],["64412.83","0"],["64412.55","0"],["64412.5","0"],["64412","0"],["64411.76","0"],["64411.6","0"],["64411.33","0"],["64411.09","0"]],"ts":"1784090336903","seq":656732643984,"pseq":656732642336}],"ts":1784090336906}
{"action":"update","arg":{"instType":"SPOT","channel":"books","instId":"BTCUSDT"},"data":[{"asks":[["64811.77","0.001543"],["64817.22","0.001691"],["64818","0"],["65074.07","0"]],"bids":[],"ts":"1784090337004","seq":656732645646,"pseq":656732643984}],"ts":1784090337006}
{"action":"update","arg":{"instType":"SPOT","channel":"books","instId":"BTCUSDT"},"data":[{"asks":[["64815.01","0.005301"],["64835.61","0.071415"],["64845.32","0.071415"],["64855.04","0.071415"],["64898.05","0.023805"],["64912.96","0"],["64922.69","0"],["64930.13","0"],["65073.53","0"]],"bids":[["64811.23","0.556189"],["64809","0.002145"],["64796.32","0.030885"],["64795.01","0"],["64781.1","0.002146"],["64753.2","0.002147"],["64725.3","0.002148"],["64697.4","0.002149"],["64415.26","0"],["64415","0"],["64414.81","0"],["64414.8","0"],["64414.63","0"]],"ts":"1784090337102","seq":656732647552,"pseq":656732645646}],"ts":1784090337104}
{"action":"update","arg":{"instType":"SPOT","channel":"books","instId":"BTCUSDT"},"data":[{"asks":[["64820.8","0"],["64820.81","0"],["64820.82","0.22145"],["64823.21","0.463262"]],"bids":[["64804.74","0.000771"],["64798.29","0.396398"],["64797.5","0.463262"],["64796.31","0"],["64796.3","0.428278"],["64793.18","0.015829"],["64415.73","0"],["64415.38","0"]],"ts":"1784090337197","seq":656732650659,"pseq":656732647552}],"ts":1784090337209}
{"action":"update","arg":{"instType":"SPOT","channel":"books","instId":"BTCUSDT"},"data":[{"asks":[],"bids":[["64811.23","0.688529"]],"ts":"1784090337237","seq":656732651696,"pseq":656732650659}],"ts":1784090337240}
{"action":"update","arg":{"instType":"SPOT","channel":"books","instId":"BTCUSDT"},"data":[{"asks":[["64811.24","1.995706"]],"bids":[],"ts":"1784090337326","seq":656732653876,"pseq":656732651696}],"ts":1784090337330}
{"action":"update","arg":{"instType":"SPOT","channel":"books","instId":"BTCUSDT"},"data":[{"asks":[],"bids":[["64811.23","0.159402"]],"ts":"1784090337412","seq":656732655420,"pseq":656732653876}],"ts":1784090337414}
{"action":"update","arg":{"instType":"SPOT","channel":"books","instId":"BTCUSDT"},"data":[{"asks":[["64811.24","2.001435"],["64813.56","0.001691"],["64814.48","0.369839"],["64814.49","1.272113"],["64817.22","0"],["64820.04","0.000771"],["64820.62","0.383481"],["64820.63","0.463258"],["64820.82","0.030884"],["64823.19","0"],["64823.21","0"],["64824.11","0"],["64826.11","0.035"],["64829.74","0"],["64830.61","0.001542"],["64830.96","0.001542"],["64838.88","0"],["64869.39","0.042776"],["65072.99","0"],["65073","0"],["65073.13","0"]],"bids":[["64811.23","0.005108"],["64804.74","0"],["64803.71","0"],["64802.92","0"],["64800.85","0"],["64800.01","0.741877"],["64800","0.02"],["64798.61","0"],["64798.29","0.269001"],["64797.5","0"],["64796.32","0"],["64796.31","0"],["64795.01","0.494153"],["64795","0.055"],["64793.69","0"],["64793.64","0.001543"],["64793.18","0"],["64792.55","0.132497"],["64791.22","0"],["64638.5","0"],["64415.73","0.000035"],["64415.38","0.000029"],["64415.26","0.000172"],["64415","0.02"],["64414.81","0.000015"]],"ts":"1784090337501","seq":656732657384,"pseq":656732655420}],"ts":1784090337504}
{"action":"update","arg":{"instType":"SPOT","channel":"books","instId":"BTCUSDT"},"data":[{"asks":[["64811.24","2.011942"],["64815.01","0.159586"],["64820.81","0.030885"],["64820.82","0"],["64823.01","0"],["64849.53","0"],["64888.58","0.012462"],["64894.77","0.023805"],["65072.85","0"]],"bids":[["64809.63","0"],["64809.62","0.026248"],["64800.85","0.061707"],["64796.3","0.560775"],["64795.02","0.46327"],["64795.01","0.030884"],["64792.55","0.025203"],["64415","0"],["64414.81","0"]],"ts":"1784090337609","seq":656732658841,"pseq":656732657384}],"ts":1784090337612}
{"action":"update","arg":{"instType":"SPOT","channel":"books","instId":"BTCUSDT"},"data":[{"asks":[["64820.2","0"],["64877.2","0"],["64934.2","0"],["64991.2","0"],["65048.2","0"],["65072.85","0.000048"],["65072.99","0.000027"],["65073","0.007112"],["65073.13","0.000011"],["65073.53","0.000179"]],"bids":[["64809","0"],["64800.85","0"],["64800.56","0.000322"],["64795.01","0"],["64794.57","0.030885"],["64794.39","0"],["64794.16","0.154268"],["64781.1","0"],["64753.2","0"],["64725.3","0"],["64697.4","0"],["64415","0.02"],["64414.81","0.000015"],["64414.8","0.00003"],["64414.63","0.000779"],["64414.41","0.000326"]],"ts":"1784090337709","seq":656732661458,"pseq":656732658841}],"ts":1784090337712}
{"action":"update","arg":{"instType":"SPOT","channel":"books","instId":"BTCUSDT"},"data":[{"asks":[["64815.01","0.005301"],["64818.7","0.002145"],["64820.81","0"],["64823.01","0.030885"],["64830","0.014309"],["64875.7","0.002143"],["64932.7","0.002141"],["64989.7","0.002139"],["65046.7","0.002137"],["65072.85","0"],["65072.99","0"],["65073","0"],["65073.13","0"],["65073.53","0"]],"bids":[["64811.23","0.566137"],["64807.6","0.002145"],["64800.85","0.061707"],["64800.56","0"],["64779.7","0.002146"],["64751.8","0.002147"],["64723.9","0.002148"],["64696","0.002149"],["64415","0"],["64414.81","0"],["64414.8","0"],["64414.63","0"],["64414.41","0"]],"ts":"1784090337802","seq":656732663895,"pseq":656732661458}],"ts":1784090337806}
{"action":"update","arg":{"instType":"SPOT","channel":"books","instId":"BTCUSDT"},"data":[{"asks":[],"bids":[["64796.31","0.463271"],["64795.02","0"]],"ts":"1784090337904","seq":656732665786,"pseq":656732663895}],"ts":1784090337908}
{"action":"update","arg":{"instType":"SPOT","channel":"books","instId":"BTCUSDT"},"data":[{"asks":[["64828.86","0.185318"],["65072.77","0"]],"bids":[],"ts":"1784090338000","seq":656732667623,"pseq":656732665786}],"ts":1784090338003}
{"action":"update","arg":{"instType":"SPOT","channel":"books","instId":"BTCUSDT"},"data":[{"asks":[["64811.24","2.011942"],["64838.88","0.154399"],["64840.75","0"]],"bids":[["64780.2","0.154399"],["64780.18","0"]],"ts":"1784090338101","seq":656732669362,"pseq":656732667623}],"ts":1784090338104}
{"action":"update","arg":{"instType":"SPOT","channel":"books","instId":"BTCUSDT"},"data":[{"asks":[["64813.86","0.046319"],["64823.02","0"]],"bids":[["64799.8","0.015156"],["64797.49","0"],["64797.2","0.077199"],["64415.26","0"]],"ts":"1784090338208","seq":656732671881,"pseq":656732669362}],"ts":1784090338210}
{"action":"update","arg":{"instType":"SPOT","channel":"books","instId":"BTCUSDT"},"data":[{"asks":[["64822.29","0.077199"],["64854.95","0.154398"],["65072.4","0"],["65072.73","0"]],"bids":[["64811.23","0.159402"],["64810.84","0.026247"],["64809.62","0"],["64805.64","0"],["64805.22","0.046319"]],"ts":"1784090338311","seq":656732673952,"pseq":656732671881}],"ts":1784090338315}
{"action":"update","arg":{"instType":"SPOT","channel":"books","instId":"BTCUSDT"},"data":[{"asks":[],"bids":[["64811.23","0.005108"]],"ts":"1784090338412","seq":656732676483,"pseq":656732673952}],"ts":1784090338416}
{"action":"update","arg":{"instType":"SPOT","channel":"books","instId":"BTCUSDT"},"data":[{"asks":[["64827.58","0.055238"],["65072.16","0"]],"bids":[["64811.23","0.265108"],["64802.92","0.061707"],["64800.85","0"]],"ts":"1784090338516","seq":656732678832,"pseq":656732676483}],"ts":1784090338518}
{"action":"update","arg":{"instType":"SPOT","channel":"books","instId":"BTCUSDT"},"data":[{"asks":[["64811.24","2.166236"],["64822.28","0.030885"],["64823.01","0"],["64835.61","0"],["64845.32","0"],["64855.04","0"],["64894.77","0"],["64898.05","0"],["65072.16","0.011176"],["65072.4","0.001256"],["65072.73","0.000019"],["65072.77","0.000143"],["65072.85","0.000048"]],"bids":[],"ts":"1784090338609","seq":656732680742,"pseq":656732678832}],"ts":1784090338612}
{"action":"update","arg":{"instType":"SPOT","channel":"books","instId":"BTCUSDT"},"data":[{"asks":[["64817.18","0.015688"],["65072.85","0"]],"bids":[["64789.11","0.015185"],["64765.03","0.154398"],["64763.11","0"],["64415.38","0"]],"ts":"1784090338706","seq":656732682551,"pseq":656732680742}],"ts":1784090338708}
{"action":"update","arg":{"instType":"SPOT","channel":"books","instId":"BTCUSDT"},"data":[{"asks":[["64892.69","0.071415"],["65072.77","0"]],"bids":[],"ts":"1784090338817","seq":656732684301,"pseq":656732682551}],"ts":1784090338820}
{"action":"update","arg":{"instType":"SPOT","channel":"books","instId":"BTCUSDT"},"data":[{"asks":[["64811.24","2.166236"],["64832.89","0"],["64849.26","0.462611"],["64849.54","0"],["65072.77","0.000143"]],"bids":[],"ts":"1784090338901","seq":656732685740,"pseq":656732684301}],"ts":1784090338904}
{"action":"update","arg":{"instType":"SPOT","channel":"books","instId":"BTCUSDT"},"data":[{"asks":[["64828.42","0.001041"],["65072.77","0"]],"bids":[["64795.01","0.030885"],["64794.57","0"]],"ts":"1784090339025","seq":656732688092,"pseq":656732685740}],"ts":1784090339028}
{"action":"update","arg":{"instType":"SPOT","channel":"books","instId":"BTCUSDT"},"data":[{"asks":[],"bids":[["64811.23","0.620056"],["64810.84","0"],["64415.38","0.000029"]],"ts":"1784090339107","seq":656732690169,"pseq":656732688092}],"ts":1784090339110}
{"action":"update","arg":{"instType":"SPOT","channel":"books","instId":"BTCUSDT"},"data":[{"asks":[["64832.41","0.071415"],["64842.13","0.071415"],["64851.85","0.071415"],["64892.69","0"],["64894.77","0.023805"],["65048.45","0.215743"],["65072.16","0"],["65072.4","0"],["65072.73","0"]],"bids":[["64811.23","0.031355"],["64803.13","0.000771"],["64802.92","0"],["64800.82","0"],["64415.26","0.000172"]],"ts":"1784090339202","seq":656732694101,"pseq":656732690169}],"ts":1784090339204}
{"action":"update","arg":{"instType":"SPOT","channel":"books","instId":"BTCUSDT"},"data":[{"asks":[["64811.76","0.001196"],["64812.9","0.001691"],["64813.56","0"],["64820.82","0"],["64822.27","0.030885"],["64822.28","0"],["64832.41","0.071415"],["64842.13","0.071415"],["64851.85","0.071415"],["64894.77","0.023805"],["64936.95","0"],["64946.68","0"],["65071.49","0"]],"bids":[["64802.92","0.152084"],["64800.85","0"],["64800.84","0"],["64800.56","0.000322"],["64800.02","0.741877"],["64800.01","0"],["64798.3","0.309116"],["64796.32","0"],["64796.31","0"],["64796.3","0"],["64795.01","0.463272"],["64794.74","0.030885"],["64792.55","0"]],"ts":"1784090339315","seq":656732696298,"pseq":656732694101}],"ts":1784090339318}
{"action":"update","arg":{"instType":"SPOT","channel":"books","instId":"BTCUSDT"},"data":[{"asks":[],"bids":[["64802.92","0.271445"],["64800.56","0.000322"],["64800.03","0"],["64799.8","0"],["64795.02","0.519902"],["64789.11","0"],["64415","0.02"]],"ts":"1784090339412","seq":656732696712,"pseq":656732696298}],"ts":1784090339416}
{"action":"update","arg":{"instType":"SPOT","channel":"books","instId":"BTCUSDT"},"data":[{"asks":[],"bids":[["64811.23","0.428462"],["64800.56","0.000322"],["64800.03","0"],["64765.56","0.107635"],["64415","0"]],"ts":"1784090339523","seq":656732696990,"pseq":656732696712}],"ts":1784090339527}
{"action":"update","arg":{"instType":"SPOT","channel":"books","instId":"BTCUSDT"},"data":[{"asks":[],"bids":[["64811.23","0.031355"],["64803.14","0.000771"],["64800.56","0"],["64800.03","0"],["64796.3","0.46327"],["64795.01","0"]],"ts":"1784090339606","seq":656732697172,"pseq":656732696990}],"ts":1784090339608}
{"action":"update","arg":{"instType":"SPOT","channel":"books","instId":"BTCUSDT"},"data":[{"asks":[["64811.24","2.166236"],["64832.41","0"],["64838.89","0.001581"],["64842.13","0"],["64846.11","0"],["64851.85","0"],["64894.77","0"],["64895.48","0.071415"],["64905.2","0.071415"],["65071.49","0.000008"],["65072.16","0.011176"]],"bids":[["64811.23","0.370628"],["64803.14","0.000771"],["64802.93","0"]],"ts":"1784090339703","seq":656732697439,"pseq":656732697172}],"ts":1784090339707}
{"action":"update","arg":{"instType":"SPOT","channel":"books","instId":"BTCUSDT"},"data":[{"asks":[],"bids":[["64803.14","0.000771"],["64802.93","0"]],"ts":"1784090339814","seq":656732697649,"pseq":656732697439}],"ts":1784090339816}
{"action":"update","arg":{"instType":"SPOT","channel":"books","instId":"BTCUSDT"},"data":[{"asks":[["64832.41","0.071415"],["64842.13","0.071415"],["64851.84","0.071415"],["64894.77","0.023805"],["64895.48","0"],["64905.2","0"],["65071.49","0"],["65072.16","0"]],"bids":[["64811.23","0.344381"],["64811.2","0.026247"],["64803.14","0"],["64802.93","0.061707"],["64415.26","0"]],"ts":"1784090339911","seq":656732698227,"pseq":656732697649}],"ts":1784090339914}
{"action":"update","arg":{"instType":"SPOT","channel":"books","instId":"BTCUSDT"},"data":[{"asks":[],"bids":[["64811.23","0.005108"]],"ts":"1784090340051","seq":656732698478,"pseq":656732698227}],"ts":1784090340054}
{"action":"update","arg":{"instType":"SPOT","channel":"books","instId":"BTCUSDT"},"data":[{"asks":[["64813.86","0"],["64820.39","0.030885"],["64822.27","0"],["64838.88","0"],["64839.74","0.154397"],["65071.49","0.000008"]],"bids":[["64811.2","0"],["64808.98","0.026248"],["64805.92","0"],["64805.02","0.060776"],["64802.93","0"],["64796.3","0"],["64795.03","0.463268"],["64781.78","0.154397"],["64780.2","0"],["64415.26","0.000172"]],"ts":"1784090340100","seq":656732699228,"pseq":656732698478}],"ts":1784090340102}
{"action":"update","arg":{"instType":"SPOT","channel":"books","instId":"BTCUSDT"},"data":[{"asks":[["64811.62","0.015023"],["64811.63","0.046321"],["64811.76","0"],["64812.9","0"],["64832.41","0"],["64842.13","0"],["64851.84","0"],["64894.77","0"],["64901.04","0.071415"],["64910.76","0.071415"],["65072.16","0.011176"],["65072.4","0.001256"]],"bids":[["64805.22","0"],["64803.56","0.046321"],["64800.56","0"],["64800.04","0.061707"],["64800.03","0.741877"],["64800.02","0"],["64797.2","0"],["64795.18","0.077202"],["64795.03","0"],["64794.74","0.463279"],["64794.17","0"],["64793.57","0.030885"],["64792.55","0.141695"],["64415.38","0"],["64415.26","0"]],"ts":"1784090340200","seq":656732701935,"pseq":656732699228}],"ts":1784090340202}
{"action":"update","arg":{"instType":"SPOT","channel":"books","instId":"BTCUSDT"},"data":[{"asks":[["64811.58","0.001691"],["64817.57","0.356635"],["64819.13","0.463281"],["64819.14","0.077203"],["64820.62","0"],["64820.63","0"],["64820.82","0.22145"],["64822.29","0"],["65072.4","0"]],"bids":[["64811.23","0.001629"],["64810.29","0.004157"],["64805.02","0.090097"],["64800.56","0"],["64800.04","0.061707"],["64793.57","0"],["64793.05","0.030885"],["64415.73","0"]],"ts":"1784090340301","seq":656732704707,"pseq":656732701935}],"ts":1784090340304}
{"action":"update","arg":{"instType":"SPOT","channel":"books","instId":"BTCUSDT"},"data":[{"asks":[["64811.24","2.166238"],["64827.58","0.069385"],["64851.57","0.154406"],["64854.95","0"],["64924.6","0.071415"],["65072.16","0"]],"bids":[["64800.56","0.000322"],["64800.04","0"],["64794.74","0"],["64794.17","0.463282"],["64794.16","0"],["64793.57","0.154268"]],"ts":"1784090340408","seq":656732708264,"pseq":656732704707}],"ts":1784090340410}
{"action":"update","arg":{"instType":"SPOT","channel":"trade","instId":"BTCUSDT"},"data":[{"ts":"1784090340429","price":"64811.23","size":"0.000019","side":"sell","tradeId":"1461146279226359808"}],"ts":1784090340431}
{"action":"update","arg":{"instType":"SPOT","channel":"trade","instId":"BTCUSDT"},"data":[{"ts":"1784090340433","price":"64810.28","size":"0.000322","side":"sell","tradeId":"1461146279243137024"}],"ts":1784090340435}
{"action":"update","arg":{"instType":"SPOT","channel":"books","instId":"BTCUSDT"},"data":[{"asks":[["64810.01","2.579042"],["64810.28","0.26"],["64810.29","1.08308"],["64810.3","0"],["64811.23","0"],["64811.24","0.557202"],["64811.62","0"],["64814.49","0.962997"],["64815.01","0"],["64817.56","0.463283"],["64817.57","0"],["64817.58","0.741877"],["64818.26","0.001542"],["64819.12","0.030885"],["64819.13","0"],["64820.39","0"],["64820.64","0"],["64821.78","0.000322"],["64823.22","0.487856"],["64827.58","0"],["64828.6","0"],["64831.22","0.001542"],["64832","0"],["64832.32","0.000322"],["64836.85","0"],["64839.35","0"],["64842.87","0.000322"],["64846.99","0"],["64853.42","0.000322"],["64857.17","0"],["64860.39","0.000028"],["64863.96","0.000322"],["64867.39","0"],["64869.39","0"],["64874.51","0.000322"],["64877.65","0"],["64885.06","0.000322"],["64887.98","0"],["64888.58","0"],["64895.6","0.000322"],["64895.65","0.071415"],["64898.33","0"],["64906.15","0.000322"],["64908.73","0"],["64916.7","0.000322"],["64919.18","0"],["64924.6","0"],["64929.67","0"],["65072.16","0.011176"],["65072.4","0.001256"],["65072.73","0.000019"],["65072.77","0.000143"]],"bids":[["64811.23","0"],["64810.29","0"],["64810.28","0"],["64810","0.021629"],["64809.67","0.004907"],["64808.98","0"],["64808.89","0"],["64808.48","0"],["64808.14","0.004907"],["64807.32","0.026249"],["64807.01","0"],["64806.38","0.01543"],["64802.92","0.066672"],["64802.91","0"],["64802.06","0.001543"],["64801.35","0.211979"],["64800.56","0"],["64800.04","0"],["64800.03","0"],["64799","0.012908"],["64798.66","0.361272"],["64798.65","0.741877"],["64798.29","0"],["64797.95","0"],["64797.22","0"],["64796.68","0.741877"],["64796.49","0.01535"],["64794.17","0"],["64794.15","0"],["64793.05","0.463283"],["64792.56","0.030885"],["64792.55","0.224876"],["64791.14","0.0159"],["64790.49","0.084158"],["64788.08","0"],["64785.86","0.001543"],["64785.8","0.01553"],["64784.2","0"],["64782.34","0.001543"],["64782.09","0.046309"],["64782.02","0.741877"],["64765.56","0"],["64713.05","0"],["64416.21","0"]],"ts":"1784090340504","seq":656732710807,"pseq":656732708264}],"ts":1784090340506}
{"action":"update","arg":{"instType":"SPOT","channel":"books","instId":"BTCUSDT"},"data":[{"asks":[["64810.01","2.580585"],["64811.58","0"],["64811.77","0"],["64816.5","0.000771"],["64817.54","0.463286"],["64817.55","0.393105"],["64817.56","0"],["64819.13","0"],["64820.04","0"],["64823.22","0.732006"],["64823.26","0.035"],["64825.59","0.211979"],["64826.11","0"],["64878.66","0"],["64895.65","0"],["64901.04","0"],["64915.45","0.071415"],["64925.18","0.071415"],["64939.7","0"],["64969.46","0"],["65072.85","0.000048"],["65072.99","0.000027"],["65073","0.007112"]],"bids":[["64810","0.02"],["64805.02","0"],["64803.13","0"],["64802.92","0"],["64801.36","0.069342"],["64799","0"],["64798.68","0.053338"],["64798.67","0.741877"],["64798.66","0"],["64798.65","0"],["64796.29","0"],["64795","0.02"],["64793.64","0"],["64793.57","0"],["64792.57","0.030885"],["64792.56","0"],["64792.55","0.049254"],["64792.15","0.035"],["64791.49","0.030885"],["64791.14","0"],["64790.83","0.000322"],["64790.49","0"],["64790.39","0.084201"],["64787.95","0.001543"],["64786.35","0.483319"],["64678.5","0"],["64416.21","0.000031"],["64415.73","0.000035"],["64415.38","0.000029"],["64415.26","0.000172"]],"ts":"1784090340601","seq":656732719448,"pseq":656732710807}],"ts":1784090340605}
{"action":"update","arg":{"instType":"SPOT","channel":"books","instId":"BTCUSDT"},"data":[{"asks":[["64810.01","2.580733"],["64811.69","0.001543"],["64817.53","0.393106"],["64817.55","0"],["64828.86","0"],["64849.45","0"],["65073.13","0.000011"]],"bids":[["64809.67","0"],["64808.94","0.004907"],["64808.14","0"],["64806.12","0.011618"],["64798.68","0.361272"],["64796.69","0.594102"],["64795.19","0.061707"],["64795.02","0"],["64793.56","0"],["64792.57","0"],["64789.84","0.001543"],["64788.24","0.154268"],["64787.95","0"],["64774.12","0"],["64765.03","0"],["64761.45","0.154408"],["64415","0.02"]],"ts":"1784090340700","seq":656732722644,"pseq":656732719448}],"ts":1784090340702}
{"action":"update","arg":{"instType":"SPOT","channel":"books","instId":"BTCUSDT"},"data":[{"asks":[["64818.7","0"],["64831.53","0.462737"],["64846.68","0.384502"],["64849.26","0"],["64875.7","0"],["64932.7","0"],["64953.44","1.196737"],["64989.7","0"],["65046.7","0"],["65073.53","0.000179"],["65074.07","0.000012"],["65074.09","0.000401"]],"bids":[["64807.6","0"],["64793.05","0.701386"],["64792.55","0"],["64779.7","0"],["64751.8","0"],["64723.9","0"],["64696","0"],["64661.54","1.167396"],["64414.81","0.000015"],["64414.8","0.00003"],["64414.63","0.000779"],["64414.41","0.000326"],["64414.32","0.000039"]],"ts":"1784090340806","seq":656732724686,"pseq":656732722644}],"ts":1784090340808}
{"action":"update","arg":{"instType":"SPOT","channel":"books","instId":"BTCUSDT"},"data":[{"asks":[["64810.01","2.582234"],["64811.24","0.402908"],["64816.7","0.002145"],["64817.57","0"],["64819.11","0"],["64819.12","0"],["64819.13","0.030886"],["64827.23","0.187945"],["64829.92","0.071415"],["64839.64","0.071415"],["64849.36","0.071415"],["64873.7","0.002143"],["64891.92","0.023805"],["64910.76","0"],["64915.45","0"],["64925.18","0"],["64930.7","0.002141"],["64987.7","0.002139"],["65044.7","0.002137"],["65072.85","0"],["65072.99","0"],["65073","0"],["65073.13","0"],["65073.53","0"],["65074.07","0"],["65074.09","0"]],"bids":[["64810","0.174297"],["64805.6","0.002145"],["64805.02","0.063355"],["64787.49","0.179912"],["64777.7","0.002146"],["64768.05","0.355026"],["64749.8","0.002147"],["64721.9","0.002148"],["64694","0.002149"],["64415.38","0"],["64415.26","0"],["64415","0"],["64414.81","0"],["64414.8","0"],["64414.63","0"],["64414.41","0"],["64414.32","0"]],"ts":"1784090340907","seq":656732726651,"pseq":656732724686}],"ts":1784090340910}
{"action":"update","arg":{"instType":"SPOT","channel":"books","instId":"BTCUSDT"},"data":[{"asks":[],"bids":[["64810","0.02"],["64806.12","0"],["64800.56","0"],["64800.01","0.02"],["64795.19","0"],["64415.38","0.000029"]],"ts":"1784090341010","seq":656732728970,"pseq":656732726651}],"ts":1784090341013}
{"action":"update","arg":{"instType":"SPOT","channel":"books","instId":"BTCUSDT"},"data":[{"asks":[["64810.01","2.745537"],["64811.24","0.376659"],["64829.92","0"],["64839.64","0"],["64849.36","0"],["64891.92","0"],["64901.74","0.071415"],["64911.47","0.071415"],["65072.85","0.000048"],["65072.99","0.000027"]],"bids":[["64810","0.024907"],["64800.56","0"],["64800.01","0.02"]],"ts":"1784090341101","seq":656732729945,"pseq":656732728970}],"ts":1784090341104}
{"action":"update","arg":{"instType":"SPOT","channel":"books","instId":"BTCUSDT"},"data":[{"asks":[["64829.92","0.071415"],["64839.64","0.071415"],["64849.36","0.071415"],["64891.92","0.023805"],["64898.46","6.165514"],["64901.74","0"],["64911.47","0"],["65072.77","0"],["65072.85","0"],["65072.99","0"]],"bids":[["64807.32","0"],["64806.45","0.026249"],["64800.56","0"],["64800.01","0"],["64415.26","0.000172"]],"ts":"1784090341217","seq":656732732847,"pseq":656732729945}],"ts":1784090341220}
{"action":"update","arg":{"instType":"SPOT","channel":"books","instId":"BTCUSDT"},"data":[{"asks":[],"bids":[["64800.01","0"],["64795.19","0"]],"ts":"1784090341309","seq":656732734736,"pseq":656732732847}],"ts":1784090341312}
{"action":"update","arg":{"instType":"SPOT","channel":"books","instId":"BTCUSDT"},"data":[{"asks":[["64810.01","2.753217"],["64810.28","0"],["64810.29","1.077304"],["64811.69","0"],["64817.52","0"],["64817.53","0.423991"],["64819.12","0"],["64819.13","0"],["64820.44","0.035"],["64823.26","0"],["64823.92","0.001542"],["64829.92","0"],["64830.61","0"],["64831.53","0"],["64839.64","0"],["64839.74","0"],["64849.36","0"],["64891.92","0"],["64898.06","0.071415"],["64917.51","0.071415"],["65003.27","0"],["65072.77","0.000143"],["65072.85","0.000048"],["65072.99","0.000027"],["65073","0.007112"],["65073.13","0.000011"],["65073.53","0.000179"],["65074.07","0.000012"],["65074.09","0.000401"]],"bids":[["64810","0.02"],["64808.94","0"],["64808.19","0.003726"],["64806.93","0.010572"],["64805.02","0"],["64798.69","0"],["64798.68","0"],["64798.67","0"],["64798.31","0.139822"],["64794.69","0"],["64794.56","0"],["64794.39","0"],["64793.05","0"],["64792.55","0.463292"],["64792.15","0"],["64791.49","0.030885"],["64791.28","0"],["64789.84","0"],["64789.33","0.035"],["64788.81","0.001041"],["64788.24","0"],["64785.85","0.154268"],["64785.14","0"],["64782.16","0.071415"],["64778.17","0.001543"],["64776.62","0.001543"],["64765.7","0.071415"],["64763.71","0"],["64739.13","0.016203"],["64641.43","0"],["64619.85","0.00162"],["64415","0.02"]],"ts":"1784090341392","seq":656732740886,"pseq":656732734736}],"ts":1784090341400}
{"action":"update","arg":{"instType":"SPOT","channel":"books","instId":"BTCUSDT"},"data":[{"asks":[],"bids":[["64791.5","0.030885"],["64415","0"]],"ts":"1784090341410","seq":656732741650,"pseq":656732740886}],"ts":1784090341412}
{"action":"update","arg":{"instType":"SPOT","channel":"books","instId":"BTCUSDT"},"data":[{"asks":[["64810.28","0.448065"],["64812","0.006923"],["64817.53","0.393106"],["64817.57","0.030886"],["64819.13","0"],["64823.22","0.24415"],["64876.71","0.071415"],["64886.54","0.071415"],["64917.51","0"],["65073.13","0"],["65073.53","0"],["65074.07","0"],["65074.09","0"]],"bids":[["64808.19","0"],["64807.98","0"],["64807.46","0.003726"],["64807.16","0"],["64806.93","0"],["64806.62","0"],["64805.01","0"],["64804.84","0.010573"],["64798.33","0.092271"],["64798.32","0.309116"],["64798.31","0"],["64798.3","0"],["64798.28","0"],["64796.71","0.290404"],["64796.7","0.741877"],["64796.69","0"],["64796.68","0"],["64796.49","0"],["64792.55","0"],["64791.5","0"],["64791.49","0.463295"],["64790.4","0.030886"],["64790.01","0.02"],["64785.8","0"],["64784.78","0"],["64778.77","0.777968"],["64777.52","0.001581"],["64740.43","0.1593"],["64415","0.02"],["64414.81","0.000015"],["64414.8","0.00003"]],"ts":"1784090341495","seq":656732747263,"pseq":656732741650}],"ts":1784090341502}
{"action":"update","arg":{"instType":"SPOT","channel":"books","instId":"BTCUSDT"},"data":[{"asks":[["64831.53","0.462737"],["65073","0"]],"bids":[],"ts":"1784090341503","seq":656732747432,"pseq":656732747263}],"ts":1784090341506}
{"action":"update","arg":{"instType":"SPOT","channel":"books","instId":"BTCUSDT"},"data":[{"asks":[["64823.22","0.283821"]],"bids":[["64798.66","0.313721"],["64798.65","0.741877"],["64798.33","0"],["64796.71","0.512345"],["64792.55","0.053019"],["64790.75","0.001543"],["64790.4","0.030886"],["64790.01","0"],["64788.83","0.001543"],["64788.24","0.007327"],["64415.26","0"],["64415","0"],["64414.81","0"],["64414.8","0"]],"ts":"1784090341600","seq":656732749599,"pseq":656732747432}],"ts":1784090341605}
{"action":"update","arg":{"instType":"SPOT","channel":"books","instId":"BTCUSDT"},"data":[{"asks":[["64876.71","0"],["64903.97","0.071415"]],"bids":[["64792.55","0.367529"],["64790.84","0.000322"],["64790.75","0"],["64785.85","0"],["64782.1","0.154268"]],"ts":"1784090341701","seq":656732751581,"pseq":656732749599}],"ts":1784090341704}
{"action":"update","arg":{"instType":"SPOT","channel":"books","instId":"BTCUSDT"},"data":[{"asks":[["64816.7","0"],["64873.7","0"],["64886.54","0"],["64914.2","0.071415"],["64930.7","0"],["64987.7","0"],["65073","0.007112"],["65073.13","0.000011"],["65073.53","0.000179"],["65074.07","0.000012"]],"bids":[["64805.6","0"],["64791.5","0.061707"],["64790.84","0"],["64777.7","0"],["64749.8","0"],["64721.9","0"],["64694","0"],["64415.26","0.000172"],["64415","0.02"],["64414.81","0.000015"],["64414.8","0.00003"],["64414.63","0.000779"]],"ts":"1784090341786","seq":656732753229,"pseq":656732751581}],"ts":1784090341810}
{"action":"update","arg":{"instType":"SPOT","channel":"books","instId":"BTCUSDT"},"data":[{"asks":[["65044.7","0"],["65074.09","0.000401"]],"bids":[],"ts":"1784090341837","seq":656732754027,"pseq":656732753229}],"ts":1784090341840}
{"action":"update","arg":{"instType":"SPOT","channel":"books","instId":"BTCUSDT"},"data":[{"asks":[["64810.01","2.47035"],["64810.27","0"],["64810.28","0"],["64810.29","0.026311"],["64811.24","0.067543"],["64813.26","0.741877"],["64814.48","0"],["64814.49","0.22112"],["64815.33","0.741877"],["64815.36","0.309116"],["64817.53","0.126556"],["64817.57","0"],["64819.27","0.309116"],["64820.82","0"],["64823.22","0"],["64825.59","0"],["64827.22","0.211979"],["65074.77","0.000062"]],"bids":[["64809.8","0.003726"],["64807.47","0"],["64807.46","0"],["64806.46","0.035855"],["64806.45","0"],["64806.22","0.026249"],["64804.84","0"],["64804.2","0.002145"],["64801.37","0.741877"],["64801.36","0"],["64798.66","0.375428"],["64792.55","0.110224"],["64791.5","0"],["64776.3","0.002146"],["64748.4","0.002147"],["64720.5","0.002148"],["64692.6","0.002149"],["64415","0"],["64414.81","0"],["64414.8","0"],["64414.63","0"]],"ts":"1784090341901","seq":656732758692,"pseq":656732754027}],"ts":1784090341904}
{"action":"update","arg":{"instType":"SPOT","channel":"books","instId":"BTCUSDT"},"data":[{"asks":[["64810.01","2.779109"],["64811.23","0.036285"],["64813.25","0.602277"],["64815.3","0.002145"],["64817.17","0.030886"],["64817.53","0.374812"],["64820.82","0.221546"],["64823.22","0.481361"],["64872.3","0.002143"],["64929.3","0.002141"],["64986.3","0.002139"],["65043.3","0.002138"],["65072.73","0"],["65072.77","0"],["65072.85","0"],["65072.99","0"],["65073","0"],["65073.13","0"],["65073.53","0"],["65074.07","0"],["65074.09","0"],["65074.77","0"]],"bids":[["64807.69","0.026249"],["64806.46","0"],["64806.22","0"],["64801.38","0.276923"],["64799","0"],["64798.67","0.061707"],["64798.66","0.313721"],["64796.71","0.549472"],["64792.56","0.463299"],["64792.55","0"],["64791.5","0.030886"],["64791.49","0"],["64790.4","0"],["64788.24","0"],["64415","0.02"]],"ts":"1784090342004","seq":656732761798,"pseq":656732758692}],"ts":1784090342008}
{"action":"update","arg":{"instType":"SPOT","channel":"books","instId":"BTCUSDT"},"data":[{"asks":[["64810.45","0.046322"],["64811.63","0"]],"bids":[["64805.01","0.020898"],["64801.4","0.290792"],["64801.39","0.741877"],["64801.38","0"],["64801.37","0"],["64798.67","0"],["64798.33","0.061707"],["64795.18","0"],["64794.25","0.077203"],["64792.57","0"],["64792.56","0"],["64792.55","0.088054"],["64791.5","0"],["64791.49","0.463294"],["64790.4","0.030886"],["64781.78","0"],["64777.77","0.154407"],["64415.26","0"],["64415","0"]],"ts":"1784090342112","seq":656732762364,"pseq":656732761798}],"ts":1784090342114}
{"action":"update","arg":{"instType":"SPOT","channel":"books","instId":"BTCUSDT"},"data":[{"asks":[["64810.44","0.036286"],["64811.23","0"],["64827.74","0.071415"],["64837.56","0.071415"],["64847.38","0.071415"],["64891.02","0.023805"],["64898.06","0"],["64903.97","0"],["64914.2","0"],["65072.4","0"]],"bids":[["64805.01","0.007071"],["64803.56","0"],["64802.23","0.046322"]],"ts":"1784090342204","seq":656732763109,"pseq":656732762364}],"ts":1784090342206}
{"action":"update","arg":{"instType":"SPOT","channel":"books","instId":"BTCUSDT"},"data":[{"asks":[["64817.17","0"],["64817.54","0"],["64818.45","0"],["64818.46","0.077203"],["64819.14","0"],["64819.26","0.463296"],["64820.39","0.030885"],["64827.74","0"],["64837.56","0"],["64847.38","0"],["64851.57","0"],["64851.71","0.154405"],["64891.02","0"],["64903.76","0.071415"],["64913.59","0.071415"],["65072.4","0.001256"],["65072.73","0.000019"]],"bids":[["64810","0.02"],["64808.27","0.003726"],["64806.39","0.011677"],["64805.01","0"],["64802.24","0.309116"],["64797.02","0.1593"],["64794.39","0"],["64794.26","0.463296"],["64793.05","0.030885"],["64792.55","0.101881"],["64791.49","0"],["64790.4","0"],["64416.21","0"],["64415.73","0"],["64415.38","0"]],"ts":"1784090342303","seq":656732765181,"pseq":656732763109}],"ts":1784090342306}
{"action":"update","arg":{"instType":"SPOT","channel":"books","instId":"BTCUSDT"},"data":[{"asks":[["64810.01","2.760922"],["64812.75","0.001543"],["64831.53","0"]],"bids":[["64810","0.28"],["64809.17","0.026248"],["64807.69","0"],["64801.41","0.061707"],["64798.33","0"],["64794.74","0.030885"],["64793.05","0"],["64790.92","0.001543"],["64788.83","0"]],"ts":"1784090342403","seq":656732769426,"pseq":656732765181}],"ts":1784090342406}
{"action":"update","arg":{"instType":"SPOT","channel":"books","instId":"BTCUSDT"},"data":[{"asks":[["64832.43","0.462731"],["65072.73","0"]],"bids":[["64713.05","0.000322"],["64416.67","0"]],"ts":"1784090342504","seq":656732772071,"pseq":656732769426}],"ts":1784090342508}
{"action":"update","arg":{"instType":"SPOT","channel":"books","instId":"BTCUSDT"},"data":[{"asks":[["64810.01","2.760921"]],"bids":[["64794.33","0.015756"],["64783.63","0.015683"],["64417.11","0"],["64416.77","0"]],"ts":"1784090342610","seq":656732773884,"pseq":656732772071}],"ts":1784090342614}
{"action":"update","arg":{"instType":"SPOT","channel":"books","instId":"BTCUSDT"},"data":[{"asks":[],"bids":[["64802.25","0.26"],["64764.79","0.154401"],["64761.45","0"],["64417.65","0"]],"ts":"1784090342721","seq":656732775859,"pseq":656732773884}],"ts":1784090342726}
{"action":"update","arg":{"instType":"SPOT","channel":"books","instId":"BTCUSDT"},"data":[{"asks":[["64903.76","0"],["64923.42","0.071415"],["64928.64","0.071415"],["65072.4","0"]],"bids":[],"ts":"1784090342804","seq":656732777560,"pseq":656732775859}],"ts":1784090342808}
{"action":"update","arg":{"instType":"SPOT","channel":"books","instId":"BTCUSDT"},"data":[{"asks":[["64812.75","0"],["64814.86","0.001543"],["64820.39","0"],["64820.81","0.030886"],["64898.91","0.071415"],["64913.87","4.332523"],["64928.64","0"],["65072.16","0"]],"bids":[["64794.74","0"],["64794.27","0.030886"],["64793.02","0.001543"],["64790.92","0"]],"ts":"1784090342902","seq":656732779473,"pseq":656732777560}],"ts":1784090342906}
{"action":"update","arg":{"instType":"SPOT","channel":"books","instId":"BTCUSDT"},"data":[{"asks":[["64898.91","0"],["64934.77","0.071415"]],"bids":[["64541.4","0.000017"],["64418.23","0"]],"ts":"1784090343004","seq":656732781522,"pseq":656732779473}],"ts":1784090343008}
{"action":"update","arg":{"instType":"SPOT","channel":"books","instId":"BTCUSDT"},"data":[{"asks":[["64819.26","0"],["64820.8","0.369053"],["64820.81","0.494159"],["64820.82","0"],["64823.22","0"],["64826.23","0.071415"],["64835.95","0.071415"],["64845.67","0.071415"],["64891.02","0.023805"],["64913.59","0"],["64923.42","0"],["64934.77","0"],["65072.16","0.011176"]],"bids":[["64810","0.41234"],["64809.66","0.026248"],["64809.17","0"],["64794.73","0.772763"],["64794.27","0"],["64763.87","1.877338"],["64719.81","1.070418"],["64715.9","0"],["64690.69","0"],["64418.23","0.000022"]],"ts":"1784090343103","seq":656732783601,"pseq":656732781522}],"ts":1784090343108}
{"action":"update","arg":{"instType":"SPOT","channel":"books","instId":"BTCUSDT"},"data":[{"asks":[["64823.22","0.333853"],["65072.16","0"]],"bids":[],"ts":"1784090343220","seq":656732785693,"pseq":656732783601}],"ts":1784090343222}
{"action":"update","arg":{"instType":"SPOT","channel":"books","instId":"BTCUSDT"},"data":[{"asks":[["64810.01","2.699101"],["64819.26","0.463273"],["64820.78","0.369053"],["64820.79","0"],["64820.8","0"],["64820.81","0.030886"],["64826.23","0"],["64835.95","0"],["64845.67","0"],["64891.02","0"],["64913.15","0.071415"],["64922.98","0.071415"],["64924.7","0"],["64944.16","0"],["64953.25","0"],["65072.16","0.011176"]],"bids":[["64797.52","0.000771"],["64794.73","0.741877"],["64794.39","0.030886"],["64418.54","0"],["64418.23","0"]],"ts":"1784090343303","seq":656732787303,"pseq":656732785693}],"ts":1784090343306}
{"action":"update","arg":{"instType":"SPOT","channel":"books","instId":"BTCUSDT"},"data":[{"asks":[["64810.01","2.699101"],["64820.39","0.030886"],["64820.78","0.230766"],["64820.81","0"],["64823.22","0.472102"],["64836.86","0.154401"],["65072.16","0"]],"bids":[["64794.74","0.463274"],["64794.26","0"]],"ts":"1784090343400","seq":656732788684,"pseq":656732787303}],"ts":1784090343403}
{"action":"update","arg":{"instType":"SPOT","channel":"books","instId":"BTCUSDT"},"data":[{"asks":[["64827.74","0.071415"],["64837.56","0.071415"],["64847.38","0.071415"],["64891.02","0.023805"],["64913.15","0"],["64922.98","0"],["65071.14","0"],["65071.49","0"]],"bids":[["64764","0.000035"],["64763.87","0"],["64763","0.000035"],["64762","0.000035"],["64761","0.000035"],["64720.47","1.878598"],["64719.81","0"],["64698.44","1.070772"],["64420","0"],["64419.3","0"],["64418.97","0"],["64418.6","0"]],"ts":"1784090343512","seq":656732789980,"pseq":656732788684}],"ts":1784090343514}
{"action":"update","arg":{"instType":"SPOT","channel":"books","instId":"BTCUSDT"},"data":[{"asks":[["64827.74","0"],["64837.56","0"],["64847.38","0"],["64891.02","0"],["64898.91","0.071415"],["64908.74","0.071415"],["65071.14","0.000056"],["65071.49","0.000008"]],"bids":[],"ts":"1784090343607","seq":656732790957,"pseq":656732789980}],"ts":1784090343610}
{"action":"update","arg":{"instType":"SPOT","channel":"books","instId":"BTCUSDT"},"data":[{"asks":[["64898.91","0.071415"],["64908.74","0.071415"],["64918.58","0.071415"],["64933.16","0"],["64942.99","0"],["64952.83","0"],["65071.49","0"]],"bids":[["64810","0.02"],["64794.39","0"],["64794.26","0.030886"],["64793.05","0"]],"ts":"1784090343718","seq":656732791415,"pseq":656732790957}],"ts":1784090343722}
{"action":"update","arg":{"instType":"SPOT","channel":"books","instId":"BTCUSDT"},"data":[{"asks":[["64898.91","0"],["64908.74","0"],["64918.58","0"],["64933.57","0.071415"],["64943.41","0.071415"],["64953.24","0.071415"]],"bids":[["64794.34","0.030886"],["64794.26","0"],["64793.05","0"]],"ts":"1784090343801","seq":656732791685,"pseq":656732791415}],"ts":1784090343804}
{"action":"update","arg":{"instType":"SPOT","channel":"books","instId":"BTCUSDT"},"data":[{"asks":[["64827.73","0.071415"],["64837.55","0.071415"],["64847.37","0.071415"],["64891.02","0.023805"],["64933.57","0"],["64943.41","0"],["64953.24","0"],["65071.14","0"]],"bids":[["64809.66","0"],["64808.69","0.026248"]],"ts":"1784090343926","seq":656732791934,"pseq":656732791685}],"ts":1784090343928}
{"action":"update","arg":{"instType":"SPOT","channel":"books","instId":"BTCUSDT"},"data":[{"asks":[],"bids":[["64790.32","0.015715"],["64780.33","0.154402"],["64777.77","0"],["64420.13","0"]],"ts":"1784090344005","seq":656732792093,"pseq":656732791934}],"ts":1784090344008}
{"action":"update","arg":{"instType":"SPOT","channel":"books","instId":"BTCUSDT"},"data":[{"asks":[["64810.01","2.699101"],["64810.44","0.033414"],["64810.45","0"],["64812.51","0.04632"],["64823.22","0"],["64827.73","0"],["64837.55","0"],["64847.37","0"],["64891.02","0"],["64912.58","0.071415"],["64922.41","0.071415"],["65071.14","0.000056"],["65071.49","0.000008"],["65072.16","0.011176"]],"bids":[["64806.39","0.02401"],["64804.45","0.04632"],["64802.23","0"],["64796.58","0.077201"],["64794.25","0"]],"ts":"1784090344102","seq":656732792760,"pseq":656732792093}],"ts":1784090344105}
{"action":"update","arg":{"instType":"SPOT","channel":"books","instId":"BTCUSDT"},"data":[{"asks":[["64810.01","2.700644"],["64814.86","0"],["64823.22","0.474974"],["64912.58","0"],["64913.07","0.000667"],["64916.58","0"],["64945.3","0.071415"]],"bids":[["64797.41","0.001543"],["64793.02","0"],["64728.88","0"],["64712.7","0.000667"]],"ts":"1784090344213","seq":656732792959,"pseq":656732792760}],"ts":1784090344216}
{"action":"update","arg":{"instType":"SPOT","channel":"books","instId":"BTCUSDT"},"data":[{"asks":[["64818.46","0"],["64820.38","0.077201"]],"bids":[],"ts":"1784090344300","seq":656732793141,"pseq":656732792959}],"ts":1784090344304}
{"action":"update","arg":{"instType":"SPOT","channel":"books","instId":"BTCUSDT"},"data":[{"asks":[["64851.71","0"],["64852.22","0.154402"]],"bids":[["64810","0.28"],["64801.09","0.001543"],["64797.41","0"]],"ts":"1784090344424","seq":656732793316,"pseq":656732793141}],"ts":1784090344428}
{"action":"update","arg":{"instType":"SPOT","channel":"books","instId":"BTCUSDT"},"data":[{"asks":[["64819.26","0"],["64820.36","0.407195"],["64820.37","0.463274"],["64820.39","0"],["64820.77","0.030886"],["64820.78","0"],["64823.22","0"],["65072.4","0.001256"]],"bids":[["64794.75","0.030886"],["64794.34","0"]],"ts":"1784090344507","seq":656732793797,"pseq":656732793316}],"ts":1784090344510}
{"action":"update","arg":{"instType":"SPOT","channel":"books","instId":"BTCUSDT"},"data":[{"asks":[["64823.22","0.298545"],["64922.41","0"],["64932.24","0.071415"],["64950.04","0.071415"],["65072.16","0"],["65072.4","0"]],"bids":[],"ts":"1784090344604","seq":656732794337,"pseq":656732793797}],"ts":1784090344609}
{"action":"update","arg":{"instType":"SPOT","channel":"books","instId":"BTCUSDT"},"data":[{"asks":[["64819.26","0.463272"],["64820.36","0"],["64820.37","0.030886"],["64820.77","0"],["64820.82","0.221546"]],"bids":[["64809.54","0.026248"],["64808.69","0"],["64794.75","0"],["64794.39","0.030886"],["64764.86","0.154402"],["64764.79","0"]],"ts":"1784090344715","seq":656732795907,"pseq":656732794337}],"ts":1784090344718}
{"action":"update","arg":{"instType":"SPOT","channel":"books","instId":"BTCUSDT"},"data":[{"asks":[["64820.37","0"],["64820.81","0.030886"],["64823.22","0"],["65072.16","0.011176"]],"bids":[["64810","0.41234"],["64794.75","0.030886"],["64794.39","0"],["64720.47","0"],["64698.44","0"],["64420.13","0.000186"],["64420","0.020102"]],"ts":"1784090344809","seq":656732797796,"pseq":656732795907}],"ts":1784090344812}
{"action":"update","arg":{"instType":"SPOT","channel":"books","instId":"BTCUSDT"},"data":[{"asks":[["64810.01","2.700644"],["64814.27","0.001542"],["64818.26","0"],["64820.37","0.030885"],["64820.81","0"],["64823.22","0.484194"],["65072.16","0"]],"bids":[["64799.88","0"],["64798.07","0.001543"],["64794.75","0"],["64794.39","0.030885"],["64780.43","0"],["64778.62","0.001543"],["64755.45","1.877582"],["64711.39","1.070558"],["64420.13","0"],["64420","0"]],"ts":"1784090344920","seq":656732800341,"pseq":656732797796}],"ts":1784090344922}
{"action":"update","arg":{"instType":"SPOT","channel":"books","instId":"BTCUSDT"},"data":[{"asks":[["64815.3","0"],["64819.26","0"],["64820.37","0.463273"],["64820.81","0.030885"],["64820.82","0"],["64823.22","0"],["64872.3","0"],["64929.3","0"],["64986.3","0"],["65043.3","0"],["65072.16","0.011176"],["65072.4","0.001256"],["65072.73","0.000019"],["65072.77","0.000143"],["65072.85","0.000048"],["65072.99","0.000027"],["65073","0.007112"]],"bids":[["64804.2","0"],["64776.3","0"],["64748.4","0"],["64720.5","0"],["64692.6","0"],["64420.13","0.000186"],["64420","0.020102"],["64419.3","0.000156"],["64418.97","0.002351"],["64418.6","0.000015"]],"ts":"1784090345006","seq":656732802270,"pseq":656732800341}],"ts":1784090345008}
{"action":"update","arg":{"instType":"SPOT","channel":"books","instId":"BTCUSDT"},"data":[{"asks":[["64820.36","0.407195"],["64823.22","0"],["64832.43","0"],["64847.44","0.462624"],["64909.43","0.071415"],["64919.26","0.071415"],["64945.3","0"],["64950.04","0"],["65073","0"]],"bids":[],"ts":"1784090345103","seq":656732804532,"pseq":656732802270}],"ts":1784090345106}
{"action":"update","arg":{"instType":"SPOT","channel":"books","instId":"BTCUSDT"},"data":[{"asks":[["64823.22","0.298545"],["64909.43","0"],["64919.26","0"],["64934.98","0.071415"],["64944.81","0.071415"],["65072.99","0"]],"bids":[],"ts":"1784090345186","seq":656732806664,"pseq":656732804532}],"ts":1784090345201}
{"action":"update","arg":{"instType":"SPOT","channel":"books","instId":"BTCUSDT"},"data":[{"asks":[["64819.26","0.463271"],["64820.37","0"]],"bids":[],"ts":"1784090345204","seq":656732807030,"pseq":656732806664}],"ts":1784090345208}
{"action":"update","arg":{"instType":"SPOT","channel":"books","instId":"BTCUSDT"},"data":[{"asks":[["64815.3","0.002145"],["64820.36","0"],["64820.82","0.221546"],["64823.22","0"],["64872.3","0.002143"],["64929.3","0.002141"],["64986.3","0.002139"],["65043.3","0.002138"],["65072.4","0"],["65072.73","0"],["65072.77","0"],["65072.85","0"]],"bids":[["64804.2","0.002145"],["64776.3","0.002146"],["64748.4","0.002147"],["64720.5","0.002148"],["64692.6","0.002149"],["64420.13","0"],["64420","0"],["64419.3","0"],["64418.97","0"],["64418.6","0"]],"ts":"1784090345297","seq":656732809036,"pseq":656732807030}],"ts":1784090345305}
{"action":"update","arg":{"instType":"SPOT","channel":"books","instId":"BTCUSDT"},"data":[{"asks":[["64835.76","0.154402"],["64836.86","0"]],"bids":[],"ts":"1784090345311","seq":656732809302,"pseq":656732809036}],"ts":1784090345314}
{"action":"update","arg":{"instType":"SPOT","channel":"books","instId":"BTCUSDT"},"data":[{"asks":[["64823.22","0.484194"],["65072.16","0"]],"bids":[["64809.54","0"],["64809.08","0.026248"]],"ts":"1784090345398","seq":656732810885,"pseq":656732809302}],"ts":1784090345407}
{"action":"update","arg":{"instType":"SPOT","channel":"books","instId":"BTCUSDT"},"data":[{"asks":[["64827.73","0.071415"],["64837.55","0.071415"],["64847.37","0.071415"],["64891.02","0.023805"],["64932.24","0"],["64934.98","0"],["64944.81","0"],["65071.49","0"]],"bids":[],"ts":"1784090345531","seq":656732812841,"pseq":656732810885}],"ts":1784090345534}
{"action":"update","arg":{"instType":"SPOT","channel":"books","instId":"BTCUSDT"},"data":[{"asks":[["64810.01","2.700644"]],"bids":[],"ts":"1784090345649","seq":656732814446,"pseq":656732812841}],"ts":1784090345652}
{"action":"update","arg":{"instType":"SPOT","channel":"books","instId":"BTCUSDT"},"data":[{"asks":[["64827.73","0"],["64837.55","0"],["64847.37","0"],["64891.02","0"],["65071.49","0.000008"],["65072.16","0.011176"],["65072.4","0.001256"],["65072.73","0.000019"]],"bids":[],"ts":"1784090345717","seq":656732815211,"pseq":656732814446}],"ts":1784090345720}
{"action":"update","arg":{"instType":"SPOT","channel":"books","instId":"BTCUSDT"},"data":[{"asks":[["64820.37","0.030885"],["64820.81","0"],["64920.98","0"],["64930.81","0.071415"],["65072.73","0"]],"bids":[],"ts":"1784090345805","seq":656732816108,"pseq":656732815211}],"ts":1784090345808}
{"action":"update","arg":{"instType":"SPOT","channel":"books","instId":"BTCUSDT"},"data":[{"asks":[["64819.26","0"],["64820.37","0.463273"],["64820.4","0"],["64820.81","0.030885"],["64820.82","0"],["64823.22","0"],["64945.87","0.071415"],["65072.73","0.000019"],["65072.77","0.000143"]],"bids":[["64794.75","0.030885"],["64794.39","0"]],"ts":"1784090345909","seq":656732817614,"pseq":656732816108}],"ts":1784090345912}
{"action":"update","arg":{"instType":"SPOT","channel":"books","instId":"BTCUSDT"},"data":[{"asks":[["64812.31","0.04632"],["64812.51","0"],["64820.36","0.402545"],["64823.22","0"],["64827.73","0"],["64837.55","0"],["64847.37","0"],["64891.02","0"],["64930.81","0"],["64940.2","0.071415"],["64945.87","0"],["64950.04","0.071415"],["65072.77","0"]],"bids":[["64795.01","0.030885"],["64794.75","0"],["64780.79","0.154401"],["64780.33","0"]],"ts":"1784090346000","seq":656732819493,"pseq":656732817614}],"ts":1784090346004}
{"action":"update","arg":{"instType":"SPOT","channel":"books","instId":"BTCUSDT"},"data":[{"asks":[["64819.26","0.463271"],["64820.36","0"],["64820.37","0"],["64820.8","0.030885"],["64820.81","0"],["65072.77","0.000143"]],"bids":[["64806.39","0.025503"],["64804.45","0"],["64804.43","0.04632"],["64796.66","0.0772"],["64796.58","0"],["64795.01","0"],["64794.75","0.030885"],["64794.39","0"]],"ts":"1784090346100","seq":656732821212,"pseq":656732819493}],"ts":1784090346104}
{"action":"update","arg":{"instType":"SPOT","channel":"books","instId":"BTCUSDT"},"data":[{"asks":[["64810.01","2.706757"],["64815.4","0.015733"],["64819.25","0.463272"],["64819.26","0"],["64820.37","0.030885"],["64820.8","0"],["64827.73","0.071415"],["64837.55","0.071415"],["64847.37","0.071415"],["64891.02","0.023805"],["64940.2","0"],["64950.04","0"],["65072.4","0"],["65072.73","0"],["65072.77","0"]],"bids":[["64810","0.28"],["64809.43","0.026248"],["64809.08","0"],["64802.24","0"],["64801.41","0"],["64801.4","0"],["64801.39","0"],["64801.36","0.061707"],["64794.75","0"],["64794.39","0"],["64793.05","0.030885"],["64755.45","0"],["64720.49","1.878597"],["64711.39","0"],["64698.47","1.070771"],["64420.13","0.000186"],["64420","0.020102"],["64419.3","0.000156"]],"ts":"1784090346204","seq":656732824278,"pseq":656732821212}],"ts":1784090346206}
{"action":"update","arg":{"instType":"SPOT","channel":"books","instId":"BTCUSDT"},"data":[{"asks":[["64818.78","0.077202"],["64820.38","0"],["64846.67","0.274184"],["65072.16","0"]],"bids":[["64802.26","0.696859"],["64801.38","0.061707"],["64801.37","0.741877"],["64801.36","0"],["64798.66","0.064295"],["64796.71","0"],["64794.39","0"],["64794.34","0.030885"],["64793.06","0"],["64793.05","0"],["64792.55","0"]],"ts":"1784090346307","seq":656732828471,"pseq":656732824278}],"ts":1784090346310}
{"action":"update","arg":{"instType":"SPOT","channel":"books","instId":"BTCUSDT"},"data":[{"asks":[["64827.73","0"],["64837.55","0"],["64847.37","0"],["64850.67","0.154403"],["64852.22","0"],["64891.02","0"],["65072.16","0.011176"],["65072.4","0.001256"],["65072.73","0.000019"],["65072.77","0.000143"]],"bids":[["64810","0.02"],["64806.39","0.099853"],["64803.71","0.26"],["64802.25","0"],["64798.66","0.353743"],["64796.71","0.421637"],["64794.34","0.030885"],["64793.05","0"],["64419.3","0"]],"ts":"1784090346416","seq":656732830616,"pseq":656732828471}],"ts":1784090346418}
{"action":"update","arg":{"instType":"SPOT","channel":"books","instId":"BTCUSDT"},"data":[{"asks":[["64810.01","2.706757"],["64869.39","0.116797"],["64888.58","0.016471"],["64928.9","0.071415"],["64948.57","0.071415"],["65072.16","0"],["65072.4","0"],["65072.73","0"],["65072.77","0"]],"bids":[],"ts":"1784090346501","seq":656732833270,"pseq":656732830616}],"ts":1784090346504}
{"action":"update","arg":{"instType":"SPOT","channel":"books","instId":"BTCUSDT"},"data":[{"asks":[["64827.73","0.071415"],["64837.55","0.071415"],["64847.37","0.071415"],["64891.02","0.023805"],["64913.86","0.298288"],["64928.9","0"],["64948.57","0"],["65070.94","0"],["65071.14","0"],["65071.49","0"]],"bids":[["64794.34","0.030885"],["64793.05","0"]],"ts":"1784090346613","seq":656732835737,"pseq":656732833270}],"ts":1784090346616}
{"action":"update","arg":{"instType":"SPOT","channel":"books","instId":"BTCUSDT"},"data":[{"asks":[],"bids":[["64794.34","0"],["64793.05","0.030885"]],"ts":"1784090346709","seq":656732837690,"pseq":656732835737}],"ts":1784090346712}
{"action":"update","arg":{"instType":"SPOT","channel":"books","instId":"BTCUSDT"},"data":[{"asks":[["65000.17","0.00162"],["65018.32","0"]],"bids":[["64764.86","0"],["64764.7","0.154403"]],"ts":"1784090346806","seq":656732839705,"pseq":656732837690}],"ts":1784090346810}
{"action":"update","arg":{"instType":"SPOT","channel":"books","instId":"BTCUSDT"},"data":[{"asks":[["64827.73","0"],["64837.55","0"],["64847.37","0"],["64891.02","0"],["64929.83","0.071415"],["64939.66","0.071415"],["65070.94","0.1593"],["65071.14","0.000056"]],"bids":[["64809.43","0"],["64808.85","0.026248"]],"ts":"1784090346917","seq":656732841970,"pseq":656732839705}],"ts":1784090346920}
{"action":"update","arg":{"instType":"SPOT","channel":"books","instId":"BTCUSDT"},"data":[{"asks":[["64817.52","0.463276"],["64818.77","0.030885"],["64819.25","0"],["64820.37","0"],["64820.82","0.221546"],["64823.22","0.101961"],["64913.86","0"],["64944.81","0.071415"],["65070.94","0"],["65071.14","0"]],"bids":[["64809.8","0"],["64808.85","0"],["64806.6","0.026249"],["64806.39","0"],["64806.24","0.010138"],["64804.44","0"],["64802.26","0"],["64801.38","0"],["64801.37","0"],["64801.36","0.069899"],["64800.56","0"],["64800.01","0"],["64798.65","0"],["64798.32","0"],["64796.72","0.741877"],["64796.71","0.040761"],["64796.7","0"],["64794.74","0"],["64794.73","0"],["64793.47","0.741877"],["64793.06","0"],["64793.05","0.463276"],["64792.55","0.030885"],["64419.3","0.000156"],["64418.97","0.002351"],["64418.6","0.000015"],["64418.54","0.000012"],["64418.23","0.000022"]],"ts":"1784090347000","seq":656732847710,"pseq":656732841970}],"ts":1784090347002}
{"action":"update","arg":{"instType":"SPOT","channel":"books","instId":"BTCUSDT"},"data":[{"asks":[["64823.22","0"],["64846.67","0"],["64869.39","0"],["64888.58","0"],["65070.94","0.1593"],["65071.14","0.000056"],["65071.49","0.000008"],["65072.16","0.011176"]],"bids":[["64804.44","0.092537"],["64801.09","0"],["64799","0"],["64798.92","0.001543"],["64798.67","0.061707"],["64798.66","0.132293"],["64797.03","0.309116"],["64796.73","0.227192"],["64796.71","0"],["64418.6","0"],["64418.54","0"],["64418.23","0"]],"ts":"1784090347124","seq":656732850852,"pseq":656732847710}],"ts":1784090347126}
{"action":"update","arg":{"instType":"SPOT","channel":"books","instId":"BTCUSDT"},"data":[{"asks":[["64810.01","2.706758"],["64823.22","0.484194"],["65072.16","0"]],"bids":[["64800.01","0"],["64799","0.012908"],["64798.67","0"],["64793.48","0.741055"],["64494.36","0.00026"],["64419.3","0"],["64418.97","0"]],"ts":"1784090347201","seq":656732852122,"pseq":656732850852}],"ts":1784090347204}
{"action":"update","arg":{"instType":"SPOT","channel":"books","instId":"BTCUSDT"},"data":[{"asks":[],"bids":[["64800.01","0"],["64799","0.012908"],["64431.5","0.000265"],["64420","0"]],"ts":"1784090347304","seq":656732855362,"pseq":656732852122}],"ts":1784090347306}
{"action":"update","arg":{"instType":"SPOT","channel":"books","instId":"BTCUSDT"},"data":[{"asks":[["64833.36","0.154407"],["64835.76","0"],["64867.72","0.000017"],["65071.49","0"]],"bids":[["64800.01","0"],["64799","0.012908"]],"ts":"1784090347415","seq":656732857415,"pseq":656732855362}],"ts":1784090347418}
{"action":"update","arg":{"instType":"SPOT","channel":"books","instId":"BTCUSDT"},"data":[{"asks":[["64827.63","0.001542"],["64830.96","0"],["64903.69","0.071415"],["64913.52","0.071415"],["64939.66","0"],["64944.81","0"]],"bids":[["64800.01","0"],["64799","0.012908"]],"ts":"1784090347512","seq":656732859975,"pseq":656732857415}],"ts":1784090347514}
{"action":"update","arg":{"instType":"SPOT","channel":"books","instId":"BTCUSDT"},"data":[{"asks":[["64903.69","0"],["64913.52","0"],["64928.49","0.071415"],["64938.33","0.071415"]],"bids":[["64800.01","0"],["64799","0.012908"],["64792.55","0.030886"],["64791.49","0"]],"ts":"1784090347610","seq":656732862509,"pseq":656732859975}],"ts":1784090347614}
{"action":"update","arg":{"instType":"SPOT","channel":"books","instId":"BTCUSDT"},"data":[{"asks":[],"bids":[["64807.51","0.026249"],["64806.6","0"],["64800.01","0"],["64799","0.012908"]],"ts":"1784090347706","seq":656732864852,"pseq":656732862509}],"ts":1784090347710}
{"action":"update","arg":{"instType":"SPOT","channel":"books","instId":"BTCUSDT"},"data":[{"asks":[["64827.73","0.071415"],["64837.55","0.071415"],["64847.37","0.071415"],["64891.02","0.023805"],["64928.49","0"],["64929.83","0"],["64938.33","0"],["65071.14","0"]],"bids":[["64800.01","0.02"],["64799","0"],["64557.22","0.000266"],["64494.36","0.000526"],["64431.5","0.000531"],["64420.13","0"]],"ts":"1784090347803","seq":656732867464,"pseq":656732864852}],"ts":1784090347806}
{"action":"update","arg":{"instType":"SPOT","channel":"books","instId":"BTCUSDT"},"data":[{"asks":[["64810.01","2.706758"],["64827.73","0"],["64837.55","0"],["64847.37","0"],["64891.02","0"],["64919.58","0.071415"],["64929.41","0.071415"],["65071.14","0.000056"],["65071.49","0.000008"]],"bids":[["64800.01","0"],["64799","0.012908"]],"ts":"1784090347903","seq":656732869525,"pseq":656732867464}],"ts":1784090347906}
{"action":"update","arg":{"instType":"SPOT","channel":"books","instId":"BTCUSDT"},"data":[{"asks":[["64810.15","0.057966"],["64810.16","0.046321"],["64810.44","0"],["64812.31","0"]],"bids":[["64804.43","0"],["64802.36","0.046321"],["64800.01","0"],["64799","0.012908"],["64780.79","0"],["64778.96","0.154406"]],"ts":"1784090348004","seq":656732871670,"pseq":656732869525}],"ts":1784090348008}
pong
{"action":"update","arg":{"instType":"SPOT","channel":"books","instId":"BTCUSDT"},"data":[{"asks":[["64941.44","0.071415"],["65071.49","0"]],"bids":[["64800.01","0"],["64799","0.012908"],["64796.66","0"],["64794.58","0.077203"]],"ts":"1784090348121","seq":656732873889,"pseq":656732871670}],"ts":1784090348124}
{"action":"update","arg":{"instType":"SPOT","channel":"books","instId":"BTCUSDT"},"data":[{"asks":[],"bids":[["64800.01","0.02"],["64799","0"]],"ts":"1784090348204","seq":656732876120,"pseq":656732873889}],"ts":1784090348208}
{"action":"update","arg":{"instType":"SPOT","channel":"books","instId":"BTCUSDT"},"data":[{"asks":[["64815.3","0"],["64817.77","0.077203"],["64818.76","0.030886"],["64818.77","0"],["64818.78","0"],["64819.26","0"],["64872.3","0"],["64929.3","0"],["64986.3","0"],["65043.3","0"],["65071.49","0.000008"],["65072.16","0.011176"],["65072.4","0.001256"],["65072.73","0.000019"],["65072.77","0.000143"]],"bids":[["64804.2","0"],["64800.01","0"],["64799","0.012908"],["64776.3","0"],["64748.4","0"],["64720.5","0"],["64692.6","0"],["64420.13","0.000186"],["64420","0.020102"],["64419.3","0.000156"],["64418.97","0.002351"],["64418.6","0.000015"]],"ts":"1784090348301","seq":656732877742,"pseq":656732876120}],"ts":1784090348304}
{"action":"update","arg":{"instType":"SPOT","channel":"books","instId":"BTCUSDT"},"data":[{"asks":[["64818.74","0"],["64818.75","0"],["64818.76","0"],["64819.26","0.030886"],["64848.99","0.154406"],["64850.67","0"]],"bids":[["64807.51","0"],["64807.39","0.026249"],["64800.01","0"],["64799","0.012908"]],"ts":"1784090348410","seq":656732879763,"pseq":656732877742}],"ts":1784090348412}
{"action":"update","arg":{"instType":"SPOT","channel":"books","instId":"BTCUSDT"},"data":[{"asks":[["64815.4","0.017878"],["64872.4","0.002143"],["64929.4","0.002141"],["64986.4","0.002139"],["65043.4","0.002138"],["65072.16","0"],["65072.4","0"],["65072.73","0"],["65072.77","0"]],"bids":[["64804.2","0.002145"],["64800.01","0"],["64799","0.012908"],["64792.55","0.030886"],["64791.49","0"],["64776.3","0.002146"],["64748.4","0.002147"],["64720.5","0.002148"],["64692.6","0.002149"],["64420.13","0"],["64420","0"],["64419.3","0"],["64418.97","0"],["64418.6","0"]],"ts":"1784090348509","seq":656732881724,"pseq":656732879763}],"ts":1784090348512}
{"action":"update","arg":{"instType":"SPOT","channel":"books","instId":"BTCUSDT"},"data":[{"asks":[["64810.01","2.706758"]],"bids":[["64800.01","0"],["64799","0.012908"]],"ts":"1784090348620","seq":656732883761,"pseq":656732881724}],"ts":1784090348622}
{"action":"update","arg":{"instType":"SPOT","channel":"books","instId":"BTCUSDT"},"data":[{"asks":[],"bids":[["64800.01","0"],["64799","0.012908"]],"ts":"1784090348702","seq":656732885338,"pseq":656732883761}],"ts":1784090348704}
{"action":"update","arg":{"instType":"SPOT","channel":"books","instId":"BTCUSDT"},"data":[{"asks":[],"bids":[["64800.01","0"],["64799","0.012908"],["64764.7","0"],["64763.52","0.154406"]],"ts":"1784090348827","seq":656732886971,"pseq":656732885338}],"ts":1784090348830}
{"action":"update","arg":{"instType":"SPOT","channel":"books","instId":"BTCUSDT"},"data":[{"asks":[["64827.73","0.071415"],["64837.55","0.071415"],["64847.37","0.071415"],["64891.02","0.023805"],["64919.58","0"],["64929.41","0"],["64941.44","0"],["65071.49","0"]],"bids":[["64800.01","0"],["64799","0.012908"]],"ts":"1784090348910","seq":656732887794,"pseq":656732886971}],"ts":1784090348914}
{"action":"update","arg":{"instType":"SPOT","channel":"books","instId":"BTCUSDT"},"data":[{"asks":[],"bids":[["64800.01","0"],["64799","0.012908"]],"ts":"1784090349007","seq":656732888841,"pseq":656732887794}],"ts":1784090349010}
{"action":"update","arg":{"instType":"SPOT","channel":"books","instId":"BTCUSDT"},"data":[{"asks":[],"bids":[["64807.41","0.026249"],["64807.39","0"],["64800.01","0"],["64799","0.012908"]],"ts":"1784090349106","seq":656732890150,"pseq":656732888841}],"ts":1784090349110}
{"action":"update","arg":{"instType":"SPOT","channel":"books","instId":"BTCUSDT"},"data":[{"asks":[],"bids":[["64800.01","0"],["64799","0.012908"],["64792.55","0"],["64791.49","0.030886"]],"ts":"1784090349201","seq":656732891416,"pseq":656732890150}],"ts":1784090349204}
{"action":"update","arg":{"instType":"SPOT","channel":"books","instId":"BTCUSDT"},"data":[{"asks":[],"bids":[["64800.01","0"],["64799","0.012908"]],"ts":"1784090349326","seq":656732893208,"pseq":656732891416}],"ts":1784090349330}
{"action":"update","arg":{"instType":"SPOT","channel":"books","instId":"BTCUSDT"},"data":[{"asks":[["64810.01","2.706758"],["64833.36","0"],["65071.49","0.000008"]],"bids":[["64800.01","0.02"],["64799","0"]],"ts":"1784090349403","seq":656732894526,"pseq":656732893208}],"ts":1784090349406}
{"action":"update","arg":{"instType":"SPOT","channel":"books","instId":"BTCUSDT"},"data":[{"asks":[["64827.73","0"],["64837.55","0"],["64847.37","0"],["64891.02","0"],["65072.16","0.011176"],["65072.4","0.001256"],["65072.73","0.000019"],["65072.77","0.000143"]],"bids":[],"ts":"1784090349609","seq":656732898509,"pseq":656732894526}],"ts":1784090349612}
{"action":"update","arg":{"instType":"SPOT","channel":"books","instId":"BTCUSDT"},"data":[{"asks":[["64924.32","0"],["64934.15","0"],["64946.22","0.071415"],["64956.05","0.071415"],["64965.89","0.071415"],["65072.4","0"],["65072.73","0"],["65072.77","0"]],"bids":[["64800.01","0"],["64799","0.012908"],["64792.55","0.030886"],["64791.49","0"]],"ts":"1784090349713","seq":656732900757,"pseq":656732898509}],"ts":1784090349716}
{"action":"update","arg":{"instType":"SPOT","channel":"books","instId":"BTCUSDT"},"data":[{"asks":[["64827.73","0.071415"],["64837.55","0.071415"],["64847.37","0.071415"],["64891.02","0.023805"],["64946.22","0"],["64956.05","0"],["64965.89","0"],["65072.16","0"]],"bids":[["64800.01","0.02"],["64799","0"],["64792.55","0"],["64791.49","0.030886"]],"ts":"1784090349806","seq":656732902245,"pseq":656732900757}],"ts":1784090349808}
{"action":"update","arg":{"instType":"SPOT","channel":"books","instId":"BTCUSDT"},"data":[{"asks":[["64810.01","2.75308"],["64810.15","0.030312"],["64810.16","0"],["65072.16","0.011176"]],"bids":[["64807.41","0"],["64806.39","0.026249"],["64800.01","0.02"],["64799","0"]],"ts":"1784090349907","seq":656732902976,"pseq":656732902245}],"ts":1784090349910}
{"action":"update","arg":{"instType":"SPOT","channel":"books","instId":"BTCUSDT"},"data":[{"asks":[["64823.22","0.487296"]],"bids":[["64809.04","0.004894"],["64808.27","0"],["64802.36","0"],["64801.43","0.046322"],["64800.01","0.02"],["64799","0"],["64794.58","0"],["64794.44","0.077204"],["64793.48","0.741055"],["64793.06","0.463288"],["64793.05","0"],["64778.96","0"],["64778.2","0.154409"]],"ts":"1784090350004","seq":656732904092,"pseq":656732902976}],"ts":1784090350008}
{"action":"update","arg":{"instType":"SPOT","channel":"books","instId":"BTCUSDT"},"data":[{"asks":[["64810.01","2.75308"]],"bids":[["64800.01","0.02"],["64799","0"],["64793.48","1.204343"],["64793.06","0"],["64420.13","0.000186"]],"ts":"1784090350115","seq":656732905091,"pseq":656732904092}],"ts":1784090350118}
{"action":"update","arg":{"instType":"SPOT","channel":"books","instId":"BTCUSDT"},"data":[{"asks":[],"bids":[["64800.01","0.02"],["64799","0"],["64793.48","1.204343"],["64793.05","0"]],"ts":"1784090350212","seq":656732905728,"pseq":656732905091}],"ts":1784090350214}
{"action":"update","arg":{"instType":"SPOT","channel":"books","instId":"BTCUSDT"},"data":[{"asks":[["64817.77","0"],["64817.92","0.077203"],["64827.73","0"],["64837.55","0"],["64847.37","0"],["64848.93","0.154407"],["64848.99","0"],["64891.02","0"],["64901.89","0.071415"],["64911.72","0.071415"],["65072.4","0.001256"],["65072.73","0.000019"]],"bids":[["64800.56","0.000322"],["64800.01","0"],["64799","0"],["64792.55","0.030886"],["64791.49","0"]],"ts":"1784090350310","seq":656732908059,"pseq":656732905728}],"ts":1784090350313}
{"action":"update","arg":{"instType":"SPOT","channel":"books","instId":"BTCUSDT"},"data":[{"asks":[["64827.73","0.071415"],["64837.55","0.071415"],["64847.37","0.071415"],["64891.02","0.023805"],["64901.89","0"],["64911.72","0"],["65072.4","0"],["65072.73","0"]],"bids":[["64800.56","0.000322"],["64800.01","0"]],"ts":"1784090350406","seq":656732910267,"pseq":656732908059}],"ts":1784090350408}
{"action":"update","arg":{"instType":"SPOT","channel":"books","instId":"BTCUSDT"},"data":[{"asks":[],"bids":[["64800.56","0.000322"],["64800.01","0"]],"ts":"1784090350503","seq":656732912095,"pseq":656732910267}],"ts":1784090350506}
{"action":"update","arg":{"instType":"SPOT","channel":"books","instId":"BTCUSDT"},"data":[{"asks":[],"bids":[["64800.56","0.000322"],["64800.01","0"]],"ts":"1784090350613","seq":656732913102,"pseq":656732912095}],"ts":1784090350618}
{"action":"update","arg":{"instType":"SPOT","channel":"books","instId":"BTCUSDT"},"data":[{"asks":[],"bids":[["64807.67","0.026249"],["64806.39","0"],["64800.56","0"],["64800.01","0"],["64792.55","0"],["64791.49","0.030886"],["64420","0.020102"]],"ts":"1784090350700","seq":656732915413,"pseq":656732913102}],"ts":1784090350704}
{"action":"update","arg":{"instType":"SPOT","channel":"books","instId":"BTCUSDT"},"data":[{"asks":[["64827.73","0"],["64837.55","0"],["64847.37","0"],["64891.02","0"],["65072.4","0.001256"],["65072.73","0.000019"],["65072.77","0.000143"],["65072.85","0.000048"]],"bids":[["64800.01","0"],["64799","0.012908"],["64793.48","0.741055"],["64793.05","0.463288"],["64764.02","0.154407"],["64763.52","0"],["64420.13","0"],["64420","0"]],"ts":"1784090350820","seq":656732917939,"pseq":656732915413}],"ts":1784090350822}
{"action":"update","arg":{"instType":"SPOT","channel":"books","instId":"BTCUSDT"},"data":[{"asks":[["64917.65","0.071434"],["64927.38","0.071415"],["65072.85","0"]],"bids":[["64799","0.012908"],["64798.93","0"]],"ts":"1784090350904","seq":656732919466,"pseq":656732917939}],"ts":1784090350906}
{"action":"update","arg":{"instType":"SPOT","channel":"books","instId":"BTCUSDT"},"data":[{"asks":[["64810.01","2.75308"]],"bids":[["64799","0.012908"],["64798.93","0"]],"ts":"1784090350987","seq":656732920923,"pseq":656732919466}],"ts":1784090351001}
{"action":"update","arg":{"instType":"SPOT","channel":"books","instId":"BTCUSDT"},"data":[{"asks":[],"bids":[["64799","0"],["64798.93","0.001543"]],"ts":"1784090351005","seq":656732921191,"pseq":656732920923}],"ts":1784090351008}
{"action":"update","arg":{"instType":"SPOT","channel":"books","instId":"BTCUSDT"},"data":[{"asks":[],"bids":[["64799","0.012908"],["64798.93","0"]],"ts":"1784090351084","seq":656732923367,"pseq":656732921191}],"ts":1784090351103}
{"action":"update","arg":{"instType":"SPOT","channel":"books","instId":"BTCUSDT"},"data":[{"asks":[["64939.99","0.071415"],["65072.77","0"]],"bids":[],"ts":"1784090351136","seq":656732924385,"pseq":656732923367}],"ts":1784090351138}
{"action":"update","arg":{"instType":"SPOT","channel":"books","instId":"BTCUSDT"},"data":[{"asks":[],"bids":[["64800.01","0.02"],["64799","0"]],"ts":"1784090351195","seq":656732926201,"pseq":656732924385}],"ts":1784090351204}
{"action":"update","arg":{"instType":"SPOT","channel":"books","instId":"BTCUSDT"},"data":[{"asks":[],"bids":[["64800.01","0"],["64799","0.012908"]],"ts":"1784090351213","seq":656732926880,"pseq":656732926201}],"ts":1784090351216}
{"action":"update","arg":{"instType":"SPOT","channel":"books","instId":"BTCUSDT"},"data":[{"asks":[],"bids":[["64800.01","0.02"],["64799","0"]],"ts":"1784090351292","seq":656732928945,"pseq":656732926880}],"ts":1784090351305}
{"action":"update","arg":{"instType":"SPOT","channel":"books","instId":"BTCUSDT"},"data":[{"asks":[["64906.05","0.071415"],["64939.99","0"]],"bids":[],"ts":"1784090351316","seq":656732929465,"pseq":656732928945}],"ts":1784090351320}
{"action":"update","arg":{"instType":"SPOT","channel":"books","instId":"BTCUSDT"},"data":[{"asks":[["64832.8","0.154409"],["65072.73","0"]],"bids":[["64800.01","0.02"],["64799","0"],["64780.78","0.003086"],["64778.17","0"],["64776.62","0"],["64420.13","0.000186"]],"ts":"1784090351404","seq":656732931219,"pseq":656732929465}],"ts":1784090351406}
{"action":"update","arg":{"instType":"SPOT","channel":"books","instId":"BTCUSDT"},"data":[{"asks":[["64810.01","2.706758"],["64815.4","0.015733"],["64817.91","0.030886"],["64819.26","0"],["64827.73","0.071415"],["64837.55","0.071415"],["64847.37","0.071415"],["64872.4","0"],["64891.02","0.023805"],["64906.05","0"],["64917.65","0.000019"],["64927.38","0"],["64929.4","0"],["64986.4","0"],["65043.4","0"],["65072.73","0.000019"],["65072.77","0.000143"]],"bids":[["64810","0.046247"],["64807.67","0"],["64806.71","0.046319"],["64804.2","0"],["64801.43","0"],["64800.01","0.02"],["64799","0"],["64776.3","0"],["64748.4","0"],["64720.5","0"],["64692.6","0"],["64420","0.020102"],["64419.3","0.000156"],["64418.97","0.002351"],["64418.6","0.000015"],["64418.54","0.000012"],["64418.23","0.000022"]],"ts":"1784090351499","seq":656732933187,"pseq":656732931219}],"ts":1784090351514}
{"action":"update","arg":{"instType":"SPOT","channel":"books","instId":"BTCUSDT"},"data":[{"asks":[["64817.91","0"],["64819.26","0.030886"]],"bids":[],"ts":"1784090351523","seq":656732933514,"pseq":656732933187}],"ts":1784090351526}
{"action":"update","arg":{"instType":"SPOT","channel":"books","instId":"BTCUSDT"},"data":[{"asks":[["64839.65","0.626634"],["64857.66","0"],["64992.07","0.000017"],["65072.77","0"]],"bids":[["64800.01","0.02"],["64799","0"],["64793.49","0.463288"],["64793.05","0"]],"ts":"1784090351610","seq":656732935995,"pseq":656732933514}],"ts":1784090351612}
{"action":"update","arg":{"instType":"SPOT","channel":"books","instId":"BTCUSDT"},"data":[{"asks":[],"bids":[["64800.01","0.02"],["64799","0"]],"ts":"1784090351707","seq":656732937827,"pseq":656732935995}],"ts":1784090351710}
{"action":"update","arg":{"instType":"SPOT","channel":"books","instId":"BTCUSDT"},"data":[{"asks":[["64810.01","2.706757"],["64810.71","0.04632"],["64815.4","0.017878"],["64872.4","0.002143"],["64929.4","0.002141"],["64986.4","0.002139"],["65043.4","0.002138"],["65071.14","0"],["65071.49","0"],["65072.16","0"],["65072.4","0"],["65072.73","0"]],"bids":[["64810","0.02"],["64808.34","0.026248"],["64806.71","0"],["64804.2","0.002145"],["64803.38","0.04632"],["64800.01","0.02"],["64799","0"],["64776.3","0.002146"],["64748.4","0.002147"],["64720.5","0.002148"],["64692.6","0.002149"],["64420","0"],["64419.3","0"],["64418.97","0"],["64418.6","0"],["64418.54","0"],["64418.23","0"]],"ts":"1784090351806","seq":656732939693,"pseq":656732937827}],"ts":1784090351808}
{"action":"update","arg":{"instType":"SPOT","channel":"books","instId":"BTCUSDT"},"data":[{"asks":[],"bids":[["64800.01","0.02"],["64799","0"],["64779.27","0.154405"],["64778.2","0"]],"ts":"1784090351901","seq":656732941133,"pseq":656732939693}],"ts":1784090351904}
{"action":"update","arg":{"instType":"SPOT","channel":"books","instId":"BTCUSDT"},"data":[{"asks":[["64827.73","0"],["64837.55","0"],["64847.37","0"],["64891.02","0"],["64921.77","0.071415"],["64931.6","0.071415"],["64953.44","0"],["65071.14","0.000056"],["65071.49","0.000008"],["65072.16","0.011176"]],"bids":[["64808.34","0"],["64806.87","0.026249"],["64800.01","0.02"],["64799","0"],["64661.54","0"],["64420","0.020102"]],"ts":"1784090352002","seq":656732942968,"pseq":656732941133}],"ts":1784090352004}
{"action":"update","arg":{"instType":"SPOT","channel":"books","instId":"BTCUSDT"},"data":[{"asks":[],"bids":[["64800.01","0.02"],["64799","0"],["64794.44","0"],["64794.21","0.077203"]],"ts":"1784090352109","seq":656732945300,"pseq":656732942968}],"ts":1784090352112}
{"action":"update","arg":{"instType":"SPOT","channel":"books","instId":"BTCUSDT"},"data":[{"asks":[["64950.21","1.199388"],["65072.16","0"]],"bids":[["64800.01","0.02"],["64799","0"],["64662.03","1.229597"],["64420","0"]],"ts":"1784090352205","seq":656732947559,"pseq":656732945300}],"ts":1784090352208}
{"action":"update","arg":{"instType":"SPOT","channel":"books","instId":"BTCUSDT"},"data":[{"asks":[["64816.9","0.077203"],["64817.92","0"],["64847.64","0.154406"],["64848.93","0"]],"bids":[["64800.01","0.02"],["64799","0"]],"ts":"1784090352317","seq":656732949818,"pseq":656732947559}],"ts":1784090352320}
{"action":"update","arg":{"instType":"SPOT","channel":"books","instId":"BTCUSDT"},"data":[{"asks":[["64816.89","0.463288"],["64817.52","0"],["64827.23","0"],["64846.68","0"],["65072.16","0.011176"],["65072.4","0.001256"]],"bids":[["64800.01","0.02"],["64799","0"],["64787.49","0"],["64768.05","0"],["64420","0.020102"],["64419.3","0.000156"]],"ts":"1784090352407","seq":656732951700,"pseq":656732949818}],"ts":1784090352410}
{"action":"update","arg":{"instType":"SPOT","channel":"books","instId":"BTCUSDT"},"data":[{"asks":[["64810.01","2.706758"],["64827.73","0.071415"],["64837.55","0.071415"],["64847.37","0.071415"],["64891.02","0.023805"],["64921.77","0"],["64931.6","0"],["65072.16","0"],["65072.4","0"]],"bids":[["64800.01","0.02"],["64799","0"],["64768.77","0.36111"],["64419.3","0"]],"ts":"1784090352518","seq":656732954511,"pseq":656732951700}],"ts":1784090352520}
{"action":"update","arg":{"instType":"SPOT","channel":"books","instId":"BTCUSDT"},"data":[{"asks":[["64824.03","0.18594"],["64843.47","0.37287"],["65071.14","0"],["65071.49","0"]],"bids":[["64800.01","0.02"],["64799","0"],["64788.21","0.17945"],["64714.91","0.000017"],["64420.13","0"],["64420","0"]],"ts":"1784090352607","seq":656732956570,"pseq":656732954511}],"ts":1784090352610}
{"action":"update","arg":{"instType":"SPOT","channel":"books","instId":"BTCUSDT"},"data":[{"asks":[],"bids":[["64800.01","0.02"],["64799","0"]],"ts":"1784090352704","seq":656732958798,"pseq":656732956570}],"ts":1784090352706}
{"action":"update","arg":{"instType":"SPOT","channel":"books","instId":"BTCUSDT"},"data":[{"asks":[["64827.73","0"],["64837.55","0"],["64847.37","0"],["64891.02","0"],["64915.88","0.071415"],["64925.71","0.071415"],["65071.14","0.000056"],["65071.49","0.000008"]],"bids":[["64806.87","0"],["64806.45","0.026249"],["64800.01","0"],["64799","0.012908"],["64764.02","0"],["64763.17","0.154407"]],"ts":"1784090352803","seq":656732961652,"pseq":656732958798}],"ts":1784090352806}
{"action":"update","arg":{"instType":"SPOT","channel":"books","instId":"BTCUSDT"},"data":[{"asks":[],"bids":[["64800.01","0.02"],["64799","0"]],"ts":"1784090352906","seq":656732965907,"pseq":656732961652}],"ts":1784090352908}
{"action":"update","arg":{"instType":"SPOT","channel":"books","instId":"BTCUSDT"},"data":[{"asks":[],"bids":[["64809.04","0"],["64808.22","0.004912"],["64800.01","0"],["64799","0"],["64798.93","0.001543"],["64792.55","0"],["64791.5","0.030886"],["64791.49","0"]],"ts":"1784090353009","seq":656732970572,"pseq":656732965907}],"ts":1784090353012}
{"action":"update","arg":{"instType":"SPOT","channel":"books","instId":"BTCUSDT"},"data":[{"asks":[["64931.02","0.071415"],["65071.49","0"]],"bids":[["64799","0"],["64798.93","0.001543"],["64793.49","0"],["64793.05","0.463288"]],"ts":"1784090353106","seq":656732972317,"pseq":656732970572}],"ts":1784090353108}
{"action":"update","arg":{"instType":"SPOT","channel":"books","instId":"BTCUSDT"},"data":[{"asks":[],"bids":[["64799","0"],["64798.93","0.001543"]],"ts":"1784090353202","seq":656732972643,"pseq":656732972317}],"ts":1784090353206}
{"action":"update","arg":{"instType":"SPOT","channel":"books","instId":"BTCUSDT"},"data":[{"asks":[["64810.01","2.706758"],["64830.92","0.154408"],["64832.8","0"]],"bids":[["64799","0"],["64798.93","0.001543"]],"ts":"1784090353300","seq":656732972936,"pseq":656732972643}],"ts":1784090353302}
{"action":"update","arg":{"instType":"SPOT","channel":"books","instId":"BTCUSDT"},"data":[{"asks":[],"bids":[["64799","0"],["64798.93","0.001543"]],"ts":"1784090353410","seq":656732974449,"pseq":656732972936}],"ts":1784090353412}
{"action":"update","arg":{"instType":"SPOT","channel":"books","instId":"BTCUSDT"},"data":[{"asks":[["64915.88","0"],["64925.71","0"],["64944.76","0.071415"],["64954.6","0.071415"]],"bids":[["64806.45","0"],["64805.86","0.026249"],["64799","0"],["64798.93","0.001543"]],"ts":"1784090353521","seq":656732976058,"pseq":656732974449}],"ts":1784090353524}
{"action":"update","arg":{"instType":"SPOT","channel":"books","instId":"BTCUSDT"},"data":[{"asks":[],"bids":[["64799","0.012908"],["64798.93","0"]],"ts":"1784090353604","seq":656732977098,"pseq":656732976058}],"ts":1784090353608}
{"action":"update","arg":{"instType":"SPOT","channel":"books","instId":"BTCUSDT"},"data":[{"asks":[],"bids":[["64799","0.012908"],["64798.93","0"]],"ts":"1784090353701","seq":656732978171,"pseq":656732977098}],"ts":1784090353704}
{"action":"update","arg":{"instType":"SPOT","channel":"books","instId":"BTCUSDT"},"data":[{"asks":[["64907.68","0"],["64917.51","0.071415"],["64932.79","0.071415"],["64944.76","0"],["64954.6","0"]],"bids":[["64799","0.012908"],["64798.93","0"],["64793.49","0.463288"],["64793.05","0"]],"ts":"1784090353814","seq":656732980101,"pseq":656732978171}],"ts":1784090353816}
{"action":"update","arg":{"instType":"SPOT","channel":"books","instId":"BTCUSDT"},"data":[{"asks":[["64810.01","2.75308"],["64810.71","0"],["64827.73","0.071415"],["64837.55","0.071415"],["64847.37","0.071415"],["64891.02","0.023805"],["64917.51","0"],["64931.02","0"],["64932.79","0"]],"bids":[["64803.38","0"],["64799","0.012908"],["64798.93","0"],["64779.27","0"],["64778.22","0.154408"],["64420.13","0.000186"]],"ts":"1784090353904","seq":656732981641,"pseq":656732980101}],"ts":1784090353909}
{"action":"update","arg":{"instType":"SPOT","channel":"books","instId":"BTCUSDT"},"data":[{"asks":[["64810.01","2.75308"]],"bids":[["64799","0.012908"],["64798.93","0"],["64794.21","0"],["64793.35","0.077204"]],"ts":"1784090354004","seq":656732983112,"pseq":656732981641}],"ts":1784090354008}
{"action":"update","arg":{"instType":"SPOT","channel":"books","instId":"BTCUSDT"},"data":[{"asks":[],"bids":[["64799","0.012908"],["64798.93","0"]],"ts":"1784090354103","seq":656732984535,"pseq":656732983112}],"ts":1784090354106}
{"action":"update","arg":{"instType":"SPOT","channel":"books","instId":"BTCUSDT"},"data":[{"asks":[["64827.73","0"],["64837.55","0"],["64847.37","0"],["64891.02","0"],["64925.45","0.071415"],["64930.9","0.071415"],["65071.49","0.000008"],["65072.16","0.011176"]],"bids":[["64805.86","0"],["64805.38","0.026249"],["64799","0"],["64798.93","0"],["64420","0.020102"]],"ts":"1784090354213","seq":656732984901,"pseq":656732984535}],"ts":1784090354217}
{"action":"update","arg":{"instType":"SPOT","channel":"books","instId":"BTCUSDT"},"data":[{"asks":[["64816.89","0"],["64816.9","0"],["64817.52","0.463293"],["64817.57","0.030886"],["64819.26","0"],["65072.4","0.001256"]],"bids":[["64798.08","0"],["64797.53","0.000771"],["64793.49","0"],["64793.05","0"],["64792.55","0.463288"],["64420","0"]],"ts":"1784090354311","seq":656732985203,"pseq":656732984901}],"ts":1784090354314}
{"action":"update","arg":{"instType":"SPOT","channel":"books","instId":"BTCUSDT"},"data":[{"asks":[["64827.73","0.071415"],["64837.55","0.071415"],["64847.37","0.071415"],["64847.64","0"],["64891.02","0.023805"],["64925.45","0"],["64930.9","0"],["65072.4","0"]],"bids":[["64798.67","0"],["64798.08","0"],["64797.53","0"],["64420","0.020102"]],"ts":"1784090354407","seq":656732985730,"pseq":656732985203}],"ts":1784090354410}
{"action":"update","arg":{"instType":"SPOT","channel":"books","instId":"BTCUSDT"},"data":[{"asks":[["64827.73","0"],["64837.55","0"],["64847.37","0"],["64891.02","0"],["64911.36","0.071415"],["64931.02","0.071415"],["65072.4","0.001256"],["65072.73","0.000019"]],"bids":[["64798.08","0.001543"],["64797.53","0"],["64420","0"]],"ts":"1784090354515","seq":656732987022,"pseq":656732985730}],"ts":1784090354518}
{"action":"update","arg":{"instType":"SPOT","channel":"books","instId":"BTCUSDT"},"data":[{"asks":[["64827.73","0.071415"],["64837.55","0.071415"],["64847.37","0.071415"],["64891.02","0.023805"],["64911.36","0"],["64931.02","0"],["65072.4","0"],["65072.73","0"]],"bids":[["64798.08","0.001543"],["64797.53","0"]],"ts":"1784090354601","seq":656732987596,"pseq":656732987022}],"ts":1784090354604}
{"action":"update","arg":{"instType":"SPOT","channel":"books","instId":"BTCUSDT"},"data":[{"asks":[["64810.01","2.75308"],["64827.73","0"],["64837.55","0"],["64847.37","0"],["64891.02","0"],["65072.4","0.001256"],["65072.73","0.000019"],["65072.77","0.000143"],["65072.85","0.000048"]],"bids":[["64798.67","0.061707"],["64798.08","0"]],"ts":"1784090354716","seq":656732988047,"pseq":656732987596}],"ts":1784090354718}
{"action":"update","arg":{"instType":"SPOT","channel":"books","instId":"BTCUSDT"},"data":[{"asks":[["64815.4","0.015733"],["64872.4","0"],["64921.19","0.071415"],["64929.4","0"],["64931.02","0.071415"],["64986.4","0"],["65043.4","0"],["65072.99","0.000027"],["65073","0.007112"]],"bids":[["64804.2","0"],["64799","0.012908"],["64798.69","0.320476"],["64798.68","0.741877"],["64798.67","0"],["64798.66","0"],["64793.48","0.552872"],["64776.3","0"],["64763.17","0"],["64762.22","0.15441"],["64748.4","0"],["64720.5","0"],["64692.6","0"],["64420","0.020102"],["64419.3","0.000156"],["64418.97","0.002351"],["64418.6","0.000015"]],"ts":"1784090354808","seq":656732988233,"pseq":656732988047}],"ts":1784090354812}
{"action":"update","arg":{"instType":"SPOT","channel":"books","instId":"BTCUSDT"},"data":[{"asks":[],"bids":[["64799","0.012908"],["64798.93","0"]],"ts":"1784090354905","seq":656732988350,"pseq":656732988233}],"ts":1784090354909}
{"action":"update","arg":{"instType":"SPOT","channel":"books","instId":"BTCUSDT"},"data":[{"asks":[],"bids":[["64805.38","0"],["64805.06","0.026249"],["64799","0"],["64798.93","0.001543"]],"ts":"1784090355004","seq":656732988545,"pseq":656732988350}],"ts":1784090355008}
{"action":"update","arg":{"instType":"SPOT","channel":"books","instId":"BTCUSDT"},"data":[{"asks":[["64815.2","0.002145"],["64817.52","0.494179"],["64817.57","0"],["64819.26","0"],["64872.2","0.002143"],["64929.2","0.002141"],["64986.2","0.002139"],["65043.2","0.002138"],["65072.77","0"],["65072.85","0"],["65072.99","0"],["65073","0"]],"bids":[["64804.1","0.002145"],["64801.38","0.161613"],["64801.37","0.309116"],["64801.36","0"],["64799","0"],["64798.93","0.001543"],["64793.48","0.461158"],["64776.2","0.002146"],["64748.3","0.002147"],["64720.4","0.002148"],["64692.5","0.002149"],["64420.92","0"],["64420.13","0"],["64420","0"],["64419.3","0"],["64418.97","0"],["64418.6","0"]],"ts":"1784090355113","seq":656732989012,"pseq":656732988545}],"ts":1784090355116}
{"action":"update","arg":{"instType":"SPOT","channel":"books","instId":"BTCUSDT"},"data":[{"asks":[["64817.52","0.463293"],["64819.26","0.030886"],["64911.36","0.071415"],["65072.4","0"],["65072.73","0"]],"bids":[["64799","0"],["64798.93","0.001543"],["64793.05","0.46329"],["64792.55","0"]],"ts":"1784090355224","seq":656732989324,"pseq":656732989012}],"ts":1784090355228}
{"action":"update","arg":{"instType":"SPOT","channel":"books","instId":"BTCUSDT"},"data":[{"asks":[["64829.66","0.154409"],["64830.92","0"],["64896.92","0.071415"],["64931.02","0"]],"bids":[["64799","0"],["64798.93","0.001543"]],"ts":"1784090355307","seq":656732989608,"pseq":656732989324}],"ts":1784090355310}
{"action":"update","arg":{"instType":"SPOT","channel":"books","instId":"BTCUSDT"},"data":[{"asks":[["64817.57","0.030886"],["64819.26","0"],["64827.73","0.071415"],["64837.55","0.071415"],["64847.37","0.071415"],["64891.02","0.023805"],["64896.92","0"],["64911.36","0"],["64921.19","0"],["65072.16","0"]],"bids":[["64799","0"],["64798.93","0.001543"]],"ts":"1784090355404","seq":656732990098,"pseq":656732989608}],"ts":1784090355406}
{"action":"update","arg":{"instType":"SPOT","channel":"books","instId":"BTCUSDT"},"data":[{"asks":[["64810.01","2.75308"]],"bids":[["64799","0"],["64798.93","0.001543"]],"ts":"1784090355506","seq":656732990632,"pseq":656732990098}],"ts":1784090355510}
{"action":"update","arg":{"instType":"SPOT","channel":"books","instId":"BTCUSDT"},"data":[{"asks":[["64827.73","0"],["64837.55","0"],["64847.37","0"],["64891.02","0"],["64900.47","0.071415"],["64910.3","0.071415"],["65072.16","0.011176"],["65072.4","0.001256"]],"bids":[["64799","0"],["64798.93","0.001543"],["64793.05","0"],["64792.55","0.463291"]],"ts":"1784090355600","seq":656732990924,"pseq":656732990632}],"ts":1784090355604}
{"action":"update","arg":{"instType":"SPOT","channel":"books","instId":"BTCUSDT"},"data":[{"asks":[["64817.57","0"],["64819.26","0.030886"],["64827.73","0.071415"],["64837.55","0.071415"],["64847.37","0.071415"],["64891.02","0.023805"],["64900.47","0"],["64910.3","0"],["65072.16","0"],["65072.4","0"]],"bids":[["64809.28","0.004234"],["64808.22","0"],["64799","0"],["64798.93","0.001543"],["64793.05","0.463291"],["64792.55","0"]],"ts":"1784090355713","seq":656732992011,"pseq":656732990924}],"ts":1784090355718}
{"action":"update","arg":{"instType":"SPOT","channel":"books","instId":"BTCUSDT"},"data":[{"asks":[["64810.01","2.75308"]],"bids":[["64805.06","0"],["64805.03","0.026249"],["64799","0"],["64798.93","0.001543"]],"ts":"1784090355805","seq":656732993026,"pseq":656732992011}],"ts":1784090355808}
{"action":"update","arg":{"instType":"SPOT","channel":"books","instId":"BTCUSDT"},"data":[{"asks":[["64810.01","2.75308"],["64815.4","0"],["65072.16","0.011176"]],"bids":[["64800.16","0.046322"],["64799","0"],["64798.93","0.001543"],["64778.22","0"],["64777.75","0.154409"],["64420.98","0"]],"ts":"1784090355889","seq":656732995030,"pseq":656732993026}],"ts":1784090355902}
{"action":"update","arg":{"instType":"SPOT","channel":"books","instId":"BTCUSDT"},"data":[{"asks":[],"bids":[["64799","0.012908"],["64798.93","0"]],"ts":"1784090355905","seq":656732995154,"pseq":656732995030}],"ts":1784090355908}
{"action":"update","arg":{"instType":"SPOT","channel":"books","instId":"BTCUSDT"},"data":[{"asks":[["64817.51","0.030886"],["64819.26","0"]],"bids":[["64809.28","0"],["64808.33","0.004234"],["64799","0"],["64798.93","0.001543"],["64793.35","0"],["64793.02","0.077204"]],"ts":"1784090355986","seq":656732995883,"pseq":656732995154}],"ts":1784090356003}
{"action":"update","arg":{"instType":"SPOT","channel":"books","instId":"BTCUSDT"},"data":[{"asks":[],"bids":[["64799","0.012908"],["64798.93","0"]],"ts":"1784090356017","seq":656732996062,"pseq":656732995883}],"ts":1784090356020}
{"action":"update","arg":{"instType":"SPOT","channel":"books","instId":"BTCUSDT"},"data":[{"asks":[["64817.51","0"],["64819.26","0.030886"]],"bids":[["64799","0"],["64798.93","0.001543"]],"ts":"1784090356096","seq":656732996781,"pseq":656732996062}],"ts":1784090356104}
{"action":"update","arg":{"instType":"SPOT","channel":"books","instId":"BTCUSDT"},"data":[{"asks":[],"bids":[["64799","0.012908"],["64798.93","0"]],"ts":"1784090356102","seq":656732996836,"pseq":656732996781}],"ts":1784090356106}
{"action":"update","arg":{"instType":"SPOT","channel":"books","instId":"BTCUSDT"},"data":[{"asks":[["64817.57","0.030886"],["64819.26","0"],["64827.73","0"],["64837.55","0"],["64847.37","0"],["64891.02","0"],["64895.64","0"],["64915.3","0.071415"],["64929.75","0.071415"],["65072.4","0.001256"],["65072.73","0.000019"]],"bids":[["64799","0"],["64798.93","0.001543"]],"ts":"1784090356195","seq":656732997472,"pseq":656732996836}],"ts":1784090356205}
{"action":"update","arg":{"instType":"SPOT","channel":"books","instId":"BTCUSDT"},"data":[{"asks":[],"bids":[["64799","0.012908"],["64798.93","0"]],"ts":"1784090356206","seq":656732997584,"pseq":656732997472}],"ts":1784090356208}
{"action":"update","arg":{"instType":"SPOT","channel":"books","instId":"BTCUSDT"},"data":[{"asks":[["64810.01","2.75308"],["64814.56","0.077204"],["64817.57","0"],["64819.26","0.030886"],["65072.73","0"]],"bids":[["64799","0"],["64798.93","0.001543"]],"ts":"1784090356284","seq":656732998010,"pseq":656732997584}],"ts":1784090356307}
{"action":"update","arg":{"instType":"SPOT","channel":"books","instId":"BTCUSDT"},"data":[{"asks":[],"bids":[["64799","0.012908"],["64798.93","0"]],"ts":"1784090356309","seq":656732998093,"pseq":656732998010}],"ts":1784090356312}
{"action":"update","arg":{"instType":"SPOT","channel":"books","instId":"BTCUSDT"},"data":[{"asks":[["64817.51","0.030886"],["64819.26","0"],["64844.67","0.154408"],["64922.31","0.016206"],["64938.8","0"],["65072.4","0"]],"bids":[["64799","0"],["64798.93","0.001543"]],"ts":"1784090356401","seq":656732998545,"pseq":656732998093}],"ts":1784090356404}
{"action":"update","arg":{"instType":"SPOT","channel":"books","instId":"BTCUSDT"},"data":[{"asks":[],"bids":[["64805.07","0.026249"],["64805.03","0"],["64799","0"],["64798.93","0.001543"]],"ts":"1784090356484","seq":656732998943,"pseq":656732998545}],"ts":1784090356510}
{"action":"update","arg":{"instType":"SPOT","channel":"books","instId":"BTCUSDT"},"data":[{"asks":[],"bids":[["64799","0.012908"],["64798.93","0"]],"ts":"1784090356516","seq":656732999059,"pseq":656732998943}],"ts":1784090356520}
{"action":"update","arg":{"instType":"SPOT","channel":"books","instId":"BTCUSDT"},"data":[{"asks":[["64817.51","0"],["64817.57","0.030886"],["64819.26","0"],["64891.48","0.071415"],["64905.47","0.071415"],["64929.75","0"],["65072.16","0"]],"bids":[["64799","0"],["64798.93","0.001543"]],"ts":"1784090356595","seq":656732999462,"pseq":656732999059}],"ts":1784090356612}
{"action":"update","arg":{"instType":"SPOT","channel":"books","instId":"BTCUSDT"},"data":[{"asks":[],"bids":[["64799","0.012908"],["64798.93","0"]],"ts":"1784090356614","seq":656732999502,"pseq":656732999462}],"ts":1784090356618}
{"action":"update","arg":{"instType":"SPOT","channel":"books","instId":"BTCUSDT"},"data":[{"asks":[["64817.57","0"],["64819.26","0.030886"]],"bids":[["64799","0"],["64798.93","0.001543"]],"ts":"1784090356706","seq":656732999975,"pseq":656732999502}],"ts":1784090356708}
{"action":"update","arg":{"instType":"SPOT","channel":"books","instId":"BTCUSDT"},"data":[{"asks":[["64827.73","0.071415"],["64837.55","0.071415"],["64847.37","0.071415"],["64891.02","0.023805"],["64891.48","0"],["64905.47","0"],["64915.3","0"],["65071.49","0"]],"bids":[["64799","0"],["64798.93","0.001543"],["64762.66","0.154408"],["64762.22","0"]],"ts":"1784090356802","seq":656733000414,"pseq":656732999975}],"ts":1784090356806}
{"action":"update","arg":{"instType":"SPOT","channel":"books","instId":"BTCUSDT"},"data":[{"asks":[["64827.73","0"],["64837.55","0"],["64847.37","0"],["64891.02","0"],["64895.64","0.071415"],["64905.47","0.071415"],["65071.49","0.000008"],["65072.16","0.011176"]],"bids":[["64799","0"],["64798.93","0.001543"]],"ts":"1784090356899","seq":656733000666,"pseq":656733000414}],"ts":1784090356919}
{"action":"update","arg":{"instType":"SPOT","channel":"books","instId":"BTCUSDT"},"data":[{"asks":[],"bids":[["64799","0.012908"],["64798.93","0"]],"ts":"1784090356927","seq":656733000747,"pseq":656733000666}],"ts":1784090356930}
{"action":"update","arg":{"instType":"SPOT","channel":"books","instId":"BTCUSDT"},"data":[{"asks":[["64810.01","2.75308"]],"bids":[["64799","0.012908"],["64798.93","0"]],"ts":"1784090357010","seq":656733001040,"pseq":656733000747}],"ts":1784090357012}
{"action":"update","arg":{"instType":"SPOT","channel":"books","instId":"BTCUSDT"},"data":[{"asks":[],"bids":[["64799","0.012908"],["64798.93","0"]],"ts":"1784090357107","seq":656733001255,"pseq":656733001040}],"ts":1784090357111}
{"action":"update","arg":{"instType":"SPOT","channel":"trade","instId":"BTCUSDT"},"data":[{"ts":"1784090357198","price":"64810.01","size":"0.000001","side":"buy","tradeId":"1461146349560643584"}],"ts":1784090357201}
{"action":"update","arg":{"instType":"SPOT","channel":"trade","instId":"BTCUSDT"},"data":[{"ts":"1784090357198","price":"64810.01","size":"0.000022","side":"buy","tradeId":"1461146349560643586"}],"ts":1784090357201}
{"action":"update","arg":{"instType":"SPOT","channel":"books","instId":"BTCUSDT"},"data":[{"asks":[["64810.01","2.753057"],["64817.57","0"],["64819.25","0.030886"],["64819.26","0"],["64895.64","0"],["64905.47","0"],["64915.3","0.071415"],["64920.83","0.071415"],["64935.81","0.071415"],["65072.16","0"]],"bids":[["64799","0.012908"],["64798.93","0"]],"ts":"1784090357219","seq":656733001764,"pseq":656733001255}],"ts":1784090357222}
{"action":"update","arg":{"instType":"SPOT","channel":"books","instId":"BTCUSDT"},"data":[{"asks":[["64817.52","0.494179"],["64819.25","0"],["65072.16","0.011176"]],"bids":[["64799","0"],["64798.93","0"],["64420.98","0.000009"]],"ts":"1784090357301","seq":656733002010,"pseq":656733001764}],"ts":1784090357304}
{"action":"update","arg":{"instType":"SPOT","channel":"books","instId":"BTCUSDT"},"data":[{"asks":[["64817.52","0.463293"],["64819.26","0.030886"],["64829.27","0.154408"],["64829.66","0"],["64896.78","0"],["64935.81","0"]],"bids":[["64805.16","0.026249"],["64805.07","0"],["64799","0"],["64798.93","0.001543"],["64420.98","0"]],"ts":"1784090357406","seq":656733002371,"pseq":656733002010}],"ts":1784090357410}
{"action":"update","arg":{"instType":"SPOT","channel":"books","instId":"BTCUSDT"},"data":[{"asks":[["64826.91","0.001542"],["64827.63","0"],["64931.64","0.071415"],["65072.16","0"]],"bids":[["64799","0"],["64798.93","0.001543"]],"ts":"1784090357508","seq":656733003600,"pseq":656733002371}],"ts":1784090357512}
{"action":"update","arg":{"instType":"SPOT","channel":"books","instId":"BTCUSDT"},"data":[{"asks":[["64817.57","0.030886"],["64819.26","0"]],"bids":[["64799","0"],["64798.93","0.001543"]],"ts":"1784090357606","seq":656733004833,"pseq":656733003600}],"ts":1784090357608}
{"action":"update","arg":{"instType":"SPOT","channel":"books","instId":"BTCUSDT"},"data":[{"asks":[["64817.57","0"],["64819.26","0.030886"]],"bids":[["64799","0"],["64798.93","0.001543"]],"ts":"1784090357710","seq":656733005378,"pseq":656733004833}],"ts":1784090357712}
{"action":"update","arg":{"instType":"SPOT","channel":"books","instId":"BTCUSDT"},"data":[{"asks":[["64810.01","2.753057"],["64826.23","0"],["64835.94","0"],["64845.66","0"],["64891.02","0"],["64899.58","0.071415"],["64909.31","0.071415"],["64915.3","0"],["64920.83","0"],["64931.64","0"],["65072.16","0.011176"]],"bids":[["64800.37","0.046322"],["64800.16","0"],["64799","0"],["64798.93","0.001543"]],"ts":"1784090357813","seq":656733006037,"pseq":656733005378}],"ts":1784090357816}
{"action":"update","arg":{"instType":"SPOT","channel":"books","instId":"BTCUSDT"},"data":[{"asks":[["64817.57","0"],["64819.26","0.030886"],["64899.58","0"],["64927.47","0.071415"],["64977.29","0.152003"],["65048.45","0.023805"],["65072.16","0"]],"bids":[["64799","0.012908"],["64798.93","0"],["64778.22","0.154408"],["64777.75","0"]],"ts":"1784090357906","seq":656733006214,"pseq":656733006037}],"ts":1784090357910}
{"action":"update","arg":{"instType":"SPOT","channel":"books","instId":"BTCUSDT"},"data":[{"asks":[],"bids":[["64799","0.012908"],["64798.93","0"],["64793.02","0"],["64792.93","0.077204"]],"ts":"1784090358003","seq":656733006400,"pseq":656733006214}],"ts":1784090358006}
{"action":"update","arg":{"instType":"SPOT","channel":"books","instId":"BTCUSDT"},"data":[{"asks":[["64815.2","0"],["64872.2","0"],["64919.04","0.071415"],["64929.2","0"],["64986.2","0"],["65043.2","0"],["65072.16","0.011176"],["65072.4","0.001256"],["65072.73","0.000019"],["65072.77","0.000143"]],"bids":[["64805.17","0.026249"],["64805.16","0"],["64804.1","0"],["64799","0"],["64798.93","0.001543"],["64776.2","0"],["64748.3","0"],["64720.4","0"],["64692.5","0"],["64420.98","0.000009"],["64420.92","2.516083"],["64420.13","0.000186"],["64420","0.020102"],["64419.3","0.000156"]],"ts":"1784090358104","seq":656733006695,"pseq":656733006400}],"ts":1784090358108}
{"action":"update","arg":{"instType":"SPOT","channel":"books","instId":"BTCUSDT"},"data":[{"asks":[],"bids":[["64799","0.012908"],["64798.93","0"]],"ts":"1784090358215","seq":656733007234,"pseq":656733006695}],"ts":1784090358218}
{"action":"update","arg":{"instType":"SPOT","channel":"books","instId":"BTCUSDT"},"data":[{"asks":[["64814.47","0.077204"],["64814.56","0"],["64817.51","0.030886"],["64819.26","0"]],"bids":[["64799","0"],["64798.93","0.001543"]],"ts":"1784090358311","seq":656733007481,"pseq":656733007234}],"ts":1784090358314}
{"action":"update","arg":{"instType":"SPOT","channel":"books","instId":"BTCUSDT"},"data":[{"asks":[["64815.2","0.002145"],["64844.3","0.154408"],["64844.67","0"],["64872.2","0.002143"],["64895.41","0.071415"],["64927.47","0"],["64929.2","0.002141"],["64986.2","0.002139"],["65043.2","0.002138"],["65071.49","0"],["65072.16","0"],["65072.4","0"],["65072.73","0"],["65072.77","0"]],"bids":[["64804.1","0.002145"],["64799","0"],["64798.93","0.001543"],["64776.2","0.002146"],["64748.3","0.002147"],["64720.4","0.002148"],["64692.5","0.002149"],["64420.98","0"],["64420.92","0"],["64420.13","0"],["64420","0"],["64419.3","0"]],"ts":"1784090358416","seq":656733007737,"pseq":656733007481}],"ts":1784090358420}
{"action":"update","arg":{"instType":"SPOT","channel":"books","instId":"BTCUSDT"},"data":[{"asks":[["64810.01","2.753057"],["64817.51","0"],["64819.26","0.030886"]],"bids":[["64799","0"],["64798.93","0.001543"],["64793.48","0.461158"],["64793.05","0.463289"]],"ts":"1784090358505","seq":656733007972,"pseq":656733007737}],"ts":1784090358508}
{"action":"update","arg":{"instType":"SPOT","channel":"books","instId":"BTCUSDT"},"data":[{"asks":[],"bids":[["64809.03","0.00601"],["64808.33","0"],["64799","0"],["64798.93","0.001543"]],"ts":"1784090358602","seq":656733008313,"pseq":656733007972}],"ts":1784090358606}
{"action":"update","arg":{"instType":"SPOT","channel":"books","instId":"BTCUSDT"},"data":[{"asks":[],"bids":[["64799","0"],["64798.93","0.001543"]],"ts":"1784090358713","seq":656733008465,"pseq":656733008313}],"ts":1784090358716}
{"action":"update","arg":{"instType":"SPOT","channel":"books","instId":"BTCUSDT"},"data":[{"asks":[["64895.41","0"],["64927.47","0.071415"]],"bids":[["64799","0"],["64798.93","0.001543"],["64798.69","0.741877"],["64798.68","0"],["64793.48","0.924446"],["64793.05","0"],["64763.42","0.154408"],["64762.66","0"],["64420.98","0.000009"],["64420.92","2.516083"]],"ts":"1784090358801","seq":656733009984,"pseq":656733008465}],"ts":1784090358804}
{"action":"update","arg":{"instType":"SPOT","channel":"books","instId":"BTCUSDT"},"data":[{"asks":[["64826.23","0.071415"],["64835.94","0.071415"],["64845.66","0.071415"],["64891.02","0.023805"],["64909.31","0"],["64919.04","0"],["64927.47","0"],["65071.14","0"]],"bids":[["64805.5","0.026249"],["64805.17","0"],["64799","0"],["64798.93","0.001543"],["64798.7","0.266301"],["64793.49","0.463288"],["64793.48","0.054326"],["64793.05","0"],["64420.98","0"],["64420.92","0"]],"ts":"1784090358921","seq":656733012954,"pseq":656733009984}],"ts":1784090358925}
{"action":"update","arg":{"instType":"SPOT","channel":"books","instId":"BTCUSDT"},"data":[{"asks":[],"bids":[["64800.64","0.001543"],["64799","0"],["64798.93","0"],["64798.92","0"],["64798.71","0.061707"],["64793.48","0.515954"]],"ts":"1784090359004","seq":656733014950,"pseq":656733012954}],"ts":1784090359006}
{"action":"update","arg":{"instType":"SPOT","channel":"books","instId":"BTCUSDT"},"data":[{"asks":[],"bids":[["64799","0"],["64798.71","0.061707"]],"ts":"1784090359101","seq":656733016442,"pseq":656733014950}],"ts":1784090359104}
{"action":"update","arg":{"instType":"SPOT","channel":"books","instId":"BTCUSDT"},"data":[{"asks":[["64913.07","0"],["65071.14","0.000056"]],"bids":[["64799","0"],["64798.71","0.061707"],["64712.7","0"],["64420.98","0.000009"]],"ts":"1784090359212","seq":656733018666,"pseq":656733016442}],"ts":1784090359214}
{"action":"update","arg":{"instType":"SPOT","channel":"books","instId":"BTCUSDT"},"data":[{"asks":[["64810.01","2.753057"],["64913.08","0.000667"],["65071.14","0"]],"bids":[["64799","0"],["64798.71","0.061707"],["64712.7","0.000667"],["64420.98","0"]],"ts":"1784090359308","seq":656733019922,"pseq":656733018666}],"ts":1784090359310}
{"action":"update","arg":{"instType":"SPOT","channel":"books","instId":"BTCUSDT"},"data":[{"asks":[["64829.27","0"],["65071.14","0.000056"]],"bids":[["64799","0"],["64798.71","0.061707"]],"ts":"1784090359419","seq":656733020497,"pseq":656733019922}],"ts":1784090359422}
{"action":"update","arg":{"instType":"SPOT","channel":"books","instId":"BTCUSDT"},"data":[{"asks":[],"bids":[["64799","0"],["64798.71","0.061707"],["64793.49","0"],["64793.05","0.463287"]],"ts":"1784090359502","seq":656733021574,"pseq":656733020497}],"ts":1784090359504}
{"action":"update","arg":{"instType":"SPOT","channel":"books","instId":"BTCUSDT"},"data":[{"asks":[],"bids":[["64805.64","0.026249"],["64805.5","0"],["64801.38","0.08363"],["64801.37","0"],["64799","0.012908"],["64798.73","0.385247"],["64798.72","0.741877"],["64798.71","0"],["64798.7","0"],["64798.69","0"],["64420.98","0.000009"]],"ts":"1784090359606","seq":656733026237,"pseq":656733021574}],"ts":1784090359611}
{"action":"update","arg":{"instType":"SPOT","channel":"books","instId":"BTCUSDT"},"data":[{"asks":[],"bids":[["64793.49","0.463288"],["64793.05","0"]],"ts":"1784090359710","seq":656733027799,"pseq":656733026237}],"ts":1784090359714}
{"action":"update","arg":{"instType":"SPOT","channel":"books","instId":"BTCUSDT"},"data":[{"asks":[["64810.01","2.753057"]],"bids":[["64800.84","0.046322"],["64800.37","0"],["64799","0.012908"],["64798.74","0"]],"ts":"1784090359804","seq":656733028430,"pseq":656733027799}],"ts":1784090359808}
{"action":"update","arg":{"instType":"SPOT","channel":"books","instId":"BTCUSDT"},"data":[{"asks":[["64826.23","0"],["64829.48","0.001542"],["64831.22","0"],["64835.94","0"],["64839.21","0.001542"],["64841.77","0"],["64845.66","0"],["64891.02","0"],["64908.07","0.071415"],["64927.72","0.071415"],["64974.99","0"],["65071.49","0.000008"],["65072.16","0.011176"],["65072.4","0.001256"]],"bids":[["64802.06","0"],["64801.4","0.175901"],["64801.39","0.309116"],["64801.38","0"],["64800.32","0.001543"],["64799","0.012908"],["64798.74","0"],["64793.48","0.454999"],["64787.5","0"],["64784.12","0.001543"],["64420.98","0"]],"ts":"1784090359904","seq":656733029477,"pseq":656733028430}],"ts":1784090359906}
{"action":"update","arg":{"instType":"SPOT","channel":"books","instId":"BTCUSDT"},"data":[{"asks":[["64810.01","2.753057"],["64827.73","0.071415"],["64837.54","0.071415"],["64847.36","0.071415"],["64891.02","0.023805"],["64908.07","0"],["64927.72","0"],["65072.16","0"],["65072.4","0"]],"bids":[["64799","0.012908"],["64798.74","0"],["64793.41","0.077204"],["64792.93","0"],["64778.22","0"],["64420.98","0.000009"]],"ts":"1784090360001","seq":656733030068,"pseq":656733029477}],"ts":1784090360004}
{"action":"update","arg":{"instType":"SPOT","channel":"books","instId":"BTCUSDT"},"data":[{"asks":[["64827.73","0"],["64837.54","0"],["64847.36","0"],["64891.02","0"],["64920.66","0.071415"],["65072.16","0.011176"],["65072.4","0.001256"],["65072.73","0.000019"]],"bids":[["64799","0.012908"],["64798.74","0"]],"ts":"1784090360110","seq":656733031290,"pseq":656733030068}],"ts":1784090360115}
{"action":"update","arg":{"instType":"SPOT","channel":"books","instId":"BTCUSDT"},"data":[{"asks":[["64926.28","0.071415"],["65072.73","0"]],"bids":[["64799","0.012908"],["64798.74","0"]],"ts":"1784090360208","seq":656733032272,"pseq":656733031290}],"ts":1784090360212}
{"action":"update","arg":{"instType":"SPOT","channel":"books","instId":"BTCUSDT"},"data":[{"asks":[["64814.47","0"],["64814.78","0.077204"],["64827.73","0.071415"],["64837.54","0.071415"],["64847.36","0.071415"],["64891.02","0.023805"],["64920.66","0"],["64926.28","0"],["65072.16","0"],["65072.4","0"]],"bids":[["64799","0.012908"],["64798.74","0"]],"ts":"1784090360305","seq":656733033314,"pseq":656733032272}],"ts":1784090360308}
{"action":"update","arg":{"instType":"SPOT","channel":"books","instId":"BTCUSDT"},"data":[{"asks":[["64844.3","0"],["64844.32","0.154408"]],"bids":[["64805.72","0.026249"],["64805.64","0"],["64799","0.012908"],["64798.74","0"]],"ts":"1784090360416","seq":656733033813,"pseq":656733033314}],"ts":1784090360420}
{"action":"update","arg":{"instType":"SPOT","channel":"books","instId":"BTCUSDT"},"data":[{"asks":[],"bids":[["64799","0.012908"],["64798.74","0"]],"ts":"1784090360513","seq":656733034150,"pseq":656733033813}],"ts":1784090360516}
{"action":"update","arg":{"instType":"SPOT","channel":"trade","instId":"BTCUSDT"},"data":[{"ts":"1784090360536","price":"64810","size":"0.017094","side":"sell","tradeId":"1461146363561230336"}],"ts":1784090360538}
