{"event":"subscribe","arg":{"instType":"SPOT","channel":"books","instId":"BTCUSDT"}}
{"event":"subscribe","arg":{"instType":"SPOT","channel":"trade","instId":"BTCUSDT"}}
{"action":"snapshot","arg":{"instType":"SPOT","channel":"books","instId":"BTCUSDT"},"data":[{"asks":[["64820","0.020619"],["64822.59","0.006093"],["64824.97","0.015625"],["64824.98","0.010575"],["64825","0.02"],["64825.29","0.015426"],["64825.94","0.182375"],["64825.95","0.26"],["64826.27","0.001542"],["64826.75","0.000322"],["64827.8","0.002145"],["64828.08","0.07956"],["64828.24","0.26"],["64828.25","0.004316"],["64828.44","0.000772"],["64828.79","0.000771"],["64829.03","0.001542"],["64829.98","0.550995"],["64829.99","0.741877"],["64830","0.013117"],["64830.01","0.309116"],["64830.47","0.001542"],["64830.69","0.026238"],["64831.42","0.01057"],["64832.05","0.001542"],["64832.28","0.741877"],["64833.3","0.05"],["64834.74","0.001542"],["64835","0.02"],["64835.07","0.046304"],["64835.53","0.22145"],["64835.54","0.741877"],["64835.58","0.035"],["64836.49","0.1593"],["64836.85","0.000322"],["64837.78","0.362874"],["64837.79","0.309116"],["64837.95","0.013325"],["64837.97","0.046269"],["64838.78","0.463121"],["64838.79","0.741877"],["64838.82","0.001041"],["64839.23","0.001542"],["64839.99","0.030877"],["64840","0.02"],["64841.77","0.001542"],["64842.03","0.218106"],["64842.04","0.741877"],["64843.58","0.077173"],["64844.49","0.001581"],["64845","0.02"],["64845.28","0.22145"],["64845.29","0.741877"],["64845.38","0.1593"],["64845.57","0.309116"],["64846.06","0.187075"],["64846.12","0.015124"],["64846.26","0.001542"],["64846.99","0.000322"],["64848.54","0.741877"],["64848.7","0.001542"],["64849.12","0.001542"],["64849.32","0.001542"],["64849.6","0.04626"],["64850","0.82"],["64850.71","0.211979"],["64851.7","0.001541"],["64854.22","0.626749"],["64854.51","0.483476"],["64855","0.02"],["64855.81","0.1593"],["64857.17","0.000322"],["64857.73","0.211979"],["64860","0.02"],["64861.29","4.389972"],["64862.13","4.779253"],["64862.3","0.1593"],["64863.57","0.02021"],["64865","0.02"],["64865.51","0.371667"],["64866.26","0.46249"],["64867.39","0.000322"],["64869.4","0.211979"],["64869.71","0.1593"],["64870","0.02"],["64873.81","0.000028"],["64875","0.02"],["64876.5","0.1593"],["64877.65","0.000322"],["64878.66","0.211979"],["64878.67","5.001544"],["64880","0.039605"],["64882.43","4.888773"],["64884.8","0.002143"],["64885","0.168481"],["64885.5","0.000196"],["64885.71","0.000017"],["64885.81","1.873811"],["64885.83","0.000483"],["64886.36","0.000056"],["64886.42","0.000014"],["64886.96","0.591255"],["64887.22","0.000117"],["64887.98","0.000322"],["64888.89","0.000463"],["64890","0.020012"],["64890.33","0.211979"],["64890.34","0.000041"],["64890.66","0.000027"],["64891.49","0.1593"],["64895","0.02"],["64895.79","0.00001"],["64896.4","0.000015"],["64898.33","0.000322"],["64899.04","4.998256"],["64900","0.03844"],["64901.69","0.000012"],["64901.78","0.002051"],["64901.85","0.016208"],["64902.18","0.000062"],["64902.36","0.1593"],["64902.68","0.000013"],["64902.78","0.000027"],["64903.61","0.00032"],["64905","0.02"],["64905.67","0.000021"],["64906.54","0.000062"],["64906.98","0.000017"],["64907.87","1.391583"],["64908.57","0.00003"],["64908.73","0.000322"],["64908.84","0.1593"],["64909.09","0.000147"],["64909.93","0.000931"],["64910","0.02"],["64910.03","0.001952"],["64910.17","0.001855"],["64910.66","0.000013"],["64910.94","0.000264"],["64912.25","0.000273"],["64914.29","0.000021"],["64914.53","0.000039"],["64915","0.021532"],["64915.32","0.1593"],["64916.12","0.000667"],["64916.32","0.000015"],["64916.67","0.000036"],["64916.84","0.00001"],["64917.65","0.000019"],["64917.91","0.000086"],["64918.55","0.005633"],["64919.06","0.000052"],["64919.18","0.000322"],["64919.46","0.000111"],["64919.53","0.000032"],["64920","0.020438"],["64920.15","0.00013"],["64921.06","0.000188"],["64921.8","0.1593"],["64923.3","0.016208"],["64923.37","6.386325"],["64923.81","0.000011"],["64923.82","0.000145"],["64924.06","0.000011"],["64925","0.020209"],["64925.33","0.000011"],["64925.38","0.000024"],["64925.47","0.000015"],["64925.63","0.000012"],["64926.32","0.000018"],["64927.32","0.00002"],["64927.7","0.000038"],["64927.84","0.011176"],["64928","0.000036"],["64928.32","0.1593"],["64928.47","0.000025"],["64928.57","0.000337"],["64928.91","0.000072"],["64929.39","0.000333"],["64929.51","0.077332"],["64929.58","0.000027"],["64930","0.02"],["64931.03","0.000011"],["64931.97","0.000023"],["64932.35","0.000011"],["64933.33","0.001201"],["64933.71","0.000031"],["64934.21","0.00001"],["64934.64","0.000011"],["64934.8","0.159333"],["64935","0.02"],["64935.08","0.000023"],["64935.37","0.000011"],["64935.62","0.000465"],["64935.9","0.000023"],["64936.31","0.000236"],["64937.92","0.000034"],["64938.15","0.000186"],["64938.32","2.608182"],["64938.37","0.000051"],["64938.99","0.001639"],["64939.27","0.000012"],["64939.7","4.944139"],["64939.8","0.00001"],["64940","0.020061"],["64940.4","0.000048"],["64941.25","0.001837"],["64941.3","0.1593"],["64941.48","0.000008"],["64941.8","0.002141"],["64942.51","0.001951"],["64942.79","3.937397"],["64942.86","0.000017"],["64943.48","0.000011"],["64943.66","0.000084"],["64943.82","0.000013"],["64944.1","0.000014"],["64944.37","0.000013"],["64944.92","0.000744"],["64945","0.02"],["64947.79","0.1593"],["64947.9","0.071415"],["64949.51","0.000013"],["64950","0.020073"],["64950.27","2.365523"],["64951.85","0.00155"],["64952.4","0.002232"],["64952.65","0.000012"],["64952.7","0.000011"],["64953.49","0.000014"],["64954.28","0.1593"],["64954.34","0.00034"],["64954.55","0.000056"],["64954.95","0.000232"],["64955","0.02"],["64955.22","0.000044"],["64956.38","0.000791"],["64956.52","0.00001"],["64957.63","0.071415"],["64957.69","0.000029"],["64957.89","0.000014"],["64958.14","0.000049"],["64958.18","0.000026"],["64958.33","0.000012"],["64958.85","0.000012"],["64959.3","0.000312"],["64959.39","0.000014"],["64960","0.020627"],["64960.76","0.1593"],["64961.56","0.00015"],["64962.03","0.000249"],["64962.09","0.000021"],["64963.39","0.009105"],["64964.05","0.000012"],["64965","0.020025"],["64966.06","0.00002"],["64966.67","0.000049"],["64967.24","0.1593"],["64967.37","0.071415"],["64967.53","0.000037"],["64967.63","0.00058"],["64968.47","0.000015"],["64969.33","1.235333"],["64969.47","0.000196"],["64969.62","0.000017"],["64969.88","0.00032"],["64970","0.020029"],["64970.41","0.000018"],["64970.56","0.000016"],["64971.09","0.000033"],["64971.24","0.000021"],["64971.43","0.000012"],["64971.59","0.000055"],["64972.22","0.000027"],["64973.73","0.1593"],["64974.99","0.00195"],["64975","0.02004"],["64976.47","0.000014"],["64976.74","0.000015"],["64977.84","0.000111"],["64977.92","0.000011"],["64978.05","0.000013"],["64978.64","0.000173"],["64979.92","0.000016"],["64980","0.020086"],["64980.22","0.1593"],["64980.43","0.000044"],["64982","0.002158"],["64982.75","0.000043"],["64982.86","0.000021"],["64984.85","0.000045"],["64984.98","0.000038"],["64985","0.02"],["64985.27","0.000032"],["64985.29","0.000032"],["64986.58","0.000111"],["64986.7","0.1593"],["64987.18","0.000045"],["64987.83","0.000013"],["64988.24","0.000019"],["64988.25","0.000015"],["64989.14","0.000039"],["64990","0.020078"],["64990.65","0.000062"],["64991.65","0.000049"],["64991.84","0.00007"],["64992.33","0.000011"],["64993.1","0.000054"],["64993.12","0.000022"],["64994.11","0.000678"],["64994.29","0.000023"],["64994.34","0.000015"],["64994.47","0.000127"],["64995","0.02"],["64995.65","0.000847"],["64997.69","0.000035"],["64997.93","1.17448"],["64998.13","0.000086"],["64998.8","0.002139"],["64998.84","0.000093"],["64999.29","0.014699"],["64999.5","0.000034"],["64999.66","0.1593"],["64999.67","0.000032"],["64999.84","0.000063"],["64999.99","0.144689"],["65000","1.963238"],["65003.27","2.009648"],["65003.84","0.00006"],["65003.91","0.000017"],["65004.67","0.000124"],["65005","0.02"],["65005.08","0.003232"],["65006.14","0.1593"],["65006.52","0.000044"],["65006.62","0.000048"],["65007.82","0.000019"],["65008.2","0.000109"],["65008.69","0.000074"],["65009.39","0.001457"],["65009.99","0.014305"],["65010","0.02014"],["65010.26","0.0001"],["65011.31","0.00001"],["65011.58","0.000013"],["65011.86","0.023805"],["65012.07","0.000395"],["65012.24","0.001065"],["65012.79","0.000056"],["65012.99","0.000012"],["65013.61","0.000011"],["65014","0.000036"],["65014.29","0.000108"],["65014.79","0.000011"],["65014.89","0.000176"],["65015","0.020525"],["65015.49","0.000011"],["65015.51","0.000052"],["65016.43","0.000023"],["65016.67","0.000208"],["65017","0.000014"],["65017.01","0.000023"],["65017.34","0.000015"],["65018","0.000043"],["65018.32","0.00162"],["65018.79","0.000013"],["65020","0.020097"],["65020.15","0.006462"],["65020.18","0.000014"],["65020.91","0.000027"],["65021","0.005115"],["65021.33","0.000041"],["65021.74","0.00005"],["65022.12","0.000011"],["65022.47","0.000012"],["65022.8","0.000492"],["65023.16","0.000208"],["65023.47","0.000084"],["65023.7","0.000072"],["65024.6","0.000024"],["65024.67","2.428324"],["65024.96","0.000209"],["65025","0.020118"],["65025.05","0.002323"],["65025.21","0.000018"],["65025.58","0.1593"],["65026.32","0.000014"],["65026.67","0.00002"],["65027.12","0.000039"],["65027.55","0.000029"],["65027.67","0.00001"],["65028.13","0.000744"],["65028.57","0.00006"],["65029.01","0.111679"],["65030","0.020012"],["65030.03","1.797118"],["65030.64","0.000049"],["65031.59","0.00018"],["65031.6","0.002151"],["65032.01","0.00003"],["65032.07","0.1593"],["65032.37","0.000014"],["65032.49","0.000012"],["65032.76","0.000041"],["65033.33","0.000114"],["65034.91","0.000297"],["65035","0.020413"],["65035.04","0.000976"],["65035.47","0.000011"],["65035.71","0.000081"],["65035.79","2.131466"],["65036.14","0.00032"],["65036.36","0.000056"],["65037.26","0.000241"],["65037.86","0.000045"],["65038.56","0.1593"],["65039.41","0.000722"],["65040","0.020918"],["65040.5","0.000931"],["65040.54","0.000036"],["65040.84","0.000011"],["65041.12","0.000016"],["65041.67","0.000027"],["65041.79","0.000044"],["65044.94","0.000035"],["65045","0.02"],["65045.05","0.000232"],["65045.73","0.001846"],["65046.71","0.000034"],["65046.88","0.000046"],["65047.33","0.000012"],["65047.49","0.000304"],["65047.73","0.000061"],["65048.45","0.191938"],["65048.67","0.000153"],["65049.59","0.000343"],["65050","0.020372"],["65050.51","0.023805"],["65050.55","0.000606"],["65050.82","0.000044"],["65051.02","0.000032"],["65051.42","0.000042"],["65051.43","0.000021"],["65051.5","0.1593"],["65051.57","0.00034"],["65051.73","0.00026"],["65051.86","0.000207"],["65052.92","0.000011"],["65052.94","0.000041"],["65053.35","0.000714"],["65053.44","0.000196"],["65053.69","0.000111"],["65053.77","0.0018"],["65054.48","0.002051"],["65054.55","0.000013"],["65054.85","0.000249"],["65055","0.02"],["65055.11","0.000013"],["65055.55","0.00002"],["65055.56","0.000024"],["65055.8","0.002137"],["65055.9","0.003347"],["65056.18","0.000013"],["65056.87","0.000013"],["65057.44","0.000028"],["65057.93","0.001844"],["65057.98","0.1593"],["65058.82","0.000044"],["65059.07","0.000036"],["65059.37","0.000083"],["65059.38","0.000333"],["65059.79","0.000016"],["65059.94","0.001544"],["65060","0.020173"],["65060.23","0.025797"],["65060.25","0.000033"],["65062.5","0.000515"],["65063.16","0.00002"],["65063.21","0.000015"],["65063.4","0.000049"],["65063.74","0.00007"],["65064.48","0.000063"],["65064.94","0.000049"],["65064.95","1.770191"],["65065","0.02"],["65066.66","0.000111"],["65066.67","0.00357"],["65068.16","0.001416"],["65068.18","0.000607"],["65068.27","0.000125"],["65068.31","0.000186"],["65068.97","0.000011"],["65069.16","0.000062"],["65069.53","0.000098"],["65069.74","0.000034"],["65070","0.020077"],["65070.42","0.000027"],["65070.74","0.000051"],["65070.94","0.1593"],["65071.14","0.000056"]],"bids":[["64819.99","3.475118"],["64817.05","0.431839"],["64817.04","1.097297"],["64816.7","0.002145"],["64816.6","0.005581"],["64816.04","0.001542"],["64815.03","0.329619"],["64815.02","0.299359"],["64815.01","0.211979"],["64814.99","0.741877"],["64813.89","0.030877"],["64813.88","0.01523"],["64813.5","0.000771"],["64812.6","0.001542"],["64811.92","0.154305"],["64811.91","0.209826"],["64811.74","0.741877"],["64810.6","0.046288"],["64809.68","0.741877"],["64808.86","0.001542"],["64808.39","0.309116"],["64808.38","0.1593"],["64807.7","0.741877"],["64806.54","0.179113"],["64806.12","0.001543"],["64805.21","0.046292"],["64805","0.02"],["64804.92","0.000322"],["64804.77","0.746421"],["64804.75","0.001041"],["64804.45","0.035"],["64803.58","0.001543"],["64803.48","0.154346"],["64803.19","0.01581"],["64802.93","0.741877"],["64802.91","0.211979"],["64800.89","0.001543"],["64800.82","0.309116"],["64800.81","0.741877"],["64800.71","0.015287"],["64800","0.02"],["64799.59","0.003086"],["64798.28","0.1593"],["64797.03","0.001543"],["64796.31","0.309116"],["64795.2","0.000322"],["64795","0.02"],["64794.72","0.211979"],["64794.56","0.071415"],["64794.41","0.001543"],["64794.27","0.071415"],["64793.73","0.001581"],["64793.19","0.015758"],["64791.14","0.001543"],["64790.99","1.876552"],["64790.26","0.309116"],["64790","0.02"],["64788.8","0.002146"],["64788.75","0.626745"],["64787.9","0.154346"],["64787.1","0.366403"],["64786.75","0.05"],["64785.84","0.1593"],["64785.47","0.000322"],["64785.05","0.211979"],["64785","0.018911"],["64784","0.000035"],["64783","0.000035"],["64782","0.000035"],["64781","0.000035"],["64780","0.020035"],["64779.97","0.071415"],["64779.8","0.020262"],["64779","0.000035"],["64778.52","0.1593"],["64778","0.000035"],["64777.11","0.211979"],["64777","0.000035"],["64776","0.000035"],["64775.75","0.000322"],["64775","0.020035"],["64774","0.000035"],["64773","0.000035"],["64772.04","0.1593"],["64772","0.000035"],["64771","0.000035"],["64770.58","0.071415"],["64770","0.020035"],["64769","0.000035"],["64768.95","1.877191"],["64768.36","0.223365"],["64768","0.000035"],["64766.03","0.000322"],["64765.55","0.58206"],["64765","0.02"],["64763.51","0.1593"],["64760.9","0.002147"],["64760","0.02"],["64759.43","0.211979"],["64756.31","0.000322"],["64755","0.02"],["64753.51","0.1593"],["64752.6","0.211979"],["64750","0.02"],["64749.19","0.016207"],["64748.91","0.034721"],["64746.92","0.1593"],["64746.91","1.068925"],["64746.59","0.001543"],["64746.58","0.000322"],["64745","0.02"],["64743.3","6.27739"],["64742.89","0.211979"],["64740","0.02"],["64736.86","0.000322"],["64735.64","5.388556"],["64735","0.02"],["64733.45","0.211979"],["64733","0.002148"],["64730","0.02"],["64728.11","0.1593"],["64727.14","0.000322"],["64726.85","6.611111"],["64725","0.02"],["64723.07","5.555213"],["64721.52","0.001544"],["64720","0.02"],["64719.99","0.09256"],["64717.42","0.000322"],["64716.4","0.000667"],["64715.22","0.1593"],["64715","0.007204"],["64712.53","4.282256"],["64710","0.02"],["64709.83","5.944444"],["64708.52","0.1593"],["64705.66","0.008302"],["64705.1","0.002149"],["64705","0.02"],["64704.27","6.618033"],["64702.61","0.016208"],["64701.16","0.1593"],["64700.69","5.388888"],["64700","0.02"],["64696.63","3.906044"],["64695","0.02"],["64694.67","0.1593"],["64694.02","0.04761"],["64690","0.02"],["64688.18","0.1593"],["64685","0.02"],["64681.69","0.1593"],["64680.03","1.16479"],["64680","0.02"],["64677.29","0.008019"],["64675.2","0.1593"],["64675","0.02"],["64670.37","4.50139"],["64670","0.02"],["64668.72","0.1593"],["64665","0.02"],["64662.24","0.1593"],["64660","0.02"],["64655.73","0.1593"],["64655","0.02"],["64650.1","0.007253"],["64650","0.02"],["64649.25","0.1593"],["64645","0.02"],["64644.11","0.098054"],["64642.77","0.1593"],["64641.43","0.00162"],["64640","0.02"],["64638.5","4.394213"],["64638.2","1.602618"],["64636.29","0.1593"],["64635","0.02"],["64630","0.02"],["64629.81","0.1593"],["64625","0.02"],["64623.33","0.1593"],["64620","0.02"],["64619.79","0.0001"],["64617.01","0.000109"],["64616.85","0.1593"],["64615.53","0.000016"],["64615","0.02"],["64612.78","0.000061"],["64610.3","0.1593"],["64610","0.02"],["64606.45","0.000017"],["64606.44","0.02152"],["64605","0.02"],["64603.82","0.1593"],["64602.65","0.000019"],["64600","0.023117"],["64598.95","0.000015"],["64597.32","0.1593"],["64595","0.02"],["64593.23","0.000101"],["64591.82","0.000071"],["64590.83","0.1593"],["64590","0.02"],["64588.89","0.000011"],["64588.31","0.000111"],["64585","0.018093"],["64584.35","0.1593"],["64580","0.02002"],["64577.92","0.000037"],["64575","0.020024"],["64573.1","0.04761"],["64572.43","0.003027"],["64572.29","0.00032"],["64571.43","0.000216"],["64571.42","0.1593"],["64570.11","0.04761"],["64570","0.02"],["64565","0.02"],["64561.08","0.189508"],["64560","0.020451"],["64557.22","0.000266"],["64555","0.020095"],["64551.95","0.1593"],["64550","0.020112"],["64547.37","0.000014"],["64545.47","0.1593"],["64545.45","0.000056"],["64545.2","0.000031"],["64545","0.02"],["64544.6","0.000084"],["64543.41","2.492563"],["64543.05","0.000048"],["64542.89","0.000051"],["64542.48","0.000011"],["64541.67","0.000022"],["64540","0.020012"],["64539.47","0.00001"],["64538.91","0.1593"],["64538.85","0.000011"],["64538.46","0.000125"],["64536.04","0.000015"],["64535","0.02"],["64534.88","0.000017"],["64533.33","0.00117"],["64532.42","0.1593"],["64532.36","3.132419"],["64530.54","0.001639"],["64530","0.02"],["64529.46","0.000049"],["64528.91","0.000744"],["64526.68","0.000011"],["64525.93","0.1593"],["64525.04","0.000032"],["64525","0.018625"],["64522.39","0.000044"],["64521.5","0.00002"],["64520.69","0.000021"],["64520","0.020884"],["64519.77","0.000931"],["64519.44","0.1593"],["64518.5","0.000042"],["64518.42","5.946623"],["64516.78","0.000111"],["64516.46","0.000012"],["64516.13","0.00005"],["64515","0.02"],["64514.29","0.000012"],["64512.95","0.1593"],["64512.26","0.000015"],["64510","0.02"],["64507.74","0.00015"],["64507.04","0.000027"],["64506.02","0.00032"],["64505","0.02"],["64504.76","0.000011"],["64504.5","0.000216"],["64504.49","0.000011"],["64503.88","0.000717"],["64502.86","0.000021"],["64500.42","0.00001"],["64500","0.029624"],["64499.06","0.000049"],["64498.94","0.000041"],["64498","0.000036"],["64497.89","0.000249"],["64495.1","0.000032"],["64495","0.02"],["64494.85","0.011176"],["64494.37","0.000057"],["64494.36","0.000526"],["64494.12","0.000019"],["64493.51","0.000012"],["64492.31","0.000012"],["64491.13","4.057089"],["64490.15","0.0001"],["64490","0.02"],["64489.92","0.000593"],["64489.35","0.000032"],["64488.55","0.000011"],["64488","0.007588"],["64487.13","0.000109"],["64486.64","0.000014"],["64486.11","0.000027"],["64485.98","0.000062"],["64485.71","0.001123"],["64485.37","0.000331"],["64485.1","0.000015"],["64485.05","0.00003"],["64485","0.020015"],["64484.71","0.000086"],["64483.42","0.015508"],["64482.26","0.000142"],["64481.82","0.000404"],["64481.55","0.000042"],["64481.48","0.000014"],["64481.47","0.000551"],["64481.46","0.000091"],["64481.09","0.001846"],["64480.64","0.000954"],["64480.52","0.000037"],["64480","0.024304"],["64479.57","0.000093"],["64479.39","0.000196"],["64478.95","0.000014"],["64478.9","0.002014"],["64478.8","0.000021"],["64477.78","0.000012"],["64477.75","0.000207"],["64477.12","0.000011"],["64476.89","0.000013"],["64476.84","0.000011"],["64476.82","0.000048"],["64476.65","0.000016"],["64476.63","0.000063"],["64476.22","0.000071"],["64476.01","0.013239"],["64475","0.020206"],["64474.98","0.000962"],["64474.51","0.000017"],["64474.2","0.000679"],["64473.86","0.000854"],["64473.68","0.00012"],["64473.16","0.001789"],["64471.62","0.000011"],["64471.43","0.000063"],["64471.19","0.00002"],["64471.01","0.00005"],["64470.59","0.000012"],["64470","0.02011"],["64469.71","0.000015"],["64469.56","0.001551"],["64469.29","0.000158"],["64469.23","0.000022"],["64469.18","0.000189"],["64469.11","0.000062"],["64468.78","0.000016"],["64468.75","0.000145"],["64468.17","0.000067"],["64468.15","0.000019"],["64468","0.000016"],["64466.89","0.000039"],["64466.88","0.000018"],["64466.77","0.000083"],["64466.67","0.001275"],["64466.63","0.000032"],["64465.99","0.000011"],["64465.65","0.000196"],["64465.22","0.000044"],["64465","0.020078"],["64464.8","0.000013"],["64464.79","0.000084"],["64463.96","0.000015"],["64463.64","0.000056"],["64461.54","0.000046"],["64460.59","0.001723"],["64460.17","0.00007"],["64460","0.051388"],["64459.46","0.000029"],["64459.29","0.000032"],["64459.25","0.000016"],["64459.21","0.001785"],["64459.15","0.000295"],["64458.98","0.000111"],["64458.62","0.000024"],["64458.3","0.000013"],["64457.84","0.000033"],["64457.82","0.000066"],["64457.67","2.697292"],["64456.9","0.000193"],["64456.11","0.00001"],["64456.08","0.000011"],["64455.75","0.000186"],["64455.04","0.002469"],["64455","0.02"],["64454.98","0.000072"],["64454.96","0.000011"],["64454.89","0.000057"],["64454.55","0.000273"],["64454.29","0.000069"],["64454.15","0.000016"],["64454.14","0.000314"],["64453.73","0.000011"],["64453.52","0.001115"],["64451.87","0.002059"],["64451.79","0.006002"],["64451.61","0.000013"],["64451.43","0.000023"],["64451.31","0.000425"],["64450.58","0.000033"],["64450.08","0.000028"],["64450","0.020278"],["64449.66","0.000111"],["64449.11","0.000012"],["64448.59","0.000014"],["64447.5","0.000013"],["64447.2","0.000155"],["64446.76","0.000145"],["64445.83","0.002051"],["64445.7","0.000744"],["64445.3","0.000056"],["64445","0.02"],["64444.6","0.000093"],["64444.44","0.002666"],["64443.77","0.000041"],["64443.4","0.000015"],["64443.38","0.000038"],["64443.12","0.001175"],["64442.92","0.000022"],["64442.55","0.00004"],["64442.15","0.002966"],["64441.86","0.000017"],["64441.73","0.00009"],["64441.03","0.000013"],["64440.7","0.000013"],["64440.55","0.000055"],["64440.07","0.000015"],["64440","0.02046"],["64439.76","0.00032"],["64439.54","0.000046"],["64439.1","0.00313"],["64438.15","0.000012"],["64438.14","0.000129"],["64437.9","0.000069"],["64437.51","0.000011"],["64437.5","0.000042"],["64437.03","0.000484"],["64436.62","0.000027"],["64436.57","0.000086"],["64436.56","0.000039"],["64436.1","0.001551"],["64435.82","0.000044"],["64435","0.02"],["64434.94","0.000011"],["64434.29","0.000021"],["64434.14","0.002671"],["64433.96","0.00004"],["64433.55","0.000743"],["64433.33","0.000049"],["64432.36","0.000013"],["64432.05","0.000028"],["64431.82","0.000056"],["64431.5","0.000531"],["64431.13","0.000048"],["64430.77","0.000131"],["64430.3","0.000013"],["64430","0.02004"],["64429.9","0.000012"],["64428.57","0.000864"],["64427.98","0.000012"],["64426.72","0.000014"],["64426.2","0.000077"],["64425.93","0.000024"],["64425.82","0.000052"],["64425","0.020236"],["64424.01","0.000008"],["64423.79","0.00001"],["64423.6","0.000015"],["64423.53","0.000019"],["64422.68","0.011176"],["64422.04","0.00031"],["64422.03","0.000118"],["64421.77","0.000036"],["64421.06","0.000012"],["64420.98","0.000009"],["64420.92","2.516083"],["64420.13","0.000186"],["64420","0.020102"],["64419.3","0.000156"],["64418.97","0.002351"],["64418.6","0.000015"],["64418.54","0.000012"],["64418.23","0.000022"],["64417.65","0.000041"],["64417.11","0.000137"],["64416.77","0.000388"],["64416.67","0.000706"],["64416.21","0.000031"],["64415.73","0.000035"],["64415.38","0.000029"],["64415.26","0.000172"]],"ts":"1784090298000","seq":656732050477,"pseq":0}],"ts":1784090298047}
{"action":"snapshot","arg":{"instType":"SPOT","channel":"trade","instId":"BTCUSDT"},"data":[{"ts":"1784090297231","price":"64820","size":"0.0038","side":"buy","tradeId":"1461146098040815616"},{"ts":"1784090297228","price":"64820","size":"0.0012","side":"buy","tradeId":"1461146098028232704"},{"ts":"1784090297217","price":"64817.05","size":"0.001501","side":"buy","tradeId":"1461146097982095372"},{"ts":"1784090297217","price":"64817.05","size":"0.001501","side":"buy","tradeId":"1461146097982095370"},{"ts":"1784090297217","price":"64817.05","size":"0.001501","side":"buy","tradeId":"1461146097982095368"},{"ts":"1784090297217","price":"64817.05","size":"0.001501","side":"buy","tradeId":"1461146097982095366"},{"ts":"1784090297217","price":"64817.05","size":"0.001501","side":"buy","tradeId":"1461146097982095364"},{"ts":"1784090297217","price":"64817.05","size":"0.001501","side":"buy","tradeId":"1461146097982095362"},{"ts":"1784090297217","price":"64817.05","size":"0.000434","side":"buy","tradeId":"1461146097982095360"},{"ts":"1784090293272","price":"64817.05","size":"0.000257","side":"buy","tradeId":"1461146081435566080"},{"ts":"1784090291011","price":"64817.05","size":"0.000019","side":"buy","tradeId":"1461146071952244736"},{"ts":"1784090289813","price":"64816.61","size":"0.000322","side":"buy","tradeId":"1461146066927468544"},{"ts":"1784090289810","price":"64815","size":"0.000006","side":"buy","tradeId":"1461146066914885632"},{"ts":"1784090289809","price":"64815","size":"0.001495","side":"buy","tradeId":"1461146066910691334"},{"ts":"1784090289809","price":"64815","size":"0.001501","side":"buy","tradeId":"1461146066910691332"},{"ts":"1784090289809","price":"64815","size":"0.001501","side":"buy","tradeId":"1461146066910691330"},{"ts":"1784090289809","price":"64815","size":"0.014903","side":"buy","tradeId":"1461146066910691328"},{"ts":"1784090289674","price":"64815","size":"0.00004","side":"buy","tradeId":"1461146066344460292"},{"ts":"1784090289674","price":"64814.99","size":"0.01","side":"buy","tradeId":"1461146066344460290"},{"ts":"1784090289674","price":"64814.64","size":"0.15036","side":"buy","tradeId":"1461146066344460288"},{"ts":"1784090289641","price":"64814.64","size":"0.0031","side":"buy","tradeId":"1461146066206048256"},{"ts":"1784090289637","price":"64814.64","size":"0.000826","side":"buy","tradeId":"1461146066189271042"},{"ts":"1784090289637","price":"64814.64","size":"0.001074","side":"buy","tradeId":"1461146066189271040"},{"ts":"1784090289626","price":"64814.64","size":"0.000019","side":"buy","tradeId":"1461146066143133696"},{"ts":"1784090289495","price":"64814.63","size":"0.00288","side":"sell","tradeId":"1461146065593679872"},{"ts":"1784090287025","price":"64807.71","size":"0.005","side":"buy","tradeId":"1461146055233748992"},{"ts":"1784090287002","price":"64804.78","size":"0.001737","side":"buy","tradeId":"1461146055137280018"},{"ts":"1784090287002","price":"64804.78","size":"0.001501","side":"buy","tradeId":"1461146055137280016"},{"ts":"1784090287002","price":"64804.78","size":"0.001501","side":"buy","tradeId":"1461146055137280014"},{"ts":"1784090287002","price":"64804.78","size":"0.001501","side":"buy","tradeId":"1461146055137280012"},{"ts":"1784090287002","price":"64804.78","size":"0.001501","side":"buy","tradeId":"1461146055137280010"},{"ts":"1784090287002","price":"64804.78","size":"0.001501","side":"buy","tradeId":"1461146055137280008"},{"ts":"1784090287002","price":"64804.78","size":"0.001501","side":"buy","tradeId":"1461146055137280006"},{"ts":"1784090287002","price":"64804.78","size":"0.001501","side":"buy","tradeId":"1461146055137280004"},{"ts":"1784090287002","price":"64804.78","size":"0.116855","side":"buy","tradeId":"1461146055137280002"},{"ts":"1784090287002","price":"64804.78","size":"0.0154","side":"buy","tradeId":"1461146055137280000"},{"ts":"1784090283493","price":"64804.77","size":"0.003527","side":"sell","tradeId":"1461146040419467264"},{"ts":"1784090281466","price":"64804.78","size":"0.00021","side":"buy","tradeId":"1461146031917613056"},{"ts":"1784090274656","price":"64804.78","size":"0.005","side":"buy","tradeId":"1461146003354402816"},{"ts":"1784090270055","price":"64804.78","size":"0.005","side":"buy","tradeId":"1461145984056410112"},{"ts":"1784090259061","price":"64804.78","size":"0.000847","side":"buy","tradeId":"1461145937944231936"},{"ts":"1784090253655","price":"64804.77","size":"0.00732","side":"sell","tradeId":"1461145915269824512"},{"ts":"1784090252558","price":"64804.78","size":"0.000046","side":"buy","tradeId":"1461145910668673024"},{"ts":"1784090248792","price":"64804.78","size":"0.000027","side":"buy","tradeId":"1461145894872924160"},{"ts":"1784090245709","price":"64804.78","size":"0.002625","side":"buy","tradeId":"1461145881941884928"},{"ts":"1784090242484","price":"64804.78","size":"0.005","side":"buy","tradeId":"1461145868415254528"},{"ts":"1784090242095","price":"64804.77","size":"0.000604","side":"sell","tradeId":"1461145866783670272"},{"ts":"1784090240707","price":"64804.78","size":"0.000019","side":"buy","tradeId":"1461145860961976320"},{"ts":"1784090240126","price":"64804.78","size":"0.00328","side":"buy","tradeId":"1461145858525085698"},{"ts":"1784090240126","price":"64804.78","size":"0.00172","side":"buy","tradeId":"1461145858525085696"}],"ts":1784090298047}
{"action":"update","arg":{"instType":"SPOT","channel":"books","instId":"BTCUSDT"},"data":[{"asks":[["64820","0.026623"],["64825.93","0.309116"],["64830.01","0.335355"],["64830.69","0"],["64839.99","0"],["64842.02","0.030877"]],"bids":[],"ts":"1784090298110","seq":656732052891,"pseq":656732050477}],"ts":1784090298114}
{"action":"update","arg":{"instType":"SPOT","channel":"books","instId":"BTCUSDT"},"data":[{"asks":[],"bids":[["64819.99","3.465118"]],"ts":"1784090298207","seq":656732055036,"pseq":656732052891}],"ts":1784090298211}
{"action":"update","arg":{"instType":"SPOT","channel":"books","instId":"BTCUSDT"},"data":[{"asks":[["64827.46","0.004316"],["64828.25","0"],["64831.42","0"],["65071.49","0.000008"]],"bids":[],"ts":"1784090298304","seq":656732056875,"pseq":656732055036}],"ts":1784090298306}
{"action":"update","arg":{"instType":"SPOT","channel":"books","instId":"BTCUSDT"},"data":[{"asks":[["64825.91","0.26"],["64825.92","0.196395"],["64825.94","0"],["64825.95","0"],["64828.24","0"],["64830.11","0.007069"]],"bids":[],"ts":"1784090298400","seq":656732058179,"pseq":656732056875}],"ts":1784090298402}
{"action":"update","arg":{"instType":"SPOT","channel":"books","instId":"BTCUSDT"},"data":[{"asks":[["64824.98","0.086833"],["64825.92","0.119426"]],"bids":[["64819.99","3.459297"]],"ts":"1784090298526","seq":656732059684,"pseq":656732058179}],"ts":1784090298530}
{"action":"update","arg":{"instType":"SPOT","channel":"books","instId":"BTCUSDT"},"data":[{"asks":[],"bids":[["64819.99","3.464992"]],"ts":"1784090298627","seq":656732061444,"pseq":656732059684}],"ts":1784090298630}
{"action":"update","arg":{"instType":"SPOT","channel":"books","instId":"BTCUSDT"},"data":[{"asks":[["64846.06","0"],["64865.51","0"],["65072.16","0.011176"],["65072.4","0.001256"]],"bids":[["64806.54","0"],["64787.1","0"],["64415","0.02"],["64414.81","0.000015"]],"ts":"1784090298706","seq":656732062881,"pseq":656732061444}],"ts":1784090298708}
{"action":"update","arg":{"instType":"SPOT","channel":"trade","instId":"BTCUSDT"},"data":[{"ts":"1784090298774","price":"64820","size":"0.005","side":"buy","tradeId":"1461146104512626688"}],"ts":1784090298776}
{"action":"update","arg":{"instType":"SPOT","channel":"books","instId":"BTCUSDT"},"data":[{"asks":[["64820","0.011116"],["64825.92","0.027155"],["64825.93","0"],["64827.46","0"],["64828.65","0.005881"],["64829.98","0.741877"],["64829.99","0"],["64830.01","0.309116"],["64830.48","0.026238"],["64847.24","0.187171"],["64866.69","0.378879"],["64947.9","0"],["64972.22","0.071442"]],"bids":[["64819.99","3.464991"],["64806.64","0.189169"],["64787.2","0.371492"],["64415","0"],["64414.81","0"]],"ts":"1784090298817","seq":656732067372,"pseq":656732062881}],"ts":1784090298820}
{"action":"update","arg":{"instType":"SPOT","channel":"books","instId":"BTCUSDT"},"data":[{"asks":[["64820","0.01712"],["64824.97","0"],["64824.98","0"],["64824.99","0.01692"],["64825.9","0"],["64825.91","0"],["64829.96","0.546034"],["64829.97","0.741877"],["64829.98","0"],["64830","0.013117"],["64845.56","0.120555"],["64846.12","0"],["65072.73","0.000019"]],"bids":[["64819.99","3.511294"],["64817.05","0"],["64817.04","1.050993"],["64815.02","0"],["64815","0"],["64813.9","0.030876"],["64813.89","0"],["64811.91","0"],["64809.69","0"],["64415","0.02"],["64414.81","0.000015"],["64414.8","0.00003"]],"ts":"1784090298900","seq":656732070359,"pseq":656732067372}],"ts":1784090298902}
{"action":"update","arg":{"instType":"SPOT","channel":"books","instId":"BTCUSDT"},"data":[{"asks":[["64827.58","0.005881"],["64828.65","0"]],"bids":[["64817.05","0.316028"],["64815.04","0.39711"],["64414.81","0"],["64414.8","0"]],"ts":"1784090299024","seq":656732073199,"pseq":656732070359}],"ts":1784090299028}
{"action":"update","arg":{"instType":"SPOT","channel":"books","instId":"BTCUSDT"},"data":[{"asks":[],"bids":[["64811.75","0.227765"],["64415","0"]],"ts":"1784090299107","seq":656732075296,"pseq":656732073199}],"ts":1784090299110}
{"action":"update","arg":{"instType":"SPOT","channel":"books","instId":"BTCUSDT"},"data":[{"asks":[["64820","0.021623"],["64824.99","0"],["64829.96","0"],["64829.97","0"],["64830","0.337701"],["64916.12","0"],["64916.58","0.000667"],["65072.77","0.000143"],["65072.85","0.000048"],["65072.99","0.000027"]],"bids":[["64819.99","3.511294"],["64729.78","0.000667"],["64716.4","0"]],"ts":"1784090299204","seq":656732078347,"pseq":656732075296}],"ts":1784090299206}
{"action":"update","arg":{"instType":"SPOT","channel":"books","instId":"BTCUSDT"},"data":[{"asks":[["64825.28","0.015426"],["64828.07","0.26"],["64837.78","0"],["64842.03","0"],["64845.28","0"],["64845.56","0"],["65073","0.007112"],["65073.13","0.000011"]],"bids":[["64819.99","3.511295"]],"ts":"1784090299304","seq":656732081173,"pseq":656732078347}],"ts":1784090299307}
{"action":"update","arg":{"instType":"SPOT","channel":"books","instId":"BTCUSDT"},"data":[{"asks":[["64825.92","0.10176"],["64835.58","0.050749"],["64837.78","0.470063"],["65073.13","0"]],"bids":[],"ts":"1784090299403","seq":656732083567,"pseq":656732081173}],"ts":1784090299406}
{"action":"update","arg":{"instType":"SPOT","channel":"books","instId":"BTCUSDT"},"data":[{"asks":[["64830.48","0"],["64831.28","0.026238"],["64842.03","0.22145"],["64845.28","0.22145"],["64845.55","0.156867"],["64845.56","0"],["65072.85","0"],["65072.99","0"],["65073","0"]],"bids":[["64819.99","3.510595"]],"ts":"1784090299507","seq":656732085851,"pseq":656732083567}],"ts":1784090299510}
{"action":"update","arg":{"instType":"SPOT","channel":"books","instId":"BTCUSDT"},"data":[{"asks":[],"bids":[["64819.99","3.511295"]],"ts":"1784090299606","seq":656732087861,"pseq":656732085851}],"ts":1784090299608}
{"action":"update","arg":{"instType":"SPOT","channel":"books","instId":"BTCUSDT"},"data":[{"asks":[["64825.92","0"],["64828.06","0.10228"],["64854.22","0"],["64854.51","0"],["64865.57","0.483429"],["64871.07","0.626668"],["64934.32","0.071415"],["64944.05","0.071415"],["64967.37","0"],["64972.22","0.000027"],["65072.77","0"]],"bids":[],"ts":"1784090299703","seq":656732090364,"pseq":656732087861}],"ts":1784090299706}
{"action":"update","arg":{"instType":"SPOT","channel":"books","instId":"BTCUSDT"},"data":[{"asks":[],"bids":[["64819.99","3.510595"]],"ts":"1784090299805","seq":656732092251,"pseq":656732090364}],"ts":1784090299808}
{"action":"update","arg":{"instType":"SPOT","channel":"books","instId":"BTCUSDT"},"data":[{"asks":[["64824.99","0.01692"],["64825.28","0"],["64830.47","0"],["64835.07","0"],["64835.5","0.046303"],["64843.3","0.077173"],["64843.58","0"],["64845.36","0.015466"],["64849.19","0.001542"],["64849.32","0"],["64859.31","0.154346"],["64874.83","0.154346"],["64881.01","0.034356"],["65072.16","0"],["65072.4","0"],["65072.73","0"]],"bids":[["64819.99","3.511295"],["64803.87","0.154346"],["64803.48","0"],["64801.46","0.003086"],["64799.59","0"],["64788.36","0.154346"],["64787.9","0"]],"ts":"1784090299903","seq":656732094904,"pseq":656732092251}],"ts":1784090299906}
{"action":"update","arg":{"instType":"SPOT","channel":"books","instId":"BTCUSDT"},"data":[{"asks":[["64828.17","0.001542"],["64829.99","0.741877"],["64842.1","0.071415"],["64851.82","0.071415"],["64861.54","0.071415"],["64904.55","0.023805"],["64934.32","0"],["64944.05","0"],["64957.63","0"],["64961.8","0"],["64971.54","0"],["65070.94","0"],["65071.14","0"],["65071.49","0"]],"bids":[],"ts":"1784090300006","seq":656732097311,"pseq":656732094904}],"ts":1784090300010}
{"action":"update","arg":{"instType":"SPOT","channel":"books","instId":"BTCUSDT"},"data":[{"asks":[["64829.92","0.026239"],["64829.98","0"],["64830","0.013117"],["64831.28","0"],["64837.78","0"],["64842.03","0"],["64845.28","0"],["64845.55","0"],["65070.94","0.1593"],["65071.14","0.000056"],["65071.49","0.000008"],["65072.16","0.011176"]],"bids":[["64819.99","3.510595"]],"ts":"1784090300104","seq":656732099073,"pseq":656732097311}],"ts":1784090300108}
{"action":"update","arg":{"instType":"SPOT","channel":"books","instId":"BTCUSDT"},"data":[{"asks":[["64829.98","0.541658"],["64837.78","0.470063"],["64842.03","0.242768"],["64845.28","0.139405"],["65070.94","0"],["65071.14","0"],["65071.49","0"],["65072.16","0"]],"bids":[["64819.99","3.511295"]],"ts":"1784090300202","seq":656732100903,"pseq":656732099073}],"ts":1784090300204}
{"action":"update","arg":{"instType":"SPOT","channel":"books","instId":"BTCUSDT"},"data":[{"asks":[["64842.1","0"],["64849.11","0.001542"],["64849.12","0"],["64851.82","0"],["64861.54","0"],["64904.55","0"],["64965.97","0.071415"],["64975.71","0.071415"],["65070.94","0.1593"],["65071.14","0.000056"]],"bids":[["64819.99","3.511296"]],"ts":"1784090300310","seq":656732103059,"pseq":656732100903}],"ts":1784090300312}
{"action":"update","arg":{"instType":"SPOT","channel":"books","instId":"BTCUSDT"},"data":[{"asks":[["64829.98","0"],["64829.99","0"],["64830","0.329409"],["65071.49","0.000008"],["65072.16","0.011176"]],"bids":[],"ts":"1784090300408","seq":656732105160,"pseq":656732103059}],"ts":1784090300410}
{"action":"update","arg":{"instType":"SPOT","channel":"books","instId":"BTCUSDT"},"data":[{"asks":[],"bids":[["64819.99","3.521296"]],"ts":"1784090300520","seq":656732107811,"pseq":656732105160}],"ts":1784090300522}
{"action":"update","arg":{"instType":"SPOT","channel":"books","instId":"BTCUSDT"},"data":[{"asks":[],"bids":[["64819.99","3.520596"]],"ts":"1784090300669","seq":656732111440,"pseq":656732107811}],"ts":1784090300672}
{"action":"update","arg":{"instType":"SPOT","channel":"books","instId":"BTCUSDT"},"data":[{"asks":[["64956.24","0.071415"],["65072.16","0"]],"bids":[["64816.7","0"],["64788.8","0"],["64760.9","0"],["64733","0"],["64705.1","0"],["64415","0.02"],["64414.81","0.000015"],["64414.8","0.00003"],["64414.63","0.000779"],["64414.41","0.000326"]],"ts":"1784090300700","seq":656732112316,"pseq":656732111440}],"ts":1784090300702}
{"action":"update","arg":{"instType":"SPOT","channel":"books","instId":"BTCUSDT"},"data":[{"asks":[["64820","0.01"],["64827.8","0"],["64829.92","0"],["64830.72","0.026238"],["64842.1","0.071415"],["64850.39","0.483418"],["64851.82","0.071415"],["64861.54","0.071415"],["64865.56","0.225366"],["64865.57","0"],["64884.8","0"],["64885.81","0"],["64888.15","1.873743"],["64904.55","0.023805"],["64907.87","0"],["64910.2","1.391318"],["64941.8","0"],["64943.08","0"],["64956.24","0"],["64965.97","0"],["64975.71","0"],["64998.8","0"],["65022.8","0"],["65055.8","0"],["65072.16","0.011176"],["65072.4","0.001256"],["65072.73","0.000019"],["65072.77","0.000143"]],"bids":[["64819.99","3.458874"]],"ts":"1784090300811","seq":656732115853,"pseq":656732112316}],"ts":1784090300814}
{"action":"update","arg":{"instType":"SPOT","channel":"books","instId":"BTCUSDT"},"data":[{"asks":[["64820","0.020507"],["64845.56","0.225366"],["64861.56","0.011713"],["64865.56","0"],["65072.77","0"]],"bids":[["64819.99","3.52128"]],"ts":"1784090300907","seq":656732119064,"pseq":656732115853}],"ts":1784090300910}
{"action":"update","arg":{"instType":"SPOT","channel":"books","instId":"BTCUSDT"},"data":[{"asks":[["64820","0.021623"],["64827.8","0.002145"],["64884.8","0.002143"],["64941.8","0.002141"],["64998.8","0.002139"],["65022.8","0.000492"],["65055.8","0.002137"],["65070.94","0"],["65071.14","0"],["65071.49","0"],["65072.16","0"],["65072.4","0"],["65072.73","0"]],"bids":[["64819.99","3.52128"],["64816.7","0.002145"],["64788.8","0.002146"],["64760.9","0.002147"],["64733","0.002148"],["64705.1","0.002149"],["64415","0"],["64414.81","0"],["64414.8","0"],["64414.63","0"],["64414.41","0"]],"ts":"1784090301007","seq":656732120290,"pseq":656732119064}],"ts":1784090301010}
{"action":"update","arg":{"instType":"SPOT","channel":"books","instId":"BTCUSDT"},"data":[{"asks":[["64842.1","0"],["64851.82","0"],["64861.54","0"],["64904.55","0"],["64944.05","0.071415"],["64953.78","0.071415"],["65070.94","0.1593"],["65071.14","0.000056"]],"bids":[["64819.99","3.675553"]],"ts":"1784090301101","seq":656732121193,"pseq":656732120290}],"ts":1784090301104}
{"action":"update","arg":{"instType":"SPOT","channel":"books","instId":"BTCUSDT"},"data":[{"asks":[],"bids":[["64819.99","3.674853"]],"ts":"1784090301223","seq":656732123214,"pseq":656732121193}],"ts":1784090301226}
{"action":"update","arg":{"instType":"SPOT","channel":"books","instId":"BTCUSDT"},"data":[{"asks":[],"bids":[["64819.99","3.598381"],["64819.5","0.077173"],["64815.05","0.309764"],["64815.03","0"],["64606.44","0"]],"ts":"1784090301300","seq":656732124579,"pseq":656732123214}],"ts":1784090301304}
{"action":"update","arg":{"instType":"SPOT","channel":"books","instId":"BTCUSDT"},"data":[{"asks":[["64843.11","0.071415"],["64850.39","0"],["64852.83","0.071415"],["64860.71","0.483412"],["64862.55","0.071415"],["64905.56","0.023805"],["64944.05","0"],["64953.78","0"],["65070.94","0"],["65071.14","0"]],"bids":[],"ts":"1784090301406","seq":656732126840,"pseq":656732124579}],"ts":1784090301408}
{"action":"update","arg":{"instType":"SPOT","channel":"books","instId":"BTCUSDT"},"data":[{"asks":[["64820","0.020507"]],"bids":[],"ts":"1784090301501","seq":656732128407,"pseq":656732126840}],"ts":1784090301504}
{"action":"update","arg":{"instType":"SPOT","channel":"books","instId":"BTCUSDT"},"data":[{"asks":[["64820","0.021623"],["64846.28","0.015063"],["65070.74","0"]],"bids":[],"ts":"1784090301600","seq":656732130066,"pseq":656732128407}],"ts":1784090301602}
{"action":"update","arg":{"instType":"SPOT","channel":"books","instId":"BTCUSDT"},"data":[{"asks":[["64820","0.020507"],["64829.96","0.026239"],["64830.72","0"]],"bids":[],"ts":"1784090301706","seq":656732131830,"pseq":656732130066}],"ts":1784090301710}
{"action":"update","arg":{"instType":"SPOT","channel":"books","instId":"BTCUSDT"},"data":[{"asks":[["64820","0.021623"]],"bids":[],"ts":"1784090301807","seq":656732133681,"pseq":656732131830}],"ts":1784090301810}
{"action":"update","arg":{"instType":"SPOT","channel":"books","instId":"BTCUSDT"},"data":[{"asks":[["64835.5","0"],["64835.6","0.046303"],["64843.3","0"],["64843.36","0.077173"],["64845.28","0.208244"],["64859.14","0.154346"],["64859.31","0"],["64874.83","0"],["65070.74","0.000051"]],"bids":[["64819.99","3.59838"],["64804.44","0.154346"],["64803.87","0"],["64788.97","0.154346"],["64788.36","0"]],"ts":"1784090301904","seq":656732135563,"pseq":656732133681}],"ts":1784090301908}
{"action":"update","arg":{"instType":"SPOT","channel":"books","instId":"BTCUSDT"},"data":[{"asks":[],"bids":[["64819.99","3.59768"]],"ts":"1784090302044","seq":656732138826,"pseq":656732135563}],"ts":1784090302046}
{"action":"update","arg":{"instType":"SPOT","channel":"books","instId":"BTCUSDT"},"data":[{"asks":[["64829.94","0"],["64829.95","0.741877"],["64830","0.013117"],["65070.74","0"]],"bids":[["64819.99","3.59838"]],"ts":"1784090302105","seq":656732140162,"pseq":656732138826}],"ts":1784090302108}
{"action":"update","arg":{"instType":"SPOT","channel":"books","instId":"BTCUSDT"},"data":[{"asks":[["64820","0.020507"],["64829.94","0.402365"],["64835.58","0.035"],["64843.11","0"],["64845.56","0"],["64846.28","0"],["64852.83","0"],["64862.55","0"],["64905.56","0"],["64958.31","0.071415"],["64968.05","0.071415"],["65070.74","0.000051"],["65070.94","0.1593"],["65071.14","0.000056"]],"bids":[],"ts":"1784090302209","seq":656732142167,"pseq":656732140162}],"ts":1784090302212}
{"action":"update","arg":{"instType":"SPOT","channel":"books","instId":"BTCUSDT"},"data":[{"asks":[["64829.95","0"],["64921.79","0.047551"],["64975.71","0.071415"],["65071.14","0"]],"bids":[],"ts":"1784090302306","seq":656732143882,"pseq":656732142167}],"ts":1784090302308}
{"action":"update","arg":{"instType":"SPOT","channel":"books","instId":"BTCUSDT"},"data":[{"asks":[["64820","0.021623"],["64939.69","0.022683"],["65070.94","0"]],"bids":[],"ts":"1784090302403","seq":656732145547,"pseq":656732143882}],"ts":1784090302406}
{"action":"update","arg":{"instType":"SPOT","channel":"books","instId":"BTCUSDT"},"data":[{"asks":[["64829.96","0"],["64830.12","0.026239"]],"bids":[["64819.99","3.598381"]],"ts":"1784090302535","seq":656732148173,"pseq":656732145547}],"ts":1784090302538}
{"action":"update","arg":{"instType":"SPOT","channel":"books","instId":"BTCUSDT"},"data":[{"asks":[],"bids":[["64819.99","3.597681"]],"ts":"1784090302743","seq":656732151923,"pseq":656732148173}],"ts":1784090302746}
{"action":"update","arg":{"instType":"SPOT","channel":"books","instId":"BTCUSDT"},"data":[{"asks":[["64829.93","0.741877"],["65070.74","0"]],"bids":[],"ts":"1784090302776","seq":656732153341,"pseq":656732151923}],"ts":1784090302802}
{"action":"update","arg":{"instType":"SPOT","channel":"books","instId":"BTCUSDT"},"data":[{"asks":[],"bids":[["64819.99","3.598381"]],"ts":"1784090302801","seq":656732154045,"pseq":656732153341}],"ts":1784090302804}
{"action":"update","arg":{"instType":"SPOT","channel":"books","instId":"BTCUSDT"},"data":[{"asks":[["64845.56","0.070234"],["65070.42","0"]],"bids":[["64819.99","3.598381"]],"ts":"1784090302887","seq":656732156168,"pseq":656732154045}],"ts":1784090302903}
{"action":"update","arg":{"instType":"SPOT","channel":"books","instId":"BTCUSDT"},"data":[{"asks":[],"bids":[["64702.61","0"],["64415","0.02"]],"ts":"1784090302928","seq":656732157070,"pseq":656732156168}],"ts":1784090302930}
{"action":"update","arg":{"instType":"SPOT","channel":"books","instId":"BTCUSDT"},"data":[{"asks":[],"bids":[["64720.3","0.016206"],["64415","0"]],"ts":"1784090302984","seq":656732158324,"pseq":656732157070}],"ts":1784090303005}
{"action":"update","arg":{"instType":"SPOT","channel":"books","instId":"BTCUSDT"},"data":[{"asks":[],"bids":[["64819.99","3.597681"]],"ts":"1784090303153","seq":656732162882,"pseq":656732158324}],"ts":1784090303156}
{"action":"update","arg":{"instType":"SPOT","channel":"books","instId":"BTCUSDT"},"data":[{"asks":[["64827.58","0"],["64828.6","0.003996"],["64829.93","0"],["65070.42","0.000027"]],"bids":[["64819.99","3.598381"]],"ts":"1784090303193","seq":656732163725,"pseq":656732162882}],"ts":1784090303208}
{"action":"update","arg":{"instType":"SPOT","channel":"trade","instId":"BTCUSDT"},"data":[{"ts":"1784090303243","price":"64820","size":"0.005","side":"buy","tradeId":"1461146123256971264"}],"ts":1784090303244}
{"action":"update","arg":{"instType":"SPOT","channel":"books","instId":"BTCUSDT"},"data":[{"asks":[["64820","0.016623"]],"bids":[],"ts":"1784090303243","seq":656732164825,"pseq":656732163725}],"ts":1784090303246}
{"action":"update","arg":{"instType":"SPOT","channel":"books","instId":"BTCUSDT"},"data":[{"asks":[["64830.1","0.026239"],["64830.12","0"]],"bids":[["64819.99","3.598381"],["64819.86","0.077173"],["64819.5","0"]],"ts":"1784090303313","seq":656732166385,"pseq":656732164825}],"ts":1784090303316}
{"action":"update","arg":{"instType":"SPOT","channel":"books","instId":"BTCUSDT"},"data":[{"asks":[],"bids":[["64819.99","3.597681"]],"ts":"1784090303526","seq":656732170720,"pseq":656732166385}],"ts":1784090303530}
{"action":"update","arg":{"instType":"SPOT","channel":"books","instId":"BTCUSDT"},"data":[{"asks":[["64827.85","0.004631"],["64828.6","0"]],"bids":[["64819.99","3.598381"]],"ts":"1784090303607","seq":656732172022,"pseq":656732170720}],"ts":1784090303611}
{"action":"update","arg":{"instType":"SPOT","channel":"books","instId":"BTCUSDT"},"data":[{"asks":[],"bids":[["64819.99","3.597681"]],"ts":"1784090303831","seq":656732175819,"pseq":656732172022}],"ts":1784090303834}
{"action":"update","arg":{"instType":"SPOT","channel":"books","instId":"BTCUSDT"},"data":[{"asks":[["64835.6","0"],["64842.35","0.077174"],["64843.36","0"],["64859.14","0"],["65070.74","0.000051"],["65070.94","0.1593"]],"bids":[["64804.44","0"],["64788.97","0"],["64788.53","0.154348"],["64415","0.02"]],"ts":"1784090303926","seq":656732177832,"pseq":656732175819}],"ts":1784090303928}
{"action":"update","arg":{"instType":"SPOT","channel":"books","instId":"BTCUSDT"},"data":[{"asks":[["64827.8","0"],["64884.8","0"],["64941.8","0"],["64998.8","0"],["65055.8","0"],["65071.14","0.000056"],["65071.49","0.000008"],["65072.16","0.011176"],["65072.4","0.001256"],["65072.73","0.000019"]],"bids":[["64788.8","0"],["64760.9","0"],["64733","0"],["64705.1","0"],["64414.81","0.000015"],["64414.8","0.00003"],["64414.63","0.000779"],["64414.41","0.000326"]],"ts":"1784090304036","seq":656732179732,"pseq":656732177832}],"ts":1784090304038}
{"action":"update","arg":{"instType":"SPOT","channel":"books","instId":"BTCUSDT"},"data":[{"asks":[["64829.68","0.026239"],["64830.1","0"],["64835.65","0.015808"],["65072.73","0"]],"bids":[["64819.99","3.597681"],["64816.7","0"],["64414.32","0.000039"]],"ts":"1784090304106","seq":656732181542,"pseq":656732179732}],"ts":1784090304108}
{"action":"update","arg":{"instType":"SPOT","channel":"books","instId":"BTCUSDT"},"data":[{"asks":[["64827.85","0"],["65072.73","0.000019"]],"bids":[],"ts":"1784090304309","seq":656732185911,"pseq":656732181542}],"ts":1784090304312}
{"action":"update","arg":{"instType":"SPOT","channel":"books","instId":"BTCUSDT"},"data":[{"asks":[["64827.1","0.004245"],["64827.8","0.002145"],["64884.8","0.002143"],["64941.8","0.002141"],["64998.8","0.002139"],["65055.8","0.002137"],["65070.94","0"],["65071.14","0"],["65071.49","0"],["65072.16","0"],["65072.4","0"],["65072.73","0"]],"bids":[["64816.7","0.002145"],["64788.8","0.002146"],["64760.9","0.002147"],["64733","0.002148"],["64705.1","0.002149"],["64414.81","0"],["64414.8","0"],["64414.63","0"],["64414.41","0"],["64414.32","0"]],"ts":"1784090304424","seq":656732188097,"pseq":656732185911}],"ts":1784090304426}
{"action":"update","arg":{"instType":"SPOT","channel":"books","instId":"BTCUSDT"},"data":[{"asks":[["64847.24","0"],["64866.69","0"],["65070.94","0.1593"],["65071.14","0.000056"]],"bids":[["64806.64","0"],["64787.2","0"],["64414.81","0.000015"],["64414.8","0.00003"]],"ts":"1784090304591","seq":656732190801,"pseq":656732188097}],"ts":1784090304594}
{"action":"update","arg":{"instType":"SPOT","channel":"books","instId":"BTCUSDT"},"data":[{"asks":[["64829.93","0.741877"],["65071.14","0"]],"bids":[],"ts":"1784090304698","seq":656732192308,"pseq":656732190801}],"ts":1784090304700}
{"action":"update","arg":{"instType":"SPOT","channel":"books","instId":"BTCUSDT"},"data":[{"asks":[["64829.93","0"],["65071.14","0.000056"]],"bids":[],"ts":"1784090304702","seq":656732192378,"pseq":656732192308}],"ts":1784090304704}
{"action":"update","arg":{"instType":"SPOT","channel":"books","instId":"BTCUSDT"},"data":[{"asks":[["64829.93","0.741877"],["64835.65","0"],["64845.23","0.179583"],["64864.68","0.353735"],["65070.94","0"],["65071.14","0"]],"bids":[["64807.79","0.180875"],["64788.35","0.363961"],["64414.81","0"],["64414.8","0"]],"ts":"1784090304812","seq":656732194059,"pseq":656732192378}],"ts":1784090304814}
{"action":"update","arg":{"instType":"SPOT","channel":"books","instId":"BTCUSDT"},"data":[{"asks":[["64829.08","0.026239"],["64829.68","0"],["64848.11","0.483405"],["64860.71","0"]],"bids":[["64819.99","3.597681"]],"ts":"1784090304923","seq":656732195231,"pseq":656732194059}],"ts":1784090304926}
{"action":"update","arg":{"instType":"SPOT","channel":"books","instId":"BTCUSDT"},"data":[{"asks":[],"bids":[["64819.99","3.598381"]],"ts":"1784090305006","seq":656732195937,"pseq":656732195231}],"ts":1784090305008}
{"action":"update","arg":{"instType":"SPOT","channel":"trade","instId":"BTCUSDT"},"data":[{"ts":"1784090305056","price":"64820","size":"0.00003","side":"buy","tradeId":"1461146130861244416"}],"ts":1784090305058}
{"action":"update","arg":{"instType":"SPOT","channel":"books","instId":"BTCUSDT"},"data":[{"asks":[["64820","0.016593"],["64829.93","0"],["64936.98","0.071415"],["64946.71","0.071415"],["64968.05","0"],["64975.71","0"],["65070.94","0.1593"]],"bids":[],"ts":"1784090305103","seq":656732197409,"pseq":656732195937}],"ts":1784090305106}
{"action":"update","arg":{"instType":"SPOT","channel":"books","instId":"BTCUSDT"},"data":[{"asks":[["64936.98","0"],["64946.71","0"],["65071.14","0.000056"],["65071.49","0.000008"]],"bids":[],"ts":"1784090305261","seq":656732199649,"pseq":656732197409}],"ts":1784090305264}
{"action":"update","arg":{"instType":"SPOT","channel":"books","instId":"BTCUSDT"},"data":[{"asks":[["64827.1","0"],["64828.08","0.083805"],["64965.97","0.071415"],["64975.71","0.071415"],["65071.49","0"]],"bids":[["64819.86","0"],["64819.49","0.077174"]],"ts":"1784090305306","seq":656732201199,"pseq":656732199649}],"ts":1784090305308}
{"action":"update","arg":{"instType":"SPOT","channel":"books","instId":"BTCUSDT"},"data":[{"asks":[["64846.02","0.071415"],["64855.74","0.071415"],["64865.46","0.071415"],["64908.47","0.023805"],["64958.31","0"],["64965.97","0"],["64975.71","0"],["65071.14","0"]],"bids":[["64819.99","3.597681"]],"ts":"1784090305421","seq":656732203651,"pseq":656732201199}],"ts":1784090305425}
{"action":"update","arg":{"instType":"SPOT","channel":"books","instId":"BTCUSDT"},"data":[{"asks":[["64846.02","0"],["64846.85","0.015524"],["64855.74","0"],["64865.46","0"],["64908.47","0"],["64952.07","0.071415"],["64961.8","0.071415"],["65071.14","0.000056"]],"bids":[["64819.99","3.598381"]],"ts":"1784090305505","seq":656732205418,"pseq":656732203651}],"ts":1784090305508}
{"action":"update","arg":{"instType":"SPOT","channel":"books","instId":"BTCUSDT"},"data":[{"asks":[["64829.93","0"],["64848.11","0"],["64857.26","0.483402"]],"bids":[["64688.82","0.00801"],["64677.29","0"]],"ts":"1784090305601","seq":656732209135,"pseq":656732205418}],"ts":1784090305604}
{"action":"update","arg":{"instType":"SPOT","channel":"books","instId":"BTCUSDT"},"data":[{"asks":[["64829.08","0"],["64829.55","0.026239"]],"bids":[["64819.99","3.598381"]],"ts":"1784090305712","seq":656732211977,"pseq":656732209135}],"ts":1784090305713}
{"action":"update","arg":{"instType":"SPOT","channel":"books","instId":"BTCUSDT"},"data":[{"asks":[["64822.58","0"],["64824.99","0"],["64849.92","0.071415"],["64859.64","0.071415"],["64869.36","0.071415"],["64912.37","0.023805"],["64952.07","0"],["64961.8","0"],["65071.14","0"]],"bids":[["64819.99","3.536676"],["64819.5","0.061705"],["64415","0"]],"ts":"1784090305809","seq":656732214085,"pseq":656732211977}],"ts":1784090305812}
{"action":"update","arg":{"instType":"SPOT","channel":"books","instId":"BTCUSDT"},"data":[{"asks":[["64824.99","0.01692"],["64834.47","0.046304"],["64842.1","0.077174"],["64842.35","0"],["64846.85","0"],["64849.92","0"],["64857.44","0.154348"],["64859.64","0"],["64869.36","0"],["64912.37","0"],["64956.98","0"],["64966.71","0"],["64976.75","0.071415"],["65011.86","0"],["65071.14","0.000056"],["65071.49","0.000008"]],"bids":[["64819.99","3.598381"],["64819.5","0"],["64804.22","0.154348"],["64788.86","0.154348"],["64788.53","0"],["64769","0"],["64768","0"],["64415","0.02"],["64414.81","0.000015"]],"ts":"1784090305911","seq":656732216295,"pseq":656732214085}],"ts":1784090305914}
{"action":"update","arg":{"instType":"SPOT","channel":"trade","instId":"BTCUSDT"},"data":[{"ts":"1784090305994","price":"64820","size":"0.001023","side":"buy","tradeId":"1461146134795501584"},{"ts":"1784090305994","price":"64820","size":"0.001501","side":"buy","tradeId":"1461146134795501582"},{"ts":"1784090305994","price":"64820","size":"0.001501","side":"buy","tradeId":"1461146134795501580"},{"ts":"1784090305994","price":"64820","size":"0.001501","side":"buy","tradeId":"1461146134795501578"},{"ts":"1784090305994","price":"64820","size":"0.001501","side":"buy","tradeId":"1461146134795501576"},{"ts":"1784090305994","price":"64820","size":"0.001501","side":"buy","tradeId":"1461146134795501574"},{"ts":"1784090305994","price":"64820","size":"0.001501","side":"buy","tradeId":"1461146134795501572"},{"ts":"1784090305994","price":"64820","size":"0.001501","side":"buy","tradeId":"1461146134795501570"},{"ts":"1784090305994","price":"64820","size":"0.00497","side":"buy","tradeId":"1461146134795501568"}],"ts":1784090305995}
{"action":"update","arg":{"instType":"SPOT","channel":"trade","instId":"BTCUSDT"},"data":[{"ts":"1784090305995","price":"64820","size":"0.000093","side":"buy","tradeId":"1461146134799695872"}],"ts":1784090305997}
{"action":"update","arg":{"instType":"SPOT","channel":"books","instId":"BTCUSDT"},"data":[{"asks":[["64820","0"],["64822.59","0.007721"],["64826.27","0"],["64827.8","0"],["64828.08","0"],["64829.63","0"],["64829.94","0"],["64830.11","0"],["64831.96","0.011079"],["64832.28","0"],["64836.49","0"],["64845.36","0"],["64848.7","0"],["64861.56","0"],["64881.01","0"],["64884.8","0"],["64941.8","0"],["64951.41","0.071415"],["64961.14","0.071415"],["64986.49","0"],["64996.23","0"],["64998.8","0"],["65055.8","0"],["65069.57","2.48671"],["65072.16","0.011176"],["65072.4","0.001256"],["65072.73","0.000019"],["65072.77","0.000143"],["65072.85","0.000048"],["65072.99","0.000027"],["65073","0.007112"],["65073.13","0.000011"],["65073.53","0.000179"],["65074.07","0.000012"],["65074.09","0.000401"],["65074.77","0.000062"]],"bids":[["64822.58","2.089873"],["64820.99","0.075801"],["64820.27","0.010539"],["64820.26","0.4193"],["64820","0.270539"],["64819.99","2.575183"],["64817.04","0.741877"],["64816.6","0"],["64815.04","0"],["64811.75","0"],["64804.77","0.741877"],["64800.89","0"],["64794.41","0"],["64791.14","0"],["64733.45","0"],["64414.8","0.00003"],["64414.63","0.000779"]],"ts":"1784090306000","seq":656732218331,"pseq":656732216295}],"ts":1784090306002}
{"action":"update","arg":{"instType":"SPOT","channel":"books","instId":"BTCUSDT"},"data":[{"asks":[["64822.59","0.011839"],["64824.99","0"],["64828.06","0"],["64829.54","0"],["64829.55","0"],["64830","0.013117"],["64830.01","0"],["64830.1","0.033069"],["64830.11","0.07956"],["64830.49","0"],["64831","0.003444"],["64831.27","0.026238"],["64831.76","0"],["64831.95","0"],["64831.96","0"],["64833.29","0.264126"],["64833.76","0.309116"],["64834.08","0"],["64834.09","0.011079"],["64835.52","0.741877"],["64835.53","0"],["64835.54","0"],["64837.07","0"],["64837.95","0"],["64838.78","0"],["64839.99","0"],["64842.01","0.030876"],["64842.02","0.463123"],["64843.34","0.011807"],["64848.44","0.001542"],["64851.79","0.741877"],["64853.35","0.309116"],["64854.92","0.001541"],["64861.28","0.337204"],["64951.41","0"],["64961.14","0"],["64969.33","0"],["64976.76","0.071415"],["64989.27","0.071415"],["65073.13","0"],["65073.53","0"],["65074.07","0"],["65074.09","0"],["65074.77","0"]],"bids":[["64822.58","2.470782"],["64821.25","0.000771"],["64820.99","0"],["64820.28","0"],["64820.27","0.061705"],["64820.26","0.26"],["64820","0.26"],["64819.99","2.129473"],["64819.27","0.001542"],["64817.05","0"],["64813.91","0.030877"],["64813.9","0"],["64811.93","0"],["64810.51","0.014037"],["64810","0.02"],["64802.62","0.071415"],["64799.82","0.001543"],["64793.34","0.001543"],["64790.26","0"],["64770.58","0"],["64680.03","0"],["64414.8","0"],["64414.63","0"]],"ts":"1784090306101","seq":656732223601,"pseq":656732218331}],"ts":1784090306104}
{"action":"update","arg":{"instType":"SPOT","channel":"books","instId":"BTCUSDT"},"data":[{"asks":[["64822.59","0.009095"],["64828.06","0"],["64828.44","0"],["64830.1","0"],["64830.11","0"],["64831","0"],["64831.27","0"],["64832.05","0.004986"],["64832.1","0.000772"],["64833.02","0.026237"],["64833.75","0"],["64834.47","0"],["64835.51","0"],["64835.52","0"],["64837.77","0"],["64837.78","0.327843"],["64837.95","0.046302"],["64839.99","0"],["64842.01","0"],["64842.02","0"],["64842.03","0.463119"],["64843.33","0.030876"],["64847.81","0"],["64939.69","0"],["65073.13","0.000011"],["65073.53","0.000179"],["65074.07","0.000012"],["65074.09","0.000401"],["65074.77","0.000062"],["65074.93","0.000016"]],"bids":[["64822.58","2.67032"],["64820.01","0.640568"],["64817.06","0.337648"],["64817.05","0.222091"],["64815.07","0"],["64815.06","0.078383"],["64815.05","0"],["64813.91","0"],["64813.89","0"],["64811.93","0"],["64415","0"],["64414.81","0"]],"ts":"1784090306206","seq":656732227341,"pseq":656732223601}],"ts":1784090306208}
{"action":"update","arg":{"instType":"SPOT","channel":"trade","instId":"BTCUSDT"},"data":[{"ts":"1784090306206","price":"64822.59","size":"0.001406","side":"buy","tradeId":"1461146135684694020"},{"ts":"1784090306206","price":"64822.59","size":"0.001501","side":"buy","tradeId":"1461146135684694018"},{"ts":"1784090306206","price":"64822.59","size":"0.006093","side":"buy","tradeId":"1461146135684694016"}],"ts":1784090306208}
{"action":"update","arg":{"instType":"SPOT","channel":"trade","instId":"BTCUSDT"},"data":[{"ts":"1784090306207","price":"64822.59","size":"0.000095","side":"buy","tradeId":"1461146135688888320"}],"ts":1784090306209}
{"action":"update","arg":{"instType":"SPOT","channel":"trade","instId":"BTCUSDT"},"data":[{"ts":"1784090306216","price":"64825","size":"0.02","side":"buy","tradeId":"1461146135726637056"}],"ts":1784090306218}
{"action":"update","arg":{"instType":"SPOT","channel":"trade","instId":"BTCUSDT"},"data":[{"ts":"1784090306226","price":"64826.75","size":"0.000322","side":"buy","tradeId":"1461146135768580096"}],"ts":1784090306228}
{"action":"update","arg":{"instType":"SPOT","channel":"trade","instId":"BTCUSDT"},"data":[{"ts":"1784090306226","price":"64828.29","size":"0.000001","side":"buy","tradeId":"1461146135768580098"}],"ts":1784090306228}
{"action":"update","arg":{"instType":"SPOT","channel":"trade","instId":"BTCUSDT"},"data":[{"ts":"1784090306253","price":"64828.37","size":"0.006093","side":"buy","tradeId":"1461146135881826304"}],"ts":1784090306255}
{"action":"update","arg":{"instType":"SPOT","channel":"books","instId":"BTCUSDT"},"data":[{"asks":[["64822.59","0"],["64825","0"],["64825.29","0"],["64826.75","0"],["64828.07","0"],["64828.17","0"],["64828.29","0"],["64828.37","0"],["64828.79","0"],["64829.03","0"],["64829.99","0"],["64830","0.401724"],["64831.66","0"],["64832.05","0"],["64832.1","0"],["64832.29","0.015424"],["64833.02","0"],["64833.29","0"],["64833.3","0"],["64833.76","0"],["64834.09","0"],["64834.17","0"],["64834.63","0.00802"],["64834.64","0.006094"],["64834.74","0"],["64834.86","0.000771"],["64834.99","0"],["64835.58","0"],["64835.64","0.000772"],["64835.76","0"],["64836.49","0"],["64836.58","0.001542"],["64836.91","0.008142"],["64836.92","0"],["64837.56","0"],["64837.77","0"],["64837.78","0"],["64837.79","0"],["64837.92","0.026235"],["64837.95","0"],["64837.97","0"],["64838.25","0"],["64838.69","0"],["64838.79","0"],["64838.82","0"],["64838.99","0"],["64839.22","0"],["64840.52","0"],["64841.43","0"],["64841.66","0.106552"],["64841.67","0.309116"],["64841.68","0.046299"],["64841.78","0"],["64842.01","0.741877"],["64842.02","0"],["64842.03","0"],["64842.04","0"],["64842.1","0"],["64842.87","0.046265"],["64843.33","0"],["64843.34","0"],["64843.62","0"],["64843.76","0"],["64843.77","0"],["64844.46","0.07956"],["64844.49","0"],["64844.62","0"],["64844.77","0.22742"],["64844.78","0.741877"],["64844.99","0"],["64845.23","0"],["64845.28","0"],["64845.29","0"],["64845.56","0.305299"],["64847.01","0.741877"],["64847.02","0"],["64848.44","0"],["64848.53","0"],["64848.54","0"],["64848.85","0"],["64849.11","0"],["64849.19","0"],["64849.6","0"],["64849.98","0.463072"],["64849.99","0.741877"],["64850.71","0"],["64851.79","0"],["64852.13","0"],["64852.91","0.015796"],["64853.34","0.030874"],["64854.63","0.001581"],["64855.04","0.741877"],["64855.76","0.001541"],["64855.96","0.001541"],["64856.6","0.046255"],["64857.26","0"],["64857.44","0"],["64857.73","0"],["64858.29","0.741877"],["64861.11","0.211979"],["64861.13","0.309116"],["64861.27","0.741877"],["64861.28","0.047612"],["64861.29","0"],["64862.13","0"],["64863.54","5.333004"],["64863.57","0"],["64864.52","0.741877"],["64864.68","0"],["64866.04","0.483402"],["64866.26","0"],["64867.7","0"],["64867.77","0.741877"],["64868.91","0.309116"],["64871.02","0.741877"],["64873.81","0"],["64887.15","0"],["64888.15","0"],["64899.03","0.211979"],["64899.85","1.873405"],["64910.19","0.211979"],["64910.2","0"],["64921.91","1.391067"],["64929.67","0.000322"],["64959.86","0"],["64979.41","1.171994"],["64988.59","0.071415"],["64989.27","0"],["65075","0.02"],["65075.19","0.001206"],["65075.71","0.001639"],["65075.85","0.000015"],["65076.4","0.000057"],["65076.92","0.00004"],["65077.48","0.000032"],["65077.81","0.023285"]],"bids":[["64829.99","1.638949"],["64828.79","0"],["64828.78","0.1593"],["64828.37","0"],["64828.36","1.050993"],["64828.28","0"],["64828.17","0"],["64828.16","0"],["64828.06","0"],["64827.74","0"],["64826.75","0.061705"],["64826.74","0"],["64826.65","0.077166"],["64825.98","0.000771"],["64825.31","0.001542"],["64825.3","0.030874"],["64825.29","0.741877"],["64825.28","0"],["64825.27","0"],["64825.26","0"],["64825","0.149098"],["64824.99","0.267778"],["64824.82","0"],["64824.63","0"],["64824.42","0"],["64824.07","0"],["64823.93","0"],["64823.58","0"],["64823.21","0"],["64823.2","0"],["64823.13","0"],["64822.97","0"],["64822.96","0.4193"],["64822.86","0"],["64822.59","0.569116"],["64822.58","1.244516"],["64821.93","0"],["64821.25","0"],["64820.28","0"],["64820.27","0"],["64820.26","0"],["64820.01","0"],["64819.99","1.379593"],["64819.49","0"],["64818.5","0"],["64817.4","0.046283"],["64817.07","0.309116"],["64817.06","0"],["64816.7","0"],["64815.06","0"],["64815","0.02"],["64813.88","0"],["64813.5","0"],["64812.49","0"],["64811.91","0.071415"],["64811.12","0.154333"],["64810.74","0.001041"],["64810.51","0"],["64810.28","0.000322"],["64809.76","0.626621"],["64809.37","0.001542"],["64808.11","0.001543"],["64807.26","0.071415"],["64806.43","0"],["64806.12","0"],["64805.21","0"],["64804.92","0"],["64804.77","0"],["64804.75","0"],["64804.45","0"],["64804.22","0"],["64802.93","0"],["64801.46","0"],["64800.81","0"],["64800.55","0.000322"],["64797.03","0"],["64796.52","0.154331"],["64796.31","0"],["64796.08","1.876405"],["64795.2","0"],["64794.27","0"],["64793.73","0"],["64793.55","0.01"],["64793.34","0"],["64793.28","0.04"],["64790.99","0"],["64790.83","0.000322"],["64788.86","0"],["64788.8","0"],["64788.75","0"],["64785.47","0"],["64781.11","0.000322"],["64779.97","0"],["64775.75","0"],["64774.04","1.877044"],["64771.39","0.000322"],["64768.95","0"],["64766.03","0"],["64761.66","0.000322"],["64760.9","0"],["64756.31","0"],["64752","1.068841"],["64751.94","0.000322"],["64746.91","0"],["64746.58","0"],["64742.22","0.000322"],["64740.01","0.001543"],["64736.86","0"],["64733","0"],["64732.49","0.000322"],["64727.14","0"],["64722.77","0.000322"],["64721.52","0"],["64717.42","0"],["64705.1","0"],["64684.17","1.233066"],["64632.01","0.021641"],["64512.95","0"],["64415","0.02"],["64414.81","0.000015"],["64414.8","0.00003"],["64414.63","0.000779"],["64414.41","0.000326"]],"ts":"1784090306306","seq":656732234428,"pseq":656732227341}],"ts":1784090306308}
{"action":"update","arg":{"instType":"SPOT","channel":"books","instId":"BTCUSDT"},"data":[{"asks":[["64830","0.40284"],["64834.86","0"],["64835.64","0"],["64836.91","0.030539"],["64838.07","0.07956"],["64839.02","0.000772"],["64841.65","0.016936"],["64841.66","0.314379"],["64844.46","0"],["64846.13","0.015254"],["64847.78","0.001041"],["64849.97","0.030874"],["64853.18","0.181267"],["64853.34","0"],["64856.83","0.015363"],["64861.28","0"],["64872.64","0.354963"],["64878.66","0.55659"],["65076.4","0"],["65076.92","0"],["65077.48","0"],["65077.81","0"]],"bids":[["64829.99","2.128301"],["64828.79","0.061705"],["64828.37","0.336986"],["64828.25","0"],["64827.57","0.000771"],["64826.75","0"],["64825.98","0"],["64825.3","0.475742"],["64825","0"],["64824.99","0.283501"],["64822.97","0.158045"],["64822.6","0.449087"],["64822.58","1.085216"],["64822.4","0.002145"],["64822.15","0.000771"],["64819.99","0.89615"],["64817.05","0"],["64815.34","0.015627"],["64802.38","0.001581"],["64794.5","0.002146"],["64793.19","0"],["64786.75","0"],["64766.6","0.002147"],["64738.7","0.002148"],["64710.8","0.002149"],["64415.38","0"],["64415.26","0"],["64415","0"],["64414.81","0"],["64414.8","0"],["64414.63","0"],["64414.41","0"]],"ts":"1784090306411","seq":656732238685,"pseq":656732234428}],"ts":1784090306414}
{"action":"update","arg":{"instType":"SPOT","channel":"trade","instId":"BTCUSDT"},"data":[{"ts":"1784090306462","price":"64829.99","size":"0.000441","side":"sell","tradeId":"1461146136758435840"}],"ts":1784090306464}
{"action":"update","arg":{"instType":"SPOT","channel":"books","instId":"BTCUSDT"},"data":[{"asks":[["64830","0.6662"],["64832.28","0.004604"],["64836.29","0.026236"],["64836.91","0.112115"],["64837.78","0.309116"],["64837.92","0"],["64839.22","0.001542"],["64839.63","0.519882"],["64839.64","0.741877"],["64841.65","0"],["64841.66","0"],["64846.99","0.463392"],["64847","0"],["64849.98","0"],["64852.91","0"],["64871.02","0"],["64887.47","1.873763"],["64899.85","0"],["64909.52","1.391839"],["64921.79","0"],["64921.91","0"],["65076.4","0.000057"]],"bids":[["64829.99","1.818744"],["64827.57","0"],["64826.91","0.000771"],["64822.98","0.174636"],["64822.97","0"],["64822.96","0.26"],["64820.01","0.030874"],["64415.73","0"]],"ts":"1784090306501","seq":656732243504,"pseq":656732238685}],"ts":1784090306504}
{"action":"update","arg":{"instType":"SPOT","channel":"books","instId":"BTCUSDT"},"data":[{"asks":[["64836.57","0"],["64839.22","0"],["64873.28","0.46244"]],"bids":[["64788.35","0"],["64415.73","0.000035"]],"ts":"1784090306605","seq":656732244069,"pseq":656732243504}],"ts":1784090306610}
{"action":"update","arg":{"instType":"SPOT","channel":"books","instId":"BTCUSDT"},"data":[{"asks":[["64830","0.820449"],["64835.17","0"],["64836.29","0.026236"],["64836.57","0"],["64849.07","0.009899"],["64877.35","0.025153"],["64955.16","0.071415"],["64988.59","0"],["65075.85","0"],["65076.4","0"]],"bids":[["64829.99","1.906429"],["64826.91","0"],["64826.25","0.000771"],["64822.58","1.001415"],["64822.15","0"],["64819.99","0.741877"],["64819.88","0.000771"],["64816.04","0.015578"],["64815.12","0.181619"],["64415.73","0"]],"ts":"1784090306709","seq":656732245450,"pseq":656732244069}],"ts":1784090306712}
{"action":"update","arg":{"instType":"SPOT","channel":"books","instId":"BTCUSDT"},"data":[{"asks":[["64836.57","0"],["64837.77","0.016936"],["64846.99","0.000322"],["64935.98","6.610703"],["65075.19","0"],["65075.71","0"]],"bids":[["64822.98","0"],["64822.96","0"],["64822.59","0.309116"],["64820","0"],["64415.73","0.000035"],["64415.38","0.000029"],["64415.26","0.000172"]],"ts":"1784090306800","seq":656732245957,"pseq":656732245450}],"ts":1784090306803}
{"action":"update","arg":{"instType":"SPOT","channel":"books","instId":"BTCUSDT"},"data":[{"asks":[["64830","0.4062"],["64832.28","0.004604"],["64836.28","0"],["64837.77","0.016936"],["64845.71","0.05"],["64955.16","0"],["64992.39","0.071415"],["65075","0"]],"bids":[["64825.31","0.321834"],["64825.3","0"],["64822.4","0"],["64817.08","0.15545"],["64794.5","0"],["64766.6","0"],["64738.7","0"],["64710.8","0"],["64415","0.02"],["64414.81","0.000015"],["64414.8","0.00003"],["64414.63","0.000779"],["64414.41","0.000326"]],"ts":"1784090306909","seq":656732247333,"pseq":656732245957}],"ts":1784090306912}
{"action":"update","arg":{"instType":"SPOT","channel":"books","instId":"BTCUSDT"},"data":[{"asks":[["64836.27","0.231423"],["64836.28","0.26"],["64836.84","0.000322"],["64836.91","0"],["64837.77","0"],["64976.75","0"],["64976.76","0"],["64991.49","0.071415"],["65001.23","0.071415"],["65074.93","0"]],"bids":[["64829.99","1.90643"],["64826.6","0.002145"],["64798.7","0.002146"],["64770.8","0.002147"],["64742.9","0.002147"],["64715","0.009352"],["64414.81","0"],["64414.8","0"],["64414.63","0"],["64414.41","0"]],"ts":"1784090307004","seq":656732248473,"pseq":656732247333}],"ts":1784090307006}
{"action":"update","arg":{"instType":"SPOT","channel":"books","instId":"BTCUSDT"},"data":[{"asks":[["64830","0.411846"],["64836.57","0.001542"],["64836.84","0"],["64837.7","0.002144"],["64849.63","0.001542"],["64849.98","0.420756"],["64894.8","0.002142"],["64951.9","0.002141"],["65009","0.002139"],["65066.1","0.002137"],["65072.99","0"],["65073","0"],["65073.13","0"],["65073.53","0"],["65074.07","0"],["65074.09","0"],["65074.77","0"]],"bids":[["64829.99","2.060679"],["64826.94","0.001542"],["64415","0"]],"ts":"1784090307096","seq":656732248750,"pseq":656732248473}],"ts":1784090307105}
{"action":"update","arg":{"instType":"SPOT","channel":"books","instId":"BTCUSDT"},"data":[{"asks":[["64836.26","0.016936"],["64836.57","0"]],"bids":[],"ts":"1784090307129","seq":656732248828,"pseq":656732248750}],"ts":1784090307132}
{"action":"update","arg":{"instType":"SPOT","channel":"books","instId":"BTCUSDT"},"data":[{"asks":[["64830","0.413347"],["64878.66","0.211979"],["64968.75","0.071415"],["65001.23","0"]],"bids":[],"ts":"1784090307192","seq":656732249098,"pseq":656732248828}],"ts":1784090307207}
{"action":"update","arg":{"instType":"SPOT","channel":"books","instId":"BTCUSDT"},"data":[{"asks":[["64835.95","0.026236"],["64836.29","0"],["64838.35","0.001542"],["65072.85","0"]],"bids":[],"ts":"1784090307210","seq":656732249373,"pseq":656732249098}],"ts":1784090307212}
{"action":"update","arg":{"instType":"SPOT","channel":"books","instId":"BTCUSDT"},"data":[{"asks":[["64834.42","0.003787"],["64835.92","0.016936"],["64835.93","0.208173"],["64835.94","0.26"],["64836.26","0"],["64836.27","0"],["64836.28","0"],["64838.35","0"]],"bids":[["64828.36","1.054982"]],"ts":"1784090307304","seq":656732250953,"pseq":656732249373}],"ts":1784090307306}
{"action":"update","arg":{"instType":"SPOT","channel":"books","instId":"BTCUSDT"},"data":[{"asks":[["64830","0.413347"],["64836.66","0.001542"],["64849.06","0.030872"],["64849.97","0"],["64859.36","0.001541"],["64862.6","0.001541"],["64868.9","0.02325"],["64869.14","0.011343"],["64875.53","1.874108"],["64887.47","0"],["64888.59","0.034636"],["64897.58","1.391897"],["64909.52","0"],["64957.4","0.071415"],["64967.14","0.071415"],["64991.49","0"],["64992.39","0"],["65024.67","0"],["65030.03","0"],["65069.57","0"],["65072.4","0"],["65072.73","0"],["65072.77","0"]],"bids":[["64829.99","2.369795"],["64810.73","0.001542"],["64415.26","0"]],"ts":"1784090307406","seq":656732252116,"pseq":656732250953}],"ts":1784090307410}
{"action":"update","arg":{"instType":"SPOT","channel":"books","instId":"BTCUSDT"},"data":[{"asks":[["64833.19","0.005046"],["64834.63","0.084374"],["64834.99","0.26"],["65071.49","0"],["65072.16","0"]],"bids":[],"ts":"1784090307502","seq":656732253234,"pseq":656732252116}],"ts":1784090307506}
{"action":"update","arg":{"instType":"SPOT","channel":"books","instId":"BTCUSDT"},"data":[{"asks":[["64834.98","0.016936"],["64835.92","0"]],"bids":[],"ts":"1784090307595","seq":656732254220,"pseq":656732253234}],"ts":1784090307613}
{"action":"update","arg":{"instType":"SPOT","channel":"books","instId":"BTCUSDT"},"data":[{"asks":[["64833.19","0"],["65071.49","0.000008"]],"bids":[],"ts":"1784090307640","seq":656732254708,"pseq":656732254220}],"ts":1784090307642}
{"action":"update","arg":{"instType":"SPOT","channel":"books","instId":"BTCUSDT"},"data":[{"asks":[["64832.27","0.005046"],["64834.41","0"],["64834.62","0"],["64834.98","0"],["64851.78","0.071415"],["64861.5","0.071415"],["64871.22","0.071415"],["64914.24","0.023805"],["64957.4","0"],["64967.14","0"],["64968.75","0"],["64993.22","0.023805"],["65071.14","0"],["65071.49","0"]],"bids":[["64828.79","0"],["64415.26","0.000172"]],"ts":"1784090307706","seq":656732255566,"pseq":656732254708}],"ts":1784090307710}
{"action":"update","arg":{"instType":"SPOT","channel":"books","instId":"BTCUSDT"},"data":[{"asks":[["64834.41","0.003787"],["64834.62","0"],["65070.94","0"]],"bids":[["64829.99","2.699295"],["64828.79","0.061705"],["64824.99","0.274001"],["64822.58","0.941415"],["64415.26","0"]],"ts":"1784090307802","seq":656732256647,"pseq":656732255566}],"ts":1784090307806}
{"action":"update","arg":{"instType":"SPOT","channel":"books","instId":"BTCUSDT"},"data":[{"asks":[],"bids":[["64826.91","0.000771"],["64826.25","0"]],"ts":"1784090307913","seq":656732257838,"pseq":656732256647}],"ts":1784090307916}
{"action":"update","arg":{"instType":"SPOT","channel":"books","instId":"BTCUSDT"},"data":[{"asks":[["64832.26","0.005046"],["64834.41","0"],["64835.93","0.125508"],["64835.94","0"],["64835.95","0"],["64836.59","0.026236"],["65070.94","0.1593"]],"bids":[["64829.99","2.545046"]],"ts":"1784090308010","seq":656732258912,"pseq":656732257838}],"ts":1784090308014}
{"action":"update","arg":{"instType":"SPOT","channel":"books","instId":"BTCUSDT"},"data":[{"asks":[["64851.78","0"],["64861.5","0"],["64871.22","0"],["64914.24","0"],["64993.22","0"],["65071.14","0.000056"],["65071.49","0.000008"],["65072.16","0.011176"],["65072.4","0.001256"],["65072.73","0.000019"]],"bids":[],"ts":"1784090308093","seq":656732259790,"pseq":656732258912}],"ts":1784090308119}
{"action":"update","arg":{"instType":"SPOT","channel":"books","instId":"BTCUSDT"},"data":[{"asks":[["64841.59","0.046299"],["64841.68","0"],["64864.56","0.154332"],["65072.73","0"]],"bids":[["64829.99","2.591345"],["64824.99","0.227702"],["64811.12","0"],["64415.26","0.000172"]],"ts":"1784090308171","seq":656732260541,"pseq":656732259790}],"ts":1784090308174}
{"action":"update","arg":{"instType":"SPOT","channel":"books","instId":"BTCUSDT"},"data":[{"asks":[["64849.24","0.077166"],["64853.34","0.029561"],["64879.92","0.154332"],["65071.49","0"],["65072.16","0"],["65072.4","0"]],"bids":[["64826.69","0.077166"],["64826.65","0"]],"ts":"1784090308201","seq":656732260858,"pseq":656732260541}],"ts":1784090308204}
{"action":"update","arg":{"instType":"SPOT","channel":"books","instId":"BTCUSDT"},"data":[{"asks":[["64999.29","0"],["65071.49","0.000008"]],"bids":[["64796.52","0"],["64796.01","0.154332"]],"ts":"1784090308301","seq":656732262430,"pseq":656732260858}],"ts":1784090308304}
{"action":"update","arg":{"instType":"SPOT","channel":"books","instId":"BTCUSDT"},"data":[{"asks":[["64840.23","0.000771"],["65071.49","0"]],"bids":[["64826.91","0"],["64415","0.02"]],"ts":"1784090308400","seq":656732263334,"pseq":656732262430}],"ts":1784090308402}
{"action":"update","arg":{"instType":"SPOT","channel":"books","instId":"BTCUSDT"},"data":[{"asks":[["64972.91","0.071415"],["64982.65","0.071415"],["64992.39","0.071415"],["65070.74","0"],["65070.94","0"],["65071.14","0"]],"bids":[["64829.99","2.591345"],["64827.6","0.000771"],["64415","0"]],"ts":"1784090308509","seq":656732264171,"pseq":656732263334}],"ts":1784090308512}
{"action":"update","arg":{"instType":"SPOT","channel":"books","instId":"BTCUSDT"},"data":[{"asks":[],"bids":[["64829.99","2.745594"]],"ts":"1784090308620","seq":656732265437,"pseq":656732264171}],"ts":1784090308622}
{"action":"update","arg":{"instType":"SPOT","channel":"books","instId":"BTCUSDT"},"data":[{"asks":[["64836.58","0.027778"],["64836.59","0"],["65070.74","0.000051"]],"bids":[],"ts":"1784090308718","seq":656732266729,"pseq":656732265437}],"ts":1784090308720}
{"action":"update","arg":{"instType":"SPOT","channel":"books","instId":"BTCUSDT"},"data":[{"asks":[["64830","0.673347"]],"bids":[],"ts":"1784090308820","seq":656732268434,"pseq":656732266729}],"ts":1784090308824}
{"action":"update","arg":{"instType":"SPOT","channel":"books","instId":"BTCUSDT"},"data":[{"asks":[],"bids":[["64827.6","0"],["64415","0.02"]],"ts":"1784090308970","seq":656732270466,"pseq":656732268434}],"ts":1784090308972}
{"action":"update","arg":{"instType":"SPOT","channel":"books","instId":"BTCUSDT"},"data":[{"asks":[],"bids":[["64828.28","0.000771"],["64415","0"]],"ts":"1784090309007","seq":656732271048,"pseq":656732270466}],"ts":1784090309010}
{"action":"update","arg":{"instType":"SPOT","channel":"books","instId":"BTCUSDT"},"data":[{"asks":[["64830","0.681197"],["64950.99","0.071415"],["64960.73","0.071415"],["64982.65","0"],["64992.39","0"]],"bids":[],"ts":"1784090309118","seq":656732272744,"pseq":656732271048}],"ts":1784090309122}
{"action":"update","arg":{"instType":"SPOT","channel":"books","instId":"BTCUSDT"},"data":[{"asks":[["64830","0.421197"],["64923.3","0"],["64947.83","0.016205"]],"bids":[],"ts":"1784090309201","seq":656732274206,"pseq":656732272744}],"ts":1784090309206}
{"action":"update","arg":{"instType":"SPOT","channel":"books","instId":"BTCUSDT"},"data":[{"asks":[],"bids":[["64829.99","2.745594"],["64822.58","0.741877"]],"ts":"1784090309326","seq":656732276341,"pseq":656732274206}],"ts":1784090309328}
{"action":"update","arg":{"instType":"SPOT","channel":"books","instId":"BTCUSDT"},"data":[{"asks":[],"bids":[["64829.99","2.868008"],["64822.18","0.000771"],["64819.88","0"]],"ts":"1784090309403","seq":656732277193,"pseq":656732276341}],"ts":1784090309406}
{"action":"update","arg":{"instType":"SPOT","channel":"books","instId":"BTCUSDT"},"data":[{"asks":[["64836.58","0.001542"],["64836.6","0.026236"],["64863.14","0.071415"],["64872.87","0.071415"],["64882.59","0.071415"],["64925.61","0.023805"],["64950.99","0"],["64960.73","0"],["64972.91","0"],["65070.42","0"],["65070.74","0"]],"bids":[],"ts":"1784090309505","seq":656732278500,"pseq":656732277193}],"ts":1784090309508}
{"action":"update","arg":{"instType":"SPOT","channel":"books","instId":"BTCUSDT"},"data":[{"asks":[["64830","0.413347"]],"bids":[],"ts":"1784090309600","seq":656732279600,"pseq":656732278500}],"ts":1784090309602}
{"action":"update","arg":{"instType":"SPOT","channel":"books","instId":"BTCUSDT"},"data":[{"asks":[["64843.6","0.015276"],["65070","0"]],"bids":[],"ts":"1784090309713","seq":656732280285,"pseq":656732279600}],"ts":1784090309716}
{"action":"update","arg":{"instType":"SPOT","channel":"books","instId":"BTCUSDT"},"data":[{"asks":[["64830","0.673347"]],"bids":[["64828.96","0.000771"],["64828.28","0"]],"ts":"1784090309824","seq":656732281474,"pseq":656732280285}],"ts":1784090309829}
{"action":"update","arg":{"instType":"SPOT","channel":"books","instId":"BTCUSDT"},"data":[{"asks":[["64843.6","0"],["65070","0.020077"]],"bids":[["64828.97","0"],["64828.79","0.061705"]],"ts":"1784090309907","seq":656732282662,"pseq":656732281474}],"ts":1784090309910}
{"action":"update","arg":{"instType":"SPOT","channel":"books","instId":"BTCUSDT"},"data":[{"asks":[],"bids":[["64829.99","3.022257"],["64828.97","0"],["64828.79","0.061705"],["64826.6","0"],["64798.7","0"],["64770.8","0"],["64742.9","0"],["64715","0.007204"],["64415","0.02"],["64414.81","0.000015"],["64414.8","0.00003"],["64414.63","0.000779"]],"ts":"1784090310004","seq":656732283973,"pseq":656732282662}],"ts":1784090310006}
{"action":"update","arg":{"instType":"SPOT","channel":"books","instId":"BTCUSDT"},"data":[{"asks":[["64837.7","0"],["64863.14","0"],["64872.87","0"],["64882.59","0"],["64894.8","0"],["64925.61","0"],["64951.9","0"],["65009","0"],["65066.1","0"],["65070.42","0.000027"],["65070.74","0.000051"],["65070.94","0.1593"],["65071.14","0.000056"],["65071.49","0.000008"],["65072.16","0.011176"],["65072.4","0.001256"],["65072.73","0.000019"],["65072.77","0.000143"]],"bids":[["64828.97","0"],["64828.79","0.061705"]],"ts":"1784090310103","seq":656732285340,"pseq":656732283973}],"ts":1784090310107}
{"action":"update","arg":{"instType":"SPOT","channel":"books","instId":"BTCUSDT"},"data":[{"asks":[["64852.93","0.015185"],["64979.16","0.071415"],["64988.9","0.071415"],["65072.4","0"],["65072.73","0"],["65072.77","0"]],"bids":[["64828.97","0"],["64828.79","0.061705"]],"ts":"1784090310211","seq":656732286876,"pseq":656732285340}],"ts":1784090310214}
{"action":"update","arg":{"instType":"SPOT","channel":"books","instId":"BTCUSDT"},"data":[{"asks":[["64830","0.413347"],["64836.6","0"],["64836.69","0.026236"],["64841.59","0.046299"],["64849.24","0"],["64864.56","0"],["64879.92","0"],["65072.4","0.001256"],["65072.73","0.000019"],["65072.77","0.000143"]],"bids":[["64829.99","2.975958"],["64828.97","0"],["64828.79","0.061705"],["64826.69","0"],["64826.6","0.002145"],["64811.88","0.154332"],["64798.7","0.002146"],["64796.58","0.154332"],["64796.01","0"],["64770.8","0.002147"],["64742.9","0.002147"],["64715","0.009352"],["64415","0"],["64414.81","0"],["64414.8","0"],["64414.63","0"]],"ts":"1784090310322","seq":656732288467,"pseq":656732286876}],"ts":1784090310324}
{"action":"update","arg":{"instType":"SPOT","channel":"books","instId":"BTCUSDT"},"data":[{"asks":[["64837.7","0.002144"],["64894.8","0.002142"],["64951.9","0.002141"],["65009","0.002139"],["65066.1","0.002137"],["65071.49","0"],["65072.16","0"],["65072.4","0"],["65072.73","0"],["65072.77","0"]],"bids":[["64828.97","0"],["64828.79","0.061705"]],"ts":"1784090310406","seq":656732289785,"pseq":656732288467}],"ts":1784090310409}
{"action":"update","arg":{"instType":"SPOT","channel":"books","instId":"BTCUSDT"},"data":[{"asks":[["64853.18","0"],["64872.64","0"],["64886.22","0.000028"],["65071.49","0.000008"]],"bids":[["64828.97","0"],["64828.79","0.061705"],["64815.12","0"],["64807.79","0"],["64415","0.02"],["64414.81","0.000015"]],"ts":"1784090310502","seq":656732290934,"pseq":656732289785}],"ts":1784090310504}
{"action":"update","arg":{"instType":"SPOT","channel":"books","instId":"BTCUSDT"},"data":[{"asks":[["64835.93","0.330912"],["64837.52","0.741877"],["64849.98","0.244913"],["64850.37","0.186433"],["64867.77","0"],["64869.83","0.372737"],["64969.42","0.071415"],["65070.94","0"],["65071.14","0"],["65071.49","0"]],"bids":[["64829.99","2.666842"],["64828.97","0"],["64828.79","0.061705"],["64828.37","0.223742"],["64828.36","0.745866"],["64817.08","0.218735"],["64815.53","0.178485"],["64796.08","2.238281"],["64414.81","0"]],"ts":"1784090310613","seq":656732293001,"pseq":656732290934}],"ts":1784090310616}
{"action":"update","arg":{"instType":"SPOT","channel":"books","instId":"BTCUSDT"},"data":[{"asks":[],"bids":[["64828.96","0"],["64414.81","0.000015"]],"ts":"1784090310727","seq":656732293387,"pseq":656732293001}],"ts":1784090310730}
{"action":"update","arg":{"instType":"SPOT","channel":"books","instId":"BTCUSDT"},"data":[{"asks":[["64830","0.673347"]],"bids":[["64829.99","2.666842"],["64829.61","0.000771"],["64815.02","0.049959"],["64415","0"],["64414.81","0"]],"ts":"1784090310821","seq":656732293845,"pseq":656732293387}],"ts":1784090310825}
{"action":"update","arg":{"instType":"SPOT","channel":"books","instId":"BTCUSDT"},"data":[{"asks":[["64830","0.686827"],["64832.26","0"],["64950.99","0.071415"],["64988.9","0"],["65070.94","0.1593"]],"bids":[["64828.79","0.061705"]],"ts":"1784090310904","seq":656732294165,"pseq":656732293845}],"ts":1784090310908}
{"action":"update","arg":{"instType":"SPOT","channel":"books","instId":"BTCUSDT"},"data":[{"asks":[["64832.26","0.005046"],["64836.69","0.026236"],["65070.94","0"]],"bids":[],"ts":"1784090311000","seq":656732294392,"pseq":656732294165}],"ts":1784090311002}
{"action":"update","arg":{"instType":"SPOT","channel":"books","instId":"BTCUSDT"},"data":[{"asks":[["64831.22","0.007898"],["64831.23","0.007898"],["64831.24","0.005989"],["64832.26","0"],["64832.27","0"],["64832.28","0"],["64837.96","0.000771"],["64840.23","0"],["64847","0.030873"],["64849.06","0"]],"bids":[["64829.99","2.660884"]],"ts":"1784090311103","seq":656732297627,"pseq":656732294392}],"ts":1784090311106}
{"action":"update","arg":{"instType":"SPOT","channel":"trade","instId":"BTCUSDT"},"data":[{"ts":"1784090311164","price":"64829.99","size":"0.000019","side":"sell","tradeId":"1461146156480053248"}],"ts":1784090311166}
{"action":"update","arg":{"instType":"SPOT","channel":"books","instId":"BTCUSDT"},"data":[{"asks":[["64830","1.766855"],["64831.12","0.026239"],["64831.22","0"],["64831.23","0.223009"],["64831.29","0"],["64832","0.741877"],["64832.17","0"],["64832.29","0"],["64833.34","0"],["64833.94","0.306849"],["64833.95","0.741877"],["64834.42","0"],["64834.52","0"],["64834.63","0"],["64834.69","0"],["64835.55","0.000772"],["64836.49","0.1593"],["64836.66","0"],["64836.69","0"],["64838.19","0.046302"],["64839.02","0"],["64841.59","0"],["64841.66","0.030875"],["64842.86","0"],["64843.31","0.015908"],["64843.34","0"],["64845.56","0.070234"],["64846.13","0"],["64847","0"],["64847.43","0"],["64849.07","0"],["64849.97","0.211979"],["64849.98","0.005405"],["64856.38","1.874661"],["64858.29","0"],["64861.13","0"],["64861.27","0"],["64864.52","0"],["64868.91","0"],["64875.53","0"],["64878.42","1.392308"],["64897.58","0"],["64910.19","0"],["64950.99","0"],["64984.73","0.071415"],["65070.94","0.1593"],["65071.14","0.000056"],["65071.49","0.000008"],["65072.16","0.011176"],["65072.4","0.001256"],["65072.73","0.000019"],["65072.77","0.000143"]],"bids":[["64829.99","0.530008"],["64828.79","0"],["64828.78","0"],["64828.77","0.48337"],["64828.37","0"],["64828.36","0.003989"],["64828.24","0"],["64828.18","0.015425"],["64826.73","0.046305"],["64825.89","0.001542"],["64825.31","0.001542"],["64825.29","0"],["64824.99","0.211979"],["64823.44","0.015161"],["64823.01","0.741877"],["64822.6","0"],["64822.59","0"],["64822.58","0"],["64821.05","0.22145"],["64821.04","0.741877"],["64820.12","0.077174"],["64820.01","0"],["64819.99","0"],["64819.28","0"],["64819.1","0.309116"],["64819.09","0.741877"],["64817.08","0.063285"],["64817.07","0"],["64817.04","0"],["64817.01","0.1593"],["64815.84","0.741877"],["64815.54","0"],["64815.34","0"],["64815.03","0.030876"],["64814.99","0"],["64812.98","0"],["64812.97","0.309116"],["64812.75","0"],["64812.74","0.015083"],["64812.59","0.741877"],["64811.88","0"],["64811.74","0"],["64810.6","0"],["64809.77","0.741877"],["64809.68","0"],["64804.9","0.154347"],["64804.45","0.741877"],["64804.17","0.046293"],["64801.2","0.741877"],["64796.58","0"],["64796.08","0.361876"],["64793.04","0.309116"],["64785.26","0.309116"],["64774.04","0"],["64759.17","1.877474"],["64752","0"],["64737.14","1.878114"],["64715.11","1.069395"],["64417.11","0"],["64416.77","0"],["64416.67","0"],["64416.21","0"],["64415.73","0"],["64415.38","0"],["64415.26","0"]],"ts":"1784090311204","seq":656732307366,"pseq":656732297627}],"ts":1784090311206}
{"action":"update","arg":{"instType":"SPOT","channel":"books","instId":"BTCUSDT"},"data":[{"asks":[["64830","1.766855"],["64835.03","0"],["64835.55","0"],["64837.12","0"],["64953.74","0.071415"],["64984.73","0"],["65072.85","0.000048"]],"bids":[["64825.89","0"],["64825","0.172889"],["64823.44","0"],["64823.03","0.741877"],["64823.01","0"],["64821.61","0"],["64819.11","0"],["64817.09","0"],["64817.08","0"],["64816.05","0.015578"],["64815.02","0"],["64812.74","0"],["64809.37","0"],["64802.78","0.001543"],["64777.95","1.87693"],["64759.17","0"],["64755.92","1.877569"],["64737.14","0"],["64733.88","1.068641"],["64715.11","0"],["64417.11","0.000137"],["64416.77","0.000388"],["64416.67","0.000706"]],"ts":"1784090311309","seq":656732308173,"pseq":656732307366}],"ts":1784090311312}
{"action":"update","arg":{"instType":"SPOT","channel":"books","instId":"BTCUSDT"},"data":[{"asks":[["64830","1.024978"],["64832.83","0.000772"],["64841.66","0"],["64842.86","0.030876"],["64850.23","0.015185"],["65072.77","0"],["65072.85","0"]],"bids":[["64825","0.262622"],["64819.11","0.375088"],["64816.05","0.015578"],["64815.85","0.402655"],["64811.92","0"],["64809.78","0.154264"],["64416.77","0"],["64416.67","0"]],"ts":"1784090311403","seq":656732308456,"pseq":656732308173}],"ts":1784090311406}
{"action":"update","arg":{"instType":"SPOT","channel":"books","instId":"BTCUSDT"},"data":[{"asks":[],"bids":[["64817.41","0"],["64817.02","0.061705"],["64816.05","0"],["64815.01","0.295769"]],"ts":"1784090311512","seq":656732309138,"pseq":656732308456}],"ts":1784090311514}
{"action":"update","arg":{"instType":"SPOT","channel":"books","instId":"BTCUSDT"},"data":[{"asks":[["64830","1.035485"]],"bids":[["64829.99","0.527945"],["64817.41","0"],["64817.02","0.061705"]],"ts":"1784090311582","seq":656732309531,"pseq":656732309138}],"ts":1784090311604}
{"action":"update","arg":{"instType":"SPOT","channel":"books","instId":"BTCUSDT"},"data":[{"asks":[],"bids":[["64777.95","0"],["64733.88","0"],["64416.77","0.000388"],["64416.67","0.000706"]],"ts":"1784090311602","seq":656732309709,"pseq":656732309531}],"ts":1784090311604}
{"action":"update","arg":{"instType":"SPOT","channel":"books","instId":"BTCUSDT"},"data":[{"asks":[["64830","1.035485"],["64839.53","0.015296"],["64953.74","0"],["64988.9","0.071415"],["65072.73","0"]],"bids":[["64819.86","0.015269"],["64817.41","0"],["64817.02","0.061705"],["64730.31","1.878312"],["64708.29","1.069058"],["64417.11","0"],["64416.77","0"],["64416.67","0"]],"ts":"1784090311693","seq":656732311366,"pseq":656732309709}],"ts":1784090311704}
{"action":"update","arg":{"instType":"SPOT","channel":"books","instId":"BTCUSDT"},"data":[{"asks":[["64834.99","0"],["65072.73","0.000019"]],"bids":[],"ts":"1784090311704","seq":656732311469,"pseq":656732311366}],"ts":1784090311706}
{"action":"update","arg":{"instType":"SPOT","channel":"books","instId":"BTCUSDT"},"data":[{"asks":[["64833.94","0.229239"]],"bids":[["64819.87","0.015269"],["64817.41","0"],["64817.02","0"]],"ts":"1784090311790","seq":656732312029,"pseq":656732311469}],"ts":1784090311805}
{"action":"update","arg":{"instType":"SPOT","channel":"books","instId":"BTCUSDT"},"data":[{"asks":[],"bids":[["64820.13","0.061705"],["64819.87","0"]],"ts":"1784090311823","seq":656732312123,"pseq":656732312029}],"ts":1784090311826}
{"action":"update","arg":{"instType":"SPOT","channel":"books","instId":"BTCUSDT"},"data":[{"asks":[],"bids":[["64820.13","0"],["64819.28","0.001542"]],"ts":"1784090311901","seq":656732312758,"pseq":656732312123}],"ts":1784090311904}
{"action":"update","arg":{"instType":"SPOT","channel":"books","instId":"BTCUSDT"},"data":[{"asks":[["64830","1.059814"],["64831.12","0"],["64851.32","0.483367"],["64866.04","0"],["65072.77","0.000143"]],"bids":[["64829.99","0.373696"],["64819.28","0.001542"],["64819.12","0"]],"ts":"1784090311998","seq":656732313030,"pseq":656732312758}],"ts":1784090312007}
{"action":"update","arg":{"instType":"SPOT","channel":"books","instId":"BTCUSDT"},"data":[{"asks":[],"bids":[["64825","0.324327"],["64819.28","0"],["64417.11","0.000137"]],"ts":"1784090312030","seq":656732313168,"pseq":656732313030}],"ts":1784090312035}
{"action":"update","arg":{"instType":"SPOT","channel":"books","instId":"BTCUSDT"},"data":[{"asks":[],"bids":[["64825","0.262622"],["64823.04","0.061705"],["64417.11","0"]],"ts":"1784090312081","seq":656732313281,"pseq":656732313168}],"ts":1784090312108}
{"action":"update","arg":{"instType":"SPOT","channel":"books","instId":"BTCUSDT"},"data":[{"asks":[],"bids":[["64823.04","0"],["64417.11","0.000137"]],"ts":"1784090312172","seq":656732313505,"pseq":656732313281}],"ts":1784090312174}
{"action":"update","arg":{"instType":"SPOT","channel":"books","instId":"BTCUSDT"},"data":[{"asks":[],"bids":[["64820.13","0.061705"],["64816.05","0.030876"],["64815.03","0"],["64417.11","0"]],"ts":"1784090312205","seq":656732313827,"pseq":656732313505}],"ts":1784090312210}
{"action":"update","arg":{"instType":"SPOT","channel":"trade","instId":"BTCUSDT"},"data":[{"ts":"1784090312246","price":"64829.99","size":"0.00052","side":"sell","tradeId":"1461146161018290176"}],"ts":1784090312248}
{"action":"update","arg":{"instType":"SPOT","channel":"books","instId":"BTCUSDT"},"data":[{"asks":[["64830.93","0.001542"],["64843.31","0.088621"],["64845.56","0.187256"],["64861.03","0.145427"],["64876.99","0.145427"],["65072.4","0"],["65072.73","0"],["65072.77","0"]],"bids":[["64829.99","0.373176"],["64823.04","0.061705"],["64820.13","0"],["64817.51","0.001542"],["64417.65","0"]],"ts":"1784090312289","seq":656732314264,"pseq":656732313827}],"ts":1784090312311}
{"action":"update","arg":{"instType":"SPOT","channel":"books","instId":"BTCUSDT"},"data":[{"asks":[],"bids":[["64829.99","0.373725"]],"ts":"1784090312392","seq":656732314525,"pseq":656732314264}],"ts":1784090312396}
{"action":"update","arg":{"instType":"SPOT","channel":"books","instId":"BTCUSDT"},"data":[{"asks":[["64957.4","0.071415"],["64988.9","0"]],"bids":[],"ts":"1784090312442","seq":656732314582,"pseq":656732314525}],"ts":1784090312444}
{"action":"update","arg":{"instType":"SPOT","channel":"books","instId":"BTCUSDT"},"data":[{"asks":[],"bids":[["64828.18","0"],["64417.65","0.000041"]],"ts":"1784090312496","seq":656732315152,"pseq":656732314582}],"ts":1784090312518}
{"action":"update","arg":{"instType":"SPOT","channel":"books","instId":"BTCUSDT"},"data":[{"asks":[["64842","0.030876"],["64842.86","0"]],"bids":[],"ts":"1784090312518","seq":656732315207,"pseq":656732315152}],"ts":1784090312520}
{"action":"update","arg":{"instType":"SPOT","channel":"trade","instId":"BTCUSDT"},"data":[{"ts":"1784090312568","price":"64829.99","size":"0.000019","side":"sell","tradeId":"1461146162368856064"}],"ts":1784090312570}
{"action":"update","arg":{"instType":"SPOT","channel":"books","instId":"BTCUSDT"},"data":[{"asks":[["64830","1.059814"],["64830.93","0"],["64841.66","0.030875"],["64842","0"],["64842.86","0"],["64843.3","0"],["64849.79","0.04626"],["64856.6","0"],["64879.42","0.000028"],["64886.22","0"],["65072.4","0.001256"]],"bids":[["64829.99","0.373706"],["64828.77","0"],["64826.74","0"],["64825.38","0.015426"],["64824.99","0"],["64821.6","0.211979"],["64819.86","0"],["64817.4","0"],["64817.02","0"],["64816.05","0"],["64815.54","0.030876"],["64815.02","0"],["64815.01","0.211979"],["64812.06","0.083794"],["64810.8","0.046288"],["64808.11","0"],["64800.47","0.001543"],["64793.55","0"],["64793.28","0"],["64772.17","1.877098"],["64755.92","0"],["64750.14","1.877737"],["64737.18","0"],["64730.31","0"],["64728.11","1.228051"],["64715.16","0"],["64708.29","0"],["64417.11","0.000137"],["64416.77","0.000388"],["64416.67","0.000706"]],"ts":"1784090312603","seq":656732315624,"pseq":656732315207}],"ts":1784090312606}
{"action":"update","arg":{"instType":"SPOT","channel":"books","instId":"BTCUSDT"},"data":[{"asks":[["64833.43","0.001542"],["64837.6","0.015577"],["64841.66","0"],["64842","0.030876"],["65072.16","0"],["65072.4","0"]],"bids":[["64823.06","0.061705"],["64823.05","0.309116"],["64823.04","0"],["64818.49","0.015299"],["64817.51","0"],["64815.53","0"],["64815.01","0.213521"],["64809.76","0"],["64787.83","0.05"],["64785.26","0"],["64416.21","0.000031"]],"ts":"1784090312701","seq":656732316151,"pseq":656732315624}],"ts":1784090312704}
{"action":"update","arg":{"instType":"SPOT","channel":"books","instId":"BTCUSDT"},"data":[{"asks":[["64830","1.035485"],["64842","0"],["64842.86","0.030876"],["64957.4","0"],["64984.73","0.071415"]],"bids":[["64827.07","0.483353"],["64826.74","0.014462"],["64808.06","0.626555"],["64805.2","0.182926"],["64417.11","0"],["64416.77","0"],["64416.67","0"],["64416.21","0"]],"ts":"1784090312808","seq":656732316844,"pseq":656732316151}],"ts":1784090312813}
{"action":"update","arg":{"instType":"SPOT","channel":"books","instId":"BTCUSDT"},"data":[{"asks":[["64833.43","0"],["64835.44","0.001542"]],"bids":[["64827.08","0.109221"],["64826.74","0"],["64817.02","0.001542"],["64815.85","0.021896"],["64815.01","0.211979"],["64417.65","0"]],"ts":"1784090312911","seq":656732317261,"pseq":656732316844}],"ts":1784090312915}
{"action":"update","arg":{"instType":"SPOT","channel":"books","instId":"BTCUSDT"},"data":[{"asks":[],"bids":[["64825.09","0.741877"],["64815.85","0.29312"],["64418.23","0"]],"ts":"1784090313022","seq":656732317705,"pseq":656732317261}],"ts":1784090313026}
{"action":"update","arg":{"instType":"SPOT","channel":"books","instId":"BTCUSDT"},"data":[{"asks":[["64835.95","0.044879"],["64838.19","0"]],"bids":[],"ts":"1784090313105","seq":656732317997,"pseq":656732317705}],"ts":1784090313108}
{"action":"update","arg":{"instType":"SPOT","channel":"books","instId":"BTCUSDT"},"data":[{"asks":[["64842","0"],["64842.86","0.030876"]],"bids":[["64829.99","0.374539"],["64827.15","0.045098"],["64826.73","0"],["64820.12","0"],["64818.94","0.075163"],["64804.9","0"],["64801.38","0.150326"],["64785.46","0.150326"],["64418.54","0"]],"ts":"1784090313202","seq":656732318337,"pseq":656732317997}],"ts":1784090313206}
{"action":"update","arg":{"instType":"SPOT","channel":"books","instId":"BTCUSDT"},"data":[{"asks":[["64842","0"],["64842.85","0.030876"],["64842.86","0"],["64851.78","0.071415"],["64861.5","0.071415"],["64871.22","0.071415"],["64914.24","0.023805"],["64969.42","0"],["64979.16","0"],["64984.73","0"],["64993.22","0.023805"],["65071.14","0"],["65071.49","0"]],"bids":[["64826.6","0"],["64798.7","0"],["64770.8","0"],["64742.9","0"],["64715","0.007204"],["64418.54","0.000012"],["64418.23","0.000022"],["64417.65","0.000041"],["64417.11","0.000137"]],"ts":"1784090313303","seq":656732318662,"pseq":656732318337}],"ts":1784090313306}
{"action":"update","arg":{"instType":"SPOT","channel":"books","instId":"BTCUSDT"},"data":[{"asks":[["64837.7","0"],["64894.8","0"],["64951.9","0"],["65009","0"],["65066.1","0"],["65071.14","0.000056"],["65071.49","0.000008"],["65072.16","0.011176"],["65072.4","0.001256"],["65072.73","0.000019"]],"bids":[],"ts":"1784090313436","seq":656732319166,"pseq":656732318662}],"ts":1784090313440}
{"action":"update","arg":{"instType":"SPOT","channel":"books","instId":"BTCUSDT"},"data":[{"asks":[["64830.57","0.0258"],["65072.73","0"]],"bids":[],"ts":"1784090313521","seq":656732319336,"pseq":656732319166}],"ts":1784090313524}
{"action":"update","arg":{"instType":"SPOT","channel":"books","instId":"BTCUSDT"},"data":[{"asks":[],"bids":[["64826.6","0.002145"],["64798.7","0.002146"],["64770.8","0.002147"],["64742.9","0.002147"],["64715","0.009352"],["64418.54","0"],["64418.23","0"],["64417.65","0"],["64417.11","0"]],"ts":"1784090313604","seq":656732320022,"pseq":656732319336}],"ts":1784090313606}
{"action":"update","arg":{"instType":"SPOT","channel":"books","instId":"BTCUSDT"},"data":[{"asks":[["64830","1.024978"],["64837.7","0.002144"],["64851.78","0"],["64861.5","0"],["64871.22","0"],["64894.8","0.002142"],["64914.24","0"],["64951.9","0.002141"],["64993.22","0"],["65009","0.002139"],["65066.1","0.002137"]],"bids":[["64816.05","0.030876"],["64815.54","0"]],"ts":"1784090313701","seq":656732320494,"pseq":656732320022}],"ts":1784090313704}
{"action":"update","arg":{"instType":"SPOT","channel":"books","instId":"BTCUSDT"},"data":[{"asks":[],"bids":[["64828.37","0"],["64823.06","0.061705"],["64779","0"],["64778","0"],["64777","0"],["64776","0"],["64775","0.02"],["64774","0"],["64773","0"],["64772","0"],["64771","0"],["64770","0.02"],["64418.54","0.000012"],["64418.23","0.000022"],["64417.65","0.000041"],["64417.11","0.000137"],["64416.77","0.000388"],["64416.67","0.000706"],["64416.21","0.000031"],["64415.73","0.000035"]],"ts":"1784090313811","seq":656732320856,"pseq":656732320494}],"ts":1784090313815}
{"action":"update","arg":{"instType":"SPOT","channel":"books","instId":"BTCUSDT"},"data":[{"asks":[["64842","0.030876"],["64842.85","0"]],"bids":[],"ts":"1784090313930","seq":656732321128,"pseq":656732320856}],"ts":1784090313932}
{"action":"update","arg":{"instType":"SPOT","channel":"books","instId":"BTCUSDT"},"data":[{"asks":[["64970.46","0.071415"],["64979.16","0.071415"],["64988.9","0.071415"],["65071.49","0"],["65072.16","0"],["65072.4","0"]],"bids":[["64829.99","0.375187"],["64827.08","0"],["64812.6","0.110763"],["64415.38","0.000029"]],"ts":"1784090314019","seq":656732321519,"pseq":656732321128}],"ts":1784090314022}
{"action":"update","arg":{"instType":"SPOT","channel":"books","instId":"BTCUSDT"},"data":[{"asks":[["64957.91","0.071415"],["64988.9","0"]],"bids":[["64823.06","0"],["64415.26","0.000172"]],"ts":"1784090314101","seq":656732321725,"pseq":656732321519}],"ts":1784090314104}
{"action":"update","arg":{"instType":"SPOT","channel":"books","instId":"BTCUSDT"},"data":[{"asks":[["64830","1.794595"],["64830.57","0"],["64831.48","0.001542"],["64833.42","0"],["64835.44","0"],["64916.58","0.000667"],["64957.91","0"],["64988.9","0.071415"],["65071.49","0.000008"]],"bids":[["64825.39","0.005065"],["64825.09","0"],["64825","0"],["64823.05","0"],["64823.03","0"],["64822.19","0.000771"],["64821.61","0.741877"],["64821.05","0"],["64821.04","0"],["64819.11","0"],["64819.1","0"],["64819.09","0"],["64818.49","0"],["64818.36","0.741877"],["64818.12","0.015626"],["64817.02","0"],["64816.05","0"],["64815.02","0.030877"],["64813.06","0.001542"],["64772.17","0"],["64737.77","0.000667"],["64737.08","1.878116"],["64729.78","0"],["64728.11","0.1593"],["64715.06","1.068997"],["64415","0.02"],["64414.81","0.000015"],["64414.8","0.00003"],["64414.63","0.000779"]],"ts":"1784090314209","seq":656732322007,"pseq":656732321725}],"ts":1784090314214}
{"action":"update","arg":{"instType":"SPOT","channel":"books","instId":"BTCUSDT"},"data":[{"asks":[["64830","1.800319"],["64843.02","0.077175"],["64843.31","0.015908"],["64861.03","0"],["64876.33","0.154351"],["64876.99","0"]],"bids":[["64822.19","0"],["64821.63","0.061705"],["64821.62","0.284726"],["64818.38","0.309116"],["64818.37","0.273666"],["64815.02","0.030877"],["64812.98","0"],["64812.6","0.406466"],["64414.81","0"],["64414.8","0"],["64414.63","0"]],"ts":"1784090314308","seq":656732324635,"pseq":656732322007}],"ts":1784090314310}
{"action":"update","arg":{"instType":"SPOT","channel":"trade","instId":"BTCUSDT"},"data":[{"ts":"1784090314325","price":"64829.99","size":"0.00052","side":"sell","tradeId":"1461146169738248192"}],"ts":1784090314327}
{"action":"update","arg":{"instType":"SPOT","channel":"books","instId":"BTCUSDT"},"data":[{"asks":[],"bids":[["64829.99","0.374667"],["64825.39","0"],["64822.19","0"],["64821.63","0.061705"],["64808.39","0.314181"],["64414.81","0.000015"]],"ts":"1784090314407","seq":656732326485,"pseq":656732324635}],"ts":1784090314410}
{"action":"update","arg":{"instType":"SPOT","channel":"trade","instId":"BTCUSDT"},"data":[{"ts":"1784090314462","price":"64829.99","size":"0.00052","side":"sell","tradeId":"1461146170312867840"}],"ts":1784090314463}
{"action":"update","arg":{"instType":"SPOT","channel":"books","instId":"BTCUSDT"},"data":[{"asks":[],"bids":[["64829.99","0.374147"],["64825.39","0.005065"],["64822.19","0.000771"],["64821.63","0"],["64414.81","0"]],"ts":"1784090314518","seq":656732329749,"pseq":656732326485}],"ts":1784090314522}
{"action":"update","arg":{"instType":"SPOT","channel":"books","instId":"BTCUSDT"},"data":[{"asks":[],"bids":[["64822.19","0.000771"],["64821.63","0"]],"ts":"1784090314601","seq":656732332133,"pseq":656732329749}],"ts":1784090314604}
{"action":"update","arg":{"instType":"SPOT","channel":"books","instId":"BTCUSDT"},"data":[{"asks":[],"bids":[["64829.99","0.374183"],["64822.19","0"],["64821.63","0.061705"]],"ts":"1784090314725","seq":656732334923,"pseq":656732332133}],"ts":1784090314728}
{"action":"update","arg":{"instType":"SPOT","channel":"books","instId":"BTCUSDT"},"data":[{"asks":[],"bids":[["64822.19","0.000771"],["64821.63","0"]],"ts":"1784090314808","seq":656732336594,"pseq":656732334923}],"ts":1784090314812}
{"action":"update","arg":{"instType":"SPOT","channel":"books","instId":"BTCUSDT"},"data":[{"asks":[],"bids":[["64826.94","0"],["64823.46","0.001542"],["64822.19","0.000771"],["64821.63","0"],["64815.86","0.030877"],["64815.02","0"]],"ts":"1784090314905","seq":656732339066,"pseq":656732336594}],"ts":1784090314908}
{"action":"update","arg":{"instType":"SPOT","channel":"books","instId":"BTCUSDT"},"data":[{"asks":[["64830","1.800319"],["64834.72","0.046305"],["64835.95","0"]],"bids":[["64825.38","0.015426"],["64822.19","0.000771"],["64821.63","0"],["64815.86","0"],["64815.02","0.030878"]],"ts":"1784090315005","seq":656732340932,"pseq":656732339066}],"ts":1784090315008}
{"action":"update","arg":{"instType":"SPOT","channel":"books","instId":"BTCUSDT"},"data":[{"asks":[],"bids":[["64827.15","0"],["64826.16","0.046305"],["64822.19","0.000771"],["64821.63","0"]],"ts":"1784090315110","seq":656732342180,"pseq":656732340932}],"ts":1784090315114}
{"action":"update","arg":{"instType":"SPOT","channel":"trade","instId":"BTCUSDT"},"data":[{"ts":"1784090315125","price":"64829.99","size":"0.000019","side":"sell","tradeId":"1461146173093691392"}],"ts":1784090315127}
{"action":"update","arg":{"instType":"SPOT","channel":"books","instId":"BTCUSDT"},"data":[{"asks":[["64830","1.794595"],["64838.43","0.05"],["64850.37","0"],["64853.23","1.874752"],["64856.38","0"],["64864.75","0.4625"],["64869.83","0"],["64873.28","0"],["64875.27","1.390618"],["64878.42","0"],["65072.16","0.011176"]],"bids":[["64829.99","0.374164"],["64825.39","0.005407"],["64825.38","0"],["64824.28","0"],["64823.68","0.015426"],["64822.38","0"],["64822.19","0"],["64821.63","0"],["64821.62","0"],["64821.61","0.276636"],["64820.33","0.061705"],["64820.32","0.741877"],["64818.94","0"],["64818.39","0.309116"],["64818.38","0"],["64818.12","0"],["64816.8","0.077176"],["64815.02","0"],["64813.06","0"],["64812.99","0.030877"],["64812.98","0"],["64806.03","0.181834"],["64805.2","0"],["64801.38","0"],["64800.03","0.154352"],["64796.08","0"],["64786.59","0.373445"],["64750.14","0"],["64747.66","1.877808"],["64737.08","0"],["64725.63","1.878448"],["64715.06","0"],["64703.61","1.069186"],["64414.81","0.000015"],["64414.8","0.00003"]],"ts":"1784090315203","seq":656732344865,"pseq":656732342180}],"ts":1784090315206}
{"action":"update","arg":{"instType":"SPOT","channel":"books","instId":"BTCUSDT"},"data":[{"asks":[["64830","1.804373"],["64832.83","0"],["64845.71","0"],["64944.24","0.071415"],["64953.97","0.071415"],["64979.16","0"],["64988.9","0"],["65072.4","0.001256"],["65072.73","0.000019"]],"bids":[["64822.33","0"],["64822.32","0.452262"],["64822.31","0.741877"],["64822.19","0"],["64821.61","0"],["64820.33","0"],["64815.03","0"],["64815.02","0"],["64812.99","0"],["64812.98","0.030877"],["64812.6","0.110763"],["64811.29","0.001542"],["64808.39","0.309116"],["64790.01","0"],["64785.46","0"],["64784.57","0.154351"],["64763.26","1.877356"],["64725.63","0"],["64719.2","1.068929"],["64703.61","0"],["64414.8","0"]],"ts":"1784090315307","seq":656732346026,"pseq":656732344865}],"ts":1784090315310}
{"action":"update","arg":{"instType":"SPOT","channel":"books","instId":"BTCUSDT"},"data":[{"asks":[["64830","1.810407"],["64845.27","0.181116"],["64864.72","0.352597"],["64944.24","0"],["64953.97","0"],["64979.16","0.071415"],["64988.9","0.071415"],["65072.4","0"],["65072.73","0"]],"bids":[["64822.32","0.452262"],["64812.6","0.238588"],["64747.66","0"],["64414.8","0.00003"]],"ts":"1784090315404","seq":656732346572,"pseq":656732346026}],"ts":1784090315406}
{"action":"update","arg":{"instType":"SPOT","channel":"books","instId":"BTCUSDT"},"data":[{"asks":[["64830","1.812098"],["64831.21","0.046308"],["64834.72","0"],["64835.92","0"],["64836.48","0.030879"],["64837.51","0"],["64838.42","0"],["64839.52","0"],["64839.99","0"],["64841.1","0.035"],["64842","0"],["64848.77","0.001542"],["64849.06","0.001542"],["64855.76","0"],["64855.96","0"],["65072.16","0"]],"bids":[["64829.99","0.344546"],["64829.83","0"],["64829.61","0"],["64828.96","0"],["64828.46","0"],["64828.36","0"],["64827.55","0.005714"],["64827.07","0"],["64826.59","0"],["64826.16","0"],["64825.39","0"],["64824.88","0.00853"],["64823.69","0"],["64822.79","0.046307"],["64822.32","0"],["64822.31","0"],["64822.18","0"],["64820.33","0"],["64820.32","0"],["64819.47","0.483319"],["64819.09","0.000771"],["64818.76","0.741877"],["64818.39","0"],["64818.37","0"],["64818.36","0"],["64817.88","0.015802"],["64817.01","0"],["64816.78","0.741877"],["64815.85","0.021896"],["64815.84","0"],["64812.98","0"],["64812.07","0"],["64812.06","0"],["64811.29","0"],["64810.81","0"],["64809.97","0.035"],["64809.79","0.03088"],["64809.65","0"],["64807.79","0.001542"],["64802.78","0"],["64800.47","0"],["64795.3","0.001543"],["64793","0.001543"],["64731.51","1.878277"],["64414.63","0.000779"],["64414.41","0.000326"],["64414.32","0.000039"],["64413.31","0.000034"],["64412.83","0.000791"]],"ts":"1784090315501","seq":656732349437,"pseq":656732346572}],"ts":1784090315504}
{"action":"update","arg":{"instType":"SPOT","channel":"trade","instId":"BTCUSDT"},"data":[{"ts":"1784090315512","price":"64829.99","size":"0.03635","side":"sell","tradeId":"1461146174716887040"}],"ts":1784090315514}
{"action":"update","arg":{"instType":"SPOT","channel":"books","instId":"BTCUSDT"},"data":[{"asks":[["64836.48","0"],["64837.51","0.030879"],["64841.66","0.211979"],["64857.66","0.626525"],["64871.07","0"],["64899.03","0"]],"bids":[["64829.99","0.308196"],["64828.06","0.005713"],["64827.55","0"],["64826.6","0"],["64825.98","0"],["64825.95","0.026241"],["64823.68","0"],["64821.61","0.207546"],["64818.77","0.470655"],["64817.89","0"],["64817.88","0"],["64816.81","0.061705"],["64815.85","0.158717"],["64812.6","0.426125"],["64808.26","0"],["64807.41","0.083861"],["64804.17","0"],["64799.27","0.046296"],["64798.7","0"],["64770.8","0"],["64742.9","0"],["64715","0.007204"],["64412.55","0.00001"]],"ts":"1784090315611","seq":656732352529,"pseq":656732349437}],"ts":1784090315614}
{"action":"update","arg":{"instType":"SPOT","channel":"books","instId":"BTCUSDT"},"data":[{"asks":[["64830","1.812101"],["64837.6","0"],["64839.53","0"],["64869.71","0.313666"],["64876.33","0"],["65072.16","0.011176"],["65072.4","0.001256"],["65072.73","0.000019"]],"bids":[["64821.61","0"],["64816.81","0"],["64813.64","0"],["64812.98","0.061705"],["64808.39","0.516662"],["64803.19","0"],["64412.5","0.000981"],["64412","0.000036"]],"ts":"1784090315701","seq":656732355596,"pseq":656732352529}],"ts":1784090315704}
{"action":"update","arg":{"instType":"SPOT","channel":"books","instId":"BTCUSDT"},"data":[{"asks":[["64837.7","0"],["64894.8","0"],["64951.9","0"],["65009","0"],["65066.1","0"],["65072.77","0.000143"],["65072.85","0.000048"],["65072.99","0.000027"],["65073","0.007112"],["65073.13","0.000011"]],"bids":[["64816.05","0"],["64815.86","0.061705"],["64815.02","0"],["64812.98","0"]],"ts":"1784090315805","seq":656732357669,"pseq":656732355596}],"ts":1784090315808}
{"action":"update","arg":{"instType":"SPOT","channel":"books","instId":"BTCUSDT"},"data":[{"asks":[["64835.3","0.002144"],["64892.4","0.002143"],["64949.5","0.002141"],["65006.6","0.002139"],["65063.7","0.002137"],["65072.77","0"],["65072.85","0"],["65072.99","0"],["65073","0"],["65073.13","0"]],"bids":[["64816.05","0"],["64815.86","0.061705"],["64809.78","0"],["64808.4","0.154264"]],"ts":"1784090315902","seq":656732358047,"pseq":656732357669}],"ts":1784090315904}
{"action":"update","arg":{"instType":"SPOT","channel":"trade","instId":"BTCUSDT"},"data":[{"ts":"1784090315977","price":"64829.99","size":"0.024323","side":"sell","tradeId":"1461146176667238410"},{"ts":"1784090315977","price":"64829.99","size":"0.028244","side":"sell","tradeId":"1461146176667238408"},{"ts":"1784090315977","price":"64829.99","size":"0.174301","side":"sell","tradeId":"1461146176667238406"},{"ts":"1784090315977","price":"64829.99","size":"0.038754","side":"sell","tradeId":"1461146176667238404"},{"ts":"1784090315977","price":"64829.99","size":"0.0095","side":"sell","tradeId":"1461146176667238402"},{"ts":"1784090315977","price":"64829.99","size":"0.022033","side":"sell","tradeId":"1461146176667238400"}],"ts":1784090315979}
{"action":"update","arg":{"instType":"SPOT","channel":"books","instId":"BTCUSDT"},"data":[{"asks":[["64828.07","2.268574"],["64828.34","0.001691"],["64829","0"],["64829.24","0.001542"],["64829.99","0"],["64830","1.375242"],["64831.23","0"],["64831.24","0"],["64831.48","0"],["64832.29","0"],["64834.5","0.001542"],["64834.64","0"],["64834.82","0.000771"],["64837.96","0"],["64839.23","0"],["64844.22","0.001542"],["64849.63","0"],["64853.34","0"],["64855.04","0"],["64857.19","0.001541"],["64862.6","0"],["64868.9","0"],["64958.63","0.071415"],["64988.9","0"],["65072.77","0.000143"],["65072.85","0.000048"],["65072.99","0.000027"],["65073","0.007112"]],"bids":[["64829.99","0"],["64828.06","0.007341"],["64823.58","0.015426"],["64823.46","0"],["64821.6","0"],["64821.53","0.001542"],["64819.48","0.205976"],["64816.81","0"],["64815.86","0"],["64810.73","0"],["64808.4","0.217539"],["64808.39","0.309116"],["64805.33","0.001543"],["64411.76","0.000011"]],"ts":"1784090316001","seq":656732358478,"pseq":656732358047}],"ts":1784090316004}
{"action":"update","arg":{"instType":"SPOT","channel":"books","instId":"BTCUSDT"},"data":[{"asks":[["64828.07","2.334145"],["64830","1.071292"],["64833.84","0.015701"],["64836.17","0.07956"],["64838.07","0"],["64845.56","0.070234"],["64848.75","0.071415"],["64858.47","0.071415"],["64868.19","0.071415"],["64910.7","0.023805"],["64958.63","0"],["64970.46","0"],["64979.16","0"],["65072.99","0"],["65073","0"]],"bids":[["64828.06","0.151193"],["64819.51","0.061705"],["64819.5","0.2403"],["64819.49","0.26"],["64819.48","0"],["64813.6","0.015085"],["64811.92","0"],["64810.81","0.030877"],["64809.79","0"],["64808.4","0.154264"],["64802.9","0.015301"],["64412.55","0"],["64412.5","0"],["64412","0"],["64411.76","0"]],"ts":"1784090316110","seq":656732359781,"pseq":656732358478}],"ts":1784090316112}
{"action":"update","arg":{"instType":"SPOT","channel":"books","instId":"BTCUSDT"},"data":[{"asks":[],"bids":[["64828.06","0.305447"],["64819.52","0.26"],["64819.5","0"],["64819.49","0"],["64811.92","0.030877"],["64810.81","0"],["64412.55","0.00001"]],"ts":"1784090316210","seq":656732361205,"pseq":656732359781}],"ts":1784090316214}
{"action":"update","arg":{"instType":"SPOT","channel":"books","instId":"BTCUSDT"},"data":[{"asks":[["64838.54","0.07718"],["64843.02","0"]],"bids":[["64826.81","0.026241"],["64825.95","0"],["64819.53","0.061705"],["64819.51","0"],["64811.92","0"],["64810.81","0.030877"]],"ts":"1784090316304","seq":656732363032,"pseq":656732361205}],"ts":1784090316308}
{"action":"update","arg":{"instType":"SPOT","channel":"books","instId":"BTCUSDT"},"data":[{"asks":[],"bids":[["64828.06","0.151193"],["64819.55","0.061705"],["64819.54","0.26"],["64819.53","0"],["64819.52","0"],["64814.36","0.001542"],["64807.79","0"]],"ts":"1784090316401","seq":656732365293,"pseq":656732363032}],"ts":1784090316404}
{"action":"update","arg":{"instType":"SPOT","channel":"trade","instId":"BTCUSDT"},"data":[{"ts":"1784090316510","price":"64828.06","size":"0.00015","side":"sell","tradeId":"1461146178902802432"}],"ts":1784090316511}
{"action":"update","arg":{"instType":"SPOT","channel":"books","instId":"BTCUSDT"},"data":[{"asks":[["64828.07","2.488399"]],"bids":[["64828.06","0.151043"],["64819.55","0.283586"]],"ts":"1784090316510","seq":656732367770,"pseq":656732365293}],"ts":1784090316514}
{"action":"update","arg":{"instType":"SPOT","channel":"books","instId":"BTCUSDT"},"data":[{"asks":[["64836.48","0"],["64837.5","0.030878"],["64837.51","0"]],"bids":[["64823.1","0.002145"],["64819.57","0.192981"],["64819.56","0.26"],["64819.55","0"],["64819.54","0"],["64816.81","0.061705"],["64810.81","0.030878"],["64810.01","0"],["64795.2","0.002146"],["64767.3","0.002147"],["64739.4","0.002148"],["64711.5","0.002148"],["64414.63","0"],["64414.41","0"],["64414.32","0"],["64413.31","0"],["64412.83","0"],["64412.55","0"]],"ts":"1784090316608","seq":656732369623,"pseq":656732367770}],"ts":1784090316612}
{"action":"update","arg":{"instType":"SPOT","channel":"books","instId":"BTCUSDT"},"data":[{"asks":[["64998.01","0.009245"],["65072.85","0"]],"bids":[["64819.58","0.26"],["64819.56","0"],["64818.77","0.252884"],["64818.76","0"],["64808.4","0.3866"],["64414.63","0.000779"]],"ts":"1784090316717","seq":656732372109,"pseq":656732369623}],"ts":1784090316720}
{"action":"update","arg":{"instType":"SPOT","channel":"books","instId":"BTCUSDT"},"data":[{"asks":[["64828.07","2.488399"]],"bids":[["64819.6","0.027384"],["64819.59","0"],["64819.58","0"],["64819.57","0"],["64812.6","0.001542"],["64808.4","0.154264"],["64414.41","0.000326"]],"ts":"1784090316783","seq":656732373478,"pseq":656732372109}],"ts":1784090316800}
{"action":"update","arg":{"instType":"SPOT","channel":"books","instId":"BTCUSDT"},"data":[{"asks":[],"bids":[["64779","0.000035"],["64414.41","0"]],"ts":"1784090316839","seq":656732374581,"pseq":656732373478}],"ts":1784090316844}
{"action":"update","arg":{"instType":"SPOT","channel":"books","instId":"BTCUSDT"},"data":[{"asks":[],"bids":[["64819.6","0.14077"],["64812.6","0.505618"],["64808.4","0.359318"]],"ts":"1784090316885","seq":656732375444,"pseq":656732374581}],"ts":1784090316901}
{"action":"update","arg":{"instType":"SPOT","channel":"books","instId":"BTCUSDT"},"data":[{"asks":[["64848.75","0"],["64858.47","0"],["64868.19","0"],["64910.7","0"],["65072.85","0.000048"],["65072.99","0.000027"],["65073","0.007112"],["65073.13","0.000011"]],"bids":[],"ts":"1784090316925","seq":656732376156,"pseq":656732375444}],"ts":1784090316928}
{"action":"update","arg":{"instType":"SPOT","channel":"books","instId":"BTCUSDT"},"data":[{"asks":[["64837.5","0"],["64837.77","0.030878"],["64843.31","0.016949"],["64847.78","0"],["64953.74","0.071415"],["64963.48","0.071415"],["65073.13","0"]],"bids":[["64818.78","0.061705"],["64816.81","0"],["64811.92","0.030878"],["64810.81","0"]],"ts":"1784090316997","seq":656732377487,"pseq":656732376156}],"ts":1784090317002}
{"action":"update","arg":{"instType":"SPOT","channel":"books","instId":"BTCUSDT"},"data":[{"asks":[["64837.77","0"],["64838.42","0.030877"]],"bids":[],"ts":"1784090317003","seq":656732377596,"pseq":656732377487}],"ts":1784090317006}
{"action":"update","arg":{"instType":"SPOT","channel":"books","instId":"BTCUSDT"},"data":[{"asks":[["64829.99","0.481661"],["64833.84","0"],["64839.63","0.319779"],["64844.77","0"],["64845.56","0"],["64953.74","0"],["65073.13","0.000011"],["65073.53","0.000179"],["65074.07","0.000012"]],"bids":[["64826.81","0"],["64826.29","0.026241"],["64819.62","0.26"],["64819.61","0.061705"],["64819.6","0"],["64818.94","0"],["64818.93","0.741877"],["64818.78","0"],["64818.77","0"],["64811.92","0"],["64810.81","0.030878"],["64808.4","0.154264"],["64800.03","0"],["64796.03","0.154363"]],"ts":"1784090317104","seq":656732379175,"pseq":656732377596}],"ts":1784090317106}
{"action":"update","arg":{"instType":"SPOT","channel":"books","instId":"BTCUSDT"},"data":[{"asks":[["64985.23","0.071415"],["65074.07","0"]],"bids":[["64819.64","0.061705"],["64819.63","0.221881"],["64819.61","0"],["64818.94","0.426173"],["64816.8","0"],["64813.05","0.077181"],["64811.92","0.030877"],["64810.81","0"],["64494.36","0.000266"],["64431.5","0.000266"],["64414.8","0"],["64414.63","0"]],"ts":"1784090317190","seq":656732380544,"pseq":656732379175}],"ts":1784090317211}
{"action":"update","arg":{"instType":"SPOT","channel":"books","instId":"BTCUSDT"},"data":[{"asks":[["64973.21","0.071415"],["65073.53","0"]],"bids":[["64811.92","0"],["64810.81","0.030877"]],"ts":"1784090317212","seq":656732380852,"pseq":656732380544}],"ts":1784090317214}
{"action":"update","arg":{"instType":"SPOT","channel":"books","instId":"BTCUSDT"},"data":[{"asks":[["64835.93","0.127556"],["64836.16","0.46315"],["64837.51","0.030878"],["64838.42","0"],["64839.63","0.118926"],["65073.13","0"]],"bids":[["64819.67","0.061705"],["64819.66","0.2403"],["64819.65","0.26"],["64819.64","0"],["64819.63","0"],["64819.62","0"],["64818.93","0"],["64812.61","0.46315"],["64784.57","0"],["64780.25","0.154363"]],"ts":"1784090317301","seq":656732381855,"pseq":656732380852}],"ts":1784090317304}
{"action":"update","arg":{"instType":"SPOT","channel":"books","instId":"BTCUSDT"},"data":[{"asks":[["64833.95","0.757383"],["64835.93","0.5547"]],"bids":[["64819.69","0.061705"],["64819.68","0.26"],["64819.67","0"],["64819.65","0"],["64818.94","0.22145"],["64811.92","0"],["64810.81","0.030878"],["64808.4","0.291222"]],"ts":"1784090317407","seq":656732383385,"pseq":656732381855}],"ts":1784090317410}
{"action":"update","arg":{"instType":"SPOT","channel":"books","instId":"BTCUSDT"},"data":[{"asks":[["64829.84","0.046308"],["64831.21","0"]],"bids":[["64822.79","0"],["64821.12","0.046308"],["64819.7","0.061705"],["64819.69","0.221881"],["64819.66","0"],["64808.4","0.309641"]],"ts":"1784090317508","seq":656732385253,"pseq":656732383385}],"ts":1784090317510}
{"action":"update","arg":{"instType":"SPOT","channel":"books","instId":"BTCUSDT"},"data":[{"asks":[["64828.07","2.488399"]],"bids":[["64819.72","0.2403"],["64819.71","0.26"],["64819.69","0"],["64819.68","0"]],"ts":"1784090317603","seq":656732386753,"pseq":656732385253}],"ts":1784090317606}
{"action":"update","arg":{"instType":"SPOT","channel":"books","instId":"BTCUSDT"},"data":[{"asks":[["64854.82","0.154363"],["64869.71","0.1593"],["65073","0"]],"bids":[["64819.73","0.061705"],["64819.7","0"],["64815.85","0"],["64812.98","0.449189"],["64812.61","0"],["64812.6","0.001542"],["64808.4","0.154264"],["64414.8","0.00003"]],"ts":"1784090317688","seq":656732388140,"pseq":656732386753}],"ts":1784090317717}
{"action":"update","arg":{"instType":"SPOT","channel":"books","instId":"BTCUSDT"},"data":[{"asks":[["64851.32","0"],["65073","0.007112"]],"bids":[["64819.71","0"],["64414.63","0.000779"]],"ts":"1784090317728","seq":656732388827,"pseq":656732388140}],"ts":1784090317730}
{"action":"update","arg":{"instType":"SPOT","channel":"books","instId":"BTCUSDT"},"data":[{"asks":[["64841.87","0.483309"],["65073","0"]],"bids":[["64819.74","0"],["64819.73","0.203436"],["64819.72","0"],["64819.48","0.26"],["64815.02","0.323601"],["64557.22","0"],["64494.36","0"],["64431.5","0"],["64414.41","0.000326"],["64414.32","0.000039"]],"ts":"1784090317803","seq":656732390718,"pseq":656732388827}],"ts":1784090317806}
{"action":"update","arg":{"instType":"SPOT","channel":"books","instId":"BTCUSDT"},"data":[{"asks":[["64848.75","0.071415"],["64858.47","0.071415"],["64868.19","0.071415"],["64910.7","0.023805"],["64963.48","0"],["64973.21","0"],["64985.23","0"],["65072.99","0"]],"bids":[["64826.33","0.026241"],["64826.29","0"],["64816.79","0.061705"],["64815.02","0.189519"],["64812.98","0"],["64812.6","0.505618"],["64811.92","0.449365"],["64808.39","0.380176"],["64414.32","0"]],"ts":"1784090317896","seq":656732392514,"pseq":656732390718}],"ts":1784090317919}
{"action":"update","arg":{"instType":"SPOT","channel":"books","instId":"BTCUSDT"},"data":[{"asks":[["64828.07","2.488399"],["64837.4","0.077182"],["64838.54","0"]],"bids":[],"ts":"1784090318283","seq":656732398061,"pseq":656732392514}],"ts":1784090318286}
{"action":"update","arg":{"instType":"SPOT","channel":"books","instId":"BTCUSDT"},"data":[{"asks":[],"bids":[["64808.39","0.452136"]],"ts":"1784090318311","seq":656732398126,"pseq":656732398061}],"ts":1784090318314}
{"action":"update","arg":{"instType":"SPOT","channel":"books","instId":"BTCUSDT"},"data":[{"asks":[],"bids":[["64826.33","0"],["64825.93","0.026241"]],"ts":"1784090318590","seq":656732400387,"pseq":656732398126}],"ts":1784090318594}
{"action":"update","arg":{"instType":"SPOT","channel":"books","instId":"BTCUSDT"},"data":[{"asks":[["64835.3","0"],["64892.4","0"],["64949.5","0"],["65006.6","0"],["65063.7","0"],["65072.99","0.000027"],["65073","0.007112"],["65073.13","0.000011"],["65073.53","0.000179"],["65074.07","0.000012"]],"bids":[],"ts":"1784090318936","seq":656732401630,"pseq":656732400387}],"ts":1784090318940}
{"action":"update","arg":{"instType":"SPOT","channel":"books","instId":"BTCUSDT"},"data":[{"asks":[["64828.07","2.488399"]],"bids":[],"ts":"1784090319004","seq":656732401815,"pseq":656732401630}],"ts":1784090319008}
{"action":"update","arg":{"instType":"SPOT","channel":"trade","instId":"BTCUSDT"},"data":[{"ts":"1784090319064","price":"64828.07","size":"0.000847","side":"buy","tradeId":"1461146189615054848"}],"ts":1784090319065}
{"action":"update","arg":{"instType":"SPOT","channel":"books","instId":"BTCUSDT"},"data":[{"asks":[["64828.07","2.487552"]],"bids":[["64818.77","0.741877"],["64812.6","0.968774"],["64811.92","0"],["64808.39","0.452983"],["64796.03","0"],["64795.96","0.154364"]],"ts":"1784090319101","seq":656732402376,"pseq":656732401815}],"ts":1784090319104}
{"action":"update","arg":{"instType":"SPOT","channel":"books","instId":"BTCUSDT"},"data":[{"asks":[],"bids":[["64819.74","0.061705"],["64818.94","0.433008"],["64816.79","0"],["64813.05","0"],["64812.81","0.077182"],["64808.39","0.309116"]],"ts":"1784090319206","seq":656732404268,"pseq":656732402376}],"ts":1784090319208}
{"action":"update","arg":{"instType":"SPOT","channel":"books","instId":"BTCUSDT"},"data":[{"asks":[["64834.2","0.002144"],["64891.3","0.002143"],["64948.4","0.002141"],["65005.5","0.002139"],["65062.6","0.002137"],["65072.99","0"],["65073","0"],["65073.13","0"],["65073.53","0"],["65074.07","0"]],"bids":[["64780.79","0.154363"],["64780.25","0"]],"ts":"1784090319308","seq":656732406354,"pseq":656732404268}],"ts":1784090319312}
{"action":"update","arg":{"instType":"SPOT","channel":"books","instId":"BTCUSDT"},"data":[{"asks":[["64829.7","0.046308"],["64829.84","0"]],"bids":[["64826.37","0.026241"],["64825.93","0"],["64821.22","0.046308"],["64821.12","0"],["64819.76","0.191289"],["64819.75","0.26"],["64819.73","0"],["64812.6","0.848516"],["64414.41","0"]],"ts":"1784090319404","seq":656732408472,"pseq":656732406354}],"ts":1784090319406}
{"action":"update","arg":{"instType":"SPOT","channel":"books","instId":"BTCUSDT"},"data":[{"asks":[],"bids":[["64819.77","0.061705"],["64819.74","0"],["64815.02","0"],["64812.6","0.464698"],["64414.41","0.000326"]],"ts":"1784090319502","seq":656732410358,"pseq":656732408472}],"ts":1784090319506}
{"action":"update","arg":{"instType":"SPOT","channel":"books","instId":"BTCUSDT"},"data":[{"asks":[["64854.82","0"],["65072.99","0.000027"]],"bids":[["64823.1","0"],["64819.79","0.379615"],["64819.78","0.26"],["64819.77","0"],["64819.76","0"],["64819.75","0"],["64815.02","0.16648"],["64812.61","0.34501"],["64795.2","0"],["64767.3","0"],["64739.4","0"],["64711.5","0"],["64414.32","0.000039"],["64413.31","0.000034"],["64412.83","0.000791"],["64412.55","0.00001"]],"ts":"1784090319603","seq":656732412349,"pseq":656732410358}],"ts":1784090319606}
{"action":"update","arg":{"instType":"SPOT","channel":"books","instId":"BTCUSDT"},"data":[{"asks":[["64870.13","0.154363"],["65072.99","0"]],"bids":[["64819.8","0.061705"],["64819.79","0.31791"],["64412.55","0"]],"ts":"1784090319710","seq":656732414276,"pseq":656732412349}],"ts":1784090319713}
{"action":"update","arg":{"instType":"SPOT","channel":"books","instId":"BTCUSDT"},"data":[{"asks":[["64828.07","2.487552"]],"bids":[["64819.81","0.321705"],["64819.8","0"],["64819.79","0"],["64819.78","0"],["64819.49","0.214324"],["64812.61","0"],["64412.55","0.00001"],["64412.5","0.000981"]],"ts":"1784090319807","seq":656732416336,"pseq":656732414276}],"ts":1784090319811}
{"action":"update","arg":{"instType":"SPOT","channel":"books","instId":"BTCUSDT"},"data":[{"asks":[["64848.75","0"],["64858.47","0"],["64868.19","0"],["64910.7","0"],["65072.99","0.000027"],["65073","0.007112"],["65073.13","0.000011"],["65073.53","0.000179"]],"bids":[["64823.1","0.002145"],["64812.61","0.448596"],["64795.2","0.002146"],["64767.3","0.002147"],["64739.4","0.002148"],["64711.5","0.002148"],["64414.41","0"],["64414.32","0"],["64413.31","0"],["64412.83","0"],["64412.55","0"],["64412.5","0"]],"ts":"1784090319911","seq":656732418830,"pseq":656732416336}],"ts":1784090319914}
{"action":"update","arg":{"instType":"SPOT","channel":"books","instId":"BTCUSDT"},"data":[{"asks":[["64963.98","0.071415"],["64973.71","0.071415"],["65073.13","0"],["65073.53","0"]],"bids":[["64819.82","0"],["64819.81","0"],["64819.51","0.26"],["64819.5","0.061705"],["64414.63","0"]],"ts":"1784090320001","seq":656732420617,"pseq":656732418830}],"ts":1784090320004}
{"action":"update","arg":{"instType":"SPOT","channel":"books","instId":"BTCUSDT"},"data":[{"asks":[],"bids":[["64819.52","0.061705"],["64819.5","0"]],"ts":"1784090320125","seq":656732423062,"pseq":656732420617}],"ts":1784090320128}
{"action":"update","arg":{"instType":"SPOT","channel":"books","instId":"BTCUSDT"},"data":[{"asks":[],"bids":[["64828.06","0.177283"],["64826.37","0"],["64819.53","0.26"],["64819.51","0"],["64414.63","0.000779"]],"ts":"1784090320210","seq":656732424434,"pseq":656732423062}],"ts":1784090320212}
{"action":"update","arg":{"instType":"SPOT","channel":"books","instId":"BTCUSDT"},"data":[{"asks":[["64837.4","0"],["64839.15","0.077179"]],"bids":[["64819.54","0.061705"],["64819.52","0"]],"ts":"1784090320305","seq":656732425813,"pseq":656732424434}],"ts":1784090320308}
{"action":"update","arg":{"instType":"SPOT","channel":"books","instId":"BTCUSDT"},"data":[{"asks":[],"bids":[["64819.55","0.26"],["64819.53","0"],["64763.71","0.016202"],["64749.19","0"]],"ts":"1784090320416","seq":656732427398,"pseq":656732425813}],"ts":1784090320420}
{"action":"update","arg":{"instType":"SPOT","channel":"books","instId":"BTCUSDT"},"data":[{"asks":[["64828.07","2.487552"]],"bids":[["64828.06","0.151043"],["64826.7","0.026241"],["64819.56","0.061705"],["64819.54","0"],["64414.63","0"]],"ts":"1784090320513","seq":656732429238,"pseq":656732427398}],"ts":1784090320517}
{"action":"update","arg":{"instType":"SPOT","channel":"books","instId":"BTCUSDT"},"data":[{"asks":[["64833.95","0.741877"],["64954.24","0.071415"],["65073","0"]],"bids":[["64819.56","0"],["64819.55","0"],["64816.79","0.061705"],["64812.6","0.001542"],["64811.92","0.452935"]],"ts":"1784090320624","seq":656732431272,"pseq":656732429238}],"ts":1784090320626}
{"action":"update","arg":{"instType":"SPOT","channel":"books","instId":"BTCUSDT"},"data":[{"asks":[],"bids":[["64796.93","0.154362"],["64795.96","0"]],"ts":"1784090321005","seq":656732438132,"pseq":656732431272}],"ts":1784090321008}
{"action":"update","arg":{"instType":"SPOT","channel":"books","instId":"BTCUSDT"},"data":[{"asks":[["64954.24","0"],["64985.16","0.071415"]],"bids":[["64819.5","0.061705"],["64816.79","0"],["64812.62","0.463157"],["64811.92","0"]],"ts":"1784090321115","seq":656732440808,"pseq":656732438132}],"ts":1784090321118}
{"action":"update","arg":{"instType":"SPOT","channel":"books","instId":"BTCUSDT"},"data":[{"asks":[],"bids":[["64819.52","0.061705"],["64819.51","0.26"],["64819.5","0"],["64814.36","0"],["64813.5","0.077181"],["64812.81","0"]],"ts":"1784090321203","seq":656732442546,"pseq":656732440808}],"ts":1784090321206}
{"action":"update","arg":{"instType":"SPOT","channel":"books","instId":"BTCUSDT"},"data":[{"asks":[["64828.07","2.487552"],["64829.7","0.046308"]],"bids":[["64826.7","0"],["64826.55","0.026241"],["64821.44","0.046308"],["64821.22","0"],["64816.11","0.001542"],["64781.39","0.154362"],["64780.79","0"],["64414.8","0"]],"ts":"1784090321302","seq":656732444471,"pseq":656732442546}],"ts":1784090321306}
{"action":"update","arg":{"instType":"SPOT","channel":"books","instId":"BTCUSDT"},"data":[{"asks":[],"bids":[["64819.52","0"],["64819.51","0"],["64816.79","0.061705"],["64812.62","0"],["64811.92","0.450819"],["64414.8","0.00003"]],"ts":"1784090321413","seq":656732446811,"pseq":656732444471}],"ts":1784090321416}
{"action":"update","arg":{"instType":"SPOT","channel":"books","instId":"BTCUSDT"},"data":[{"asks":[["64954.24","0.071415"],["64985.16","0"]],"bids":[],"ts":"1784090321510","seq":656732448359,"pseq":656732446811}],"ts":1784090321512}
{"action":"update","arg":{"instType":"SPOT","channel":"books","instId":"BTCUSDT"},"data":[{"asks":[["64854.11","0.154362"],["65072.99","0"]],"bids":[],"ts":"1784090321621","seq":656732449768,"pseq":656732448359}],"ts":1784090321624}
{"action":"update","arg":{"instType":"SPOT","channel":"books","instId":"BTCUSDT"},"data":[{"asks":[["64870.13","0"],["65072.99","0.000027"]],"bids":[["64819.5","0.26"],["64819.49","0.144271"],["64819.48","0"],["64808.4","0.224317"]],"ts":"1784090321701","seq":656732450679,"pseq":656732449768}],"ts":1784090321704}
{"action":"update","arg":{"instType":"SPOT","channel":"books","instId":"BTCUSDT"},"data":[{"asks":[],"bids":[["64819.51","0.221881"],["64819.49","0"]],"ts":"1784090321800","seq":656732452510,"pseq":656732450679}],"ts":1784090321805}
{"action":"update","arg":{"instType":"SPOT","channel":"books","instId":"BTCUSDT"},"data":[{"asks":[["64939.86","0.071415"],["64973.71","0"]],"bids":[["64819.53","0.240337"],["64819.52","0.26"],["64819.51","0"],["64819.5","0"],["64808.4","0.154264"]],"ts":"1784090321911","seq":656732454694,"pseq":656732452510}],"ts":1784090321917}
{"action":"update","arg":{"instType":"SPOT","channel":"books","instId":"BTCUSDT"},"data":[{"asks":[["64828.07","2.487552"]],"bids":[["64826.55","0"],["64826.1","0.026241"]],"ts":"1784090322008","seq":656732457009,"pseq":656732454694}],"ts":1784090322010}
{"action":"update","arg":{"instType":"SPOT","channel":"books","instId":"BTCUSDT"},"data":[{"asks":[["64828.07","2.477552"]],"bids":[["64819.55","0.221881"],["64819.54","0.26"],["64819.53","0"],["64819.52","0"]],"ts":"1784090322119","seq":656732459229,"pseq":656732457009}],"ts":1784090322122}
{"action":"update","arg":{"instType":"SPOT","channel":"books","instId":"BTCUSDT"},"data":[{"asks":[["64837.09","0.077182"],["64839.15","0"]],"bids":[],"ts":"1784090322230","seq":656732461347,"pseq":656732459229}],"ts":1784090322234}
{"action":"update","arg":{"instType":"SPOT","channel":"books","instId":"BTCUSDT"},"data":[{"asks":[["64834.2","0"],["64837.08","0.030878"],["64837.51","0"],["64847.82","0.071415"],["64857.54","0.071415"],["64867.26","0.071415"],["64891.3","0"],["64909.77","0.023805"],["64939.86","0"],["64948.4","0"],["64954.24","0"],["64963.98","0"],["65005.5","0"],["65062.6","0"],["65073","0.007112"],["65073.13","0.000011"],["65073.53","0.000179"],["65074.07","0.000012"]],"bids":[["64819.57","0.240337"],["64819.56","0.26"],["64819.55","0"],["64819.54","0"]],"ts":"1784090322325","seq":656732463212,"pseq":656732461347}],"ts":1784090322328}
{"action":"update","arg":{"instType":"SPOT","channel":"books","instId":"BTCUSDT"},"data":[{"asks":[],"bids":[["64819.58","0.26"],["64819.56","0"]],"ts":"1784090322431","seq":656732465253,"pseq":656732463212}],"ts":1784090322434}
{"action":"update","arg":{"instType":"SPOT","channel":"books","instId":"BTCUSDT"},"data":[{"asks":[],"bids":[["64819.59","0.221881"],["64819.57","0"]],"ts":"1784090322493","seq":656732466423,"pseq":656732465253}],"ts":1784090322503}
{"action":"update","arg":{"instType":"SPOT","channel":"books","instId":"BTCUSDT"},"data":[{"asks":[["64834.2","0.002144"],["64891.3","0.002143"],["64948.4","0.002141"],["65005.5","0.002139"],["65062.6","0.002137"],["65072.99","0"],["65073","0"],["65073.13","0"],["65073.53","0"],["65074.07","0"]],"bids":[],"ts":"1784090322536","seq":656732467218,"pseq":656732466423}],"ts":1784090322541}
{"action":"update","arg":{"instType":"SPOT","channel":"books","instId":"BTCUSDT"},"data":[{"asks":[["64828.07","2.467045"]],"bids":[["64819.59","0.143305"],["64819.58","0"],["64414.63","0.000779"]],"ts":"1784090322590","seq":656732468295,"pseq":656732467218}],"ts":1784090322604}
{"action":"update","arg":{"instType":"SPOT","channel":"books","instId":"BTCUSDT"},"data":[{"asks":[],"bids":[["64808.4","0.225283"]],"ts":"1784090322622","seq":656732468853,"pseq":656732468295}],"ts":1784090322626}
{"action":"update","arg":{"instType":"SPOT","channel":"books","instId":"BTCUSDT"},"data":[{"asks":[["64845.27","0"],["64864.72","0"],["65072.99","0.000027"],["65073","0.007112"]],"bids":[["64806.03","0"],["64786.59","0"],["64414.41","0.000326"],["64414.32","0.000039"]],"ts":"1784090322700","seq":656732470149,"pseq":656732468853}],"ts":1784090322704}
{"action":"update","arg":{"instType":"SPOT","channel":"books","instId":"BTCUSDT"},"data":[{"asks":[["64828.07","2.467046"],["64862.69","0.36224"],["65073","0"]],"bids":[["64826.1","0"],["64825.73","0.026242"],["64804.73","0.179474"],["64785.29","0.36886"],["64414.41","0"],["64414.32","0"]],"ts":"1784090322805","seq":656732471832,"pseq":656732470149}],"ts":1784090322808}
{"action":"update","arg":{"instType":"SPOT","channel":"books","instId":"BTCUSDT"},"data":[{"asks":[["64843.24","0.183982"],["65072.99","0"]],"bids":[["64823.1","0"],["64795.2","0"],["64767.3","0"],["64739.4","0"],["64711.5","0"],["64414.41","0.000326"],["64414.32","0.000039"],["64413.31","0.000034"],["64412.83","0.000791"],["64412.55","0.00001"]],"ts":"1784090322908","seq":656732472053,"pseq":656732471832}],"ts":1784090322912}
{"action":"update","arg":{"instType":"SPOT","channel":"books","instId":"BTCUSDT"},"data":[{"asks":[],"bids":[["64796.93","0"],["64796.5","0.154365"]],"ts":"1784090323005","seq":656732472206,"pseq":656732472053}],"ts":1784090323010}
pong
{"action":"update","arg":{"instType":"SPOT","channel":"books","instId":"BTCUSDT"},"data":[{"asks":[["64847.82","0"],["64857.54","0"],["64867.26","0"],["64909.77","0"],["64948.91","0.071415"],["64968.38","0.071415"],["65072.99","0.000027"],["65073","0.007112"]],"bids":[["64823.1","0.002145"],["64795.2","0.002146"],["64767.3","0.002147"],["64739.4","0.002148"],["64711.5","0.002148"],["64414.41","0"],["64414.32","0"],["64413.31","0"],["64412.83","0"],["64412.55","0"]],"ts":"1784090323088","seq":656732472909,"pseq":656732472206}],"ts":1784090323118}
{"action":"update","arg":{"instType":"SPOT","channel":"books","instId":"BTCUSDT"},"data":[{"asks":[],"bids":[["64819.48","0.26"],["64414.63","0"]],"ts":"1784090323189","seq":656732473065,"pseq":656732472909}],"ts":1784090323192}
{"action":"update","arg":{"instType":"SPOT","channel":"books","instId":"BTCUSDT"},"data":[{"asks":[],"bids":[["64819.59","0.203559"]],"ts":"1784090323213","seq":656732473158,"pseq":656732473065}],"ts":1784090323217}
{"action":"update","arg":{"instType":"SPOT","channel":"books","instId":"BTCUSDT"},"data":[{"asks":[["64828.69","0.046309"],["64829.7","0"]],"bids":[["64821.44","0"],["64820.67","0.046309"],["64813.5","0"],["64812.8","0.077182"],["64781.39","0"],["64414.63","0.000779"]],"ts":"1784090323311","seq":656732473405,"pseq":656732473158}],"ts":1784090323314}
{"action":"update","arg":{"instType":"SPOT","channel":"books","instId":"BTCUSDT"},"data":[{"asks":[["64832.89","0.015147"],["64847.82","0.071415"],["64857.54","0.071415"],["64867.26","0.071415"],["64909.77","0.023805"],["64948.91","0"],["64968.38","0"],["65072.85","0"],["65072.99","0"],["65073","0"]],"bids":[],"ts":"1784090323407","seq":656732473651,"pseq":656732473405}],"ts":1784090323410}
{"action":"update","arg":{"instType":"SPOT","channel":"books","instId":"BTCUSDT"},"data":[{"asks":[["64828.07","2.468547"]],"bids":[["64825.74","0.026242"],["64825.73","0"]],"ts":"1784090323501","seq":656732474071,"pseq":656732473651}],"ts":1784090323504}
{"action":"update","arg":{"instType":"SPOT","channel":"books","instId":"BTCUSDT"},"data":[{"asks":[["64854.11","0"],["65072.85","0.000048"]],"bids":[],"ts":"1784090323615","seq":656732475985,"pseq":656732474071}],"ts":1784090323618}
{"action":"update","arg":{"instType":"SPOT","channel":"books","instId":"BTCUSDT"},"data":[{"asks":[["64868.23","0.154365"],["65072.85","0"]],"bids":[],"ts":"1784090323786","seq":656732478131,"pseq":656732475985}],"ts":1784090323788}
{"action":"update","arg":{"instType":"SPOT","channel":"books","instId":"BTCUSDT"},"data":[{"asks":[["64828.07","2.478547"]],"bids":[],"ts":"1784090323850","seq":656732478830,"pseq":656732478131}],"ts":1784090323852}
{"action":"update","arg":{"instType":"SPOT","channel":"books","instId":"BTCUSDT"},"data":[{"asks":[["64864.41","0.019574"],["64877.35","0"]],"bids":[],"ts":"1784090323900","seq":656732479379,"pseq":656732478830}],"ts":1784090323902}
{"action":"update","arg":{"instType":"SPOT","channel":"books","instId":"BTCUSDT"},"data":[{"asks":[["64847.82","0"],["64857.54","0"],["64867.26","0"],["64909.77","0"],["64944.76","0.071415"],["64954.49","0.071415"],["65072.85","0.000048"],["65072.99","0.000027"]],"bids":[],"ts":"1784090324116","seq":656732482237,"pseq":656732479379}],"ts":1784090324118}
{"action":"update","arg":{"instType":"SPOT","channel":"books","instId":"BTCUSDT"},"data":[{"asks":[["64828.07","2.478547"],["64836.51","0.077182"],["64837.09","0"]],"bids":[["64825.75","0.026242"],["64825.74","0"]],"ts":"1784090324290","seq":656732484276,"pseq":656732482237}],"ts":1784090324294}
{"action":"update","arg":{"instType":"SPOT","channel":"books","instId":"BTCUSDT"},"data":[{"asks":[["64837.08","0"],["64837.51","0.030878"]],"bids":[],"ts":"1784090324302","seq":656732484389,"pseq":656732484276}],"ts":1784090324306}
{"action":"update","arg":{"instType":"SPOT","channel":"books","instId":"BTCUSDT"},"data":[{"asks":[],"bids":[["64828.06","0.14548"]],"ts":"1784090324601","seq":656732487469,"pseq":656732484389}],"ts":1784090324604}
{"action":"update","arg":{"instType":"SPOT","channel":"books","instId":"BTCUSDT"},"data":[{"asks":[],"bids":[["64826.98","0.003864"],["64414.63","0"]],"ts":"1784090324708","seq":656732488072,"pseq":656732487469}],"ts":1784090324711}
{"action":"update","arg":{"instType":"SPOT","channel":"books","instId":"BTCUSDT"},"data":[{"asks":[],"bids":[["64796.91","0.154365"],["64796.5","0"]],"ts":"1784090324947","seq":656732488888,"pseq":656732488072}],"ts":1784090324950}
{"action":"update","arg":{"instType":"SPOT","channel":"books","instId":"BTCUSDT"},"data":[{"asks":[["64828.07","2.478547"]],"bids":[["64825.78","0.026242"],["64825.75","0"]],"ts":"1784090325019","seq":656732489015,"pseq":656732488888}],"ts":1784090325022}
{"action":"update","arg":{"instType":"SPOT","channel":"books","instId":"BTCUSDT"},"data":[{"asks":[["64944.76","0"],["64964.22","0.071415"],["64969.56","0.071415"],["65072.99","0"]],"bids":[],"ts":"1784090325110","seq":656732489394,"pseq":656732489015}],"ts":1784090325113}
{"action":"update","arg":{"instType":"SPOT","channel":"trade","instId":"BTCUSDT"},"data":[{"ts":"1784090325193","price":"64828.06","size":"0.00015","side":"sell","tradeId":"1461146215321944064"}],"ts":1784090325196}
{"action":"update","arg":{"instType":"SPOT","channel":"books","instId":"BTCUSDT"},"data":[{"asks":[["64938.8","0.016201"],["64947.83","0"]],"bids":[["64828.06","0.14533"],["64828.04","0.003864"],["64826.98","0"]],"ts":"1784090325206","seq":656732490221,"pseq":656732489394}],"ts":1784090325210}
{"action":"update","arg":{"instType":"SPOT","channel":"books","instId":"BTCUSDT"},"data":[{"asks":[["64828.59","0.046309"],["64828.69","0"]],"bids":[["64820.74","0.046309"],["64820.67","0"],["64812.95","0.077182"],["64812.8","0"],["64781.49","0.154365"],["64414.8","0"]],"ts":"1784090325316","seq":656732490483,"pseq":656732490221}],"ts":1784090325318}
{"action":"update","arg":{"instType":"SPOT","channel":"books","instId":"BTCUSDT"},"data":[{"asks":[["64845.68","0.001542"],["64848.77","0"]],"bids":[],"ts":"1784090325409","seq":656732490706,"pseq":656732490483}],"ts":1784090325412}
{"action":"update","arg":{"instType":"SPOT","channel":"books","instId":"BTCUSDT"},"data":[{"asks":[["64845.68","0.003084"],["64847.82","0.071415"],["64849.06","0"],["64852.33","0.154365"],["64857.54","0.071415"],["64867.26","0.071415"],["64909.77","0.023805"],["64954.49","0"],["64964.22","0"],["64969.56","0"],["65072.85","0"]],"bids":[["64798.52","0.003086"],["64795.3","0"],["64793","0"],["64414.8","0.00003"]],"ts":"1784090325507","seq":656732490932,"pseq":656732490706}],"ts":1784090325510}
{"action":"update","arg":{"instType":"SPOT","channel":"books","instId":"BTCUSDT"},"data":[{"asks":[["64834.2","0"],["64891.3","0"],["64948.4","0"],["65005.5","0"],["65062.6","0"],["65072.85","0.000048"],["65072.99","0.000027"],["65073","0.007112"],["65073.13","0.000011"],["65073.53","0.000179"]],"bids":[],"ts":"1784090325608","seq":656732491306,"pseq":656732490932}],"ts":1784090325612}
{"action":"update","arg":{"instType":"SPOT","channel":"books","instId":"BTCUSDT"},"data":[{"asks":[["64847.82","0"],["64857.54","0"],["64867.26","0"],["64909.77","0"],["64955.15","0.071415"],["64964.89","0.071415"],["65074.07","0.000012"],["65074.09","0.000401"]],"bids":[],"ts":"1784090325705","seq":656732491451,"pseq":656732491306}],"ts":1784090325708}
{"action":"update","arg":{"instType":"SPOT","channel":"books","instId":"BTCUSDT"},"data":[{"asks":[["64834.2","0.002144"],["64891.3","0.002143"],["64948.4","0.002141"],["65005.5","0.002139"],["65062.6","0.002137"],["65073","0"],["65073.13","0"],["65073.53","0"],["65074.07","0"],["65074.09","0"]],"bids":[],"ts":"1784090325816","seq":656732491761,"pseq":656732491451}],"ts":1784090325818}
{"action":"update","arg":{"instType":"SPOT","channel":"books","instId":"BTCUSDT"},"data":[{"asks":[["64828.07","2.478546"],["64868.23","0"],["64955.15","0"],["64964.89","0"],["64974.76","0.071415"],["64984.5","0.071415"],["64994.24","0.071415"]],"bids":[["64826.29","0.026241"],["64825.78","0"]],"ts":"1784090325913","seq":656732491977,"pseq":656732491761}],"ts":1784090325916}
{"action":"update","arg":{"instType":"SPOT","channel":"books","instId":"BTCUSDT"},"data":[{"asks":[],"bids":[["64823.1","0"],["64795.2","0"],["64767.3","0"],["64739.4","0"],["64711.5","0"],["64414.63","0.000779"],["64414.41","0.000326"],["64414.32","0.000039"],["64413.31","0.000034"],["64412.83","0.000791"]],"ts":"1784090326136","seq":656732492500,"pseq":656732491977}],"ts":1784090326138}
{"action":"update","arg":{"instType":"SPOT","channel":"trade","instId":"BTCUSDT"},"data":[{"ts":"1784090326197","price":"64828.06","size":"0.00015","side":"sell","tradeId":"1461146219533025280"}],"ts":1784090326199}
{"action":"update","arg":{"instType":"SPOT","channel":"books","instId":"BTCUSDT"},"data":[{"asks":[],"bids":[["64828.06","0.14518"]],"ts":"1784090326203","seq":656732493167,"pseq":656732492500}],"ts":1784090326206}
{"action":"update","arg":{"instType":"SPOT","channel":"books","instId":"BTCUSDT"},"data":[{"asks":[["64828.07","2.481548"],["64836.36","0.077182"],["64836.48","0"],["64836.51","0"],["64837.5","0.030878"],["64837.51","0"],["64950.09","0.071415"],["64959.82","0.071415"],["64984.5","0"],["64994.24","0"]],"bids":[["64810.82","0.030878"],["64810.81","0"],["64810.01","0"]],"ts":"1784090326314","seq":656732493528,"pseq":656732493167}],"ts":1784090326318}
{"action":"update","arg":{"instType":"SPOT","channel":"books","instId":"BTCUSDT"},"data":[{"asks":[["64847.82","0.071415"],["64857.54","0.071415"],["64867.25","0.071415"],["64909.77","0.023805"],["64950.09","0"],["64959.82","0"],["64974.76","0"],["65072.99","0"]],"bids":[["64823","0.002145"],["64795.1","0.002146"],["64767.2","0.002147"],["64739.3","0.002148"],["64711.4","0.002148"],["64414.63","0"],["64414.41","0"],["64414.32","0"],["64413.31","0"],["64412.83","0"]],"ts":"1784090326411","seq":656732493743,"pseq":656732493528}],"ts":1784090326414}
{"action":"update","arg":{"instType":"SPOT","channel":"books","instId":"BTCUSDT"},"data":[{"asks":[["64847.82","0"],["64857.54","0"],["64867.25","0"],["64909.77","0"],["65072.99","0.000027"],["65073","0.007112"],["65073.13","0.000011"],["65073.53","0.000179"]],"bids":[],"ts":"1784090326541","seq":656732494123,"pseq":656732493743}],"ts":1784090326544}
{"action":"update","arg":{"instType":"SPOT","channel":"books","instId":"BTCUSDT"},"data":[{"asks":[["64940.57","0.071415"],["64960.03","0.071415"],["65073.13","0"],["65073.53","0"]],"bids":[],"ts":"1784090326605","seq":656732494433,"pseq":656732494123}],"ts":1784090326608}
{"action":"update","arg":{"instType":"SPOT","channel":"books","instId":"BTCUSDT"},"data":[{"asks":[["64828.07","2.481549"]],"bids":[["64826.29","0"],["64825.86","0.026242"]],"ts":"1784090326702","seq":656732494861,"pseq":656732494433}],"ts":1784090326706}
{"action":"update","arg":{"instType":"SPOT","channel":"books","instId":"BTCUSDT"},"data":[{"asks":[["64940.57","0"],["64964.87","0.071415"]],"bids":[],"ts":"1784090326812","seq":656732495147,"pseq":656732494861}],"ts":1784090326816}
{"action":"update","arg":{"instType":"SPOT","channel":"trade","instId":"BTCUSDT"},"data":[{"ts":"1784090326877","price":"64828.06","size":"0.000019","side":"sell","tradeId":"1461146222385152000"}],"ts":1784090326878}
{"action":"update","arg":{"instType":"SPOT","channel":"trade","instId":"BTCUSDT"},"data":[{"ts":"1784090326888","price":"64828.06","size":"0.00052","side":"sell","tradeId":"1461146222431289344"}],"ts":1784090326890}
{"action":"update","arg":{"instType":"SPOT","channel":"books","instId":"BTCUSDT"},"data":[{"asks":[["64828.07","2.487553"],["64832.89","0"],["64836.48","0.030878"],["64836.77","0.04627"],["64837.5","0"],["64841.65","0.211979"],["64841.66","0"],["64847.82","0.071415"],["64849.79","0"],["64857.54","0.071415"],["64867.25","0.071415"],["64909.77","0.023805"],["64960.03","0"],["64964.87","0"],["65073","0"]],"bids":[["64828.06","0.144641"],["64828.04","0"],["64826.09","0.004072"],["64823.58","0"],["64822.08","0.015426"],["64819.6","0.741877"],["64819.47","0"],["64818.94","0.22145"],["64818.77","0"],["64818.74","0"],["64816.79","0"],["64815.01","0"],["64813.91","0.211979"],["64810.82","0"],["64810.61","0.48328"],["64810.01","0.030878"],["64557.22","0.000266"],["64494.36","0.000265"],["64414.8","0"]],"ts":"1784090326896","seq":656732495414,"pseq":656732495147}],"ts":1784090326901}
{"action":"update","arg":{"instType":"SPOT","channel":"books","instId":"BTCUSDT"},"data":[{"asks":[["64836.48","0"],["64837.49","0.030878"]],"bids":[["64810.81","0.030878"],["64810.01","0"],["64557.22","0.000526"]],"ts":"1784090326900","seq":656732495424,"pseq":656732495414}],"ts":1784090326905}
{"action":"update","arg":{"instType":"SPOT","channel":"books","instId":"BTCUSDT"},"data":[{"asks":[["64836.76","0.030878"],["64837.49","0"],["64847.82","0"],["64857.54","0"],["64867.25","0"],["64909.77","0"],["64945.92","0.071415"],["64955.65","0.071415"],["65073","0.007112"],["65073.13","0.000011"]],"bids":[["64828.06","0.148713"],["64824.88","0"],["64819.61","0.21117"],["64819.59","0"],["64819.48","0"],["64816.12","0"],["64816.05","0.015578"],["64812.61","0"],["64808.4","0.154264"],["64797.44","0.154364"],["64796.91","0"],["64620.08","0.000266"],["64494.36","0.000531"],["64431.5","0.000265"]],"ts":"1784090326997","seq":656732495657,"pseq":656732495424}],"ts":1784090327002}
{"action":"update","arg":{"instType":"SPOT","channel":"books","instId":"BTCUSDT"},"data":[{"asks":[],"bids":[["64812.6","0.66485"]],"ts":"1784090327006","seq":656732495672,"pseq":656732495657}],"ts":1784090327008}
{"action":"update","arg":{"instType":"SPOT","channel":"books","instId":"BTCUSDT"},"data":[{"asks":[],"bids":[["64816.78","0.741877"],["64816.05","0"],["64414.8","0.00003"]],"ts":"1784090327091","seq":656732495824,"pseq":656732495672}],"ts":1784090327105}
{"action":"update","arg":{"instType":"SPOT","channel":"books","instId":"BTCUSDT"},"data":[{"asks":[],"bids":[["64816.12","0.001542"],["64414.8","0"]],"ts":"1784090327107","seq":656732495856,"pseq":656732495824}],"ts":1784090327113}
{"action":"update","arg":{"instType":"SPOT","channel":"books","instId":"BTCUSDT"},"data":[{"asks":[["64828.59","0"],["64828.6","0.046309"],["64836.76","0"],["64837.51","0.030878"]],"bids":[["64820.95","0.046309"],["64820.74","0"],["64816.12","0"],["64816.05","0.015578"],["64812.61","0.463159"],["64811.92","0"]],"ts":"1784090327200","seq":656732496125,"pseq":656732495856}],"ts":1784090327204}
{"action":"update","arg":{"instType":"SPOT","channel":"books","instId":"BTCUSDT"},"data":[{"asks":[],"bids":[["64819.62","0.26"],["64816.79","0.061705"],["64816.05","0"],["64813.64","0.077181"],["64812.95","0"],["64414.81","0"]],"ts":"1784090327283","seq":656732496847,"pseq":656732496125}],"ts":1784090327308}
{"action":"update","arg":{"instType":"SPOT","channel":"books","instId":"BTCUSDT"},"data":[{"asks":[],"bids":[["64812.61","0"],["64811.92","0.463158"]],"ts":"1784090327328","seq":656732497059,"pseq":656732496847}],"ts":1784090327330}
{"action":"update","arg":{"instType":"SPOT","channel":"trade","instId":"BTCUSDT"},"data":[{"ts":"1784090327395","price":"64828.06","size":"0.00052","side":"sell","tradeId":"1461146224557801472"}],"ts":1784090327396}
{"action":"update","arg":{"instType":"SPOT","channel":"books","instId":"BTCUSDT"},"data":[{"asks":[["64828.07","2.487552"],["64836.76","0.030878"],["64837.51","0"]],"bids":[["64828.06","0.148193"],["64826.41","0.026241"],["64825.86","0"],["64782.45","0.154363"],["64781.49","0"]],"ts":"1784090327400","seq":656732497290,"pseq":656732497059}],"ts":1784090327405}
{"action":"update","arg":{"instType":"SPOT","channel":"books","instId":"BTCUSDT"},"data":[{"asks":[["64852.33","0"],["65073.53","0.000179"]],"bids":[],"ts":"1784090327494","seq":656732498039,"pseq":656732497290}],"ts":1784090327511}
{"action":"update","arg":{"instType":"SPOT","channel":"books","instId":"BTCUSDT"},"data":[{"asks":[["64836.76","0"],["64837.51","0.030878"]],"bids":[["64812.61","0.463159"],["64811.92","0"]],"ts":"1784090327544","seq":656732498581,"pseq":656732498039}],"ts":1784090327548}
{"action":"update","arg":{"instType":"SPOT","channel":"books","instId":"BTCUSDT"},"data":[{"asks":[],"bids":[["64815.08","0.1593"],["64415","0"]],"ts":"1784090327602","seq":656732499385,"pseq":656732498581}],"ts":1784090327606}
{"action":"update","arg":{"instType":"SPOT","channel":"books","instId":"BTCUSDT"},"data":[{"asks":[["64833.8","0"],["64837.51","0"],["64837.77","0.030878"]],"bids":[["64819.64","0.294852"],["64819.63","0.309116"],["64819.62","0"],["64819.61","0"],["64818.23","0.001542"],["64818.22","0.001542"],["64816.79","0"],["64816.11","0"],["64812.6","0.450042"]],"ts":"1784090327702","seq":656732501816,"pseq":656732499385}],"ts":1784090327705}
{"action":"update","arg":{"instType":"SPOT","channel":"books","instId":"BTCUSDT"},"data":[{"asks":[],"bids":[["64818.23","0.001542"],["64816.79","0"],["64808.4","0.28539"]],"ts":"1784090327809","seq":656732503672,"pseq":656732501816}],"ts":1784090327812}
{"action":"update","arg":{"instType":"SPOT","channel":"books","instId":"BTCUSDT"},"data":[{"asks":[["64868.88","0.154361"],["65073.53","0"]],"bids":[["64819.65","0.26"],["64818.23","0.001542"],["64816.79","0"],["64415.26","0"]],"ts":"1784090327906","seq":656732505387,"pseq":656732503672}],"ts":1784090327910}
{"action":"update","arg":{"instType":"SPOT","channel":"books","instId":"BTCUSDT"},"data":[{"asks":[],"bids":[["64818.23","0.001542"],["64816.79","0"]],"ts":"1784090328017","seq":656732507410,"pseq":656732505387}],"ts":1784090328020}
{"action":"update","arg":{"instType":"SPOT","channel":"books","instId":"BTCUSDT"},"data":[{"asks":[["64847.82","0.071415"],["64857.53","0.071415"],["64867.25","0.071415"],["64909.77","0.023805"],["64945.92","0"],["64955.65","0"],["65073","0"],["65073.13","0"]],"bids":[["64818.23","0.001542"],["64816.79","0"]],"ts":"1784090328100","seq":656732508951,"pseq":656732507410}],"ts":1784090328104}
{"action":"update","arg":{"instType":"SPOT","channel":"books","instId":"BTCUSDT"},"data":[{"asks":[["64828.07","2.487552"]],"bids":[["64827.43","0.026241"],["64826.41","0"],["64818.23","0.001542"],["64816.79","0"]],"ts":"1784090328225","seq":656732511266,"pseq":656732508951}],"ts":1784090328228}
{"action":"update","arg":{"instType":"SPOT","channel":"books","instId":"BTCUSDT"},"data":[{"asks":[["64836.36","0"],["64837.7","0.07718"]],"bids":[["64818.23","0.001542"],["64816.79","0"],["64815.02","0.304235"],["64812.98","0.457154"],["64812.61","0"],["64808.4","0.154264"]],"ts":"1784090328309","seq":656732513142,"pseq":656732511266}],"ts":1784090328313}
{"action":"update","arg":{"instType":"SPOT","channel":"books","instId":"BTCUSDT"},"data":[{"asks":[["64847.82","0"],["64857.53","0"],["64867.25","0"],["64909.77","0"],["64971.32","0.071415"],["64981.05","0.071415"],["65073","0.007112"],["65073.13","0.000011"]],"bids":[["64819.63","0"],["64818.23","0.001542"],["64816.79","0"],["64415.26","0.000172"]],"ts":"1784090328405","seq":656732514912,"pseq":656732513142}],"ts":1784090328408}
{"action":"update","arg":{"instType":"SPOT","channel":"books","instId":"BTCUSDT"},"data":[{"asks":[["64828.07","2.477552"]],"bids":[["64818.23","0.001542"],["64816.79","0"],["64815.02","0.306026"],["64812.98","0.463156"],["64812.61","0"],["64808.4","0.154264"]],"ts":"1784090328516","seq":656732516508,"pseq":656732514912}],"ts":1784090328518}
{"action":"update","arg":{"instType":"SPOT","channel":"books","instId":"BTCUSDT"},"data":[{"asks":[["64862.69","0"],["65073.53","0.000179"]],"bids":[["64818.23","0.001542"],["64816.79","0"],["64804.73","0"],["64785.29","0"],["64415","0.02"],["64414.81","0.000015"]],"ts":"1784090328603","seq":656732517284,"pseq":656732516508}],"ts":1784090328606}
{"action":"update","arg":{"instType":"SPOT","channel":"books","instId":"BTCUSDT"},"data":[{"asks":[["64843.24","0"],["65074.07","0.000012"]],"bids":[["64818.23","0.001542"],["64816.79","0"]],"ts":"1784090328723","seq":656732518374,"pseq":656732517284}],"ts":1784090328726}
{"action":"update","arg":{"instType":"SPOT","channel":"books","instId":"BTCUSDT"},"data":[{"asks":[["64834.2","0"],["64837.51","0.030878"],["64837.77","0"],["64843.25","0.180076"],["64862.71","0.351512"],["64891.3","0"],["64948.4","0"],["65005.5","0"],["65062.6","0"],["65074.09","0.000401"],["65074.77","0.000062"],["65074.93","0.000016"]],"bids":[["64818.23","0.001542"],["64816.79","0"],["64805.77","0.181796"],["64786.33","0.356719"],["64415","0"],["64414.81","0"]],"ts":"1784090328806","seq":656732519563,"pseq":656732518374}],"ts":1784090328811}
{"action":"update","arg":{"instType":"SPOT","channel":"books","instId":"BTCUSDT"},"data":[{"asks":[["64828.07","2.477552"],["64847.82","0.071415"],["64857.53","0.071415"],["64867.25","0.071415"],["64909.77","0.023805"],["64971.32","0"],["64981.05","0"],["65074.77","0"],["65074.93","0"]],"bids":[["64827.45","0.026241"],["64827.43","0"],["64818.23","0.001542"],["64816.79","0"]],"ts":"1784090328903","seq":656732521243,"pseq":656732519563}],"ts":1784090328906}
{"action":"update","arg":{"instType":"SPOT","channel":"books","instId":"BTCUSDT"},"data":[{"asks":[["64979.41","0"],["65074.77","0.000062"]],"bids":[["64818.23","0.001542"],["64816.79","0"],["64799.2","0.154361"],["64797.44","0"],["64684.17","0"],["64415","0.02"]],"ts":"1784090329014","seq":656732522948,"pseq":656732521243}],"ts":1784090329018}
{"action":"update","arg":{"instType":"SPOT","channel":"books","instId":"BTCUSDT"},"data":[{"asks":[["64834.3","0.002144"],["64837.51","0"],["64837.77","0.030878"],["64891.4","0.002143"],["64948.5","0.002141"],["65005.6","0.002139"],["65062.7","0.002137"],["65073.13","0"],["65073.53","0"],["65074.07","0"],["65074.09","0"],["65074.77","0"]],"bids":[["64818.23","0.001542"],["64816.79","0"],["64811.92","0.030878"],["64810.81","0"]],"ts":"1784090329104","seq":656732524435,"pseq":656732522948}],"ts":1784090329108}
{"action":"update","arg":{"instType":"SPOT","channel":"books","instId":"BTCUSDT"},"data":[{"asks":[["64828.6","0"],["64829.93","0.046308"],["64847.82","0"],["64857.53","0"],["64867.25","0"],["64909.77","0"],["64916.58","0.000667"],["64950.3","0.071415"],["64960.03","0.071415"],["64969.46","1.22524"],["65073.13","0.000011"]],"bids":[["64822.46","0.046308"],["64820.95","0"],["64818.23","0.001542"],["64816.79","0"],["64811.92","0"],["64810.81","0.030878"],["64737.77","0"],["64728.88","0.000667"],["64678.5","1.222403"],["64415","0"]],"ts":"1784090329222","seq":656732526258,"pseq":656732524435}],"ts":1784090329225}
{"action":"update","arg":{"instType":"SPOT","channel":"books","instId":"BTCUSDT"},"data":[{"asks":[],"bids":[["64818.23","0.001542"],["64816.79","0"],["64814.78","0.07718"],["64813.64","0"]],"ts":"1784090329305","seq":656732527582,"pseq":656732526258}],"ts":1784090329310}
{"action":"update","arg":{"instType":"SPOT","channel":"books","instId":"BTCUSDT"},"data":[{"asks":[],"bids":[["64823","0"],["64818.23","0.001542"],["64816.79","0"],["64795.1","0"],["64767.2","0"],["64739.3","0"],["64711.4","0"],["64415","0.02"],["64414.81","0.000015"],["64414.8","0.00003"],["64414.63","0.000779"],["64414.41","0.000326"]],"ts":"1784090329402","seq":656732529462,"pseq":656732527582}],"ts":1784090329406}
{"action":"update","arg":{"instType":"SPOT","channel":"books","instId":"BTCUSDT"},"data":[{"asks":[["64853.11","0.154361"],["65073.13","0"]],"bids":[["64818.23","0.001542"],["64816.79","0"],["64783.87","0.154361"],["64782.45","0"]],"ts":"1784090329513","seq":656732531245,"pseq":656732529462}],"ts":1784090329516}
{"action":"update","arg":{"instType":"SPOT","channel":"books","instId":"BTCUSDT"},"data":[{"asks":[],"bids":[["64818.23","0"],["64816.79","0"],["64414.32","0.000039"]],"ts":"1784090329606","seq":656732532756,"pseq":656732531245}],"ts":1784090329608}
{"action":"update","arg":{"instType":"SPOT","channel":"books","instId":"BTCUSDT"},"data":[{"asks":[["64828.07","2.477552"],["64836.76","0.030878"],["64837.77","0"]],"bids":[["64827.45","0"],["64827.04","0.026241"],["64823.1","0.002145"],["64816.79","0.061705"],["64815.02","0.16648"],["64812.98","0"],["64812.6","0.581168"],["64811.92","0.463158"],["64795.2","0.002146"],["64767.3","0.002147"],["64739.4","0.002148"],["64711.5","0.002148"],["64415","0"],["64414.81","0"],["64414.8","0"],["64414.63","0"],["64414.41","0"],["64414.32","0"]],"ts":"1784090329720","seq":656732534220,"pseq":656732532756}],"ts":1784090329724}
{"action":"update","arg":{"instType":"SPOT","channel":"books","instId":"BTCUSDT"},"data":[{"asks":[["64844.22","0"],["64854.92","0"],["65073.13","0.000011"],["65073.53","0.000179"]],"bids":[["64821.53","0"],["64805.33","0"],["64415","0.02"],["64414.81","0.000015"]],"ts":"1784090329832","seq":656732535754,"pseq":656732534220}],"ts":1784090329836}
{"action":"update","arg":{"instType":"SPOT","channel":"books","instId":"BTCUSDT"},"data":[{"asks":[["64839.9","0.001542"],["64849.63","0.001542"],["64867.99","0.154362"],["64868.88","0"],["65073.13","0"],["65073.53","0"]],"bids":[["64810.73","0.001542"],["64797.77","0.001543"],["64415","0"],["64414.81","0"]],"ts":"1784090329900","seq":656732536222,"pseq":656732535754}],"ts":1784090329904}
{"action":"update","arg":{"instType":"SPOT","channel":"books","instId":"BTCUSDT"},"data":[{"asks":[["64833.96","0.015668"],["64893.01","0.016201"],["64901.85","0"],["65073","0"]],"bids":[],"ts":"1784090330011","seq":656732536419,"pseq":656732536222}],"ts":1784090330014}
{"action":"update","arg":{"instType":"SPOT","channel":"books","instId":"BTCUSDT"},"data":[{"asks":[["64837.09","0.077181"],["64837.7","0"]],"bids":[],"ts":"1784090330274","seq":656732537220,"pseq":656732536419}],"ts":1784090330276}
{"action":"update","arg":{"instType":"SPOT","channel":"books","instId":"BTCUSDT"},"data":[{"asks":[["64835.92","0.46316"],["64836.16","0"]],"bids":[],"ts":"1784090330321","seq":656732537321,"pseq":656732537220}],"ts":1784090330325}
{"action":"update","arg":{"instType":"SPOT","channel":"books","instId":"BTCUSDT"},"data":[{"asks":[["64828.07","2.477552"],["64940.57","0.071415"],["65072.99","0"]],"bids":[["64827.05","0.026241"],["64827.04","0"]],"ts":"1784090330412","seq":656732537984,"pseq":656732537321}],"ts":1784090330416}
{"action":"update","arg":{"instType":"SPOT","channel":"books","instId":"BTCUSDT"},"data":[{"asks":[["64828.07","2.471424"]],"bids":[],"ts":"1784090330636","seq":656732538591,"pseq":656732537984}],"ts":1784090330640}
{"action":"update","arg":{"instType":"SPOT","channel":"books","instId":"BTCUSDT"},"data":[{"asks":[["64828.07","1.718268"],["64829.92","0"],["64829.98","0.741877"],["64829.99","0.414585"],["64830","0.329415"],["64835.92","0"],["64836.48","0.463147"],["64836.76","0"],["64837.08","0"],["64837.77","0.030877"],["64838.42","0"],["64839.63","0.163007"],["65072.85","0"]],"bids":[["64828.06","0.280533"],["64827.06","0"],["64825.32","0.001101"],["64821.8","0.310622"],["64821.79","0.741877"],["64819.66","0.309116"],["64819.65","0"],["64819.64","0"],["64819.28","0"],["64818.95","0"],["64816.79","0"],["64813.92","0"],["64812.98","0.463147"],["64812.6","0.001542"],["64811.93","0"],["64811.92","0"],["64810.81","0.030877"],["64415.26","0"]],"ts":"1784090330702","seq":656732538876,"pseq":656732538591}],"ts":1784090330704}
{"action":"update","arg":{"instType":"SPOT","channel":"books","instId":"BTCUSDT"},"data":[{"asks":[["64828.07","1.746975"]],"bids":[["64825.32","0"],["64821.81","0.26"],["64821.8","0.495459"],["64819.27","0.001542"],["64818.95","0.061705"],["64815.02","0.306023"],["64812.6","0.241018"],["64811.94","0"],["64810.82","0.030877"],["64810.81","0"],["64415.38","0"]],"ts":"1784090330800","seq":656732539525,"pseq":656732538876}],"ts":1784090330804}
{"action":"update","arg":{"instType":"SPOT","channel":"books","instId":"BTCUSDT"},"data":[{"asks":[["64828.07","2.488255"],["64835.92","0.463152"],["64836.48","0"],["64837.77","0"],["64838.42","0.030877"],["65022.8","0"],["65072.85","0.000048"]],"bids":[["64828.06","0.148193"],["64818.95","0"],["64818.23","0.001542"],["64811.92","0.030877"],["64810.82","0"]],"ts":"1784090330911","seq":656732540797,"pseq":656732539525}],"ts":1784090330914}
{"action":"update","arg":{"instType":"SPOT","channel":"books","instId":"BTCUSDT"},"data":[{"asks":[["64837.77","0.030877"],["64838.42","0"],["64847.82","0.071415"],["64857.53","0.071415"],["64867.25","0.071415"],["64909.77","0.023805"],["64940.57","0"],["64950.3","0"],["64960.03","0"],["65022.8","0.000492"],["65072.77","0"],["65072.85","0"]],"bids":[["64818.23","0.001542"],["64816.79","0"],["64800.43","0.154359"],["64799.2","0"]],"ts":"1784090331008","seq":656732541819,"pseq":656732540797}],"ts":1784090331010}
{"action":"update","arg":{"instType":"SPOT","channel":"books","instId":"BTCUSDT"},"data":[{"asks":[["64829.93","0"],["64830.68","0.046307"]],"bids":[["64823.42","0.014463"],["64823.41","0.046307"],["64822.46","0"],["64818.23","0.001542"],["64816.79","0"],["64415.73","0"]],"ts":"1784090331105","seq":656732542897,"pseq":656732541819}],"ts":1784090331108}
{"action":"update","arg":{"instType":"SPOT","channel":"books","instId":"BTCUSDT"},"data":[{"asks":[["64828.07","2.488255"],["64837.08","0.030877"],["64837.77","0"]],"bids":[["64827.98","0.026241"],["64827.05","0"],["64821.8","0.310622"],["64821.79","0"],["64818.23","0"],["64816.79","0.061707"],["64815.02","0.16648"],["64812.98","0"],["64812.61","0.463153"],["64812.6","0.142815"],["64811.92","0"],["64810.81","0.030877"],["64415.73","0.000035"]],"ts":"1784090331216","seq":656732544561,"pseq":656732542897}],"ts":1784090331218}
{"action":"update","arg":{"instType":"SPOT","channel":"books","instId":"BTCUSDT"},"data":[{"asks":[],"bids":[["64779.8","0"],["64415.38","0.000029"]],"ts":"1784090331387","seq":656732546112,"pseq":656732544561}],"ts":1784090331390}
{"action":"update","arg":{"instType":"SPOT","channel":"books","instId":"BTCUSDT"},"data":[{"asks":[],"bids":[["64812.6","0.550935"],["64792.71","0.026644"],["64415.38","0"]],"ts":"1784090331423","seq":656732546205,"pseq":656732546112}],"ts":1784090331426}
{"action":"update","arg":{"instType":"SPOT","channel":"books","instId":"BTCUSDT"},"data":[{"asks":[["64828.07","2.487717"],["64853.11","0"],["64853.19","0.15436"]],"bids":[["64814.78","0"],["64784.76","0.15436"],["64783.87","0"],["64415.38","0.000029"]],"ts":"1784090331506","seq":656732546725,"pseq":656732546205}],"ts":1784090331510}
{"action":"update","arg":{"instType":"SPOT","channel":"books","instId":"BTCUSDT"},"data":[{"asks":[["64828.07","2.493659"]],"bids":[],"ts":"1784090331847","seq":656732547530,"pseq":656732546725}],"ts":1784090331850}
{"action":"update","arg":{"instType":"SPOT","channel":"books","instId":"BTCUSDT"},"data":[{"asks":[["64828.07","2.493659"],["64867.99","0"],["64868.45","0.15436"]],"bids":[["64828","0.026241"],["64827.98","0"]],"ts":"1784090331922","seq":656732547782,"pseq":656732547530}],"ts":1784090331926}
{"action":"update","arg":{"instType":"SPOT","channel":"books","instId":"BTCUSDT"},"data":[{"asks":[],"bids":[["64813.6","0"],["64415.26","0.000172"]],"ts":"1784090332005","seq":656732547908,"pseq":656732547782}],"ts":1784090332008}
{"action":"update","arg":{"instType":"SPOT","channel":"books","instId":"BTCUSDT"},"data":[{"asks":[["64834.3","0"],["64891.4","0"],["64948.5","0"],["65005.6","0"],["65062.7","0"],["65072.77","0.000143"],["65072.85","0.000048"],["65072.99","0.000027"],["65073","0.007112"],["65073.13","0.000011"]],"bids":[],"ts":"1784090332137","seq":656732548115,"pseq":656732547908}],"ts":1784090332140}
{"action":"update","arg":{"instType":"SPOT","channel":"books","instId":"BTCUSDT"},"data":[{"asks":[],"bids":[["64819.66","0"],["64415","0.02"]],"ts":"1784090332264","seq":656732548433,"pseq":656732548115}],"ts":1784090332266}
{"action":"update","arg":{"instType":"SPOT","channel":"books","instId":"BTCUSDT"},"data":[{"asks":[["64828.07","2.493172"],["64837.09","0"],["64837.8","0.07718"],["64847.82","0"],["64857.53","0"],["64867.25","0"],["64909.77","0"],["64963","0.071415"],["65073.53","0.000179"],["65074.07","0.000012"],["65074.09","0.000401"]],"bids":[["64821.82","0.29906"],["64821.81","0"],["64821.8","0"],["64414.81","0.000015"]],"ts":"1784090332295","seq":656732548903,"pseq":656732548433}],"ts":1784090332300}
{"action":"update","arg":{"instType":"SPOT","channel":"books","instId":"BTCUSDT"},"data":[{"asks":[],"bids":[["64821.82","0.214324"]],"ts":"1784090332309","seq":656732548930,"pseq":656732548903}],"ts":1784090332312}
{"action":"update","arg":{"instType":"SPOT","channel":"books","instId":"BTCUSDT"},"data":[{"asks":[["64834.2","0.002144"],["64837.06","0.030877"],["64837.07","0"],["64837.08","0"],["64837.51","0"],["64891.3","0.002143"],["64948.4","0.002141"],["65005.5","0.002139"],["65062.6","0.002137"],["65073","0"],["65073.13","0"],["65073.53","0"],["65074.07","0"],["65074.09","0"]],"bids":[],"ts":"1784090332394","seq":656732549491,"pseq":656732548930}],"ts":1784090332402}
{"action":"update","arg":{"instType":"SPOT","channel":"books","instId":"BTCUSDT"},"data":[{"asks":[],"bids":[["64808.4","0.250562"]],"ts":"1784090332420","seq":656732549752,"pseq":656732549491}],"ts":1784090332422}
{"action":"update","arg":{"instType":"SPOT","channel":"books","instId":"BTCUSDT"},"data":[{"asks":[["64837.06","0"],["64837.51","0.030877"]],"bids":[],"ts":"1784090332475","seq":656732550397,"pseq":656732549752}],"ts":1784090332504}
{"action":"update","arg":{"instType":"SPOT","channel":"books","instId":"BTCUSDT"},"data":[{"asks":[["64972.73","0.071415"],["65072.99","0"]],"bids":[],"ts":"1784090332607","seq":656732551266,"pseq":656732550397}],"ts":1784090332610}
{"action":"update","arg":{"instType":"SPOT","channel":"books","instId":"BTCUSDT"},"data":[{"asks":[["64828.07","2.493172"]],"bids":[["64828","0"],["64827.98","0.026241"],["64823.1","0"],["64795.2","0"],["64767.3","0"],["64739.4","0"],["64711.5","0"],["64414.8","0.00003"],["64414.63","0.000779"],["64414.41","0.000326"],["64414.32","0.000039"],["64413.31","0.000034"]],"ts":"1784090332683","seq":656732551611,"pseq":656732551266}],"ts":1784090332707}
{"action":"update","arg":{"instType":"SPOT","channel":"books","instId":"BTCUSDT"},"data":[{"asks":[["64847.82","0.071415"],["64857.53","0.071415"],["64867.25","0.071415"],["64909.77","0.023805"],["64963","0"],["64972.73","0"],["65072.77","0"],["65072.85","0"]],"bids":[],"ts":"1784090332724","seq":656732551726,"pseq":656732551611}],"ts":1784090332726}
{"action":"update","arg":{"instType":"SPOT","channel":"books","instId":"BTCUSDT"},"data":[{"asks":[["64847.82","0"],["64857.53","0"],["64867.25","0"],["64909.77","0"],["65072.77","0.000143"],["65072.85","0.000048"],["65072.99","0.000027"],["65073","0.007112"]],"bids":[],"ts":"1784090332897","seq":656732552353,"pseq":656732551726}],"ts":1784090332900}
{"action":"update","arg":{"instType":"SPOT","channel":"books","instId":"BTCUSDT"},"data":[{"asks":[["64962.98","0.071415"],["64972.71","0.071415"],["65072.99","0"],["65073","0"]],"bids":[],"ts":"1784090332899","seq":656732552365,"pseq":656732552353}],"ts":1784090332911}
{"action":"update","arg":{"instType":"SPOT","channel":"books","instId":"BTCUSDT"},"data":[{"asks":[],"bids":[["64800.43","0"],["64799.94","0.154361"]],"ts":"1784090332924","seq":656732552523,"pseq":656732552365}],"ts":1784090332926}
{"action":"update","arg":{"instType":"SPOT","channel":"books","instId":"BTCUSDT"},"data":[{"asks":[],"bids":[["64823.1","0.002145"],["64795.2","0.002146"],["64767.3","0.002147"],["64739.4","0.002148"],["64711.5","0.002148"],["64414.8","0"],["64414.63","0"],["64414.41","0"],["64414.32","0"],["64413.31","0"]],"ts":"1784090333002","seq":656732552741,"pseq":656732552523}],"ts":1784090333004}
{"action":"update","arg":{"instType":"SPOT","channel":"books","instId":"BTCUSDT"},"data":[{"asks":[["64829.73","0.046308"],["64830.68","0"]],"bids":[["64823.42","0"],["64823.41","0"],["64822.65","0.046308"],["64819.61","0.26"],["64808.4","0.265025"]],"ts":"1784090333103","seq":656732552874,"pseq":656732552741}],"ts":1784090333106}
{"action":"update","arg":{"instType":"SPOT","channel":"books","instId":"BTCUSDT"},"data":[{"asks":[["64847.82","0"],["64857.53","0"],["64867.25","0"],["64909.77","0"],["64937.56","0.071415"],["64947.29","0.071415"],["64962.98","0"],["64972.71","0"]],"bids":[],"ts":"1784090333210","seq":656732553029,"pseq":656732552874}],"ts":1784090333212}
{"action":"update","arg":{"instType":"SPOT","channel":"books","instId":"BTCUSDT"},"data":[{"asks":[],"bids":[["64819.6","0"],["64816.78","0"],["64414.8","0.00003"],["64414.63","0.000779"]],"ts":"1784090333346","seq":656732553257,"pseq":656732553029}],"ts":1784090333348}
{"action":"update","arg":{"instType":"SPOT","channel":"books","instId":"BTCUSDT"},"data":[{"asks":[["64828.07","2.493172"],["64847.81","0.071415"],["64857.53","0.071415"],["64867.25","0.071415"],["64909.77","0.023805"],["64937.56","0"],["64947.29","0"],["65072.77","0"],["65072.85","0"]],"bids":[["64827.98","0"],["64827.58","0.026241"],["64821.82","0"],["64819.64","0.07761"],["64819.63","0.26"],["64819.62","0"],["64819.61","0"],["64818.94","0"],["64818.23","0"],["64817.58","0.22145"],["64817.57","0.741877"],["64816.79","0"],["64816.05","0"],["64815.1","0"],["64815.09","0.741877"],["64815.02","0"]],"ts":"1784090333403","seq":656732553422,"pseq":656732553257}],"ts":1784090333406}
{"action":"update","arg":{"instType":"SPOT","channel":"books","instId":"BTCUSDT"},"data":[{"asks":[["64847.81","0"],["64852.36","0.154361"],["64853.19","0"],["64857.53","0"],["64867.25","0"],["64909.77","0"],["64954.66","0.071415"],["64964.39","0.071415"],["65072.77","0.000143"],["65072.85","0.000048"]],"bids":[["64816.05","0"],["64815.1","0.061707"],["64815.07","0.07718"],["64808.4","0.154264"],["64784.76","0"],["64784.71","0.154361"],["64414.8","0"],["64414.63","0"]],"ts":"1784090333500","seq":656732553643,"pseq":656732553422}],"ts":1784090333504}
{"action":"update","arg":{"instType":"SPOT","channel":"books","instId":"BTCUSDT"},"data":[{"asks":[],"bids":[["64819.65","0"],["64819.64","0"],["64819.63","0"],["64817.59","0.309116"],["64816.05","0"],["64815.1","0.061707"],["64808.39","0.689886"],["64414.8","0.00003"]],"ts":"1784090333597","seq":656732554315,"pseq":656732553643}],"ts":1784090333621}
{"action":"update","arg":{"instType":"SPOT","channel":"books","instId":"BTCUSDT"},"data":[{"asks":[],"bids":[["64816.05","0.015578"],["64815.1","0"]],"ts":"1784090333629","seq":656732554366,"pseq":656732554315}],"ts":1784090333633}
{"action":"update","arg":{"instType":"SPOT","channel":"books","instId":"BTCUSDT"},"data":[{"asks":[["64836.76","0.030878"],["64837.51","0"],["64847.81","0.071415"],["64857.53","0.071415"],["64867.25","0.071415"],["64909.77","0.023805"],["64954.66","0"],["64964.39","0"],["65072.77","0"],["65072.85","0"]],"bids":[["64816.05","0"],["64815.1","0.061707"]],"ts":"1784090333708","seq":656732554674,"pseq":656732554366}],"ts":1784090333710}
{"action":"update","arg":{"instType":"SPOT","channel":"books","instId":"BTCUSDT"},"data":[{"asks":[],"bids":[["64828.06","0.144121"],["64827.78","0"],["64827.12","0"],["64824.11","0.01191"],["64816.05","0"],["64815.1","0.061707"],["64813.59","0.015098"],["64812.61","0"],["64811.92","0.463159"],["64810.81","0"],["64810.62","0.030878"],["64414.81","0"],["64414.8","0"]],"ts":"1784090333805","seq":656732558497,"pseq":656732554674}],"ts":1784090333808}
{"action":"update","arg":{"instType":"SPOT","channel":"books","instId":"BTCUSDT"},"data":[{"asks":[["64833.92","0.371681"],["64833.93","0.463161"],["64833.94","0"],["64835.91","0.030878"],["64835.92","0"],["64836.76","0"],["64839.63","0.044081"],["64847.81","0"],["64852.73","0.462586"],["64857.53","0"],["64864.75","0"],["64866.65","0.154363"],["64867.25","0"],["64868.45","0"],["64909.77","0"],["64933.41","0.071415"],["64952.87","0.071415"],["65072.77","0.000143"],["65072.85","0.000048"]],"bids":[["64828.06","0.143852"],["64826.09","0"],["64825.21","0.004643"],["64824.11","0"],["64822.45","0.011911"],["64817.59","0"],["64817.57","0"],["64816.05","0"],["64815.1","0.061707"],["64815.08","0"],["64811.92","0"],["64810.62","0.463161"],["64810.01","0.030878"],["64805.01","0.110795"],["64763.26","0"],["64748.32","1.877789"],["64719.2","0"],["64704.27","7.687688"],["64414.81","0.000015"],["64414.8","0.00003"],["64414.63","0.000779"]],"ts":"1784090333904","seq":656732562798,"pseq":656732558497}],"ts":1784090333908}
{"action":"update","arg":{"instType":"SPOT","channel":"trade","instId":"BTCUSDT"},"data":[{"ts":"1784090333918","price":"64828.06","size":"0.14385","side":"sell","tradeId":"1461146251917246464"}],"ts":1784090333919}
{"action":"update","arg":{"instType":"SPOT","channel":"trade","instId":"BTCUSDT"},"data":[{"ts":"1784090333921","price":"64828.06","size":"0.000002","side":"sell","tradeId":"1461146251929829376"}],"ts":1784090333922}
{"action":"update","arg":{"instType":"SPOT","channel":"books","instId":"BTCUSDT"},"data":[{"asks":[["64827.59","2.689176"],["64828.06","0"],["64828.07","1.518661"],["64828.34","0"],["64829.24","0"],["64829.99","0"],["64830","0.020299"],["64833.92","0"],["64834.99","0"],["64835.9","0.030878"],["64835.91","0"],["64835.93","0"],["64839.63","0"],["64849.98","0"],["64849.99","0"],["64853.35","0"],["64933.41","0"],["64944.8","0.071415"],["64952.87","0"],["64954.53","0.071415"],["64964.34","0.071415"],["64973.97","0"],["64983.7","0"],["65072.99","0.000027"],["65073","0.007112"],["65073.13","0.000011"],["65073.53","0.000179"],["65074.07","0.000012"],["65074.09","0.000401"],["65074.77","0.000062"]],"bids":[["64828.06","0"],["64827.58","0.071926"],["64825.6","0.026241"],["64825.31","0"],["64823.22","0.001542"],["64823.1","0"],["64817.58","0"],["64810.73","0"],["64810.01","0"],["64809.78","0"],["64808.41","0.030878"],["64807.01","0.001543"],["64805.01","0.213716"],["64795.2","0"],["64787.83","0.01"],["64784.64","0.04"],["64777.12","0.069246"],["64767.3","0"],["64755.01","0.00597"],["64739.4","0"],["64711.5","0"],["64414.41","0.000326"],["64414.32","0.000039"],["64413.31","0.000034"]],"ts":"1784090334005","seq":656732567790,"pseq":656732562798}],"ts":1784090334008}
{"action":"update","arg":{"instType":"SPOT","channel":"trade","instId":"BTCUSDT"},"data":[{"ts":"1784090334015","price":"64827.58","size":"0.071926","side":"sell","tradeId":"1461146252324093952"}],"ts":1784090334016}
{"action":"update","arg":{"instType":"SPOT","channel":"trade","instId":"BTCUSDT"},"data":[{"ts":"1784090334015","price":"64825.6","size":"0.000793","side":"sell","tradeId":"1461146252324093954"}],"ts":1784090334016}
{"action":"update","arg":{"instType":"SPOT","channel":"trade","instId":"BTCUSDT"},"data":[{"ts":"1784090334016","price":"64825.6","size":"0.025448","side":"sell","tradeId":"1461146252328288256"}],"ts":1784090334017}
{"action":"update","arg":{"instType":"SPOT","channel":"trade","instId":"BTCUSDT"},"data":[{"ts":"1784090334018","price":"64819.13","size":"0.003358","side":"sell","tradeId":"1461146252336676866"},{"ts":"1784090334018","price":"64819.27","size":"0.001542","side":"sell","tradeId":"1461146252336676864"}],"ts":1784090334021}
{"action":"update","arg":{"instType":"SPOT","channel":"trade","instId":"BTCUSDT"},"data":[{"ts":"1784090334022","price":"64819.13","size":"0.000772","side":"sell","tradeId":"1461146252353454080"}],"ts":1784090334023}
{"action":"update","arg":{"instType":"SPOT","channel":"books","instId":"BTCUSDT"},"data":[{"asks":[["64819.14","1.819639"],["64819.28","0"],["64819.34","0.22145"],["64819.35","0.741877"],["64819.98","0"],["64820.15","0.000772"],["64821.27","0.011177"],["64822.04","0"],["64822.08","0"],["64822.09","0"],["64822.46","0"],["64822.66","0"],["64823.22","0.454749"],["64823.23","1.050993"],["64824.07","0.001542"],["64825.07","0"],["64825.21","0"],["64825.22","0"],["64825.6","0.046311"],["64825.61","0.2653"],["64825.77","0.1593"],["64825.95","0"],["64826.45","0"],["64826.52","0"],["64826.86","0"],["64826.94","0"],["64826.95","0"],["64827.05","0"],["64827.06","0"],["64827.18","0"],["64827.19","0"],["64827.22","0.07956"],["64827.25","0"],["64827.4","0"],["64827.45","0"],["64827.47","0"],["64827.51","0"],["64827.56","0.210619"],["64827.57","0.494089"],["64827.58","0.27192"],["64827.59","1.112813"],["64828.06","0"],["64828.07","0.160347"],["64828.6","0.001542"],["64829.72","0"],["64829.73","0"],["64829.97","0"],["64830","0.014309"],["64830.96","0.001542"],["64831.07","0.046274"],["64831.23","0.077186"],["64831.99","0.309116"],["64833.92","0"],["64833.93","0"],["64833.96","0"],["64834.5","0"],["64834.82","0"],["64835.63","0.035"],["64835.9","0"],["64836.17","0"],["64836.74","0"],["64837.8","0"],["64838.23","0"],["64838.39","0"],["64838.58","0"],["64839.9","0"],["64841.1","0"],["64841.17","1.875101"],["64842.87","0"],["64843.31","0"],["64843.93","0"],["64844.78","0"],["64844.87","0.001542"],["64845.57","0"],["64846.26","0"],["64847.01","0"],["64849.63","0"],["64851.7","0"],["64853.23","0"],["64853.65","0"],["64856.83","0"],["64857.19","0"],["64859.36","0"],["64863.2","1.390441"],["64875.27","0"],["64879.42","0"],["64934.1","0.071415"],["64964.34","0"]],"bids":[["64827.58","0"],["64825.6","0"],["64825.21","0"],["64823.22","0"],["64822.65","0"],["64822.45","0"],["64822.08","0"],["64819.27","0"],["64819.13","0.026243"],["64819.09","0"],["64818.88","0"],["64818.22","0"],["64816.38","0.015428"],["64816.04","0"],["64815.1","0"],["64815.09","0"],["64815.08","0"],["64815.07","0"],["64814.35","0.047855"],["64813.91","0"],["64813.59","0"],["64812.97","0"],["64812.78","0.000771"],["64812.6","0.008379"],["64812.59","0"],["64812.41","0"],["64811.91","0"],["64810.98","0"],["64810.96","0"],["64810.8","0"],["64810.74","0"],["64810.72","0.001542"],["64810.62","0"],["64810.61","0"],["64810.01","0"],["64809.97","0"],["64809.77","0"],["64809.41","0.309116"],["64809.4","0.211979"],["64809.36","0"],["64809.22","0"],["64808.86","0"],["64808.7","0.492515"],["64808.69","0.741877"],["64808.41","0"],["64808.4","0"],["64808.39","0"],["64808.19","0.077187"],["64807.7","0"],["64807.42","0"],["64807.41","0"],["64807.26","0"],["64807.1","0"],["64805.89","0.011557"],["64805.78","0"],["64805.77","0"],["64805.45","0.358855"],["64805.44","0.741877"],["64805.02","0"],["64805.01","0"],["64804.86","0.309116"],["64804.7","0.046292"],["64804.5","0.035"],["64804.46","0"],["64804.45","0"],["64803.58","0"],["64803.51","0.46321"],["64803.5","0.483269"],["64802.92","0"],["64802.9","0"],["64802.38","0"],["64801.79","0.001543"],["64801.21","0.741877"],["64801.2","0"],["64800.83","0.030881"],["64799.94","0"],["64799.82","0"],["64799.75","0"],["64799.5","0.001543"],["64799.43","0.071415"],["64799.27","0"],["64798.52","0"],["64797.95","0.741877"],["64797.77","0"],["64796.72","0"],["64794.73","0.741877"],["64794.38","0.0463"],["64792.9","0.154373"],["64791.99","0.003086"],["64791.48","0.741877"],["64788.23","0.741877"],["64787.83","0"],["64785.26","0.309116"],["64784.81","0.071415"],["64784.71","0"],["64784.64","0"],["64778.16","0.154373"],["64740.01","0"],["64732.5","0.001543"],["64620.08","0"],["64557.22","0"],["64494.36","0"],["64431.5","0"],["64412.83","0.000791"],["64412.55","0.00001"],["64412.5","0.000981"],["64412","0.000036"],["64411.76","0.000011"],["64411.6","0.000051"],["64411.33","0.002071"],["64411.09","0.000706"],["64410.89","0.00002"],["64410.75","0.000941"],["64410.6","0.000048"],["64410.53","0.000014"],["64410","0.020049"],["64409.45","0.000013"],["64409.43","0.000333"],["64409.25","0.000439"],["64408.39","0.00021"],["64407.89","0.00001"]],"ts":"1784090334100","seq":656732577869,"pseq":656732567790}],"ts":1784090334102}
{"action":"update","arg":{"instType":"SPOT","channel":"books","instId":"BTCUSDT"},"data":[{"asks":[["64817.58","1.946861"],["64817.77","0"],["64818.14","0"],["64819.13","0.328531"],["64819.14","1.056294"],["64819.34","0"],["64819.35","0"],["64819.89","0"],["64820.15","0"],["64821.26","0.003336"],["64822.12","0"],["64823.22","0.487856"],["64825.6","0"],["64825.76","0.463215"],["64826.42","0.000771"],["64827.56","0"],["64827.57","0.33078"],["64827.89","0.015512"],["64828.07","0.154254"],["64828.6","0.001542"],["64829.97","0.216946"],["64830.9","0.05"],["64830.96","0"],["64831.31","0.483269"],["64833.94","0.211979"],["64834.2","0"],["64835.63","0"],["64837.35","0.001041"],["64837.78","0"],["64838.43","0"],["64838.59","0.015079"],["64838.88","0.003084"],["64841.67","0"],["64841.87","0"],["64845.68","0"],["64846.11","0.001581"],["64852.36","0"],["64854.63","0"],["64862.71","0"],["64890.33","0"],["64891.3","0"],["64934.1","0"],["64948.4","0"],["64959.71","0.071415"],["65005.5","0"],["65062.6","0"],["65074.93","0.000016"],["65075","0.02"],["65075.19","0.001206"],["65075.71","0.001639"],["65075.85","0.000015"],["65076.4","0.000057"],["65076.92","0.00004"]],"bids":[["64819.13","0"],["64818.08","0"],["64817.57","0.001628"],["64816.38","0"],["64816.16","0.02534"],["64815.08","0"],["64815.01","0"],["64815","0.368888"],["64814.68","0.015428"],["64814.35","0"],["64812.78","0"],["64812.77","0.001542"],["64812.6","0"],["64810.93","0.019414"],["64810.92","0.044717"],["64810.72","0"],["64810.01","0"],["64809.43","0.445969"],["64809.42","0.309116"],["64809.41","0"],["64808.71","0.741877"],["64808.7","0"],["64808.69","0"],["64808.06","0"],["64807.8","0"],["64805.9","0"],["64805.46","1.050993"],["64805.45","0"],["64805.44","0"],["64805.26","0"],["64805.01","0.02"],["64804.86","0"],["64804.5","0"],["64803.89","0.001041"],["64803.51","0"],["64803.5","0"],["64802.92","0"],["64802.21","0.741877"],["64801.22","0.463215"],["64801.21","0"],["64800.83","0"],["64800.71","0"],["64799.5","0"],["64799.44","0.030881"],["64798.29","0.154268"],["64796.29","0.483269"],["64796.27","0.178686"],["64794.53","0.015342"],["64792.9","0"],["64792.87","0.001581"],["64792.71","0"],["64792.54","0.626458"],["64785.27","0.741877"],["64785.25","0.149059"],["64778.16","0"],["64777.48","0.309116"],["64777.12","0"],["64755.01","0"],["64407.26","0.00058"]],"ts":"1784090334201","seq":656732583670,"pseq":656732577869}],"ts":1784090334204}
{"action":"update","arg":{"instType":"SPOT","channel":"trade","instId":"BTCUSDT"},"data":[{"ts":"1784090334265","price":"64817.57","size":"0.000019","side":"sell","tradeId":"1461146253372669952"}],"ts":1784090334266}
{"action":"update","arg":{"instType":"SPOT","channel":"books","instId":"BTCUSDT"},"data":[{"asks":[["64815.01","1.722875"],["64815.17","0"],["64816.16","0.025426"],["64816.17","0"],["64817.57","0"],["64817.58","1.21188"],["64818.82","0.000772"],["64819.13","0"],["64819.14","0"],["64819.78","0"],["64820.55","0"],["64820.83","0.741877"],["64821.26","0"],["64821.27","0"],["64823.21","0"],["64824.6","0.07956"],["64825.6","1.205114"],["64825.76","0"],["64827.22","0"],["64828.3","0.002145"],["64829.97","0"],["64837.52","0"],["64839.64","0"],["64841.16","1.875101"],["64841.17","0"],["64842.01","0"],["64851.11","0.034054"],["64859.85","0.149526"],["64863.2","1.390368"],["64864.41","0"],["64866.65","0"],["64885.3","0.002143"],["64920.52","0.071415"],["64930.25","0.071415"],["64942.3","0.002141"],["64954.53","0"],["64959.71","0"],["64999.3","0.002139"],["65056.3","0.002137"],["65076.92","0"]],"bids":[["64817.57","0"],["64816.16","0"],["64815","0.021628"],["64814.68","0"],["64814.49","0.025419"],["64812.77","0"],["64811.68","0.015429"],["64810.93","0"],["64809.44","0.211979"],["64809.43","0"],["64809.42","0"],["64809.4","0"],["64808.71","0"],["64808.38","0"],["64808.19","0"],["64805.48","1.050993"],["64805.47","0"],["64805.46","0"],["64805.01","0"],["64804.71","0"],["64804.7","0"],["64803.49","0.01541"],["64802.91","0.953856"],["64802.22","0.457235"],["64802.21","0"],["64801.6","0.074639"],["64801.22","0"],["64800.95","0.741877"],["64799.44","0.463234"],["64798.3","0.030883"],["64797.64","0"],["64796.27","0"],["64794.53","0"],["64788.08","0.046304"],["64407.14","0.000011"],["64406.29","0.000032"],["64406.09","0.000016"],["64405.63","0.00005"],["64405.25","0.000082"],["64405.06","0.000249"],["64405","0.02"],["64404.17","0.00001"]],"ts":"1784090334300","seq":656732585453,"pseq":656732583670}],"ts":1784090334304}
{"action":"update","arg":{"instType":"SPOT","channel":"books","instId":"BTCUSDT"},"data":[{"asks":[["64815.01","1.781113"],["64817.57","0.349198"],["64817.58","1.16907"],["64820.53","0.001691"],["64820.82","0.22145"],["64821.21","0"],["64823.21","0.463257"],["64823.22","0.684068"],["64823.89","0.074899"],["64824.18","0.05"],["64824.59","0.030884"],["64825.37","0.046278"],["64825.6","0.741877"],["64827.57","0.299899"],["64831.23","0"],["64832.75","0.035"],["64833.64","0.015258"],["64836.77","0"],["64843.25","0"],["64852.93","0"],["64920.52","0"],["64922.46","0.071415"],["64950.27","0"],["64951.49","0"],["65075","0"],["65075.19","0"],["65075.71","0"],["65075.85","0"],["65076.4","0"]],"bids":[["64815","0.02"],["64814.49","0"],["64812.84","0.025465"],["64811.68","0"],["64810.93","0"],["64810.92","0"],["64810.68","0"],["64809.45","0"],["64809.44","0"],["64808.48","0.01543"],["64807.61","0.013875"],["64807.6","0.044938"],["64805.9","0.010667"],["64805.49","0"],["64805.48","0"],["64805.04","0.741877"],["64803.89","0"],["64803.49","0"],["64802.93","0.326155"],["64802.92","0.741877"],["64802.91","0.211979"],["64802.22","0"],["64801.62","0.035"],["64800.96","0"],["64799.44","0"],["64799.4","0.001041"],["64798.3","0.463248"],["64798.29","0"],["64796.3","0.030885"],["64794.39","0.154268"],["64794.31","0"],["64792.76","0"],["64791.99","0"],["64786.33","0"],["64785.14","0.003086"],["64731.51","0"],["64715.9","1.87873"],["64404.17","0"]],"ts":"1784090334412","seq":656732590959,"pseq":656732585453}],"ts":1784090334414}
{"action":"update","arg":{"instType":"SPOT","channel":"books","instId":"BTCUSDT"},"data":[{"asks":[["64815.01","1.780717"],["64815.07","0.000772"],["64818.75","0.001691"],["64818.82","0"],["64820.53","0"],["64825.61","0.0053"],["64827.58","0.07192"],["64827.89","0"],["64828.07","0"],["64829.74","0.035"],["64829.97","0.162196"],["64830.9","0"],["64832.75","0"],["65075","0.02"],["65075.19","0.001206"]],"bids":[["64805.91","0.26"],["64805.9","0.229506"],["64805.05","0.309116"],["64803.44","0"],["64802.93","0.559303"],["64802.62","0"],["64801.62","0"],["64800.01","0"],["64799.44","0.061707"],["64798.61","0.035"],["64798.3","0"],["64798.29","0.269001"],["64796.31","0.190723"],["64796.3","0.46325"],["64795.01","0.030884"],["64793.97","0.015514"],["64792.87","0"],["64790.49","0.015451"],["64784.78","0.001581"],["64775.89","0.071415"],["64407.14","0"],["64406.29","0"],["64406.09","0"],["64405.63","0"],["64405.25","0"],["64405.06","0"],["64405","0"]],"ts":"1784090334511","seq":656732593813,"pseq":656732590959}],"ts":1784090334514}
{"action":"update","arg":{"instType":"SPOT","channel":"books","instId":"BTCUSDT"},"data":[{"asks":[["64818.75","0"],["64819.42","0.001691"],["64827.57","0.214741"],["64827.58","0"],["64829.97","0.247354"],["64830","0.200715"],["64849.45","0.37987"]],"bids":[["64800.56","0.000644"],["64800.55","0.000322"],["64799.44","0"],["64799.43","0"],["64794.75","0.084116"],["64793.97","0"],["64793.56","0.182847"],["64774.12","0.359315"],["64407.26","0"]],"ts":"1784090334601","seq":656732596004,"pseq":656732593813}],"ts":1784090334604}
{"action":"update","arg":{"instType":"SPOT","channel":"books","instId":"BTCUSDT"},"data":[{"asks":[["64815.01","1.786867"],["64824.38","0.483268"],["64827.59","1.267068"],["64831.31","0"]],"bids":[["64812.84","0"],["64811.52","0.025703"],["64800.83","0.061707"],["64800.56","0"],["64799.4","0"],["64794.69","0.001041"],["64791.28","0.071415"],["64764.35","0.151379"],["64408.39","0"],["64407.89","0"]],"ts":"1784090334705","seq":656732599235,"pseq":656732596004}],"ts":1784090334708}
{"action":"update","arg":{"instType":"SPOT","channel":"books","instId":"BTCUSDT"},"data":[{"asks":[["64828.3","0"],["64835.83","0.071415"],["64845.55","0.071415"],["64855.27","0.071415"],["64885.3","0"],["64898.05","0.023805"],["64922.46","0"],["64930.25","0"],["64942.3","0"],["64944.8","0"],["64999.3","0"],["65056.3","0"],["65075.71","0.001639"],["65075.85","0.000015"],["65076.4","0.000057"],["65076.92","0.00004"]],"bids":[["64811.52","0"],["64810.2","0.025793"],["64800.96","0.061707"],["64800.83","0"]],"ts":"1784090334802","seq":656732601435,"pseq":656732599235}],"ts":1784090334804}
{"action":"update","arg":{"instType":"SPOT","channel":"books","instId":"BTCUSDT"},"data":[{"asks":[["64822.3","0.002145"],["64843.33","0.462653"],["64852.73","0"],["64879.3","0.002143"],["64936.3","0.002141"],["64993.3","0.002139"],["65050.3","0.002137"],["65075.19","0"],["65075.71","0"],["65075.85","0"],["65076.4","0"],["65076.92","0"]],"bids":[["64811.57","0.025917"],["64811.2","0.002145"],["64810.2","0"],["64783.3","0.002146"],["64755.4","0.002147"],["64727.5","0.002148"],["64699.6","0.002149"],["64410.53","0"],["64410","0"],["64409.45","0"],["64409.43","0"],["64409.25","0"]],"ts":"1784090334912","seq":656732603162,"pseq":656732601435}],"ts":1784090334917}
{"action":"update","arg":{"instType":"SPOT","channel":"books","instId":"BTCUSDT"},"data":[{"asks":[["64815.01","1.812784"],["64816.56","0.001543"],["65075","0"]],"bids":[],"ts":"1784090335006","seq":656732604233,"pseq":656732603162}],"ts":1784090335008}
{"action":"update","arg":{"instType":"SPOT","channel":"books","instId":"BTCUSDT"},"data":[{"asks":[["64815.01","1.815057"],["64815.07","0"],["64816.16","0"],["64819.9","0.001542"],["64820.81","0"],["64820.82","0"],["64823.02","0.015685"],["64823.2","0.463262"],["64823.21","0"],["64826.38","0.001542"],["64827.57","0.351226"],["64827.59","1.112813"],["64829.97","0"],["64832.87","0.001542"],["64835.83","0"],["64839.35","0.001542"],["64843.33","0"],["64845.55","0"],["64849.54","0.462609"],["64855.27","0"],["64898.05","0"],["64901.18","0.071415"],["64919.58","0.071415"],["64939.04","0"],["65075","0.02"]],"bids":[["64810.18","0.001542"],["64803.7","0.001543"],["64801.18","0.015289"],["64797.22","0.001543"],["64795.78","0.001543"],["64793.98","0.001543"],["64790.74","0.001543"],["64787.5","0.001543"],["64771.05","0.05"],["64412.5","0"],["64412","0"],["64411.76","0"],["64411.6","0"],["64411.33","0"],["64411.09","0"],["64410.89","0"],["64410.75","0"],["64410.6","0"]],"ts":"1784090335112","seq":656732606542,"pseq":656732604233}],"ts":1784090335115}
{"action":"update","arg":{"instType":"SPOT","channel":"books","instId":"BTCUSDT"},"data":[{"asks":[["64815.01","1.824063"],["64820.82","0.222091"],["64823.01","0.030884"],["64824.59","0"],["64829.97","0.110228"],["65074.93","0"],["65075","0"]],"bids":[["64815","0.174285"],["64801.19","0"],["64800.96","0.061707"],["64798.29","0.373354"],["64797.96","0.463261"],["64796.32","0.030884"],["64796.31","0"],["64796.3","0.08637"],["64795.01","0"],["64784.2","0.001543"],["64746.59","0"],["64740.01","0.001544"],["64412.55","0"]],"ts":"1784090335200","seq":656732609733,"pseq":656732606542}],"ts":1784090335203}
{"action":"update","arg":{"instType":"SPOT","channel":"books","instId":"BTCUSDT"},"data":[{"asks":[["64901.18","0"],["64930.13","0.071415"]],"bids":[["64814.46","0.00453"],["64811.23","0.011628"],["64801.19","0"],["64800.96","0.061707"],["64778.77","0.036091"],["64414.32","0"],["64413.31","0"],["64412.83","0"]],"ts":"1784090335300","seq":656732612127,"pseq":656732609733}],"ts":1784090335304}
{"action":"update","arg":{"instType":"SPOT","channel":"books","instId":"BTCUSDT"},"data":[{"asks":[["64919.58","0"],["64944.32","0.071415"],["64954.06","0.071415"],["65074.77","0"]],"bids":[["64801.61","0.061707"],["64801.19","0"],["64800.96","0"]],"ts":"1784090335411","seq":656732614421,"pseq":656732612127}],"ts":1784090335414}
{"action":"update","arg":{"instType":"SPOT","channel":"books","instId":"BTCUSDT"},"data":[{"asks":[["64815.01","2.238348"]],"bids":[["64815","0.02"],["64801.8","0.001543"],["64801.61","0"],["64798.29","0.373354"],["64797.96","0.463261"],["64796.31","0"],["64796.3","0.08637"]],"ts":"1784090335508","seq":656732616410,"pseq":656732614421}],"ts":1784090335510}
