{"id":"aetelier-capture","type":"welcome"}
{"id":"sub-l2","type":"ack"}
{"topic":"/market/level2:BTC-USDT","type":"message","subject":"trade.l2update","data":{"changes":{"asks":[],"bids":[["64963.8","0","34557197577"]]},"sequenceEnd":34557197577,"sequenceStart":34557197577,"symbol":"BTC-USDT","time":1784133306841}}
{"topic":"/market/level2:BTC-USDT","type":"message","subject":"trade.l2update","data":{"changes":{"asks":[],"bids":[["64972.6","0.01438744","34557197578"]]},"sequenceEnd":34557197578,"sequenceStart":34557197578,"symbol":"BTC-USDT","time":1784133306841}}
{"topic":"/market/level2:BTC-USDT","type":"message","subject":"trade.l2update","data":{"changes":{"asks":[],"bids":[["64967","0.1","34557197579"]]},"sequenceEnd":34557197579,"sequenceStart":34557197579,"symbol":"BTC-USDT","time":1784133306841}}
{"topic":"/market/level2:BTC-USDT","type":"message","subject":"trade.l2update","data":{"changes":{"asks":[],"bids":[["64970.1","0.01111102","34557197581"]]},"sequenceEnd":34557197581,"sequenceStart":34557197580,"symbol":"BTC-USDT","time":1784133306841}}
{"topic":"/market/level2:BTC-USDT","type":"message","subject":"trade.l2update","data":{"changes":{"asks":[["64973.8","0.60599993","34557197582"],["64975.3","0.29973139","34557197583"]],"bids":[]},"sequenceEnd":34557197583,"sequenceStart":34557197582,"symbol":"BTC-USDT","time":1784133306842}}
{"topic":"/market/level2:BTC-USDT","type":"message","subject":"trade.l2update","data":{"changes":{"asks":[["64977.6","0.086225","34557197584"]],"bids":[]},"sequenceEnd":34557197584,"sequenceStart":34557197584,"symbol":"BTC-USDT","time":1784133306843}}
{"topic":"/market/level2:BTC-USDT","type":"message","subject":"trade.l2update","data":{"changes":{"asks":[],"bids":[["64970.1","0","34557197585"]]},"sequenceEnd":34557197585,"sequenceStart":34557197585,"symbol":"BTC-USDT","time":1784133306843}}
{"topic":"/market/match:BTC-USDT","type":"message","subject":"trade.l3match","data":{"makerOrderId":"6a57b6ba8b6dd60007c383e5","price":"64973.7","sequence":"23580481491845120","side":"sell","size":"0.00711","symbol":"BTC-USDT","takerOrderId":"6a57b6ba0b03f90007f192c4","time":"1784133306836000000","tradeId":"23580481491845120","type":"match"}}
{"topic":"/market/level2:BTC-USDT","type":"message","subject":"trade.l2update","data":{"changes":{"asks":[["64975.3","0.25128357","34557197586"]],"bids":[]},"sequenceEnd":34557197586,"sequenceStart":34557197586,"symbol":"BTC-USDT","time":1784133306844}}
{"topic":"/market/level2:BTC-USDT","type":"message","subject":"trade.l2update","data":{"changes":{"asks":[],"bids":[["64914.2","0","34557197587"]]},"sequenceEnd":34557197587,"sequenceStart":34557197587,"symbol":"BTC-USDT","time":1784133306845}}
{"topic":"/market/level2:BTC-USDT","type":"message","subject":"trade.l2update","data":{"changes":{"asks":[],"bids":[["64963.8","0.01642024","34557197588"]]},"sequenceEnd":34557197588,"sequenceStart":34557197588,"symbol":"BTC-USDT","time":1784133306846}}
{"topic":"/market/level2:BTC-USDT","type":"message","subject":"trade.l2update","data":{"changes":{"asks":[],"bids":[["64959.8","0.20522371","34557197589"]]},"sequenceEnd":34557197589,"sequenceStart":34557197589,"symbol":"BTC-USDT","time":1784133306848}}
{"topic":"/market/level2:BTC-USDT","type":"message","subject":"trade.l2update","data":{"changes":{"asks":[["64973.8","0.60908089","34557197590"]],"bids":[["64973.7","0.17206","34557197591"]]},"sequenceEnd":34557197591,"sequenceStart":34557197590,"symbol":"BTC-USDT","time":1784133306849}}
{"topic":"/market/level2:BTC-USDT","type":"message","subject":"trade.l2update","data":{"changes":{"asks":[["64973.8","0.52288192","34557197592"]],"bids":[]},"sequenceEnd":34557197592,"sequenceStart":34557197592,"symbol":"BTC-USDT","time":1784133306850}}
{"topic":"/market/level2:BTC-USDT","type":"message","subject":"trade.l2update","data":{"changes":{"asks":[["64973.8","0.51980096","34557197593"]],"bids":[]},"sequenceEnd":34557197593,"sequenceStart":34557197593,"symbol":"BTC-USDT","time":1784133306851}}
{"topic":"/market/level2:BTC-USDT","type":"message","subject":"trade.l2update","data":{"changes":{"asks":[["64988.1","0","34557197594"]],"bids":[]},"sequenceEnd":34557197594,"sequenceStart":34557197594,"symbol":"BTC-USDT","time":1784133306851}}
{"topic":"/market/level2:BTC-USDT","type":"message","subject":"trade.l2update","data":{"changes":{"asks":[["64984.5","0.01540234","34557197595"]],"bids":[]},"sequenceEnd":34557197595,"sequenceStart":34557197595,"symbol":"BTC-USDT","time":1784133306851}}
{"topic":"/market/level2:BTC-USDT","type":"message","subject":"trade.l2update","data":{"changes":{"asks":[["64975.4","0.18318498","34557197596"]],"bids":[]},"sequenceEnd":34557197596,"sequenceStart":34557197596,"symbol":"BTC-USDT","time":1784133306852}}
{"topic":"/market/level2:BTC-USDT","type":"message","subject":"trade.l2update","data":{"changes":{"asks":[["64975.4","0.13099902","34557197597"]],"bids":[]},"sequenceEnd":34557197597,"sequenceStart":34557197597,"symbol":"BTC-USDT","time":1784133306853}}
{"topic":"/market/level2:BTC-USDT","type":"message","subject":"trade.l2update","data":{"changes":{"asks":[["64978.3","0.0138065","34557197598"]],"bids":[]},"sequenceEnd":34557197598,"sequenceStart":34557197598,"symbol":"BTC-USDT","time":1784133306853}}
{"topic":"/market/level2:BTC-USDT","type":"message","subject":"trade.l2update","data":{"changes":{"asks":[["64978.4","0","34557197600"]],"bids":[]},"sequenceEnd":34557197600,"sequenceStart":34557197599,"symbol":"BTC-USDT","time":1784133306853}}
{"topic":"/market/level2:BTC-USDT","type":"message","subject":"trade.l2update","data":{"changes":{"asks":[["64978","0","34557197601"]],"bids":[]},"sequenceEnd":34557197601,"sequenceStart":34557197601,"symbol":"BTC-USDT","time":1784133306853}}
{"topic":"/market/level2:BTC-USDT","type":"message","subject":"trade.l2update","data":{"changes":{"asks":[["64978.3","0","34557197602"]],"bids":[]},"sequenceEnd":34557197602,"sequenceStart":34557197602,"symbol":"BTC-USDT","time":1784133306853}}
{"topic":"/market/level2:BTC-USDT","type":"message","subject":"trade.l2update","data":{"changes":{"asks":[["64975.4","0.114387","34557197603"]],"bids":[]},"sequenceEnd":34557197603,"sequenceStart":34557197603,"symbol":"BTC-USDT","time":1784133306853}}
{"topic":"/market/level2:BTC-USDT","type":"message","subject":"trade.l2update","data":{"changes":{"asks":[["64975.5","0","34557197604"]],"bids":[]},"sequenceEnd":34557197604,"sequenceStart":34557197604,"symbol":"BTC-USDT","time":1784133306853}}
{"topic":"/market/level2:BTC-USDT","type":"message","subject":"trade.l2update","data":{"changes":{"asks":[["64975.4","0.0921354","34557197605"]],"bids":[["64968.6","0.05441703","34557197606"],["64971.2","0.03421213","34557197607"]]},"sequenceEnd":34557197607,"sequenceStart":34557197605,"symbol":"BTC-USDT","time":1784133306853}}
{"topic":"/market/level2:BTC-USDT","type":"message","subject":"trade.l2update","data":{"changes":{"asks":[],"bids":[["64959.7","0","34557197608"],["64959.9","0.14784175","34557197609"]]},"sequenceEnd":34557197609,"sequenceStart":34557197608,"symbol":"BTC-USDT","time":1784133306853}}
{"topic":"/market/level2:BTC-USDT","type":"message","subject":"trade.l2update","data":{"changes":{"asks":[["64984.5","0","34557197610"]],"bids":[]},"sequenceEnd":34557197610,"sequenceStart":34557197610,"symbol":"BTC-USDT","time":1784133306854}}
{"topic":"/market/level2:BTC-USDT","type":"message","subject":"trade.l2update","data":{"changes":{"asks":[["64980.3","0.01540234","34557197611"]],"bids":[]},"sequenceEnd":34557197611,"sequenceStart":34557197611,"symbol":"BTC-USDT","time":1784133306854}}
{"topic":"/market/level2:BTC-USDT","type":"message","subject":"trade.l2update","data":{"changes":{"asks":[],"bids":[["64963.1","0.00925917","34557197612"]]},"sequenceEnd":34557197612,"sequenceStart":34557197612,"symbol":"BTC-USDT","time":1784133306854}}
{"topic":"/market/level2:BTC-USDT","type":"message","subject":"trade.l2update","data":{"changes":{"asks":[["64983.8","0","34557197613"]],"bids":[]},"sequenceEnd":34557197613,"sequenceStart":34557197613,"symbol":"BTC-USDT","time":1784133306855}}
{"topic":"/market/level2:BTC-USDT","type":"message","subject":"trade.l2update","data":{"changes":{"asks":[["64977.6","0.06002452","34557197614"]],"bids":[]},"sequenceEnd":34557197614,"sequenceStart":34557197614,"symbol":"BTC-USDT","time":1784133306858}}
{"topic":"/market/level2:BTC-USDT","type":"message","subject":"trade.l2update","data":{"changes":{"asks":[],"bids":[["64972.6","0","34557197615"]]},"sequenceEnd":34557197615,"sequenceStart":34557197615,"symbol":"BTC-USDT","time":1784133306858}}
{"topic":"/market/level2:BTC-USDT","type":"message","subject":"trade.l2update","data":{"changes":{"asks":[],"bids":[["64972.2","0.02459976","34557197616"]]},"sequenceEnd":34557197616,"sequenceStart":34557197616,"symbol":"BTC-USDT","time":1784133306858}}
{"topic":"/market/level2:BTC-USDT","type":"message","subject":"trade.l2update","data":{"changes":{"asks":[],"bids":[["64968.7","0.01624348","34557197617"]]},"sequenceEnd":34557197617,"sequenceStart":34557197617,"symbol":"BTC-USDT","time":1784133306858}}
{"topic":"/market/level2:BTC-USDT","type":"message","subject":"trade.l2update","data":{"changes":{"asks":[["64994","0.37742987","34557197618"]],"bids":[]},"sequenceEnd":34557197618,"sequenceStart":34557197618,"symbol":"BTC-USDT","time":1784133306859}}
{"topic":"/market/level2:BTC-USDT","type":"message","subject":"trade.l2update","data":{"changes":{"asks":[],"bids":[["64787.5","0.00154032","34557197619"]]},"sequenceEnd":34557197619,"sequenceStart":34557197619,"symbol":"BTC-USDT","time":1784133306860}}
{"topic":"/market/level2:BTC-USDT","type":"message","subject":"trade.l2update","data":{"changes":{"asks":[["64996.2","0","34557197620"]],"bids":[]},"sequenceEnd":34557197620,"sequenceStart":34557197620,"symbol":"BTC-USDT","time":1784133306860}}
{"topic":"/market/level2:BTC-USDT","type":"message","subject":"trade.l2update","data":{"changes":{"asks":[],"bids":[["64920.5","0.00154032","34557197621"]]},"sequenceEnd":34557197621,"sequenceStart":34557197621,"symbol":"BTC-USDT","time":1784133306862}}
{"topic":"/market/level2:BTC-USDT","type":"message","subject":"trade.l2update","data":{"changes":{"asks":[],"bids":[["64956.3","0.01540225","34557197622"]]},"sequenceEnd":34557197622,"sequenceStart":34557197622,"symbol":"BTC-USDT","time":1784133306864}}
{"topic":"/market/level2:BTC-USDT","type":"message","subject":"trade.l2update","data":{"changes":{"asks":[["64992.7","0.37743677","34557197623"]],"bids":[]},"sequenceEnd":34557197623,"sequenceStart":34557197623,"symbol":"BTC-USDT","time":1784133306867}}
{"topic":"/market/level2:BTC-USDT","type":"message","subject":"trade.l2update","data":{"changes":{"asks":[["64994","0","34557197624"]],"bids":[]},"sequenceEnd":34557197624,"sequenceStart":34557197624,"symbol":"BTC-USDT","time":1784133306867}}
{"topic":"/market/level2:BTC-USDT","type":"message","subject":"trade.l2update","data":{"changes":{"asks":[],"bids":[["63999","0.00001","34557197625"]]},"sequenceEnd":34557197625,"sequenceStart":34557197625,"symbol":"BTC-USDT","time":1784133306868}}
{"topic":"/market/level2:BTC-USDT","type":"message","subject":"trade.l2update","data":{"changes":{"asks":[],"bids":[["63039.1","0.00001","34557197626"]]},"sequenceEnd":34557197626,"sequenceStart":34557197626,"symbol":"BTC-USDT","time":1784133306868}}
{"topic":"/market/level2:BTC-USDT","type":"message","subject":"trade.l2update","data":{"changes":{"asks":[],"bids":[["64791","0.00163435","34557197627"]]},"sequenceEnd":34557197627,"sequenceStart":34557197627,"symbol":"BTC-USDT","time":1784133306870}}
{"topic":"/market/level2:BTC-USDT","type":"message","subject":"trade.l2update","data":{"changes":{"asks":[],"bids":[["64920.6","0.00154036","34557197628"]]},"sequenceEnd":34557197628,"sequenceStart":34557197628,"symbol":"BTC-USDT","time":1784133306872}}
{"topic":"/market/level2:BTC-USDT","type":"message","subject":"trade.l2update","data":{"changes":{"asks":[],"bids":[["64791","0.00317471","34557197629"]]},"sequenceEnd":34557197629,"sequenceStart":34557197629,"symbol":"BTC-USDT","time":1784133306872}}
{"topic":"/market/level2:BTC-USDT","type":"message","subject":"trade.l2update","data":{"changes":{"asks":[],"bids":[["64968.6","0","34557197630"]]},"sequenceEnd":34557197630,"sequenceStart":34557197630,"symbol":"BTC-USDT","time":1784133306872}}
{"topic":"/market/level2:BTC-USDT","type":"message","subject":"trade.l2update","data":{"changes":{"asks":[["64980.3","0","34557197631"]],"bids":[]},"sequenceEnd":34557197631,"sequenceStart":34557197631,"symbol":"BTC-USDT","time":1784133306873}}
{"topic":"/market/level2:BTC-USDT","type":"message","subject":"trade.l2update","data":{"changes":{"asks":[["64981.7","0.01540419","34557197632"]],"bids":[]},"sequenceEnd":34557197632,"sequenceStart":34557197632,"symbol":"BTC-USDT","time":1784133306873}}
{"topic":"/market/level2:BTC-USDT","type":"message","subject":"trade.l2update","data":{"changes":{"asks":[["64992.7","0","34557197633"]],"bids":[]},"sequenceEnd":34557197633,"sequenceStart":34557197633,"symbol":"BTC-USDT","time":1784133306875}}
{"topic":"/market/level2:BTC-USDT","type":"message","subject":"trade.l2update","data":{"changes":{"asks":[["64994","0.37743033","34557197634"]],"bids":[]},"sequenceEnd":34557197634,"sequenceStart":34557197634,"symbol":"BTC-USDT","time":1784133306875}}
{"topic":"/market/level2:BTC-USDT","type":"message","subject":"trade.l2update","data":{"changes":{"asks":[],"bids":[["64968.7","0","34557197635"]]},"sequenceEnd":34557197635,"sequenceStart":34557197635,"symbol":"BTC-USDT","time":1784133306877}}
{"topic":"/market/level2:BTC-USDT","type":"message","subject":"trade.l2update","data":{"changes":{"asks":[],"bids":[["1","13601.7854165","34557197637"]]},"sequenceEnd":34557197637,"sequenceStart":34557197636,"symbol":"BTC-USDT","time":1784133306880}}
{"topic":"/market/level2:BTC-USDT","type":"message","subject":"trade.l2update","data":{"changes":{"asks":[["65011.1","0.04481509","34557197639"]],"bids":[["1","13601.6854165","34557197638"]]},"sequenceEnd":34557197639,"sequenceStart":34557197638,"symbol":"BTC-USDT","time":1784133306881}}
{"topic":"/market/level2:BTC-USDT","type":"message","subject":"trade.l2update","data":{"changes":{"asks":[["64994","0","34557197640"]],"bids":[]},"sequenceEnd":34557197640,"sequenceStart":34557197640,"symbol":"BTC-USDT","time":1784133306882}}
{"topic":"/market/level2:BTC-USDT","type":"message","subject":"trade.l2update","data":{"changes":{"asks":[],"bids":[["1","13601.7854165","34557197641"]]},"sequenceEnd":34557197641,"sequenceStart":34557197641,"symbol":"BTC-USDT","time":1784133306883}}
{"topic":"/market/level2:BTC-USDT","type":"message","subject":"trade.l2update","data":{"changes":{"asks":[["64973.8","0.52288196","34557197642"]],"bids":[]},"sequenceEnd":34557197642,"sequenceStart":34557197642,"symbol":"BTC-USDT","time":1784133306885}}
{"topic":"/market/level2:BTC-USDT","type":"message","subject":"trade.l2update","data":{"changes":{"asks":[["64996.2","0.37742373","34557197643"]],"bids":[]},"sequenceEnd":34557197643,"sequenceStart":34557197643,"symbol":"BTC-USDT","time":1784133306885}}
{"topic":"/market/level2:BTC-USDT","type":"message","subject":"trade.l2update","data":{"changes":{"asks":[],"bids":[["64973.7","0.175141","34557197644"]]},"sequenceEnd":34557197644,"sequenceStart":34557197644,"symbol":"BTC-USDT","time":1784133306885}}
{"topic":"/market/level2:BTC-USDT","type":"message","subject":"trade.l2update","data":{"changes":{"asks":[],"bids":[["101","2.856","34557197645"]]},"sequenceEnd":34557197645,"sequenceStart":34557197645,"symbol":"BTC-USDT","time":1784133306890}}
{"topic":"/market/level2:BTC-USDT","type":"message","subject":"trade.l2update","data":{"changes":{"asks":[],"bids":[["101","2.846","34557197646"]]},"sequenceEnd":34557197646,"sequenceStart":34557197646,"symbol":"BTC-USDT","time":1784133306892}}
{"topic":"/market/level2:BTC-USDT","type":"message","subject":"trade.l2update","data":{"changes":{"asks":[["64976.3","0.00600222","34557197647"]],"bids":[]},"sequenceEnd":34557197647,"sequenceStart":34557197647,"symbol":"BTC-USDT","time":1784133306920}}
{"topic":"/market/level2:BTC-USDT","type":"message","subject":"trade.l2update","data":{"changes":{"asks":[],"bids":[["64973.7","0.35097382","34557197648"]]},"sequenceEnd":34557197648,"sequenceStart":34557197648,"symbol":"BTC-USDT","time":1784133306970}}
{"topic":"/market/level2:BTC-USDT","type":"message","subject":"trade.l2update","data":{"changes":{"asks":[],"bids":[["64940","0.00001072","34557197649"]]},"sequenceEnd":34557197649,"sequenceStart":34557197649,"symbol":"BTC-USDT","time":1784133306972}}
{"topic":"/market/level2:BTC-USDT","type":"message","subject":"trade.l2update","data":{"changes":{"asks":[],"bids":[["64908.9","0.20001374","34557197650"]]},"sequenceEnd":34557197650,"sequenceStart":34557197650,"symbol":"BTC-USDT","time":1784133306980}}
{"topic":"/market/level2:BTC-USDT","type":"message","subject":"trade.l2update","data":{"changes":{"asks":[["64973.8","0.52863898","34557197651"]],"bids":[]},"sequenceEnd":34557197651,"sequenceStart":34557197651,"symbol":"BTC-USDT","time":1784133306983}}
{"topic":"/market/level2:BTC-USDT","type":"message","subject":"trade.l2update","data":{"changes":{"asks":[["64975.2","0.10915466","34557197652"]],"bids":[]},"sequenceEnd":34557197652,"sequenceStart":34557197652,"symbol":"BTC-USDT","time":1784133306990}}
{"topic":"/market/level2:BTC-USDT","type":"message","subject":"trade.l2update","data":{"changes":{"asks":[],"bids":[["64956.3","0","34557197653"]]},"sequenceEnd":34557197653,"sequenceStart":34557197653,"symbol":"BTC-USDT","time":1784133306992}}
{"topic":"/market/level2:BTC-USDT","type":"message","subject":"trade.l2update","data":{"changes":{"asks":[],"bids":[["64954.7","0.01540402","34557197654"]]},"sequenceEnd":34557197654,"sequenceStart":34557197654,"symbol":"BTC-USDT","time":1784133306992}}
{"topic":"/market/level2:BTC-USDT","type":"message","subject":"trade.l2update","data":{"changes":{"asks":[],"bids":[["64955.8","0.00601465","34557197655"]]},"sequenceEnd":34557197655,"sequenceStart":34557197655,"symbol":"BTC-USDT","time":1784133306995}}
{"topic":"/market/level2:BTC-USDT","type":"message","subject":"trade.l2update","data":{"changes":{"asks":[],"bids":[["64873.6","0","34557197656"]]},"sequenceEnd":34557197656,"sequenceStart":34557197656,"symbol":"BTC-USDT","time":1784133306995}}
{"topic":"/market/level2:BTC-USDT","type":"message","subject":"trade.l2update","data":{"changes":{"asks":[],"bids":[["64928.4","0.02411492","34557197657"]]},"sequenceEnd":34557197657,"sequenceStart":34557197657,"symbol":"BTC-USDT","time":1784133306996}}
{"topic":"/market/level2:BTC-USDT","type":"message","subject":"trade.l2update","data":{"changes":{"asks":[["64996.2","0","34557197658"]],"bids":[]},"sequenceEnd":34557197658,"sequenceStart":34557197658,"symbol":"BTC-USDT","time":1784133306997}}
{"topic":"/market/level2:BTC-USDT","type":"message","subject":"trade.l2update","data":{"changes":{"asks":[["64992.7","0.37743793","34557197659"]],"bids":[]},"sequenceEnd":34557197659,"sequenceStart":34557197659,"symbol":"BTC-USDT","time":1784133306997}}
{"topic":"/market/level2:BTC-USDT","type":"message","subject":"trade.l2update","data":{"changes":{"asks":[],"bids":[["64973.7","0.24747382","34557197660"]]},"sequenceEnd":34557197660,"sequenceStart":34557197660,"symbol":"BTC-USDT","time":1784133306998}}
{"topic":"/market/level2:BTC-USDT","type":"message","subject":"trade.l2update","data":{"changes":{"asks":[["64981.7","0","34557197661"]],"bids":[]},"sequenceEnd":34557197661,"sequenceStart":34557197661,"symbol":"BTC-USDT","time":1784133307000}}
{"topic":"/market/level2:BTC-USDT","type":"message","subject":"trade.l2update","data":{"changes":{"asks":[],"bids":[["64954.7","0","34557197662"]]},"sequenceEnd":34557197662,"sequenceStart":34557197662,"symbol":"BTC-USDT","time":1784133307000}}
{"topic":"/market/level2:BTC-USDT","type":"message","subject":"trade.l2update","data":{"changes":{"asks":[],"bids":[["64953","0.01543901","34557197663"]]},"sequenceEnd":34557197663,"sequenceStart":34557197663,"symbol":"BTC-USDT","time":1784133307000}}
{"topic":"/market/level2:BTC-USDT","type":"message","subject":"trade.l2update","data":{"changes":{"asks":[["64977.5","0.01540402","34557197664"]],"bids":[]},"sequenceEnd":34557197664,"sequenceStart":34557197664,"symbol":"BTC-USDT","time":1784133307000}}
{"topic":"/market/level2:BTC-USDT","type":"message","subject":"trade.l2update","data":{"changes":{"asks":[["64990.7","0.2307718","34557197665"]],"bids":[]},"sequenceEnd":34557197665,"sequenceStart":34557197665,"symbol":"BTC-USDT","time":1784133307002}}
{"topic":"/market/level2:BTC-USDT","type":"message","subject":"trade.l2update","data":{"changes":{"asks":[],"bids":[["64967.2","0.1035","34557197666"]]},"sequenceEnd":34557197666,"sequenceStart":34557197666,"symbol":"BTC-USDT","time":1784133307003}}
{"topic":"/market/level2:BTC-USDT","type":"message","subject":"trade.l2update","data":{"changes":{"asks":[["64977.5","0","34557197667"]],"bids":[]},"sequenceEnd":34557197667,"sequenceStart":34557197667,"symbol":"BTC-USDT","time":1784133307004}}
{"topic":"/market/level2:BTC-USDT","type":"message","subject":"trade.l2update","data":{"changes":{"asks":[],"bids":[["64953","0.00003499","34557197668"]]},"sequenceEnd":34557197668,"sequenceStart":34557197668,"symbol":"BTC-USDT","time":1784133307004}}
{"topic":"/market/level2:BTC-USDT","type":"message","subject":"trade.l2update","data":{"changes":{"asks":[["64978.9","0.01540401","34557197669"]],"bids":[]},"sequenceEnd":34557197669,"sequenceStart":34557197669,"symbol":"BTC-USDT","time":1784133307004}}
{"topic":"/market/level2:BTC-USDT","type":"message","subject":"trade.l2update","data":{"changes":{"asks":[],"bids":[["64954.2","0.01540401","34557197670"]]},"sequenceEnd":34557197670,"sequenceStart":34557197670,"symbol":"BTC-USDT","time":1784133307004}}
{"topic":"/market/level2:BTC-USDT","type":"message","subject":"trade.l2update","data":{"changes":{"asks":[],"bids":[["64873.2","0.11204389","34557197671"]]},"sequenceEnd":34557197671,"sequenceStart":34557197671,"symbol":"BTC-USDT","time":1784133307006}}
{"topic":"/market/level2:BTC-USDT","type":"message","subject":"trade.l2update","data":{"changes":{"asks":[["64993.2","0.37743429","34557197672"]],"bids":[]},"sequenceEnd":34557197672,"sequenceStart":34557197672,"symbol":"BTC-USDT","time":1784133307007}}
{"topic":"/market/level2:BTC-USDT","type":"message","subject":"trade.l2update","data":{"changes":{"asks":[["64992.7","0","34557197673"]],"bids":[]},"sequenceEnd":34557197673,"sequenceStart":34557197673,"symbol":"BTC-USDT","time":1784133307007}}
{"topic":"/market/level2:BTC-USDT","type":"message","subject":"trade.l2update","data":{"changes":{"asks":[],"bids":[["64967.3","0.03089475","34557197674"]]},"sequenceEnd":34557197674,"sequenceStart":34557197674,"symbol":"BTC-USDT","time":1784133307009}}
{"topic":"/market/level2:BTC-USDT","type":"message","subject":"trade.l2update","data":{"changes":{"asks":[],"bids":[["64949.2","0.02098942","34557197675"]]},"sequenceEnd":34557197675,"sequenceStart":34557197675,"symbol":"BTC-USDT","time":1784133307012}}
{"topic":"/market/level2:BTC-USDT","type":"message","subject":"trade.l2update","data":{"changes":{"asks":[],"bids":[["64920.5","0","34557197676"]]},"sequenceEnd":34557197676,"sequenceStart":34557197676,"symbol":"BTC-USDT","time":1784133307014}}
{"topic":"/market/level2:BTC-USDT","type":"message","subject":"trade.l2update","data":{"changes":{"asks":[],"bids":[["64787.5","0","34557197677"]]},"sequenceEnd":34557197677,"sequenceStart":34557197677,"symbol":"BTC-USDT","time":1784133307014}}
{"topic":"/market/level2:BTC-USDT","type":"message","subject":"trade.l2update","data":{"changes":{"asks":[],"bids":[["64954.2","0","34557197678"]]},"sequenceEnd":34557197678,"sequenceStart":34557197678,"symbol":"BTC-USDT","time":1784133307019}}
{"topic":"/market/level2:BTC-USDT","type":"message","subject":"trade.l2update","data":{"changes":{"asks":[],"bids":[["64954.7","0.01540398","34557197679"]]},"sequenceEnd":34557197679,"sequenceStart":34557197679,"symbol":"BTC-USDT","time":1784133307019}}
{"topic":"/market/level2:BTC-USDT","type":"message","subject":"trade.l2update","data":{"changes":{"asks":[],"bids":[["64954.7","0","34557197680"]]},"sequenceEnd":34557197680,"sequenceStart":34557197680,"symbol":"BTC-USDT","time":1784133307024}}
{"topic":"/market/level2:BTC-USDT","type":"message","subject":"trade.l2update","data":{"changes":{"asks":[],"bids":[["64954.2","0.01540398","34557197681"]]},"sequenceEnd":34557197681,"sequenceStart":34557197681,"symbol":"BTC-USDT","time":1784133307024}}
{"topic":"/market/level2:BTC-USDT","type":"message","subject":"trade.l2update","data":{"changes":{"asks":[],"bids":[["64954.2","0","34557197682"]]},"sequenceEnd":34557197682,"sequenceStart":34557197682,"symbol":"BTC-USDT","time":1784133307024}}
{"topic":"/market/level2:BTC-USDT","type":"message","subject":"trade.l2update","data":{"changes":{"asks":[],"bids":[["64954.2","0.01540398","34557197683"]]},"sequenceEnd":34557197683,"sequenceStart":34557197683,"symbol":"BTC-USDT","time":1784133307027}}
{"topic":"/market/level2:BTC-USDT","type":"message","subject":"trade.l2update","data":{"changes":{"asks":[["64993.2","0","34557197684"]],"bids":[]},"sequenceEnd":34557197684,"sequenceStart":34557197684,"symbol":"BTC-USDT","time":1784133307027}}
{"topic":"/market/level2:BTC-USDT","type":"message","subject":"trade.l2update","data":{"changes":{"asks":[["64993.4","0.37743253","34557197685"]],"bids":[]},"sequenceEnd":34557197685,"sequenceStart":34557197685,"symbol":"BTC-USDT","time":1784133307027}}
{"topic":"/market/level2:BTC-USDT","type":"message","subject":"trade.l2update","data":{"changes":{"asks":[],"bids":[["64954.2","0","34557197686"]]},"sequenceEnd":34557197686,"sequenceStart":34557197686,"symbol":"BTC-USDT","time":1784133307028}}
{"topic":"/market/level2:BTC-USDT","type":"message","subject":"trade.l2update","data":{"changes":{"asks":[],"bids":[["64954.7","0.01540398","34557197687"]]},"sequenceEnd":34557197687,"sequenceStart":34557197687,"symbol":"BTC-USDT","time":1784133307028}}
{"topic":"/market/level2:BTC-USDT","type":"message","subject":"trade.l2update","data":{"changes":{"asks":[],"bids":[["64954.7","0","34557197688"]]},"sequenceEnd":34557197688,"sequenceStart":34557197688,"symbol":"BTC-USDT","time":1784133307031}}
{"topic":"/market/level2:BTC-USDT","type":"message","subject":"trade.l2update","data":{"changes":{"asks":[],"bids":[["64954.2","0.01540398","34557197689"]]},"sequenceEnd":34557197689,"sequenceStart":34557197689,"symbol":"BTC-USDT","time":1784133307031}}
{"topic":"/market/level2:BTC-USDT","type":"message","subject":"trade.l2update","data":{"changes":{"asks":[["64993.4","0","34557197690"]],"bids":[]},"sequenceEnd":34557197690,"sequenceStart":34557197690,"symbol":"BTC-USDT","time":1784133307034}}
{"topic":"/market/level2:BTC-USDT","type":"message","subject":"trade.l2update","data":{"changes":{"asks":[["64993.5","0.4684368","34557197691"]],"bids":[]},"sequenceEnd":34557197691,"sequenceStart":34557197691,"symbol":"BTC-USDT","time":1784133307034}}
{"topic":"/market/level2:BTC-USDT","type":"message","subject":"trade.l2update","data":{"changes":{"asks":[],"bids":[["0.1","353051.72608864","34557197692"]]},"sequenceEnd":34557197692,"sequenceStart":34557197692,"symbol":"BTC-USDT","time":1784133307034}}
{"topic":"/market/level2:BTC-USDT","type":"message","subject":"trade.l2update","data":{"changes":{"asks":[["65006.5","0.00406696","34557197693"]],"bids":[]},"sequenceEnd":34557197693,"sequenceStart":34557197693,"symbol":"BTC-USDT","time":1784133307035}}
{"topic":"/market/level2:BTC-USDT","type":"message","subject":"trade.l2update","data":{"changes":{"asks":[["65012.2","0.0198309","34557197694"]],"bids":[]},"sequenceEnd":34557197694,"sequenceStart":34557197694,"symbol":"BTC-USDT","time":1784133307035}}
{"topic":"/market/level2:BTC-USDT","type":"message","subject":"trade.l2update","data":{"changes":{"asks":[],"bids":[["0.1","353050.72608864","34557197695"]]},"sequenceEnd":34557197695,"sequenceStart":34557197695,"symbol":"BTC-USDT","time":1784133307037}}
{"topic":"/market/level2:BTC-USDT","type":"message","subject":"trade.l2update","data":{"changes":{"asks":[["65006.5","0","34557197696"]],"bids":[]},"sequenceEnd":34557197696,"sequenceStart":34557197696,"symbol":"BTC-USDT","time":1784133307041}}
{"topic":"/market/level2:BTC-USDT","type":"message","subject":"trade.l2update","data":{"changes":{"asks":[],"bids":[["0.1","353051.72608864","34557197697"]]},"sequenceEnd":34557197697,"sequenceStart":34557197697,"symbol":"BTC-USDT","time":1784133307041}}
{"topic":"/market/level2:BTC-USDT","type":"message","subject":"trade.l2update","data":{"changes":{"asks":[["65008.7","0.00406695","34557197698"]],"bids":[]},"sequenceEnd":34557197698,"sequenceStart":34557197698,"symbol":"BTC-USDT","time":1784133307041}}
{"topic":"/market/level2:BTC-USDT","type":"message","subject":"trade.l2update","data":{"changes":{"asks":[["64993.5","0.09100513","34557197699"]],"bids":[]},"sequenceEnd":34557197699,"sequenceStart":34557197699,"symbol":"BTC-USDT","time":1784133307042}}
{"topic":"/market/level2:BTC-USDT","type":"message","subject":"trade.l2update","data":{"changes":{"asks":[["64993.2","0.37743531","34557197700"]],"bids":[]},"sequenceEnd":34557197700,"sequenceStart":34557197700,"symbol":"BTC-USDT","time":1784133307042}}
{"topic":"/market/level2:BTC-USDT","type":"message","subject":"trade.l2update","data":{"changes":{"asks":[],"bids":[["0.1","353050.72608864","34557197701"]]},"sequenceEnd":34557197701,"sequenceStart":34557197701,"symbol":"BTC-USDT","time":1784133307045}}
{"topic":"/market/level2:BTC-USDT","type":"message","subject":"trade.l2update","data":{"changes":{"asks":[],"bids":[["0.1","353051.72608864","34557197702"]]},"sequenceEnd":34557197702,"sequenceStart":34557197702,"symbol":"BTC-USDT","time":1784133307048}}
{"topic":"/market/level2:BTC-USDT","type":"message","subject":"trade.l2update","data":{"changes":{"asks":[["64990.7","0.13627496","34557197703"]],"bids":[]},"sequenceEnd":34557197703,"sequenceStart":34557197703,"symbol":"BTC-USDT","time":1784133307049}}
{"topic":"/market/level2:BTC-USDT","type":"message","subject":"trade.l2update","data":{"changes":{"asks":[],"bids":[["0.1","353050.72608864","34557197704"]]},"sequenceEnd":34557197704,"sequenceStart":34557197704,"symbol":"BTC-USDT","time":1784133307049}}
{"topic":"/market/level2:BTC-USDT","type":"message","subject":"trade.l2update","data":{"changes":{"asks":[],"bids":[["0.1","353051.72608864","34557197705"]]},"sequenceEnd":34557197705,"sequenceStart":34557197705,"symbol":"BTC-USDT","time":1784133307054}}
{"topic":"/market/level2:BTC-USDT","type":"message","subject":"trade.l2update","data":{"changes":{"asks":[],"bids":[["64955.8","0","34557197706"]]},"sequenceEnd":34557197706,"sequenceStart":34557197706,"symbol":"BTC-USDT","time":1784133307056}}
{"topic":"/market/level2:BTC-USDT","type":"message","subject":"trade.l2update","data":{"changes":{"asks":[],"bids":[["0.1","353050.72608864","34557197707"]]},"sequenceEnd":34557197707,"sequenceStart":34557197707,"symbol":"BTC-USDT","time":1784133307057}}
{"topic":"/market/level2:BTC-USDT","type":"message","subject":"trade.l2update","data":{"changes":{"asks":[],"bids":[["64973.7","0.17891382","34557197708"]]},"sequenceEnd":34557197708,"sequenceStart":34557197708,"symbol":"BTC-USDT","time":1784133307059}}
{"topic":"/market/level2:BTC-USDT","type":"message","subject":"trade.l2update","data":{"changes":{"asks":[],"bids":[["1","13601.5854165","34557197712"]]},"sequenceEnd":34557197712,"sequenceStart":34557197709,"symbol":"BTC-USDT","time":1784133307059}}
{"topic":"/market/level2:BTC-USDT","type":"message","subject":"trade.l2update","data":{"changes":{"asks":[],"bids":[["1","13601.6854165","34557197713"]]},"sequenceEnd":34557197713,"sequenceStart":34557197713,"symbol":"BTC-USDT","time":1784133307059}}
{"topic":"/market/level2:BTC-USDT","type":"message","subject":"trade.l2update","data":{"changes":{"asks":[],"bids":[["0.1","353051.72608864","34557197714"]]},"sequenceEnd":34557197714,"sequenceStart":34557197714,"symbol":"BTC-USDT","time":1784133307060}}
{"topic":"/market/level2:BTC-USDT","type":"message","subject":"trade.l2update","data":{"changes":{"asks":[],"bids":[["1","13601.5854165","34557197717"]]},"sequenceEnd":34557197717,"sequenceStart":34557197715,"symbol":"BTC-USDT","time":1784133307060}}
{"topic":"/market/level2:BTC-USDT","type":"message","subject":"trade.l2update","data":{"changes":{"asks":[],"bids":[["1","13601.6854165","34557197718"]]},"sequenceEnd":34557197718,"sequenceStart":34557197718,"symbol":"BTC-USDT","time":1784133307060}}
{"topic":"/market/level2:BTC-USDT","type":"message","subject":"trade.l2update","data":{"changes":{"asks":[],"bids":[["1","13601.7854165","34557197720"],["64791","0.00158993","34557197719"]]},"sequenceEnd":34557197720,"sequenceStart":34557197719,"symbol":"BTC-USDT","time":1784133307060}}
{"topic":"/market/level2:BTC-USDT","type":"message","subject":"trade.l2update","data":{"changes":{"asks":[["64993.4","0.37743201","34557197721"]],"bids":[]},"sequenceEnd":34557197721,"sequenceStart":34557197721,"symbol":"BTC-USDT","time":1784133307062}}
{"topic":"/market/level2:BTC-USDT","type":"message","subject":"trade.l2update","data":{"changes":{"asks":[["64993.2","0","34557197722"]],"bids":[]},"sequenceEnd":34557197722,"sequenceStart":34557197722,"symbol":"BTC-USDT","time":1784133307062}}
{"topic":"/market/level2:BTC-USDT","type":"message","subject":"trade.l2update","data":{"changes":{"asks":[],"bids":[["0.1","353050.72608864","34557197723"]]},"sequenceEnd":34557197723,"sequenceStart":34557197723,"symbol":"BTC-USDT","time":1784133307063}}
{"topic":"/market/level2:BTC-USDT","type":"message","subject":"trade.l2update","data":{"changes":{"asks":[],"bids":[["64973.7","0.003081","34557197724"]]},"sequenceEnd":34557197724,"sequenceStart":34557197724,"symbol":"BTC-USDT","time":1784133307064}}
{"topic":"/market/level2:BTC-USDT","type":"message","subject":"trade.l2update","data":{"changes":{"asks":[["64993.5","0.46843701","34557197725"]],"bids":[]},"sequenceEnd":34557197725,"sequenceStart":34557197725,"symbol":"BTC-USDT","time":1784133307068}}
{"topic":"/market/level2:BTC-USDT","type":"message","subject":"trade.l2update","data":{"changes":{"asks":[["64972.3","0.015294","34557197727"]],"bids":[["64908.9","0.00001374","34557197728"],["64973.7","0","34557197726"]]},"sequenceEnd":34557197728,"sequenceStart":34557197726,"symbol":"BTC-USDT","time":1784133307068}}
{"topic":"/market/level2:BTC-USDT","type":"message","subject":"trade.l2update","data":{"changes":{"asks":[],"bids":[["64791","0.00004957","34557197729"]]},"sequenceEnd":34557197729,"sequenceStart":34557197729,"symbol":"BTC-USDT","time":1784133307069}}
{"topic":"/market/level2:BTC-USDT","type":"message","subject":"trade.l2update","data":{"changes":{"asks":[],"bids":[["64920.6","0","34557197730"]]},"sequenceEnd":34557197730,"sequenceStart":34557197730,"symbol":"BTC-USDT","time":1784133307069}}
{"topic":"/market/level2:BTC-USDT","type":"message","subject":"trade.l2update","data":{"changes":{"asks":[],"bids":[["1","13601.7854165","34557197732"]]},"sequenceEnd":34557197732,"sequenceStart":34557197731,"symbol":"BTC-USDT","time":1784133307070}}
{"topic":"/market/level2:BTC-USDT","type":"message","subject":"trade.l2update","data":{"changes":{"asks":[["64993.4","0","34557197733"],["65020.9","0","34557197734"]],"bids":[]},"sequenceEnd":34557197734,"sequenceStart":34557197733,"symbol":"BTC-USDT","time":1784133307070}}
{"topic":"/market/level2:BTC-USDT","type":"message","subject":"trade.l2update","data":{"changes":{"asks":[["65148.1","0","34557197735"]],"bids":[]},"sequenceEnd":34557197735,"sequenceStart":34557197735,"symbol":"BTC-USDT","time":1784133307070}}
{"topic":"/market/level2:BTC-USDT","type":"message","subject":"trade.l2update","data":{"changes":{"asks":[["64973.8","0.46007898","34557197736"]],"bids":[]},"sequenceEnd":34557197736,"sequenceStart":34557197736,"symbol":"BTC-USDT","time":1784133307072}}
{"topic":"/market/level2:BTC-USDT","type":"message","subject":"trade.l2update","data":{"changes":{"asks":[["64972.3","0.083854","34557197737"]],"bids":[]},"sequenceEnd":34557197737,"sequenceStart":34557197737,"symbol":"BTC-USDT","time":1784133307072}}
{"topic":"/market/level2:BTC-USDT","type":"message","subject":"trade.l2update","data":{"changes":{"asks":[["64973.7","0.04810881","34557197738"]],"bids":[]},"sequenceEnd":34557197738,"sequenceStart":34557197738,"symbol":"BTC-USDT","time":1784133307072}}
{"topic":"/market/level2:BTC-USDT","type":"message","subject":"trade.l2update","data":{"changes":{"asks":[["64972.3","0.15318794","34557197739"]],"bids":[]},"sequenceEnd":34557197739,"sequenceStart":34557197739,"symbol":"BTC-USDT","time":1784133307072}}
{"topic":"/market/level2:BTC-USDT","type":"message","subject":"trade.l2update","data":{"changes":{"asks":[],"bids":[["64954.2","0","34557197740"]]},"sequenceEnd":34557197740,"sequenceStart":34557197740,"symbol":"BTC-USDT","time":1784133307072}}
{"topic":"/market/level2:BTC-USDT","type":"message","subject":"trade.l2update","data":{"changes":{"asks":[],"bids":[["64954.7","0.01540408","34557197741"]]},"sequenceEnd":34557197741,"sequenceStart":34557197741,"symbol":"BTC-USDT","time":1784133307072}}
{"topic":"/market/level2:BTC-USDT","type":"message","subject":"trade.l2update","data":{"changes":{"asks":[["64973.8","0.45432196","34557197742"]],"bids":[]},"sequenceEnd":34557197742,"sequenceStart":34557197742,"symbol":"BTC-USDT","time":1784133307072}}
{"topic":"/market/level2:BTC-USDT","type":"message","subject":"trade.l2update","data":{"changes":{"asks":[["64973.8","0.45214549","34557197743"]],"bids":[]},"sequenceEnd":34557197743,"sequenceStart":34557197743,"symbol":"BTC-USDT","time":1784133307073}}
{"topic":"/market/level2:BTC-USDT","type":"message","subject":"trade.l2update","data":{"changes":{"asks":[["64972.3","0.25668794","34557197744"],["64973.8","0.43472642","34557197746"]],"bids":[["64972.2","0.12809976","34557197745"]]},"sequenceEnd":34557197746,"sequenceStart":34557197744,"symbol":"BTC-USDT","time":1784133307073}}
{"topic":"/market/level2:BTC-USDT","type":"message","subject":"trade.l2update","data":{"changes":{"asks":[["64972.3","0.28783204","34557197748"],["64973.8","0.40358232","34557197747"]],"bids":[]},"sequenceEnd":34557197748,"sequenceStart":34557197747,"symbol":"BTC-USDT","time":1784133307073}}
{"topic":"/market/level2:BTC-USDT","type":"message","subject":"trade.l2update","data":{"changes":{"asks":[],"bids":[["64972.2","0.11914115","34557197750"]]},"sequenceEnd":34557197750,"sequenceStart":34557197749,"symbol":"BTC-USDT","time":1784133307074}}
{"topic":"/market/level2:BTC-USDT","type":"message","subject":"trade.l2update","data":{"changes":{"asks":[["64973.8","0.30008232","34557197751"]],"bids":[["64954.7","0","34557197753"],["64967.2","0","34557197752"]]},"sequenceEnd":34557197753,"sequenceStart":34557197751,"symbol":"BTC-USDT","time":1784133307074}}
{"topic":"/market/level2:BTC-USDT","type":"message","subject":"trade.l2update","data":{"changes":{"asks":[["64973.7","0","34557197754"]],"bids":[]},"sequenceEnd":34557197754,"sequenceStart":34557197754,"symbol":"BTC-USDT","time":1784133307075}}
{"topic":"/market/level2:BTC-USDT","type":"message","subject":"trade.l2update","data":{"changes":{"asks":[["64993.5","0.09100513","34557197755"]],"bids":[]},"sequenceEnd":34557197755,"sequenceStart":34557197755,"symbol":"BTC-USDT","time":1784133307075}}
{"topic":"/market/level2:BTC-USDT","type":"message","subject":"trade.l2update","data":{"changes":{"asks":[["64976.3","0","34557197756"]],"bids":[]},"sequenceEnd":34557197756,"sequenceStart":34557197756,"symbol":"BTC-USDT","time":1784133307075}}
{"topic":"/market/level2:BTC-USDT","type":"message","subject":"trade.l2update","data":{"changes":{"asks":[],"bids":[["64971.3","0.01021232","34557197757"]]},"sequenceEnd":34557197757,"sequenceStart":34557197757,"symbol":"BTC-USDT","time":1784133307076}}
{"topic":"/market/match:BTC-USDT","type":"message","subject":"trade.l3match","data":{"makerOrderId":"6a57b6bad758b50007091f37","price":"64973.7","sequence":"23580481547943936","side":"sell","size":"0.003081","symbol":"BTC-USDT","takerOrderId":"6a57b6bb8da4f800076e7e12","time":"1784133307068000000","tradeId":"23580481547943936","type":"match"}}
{"topic":"/market/level2:BTC-USDT","type":"message","subject":"trade.l2update","data":{"changes":{"asks":[],"bids":[["64954.2","0.01540408","34557197758"]]},"sequenceEnd":34557197758,"sequenceStart":34557197758,"symbol":"BTC-USDT","time":1784133307076}}
{"topic":"/market/level2:BTC-USDT","type":"message","subject":"trade.l2update","data":{"changes":{"asks":[],"bids":[["64972.2","0.15650115","34557197759"]]},"sequenceEnd":34557197759,"sequenceStart":34557197759,"symbol":"BTC-USDT","time":1784133307076}}
{"topic":"/market/level2:BTC-USDT","type":"message","subject":"trade.l2update","data":{"changes":{"asks":[["64994","0.37742931","34557197760"]],"bids":[]},"sequenceEnd":34557197760,"sequenceStart":34557197760,"symbol":"BTC-USDT","time":1784133307077}}
{"topic":"/market/level2:BTC-USDT","type":"message","subject":"trade.l2update","data":{"changes":{"asks":[],"bids":[["1","13601.8854165","34557197761"]]},"sequenceEnd":34557197761,"sequenceStart":34557197761,"symbol":"BTC-USDT","time":1784133307077}}
{"topic":"/market/level2:BTC-USDT","type":"message","subject":"trade.l2update","data":{"changes":{"asks":[],"bids":[["64787.5","0.00154038","34557197763"],["64920.5","0.00154038","34557197762"]]},"sequenceEnd":34557197763,"sequenceStart":34557197762,"symbol":"BTC-USDT","time":1784133307077}}
{"topic":"/market/level2:BTC-USDT","type":"message","subject":"trade.l2update","data":{"changes":{"asks":[["64973.8","0.12007292","34557197767"]],"bids":[["64906.9","0.2","34557197765"],["64972.2","0.19188386","34557197766"]]},"sequenceEnd":34557197767,"sequenceStart":34557197764,"symbol":"BTC-USDT","time":1784133307078}}
{"topic":"/market/level2:BTC-USDT","type":"message","subject":"trade.l2update","data":{"changes":{"asks":[["64972.3","0.46784144","34557197768"],["65204.9","0.00099002","34557197769"]],"bids":[]},"sequenceEnd":34557197769,"sequenceStart":34557197768,"symbol":"BTC-USDT","time":1784133307078}}
{"topic":"/market/level2:BTC-USDT","type":"message","subject":"trade.l2update","data":{"changes":{"asks":[["64975","0.05146347","34557197770"]],"bids":[]},"sequenceEnd":34557197770,"sequenceStart":34557197770,"symbol":"BTC-USDT","time":1784133307078}}
{"topic":"/market/level2:BTC-USDT","type":"message","subject":"trade.l2update","data":{"changes":{"asks":[["65201.1","0.00179787","34557197771"]],"bids":[]},"sequenceEnd":34557197771,"sequenceStart":34557197771,"symbol":"BTC-USDT","time":1784133307078}}
{"topic":"/market/level2:BTC-USDT","type":"message","subject":"trade.l2update","data":{"changes":{"asks":[["64972.4","0.06043785","34557197772"]],"bids":[["64968.6","0.02540518","34557197773"]]},"sequenceEnd":34557197773,"sequenceStart":34557197772,"symbol":"BTC-USDT","time":1784133307078}}
{"topic":"/market/level2:BTC-USDT","type":"message","subject":"trade.l2update","data":{"changes":{"asks":[["64972.4","0.12125392","34557197774"]],"bids":[]},"sequenceEnd":34557197774,"sequenceStart":34557197774,"symbol":"BTC-USDT","time":1784133307078}}
{"topic":"/market/level2:BTC-USDT","type":"message","subject":"trade.l2update","data":{"changes":{"asks":[],"bids":[["64967.3","0","34557197775"]]},"sequenceEnd":34557197775,"sequenceStart":34557197775,"symbol":"BTC-USDT","time":1784133307079}}
{"topic":"/market/level2:BTC-USDT","type":"message","subject":"trade.l2update","data":{"changes":{"asks":[["64975.3","0.29706251","34557197776"]],"bids":[]},"sequenceEnd":34557197776,"sequenceStart":34557197776,"symbol":"BTC-USDT","time":1784133307080}}
{"topic":"/market/level2:BTC-USDT","type":"message","subject":"trade.l2update","data":{"changes":{"asks":[["64975.2","0.00940104","34557197777"]],"bids":[]},"sequenceEnd":34557197777,"sequenceStart":34557197777,"symbol":"BTC-USDT","time":1784133307082}}
{"topic":"/market/level2:BTC-USDT","type":"message","subject":"trade.l2update","data":{"changes":{"asks":[["64975","0","34557197778"]],"bids":[]},"sequenceEnd":34557197778,"sequenceStart":34557197778,"symbol":"BTC-USDT","time":1784133307083}}
{"topic":"/market/level2:BTC-USDT","type":"message","subject":"trade.l2update","data":{"changes":{"asks":[],"bids":[["64920.5","0","34557197779"]]},"sequenceEnd":34557197779,"sequenceStart":34557197779,"symbol":"BTC-USDT","time":1784133307083}}
{"topic":"/market/level2:BTC-USDT","type":"message","subject":"trade.l2update","data":{"changes":{"asks":[["65207.1","0","34557197782"]],"bids":[["64917.4","0.00166137","34557197780"],["64968.6","0","34557197781"]]},"sequenceEnd":34557197782,"sequenceStart":34557197780,"symbol":"BTC-USDT","time":1784133307083}}
{"topic":"/market/level2:BTC-USDT","type":"message","subject":"trade.l2update","data":{"changes":{"asks":[["64994","0","34557197783"]],"bids":[]},"sequenceEnd":34557197783,"sequenceStart":34557197783,"symbol":"BTC-USDT","time":1784133307084}}
{"topic":"/market/level2:BTC-USDT","type":"message","subject":"trade.l2update","data":{"changes":{"asks":[["64996.2","0.37742836","34557197784"]],"bids":[]},"sequenceEnd":34557197784,"sequenceStart":34557197784,"symbol":"BTC-USDT","time":1784133307084}}
{"topic":"/market/level2:BTC-USDT","type":"message","subject":"trade.l2update","data":{"changes":{"asks":[],"bids":[["64787.5","0.00308076","34557197785"]]},"sequenceEnd":34557197785,"sequenceStart":34557197785,"symbol":"BTC-USDT","time":1784133307084}}
{"topic":"/market/level2:BTC-USDT","type":"message","subject":"trade.l2update","data":{"changes":{"asks":[["64975.3","0.25100265","34557197786"]],"bids":[]},"sequenceEnd":34557197786,"sequenceStart":34557197786,"symbol":"BTC-USDT","time":1784133307084}}
{"topic":"/market/level2:BTC-USDT","type":"message","subject":"trade.l2update","data":{"changes":{"asks":[["64972.4","0.06043785","34557197787"]],"bids":[]},"sequenceEnd":34557197787,"sequenceStart":34557197787,"symbol":"BTC-USDT","time":1784133307085}}
{"topic":"/market/level2:BTC-USDT","type":"message","subject":"trade.l2update","data":{"changes":{"asks":[],"bids":[["64791.1","0.00154039","34557197788"]]},"sequenceEnd":34557197788,"sequenceStart":34557197788,"symbol":"BTC-USDT","time":1784133307086}}
{"topic":"/market/level2:BTC-USDT","type":"message","subject":"trade.l2update","data":{"changes":{"asks":[],"bids":[["64920.5","0.00154039","34557197789"]]},"sequenceEnd":34557197789,"sequenceStart":34557197789,"symbol":"BTC-USDT","time":1784133307086}}
{"topic":"/market/level2:BTC-USDT","type":"message","subject":"trade.l2update","data":{"changes":{"asks":[["65027.3","0","34557197790"]],"bids":[]},"sequenceEnd":34557197790,"sequenceStart":34557197790,"symbol":"BTC-USDT","time":1784133307086}}
{"topic":"/market/level2:BTC-USDT","type":"message","subject":"trade.l2update","data":{"changes":{"asks":[["65024","0.00154038","34557197792"]],"bids":[["64919.8","0.00154038","34557197793"],["64920.5","0","34557197791"]]},"sequenceEnd":34557197793,"sequenceStart":34557197791,"symbol":"BTC-USDT","time":1784133307086}}
{"topic":"/market/level2:BTC-USDT","type":"message","subject":"trade.l2update","data":{"changes":{"asks":[],"bids":[["64972.2","0.20676227","34557197794"]]},"sequenceEnd":34557197794,"sequenceStart":34557197794,"symbol":"BTC-USDT","time":1784133307087}}
{"topic":"/market/level2:BTC-USDT","type":"message","subject":"trade.l2update","data":{"changes":{"asks":[["64972.3","0.54631935","34557197795"]],"bids":[]},"sequenceEnd":34557197795,"sequenceStart":34557197795,"symbol":"BTC-USDT","time":1784133307087}}
{"topic":"/market/level2:BTC-USDT","type":"message","subject":"trade.l2update","data":{"changes":{"asks":[],"bids":[["64791.1","0","34557197796"]]},"sequenceEnd":34557197796,"sequenceStart":34557197796,"symbol":"BTC-USDT","time":1784133307089}}
{"topic":"/market/level2:BTC-USDT","type":"message","subject":"trade.l2update","data":{"changes":{"asks":[["64972.4","0","34557197797"]],"bids":[]},"sequenceEnd":34557197797,"sequenceStart":34557197797,"symbol":"BTC-USDT","time":1784133307089}}
{"topic":"/market/level2:BTC-USDT","type":"message","subject":"trade.l2update","data":{"changes":{"asks":[["64975.3","0.20522371","34557197798"]],"bids":[]},"sequenceEnd":34557197798,"sequenceStart":34557197798,"symbol":"BTC-USDT","time":1784133307089}}
{"topic":"/market/level2:BTC-USDT","type":"message","subject":"trade.l2update","data":{"changes":{"asks":[["64972.3","0.59238128","34557197799"],["64973.8","0.11699192","34557197800"]],"bids":[]},"sequenceEnd":34557197800,"sequenceStart":34557197799,"symbol":"BTC-USDT","time":1784133307091}}
{"topic":"/market/level2:BTC-USDT","type":"message","subject":"trade.l2update","data":{"changes":{"asks":[["64973.8","0.12007297","34557197801"]],"bids":[]},"sequenceEnd":34557197801,"sequenceStart":34557197801,"symbol":"BTC-USDT","time":1784133307091}}
{"topic":"/market/level2:BTC-USDT","type":"message","subject":"trade.l2update","data":{"changes":{"asks":[["64973.8","0.11699192","34557197802"]],"bids":[]},"sequenceEnd":34557197802,"sequenceStart":34557197802,"symbol":"BTC-USDT","time":1784133307091}}
{"topic":"/market/level2:BTC-USDT","type":"message","subject":"trade.l2update","data":{"changes":{"asks":[["65505","0","34557197803"]],"bids":[]},"sequenceEnd":34557197803,"sequenceStart":34557197803,"symbol":"BTC-USDT","time":1784133307100}}
{"topic":"/market/level2:BTC-USDT","type":"message","subject":"trade.l2update","data":{"changes":{"asks":[],"bids":[["1","13601.7854165","34557197804"],["64787.6","0.00158483","34557197805"]]},"sequenceEnd":34557197805,"sequenceStart":34557197804,"symbol":"BTC-USDT","time":1784133307113}}
{"topic":"/market/level2:BTC-USDT","type":"message","subject":"trade.l2update","data":{"changes":{"asks":[["65013.2","0.00385107","34557197806"]],"bids":[]},"sequenceEnd":34557197806,"sequenceStart":34557197806,"symbol":"BTC-USDT","time":1784133307120}}
{"topic":"/market/level2:BTC-USDT","type":"message","subject":"trade.l2update","data":{"changes":{"asks":[["65148.1","0.00385107","34557197807"]],"bids":[]},"sequenceEnd":34557197807,"sequenceStart":34557197807,"symbol":"BTC-USDT","time":1784133307120}}
{"topic":"/market/level2:BTC-USDT","type":"message","subject":"trade.l2update","data":{"changes":{"asks":[],"bids":[["64966","0","34557197808"]]},"sequenceEnd":34557197808,"sequenceStart":34557197808,"symbol":"BTC-USDT","time":1784133307122}}
{"topic":"/market/level2:BTC-USDT","type":"message","subject":"trade.l2update","data":{"changes":{"asks":[],"bids":[["1","13601.8854165","34557197809"]]},"sequenceEnd":34557197809,"sequenceStart":34557197809,"symbol":"BTC-USDT","time":1784133307129}}
{"topic":"/market/level2:BTC-USDT","type":"message","subject":"trade.l2update","data":{"changes":{"asks":[],"bids":[["64954.2","0","34557197810"]]},"sequenceEnd":34557197810,"sequenceStart":34557197810,"symbol":"BTC-USDT","time":1784133307130}}
{"topic":"/market/level2:BTC-USDT","type":"message","subject":"trade.l2update","data":{"changes":{"asks":[],"bids":[["1","13601.7854165","34557197811"],["64955.4","0.10753955","34557197812"]]},"sequenceEnd":34557197812,"sequenceStart":34557197811,"symbol":"BTC-USDT","time":1784133307130}}
{"topic":"/market/level2:BTC-USDT","type":"message","subject":"trade.l2update","data":{"changes":{"asks":[],"bids":[["64955.4","0.0921354","34557197813"]]},"sequenceEnd":34557197813,"sequenceStart":34557197813,"symbol":"BTC-USDT","time":1784133307131}}
{"topic":"/market/level2:BTC-USDT","type":"message","subject":"trade.l2update","data":{"changes":{"asks":[],"bids":[["64954.7","0.01540415","34557197814"]]},"sequenceEnd":34557197814,"sequenceStart":34557197814,"symbol":"BTC-USDT","time":1784133307133}}
{"topic":"/market/level2:BTC-USDT","type":"message","subject":"trade.l2update","data":{"changes":{"asks":[["65198.7","0","34557197815"]],"bids":[]},"sequenceEnd":34557197815,"sequenceStart":34557197815,"symbol":"BTC-USDT","time":1784133307154}}
{"topic":"/market/level2:BTC-USDT","type":"message","subject":"trade.l2update","data":{"changes":{"asks":[["65210.9","0","34557197816"]],"bids":[]},"sequenceEnd":34557197816,"sequenceStart":34557197816,"symbol":"BTC-USDT","time":1784133307155}}
{"topic":"/market/level2:BTC-USDT","type":"message","subject":"trade.l2update","data":{"changes":{"asks":[],"bids":[["64954.7","0","34557197817"]]},"sequenceEnd":34557197817,"sequenceStart":34557197817,"symbol":"BTC-USDT","time":1784133307165}}
{"topic":"/market/level2:BTC-USDT","type":"message","subject":"trade.l2update","data":{"changes":{"asks":[],"bids":[["64955.4","0.10753948","34557197818"]]},"sequenceEnd":34557197818,"sequenceStart":34557197818,"symbol":"BTC-USDT","time":1784133307165}}
{"topic":"/market/level2:BTC-USDT","type":"message","subject":"trade.l2update","data":{"changes":{"asks":[["64978.9","0","34557197819"]],"bids":[]},"sequenceEnd":34557197819,"sequenceStart":34557197819,"symbol":"BTC-USDT","time":1784133307173}}
{"topic":"/market/level2:BTC-USDT","type":"message","subject":"trade.l2update","data":{"changes":{"asks":[["64979.7","0.01540408","34557197820"]],"bids":[]},"sequenceEnd":34557197820,"sequenceStart":34557197820,"symbol":"BTC-USDT","time":1784133307173}}
{"topic":"/market/level2:BTC-USDT","type":"message","subject":"trade.l2update","data":{"changes":{"asks":[],"bids":[["1","13601.7854165","34557197822"]]},"sequenceEnd":34557197822,"sequenceStart":34557197821,"symbol":"BTC-USDT","time":1784133307180}}
{"topic":"/market/level2:BTC-USDT","type":"message","subject":"trade.l2update","data":{"changes":{"asks":[],"bids":[["0.1","353051.72608864","34557197823"]]},"sequenceEnd":34557197823,"sequenceStart":34557197823,"symbol":"BTC-USDT","time":1784133307183}}
{"topic":"/market/level2:BTC-USDT","type":"message","subject":"trade.l2update","data":{"changes":{"asks":[],"bids":[["0.1","353050.72608864","34557197824"]]},"sequenceEnd":34557197824,"sequenceStart":34557197824,"symbol":"BTC-USDT","time":1784133307185}}
{"topic":"/market/level2:BTC-USDT","type":"message","subject":"trade.l2update","data":{"changes":{"asks":[],"bids":[["1","13600.7854165","34557197836"]]},"sequenceEnd":34557197836,"sequenceStart":34557197825,"symbol":"BTC-USDT","time":1784133307185}}
{"topic":"/market/level2:BTC-USDT","type":"message","subject":"trade.l2update","data":{"changes":{"asks":[],"bids":[["1","13601.0854165","34557197839"]]},"sequenceEnd":34557197839,"sequenceStart":34557197837,"symbol":"BTC-USDT","time":1784133307185}}
{"topic":"/market/level2:BTC-USDT","type":"message","subject":"trade.l2update","data":{"changes":{"asks":[],"bids":[["1","13601.2854165","34557197841"]]},"sequenceEnd":34557197841,"sequenceStart":34557197840,"symbol":"BTC-USDT","time":1784133307185}}
{"topic":"/market/level2:BTC-USDT","type":"message","subject":"trade.l2update","data":{"changes":{"asks":[],"bids":[["1","13601.3854165","34557197842"]]},"sequenceEnd":34557197842,"sequenceStart":34557197842,"symbol":"BTC-USDT","time":1784133307187}}
{"topic":"/market/level2:BTC-USDT","type":"message","subject":"trade.l2update","data":{"changes":{"asks":[],"bids":[["1","13601.4854165","34557197843"]]},"sequenceEnd":34557197843,"sequenceStart":34557197843,"symbol":"BTC-USDT","time":1784133307187}}
{"topic":"/market/level2:BTC-USDT","type":"message","subject":"trade.l2update","data":{"changes":{"asks":[],"bids":[["1","13601.5854165","34557197844"]]},"sequenceEnd":34557197844,"sequenceStart":34557197844,"symbol":"BTC-USDT","time":1784133307187}}
{"topic":"/market/level2:BTC-USDT","type":"message","subject":"trade.l2update","data":{"changes":{"asks":[],"bids":[["1","13601.7854165","34557197846"]]},"sequenceEnd":34557197846,"sequenceStart":34557197845,"symbol":"BTC-USDT","time":1784133307187}}
{"topic":"/market/level2:BTC-USDT","type":"message","subject":"trade.l2update","data":{"changes":{"asks":[],"bids":[["1","13601.5854165","34557197848"]]},"sequenceEnd":34557197848,"sequenceStart":34557197847,"symbol":"BTC-USDT","time":1784133307188}}
{"topic":"/market/level2:BTC-USDT","type":"message","subject":"trade.l2update","data":{"changes":{"asks":[],"bids":[["0.1","353051.72608864","34557197849"]]},"sequenceEnd":34557197849,"sequenceStart":34557197849,"symbol":"BTC-USDT","time":1784133307189}}
{"topic":"/market/level2:BTC-USDT","type":"message","subject":"trade.l2update","data":{"changes":{"asks":[],"bids":[["1","13601.6854165","34557197850"]]},"sequenceEnd":34557197850,"sequenceStart":34557197850,"symbol":"BTC-USDT","time":1784133307189}}
{"topic":"/market/level2:BTC-USDT","type":"message","subject":"trade.l2update","data":{"changes":{"asks":[],"bids":[["1","13601.7854165","34557197851"]]},"sequenceEnd":34557197851,"sequenceStart":34557197851,"symbol":"BTC-USDT","time":1784133307189}}
{"topic":"/market/level2:BTC-USDT","type":"message","subject":"trade.l2update","data":{"changes":{"asks":[],"bids":[["1","13601.5854165","34557197853"]]},"sequenceEnd":34557197853,"sequenceStart":34557197852,"symbol":"BTC-USDT","time":1784133307190}}
{"topic":"/market/level2:BTC-USDT","type":"message","subject":"trade.l2update","data":{"changes":{"asks":[],"bids":[["1","13601.6854165","34557197854"]]},"sequenceEnd":34557197854,"sequenceStart":34557197854,"symbol":"BTC-USDT","time":1784133307190}}
{"topic":"/market/level2:BTC-USDT","type":"message","subject":"trade.l2update","data":{"changes":{"asks":[],"bids":[["1","13601.7854165","34557197855"]]},"sequenceEnd":34557197855,"sequenceStart":34557197855,"symbol":"BTC-USDT","time":1784133307190}}
{"topic":"/market/level2:BTC-USDT","type":"message","subject":"trade.l2update","data":{"changes":{"asks":[],"bids":[["0.1","353050.72608864","34557197856"]]},"sequenceEnd":34557197856,"sequenceStart":34557197856,"symbol":"BTC-USDT","time":1784133307191}}
{"topic":"/market/level2:BTC-USDT","type":"message","subject":"trade.l2update","data":{"changes":{"asks":[],"bids":[["0.1","353051.72608864","34557197857"]]},"sequenceEnd":34557197857,"sequenceStart":34557197857,"symbol":"BTC-USDT","time":1784133307193}}
{"topic":"/market/level2:BTC-USDT","type":"message","subject":"trade.l2update","data":{"changes":{"asks":[],"bids":[["64972.2","0.20984328","34557197858"]]},"sequenceEnd":34557197858,"sequenceStart":34557197858,"symbol":"BTC-USDT","time":1784133307195}}
{"topic":"/market/level2:BTC-USDT","type":"message","subject":"trade.l2update","data":{"changes":{"asks":[["64972.3","0.59546229","34557197859"]],"bids":[]},"sequenceEnd":34557197859,"sequenceStart":34557197859,"symbol":"BTC-USDT","time":1784133307197}}
{"topic":"/market/level2:BTC-USDT","type":"message","subject":"trade.l2update","data":{"changes":{"asks":[],"bids":[["0.1","353050.72608864","34557197860"]]},"sequenceEnd":34557197860,"sequenceStart":34557197860,"symbol":"BTC-USDT","time":1784133307197}}
{"topic":"/market/level2:BTC-USDT","type":"message","subject":"trade.l2update","data":{"changes":{"asks":[],"bids":[["0.1","353051.72608864","34557197861"]]},"sequenceEnd":34557197861,"sequenceStart":34557197861,"symbol":"BTC-USDT","time":1784133307199}}
{"topic":"/market/level2:BTC-USDT","type":"message","subject":"trade.l2update","data":{"changes":{"asks":[],"bids":[["0.1","353050.72608864","34557197862"]]},"sequenceEnd":34557197862,"sequenceStart":34557197862,"symbol":"BTC-USDT","time":1784133307202}}
{"topic":"/market/level2:BTC-USDT","type":"message","subject":"trade.l2update","data":{"changes":{"asks":[],"bids":[["0.1","353051.72608864","34557197863"]]},"sequenceEnd":34557197863,"sequenceStart":34557197863,"symbol":"BTC-USDT","time":1784133307205}}
{"topic":"/market/level2:BTC-USDT","type":"message","subject":"trade.l2update","data":{"changes":{"asks":[],"bids":[["0.1","353050.72608864","34557197864"]]},"sequenceEnd":34557197864,"sequenceStart":34557197864,"symbol":"BTC-USDT","time":1784133307210}}
{"topic":"/market/level2:BTC-USDT","type":"message","subject":"trade.l2update","data":{"changes":{"asks":[],"bids":[["1","13601.4854165","34557197869"]]},"sequenceEnd":34557197869,"sequenceStart":34557197865,"symbol":"BTC-USDT","time":1784133307219}}
{"topic":"/market/level2:BTC-USDT","type":"message","subject":"trade.l2update","data":{"changes":{"asks":[],"bids":[["1","13601.5854165","34557197870"]]},"sequenceEnd":34557197870,"sequenceStart":34557197870,"symbol":"BTC-USDT","time":1784133307219}}
{"topic":"/market/level2:BTC-USDT","type":"message","subject":"trade.l2update","data":{"changes":{"asks":[],"bids":[["1","13601.6854165","34557197871"]]},"sequenceEnd":34557197871,"sequenceStart":34557197871,"symbol":"BTC-USDT","time":1784133307219}}
{"topic":"/market/level2:BTC-USDT","type":"message","subject":"trade.l2update","data":{"changes":{"asks":[],"bids":[["1","13601.7854165","34557197872"]]},"sequenceEnd":34557197872,"sequenceStart":34557197872,"symbol":"BTC-USDT","time":1784133307221}}
{"topic":"/market/level2:BTC-USDT","type":"message","subject":"trade.l2update","data":{"changes":{"asks":[],"bids":[["1","13601.8854165","34557197873"]]},"sequenceEnd":34557197873,"sequenceStart":34557197873,"symbol":"BTC-USDT","time":1784133307221}}
{"topic":"/market/level2:BTC-USDT","type":"message","subject":"trade.l2update","data":{"changes":{"asks":[],"bids":[["1","13601.9854165","34557197874"]]},"sequenceEnd":34557197874,"sequenceStart":34557197874,"symbol":"BTC-USDT","time":1784133307221}}
{"topic":"/market/level2:BTC-USDT","type":"message","subject":"trade.l2update","data":{"changes":{"asks":[],"bids":[["1","13602.0854165","34557197875"]]},"sequenceEnd":34557197875,"sequenceStart":34557197875,"symbol":"BTC-USDT","time":1784133307221}}
{"topic":"/market/level2:BTC-USDT","type":"message","subject":"trade.l2update","data":{"changes":{"asks":[],"bids":[["1","13601.6854165","34557197881"]]},"sequenceEnd":34557197881,"sequenceStart":34557197876,"symbol":"BTC-USDT","time":1784133307221}}
{"topic":"/market/level2:BTC-USDT","type":"message","subject":"trade.l2update","data":{"changes":{"asks":[],"bids":[["1","13601.7854165","34557197882"]]},"sequenceEnd":34557197882,"sequenceStart":34557197882,"symbol":"BTC-USDT","time":1784133307221}}
{"topic":"/market/level2:BTC-USDT","type":"message","subject":"trade.l2update","data":{"changes":{"asks":[],"bids":[["1","13601.3854165","34557197888"]]},"sequenceEnd":34557197888,"sequenceStart":34557197883,"symbol":"BTC-USDT","time":1784133307224}}
{"topic":"/market/level2:BTC-USDT","type":"message","subject":"trade.l2update","data":{"changes":{"asks":[],"bids":[["1","13601.4854165","34557197889"]]},"sequenceEnd":34557197889,"sequenceStart":34557197889,"symbol":"BTC-USDT","time":1784133307224}}
{"topic":"/market/level2:BTC-USDT","type":"message","subject":"trade.l2update","data":{"changes":{"asks":[],"bids":[["1","13601.5854165","34557197890"]]},"sequenceEnd":34557197890,"sequenceStart":34557197890,"symbol":"BTC-USDT","time":1784133307224}}
{"topic":"/market/level2:BTC-USDT","type":"message","subject":"trade.l2update","data":{"changes":{"asks":[],"bids":[["1","13601.6854165","34557197891"]]},"sequenceEnd":34557197891,"sequenceStart":34557197891,"symbol":"BTC-USDT","time":1784133307225}}
{"topic":"/market/level2:BTC-USDT","type":"message","subject":"trade.l2update","data":{"changes":{"asks":[],"bids":[["1","13601.7854165","34557197892"]]},"sequenceEnd":34557197892,"sequenceStart":34557197892,"symbol":"BTC-USDT","time":1784133307226}}
{"topic":"/market/level2:BTC-USDT","type":"message","subject":"trade.l2update","data":{"changes":{"asks":[],"bids":[["100","48.83289347","34557197893"]]},"sequenceEnd":34557197893,"sequenceStart":34557197893,"symbol":"BTC-USDT","time":1784133307232}}
{"topic":"/market/level2:BTC-USDT","type":"message","subject":"trade.l2update","data":{"changes":{"asks":[],"bids":[["100","48.83179347","34557197894"]]},"sequenceEnd":34557197894,"sequenceStart":34557197894,"symbol":"BTC-USDT","time":1784133307234}}
{"topic":"/market/level2:BTC-USDT","type":"message","subject":"trade.l2update","data":{"changes":{"asks":[["64972.3","0.60121556","34557197895"]],"bids":[]},"sequenceEnd":34557197895,"sequenceStart":34557197895,"symbol":"BTC-USDT","time":1784133307236}}
{"topic":"/market/level2:BTC-USDT","type":"message","subject":"trade.l2update","data":{"changes":{"asks":[],"bids":[["64947.2","0","34557197897"],["64972.2","0.17248328","34557197896"]]},"sequenceEnd":34557197897,"sequenceStart":34557197896,"symbol":"BTC-USDT","time":1784133307240}}
{"topic":"/market/level2:BTC-USDT","type":"message","subject":"trade.l2update","data":{"changes":{"asks":[],"bids":[["64972.2","0.15760487","34557197898"]]},"sequenceEnd":34557197898,"sequenceStart":34557197898,"symbol":"BTC-USDT","time":1784133307240}}
{"topic":"/market/level2:BTC-USDT","type":"message","subject":"trade.l2update","data":{"changes":{"asks":[],"bids":[["64787.6","0","34557197901"],["64972.2","0.05102386","34557197900"]]},"sequenceEnd":34557197901,"sequenceStart":34557197899,"symbol":"BTC-USDT","time":1784133307241}}
{"topic":"/market/level2:BTC-USDT","type":"message","subject":"trade.l2update","data":{"changes":{"asks":[],"bids":[["64971.3","0","34557197906"],["64972.1","0","34557197905"],["64972.2","0","34557197904"]]},"sequenceEnd":34557197906,"sequenceStart":34557197902,"symbol":"BTC-USDT","time":1784133307243}}
{"topic":"/market/level2:BTC-USDT","type":"message","subject":"trade.l2update","data":{"changes":{"asks":[],"bids":[["64963.1","0","34557197907"]]},"sequenceEnd":34557197907,"sequenceStart":34557197907,"symbol":"BTC-USDT","time":1784133307244}}
{"topic":"/market/level2:BTC-USDT","type":"message","subject":"trade.l2update","data":{"changes":{"asks":[["64972.2","0.04796479","34557197908"]],"bids":[]},"sequenceEnd":34557197908,"sequenceStart":34557197908,"symbol":"BTC-USDT","time":1784133307245}}
{"topic":"/market/level2:BTC-USDT","type":"message","subject":"trade.l2update","data":{"changes":{"asks":[["64972.2","0.18806498","34557197910"]],"bids":[["64956.4","0.05098271","34557197911"]]},"sequenceEnd":34557197911,"sequenceStart":34557197909,"symbol":"BTC-USDT","time":1784133307245}}
{"topic":"/market/level2:BTC-USDT","type":"message","subject":"trade.l2update","data":{"changes":{"asks":[],"bids":[["64971.2","0","34557197912"]]},"sequenceEnd":34557197912,"sequenceStart":34557197912,"symbol":"BTC-USDT","time":1784133307246}}
{"topic":"/market/level2:BTC-USDT","type":"message","subject":"trade.l2update","data":{"changes":{"asks":[["64971.5","0.01741808","34557197915"],["64972.2","0.22138558","34557197914"]],"bids":[]},"sequenceEnd":34557197915,"sequenceStart":34557197913,"symbol":"BTC-USDT","time":1784133307246}}
{"topic":"/market/level2:BTC-USDT","type":"message","subject":"trade.l2update","data":{"changes":{"asks":[["64972.2","0.23880465","34557197916"]],"bids":[]},"sequenceEnd":34557197916,"sequenceStart":34557197916,"symbol":"BTC-USDT","time":1784133307246}}
{"topic":"/market/level2:BTC-USDT","type":"message","subject":"trade.l2update","data":{"changes":{"asks":[],"bids":[["64969.4","0.05100121","34557197917"]]},"sequenceEnd":34557197917,"sequenceStart":34557197917,"symbol":"BTC-USDT","time":1784133307246}}
{"topic":"/market/level2:BTC-USDT","type":"message","subject":"trade.l2update","data":{"changes":{"asks":[["64972.3","0.57007146","34557197918"],["64992","0.37744154","34557197920"],["64996.2","0","34557197919"]],"bids":[]},"sequenceEnd":34557197920,"sequenceStart":34557197918,"symbol":"BTC-USDT","time":1784133307246}}
{"topic":"/market/level2:BTC-USDT","type":"message","subject":"trade.l2update","data":{"changes":{"asks":[["64971.5","0.13394287","34557197923"],["64972.3","0.50151146","34557197921"]],"bids":[]},"sequenceEnd":34557197923,"sequenceStart":34557197921,"symbol":"BTC-USDT","time":1784133307246}}
{"topic":"/market/level2:BTC-USDT","type":"message","subject":"trade.l2update","data":{"changes":{"asks":[["64971.4","0.00000001","34557197925"]],"bids":[["64971.4","0","34557197924"]]},"sequenceEnd":34557197925,"sequenceStart":34557197924,"symbol":"BTC-USDT","time":1784133307246}}
{"topic":"/market/level2:BTC-USDT","type":"message","subject":"trade.l2update","data":{"changes":{"asks":[["64971.4","0.07194721","34557197929"],["64971.5","0.18190766","34557197926"]],"bids":[]},"sequenceEnd":34557197929,"sequenceStart":34557197926,"symbol":"BTC-USDT","time":1784133307247}}
{"topic":"/market/level2:BTC-USDT","type":"message","subject":"trade.l2update","data":{"changes":{"asks":[["64972.3","0.49575819","34557197930"]],"bids":[]},"sequenceEnd":34557197930,"sequenceStart":34557197930,"symbol":"BTC-USDT","time":1784133307247}}
{"topic":"/market/level2:BTC-USDT","type":"message","subject":"trade.l2update","data":{"changes":{"asks":[["64971.5","0.28540766","34557197931"]],"bids":[]},"sequenceEnd":34557197931,"sequenceStart":34557197931,"symbol":"BTC-USDT","time":1784133307247}}
{"topic":"/market/level2:BTC-USDT","type":"message","subject":"trade.l2update","data":{"changes":{"asks":[["64971.5","0.28758314","34557197932"]],"bids":[]},"sequenceEnd":34557197932,"sequenceStart":34557197932,"symbol":"BTC-USDT","time":1784133307247}}
{"topic":"/market/level2:BTC-USDT","type":"message","subject":"trade.l2update","data":{"changes":{"asks":[],"bids":[["64959.6","0","34557197935"],["64959.8","0","34557197934"],["64965.7","0.1035","34557197933"]]},"sequenceEnd":34557197935,"sequenceStart":34557197933,"symbol":"BTC-USDT","time":1784133307247}}
{"topic":"/market/level2:BTC-USDT","type":"message","subject":"trade.l2update","data":{"changes":{"asks":[],"bids":[["64911.9","0.0921354","34557197936"]]},"sequenceEnd":34557197936,"sequenceStart":34557197936,"symbol":"BTC-USDT","time":1784133307247}}
{"topic":"/market/level2:BTC-USDT","type":"message","subject":"trade.l2update","data":{"changes":{"asks":[["64977.7","0.04471318","34557197938"]],"bids":[["64907","0.0921354","34557197937"]]},"sequenceEnd":34557197938,"sequenceStart":34557197937,"symbol":"BTC-USDT","time":1784133307247}}
{"topic":"/market/level2:BTC-USDT","type":"message","subject":"trade.l2update","data":{"changes":{"asks":[],"bids":[["64923.2","0","34557197939"]]},"sequenceEnd":34557197939,"sequenceStart":34557197939,"symbol":"BTC-USDT","time":1784133307248}}
{"topic":"/market/level2:BTC-USDT","type":"message","subject":"trade.l2update","data":{"changes":{"asks":[["64972.3","0.42642425","34557197940"]],"bids":[]},"sequenceEnd":34557197940,"sequenceStart":34557197940,"symbol":"BTC-USDT","time":1784133307248}}
{"topic":"/market/level2:BTC-USDT","type":"message","subject":"trade.l2update","data":{"changes":{"asks":[],"bids":[["64949.2","0.00944942","34557197941"]]},"sequenceEnd":34557197941,"sequenceStart":34557197941,"symbol":"BTC-USDT","time":1784133307248}}
{"topic":"/market/level2:BTC-USDT","type":"message","subject":"trade.l2update","data":{"changes":{"asks":[],"bids":[["64942","0.01156037","34557197942"]]},"sequenceEnd":34557197942,"sequenceStart":34557197942,"symbol":"BTC-USDT","time":1784133307248}}
{"topic":"/market/level2:BTC-USDT","type":"message","subject":"trade.l2update","data":{"changes":{"asks":[],"bids":[["64955.4","0.01540408","34557197943"]]},"sequenceEnd":34557197943,"sequenceStart":34557197943,"symbol":"BTC-USDT","time":1784133307249}}
{"topic":"/market/level2:BTC-USDT","type":"message","subject":"trade.l2update","data":{"changes":{"asks":[],"bids":[["64952.9","0","34557197944"]]},"sequenceEnd":34557197944,"sequenceStart":34557197944,"symbol":"BTC-USDT","time":1784133307249}}
{"topic":"/market/level2:BTC-USDT","type":"message","subject":"trade.l2update","data":{"changes":{"asks":[],"bids":[["64947.6","0","34557197945"]]},"sequenceEnd":34557197945,"sequenceStart":34557197945,"symbol":"BTC-USDT","time":1784133307249}}
{"topic":"/market/level2:BTC-USDT","type":"message","subject":"trade.l2update","data":{"changes":{"asks":[],"bids":[["64899.2","0.09229148","34557197948"],["64939.4","0","34557197949"],["64939.8","0","34557197947"],["64946.4","0","34557197946"]]},"sequenceEnd":34557197949,"sequenceStart":34557197946,"symbol":"BTC-USDT","time":1784133307249}}
{"topic":"/market/level2:BTC-USDT","type":"message","subject":"trade.l2update","data":{"changes":{"asks":[["64972.3","0.34794634","34557197951"]],"bids":[["64891.4","0.0921354","34557197950"]]},"sequenceEnd":34557197951,"sequenceStart":34557197950,"symbol":"BTC-USDT","time":1784133307249}}
{"topic":"/market/level2:BTC-USDT","type":"message","subject":"trade.l2update","data":{"changes":{"asks":[["64971.5","0.39108519","34557197953"]],"bids":[["64906.9","0","34557197952"]]},"sequenceEnd":34557197953,"sequenceStart":34557197952,"symbol":"BTC-USDT","time":1784133307249}}
{"topic":"/market/level2:BTC-USDT","type":"message","subject":"trade.l2update","data":{"changes":{"asks":[["64971.3","0.01537323","34557197954"],["64972.2","0.21920908","34557197961"],["64972.3","0.24444634","34557197958"],["64977.7","0.06454408","34557197955"],["64987.2","0.01527783","34557197959"]],"bids":[["64945.9","0","34557197956"],["64955.3","0","34557197957"],["64969.4","0","34557197962"]]},"sequenceEnd":34557197962,"sequenceStart":34557197954,"symbol":"BTC-USDT","time":1784133307249}}
{"topic":"/market/level2:BTC-USDT","type":"message","subject":"trade.l2update","data":{"changes":{"asks":[],"bids":[["64949.2","0","34557197963"],["64955.4","0","34557197964"]]},"sequenceEnd":34557197964,"sequenceStart":34557197963,"symbol":"BTC-USDT","time":1784133307249}}
{"topic":"/market/level2:BTC-USDT","type":"message","subject":"trade.l2update","data":{"changes":{"asks":[["64972.3","0.19838441","34557197966"]],"bids":[["64873.2","0.1035","34557197965"]]},"sequenceEnd":34557197966,"sequenceStart":34557197965,"symbol":"BTC-USDT","time":1784133307249}}
{"topic":"/market/level2:BTC-USDT","type":"message","subject":"trade.l2update","data":{"changes":{"asks":[],"bids":[["64944.6","0","34557197967"]]},"sequenceEnd":34557197967,"sequenceStart":34557197967,"symbol":"BTC-USDT","time":1784133307250}}
{"topic":"/market/level2:BTC-USDT","type":"message","subject":"trade.l2update","data":{"changes":{"asks":[],"bids":[["64937.5","0.01154","34557197968"]]},"sequenceEnd":34557197968,"sequenceStart":34557197968,"symbol":"BTC-USDT","time":1784133307250}}
{"topic":"/market/level2:BTC-USDT","type":"message","subject":"trade.l2update","data":{"changes":{"asks":[["64969.5","0.06856","34557197970"]],"bids":[["64915.6","0.04615","34557197969"]]},"sequenceEnd":34557197970,"sequenceStart":34557197969,"symbol":"BTC-USDT","time":1784133307250}}
{"topic":"/market/level2:BTC-USDT","type":"message","subject":"trade.l2update","data":{"changes":{"asks":[["64971.5","0.32252519","34557197971"]],"bids":[]},"sequenceEnd":34557197971,"sequenceStart":34557197971,"symbol":"BTC-USDT","time":1784133307250}}
{"topic":"/market/level2:BTC-USDT","type":"message","subject":"trade.l2update","data":{"changes":{"asks":[["64996.3","0","34557197972"],["65012.3","0","34557197973"]],"bids":[]},"sequenceEnd":34557197973,"sequenceStart":34557197972,"symbol":"BTC-USDT","time":1784133307250}}
{"topic":"/market/level2:BTC-USDT","type":"message","subject":"trade.l2update","data":{"changes":{"asks":[["64969.5","0.17206","34557197978"],["64971.5","0.32034971","34557197976"],["64972.2","0.18806498","34557197975"]],"bids":[["64914.2","0.20521107","34557197974"],["64965.7","0","34557197977"]]},"sequenceEnd":34557197978,"sequenceStart":34557197974,"symbol":"BTC-USDT","time":1784133307250}}
{"topic":"/market/level2:BTC-USDT","type":"message","subject":"trade.l2update","data":{"changes":{"asks":[["64969.5","0.23097129","34557197983"],["64971.4","0.07429078","34557197989"],["64971.5","0.20700205","34557197987"],["64972.2","0.0921354","34557197984"],["64992","0","34557197985"]],"bids":[["64787.5","0.00154038","34557197988"],["64865.5","0","34557197986"],["64917.4","0.00012099","34557197990"]]},"sequenceEnd":34557197990,"sequenceStart":34557197979,"symbol":"BTC-USDT","time":1784133307251}}
{"topic":"/market/level2:BTC-USDT","type":"message","subject":"trade.l2update","data":{"changes":{"asks":[],"bids":[["64915.6","0","34557197991"],["64930.8","0.01155","34557197994"],["64931.1","0.01155","34557197993"],["64942","0.00002037","34557197992"]]},"sequenceEnd":34557197994,"sequenceStart":34557197991,"symbol":"BTC-USDT","time":1784133307252}}
{"topic":"/market/level2:BTC-USDT","type":"message","subject":"trade.l2update","data":{"changes":{"asks":[],"bids":[["64919.8","0","34557197995"]]},"sequenceEnd":34557197995,"sequenceStart":34557197995,"symbol":"BTC-USDT","time":1784133307252}}
{"topic":"/market/level2:BTC-USDT","type":"message","subject":"trade.l2update","data":{"changes":{"asks":[],"bids":[["64787.5","0","34557197996"]]},"sequenceEnd":34557197996,"sequenceStart":34557197996,"symbol":"BTC-USDT","time":1784133307252}}
{"topic":"/market/level2:BTC-USDT","type":"message","subject":"trade.l2update","data":{"changes":{"asks":[["64971.5","0.1035","34557197999"],["64972.3","0.21821531","34557197998"]],"bids":[["64967","0","34557197997"]]},"sequenceEnd":34557197999,"sequenceStart":34557197997,"symbol":"BTC-USDT","time":1784133307252}}
{"topic":"/market/level2:BTC-USDT","type":"message","subject":"trade.l2update","data":{"changes":{"asks":[["64971.4","0.07429077","34557198001"]],"bids":[["64959.9","0","34557198000"]]},"sequenceEnd":34557198001,"sequenceStart":34557198000,"symbol":"BTC-USDT","time":1784133307252}}
{"topic":"/market/level2:BTC-USDT","type":"message","subject":"trade.l2update","data":{"changes":{"asks":[],"bids":[["64899.7","0.20859409","34557198003"],["64907.1","0.20521107","34557198002"],["64934.3","0.0921354","34557198004"],["64935.7","0.20521107","34557198005"]]},"sequenceEnd":34557198005,"sequenceStart":34557198002,"symbol":"BTC-USDT","time":1784133307252}}
{"topic":"/market/level2:BTC-USDT","type":"message","subject":"trade.l2update","data":{"changes":{"asks":[["64986.8","0","34557198007"]],"bids":[["64936.9","0.09215335","34557198006"]]},"sequenceEnd":34557198007,"sequenceStart":34557198006,"symbol":"BTC-USDT","time":1784133307253}}
{"topic":"/market/level2:BTC-USDT","type":"message","subject":"trade.l2update","data":{"changes":{"asks":[["64969.5","0.16241129","34557198008"]],"bids":[]},"sequenceEnd":34557198008,"sequenceStart":34557198008,"symbol":"BTC-USDT","time":1784133307253}}
{"topic":"/market/level2:BTC-USDT","type":"message","subject":"trade.l2update","data":{"changes":{"asks":[["64968","0.06856","34557198009"]],"bids":[]},"sequenceEnd":34557198009,"sequenceStart":34557198009,"symbol":"BTC-USDT","time":1784133307253}}
{"topic":"/market/level2:BTC-USDT","type":"message","subject":"trade.l2update","data":{"changes":{"asks":[],"bids":[["64776.8","0.00226995","34557198010"],["64937.5","0","34557198011"]]},"sequenceEnd":34557198011,"sequenceStart":34557198010,"symbol":"BTC-USDT","time":1784133307253}}
{"topic":"/market/level2:BTC-USDT","type":"message","subject":"trade.l2update","data":{"changes":{"asks":[["64971.3","0.01537323","34557198013"],["64971.5","0","34557198015"],["64992.7","0.37743921","34557198014"]],"bids":[["64957.8","0","34557198016"]]},"sequenceEnd":34557198016,"sequenceStart":34557198012,"symbol":"BTC-USDT","time":1784133307254}}
{"topic":"/market/level2:BTC-USDT","type":"message","subject":"trade.l2update","data":{"changes":{"asks":[],"bids":[["64776.8","0","34557198017"]]},"sequenceEnd":34557198017,"sequenceStart":34557198017,"symbol":"BTC-USDT","time":1784133307254}}
{"topic":"/market/level2:BTC-USDT","type":"message","subject":"trade.l2update","data":{"changes":{"asks":[["64971.4","0.35597569","34557198019"],["64972.3","0.20292131","34557198020"]],"bids":[["64959.9","0.05908006","34557198018"]]},"sequenceEnd":34557198020,"sequenceStart":34557198018,"symbol":"BTC-USDT","time":1784133307254}}
{"topic":"/market/level2:BTC-USDT","type":"message","subject":"trade.l2update","data":{"changes":{"asks":[["64969.5","0.24503279","34557198022"],["64971.3","0","34557198021"]],"bids":[["64952.5","0","34557198025"],["64953","0.10280382","34557198023"],["64956.4","0.02010956","34557198026"]]},"sequenceEnd":34557198026,"sequenceStart":34557198021,"symbol":"BTC-USDT","time":1784133307254}}
{"topic":"/market/level2:BTC-USDT","type":"message","subject":"trade.l2update","data":{"changes":{"asks":[],"bids":[["64938.6","0.00913178","34557198028"],["64947.7","0.02756533","34557198027"]]},"sequenceEnd":34557198028,"sequenceStart":34557198027,"symbol":"BTC-USDT","time":1784133307254}}
{"topic":"/market/level2:BTC-USDT","type":"message","subject":"trade.l2update","data":{"changes":{"asks":[["64971.4","0.35363212","34557198029"]],"bids":[]},"sequenceEnd":34557198029,"sequenceStart":34557198029,"symbol":"BTC-USDT","time":1784133307254}}
{"topic":"/market/level2:BTC-USDT","type":"message","subject":"trade.l2update","data":{"changes":{"asks":[["64967.1","0.0311441","34557198032"],["65069.9","0","34557198030"]],"bids":[["64861.5","0","34557198031"],["64953","0.14431337","34557198033"]]},"sequenceEnd":34557198033,"sequenceStart":34557198030,"symbol":"BTC-USDT","time":1784133307254}}
{"topic":"/market/level2:BTC-USDT","type":"message","subject":"trade.l2update","data":{"changes":{"asks":[["64971.4","0.0719472","34557198036"]],"bids":[["64946.3","0","34557198035"],["64953","0.04154454","34557198034"]]},"sequenceEnd":34557198036,"sequenceStart":34557198034,"symbol":"BTC-USDT","time":1784133307254}}
{"topic":"/market/match:BTC-USDT","type":"message","subject":"trade.l3match","data":{"makerOrderId":"6a57b6bad758b50007091ecc","price":"64971.4","sequence":"23580481584250880","side":"sell","size":"0.00007923","symbol":"BTC-USDT","takerOrderId":"466910362701238273","time":"1784133307246000000","tradeId":"23580481584250880","type":"match"}}
{"topic":"/market/level2:BTC-USDT","type":"message","subject":"trade.l2update","data":{"changes":{"asks":[["64967.1","0.32849057","34557198038"],["64969.5","0.16241129","34557198040"]],"bids":[["64939.6","0.0921354","34557198039"]]},"sequenceEnd":34557198040,"sequenceStart":34557198037,"symbol":"BTC-USDT","time":1784133307255}}
{"topic":"/market/level2:BTC-USDT","type":"message","subject":"trade.l2update","data":{"changes":{"asks":[],"bids":[["64956.4","0","34557198041"]]},"sequenceEnd":34557198041,"sequenceStart":34557198041,"symbol":"BTC-USDT","time":1784133307255}}
{"topic":"/market/level2:BTC-USDT","type":"message","subject":"trade.l2update","data":{"changes":{"asks":[["64967.1","0.38543203","34557198042"],["64968","0","34557198045"],["64971.4","0.28244242","34557198043"]],"bids":[["64947.7","0","34557198044"]]},"sequenceEnd":34557198045,"sequenceStart":34557198042,"symbol":"BTC-USDT","time":1784133307255}}
{"topic":"/market/level2:BTC-USDT","type":"message","subject":"trade.l2update","data":{"changes":{"asks":[["64967.1","0.40680118","34557198048"],["64971.4","0.25846002","34557198049"]],"bids":[]},"sequenceEnd":34557198049,"sequenceStart":34557198046,"symbol":"BTC-USDT","time":1784133307256}}
{"topic":"/market/level2:BTC-USDT","type":"message","subject":"trade.l2update","data":{"changes":{"asks":[["64971.4","0.23447762","34557198050"]],"bids":[]},"sequenceEnd":34557198050,"sequenceStart":34557198050,"symbol":"BTC-USDT","time":1784133307256}}
{"topic":"/market/level2:BTC-USDT","type":"message","subject":"trade.l2update","data":{"changes":{"asks":[["64967.1","0.58681058","34557198053"],["64972.3","0.02291191","34557198052"],["65024","0","34557198054"]],"bids":[["64939.6","0","34557198051"]]},"sequenceEnd":34557198054,"sequenceStart":34557198051,"symbol":"BTC-USDT","time":1784133307256}}
{"topic":"/market/level2:BTC-USDT","type":"message","subject":"trade.l2update","data":{"changes":{"asks":[["64993.5","0","34557198055"]],"bids":[]},"sequenceEnd":34557198055,"sequenceStart":34557198055,"symbol":"BTC-USDT","time":1784133307256}}
{"topic":"/market/level2:BTC-USDT","type":"message","subject":"trade.l2update","data":{"changes":{"asks":[["65001.8","0.00406728","34557198057"],["65008.7","0","34557198058"]],"bids":[["64894.4","0.0551839","34557198056"]]},"sequenceEnd":34557198058,"sequenceStart":34557198056,"symbol":"BTC-USDT","time":1784133307257}}
{"topic":"/market/level2:BTC-USDT","type":"message","subject":"trade.l2update","data":{"changes":{"asks":[["65011.1","0.01985056","34557198059"]],"bids":[]},"sequenceEnd":34557198059,"sequenceStart":34557198059,"symbol":"BTC-USDT","time":1784133307257}}
{"topic":"/market/level2:BTC-USDT","type":"message","subject":"trade.l2update","data":{"changes":{"asks":[["64971.3","0.0401089","34557198062"],["64971.4","0.35209253","34557198061"]],"bids":[["64963.8","0","34557198060"]]},"sequenceEnd":34557198062,"sequenceStart":34557198060,"symbol":"BTC-USDT","time":1784133307257}}
{"topic":"/market/level2:BTC-USDT","type":"message","subject":"trade.l2update","data":{"changes":{"asks":[["64971.3","0.09335722","34557198064"],["64974.3","0.02144602","34557198063"],["65012.7","0.02411492","34557198065"]],"bids":[["64775.5","0.00170371","34557198066"]]},"sequenceEnd":34557198066,"sequenceStart":34557198063,"symbol":"BTC-USDT","time":1784133307257}}
{"topic":"/market/level2:BTC-USDT","type":"message","subject":"trade.l2update","data":{"changes":{"asks":[["64966.2","0.06856","34557198070"],["64969.8","0.0674478","34557198067"],["64971.4","0.14159731","34557198071"],["64973.6","0.09521258","34557198068"],["64977.4","0.08139268","34557198069"]],"bids":[]},"sequenceEnd":34557198071,"sequenceStart":34557198067,"symbol":"BTC-USDT","time":1784133307257}}
{"topic":"/market/level2:BTC-USDT","type":"message","subject":"trade.l2update","data":{"changes":{"asks":[["64963.9","0.015294","34557198078"],["64965.6","0.04573232","34557198079"]],"bids":[["64964","0","34557198077"],["64964.2","0","34557198076"],["64965","0","34557198075"],["64965.1","0","34557198074"],["64965.4","0","34557198073"],["64965.5","0","34557198072"]]},"sequenceEnd":34557198079,"sequenceStart":34557198072,"symbol":"BTC-USDT","time":1784133307257}}
{"topic":"/market/level2:BTC-USDT","type":"message","subject":"trade.l2update","data":{"changes":{"asks":[["64971.4","0.11761491","34557198080"]],"bids":[]},"sequenceEnd":34557198080,"sequenceStart":34557198080,"symbol":"BTC-USDT","time":1784133307258}}
{"topic":"/market/level2:BTC-USDT","type":"message","subject":"trade.l2update","data":{"changes":{"asks":[["64974.2","0.05976622","34557198081"]],"bids":[]},"sequenceEnd":34557198081,"sequenceStart":34557198081,"symbol":"BTC-USDT","time":1784133307258}}
{"topic":"/market/level2:BTC-USDT","type":"message","subject":"trade.l2update","data":{"changes":{"asks":[["64971.3","0.11963704","34557198082"]],"bids":[["64775.5","0","34557198083"]]},"sequenceEnd":34557198083,"sequenceStart":34557198082,"symbol":"BTC-USDT","time":1784133307258}}
{"topic":"/market/level2:BTC-USDT","type":"message","subject":"trade.l2update","data":{"changes":{"asks":[["64973.9","0.06450174","34557198084"]],"bids":[]},"sequenceEnd":34557198084,"sequenceStart":34557198084,"symbol":"BTC-USDT","time":1784133307258}}
{"topic":"/market/level2:BTC-USDT","type":"message","subject":"trade.l2update","data":{"changes":{"asks":[["64984.6","0.0198309","34557198085"]],"bids":[]},"sequenceEnd":34557198085,"sequenceStart":34557198085,"symbol":"BTC-USDT","time":1784133307258}}
{"topic":"/market/level2:BTC-USDT","type":"message","subject":"trade.l2update","data":{"changes":{"asks":[["64974.3","0.03648422","34557198086"],["64976.2","0.04491703","34557198087"]],"bids":[]},"sequenceEnd":34557198087,"sequenceStart":34557198086,"symbol":"BTC-USDT","time":1784133307258}}
{"topic":"/market/level2:BTC-USDT","type":"message","subject":"trade.l2update","data":{"changes":{"asks":[["64967.1","0.69031058","34557198089"],["64969.5","0.05891129","34557198093"],["64971.3","0.14834585","34557198088"],["65011.2","0","34557198095"],["65023.4","0.00308101","34557198094"],["65027.2","0","34557198090"]],"bids":[["64861.5","0","34557198096"]]},"sequenceEnd":34557198096,"sequenceStart":34557198088,"symbol":"BTC-USDT","time":1784133307258}}
{"topic":"/market/level2:BTC-USDT","type":"message","subject":"trade.l2update","data":{"changes":{"asks":[["64974.9","0.02740557","34557198098"]],"bids":[["64963.7","0","34557198097"]]},"sequenceEnd":34557198098,"sequenceStart":34557198097,"symbol":"BTC-USDT","time":1784133307258}}
{"topic":"/market/level2:BTC-USDT","type":"message","subject":"trade.l2update","data":{"changes":{"asks":[["64983.3","0","34557198099"]],"bids":[]},"sequenceEnd":34557198099,"sequenceStart":34557198099,"symbol":"BTC-USDT","time":1784133307258}}
{"topic":"/market/level2:BTC-USDT","type":"message","subject":"trade.l2update","data":{"changes":{"asks":[["64992.7","0","34557198100"]],"bids":[]},"sequenceEnd":34557198100,"sequenceStart":34557198100,"symbol":"BTC-USDT","time":1784133307259}}
{"topic":"/market/level2:BTC-USDT","type":"message","subject":"trade.l2update","data":{"changes":{"asks":[],"bids":[["64928.4","0","34557198101"]]},"sequenceEnd":34557198101,"sequenceStart":34557198101,"symbol":"BTC-USDT","time":1784133307259}}
{"topic":"/market/level2:BTC-USDT","type":"message","subject":"trade.l2update","data":{"changes":{"asks":[["64965.6","0.11429232","34557198102"],["64966.2","0","34557198103"]],"bids":[]},"sequenceEnd":34557198103,"sequenceStart":34557198102,"symbol":"BTC-USDT","time":1784133307259}}
{"topic":"/market/level2:BTC-USDT","type":"message","subject":"trade.l2update","data":{"changes":{"asks":[["64967.9","0.07932359","34557198104"]],"bids":[]},"sequenceEnd":34557198104,"sequenceStart":34557198104,"symbol":"BTC-USDT","time":1784133307259}}
{"topic":"/market/level2:BTC-USDT","type":"message","subject":"trade.l2update","data":{"changes":{"asks":[["65032.7","0","34557198105"]],"bids":[]},"sequenceEnd":34557198105,"sequenceStart":34557198105,"symbol":"BTC-USDT","time":1784133307259}}
{"topic":"/market/level2:BTC-USDT","type":"message","subject":"trade.l2update","data":{"changes":{"asks":[["64967.1","0.70031055","34557198107"]],"bids":[["64947.2","0.04489195","34557198106"]]},"sequenceEnd":34557198107,"sequenceStart":34557198106,"symbol":"BTC-USDT","time":1784133307259}}
{"topic":"/market/level2:BTC-USDT","type":"message","subject":"trade.l2update","data":{"changes":{"asks":[],"bids":[["64774.2","0.10455282","34557198108"]]},"sequenceEnd":34557198108,"sequenceStart":34557198108,"symbol":"BTC-USDT","time":1784133307260}}
{"topic":"/market/level2:BTC-USDT","type":"message","subject":"trade.l2update","data":{"changes":{"asks":[["64974.1","0.03586597","34557198109"]],"bids":[]},"sequenceEnd":34557198109,"sequenceStart":34557198109,"symbol":"BTC-USDT","time":1784133307260}}
{"topic":"/market/level2:BTC-USDT","type":"message","subject":"trade.l2update","data":{"changes":{"asks":[["64971.3","0.20971465","34557198110"]],"bids":[["64899.7","0.00338302","34557198111"]]},"sequenceEnd":34557198111,"sequenceStart":34557198110,"symbol":"BTC-USDT","time":1784133307260}}
{"topic":"/market/level2:BTC-USDT","type":"message","subject":"trade.l2update","data":{"changes":{"asks":[],"bids":[["64940","0.09214612","34557198112"],["64947.1","0","34557198114"],["64959","0.00027138","34557198113"]]},"sequenceEnd":34557198114,"sequenceStart":34557198112,"symbol":"BTC-USDT","time":1784133307260}}
{"topic":"/market/level2:BTC-USDT","type":"message","subject":"trade.l2update","data":{"changes":{"asks":[["64965.6","0.21779232","34557198115"]],"bids":[]},"sequenceEnd":34557198115,"sequenceStart":34557198115,"symbol":"BTC-USDT","time":1784133307260}}
{"topic":"/market/level2:BTC-USDT","type":"message","subject":"trade.l2update","data":{"changes":{"asks":[["64971.1","0.08269858","34557198116"]],"bids":[]},"sequenceEnd":34557198116,"sequenceStart":34557198116,"symbol":"BTC-USDT","time":1784133307260}}
{"topic":"/market/level2:BTC-USDT","type":"message","subject":"trade.l2update","data":{"changes":{"asks":[],"bids":[["64938.6","0","34557198117"]]},"sequenceEnd":34557198117,"sequenceStart":34557198117,"symbol":"BTC-USDT","time":1784133307260}}
{"topic":"/market/level2:BTC-USDT","type":"message","subject":"trade.l2update","data":{"changes":{"asks":[["64971.5","0.00308141","34557198118"]],"bids":[["64774.2","0.1035","34557198119"]]},"sequenceEnd":34557198119,"sequenceStart":34557198118,"symbol":"BTC-USDT","time":1784133307261}}
{"topic":"/market/level2:BTC-USDT","type":"message","subject":"trade.l2update","data":{"changes":{"asks":[],"bids":[["64771.6","0.00178267","34557198120"]]},"sequenceEnd":34557198120,"sequenceStart":34557198120,"symbol":"BTC-USDT","time":1784133307261}}
{"topic":"/market/level2:BTC-USDT","type":"message","subject":"trade.l2update","data":{"changes":{"asks":[],"bids":[["64960.9","0","34557198121"]]},"sequenceEnd":34557198121,"sequenceStart":34557198121,"symbol":"BTC-USDT","time":1784133307261}}
{"topic":"/market/level2:BTC-USDT","type":"message","subject":"trade.l2update","data":{"changes":{"asks":[],"bids":[["64772.9","0.00154121","34557198122"],["64958.1","0","34557198123"]]},"sequenceEnd":34557198123,"sequenceStart":34557198122,"symbol":"BTC-USDT","time":1784133307261}}
{"topic":"/market/level2:BTC-USDT","type":"message","subject":"trade.l2update","data":{"changes":{"asks":[],"bids":[["64861.6","0","34557198124"]]},"sequenceEnd":34557198124,"sequenceStart":34557198124,"symbol":"BTC-USDT","time":1784133307261}}
{"topic":"/market/level2:BTC-USDT","type":"message","subject":"trade.l2update","data":{"changes":{"asks":[],"bids":[["64959.9","0","34557198125"]]},"sequenceEnd":34557198125,"sequenceStart":34557198125,"symbol":"BTC-USDT","time":1784133307261}}
{"topic":"/market/level2:BTC-USDT","type":"message","subject":"trade.l2update","data":{"changes":{"asks":[["64975.2","0.0652333","34557198126"]],"bids":[]},"sequenceEnd":34557198126,"sequenceStart":34557198126,"symbol":"BTC-USDT","time":1784133307261}}
{"topic":"/market/level2:BTC-USDT","type":"message","subject":"trade.l2update","data":{"changes":{"asks":[["64979.3","0.06441411","34557198127"]],"bids":[]},"sequenceEnd":34557198127,"sequenceStart":34557198127,"symbol":"BTC-USDT","time":1784133307261}}
{"topic":"/market/level2:BTC-USDT","type":"message","subject":"trade.l2update","data":{"changes":{"asks":[["64965.6","0.14923232","34557198128"]],"bids":[]},"sequenceEnd":34557198128,"sequenceStart":34557198128,"symbol":"BTC-USDT","time":1784133307261}}
{"topic":"/market/level2:BTC-USDT","type":"message","subject":"trade.l2update","data":{"changes":{"asks":[["64965.2","0.06856","34557198130"],["64965.5","0.06856","34557198129"]],"bids":[]},"sequenceEnd":34557198130,"sequenceStart":34557198129,"symbol":"BTC-USDT","time":1784133307261}}
{"topic":"/market/level2:BTC-USDT","type":"message","subject":"trade.l2update","data":{"changes":{"asks":[["64963.8","0.06856","34557198131"],["64963.9","0.01571986","34557198133"],["64965.2","0","34557198132"]],"bids":[]},"sequenceEnd":34557198133,"sequenceStart":34557198131,"symbol":"BTC-USDT","time":1784133307262}}
{"topic":"/market/level2:BTC-USDT","type":"message","subject":"trade.l2update","data":{"changes":{"asks":[["64967.1","0.69031058","34557198134"]],"bids":[]},"sequenceEnd":34557198134,"sequenceStart":34557198134,"symbol":"BTC-USDT","time":1784133307262}}
{"topic":"/market/level2:BTC-USDT","type":"message","subject":"trade.l2update","data":{"changes":{"asks":[["64967.1","0.58681058","34557198135"]],"bids":[["64864.5","0.00876588","34557198136"]]},"sequenceEnd":34557198136,"sequenceStart":34557198135,"symbol":"BTC-USDT","time":1784133307262}}
{"topic":"/market/level2:BTC-USDT","type":"message","subject":"trade.l2update","data":{"changes":{"asks":[["64965.6","0.18037642","34557198137"]],"bids":[]},"sequenceEnd":34557198137,"sequenceStart":34557198137,"symbol":"BTC-USDT","time":1784133307262}}
{"topic":"/market/level2:BTC-USDT","type":"message","subject":"trade.l2update","data":{"changes":{"asks":[["65150.9","0.00154059","34557198138"]],"bids":[["64930.8","0","34557198139"]]},"sequenceEnd":34557198139,"sequenceStart":34557198138,"symbol":"BTC-USDT","time":1784133307262}}
{"topic":"/market/level2:BTC-USDT","type":"message","subject":"trade.l2update","data":{"changes":{"asks":[["64999.5","0.01153","34557198141"]],"bids":[["64922.2","0.01155","34557198140"],["64931.1","0","34557198142"]]},"sequenceEnd":34557198142,"sequenceStart":34557198140,"symbol":"BTC-USDT","time":1784133307262}}
{"topic":"/market/level2:BTC-USDT","type":"message","subject":"trade.l2update","data":{"changes":{"asks":[["64999.5","0","34557198143"]],"bids":[]},"sequenceEnd":34557198143,"sequenceStart":34557198143,"symbol":"BTC-USDT","time":1784133307262}}
{"topic":"/market/level2:BTC-USDT","type":"message","subject":"trade.l2update","data":{"changes":{"asks":[],"bids":[["64922","0.01155","34557198144"]]},"sequenceEnd":34557198144,"sequenceStart":34557198144,"symbol":"BTC-USDT","time":1784133307262}}
{"topic":"/market/level2:BTC-USDT","type":"message","subject":"trade.l2update","data":{"changes":{"asks":[["65004.5","0","34557198145"]],"bids":[]},"sequenceEnd":34557198145,"sequenceStart":34557198145,"symbol":"BTC-USDT","time":1784133307262}}
{"topic":"/market/level2:BTC-USDT","type":"message","subject":"trade.l2update","data":{"changes":{"asks":[["64965.6","0.19997199","34557198147"]],"bids":[]},"sequenceEnd":34557198147,"sequenceStart":34557198146,"symbol":"BTC-USDT","time":1784133307262}}
{"topic":"/market/level2:BTC-USDT","type":"message","subject":"trade.l2update","data":{"changes":{"asks":[["64965.5","0.08597808","34557198148"],["65023.4","0.00154051","34557198149"]],"bids":[]},"sequenceEnd":34557198149,"sequenceStart":34557198148,"symbol":"BTC-USDT","time":1784133307263}}
{"topic":"/market/level2:BTC-USDT","type":"message","subject":"trade.l2update","data":{"changes":{"asks":[["64967.1","0.55566648","34557198150"],["65171.8","0","34557198151"]],"bids":[]},"sequenceEnd":34557198151,"sequenceStart":34557198150,"symbol":"BTC-USDT","time":1784133307263}}
{"topic":"/market/level2:BTC-USDT","type":"message","subject":"trade.l2update","data":{"changes":{"asks":[["64975.2","0.05583226","34557198154"],["65150.9","0.00308118","34557198152"]],"bids":[["64956.9","0.00922412","34557198153"]]},"sequenceEnd":34557198154,"sequenceStart":34557198152,"symbol":"BTC-USDT","time":1784133307263}}
{"topic":"/market/level2:BTC-USDT","type":"message","subject":"trade.l2update","data":{"changes":{"asks":[],"bids":[["64959.1","0","34557198156"]]},"sequenceEnd":34557198156,"sequenceStart":34557198155,"symbol":"BTC-USDT","time":1784133307263}}
{"topic":"/market/level2:BTC-USDT","type":"message","subject":"trade.l2update","data":{"changes":{"asks":[["64987.4","0.37767635","34557198157"]],"bids":[]},"sequenceEnd":34557198157,"sequenceStart":34557198157,"symbol":"BTC-USDT","time":1784133307263}}
{"topic":"/market/level2:BTC-USDT","type":"message","subject":"trade.l2update","data":{"changes":{"asks":[["64961","0.06856","34557198158"],["64963.8","0","34557198159"]],"bids":[]},"sequenceEnd":34557198159,"sequenceStart":34557198158,"symbol":"BTC-USDT","time":1784133307263}}
{"topic":"/market/level2:BTC-USDT","type":"message","subject":"trade.l2update","data":{"changes":{"asks":[],"bids":[["64772.9","0","34557198160"]]},"sequenceEnd":34557198160,"sequenceStart":34557198160,"symbol":"BTC-USDT","time":1784133307263}}
{"topic":"/market/level2:BTC-USDT","type":"message","subject":"trade.l2update","data":{"changes":{"asks":[],"bids":[["64771.6","0","34557198161"]]},"sequenceEnd":34557198161,"sequenceStart":34557198161,"symbol":"BTC-USDT","time":1784133307263}}
{"topic":"/market/level2:BTC-USDT","type":"message","subject":"trade.l2update","data":{"changes":{"asks":[],"bids":[["64920","0.02421755","34557198162"]]},"sequenceEnd":34557198162,"sequenceStart":34557198162,"symbol":"BTC-USDT","time":1784133307263}}
{"topic":"/market/level2:BTC-USDT","type":"message","subject":"trade.l2update","data":{"changes":{"asks":[["64988.6","0.01154","34557198165"],["64990.3","0.01154","34557198164"]],"bids":[["64919","0","34557198163"]]},"sequenceEnd":34557198165,"sequenceStart":34557198163,"symbol":"BTC-USDT","time":1784133307263}}
{"topic":"/market/level2:BTC-USDT","type":"message","subject":"trade.l2update","data":{"changes":{"asks":[["64965.5","0.08815356","34557198166"]],"bids":[]},"sequenceEnd":34557198166,"sequenceStart":34557198166,"symbol":"BTC-USDT","time":1784133307264}}
{"topic":"/market/level2:BTC-USDT","type":"message","subject":"trade.l2update","data":{"changes":{"asks":[["64990.8","0","34557198170"],["65023.4","0","34557198167"],["65171.7","0","34557198168"]],"bids":[["64940","0.29735719","34557198169"]]},"sequenceEnd":34557198170,"sequenceStart":34557198167,"symbol":"BTC-USDT","time":1784133307264}}
{"topic":"/market/level2:BTC-USDT","type":"message","subject":"trade.l2update","data":{"changes":{"asks":[["64971.4","0","34557198171"]],"bids":[]},"sequenceEnd":34557198171,"sequenceStart":34557198171,"symbol":"BTC-USDT","time":1784133307264}}
{"topic":"/market/level2:BTC-USDT","type":"message","subject":"trade.l2update","data":{"changes":{"asks":[["64971.2","0.0693675","34557198172"]],"bids":[]},"sequenceEnd":34557198172,"sequenceStart":34557198172,"symbol":"BTC-USDT","time":1784133307264}}
{"topic":"/market/level2:BTC-USDT","type":"message","subject":"trade.l2update","data":{"changes":{"asks":[["64967.1","0.49872502","34557198173"]],"bids":[]},"sequenceEnd":34557198173,"sequenceStart":34557198173,"symbol":"BTC-USDT","time":1784133307265}}
{"topic":"/market/level2:BTC-USDT","type":"message","subject":"trade.l2update","data":{"changes":{"asks":[["64963.8","0.10491409","34557198174"]],"bids":[]},"sequenceEnd":34557198174,"sequenceStart":34557198174,"symbol":"BTC-USDT","time":1784133307265}}
{"topic":"/market/match:BTC-USDT","type":"message","subject":"trade.l3match","data":{"makerOrderId":"6a57acd35c618000075e9383","price":"64965.5","sequence":"23580481612824576","side":"sell","size":"0.00009379","symbol":"BTC-USDT","takerOrderId":"6a57b6bbdff4b50007d458c2","time":"1784133307257000000","tradeId":"23580481612824576","type":"match"}}
{"topic":"/market/level2:BTC-USDT","type":"message","subject":"trade.l2update","data":{"changes":{"asks":[],"bids":[["64956.9","0","34557198175"]]},"sequenceEnd":34557198175,"sequenceStart":34557198175,"symbol":"BTC-USDT","time":1784133307265}}
{"topic":"/market/level2:BTC-USDT","type":"message","subject":"trade.l2update","data":{"changes":{"asks":[["64965.6","0.19779549","34557198177"]],"bids":[["64864.5","0","34557198176"]]},"sequenceEnd":34557198177,"sequenceStart":34557198176,"symbol":"BTC-USDT","time":1784133307265}}
{"topic":"/market/level2:BTC-USDT","type":"message","subject":"trade.l2update","data":{"changes":{"asks":[["64960.6","0.06856","34557198180"],["64961","0","34557198178"],["64965.5","0.01959356","34557198179"]],"bids":[]},"sequenceEnd":34557198180,"sequenceStart":34557198178,"symbol":"BTC-USDT","time":1784133307265}}
{"topic":"/market/level2:BTC-USDT","type":"message","subject":"trade.l2update","data":{"changes":{"asks":[],"bids":[["64916.2","0.02411492","34557198181"]]},"sequenceEnd":34557198181,"sequenceStart":34557198181,"symbol":"BTC-USDT","time":1784133307265}}
{"topic":"/market/level2:BTC-USDT","type":"message","subject":"trade.l2update","data":{"changes":{"asks":[["64963.9","0.17662135","34557198182"],["64965.6","0.15206317","34557198184"],["65001.8","0","34557198183"]],"bids":[]},"sequenceEnd":34557198184,"sequenceStart":34557198182,"symbol":"BTC-USDT","time":1784133307265}}
{"topic":"/market/level2:BTC-USDT","type":"message","subject":"trade.l2update","data":{"changes":{"asks":[["64969.4","0","34557198186"]],"bids":[]},"sequenceEnd":34557198186,"sequenceStart":34557198185,"symbol":"BTC-USDT","time":1784133307265}}
{"topic":"/market/level2:BTC-USDT","type":"message","subject":"trade.l2update","data":{"changes":{"asks":[["64969.5","0.04796479","34557198188"],["64996.8","0.00406764","34557198187"]],"bids":[]},"sequenceEnd":34557198188,"sequenceStart":34557198187,"symbol":"BTC-USDT","time":1784133307265}}
{"topic":"/market/level2:BTC-USDT","type":"message","subject":"trade.l2update","data":{"changes":{"asks":[["64969.5","0","34557198189"]],"bids":[]},"sequenceEnd":34557198189,"sequenceStart":34557198189,"symbol":"BTC-USDT","time":1784133307265}}
{"topic":"/market/level2:BTC-USDT","type":"message","subject":"trade.l2update","data":{"changes":{"asks":[["64963.8","0","34557198191"],["64967","0.41583955","34557198192"]],"bids":[]},"sequenceEnd":34557198192,"sequenceStart":34557198190,"symbol":"BTC-USDT","time":1784133307265}}
{"topic":"/market/level2:BTC-USDT","type":"message","subject":"trade.l2update","data":{"changes":{"asks":[],"bids":[["64935.8","0.12784017","34557198193"]]},"sequenceEnd":34557198193,"sequenceStart":34557198193,"symbol":"BTC-USDT","time":1784133307265}}
{"topic":"/market/level2:BTC-USDT","type":"message","subject":"trade.l2update","data":{"changes":{"asks":[["64965.5","0.00217548","34557198194"]],"bids":[]},"sequenceEnd":34557198194,"sequenceStart":34557198194,"symbol":"BTC-USDT","time":1784133307266}}
{"topic":"/market/level2:BTC-USDT","type":"message","subject":"trade.l2update","data":{"changes":{"asks":[["64965.5","0","34557198197"],["64965.6","0.12091907","34557198195"],["65065.4","0.00880553","34557198196"]],"bids":[]},"sequenceEnd":34557198197,"sequenceStart":34557198195,"symbol":"BTC-USDT","time":1784133307266}}
{"topic":"/market/level2:BTC-USDT","type":"message","subject":"trade.l2update","data":{"changes":{"asks":[["64965.6","0.1035","34557198198"],["65001.9","0","34557198200"]],"bids":[["64951.4","0","34557198199"]]},"sequenceEnd":34557198200,"sequenceStart":34557198198,"symbol":"BTC-USDT","time":1784133307266}}
{"topic":"/market/level2:BTC-USDT","type":"message","subject":"trade.l2update","data":{"changes":{"asks":[["64960.2","0.0921354","34557198201"]],"bids":[]},"sequenceEnd":34557198201,"sequenceStart":34557198201,"symbol":"BTC-USDT","time":1784133307266}}
{"topic":"/market/level2:BTC-USDT","type":"message","subject":"trade.l2update","data":{"changes":{"asks":[["64961","0.1800094","34557198203"],["64963.9","0.01571986","34557198204"],["64967.1","0.31871562","34557198202"]],"bids":[]},"sequenceEnd":34557198204,"sequenceStart":34557198202,"symbol":"BTC-USDT","time":1784133307266}}
{"topic":"/market/level2:BTC-USDT","type":"message","subject":"trade.l2update","data":{"changes":{"asks":[["64967.8","0.06139628","34557198206"]],"bids":[["64935.6","0","34557198205"]]},"sequenceEnd":34557198206,"sequenceStart":34557198205,"symbol":"BTC-USDT","time":1784133307266}}
{"topic":"/market/level2:BTC-USDT","type":"message","subject":"trade.l2update","data":{"changes":{"asks":[["64963.9","0.00042586","34557198207"]],"bids":[]},"sequenceEnd":34557198207,"sequenceStart":34557198207,"symbol":"BTC-USDT","time":1784133307266}}
{"topic":"/market/level2:BTC-USDT","type":"message","subject":"trade.l2update","data":{"changes":{"asks":[["64960.2","0.1956354","34557198208"]],"bids":[["64924.7","0.02411492","34557198209"]]},"sequenceEnd":34557198209,"sequenceStart":34557198208,"symbol":"BTC-USDT","time":1784133307266}}
{"topic":"/market/level2:BTC-USDT","type":"message","subject":"trade.l2update","data":{"changes":{"asks":[],"bids":[["64957.1","0.01792083","34557198210"]]},"sequenceEnd":34557198210,"sequenceStart":34557198210,"symbol":"BTC-USDT","time":1784133307267}}
{"topic":"/market/level2:BTC-USDT","type":"message","subject":"trade.l2update","data":{"changes":{"asks":[],"bids":[["64951.5","0.0428476","34557198211"],["64954.3","0.05070589","34557198212"]]},"sequenceEnd":34557198212,"sequenceStart":34557198211,"symbol":"BTC-USDT","time":1784133307267}}
{"topic":"/market/level2:BTC-USDT","type":"message","subject":"trade.l2update","data":{"changes":{"asks":[["64972.1","0.05071495","34557198214"],["64980.5","0","34557198213"]],"bids":[]},"sequenceEnd":34557198214,"sequenceStart":34557198213,"symbol":"BTC-USDT","time":1784133307267}}
{"topic":"/market/level2:BTC-USDT","type":"message","subject":"trade.l2update","data":{"changes":{"asks":[["64966","0.05294399","34557198216"],["64977.4","0","34557198215"]],"bids":[]},"sequenceEnd":34557198216,"sequenceStart":34557198215,"symbol":"BTC-USDT","time":1784133307267}}
{"topic":"/market/level2:BTC-USDT","type":"message","subject":"trade.l2update","data":{"changes":{"asks":[["64960.6","0","34557198218"],["65203.7","0.00166803","34557198217"]],"bids":[]},"sequenceEnd":34557198218,"sequenceStart":34557198217,"symbol":"BTC-USDT","time":1784133307267}}
{"topic":"/market/level2:BTC-USDT","type":"message","subject":"trade.l2update","data":{"changes":{"asks":[["64960.5","0.06856","34557198219"]],"bids":[]},"sequenceEnd":34557198219,"sequenceStart":34557198219,"symbol":"BTC-USDT","time":1784133307267}}
{"topic":"/market/level2:BTC-USDT","type":"message","subject":"trade.l2update","data":{"changes":{"asks":[["64968.3","0.014235","34557198220"],["64971.3","0.16960575","34557198221"],["64974.2","0","34557198222"]],"bids":[]},"sequenceEnd":34557198222,"sequenceStart":34557198220,"symbol":"BTC-USDT","time":1784133307267}}
{"topic":"/market/level2:BTC-USDT","type":"message","subject":"trade.l2update","data":{"changes":{"asks":[["64990.2","0.0383802","34557198223"]],"bids":[]},"sequenceEnd":34557198223,"sequenceStart":34557198223,"symbol":"BTC-USDT","time":1784133307267}}
{"topic":"/market/level2:BTC-USDT","type":"message","subject":"trade.l2update","data":{"changes":{"asks":[["64961","0.23192137","34557198225"]],"bids":[["64915.3","0.0386957","34557198226"],["64940.7","0.05567423","34557198224"]]},"sequenceEnd":34557198226,"sequenceStart":34557198224,"symbol":"BTC-USDT","time":1784133307267}}
{"topic":"/market/level2:BTC-USDT","type":"message","subject":"trade.l2update","data":{"changes":{"asks":[["65150.9","0.00154059","34557198227"]],"bids":[]},"sequenceEnd":34557198227,"sequenceStart":34557198227,"symbol":"BTC-USDT","time":1784133307268}}
{"topic":"/market/level2:BTC-USDT","type":"message","subject":"trade.l2update","data":{"changes":{"asks":[["64961","0.24192134","34557198228"]],"bids":[]},"sequenceEnd":34557198228,"sequenceStart":34557198228,"symbol":"BTC-USDT","time":1784133307268}}
{"topic":"/market/level2:BTC-USDT","type":"message","subject":"trade.l2update","data":{"changes":{"asks":[["64987.4","0.00020886","34557198229"]],"bids":[]},"sequenceEnd":34557198229,"sequenceStart":34557198229,"symbol":"BTC-USDT","time":1784133307268}}
{"topic":"/market/level2:BTC-USDT","type":"message","subject":"trade.l2update","data":{"changes":{"asks":[["65053.9","0","34557198230"]],"bids":[]},"sequenceEnd":34557198230,"sequenceStart":34557198230,"symbol":"BTC-USDT","time":1784133307268}}
{"topic":"/market/level2:BTC-USDT","type":"message","subject":"trade.l2update","data":{"changes":{"asks":[["64994.2","0.20521107","34557198231"]],"bids":[]},"sequenceEnd":34557198231,"sequenceStart":34557198231,"symbol":"BTC-USDT","time":1784133307268}}
{"topic":"/market/level2:BTC-USDT","type":"message","subject":"trade.l2update","data":{"changes":{"asks":[],"bids":[["64954.2","0.05101315","34557198232"]]},"sequenceEnd":34557198232,"sequenceStart":34557198232,"symbol":"BTC-USDT","time":1784133307268}}
{"topic":"/market/level2:BTC-USDT","type":"message","subject":"trade.l2update","data":{"changes":{"asks":[],"bids":[["64786.9","0.18984657","34557198233"]]},"sequenceEnd":34557198233,"sequenceStart":34557198233,"symbol":"BTC-USDT","time":1784133307268}}
{"topic":"/market/level2:BTC-USDT","type":"message","subject":"trade.l2update","data":{"changes":{"asks":[],"bids":[["64855.8","0.01613409","34557198234"]]},"sequenceEnd":34557198234,"sequenceStart":34557198234,"symbol":"BTC-USDT","time":1784133307268}}
{"topic":"/market/level2:BTC-USDT","type":"message","subject":"trade.l2update","data":{"changes":{"asks":[["64967","0.46380434","34557198236"],["64967.1","0.29734647","34557198235"]],"bids":[]},"sequenceEnd":34557198236,"sequenceStart":34557198235,"symbol":"BTC-USDT","time":1784133307269}}
{"topic":"/market/level2:BTC-USDT","type":"message","subject":"trade.l2update","data":{"changes":{"asks":[["65011.1","0","34557198237"]],"bids":[]},"sequenceEnd":34557198237,"sequenceStart":34557198237,"symbol":"BTC-USDT","time":1784133307269}}
{"topic":"/market/level2:BTC-USDT","type":"message","subject":"trade.l2update","data":{"changes":{"asks":[["64969.4","0.03771819","34557198239"],["64971.2","0.09817532","34557198238"]],"bids":[]},"sequenceEnd":34557198239,"sequenceStart":34557198238,"symbol":"BTC-USDT","time":1784133307269}}
{"topic":"/market/level2:BTC-USDT","type":"message","subject":"trade.l2update","data":{"changes":{"asks":[],"bids":[["64947.2","0.07638454","34557198240"]]},"sequenceEnd":34557198240,"sequenceStart":34557198240,"symbol":"BTC-USDT","time":1784133307269}}
{"topic":"/market/level2:BTC-USDT","type":"message","subject":"trade.l2update","data":{"changes":{"asks":[["64993.5","0.02977102","34557198241"]],"bids":[]},"sequenceEnd":34557198241,"sequenceStart":34557198241,"symbol":"BTC-USDT","time":1784133307269}}
{"topic":"/market/level2:BTC-USDT","type":"message","subject":"trade.l2update","data":{"changes":{"asks":[],"bids":[["64914.3","0.12556085","34557198242"]]},"sequenceEnd":34557198242,"sequenceStart":34557198242,"symbol":"BTC-USDT","time":1784133307269}}
{"topic":"/market/level2:BTC-USDT","type":"message","subject":"trade.l2update","data":{"changes":{"asks":[],"bids":[["64930.7","0.09417324","34557198245"],["64940.1","0.07311614","34557198243"],["64947.2","0.03149259","34557198244"]]},"sequenceEnd":34557198245,"sequenceStart":34557198243,"symbol":"BTC-USDT","time":1784133307269}}
{"topic":"/market/level2:BTC-USDT","type":"message","subject":"trade.l2update","data":{"changes":{"asks":[],"bids":[["64922.9","0.08876531","34557198246"]]},"sequenceEnd":34557198246,"sequenceStart":34557198246,"symbol":"BTC-USDT","time":1784133307269}}
{"topic":"/market/level2:BTC-USDT","type":"message","subject":"trade.l2update","data":{"changes":{"asks":[["64969.4","0","34557198248"]],"bids":[["64940","0.34569355","34557198247"]]},"sequenceEnd":34557198248,"sequenceStart":34557198247,"symbol":"BTC-USDT","time":1784133307269}}
{"topic":"/market/level2:BTC-USDT","type":"message","subject":"trade.l2update","data":{"changes":{"asks":[["64968.4","0.05649032","34557198250"],["65199.9","0.00169293","34557198252"],["65205.9","0","34557198251"]],"bids":[["64907.2","0.11977921","34557198249"]]},"sequenceEnd":34557198252,"sequenceStart":34557198249,"symbol":"BTC-USDT","time":1784133307269}}
{"topic":"/market/level2:BTC-USDT","type":"message","subject":"trade.l2update","data":{"changes":{"asks":[["65209.7","0","34557198253"]],"bids":[]},"sequenceEnd":34557198253,"sequenceStart":34557198253,"symbol":"BTC-USDT","time":1784133307269}}
{"topic":"/market/level2:BTC-USDT","type":"message","subject":"trade.l2update","data":{"changes":{"asks":[["64960.5","0","34557198254"]],"bids":[]},"sequenceEnd":34557198254,"sequenceStart":34557198254,"symbol":"BTC-USDT","time":1784133307270}}
{"topic":"/market/level2:BTC-USDT","type":"message","subject":"trade.l2update","data":{"changes":{"asks":[["64960.2","0.2641954","34557198255"]],"bids":[]},"sequenceEnd":34557198255,"sequenceStart":34557198255,"symbol":"BTC-USDT","time":1784133307270}}
{"topic":"/market/level2:BTC-USDT","type":"message","subject":"trade.l2update","data":{"changes":{"asks":[["64963.8","0.0921354","34557198256"]],"bids":[]},"sequenceEnd":34557198256,"sequenceStart":34557198256,"symbol":"BTC-USDT","time":1784133307270}}
{"topic":"/market/level2:BTC-USDT","type":"message","subject":"trade.l2update","data":{"changes":{"asks":[["64971.5","0","34557198257"]],"bids":[]},"sequenceEnd":34557198257,"sequenceStart":34557198257,"symbol":"BTC-USDT","time":1784133307270}}
{"topic":"/market/level2:BTC-USDT","type":"message","subject":"trade.l2update","data":{"changes":{"asks":[["65150.9","0","34557198258"]],"bids":[]},"sequenceEnd":34557198258,"sequenceStart":34557198258,"symbol":"BTC-USDT","time":1784133307270}}
{"topic":"/market/level2:BTC-USDT","type":"message","subject":"trade.l2update","data":{"changes":{"asks":[["64965.6","0","34557198259"]],"bids":[]},"sequenceEnd":34557198259,"sequenceStart":34557198259,"symbol":"BTC-USDT","time":1784133307270}}
{"topic":"/market/level2:BTC-USDT","type":"message","subject":"trade.l2update","data":{"changes":{"asks":[["64987.2","0","34557198260"]],"bids":[]},"sequenceEnd":34557198260,"sequenceStart":34557198260,"symbol":"BTC-USDT","time":1784133307270}}
{"topic":"/market/level2:BTC-USDT","type":"message","subject":"trade.l2update","data":{"changes":{"asks":[],"bids":[["64954.2","0","34557198261"]]},"sequenceEnd":34557198261,"sequenceStart":34557198261,"symbol":"BTC-USDT","time":1784133307270}}
{"topic":"/market/level2:BTC-USDT","type":"message","subject":"trade.l2update","data":{"changes":{"asks":[["64974.3","0.0150382","34557198263"]],"bids":[["64721.7","0.1035","34557198262"]]},"sequenceEnd":34557198263,"sequenceStart":34557198262,"symbol":"BTC-USDT","time":1784133307270}}
{"topic":"/market/level2:BTC-USDT","type":"message","subject":"trade.l2update","data":{"changes":{"asks":[["64961","0.23192137","34557198264"]],"bids":[]},"sequenceEnd":34557198264,"sequenceStart":34557198264,"symbol":"BTC-USDT","time":1784133307270}}
{"topic":"/market/level2:BTC-USDT","type":"message","subject":"trade.l2update","data":{"changes":{"asks":[],"bids":[["64900.9","0.07417907","34557198266"],["64906.8","0.00013628","34557198265"]]},"sequenceEnd":34557198266,"sequenceStart":34557198265,"symbol":"BTC-USDT","time":1784133307270}}
{"topic":"/market/level2:BTC-USDT","type":"message","subject":"trade.l2update","data":{"changes":{"asks":[],"bids":[["64855.8","0","34557198267"]]},"sequenceEnd":34557198267,"sequenceStart":34557198267,"symbol":"BTC-USDT","time":1784133307271}}
{"topic":"/market/level2:BTC-USDT","type":"message","subject":"trade.l2update","data":{"changes":{"asks":[["65016.1","0.00154065","34557198268"]],"bids":[]},"sequenceEnd":34557198268,"sequenceStart":34557198268,"symbol":"BTC-USDT","time":1784133307271}}
{"topic":"/market/level2:BTC-USDT","type":"message","subject":"trade.l2update","data":{"changes":{"asks":[["64965.6","0.0030815","34557198269"]],"bids":[]},"sequenceEnd":34557198269,"sequenceStart":34557198269,"symbol":"BTC-USDT","time":1784133307272}}
{"topic":"/market/level2:BTC-USDT","type":"message","subject":"trade.l2update","data":{"changes":{"asks":[],"bids":[["64888.7","0.5999","34557198270"]]},"sequenceEnd":34557198270,"sequenceStart":34557198270,"symbol":"BTC-USDT","time":1784133307273}}
{"topic":"/market/level2:BTC-USDT","type":"message","subject":"trade.l2update","data":{"changes":{"asks":[["65148","0.00154062","34557198271"]],"bids":[]},"sequenceEnd":34557198271,"sequenceStart":34557198271,"symbol":"BTC-USDT","time":1784133307273}}
{"topic":"/market/level2:BTC-USDT","type":"message","subject":"trade.l2update","data":{"changes":{"asks":[["65016.1","0","34557198272"]],"bids":[]},"sequenceEnd":34557198272,"sequenceStart":34557198272,"symbol":"BTC-USDT","time":1784133307273}}
{"topic":"/market/level2:BTC-USDT","type":"message","subject":"trade.l2update","data":{"changes":{"asks":[["64973.8","0.17355546","34557198274"],["64985.5","0.37747859","34557198273"]],"bids":[]},"sequenceEnd":34557198274,"sequenceStart":34557198273,"symbol":"BTC-USDT","time":1784133307274}}
{"topic":"/market/level2:BTC-USDT","type":"message","subject":"trade.l2update","data":{"changes":{"asks":[],"bids":[["64957.1","0","34557198275"]]},"sequenceEnd":34557198275,"sequenceStart":34557198275,"symbol":"BTC-USDT","time":1784133307274}}
{"topic":"/market/level2:BTC-USDT","type":"message","subject":"trade.l2update","data":{"changes":{"asks":[],"bids":[["64954.3","0","34557198276"]]},"sequenceEnd":34557198276,"sequenceStart":34557198276,"symbol":"BTC-USDT","time":1784133307274}}
{"topic":"/market/level2:BTC-USDT","type":"message","subject":"trade.l2update","data":{"changes":{"asks":[["64963.8","0.14010019","34557198277"]],"bids":[]},"sequenceEnd":34557198277,"sequenceStart":34557198277,"symbol":"BTC-USDT","time":1784133307274}}
{"topic":"/market/level2:BTC-USDT","type":"message","subject":"trade.l2update","data":{"changes":{"asks":[["64963.8","0.1640826","34557198278"]],"bids":[]},"sequenceEnd":34557198278,"sequenceStart":34557198278,"symbol":"BTC-USDT","time":1784133307274}}
{"topic":"/market/level2:BTC-USDT","type":"message","subject":"trade.l2update","data":{"changes":{"asks":[],"bids":[["64914.1","0","34557198279"]]},"sequenceEnd":34557198279,"sequenceStart":34557198279,"symbol":"BTC-USDT","time":1784133307274}}
{"topic":"/market/level2:BTC-USDT","type":"message","subject":"trade.l2update","data":{"changes":{"asks":[["64977.3","0.10516097","34557198280"]],"bids":[]},"sequenceEnd":34557198280,"sequenceStart":34557198280,"symbol":"BTC-USDT","time":1784133307274}}
{"topic":"/market/level2:BTC-USDT","type":"message","subject":"trade.l2update","data":{"changes":{"asks":[["64977.6","0","34557198282"],["64987.5","0.04947288","34557198283"],["65004.1","0","34557198281"]],"bids":[]},"sequenceEnd":34557198283,"sequenceStart":34557198281,"symbol":"BTC-USDT","time":1784133307274}}
{"topic":"/market/level2:BTC-USDT","type":"message","subject":"trade.l2update","data":{"changes":{"asks":[["64990.7","0","34557198285"],["65012.1","0.01426737","34557198286"]],"bids":[["64920.5","0.08701214","34557198284"]]},"sequenceEnd":34557198286,"sequenceStart":34557198284,"symbol":"BTC-USDT","time":1784133307274}}
{"topic":"/market/level2:BTC-USDT","type":"message","subject":"trade.l2update","data":{"changes":{"asks":[["64967","0.23702547","34557198288"],["64987.3","0.2053714","34557198289"],["64987.5","0","34557198287"]],"bids":[["64919.6","0","34557198290"]]},"sequenceEnd":34557198290,"sequenceStart":34557198287,"symbol":"BTC-USDT","time":1784133307274}}
{"topic":"/market/level2:BTC-USDT","type":"message","subject":"trade.l2update","data":{"changes":{"asks":[["64990.7","0.07428402","34557198292"]],"bids":[["64837.3","0.0225929","34557198291"]]},"sequenceEnd":34557198292,"sequenceStart":34557198291,"symbol":"BTC-USDT","time":1784133307274}}
{"topic":"/market/level2:BTC-USDT","type":"message","subject":"trade.l2update","data":{"changes":{"asks":[],"bids":[["64940.1","0.12502389","34557198293"]]},"sequenceEnd":34557198293,"sequenceStart":34557198293,"symbol":"BTC-USDT","time":1784133307274}}
{"topic":"/market/level2:BTC-USDT","type":"message","subject":"trade.l2update","data":{"changes":{"asks":[],"bids":[["64940","0.14048248","34557198294"]]},"sequenceEnd":34557198294,"sequenceStart":34557198294,"symbol":"BTC-USDT","time":1784133307275}}
{"topic":"/market/level2:BTC-USDT","type":"message","subject":"trade.l2update","data":{"changes":{"asks":[["64967.8","0","34557198295"]],"bids":[]},"sequenceEnd":34557198295,"sequenceStart":34557198295,"symbol":"BTC-USDT","time":1784133307276}}
{"topic":"/market/level2:BTC-USDT","type":"message","subject":"trade.l2update","data":{"changes":{"asks":[["65013.1","0.00154062","34557198296"]],"bids":[]},"sequenceEnd":34557198296,"sequenceStart":34557198296,"symbol":"BTC-USDT","time":1784133307276}}
{"topic":"/market/level2:BTC-USDT","type":"message","subject":"trade.l2update","data":{"changes":{"asks":[["65000.1","0","34557198297"]],"bids":[]},"sequenceEnd":34557198297,"sequenceStart":34557198297,"symbol":"BTC-USDT","time":1784133307276}}
{"topic":"/market/level2:BTC-USDT","type":"message","subject":"trade.l2update","data":{"changes":{"asks":[["64967.8","0.04381126","34557198298"]],"bids":[]},"sequenceEnd":34557198298,"sequenceStart":34557198298,"symbol":"BTC-USDT","time":1784133307276}}
{"topic":"/market/level2:BTC-USDT","type":"message","subject":"trade.l2update","data":{"changes":{"asks":[],"bids":[["64917.4","0.01119828","34557198300"],["64953","0.00003499","34557198299"]]},"sequenceEnd":34557198300,"sequenceStart":34557198299,"symbol":"BTC-USDT","time":1784133307276}}
{"topic":"/market/level2:BTC-USDT","type":"message","subject":"trade.l2update","data":{"changes":{"asks":[],"bids":[["64953","0.03106955","34557198301"]]},"sequenceEnd":34557198301,"sequenceStart":34557198301,"symbol":"BTC-USDT","time":1784133307276}}
{"topic":"/market/level2:BTC-USDT","type":"message","subject":"trade.l2update","data":{"changes":{"asks":[["64960.5","0.02046516","34557198303"]],"bids":[["64939.9","0","34557198302"]]},"sequenceEnd":34557198303,"sequenceStart":34557198302,"symbol":"BTC-USDT","time":1784133307276}}
{"topic":"/market/level2:BTC-USDT","type":"message","subject":"trade.l2update","data":{"changes":{"asks":[["64985.5","0","34557198304"]],"bids":[]},"sequenceEnd":34557198304,"sequenceStart":34557198304,"symbol":"BTC-USDT","time":1784133307276}}
{"topic":"/market/level2:BTC-USDT","type":"message","subject":"trade.l2update","data":{"changes":{"asks":[["64961","0.32785095","34557198306"]],"bids":[]},"sequenceEnd":34557198306,"sequenceStart":34557198305,"symbol":"BTC-USDT","time":1784133307276}}
{"topic":"/market/level2:BTC-USDT","type":"message","subject":"trade.l2update","data":{"changes":{"asks":[["64960.2","0.27419537","34557198307"],["65026","0.00022266","34557198308"]],"bids":[]},"sequenceEnd":34557198308,"sequenceStart":34557198307,"symbol":"BTC-USDT","time":1784133307277}}
{"topic":"/market/level2:BTC-USDT","type":"message","subject":"trade.l2update","data":{"changes":{"asks":[],"bids":[["64940.8","0.01661876","34557198309"]]},"sequenceEnd":34557198309,"sequenceStart":34557198309,"symbol":"BTC-USDT","time":1784133307277}}
{"topic":"/market/level2:BTC-USDT","type":"message","subject":"trade.l2update","data":{"changes":{"asks":[["64967","0.04796479","34557198310"]],"bids":[]},"sequenceEnd":34557198310,"sequenceStart":34557198310,"symbol":"BTC-USDT","time":1784133307277}}
{"topic":"/market/match:BTC-USDT","type":"message","subject":"trade.l3match","data":{"makerOrderId":"6a57940101773500078d5642","price":"64965.4","sequence":"23580481612824577","side":"sell","size":"0.00004839","symbol":"BTC-USDT","takerOrderId":"6a57b6bbdff4b50007d458c2","time":"1784133307257000000","tradeId":"23580481612824577","type":"match"}}
{"topic":"/market/level2:BTC-USDT","type":"message","subject":"trade.l2update","data":{"changes":{"asks":[["64966.9","0.21926472","34557198311"]],"bids":[]},"sequenceEnd":34557198311,"sequenceStart":34557198311,"symbol":"BTC-USDT","time":1784133307277}}
{"topic":"/market/level2:BTC-USDT","type":"message","subject":"trade.l2update","data":{"changes":{"asks":[["64960.2","0.45420477","34557198312"],["64961","0.14784155","34557198313"]],"bids":[]},"sequenceEnd":34557198313,"sequenceStart":34557198312,"symbol":"BTC-USDT","time":1784133307277}}
{"topic":"/market/level2:BTC-USDT","type":"message","subject":"trade.l2update","data":{"changes":{"asks":[["64961","0.09592958","34557198314"],["65065.4","0","34557198315"]],"bids":[]},"sequenceEnd":34557198315,"sequenceStart":34557198314,"symbol":"BTC-USDT","time":1784133307278}}
{"topic":"/market/level2:BTC-USDT","type":"message","subject":"trade.l2update","data":{"changes":{"asks":[["65012.6","0.00154064","34557198316"]],"bids":[]},"sequenceEnd":34557198316,"sequenceStart":34557198316,"symbol":"BTC-USDT","time":1784133307278}}
{"topic":"/market/level2:BTC-USDT","type":"message","subject":"trade.l2update","data":{"changes":{"asks":[["64957.2","0.015294","34557198322"]],"bids":[["64957.2","0","34557198321"],["64958","0","34557198320"],["64959","0","34557198319"],["64960.1","0","34557198317"]]},"sequenceEnd":34557198322,"sequenceStart":34557198317,"symbol":"BTC-USDT","time":1784133307278}}
{"topic":"/market/level2:BTC-USDT","type":"message","subject":"trade.l2update","data":{"changes":{"asks":[["64960.5","0.07158154","34557198324"],["64987.3","0.10759853","34557198326"]],"bids":[["64917.4","0.02127731","34557198325"]]},"sequenceEnd":34557198326,"sequenceStart":34557198323,"symbol":"BTC-USDT","time":1784133307278}}
{"topic":"/market/level2:BTC-USDT","type":"message","subject":"trade.l2update","data":{"changes":{"asks":[["64993.5","0.08843455","34557198329"]],"bids":[["64940","0.09214612","34557198328"],["64954.4","0.03090349","34557198327"]]},"sequenceEnd":34557198329,"sequenceStart":34557198327,"symbol":"BTC-USDT","time":1784133307278}}
{"topic":"/market/level2:BTC-USDT","type":"message","subject":"trade.l2update","data":{"changes":{"asks":[],"bids":[["64936.9","0.00001795","34557198330"]]},"sequenceEnd":34557198330,"sequenceStart":34557198330,"symbol":"BTC-USDT","time":1784133307279}}
{"topic":"/market/level2:BTC-USDT","type":"message","subject":"trade.l2update","data":{"changes":{"asks":[],"bids":[["64940","0.00001072","34557198331"]]},"sequenceEnd":34557198331,"sequenceStart":34557198331,"symbol":"BTC-USDT","time":1784133307279}}
{"topic":"/market/level2:BTC-USDT","type":"message","subject":"trade.l2update","data":{"changes":{"asks":[["64967","0","34557198334"]],"bids":[["64899.7","0.20859409","34557198333"],["64935.7","0","34557198332"]]},"sequenceEnd":34557198334,"sequenceStart":34557198332,"symbol":"BTC-USDT","time":1784133307279}}
{"topic":"/market/level2:BTC-USDT","type":"message","subject":"trade.l2update","data":{"changes":{"asks":[["64960","0.0000202","34557198335"]],"bids":[]},"sequenceEnd":34557198335,"sequenceStart":34557198335,"symbol":"BTC-USDT","time":1784133307279}}
{"topic":"/market/level2:BTC-USDT","type":"message","subject":"trade.l2update","data":{"changes":{"asks":[["64960","0.0240026","34557198336"]],"bids":[["64954.4","0","34557198337"]]},"sequenceEnd":34557198337,"sequenceStart":34557198336,"symbol":"BTC-USDT","time":1784133307280}}
{"topic":"/market/level2:BTC-USDT","type":"message","subject":"trade.l2update","data":{"changes":{"asks":[["64960","0.047985","34557198338"]],"bids":[]},"sequenceEnd":34557198338,"sequenceStart":34557198338,"symbol":"BTC-USDT","time":1784133307280}}
{"topic":"/market/level2:BTC-USDT","type":"message","subject":"trade.l2update","data":{"changes":{"asks":[["64960.2","0.50172349","34557198339"]],"bids":[]},"sequenceEnd":34557198339,"sequenceStart":34557198339,"symbol":"BTC-USDT","time":1784133307280}}
{"topic":"/market/level2:BTC-USDT","type":"message","subject":"trade.l2update","data":{"changes":{"asks":[["65151","0","34557198340"]],"bids":[]},"sequenceEnd":34557198340,"sequenceStart":34557198340,"symbol":"BTC-USDT","time":1784133307280}}
{"topic":"/market/level2:BTC-USDT","type":"message","subject":"trade.l2update","data":{"changes":{"asks":[],"bids":[["64920","0.00010263","34557198341"]]},"sequenceEnd":34557198341,"sequenceStart":34557198341,"symbol":"BTC-USDT","time":1784133307281}}
{"topic":"/market/level2:BTC-USDT","type":"message","subject":"trade.l2update","data":{"changes":{"asks":[],"bids":[["64852.5","0.01641643","34557198342"]]},"sequenceEnd":34557198342,"sequenceStart":34557198342,"symbol":"BTC-USDT","time":1784133307281}}
{"topic":"/market/level2:BTC-USDT","type":"message","subject":"trade.l2update","data":{"changes":{"asks":[["64960.2","0.43316349","34557198343"]],"bids":[]},"sequenceEnd":34557198343,"sequenceStart":34557198343,"symbol":"BTC-USDT","time":1784133307282}}
{"topic":"/market/level2:BTC-USDT","type":"message","subject":"trade.l2update","data":{"changes":{"asks":[["64959.1","0.06856","34557198344"]],"bids":[]},"sequenceEnd":34557198344,"sequenceStart":34557198344,"symbol":"BTC-USDT","time":1784133307282}}
{"topic":"/market/level2:BTC-USDT","type":"message","subject":"trade.l2update","data":{"changes":{"asks":[["64956.9","0.06856","34557198345"]],"bids":[]},"sequenceEnd":34557198345,"sequenceStart":34557198345,"symbol":"BTC-USDT","time":1784133307282}}
{"topic":"/market/level2:BTC-USDT","type":"message","subject":"trade.l2update","data":{"changes":{"asks":[["64956.3","0.06856","34557198349"],["64956.9","0","34557198348"],["64957.3","0.06856","34557198347"],["64959.1","0","34557198346"],["64985.8","0.00538579","34557198350"]],"bids":[]},"sequenceEnd":34557198350,"sequenceStart":34557198346,"symbol":"BTC-USDT","time":1784133307282}}
{"topic":"/market/level2:BTC-USDT","type":"message","subject":"trade.l2update","data":{"changes":{"asks":[["64959.1","0.0311441","34557198351"]],"bids":[]},"sequenceEnd":34557198351,"sequenceStart":34557198351,"symbol":"BTC-USDT","time":1784133307282}}
{"topic":"/market/level2:BTC-USDT","type":"message","subject":"trade.l2update","data":{"changes":{"asks":[["64958.1","0.04856119","34557198353"]],"bids":[]},"sequenceEnd":34557198353,"sequenceStart":34557198352,"symbol":"BTC-USDT","time":1784133307282}}
{"topic":"/market/level2:BTC-USDT","type":"message","subject":"trade.l2update","data":{"changes":{"asks":[["64994.2","0","34557198354"]],"bids":[]},"sequenceEnd":34557198354,"sequenceStart":34557198354,"symbol":"BTC-USDT","time":1784133307282}}
{"topic":"/market/level2:BTC-USDT","type":"message","subject":"trade.l2update","data":{"changes":{"asks":[["64998.1","0","34557198355"]],"bids":[["64935.9","0.20560721","34557198357"],["64937","0.09217738","34557198356"],["64940.2","0.0921354","34557198358"]]},"sequenceEnd":34557198358,"sequenceStart":34557198355,"symbol":"BTC-USDT","time":1784133307282}}
{"topic":"/market/level2:BTC-USDT","type":"message","subject":"trade.l2update","data":{"changes":{"asks":[["65002.2","0","34557198359"]],"bids":[]},"sequenceEnd":34557198359,"sequenceStart":34557198359,"symbol":"BTC-USDT","time":1784133307282}}
{"topic":"/market/level2:BTC-USDT","type":"message","subject":"trade.l2update","data":{"changes":{"asks":[],"bids":[["64949.7","0","34557198360"]]},"sequenceEnd":34557198360,"sequenceStart":34557198360,"symbol":"BTC-USDT","time":1784133307282}}
{"topic":"/market/level2:BTC-USDT","type":"message","subject":"trade.l2update","data":{"changes":{"asks":[["64994.1","0","34557198363"]],"bids":[["64938.3","0","34557198361"],["64954.6","0.00006466","34557198362"]]},"sequenceEnd":34557198363,"sequenceStart":34557198361,"symbol":"BTC-USDT","time":1784133307283}}
{"topic":"/market/level2:BTC-USDT","type":"message","subject":"trade.l2update","data":{"changes":{"asks":[["64959.1","0.05073967","34557198365"]],"bids":[]},"sequenceEnd":34557198365,"sequenceStart":34557198364,"symbol":"BTC-USDT","time":1784133307283}}
{"topic":"/market/level2:BTC-USDT","type":"message","subject":"trade.l2update","data":{"changes":{"asks":[["64956.3","0.17206","34557198366"]],"bids":[]},"sequenceEnd":34557198366,"sequenceStart":34557198366,"symbol":"BTC-USDT","time":1784133307283}}
{"topic":"/market/level2:BTC-USDT","type":"message","subject":"trade.l2update","data":{"changes":{"asks":[["64958.1","0.05073667","34557198367"]],"bids":[]},"sequenceEnd":34557198367,"sequenceStart":34557198367,"symbol":"BTC-USDT","time":1784133307283}}
{"topic":"/market/level2:BTC-USDT","type":"message","subject":"trade.l2update","data":{"changes":{"asks":[["64974.1","0","34557198368"]],"bids":[]},"sequenceEnd":34557198368,"sequenceStart":34557198368,"symbol":"BTC-USDT","time":1784133307283}}
{"topic":"/market/level2:BTC-USDT","type":"message","subject":"trade.l2update","data":{"changes":{"asks":[["64971.3","0.10823695","34557198369"]],"bids":[]},"sequenceEnd":34557198369,"sequenceStart":34557198369,"symbol":"BTC-USDT","time":1784133307283}}
{"topic":"/market/level2:BTC-USDT","type":"message","subject":"trade.l2update","data":{"changes":{"asks":[],"bids":[["64935.9","0.00039614","34557198370"]]},"sequenceEnd":34557198370,"sequenceStart":34557198370,"symbol":"BTC-USDT","time":1784133307284}}
{"topic":"/market/level2:BTC-USDT","type":"message","subject":"trade.l2update","data":{"changes":{"asks":[],"bids":[["64929.6","0.0000661","34557198372"],["64940.2","0","34557198371"]]},"sequenceEnd":34557198372,"sequenceStart":34557198371,"symbol":"BTC-USDT","time":1784133307284}}
{"topic":"/market/level2:BTC-USDT","type":"message","subject":"trade.l2update","data":{"changes":{"asks":[["64960.2","0.42316352","34557198377"],["64965.5","0.00308133","34557198378"],["64965.6","0","34557198379"]],"bids":[["64888.8","0.0921354","34557198376"],["64930.6","0","34557198374"],["64934.3","0","34557198373"],["64937","0.00004198","34557198375"]]},"sequenceEnd":34557198379,"sequenceStart":34557198373,"symbol":"BTC-USDT","time":1784133307284}}
{"topic":"/market/level2:BTC-USDT","type":"message","subject":"trade.l2update","data":{"changes":{"asks":[],"bids":[["64922","0","34557198381"],["64922.2","0","34557198380"]]},"sequenceEnd":34557198381,"sequenceStart":34557198380,"symbol":"BTC-USDT","time":1784133307284}}
{"topic":"/market/level2:BTC-USDT","type":"message","subject":"trade.l2update","data":{"changes":{"asks":[],"bids":[["64914.2","0.21676107","34557198383"],["64915.5","0.01155","34557198382"]]},"sequenceEnd":34557198383,"sequenceStart":34557198382,"symbol":"BTC-USDT","time":1784133307284}}
{"topic":"/market/level2:BTC-USDT","type":"message","subject":"trade.l2update","data":{"changes":{"asks":[["64960.2","0.31966352","34557198386"],["64985.9","0","34557198387"],["65148","0.00308127","34557198384"]],"bids":[["64852.5","0","34557198385"],["64913.2","0.02411492","34557198388"]]},"sequenceEnd":34557198388,"sequenceStart":34557198384,"symbol":"BTC-USDT","time":1784133307285}}
{"topic":"/market/level2:BTC-USDT","type":"message","subject":"trade.l2update","data":{"changes":{"asks":[["64968.5","0.02409666","34557198389"]],"bids":[]},"sequenceEnd":34557198389,"sequenceStart":34557198389,"symbol":"BTC-USDT","time":1784133307285}}
{"topic":"/market/level2:BTC-USDT","type":"message","subject":"trade.l2update","data":{"changes":{"asks":[["64974.3","0","34557198390"]],"bids":[]},"sequenceEnd":34557198390,"sequenceStart":34557198390,"symbol":"BTC-USDT","time":1784133307285}}
{"topic":"/market/level2:BTC-USDT","type":"message","subject":"trade.l2update","data":{"changes":{"asks":[["64968.3","0.03806219","34557198391"]],"bids":[]},"sequenceEnd":34557198391,"sequenceStart":34557198391,"symbol":"BTC-USDT","time":1784133307285}}
{"topic":"/market/level2:BTC-USDT","type":"message","subject":"trade.l2update","data":{"changes":{"asks":[["64958.1","0.03331859","34557198394"],["64959.1","0.04856317","34557198395"],["64971.3","0.07952814","34557198392"],["65056","0.01696306","34557198393"]],"bids":[]},"sequenceEnd":34557198395,"sequenceStart":34557198392,"symbol":"BTC-USDT","time":1784133307285}}
{"topic":"/market/level2:BTC-USDT","type":"message","subject":"trade.l2update","data":{"changes":{"asks":[["64985","0.20289753","34557198396"]],"bids":[]},"sequenceEnd":34557198396,"sequenceStart":34557198396,"symbol":"BTC-USDT","time":1784133307286}}
{"topic":"/market/level2:BTC-USDT","type":"message","subject":"trade.l2update","data":{"changes":{"asks":[["64960.5","0.05111638","34557198397"]],"bids":[]},"sequenceEnd":34557198397,"sequenceStart":34557198397,"symbol":"BTC-USDT","time":1784133307286}}
{"topic":"/market/level2:BTC-USDT","type":"message","subject":"trade.l2update","data":{"changes":{"asks":[["64960.5","0.10905563","34557198400"]],"bids":[["64889.7","0.21819048","34557198399"],["64891","0.07139123","34557198401"]]},"sequenceEnd":34557198401,"sequenceStart":34557198398,"symbol":"BTC-USDT","time":1784133307286}}
{"topic":"/market/level2:BTC-USDT","type":"message","subject":"trade.l2update","data":{"changes":{"asks":[["64966.9","0.15951002","34557198403"]],"bids":[]},"sequenceEnd":34557198403,"sequenceStart":34557198402,"symbol":"BTC-USDT","time":1784133307286}}
{"topic":"/market/level2:BTC-USDT","type":"message","subject":"trade.l2update","data":{"changes":{"asks":[["64956.3","0.26199254","34557198408"],["64960.5","0.18666927","34557198410"],["64966.9","0.10307541","34557198407"],["64985","0.11495939","34557198409"],["64994.2","0","34557198412"]],"bids":[["64940.1","0.07311614","34557198404"],["64953","0.00003499","34557198405"]]},"sequenceEnd":34557198412,"sequenceStart":34557198404,"symbol":"BTC-USDT","time":1784133307286}}
{"topic":"/market/level2:BTC-USDT","type":"message","subject":"trade.l2update","data":{"changes":{"asks":[["64986.2","0.37747451","34557198413"]],"bids":[]},"sequenceEnd":34557198413,"sequenceStart":34557198413,"symbol":"BTC-USDT","time":1784133307286}}
{"topic":"/market/level2:BTC-USDT","type":"message","subject":"trade.l2update","data":{"changes":{"asks":[["64971.3","0.05324832","34557198414"]],"bids":[]},"sequenceEnd":34557198414,"sequenceStart":34557198414,"symbol":"BTC-USDT","time":1784133307286}}
{"topic":"/market/level2:BTC-USDT","type":"message","subject":"trade.l2update","data":{"changes":{"asks":[["64960.5","0.07761364","34557198415"],["64979.7","0","34557198416"]],"bids":[]},"sequenceEnd":34557198416,"sequenceStart":34557198415,"symbol":"BTC-USDT","time":1784133307286}}
{"topic":"/market/level2:BTC-USDT","type":"message","subject":"trade.l2update","data":{"changes":{"asks":[["64977.5","0.01540403","34557198417"]],"bids":[]},"sequenceEnd":34557198417,"sequenceStart":34557198417,"symbol":"BTC-USDT","time":1784133307287}}
{"topic":"/market/level2:BTC-USDT","type":"message","subject":"trade.l2update","data":{"changes":{"asks":[["64957.1","0.0921354","34557198418"]],"bids":[]},"sequenceEnd":34557198418,"sequenceStart":34557198418,"symbol":"BTC-USDT","time":1784133307287}}
{"topic":"/market/level2:BTC-USDT","type":"message","subject":"trade.l2update","data":{"changes":{"asks":[],"bids":[["64891.9","0.20526768","34557198419"]]},"sequenceEnd":34557198419,"sequenceStart":34557198419,"symbol":"BTC-USDT","time":1784133307287}}
{"topic":"/market/level2:BTC-USDT","type":"message","subject":"trade.l2update","data":{"changes":{"asks":[],"bids":[["64884.1","0.20521107","34557198420"]]},"sequenceEnd":34557198420,"sequenceStart":34557198420,"symbol":"BTC-USDT","time":1784133307287}}
{"topic":"/market/level2:BTC-USDT","type":"message","subject":"trade.l2update","data":{"changes":{"asks":[["64958.1","0.03114311","34557198422"],["64985.7","0.0053913","34557198423"]],"bids":[["64925.6","0.09214889","34557198421"]]},"sequenceEnd":34557198423,"sequenceStart":34557198421,"symbol":"BTC-USDT","time":1784133307287}}
{"topic":"/market/level2:BTC-USDT","type":"message","subject":"trade.l2update","data":{"changes":{"asks":[["64959.1","0","34557198425"]],"bids":[["64947.3","0.05101857","34557198426"]]},"sequenceEnd":34557198426,"sequenceStart":34557198424,"symbol":"BTC-USDT","time":1784133307287}}
{"topic":"/market/level2:BTC-USDT","type":"message","subject":"trade.l2update","data":{"changes":{"asks":[["64960.2","0.33061002","34557198429"],["64965.5","0.0365356","34557198428"]],"bids":[["64952.4","0","34557198427"]]},"sequenceEnd":34557198429,"sequenceStart":34557198427,"symbol":"BTC-USDT","time":1784133307287}}
{"topic":"/market/level2:BTC-USDT","type":"message","subject":"trade.l2update","data":{"changes":{"asks":[],"bids":[["64735.2","0","34557198430"]]},"sequenceEnd":34557198430,"sequenceStart":34557198430,"symbol":"BTC-USDT","time":1784133307288}}
{"topic":"/market/level2:BTC-USDT","type":"message","subject":"trade.l2update","data":{"changes":{"asks":[["64958.1","0","34557198431"]],"bids":[]},"sequenceEnd":34557198431,"sequenceStart":34557198431,"symbol":"BTC-USDT","time":1784133307288}}
{"topic":"/market/level2:BTC-USDT","type":"message","subject":"trade.l2update","data":{"changes":{"asks":[["64960.5","0.12952601","34557198432"],["64968.4","0","34557198433"]],"bids":[]},"sequenceEnd":34557198433,"sequenceStart":34557198432,"symbol":"BTC-USDT","time":1784133307288}}
{"topic":"/market/level2:BTC-USDT","type":"message","subject":"trade.l2update","data":{"changes":{"asks":[["64979.3","0","34557198434"]],"bids":[["64914.2","0.20521107","34557198435"]]},"sequenceEnd":34557198435,"sequenceStart":34557198434,"symbol":"BTC-USDT","time":1784133307289}}
{"topic":"/market/level2:BTC-USDT","type":"message","subject":"trade.l2update","data":{"changes":{"asks":[],"bids":[["64908.2","0.01184519","34557198436"],["64915.5","0","34557198437"]]},"sequenceEnd":34557198437,"sequenceStart":34557198436,"symbol":"BTC-USDT","time":1784133307289}}
{"topic":"/market/level2:BTC-USDT","type":"message","subject":"trade.l2update","data":{"changes":{"asks":[],"bids":[["64906.9","0.01155","34557198438"],["64951.5","0","34557198439"]]},"sequenceEnd":34557198439,"sequenceStart":34557198438,"symbol":"BTC-USDT","time":1784133307289}}
{"topic":"/market/level2:BTC-USDT","type":"message","subject":"trade.l2update","data":{"changes":{"asks":[["64956.3","0.44200194","34557198441"],["64959.9","0.20521107","34557198444"],["64960.2","0.15060062","34557198443"]],"bids":[["64884.1","0","34557198442"],["64928.3","0.09223487","34557198440"]]},"sequenceEnd":34557198444,"sequenceStart":34557198440,"symbol":"BTC-USDT","time":1784133307289}}
{"topic":"/market/match:BTC-USDT","type":"message","subject":"trade.l3match","data":{"makerOrderId":"6a57a84dae25030007d14a0f","price":"64965.1","sequence":"23580481612824578","side":"sell","size":"0.00007378","symbol":"BTC-USDT","takerOrderId":"6a57b6bbdff4b50007d458c2","time":"1784133307257000000","tradeId":"23580481612824578","type":"match"}}
{"topic":"/market/level2:BTC-USDT","type":"message","subject":"trade.l2update","data":{"changes":{"asks":[["65111.9","0","34557198445"]],"bids":[]},"sequenceEnd":34557198445,"sequenceStart":34557198445,"symbol":"BTC-USDT","time":1784133307289}}
{"topic":"/market/level2:BTC-USDT","type":"message","subject":"trade.l2update","data":{"changes":{"asks":[["64967","0.06066059","34557198446"]],"bids":[]},"sequenceEnd":34557198446,"sequenceStart":34557198446,"symbol":"BTC-USDT","time":1784133307290}}
{"topic":"/market/level2:BTC-USDT","type":"message","subject":"trade.l2update","data":{"changes":{"asks":[["64971.3","0","34557198448"],["64973.9","0","34557198447"]],"bids":[["64755.3","0.00235377","34557198449"]]},"sequenceEnd":34557198449,"sequenceStart":34557198447,"symbol":"BTC-USDT","time":1784133307290}}
{"topic":"/market/level2:BTC-USDT","type":"message","subject":"trade.l2update","data":{"changes":{"asks":[["64968.7","0.02332646","34557198450"]],"bids":[]},"sequenceEnd":34557198450,"sequenceStart":34557198450,"symbol":"BTC-USDT","time":1784133307290}}
{"topic":"/market/level2:BTC-USDT","type":"message","subject":"trade.l2update","data":{"changes":{"asks":[],"bids":[["64886.5","0.1035","34557198451"]]},"sequenceEnd":34557198451,"sequenceStart":34557198451,"symbol":"BTC-USDT","time":1784133307290}}
{"topic":"/market/level2:BTC-USDT","type":"message","subject":"trade.l2update","data":{"changes":{"asks":[],"bids":[["64947.3","0","34557198452"]]},"sequenceEnd":34557198452,"sequenceStart":34557198452,"symbol":"BTC-USDT","time":1784133307290}}
{"topic":"/market/level2:BTC-USDT","type":"message","subject":"trade.l2update","data":{"changes":{"asks":[],"bids":[["64894.1","0","34557198454"],["64931.2","0","34557198455"],["64940.7","0","34557198453"],["64947.5","0","34557198456"]]},"sequenceEnd":34557198456,"sequenceStart":34557198453,"symbol":"BTC-USDT","time":1784133307290}}
{"topic":"/market/level2:BTC-USDT","type":"message","subject":"trade.l2update","data":{"changes":{"asks":[["65061.4","0","34557198458"],["65180.5","0","34557198457"]],"bids":[["64935.8","0.06658467","34557198461"],["64940.1","0.03342436","34557198462"]]},"sequenceEnd":34557198462,"sequenceStart":34557198457,"symbol":"BTC-USDT","time":1784133307290}}
{"topic":"/market/level2:BTC-USDT","type":"message","subject":"trade.l2update","data":{"changes":{"asks":[["64961","0","34557198467"],["64963.8","0.0921354","34557198466"],["64963.9","0","34557198464"]],"bids":[["64763.1","0.00149513","34557198469"],["64764.4","0.00192968","34557198468"]]},"sequenceEnd":34557198469,"sequenceStart":34557198463,"symbol":"BTC-USDT","time":1784133307290}}
{"topic":"/market/level2:BTC-USDT","type":"message","subject":"trade.l2update","data":{"changes":{"asks":[["65012","0.00154071","34557198474"],["65202.5","0.00193835","34557198473"]],"bids":[["64759.2","0.00229375","34557198472"],["64760.5","0.00220133","34557198471"],["64761.8","0.00154971","34557198470"]]},"sequenceEnd":34557198474,"sequenceStart":34557198470,"symbol":"BTC-USDT","time":1784133307290}}
{"topic":"/market/level2:BTC-USDT","type":"message","subject":"trade.l2update","data":{"changes":{"asks":[["64968.5","0","34557198476"],["64977.5","0","34557198480"],["65013.1","0","34557198475"]],"bids":[["64754","0.00277731","34557198479"],["64757.9","0.00137914","34557198477"],["64759.2","0.00339825","34557198478"]]},"sequenceEnd":34557198480,"sequenceStart":34557198475,"symbol":"BTC-USDT","time":1784133307290}}
{"topic":"/market/level2:BTC-USDT","type":"message","subject":"trade.l2update","data":{"changes":{"asks":[["65012.6","0","34557198481"]],"bids":[]},"sequenceEnd":34557198481,"sequenceStart":34557198481,"symbol":"BTC-USDT","time":1784133307291}}
{"topic":"/market/level2:BTC-USDT","type":"message","subject":"trade.l2update","data":{"changes":{"asks":[["65112.3","0","34557198482"]],"bids":[]},"sequenceEnd":34557198482,"sequenceStart":34557198482,"symbol":"BTC-USDT","time":1784133307291}}
{"topic":"/market/level2:BTC-USDT","type":"message","subject":"trade.l2update","data":{"changes":{"asks":[["65008.7","0.00154073","34557198483"]],"bids":[["64900.9","0.05351895","34557198484"]]},"sequenceEnd":34557198484,"sequenceStart":34557198483,"symbol":"BTC-USDT","time":1784133307291}}
{"topic":"/market/level2:BTC-USDT","type":"message","subject":"trade.l2update","data":{"changes":{"asks":[],"bids":[["64900.9","0.18631217","34557198485"]]},"sequenceEnd":34557198485,"sequenceStart":34557198485,"symbol":"BTC-USDT","time":1784133307291}}
{"topic":"/market/level2:BTC-USDT","type":"message","subject":"trade.l2update","data":{"changes":{"asks":[],"bids":[["64940.1","0","34557198486"],["64940.3","0.06097316","34557198487"]]},"sequenceEnd":34557198487,"sequenceStart":34557198486,"symbol":"BTC-USDT","time":1784133307291}}
{"topic":"/market/level2:BTC-USDT","type":"message","subject":"trade.l2update","data":{"changes":{"asks":[["64993.5","0.02977102","34557198488"]],"bids":[]},"sequenceEnd":34557198488,"sequenceStart":34557198488,"symbol":"BTC-USDT","time":1784133307291}}
{"topic":"/market/level2:BTC-USDT","type":"message","subject":"trade.l2update","data":{"changes":{"asks":[["64996.8","0","34557198489"]],"bids":[["64940.3","0.03120214","34557198491"]]},"sequenceEnd":34557198491,"sequenceStart":34557198489,"symbol":"BTC-USDT","time":1784133307292}}
{"topic":"/market/level2:BTC-USDT","type":"message","subject":"trade.l2update","data":{"changes":{"asks":[["64953.1","0.015294","34557198499"]],"bids":[["64953.8","0","34557198498"],["64953.9","0","34557198497"],["64954","0","34557198496"],["64954.1","0","34557198495"],["64954.6","0","34557198494"],["64955.1","0","34557198493"],["64956.2","0","34557198492"]]},"sequenceEnd":34557198499,"sequenceStart":34557198492,"symbol":"BTC-USDT","time":1784133307292}}
{"topic":"/market/level2:BTC-USDT","type":"message","subject":"trade.l2update","data":{"changes":{"asks":[],"bids":[["64900.9","0.13279322","34557198500"],["64935.8","0","34557198501"]]},"sequenceEnd":34557198501,"sequenceStart":34557198500,"symbol":"BTC-USDT","time":1784133307292}}
{"topic":"/market/level2:BTC-USDT","type":"message","subject":"trade.l2update","data":{"changes":{"asks":[["64956.3","0.45200191","34557198502"],["65208.5","0","34557198503"]],"bids":[]},"sequenceEnd":34557198503,"sequenceStart":34557198502,"symbol":"BTC-USDT","time":1784133307292}}
{"topic":"/market/level2:BTC-USDT","type":"message","subject":"trade.l2update","data":{"changes":{"asks":[["64968.3","0.014235","34557198506"]],"bids":[["64756.6","0.001696","34557198505"],["64935.9","0.09253154","34557198504"]]},"sequenceEnd":34557198506,"sequenceStart":34557198504,"symbol":"BTC-USDT","time":1784133307292}}
{"topic":"/market/level2:BTC-USDT","type":"message","subject":"trade.l2update","data":{"changes":{"asks":[],"bids":[["64948.6","0.01544222","34557198507"]]},"sequenceEnd":34557198507,"sequenceStart":34557198507,"symbol":"BTC-USDT","time":1784133307292}}
{"topic":"/market/level2:BTC-USDT","type":"message","subject":"trade.l2update","data":{"changes":{"asks":[["64986.2","0","34557198508"]],"bids":[]},"sequenceEnd":34557198508,"sequenceStart":34557198508,"symbol":"BTC-USDT","time":1784133307292}}
{"topic":"/market/match:BTC-USDT","type":"message","subject":"trade.l3match","data":{"makerOrderId":"6a5793ec064f2f0007996d2b","price":"64965","sequence":"23580481612824579","side":"sell","size":"0.00017957","symbol":"BTC-USDT","takerOrderId":"6a57b6bbdff4b50007d458c2","time":"1784133307257000000","tradeId":"23580481612824579","type":"match"}}
{"topic":"/market/level2:BTC-USDT","type":"message","subject":"trade.l2update","data":{"changes":{"asks":[["64962.6","0.05745247","34557198509"]],"bids":[]},"sequenceEnd":34557198509,"sequenceStart":34557198509,"symbol":"BTC-USDT","time":1784133307292}}
{"topic":"/market/level2:BTC-USDT","type":"message","subject":"trade.l2update","data":{"changes":{"asks":[["64990.9","0.00406794","34557198510"]],"bids":[["64930.7","0","34557198511"]]},"sequenceEnd":34557198511,"sequenceStart":34557198510,"symbol":"BTC-USDT","time":1784133307292}}
{"topic":"/market/level2:BTC-USDT","type":"message","subject":"trade.l2update","data":{"changes":{"asks":[["64967.8","0.06651444","34557198513"]],"bids":[["64935.8","0.03908225","34557198512"]]},"sequenceEnd":34557198513,"sequenceStart":34557198512,"symbol":"BTC-USDT","time":1784133307292}}
{"topic":"/market/level2:BTC-USDT","type":"message","subject":"trade.l2update","data":{"changes":{"asks":[],"bids":[["64891.9","0.00005661","34557198514"],["64935.9","0.29774261","34557198515"]]},"sequenceEnd":34557198515,"sequenceStart":34557198514,"symbol":"BTC-USDT","time":1784133307293}}
{"topic":"/market/level2:BTC-USDT","type":"message","subject":"trade.l2update","data":{"changes":{"asks":[["64960.2","0.16582202","34557198516"]],"bids":[]},"sequenceEnd":34557198516,"sequenceStart":34557198516,"symbol":"BTC-USDT","time":1784133307293}}
{"topic":"/market/level2:BTC-USDT","type":"message","subject":"trade.l2update","data":{"changes":{"asks":[["65083.3","0.006925","34557198517"]],"bids":[]},"sequenceEnd":34557198517,"sequenceStart":34557198517,"symbol":"BTC-USDT","time":1784133307293}}
{"topic":"/market/level2:BTC-USDT","type":"message","subject":"trade.l2update","data":{"changes":{"asks":[["64962.8","0.1035","34557198518"]],"bids":[["64847.8","0.01634966","34557198519"]]},"sequenceEnd":34557198519,"sequenceStart":34557198518,"symbol":"BTC-USDT","time":1784133307293}}
{"topic":"/market/level2:BTC-USDT","type":"message","subject":"trade.l2update","data":{"changes":{"asks":[["64965.5","0.00308133","34557198520"]],"bids":[]},"sequenceEnd":34557198520,"sequenceStart":34557198520,"symbol":"BTC-USDT","time":1784133307294}}
{"topic":"/market/level2:BTC-USDT","type":"message","subject":"trade.l2update","data":{"changes":{"asks":[],"bids":[["64847.8","0","34557198521"]]},"sequenceEnd":34557198521,"sequenceStart":34557198521,"symbol":"BTC-USDT","time":1784133307294}}
{"topic":"/market/level2:BTC-USDT","type":"message","subject":"trade.l2update","data":{"changes":{"asks":[["64965.5","0","34557198522"]],"bids":[]},"sequenceEnd":34557198522,"sequenceStart":34557198522,"symbol":"BTC-USDT","time":1784133307295}}
{"topic":"/market/level2:BTC-USDT","type":"message","subject":"trade.l2update","data":{"changes":{"asks":[["64965.2","0.00308148","34557198523"]],"bids":[]},"sequenceEnd":34557198523,"sequenceStart":34557198523,"symbol":"BTC-USDT","time":1784133307295}}
{"topic":"/market/match:BTC-USDT","type":"message","subject":"trade.l3match","data":{"makerOrderId":"6a57acd366a52d0007370be9","price":"64964.2","sequence":"23580481612824580","side":"sell","size":"0.00001243","symbol":"BTC-USDT","takerOrderId":"6a57b6bbdff4b50007d458c2","time":"1784133307257000000","tradeId":"23580481612824580","type":"match"}}
{"topic":"/market/level2:BTC-USDT","type":"message","subject":"trade.l2update","data":{"changes":{"asks":[],"bids":[["64926.1","0.06182033","34557198524"]]},"sequenceEnd":34557198524,"sequenceStart":34557198524,"symbol":"BTC-USDT","time":1784133307295}}
{"topic":"/market/level2:BTC-USDT","type":"message","subject":"trade.l2update","data":{"changes":{"asks":[],"bids":[["64947.4","0.01522904","34557198525"]]},"sequenceEnd":34557198525,"sequenceStart":34557198525,"symbol":"BTC-USDT","time":1784133307295}}
{"topic":"/market/level2:BTC-USDT","type":"message","subject":"trade.l2update","data":{"changes":{"asks":[["65012","0","34557198526"]],"bids":[]},"sequenceEnd":34557198526,"sequenceStart":34557198526,"symbol":"BTC-USDT","time":1784133307295}}
{"topic":"/market/level2:BTC-USDT","type":"message","subject":"trade.l2update","data":{"changes":{"asks":[],"bids":[["64948.6","0","34557198527"]]},"sequenceEnd":34557198527,"sequenceStart":34557198527,"symbol":"BTC-USDT","time":1784133307295}}
{"topic":"/market/level2:BTC-USDT","type":"message","subject":"trade.l2update","data":{"changes":{"asks":[["65008.7","0.0030815","34557198528"]],"bids":[]},"sequenceEnd":34557198528,"sequenceStart":34557198528,"symbol":"BTC-USDT","time":1784133307295}}
{"topic":"/market/level2:BTC-USDT","type":"message","subject":"trade.l2update","data":{"changes":{"asks":[["64957.3","0","34557198529"]],"bids":[]},"sequenceEnd":34557198529,"sequenceStart":34557198529,"symbol":"BTC-USDT","time":1784133307296}}
{"topic":"/market/level2:BTC-USDT","type":"message","subject":"trade.l2update","data":{"changes":{"asks":[["64954.2","0.06856","34557198532"],["64955.2","0.06856","34557198531"],["64956.3","0.38344191","34557198530"]],"bids":[]},"sequenceEnd":34557198532,"sequenceStart":34557198530,"symbol":"BTC-USDT","time":1784133307296}}
{"topic":"/market/level2:BTC-USDT","type":"message","subject":"trade.l2update","data":{"changes":{"asks":[["64954.2","0","34557198534"],["64954.7","0.06856","34557198533"]],"bids":[]},"sequenceEnd":34557198534,"sequenceStart":34557198533,"symbol":"BTC-USDT","time":1784133307296}}
{"topic":"/market/level2:BTC-USDT","type":"message","subject":"trade.l2update","data":{"changes":{"asks":[["64954","0.06856","34557198536"],["64955.2","0","34557198535"]],"bids":[]},"sequenceEnd":34557198536,"sequenceStart":34557198535,"symbol":"BTC-USDT","time":1784133307296}}
{"topic":"/market/level2:BTC-USDT","type":"message","subject":"trade.l2update","data":{"changes":{"asks":[["64954.1","0.06856","34557198538"],["64954.7","0","34557198537"]],"bids":[]},"sequenceEnd":34557198538,"sequenceStart":34557198537,"symbol":"BTC-USDT","time":1784133307296}}
{"topic":"/market/level2:BTC-USDT","type":"message","subject":"trade.l2update","data":{"changes":{"asks":[["64953.1","0.083854","34557198540"],["64953.9","0","34557198542"],["64954.1","0","34557198539"]],"bids":[]},"sequenceEnd":34557198542,"sequenceStart":34557198539,"symbol":"BTC-USDT","time":1784133307296}}
{"topic":"/market/level2:BTC-USDT","type":"message","subject":"trade.l2update","data":{"changes":{"asks":[["64968.7","0","34557198543"]],"bids":[]},"sequenceEnd":34557198543,"sequenceStart":34557198543,"symbol":"BTC-USDT","time":1784133307296}}
{"topic":"/market/level2:BTC-USDT","type":"message","subject":"trade.l2update","data":{"changes":{"asks":[["64984.1","0.3774874","34557198544"]],"bids":[]},"sequenceEnd":34557198544,"sequenceStart":34557198544,"symbol":"BTC-USDT","time":1784133307296}}
{"topic":"/market/level2:BTC-USDT","type":"message","subject":"trade.l2update","data":{"changes":{"asks":[["64953.1","0.1149981","34557198545"],["65105.5","0","34557198546"]],"bids":[]},"sequenceEnd":34557198546,"sequenceStart":34557198545,"symbol":"BTC-USDT","time":1784133307296}}
{"topic":"/market/level2:BTC-USDT","type":"message","subject":"trade.l2update","data":{"changes":{"asks":[],"bids":[["64860.9","0.0087524","34557198547"]]},"sequenceEnd":34557198547,"sequenceStart":34557198547,"symbol":"BTC-USDT","time":1784133307296}}
{"topic":"/market/level2:BTC-USDT","type":"message","subject":"trade.l2update","data":{"changes":{"asks":[["64985","0.20384467","34557198550"]],"bids":[["64894.4","0","34557198549"]]},"sequenceEnd":34557198550,"sequenceStart":34557198548,"symbol":"BTC-USDT","time":1784133307297}}
{"topic":"/market/level2:BTC-USDT","type":"message","subject":"trade.l2update","data":{"changes":{"asks":[["65028.2","0","34557198551"]],"bids":[]},"sequenceEnd":34557198551,"sequenceStart":34557198551,"symbol":"BTC-USDT","time":1784133307297}}
{"topic":"/market/level2:BTC-USDT","type":"message","subject":"trade.l2update","data":{"changes":{"asks":[],"bids":[["64894.4","0.11338792","34557198552"]]},"sequenceEnd":34557198552,"sequenceStart":34557198552,"symbol":"BTC-USDT","time":1784133307297}}
{"topic":"/market/level2:BTC-USDT","type":"message","subject":"trade.l2update","data":{"changes":{"asks":[["64961.3","0.0198309","34557198554"]],"bids":[["64884.2","0.06383007","34557198553"],["64930.2","0.00001185","34557198555"]]},"sequenceEnd":34557198555,"sequenceStart":34557198553,"symbol":"BTC-USDT","time":1784133307297}}
{"topic":"/market/level2:BTC-USDT","type":"message","subject":"trade.l2update","data":{"changes":{"asks":[],"bids":[["64928.4","0.20521107","34557198556"],["64935.9","0.00039614","34557198558"]]},"sequenceEnd":34557198558,"sequenceStart":34557198556,"symbol":"BTC-USDT","time":1784133307297}}
{"topic":"/market/level2:BTC-USDT","type":"message","subject":"trade.l2update","data":{"changes":{"asks":[["64956.3","0.37344194","34557198561"],["64978.9","0.01540403","34557198559"]],"bids":[["64924.7","0","34557198560"]]},"sequenceEnd":34557198561,"sequenceStart":34557198559,"symbol":"BTC-USDT","time":1784133307297}}
{"topic":"/market/level2:BTC-USDT","type":"message","subject":"trade.l2update","data":{"changes":{"asks":[],"bids":[["64884.2","0","34557198562"]]},"sequenceEnd":34557198562,"sequenceStart":34557198562,"symbol":"BTC-USDT","time":1784133307297}}
{"topic":"/market/level2:BTC-USDT","type":"message","subject":"trade.l2update","data":{"changes":{"asks":[],"bids":[["64947.2","0","34557198563"],["64947.4","0","34557198564"]]},"sequenceEnd":34557198564,"sequenceStart":34557198563,"symbol":"BTC-USDT","time":1784133307297}}
{"topic":"/market/level2:BTC-USDT","type":"message","subject":"trade.l2update","data":{"changes":{"asks":[["64965.1","0.00308153","34557198565"]],"bids":[]},"sequenceEnd":34557198565,"sequenceStart":34557198565,"symbol":"BTC-USDT","time":1784133307297}}
{"topic":"/market/level2:BTC-USDT","type":"message","subject":"trade.l2update","data":{"changes":{"asks":[["64965.2","0","34557198566"]],"bids":[]},"sequenceEnd":34557198566,"sequenceStart":34557198566,"symbol":"BTC-USDT","time":1784133307297}}
{"topic":"/market/level2:BTC-USDT","type":"message","subject":"trade.l2update","data":{"changes":{"asks":[["64962.6","0","34557198567"]],"bids":[]},"sequenceEnd":34557198567,"sequenceStart":34557198567,"symbol":"BTC-USDT","time":1784133307298}}
{"topic":"/market/level2:BTC-USDT","type":"message","subject":"trade.l2update","data":{"changes":{"asks":[["64953.1","0.2184981","34557198568"],["65056","0.008307","34557198570"]],"bids":[["64682.3","0.1035","34557198569"]]},"sequenceEnd":34557198570,"sequenceStart":34557198568,"symbol":"BTC-USDT","time":1784133307298}}
{"topic":"/market/level2:BTC-USDT","type":"message","subject":"trade.l2update","data":{"changes":{"asks":[["64978.9","0","34557198571"]],"bids":[]},"sequenceEnd":34557198571,"sequenceStart":34557198571,"symbol":"BTC-USDT","time":1784133307298}}
{"topic":"/market/level2:BTC-USDT","type":"message","subject":"trade.l2update","data":{"changes":{"asks":[["64973.8","0.11699192","34557198572"]],"bids":[["64928.4","0.23281082","34557198573"]]},"sequenceEnd":34557198573,"sequenceStart":34557198572,"symbol":"BTC-USDT","time":1784133307298}}
{"topic":"/market/match:BTC-USDT","type":"message","subject":"trade.l3match","data":{"makerOrderId":"6a579357b3b9130007ef1795","price":"64964","sequence":"23580481612824581","side":"sell","size":"0.00001789","symbol":"BTC-USDT","takerOrderId":"6a57b6bbdff4b50007d458c2","time":"1784133307257000000","tradeId":"23580481612824581","type":"match"}}
{"topic":"/market/level2:BTC-USDT","type":"message","subject":"trade.l2update","data":{"changes":{"asks":[],"bids":[["64945.9","0.03091394","34557198574"]]},"sequenceEnd":34557198574,"sequenceStart":34557198574,"symbol":"BTC-USDT","time":1784133307298}}
{"topic":"/market/level2:BTC-USDT","type":"message","subject":"trade.l2update","data":{"changes":{"asks":[],"bids":[["64878.9","0","34557198575"]]},"sequenceEnd":34557198575,"sequenceStart":34557198575,"symbol":"BTC-USDT","time":1784133307299}}
{"topic":"/market/level2:BTC-USDT","type":"message","subject":"trade.l2update","data":{"changes":{"asks":[["64991.4","0","34557198576"]],"bids":[]},"sequenceEnd":34557198576,"sequenceStart":34557198576,"symbol":"BTC-USDT","time":1784133307299}}
{"topic":"/market/level2:BTC-USDT","type":"message","subject":"trade.l2update","data":{"changes":{"asks":[["64975.1","0.01540403","34557198577"]],"bids":[]},"sequenceEnd":34557198577,"sequenceStart":34557198577,"symbol":"BTC-USDT","time":1784133307300}}
{"topic":"/market/level2:BTC-USDT","type":"message","subject":"trade.l2update","data":{"changes":{"asks":[["64975.1","0","34557198578"]],"bids":[]},"sequenceEnd":34557198578,"sequenceStart":34557198578,"symbol":"BTC-USDT","time":1784133307300}}
{"topic":"/market/level2:BTC-USDT","type":"message","subject":"trade.l2update","data":{"changes":{"asks":[["64956.3","0.26994194","34557198579"]],"bids":[["64945.8","0","34557198580"]]},"sequenceEnd":34557198580,"sequenceStart":34557198579,"symbol":"BTC-USDT","time":1784133307300}}
{"topic":"/market/level2:BTC-USDT","type":"message","subject":"trade.l2update","data":{"changes":{"asks":[["64967.1","0.30685245","34557198581"]],"bids":[["64948.7","0.00947756","34557198582"]]},"sequenceEnd":34557198582,"sequenceStart":34557198581,"symbol":"BTC-USDT","time":1784133307300}}
{"topic":"/market/level2:BTC-USDT","type":"message","subject":"trade.l2update","data":{"changes":{"asks":[["64993.6","0","34557198583"]],"bids":[]},"sequenceEnd":34557198583,"sequenceStart":34557198583,"symbol":"BTC-USDT","time":1784133307300}}
{"topic":"/market/level2:BTC-USDT","type":"message","subject":"trade.l2update","data":{"changes":{"asks":[["64965.1","0","34557198586"],["64972.3","0.0198309","34557198585"]],"bids":[["64893.1","0.20521107","34557198584"]]},"sequenceEnd":34557198586,"sequenceStart":34557198584,"symbol":"BTC-USDT","time":1784133307300}}
{"topic":"/market/level2:BTC-USDT","type":"message","subject":"trade.l2update","data":{"changes":{"asks":[["65031.9","0.04835042","34557198588"]],"bids":[["64930.4","0.05568305","34557198587"]]},"sequenceEnd":34557198588,"sequenceStart":34557198587,"symbol":"BTC-USDT","time":1784133307300}}
{"topic":"/market/level2:BTC-USDT","type":"message","subject":"trade.l2update","data":{"changes":{"asks":[["64977.3","0.1667986","34557198589"]],"bids":[]},"sequenceEnd":34557198589,"sequenceStart":34557198589,"symbol":"BTC-USDT","time":1784133307301}}
{"topic":"/market/level2:BTC-USDT","type":"message","subject":"trade.l2update","data":{"changes":{"asks":[["64977.3","0.06163763","34557198591"]],"bids":[["64940.8","0","34557198590"]]},"sequenceEnd":34557198591,"sequenceStart":34557198590,"symbol":"BTC-USDT","time":1784133307301}}
{"topic":"/market/level2:BTC-USDT","type":"message","subject":"trade.l2update","data":{"changes":{"asks":[["64960.5","0.05191237","34557198593"],["64963.7","0.02750242","34557198592"]],"bids":[]},"sequenceEnd":34557198593,"sequenceStart":34557198592,"symbol":"BTC-USDT","time":1784133307301}}
{"topic":"/market/level2:BTC-USDT","type":"message","subject":"trade.l2update","data":{"changes":{"asks":[["64953.1","0.28517963","34557198595"]],"bids":[["64833.7","0.03114289","34557198594"],["64847.8","0.01628978","34557198597"],["64941.9","0.05102279","34557198596"]]},"sequenceEnd":34557198597,"sequenceStart":34557198594,"symbol":"BTC-USDT","time":1784133307301}}
{"topic":"/market/level2:BTC-USDT","type":"message","subject":"trade.l2update","data":{"changes":{"asks":[["64957.1","0.14405049","34557198600"],["65035.8","0.01630079","34557198601"]],"bids":[["64847.8","0","34557198598"],["64948.7","0.0001266","34557198599"]]},"sequenceEnd":34557198601,"sequenceStart":34557198598,"symbol":"BTC-USDT","time":1784133307301}}
{"topic":"/market/level2:BTC-USDT","type":"message","subject":"trade.l2update","data":{"changes":{"asks":[["65008.7","0.00154073","34557198603"],["65121.9","0.13492248","34557198602"]],"bids":[]},"sequenceEnd":34557198603,"sequenceStart":34557198602,"symbol":"BTC-USDT","time":1784133307301}}
{"topic":"/market/level2:BTC-USDT","type":"message","subject":"trade.l2update","data":{"changes":{"asks":[],"bids":[["64893.1","0","34557198604"]]},"sequenceEnd":34557198604,"sequenceStart":34557198604,"symbol":"BTC-USDT","time":1784133307301}}
{"topic":"/market/level2:BTC-USDT","type":"message","subject":"trade.l2update","data":{"changes":{"asks":[],"bids":[["64859","0.04856873","34557198605"]]},"sequenceEnd":34557198605,"sequenceStart":34557198605,"symbol":"BTC-USDT","time":1784133307302}}
{"topic":"/market/match:BTC-USDT","type":"message","subject":"trade.l3match","data":{"makerOrderId":"6a5795f497f0810007260363","price":"64960.1","sequence":"23580481663680512","side":"sell","size":"0.00002019","symbol":"BTC-USDT","takerOrderId":"6a57b6bb04683c0007382715","time":"1784133307278000000","tradeId":"23580481663680512","type":"match"}}
{"topic":"/market/level2:BTC-USDT","type":"message","subject":"trade.l2update","data":{"changes":{"asks":[["64953.1","0.2951796","34557198606"],["64986.2","0.00406824","34557198607"]],"bids":[]},"sequenceEnd":34557198607,"sequenceStart":34557198606,"symbol":"BTC-USDT","time":1784133307303}}
{"topic":"/market/level2:BTC-USDT","type":"message","subject":"trade.l2update","data":{"changes":{"asks":[["64990.9","0","34557198608"]],"bids":[]},"sequenceEnd":34557198608,"sequenceStart":34557198608,"symbol":"BTC-USDT","time":1784133307303}}
{"topic":"/market/level2:BTC-USDT","type":"message","subject":"trade.l2update","data":{"changes":{"asks":[["64947.3","0.015294","34557198621"]],"bids":[["64894.4","0","34557198623"],["64936","0.06671505","34557198622"],["64948","0","34557198620"],["64948.5","0","34557198619"],["64948.7","0","34557198618"],["64949","0","34557198617"],["64950.3","0","34557198615"],["64950.9","0","34557198614"],["64951.1","0","34557198613"],["64952","0","34557198612"],["64952.8","0","34557198611"],["64953","0","34557198609"]]},"sequenceEnd":34557198623,"sequenceStart":34557198609,"symbol":"BTC-USDT","time":1784133307303}}
{"topic":"/market/level2:BTC-USDT","type":"message","subject":"trade.l2update","data":{"changes":{"asks":[["64956.3","0.1800094","34557198627"],["64962.5","0.06983806","34557198628"],["64963.7","0","34557198624"],["64984.1","0","34557198629"],["64985","0.11495939","34557198625"]],"bids":[["64932.8","0.0921354","34557198630"]]},"sequenceEnd":34557198630,"sequenceStart":34557198624,"symbol":"BTC-USDT","time":1784133307303}}
{"topic":"/market/level2:BTC-USDT","type":"message","subject":"trade.l2update","data":{"changes":{"asks":[["64953.1","0.475189","34557198631"],["64956.3","0","34557198632"],["65204.7","0","34557198633"]],"bids":[["64859.8","0.000034","34557198634"]]},"sequenceEnd":34557198634,"sequenceStart":34557198631,"symbol":"BTC-USDT","time":1784133307303}}
{"topic":"/market/level2:BTC-USDT","type":"message","subject":"trade.l2update","data":{"changes":{"asks":[],"bids":[["64860.1","0.03302736","34557198635"]]},"sequenceEnd":34557198635,"sequenceStart":34557198635,"symbol":"BTC-USDT","time":1784133307303}}
{"topic":"/market/level2:BTC-USDT","type":"message","subject":"trade.l2update","data":{"changes":{"asks":[],"bids":[["64881.2","0.07139123","34557198637"],["64935.8","0","34557198636"],["64936","0.11944271","34557198638"]]},"sequenceEnd":34557198638,"sequenceStart":34557198636,"symbol":"BTC-USDT","time":1784133307303}}
{"topic":"/market/level2:BTC-USDT","type":"message","subject":"trade.l2update","data":{"changes":{"asks":[],"bids":[["64860.9","0","34557198640"],["64879.6","0.00124034","34557198639"]]},"sequenceEnd":34557198640,"sequenceStart":34557198639,"symbol":"BTC-USDT","time":1784133307304}}
{"topic":"/market/level2:BTC-USDT","type":"message","subject":"trade.l2update","data":{"changes":{"asks":[["65006.5","0.00154083","34557198641"],["65027.5","0","34557198642"]],"bids":[]},"sequenceEnd":34557198642,"sequenceStart":34557198641,"symbol":"BTC-USDT","time":1784133307304}}
{"topic":"/market/level2:BTC-USDT","type":"message","subject":"trade.l2update","data":{"changes":{"asks":[["65008.7","0","34557198644"]],"bids":[["64484.3","0","34557198643"]]},"sequenceEnd":34557198644,"sequenceStart":34557198643,"symbol":"BTC-USDT","time":1784133307304}}
{"topic":"/market/level2:BTC-USDT","type":"message","subject":"trade.l2update","data":{"changes":{"asks":[],"bids":[["64915.6","0.00062017","34557198645"]]},"sequenceEnd":34557198645,"sequenceStart":34557198645,"symbol":"BTC-USDT","time":1784133307304}}
{"topic":"/market/match:BTC-USDT","type":"message","subject":"trade.l3match","data":{"makerOrderId":"6a57acd3a4a7a7000739197c","price":"64959","sequence":"23580481663680513","side":"sell","size":"0.00014","symbol":"BTC-USDT","takerOrderId":"6a57b6bb04683c0007382715","time":"1784133307278000000","tradeId":"23580481663680513","type":"match"}}
{"topic":"/market/level2:BTC-USDT","type":"message","subject":"trade.l2update","data":{"changes":{"asks":[],"bids":[["64893.1","0.05880703","34557198646"]]},"sequenceEnd":34557198646,"sequenceStart":34557198646,"symbol":"BTC-USDT","time":1784133307305}}
{"topic":"/market/level2:BTC-USDT","type":"message","subject":"trade.l2update","data":{"changes":{"asks":[],"bids":[["64622","0.04822984","34557198647"]]},"sequenceEnd":34557198647,"sequenceStart":34557198647,"symbol":"BTC-USDT","time":1784133307305}}
{"topic":"/market/level2:BTC-USDT","type":"message","subject":"trade.l2update","data":{"changes":{"asks":[["65198.7","0.00112796","34557198649"]],"bids":[["64913.2","0","34557198648"],["64932.8","0.29734647","34557198651"],["64935.6","0.0921354","34557198650"]]},"sequenceEnd":34557198651,"sequenceStart":34557198648,"symbol":"BTC-USDT","time":1784133307305}}
{"topic":"/market/level2:BTC-USDT","type":"message","subject":"trade.l2update","data":{"changes":{"asks":[["64966.9","0.11234644","34557198652"]],"bids":[]},"sequenceEnd":34557198652,"sequenceStart":34557198652,"symbol":"BTC-USDT","time":1784133307305}}
{"topic":"/market/level2:BTC-USDT","type":"message","subject":"trade.l2update","data":{"changes":{"asks":[["65077.8","0.00132025","34557198653"]],"bids":[]},"sequenceEnd":34557198653,"sequenceStart":34557198653,"symbol":"BTC-USDT","time":1784133307305}}
{"topic":"/market/level2:BTC-USDT","type":"message","subject":"trade.l2update","data":{"changes":{"asks":[],"bids":[["64932","0.00020672","34557198654"]]},"sequenceEnd":34557198654,"sequenceStart":34557198654,"symbol":"BTC-USDT","time":1784133307306}}
{"topic":"/market/level2:BTC-USDT","type":"message","subject":"trade.l2update","data":{"changes":{"asks":[["65035.8","0","34557198655"]],"bids":[]},"sequenceEnd":34557198655,"sequenceStart":34557198655,"symbol":"BTC-USDT","time":1784133307306}}
{"topic":"/market/level2:BTC-USDT","type":"message","subject":"trade.l2update","data":{"changes":{"asks":[["64971.2","0.1135793","34557198656"]],"bids":[]},"sequenceEnd":34557198656,"sequenceStart":34557198656,"symbol":"BTC-USDT","time":1784133307306}}
{"topic":"/market/level2:BTC-USDT","type":"message","subject":"trade.l2update","data":{"changes":{"asks":[],"bids":[["64863.3","0","34557198657"]]},"sequenceEnd":34557198657,"sequenceStart":34557198657,"symbol":"BTC-USDT","time":1784133307306}}
{"topic":"/market/level2:BTC-USDT","type":"message","subject":"trade.l2update","data":{"changes":{"asks":[["64953.1","0.406629","34557198658"]],"bids":[]},"sequenceEnd":34557198658,"sequenceStart":34557198658,"symbol":"BTC-USDT","time":1784133307306}}
{"topic":"/market/level2:BTC-USDT","type":"message","subject":"trade.l2update","data":{"changes":{"asks":[["64952.9","0","34557198661"],["64954","0","34557198660"]],"bids":[]},"sequenceEnd":34557198661,"sequenceStart":34557198659,"symbol":"BTC-USDT","time":1784133307307}}
{"topic":"/market/level2:BTC-USDT","type":"message","subject":"trade.l2update","data":{"changes":{"asks":[["64951.2","0","34557198663"]],"bids":[]},"sequenceEnd":34557198663,"sequenceStart":34557198662,"symbol":"BTC-USDT","time":1784133307307}}
{"topic":"/market/level2:BTC-USDT","type":"message","subject":"trade.l2update","data":{"changes":{"asks":[["64949.8","0","34557198669"],["64950.4","0","34557198668"],["64951","0","34557198666"]],"bids":[]},"sequenceEnd":34557198669,"sequenceStart":34557198664,"symbol":"BTC-USDT","time":1784133307307}}
{"topic":"/market/level2:BTC-USDT","type":"message","subject":"trade.l2update","data":{"changes":{"asks":[["64947","0.06856","34557198670"],["64969.3","0.03027308","34557198673"]],"bids":[["64942.5","0.04663594","34557198672"],["64945.3","0.0487512","34557198671"]]},"sequenceEnd":34557198673,"sequenceStart":34557198670,"symbol":"BTC-USDT","time":1784133307307}}
{"topic":"/market/level2:BTC-USDT","type":"message","subject":"trade.l2update","data":{"changes":{"asks":[["64967.8","0.04381126","34557198675"],["64984","0.25536013","34557198676"],["64985","0","34557198677"]],"bids":[["64939.7","0.0233757","34557198674"]]},"sequenceEnd":34557198677,"sequenceStart":34557198674,"symbol":"BTC-USDT","time":1784133307307}}
{"topic":"/market/match:BTC-USDT","type":"message","subject":"trade.l3match","data":{"makerOrderId":"6a57acd3d758b50007ecc149","price":"64959","sequence":"23580481663680514","side":"sell","size":"0.00013138","symbol":"BTC-USDT","takerOrderId":"6a57b6bb04683c0007382715","time":"1784133307278000000","tradeId":"23580481663680514","type":"match"}}
{"topic":"/market/level2:BTC-USDT","type":"message","subject":"trade.l2update","data":{"changes":{"asks":[["64953","0.0921354","34557198678"]],"bids":[]},"sequenceEnd":34557198678,"sequenceStart":34557198678,"symbol":"BTC-USDT","time":1784133307307}}
{"topic":"/market/level2:BTC-USDT","type":"message","subject":"trade.l2update","data":{"changes":{"asks":[["64954.7","0.0239824","34557198679"]],"bids":[]},"sequenceEnd":34557198679,"sequenceStart":34557198679,"symbol":"BTC-USDT","time":1784133307308}}
{"topic":"/market/level2:BTC-USDT","type":"message","subject":"trade.l2update","data":{"changes":{"asks":[["64954.7","0.07244595","34557198682"]],"bids":[]},"sequenceEnd":34557198682,"sequenceStart":34557198680,"symbol":"BTC-USDT","time":1784133307308}}
{"topic":"/market/level2:BTC-USDT","type":"message","subject":"trade.l2update","data":{"changes":{"asks":[["64953.1","0.39662903","34557198683"]],"bids":[]},"sequenceEnd":34557198683,"sequenceStart":34557198683,"symbol":"BTC-USDT","time":1784133307308}}
{"topic":"/market/level2:BTC-USDT","type":"message","subject":"trade.l2update","data":{"changes":{"asks":[],"bids":[["64928.5","0.08885525","34557198684"]]},"sequenceEnd":34557198684,"sequenceStart":34557198684,"symbol":"BTC-USDT","time":1784133307308}}
{"topic":"/market/level2:BTC-USDT","type":"message","subject":"trade.l2update","data":{"changes":{"asks":[],"bids":[["64936","0.05273979","34557198685"]]},"sequenceEnd":34557198685,"sequenceStart":34557198685,"symbol":"BTC-USDT","time":1784133307308}}
{"topic":"/market/level2:BTC-USDT","type":"message","subject":"trade.l2update","data":{"changes":{"asks":[["65027.4","0","34557198686"]],"bids":[]},"sequenceEnd":34557198686,"sequenceStart":34557198686,"symbol":"BTC-USDT","time":1784133307308}}
{"topic":"/market/level2:BTC-USDT","type":"message","subject":"trade.l2update","data":{"changes":{"asks":[],"bids":[["64936","0.00001213","34557198687"]]},"sequenceEnd":34557198687,"sequenceStart":34557198687,"symbol":"BTC-USDT","time":1784133307308}}
{"topic":"/market/level2:BTC-USDT","type":"message","subject":"trade.l2update","data":{"changes":{"asks":[],"bids":[["64916.2","0","34557198688"]]},"sequenceEnd":34557198688,"sequenceStart":34557198688,"symbol":"BTC-USDT","time":1784133307309}}
{"topic":"/market/level2:BTC-USDT","type":"message","subject":"trade.l2update","data":{"changes":{"asks":[],"bids":[["64936","0.03921263","34557198689"]]},"sequenceEnd":34557198689,"sequenceStart":34557198689,"symbol":"BTC-USDT","time":1784133307309}}
{"topic":"/market/level2:BTC-USDT","type":"message","subject":"trade.l2update","data":{"changes":{"asks":[],"bids":[["64928.4","0.20521107","34557198690"]]},"sequenceEnd":34557198690,"sequenceStart":34557198690,"symbol":"BTC-USDT","time":1784133307309}}
{"topic":"/market/level2:BTC-USDT","type":"message","subject":"trade.l2update","data":{"changes":{"asks":[["64956.3","0.0208704","34557198691"]],"bids":[]},"sequenceEnd":34557198691,"sequenceStart":34557198691,"symbol":"BTC-USDT","time":1784133307309}}
{"topic":"/market/level2:BTC-USDT","type":"message","subject":"trade.l2update","data":{"changes":{"asks":[["64947","0.06807659","34557198692"]],"bids":[]},"sequenceEnd":34557198692,"sequenceStart":34557198692,"symbol":"BTC-USDT","time":1784133307309}}
{"topic":"/market/level2:BTC-USDT","type":"message","subject":"trade.l2update","data":{"changes":{"asks":[["64977.7","0.0198309","34557198693"]],"bids":[]},"sequenceEnd":34557198693,"sequenceStart":34557198693,"symbol":"BTC-USDT","time":1784133307309}}
{"topic":"/market/level2:BTC-USDT","type":"message","subject":"trade.l2update","data":{"changes":{"asks":[["64970.3","0.0076","34557198694"]],"bids":[]},"sequenceEnd":34557198694,"sequenceStart":34557198694,"symbol":"BTC-USDT","time":1784133307310}}
{"topic":"/market/level2:BTC-USDT","type":"message","subject":"trade.l2update","data":{"changes":{"asks":[["64975.2","0.06343226","34557198695"],["64986.5","0.0076","34557198696"]],"bids":[]},"sequenceEnd":34557198696,"sequenceStart":34557198695,"symbol":"BTC-USDT","time":1784133307310}}
{"topic":"/market/match:BTC-USDT","type":"message","subject":"trade.l3match","data":{"makerOrderId":"6a579ab43dc28400075fce4f","price":"64958","sequence":"23580481663680515","side":"sell","size":"0.00002379","symbol":"BTC-USDT","takerOrderId":"6a57b6bb04683c0007382715","time":"1784133307278000000","tradeId":"23580481663680515","type":"match"}}
{"topic":"/market/level2:BTC-USDT","type":"message","subject":"trade.l2update","data":{"changes":{"asks":[],"bids":[["64945.9","0","34557198697"]]},"sequenceEnd":34557198697,"sequenceStart":34557198697,"symbol":"BTC-USDT","time":1784133307311}}
{"topic":"/market/level2:BTC-USDT","type":"message","subject":"trade.l2update","data":{"changes":{"asks":[],"bids":[["64893.1","0","34557198698"]]},"sequenceEnd":34557198698,"sequenceStart":34557198698,"symbol":"BTC-USDT","time":1784133307311}}
{"topic":"/market/level2:BTC-USDT","type":"message","subject":"trade.l2update","data":{"changes":{"asks":[["64993.5","0","34557198700"]],"bids":[["64893.2","0.12007504","34557198699"]]},"sequenceEnd":34557198700,"sequenceStart":34557198699,"symbol":"BTC-USDT","time":1784133307311}}
{"topic":"/market/level2:BTC-USDT","type":"message","subject":"trade.l2update","data":{"changes":{"asks":[],"bids":[["64701.9","0.0033175","34557198701"]]},"sequenceEnd":34557198701,"sequenceStart":34557198701,"symbol":"BTC-USDT","time":1784133307311}}
{"topic":"/market/level2:BTC-USDT","type":"message","subject":"trade.l2update","data":{"changes":{"asks":[["65065.6","0","34557198703"]],"bids":[["64900.8","0.07139123","34557198702"]]},"sequenceEnd":34557198703,"sequenceStart":34557198702,"symbol":"BTC-USDT","time":1784133307311}}
{"topic":"/market/level2:BTC-USDT","type":"message","subject":"trade.l2update","data":{"changes":{"asks":[["65031.8","0.0144326","34557198704"]],"bids":[]},"sequenceEnd":34557198704,"sequenceStart":34557198704,"symbol":"BTC-USDT","time":1784133307311}}
{"topic":"/market/level2:BTC-USDT","type":"message","subject":"trade.l2update","data":{"changes":{"asks":[["64960.2","0.1183033","34557198705"]],"bids":[]},"sequenceEnd":34557198705,"sequenceStart":34557198705,"symbol":"BTC-USDT","time":1784133307311}}
{"topic":"/market/level2:BTC-USDT","type":"message","subject":"trade.l2update","data":{"changes":{"asks":[["64973.4","0.02408687","34557198706"]],"bids":[]},"sequenceEnd":34557198706,"sequenceStart":34557198706,"symbol":"BTC-USDT","time":1784133307312}}
{"topic":"/market/level2:BTC-USDT","type":"message","subject":"trade.l2update","data":{"changes":{"asks":[["64981.8","0","34557198707"]],"bids":[]},"sequenceEnd":34557198707,"sequenceStart":34557198707,"symbol":"BTC-USDT","time":1784133307312}}
{"topic":"/market/level2:BTC-USDT","type":"message","subject":"trade.l2update","data":{"changes":{"asks":[],"bids":[["64845","0.0164426","34557198708"]]},"sequenceEnd":34557198708,"sequenceStart":34557198708,"symbol":"BTC-USDT","time":1784133307312}}
{"topic":"/market/level2:BTC-USDT","type":"message","subject":"trade.l2update","data":{"changes":{"asks":[["64947","0.17157659","34557198709"]],"bids":[]},"sequenceEnd":34557198709,"sequenceStart":34557198709,"symbol":"BTC-USDT","time":1784133307312}}
{"topic":"/market/match:BTC-USDT","type":"message","subject":"trade.l3match","data":{"makerOrderId":"6a579a4804683c0007e745da","price":"64957.2","sequence":"23580481663680516","side":"sell","size":"0.00001664","symbol":"BTC-USDT","takerOrderId":"6a57b6bb04683c0007382715","time":"1784133307278000000","tradeId":"23580481663680516","type":"match"}}
{"topic":"/market/level2:BTC-USDT","type":"message","subject":"trade.l2update","data":{"changes":{"asks":[["64947","0.22013976","34557198711"],["64953.1","0.36548493","34557198712"]],"bids":[["64893.2","0.17888207","34557198713"]]},"sequenceEnd":34557198713,"sequenceStart":34557198710,"symbol":"BTC-USDT","time":1784133307312}}
{"topic":"/market/level2:BTC-USDT","type":"message","subject":"trade.l2update","data":{"changes":{"asks":[],"bids":[["64893.2","0.05881953","34557198714"],["64932.7","0","34557198716"],["64942","0.01525406","34557198715"]]},"sequenceEnd":34557198716,"sequenceStart":34557198714,"symbol":"BTC-USDT","time":1784133307312}}
{"topic":"/market/level2:BTC-USDT","type":"message","subject":"trade.l2update","data":{"changes":{"asks":[],"bids":[["64896","0.00012663","34557198717"]]},"sequenceEnd":34557198717,"sequenceStart":34557198717,"symbol":"BTC-USDT","time":1784133307313}}
{"topic":"/market/level2:BTC-USDT","type":"message","subject":"trade.l2update","data":{"changes":{"asks":[["65199.1","0","34557198718"]],"bids":[["64726.6","0","34557198719"]]},"sequenceEnd":34557198719,"sequenceStart":34557198718,"symbol":"BTC-USDT","time":1784133307313}}
{"topic":"/market/level2:BTC-USDT","type":"message","subject":"trade.l2update","data":{"changes":{"asks":[["64977.6","0.37752375","34557198721"],["65039.2","0","34557198720"]],"bids":[]},"sequenceEnd":34557198721,"sequenceStart":34557198720,"symbol":"BTC-USDT","time":1784133307313}}
{"topic":"/market/level2:BTC-USDT","type":"message","subject":"trade.l2update","data":{"changes":{"asks":[],"bids":[["64896","0.02424155","34557198722"]]},"sequenceEnd":34557198722,"sequenceStart":34557198722,"symbol":"BTC-USDT","time":1784133307314}}
{"topic":"/market/level2:BTC-USDT","type":"message","subject":"trade.l2update","data":{"changes":{"asks":[["64960","0.0479648","34557198724"],["64960.2","0.1073568","34557198723"]],"bids":[]},"sequenceEnd":34557198724,"sequenceStart":34557198723,"symbol":"BTC-USDT","time":1784133307314}}
{"topic":"/market/level2:BTC-USDT","type":"message","subject":"trade.l2update","data":{"changes":{"asks":[["64960","0","34557198726"]],"bids":[]},"sequenceEnd":34557198726,"sequenceStart":34557198725,"symbol":"BTC-USDT","time":1784133307314}}
{"topic":"/market/level2:BTC-USDT","type":"message","subject":"trade.l2update","data":{"changes":{"asks":[["64947","0.23013973","34557198727"],["64953.1","0.2988034","34557198728"]],"bids":[]},"sequenceEnd":34557198728,"sequenceStart":34557198727,"symbol":"BTC-USDT","time":1784133307314}}
{"topic":"/market/level2:BTC-USDT","type":"message","subject":"trade.l2update","data":{"changes":{"asks":[["64947","0.27235414","34557198729"],["64947.3","0","34557198730"],["64953.1","0.1953034","34557198733"]],"bids":[["64845","0","34557198735"],["64879.9","0.00181169","34557198731"],["64932.9","0.06124722","34557198732"],["64946.9","0.10533883","34557198734"]]},"sequenceEnd":34557198735,"sequenceStart":34557198729,"symbol":"BTC-USDT","time":1784133307314}}
{"topic":"/market/level2:BTC-USDT","type":"message","subject":"trade.l2update","data":{"changes":{"asks":[["64947","0.27453064","34557198738"],["64957.1","0.0921354","34557198736"],["65006.5","0.00308171","34557198741"],["65047.4","0.00868858","34557198737"]],"bids":[["64662.8","0.1035","34557198739"],["64843.9","0.00872166","34557198740"]]},"sequenceEnd":34557198741,"sequenceStart":34557198736,"symbol":"BTC-USDT","time":1784133307314}}
{"topic":"/market/level2:BTC-USDT","type":"message","subject":"trade.l2update","data":{"changes":{"asks":[["64959.7","0.0554411","34557198743"],["64977.6","0","34557198744"],["65006.5","0.00154083","34557198742"]],"bids":[]},"sequenceEnd":34557198744,"sequenceStart":34557198742,"symbol":"BTC-USDT","time":1784133307314}}
{"topic":"/market/level2:BTC-USDT","type":"message","subject":"trade.l2update","data":{"changes":{"asks":[["64984","0.14389451","34557198749"]],"bids":[["64881.3","0.05287998","34557198745"],["64936","0.06170334","34557198746"],["64946.9","0.20533883","34557198748"]]},"sequenceEnd":34557198749,"sequenceStart":34557198745,"symbol":"BTC-USDT","time":1784133307315}}
{"topic":"/market/match:BTC-USDT","type":"message","subject":"trade.l3match","data":{"makerOrderId":"6a57b4e597f08100077fe2a7","price":"64956.2","sequence":"23580481695793152","side":"sell","size":"0.0001582","symbol":"BTC-USDT","takerOrderId":"6a57b6bbdff4b50007d4595a","time":"1784133307291000000","tradeId":"23580481695793152","type":"match"}}
{"topic":"/market/level2:BTC-USDT","type":"message","subject":"trade.l2update","data":{"changes":{"asks":[["64958.1","0.00308205","34557198750"]],"bids":[]},"sequenceEnd":34557198750,"sequenceStart":34557198750,"symbol":"BTC-USDT","time":1784133307315}}
{"topic":"/market/level2:BTC-USDT","type":"message","subject":"trade.l2update","data":{"changes":{"asks":[["64958.1","0","34557198751"]],"bids":[]},"sequenceEnd":34557198751,"sequenceStart":34557198751,"symbol":"BTC-USDT","time":1784133307315}}
{"topic":"/market/level2:BTC-USDT","type":"message","subject":"trade.l2update","data":{"changes":{"asks":[["64999.3","0","34557198752"]],"bids":[]},"sequenceEnd":34557198752,"sequenceStart":34557198752,"symbol":"BTC-USDT","time":1784133307315}}
{"topic":"/market/level2:BTC-USDT","type":"message","subject":"trade.l2update","data":{"changes":{"asks":[],"bids":[["64932.9","0.11506442","34557198753"]]},"sequenceEnd":34557198753,"sequenceStart":34557198753,"symbol":"BTC-USDT","time":1784133307316}}
{"topic":"/market/level2:BTC-USDT","type":"message","subject":"trade.l2update","data":{"changes":{"asks":[["65035.8","0.01631689","34557198755"],["65148","0.00154062","34557198754"]],"bids":[]},"sequenceEnd":34557198755,"sequenceStart":34557198754,"symbol":"BTC-USDT","time":1784133307316}}
{"topic":"/market/level2:BTC-USDT","type":"message","subject":"trade.l2update","data":{"changes":{"asks":[["65006.5","0","34557198756"]],"bids":[["64946.9","0.10183883","34557198757"]]},"sequenceEnd":34557198757,"sequenceStart":34557198756,"symbol":"BTC-USDT","time":1784133307316}}
{"topic":"/market/level2:BTC-USDT","type":"message","subject":"trade.l2update","data":{"changes":{"asks":[["64999.1","0.0015409","34557198758"]],"bids":[]},"sequenceEnd":34557198758,"sequenceStart":34557198758,"symbol":"BTC-USDT","time":1784133307316}}
{"topic":"/market/level2:BTC-USDT","type":"message","subject":"trade.l2update","data":{"changes":{"asks":[["64987.4","0","34557198759"]],"bids":[]},"sequenceEnd":34557198759,"sequenceStart":34557198759,"symbol":"BTC-USDT","time":1784133307316}}
{"topic":"/market/level2:BTC-USDT","type":"message","subject":"trade.l2update","data":{"changes":{"asks":[["64986.3","0.05194164","34557198760"]],"bids":[]},"sequenceEnd":34557198760,"sequenceStart":34557198760,"symbol":"BTC-USDT","time":1784133307316}}
{"topic":"/market/level2:BTC-USDT","type":"message","subject":"trade.l2update","data":{"changes":{"asks":[["64973.7","0.37754703","34557198761"]],"bids":[]},"sequenceEnd":34557198761,"sequenceStart":34557198761,"symbol":"BTC-USDT","time":1784133307316}}
