{"success":true,"ret_msg":"subscribe","conn_id":"d9avrremonceh80v85sg-4vx3","op":"subscribe"}
{"topic":"orderbook.50.BTCUSDT","ts":1784086810276,"type":"snapshot","data":{"s":"BTCUSDT","b":[["64640.9","1.166365"],["64640.6","0.020615"],["64640.5","0.229246"],["64639.8","0.196716"],["64639.7","0.00036"],["64636.7","0.017545"],["64636.6","0.018586"],["64634.8","0.038692"],["64634.1","0.0015"],["64631.9","0.000117"],["64630.8","0.084772"],["64630.7","0.166993"],["64630.6","0.226898"],["64629.9","0.003094"],["64629","0.068364"],["64628.9","0.091386"],["64628.5","0.001241"],["64628","0.002"],["64627.5","0.037129"],["64627.3","0.136398"],["64626.2","0.06445"],["64625.8","0.063853"],["64625.7","0.097703"],["64625.4","0.000117"],["64624.4","0.116092"],["64623.8","0.022656"],["64623.7","0.03"],["64623.4","0.005"],["64622.3","0.001241"],["64622","0.039658"],["64620.4","0.039488"],["64620.3","0.02"],["64620.2","0.056865"],["64620.1","0.116092"],["64619.2","0.0619"],["64618.9","0.000117"],["64617.9","0.003434"],["64616.7","0.210371"],["64616.6","0.514702"],["64616.1","0.001241"],["64615.3","0.037129"],["64615.1","0.116092"],["64614.2","0.855551"],["64614","0.05"],["64612.4","0.000117"],["64612.3","0.037129"],["64612.2","0.284609"],["64611.9","2.526296"],["64611.6","0.001391"],["64610.9","0.018586"]],"a":[["64641","0.043841"],["64641.7","0.004205"],["64643.3","0.038697"],["64644.3","0.000117"],["64644.7","0.000117"],["64645.8","0.005"],["64647.1","0.161741"],["64647.2","0.118241"],["64647.5","0.031905"],["64647.6","0.091703"],["64647.8","0.038692"],["64649.2","0.097668"],["64649.3","0.03"],["64649.4","0.004258"],["64649.5","0.003763"],["64649.8","0.002336"],["64650.4","0.116092"],["64650.5","0.074009"],["64650.8","0.098775"],["64651.2","0.000117"],["64651.4","0.002126"],["64652","0.003093"],["64652.3","0.092927"],["64652.8","0.001"],["64653.2","0.037129"],["64653.3","0.028933"],["64653.4","0.001241"],["64653.6","0.07973"],["64653.7","0.117"],["64653.9","0.001"],["64654.5","0.148366"],["64654.8","0.0015"],["64654.9","0.02"],["64656.3","0.047964"],["64656.6","0.03"],["64656.7","0.012309"],["64657.7","0.000117"],["64658.5","0.116092"],["64659.6","0.001241"],["64660.4","0.037129"],["64660.5","0.206406"],["64660.6","0.117"],["64661.1","0.509352"],["64661.6","0.002165"],["64662.3","0.089658"],["64663.5","0.125313"],["64664.2","0.000117"],["64664.4","0.116092"],["64665.2","0.037129"],["64665.3","0.284626"]],"u":128530587,"seq":111455881321},"cts":1784086810273}
{"topic":"orderbook.50.BTCUSDT","ts":1784086810296,"type":"delta","data":{"s":"BTCUSDT","b":[["64640.6","0"],["64640.5","0.117"],["64617.6","0.012553"]],"a":[["64650.4","0"],["64652.3","0"],["64653.2","0"],["64665.5","0.033832"],["64665.8","0.001241"],["64666.2","0.058047"]],"u":128530588,"seq":111455881390},"cts":1784086810294}
{"topic":"orderbook.50.BTCUSDT","ts":1784086810316,"type":"delta","data":{"s":"BTCUSDT","b":[["64640.9","1.167135"],["64639.9","0.002052"],["64610.9","0"]],"a":[["64641","0.051571"],["64650.5","0.031376"],["64653.5","0.037129"],["64666.2","0"]],"u":128530589,"seq":111455881445},"cts":1784086810315}
{"topic":"orderbook.50.BTCUSDT","ts":1784086810336,"type":"delta","data":{"s":"BTCUSDT","b":[["64640.9","1.200468"],["64631.1","0.003094"],["64629.9","0"]],"a":[],"u":128530590,"seq":111455881528},"cts":1784086810334}
{"topic":"orderbook.50.BTCUSDT","ts":1784086810356,"type":"delta","data":{"s":"BTCUSDT","b":[["64640.9","1.202778"],["64628.1","0.012"],["64611.6","0"]],"a":[["64641","0.063161"]],"u":128530591,"seq":111455881575},"cts":1784086810354}
{"topic":"orderbook.50.BTCUSDT","ts":1784086810375,"type":"delta","data":{"s":"BTCUSDT","b":[["64639.8","0.193088"],["64639.7","0"],["64614.1","2.50623"],["64611.9","0.02"]],"a":[],"u":128530592,"seq":111455881652},"cts":1784086810374}
{"topic":"orderbook.50.BTCUSDT","ts":1784086810396,"type":"delta","data":{"s":"BTCUSDT","b":[["64640.9","1.203548"],["64640.5","0"],["64639.8","0.076088"],["64611.6","0.001391"]],"a":[],"u":128530593,"seq":111455881682},"cts":1784086810392}
{"topic":"orderbook.50.BTCUSDT","ts":1784086810416,"type":"delta","data":{"s":"BTCUSDT","b":[["64640.9","1.204318"],["64640.8","0.000335"],["64611.6","0"]],"a":[["64653.5","0"],["64666.2","0.058047"]],"u":128530594,"seq":111455881725},"cts":1784086810414}
{"topic":"orderbook.50.BTCUSDT","ts":1784086810436,"type":"delta","data":{"s":"BTCUSDT","b":[["64640.9","1.203548"]],"a":[["64641","0.043841"],["64650.4","0.152861"],["64666.2","0"]],"u":128530595,"seq":111455881763},"cts":1784086810434}
{"topic":"orderbook.50.BTCUSDT","ts":1784086810456,"type":"delta","data":{"s":"BTCUSDT","b":[["64640.9","1.203626"]],"a":[["64650.3","0.077005"],["64650.5","0"]],"u":128530596,"seq":111455881781},"cts":1784086810452}
{"topic":"orderbook.50.BTCUSDT","ts":1784086810476,"type":"delta","data":{"s":"BTCUSDT","b":[["64640.9","1.211356"],["64639.8","0.051288"]],"a":[],"u":128530597,"seq":111455881796},"cts":1784086810471}
{"topic":"orderbook.50.BTCUSDT","ts":1784086810496,"type":"delta","data":{"s":"BTCUSDT","b":[["64640.9","1.226738"]],"a":[["64652","0"],["64654","0.003093"]],"u":128530598,"seq":111455881813},"cts":1784086810491}
{"topic":"orderbook.50.BTCUSDT","ts":1784086810516,"type":"delta","data":{"s":"BTCUSDT","b":[["64640.9","1.230598"]],"a":[],"u":128530599,"seq":111455881833},"cts":1784086810512}
{"topic":"orderbook.50.BTCUSDT","ts":1784086810536,"type":"delta","data":{"s":"BTCUSDT","b":[["64640.9","1.246828"]],"a":[],"u":128530600,"seq":111455881853},"cts":1784086810533}
{"topic":"orderbook.50.BTCUSDT","ts":1784086810556,"type":"delta","data":{"s":"BTCUSDT","b":[["64640.9","1.243748"]],"a":[],"u":128530601,"seq":111455881879},"cts":1784086810553}
{"topic":"orderbook.50.BTCUSDT","ts":1784086810576,"type":"delta","data":{"s":"BTCUSDT","b":[["64640.9","1.22655"]],"a":[["64654.1","0.107943"],["64665.8","0"]],"u":128530602,"seq":111455881894},"cts":1784086810562}
{"topic":"orderbook.50.BTCUSDT","ts":1784086810596,"type":"delta","data":{"s":"BTCUSDT","b":[["64640.9","1.20723"]],"a":[["64653.2","0.037129"],["64665.5","0"]],"u":128530603,"seq":111455881902},"cts":1784086810592}
{"topic":"orderbook.50.BTCUSDT","ts":1784086810616,"type":"delta","data":{"s":"BTCUSDT","b":[["64640.9","1.208547"]],"a":[],"u":128530604,"seq":111455881910},"cts":1784086810615}
{"topic":"orderbook.50.BTCUSDT","ts":1784086810636,"type":"delta","data":{"s":"BTCUSDT","b":[["64640.9","1.210087"]],"a":[],"u":128530605,"seq":111455881921},"cts":1784086810634}
{"topic":"orderbook.50.BTCUSDT","ts":1784086810655,"type":"delta","data":{"s":"BTCUSDT","b":[["64640.9","1.234347"]],"a":[],"u":128530606,"seq":111455881935},"cts":1784086810654}
{"topic":"orderbook.50.BTCUSDT","ts":1784086810675,"type":"delta","data":{"s":"BTCUSDT","b":[["64640.9","1.243617"]],"a":[],"u":128530607,"seq":111455881953},"cts":1784086810674}
{"topic":"orderbook.50.BTCUSDT","ts":1784086810696,"type":"delta","data":{"s":"BTCUSDT","b":[["64640.9","1.245157"],["64639.5","0.0258"],["64611.9","0"]],"a":[["64656.7","0"],["64665.5","0.033832"]],"u":128530608,"seq":111455881972},"cts":1784086810692}
{"topic":"orderbook.50.BTCUSDT","ts":1784086810716,"type":"delta","data":{"s":"BTCUSDT","b":[["64640.9","1.235577"],["64639.9","0.025063"],["64614.1","0"],["64611.9","0.02"]],"a":[],"u":128530609,"seq":111455882013},"cts":1784086810713}
{"topic":"orderbook.50.BTCUSDT","ts":1784086810735,"type":"delta","data":{"s":"BTCUSDT","b":[["64640.9","1.220897"],["64614.2","0.117384"]],"a":[],"u":128530610,"seq":111455882040},"cts":1784086810731}
{"topic":"orderbook.50.BTCUSDT","ts":1784086810755,"type":"delta","data":{"s":"BTCUSDT","b":[["64640.9","1.211627"],["64639.8","0.080705"],["64634.8","0.070747"],["64631.2","0.003094"],["64631.1","0"],["64621.1","0.028995"],["64611.9","0"]],"a":[],"u":128530611,"seq":111455882072},"cts":1784086810754}
{"topic":"orderbook.50.BTCUSDT","ts":1784086810776,"type":"delta","data":{"s":"BTCUSDT","b":[["64640.9","1.209317"],["64616.3","2.50542"],["64612.2","0"]],"a":[],"u":128530612,"seq":111455882108},"cts":1784086810775}
{"topic":"orderbook.50.BTCUSDT","ts":1784086810796,"type":"delta","data":{"s":"BTCUSDT","b":[["64640.9","1.210857"],["64616.7","0.920718"]],"a":[],"u":128530613,"seq":111455882119},"cts":1784086810794}
{"topic":"orderbook.50.BTCUSDT","ts":1784086810816,"type":"delta","data":{"s":"BTCUSDT","b":[["64640.9","1.214707"]],"a":[],"u":128530614,"seq":111455882127},"cts":1784086810811}
{"topic":"orderbook.50.BTCUSDT","ts":1784086810836,"type":"delta","data":{"s":"BTCUSDT","b":[["64640.9","1.217017"],["64639.5","0"],["64612.2","0.284609"]],"a":[],"u":128530615,"seq":111455882134},"cts":1784086810835}
{"topic":"orderbook.50.BTCUSDT","ts":1784086810856,"type":"delta","data":{"s":"BTCUSDT","b":[["64640.9","1.218557"]],"a":[],"u":128530616,"seq":111455882146},"cts":1784086810854}
{"topic":"orderbook.50.BTCUSDT","ts":1784086810876,"type":"delta","data":{"s":"BTCUSDT","b":[["64640.9","1.213937"]],"a":[],"u":128530617,"seq":111455882159},"cts":1784086810873}
{"topic":"orderbook.50.BTCUSDT","ts":1784086810896,"type":"delta","data":{"s":"BTCUSDT","b":[["64640.9","1.213167"]],"a":[],"u":128530618,"seq":111455882172},"cts":1784086810889}
{"topic":"orderbook.50.BTCUSDT","ts":1784086810916,"type":"delta","data":{"s":"BTCUSDT","b":[["64640.9","1.210087"]],"a":[],"u":128530619,"seq":111455882183},"cts":1784086810912}
{"topic":"orderbook.50.BTCUSDT","ts":1784086810936,"type":"delta","data":{"s":"BTCUSDT","b":[["64640.9","1.209317"],["64639.5","0.0258"],["64612.2","0"]],"a":[["64641.9","0.004134"],["64665.5","0"]],"u":128530620,"seq":111455882193},"cts":1784086810932}
{"topic":"orderbook.50.BTCUSDT","ts":1784086810956,"type":"delta","data":{"s":"BTCUSDT","b":[["64640.9","1.213937"]],"a":[],"u":128530621,"seq":111455882202},"cts":1784086810949}
{"topic":"orderbook.50.BTCUSDT","ts":1784086810976,"type":"delta","data":{"s":"BTCUSDT","b":[["64640.9","1.213167"],["64616.3","0"],["64614.1","2.50542"]],"a":[],"u":128530622,"seq":111455882206},"cts":1784086810972}
{"topic":"orderbook.50.BTCUSDT","ts":1784086810996,"type":"delta","data":{"s":"BTCUSDT","b":[["64640.9","1.214707"],["64616.7","0.210371"],["64614.2","0.850244"]],"a":[],"u":128530623,"seq":111455882212},"cts":1784086810992}
{"topic":"orderbook.50.BTCUSDT","ts":1784086811018,"type":"delta","data":{"s":"BTCUSDT","b":[["64640.9","1.217017"]],"a":[["64643.8","0.005512"],["64661","0.038436"],["64665.2","0"],["64665.3","0"]],"u":128530624,"seq":111455882224},"cts":1784086811014}
{"topic":"orderbook.50.BTCUSDT","ts":1784086811036,"type":"delta","data":{"s":"BTCUSDT","b":[["64640.9","0.889317"],["64639.8","0.060705"],["64639.5","0"],["64630.7","0.05"],["64612.2","0.284609"]],"a":[["64641","0.192041"],["64649","0.146575"],["64650.4","0"]],"u":128530625,"seq":111455882283},"cts":1784086811033}
{"topic":"orderbook.50.BTCUSDT","ts":1784086811056,"type":"delta","data":{"s":"BTCUSDT","b":[["64638.1","0.02823"],["64628.1","0"]],"a":[["64641.7","0"],["64646.1","0.030315"],["64647.5","0"],["64650.3","0.030452"],["64665.2","0.037129"]],"u":128530626,"seq":111455882310},"cts":1784086811055}
{"topic":"orderbook.50.BTCUSDT","ts":1784086811076,"type":"delta","data":{"s":"BTCUSDT","b":[["64640.9","0.886237"]],"a":[],"u":128530627,"seq":111455882321},"cts":1784086811072}
{"topic":"orderbook.50.BTCUSDT","ts":1784086811096,"type":"delta","data":{"s":"BTCUSDT","b":[["64631.8","0.003094"],["64631.2","0"]],"a":[["64641","0.193691"],["64645.8","0.011891"],["64646.6","0.001547"],["64665.2","0"]],"u":128530628,"seq":111455882331},"cts":1784086811092}
{"topic":"orderbook.50.BTCUSDT","ts":1784086811136,"type":"delta","data":{"s":"BTCUSDT","b":[["64639.5","0.0258"],["64612.2","0"]],"a":[],"u":128530629,"seq":111455882350},"cts":1784086811134}
{"topic":"orderbook.50.BTCUSDT","ts":1784086811156,"type":"delta","data":{"s":"BTCUSDT","b":[["64640.9","0.888547"]],"a":[["64643.6","0.039297"],["64647.7","0.008269"],["64664.2","0"],["64664.4","0"]],"u":128530630,"seq":111455882362},"cts":1784086811152}
{"topic":"orderbook.50.BTCUSDT","ts":1784086811176,"type":"delta","data":{"s":"BTCUSDT","b":[["64640.9","0.889317"]],"a":[],"u":128530631,"seq":111455882367},"cts":1784086811166}
{"topic":"orderbook.50.BTCUSDT","ts":1784086811196,"type":"delta","data":{"s":"BTCUSDT","b":[["64640.9","0.890087"]],"a":[["64641","0.195341"],["64647.1","0.295941"],["64649","0"],["64653","0.003093"],["64654","0"],["64664.2","0.000117"]],"u":128530632,"seq":111455882374},"cts":1784086811193}
{"topic":"orderbook.50.BTCUSDT","ts":1784086811216,"type":"delta","data":{"s":"BTCUSDT","b":[["64640.9","0.889317"]],"a":[],"u":128530633,"seq":111455882377},"cts":1784086811203}
{"topic":"orderbook.50.BTCUSDT","ts":1784086811236,"type":"delta","data":{"s":"BTCUSDT","b":[["64640.9","0.885467"]],"a":[],"u":128530634,"seq":111455882387},"cts":1784086811232}
{"topic":"orderbook.50.BTCUSDT","ts":1784086811255,"type":"delta","data":{"s":"BTCUSDT","b":[["64640.9","0.886237"],["64618.1","0.003434"],["64617.9","0"]],"a":[["64641","0.164141"]],"u":128530635,"seq":111455882398},"cts":1784086811255}
{"topic":"orderbook.50.BTCUSDT","ts":1784086811276,"type":"delta","data":{"s":"BTCUSDT","b":[["64640.9","0.885467"]],"a":[["64641","0.165791"]],"u":128530636,"seq":111455882400},"cts":1784086811267}
{"topic":"orderbook.50.BTCUSDT","ts":1784086811316,"type":"delta","data":{"s":"BTCUSDT","b":[["64640.9","0.888547"]],"a":[],"u":128530637,"seq":111455882415},"cts":1784086811312}
{"topic":"orderbook.50.BTCUSDT","ts":1784086811336,"type":"delta","data":{"s":"BTCUSDT","b":[["64640.9","0.889317"]],"a":[],"u":128530638,"seq":111455882418},"cts":1784086811333}
{"topic":"orderbook.50.BTCUSDT","ts":1784086811356,"type":"delta","data":{"s":"BTCUSDT","b":[["64640.9","0.890087"]],"a":[["64646.8","0.133208"],["64647.1","0.161741"],["64664.2","0"]],"u":128530639,"seq":111455882422},"cts":1784086811354}
{"topic":"orderbook.50.BTCUSDT","ts":1784086811376,"type":"delta","data":{"s":"BTCUSDT","b":[["64640.9","0.887777"],["64639.5","0"],["64612.2","0.284609"]],"a":[],"u":128530640,"seq":111455882433},"cts":1784086811374}
{"topic":"orderbook.50.BTCUSDT","ts":1784086811396,"type":"delta","data":{"s":"BTCUSDT","b":[["64640.9","0.886237"]],"a":[],"u":128530641,"seq":111455882439},"cts":1784086811389}
{"topic":"orderbook.50.BTCUSDT","ts":1784086811416,"type":"delta","data":{"s":"BTCUSDT","b":[["64640.9","0.885467"],["64625.1","0.284653"],["64612.2","0"]],"a":[],"u":128530642,"seq":111455882445},"cts":1784086811411}
{"topic":"orderbook.50.BTCUSDT","ts":1784086811436,"type":"delta","data":{"s":"BTCUSDT","b":[["64625.8","0.140658"]],"a":[],"u":128530643,"seq":111455882453},"cts":1784086811430}
{"topic":"orderbook.50.BTCUSDT","ts":1784086811456,"type":"delta","data":{"s":"BTCUSDT","b":[["64640.9","0.887777"]],"a":[],"u":128530644,"seq":111455882459},"cts":1784086811447}
{"topic":"orderbook.50.BTCUSDT","ts":1784086811476,"type":"delta","data":{"s":"BTCUSDT","b":[["64640.9","0.887007"]],"a":[],"u":128530645,"seq":111455882460},"cts":1784086811470}
{"topic":"orderbook.50.BTCUSDT","ts":1784086811496,"type":"delta","data":{"s":"BTCUSDT","b":[["64640.9","0.887777"]],"a":[["64641","0.162491"]],"u":128530646,"seq":111455882466},"cts":1784086811488}
{"topic":"orderbook.50.BTCUSDT","ts":1784086811516,"type":"delta","data":{"s":"BTCUSDT","b":[["64640.9","0.889317"]],"a":[],"u":128530647,"seq":111455882468},"cts":1784086811512}
{"topic":"orderbook.50.BTCUSDT","ts":1784086811536,"type":"delta","data":{"s":"BTCUSDT","b":[["64640.9","0.886237"]],"a":[["64641","0.160841"]],"u":128530648,"seq":111455882478},"cts":1784086811533}
{"topic":"orderbook.50.BTCUSDT","ts":1784086811556,"type":"delta","data":{"s":"BTCUSDT","b":[["64640.9","0.887007"]],"a":[],"u":128530649,"seq":111455882482},"cts":1784086811552}
{"topic":"orderbook.50.BTCUSDT","ts":1784086811576,"type":"delta","data":{"s":"BTCUSDT","b":[["64640.9","0.885467"],["64639.5","0.0258"],["64612.3","0"]],"a":[],"u":128530650,"seq":111455882486},"cts":1784086811570}
{"topic":"orderbook.50.BTCUSDT","ts":1784086811616,"type":"delta","data":{"s":"BTCUSDT","b":[["64640.9","0.887007"]],"a":[["64653","0"],["64654","0.003093"]],"u":128530651,"seq":111455882495},"cts":1784086811607}
{"topic":"orderbook.50.BTCUSDT","ts":1784086811656,"type":"delta","data":{"s":"BTCUSDT","b":[["64640.9","0.889317"]],"a":[],"u":128530652,"seq":111455882505},"cts":1784086811653}
{"topic":"orderbook.50.BTCUSDT","ts":1784086811676,"type":"delta","data":{"s":"BTCUSDT","b":[["64639.5","0"],["64612.3","0.037129"]],"a":[],"u":128530653,"seq":111455882507},"cts":1784086811663}
{"topic":"orderbook.50.BTCUSDT","ts":1784086811695,"type":"delta","data":{"s":"BTCUSDT","b":[["64640.9","0.887777"],["64629.1","0.116092"],["64612.3","0"]],"a":[["64641","0.043841"]],"u":128530654,"seq":111455882556},"cts":1784086811695}
{"topic":"orderbook.50.BTCUSDT","ts":1784086811716,"type":"delta","data":{"s":"BTCUSDT","b":[["64640.9","0.888547"],["64629.2","0.114697"],["64629","0"]],"a":[],"u":128530655,"seq":111455882585},"cts":1784086811715}
{"topic":"orderbook.50.BTCUSDT","ts":1784086811736,"type":"delta","data":{"s":"BTCUSDT","b":[["64640.9","1.182757"]],"a":[],"u":128530656,"seq":111455882633},"cts":1784086811734}
{"topic":"orderbook.50.BTCUSDT","ts":1784086811756,"type":"delta","data":{"s":"BTCUSDT","b":[],"a":[["64646.6","0"],["64664.2","0.000117"]],"u":128530657,"seq":111455882683},"cts":1784086811755}
{"topic":"orderbook.50.BTCUSDT","ts":1784086811776,"type":"delta","data":{"s":"BTCUSDT","b":[["64640.9","1.181987"]],"a":[],"u":128530658,"seq":111455882725},"cts":1784086811773}
{"topic":"orderbook.50.BTCUSDT","ts":1784086811796,"type":"delta","data":{"s":"BTCUSDT","b":[["64640.9","1.182757"]],"a":[["64641","0.047701"],["64646.1","0"],["64646.8","0"],["64647.8","0.068696"],["64664.4","0.116092"],["64665.2","0.037129"]],"u":128530659,"seq":111455882787},"cts":1784086811795}
{"topic":"orderbook.50.BTCUSDT","ts":1784086811818,"type":"delta","data":{"s":"BTCUSDT","b":[["64640.9","1.185837"],["64639.5","0.0258"],["64612.4","0"]],"a":[],"u":128530660,"seq":111455882839},"cts":1784086811817}
{"topic":"orderbook.50.BTCUSDT","ts":1784086811857,"type":"delta","data":{"s":"BTCUSDT","b":[["64640.9","1.186607"]],"a":[["64641","0.005101"],["64641.8","0.094078"],["64643.2","0.094078"],["64649.3","0"],["64665.2","0"]],"u":128530661,"seq":111455882914},"cts":1784086811851}
{"topic":"publicTrade.BTCUSDT","ts":1784086811860,"type":"snapshot","data":[{"i":"2290000001178591469","T":1784086811859,"p":"64641","v":"0.001241","S":"Buy","seq":111455882929,"s":"BTCUSDT","BT":false,"RPI":false},{"i":"2290000001178591470","T":1784086811859,"p":"64641","v":"0.00386","S":"Buy","seq":111455882929,"s":"BTCUSDT","BT":false,"RPI":false}]}
{"topic":"orderbook.50.BTCUSDT","ts":1784086811876,"type":"delta","data":{"s":"BTCUSDT","b":[["64641.7","1.499313"],["64641","0.329665"],["64640.9","0.162262"],["64639.8","0"],["64634.7","0.001241"],["64624.2","0.005"],["64623.4","0"],["64618.9","0.003551"],["64618.1","0"],["64614","0"]],"a":[["64641","0"],["64643.2","0"],["64649.4","0"],["64649.5","0"],["64649.8","0"],["64650.3","0.03471"],["64650.4","0.003763"],["64656.8","0.002336"],["64665.2","0.037129"],["64665.3","0.284626"],["64665.5","0.033832"]],"u":128530662,"seq":111455883035},"cts":1784086811875}
{"topic":"orderbook.50.BTCUSDT","ts":1784086811896,"type":"delta","data":{"s":"BTCUSDT","b":[["64641.7","1.50086"],["64641.1","0.098505"],["64641","0.031288"],["64640.9","0.163032"],["64639.9","0.002052"],["64639.6","0.016128"],["64639.5","0"],["64628.8","0.002"],["64628.1","0.0643"],["64628","0"],["64614.2","0"],["64614.1","0"]],"a":[],"u":128530663,"seq":111455883078},"cts":1784086811894}
{"topic":"orderbook.50.BTCUSDT","ts":1784086811916,"type":"delta","data":{"s":"BTCUSDT","b":[["64641.1","0"],["64640.9","0.15781"],["64639.6","0"],["64614.2","0.850244"],["64614.1","2.50542"]],"a":[],"u":128530664,"seq":111455883120},"cts":1784086811913}
{"topic":"orderbook.50.BTCUSDT","ts":1784086811936,"type":"delta","data":{"s":"BTCUSDT","b":[["64640.9","0.15704"]],"a":[],"u":128530665,"seq":111455883159},"cts":1784086811933}
{"topic":"orderbook.50.BTCUSDT","ts":1784086811956,"type":"delta","data":{"s":"BTCUSDT","b":[["64641.7","1.50317"],["64640.9","0.15627"],["64626.2","0"],["64614","0.05"]],"a":[],"u":128530666,"seq":111455883196},"cts":1784086811953}
{"topic":"orderbook.50.BTCUSDT","ts":1784086811976,"type":"delta","data":{"s":"BTCUSDT","b":[["64641.7","1.506493"],["64640.9","0.120627"]],"a":[["64641.8","0.101808"],["64647.1","0.018586"],["64647.8","0.038692"],["64649.3","0.030003"],["64650.8","0.097666"],["64653.2","0"],["64654.5","0.032274"]],"u":128530667,"seq":111455883247},"cts":1784086811975}
{"topic":"orderbook.50.BTCUSDT","ts":1784086811996,"type":"delta","data":{"s":"BTCUSDT","b":[["64641.7","1.539826"],["64640.9","0.11777"]],"a":[["64647.1","0.133382"]],"u":128530668,"seq":111455883283},"cts":1784086811992}
{"topic":"orderbook.50.BTCUSDT","ts":1784086812016,"type":"delta","data":{"s":"BTCUSDT","b":[["64640.9","0.117"],["64634.2","0.0015"],["64634.1","0"]],"a":[["64641.8","0.00773"],["64654","0.119185"]],"u":128530669,"seq":111455883323},"cts":1784086812015}
{"topic":"publicTrade.BTCUSDT","ts":1784086812018,"type":"snapshot","data":[{"i":"2290000001178591471","T":1784086812018,"p":"64641.8","v":"0.00773","S":"Buy","seq":111455883356,"s":"BTCUSDT","BT":false,"RPI":false},{"i":"2290000001178591472","T":1784086812018,"p":"64641.9","v":"0.004134","S":"Buy","seq":111455883356,"s":"BTCUSDT","BT":false,"RPI":false}]}
{"topic":"orderbook.50.BTCUSDT","ts":1784086812036,"type":"delta","data":{"s":"BTCUSDT","b":[["64643.2","1.482488"],["64641.8","0.469078"],["64641.7","0.05922"],["64640.9","0"],["64632","0.003094"],["64631.8","0"],["64625.7","0.102703"],["64624.2","0"],["64621.1","0"],["64620.4","0.042922"],["64618.9","0.000117"],["64612.4","0.000117"]],"a":[["64641.8","0"],["64641.9","0"],["64643.3","0.081297"],["64650.3","0.030452"],["64650.4","0"],["64651.4","0"],["64651.8","0.004258"],["64651.9","0.003763"],["64652.6","0.001125"],["64654.1","0"],["64658.3","0.002126"],["64665.8","0.001241"]],"u":128530670,"seq":111455883520},"cts":1784086812034}
{"topic":"orderbook.50.BTCUSDT","ts":1784086812055,"type":"delta","data":{"s":"BTCUSDT","b":[["64643.2","1.517368"],["64641.8","0.027117"],["64641.7","0.063064"],["64614.1","0"],["64612.3","0.037129"]],"a":[["64652.7","0.165118"],["64665.8","0"]],"u":128530671,"seq":111455883569},"cts":1784086812054}
{"topic":"orderbook.50.BTCUSDT","ts":1784086812076,"type":"delta","data":{"s":"BTCUSDT","b":[["64639.9","0"],["64614.2","0"],["64611.9","0.02"],["64611.6","0.001391"]],"a":[["64650.3","0.077611"],["64653.3","0"],["64665.8","0.001241"]],"u":128530672,"seq":111455883595},"cts":1784086812073}
{"topic":"orderbook.50.BTCUSDT","ts":1784086812096,"type":"delta","data":{"s":"BTCUSDT","b":[["64643.2","1.518138"],["64632.1","0.003094"],["64632","0"]],"a":[["64643.3","0.082377"]],"u":128530673,"seq":111455883620},"cts":1784086812095}
{"topic":"orderbook.50.BTCUSDT","ts":1784086812116,"type":"delta","data":{"s":"BTCUSDT","b":[["64641.7","0.061524"]],"a":[["64643.3","0.093967"],["64649.3","0"],["64650.5","0.030003"]],"u":128530674,"seq":111455883661},"cts":1784086812113}
{"topic":"orderbook.50.BTCUSDT","ts":1784086812136,"type":"delta","data":{"s":"BTCUSDT","b":[["64642.7","0.002049"],["64641.7","0.060754"],["64611.6","0"]],"a":[["64643.3","0.101697"]],"u":128530675,"seq":111455883681},"cts":1784086812125}
{"topic":"orderbook.50.BTCUSDT","ts":1784086812156,"type":"delta","data":{"s":"BTCUSDT","b":[["64641.7","0.059214"],["64620.2","0.797255"],["64618.5","2.504563"],["64611.9","0"]],"a":[["64643.3","0.109427"],["64643.6","0"],["64666.2","0.088047"]],"u":128530676,"seq":111455883696},"cts":1784086812155}
{"topic":"orderbook.50.BTCUSDT","ts":1784086812175,"type":"delta","data":{"s":"BTCUSDT","b":[["64643.2","1.517368"],["64641.8","0"],["64640.8","0"],["64611.9","0.02"],["64611.6","0.001391"]],"a":[],"u":128530677,"seq":111455883704},"cts":1784086812172}
{"topic":"orderbook.50.BTCUSDT","ts":1784086812195,"type":"delta","data":{"s":"BTCUSDT","b":[["64643.2","1.220078"]],"a":[["64643.3","0.241887"],["64647.2","0.001241"]],"u":128530678,"seq":111455883728},"cts":1784086812194}
{"topic":"orderbook.50.BTCUSDT","ts":1784086812216,"type":"delta","data":{"s":"BTCUSDT","b":[["64643.1","0.000283"],["64611.6","0"]],"a":[["64643.3","0.249617"],["64647.1","0.089502"],["64652.7","0"],["64667.1","0.117"]],"u":128530679,"seq":111455883735},"cts":1784086812202}
{"topic":"orderbook.50.BTCUSDT","ts":1784086812236,"type":"delta","data":{"s":"BTCUSDT","b":[["64643.2","1.217805"]],"a":[["64650.3","0.030452"]],"u":128530680,"seq":111455883747},"cts":1784086812223}
{"topic":"orderbook.50.BTCUSDT","ts":1784086812256,"type":"delta","data":{"s":"BTCUSDT","b":[],"a":[["64645.1","0.057889"],["64667.1","0"]],"u":128530681,"seq":111455883752},"cts":1784086812252}
{"topic":"orderbook.50.BTCUSDT","ts":1784086812275,"type":"delta","data":{"s":"BTCUSDT","b":[],"a":[["64643.3","0.234157"]],"u":128530682,"seq":111455883759},"cts":1784086812274}
{"topic":"orderbook.50.BTCUSDT","ts":1784086812296,"type":"delta","data":{"s":"BTCUSDT","b":[["64643.2","1.229395"],["64641.7","0.034414"]],"a":[["64643.3","0.209887"]],"u":128530683,"seq":111455883770},"cts":1784086812291}
{"topic":"orderbook.50.BTCUSDT","ts":1784086812316,"type":"delta","data":{"s":"BTCUSDT","b":[["64643.2","1.237115"]],"a":[["64643.3","0.198297"]],"u":128530684,"seq":111455883776},"cts":1784086812299}
{"topic":"orderbook.50.BTCUSDT","ts":1784086812336,"type":"delta","data":{"s":"BTCUSDT","b":[],"a":[["64655.6","0.10405"],["64666.2","0"]],"u":128530685,"seq":111455883784},"cts":1784086812334}
{"topic":"orderbook.50.BTCUSDT","ts":1784086812356,"type":"delta","data":{"s":"BTCUSDT","b":[["64641.8","0.019612"],["64611.9","0"]],"a":[],"u":128530686,"seq":111455883790},"cts":1784086812353}
{"topic":"orderbook.50.BTCUSDT","ts":1784086812376,"type":"delta","data":{"s":"BTCUSDT","b":[["64643.2","1.219345"]],"a":[["64651.2","0.160982"]],"u":128530687,"seq":111455883802},"cts":1784086812369}
{"topic":"orderbook.50.BTCUSDT","ts":1784086812396,"type":"delta","data":{"s":"BTCUSDT","b":[["64643.2","1.223195"],["64630.3","0.001"],["64628.8","0.001"],["64612.3","0"]],"a":[["64650.3","0.085298"],["64654","0.116092"],["64657","0.003093"],["64665.8","0"]],"u":128530688,"seq":111455883810},"cts":1784086812394}
{"topic":"orderbook.50.BTCUSDT","ts":1784086812416,"type":"delta","data":{"s":"BTCUSDT","b":[["64643.2","1.223965"],["64630.3","0.002"],["64628.8","0"],["64612.3","0.037129"]],"a":[],"u":128530689,"seq":111455883817},"cts":1784086812412}
{"topic":"orderbook.50.BTCUSDT","ts":1784086812456,"type":"delta","data":{"s":"BTCUSDT","b":[["64643.2","1.238645"]],"a":[],"u":128530690,"seq":111455883832},"cts":1784086812455}
{"topic":"orderbook.50.BTCUSDT","ts":1784086812476,"type":"delta","data":{"s":"BTCUSDT","b":[["64643.2","1.246375"]],"a":[],"u":128530691,"seq":111455883835},"cts":1784086812468}
{"topic":"orderbook.50.BTCUSDT","ts":1784086812496,"type":"delta","data":{"s":"BTCUSDT","b":[["64643.2","1.250235"],["64632.2","0.01"],["64612.3","0"]],"a":[],"u":128530692,"seq":111455883837},"cts":1784086812483}
{"topic":"publicTrade.BTCUSDT","ts":1784086812508,"type":"snapshot","data":[{"i":"2290000001178591473","T":1784086812507,"p":"64643.3","v":"0.038697","S":"Buy","seq":111455883878,"s":"BTCUSDT","BT":false,"RPI":false}]}
{"topic":"orderbook.50.BTCUSDT","ts":1784086812515,"type":"delta","data":{"s":"BTCUSDT","b":[["64643.7","1.359294"],["64643.3","0.327162"],["64643.2","0.371549"],["64641.8","0"],["64637.8","0.105663"],["64633","0.039658"],["64630.9","0.037129"],["64630.6","0.122"],["64627.3","0.097701"],["64626.2","0.005"],["64625.7","0.097703"],["64620.9","0.003434"],["64620.4","0.039488"],["64616.6","0"],["64616.1","0"],["64615.3","0"],["64615.1","0"],["64614","0"],["64612.4","0"]],"a":[["64643.3","0"],["64647.1","0"],["64650.5","0"],["64651.8","0"],["64651.9","0"],["64652.1","0.004258"],["64652.4","0.003763"],["64654","0"],["64654.5","0.030001"],["64654.9","0"],["64658.4","0.032952"],["64658.5","0"],["64660.4","0"],["64660.9","0.116092"],["64661.6","0"],["64664.4","0"],["64665.1","0.153221"],["64665.2","0"],["64665.8","0.001241"],["64666.2","0.088047"],["64667.1","0.117"],["64667.3","0.001"],["64668","0.00016"],["64668.5","0.037129"],["64668.9","0.143082"]],"u":128530693,"seq":111455884031},"cts":1784086812514}
{"topic":"publicTrade.BTCUSDT","ts":1784086812518,"type":"snapshot","data":[{"i":"2290000001178591474","T":1784086812517,"p":"64643.8","v":"0.005512","S":"Buy","seq":111455884060,"s":"BTCUSDT","BT":false,"RPI":false}]}
{"topic":"publicTrade.BTCUSDT","ts":1784086812518,"type":"snapshot","data":[{"i":"2290000001178591475","T":1784086812518,"p":"64645","v":"0.045898","S":"Buy","seq":111455884081,"s":"BTCUSDT","BT":false,"RPI":false}]}
{"topic":"orderbook.50.BTCUSDT","ts":1784086812536,"type":"delta","data":{"s":"BTCUSDT","b":[["64645","0.837689"],["64644.9","0.002456"],["64644.3","0.206392"],["64644.2","0.19986"],["64643.8","0.650505"],["64643.7","0.001547"],["64643.3","0"],["64643.2","0.30461"],["64641.8","0.019612"],["64638.2","0.039967"],["64638.1","0.105624"],["64636.6","0"],["64632.2","0.073383"],["64630.8","0"],["64627.5","0.042129"],["64626.2","0"],["64622.2","0.003434"],["64620.9","0"],["64618.5","0"],["64617.6","0"],["64616.7","0"]],"a":[["64643.8","0"],["64644.3","0"],["64644.7","0"],["64645.1","0.100489"],["64645.8","0.006891"],["64651.2","0.000117"],["64652.1","0"],["64652.2","0.018586"],["64652.4","0"],["64653.5","0.038697"],["64653.6","0.083988"],["64653.7","0.120763"],["64654.5","0"],["64655.6","0"],["64656.3","0"],["64656.5","0.021081"],["64660.9","0.153221"],["64666.2","0.058047"],["64669","0.330811"],["64669.4","0.002166"],["64670.4","0.116092"],["64670.7","0.000116"],["64671","0.034785"]],"u":128530694,"seq":111455884334},"cts":1784086812534}
{"topic":"orderbook.50.BTCUSDT","ts":1784086812556,"type":"delta","data":{"s":"BTCUSDT","b":[["64645","0.871022"],["64644.9","0"],["64644.3","0.485502"],["64643.8","0.19996"],["64643.7","0"],["64643.2","0.312642"],["64638.4","0.000117"],["64638.2","0.057959"],["64634.8","0.162133"],["64633.2","0.097701"],["64631.5","0.097703"],["64631.4","0.06421"],["64628.9","0"],["64627.3","0"],["64625.7","0"],["64622.5","0.509702"]],"a":[["64647.5","0.070545"],["64647.6","0"],["64649.2","0"],["64650.3","0.030452"],["64650.8","0"],["64650.9","0.091703"],["64652.2","0.048588"],["64652.5","0.097668"],["64652.6","0"],["64653.6","0.041052"],["64654.1","0.097666"],["64669","0"],["64672.1","0.001241"]],"u":128530695,"seq":111455884382},"cts":1784086812554}
{"topic":"orderbook.50.BTCUSDT","ts":1784086812576,"type":"delta","data":{"s":"BTCUSDT","b":[["64644.3","0.35295"],["64643.2","0.144342"],["64641.7","0.031333"],["64636.7","0.046972"],["64629.2","0"],["64618.5","2.504563"]],"a":[["64647.5","0"],["64650.3","0.067471"],["64653.6","0.065501"],["64655","0.175896"],["64668.9","0"],["64672.9","0.037129"]],"u":128530696,"seq":111455884405},"cts":1784086812571}
{"topic":"orderbook.50.BTCUSDT","ts":1784086812596,"type":"delta","data":{"s":"BTCUSDT","b":[["64642.7","0"],["64632.2","0.113611"],["64617.6","0.012553"]],"a":[["64652.2","0.050135"],["64653.6","0.11488"],["64662.3","0.090765"]],"u":128530697,"seq":111455884421},"cts":1784086812591}
{"topic":"orderbook.50.BTCUSDT","ts":1784086812618,"type":"delta","data":{"s":"BTCUSDT","b":[["64644.2","0.20063"],["64643.2","0.143572"]],"a":[["64650.8","0.030003"],["64652.2","0.020133"],["64653.5","0.209062"],["64653.6","0.118643"],["64653.7","0.117"],["64655","0"]],"u":128530698,"seq":111455884442},"cts":1784086812615}
{"topic":"orderbook.50.BTCUSDT","ts":1784086812635,"type":"delta","data":{"s":"BTCUSDT","b":[["64645","0.873047"]],"a":[["64645.1","0.103289"],["64653.4","0.132788"],["64653.6","0.008021"]],"u":128530699,"seq":111455884459},"cts":1784086812631}
{"topic":"orderbook.50.BTCUSDT","ts":1784086812656,"type":"delta","data":{"s":"BTCUSDT","b":[["64643.2","0.11777"],["64628.1","0"],["64616.6","0.005"]],"a":[],"u":128530700,"seq":111455884469},"cts":1784086812651}
{"topic":"orderbook.50.BTCUSDT","ts":1784086812676,"type":"delta","data":{"s":"BTCUSDT","b":[["64644.3","0.17789"],["64644.2","0.02557"],["64643.8","0.0248"],["64643.2","0.117"],["64643.1","0"],["64616.1","0.001241"]],"a":[["64653.5","0.21332"],["64653.6","0.003763"]],"u":128530701,"seq":111455884480},"cts":1784086812674}
{"topic":"orderbook.50.BTCUSDT","ts":1784086812696,"type":"delta","data":{"s":"BTCUSDT","b":[["64645","0.845717"],["64644.3","0.031332"],["64643.2","0"],["64633","0"],["64615.3","0.037129"],["64615.1","0.116092"]],"a":[["64645.1","0.220289"]],"u":128530702,"seq":111455884500},"cts":1784086812692}
{"topic":"orderbook.50.BTCUSDT","ts":1784086812716,"type":"delta","data":{"s":"BTCUSDT","b":[["64644.9","0.000243"],["64644.2","0"]],"a":[],"u":128530703,"seq":111455884513},"cts":1784086812711}
{"topic":"orderbook.50.BTCUSDT","ts":1784086812736,"type":"delta","data":{"s":"BTCUSDT","b":[],"a":[["64645.1","0.239609"],["64650","0.001547"],["64652.2","0.018586"],["64672.9","0"]],"u":128530704,"seq":111455884533},"cts":1784086812731}
{"topic":"orderbook.50.BTCUSDT","ts":1784086812756,"type":"delta","data":{"s":"BTCUSDT","b":[],"a":[["64651.8","0.161446"],["64652.5","0.102668"],["64653.5","0.042955"],["64657.3","0.099736"],["64669.3","0.005"],["64669.5","0.03"],["64670.4","0"],["64670.7","0"],["64671","0"],["64672.1","0"]],"u":128530705,"seq":111455884552},"cts":1784086812754}
{"topic":"orderbook.50.BTCUSDT","ts":1784086812776,"type":"delta","data":{"s":"BTCUSDT","b":[],"a":[["64645.1","0.247339"],["64650.3","0.112423"],["64653.4","0.001241"]],"u":128530706,"seq":111455884564},"cts":1784086812772}
{"topic":"orderbook.50.BTCUSDT","ts":1784086812796,"type":"delta","data":{"s":"BTCUSDT","b":[],"a":[["64653.6","0.068587"]],"u":128530707,"seq":111455884565},"cts":1784086812778}
{"topic":"orderbook.50.BTCUSDT","ts":1784086812816,"type":"delta","data":{"s":"BTCUSDT","b":[["64643.2","0.003081"],["64615.1","0"]],"a":[],"u":128530708,"seq":111455884571},"cts":1784086812814}
{"topic":"orderbook.50.BTCUSDT","ts":1784086812836,"type":"delta","data":{"s":"BTCUSDT","b":[["64643.8","0"],["64615.1","0.116092"]],"a":[["64645.1","0.228019"],["64649.2","0.028797"],["64656.5","0.048157"],["64665.5","0"]],"u":128530709,"seq":111455884590},"cts":1784086812833}
{"topic":"orderbook.50.BTCUSDT","ts":1784086812856,"type":"delta","data":{"s":"BTCUSDT","b":[["64645","0.851097"]],"a":[["64647.7","0.028414"]],"u":128530710,"seq":111455884602},"cts":1784086812851}
{"topic":"orderbook.50.BTCUSDT","ts":1784086812876,"type":"delta","data":{"s":"BTCUSDT","b":[],"a":[["64645.1","0.217489"]],"u":128530711,"seq":111455884607},"cts":1784086812871}
{"topic":"orderbook.50.BTCUSDT","ts":1784086812896,"type":"delta","data":{"s":"BTCUSDT","b":[],"a":[["64656","0.003093"],["64657","0"]],"u":128530712,"seq":111455884610},"cts":1784086812894}
{"topic":"orderbook.50.BTCUSDT","ts":1784086812915,"type":"delta","data":{"s":"BTCUSDT","b":[["64632.1","0.005094"],["64630.3","0"],["64614","0.05"]],"a":[],"u":128530713,"seq":111455884612},"cts":1784086812906}
{"topic":"orderbook.50.BTCUSDT","ts":1784086812936,"type":"delta","data":{"s":"BTCUSDT","b":[["64645","0.860367"]],"a":[["64645.1","0.218669"]],"u":128530714,"seq":111455884622},"cts":1784086812934}
{"topic":"orderbook.50.BTCUSDT","ts":1784086812956,"type":"delta","data":{"s":"BTCUSDT","b":[["64645","0.859607"]],"a":[],"u":128530715,"seq":111455884634},"cts":1784086812954}
{"topic":"orderbook.50.BTCUSDT","ts":1784086812976,"type":"delta","data":{"s":"BTCUSDT","b":[["64645","0.860377"]],"a":[],"u":128530716,"seq":111455884636},"cts":1784086812962}
{"topic":"orderbook.50.BTCUSDT","ts":1784086812996,"type":"delta","data":{"s":"BTCUSDT","b":[["64645","0.852647"]],"a":[],"u":128530717,"seq":111455884637},"cts":1784086812989}
{"topic":"orderbook.50.BTCUSDT","ts":1784086813016,"type":"delta","data":{"s":"BTCUSDT","b":[["64645","0.875907"]],"a":[["64645.1","0.219849"]],"u":128530718,"seq":111455884643},"cts":1784086813013}
{"topic":"orderbook.50.BTCUSDT","ts":1784086813037,"type":"delta","data":{"s":"BTCUSDT","b":[["64645","0.871287"]],"a":[],"u":128530719,"seq":111455884656},"cts":1784086813030}
{"topic":"orderbook.50.BTCUSDT","ts":1784086813096,"type":"delta","data":{"s":"BTCUSDT","b":[["64645","0.873597"],["64632.7","0.003094"],["64632.1","0.002"],["64614","0"]],"a":[],"u":128530720,"seq":111455884671},"cts":1784086813094}
{"topic":"orderbook.50.BTCUSDT","ts":1784086813116,"type":"delta","data":{"s":"BTCUSDT","b":[["64645","0.875137"],["64633.3","0.116092"],["64633","0.003094"],["64632.7","0"],["64615.1","0"]],"a":[],"u":128530721,"seq":111455884677},"cts":1784086813113}
{"topic":"orderbook.50.BTCUSDT","ts":1784086813136,"type":"delta","data":{"s":"BTCUSDT","b":[["64645","0.875907"],["64633.1","0.003094"],["64633","0"]],"a":[],"u":128530722,"seq":111455884683},"cts":1784086813125}
{"topic":"orderbook.50.BTCUSDT","ts":1784086813156,"type":"delta","data":{"s":"BTCUSDT","b":[["64645","0.875137"]],"a":[],"u":128530723,"seq":111455884690},"cts":1784086813141}
{"topic":"orderbook.50.BTCUSDT","ts":1784086813176,"type":"delta","data":{"s":"BTCUSDT","b":[["64645","0.872827"]],"a":[],"u":128530724,"seq":111455884699},"cts":1784086813169}
{"topic":"orderbook.50.BTCUSDT","ts":1784086813196,"type":"delta","data":{"s":"BTCUSDT","b":[["64645","0.872057"]],"a":[],"u":128530725,"seq":111455884702},"cts":1784086813189}
{"topic":"orderbook.50.BTCUSDT","ts":1784086813216,"type":"delta","data":{"s":"BTCUSDT","b":[["64645","0.873597"]],"a":[],"u":128530726,"seq":111455884708},"cts":1784086813214}
{"topic":"orderbook.50.BTCUSDT","ts":1784086813237,"type":"delta","data":{"s":"BTCUSDT","b":[["64645","0.875137"]],"a":[],"u":128530727,"seq":111455884714},"cts":1784086813234}
{"topic":"orderbook.50.BTCUSDT","ts":1784086813256,"type":"delta","data":{"s":"BTCUSDT","b":[["64645","0.875907"]],"a":[],"u":128530728,"seq":111455884724},"cts":1784086813248}
{"topic":"orderbook.50.BTCUSDT","ts":1784086813275,"type":"delta","data":{"s":"BTCUSDT","b":[["64645","0.874367"]],"a":[],"u":128530729,"seq":111455884729},"cts":1784086813271}
{"topic":"orderbook.50.BTCUSDT","ts":1784086813296,"type":"delta","data":{"s":"BTCUSDT","b":[["64645","0.873597"]],"a":[],"u":128530730,"seq":111455884730},"cts":1784086813280}
{"topic":"orderbook.50.BTCUSDT","ts":1784086813316,"type":"delta","data":{"s":"BTCUSDT","b":[["64645","0.872057"]],"a":[],"u":128530731,"seq":111455884733},"cts":1784086813314}
{"topic":"orderbook.50.BTCUSDT","ts":1784086813336,"type":"delta","data":{"s":"BTCUSDT","b":[["64645","0.870517"]],"a":[["64645.1","0.223709"]],"u":128530732,"seq":111455884743},"cts":1784086813332}
{"topic":"orderbook.50.BTCUSDT","ts":1784086813356,"type":"delta","data":{"s":"BTCUSDT","b":[],"a":[["64645.1","0.1774"]],"u":128530733,"seq":111455884758},"cts":1784086813353}
{"topic":"orderbook.50.BTCUSDT","ts":1784086813376,"type":"delta","data":{"s":"BTCUSDT","b":[],"a":[["64645.1","0.17622"]],"u":128530734,"seq":111455884767},"cts":1784086813369}
{"topic":"orderbook.50.BTCUSDT","ts":1784086813396,"type":"delta","data":{"s":"BTCUSDT","b":[],"a":[["64645.1","0.17504"]],"u":128530735,"seq":111455884772},"cts":1784086813382}
{"topic":"orderbook.50.BTCUSDT","ts":1784086813419,"type":"delta","data":{"s":"BTCUSDT","b":[],"a":[["64645.1","0.17118"]],"u":128530736,"seq":111455884775},"cts":1784086813415}
{"topic":"orderbook.50.BTCUSDT","ts":1784086813436,"type":"delta","data":{"s":"BTCUSDT","b":[],"a":[["64645.1","0.1596"]],"u":128530737,"seq":111455884783},"cts":1784086813430}
{"topic":"orderbook.50.BTCUSDT","ts":1784086813456,"type":"delta","data":{"s":"BTCUSDT","b":[],"a":[["64647.3","0.067481"],["64669.5","0"]],"u":128530738,"seq":111455884787},"cts":1784086813452}
{"topic":"orderbook.50.BTCUSDT","ts":1784086813476,"type":"delta","data":{"s":"BTCUSDT","b":[],"a":[["64647.2","0.043998"],["64647.7","0.008269"]],"u":128530739,"seq":111455884794},"cts":1784086813470}
{"topic":"orderbook.50.BTCUSDT","ts":1784086813536,"type":"delta","data":{"s":"BTCUSDT","b":[["64634.5","0.003094"],["64633.1","0"]],"a":[],"u":128530740,"seq":111455884803},"cts":1784086813527}
{"topic":"orderbook.50.BTCUSDT","ts":1784086813556,"type":"delta","data":{"s":"BTCUSDT","b":[["64645","0.755594"],["64638.2","0.039967"],["64637.8","0"],["64615.1","0.116092"]],"a":[["64648","0.028798"],["64649.2","0"]],"u":128530741,"seq":111455884838},"cts":1784086813554}
{"topic":"orderbook.50.BTCUSDT","ts":1784086813575,"type":"delta","data":{"s":"BTCUSDT","b":[["64645","0.912938"]],"a":[["64659","0.03"],["64669.4","0"]],"u":128530742,"seq":111455884849},"cts":1784086813574}
{"topic":"orderbook.50.BTCUSDT","ts":1784086813596,"type":"delta","data":{"s":"BTCUSDT","b":[["64645","0.879605"]],"a":[],"u":128530743,"seq":111455884858},"cts":1784086813588}
{"topic":"orderbook.50.BTCUSDT","ts":1784086813615,"type":"delta","data":{"s":"BTCUSDT","b":[["64641.9","0.033333"],["64615.1","0"]],"a":[],"u":128530744,"seq":111455884866},"cts":1784086813606}
{"topic":"orderbook.50.BTCUSDT","ts":1784086813635,"type":"delta","data":{"s":"BTCUSDT","b":[["64623.8","0.171438"]],"a":[["64649.9","0.151093"],["64651.8","0"]],"u":128530745,"seq":111455884882},"cts":1784086813630}
{"topic":"orderbook.50.BTCUSDT","ts":1784086813656,"type":"delta","data":{"s":"BTCUSDT","b":[["64645","0.895065"]],"a":[["64649.8","0.11842"],["64650.3","0"]],"u":128530746,"seq":111455884890},"cts":1784086813653}
{"topic":"orderbook.50.BTCUSDT","ts":1784086813676,"type":"delta","data":{"s":"BTCUSDT","b":[],"a":[["64648.5","0.001547"],["64650","0"]],"u":128530747,"seq":111455884894},"cts":1784086813673}
{"topic":"orderbook.50.BTCUSDT","ts":1784086813696,"type":"delta","data":{"s":"BTCUSDT","b":[],"a":[["64645.8","0"],["64669.4","0.002166"]],"u":128530748,"seq":111455884901},"cts":1784086813694}
{"topic":"orderbook.50.BTCUSDT","ts":1784086813756,"type":"delta","data":{"s":"BTCUSDT","b":[["64638.4","0.018703"]],"a":[["64647.7","0"],["64652.2","0"],["64669.3","0"],["64669.5","0.03"],["64670.3","0.045071"],["64670.4","0.116092"]],"u":128530749,"seq":111455884936},"cts":1784086813754}
{"topic":"orderbook.50.BTCUSDT","ts":1784086813796,"type":"delta","data":{"s":"BTCUSDT","b":[["64634.9","0.10541"],["64615.3","0"]],"a":[],"u":128530750,"seq":111455884940},"cts":1784086813792}
{"topic":"orderbook.50.BTCUSDT","ts":1784086813816,"type":"delta","data":{"s":"BTCUSDT","b":[["64636.7","0.075598"]],"a":[["64645.1","0.171159"]],"u":128530751,"seq":111455884948},"cts":1784086813807}
{"topic":"orderbook.50.BTCUSDT","ts":1784086813836,"type":"delta","data":{"s":"BTCUSDT","b":[["64634.1","0.000613"],["64616.1","0"]],"a":[],"u":128530752,"seq":111455884955},"cts":1784086813823}
{"topic":"orderbook.50.BTCUSDT","ts":1784086813876,"type":"delta","data":{"s":"BTCUSDT","b":[],"a":[["64645.1","0.173289"]],"u":128530753,"seq":111455884960},"cts":1784086813874}
{"topic":"orderbook.50.BTCUSDT","ts":1784086813916,"type":"delta","data":{"s":"BTCUSDT","b":[["64632.2","0.11453"]],"a":[["64669.5","0"],["64670.7","0.000116"]],"u":128530754,"seq":111455884967},"cts":1784086813910}
{"topic":"orderbook.50.BTCUSDT","ts":1784086813976,"type":"delta","data":{"s":"BTCUSDT","b":[["64645","0.726214"],["64630.3","0.001226"],["64616.6","0"]],"a":[["64648","0"],["64671","0.034785"]],"u":128530755,"seq":111455884996},"cts":1784086813974}
{"topic":"orderbook.50.BTCUSDT","ts":1784086813996,"type":"delta","data":{"s":"BTCUSDT","b":[["64645","0.718484"]],"a":[["64645.1","0.198089"],["64646.9","0.028173"],["64671","0"]],"u":128530756,"seq":111455885016},"cts":1784086813994}
{"topic":"orderbook.50.BTCUSDT","ts":1784086814017,"type":"delta","data":{"s":"BTCUSDT","b":[["64624.5","0.037129"],["64617.6","0"]],"a":[],"u":128530757,"seq":111455885025},"cts":1784086814003}
{"topic":"orderbook.50.BTCUSDT","ts":1784086814056,"type":"delta","data":{"s":"BTCUSDT","b":[["64645","0.710754"],["64628.3","0.001533"],["64618.5","0"]],"a":[["64645.1","0.339601"],["64649.9","0"],["64662.3","0.089658"],["64662.9","0.002166"]],"u":128530758,"seq":111455885035},"cts":1784086814053}
{"topic":"orderbook.50.BTCUSDT","ts":1784086814076,"type":"delta","data":{"s":"BTCUSDT","b":[],"a":[["64649.8","0.067309"],["64658.1","0.012072"],["64670.7","0"]],"u":128530759,"seq":111455885045},"cts":1784086814071}
{"topic":"orderbook.50.BTCUSDT","ts":1784086814096,"type":"delta","data":{"s":"BTCUSDT","b":[],"a":[["64659.6","0.002396"]],"u":128530760,"seq":111455885048},"cts":1784086814088}
{"topic":"orderbook.50.BTCUSDT","ts":1784086814136,"type":"delta","data":{"s":"BTCUSDT","b":[["64626.4","0.001839"],["64618.9","0"]],"a":[],"u":128530761,"seq":111455885058},"cts":1784086814126}
{"topic":"orderbook.50.BTCUSDT","ts":1784086814176,"type":"delta","data":{"s":"BTCUSDT","b":[["64643.2","0"],["64618.9","0.000117"]],"a":[],"u":128530762,"seq":111455885061},"cts":1784086814174}
{"topic":"orderbook.50.BTCUSDT","ts":1784086814195,"type":"delta","data":{"s":"BTCUSDT","b":[["64645","0.677421"]],"a":[],"u":128530763,"seq":111455885067},"cts":1784086814186}
{"topic":"orderbook.50.BTCUSDT","ts":1784086814218,"type":"delta","data":{"s":"BTCUSDT","b":[["64645","0.368246"],["64638.5","0.117"],["64618.9","0"]],"a":[["64645.1","0.198089"],["64648.5","0.142716"]],"u":128530764,"seq":111455885118},"cts":1784086814217}
{"topic":"orderbook.50.BTCUSDT","ts":1784086814236,"type":"delta","data":{"s":"BTCUSDT","b":[["64645","0.369793"],["64643.8","0.025802"],["64641.2","0.141184"],["64638.6","0.072036"],["64638.2","0"],["64620.1","0"],["64619.2","0"]],"a":[["64647.2","0.070068"]],"u":128530765,"seq":111455885135},"cts":1784086814230}
{"topic":"orderbook.50.BTCUSDT","ts":1784086814256,"type":"delta","data":{"s":"BTCUSDT","b":[["64645","0.486793"],["64644.4","0.017054"],["64620.2","0"]],"a":[],"u":128530766,"seq":111455885151},"cts":1784086814252}
{"topic":"orderbook.50.BTCUSDT","ts":1784086814276,"type":"delta","data":{"s":"BTCUSDT","b":[["64641.8","0.058328"]],"a":[],"u":128530767,"seq":111455885154},"cts":1784086814257}
{"topic":"orderbook.50.BTCUSDT","ts":1784086814296,"type":"delta","data":{"s":"BTCUSDT","b":[["64645","0.495793"]],"a":[],"u":128530768,"seq":111455885158},"cts":1784086814294}
{"topic":"orderbook.50.BTCUSDT","ts":1784086814316,"type":"delta","data":{"s":"BTCUSDT","b":[["64627.7","0.005"],["64627.5","0.037129"],["64622.5","0.513136"],["64622.2","0"]],"a":[["64653.5","0.038697"],["64653.8","0.004258"],["64654.3","0.03"],["64670.3","0"],["64670.4","0"]],"u":128530769,"seq":111455885174},"cts":1784086814315}
{"topic":"orderbook.50.BTCUSDT","ts":1784086814336,"type":"delta","data":{"s":"BTCUSDT","b":[["64645","0.638462"],["64641.2","0"],["64620.2","0.797255"]],"a":[["64645.1","0.329199"],["64646.9","0"],["64648.4","0.028173"],["64648.5","0.001547"]],"u":128530770,"seq":111455885188},"cts":1784086814333}
{"topic":"orderbook.50.BTCUSDT","ts":1784086814356,"type":"delta","data":{"s":"BTCUSDT","b":[["64641.8","0.019612"]],"a":[["64647.2","0.043998"]],"u":128530771,"seq":111455885198},"cts":1784086814343}
{"topic":"publicTrade.BTCUSDT","ts":1784086814412,"type":"snapshot","data":[{"i":"2290000001178591476","T":1784086814411,"p":"64645.1","v":"0.070448","S":"Buy","seq":111455885211,"s":"BTCUSDT","BT":false,"RPI":false}]}
{"topic":"publicTrade.BTCUSDT","ts":1784086814412,"type":"snapshot","data":[{"i":"2290000001178591477","T":1784086814411,"p":"64645.1","v":"0.012815","S":"Buy","seq":111455885212,"s":"BTCUSDT","BT":false,"RPI":false}]}
{"topic":"publicTrade.BTCUSDT","ts":1784086814412,"type":"snapshot","data":[{"i":"2290000001178591478","T":1784086814411,"p":"64645.1","v":"0.019663","S":"Buy","seq":111455885213,"s":"BTCUSDT","BT":false,"RPI":false}]}
{"topic":"publicTrade.BTCUSDT","ts":1784086814412,"type":"snapshot","data":[{"i":"2290000001178591479","T":1784086814411,"p":"64645.1","v":"0.014074","S":"Buy","seq":111455885215,"s":"BTCUSDT","BT":false,"RPI":false},{"i":"2290000001178591480","T":1784086814411,"p":"64645.1","v":"0.00213","S":"Buy","seq":111455885215,"s":"BTCUSDT","BT":false,"RPI":false},{"i":"2290000001178591481","T":1784086814411,"p":"64645.1","v":"0.0248","S":"Buy","seq":111455885215,"s":"BTCUSDT","BT":false,"RPI":false},{"i":"2290000001178591482","T":1784086814411,"p":"64645.1","v":"0.04685","S":"Buy","seq":111455885215,"s":"BTCUSDT","BT":false,"RPI":false}]}
{"topic":"publicTrade.BTCUSDT","ts":1784086814412,"type":"snapshot","data":[{"i":"2290000001178591483","T":1784086814411,"p":"64645.1","v":"0.064359","S":"Buy","seq":111455885216,"s":"BTCUSDT","BT":false,"RPI":false}]}
{"topic":"publicTrade.BTCUSDT","ts":1784086814412,"type":"snapshot","data":[{"i":"2290000001178591484","T":1784086814411,"p":"64645.1","v":"0.03146","S":"Buy","seq":111455885217,"s":"BTCUSDT","BT":false,"RPI":false}]}
{"topic":"publicTrade.BTCUSDT","ts":1784086814412,"type":"snapshot","data":[{"i":"2290000001178591485","T":1784086814411,"p":"64647.2","v":"0.001241","S":"Buy","seq":111455885224,"s":"BTCUSDT","BT":false,"RPI":false},{"i":"2290000001178591486","T":1784086814411,"p":"64647.2","v":"0.042757","S":"Buy","seq":111455885224,"s":"BTCUSDT","BT":false,"RPI":false},{"i":"2290000001178591487","T":1784086814411,"p":"64647.3","v":"0.025628","S":"Buy","seq":111455885224,"s":"BTCUSDT","BT":false,"RPI":false}]}
{"topic":"publicTrade.BTCUSDT","ts":1784086814414,"type":"snapshot","data":[{"i":"2290000001178591488","T":1784086814412,"p":"64647.3","v":"0.041853","S":"Buy","seq":111455885236,"s":"BTCUSDT","BT":false,"RPI":false}]}
{"topic":"publicTrade.BTCUSDT","ts":1784086814414,"type":"snapshot","data":[{"i":"2290000001178591489","T":1784086814412,"p":"64647.8","v":"0.038692","S":"Buy","seq":111455885246,"s":"BTCUSDT","BT":false,"RPI":false},{"i":"2290000001178591490","T":1784086814412,"p":"64648.4","v":"0.028173","S":"Buy","seq":111455885246,"s":"BTCUSDT","BT":false,"RPI":false},{"i":"2290000001178591491","T":1784086814412,"p":"64648.5","v":"0.001547","S":"Buy","seq":111455885246,"s":"BTCUSDT","BT":false,"RPI":false}]}
{"topic":"publicTrade.BTCUSDT","ts":1784086814414,"type":"snapshot","data":[{"i":"2290000001178591492","T":1784086814412,"p":"64649.8","v":"0.067309","S":"Buy","seq":111455885247,"s":"BTCUSDT","BT":false,"RPI":false},{"i":"2290000001178591493","T":1784086814412,"p":"64650.8","v":"0.030003","S":"Buy","seq":111455885247,"s":"BTCUSDT","BT":false,"RPI":false},{"i":"2290000001178591494","T":1784086814412,"p":"64650.9","v":"0.078248","S":"Buy","seq":111455885247,"s":"BTCUSDT","BT":false,"RPI":false}]}
{"topic":"publicTrade.BTCUSDT","ts":1784086814414,"type":"snapshot","data":[{"i":"2290000001178591495","T":1784086814412,"p":"64650.9","v":"0.013455","S":"Buy","seq":111455885257,"s":"BTCUSDT","BT":false,"RPI":false},{"i":"2290000001178591496","T":1784086814412,"p":"64651.2","v":"0.000117","S":"Buy","seq":111455885257,"s":"BTCUSDT","BT":false,"RPI":false}]}
{"topic":"orderbook.50.BTCUSDT","ts":1784086814416,"type":"delta","data":{"s":"BTCUSDT","b":[["64652.4","0.17911"],["64651.1","0.126415"],["64649.7","0.157615"],["64648.5","0.000148"],["64648","0.093932"],["64647.7","0.0738"],["64647.3","0.069707"],["64647.2","0.423205"],["64647.1","0.953716"],["64645.4","0.093937"],["64645.1","0.288066"],["64645","0.820145"],["64644.3","0"],["64638.1","0.077394"],["64635","0.037129"],["64634.3","0.039658"],["64628.7","0.005"],["64627.7","0"],["64625.4","0"],["64625.1","0"],["64624.5","0"],["64624.4","0"],["64623.8","0"],["64623.7","0"],["64622.5","0"],["64622.3","0"],["64622","0"],["64620.4","0"],["64620.3","0"],["64620.2","0"]],"a":[["64645.1","0"],["64647.2","0"],["64647.3","0"],["64647.8","0"],["64648.4","0"],["64648.5","0"],["64649.8","0"],["64650.8","0"],["64650.9","0"],["64651.2","0"],["64653.6","0"],["64653.7","0"],["64653.8","0"],["64654.7","0.003763"],["64654.8","0.005758"],["64656.6","0"],["64657.3","0"],["64658.1","0"],["64660.9","0.116092"],["64662.3","0"],["64662.9","0"],["64665.1","0"],["64668.5","0"],["64670.3","0.045071"],["64670.7","0.000116"],["64671","0.032466"],["64672.1","0.001241"],["64673.1","0.285395"],["64674.1","0.854072"],["64674.2","0.01547"],["64675.7","0.039658"],["64675.9","0.055412"],["64676.1","0.117"],["64676.6","0.000117"],["64676.7","0.330811"],["64677.1","0.03"],["64677.2","0.000116"],["64678.3","0.001241"],["64678.5","0.246389"],["64679","0.03036"],["64680.8","0.018586"],["64681.3","0.614802"]],"u":128530772,"seq":111455885400},"cts":1784086814415}
{"topic":"publicTrade.BTCUSDT","ts":1784086814417,"type":"snapshot","data":[{"i":"2290000001178591497","T":1784086814415,"p":"64652.5","v":"0.097668","S":"Buy","seq":111455885461,"s":"BTCUSDT","BT":false,"RPI":false},{"i":"2290000001178591498","T":1784086814415,"p":"64652.5","v":"0.005","S":"Buy","seq":111455885461,"s":"BTCUSDT","BT":false,"RPI":false},{"i":"2290000001178591499","T":1784086814415,"p":"64652.8","v":"0.000932","S":"Buy","seq":111455885461,"s":"BTCUSDT","BT":false,"RPI":false}]}
{"topic":"publicTrade.BTCUSDT","ts":1784086814417,"type":"snapshot","data":[{"i":"2290000001178591500","T":1784086814416,"p":"64652.8","v":"0.000068","S":"Buy","seq":111455885473,"s":"BTCUSDT","BT":false,"RPI":false},{"i":"2290000001178591501","T":1784086814416,"p":"64653.4","v":"0.001241","S":"Buy","seq":111455885473,"s":"BTCUSDT","BT":false,"RPI":false},{"i":"2290000001178591502","T":1784086814416,"p":"64653.5","v":"0.015991","S":"Buy","seq":111455885473,"s":"BTCUSDT","BT":false,"RPI":false}]}
{"topic":"orderbook.50.BTCUSDT","ts":1784086814436,"type":"delta","data":{"s":"BTCUSDT","b":[["64653.4","0.857804"],["64653.3","0.089026"],["64652.8","0.032223"],["64652.7","0.0248"],["64652.5","0.115926"],["64652.4","0.009"],["64651.2","0.0248"],["64651.1","0.05"],["64649.7","0.11342"],["64648.6","0.027693"],["64648.5","0"],["64648","0"],["64647.7","0.11342"],["64647.4","0.001547"],["64647.3","0.378905"],["64647.2","0.11342"],["64647.1","0.11342"],["64645.4","0"],["64645.2","0.116092"],["64645.1","0.0248"],["64645","0.308114"],["64644.9","0.00036"],["64644.4","0"],["64641.9","0"],["64641.7","0.122719"],["64640.9","0.001241"],["64640.5","0.002"],["64640.1","0.097701"],["64638.5","0.214703"],["64638.4","0.000117"],["64638.2","0.037129"],["64637.4","0.116092"],["64636.6","0.0015"],["64636.1","0.005"],["64634.8","0.032055"],["64634.6","0.003094"],["64634.5","0"],["64634.2","0"],["64633.2","0"],["64632.1","0"],["64631.5","0"],["64630.6","0.125434"],["64629.1","0"],["64628.7","0"],["64628.5","0"],["64628.3","0"],["64627.5","0"],["64626.4","0"],["64625.8","0"]],"a":[["64652.5","0"],["64652.8","0"],["64653.4","0"],["64653.5","0.022706"],["64654.1","0"],["64654.7","0"],["64654.8","0"],["64656","0"],["64656.5","0.021081"],["64656.8","0"],["64658.3","0"],["64658.4","0"],["64660.6","0"],["64660.9","0"],["64661.1","0"],["64661.3","0.003093"],["64662.1","0.003763"],["64662.2","0.004258"],["64662.3","0.0015"],["64662.7","0.097666"],["64663.5","0.080561"],["64664.2","0.002453"],["64665.3","0"],["64665.7","0.002126"],["64666.2","0"],["64667","0.035271"],["64669.4","0"],["64670.3","0"],["64673.1","0.794747"],["64674.1","0"],["64674.2","0"],["64676.7","0"],["64677.1","0.060718"],["64678.4","0.037129"],["64680.1","0.015468"],["64681.1","0.116092"],["64681.3","0"],["64681.7","0.001933"],["64683.6","0.117"],["64683.7","0.000116"],["64684.5","0.001241"],["64685.1","0.100088"],["64685.3","0.330811"],["64687.7","0.153221"],["64689.2","0.039658"],["64690.2","0.000116"],["64690.7","0.001241"],["64691.4","0.002165"]],"u":128530773,"seq":111455885938},"cts":1784086814435}
{"topic":"publicTrade.BTCUSDT","ts":1784086814448,"type":"snapshot","data":[{"i":"2290000001178591503","T":1784086814447,"p":"64653.5","v":"0.001","S":"Buy","seq":111455886044,"s":"BTCUSDT","BT":false,"RPI":false}]}
{"topic":"publicTrade.BTCUSDT","ts":1784086814448,"type":"snapshot","data":[{"i":"2290000001178591504","T":1784086814447,"p":"64653.5","v":"0.021706","S":"Buy","seq":111455886046,"s":"BTCUSDT","BT":false,"RPI":false}]}
{"topic":"publicTrade.BTCUSDT","ts":1784086814451,"type":"snapshot","data":[{"i":"2290000001178591505","T":1784086814450,"p":"64653.9","v":"0.001","S":"Buy","seq":111455886071,"s":"BTCUSDT","BT":false,"RPI":false}]}
{"topic":"publicTrade.BTCUSDT","ts":1784086814454,"type":"snapshot","data":[{"i":"2290000001178591506","T":1784086814453,"p":"64654.8","v":"0.0077","S":"Buy","seq":111455886158,"s":"BTCUSDT","BT":false,"RPI":false}]}
{"topic":"orderbook.50.BTCUSDT","ts":1784086814456,"type":"delta","data":{"s":"BTCUSDT","b":[["64654.7","0.630048"],["64654.3","0.112246"],["64654.2","0.649783"],["64653.9","0.112246"],["64653.8","0.66065"],["64653.5","0.335731"],["64653.4","0.302737"],["64653.3","0"],["64652.5","0"],["64652.1","0.00774"],["64651.4","0.033333"],["64649.7","0"],["64648.3","0.077384"],["64647.7","0"],["64647.4","0.180815"],["64647.3","0"],["64646.3","0.091386"],["64645.3","0.141838"],["64645.2","0"],["64645","0.05887"],["64644.7","0.097701"],["64643.1","0.097703"],["64642","0.0015"],["64641.8","0.073595"],["64641.7","0.031333"],["64641","0"],["64640.1","0"],["64638.6","0.123753"],["64638.5","0.117"],["64638.2","0"],["64636.7","0.077957"],["64636.6","0"],["64636.5","0.005"],["64636.1","0"],["64634.8","0"],["64634.2","0.018586"],["64634","0.509702"],["64631.4","0"],["64630.9","0"],["64630.7","0"],["64630.6","0"],["64630.3","0"]],"a":[["64653.5","0"],["64653.9","0"],["64654.3","0"],["64654.8","0.00004"],["64656.5","0"],["64659","0"],["64659.6","0.001241"],["64660.5","0"],["64662.1","0"],["64662.3","0"],["64662.5","0.003763"],["64662.6","0.031386"],["64662.7","0"],["64663.5","0.038692"],["64666.2","0.028165"],["64666.4","0.001"],["64667.7","0.097666"],["64671","0"],["64673","0.268134"],["64673.1","0"],["64675.8","0.037129"],["64677.2","0.116208"],["64678.1","0.509352"],["64678.5","0"],["64680","0.044819"],["64680.8","0"],["64683.5","0.03533"],["64685","0.037129"],["64685.1","0.140737"],["64693.3","0.154673"]],"u":128530774,"seq":111455886167},"cts":1784086814454}
{"topic":"publicTrade.BTCUSDT","ts":1784086814457,"type":"snapshot","data":[{"i":"2290000001178591507","T":1784086814456,"p":"64654.8","v":"0.00004","S":"Buy","seq":111455886209,"s":"BTCUSDT","BT":false,"RPI":false}]}
{"topic":"publicTrade.BTCUSDT","ts":1784086814460,"type":"snapshot","data":[{"i":"2290000001178591508","T":1784086814459,"p":"64657.7","v":"0.000117","S":"Buy","seq":111455886271,"s":"BTCUSDT","BT":false,"RPI":false},{"i":"2290000001178591509","T":1784086814459,"p":"64659.6","v":"0.001241","S":"Buy","seq":111455886271,"s":"BTCUSDT","BT":false,"RPI":false}]}
{"topic":"orderbook.50.BTCUSDT","ts":1784086814476,"type":"delta","data":{"s":"BTCUSDT","b":[["64660.9","0.317455"],["64657.7","0.06738"],["64657.6","0.117"],["64654.8","0.806314"],["64654.7","0.14791"],["64654.3","0"],["64654.2","0"],["64653.9","0"],["64653.8","0.117"],["64653.5","0"],["64653.4","0"],["64653.3","0.001241"],["64652.8","0.029752"],["64652.7","0"],["64652.1","0"],["64651.4","0"],["64651.2","0"],["64648.6","0"],["64647.4","0"],["64647.1","0.114661"],["64646.4","0.116091"],["64645.3","0"],["64645","0.061951"],["64644.9","0.000117"],["64643.6","0.005"],["64641.8","0"],["64638.7","0.037129"],["64638.1","0"],["64636.5","0"],["64633.2","0.005"],["64632","0.003434"],["64630.9","0.037129"],["64630.7","0.05"],["64630.6","0.122"],["64630.3","0.001226"],["64629.6","0.06189"]],"a":[["64654.8","0"],["64657.7","0"],["64659.6","0"],["64662.2","0"],["64662.5","0"],["64662.6","0.004258"],["64662.7","0.0015"],["64664.2","0.000117"],["64665.7","0"],["64666.2","0"],["64666.9","0.038697"],["64667","0.059915"],["64668.1","0.028164"],["64669.6","0.003763"],["64670.6","0.001"],["64672.1","0.003577"],["64672.8","0.002126"],["64673","0.153221"],["64680.1","0"],["64684.2","0.030715"],["64685.1","0.132713"],["64689.4","0.015466"]],"u":128530775,"seq":111455886459},"cts":1784086814474}
{"topic":"orderbook.50.BTCUSDT","ts":1784086814496,"type":"delta","data":{"s":"BTCUSDT","b":[["64660.9","0.385082"],["64659","0.001968"],["64657.7","0.034925"],["64656","0.018586"],["64654.9","0.329012"],["64654.8","0.033333"],["64653.8","0"],["64653.4","0.00077"],["64652.8","0"],["64651.4","0.000116"],["64647.3","0.102735"],["64638.6","0.072036"],["64638.5","0.120434"],["64636.7","0.206251"],["64632.2","0.074302"],["64632","0"],["64630.6","0"],["64630.3","0"],["64629.6","0"]],"a":[["64662.6","0"],["64668","0"],["64669.7","0.004258"],["64672.9","0.045736"],["64675.9","0.244183"],["64680.8","0.018586"],["64686","0.00016"],["64689.1","0.01686"],["64690.7","0"],["64691.4","0"],["64693.3","0"]],"u":128530776,"seq":111455886544},"cts":1784086814494}
{"topic":"orderbook.50.BTCUSDT","ts":1784086814515,"type":"delta","data":{"s":"BTCUSDT","b":[["64656.5","0.032222"],["64654.9","0.054701"],["64653.4","0.00385"],["64651","0.000106"],["64630.9","0"],["64630.7","0"]],"a":[["64661","0.155436"],["64667","0.08808"],["64667.1","0"],["64667.5","0.117"],["64668.1","0"],["64690.7","0.001241"]],"u":128530777,"seq":111455886598},"cts":1784086814515}
{"topic":"orderbook.50.BTCUSDT","ts":1784086814536,"type":"delta","data":{"s":"BTCUSDT","b":[["64660.9","0.273654"],["64657.7","0"],["64654.7","0"],["64653.4","0.007749"],["64646.4","0.207658"],["64636.7","0.203892"],["64633.4","0.101865"],["64632.2","0.010919"],["64630.9","0.037129"]],"a":[["64661","0.626783"],["64667","0.059915"],["64667.4","0.116092"],["64686.5","0.284649"],["64690.2","0"],["64690.7","0"]],"u":128530778,"seq":111455886672},"cts":1784086814534}
{"topic":"orderbook.50.BTCUSDT","ts":1784086814556,"type":"delta","data":{"s":"BTCUSDT","b":[["64660.9","0.067627"],["64657.7","0.050091"],["64657.6","0"],["64654.9","0"],["64654.7","0.032223"],["64654.4","0.117"],["64651.1","0.02"],["64647.1","0.001241"],["64645","0.05"],["64630.9","0"]],"a":[["64661","0.642724"],["64665.2","0.091734"],["64666.8","0.097638"],["64667","0.09137"],["64689.2","0"],["64689.4","0"]],"u":128530779,"seq":111455886769},"cts":1784086814554}
{"topic":"orderbook.50.BTCUSDT","ts":1784086814575,"type":"delta","data":{"s":"BTCUSDT","b":[["64657.7","0"],["64654.8","0.08056"],["64648.4","0.091979"],["64647.3","0"],["64630.9","0.037129"]],"a":[["64662.8","0.028167"],["64665.1","0.027383"],["64685.1","0.212532"],["64687.7","0"],["64689.1","0"]],"u":128530780,"seq":111455886821},"cts":1784086814574}
{"topic":"publicTrade.BTCUSDT","ts":1784086814577,"type":"snapshot","data":[{"i":"2290000001178591510","T":1784086814576,"p":"64660.9","v":"0.032219","S":"Sell","seq":111455886827,"s":"BTCUSDT","BT":false,"RPI":false},{"i":"2290000001178591511","T":1784086814576,"p":"64660.9","v":"0.015408","S":"Sell","seq":111455886827,"s":"BTCUSDT","BT":false,"RPI":false},{"i":"2290000001178591512","T":1784086814576,"p":"64660.9","v":"0.019973","S":"Sell","seq":111455886827,"s":"BTCUSDT","BT":false,"RPI":false}]}
{"topic":"publicTrade.BTCUSDT","ts":1784086814578,"type":"snapshot","data":[{"i":"2290000001178591513","T":1784086814577,"p":"64660.9","v":"0.000027","S":"Sell","seq":111455886834,"s":"BTCUSDT","BT":false,"RPI":false}]}
{"topic":"publicTrade.BTCUSDT","ts":1784086814580,"type":"snapshot","data":[{"i":"2290000001178591514","T":1784086814579,"p":"64659","v":"0.001968","S":"Sell","seq":111455886852,"s":"BTCUSDT","BT":false,"RPI":false}]}
{"topic":"orderbook.50.BTCUSDT","ts":1784086814596,"type":"delta","data":{"s":"BTCUSDT","b":[["64660.9","0"],["64659","0"],["64656.5","0.052222"],["64656","0"],["64654.8","0.047227"],["64654.4","0"],["64653.4","0.00231"],["64651.4","0.018702"],["64651.1","0"],["64650","0.033333"],["64647.9","0.117"],["64645","0.02"],["64643.8","0"],["64643.6","0"],["64643.2","0.039932"],["64640.8","0.033636"],["64639.2","0.005"],["64638.7","0"],["64638.5","0.117"],["64634.1","0.004047"],["64630.7","0.05"],["64630.6","0.122"],["64630.3","0.001226"]],"a":[["64656.6","1.066135"],["64659","0.031297"],["64659.1","0.203209"],["64660","0.001737"],["64660.9","0.192776"],["64661","0.057457"],["64663.3","0.018586"],["64665.2","0.095497"],["64665.3","0.004258"],["64667.3","0.038129"],["64669.6","0"],["64669.7","0"],["64669.8","0.028163"],["64677.1","0.03"],["64684.5","0"],["64685","0"],["64685.1","0"],["64685.3","0"],["64686","0"],["64686.5","0"]],"u":128530781,"seq":111455886995},"cts":1784086814595}
{"topic":"orderbook.50.BTCUSDT","ts":1784086814616,"type":"delta","data":{"s":"BTCUSDT","b":[["64654.8","0"],["64653.4","0"],["64651.5","0.015564"],["64651.4","0.000116"],["64648.2","0.001921"],["64644.5","0.018586"],["64634.2","0"]],"a":[["64659","0.056657"],["64660.9","0.018074"],["64661","0.153569"],["64662.6","0.0015"],["64662.7","0.043768"],["64663.3","0"],["64665.1","0"],["64684.5","0.001241"]],"u":128530782,"seq":111455887077},"cts":1784086814614}
{"topic":"orderbook.50.BTCUSDT","ts":1784086814636,"type":"delta","data":{"s":"BTCUSDT","b":[["64651.5","0"],["64650","0"],["64646.2","0.033333"],["64629.6","0.06189"]],"a":[["64656.6","1.084721"],["64658.6","0.028168"],["64660.9","0.044453"],["64661","0.138109"],["64661.3","0"],["64661.7","0.003093"],["64684.5","0"]],"u":128530783,"seq":111455887168},"cts":1784086814634}
{"topic":"publicTrade.BTCUSDT","ts":1784086814636,"type":"snapshot","data":[{"i":"2290000001178591515","T":1784086814636,"p":"64656.5","v":"0.032222","S":"Sell","seq":111455887173,"s":"BTCUSDT","BT":false,"RPI":false},{"i":"2290000001178591516","T":1784086814636,"p":"64656.5","v":"0.02","S":"Sell","seq":111455887173,"s":"BTCUSDT","BT":false,"RPI":false}]}
{"topic":"orderbook.50.BTCUSDT","ts":1784086814656,"type":"delta","data":{"s":"BTCUSDT","b":[["64656.5","0"],["64654.7","0.02"],["64650.8","0.027692"],["64648.2","0"],["64639.2","0"],["64637.4","0.121092"],["64634.1","0.000613"],["64632.3","0.003434"],["64629.2","0.048057"]],"a":[["64654.8","0.918396"],["64656.5","0.566259"],["64656.6","0.018586"],["64658.6","0.015408"],["64658.7","0.028168"],["64659","0"],["64659.1","0.178409"],["64660","0"],["64661","0.141969"],["64663.4","0.003763"],["64663.5","0.04295"],["64665.2","0.091734"],["64665.3","0"],["64684.2","0"]],"u":128530784,"seq":111455887283},"cts":1784086814654}
{"topic":"orderbook.50.BTCUSDT","ts":1784086814676,"type":"delta","data":{"s":"BTCUSDT","b":[],"a":[["64654.8","0.933804"],["64656.4","0.240839"],["64656.5","0.173404"],["64658.6","0"],["64661","0.138889"]],"u":128530785,"seq":111455887347},"cts":1784086814675}
{"topic":"orderbook.50.BTCUSDT","ts":1784086814696,"type":"delta","data":{"s":"BTCUSDT","b":[["64647.2","0"],["64644.5","0"],["64629.1","0.116092"],["64628.8","0.002359"]],"a":[["64654.8","0.935705"],["64656.4","0.118972"],["64656.5","0.061158"],["64658.7","0"],["64660","0.001737"]],"u":128530786,"seq":111455887416},"cts":1784086814694}
{"topic":"publicTrade.BTCUSDT","ts":1784086814701,"type":"snapshot","data":[{"i":"2290000001178591517","T":1784086814700,"p":"64654.7","v":"0.002","S":"Sell","seq":111455887438,"s":"BTCUSDT","BT":false,"RPI":false}]}
{"topic":"publicTrade.BTCUSDT","ts":1784086814710,"type":"snapshot","data":[{"i":"2290000001178591518","T":1784086814709,"p":"64654.7","v":"0.018","S":"Sell","seq":111455887502,"s":"BTCUSDT","BT":false,"RPI":false}]}
{"topic":"publicTrade.BTCUSDT","ts":1784086814713,"type":"snapshot","data":[{"i":"2290000001178591519","T":1784086814712,"p":"64653.3","v":"0.001241","S":"Sell","seq":111455887525,"s":"BTCUSDT","BT":false,"RPI":false}]}
{"topic":"orderbook.50.BTCUSDT","ts":1784086814716,"type":"delta","data":{"s":"BTCUSDT","b":[["64654.7","0"],["64653.3","0"],["64650.8","0"],["64646.6","0.027694"],["64645","0"],["64641.1","0.06406"],["64640.3","0.001958"],["64637.4","0"],["64636.7","0.208892"],["64635","0"],["64633.5","0.037129"],["64632.3","0"],["64631.6","0.003434"],["64631.2","0.012311"],["64628.7","0.001391"]],"a":[["64652.5","0.350531"],["64653.4","0.838846"],["64654.7","0.589611"],["64654.8","0.352866"],["64656.4","0.077059"],["64656.6","0"],["64661.7","0"],["64662.7","0.047531"],["64662.8","0.032425"],["64663.4","0"],["64663.5","0.038692"],["64671","0.003092"],["64674.9","0.012541"],["64683.6","0"],["64683.7","0"]],"u":128530787,"seq":111455887567},"cts":1784086814715}
{"topic":"orderbook.50.BTCUSDT","ts":1784086814735,"type":"delta","data":{"s":"BTCUSDT","b":[["64652.4","0.029"],["64643.2","0.064574"],["64642","0"],["64640.2","0.0015"],["64638.6","0.034959"],["64636.7","0.203892"],["64635","0.005"],["64631.6","0"],["64630","0.003434"],["64628.7","0"]],"a":[["64652.5","0.94659"],["64653.3","0.513212"],["64653.4","0.29491"],["64654.7","0.0248"],["64654.8","0.143701"],["64659.1","0.03"],["64659.6","0.001241"],["64660.8","0.0015"],["64661","0.138792"],["64661.1","0.004258"],["64662.6","0"],["64662.7","0.043768"],["64662.8","0.028167"],["64663.5","0.154784"],["64664.7","0.037129"],["64680.8","0"],["64681.1","0"],["64681.7","0"],["64683.5","0"]],"u":128530788,"seq":111455887668},"cts":1784086814734}
{"topic":"orderbook.50.BTCUSDT","ts":1784086814755,"type":"delta","data":{"s":"BTCUSDT","b":[["64651.8","0.032224"],["64651","0"],["64628.8","0"],["64628.7","0.001391"]],"a":[["64652.6","0.018586"],["64653.2","0.138558"],["64653.3","0.005"],["64654.8","0.144471"],["64655.6","0.02817"],["64656.4","0.027211"],["64662.7","0.063468"],["64669.6","0.005"],["64672.9","0"],["64678.4","0"],["64679","0"],["64680","0"]],"u":128530789,"seq":111455887733},"cts":1784086814754}
{"topic":"orderbook.50.BTCUSDT","ts":1784086814776,"type":"delta","data":{"s":"BTCUSDT","b":[["64646.2","0"],["64642.3","0.033333"],["64641.6","0.018586"],["64628.7","0"]],"a":[["64654.8","0.145241"]],"u":128530790,"seq":111455887785},"cts":1784086814775}
{"topic":"orderbook.50.BTCUSDT","ts":1784086814796,"type":"delta","data":{"s":"BTCUSDT","b":[["64652.4","0.0317"],["64646.4","0.179971"]],"a":[["64652.5","0.7959"],["64653.2","0"],["64654.8","0.146781"],["64678.4","0.037129"]],"u":128530791,"seq":111455887813},"cts":1784086814795}
{"topic":"orderbook.50.BTCUSDT","ts":1784086814817,"type":"delta","data":{"s":"BTCUSDT","b":[["64652.4","0.03478"]],"a":[["64652.5","0.81736"],["64654.8","0.14488"],["64659","0.006"],["64672.9","0.04948"],["64678.3","0"],["64678.4","0"]],"u":128530792,"seq":111455887861},"cts":1784086814816}
{"topic":"orderbook.50.BTCUSDT","ts":1784086814856,"type":"delta","data":{"s":"BTCUSDT","b":[],"a":[["64652.7","0.001933"],["64654.8","0.14411"],["64663.7","0.002165"],["64676.7","0.00433"],["64677.1","0"],["64677.2","0"],["64678.1","0"]],"u":128530793,"seq":111455887917},"cts":1784086814855}
{"topic":"orderbook.50.BTCUSDT","ts":1784086814876,"type":"delta","data":{"s":"BTCUSDT","b":[["64652.4","0.029"]],"a":[["64653.3","0.151859"],["64653.4","0.17791"],["64654.8","0.0248"]],"u":128530794,"seq":111455887947},"cts":1784086814873}
{"topic":"orderbook.50.BTCUSDT","ts":1784086814896,"type":"delta","data":{"s":"BTCUSDT","b":[["64646.4","0.181518"]],"a":[["64652.5","0.83668"],["64653.3","0.08132"],["64659","0.123"]],"u":128530795,"seq":111455887977},"cts":1784086814895}
{"topic":"orderbook.50.BTCUSDT","ts":1784086814916,"type":"delta","data":{"s":"BTCUSDT","b":[],"a":[["64652.5","0.8444"],["64656.4","0.060447"],["64668.5","0.003092"],["64671","0"]],"u":128530796,"seq":111455888015},"cts":1784086814914}
{"topic":"orderbook.50.BTCUSDT","ts":1784086814936,"type":"delta","data":{"s":"BTCUSDT","b":[["64652.4","0.032662"]],"a":[],"u":128530797,"seq":111455888040},"cts":1784086814935}
{"topic":"orderbook.50.BTCUSDT","ts":1784086814956,"type":"delta","data":{"s":"BTCUSDT","b":[],"a":[["64665.4","0.001"],["64666.4","0"]],"u":128530798,"seq":111455888064},"cts":1784086814954}
{"topic":"orderbook.50.BTCUSDT","ts":1784086814976,"type":"delta","data":{"s":"BTCUSDT","b":[["64645.1","0"],["64628.7","0.001391"]],"a":[["64652.5","0.85213"],["64654.8","0"],["64677.1","0.03"]],"u":128530799,"seq":111455888074},"cts":1784086814973}
{"topic":"orderbook.50.BTCUSDT","ts":1784086814996,"type":"delta","data":{"s":"BTCUSDT","b":[],"a":[["64652.5","0.86372"],["64654.7","0"],["64665.4","0.002"],["64670.6","0"],["64677.2","0.116208"],["64678.1","0.509352"]],"u":128530800,"seq":111455888093},"cts":1784086814994}
{"topic":"orderbook.50.BTCUSDT","ts":1784086815019,"type":"delta","data":{"s":"BTCUSDT","b":[["64651.2","0.030053"],["64636.8","0.037129"],["64629.1","0"],["64628.7","0"]],"a":[["64653.8","0.028623"],["64655","0.03"],["64677.2","0"],["64678.1","0"]],"u":128530801,"seq":111455888111},"cts":1784086815013}
{"topic":"orderbook.50.BTCUSDT","ts":1784086815036,"type":"delta","data":{"s":"BTCUSDT","b":[],"a":[["64652.5","0.56643"]],"u":128530802,"seq":111455888128},"cts":1784086815032}
{"topic":"orderbook.50.BTCUSDT","ts":1784086815056,"type":"delta","data":{"s":"BTCUSDT","b":[["64644.8","0.181764"],["64629.2","0"]],"a":[["64652.5","0.58297"],["64653.4","0.03"]],"u":128530803,"seq":111455888147},"cts":1784086815055}
{"topic":"orderbook.50.BTCUSDT","ts":1784086815076,"type":"delta","data":{"s":"BTCUSDT","b":[["64646.4","0.220205"],["64641.5","0.088395"],["64634.9","0"]],"a":[["64652.5","0.764713"],["64653.3","0.039863"],["64653.8","0"],["64664.7","0"],["64677.2","0.116208"],["64678.1","0.509352"]],"u":128530804,"seq":111455888167},"cts":1784086815074}
{"topic":"orderbook.50.BTCUSDT","ts":1784086815096,"type":"delta","data":{"s":"BTCUSDT","b":[["64652.4","0.149662"],["64651.9","0.018624"],["64647.9","0"],["64643.2","0.103307"],["64642.3","0"],["64641.6","0"],["64629.2","0.048057"],["64629.1","0.116092"]],"a":[["64652.5","0.58297"],["64652.6","0"],["64669.6","0.289646"],["64675.6","0.028181"]],"u":128530805,"seq":111455888219},"cts":1784086815094}
{"topic":"orderbook.50.BTCUSDT","ts":1784086815116,"type":"delta","data":{"s":"BTCUSDT","b":[["64652.4","0.435065"],["64648.4","0.066851"],["64645.5","0.033333"],["64644.8","0"],["64642","0.0015"],["64640.3","0"],["64640.2","0"],["64628.7","0.001391"]],"a":[["64652.5","0.450562"],["64653.4","0"],["64655.6","0"],["64657.3","0.028621"],["64660.8","0"],["64661","0.04268"],["64662.6","0.0015"],["64663.7","0"],["64669.5","0.094901"],["64678.2","0.015468"]],"u":128530806,"seq":111455888289},"cts":1784086815114}
{"topic":"orderbook.50.BTCUSDT","ts":1784086815136,"type":"delta","data":{"s":"BTCUSDT","b":[["64646.4","0.218658"]],"a":[["64652.5","0.424862"],["64653.3","0.005"],["64657.3","0"],["64660.9","0.018074"],["64678.3","0.001241"]],"u":128530807,"seq":111455888331},"cts":1784086815133}
{"topic":"orderbook.50.BTCUSDT","ts":1784086815156,"type":"delta","data":{"s":"BTCUSDT","b":[["64648.6","0.033333"],["64647.4","0.001969"],["64646.4","0.179971"],["64645.5","0"],["64628.7","0"]],"a":[["64652.5","0.432592"],["64652.7","0"],["64678.4","0.037129"]],"u":128530808,"seq":111455888352},"cts":1784086815154}
{"topic":"orderbook.50.BTCUSDT","ts":1784086815176,"type":"delta","data":{"s":"BTCUSDT","b":[["64652.4","0.468398"],["64650.8","0.025802"],["64629.1","0"]],"a":[],"u":128530809,"seq":111455888365},"cts":1784086815175}
{"topic":"orderbook.50.BTCUSDT","ts":1784086815216,"type":"delta","data":{"s":"BTCUSDT","b":[],"a":[["64652.5","0.421012"],["64656.7","0.001911"],["64678.4","0"]],"u":128530810,"seq":111455888395},"cts":1784086815211}
{"topic":"orderbook.50.BTCUSDT","ts":1784086815236,"type":"delta","data":{"s":"BTCUSDT","b":[],"a":[["64652.5","0.432602"]],"u":128530811,"seq":111455888439},"cts":1784086815235}
{"topic":"orderbook.50.BTCUSDT","ts":1784086815256,"type":"delta","data":{"s":"BTCUSDT","b":[["64650.8","0"],["64629.1","0.116092"]],"a":[["64652.5","0.448062"],["64678.2","0"],["64678.4","0.037129"]],"u":128530812,"seq":111455888457},"cts":1784086815252}
{"topic":"orderbook.50.BTCUSDT","ts":1784086815276,"type":"delta","data":{"s":"BTCUSDT","b":[["64652.4","0.638172"]],"a":[["64652.5","0.432602"]],"u":128530813,"seq":111455888465},"cts":1784086815273}
{"topic":"orderbook.50.BTCUSDT","ts":1784086815295,"type":"delta","data":{"s":"BTCUSDT","b":[["64652.4","0.935462"],["64647.8","0.018586"],["64639.8","0.037129"],["64629.2","0"],["64629.1","0"]],"a":[["64652.5","0.235425"],["64667.3","0.001"],["64669.5","0.13203"]],"u":128530814,"seq":111455888532},"cts":1784086815295}
{"topic":"orderbook.50.BTCUSDT","ts":1784086815316,"type":"delta","data":{"s":"BTCUSDT","b":[["64643.3","0.037129"],["64637.2","0.002359"],["64630","0"],["64629.6","0"]],"a":[["64652.5","0.208375"],["64653.3","0"],["64656.7","0"],["64661","0.046938"],["64661.1","0"],["64666.7","0.140649"],["64667","0"],["64679","0.03036"],["64680","0.044819"],["64680.8","0.018586"]],"u":128530815,"seq":111455888574},"cts":1784086815314}
{"topic":"orderbook.50.BTCUSDT","ts":1784086815336,"type":"delta","data":{"s":"BTCUSDT","b":[],"a":[["64652.5","0.200645"]],"u":128530816,"seq":111455888584},"cts":1784086815331}
{"topic":"orderbook.50.BTCUSDT","ts":1784086815355,"type":"delta","data":{"s":"BTCUSDT","b":[],"a":[["64660.8","0.001863"],["64665.7","0.087724"],["64680","0"],["64680.8","0"]],"u":128530817,"seq":111455888595},"cts":1784086815354}
{"topic":"orderbook.50.BTCUSDT","ts":1784086815376,"type":"delta","data":{"s":"BTCUSDT","b":[],"a":[["64657.5","0.001547"],["64679","0"]],"u":128530818,"seq":111455888603},"cts":1784086815358}
{"topic":"orderbook.50.BTCUSDT","ts":1784086815436,"type":"delta","data":{"s":"BTCUSDT","b":[["64648.6","0"],["64640.3","0.003094"],["64634.6","0"],["64629.6","0.065324"]],"a":[],"u":128530819,"seq":111455888624},"cts":1784086815427}
{"topic":"publicTrade.BTCUSDT","ts":1784086815451,"type":"snapshot","data":[{"i":"2290000001178591520","T":1784086815450,"p":"64652.4","v":"0.002","S":"Sell","seq":111455888631,"s":"BTCUSDT","BT":false,"RPI":false}]}
{"topic":"orderbook.50.BTCUSDT","ts":1784086815456,"type":"delta","data":{"s":"BTCUSDT","b":[["64652.4","0.966795"]],"a":[],"u":128530820,"seq":111455888633},"cts":1784086815454}
{"topic":"orderbook.50.BTCUSDT","ts":1784086815516,"type":"delta","data":{"s":"BTCUSDT","b":[["64647.4","0"],["64629.2","0.048057"]],"a":[],"u":128530821,"seq":111455888668},"cts":1784086815512}
{"topic":"orderbook.50.BTCUSDT","ts":1784086815556,"type":"delta","data":{"s":"BTCUSDT","b":[["64652.4","0.669505"]],"a":[],"u":128530822,"seq":111455888684},"cts":1784086815555}
{"topic":"orderbook.50.BTCUSDT","ts":1784086815576,"type":"delta","data":{"s":"BTCUSDT","b":[["64649.6","0.002059"],["64629.2","0"]],"a":[["64652.5","0.202245"],["64659","0.1246"]],"u":128530823,"seq":111455888716},"cts":1784086815571}
{"topic":"orderbook.50.BTCUSDT","ts":1784086815596,"type":"delta","data":{"s":"BTCUSDT","b":[],"a":[["64657.2","0.028621"],["64678.4","0"]],"u":128530824,"seq":111455888725},"cts":1784086815593}
{"topic":"orderbook.50.BTCUSDT","ts":1784086815616,"type":"delta","data":{"s":"BTCUSDT","b":[["64652.4","0.678005"]],"a":[["64652.5","0.327745"],["64659","0.1331"]],"u":128530825,"seq":111455888743},"cts":1784086815614}
{"topic":"orderbook.50.BTCUSDT","ts":1784086815636,"type":"delta","data":{"s":"BTCUSDT","b":[["64652.4","0.669505"],["64640.4","0.003094"],["64640.3","0"]],"a":[],"u":128530826,"seq":111455888751},"cts":1784086815623}
{"topic":"orderbook.50.BTCUSDT","ts":1784086815656,"type":"delta","data":{"s":"BTCUSDT","b":[["64652.4","0.683235"],["64641","0.003094"],["64640.4","0"]],"a":[["64652.5","0.333745"],["64656.2","0.015408"],["64659","0.1391"],["64678.3","0"]],"u":128530827,"seq":111455888766},"cts":1784086815653}
{"topic":"orderbook.50.BTCUSDT","ts":1784086815676,"type":"delta","data":{"s":"BTCUSDT","b":[["64652.4","0.677235"],["64650.8","0.025802"],["64629.6","0"]],"a":[["64660.8","0"],["64678.3","0.001241"]],"u":128530828,"seq":111455888775},"cts":1784086815665}
{"topic":"orderbook.50.BTCUSDT","ts":1784086815696,"type":"delta","data":{"s":"BTCUSDT","b":[["64652.4","0.684965"]],"a":[],"u":128530829,"seq":111455888779},"cts":1784086815693}
{"topic":"orderbook.50.BTCUSDT","ts":1784086815717,"type":"delta","data":{"s":"BTCUSDT","b":[],"a":[["64658.5","0.002061"],["64666","0.003092"],["64668.5","0"],["64678.3","0"]],"u":128530830,"seq":111455888786},"cts":1784086815714}
{"topic":"orderbook.50.BTCUSDT","ts":1784086815736,"type":"delta","data":{"s":"BTCUSDT","b":[["64652.4","0.651632"]],"a":[],"u":128530831,"seq":111455888793},"cts":1784086815733}
{"topic":"orderbook.50.BTCUSDT","ts":1784086815755,"type":"delta","data":{"s":"BTCUSDT","b":[["64650.8","0"],["64649.7","0.033333"],["64648.3","0.082384"],["64634.1","0"],["64629.6","0.065324"]],"a":[],"u":128530832,"seq":111455888806},"cts":1784086815754}
{"topic":"orderbook.50.BTCUSDT","ts":1784086815796,"type":"delta","data":{"s":"BTCUSDT","b":[],"a":[["64655.7","0.015408"],["64656.2","0"]],"u":128530833,"seq":111455888816},"cts":1784086815794}
{"topic":"orderbook.50.BTCUSDT","ts":1784086815819,"type":"delta","data":{"s":"BTCUSDT","b":[["64632.2","0.01"]],"a":[["64653.5","0.015408"],["64655.7","0"]],"u":128530834,"seq":111455888824},"cts":1784086815817}
{"topic":"orderbook.50.BTCUSDT","ts":1784086815856,"type":"delta","data":{"s":"BTCUSDT","b":[],"a":[["64653.5","0"],["64654.1","0.015408"]],"u":128530835,"seq":111455888835},"cts":1784086815854}
{"topic":"orderbook.50.BTCUSDT","ts":1784086815896,"type":"delta","data":{"s":"BTCUSDT","b":[["64630.3","0"],["64629.2","0.048057"]],"a":[["64653.3","0.015408"],["64654.1","0"]],"u":128530836,"seq":111455888841},"cts":1784086815887}
{"topic":"orderbook.50.BTCUSDT","ts":1784086815956,"type":"delta","data":{"s":"BTCUSDT","b":[["64649.7","0"],["64646.7","0.037129"],["64638.7","0.116092"],["64629.2","0"]],"a":[["64652.5","0.0847"],["64653.3","0"],["64656.4","0"],["64656.6","0.015408"],["64657.2","0"],["64657.5","0"],["64662.6","0"],["64662.7","0.064968"],["64662.8","0"],["64663","0.032963"],["64663.5","0.038692"],["64666.7","0.256741"],["64667.4","0"],["64669.5","0.094901"],["64673","0.116092"],["64675.6","0"],["64675.8","0"],["64678","0.037129"],["64678.3","0.001241"],["64679","0.03036"],["64680","0.044819"],["64680.8","0.018586"],["64681.1","0.116092"],["64681.7","0.001933"]],"u":128530837,"seq":111455889007},"cts":1784086815954}
{"topic":"orderbook.50.BTCUSDT","ts":1784086815976,"type":"delta","data":{"s":"BTCUSDT","b":[["64652.4","0.948115"],["64647.8","0"],["64638.8","0.0814"],["64638.6","0"],["64634.2","0.018586"]],"a":[["64652.5","0.0421"],["64655","0"],["64656.6","0"],["64658.5","0"],["64658.9","0.001547"],["64662.7","0.045268"],["64665.7","0"],["64666.7","0.221164"],["64673.5","0.03"],["64682.2","0.037129"],["64683.5","0.06694"]],"u":128530838,"seq":111455889064},"cts":1784086815973}
{"topic":"orderbook.50.BTCUSDT","ts":1784086815996,"type":"delta","data":{"s":"BTCUSDT","b":[["64652.4","0.709765"]],"a":[["64652.5","0.0847"],["64662.6","0.116092"],["64682.1","0.055848"],["64682.2","0"],["64683.5","0"]],"u":128530839,"seq":111455889121},"cts":1784086815994}
{"topic":"orderbook.50.BTCUSDT","ts":1784086816016,"type":"delta","data":{"s":"BTCUSDT","b":[["64646.7","0"],["64643.3","0"],["64629.2","0.048057"],["64629.1","0.116092"]],"a":[["64656.4","0.069194"],["64660.7","0.032965"],["64661.3","0.001962"],["64662.5","0.037129"],["64667.4","0.037129"],["64675.2","0.037129"],["64679","0"],["64680","0"],["64680.8","0"],["64681.1","0"],["64681.7","0"],["64682.1","0"]],"u":128530840,"seq":111455889153},"cts":1784086816015}
{"topic":"orderbook.50.BTCUSDT","ts":1784086816036,"type":"delta","data":{"s":"BTCUSDT","b":[["64652.4","0.713615"]],"a":[["64662.5","0.121634"],["64662.7","0.0015"]],"u":128530841,"seq":111455889184},"cts":1784086816033}
{"topic":"orderbook.50.BTCUSDT","ts":1784086816056,"type":"delta","data":{"s":"BTCUSDT","b":[["64652.4","0.702005"]],"a":[["64660.7","0"],["64679","0.03036"]],"u":128530842,"seq":111455889200},"cts":1784086816053}
{"topic":"orderbook.50.BTCUSDT","ts":1784086816076,"type":"delta","data":{"s":"BTCUSDT","b":[["64652.4","0.725195"]],"a":[["64657","0.015408"],["64659.6","0.034206"],["64679","0"]],"u":128530843,"seq":111455889213},"cts":1784086816070}
{"topic":"orderbook.50.BTCUSDT","ts":1784086816096,"type":"delta","data":{"s":"BTCUSDT","b":[],"a":[["64657","0"],["64679","0.03036"]],"u":128530844,"seq":111455889218},"cts":1784086816090}
{"topic":"orderbook.50.BTCUSDT","ts":1784086816116,"type":"delta","data":{"s":"BTCUSDT","b":[],"a":[["64652.5","0.086545"]],"u":128530845,"seq":111455889239},"cts":1784086816115}
{"topic":"orderbook.50.BTCUSDT","ts":1784086816136,"type":"delta","data":{"s":"BTCUSDT","b":[["64629.2","0.786516"]],"a":[],"u":128530846,"seq":111455889242},"cts":1784086816118}
{"topic":"orderbook.50.BTCUSDT","ts":1784086816156,"type":"delta","data":{"s":"BTCUSDT","b":[["64652.4","0.740655"]],"a":[],"u":128530847,"seq":111455889254},"cts":1784086816149}
{"topic":"publicTrade.BTCUSDT","ts":1784086816162,"type":"snapshot","data":[{"i":"2290000001178591521","T":1784086816161,"p":"64652.5","v":"0.02","S":"Buy","seq":111455889264,"s":"BTCUSDT","BT":false,"RPI":false},{"i":"2290000001178591522","T":1784086816161,"p":"64652.5","v":"0.006","S":"Buy","seq":111455889264,"s":"BTCUSDT","BT":false,"RPI":false},{"i":"2290000001178591523","T":1784086816161,"p":"64652.5","v":"0.0016","S":"Buy","seq":111455889264,"s":"BTCUSDT","BT":false,"RPI":false},{"i":"2290000001178591524","T":1784086816161,"p":"64652.5","v":"0.006","S":"Buy","seq":111455889264,"s":"BTCUSDT","BT":false,"RPI":false},{"i":"2290000001178591525","T":1784086816161,"p":"64652.5","v":"0.0025","S":"Buy","seq":111455889264,"s":"BTCUSDT","BT":false,"RPI":false},{"i":"2290000001178591526","T":1784086816161,"p":"64652.5","v":"0.0025","S":"Buy","seq":111455889264,"s":"BTCUSDT","BT":false,"RPI":false},{"i":"2290000001178591527","T":1784086816161,"p":"64652.5","v":"0.0025","S":"Buy","seq":111455889264,"s":"BTCUSDT","BT":false,"RPI":false},{"i":"2290000001178591528","T":1784086816161,"p":"64652.5","v":"0.001","S":"Buy","seq":111455889264,"s":"BTCUSDT","BT":false,"RPI":false},{"i":"2290000001178591529","T":1784086816161,"p":"64652.5","v":"0.001845","S":"Buy","seq":111455889264,"s":"BTCUSDT","BT":false,"RPI":false}]}
{"topic":"publicTrade.BTCUSDT","ts":1784086816167,"type":"snapshot","data":[{"i":"2290000001178591530","T":1784086816166,"p":"64656.5","v":"0.0312","S":"Buy","seq":111455889434,"s":"BTCUSDT","BT":false,"RPI":false},{"i":"2290000001178591531","T":1784086816166,"p":"64656.5","v":"0.0426","S":"Buy","seq":111455889434,"s":"BTCUSDT","BT":false,"RPI":false},{"i":"2290000001178591532","T":1784086816166,"p":"64656.5","v":"0.006","S":"Buy","seq":111455889434,"s":"BTCUSDT","BT":false,"RPI":false}]}
{"topic":"orderbook.50.BTCUSDT","ts":1784086816175,"type":"delta","data":{"s":"BTCUSDT","b":[["64658.9","0.750399"],["64656.5","0.315793"],["64656.4","0.137"],["64655.1","0.033333"],["64652.5","0.284264"],["64652.4","0.343786"],["64651.9","0"],["64650.9","0.092594"],["64643.9","0.039658"],["64643.3","0.153221"],["64641.7","0"],["64641.4","0.005"],["64640.8","0"],["64636.1","0.003434"],["64635","0"],["64630.9","0"],["64630.7","0"],["64630.6","0"],["64629.6","0"],["64629.2","0"],["64629.1","0"]],"a":[["64652.5","0"],["64656.4","0"],["64656.5","0"],["64658.9","0"],["64659","0.124399"],["64659.1","0"],["64659.6","0.001241"],["64660.9","0"],["64661","0.046517"],["64662.5","0"],["64662.6","0"],["64663","0"],["64666.5","0.032962"],["64666.7","0.105072"],["64667.4","0"],["64667.5","0.125021"],["64669.6","0.005"],["64669.8","0"],["64671.7","0.093238"],["64673","0"],["64673.1","0.034237"],["64673.8","0.116092"],["64674.9","0"],["64675.2","0"],["64675.5","0.037129"],["64677.2","0.000116"],["64677.9","0.116092"],["64678","0"],["64680","0.044819"],["64680.8","0.018586"],["64681.7","0.001933"],["64682.1","0.055848"],["64683.3","0.037129"],["64683.6","0.117"],["64683.7","0.000116"],["64684.5","0.001241"],["64684.9","0.116092"]],"u":128530848,"seq":111455889625},"cts":1784086816174}
{"topic":"orderbook.50.BTCUSDT","ts":1784086816196,"type":"delta","data":{"s":"BTCUSDT","b":[["64658.9","0.80503"],["64656.5","0"],["64652.6","0.234351"],["64652.5","0.074586"],["64652.4","0.167012"],["64651.2","0"],["64648.1","0.0015"],["64646.4","0.221976"],["64646","0.002"],["64642","0"],["64641.5","0"],["64640.5","0"],["64630.9","0.037129"],["64630.7","0.05"]],"a":[["64659","0.1014"],["64661","0.038917"],["64662.7","0"],["64663.4","0.039564"],["64665.5","0.0076"],["64666.5","0"],["64667.4","0.037129"],["64668.7","0.0015"],["64669.5","0"],["64671.6","0.027832"],["64672.8","0.039255"],["64673.5","0"],["64680","0"],["64680.9","0.03"],["64684.9","0"]],"u":128530849,"seq":111455889727},"cts":1784086816194}
{"topic":"orderbook.50.BTCUSDT","ts":1784086816216,"type":"delta","data":{"s":"BTCUSDT","b":[["64652.6","0.110024"],["64652.4","0.155432"],["64649.6","0"],["64644.8","0.06398"],["64643.2","0.051073"],["64636.5","0.061883"],["64630.7","0"]],"a":[["64661.3","0"],["64667.4","0.153221"],["64678.9","0.023565"]],"u":128530850,"seq":111455889770},"cts":1784086816214}
{"topic":"publicTrade.BTCUSDT","ts":1784086816231,"type":"snapshot","data":[{"i":"2290000001178591533","T":1784086816230,"p":"64658.9","v":"0.002","S":"Sell","seq":111455889809,"s":"BTCUSDT","BT":false,"RPI":false}]}
{"topic":"orderbook.50.BTCUSDT","ts":1784086816236,"type":"delta","data":{"s":"BTCUSDT","b":[["64658.9","0.80303"],["64657","0.01"],["64656","0.01"],["64652.4","0.122972"],["64633.9","2.383094"],["64631.9","0"],["64631.2","0"],["64630.9","0"]],"a":[["64659","0.2432"],["64665","0.003092"],["64666","0"]],"u":128530851,"seq":111455889817},"cts":1784086816235}
{"topic":"orderbook.50.BTCUSDT","ts":1784086816256,"type":"delta","data":{"s":"BTCUSDT","b":[["64652.4","0.120662"],["64650.9","0"],["64641.1","0"],["64636.7","0.874686"],["64631.9","0.000117"],["64631.2","0.012311"]],"a":[],"u":128530852,"seq":111455889853},"cts":1784086816254}
{"topic":"orderbook.50.BTCUSDT","ts":1784086816276,"type":"delta","data":{"s":"BTCUSDT","b":[["64656","0.012015"],["64652.6","0.067935"],["64652.4","0.117"],["64643.2","0"],["64630.9","0.037129"]],"a":[["64665","0"],["64666.6","0.001957"],["64666.8","0.10073"]],"u":128530853,"seq":111455889872},"cts":1784086816273}
{"topic":"orderbook.50.BTCUSDT","ts":1784086816296,"type":"delta","data":{"s":"BTCUSDT","b":[["64643.9","0.324304"],["64643.2","0.031951"],["64630.9","0"]],"a":[],"u":128530854,"seq":111455889883},"cts":1784086816291}
{"topic":"orderbook.50.BTCUSDT","ts":1784086816316,"type":"delta","data":{"s":"BTCUSDT","b":[["64646.4","0.321267"]],"a":[["64659","0.24158"],["64667.4","0.157479"],["64667.5","0.120763"]],"u":128530855,"seq":111455889905},"cts":1784086816314}
{"topic":"orderbook.50.BTCUSDT","ts":1784086816336,"type":"delta","data":{"s":"BTCUSDT","b":[["64656.4","0.02"],["64652.4","0"],["64630.9","0.037129"]],"a":[["64659","0.25704"]],"u":128530856,"seq":111455889926},"cts":1784086816334}
{"topic":"orderbook.50.BTCUSDT","ts":1784086816356,"type":"delta","data":{"s":"BTCUSDT","b":[["64652.6","0.031917"]],"a":[["64665.2","0.11032"]],"u":128530857,"seq":111455889939},"cts":1784086816354}
{"topic":"orderbook.50.BTCUSDT","ts":1784086816396,"type":"delta","data":{"s":"BTCUSDT","b":[["64658.9","0.809354"]],"a":[["64659","0.2929"],["64665.5","0.153095"]],"u":128530858,"seq":111455889958},"cts":1784086816394}
{"topic":"orderbook.50.BTCUSDT","ts":1784086816416,"type":"delta","data":{"s":"BTCUSDT","b":[],"a":[["64659","0.29676"],["64660.3","0.005535"],["64663.4","0.085753"],["64684.5","0"]],"u":128530859,"seq":111455889971},"cts":1784086816415}
{"topic":"orderbook.50.BTCUSDT","ts":1784086816436,"type":"delta","data":{"s":"BTCUSDT","b":[["64648.1","0.004593"],["64641","0"],["64630.7","0.05"]],"a":[["64662","0.015408"],["64683.7","0"]],"u":128530860,"seq":111455889982},"cts":1784086816424}
{"topic":"orderbook.50.BTCUSDT","ts":1784086816456,"type":"delta","data":{"s":"BTCUSDT","b":[],"a":[["64660.9","0.016216"],["64683.6","0"]],"u":128530861,"seq":111455889989},"cts":1784086816454}
{"topic":"orderbook.50.BTCUSDT","ts":1784086816476,"type":"delta","data":{"s":"BTCUSDT","b":[["64658.9","0.807814"]],"a":[],"u":128530862,"seq":111455889997},"cts":1784086816472}
{"topic":"orderbook.50.BTCUSDT","ts":1784086816496,"type":"delta","data":{"s":"BTCUSDT","b":[["64649.3","0.091241"],["64648.1","1.548335"],["64630.7","0"]],"a":[["64659","0.29568"],["64659.8","0.015408"],["64662","0"]],"u":128530863,"seq":111455890006},"cts":1784086816495}
{"topic":"orderbook.50.BTCUSDT","ts":1784086816516,"type":"delta","data":{"s":"BTCUSDT","b":[["64655.1","0"],["64648.4","0.551151"],["64630.7","0.05"]],"a":[["64659","0.15164"],["64659.8","0"],["64660.9","0"],["64661.1","0.015408"],["64683.6","0.117"]],"u":128530864,"seq":111455890025},"cts":1784086816514}
{"topic":"orderbook.50.BTCUSDT","ts":1784086816536,"type":"delta","data":{"s":"BTCUSDT","b":[["64658.9","0.841147"],["64657.9","0.030646"],["64648.2","1.546833"],["64648.1","0.0015"],["64630.9","0"],["64630.7","0"]],"a":[["64659","0.0702"],["64661.1","0"],["64683.7","0.000116"]],"u":128530865,"seq":111455890069},"cts":1784086816535}
{"topic":"orderbook.50.BTCUSDT","ts":1784086816556,"type":"delta","data":{"s":"BTCUSDT","b":[["64658","0.021689"],["64631.2","0"]],"a":[["64659","0.1014"]],"u":128530866,"seq":111455890079},"cts":1784086816554}
{"topic":"orderbook.50.BTCUSDT","ts":1784086816576,"type":"delta","data":{"s":"BTCUSDT","b":[],"a":[["64666.6","0"],["64684.5","0.001241"]],"u":128530867,"seq":111455890081},"cts":1784086816566}
{"topic":"orderbook.50.BTCUSDT","ts":1784086816596,"type":"delta","data":{"s":"BTCUSDT","b":[["64658.9","0.842687"]],"a":[["64659","0.0702"],["64667.4","0.041387"]],"u":128530868,"seq":111455890097},"cts":1784086816593}
{"topic":"orderbook.50.BTCUSDT","ts":1784086816618,"type":"delta","data":{"s":"BTCUSDT","b":[["64658.9","0.843457"]],"a":[["64669.1","0.001883"],["64684.5","0"]],"u":128530869,"seq":111455890107},"cts":1784086816615}
{"topic":"orderbook.50.BTCUSDT","ts":1784086816656,"type":"delta","data":{"s":"BTCUSDT","b":[["64658.9","0.846537"]],"a":[],"u":128530870,"seq":111455890118},"cts":1784086816652}
{"topic":"orderbook.50.BTCUSDT","ts":1784086816675,"type":"delta","data":{"s":"BTCUSDT","b":[["64658.9","0.844997"]],"a":[],"u":128530871,"seq":111455890123},"cts":1784086816674}
{"topic":"orderbook.50.BTCUSDT","ts":1784086816696,"type":"delta","data":{"s":"BTCUSDT","b":[["64658.9","0.844227"]],"a":[["64663.3","0.015408"],["64667.4","0.004258"],["64683.7","0"]],"u":128530872,"seq":111455890137},"cts":1784086816695}
{"topic":"orderbook.50.BTCUSDT","ts":1784086816715,"type":"delta","data":{"s":"BTCUSDT","b":[["64658.9","0.843457"]],"a":[["64659","0.1014"]],"u":128530873,"seq":111455890154},"cts":1784086816713}
{"topic":"orderbook.50.BTCUSDT","ts":1784086816736,"type":"delta","data":{"s":"BTCUSDT","b":[["64658.9","0.841147"]],"a":[["64659","0.2184"],["64663.3","0"],["64666.6","0.037129"],["64666.8","0.097638"],["64670","0.003092"],["64683.6","0"]],"u":128530874,"seq":111455890182},"cts":1784086816733}
{"topic":"orderbook.50.BTCUSDT","ts":1784086816756,"type":"delta","data":{"s":"BTCUSDT","b":[["64658.9","0.842687"],["64656.4","0.047633"]],"a":[["64660.9","0.016216"],["64663.2","0.015408"],["64664.8","0.032962"],["64681.7","0"],["64682.1","0"],["64683.3","0"]],"u":128530875,"seq":111455890208},"cts":1784086816754}
{"topic":"orderbook.50.BTCUSDT","ts":1784086816776,"type":"delta","data":{"s":"BTCUSDT","b":[["64658.9","0.843457"]],"a":[["64660.9","0"],["64663.2","0"],["64669.1","0"],["64681.7","0.001933"],["64682.1","0.055848"],["64683.3","0.037129"]],"u":128530876,"seq":111455890219},"cts":1784086816775}
{"topic":"publicTrade.BTCUSDT","ts":1784086816779,"type":"snapshot","data":[{"i":"2290000001178591534","T":1784086816778,"p":"64658.9","v":"0.002524","S":"Sell","seq":111455890225,"s":"BTCUSDT","BT":false,"RPI":false}]}
{"topic":"orderbook.50.BTCUSDT","ts":1784086816796,"type":"delta","data":{"s":"BTCUSDT","b":[["64658.9","0.841703"]],"a":[["64663","0.015408"],["64683.3","0"]],"u":128530877,"seq":111455890227},"cts":1784086816792}
{"topic":"orderbook.50.BTCUSDT","ts":1784086816816,"type":"delta","data":{"s":"BTCUSDT","b":[["64658.9","0.843243"]],"a":[["64666.7","0.107074"]],"u":128530878,"seq":111455890241},"cts":1784086816815}
{"topic":"orderbook.50.BTCUSDT","ts":1784086816836,"type":"delta","data":{"s":"BTCUSDT","b":[["64658.9","0.842473"]],"a":[],"u":128530879,"seq":111455890245},"cts":1784086816827}
{"topic":"orderbook.50.BTCUSDT","ts":1784086816856,"type":"delta","data":{"s":"BTCUSDT","b":[["64658.9","0.841703"]],"a":[],"u":128530880,"seq":111455890247},"cts":1784086816850}
{"topic":"orderbook.50.BTCUSDT","ts":1784086816876,"type":"delta","data":{"s":"BTCUSDT","b":[["64658.9","0.840163"]],"a":[],"u":128530881,"seq":111455890250},"cts":1784086816870}
{"topic":"orderbook.50.BTCUSDT","ts":1784086816896,"type":"delta","data":{"s":"BTCUSDT","b":[["64658.9","0.838623"]],"a":[["64663","0"],["64663.4","0.101161"],["64683.3","0.037129"]],"u":128530882,"seq":111455890254},"cts":1784086816894}
{"topic":"orderbook.50.BTCUSDT","ts":1784086816936,"type":"delta","data":{"s":"BTCUSDT","b":[],"a":[["64663.4","0.085753"]],"u":128530883,"seq":111455890268},"cts":1784086816923}
{"topic":"orderbook.50.BTCUSDT","ts":1784086816956,"type":"delta","data":{"s":"BTCUSDT","b":[["64658.9","0.854843"]],"a":[["64659","0.219947"],["64663.4","0.101161"]],"u":128530884,"seq":111455890280},"cts":1784086816952}
{"topic":"orderbook.50.BTCUSDT","ts":1784086816976,"type":"delta","data":{"s":"BTCUSDT","b":[["64658.9","0.862573"],["64652.5","0.030646"]],"a":[],"u":128530885,"seq":111455890283},"cts":1784086816970}
{"topic":"orderbook.50.BTCUSDT","ts":1784086816996,"type":"delta","data":{"s":"BTCUSDT","b":[["64652.6","0.018801"]],"a":[["64663.2","0.015408"],["64663.4","0.085753"],["64683.3","0"]],"u":128530886,"seq":111455890287},"cts":1784086816982}
{"topic":"orderbook.50.BTCUSDT","ts":1784086817056,"type":"delta","data":{"s":"BTCUSDT","b":[["64658.9","0.890703"]],"a":[["64661.6","0.015408"],["64663.2","0"]],"u":128530887,"seq":111455890306},"cts":1784086817050}
{"topic":"orderbook.50.BTCUSDT","ts":1784086817076,"type":"delta","data":{"s":"BTCUSDT","b":[],"a":[["64660.9","0.016216"],["64677.2","0.012333"],["64682.1","0"]],"u":128530888,"seq":111455890317},"cts":1784086817073}
{"topic":"orderbook.50.BTCUSDT","ts":1784086817096,"type":"delta","data":{"s":"BTCUSDT","b":[],"a":[["64661.6","0"],["64662.2","0.015408"]],"u":128530889,"seq":111455890325},"cts":1784086817080}
{"topic":"orderbook.50.BTCUSDT","ts":1784086817115,"type":"delta","data":{"s":"BTCUSDT","b":[],"a":[["64662.2","0"],["64682.1","0.055848"]],"u":128530890,"seq":111455890330},"cts":1784086817114}
{"topic":"orderbook.50.BTCUSDT","ts":1784086817136,"type":"delta","data":{"s":"BTCUSDT","b":[],"a":[["64660.9","0"],["64662","0.015408"]],"u":128530891,"seq":111455890340},"cts":1784086817127}
{"topic":"orderbook.50.BTCUSDT","ts":1784086817156,"type":"delta","data":{"s":"BTCUSDT","b":[],"a":[["64660.9","0.016216"],["64661.8","0.015408"],["64662","0"],["64682.1","0"]],"u":128530892,"seq":111455890349},"cts":1784086817149}
{"topic":"orderbook.50.BTCUSDT","ts":1784086817176,"type":"delta","data":{"s":"BTCUSDT","b":[["64648.7","1.546821"],["64648.2","0"]],"a":[],"u":128530893,"seq":111455890357},"cts":1784086817173}
{"topic":"orderbook.50.BTCUSDT","ts":1784086817196,"type":"delta","data":{"s":"BTCUSDT","b":[["64648.8","0.530056"],["64648.4","0"]],"a":[],"u":128530894,"seq":111455890363},"cts":1784086817193}
{"topic":"orderbook.50.BTCUSDT","ts":1784086817256,"type":"delta","data":{"s":"BTCUSDT","b":[],"a":[["64661.8","0"],["64663","0.015408"]],"u":128530895,"seq":111455890377},"cts":1784086817253}
{"topic":"orderbook.50.BTCUSDT","ts":1784086817276,"type":"delta","data":{"s":"BTCUSDT","b":[],"a":[["64659","0.188747"],["64660.9","0"],["64682.1","0.055848"]],"u":128530896,"seq":111455890387},"cts":1784086817274}
{"topic":"orderbook.50.BTCUSDT","ts":1784086817296,"type":"delta","data":{"s":"BTCUSDT","b":[["64652.5","0"],["64631.2","0.012311"]],"a":[],"u":128530897,"seq":111455890406},"cts":1784086817292}
{"topic":"orderbook.50.BTCUSDT","ts":1784086817316,"type":"delta","data":{"s":"BTCUSDT","b":[["64652.6","0"],["64630.9","0.037129"]],"a":[],"u":128530898,"seq":111455890418},"cts":1784086817314}
{"topic":"orderbook.50.BTCUSDT","ts":1784086817375,"type":"delta","data":{"s":"BTCUSDT","b":[["64658.9","0.898433"],["64636.6","0.003434"],["64636.1","0"]],"a":[["64667.4","0"],["64667.7","0.101924"],["64683.3","0.037129"]],"u":128530899,"seq":111455890433},"cts":1784086817372}
{"topic":"orderbook.50.BTCUSDT","ts":1784086817418,"type":"delta","data":{"s":"BTCUSDT","b":[["64658.9","0.150425"],["64658","0"],["64656.4","0.027633"],["64653.1","0.033333"],["64652.4","0.117"],["64649.3","0"],["64643.3","0.116092"],["64633.9","0"],["64630.7","0.05"]],"a":[["64659","0.688202"],["64662","0.027574"],["64663","0"],["64664.8","0"],["64665.2","0.091734"],["64665.5","0.0076"],["64666.5","0.116092"]],"u":128530900,"seq":111455890521},"cts":1784086817417}
{"topic":"orderbook.50.BTCUSDT","ts":1784086817436,"type":"delta","data":{"s":"BTCUSDT","b":[["64658.9","0.134965"],["64656","0.01"],["64652.5","0.044578"],["64636.7","0"],["64634.1","0.152146"],["64630.7","0"]],"a":[["64660.9","0.019848"],["64662","0"],["64663.4","0.039564"],["64666.7","0.105072"]],"u":128530901,"seq":111455890559},"cts":1784086817435}
{"topic":"publicTrade.BTCUSDT","ts":1784086817442,"type":"snapshot","data":[{"i":"2290000001178591535","T":1784086817441,"p":"64658.9","v":"0.027631","S":"Sell","seq":111455890578,"s":"BTCUSDT","BT":false,"RPI":false},{"i":"2290000001178591536","T":1784086817441,"p":"64658.9","v":"0.02","S":"Sell","seq":111455890578,"s":"BTCUSDT","BT":false,"RPI":false},{"i":"2290000001178591537","T":1784086817441,"p":"64658.9","v":"0.004784","S":"Sell","seq":111455890578,"s":"BTCUSDT","BT":false,"RPI":false},{"i":"2290000001178591538","T":1784086817441,"p":"64658.9","v":"0.00077","S":"Sell","seq":111455890578,"s":"BTCUSDT","BT":false,"RPI":false},{"i":"2290000001178591539","T":1784086817441,"p":"64658.9","v":"0.00386","S":"Sell","seq":111455890578,"s":"BTCUSDT","BT":false,"RPI":false},{"i":"2290000001178591540","T":1784086817441,"p":"64658.9","v":"0.00386","S":"Sell","seq":111455890578,"s":"BTCUSDT","BT":false,"RPI":false},{"i":"2290000001178591541","T":1784086817441,"p":"64658.9","v":"0.00773","S":"Sell","seq":111455890578,"s":"BTCUSDT","BT":false,"RPI":false},{"i":"2290000001178591542","T":1784086817441,"p":"64658.9","v":"0.00773","S":"Sell","seq":111455890578,"s":"BTCUSDT","BT":false,"RPI":false},{"i":"2290000001178591543","T":1784086817441,"p":"64658.9","v":"0.00386","S":"Sell","seq":111455890578,"s":"BTCUSDT","BT":false,"RPI":false},{"i":"2290000001178591544","T":1784086817441,"p":"64658.9","v":"0.00773","S":"Sell","seq":111455890578,"s":"BTCUSDT","BT":false,"RPI":false}]}
{"topic":"orderbook.50.BTCUSDT","ts":1784086817456,"type":"delta","data":{"s":"BTCUSDT","b":[["64658.9","0"],["64656.4","0"],["64653.1","0"],["64651.8","0"],["64649.4","0.033333"],["64648.1","0"],["64648","0.0015"],["64643.9","0.284646"],["64643.3","0"],["64641.4","0"],["64640.4","0.005"],["64639.8","0"],["64637.8","0.028055"],["64637.2","0"],["64636.6","0"],["64635.6","0.003434"],["64630.7","0.05"],["64630.6","0.122"],["64629.2","0.048057"],["64629.1","0.116092"],["64628.7","0.001391"]],"a":[["64658","0.897869"],["64658.3","0.027576"],["64658.9","0.219586"],["64659","0.148547"],["64660.9","0"],["64661.8","0.018586"],["64663.3","0.037129"],["64664.5","0.0076"],["64665.5","0"],["64666.5","0.119855"],["64666.7","0.10933"],["64667.5","0.117"],["64667.7","0.097666"],["64680.9","0"],["64681.7","0"],["64682.1","0"],["64683.3","0"]],"u":128530902,"seq":111455890708},"cts":1784086817454}
{"topic":"orderbook.50.BTCUSDT","ts":1784086817476,"type":"delta","data":{"s":"BTCUSDT","b":[["64657.9","0.050646"],["64648.7","0"],["64648","0"],["64646.8","0.0015"],["64646.7","0.002089"],["64642.8","1.546962"],["64628.7","0"]],"a":[["64658","0.919897"],["64658.9","0.064047"],["64659","0.147"],["64667.4","0.0015"],["64668.7","0"]],"u":128530903,"seq":111455890811},"cts":1784086817474}
{"topic":"orderbook.50.BTCUSDT","ts":1784086817496,"type":"delta","data":{"s":"BTCUSDT","b":[["64657.9","0.081846"],["64648.8","0.068953"],["64646.8","0"],["64642.2","0.0015"]],"a":[["64659","0.16632"],["64660.9","0.027575"],["64662.8","0.0015"],["64667.4","0"],["64680.8","0"]],"u":128530904,"seq":111455890865},"cts":1784086817495}
{"topic":"orderbook.50.BTCUSDT","ts":1784086817516,"type":"delta","data":{"s":"BTCUSDT","b":[["64657.2","0.030747"],["64643.2","0.489158"],["64629.1","0"]],"a":[["64659","0.177918"],["64669","0.003092"],["64670","0"]],"u":128530905,"seq":111455890931},"cts":1784086817514}
{"topic":"orderbook.50.BTCUSDT","ts":1784086817535,"type":"delta","data":{"s":"BTCUSDT","b":[["64647.8","0.018586"],["64629.2","0"]],"a":[["64658","0.927627"],["64661.8","0"],["64663.3","0"],["64669.4","0.002165"],["64676.7","0.002165"],["64680.8","0.018586"]],"u":128530906,"seq":111455891027},"cts":1784086817534}
{"topic":"orderbook.50.BTCUSDT","ts":1784086817556,"type":"delta","data":{"s":"BTCUSDT","b":[["64657.9","0.0938"],["64649.8","0.172407"],["64649.4","0"],["64643.6","0.033333"],["64630.6","0"]],"a":[["64658","0.928707"],["64678.9","0"],["64681.7","0.001933"]],"u":128530907,"seq":111455891069},"cts":1784086817555}
{"topic":"orderbook.50.BTCUSDT","ts":1784086817576,"type":"delta","data":{"s":"BTCUSDT","b":[["64652.5","0.080723"]],"a":[["64658","0.631417"],["64659","0.158598"],["64666.4","0.037129"],["64666.6","0"]],"u":128530908,"seq":111455891109},"cts":1784086817572}
{"topic":"orderbook.50.BTCUSDT","ts":1784086817596,"type":"delta","data":{"s":"BTCUSDT","b":[["64657.9","0.2108"],["64652.8","0.030749"],["64648.1","0.0015"],["64642.2","0"],["64630.7","0"]],"a":[["64658","0.631769"],["64658.3","0"],["64659","0.117"],["64662.8","0"],["64668.2","0.032961"],["64668.7","0.0015"],["64680.8","0.048408"]],"u":128530909,"seq":111455891148},"cts":1784086817593}
{"topic":"orderbook.50.BTCUSDT","ts":1784086817617,"type":"delta","data":{"s":"BTCUSDT","b":[["64648.2","0.033333"],["64643.6","0"]],"a":[["64658","0.599239"],["64659","0"],["64678.9","0.023512"]],"u":128530910,"seq":111455891169},"cts":1784086817614}
{"topic":"orderbook.50.BTCUSDT","ts":1784086817636,"type":"delta","data":{"s":"BTCUSDT","b":[["64657.9","0.344757"],["64648.2","0.107847"],["64646.7","0"],["64642.9","0.116092"]],"a":[["64658","0.202698"],["64658.9","0"],["64666.4","0"],["64666.5","0.003763"],["64682.1","0.055848"],["64683.3","0.037129"]],"u":128530911,"seq":111455891219},"cts":1784086817635}
{"topic":"orderbook.50.BTCUSDT","ts":1784086817656,"type":"delta","data":{"s":"BTCUSDT","b":[["64657.9","0.56717"],["64653.2","0.033333"],["64648.8","0.097254"],["64647.8","0"],["64645.3","1.546902"],["64642.8","0"]],"a":[["64658","0.08169"],["64660.5","0.015408"],["64660.8","0.019848"],["64660.9","0"],["64661","0.038436"],["64669.4","0"]],"u":128530912,"seq":111455891341},"cts":1784086817654}
{"topic":"orderbook.50.BTCUSDT","ts":1784086817676,"type":"delta","data":{"s":"BTCUSDT","b":[["64657.9","0.600503"],["64654.9","0.001951"],["64654.3","0.149561"],["64653.3","0.019128"],["64653.2","0"],["64649.8","0"],["64646.7","1.546869"],["64645.3","0"],["64643.2","0.031951"],["64630.9","0"]],"a":[["64658","0.079662"],["64660.5","0"],["64660.8","0"],["64667.4","0.037129"],["64683.6","0.117"]],"u":128530913,"seq":111455891428},"cts":1784086817674}
{"topic":"orderbook.50.BTCUSDT","ts":1784086817696,"type":"delta","data":{"s":"BTCUSDT","b":[["64654.4","0.053823"],["64653.6","0.018586"],["64653.3","0"],["64652.5","0.044578"],["64647.1","1.5481"],["64646.7","0"],["64634.6","0.002359"],["64631.2","0"]],"a":[["64662.4","0.015408"],["64663.9","0.027573"],["64683.3","0"],["64683.6","0"]],"u":128530914,"seq":111455891474},"cts":1784086817693}
{"topic":"orderbook.50.BTCUSDT","ts":1784086817716,"type":"delta","data":{"s":"BTCUSDT","b":[["64657.9","0.602895"],["64648.8","0.549826"],["64647.4","1.546852"],["64647.1","0.001241"],["64631.9","0"]],"a":[["64660.9","0.016072"],["64662.4","0"]],"u":128530915,"seq":111455891492},"cts":1784086817714}
{"topic":"orderbook.50.BTCUSDT","ts":1784086817736,"type":"delta","data":{"s":"BTCUSDT","b":[["64652.4","0"],["64643.2","0.061596"],["64631.9","0.000117"]],"a":[["64660.9","0"],["64666.6","0.00189"]],"u":128530916,"seq":111455891506},"cts":1784086817733}
{"topic":"orderbook.50.BTCUSDT","ts":1784086817756,"type":"delta","data":{"s":"BTCUSDT","b":[["64652.5","0"],["64631.7","2.292178"]],"a":[["64658","0.0702"],["64659.2","0.000481"],["64662.5","0.027574"],["64663.9","0"],["64665.1","0.018586"],["64668","0.003092"],["64669","0"],["64681.7","0"],["64682.1","0"]],"u":128530917,"seq":111455891530},"cts":1784086817754}
{"topic":"orderbook.50.BTCUSDT","ts":1784086817776,"type":"delta","data":{"s":"BTCUSDT","b":[["64657.9","0.413815"]],"a":[["64658","0.1872"]],"u":128530918,"seq":111455891545},"cts":1784086817773}
{"topic":"orderbook.50.BTCUSDT","ts":1784086817796,"type":"delta","data":{"s":"BTCUSDT","b":[],"a":[["64658","0.21533"],["64661.5","0.015408"],["64680.8","0"]],"u":128530919,"seq":111455891556},"cts":1784086817793}
{"topic":"publicTrade.BTCUSDT","ts":1784086817799,"type":"snapshot","data":[{"i":"2290000001178591545","T":1784086817799,"p":"64658","v":"0.00003","S":"Buy","seq":111455891561,"s":"BTCUSDT","BT":false,"RPI":false}]}
{"topic":"orderbook.50.BTCUSDT","ts":1784086817817,"type":"delta","data":{"s":"BTCUSDT","b":[["64657.9","0.438615"]],"a":[["64658","0.2153"],["64660.9","0.016072"],["64661.1","0.015408"],["64661.5","0"],["64679","0"]],"u":128530920,"seq":111455891576},"cts":1784086817806}
{"topic":"orderbook.50.BTCUSDT","ts":1784086817835,"type":"delta","data":{"s":"BTCUSDT","b":[],"a":[["64666.6","0"],["64679","0.03036"]],"u":128530921,"seq":111455891589},"cts":1784086817834}
{"topic":"orderbook.50.BTCUSDT","ts":1784086817856,"type":"delta","data":{"s":"BTCUSDT","b":[],"a":[["64658","0.23462"],["64660.7","0.015408"],["64661.1","0"]],"u":128530922,"seq":111455891602},"cts":1784086817850}
{"topic":"orderbook.50.BTCUSDT","ts":1784086817876,"type":"delta","data":{"s":"BTCUSDT","b":[["64657.2","0.056549"]],"a":[["64658","0.25008"],["64660","0.017145"],["64660.6","0.016072"],["64660.7","0"],["64660.9","0"],["64663.1","0.002064"]],"u":128530923,"seq":111455891618},"cts":1784086817874}
{"topic":"orderbook.50.BTCUSDT","ts":1784086817896,"type":"delta","data":{"s":"BTCUSDT","b":[["64657.3","0.02285"],["64631.7","0"]],"a":[["64659.8","0.015408"],["64660","0.001737"],["64660.6","0"]],"u":128530924,"seq":111455891624},"cts":1784086817892}
{"topic":"orderbook.50.BTCUSDT","ts":1784086817955,"type":"delta","data":{"s":"BTCUSDT","b":[],"a":[["64659.8","0"],["64680.8","0.048408"]],"u":128530925,"seq":111455891638},"cts":1784086817949}
{"topic":"orderbook.50.BTCUSDT","ts":1784086817976,"type":"delta","data":{"s":"BTCUSDT","b":[["64657.9","0.440162"]],"a":[["64660.5","0.001547"],["64680.8","0"]],"u":128530926,"seq":111455891644},"cts":1784086817958}
{"topic":"orderbook.50.BTCUSDT","ts":1784086818036,"type":"delta","data":{"s":"BTCUSDT","b":[],"a":[["64658","0.2153"]],"u":128530927,"seq":111455891663},"cts":1784086818033}
{"topic":"orderbook.50.BTCUSDT","ts":1784086818056,"type":"delta","data":{"s":"BTCUSDT","b":[["64657.9","0.588796"],["64654.3","0"],["64631.7","2.292178"]],"a":[["64658","0.20263"],["64664.2","0.148736"]],"u":128530928,"seq":111455891688},"cts":1784086818052}
{"topic":"orderbook.50.BTCUSDT","ts":1784086818076,"type":"delta","data":{"s":"BTCUSDT","b":[["64654.4","0"],["64631.2","0.012311"]],"a":[["64658","0.18717"],["64663.1","0"],["64663.4","0.086685"],["64680.8","0.048408"]],"u":128530929,"seq":111455891696},"cts":1784086818074}
{"topic":"orderbook.50.BTCUSDT","ts":1784086818095,"type":"delta","data":{"s":"BTCUSDT","b":[["64657.9","0.619442"]],"a":[["64676","0.03"],["64680.8","0"]],"u":128530930,"seq":111455891701},"cts":1784086818087}
{"topic":"orderbook.50.BTCUSDT","ts":1784086818136,"type":"delta","data":{"s":"BTCUSDT","b":[],"a":[["64665.8","0.003262"]],"u":128530931,"seq":111455891706},"cts":1784086818127}
{"topic":"orderbook.50.BTCUSDT","ts":1784086818156,"type":"delta","data":{"s":"BTCUSDT","b":[["64657.9","0.627172"]],"a":[],"u":128530932,"seq":111455891712},"cts":1784086818151}
{"topic":"orderbook.50.BTCUSDT","ts":1784086818176,"type":"delta","data":{"s":"BTCUSDT","b":[["64657.9","0.924462"],["64657.2","0.030747"],["64656.3","0.00147"],["64631.2","0"]],"a":[["64658","0.07017"],["64660.5","0"],["64662.4","0.001547"],["64662.5","0"],["64663.4","0"],["64664.2","0.177372"],["64680.8","0.048408"],["64681.7","0.001933"]],"u":128530933,"seq":111455891762},"cts":1784086818174}
{"topic":"orderbook.50.BTCUSDT","ts":1784086818195,"type":"delta","data":{"s":"BTCUSDT","b":[["64657.3","0.015587"]],"a":[["64662.4","0"],["64664.2","0.028753"],["64667.4","0"],["64682.1","0.055848"],["64683.3","0.037129"]],"u":128530934,"seq":111455891814},"cts":1784086818194}
{"topic":"orderbook.50.BTCUSDT","ts":1784086818218,"type":"delta","data":{"s":"BTCUSDT","b":[["64649.2","1.546809"],["64647.4","0"],["64639.4","0.037129"],["64631.7","0"]],"a":[],"u":128530935,"seq":111455891869},"cts":1784086818215}
{"topic":"orderbook.50.BTCUSDT","ts":1784086818236,"type":"delta","data":{"s":"BTCUSDT","b":[["64649.3","0.562244"],["64648.8","0"]],"a":[["64665.8","0.001241"]],"u":128530936,"seq":111455891891},"cts":1784086818228}
{"topic":"orderbook.50.BTCUSDT","ts":1784086818256,"type":"delta","data":{"s":"BTCUSDT","b":[["64657.9","0.932192"],["64654.3","0.002206"],["64631.9","0"]],"a":[["64663.4","0.055928"],["64664.2","0.000117"],["64666.6","0.028635"],["64667","0.003092"],["64668","0"],["64668.2","0"],["64683.3","0"]],"u":128530937,"seq":111455891921},"cts":1784086818252}
{"topic":"orderbook.50.BTCUSDT","ts":1784086818296,"type":"delta","data":{"s":"BTCUSDT","b":[],"a":[["64668.2","0.001931"],["64682.1","0"]],"u":128530938,"seq":111455891973},"cts":1784086818294}
{"topic":"orderbook.50.BTCUSDT","ts":1784086818336,"type":"delta","data":{"s":"BTCUSDT","b":[["64654.9","0"],["64653.6","0"],["64652.4","0.002941"],["64631.9","0.000117"]],"a":[["64658","0.02757"],["64663.4","0"],["64665.1","0"],["64682.1","0.055848"],["64683.3","0.037129"]],"u":128530939,"seq":111455892079},"cts":1784086818334}
{"topic":"publicTrade.BTCUSDT","ts":1784086818337,"type":"snapshot","data":[{"i":"2290000001178591546","T":1784086818336,"p":"64658","v":"0.00157","S":"Buy","seq":111455892085,"s":"BTCUSDT","BT":false,"RPI":false},{"i":"2290000001178591547","T":1784086818336,"p":"64658","v":"0.0025","S":"Buy","seq":111455892085,"s":"BTCUSDT","BT":false,"RPI":false},{"i":"2290000001178591548","T":1784086818336,"p":"64658","v":"0.001","S":"Buy","seq":111455892085,"s":"BTCUSDT","BT":false,"RPI":false},{"i":"2290000001178591549","T":1784086818336,"p":"64658","v":"0.0025","S":"Buy","seq":111455892085,"s":"BTCUSDT","BT":false,"RPI":false},{"i":"2290000001178591550","T":1784086818336,"p":"64658","v":"0.02","S":"Buy","seq":111455892085,"s":"BTCUSDT","BT":false,"RPI":false}]}
{"topic":"publicTrade.BTCUSDT","ts":1784086818340,"type":"snapshot","data":[{"i":"2290000001178591551","T":1784086818339,"p":"64659.2","v":"0.000481","S":"Buy","seq":111455892112,"s":"BTCUSDT","BT":false,"RPI":false},{"i":"2290000001178591552","T":1784086818339,"p":"64659.6","v":"0.001241","S":"Buy","seq":111455892112,"s":"BTCUSDT","BT":false,"RPI":false}]}
{"topic":"orderbook.50.BTCUSDT","ts":1784086818356,"type":"delta","data":{"s":"BTCUSDT","b":[["64659.9","1.270691"],["64659.1","0.233585"],["64658.9","0.018586"],["64658","0.0248"],["64657.9","0.217045"],["64657.3","0"],["64656","0"],["64653.3","0.001241"],["64646.2","0.002"],["64646","0"],["64642.5","0.005"],["64640.4","0"],["64637.8","0"],["64637.7","0.003434"],["64635.6","0"],["64632.2","0"],["64631.9","0"]],"a":[["64658","0"],["64659.2","0"],["64659.6","0"],["64660","0.026837"],["64664.5","0"],["64666.5","0.0051"],["64666.6","0"],["64666.7","0.105072"],["64667.3","0.029634"],["64668.6","0.003763"],["64668.8","0.004258"],["64669.4","0.018586"],["64671.7","0"],["64677.2","0.000116"],["64680.8","0.029822"],["64683.6","0.117"],["64683.7","0.000116"],["64684.5","0.001241"]],"u":128530940,"seq":111455892365},"cts":1784086818354}
{"topic":"orderbook.50.BTCUSDT","ts":1784086818376,"type":"delta","data":{"s":"BTCUSDT","b":[["64659.2","0.160066"],["64659.1","0.14791"],["64657.9","0.215498"],["64637.7","0"],["64637.3","0.003434"],["64633.9","2.257555"],["64633.3","0"],["64633.2","0"]],"a":[["64660","0.069437"],["64668.6","0.008021"],["64668.7","0"],["64668.8","0.0015"],["64671.6","0"],["64684.9","0.116092"],["64685.1","0.171131"]],"u":128530941,"seq":111455892475},"cts":1784086818374}
{"topic":"orderbook.50.BTCUSDT","ts":1784086818396,"type":"delta","data":{"s":"BTCUSDT","b":[["64659","0.001977"],["64649.3","2.109051"],["64649.2","0"]],"a":[["64668.2","0"],["64685.3","0.330811"]],"u":128530942,"seq":111455892508},"cts":1784086818393}
{"topic":"orderbook.50.BTCUSDT","ts":1784086818416,"type":"delta","data":{"s":"BTCUSDT","b":[["64657.9","0.212708"],["64650.4","0.003677"],["64649.4","0.562244"],["64649.3","1.546807"],["64633.5","0"],["64633.4","0"]],"a":[],"u":128530943,"seq":111455892535},"cts":1784086818413}
{"topic":"orderbook.50.BTCUSDT","ts":1784086818436,"type":"delta","data":{"s":"BTCUSDT","b":[["64659.1","0.15564"],["64636.1","2.257555"],["64633.9","0"]],"a":[["64670.5","0.00192"],["64685.3","0"]],"u":128530944,"seq":111455892558},"cts":1784086818432}
{"topic":"orderbook.50.BTCUSDT","ts":1784086818456,"type":"delta","data":{"s":"BTCUSDT","b":[["64659.9","1.297741"],["64657.9","0.210316"]],"a":[],"u":128530945,"seq":111455892571},"cts":1784086818452}
{"topic":"orderbook.50.BTCUSDT","ts":1784086818476,"type":"delta","data":{"s":"BTCUSDT","b":[["64648.5","0.004412"],["64634","0"]],"a":[],"u":128530946,"seq":111455892590},"cts":1784086818473}
{"topic":"orderbook.50.BTCUSDT","ts":1784086818516,"type":"delta","data":{"s":"BTCUSDT","b":[["64659.1","0.14791"],["64657.9","0.080646"]],"a":[],"u":128530947,"seq":111455892619},"cts":1784086818514}
{"topic":"orderbook.50.BTCUSDT","ts":1784086818536,"type":"delta","data":{"s":"BTCUSDT","b":[["64659.2","0.094367"]],"a":[["64667","0"],["64672","0.003092"]],"u":128530948,"seq":111455892637},"cts":1784086818530}
{"topic":"orderbook.50.BTCUSDT","ts":1784086818556,"type":"delta","data":{"s":"BTCUSDT","b":[["64659.9","1.305471"]],"a":[["64660.3","0"],["64685.3","0.330811"]],"u":128530949,"seq":111455892649},"cts":1784086818548}
{"topic":"orderbook.50.BTCUSDT","ts":1784086818576,"type":"delta","data":{"s":"BTCUSDT","b":[["64642.2","0.037129"],["64636.1","0"]],"a":[["64667.3","0.001"],["64668.7","0.028634"],["64669.4","0"],["64672.8","0.002126"],["64675.2","0.098244"],["64685.3","0"]],"u":128530950,"seq":111455892714},"cts":1784086818574}
{"topic":"orderbook.50.BTCUSDT","ts":1784086818596,"type":"delta","data":{"s":"BTCUSDT","b":[["64657.5","0.025796"],["64634.1","0"]],"a":[["64672.8","0.039255"]],"u":128530951,"seq":111455892719},"cts":1784086818593}
{"topic":"orderbook.50.BTCUSDT","ts":1784086818615,"type":"delta","data":{"s":"BTCUSDT","b":[],"a":[["64667.5","0.145634"],["64668.7","0"],["64685.3","0.330811"]],"u":128530952,"seq":111455892738},"cts":1784086818614}
{"topic":"orderbook.50.BTCUSDT","ts":1784086818636,"type":"delta","data":{"s":"BTCUSDT","b":[["64659.9","1.313201"]],"a":[],"u":128530953,"seq":111455892748},"cts":1784086818630}
{"topic":"orderbook.50.BTCUSDT","ts":1784086818656,"type":"delta","data":{"s":"BTCUSDT","b":[["64659.9","1.315593"],["64659.2","0.057916"]],"a":[],"u":128530954,"seq":111455892756},"cts":1784086818651}
{"topic":"orderbook.50.BTCUSDT","ts":1784086818676,"type":"delta","data":{"s":"BTCUSDT","b":[],"a":[["64667.5","0.117"]],"u":128530955,"seq":111455892761},"cts":1784086818672}
{"topic":"orderbook.50.BTCUSDT","ts":1784086818695,"type":"delta","data":{"s":"BTCUSDT","b":[["64659.9","1.324403"],["64659.2","0.094662"],["64657.5","0"],["64636.1","2.257555"]],"a":[["64665.7","0.001547"],["64666.3","0.028635"],["64685.1","0"],["64685.3","0"]],"u":128530956,"seq":111455892775},"cts":1784086818694}
{"topic":"orderbook.50.BTCUSDT","ts":1784086818716,"type":"delta","data":{"s":"BTCUSDT","b":[["64659.9","1.328263"]],"a":[],"u":128530957,"seq":111455892797},"cts":1784086818710}
{"topic":"orderbook.50.BTCUSDT","ts":1784086818736,"type":"delta","data":{"s":"BTCUSDT","b":[["64659.9","1.335993"]],"a":[],"u":128530958,"seq":111455892806},"cts":1784086818733}
{"topic":"orderbook.50.BTCUSDT","ts":1784086818756,"type":"delta","data":{"s":"BTCUSDT","b":[["64636.2","0.844487"],["64634.2","0"]],"a":[],"u":128530959,"seq":111455892817},"cts":1784086818754}
{"topic":"orderbook.50.BTCUSDT","ts":1784086818776,"type":"delta","data":{"s":"BTCUSDT","b":[["64659.9","1.332133"],["64636.1","0"],["64634.2","0.018586"]],"a":[],"u":128530960,"seq":111455892822},"cts":1784086818775}
{"topic":"orderbook.50.BTCUSDT","ts":1784086818796,"type":"delta","data":{"s":"BTCUSDT","b":[["64636.2","0"],["64634","0.509702"]],"a":[],"u":128530961,"seq":111455892827},"cts":1784086818786}
{"topic":"orderbook.50.BTCUSDT","ts":1784086818816,"type":"delta","data":{"s":"BTCUSDT","b":[["64659.9","1.350199"]],"a":[],"u":128530962,"seq":111455892832},"cts":1784086818814}
{"topic":"orderbook.50.BTCUSDT","ts":1784086818836,"type":"delta","data":{"s":"BTCUSDT","b":[["64659.9","1.342469"]],"a":[["64660","0.026837"]],"u":128530963,"seq":111455892855},"cts":1784086818834}
{"topic":"orderbook.50.BTCUSDT","ts":1784086818855,"type":"delta","data":{"s":"BTCUSDT","b":[["64659.9","1.346329"]],"a":[],"u":128530964,"seq":111455892896},"cts":1784086818854}
{"topic":"orderbook.50.BTCUSDT","ts":1784086818876,"type":"delta","data":{"s":"BTCUSDT","b":[["64647","0.002"],["64646.2","0"]],"a":[["64666.3","0"],["64685.1","0.171131"]],"u":128530965,"seq":111455892907},"cts":1784086818874}
{"topic":"orderbook.50.BTCUSDT","ts":1784086818895,"type":"delta","data":{"s":"BTCUSDT","b":[["64659.9","1.320533"]],"a":[["64667.8","0.031438"],["64685.1","0"]],"u":128530966,"seq":111455892938},"cts":1784086818894}
{"topic":"orderbook.50.BTCUSDT","ts":1784086818916,"type":"delta","data":{"s":"BTCUSDT","b":[["64659.9","1.328263"]],"a":[],"u":128530967,"seq":111455892973},"cts":1784086818914}
{"topic":"orderbook.50.BTCUSDT","ts":1784086818936,"type":"delta","data":{"s":"BTCUSDT","b":[["64659.9","1.335993"]],"a":[["64660","0.069437"],["64671","0.003092"],["64672","0"]],"u":128530968,"seq":111455892995},"cts":1784086818931}
{"topic":"orderbook.50.BTCUSDT","ts":1784086818956,"type":"delta","data":{"s":"BTCUSDT","b":[["64659.9","1.343723"]],"a":[],"u":128530969,"seq":111455893003},"cts":1784086818954}
{"topic":"orderbook.50.BTCUSDT","ts":1784086818996,"type":"delta","data":{"s":"BTCUSDT","b":[["64659.9","1.369519"]],"a":[],"u":128530970,"seq":111455893014},"cts":1784086818992}
{"topic":"orderbook.50.BTCUSDT","ts":1784086819018,"type":"delta","data":{"s":"BTCUSDT","b":[["64649.5","0.037129"],["64634","0"]],"a":[],"u":128530971,"seq":111455893019},"cts":1784086819016}
{"topic":"publicTrade.BTCUSDT","ts":1784086819027,"type":"snapshot","data":[{"i":"2290000001178591553","T":1784086819026,"p":"64660","v":"0.001737","S":"Buy","seq":111455893029,"s":"BTCUSDT","BT":false,"RPI":false},{"i":"2290000001178591554","T":1784086819026,"p":"64660","v":"0.02","S":"Buy","seq":111455893029,"s":"BTCUSDT","BT":false,"RPI":false},{"i":"2290000001178591555","T":1784086819026,"p":"64660","v":"0.0016","S":"Buy","seq":111455893029,"s":"BTCUSDT","BT":false,"RPI":false},{"i":"2290000001178591556","T":1784086819026,"p":"64660","v":"0.001","S":"Buy","seq":111455893029,"s":"BTCUSDT","BT":false,"RPI":false},{"i":"2290000001178591557","T":1784086819026,"p":"64660","v":"0.0025","S":"Buy","seq":111455893029,"s":"BTCUSDT","BT":false,"RPI":false},{"i":"2290000001178591558","T":1784086819026,"p":"64660","v":"0.0426","S":"Buy","seq":111455893029,"s":"BTCUSDT","BT":false,"RPI":false},{"i":"2290000001178591559","T":1784086819026,"p":"64661","v":"0.038436","S":"Buy","seq":111455893029,"s":"BTCUSDT","BT":false,"RPI":false}]}
{"topic":"orderbook.50.BTCUSDT","ts":1784086819036,"type":"delta","data":{"s":"BTCUSDT","b":[["64663.4","1.452313"],["64660","0.353706"],["64659.9","0.271266"],["64659.1","0"],["64657","0"],["64655.1","0.104033"],["64652.8","0"],["64648.2","0"],["64646","0.005"],["64642.5","0"],["64640.8","0.003434"],["64637.3","0"],["64634","0.509702"]],"a":[["64660","0"],["64661","0"],["64663.5","0.058692"],["64665.7","0"],["64666.5","0"],["64666.7","0"],["64667","0.0051"],["64667.8","0"],["64668.6","0"],["64671.8","0.018586"],["64672.1","0.011598"],["64672.8","0.002126"],["64673.8","0"],["64675.2","0"],["64675.5","0"],["64676.7","0"],["64677.8","0.116092"],["64677.9","0"],["64683.3","0"],["64684.8","0.153221"],["64684.9","0"],["64685.1","0.171131"],["64685.3","0.330811"],["64686","0.00016"],["64687","0.032439"],["64687.7","0.037129"],["64687.9","0.284646"],["64689.1","0.023326"],["64689.2","0.039658"],["64690.2","0.000116"],["64690.3","0.015466"]],"u":128530972,"seq":111455893201},"cts":1784086819034}
{"topic":"orderbook.50.BTCUSDT","ts":1784086819056,"type":"delta","data":{"s":"BTCUSDT","b":[["64663.4","1.520769"],["64660","0.059211"],["64659.9","0.230203"],["64659.2","0.057916"],["64658.9","0"],["64657.1","0.0015"],["64654.9","0.091386"],["64653.3","0.098942"],["64651.7","0.097703"],["64649.4","0.742146"],["64648.1","0"],["64646.3","0"],["64644.7","0"],["64643.1","0"],["64641.9","0.509702"],["64634","0"],["64633.9","2.257555"],["64633.5","0.037129"]],"a":[["64665.2","0"],["64666.8","0"],["64667","0"],["64667.7","0"],["64668.8","0"],["64670","0.0051"],["64671.8","0"],["64672.9","0.091734"],["64673.1","0"],["64674.5","0.097638"],["64675.7","0"],["64676.1","0.214666"],["64677.7","0.012646"],["64677.8","0.117592"],["64678.1","0.018586"],["64685.3","0"],["64685.7","0.509352"],["64687","0"],["64687.9","0"],["64690.2","0.002281"],["64690.3","0"],["64690.7","0.001241"],["64691.2","0.061578"],["64692.7","0.116092"],["64693.5","0.005"],["64694.4","0.117"],["64695.7","0.184616"],["64695.8","0.002319"],["64696.7","0.000116"]],"u":128530973,"seq":111455893362},"cts":1784086819055}
{"topic":"orderbook.50.BTCUSDT","ts":1784086819076,"type":"delta","data":{"s":"BTCUSDT","b":[["64663.4","1.554102"],["64660","0"],["64659.9","0.237933"],["64659.2","0.04213"],["64655.2","0.088525"],["64646.4","0.116091"],["64643.3","0.061876"],["64636.5","0"],["64636.1","2.257555"],["64633.9","0"]],"a":[["64663.5","0.106392"],["64672.8","0.043884"],["64673.9","0.031435"],["64675.9","0.119767"],["64689.1","0"],["64694","0.034035"],["64696.7","0"]],"u":128530974,"seq":111455893455},"cts":1784086819075}
{"topic":"orderbook.50.BTCUSDT","ts":1784086819096,"type":"delta","data":{"s":"BTCUSDT","b":[["64660","0.015928"],["64659.9","0.230203"],["64659","0"]],"a":[["64670.5","0"],["64672.5","0.031435"],["64676","0"],["64696.1","0.28463"]],"u":128530975,"seq":111455893467},"cts":1784086819091}
{"topic":"orderbook.50.BTCUSDT","ts":1784086819117,"type":"delta","data":{"s":"BTCUSDT","b":[["64659.9","0.182753"],["64638.3","2.257721"],["64636.1","0"]],"a":[["64695.7","0.257704"]],"u":128530976,"seq":111455893491},"cts":1784086819109}
{"topic":"orderbook.50.BTCUSDT","ts":1784086819136,"type":"delta","data":{"s":"BTCUSDT","b":[["64660","0"],["64659.9","0.180361"],["64651.8","0.030297"],["64650.9","0.002359"],["64638.8","0.744219"],["64634.6","0"]],"a":[["64671","0"],["64673","0.003092"],["64679","0"],["64695.7","0.073088"],["64696.7","0.000116"]],"u":128530977,"seq":111455893525},"cts":1784086819133}
{"topic":"orderbook.50.BTCUSDT","ts":1784086819156,"type":"delta","data":{"s":"BTCUSDT","b":[["64663.4","1.556084"],["64659.9","0.146835"],["64657.9","0.05"],["64644.8","0"],["64643.2","0.191403"],["64633.4","0.101865"]],"a":[["64678.9","0"],["64679.5","0.001182"]],"u":128530978,"seq":111455893550},"cts":1784086819155}
{"topic":"orderbook.50.BTCUSDT","ts":1784086819176,"type":"delta","data":{"s":"BTCUSDT","b":[["64663.4","1.531284"],["64644","0.142184"],["64633.4","0"]],"a":[["64673.1","0.114566"],["64696.7","0"]],"u":128530979,"seq":111455893560},"cts":1784086819166}
{"topic":"orderbook.50.BTCUSDT","ts":1784086819196,"type":"delta","data":{"s":"BTCUSDT","b":[["64659.9","0.029835"],["64634.4","0.017386"],["64633.5","0"]],"a":[["64672.8","0.083049"]],"u":128530980,"seq":111455893563},"cts":1784086819183}
{"topic":"orderbook.50.BTCUSDT","ts":1784086819216,"type":"delta","data":{"s":"BTCUSDT","b":[["64663.4","1.533676"]],"a":[["64663.5","0.063792"],["64695.2","0.03036"],["64696.1","0"]],"u":128530981,"seq":111455893582},"cts":1784086819214}
{"topic":"orderbook.50.BTCUSDT","ts":1784086819236,"type":"delta","data":{"s":"BTCUSDT","b":[["64663.4","1.535061"]],"a":[["64677.7","0.014146"],["64677.8","0.116092"]],"u":128530982,"seq":111455893595},"cts":1784086819226}
{"topic":"orderbook.50.BTCUSDT","ts":1784086819256,"type":"delta","data":{"s":"BTCUSDT","b":[["64663.4","1.535831"]],"a":[["64678.8","0.09076"],["64695.8","0"]],"u":128530983,"seq":111455893631},"cts":1784086819254}
{"topic":"orderbook.50.BTCUSDT","ts":1784086819276,"type":"delta","data":{"s":"BTCUSDT","b":[["64647.9","0.039658"],["64634.2","0"]],"a":[["64678.7","0.036347"],["64695.7","0"]],"u":128530984,"seq":111455893646},"cts":1784086819272}
{"topic":"orderbook.50.BTCUSDT","ts":1784086819296,"type":"delta","data":{"s":"BTCUSDT","b":[["64663.4","1.566751"]],"a":[],"u":128530985,"seq":111455893671},"cts":1784086819293}
{"topic":"orderbook.50.BTCUSDT","ts":1784086819336,"type":"delta","data":{"s":"BTCUSDT","b":[],"a":[["64672","0.003092"],["64673","0"]],"u":128530986,"seq":111455893701},"cts":1784086819325}
{"topic":"orderbook.50.BTCUSDT","ts":1784086819355,"type":"delta","data":{"s":"BTCUSDT","b":[],"a":[["64673","0.116092"],["64695.2","0"]],"u":128530987,"seq":111455893704},"cts":1784086819347}
{"topic":"orderbook.50.BTCUSDT","ts":1784086819376,"type":"delta","data":{"s":"BTCUSDT","b":[["64650.5","0.001"],["64649.5","1.583931"],["64649.3","0"],["64647","0.001"]],"a":[["64672.8","0.126542"]],"u":128530988,"seq":111455893712},"cts":1784086819368}
{"topic":"orderbook.50.BTCUSDT","ts":1784086819396,"type":"delta","data":{"s":"BTCUSDT","b":[["64650.5","0.002"],["64649.7","1.546797"],["64649.6","0.607839"],["64649.5","0.037129"],["64649.4","0.179902"],["64647","0"],["64634.3","0"]],"a":[],"u":128530989,"seq":111455893723},"cts":1784086819394}
{"topic":"orderbook.50.BTCUSDT","ts":1784086819416,"type":"delta","data":{"s":"BTCUSDT","b":[["64651.8","0.489443"],["64649.6","0"],["64634.3","0.039658"]],"a":[],"u":128530990,"seq":111455893734},"cts":1784086819414}
{"topic":"orderbook.50.BTCUSDT","ts":1784086819436,"type":"delta","data":{"s":"BTCUSDT","b":[["64649.5","0.171867"]],"a":[],"u":128530991,"seq":111455893749},"cts":1784086819431}
{"topic":"orderbook.50.BTCUSDT","ts":1784086819456,"type":"delta","data":{"s":"BTCUSDT","b":[],"a":[["64678.1","0"],["64695.2","0.03036"]],"u":128530992,"seq":111455893751},"cts":1784086819440}
{"topic":"orderbook.50.BTCUSDT","ts":1784086819476,"type":"delta","data":{"s":"BTCUSDT","b":[["64644","0.103437"]],"a":[],"u":128530993,"seq":111455893759},"cts":1784086819469}
{"topic":"orderbook.50.BTCUSDT","ts":1784086819496,"type":"delta","data":{"s":"BTCUSDT","b":[],"a":[["64669.6","0.006547"]],"u":128530994,"seq":111455893767},"cts":1784086819490}
{"topic":"orderbook.50.BTCUSDT","ts":1784086819516,"type":"delta","data":{"s":"BTCUSDT","b":[],"a":[["64672","0"],["64679","0.003092"]],"u":128530995,"seq":111455893773},"cts":1784086819508}
{"topic":"orderbook.50.BTCUSDT","ts":1784086819536,"type":"delta","data":{"s":"BTCUSDT","b":[],"a":[["64663.5","0.106392"]],"u":128530996,"seq":111455893787},"cts":1784086819529}
{"topic":"orderbook.50.BTCUSDT","ts":1784086819596,"type":"delta","data":{"s":"BTCUSDT","b":[["64650","1.54679"],["64649.7","0"]],"a":[["64672.6","0.113737"],["64673.1","0"]],"u":128530997,"seq":111455893795},"cts":1784086819576}
{"topic":"orderbook.50.BTCUSDT","ts":1784086819636,"type":"delta","data":{"s":"BTCUSDT","b":[],"a":[["64667.3","0"],["64695.7","0.073088"]],"u":128530998,"seq":111455893810},"cts":1784086819628}
{"topic":"orderbook.50.BTCUSDT","ts":1784086819696,"type":"delta","data":{"s":"BTCUSDT","b":[["64660.3","0.025796"],["64634.3","0"]],"a":[],"u":128530999,"seq":111455893834},"cts":1784086819693}
{"topic":"orderbook.50.BTCUSDT","ts":1784086819716,"type":"delta","data":{"s":"BTCUSDT","b":[["64660.4","0.016606"],["64634.4","0"]],"a":[["64678","0.003092"],["64679","0"]],"u":128531000,"seq":111455893843},"cts":1784086819712}
{"topic":"orderbook.50.BTCUSDT","ts":1784086819756,"type":"delta","data":{"s":"BTCUSDT","b":[],"a":[["64663.5","0.063792"],["64673","0"],["64695.8","0.002319"]],"u":128531001,"seq":111455893874},"cts":1784086819755}
{"topic":"orderbook.50.BTCUSDT","ts":1784086819776,"type":"delta","data":{"s":"BTCUSDT","b":[["64663.4","1.59799"],["64660.3","0"],["64635.1","0.01546"]],"a":[["64672.5","0.100496"],["64672.8","0.002126"],["64682.9","0.030086"],["64693.6","0.03"],["64695.7","0"],["64695.8","0"]],"u":128531002,"seq":111455893956},"cts":1784086819774}
{"topic":"orderbook.50.BTCUSDT","ts":1784086819796,"type":"delta","data":{"s":"BTCUSDT","b":[["64660.4","0"],["64634.4","0.017386"]],"a":[["64682.1","0.082907"]],"u":128531003,"seq":111455893984},"cts":1784086819794}
{"topic":"orderbook.50.BTCUSDT","ts":1784086819818,"type":"delta","data":{"s":"BTCUSDT","b":[],"a":[["64682","0.037129"],["64692.6","0.037129"],["64694.4","0"],["64695.2","0"]],"u":128531004,"seq":111455894019},"cts":1784086819816}
{"topic":"orderbook.50.BTCUSDT","ts":1784086819836,"type":"delta","data":{"s":"BTCUSDT","b":[["64663.4","1.61345"]],"a":[["64691.2","0.093395"]],"u":128531005,"seq":111455894036},"cts":1784086819834}
{"topic":"orderbook.50.BTCUSDT","ts":1784086819856,"type":"delta","data":{"s":"BTCUSDT","b":[["64663.4","1.61731"],["64651.1","1.546764"],["64650","0"]],"a":[],"u":128531006,"seq":111455894056},"cts":1784086819853}
{"topic":"orderbook.50.BTCUSDT","ts":1784086819876,"type":"delta","data":{"s":"BTCUSDT","b":[],"a":[["64672.8","0.035428"],["64682.9","0"],["64694.4","0.117"]],"u":128531007,"seq":111455894075},"cts":1784086819868}
{"topic":"orderbook.50.BTCUSDT","ts":1784086819916,"type":"delta","data":{"s":"BTCUSDT","b":[],"a":[["64677","0.003092"],["64678","0"]],"u":128531008,"seq":111455894088},"cts":1784086819915}
{"topic":"orderbook.50.BTCUSDT","ts":1784086819936,"type":"delta","data":{"s":"BTCUSDT","b":[["64663.4","1.6537"]],"a":[["64664.2","0"],["64695.2","0.03036"]],"u":128531009,"seq":111455894159},"cts":1784086819935}
{"topic":"orderbook.50.BTCUSDT","ts":1784086819956,"type":"delta","data":{"s":"BTCUSDT","b":[["64663.4","1.669167"],["64655.3","0.037129"],["64634.4","0"]],"a":[["64669.6","0.005"],["64672.8","0.002126"],["64677.8","0"],["64682","0"],["64684.8","0.116092"],["64685","0.037129"],["64695.7","0.073088"]],"u":128531010,"seq":111455894244},"cts":1784086819955}
{"topic":"orderbook.50.BTCUSDT","ts":1784086819976,"type":"delta","data":{"s":"BTCUSDT","b":[],"a":[["64672.7","0.033302"],["64675.9","0.055412"],["64677","0.13777"],["64680.9","0.116092"],["64695.2","0"],["64695.7","0"]],"u":128531011,"seq":111455894290},"cts":1784086819973}
{"topic":"orderbook.50.BTCUSDT","ts":1784086819996,"type":"delta","data":{"s":"BTCUSDT","b":[["64663.4","1.629747"]],"a":[["64675.9","0.111735"]],"u":128531012,"seq":111455894328},"cts":1784086819995}
{"topic":"orderbook.50.BTCUSDT","ts":1784086820016,"type":"delta","data":{"s":"BTCUSDT","b":[["64663.4","1.625887"]],"a":[["64687.1","0.03"],["64694.4","0"]],"u":128531013,"seq":111455894354},"cts":1784086820011}
{"topic":"orderbook.50.BTCUSDT","ts":1784086820036,"type":"delta","data":{"s":"BTCUSDT","b":[["64663.4","1.601087"],["64652.2","1.546737"],["64651.1","0"]],"a":[["64670.3","0.001547"],["64678.7","0.066353"],["64694","0"]],"u":128531014,"seq":111455894374},"cts":1784086820034}
{"topic":"orderbook.50.BTCUSDT","ts":1784086820056,"type":"delta","data":{"s":"BTCUSDT","b":[["64663.4","1.608817"],["64653.4","0.773354"],["64652.3","0.530428"],["64652.2","0"],["64651.8","0"]],"a":[["64672","0.003763"],["64672.1","0.007835"],["64693.6","0"]],"u":128531015,"seq":111455894389},"cts":1784086820054}
{"topic":"orderbook.50.BTCUSDT","ts":1784086820076,"type":"delta","data":{"s":"BTCUSDT","b":[["64655.2","0.308054"],["64652.3","0.037129"]],"a":[],"u":128531016,"seq":111455894399},"cts":1784086820074}
{"topic":"orderbook.50.BTCUSDT","ts":1784086820096,"type":"delta","data":{"s":"BTCUSDT","b":[["64663.4","1.656277"],["64653.5","0.773353"],["64653.4","0"],["64652.4","0.045622"]],"a":[["64671.4","0.033303"],["64672.7","0"]],"u":128531017,"seq":111455894411},"cts":1784086820091}
{"topic":"orderbook.50.BTCUSDT","ts":1784086820116,"type":"delta","data":{"s":"BTCUSDT","b":[],"a":[["64677","0.134678"],["64679","0.003092"],["64693.5","0"]],"u":128531018,"seq":111455894424},"cts":1784086820113}
{"topic":"orderbook.50.BTCUSDT","ts":1784086820136,"type":"delta","data":{"s":"BTCUSDT","b":[["64663.4","1.648547"]],"a":[],"u":128531019,"seq":111455894429},"cts":1784086820121}
{"topic":"orderbook.50.BTCUSDT","ts":1784086820156,"type":"delta","data":{"s":"BTCUSDT","b":[["64663.4","1.652407"]],"a":[],"u":128531020,"seq":111455894440},"cts":1784086820155}
{"topic":"orderbook.50.BTCUSDT","ts":1784086820176,"type":"delta","data":{"s":"BTCUSDT","b":[["64663.4","1.644677"]],"a":[],"u":128531021,"seq":111455894442},"cts":1784086820173}
{"topic":"orderbook.50.BTCUSDT","ts":1784086820196,"type":"delta","data":{"s":"BTCUSDT","b":[["64663.4","1.670473"]],"a":[],"u":128531022,"seq":111455894446},"cts":1784086820193}
{"topic":"orderbook.50.BTCUSDT","ts":1784086820216,"type":"delta","data":{"s":"BTCUSDT","b":[["64663.4","1.678203"]],"a":[],"u":128531023,"seq":111455894455},"cts":1784086820211}
{"topic":"orderbook.50.BTCUSDT","ts":1784086820336,"type":"delta","data":{"s":"BTCUSDT","b":[],"a":[["64678","0.003092"],["64679","0"]],"u":128531024,"seq":111455894486},"cts":1784086820326}
{"topic":"orderbook.50.BTCUSDT","ts":1784086820355,"type":"delta","data":{"s":"BTCUSDT","b":[["64652.4","0.002941"]],"a":[],"u":128531025,"seq":111455894489},"cts":1784086820355}
{"topic":"orderbook.50.BTCUSDT","ts":1784086820376,"type":"delta","data":{"s":"BTCUSDT","b":[["64652.4","0.034539"]],"a":[],"u":128531026,"seq":111455894491},"cts":1784086820356}
{"topic":"orderbook.50.BTCUSDT","ts":1784086820436,"type":"delta","data":{"s":"BTCUSDT","b":[["64641.3","0.003434"],["64640.8","0"]],"a":[],"u":128531027,"seq":111455894499},"cts":1784086820430}
{"topic":"orderbook.50.BTCUSDT","ts":1784086820456,"type":"delta","data":{"s":"BTCUSDT","b":[["64663.4","1.652407"]],"a":[],"u":128531028,"seq":111455894500},"cts":1784086820446}
{"topic":"orderbook.50.BTCUSDT","ts":1784086820536,"type":"delta","data":{"s":"BTCUSDT","b":[["64663.4","1.678203"]],"a":[["64678","0"],["64679","0.003092"]],"u":128531029,"seq":111455894518},"cts":1784086820530}
{"topic":"orderbook.50.BTCUSDT","ts":1784086820619,"type":"delta","data":{"s":"BTCUSDT","b":[["64663.4","1.685933"]],"a":[],"u":128531030,"seq":111455894529},"cts":1784086820612}
{"topic":"orderbook.50.BTCUSDT","ts":1784086820716,"type":"delta","data":{"s":"BTCUSDT","b":[["64663.4","1.660137"]],"a":[],"u":128531031,"seq":111455894537},"cts":1784086820702}
{"topic":"orderbook.50.BTCUSDT","ts":1784086820735,"type":"delta","data":{"s":"BTCUSDT","b":[],"a":[["64677","0.13777"],["64679","0"],["64693.5","0.005"]],"u":128531032,"seq":111455894542},"cts":1784086820727}
{"topic":"orderbook.50.BTCUSDT","ts":1784086820796,"type":"delta","data":{"s":"BTCUSDT","b":[["64656.3","0"],["64634.4","0.017386"]],"a":[],"u":128531033,"seq":111455894550},"cts":1784086820782}
{"topic":"orderbook.50.BTCUSDT","ts":1784086820856,"type":"delta","data":{"s":"BTCUSDT","b":[["64654.3","0"],["64634.3","0.039658"]],"a":[],"u":128531034,"seq":111455894564},"cts":1784086820849}
{"topic":"orderbook.50.BTCUSDT","ts":1784086820876,"type":"delta","data":{"s":"BTCUSDT","b":[["64640.5","2.251074"],["64638.3","0"]],"a":[],"u":128531035,"seq":111455894567},"cts":1784086820873}
{"topic":"orderbook.50.BTCUSDT","ts":1784086820896,"type":"delta","data":{"s":"BTCUSDT","b":[["64643.2","0.846753"],["64638.8","0.0814"]],"a":[],"u":128531036,"seq":111455894571},"cts":1784086820884}
{"topic":"orderbook.50.BTCUSDT","ts":1784086820936,"type":"delta","data":{"s":"BTCUSDT","b":[["64652.4","0.031598"]],"a":[],"u":128531037,"seq":111455894575},"cts":1784086820930}
{"topic":"orderbook.50.BTCUSDT","ts":1784086820956,"type":"delta","data":{"s":"BTCUSDT","b":[["64653.8","0.773349"],["64653.5","0"]],"a":[["64667.7","0.015408"],["64693.5","0"]],"u":128531038,"seq":111455894577},"cts":1784086820947}
{"topic":"orderbook.50.BTCUSDT","ts":1784086821016,"type":"delta","data":{"s":"BTCUSDT","b":[["64650.4","0"],["64634.2","0.018586"]],"a":[],"u":128531039,"seq":111455894591},"cts":1784086821003}
{"topic":"orderbook.50.BTCUSDT","ts":1784086821036,"type":"delta","data":{"s":"BTCUSDT","b":[],"a":[["64677","0.134678"],["64679","0.003092"],["64692.7","0"]],"u":128531040,"seq":111455894595},"cts":1784086821032}
{"topic":"orderbook.50.BTCUSDT","ts":1784086821076,"type":"delta","data":{"s":"BTCUSDT","b":[["64648.5","0"],["64633.5","0.037129"]],"a":[],"u":128531041,"seq":111455894596},"cts":1784086821072}
{"topic":"publicTrade.BTCUSDT","ts":1784086821097,"type":"snapshot","data":[{"i":"2290000001178591560","T":1784086821096,"p":"64663.4","v":"0.002","S":"Sell","seq":111455894600,"s":"BTCUSDT","BT":false,"RPI":false}]}
{"topic":"orderbook.50.BTCUSDT","ts":1784086821116,"type":"delta","data":{"s":"BTCUSDT","b":[["64663.4","1.658137"]],"a":[],"u":128531042,"seq":111455894608},"cts":1784086821109}
{"topic":"orderbook.50.BTCUSDT","ts":1784086821156,"type":"delta","data":{"s":"BTCUSDT","b":[],"a":[["64664.9","0.001622"],["64679.5","0"]],"u":128531043,"seq":111455894619},"cts":1784086821154}
{"topic":"orderbook.50.BTCUSDT","ts":1784086821176,"type":"delta","data":{"s":"BTCUSDT","b":[],"a":[["64667.7","0"],["64692.7","0.116092"]],"u":128531044,"seq":111455894623},"cts":1784086821158}
{"topic":"orderbook.50.BTCUSDT","ts":1784086821216,"type":"delta","data":{"s":"BTCUSDT","b":[],"a":[["64673.8","0.001223"],["64692.7","0"]],"u":128531045,"seq":111455894630},"cts":1784086821214}
{"topic":"orderbook.50.BTCUSDT","ts":1784086821236,"type":"delta","data":{"s":"BTCUSDT","b":[],"a":[["64666.9","0.04113"]],"u":128531046,"seq":111455894635},"cts":1784086821228}
{"topic":"orderbook.50.BTCUSDT","ts":1784086821256,"type":"delta","data":{"s":"BTCUSDT","b":[],"a":[["64678","0.003092"],["64679","0"]],"u":128531047,"seq":111455894640},"cts":1784086821247}
{"topic":"orderbook.50.BTCUSDT","ts":1784086821296,"type":"delta","data":{"s":"BTCUSDT","b":[],"a":[["64668.8","0.003244"],["64692.6","0"]],"u":128531048,"seq":111455894642},"cts":1784086821292}
{"topic":"orderbook.50.BTCUSDT","ts":1784086821376,"type":"delta","data":{"s":"BTCUSDT","b":[],"a":[["64670.8","0.004055"],["64691.2","0"]],"u":128531049,"seq":111455894654},"cts":1784086821367}
{"topic":"orderbook.50.BTCUSDT","ts":1784086821456,"type":"delta","data":{"s":"BTCUSDT","b":[["64641.3","0"],["64641.1","0.003434"]],"a":[["64672.7","0.004866"],["64690.7","0"]],"u":128531050,"seq":111455894661},"cts":1784086821446}
{"topic":"orderbook.50.BTCUSDT","ts":1784086821496,"type":"delta","data":{"s":"BTCUSDT","b":[["64663.4","1.668137"]],"a":[],"u":128531051,"seq":111455894671},"cts":1784086821493}
{"topic":"orderbook.50.BTCUSDT","ts":1784086821636,"type":"delta","data":{"s":"BTCUSDT","b":[["64663.4","1.641087"]],"a":[["64677","0.13777"],["64678","0"],["64690.7","0.001241"]],"u":128531052,"seq":111455894698},"cts":1784086821635}
{"topic":"orderbook.50.BTCUSDT","ts":1784086821656,"type":"delta","data":{"s":"BTCUSDT","b":[["64663.4","1.605227"]],"a":[],"u":128531053,"seq":111455894710},"cts":1784086821649}
{"topic":"orderbook.50.BTCUSDT","ts":1784086821676,"type":"delta","data":{"s":"BTCUSDT","b":[["64663.4","1.104193"]],"a":[["64663.5","0.106392"]],"u":128531054,"seq":111455894728},"cts":1784086821669}
{"topic":"orderbook.50.BTCUSDT","ts":1784086821696,"type":"delta","data":{"s":"BTCUSDT","b":[],"a":[["64667.4","0.015408"],["64690.7","0"]],"u":128531055,"seq":111455894733},"cts":1784086821694}
{"topic":"orderbook.50.BTCUSDT","ts":1784086821716,"type":"delta","data":{"s":"BTCUSDT","b":[["64663.4","1.102211"]],"a":[],"u":128531056,"seq":111455894743},"cts":1784086821705}
{"topic":"orderbook.50.BTCUSDT","ts":1784086821736,"type":"delta","data":{"s":"BTCUSDT","b":[["64663.4","1.103751"]],"a":[],"u":128531057,"seq":111455894748},"cts":1784086821735}
{"topic":"orderbook.50.BTCUSDT","ts":1784086821756,"type":"delta","data":{"s":"BTCUSDT","b":[["64663.4","1.109141"]],"a":[],"u":128531058,"seq":111455894757},"cts":1784086821746}
{"topic":"orderbook.50.BTCUSDT","ts":1784086821776,"type":"delta","data":{"s":"BTCUSDT","b":[["64663.4","1.109911"],["64661.5","0.002049"],["64633.5","0"]],"a":[],"u":128531059,"seq":111455894766},"cts":1784086821774}
{"topic":"orderbook.50.BTCUSDT","ts":1784086821816,"type":"delta","data":{"s":"BTCUSDT","b":[["64663.4","1.131087"]],"a":[],"u":128531060,"seq":111455894782},"cts":1784086821813}
{"topic":"orderbook.50.BTCUSDT","ts":1784086821836,"type":"delta","data":{"s":"BTCUSDT","b":[["64663.4","1.129547"]],"a":[],"u":128531061,"seq":111455894792},"cts":1784086821828}
{"topic":"orderbook.50.BTCUSDT","ts":1784086821856,"type":"delta","data":{"s":"BTCUSDT","b":[["64663.4","1.128777"]],"a":[],"u":128531062,"seq":111455894796},"cts":1784086821854}
{"topic":"orderbook.50.BTCUSDT","ts":1784086821876,"type":"delta","data":{"s":"BTCUSDT","b":[["64663.4","1.129547"]],"a":[],"u":128531063,"seq":111455894799},"cts":1784086821866}
{"topic":"orderbook.50.BTCUSDT","ts":1784086821896,"type":"delta","data":{"s":"BTCUSDT","b":[["64663.4","1.109141"]],"a":[["64667.4","0"],["64690.7","0.001241"]],"u":128531064,"seq":111455894812},"cts":1784086821895}
{"topic":"orderbook.50.BTCUSDT","ts":1784086821916,"type":"delta","data":{"s":"BTCUSDT","b":[["64663.4","1.134711"]],"a":[],"u":128531065,"seq":111455894823},"cts":1784086821905}
{"topic":"orderbook.50.BTCUSDT","ts":1784086821936,"type":"delta","data":{"s":"BTCUSDT","b":[["64663.4","0.986031"]],"a":[],"u":128531066,"seq":111455894834},"cts":1784086821933}
{"topic":"orderbook.50.BTCUSDT","ts":1784086821956,"type":"delta","data":{"s":"BTCUSDT","b":[["64663.4","0.119383"],["64659.3","0.129055"],["64658","0"],["64657.9","0"],["64656.9","0.117"],["64655.3","0"],["64655.1","0"],["64652.3","0"],["64650.9","0"],["64649.5","0.134738"],["64649.4","0.06381"],["64644","0.140566"],["64643.4","0.116092"],["64642.9","0"],["64642.2","0"],["64640.6","0.037129"],["64640.5","0"],["64639.4","0"],["64638.7","0"],["64636.8","0"],["64635.6","0.116092"],["64633.4","0.347226"],["64633.2","0.005"],["64633.1","0.002319"],["64632.2","0.01"],["64631.9","0.000117"],["64631.7","0.153221"],["64631.6","0.854217"]],"a":[["64663.5","0.466552"],["64671.4","0"],["64671.9","0.003763"],["64672","0"],["64672.6","0"],["64672.8","0.118218"],["64676.9","0.037129"],["64677","0.119184"],["64680.7","0.037129"],["64683.7","0.002281"]],"u":128531067,"seq":111455894991},"cts":1784086821954}
{"topic":"orderbook.50.BTCUSDT","ts":1784086821976,"type":"delta","data":{"s":"BTCUSDT","b":[["64663.4","0.094594"],["64661.5","0"],["64660.6","0.029768"],["64659.9","0"],["64659.3","0"],["64659.2","0"],["64657.3","0.04455"],["64657.1","0"],["64655.6","0.139072"],["64653.8","0"],["64652.6","0.033333"],["64651.3","0.773379"],["64649.5","0"],["64648.6","0.0015"],["64646.6","0"],["64644","0.103437"],["64643.2","0.191403"],["64642","0.033796"],["64638.8","0"],["64635.1","0"],["64631.1","0.015461"],["64630.7","0.05"],["64630.6","0.122"]],"a":[["64663.5","0.510333"],["64664.6","0.018586"],["64666.8","0.052769"],["64669.2","0.0015"],["64670.3","0"],["64671.2","0.136998"],["64672.8","0.155347"],["64673.8","0"],["64677.7","0.012646"],["64680.8","0.048408"],["64690.2","0"],["64690.7","0"]],"u":128531068,"seq":111455895118},"cts":1784086821974}
{"topic":"orderbook.50.BTCUSDT","ts":1784086821996,"type":"delta","data":{"s":"BTCUSDT","b":[["64663.4","0.063394"],["64655.7","0.098326"],["64655.2","0"],["64651.3","0"],["64650.2","0.773392"],["64643.5","0.037129"],["64631.1","0"]],"a":[["64671.1","0.042017"],["64689.2","0"]],"u":128531069,"seq":111455895164},"cts":1784086821994}
{"topic":"orderbook.50.BTCUSDT","ts":1784086822016,"type":"delta","data":{"s":"BTCUSDT","b":[["64663.4","0.105955"],["64660.6","0"],["64654","0.002285"],["64652.4","0.284402"]],"a":[["64663.5","0.512467"],["64667.8","0.028371"],["64669.2","0"],["64669.3","0.0015"],["64677","0.116092"],["64679","0.003092"],["64687.1","0"],["64687.7","0"]],"u":128531070,"seq":111455895252},"cts":1784086822015}
{"topic":"orderbook.50.BTCUSDT","ts":1784086822035,"type":"delta","data":{"s":"BTCUSDT","b":[["64663.4","0.105185"],["64649.5","0.090948"],["64630.6","0"]],"a":[["64663.5","0.532557"]],"u":128531071,"seq":111455895290},"cts":1784086822035}
{"topic":"orderbook.50.BTCUSDT","ts":1784086822056,"type":"delta","data":{"s":"BTCUSDT","b":[["64635.7","0.05241"],["64634.4","0"]],"a":[["64663.5","0.572287"]],"u":128531072,"seq":111455895307},"cts":1784086822051}
{"topic":"orderbook.50.BTCUSDT","ts":1784086822096,"type":"delta","data":{"s":"BTCUSDT","b":[],"a":[["64663.5","0.716828"],["64671.2","0"],["64687.7","0.037129"]],"u":128531073,"seq":111455895317},"cts":1784086822078}
{"topic":"orderbook.50.BTCUSDT","ts":1784086822117,"type":"delta","data":{"s":"BTCUSDT","b":[["64650.2","0.386696"]],"a":[["64663.5","0.676638"],["64667.5","0"],["64671.1","0"],["64688.3","0.017506"],["64688.4","0.015466"]],"u":128531074,"seq":111455895349},"cts":1784086822112}
{"topic":"orderbook.50.BTCUSDT","ts":1784086822136,"type":"delta","data":{"s":"BTCUSDT","b":[["64652.5","0.220687"],["64652.4","0.027788"],["64630.7","0"]],"a":[["64666.8","0.021714"]],"u":128531075,"seq":111455895359},"cts":1784086822118}
{"topic":"orderbook.50.BTCUSDT","ts":1784086822155,"type":"delta","data":{"s":"BTCUSDT","b":[["64652.5","0.145225"]],"a":[],"u":128531076,"seq":111455895372},"cts":1784086822154}
{"topic":"orderbook.50.BTCUSDT","ts":1784086822176,"type":"delta","data":{"s":"BTCUSDT","b":[["64658.4","0.144178"],["64655.6","0"]],"a":[["64663.5","0.692098"]],"u":128531077,"seq":111455895379},"cts":1784086822167}
{"topic":"orderbook.50.BTCUSDT","ts":1784086822196,"type":"delta","data":{"s":"BTCUSDT","b":[["64658.5","0.08714"],["64657.3","0"],["64655.7","0"],["64630.7","0.05"]],"a":[["64663.5","0.622142"]],"u":128531078,"seq":111455895395},"cts":1784086822194}
{"topic":"orderbook.50.BTCUSDT","ts":1784086822219,"type":"delta","data":{"s":"BTCUSDT","b":[["64663.4","0.106979"],["64655","0.057495"],["64651","0.100134"],["64631.6","0"],["64630.7","0"]],"a":[["64671.8","0.099209"],["64678.8","0"]],"u":128531079,"seq":111455895410},"cts":1784086822217}
{"topic":"orderbook.50.BTCUSDT","ts":1784086822236,"type":"delta","data":{"s":"BTCUSDT","b":[],"a":[["64671.7","0.030737"],["64688.4","0"]],"u":128531080,"seq":111455895416},"cts":1784086822221}
{"topic":"orderbook.50.BTCUSDT","ts":1784086822276,"type":"delta","data":{"s":"BTCUSDT","b":[["64654.9","0.109972"],["64654","0"],["64631.6","0.854217"]],"a":[],"u":128531081,"seq":111455895433},"cts":1784086822274}
{"topic":"orderbook.50.BTCUSDT","ts":1784086822296,"type":"delta","data":{"s":"BTCUSDT","b":[["64661.3","0.001547"],["64655.3","0.033333"],["64652.6","0"],["64631.6","0"]],"a":[],"u":128531082,"seq":111455895441},"cts":1784086822292}
{"topic":"orderbook.50.BTCUSDT","ts":1784086822316,"type":"delta","data":{"s":"BTCUSDT","b":[["64655.7","0.002282"],["64631.7","0"]],"a":[],"u":128531083,"seq":111455895448},"cts":1784086822312}
{"topic":"orderbook.50.BTCUSDT","ts":1784086822356,"type":"delta","data":{"s":"BTCUSDT","b":[["64646.2","0.005"],["64646","0"]],"a":[["64678","0.003092"],["64679","0"]],"u":128531084,"seq":111455895459},"cts":1784086822352}
{"topic":"orderbook.50.BTCUSDT","ts":1784086822416,"type":"delta","data":{"s":"BTCUSDT","b":[["64660.6","0.025796"],["64631.9","0"]],"a":[],"u":128531085,"seq":111455895474},"cts":1784086822407}
{"topic":"publicTrade.BTCUSDT","ts":1784086822461,"type":"snapshot","data":[{"i":"2290000001178591561","T":1784086822460,"p":"64663.4","v":"0.002","S":"Sell","seq":111455895486,"s":"BTCUSDT","BT":false,"RPI":false}]}
{"topic":"orderbook.50.BTCUSDT","ts":1784086822476,"type":"delta","data":{"s":"BTCUSDT","b":[["64663.4","0.135051"]],"a":[["64663.5","0.646942"],["64665.9","0.03"],["64688.3","0"]],"u":128531086,"seq":111455895493},"cts":1784086822473}
{"topic":"orderbook.50.BTCUSDT","ts":1784086822496,"type":"delta","data":{"s":"BTCUSDT","b":[["64660.6","0"],["64631.9","0.000117"]],"a":[],"u":128531087,"seq":111455895500},"cts":1784086822490}
{"topic":"orderbook.50.BTCUSDT","ts":1784086822516,"type":"delta","data":{"s":"BTCUSDT","b":[],"a":[["64663.5","0.592142"]],"u":128531088,"seq":111455895523},"cts":1784086822513}
{"topic":"orderbook.50.BTCUSDT","ts":1784086822596,"type":"delta","data":{"s":"BTCUSDT","b":[],"a":[["64663.5","0.611462"]],"u":128531089,"seq":111455895548},"cts":1784086822588}
{"topic":"orderbook.50.BTCUSDT","ts":1784086822656,"type":"delta","data":{"s":"BTCUSDT","b":[["64660.6","0.025796"],["64631.9","0"]],"a":[["64671","0.003092"],["64678","0"]],"u":128531090,"seq":111455895559},"cts":1784086822651}
{"topic":"orderbook.50.BTCUSDT","ts":1784086822716,"type":"delta","data":{"s":"BTCUSDT","b":[["64663.4","0.252051"]],"a":[],"u":128531091,"seq":111455895578},"cts":1784086822712}
{"topic":"orderbook.50.BTCUSDT","ts":1784086822735,"type":"delta","data":{"s":"BTCUSDT","b":[["64660.6","0"],["64631.9","0.000117"]],"a":[],"u":128531092,"seq":111455895583},"cts":1784086822732}
{"topic":"orderbook.50.BTCUSDT","ts":1784086822756,"type":"delta","data":{"s":"BTCUSDT","b":[["64663.3","0.029767"],["64631.9","0"]],"a":[],"u":128531093,"seq":111455895587},"cts":1784086822754}
{"topic":"orderbook.50.BTCUSDT","ts":1784086822775,"type":"delta","data":{"s":"BTCUSDT","b":[["64655.7","0"],["64631.9","0.000117"]],"a":[["64663.5","0.610098"]],"u":128531094,"seq":111455895600},"cts":1784086822764}
{"topic":"orderbook.50.BTCUSDT","ts":1784086822796,"type":"delta","data":{"s":"BTCUSDT","b":[["64663.4","0.135051"]],"a":[],"u":128531095,"seq":111455895612},"cts":1784086822788}
{"topic":"orderbook.50.BTCUSDT","ts":1784086822816,"type":"delta","data":{"s":"BTCUSDT","b":[["64655.8","0.002278"],["64631.9","0"]],"a":[["64665","0.001359"],["64669.2","0.0015"],["64669.3","0"],["64687.7","0"]],"u":128531096,"seq":111455895619},"cts":1784086822815}
{"topic":"orderbook.50.BTCUSDT","ts":1784086822896,"type":"delta","data":{"s":"BTCUSDT","b":[["64663.4","0.159851"]],"a":[],"u":128531097,"seq":111455895641},"cts":1784086822892}
{"topic":"orderbook.50.BTCUSDT","ts":1784086822916,"type":"delta","data":{"s":"BTCUSDT","b":[["64660.6","0.025796"],["64632.2","0"]],"a":[],"u":128531098,"seq":111455895643},"cts":1784086822902}
{"topic":"orderbook.50.BTCUSDT","ts":1784086822976,"type":"delta","data":{"s":"BTCUSDT","b":[],"a":[["64670","0.008192"],["64671","0"],["64687.7","0.037129"]],"u":128531099,"seq":111455895657},"cts":1784086822965}
{"topic":"orderbook.50.BTCUSDT","ts":1784086823019,"type":"delta","data":{"s":"BTCUSDT","b":[],"a":[["64663.5","0.581725"],["64664.8","0.032805"],["64687.7","0"]],"u":128531100,"seq":111455895665},"cts":1784086823016}
{"topic":"orderbook.50.BTCUSDT","ts":1784086823035,"type":"delta","data":{"s":"BTCUSDT","b":[],"a":[["64664.5","0.016827"],["64686","0"]],"u":128531101,"seq":111455895670},"cts":1784086823027}
{"topic":"orderbook.50.BTCUSDT","ts":1784086823056,"type":"delta","data":{"s":"BTCUSDT","b":[["64660.6","0"],["64632.2","0.01"]],"a":[],"u":128531102,"seq":111455895678},"cts":1784086823055}
{"topic":"orderbook.50.BTCUSDT","ts":1784086823156,"type":"delta","data":{"s":"BTCUSDT","b":[["64660.6","0.025796"],["64632.2","0"]],"a":[],"u":128531103,"seq":111455895709},"cts":1784086823153}
{"topic":"publicTrade.BTCUSDT","ts":1784086823203,"type":"snapshot","data":[{"i":"2290000001178591562","T":1784086823202,"p":"64663.4","v":"0.002","S":"Sell","seq":111455895723,"s":"BTCUSDT","BT":false,"RPI":false}]}
{"topic":"orderbook.50.BTCUSDT","ts":1784086823216,"type":"delta","data":{"s":"BTCUSDT","b":[["64663.4","0.157851"]],"a":[["64663.5","0.606525"]],"u":128531104,"seq":111455895726},"cts":1784086823206}
{"topic":"orderbook.50.BTCUSDT","ts":1784086823256,"type":"delta","data":{"s":"BTCUSDT","b":[["64660.6","0"],["64632.2","0.01"]],"a":[["64663.5","0.543615"]],"u":128531105,"seq":111455895741},"cts":1784086823249}
{"topic":"orderbook.50.BTCUSDT","ts":1784086823275,"type":"delta","data":{"s":"BTCUSDT","b":[],"a":[["64663.5","0.528155"]],"u":128531106,"seq":111455895749},"cts":1784086823271}
{"topic":"orderbook.50.BTCUSDT","ts":1784086823296,"type":"delta","data":{"s":"BTCUSDT","b":[["64663.4","0.147851"]],"a":[],"u":128531107,"seq":111455895754},"cts":1784086823289}
{"topic":"orderbook.50.BTCUSDT","ts":1784086823336,"type":"delta","data":{"s":"BTCUSDT","b":[["64660.6","0.025796"],["64632.2","0"]],"a":[["64663.5","0.503355"],["64664.8","0"],["64667.8","0"],["64669.3","0.032803"],["64686","0.00016"]],"u":128531108,"seq":111455895773},"cts":1784086823326}
{"topic":"orderbook.50.BTCUSDT","ts":1784086823356,"type":"delta","data":{"s":"BTCUSDT","b":[],"a":[["64664.5","0"],["64665.8","0.023442"],["64666.8","0"],["64687.6","0.033189"],["64687.7","0.037129"]],"u":128531109,"seq":111455895783},"cts":1784086823347}
{"topic":"orderbook.50.BTCUSDT","ts":1784086823396,"type":"delta","data":{"s":"BTCUSDT","b":[["64660.8","0.00147"],["64639.8","0.005"],["64633.2","0"],["64633.1","0"]],"a":[],"u":128531110,"seq":111455895790},"cts":1784086823379}
{"topic":"orderbook.50.BTCUSDT","ts":1784086823456,"type":"delta","data":{"s":"BTCUSDT","b":[["64660.6","0"],["64658.8","0.002205"]],"a":[],"u":128531111,"seq":111455895805},"cts":1784086823449}
{"topic":"orderbook.50.BTCUSDT","ts":1784086823496,"type":"delta","data":{"s":"BTCUSDT","b":[["64641.3","0.003434"],["64641.1","0"]],"a":[],"u":128531112,"seq":111455895812},"cts":1784086823480}
{"topic":"orderbook.50.BTCUSDT","ts":1784086823536,"type":"delta","data":{"s":"BTCUSDT","b":[["64656.9","0.119941"]],"a":[],"u":128531113,"seq":111455895828},"cts":1784086823525}
{"topic":"orderbook.50.BTCUSDT","ts":1784086823596,"type":"delta","data":{"s":"BTCUSDT","b":[["64654.9","0.113648"]],"a":[],"u":128531114,"seq":111455895835},"cts":1784086823594}
{"topic":"orderbook.50.BTCUSDT","ts":1784086823676,"type":"delta","data":{"s":"BTCUSDT","b":[["64653","0.004412"],["64633.4","0"]],"a":[],"u":128531115,"seq":111455895859},"cts":1784086823674}
{"topic":"orderbook.50.BTCUSDT","ts":1784086823756,"type":"delta","data":{"s":"BTCUSDT","b":[],"a":[["64663.5","0.53616"],["64687.6","0"],["64688.3","0.017506"]],"u":128531116,"seq":111455895873},"cts":1784086823745}
{"topic":"orderbook.50.BTCUSDT","ts":1784086823818,"type":"delta","data":{"s":"BTCUSDT","b":[],"a":[["64669.2","0"],["64669.3","0.034303"],["64688.4","0.015466"]],"u":128531117,"seq":111455895889},"cts":1784086823817}
{"topic":"orderbook.50.BTCUSDT","ts":1784086823835,"type":"delta","data":{"s":"BTCUSDT","b":[["64638.6","0.034959"],["64634.2","0"]],"a":[["64669.2","0.046159"],["64671.7","0"]],"u":128531118,"seq":111455895899},"cts":1784086823834}
{"topic":"orderbook.50.BTCUSDT","ts":1784086823895,"type":"delta","data":{"s":"BTCUSDT","b":[],"a":[["64663.5","0.56096"]],"u":128531119,"seq":111455895912},"cts":1784086823882}
{"topic":"orderbook.50.BTCUSDT","ts":1784086823956,"type":"delta","data":{"s":"BTCUSDT","b":[["64660.6","0.025796"],["64634.3","0"]],"a":[],"u":128531120,"seq":111455895925},"cts":1784086823952}
{"topic":"publicTrade.BTCUSDT","ts":1784086823970,"type":"snapshot","data":[{"i":"2290000001178591563","T":1784086823969,"p":"64663.4","v":"0.002","S":"Sell","seq":111455895928,"s":"BTCUSDT","BT":false,"RPI":false}]}
{"topic":"orderbook.50.BTCUSDT","ts":1784086823977,"type":"delta","data":{"s":"BTCUSDT","b":[["64663.4","0.145851"]],"a":[],"u":128531121,"seq":111455895930},"cts":1784086823972}
{"topic":"orderbook.50.BTCUSDT","ts":1784086824036,"type":"delta","data":{"s":"BTCUSDT","b":[["64663.4","0.072051"]],"a":[],"u":128531122,"seq":111455895951},"cts":1784086824035}
{"topic":"orderbook.50.BTCUSDT","ts":1784086824056,"type":"delta","data":{"s":"BTCUSDT","b":[],"a":[["64663.5","0.86211"]],"u":128531123,"seq":111455895979},"cts":1784086824053}
{"topic":"orderbook.50.BTCUSDT","ts":1784086824076,"type":"delta","data":{"s":"BTCUSDT","b":[["64660.6","0"],["64655.8","0"],["64634.3","0.039658"],["64634.2","0.018586"]],"a":[["64663.5","0.87757"]],"u":128531124,"seq":111455895985},"cts":1784086824073}
{"topic":"orderbook.50.BTCUSDT","ts":1784086824136,"type":"delta","data":{"s":"BTCUSDT","b":[["64654.3","0.002293"],["64634.2","0"]],"a":[["64663.5","0.89303"]],"u":128531125,"seq":111455896000},"cts":1784086824135}
{"topic":"orderbook.50.BTCUSDT","ts":1784086824156,"type":"delta","data":{"s":"BTCUSDT","b":[["64660.6","0.025796"],["64634.3","0"]],"a":[["64663.5","0.92889"]],"u":128531126,"seq":111455896018},"cts":1784086824150}
{"topic":"orderbook.50.BTCUSDT","ts":1784086824176,"type":"delta","data":{"s":"BTCUSDT","b":[],"a":[["64663.5","0.93662"]],"u":128531127,"seq":111455896024},"cts":1784086824173}
{"topic":"orderbook.50.BTCUSDT","ts":1784086824216,"type":"delta","data":{"s":"BTCUSDT","b":[["64660.6","0"],["64634.3","0.039658"]],"a":[],"u":128531128,"seq":111455896027},"cts":1784086824214}
{"topic":"orderbook.50.BTCUSDT","ts":1784086824296,"type":"delta","data":{"s":"BTCUSDT","b":[["64663.4","0.114651"]],"a":[],"u":128531129,"seq":111455896045},"cts":1784086824294}
{"topic":"orderbook.50.BTCUSDT","ts":1784086824396,"type":"delta","data":{"s":"BTCUSDT","b":[],"a":[["64663.5","0.63933"]],"u":128531130,"seq":111455896067},"cts":1784086824393}
{"topic":"orderbook.50.BTCUSDT","ts":1784086824756,"type":"delta","data":{"s":"BTCUSDT","b":[],"a":[["64663.5","0.81119"],["64670","0.010692"]],"u":128531131,"seq":111455896147},"cts":1784086824754}
{"topic":"publicTrade.BTCUSDT","ts":1784086824763,"type":"snapshot","data":[{"i":"2290000001178591564","T":1784086824762,"p":"64663.4","v":"0.002","S":"Sell","seq":111455896154,"s":"BTCUSDT","BT":false,"RPI":false}]}
{"topic":"orderbook.50.BTCUSDT","ts":1784086824776,"type":"delta","data":{"s":"BTCUSDT","b":[["64663.4","0.112651"],["64662.1","0.007739"],["64634.3","0"]],"a":[["64664.8","0.007739"],["64688.4","0"]],"u":128531132,"seq":111455896163},"cts":1784086824768}
{"topic":"orderbook.50.BTCUSDT","ts":1784086824836,"type":"delta","data":{"s":"BTCUSDT","b":[["64663.4","0.101251"]],"a":[],"u":128531133,"seq":111455896183},"cts":1784086824833}
{"topic":"orderbook.50.BTCUSDT","ts":1784086824916,"type":"delta","data":{"s":"BTCUSDT","b":[["64660.6","0.025796"],["64634.7","0"]],"a":[],"u":128531134,"seq":111455896197},"cts":1784086824912}
{"topic":"orderbook.50.BTCUSDT","ts":1784086825036,"type":"delta","data":{"s":"BTCUSDT","b":[["64640.4","0.012468"],["64635.6","0"]],"a":[["64663.5","0.80346"]],"u":128531135,"seq":111455896217},"cts":1784086825034}
{"topic":"orderbook.50.BTCUSDT","ts":1784086825056,"type":"delta","data":{"s":"BTCUSDT","b":[["64663.4","0.143851"]],"a":[["64663.5","0.57892"]],"u":128531136,"seq":111455896240},"cts":1784086825053}
{"topic":"orderbook.50.BTCUSDT","ts":1784086825076,"type":"delta","data":{"s":"BTCUSDT","b":[["64660.6","0"],["64635.6","0.116092"]],"a":[["64663.5","0.56346"]],"u":128531137,"seq":111455896245},"cts":1784086825071}
{"topic":"orderbook.50.BTCUSDT","ts":1784086825135,"type":"delta","data":{"s":"BTCUSDT","b":[],"a":[["64663.5","0.57892"]],"u":128531138,"seq":111455896267},"cts":1784086825134}
{"topic":"orderbook.50.BTCUSDT","ts":1784086825155,"type":"delta","data":{"s":"BTCUSDT","b":[],"a":[["64663.5","0.61137"]],"u":128531139,"seq":111455896280},"cts":1784086825150}
{"topic":"orderbook.50.BTCUSDT","ts":1784086825176,"type":"delta","data":{"s":"BTCUSDT","b":[],"a":[["64663.5","0.62683"]],"u":128531140,"seq":111455896288},"cts":1784086825171}
{"topic":"orderbook.50.BTCUSDT","ts":1784086825216,"type":"delta","data":{"s":"BTCUSDT","b":[["64660.6","0.025796"],["64635.6","0"]],"a":[],"u":128531141,"seq":111455896291},"cts":1784086825208}
{"topic":"orderbook.50.BTCUSDT","ts":1784086825256,"type":"delta","data":{"s":"BTCUSDT","b":[],"a":[["64663.5","0.73913"]],"u":128531142,"seq":111455896311},"cts":1784086825251}
{"topic":"orderbook.50.BTCUSDT","ts":1784086825396,"type":"delta","data":{"s":"BTCUSDT","b":[["64660.6","0"],["64635.6","0.116092"]],"a":[],"u":128531143,"seq":111455896326},"cts":1784086825394}
{"topic":"orderbook.50.BTCUSDT","ts":1784086825418,"type":"delta","data":{"s":"BTCUSDT","b":[],"a":[["64663.5","0.63456"]],"u":128531144,"seq":111455896333},"cts":1784086825403}
{"topic":"publicTrade.BTCUSDT","ts":1784086825469,"type":"snapshot","data":[{"i":"2290000001178591565","T":1784086825468,"p":"64663.4","v":"0.002","S":"Sell","seq":111455896337,"s":"BTCUSDT","BT":false,"RPI":false}]}
{"topic":"orderbook.50.BTCUSDT","ts":1784086825476,"type":"delta","data":{"s":"BTCUSDT","b":[["64663.4","0.141851"]],"a":[["64663.5","0.85286"]],"u":128531145,"seq":111455896341},"cts":1784086825474}
{"topic":"orderbook.50.BTCUSDT","ts":1784086825536,"type":"delta","data":{"s":"BTCUSDT","b":[["64660.6","0.025796"],["64635.6","0"]],"a":[["64672.1","0.003577"],["64672.4","0.004258"],["64688.3","0"]],"u":128531146,"seq":111455896351},"cts":1784086825525}
{"topic":"orderbook.50.BTCUSDT","ts":1784086825596,"type":"delta","data":{"s":"BTCUSDT","b":[["64660.6","0"],["64635.6","0.116092"]],"a":[],"u":128531147,"seq":111455896355},"cts":1784086825592}
{"topic":"publicTrade.BTCUSDT","ts":1784086825618,"type":"snapshot","data":[{"i":"2290000001178591566","T":1784086825617,"p":"64663.4","v":"0.008364","S":"Sell","seq":111455896358,"s":"BTCUSDT","BT":false,"RPI":false}]}
{"topic":"orderbook.50.BTCUSDT","ts":1784086825636,"type":"delta","data":{"s":"BTCUSDT","b":[["64663.4","0.103887"],["64656.9","0.121541"]],"a":[],"u":128531148,"seq":111455896372},"cts":1784086825629}
{"topic":"orderbook.50.BTCUSDT","ts":1784086826016,"type":"delta","data":{"s":"BTCUSDT","b":[["64660.6","0.025794"],["64635.6","0"]],"a":[],"u":128531149,"seq":111455896413},"cts":1784086826013}
{"topic":"orderbook.50.BTCUSDT","ts":1784086826096,"type":"delta","data":{"s":"BTCUSDT","b":[["64663.4","0.061287"],["64661.3","0"],["64660.6","0"],["64635.6","0.116092"],["64634.7","0.001241"]],"a":[["64663.5","0.84513"]],"u":128531150,"seq":111455896452},"cts":1784086826094}
{"topic":"orderbook.50.BTCUSDT","ts":1784086826115,"type":"delta","data":{"s":"BTCUSDT","b":[["64663.4","0.039987"],["64656.9","0.125041"]],"a":[],"u":128531151,"seq":111455896486},"cts":1784086826112}
{"topic":"orderbook.50.BTCUSDT","ts":1784086826136,"type":"delta","data":{"s":"BTCUSDT","b":[],"a":[["64663.5","0.8374"]],"u":128531152,"seq":111455896519},"cts":1784086826135}
{"topic":"orderbook.50.BTCUSDT","ts":1784086826156,"type":"delta","data":{"s":"BTCUSDT","b":[],"a":[["64663.5","0.79722"],["64676.9","0.039294"],["64683.7","0.000116"]],"u":128531153,"seq":111455896552},"cts":1784086826151}
{"topic":"orderbook.50.BTCUSDT","ts":1784086826176,"type":"delta","data":{"s":"BTCUSDT","b":[["64663.4","0.045987"],["64658.8","0.003752"],["64656.9","0.131041"]],"a":[["64663.5","0.78776"],["64670","0.016692"]],"u":128531154,"seq":111455896580},"cts":1784086826174}
{"topic":"orderbook.50.BTCUSDT","ts":1784086826196,"type":"delta","data":{"s":"BTCUSDT","b":[["64663.4","0.051987"],["64656.9","0.137041"]],"a":[["64663.5","0.79453"],["64670","0.022692"]],"u":128531155,"seq":111455896591},"cts":1784086826186}
{"topic":"orderbook.50.BTCUSDT","ts":1784086826237,"type":"delta","data":{"s":"BTCUSDT","b":[],"a":[["64663.5","0.82931"]],"u":128531156,"seq":111455896620},"cts":1784086826233}
{"topic":"publicTrade.BTCUSDT","ts":1784086826239,"type":"snapshot","data":[{"i":"2290000001178591567","T":1784086826238,"p":"64663.4","v":"0.001636","S":"Sell","seq":111455896621,"s":"BTCUSDT","BT":false,"RPI":false},{"i":"2290000001178591568","T":1784086826238,"p":"64663.4","v":"0.000364","S":"Sell","seq":111455896621,"s":"BTCUSDT","BT":false,"RPI":false}]}
{"topic":"orderbook.50.BTCUSDT","ts":1784086826256,"type":"delta","data":{"s":"BTCUSDT","b":[["64663.4","0.069987"]],"a":[["64663.5","0.84971"],["64684.8","0.131558"]],"u":128531157,"seq":111455896649},"cts":1784086826255}
{"topic":"orderbook.50.BTCUSDT","ts":1784086826276,"type":"delta","data":{"s":"BTCUSDT","b":[],"a":[["64663.5","0.86517"]],"u":128531158,"seq":111455896654},"cts":1784086826271}
{"topic":"orderbook.50.BTCUSDT","ts":1784086826316,"type":"delta","data":{"s":"BTCUSDT","b":[["64663.4","0.068966"]],"a":[],"u":128531159,"seq":111455896656},"cts":1784086826313}
{"topic":"orderbook.50.BTCUSDT","ts":1784086826336,"type":"delta","data":{"s":"BTCUSDT","b":[["64660.6","0.025794"],["64634.7","0"]],"a":[],"u":128531160,"seq":111455896660},"cts":1784086826327}
{"topic":"orderbook.50.BTCUSDT","ts":1784086826396,"type":"delta","data":{"s":"BTCUSDT","b":[["64663.4","0.070041"]],"a":[],"u":128531161,"seq":111455896668},"cts":1784086826387}
{"topic":"orderbook.50.BTCUSDT","ts":1784086826517,"type":"delta","data":{"s":"BTCUSDT","b":[["64660.6","0"],["64634.7","0.001241"]],"a":[],"u":128531162,"seq":111455896678},"cts":1784086826511}
{"topic":"orderbook.50.BTCUSDT","ts":1784086826556,"type":"delta","data":{"s":"BTCUSDT","b":[["64641.5","0.003434"],["64641.3","0"]],"a":[],"u":128531163,"seq":111455896683},"cts":1784086826541}
{"topic":"orderbook.50.BTCUSDT","ts":1784086826636,"type":"delta","data":{"s":"BTCUSDT","b":[["64660.6","0.025794"],["64634.7","0"]],"a":[],"u":128531164,"seq":111455896693},"cts":1784086826625}
{"topic":"orderbook.50.BTCUSDT","ts":1784086826717,"type":"delta","data":{"s":"BTCUSDT","b":[["64660.6","0"],["64634.7","0.001241"]],"a":[],"u":128531165,"seq":111455896701},"cts":1784086826698}
{"topic":"orderbook.50.BTCUSDT","ts":1784086826816,"type":"delta","data":{"s":"BTCUSDT","b":[["64663.4","0.112641"]],"a":[["64663.5","0.64687"]],"u":128531166,"seq":111455896730},"cts":1784086826815}
{"topic":"publicTrade.BTCUSDT","ts":1784086827036,"type":"snapshot","data":[{"i":"2290000001178591569","T":1784086827035,"p":"64663.4","v":"0.001794","S":"Sell","seq":111455896775,"s":"BTCUSDT","BT":false,"RPI":false},{"i":"2290000001178591570","T":1784086827035,"p":"64663.4","v":"0.000206","S":"Sell","seq":111455896775,"s":"BTCUSDT","BT":false,"RPI":false}]}
{"topic":"orderbook.50.BTCUSDT","ts":1784086827056,"type":"delta","data":{"s":"BTCUSDT","b":[["64663.4","0.110641"]],"a":[["64663.5","0.80541"]],"u":128531167,"seq":111455896782},"cts":1784086827047}
{"topic":"orderbook.50.BTCUSDT","ts":1784086827116,"type":"delta","data":{"s":"BTCUSDT","b":[],"a":[["64663.5","0.64687"]],"u":128531168,"seq":111455896795},"cts":1784086827112}
{"topic":"orderbook.50.BTCUSDT","ts":1784086827176,"type":"delta","data":{"s":"BTCUSDT","b":[["64660.6","0.025794"],["64634.7","0"]],"a":[],"u":128531169,"seq":111455896798},"cts":1784086827161}
{"topic":"orderbook.50.BTCUSDT","ts":1784086827376,"type":"delta","data":{"s":"BTCUSDT","b":[["64663.4","0.111987"]],"a":[],"u":128531170,"seq":111455896835},"cts":1784086827364}
{"topic":"orderbook.50.BTCUSDT","ts":1784086827476,"type":"delta","data":{"s":"BTCUSDT","b":[["64660.6","0"],["64634.7","0.001241"]],"a":[],"u":128531171,"seq":111455896840},"cts":1784086827468}
{"topic":"orderbook.50.BTCUSDT","ts":1784086827496,"type":"delta","data":{"s":"BTCUSDT","b":[["64663.4","0.120987"]],"a":[],"u":128531172,"seq":111455896850},"cts":1784086827494}
{"topic":"orderbook.50.BTCUSDT","ts":1784086827576,"type":"delta","data":{"s":"BTCUSDT","b":[["64635.2","0.001391"],["64634.7","0"]],"a":[],"u":128531173,"seq":111455896854},"cts":1784086827561}
{"topic":"publicTrade.BTCUSDT","ts":1784086827804,"type":"snapshot","data":[{"i":"2290000001178591571","T":1784086827803,"p":"64663.4","v":"0.002","S":"Sell","seq":111455896893,"s":"BTCUSDT","BT":false,"RPI":false}]}
{"topic":"orderbook.50.BTCUSDT","ts":1784086827819,"type":"delta","data":{"s":"BTCUSDT","b":[["64663.4","0.118987"]],"a":[],"u":128531174,"seq":111455896895},"cts":1784086827806}
{"topic":"orderbook.50.BTCUSDT","ts":1784086828336,"type":"delta","data":{"s":"BTCUSDT","b":[["64660.6","0.025794"],["64635.2","0"]],"a":[],"u":128531175,"seq":111455896958},"cts":1784086828334}
{"topic":"orderbook.50.BTCUSDT","ts":1784086828456,"type":"delta","data":{"s":"BTCUSDT","b":[["64660.6","0"],["64635.2","0.001391"]],"a":[],"u":128531176,"seq":111455896968},"cts":1784086828445}
{"topic":"orderbook.50.BTCUSDT","ts":1784086828496,"type":"delta","data":{"s":"BTCUSDT","b":[["64646.4","0.121091"],["64646.2","0"],["64634.7","0.001241"]],"a":[],"u":128531177,"seq":111455896974},"cts":1784086828480}
{"topic":"publicTrade.BTCUSDT","ts":1784086828525,"type":"snapshot","data":[{"i":"2290000001178591572","T":1784086828525,"p":"64663.4","v":"0.002","S":"Sell","seq":111455896979,"s":"BTCUSDT","BT":false,"RPI":false}]}
{"topic":"orderbook.50.BTCUSDT","ts":1784086828536,"type":"delta","data":{"s":"BTCUSDT","b":[["64663.4","0.119487"],["64656.9","0.139541"]],"a":[["64663.5","0.64937"],["64670","0.025192"]],"u":128531178,"seq":111455896986},"cts":1784086828535}
{"topic":"orderbook.50.BTCUSDT","ts":1784086828556,"type":"delta","data":{"s":"BTCUSDT","b":[],"a":[["64685.9","0.000128"],["64687.7","0"]],"u":128531179,"seq":111455896992},"cts":1784086828547}
{"topic":"orderbook.50.BTCUSDT","ts":1784086828596,"type":"delta","data":{"s":"BTCUSDT","b":[["64641.7","0.003434"],["64641.5","0"]],"a":[],"u":128531180,"seq":111455896999},"cts":1784086828588}
{"topic":"orderbook.50.BTCUSDT","ts":1784086828618,"type":"delta","data":{"s":"BTCUSDT","b":[],"a":[["64663.5","0.6571"]],"u":128531181,"seq":111455897001},"cts":1784086828613}
{"topic":"orderbook.50.BTCUSDT","ts":1784086828656,"type":"delta","data":{"s":"BTCUSDT","b":[["64635.9","0.015462"],["64634.7","0"]],"a":[["64679.1","0.015466"],["64684.8","0.116092"],["64686","0"]],"u":128531182,"seq":111455897008},"cts":1784086828648}
{"topic":"orderbook.50.BTCUSDT","ts":1784086828716,"type":"delta","data":{"s":"BTCUSDT","b":[],"a":[["64663.5","0.66482"]],"u":128531183,"seq":111455897017},"cts":1784086828704}
{"topic":"orderbook.50.BTCUSDT","ts":1784086828816,"type":"delta","data":{"s":"BTCUSDT","b":[],"a":[["64663.5","0.669211"]],"u":128531184,"seq":111455897031},"cts":1784086828805}
{"topic":"orderbook.50.BTCUSDT","ts":1784086828836,"type":"delta","data":{"s":"BTCUSDT","b":[["64663.4","0.144287"]],"a":[],"u":128531185,"seq":111455897041},"cts":1784086828828}
{"topic":"orderbook.50.BTCUSDT","ts":1784086828916,"type":"delta","data":{"s":"BTCUSDT","b":[["64660.6","0.025794"],["64635.2","0"]],"a":[],"u":128531186,"seq":111455897046},"cts":1784086828913}
{"topic":"orderbook.50.BTCUSDT","ts":1784086828996,"type":"delta","data":{"s":"BTCUSDT","b":[["64660.6","0"],["64635.2","0.001391"]],"a":[],"u":128531187,"seq":111455897059},"cts":1784086828983}
{"topic":"orderbook.50.BTCUSDT","ts":1784086829056,"type":"delta","data":{"s":"BTCUSDT","b":[],"a":[["64663.5","0.640321"]],"u":128531188,"seq":111455897072},"cts":1784086829055}
{"topic":"orderbook.50.BTCUSDT","ts":1784086829075,"type":"delta","data":{"s":"BTCUSDT","b":[["64660.6","0.025794"],["64635.2","0"]],"a":[["64663.5","0.617131"]],"u":128531189,"seq":111455897092},"cts":1784086829075}
{"topic":"orderbook.50.BTCUSDT","ts":1784086829156,"type":"delta","data":{"s":"BTCUSDT","b":[["64660.6","0"],["64635.2","0.001391"]],"a":[],"u":128531190,"seq":111455897099},"cts":1784086829147}
{"topic":"orderbook.50.BTCUSDT","ts":1784086829256,"type":"delta","data":{"s":"BTCUSDT","b":[["64660.6","0.025794"],["64635.2","0"]],"a":[],"u":128531191,"seq":111455897111},"cts":1784086829247}
{"topic":"publicTrade.BTCUSDT","ts":1784086829299,"type":"snapshot","data":[{"i":"2290000001178591573","T":1784086829298,"p":"64663.4","v":"0.002","S":"Sell","seq":111455897114,"s":"BTCUSDT","BT":false,"RPI":false}]}
{"topic":"orderbook.50.BTCUSDT","ts":1784086829315,"type":"delta","data":{"s":"BTCUSDT","b":[["64663.4","0.142287"]],"a":[["64663.5","0.914421"]],"u":128531192,"seq":111455897123},"cts":1784086829315}
{"topic":"orderbook.50.BTCUSDT","ts":1784086829336,"type":"delta","data":{"s":"BTCUSDT","b":[["64660.6","0"],["64635.2","0.001391"]],"a":[["64663.5","0.879641"]],"u":128531193,"seq":111455897136},"cts":1784086829331}
{"topic":"orderbook.50.BTCUSDT","ts":1784086829556,"type":"delta","data":{"s":"BTCUSDT","b":[["64660.6","0.025794"],["64635.2","0"]],"a":[],"u":128531194,"seq":111455897179},"cts":1784086829554}
{"topic":"orderbook.50.BTCUSDT","ts":1784086829576,"type":"delta","data":{"s":"BTCUSDT","b":[["64663.4","0.117487"]],"a":[],"u":128531195,"seq":111455897189},"cts":1784086829564}
{"topic":"orderbook.50.BTCUSDT","ts":1784086829636,"type":"delta","data":{"s":"BTCUSDT","b":[["64660.6","0"],["64635.2","0.001391"]],"a":[["64672.8","0.118218"]],"u":128531196,"seq":111455897208},"cts":1784086829631}
{"topic":"orderbook.50.BTCUSDT","ts":1784086829676,"type":"delta","data":{"s":"BTCUSDT","b":[["64654.3","0"],["64634.7","0.001241"]],"a":[["64665","0"],["64686","0.00016"]],"u":128531197,"seq":111455897217},"cts":1784086829667}
{"topic":"orderbook.50.BTCUSDT","ts":1784086829716,"type":"delta","data":{"s":"BTCUSDT","b":[],"a":[["64664","0.001354"],["64686","0"]],"u":128531198,"seq":111455897226},"cts":1784086829715}
{"topic":"orderbook.50.BTCUSDT","ts":1784086829736,"type":"delta","data":{"s":"BTCUSDT","b":[["64654.8","0.002269"],["64634.7","0"]],"a":[["64663.5","0.582351"]],"u":128531199,"seq":111455897239},"cts":1784086829722}
{"topic":"orderbook.50.BTCUSDT","ts":1784086829776,"type":"delta","data":{"s":"BTCUSDT","b":[["64658.4","0.149178"]],"a":[],"u":128531200,"seq":111455897248},"cts":1784086829765}
{"topic":"orderbook.50.BTCUSDT","ts":1784086829796,"type":"delta","data":{"s":"BTCUSDT","b":[],"a":[["64663.5","0.586131"]],"u":128531201,"seq":111455897253},"cts":1784086829794}
{"topic":"orderbook.50.BTCUSDT","ts":1784086829816,"type":"delta","data":{"s":"BTCUSDT","b":[["64663.4","0.142287"]],"a":[["64663.5","0.599631"]],"u":128531202,"seq":111455897269},"cts":1784086829814}
{"topic":"orderbook.50.BTCUSDT","ts":1784086829876,"type":"delta","data":{"s":"BTCUSDT","b":[],"a":[["64663.5","0.607361"]],"u":128531203,"seq":111455897280},"cts":1784086829870}
{"topic":"orderbook.50.BTCUSDT","ts":1784086829896,"type":"delta","data":{"s":"BTCUSDT","b":[],"a":[["64663.5","0.608201"]],"u":128531204,"seq":111455897289},"cts":1784086829891}
{"topic":"publicTrade.BTCUSDT","ts":1784086829899,"type":"snapshot","data":[{"i":"2290000001178591574","T":1784086829898,"p":"64663.5","v":"0.000015","S":"Buy","seq":111455897293,"s":"BTCUSDT","BT":false,"RPI":false}]}
{"topic":"orderbook.50.BTCUSDT","ts":1784086829916,"type":"delta","data":{"s":"BTCUSDT","b":[],"a":[["64663.5","0.597386"]],"u":128531205,"seq":111455897299},"cts":1784086829905}
{"topic":"orderbook.50.BTCUSDT","ts":1784086829976,"type":"delta","data":{"s":"BTCUSDT","b":[],"a":[["64663.5","0.605116"],["64670","1.568412"]],"u":128531206,"seq":111455897321},"cts":1784086829973}
{"topic":"orderbook.50.BTCUSDT","ts":1784086829995,"type":"delta","data":{"s":"BTCUSDT","b":[],"a":[["64663.5","0.613926"],["64669.2","0.505984"]],"u":128531207,"seq":111455897325},"cts":1784086829994}
{"topic":"orderbook.50.BTCUSDT","ts":1784086830016,"type":"delta","data":{"s":"BTCUSDT","b":[],"a":[["64663.5","0.633236"]],"u":128531208,"seq":111455897330},"cts":1784086830002}
{"topic":"orderbook.50.BTCUSDT","ts":1784086830056,"type":"delta","data":{"s":"BTCUSDT","b":[["64640.8","0.015462"],["64635.9","0"]],"a":[["64674.9","0.015466"],["64679.1","0"]],"u":128531209,"seq":111455897344},"cts":1784086830051}
{"topic":"publicTrade.BTCUSDT","ts":1784086830103,"type":"snapshot","data":[{"i":"2290000001178591575","T":1784086830102,"p":"64663.4","v":"0.002","S":"Sell","seq":111455897348,"s":"BTCUSDT","BT":false,"RPI":false}]}
{"topic":"orderbook.50.BTCUSDT","ts":1784086830116,"type":"delta","data":{"s":"BTCUSDT","b":[["64663.4","0.140287"]],"a":[],"u":128531210,"seq":111455897350},"cts":1784086830105}
{"topic":"orderbook.50.BTCUSDT","ts":1784086830219,"type":"delta","data":{"s":"BTCUSDT","b":[["64660.6","0.025794"],["64635.2","0"]],"a":[],"u":128531211,"seq":111455897365},"cts":1784086830198}
{"topic":"orderbook.50.BTCUSDT","ts":1784086830296,"type":"delta","data":{"s":"BTCUSDT","b":[["64663.4","0.115487"]],"a":[["64663.5","0.684396"]],"u":128531212,"seq":111455897384},"cts":1784086830293}
{"topic":"orderbook.50.BTCUSDT","ts":1784086830376,"type":"delta","data":{"s":"BTCUSDT","b":[["64660.6","0"],["64635.2","0.001391"]],"a":[],"u":128531213,"seq":111455897396},"cts":1784086830364}
{"topic":"orderbook.50.BTCUSDT","ts":1784086830396,"type":"delta","data":{"s":"BTCUSDT","b":[],"a":[["64663.5","0.675586"]],"u":128531214,"seq":111455897405},"cts":1784086830392}
{"topic":"orderbook.50.BTCUSDT","ts":1784086830416,"type":"delta","data":{"s":"BTCUSDT","b":[],"a":[["64663.5","0.656276"]],"u":128531215,"seq":111455897417},"cts":1784086830411}
{"topic":"orderbook.50.BTCUSDT","ts":1784086830436,"type":"delta","data":{"s":"BTCUSDT","b":[["64663.4","0.072887"]],"a":[],"u":128531216,"seq":111455897422},"cts":1784086830434}
{"success":true,"ret_msg":"pong","conn_id":"d9avrremonceh80v85sg-4vx3","op":"ping"}
{"topic":"orderbook.50.BTCUSDT","ts":1784086830496,"type":"delta","data":{"s":"BTCUSDT","b":[["64663.4","0.115487"]],"a":[],"u":128531217,"seq":111455897431},"cts":1784086830493}
{"topic":"orderbook.50.BTCUSDT","ts":1784086830516,"type":"delta","data":{"s":"BTCUSDT","b":[],"a":[["64663.5","0.684396"]],"u":128531218,"seq":111455897440},"cts":1784086830503}
{"topic":"orderbook.50.BTCUSDT","ts":1784086830576,"type":"delta","data":{"s":"BTCUSDT","b":[],"a":[["64663.5","0.666236"]],"u":128531219,"seq":111455897455},"cts":1784086830573}
{"topic":"orderbook.50.BTCUSDT","ts":1784086830596,"type":"delta","data":{"s":"BTCUSDT","b":[["64663.4","0.072887"]],"a":[["64663.5","0.652806"]],"u":128531220,"seq":111455897470},"cts":1784086830593}
{"topic":"orderbook.50.BTCUSDT","ts":1784086830616,"type":"delta","data":{"s":"BTCUSDT","b":[],"a":[["64663.5","0.633496"]],"u":128531221,"seq":111455897477},"cts":1784086830612}
{"topic":"orderbook.50.BTCUSDT","ts":1784086830676,"type":"delta","data":{"s":"BTCUSDT","b":[],"a":[["64663.5","0.635806"]],"u":128531222,"seq":111455897486},"cts":1784086830670}
{"topic":"orderbook.50.BTCUSDT","ts":1784086830696,"type":"delta","data":{"s":"BTCUSDT","b":[["64660.6","0.025794"],["64635.2","0"]],"a":[["64663.5","0.641196"]],"u":128531223,"seq":111455897498},"cts":1784086830695}
{"topic":"orderbook.50.BTCUSDT","ts":1784086830716,"type":"delta","data":{"s":"BTCUSDT","b":[],"a":[["64663.5","0.645046"]],"u":128531224,"seq":111455897506},"cts":1784086830701}
{"topic":"orderbook.50.BTCUSDT","ts":1784086830736,"type":"delta","data":{"s":"BTCUSDT","b":[],"a":[["64663.5","0.644276"]],"u":128531225,"seq":111455897521},"cts":1784086830735}
{"topic":"orderbook.50.BTCUSDT","ts":1784086830756,"type":"delta","data":{"s":"BTCUSDT","b":[],"a":[["64663.5","0.642736"]],"u":128531226,"seq":111455897531},"cts":1784086830750}
{"topic":"orderbook.50.BTCUSDT","ts":1784086830776,"type":"delta","data":{"s":"BTCUSDT","b":[["64660.6","0"],["64635.2","0.001391"]],"a":[["64663.5","0.635806"]],"u":128531227,"seq":111455897547},"cts":1784086830772}
{"topic":"orderbook.50.BTCUSDT","ts":1784086830796,"type":"delta","data":{"s":"BTCUSDT","b":[["64663.4","0.071541"]],"a":[["64663.5","0.633496"]],"u":128531228,"seq":111455897564},"cts":1784086830789}
{"topic":"orderbook.50.BTCUSDT","ts":1784086830816,"type":"delta","data":{"s":"BTCUSDT","b":[],"a":[["64663.5","0.634266"]],"u":128531229,"seq":111455897572},"cts":1784086830813}
{"topic":"orderbook.50.BTCUSDT","ts":1784086830835,"type":"delta","data":{"s":"BTCUSDT","b":[],"a":[["64663.5","0.636576"]],"u":128531230,"seq":111455897577},"cts":1784086830831}
{"topic":"orderbook.50.BTCUSDT","ts":1784086830856,"type":"delta","data":{"s":"BTCUSDT","b":[["64660.6","0.025794"],["64635.2","0"]],"a":[["64663.5","0.638886"]],"u":128531231,"seq":111455897582},"cts":1784086830846}
{"topic":"publicTrade.BTCUSDT","ts":1784086830864,"type":"snapshot","data":[{"i":"2290000001178591576","T":1784086830863,"p":"64663.4","v":"0.002","S":"Sell","seq":111455897584,"s":"BTCUSDT","BT":false,"RPI":false}]}
{"topic":"orderbook.50.BTCUSDT","ts":1784086830876,"type":"delta","data":{"s":"BTCUSDT","b":[["64663.4","0.112141"]],"a":[],"u":128531232,"seq":111455897600},"cts":1784086830873}
{"topic":"orderbook.50.BTCUSDT","ts":1784086830896,"type":"delta","data":{"s":"BTCUSDT","b":[],"a":[["64663.5","0.638116"]],"u":128531233,"seq":111455897602},"cts":1784086830888}
{"topic":"orderbook.50.BTCUSDT","ts":1784086830916,"type":"delta","data":{"s":"BTCUSDT","b":[],"a":[["64663.5","0.638886"]],"u":128531234,"seq":111455897615},"cts":1784086830914}
{"topic":"orderbook.50.BTCUSDT","ts":1784086830936,"type":"delta","data":{"s":"BTCUSDT","b":[["64660.6","0"],["64635.2","0.001391"]],"a":[["64663.5","0.639656"]],"u":128531235,"seq":111455897626},"cts":1784086830931}
{"topic":"orderbook.50.BTCUSDT","ts":1784086830976,"type":"delta","data":{"s":"BTCUSDT","b":[],"a":[["64663.5","0.637346"]],"u":128531236,"seq":111455897633},"cts":1784086830972}
{"topic":"orderbook.50.BTCUSDT","ts":1784086830996,"type":"delta","data":{"s":"BTCUSDT","b":[["64663.4","0.092275"],["64662.8","0.03"],["64635.2","0"]],"a":[["64663.5","0.635036"]],"u":128531237,"seq":111455897642},"cts":1784086830991}
{"topic":"orderbook.50.BTCUSDT","ts":1784086831019,"type":"delta","data":{"s":"BTCUSDT","b":[],"a":[["64663.5","0.633496"]],"u":128531238,"seq":111455897648},"cts":1784086831011}
{"topic":"orderbook.50.BTCUSDT","ts":1784086831036,"type":"delta","data":{"s":"BTCUSDT","b":[["64660.6","0.025794"],["64635.6","0"]],"a":[["64681.2","0.284578"],["64685.9","0"]],"u":128531239,"seq":111455897655},"cts":1784086831032}
{"topic":"orderbook.50.BTCUSDT","ts":1784086831056,"type":"delta","data":{"s":"BTCUSDT","b":[],"a":[["64663.5","0.635036"],["64678.7","0.13665"]],"u":128531240,"seq":111455897666},"cts":1784086831052}
{"topic":"orderbook.50.BTCUSDT","ts":1784086831076,"type":"delta","data":{"s":"BTCUSDT","b":[],"a":[["64663.5","0.637346"]],"u":128531241,"seq":111455897677},"cts":1784086831069}
{"topic":"orderbook.50.BTCUSDT","ts":1784086831096,"type":"delta","data":{"s":"BTCUSDT","b":[],"a":[["64663.5","0.642736"]],"u":128531242,"seq":111455897685},"cts":1784086831093}
{"topic":"orderbook.50.BTCUSDT","ts":1784086831116,"type":"delta","data":{"s":"BTCUSDT","b":[["64660.6","0"],["64635.6","0.116092"]],"a":[["64663.5","0.644276"]],"u":128531243,"seq":111455897688},"cts":1784086831103}
{"topic":"orderbook.50.BTCUSDT","ts":1784086831136,"type":"delta","data":{"s":"BTCUSDT","b":[],"a":[["64663.5","0.641966"]],"u":128531244,"seq":111455897695},"cts":1784086831131}
{"topic":"orderbook.50.BTCUSDT","ts":1784086831156,"type":"delta","data":{"s":"BTCUSDT","b":[],"a":[["64663.5","0.640426"]],"u":128531245,"seq":111455897706},"cts":1784086831153}
{"topic":"orderbook.50.BTCUSDT","ts":1784086831176,"type":"delta","data":{"s":"BTCUSDT","b":[],"a":[["64663.5","0.635036"]],"u":128531246,"seq":111455897715},"cts":1784086831174}
{"topic":"orderbook.50.BTCUSDT","ts":1784086831196,"type":"delta","data":{"s":"BTCUSDT","b":[],"a":[["64663.5","0.633496"]],"u":128531247,"seq":111455897718},"cts":1784086831187}
{"topic":"orderbook.50.BTCUSDT","ts":1784086831256,"type":"delta","data":{"s":"BTCUSDT","b":[],"a":[["64663.5","0.637346"]],"u":128531248,"seq":111455897731},"cts":1784086831249}
{"topic":"orderbook.50.BTCUSDT","ts":1784086831276,"type":"delta","data":{"s":"BTCUSDT","b":[],"a":[["64663.5","0.639656"]],"u":128531249,"seq":111455897735},"cts":1784086831273}
{"topic":"orderbook.50.BTCUSDT","ts":1784086831296,"type":"delta","data":{"s":"BTCUSDT","b":[],"a":[["64663.5","0.643506"]],"u":128531250,"seq":111455897743},"cts":1784086831294}
{"topic":"orderbook.50.BTCUSDT","ts":1784086831317,"type":"delta","data":{"s":"BTCUSDT","b":[],"a":[["64663.5","0.642736"]],"u":128531251,"seq":111455897745},"cts":1784086831313}
{"topic":"orderbook.50.BTCUSDT","ts":1784086831336,"type":"delta","data":{"s":"BTCUSDT","b":[],"a":[["64663.5","0.639656"]],"u":128531252,"seq":111455897749},"cts":1784086831320}
{"topic":"orderbook.50.BTCUSDT","ts":1784086831356,"type":"delta","data":{"s":"BTCUSDT","b":[],"a":[["64663.5","0.638886"]],"u":128531253,"seq":111455897755},"cts":1784086831349}
{"topic":"orderbook.50.BTCUSDT","ts":1784086831376,"type":"delta","data":{"s":"BTCUSDT","b":[],"a":[["64663.5","0.635036"]],"u":128531254,"seq":111455897762},"cts":1784086831362}
{"topic":"orderbook.50.BTCUSDT","ts":1784086831416,"type":"delta","data":{"s":"BTCUSDT","b":[],"a":[["64663.5","0.650486"]],"u":128531255,"seq":111455897769},"cts":1784086831412}
{"topic":"orderbook.50.BTCUSDT","ts":1784086831436,"type":"delta","data":{"s":"BTCUSDT","b":[],"a":[["64663.5","0.696866"]],"u":128531256,"seq":111455897777},"cts":1784086831435}
{"topic":"orderbook.50.BTCUSDT","ts":1784086831456,"type":"delta","data":{"s":"BTCUSDT","b":[],"a":[["64663.5","0.717266"]],"u":128531257,"seq":111455897785},"cts":1784086831454}
{"topic":"publicTrade.BTCUSDT","ts":1784086831574,"type":"snapshot","data":[{"i":"2290000001178591577","T":1784086831573,"p":"64663.4","v":"0.0016","S":"Sell","seq":111455897798,"s":"BTCUSDT","BT":false,"RPI":false},{"i":"2290000001178591578","T":1784086831573,"p":"64663.4","v":"0.0004","S":"Sell","seq":111455897798,"s":"BTCUSDT","BT":false,"RPI":false}]}
{"topic":"orderbook.50.BTCUSDT","ts":1784086831576,"type":"delta","data":{"s":"BTCUSDT","b":[["64663.4","0.090275"]],"a":[],"u":128531258,"seq":111455897798},"cts":1784086831573}
{"topic":"orderbook.50.BTCUSDT","ts":1784086831596,"type":"delta","data":{"s":"BTCUSDT","b":[["64663.4","0.091875"]],"a":[],"u":128531259,"seq":111455897803},"cts":1784086831594}
{"topic":"orderbook.50.BTCUSDT","ts":1784086831636,"type":"delta","data":{"s":"BTCUSDT","b":[["64641.9","0.513136"],["64641.7","0"],["64635.2","0.001391"]],"a":[],"u":128531260,"seq":111455897804},"cts":1784086831622}
{"topic":"orderbook.50.BTCUSDT","ts":1784086831936,"type":"delta","data":{"s":"BTCUSDT","b":[["64663.4","0.049275"]],"a":[],"u":128531261,"seq":111455897888},"cts":1784086831921}
{"topic":"orderbook.50.BTCUSDT","ts":1784086831976,"type":"delta","data":{"s":"BTCUSDT","b":[["64663.4","0.091875"]],"a":[],"u":128531262,"seq":111455897894},"cts":1784086831964}
{"topic":"orderbook.50.BTCUSDT","ts":1784086832096,"type":"delta","data":{"s":"BTCUSDT","b":[["64660.6","0.025794"],["64635.2","0"]],"a":[],"u":128531263,"seq":111455897905},"cts":1784086832090}
{"topic":"orderbook.50.BTCUSDT","ts":1784086832136,"type":"delta","data":{"s":"BTCUSDT","b":[["64663.4","0.049275"]],"a":[],"u":128531264,"seq":111455897909},"cts":1784086832118}
{"topic":"orderbook.50.BTCUSDT","ts":1784086832176,"type":"delta","data":{"s":"BTCUSDT","b":[["64660.6","0"],["64635.2","0.001391"]],"a":[],"u":128531265,"seq":111455897915},"cts":1784086832172}
{"topic":"orderbook.50.BTCUSDT","ts":1784086832276,"type":"delta","data":{"s":"BTCUSDT","b":[["64660.6","0.025794"],["64635.2","0"]],"a":[],"u":128531266,"seq":111455897922},"cts":1784086832268}
{"topic":"publicTrade.BTCUSDT","ts":1784086832308,"type":"snapshot","data":[{"i":"2290000001178591579","T":1784086832307,"p":"64663.4","v":"0.0006","S":"Sell","seq":111455897927,"s":"BTCUSDT","BT":false,"RPI":false},{"i":"2290000001178591580","T":1784086832307,"p":"64663.4","v":"0.0014","S":"Sell","seq":111455897927,"s":"BTCUSDT","BT":false,"RPI":false}]}
{"topic":"orderbook.50.BTCUSDT","ts":1784086832316,"type":"delta","data":{"s":"BTCUSDT","b":[["64663.4","0.090875"]],"a":[],"u":128531267,"seq":111455897935},"cts":1784086832313}
{"topic":"orderbook.50.BTCUSDT","ts":1784086832417,"type":"delta","data":{"s":"BTCUSDT","b":[["64660.6","0"],["64635.2","0.001391"]],"a":[],"u":128531268,"seq":111455897943},"cts":1784086832414}
{"topic":"orderbook.50.BTCUSDT","ts":1784086832576,"type":"delta","data":{"s":"BTCUSDT","b":[["64646.6","0.005"],["64646.4","0.116091"],["64635.2","0"]],"a":[["64671.9","0"],["64672.2","0.003763"]],"u":128531269,"seq":111455897956},"cts":1784086832562}
{"topic":"orderbook.50.BTCUSDT","ts":1784086832596,"type":"delta","data":{"s":"BTCUSDT","b":[["64663.4","0.048275"]],"a":[],"u":128531270,"seq":111455897968},"cts":1784086832595}
{"topic":"orderbook.50.BTCUSDT","ts":1784086832618,"type":"delta","data":{"s":"BTCUSDT","b":[["64650.2","0"],["64650.1","0.386697"]],"a":[],"u":128531271,"seq":111455897997},"cts":1784086832617}
{"topic":"orderbook.50.BTCUSDT","ts":1784086832656,"type":"delta","data":{"s":"BTCUSDT","b":[["64663.4","0.090875"]],"a":[],"u":128531272,"seq":111455898009},"cts":1784086832651}
{"topic":"orderbook.50.BTCUSDT","ts":1784086832696,"type":"delta","data":{"s":"BTCUSDT","b":[["64663.4","0.048275"]],"a":[],"u":128531273,"seq":111455898015},"cts":1784086832693}
{"topic":"publicTrade.BTCUSDT","ts":1784086832722,"type":"snapshot","data":[{"i":"2290000001178591581","T":1784086832721,"p":"64663.4","v":"0.0011","S":"Sell","seq":111455898067,"s":"BTCUSDT","BT":false,"RPI":false},{"i":"2290000001178591582","T":1784086832721,"p":"64663.4","v":"0.006","S":"Sell","seq":111455898067,"s":"BTCUSDT","BT":false,"RPI":false},{"i":"2290000001178591583","T":1784086832721,"p":"64663.4","v":"0.006","S":"Sell","seq":111455898067,"s":"BTCUSDT","BT":false,"RPI":false},{"i":"2290000001178591584","T":1784086832721,"p":"64663.4","v":"0.02","S":"Sell","seq":111455898067,"s":"BTCUSDT","BT":false,"RPI":false},{"i":"2290000001178591585","T":1784086832721,"p":"64663.4","v":"0.001075","S":"Sell","seq":111455898067,"s":"BTCUSDT","BT":false,"RPI":false},{"i":"2290000001178591586","T":1784086832721,"p":"64663.4","v":"0.009","S":"Sell","seq":111455898067,"s":"BTCUSDT","BT":false,"RPI":false},{"i":"2290000001178591587","T":1784086832721,"p":"64663.4","v":"0.0025","S":"Sell","seq":111455898067,"s":"BTCUSDT","BT":false,"RPI":false},{"i":"2290000001178591588","T":1784086832721,"p":"64663.4","v":"0.0016","S":"Sell","seq":111455898067,"s":"BTCUSDT","BT":false,"RPI":false},{"i":"2290000001178591589","T":1784086832721,"p":"64663.4","v":"0.001","S":"Sell","seq":111455898067,"s":"BTCUSDT","BT":false,"RPI":false}]}
{"topic":"orderbook.50.BTCUSDT","ts":1784086832736,"type":"delta","data":{"s":"BTCUSDT","b":[["64663.4","0"],["64663.3","0"],["64662.8","0.056"],["64661.4","0.034201"],["64658.8","0.002205"],["64658.5","0"],["64658.4","0.005"],["64656.9","0.002941"],["64656.3","0.1306"],["64655","0.219708"],["64651","0"],["64646.6","0"],["64646","0.005"],["64643.5","0"],["64643.4","0.037129"],["64641.9","0.509702"],["64641.3","0.003434"],["64635.2","0.001391"],["64634.7","0.001241"]],"a":[["64662.9","0.739857"],["64663.3","0.030314"],["64663.4","0.248247"],["64663.5","0.181638"],["64665.5","0.032597"],["64669.4","0.1391"],["64670","1.546312"],["64671.6","0.003763"],["64672","0.004258"],["64672.2","0"],["64672.4","0"],["64680.8","0.018586"],["64684.5","0"],["64684.8","0"],["64685","0"],["64685.1","0"],["64685.7","0"]],"u":128531274,"seq":111455898224},"cts":1784086832734}
{"topic":"publicTrade.BTCUSDT","ts":1784086832737,"type":"snapshot","data":[{"i":"2290000001178591590","T":1784086832736,"p":"64662.8","v":"0.028433","S":"Sell","seq":111455898234,"s":"BTCUSDT","BT":false,"RPI":false}]}
{"topic":"orderbook.50.BTCUSDT","ts":1784086832756,"type":"delta","data":{"s":"BTCUSDT","b":[["64662.8","0.086767"],["64662.3","0.034201"],["64662.1","0"],["64661.4","0"],["64655.3","0"],["64655.1","0.113873"],["64655","0.162213"],["64652","0.033333"],["64644.1","0.116092"],["64634.7","0"]],"a":[["64662.9","1.057147"],["64663.3","0.108699"],["64663.4","0.0248"],["64664.8","0"],["64669.2","0.507484"],["64669.3","0.032803"],["64684.5","0.001241"]],"u":128531275,"seq":111455898294},"cts":1784086832754}
{"topic":"orderbook.50.BTCUSDT","ts":1784086832776,"type":"delta","data":{"s":"BTCUSDT","b":[["64661.5","0.007739"],["64635.2","0"]],"a":[["64663.5","0.186638"],["64664.2","0.007739"],["64669.2","0.505984"],["64669.3","0.034303"],["64684.5","0"]],"u":128531276,"seq":111455898328},"cts":1784086832771}
{"topic":"orderbook.50.BTCUSDT","ts":1784086832796,"type":"delta","data":{"s":"BTCUSDT","b":[["64657.3","0.04904"],["64635.6","0"]],"a":[["64662.9","0.909237"],["64663.5","0.157447"]],"u":128531277,"seq":111455898354},"cts":1784086832793}
{"topic":"publicTrade.BTCUSDT","ts":1784086832800,"type":"snapshot","data":[{"i":"2290000001178591591","T":1784086832799,"p":"64662.9","v":"0.000159","S":"Buy","seq":111455898367,"s":"BTCUSDT","BT":false,"RPI":false}]}
{"topic":"orderbook.50.BTCUSDT","ts":1784086832817,"type":"delta","data":{"s":"BTCUSDT","b":[["64654.8","0"],["64635.6","0.116092"]],"a":[["64662.9","0.909078"],["64663.5","0.073677"]],"u":128531278,"seq":111455898396},"cts":1784086832815}
{"topic":"orderbook.50.BTCUSDT","ts":1784086832836,"type":"delta","data":{"s":"BTCUSDT","b":[],"a":[["64663.3","0.078783"]],"u":128531279,"seq":111455898416},"cts":1784086832830}
{"topic":"orderbook.50.BTCUSDT","ts":1784086832856,"type":"delta","data":{"s":"BTCUSDT","b":[["64654","0.002205"],["64635.6","0"]],"a":[],"u":128531280,"seq":111455898426},"cts":1784086832842}
{"topic":"orderbook.50.BTCUSDT","ts":1784086832896,"type":"delta","data":{"s":"BTCUSDT","b":[],"a":[["64662.9","0.960398"]],"u":128531281,"seq":111455898440},"cts":1784086832895}
{"topic":"orderbook.50.BTCUSDT","ts":1784086832916,"type":"delta","data":{"s":"BTCUSDT","b":[["64662.8","0.0852"],["64657.3","0.050587"]],"a":[["64662.9","0.975848"],["64669.2","0.507484"],["64669.3","0.032803"]],"u":128531282,"seq":111455898459},"cts":1784086832910}
