{"topic":"publicTrade.BTCUSDT","ts":1784086832926,"type":"snapshot","data":[{"i":"2290000001178591592","T":1784086832925,"p":"64662.8","v":"0.006","S":"Sell","seq":111455898475,"s":"BTCUSDT","BT":false,"RPI":false},{"i":"2290000001178591593","T":1784086832925,"p":"64662.8","v":"0.02","S":"Sell","seq":111455898475,"s":"BTCUSDT","BT":false,"RPI":false},{"i":"2290000001178591594","T":1784086832925,"p":"64662.8","v":"0.0016","S":"Sell","seq":111455898475,"s":"BTCUSDT","BT":false,"RPI":false},{"i":"2290000001178591595","T":1784086832925,"p":"64662.8","v":"0.0426","S":"Sell","seq":111455898475,"s":"BTCUSDT","BT":false,"RPI":false},{"i":"2290000001178591596","T":1784086832925,"p":"64662.8","v":"0.001","S":"Sell","seq":111455898475,"s":"BTCUSDT","BT":false,"RPI":false},{"i":"2290000001178591597","T":1784086832925,"p":"64662.8","v":"0.0025","S":"Sell","seq":111455898475,"s":"BTCUSDT","BT":false,"RPI":false},{"i":"2290000001178591598","T":1784086832925,"p":"64662.8","v":"0.0025","S":"Sell","seq":111455898475,"s":"BTCUSDT","BT":false,"RPI":false},{"i":"2290000001178591599","T":1784086832925,"p":"64662.8","v":"0.009","S":"Sell","seq":111455898475,"s":"BTCUSDT","BT":false,"RPI":false},{"i":"2290000001178591600","T":1784086832925,"p":"64662.3","v":"0.006435","S":"Sell","seq":111455898475,"s":"BTCUSDT","BT":false,"RPI":false}]}
{"topic":"orderbook.50.BTCUSDT","ts":1784086832937,"type":"delta","data":{"s":"BTCUSDT","b":[["64662.8","0"],["64662.3","0.047766"],["64656.3","0.117"],["64656.1","0.005"],["64647.6","0.095271"],["64646","0"],["64645.5","0.005"],["64641.3","0"],["64640.8","0.018896"]],"a":[["64662.4","0.982209"],["64662.8","0.566605"],["64662.9","0.06677"],["64663.3","0"],["64663.4","0"],["64668.9","0.0145"],["64669.1","0.0076"],["64669.4","0.117"],["64671.1","0.003763"],["64671.5","0.004258"],["64671.6","0"],["64672","0"],["64683.6","0"],["64683.7","0"]],"u":128531283,"seq":111455898581},"cts":1784086832934}
{"topic":"orderbook.50.BTCUSDT","ts":1784086832956,"type":"delta","data":{"s":"BTCUSDT","b":[["64662.3","0.056766"],["64661.5","0"],["64656.1","0"],["64650.1","0.193348"],["64635.6","0.116092"],["64635.2","0.001391"]],"a":[["64662.4","0.979709"],["64662.7","0.230129"],["64662.8","0.226845"],["64664.2","0"],["64668.9","0.0196"],["64669.1","0"],["64683.6","0.117"]],"u":128531284,"seq":111455898627},"cts":1784086832948}
{"topic":"orderbook.50.BTCUSDT","ts":1784086832976,"type":"delta","data":{"s":"BTCUSDT","b":[["64661","0.007739"],["64658.4","0.030794"],["64652.5","0.105755"],["64646.5","0.037129"],["64635.6","0"],["64635.2","0"]],"a":[["64662.7","0.1264"],["64662.9","0.08996"],["64663.7","0.007739"],["64683.6","0"]],"u":128531285,"seq":111455898677},"cts":1784086832969}
{"topic":"orderbook.50.BTCUSDT","ts":1784086832996,"type":"delta","data":{"s":"BTCUSDT","b":[["64654","0"],["64635.6","0.116092"]],"a":[],"u":128531286,"seq":111455898690},"cts":1784086832990}
{"topic":"orderbook.50.BTCUSDT","ts":1784086833015,"type":"delta","data":{"s":"BTCUSDT","b":[],"a":[["64662.9","0.02705"]],"u":128531287,"seq":111455898708},"cts":1784086833013}
{"topic":"orderbook.50.BTCUSDT","ts":1784086833057,"type":"delta","data":{"s":"BTCUSDT","b":[["64658.4","0.005"],["64652","0"],["64651.7","0.09982"],["64635.2","0.001391"]],"a":[["64662.4","0.831799"]],"u":128531288,"seq":111455898723},"cts":1784086833051}
{"topic":"publicTrade.BTCUSDT","ts":1784086833058,"type":"snapshot","data":[{"i":"2290000001178591601","T":1784086833057,"p":"64662.3","v":"0.002","S":"Sell","seq":111455898724,"s":"BTCUSDT","BT":false,"RPI":false}]}
{"topic":"orderbook.50.BTCUSDT","ts":1784086833076,"type":"delta","data":{"s":"BTCUSDT","b":[["64662.3","0.054766"],["64654.7","0.033333"],["64635.2","0"]],"a":[["64662.8","0.055388"],["64662.9","0.00386"]],"u":128531289,"seq":111455898744},"cts":1784086833070}
{"topic":"orderbook.50.BTCUSDT","ts":1784086833096,"type":"delta","data":{"s":"BTCUSDT","b":[],"a":[["64662.7","0.057599"]],"u":128531290,"seq":111455898748},"cts":1784086833089}
{"topic":"orderbook.50.BTCUSDT","ts":1784086833116,"type":"delta","data":{"s":"BTCUSDT","b":[],"a":[["64662.9","0"],["64683.6","0.117"]],"u":128531291,"seq":111455898755},"cts":1784086833109}
{"topic":"orderbook.50.BTCUSDT","ts":1784086833136,"type":"delta","data":{"s":"BTCUSDT","b":[],"a":[["64662.4","0.866579"]],"u":128531292,"seq":111455898767},"cts":1784086833133}
{"topic":"orderbook.50.BTCUSDT","ts":1784086833156,"type":"delta","data":{"s":"BTCUSDT","b":[],"a":[["64662.4","0.890839"]],"u":128531293,"seq":111455898775},"cts":1784086833150}
{"topic":"orderbook.50.BTCUSDT","ts":1784086833196,"type":"delta","data":{"s":"BTCUSDT","b":[["64658.4","0.030794"]],"a":[],"u":128531294,"seq":111455898781},"cts":1784086833189}
{"topic":"orderbook.50.BTCUSDT","ts":1784086833216,"type":"delta","data":{"s":"BTCUSDT","b":[],"a":[["64662.4","0.898569"]],"u":128531295,"seq":111455898782},"cts":1784086833211}
{"topic":"orderbook.50.BTCUSDT","ts":1784086833235,"type":"delta","data":{"s":"BTCUSDT","b":[["64654.1","0.03"],["64635.6","0"]],"a":[["64662.4","0.914029"]],"u":128531296,"seq":111455898791},"cts":1784086833225}
{"topic":"orderbook.50.BTCUSDT","ts":1784086833256,"type":"delta","data":{"s":"BTCUSDT","b":[],"a":[["64662.4","0.925619"],["64662.7","0.041066"]],"u":128531297,"seq":111455898799},"cts":1784086833250}
{"topic":"orderbook.50.BTCUSDT","ts":1784086833436,"type":"delta","data":{"s":"BTCUSDT","b":[["64662.3","0.085966"]],"a":[],"u":128531298,"seq":111455898826},"cts":1784086833432}
{"topic":"orderbook.50.BTCUSDT","ts":1784086833456,"type":"delta","data":{"s":"BTCUSDT","b":[],"a":[["64662.4","0.898579"]],"u":128531299,"seq":111455898835},"cts":1784086833453}
{"topic":"orderbook.50.BTCUSDT","ts":1784086833476,"type":"delta","data":{"s":"BTCUSDT","b":[["64658.4","0.005"]],"a":[["64662.4","0.875389"]],"u":128531300,"seq":111455898839},"cts":1784086833467}
{"topic":"orderbook.50.BTCUSDT","ts":1784086833496,"type":"delta","data":{"s":"BTCUSDT","b":[],"a":[["64662.4","0.832879"]],"u":128531301,"seq":111455898852},"cts":1784086833495}
{"topic":"orderbook.50.BTCUSDT","ts":1784086833555,"type":"delta","data":{"s":"BTCUSDT","b":[],"a":[["64662.4","0.836729"]],"u":128531302,"seq":111455898864},"cts":1784086833552}
{"topic":"orderbook.50.BTCUSDT","ts":1784086833576,"type":"delta","data":{"s":"BTCUSDT","b":[["64662.3","0.054766"]],"a":[["64662.4","0.839039"]],"u":128531303,"seq":111455898873},"cts":1784086833570}
{"topic":"orderbook.50.BTCUSDT","ts":1784086833596,"type":"delta","data":{"s":"BTCUSDT","b":[["64650.1","0"],["64649.9","0.193349"]],"a":[["64662.4","0.843659"]],"u":128531304,"seq":111455898919},"cts":1784086833595}
{"topic":"orderbook.50.BTCUSDT","ts":1784086833616,"type":"delta","data":{"s":"BTCUSDT","b":[["64662.3","0.076966"],["64649.9","0"],["64648.9","0.193352"]],"a":[],"u":128531305,"seq":111455898961},"cts":1784086833614}
{"topic":"orderbook.50.BTCUSDT","ts":1784086833636,"type":"delta","data":{"s":"BTCUSDT","b":[["64652.5","0.038723"],["64649.5","0.176558"]],"a":[],"u":128531306,"seq":111455898970},"cts":1784086833631}
{"topic":"orderbook.50.BTCUSDT","ts":1784086833676,"type":"delta","data":{"s":"BTCUSDT","b":[["64658.4","0.030794"]],"a":[],"u":128531307,"seq":111455898989},"cts":1784086833670}
{"topic":"orderbook.50.BTCUSDT","ts":1784086833696,"type":"delta","data":{"s":"BTCUSDT","b":[["64641.3","0.003434"],["64640.8","0.015462"],["64635.7","0"]],"a":[],"u":128531308,"seq":111455898993},"cts":1784086833686}
{"topic":"orderbook.50.BTCUSDT","ts":1784086833776,"type":"delta","data":{"s":"BTCUSDT","b":[],"a":[["64662.8","0.030588"],["64681.4","0.005"],["64683.6","0"]],"u":128531309,"seq":111455899015},"cts":1784086833774}
{"topic":"publicTrade.BTCUSDT","ts":1784086833825,"type":"snapshot","data":[{"i":"2290000001178591602","T":1784086833824,"p":"64662.3","v":"0.002","S":"Sell","seq":111455899020,"s":"BTCUSDT","BT":false,"RPI":false}]}
{"topic":"orderbook.50.BTCUSDT","ts":1784086833836,"type":"delta","data":{"s":"BTCUSDT","b":[["64662.3","0.077466"],["64655.8","0.0025"],["64638.4","0"]],"a":[["64662.4","0.846159"],["64668.9","0.0221"]],"u":128531310,"seq":111455899029},"cts":1784086833829}
{"topic":"orderbook.50.BTCUSDT","ts":1784086833916,"type":"delta","data":{"s":"BTCUSDT","b":[["64658.4","0.005"]],"a":[],"u":128531311,"seq":111455899040},"cts":1784086833899}
{"topic":"orderbook.50.BTCUSDT","ts":1784086833996,"type":"delta","data":{"s":"BTCUSDT","b":[["64662.3","0.120066"],["64658.4","0.030794"]],"a":[],"u":128531312,"seq":111455899058},"cts":1784086833991}
{"topic":"orderbook.50.BTCUSDT","ts":1784086834056,"type":"delta","data":{"s":"BTCUSDT","b":[],"a":[["64662.4","0.532352"]],"u":128531313,"seq":111455899080},"cts":1784086834050}
{"topic":"orderbook.50.BTCUSDT","ts":1784086834116,"type":"delta","data":{"s":"BTCUSDT","b":[["64651.7","0.097703"]],"a":[],"u":128531314,"seq":111455899122},"cts":1784086834111}
{"topic":"orderbook.50.BTCUSDT","ts":1784086834136,"type":"delta","data":{"s":"BTCUSDT","b":[["64656.5","0.163653"],["64655","0"]],"a":[],"u":128531315,"seq":111455899127},"cts":1784086834132}
{"topic":"orderbook.50.BTCUSDT","ts":1784086834156,"type":"delta","data":{"s":"BTCUSDT","b":[["64657.3","0.089108"],["64655.1","0"],["64655","0.084355"],["64654.3","0.002262"],["64638.5","0"]],"a":[],"u":128531316,"seq":111455899147},"cts":1784086834154}
{"topic":"orderbook.50.BTCUSDT","ts":1784086834176,"type":"delta","data":{"s":"BTCUSDT","b":[],"a":[["64663.5","0.043677"]],"u":128531317,"seq":111455899165},"cts":1784086834173}
{"topic":"orderbook.50.BTCUSDT","ts":1784086834196,"type":"delta","data":{"s":"BTCUSDT","b":[["64658.4","0.005"]],"a":[],"u":128531318,"seq":111455899172},"cts":1784086834188}
{"topic":"orderbook.50.BTCUSDT","ts":1784086834416,"type":"delta","data":{"s":"BTCUSDT","b":[],"a":[["64664.9","0"],["64683.6","0.117"]],"u":128531319,"seq":111455899214},"cts":1784086834413}
{"topic":"orderbook.50.BTCUSDT","ts":1784086834476,"type":"delta","data":{"s":"BTCUSDT","b":[["64658.4","0.030794"]],"a":[],"u":128531320,"seq":111455899224},"cts":1784086834458}
