{"e":"depthUpdate","E":1781816957214,"s":"BTCUSDT","U":96005695588,"u":96005695616,"b":[["63108.00000000","1.94743000"],["63107.32000000","0.00669000"],["63106.49000000","0.00009000"],["63101.01000000","0.00070000"],["63097.07000000","0.00000000"],["63092.19000000","0.00000000"],["63091.04000000","0.00400000"],["63090.81000000","0.00000000"],["63088.88000000","0.38861000"],["63082.47000000","0.01400000"],["63057.12000000","0.00009000"],["56797.20000000","0.00449000"],["50486.40000000","0.00044000"]],"a":[["63108.01000000","4.72678000"],["63108.02000000","0.00034000"],["63113.99000000","0.03627000"],["63116.33000000","0.00000000"],["63116.98000000","0.26138000"],["63117.73000000","0.00000000"],["63120.07000000","0.00400000"],["63121.26000000","0.00000000"]]}
{"e":"depthUpdate","E":1781816957314,"s":"BTCUSDT","U":96005695617,"u":96005695622,"b":[["63108.00000000","1.87139000"],["56797.20000000","0.00449000"]],"a":[]}
{"e":"depthUpdate","E":1781816957414,"s":"BTCUSDT","U":96005695623,"u":96005695636,"b":[["63108.00000000","1.94822000"],["63098.43000000","0.00000000"],["63097.97000000","0.00400000"],["56797.20000000","0.00449000"],["50486.00000000","0.00099000"]],"a":[["63108.01000000","4.72608000"],["63114.37000000","0.00400000"],["63114.86000000","0.00000000"],["63116.98000000","0.11389000"]]}
{"e":"depthUpdate","E":1781816957514,"s":"BTCUSDT","U":96005695637,"u":96005695642,"b":[["56797.20000000","0.00449000"],["50486.40000000","0.00083000"]],"a":[["63108.01000000","4.72554000"]]}
{"e":"depthUpdate","E":1781816957614,"s":"BTCUSDT","U":96005695643,"u":96005695658,"b":[["63108.00000000","1.74523000"],["56797.20000000","0.00449000"],["50486.40000000","0.00044000"]],"a":[["63108.01000000","4.85393000"]]}
{"e":"depthUpdate","E":1781816957714,"s":"BTCUSDT","U":96005695659,"u":96005695674,"b":[["63108.00000000","1.48644000"],["63100.31000000","0.00000000"],["63096.86000000","0.00000000"],["63096.84000000","0.00000000"],["63091.77000000","0.00000000"],["63047.28000000","3.16917000"],["63038.79000000","3.16917000"],["56797.20000000","0.00469000"],["56797.00000000","0.30000000"]],"a":[["63108.01000000","5.05891000"]]}
{"e":"depthUpdate","E":1781816957814,"s":"BTCUSDT","U":96005695675,"u":96005695793,"b":[["63108.00000000","1.09601000"],["63107.99000000","0.00088000"],["63106.86000000","0.00036000"],["63106.28000000","0.00000000"],["63106.27000000","0.00018000"],["63105.00000000","0.00000000"],["63104.86000000","0.00018000"],["63103.70000000","0.00018000"],["63102.36000000","0.00000000"],["63100.68000000","0.00018000"],["63100.67000000","0.61861000"],["63100.32000000","0.00000000"],["63100.03000000","0.00000000"],["63099.41000000","0.00018000"],["63098.06000000","0.00000000"],["63097.97000000","0.00000000"],["63097.63000000","1.52292000"],["63097.07000000","0.00018000"],["63096.88000000","2.56712000"],["63096.87000000","0.00000000"],["63096.85000000","0.00000000"],["63094.61000000","0.00018000"],["63094.60000000","1.18963000"],["63094.49000000","0.00000000"],["63094.21000000","1.04183000"],["63093.36000000","0.00000000"],["63092.01000000","0.00018000"],["63091.78000000","0.00000000"],["63091.18000000","0.00000000"],["63091.04000000","0.00000000"],["63090.97000000","0.00400000"],["63090.74000000","2.73857000"],["63090.73000000","3.16917000"],["63090.72000000","0.00018000"],["63089.74000000","0.00018000"],["63089.50000000","0.13954000"],["63088.79000000","0.01586000"],["63085.40000000","0.00000000"],["63050.39000000","2.50163000"],["63038.79000000","0.00000000"],["63021.26000000","0.87779000"],["63021.25000000","0.00000000"],["63019.13000000","2.89233000"],["62108.00000000","0.01630000"],["56797.20000000","0.00449000"]],"a":[["63108.01000000","5.05899000"],["63108.02000000","0.00034000"],["63108.90000000","0.00009000"],["63108.91000000","0.07613000"],["63109.86000000","0.00000000"],["63109.98000000","0.00018000"],["63109.99000000","0.02886000"],["63110.00000000","0.02490000"],["63110.16000000","0.00036000"],["63111.53000000","0.00000000"],["63111.54000000","0.00018000"],["63111.94000000","2.16620000"],["63111.95000000","3.16917000"],["63111.96000000","0.46092000"],["63112.47000000","0.03894000"],["63116.97000000","0.00018000"],["63116.99000000","0.02868000"],["63117.36000000","0.57102000"],["63119.67000000","0.00018000"],["63119.68000000","0.79321000"],["63119.97000000","0.00400000"],["63120.07000000","0.00000000"],["63122.93000000","0.00018000"],["63126.29000000","0.00018000"],["63129.31000000","0.00000000"],["63131.98000000","0.00018000"],["63132.37000000","0.00000000"],["63138.99000000","0.00000000"],["63152.57000000","0.00000000"],["63170.72000000","1.70476000"],["63170.73000000","0.00000000"]]}
{"e":"depthUpdate","E":1781816957920,"s":"BTCUSDT","U":96005695794,"u":96005696781,"b":[["63108.00000000","0.00000000"],["63107.99000000","0.00000000"],["63107.98000000","0.00000000"],["63107.81000000","0.00000000"],["63107.32000000","0.00000000"],["63107.20000000","0.00000000"],["63107.12000000","0.00000000"],["63107.09000000","0.00000000"],["63107.04000000","0.00000000"],["63106.86000000","0.00000000"],["63106.85000000","0.00000000"],["63106.49000000","0.00000000"],["63106.27000000","0.00000000"],["63106.26000000","0.00000000"],["63106.24000000","0.00000000"],["63106.01000000","0.00000000"],["63106.00000000","0.00000000"],["63105.99000000","0.00000000"],["63105.98000000","0.00000000"],["63105.67000000","0.00000000"],["63105.66000000","0.00000000"],["63105.33000000","0.00000000"],["63105.23000000","0.00000000"],["63105.16000000","0.00000000"],["63104.96000000","0.19944000"],["63104.95000000","0.00045000"],["63104.86000000","0.00000000"],["63104.85000000","0.00018000"],["63104.23000000","0.00018000"],["63104.02000000","0.00000000"],["63104.01000000","0.00018000"],["63104.00000000","0.02318000"],["63103.99000000","0.00181000"],["63103.96000000","0.00018000"],["63103.95000000","0.00044000"],["63103.94000000","0.00026000"],["63103.90000000","0.00009000"],["63103.70000000","0.00036000"],["63103.69000000","0.06599000"],["63103.62000000","0.00000000"],["63103.50000000","0.00009000"],["63103.49000000","0.00018000"],["63103.21000000","0.00000000"],["63102.65000000","0.00000000"],["63102.35000000","0.00016000"],["63102.10000000","0.00000000"],["63102.09000000","0.00000000"],["63102.04000000","0.00000000"],["63102.01000000","0.00000000"],["63102.00000000","0.02300000"],["63101.99000000","0.00000000"],["63101.70000000","0.00000000"],["63101.68000000","0.00000000"],["63101.65000000","0.00000000"],["63101.47000000","0.00000000"],["63100.67000000","0.00000000"],["63100.46000000","0.00000000"],["63100.34000000","0.00000000"],["63100.15000000","0.00000000"],["63100.04000000","0.00000000"],["63099.99000000","0.00000000"],["63099.75000000","0.00000000"],["63099.72000000","0.00000000"],["63099.40000000","0.00000000"],["63099.02000000","0.00000000"],["63098.98000000","0.00301000"],["63098.95000000","0.00000000"],["63098.84000000","0.00008000"],["63098.71000000","0.00000000"],["63098.65000000","0.00000000"],["63098.31000000","0.00000000"],["63098.05000000","0.00000000"],["63097.95000000","0.20000000"],["63097.92000000","0.36429000"],["63097.84000000","0.01585000"],["63097.63000000","0.00000000"],["63096.93000000","0.00000000"],["63096.88000000","0.00000000"],["63096.68000000","0.02710000"],["63096.58000000","0.01585000"],["63096.47000000","0.00000000"],["63096.42000000","0.00000000"],["63095.75000000","0.00000000"],["63095.66000000","0.00000000"],["63094.60000000","0.00000000"],["63094.22000000","0.02629000"],["63094.21000000","0.00000000"],["63094.20000000","0.00000000"],["63093.74000000","0.00252000"],["63092.47000000","0.00000000"],["63092.29000000","0.00000000"],["63092.00000000","0.02300000"],["63091.35000000","0.00000000"],["63091.26000000","0.00000000"],["63090.97000000","0.00000000"],["63090.74000000","0.00000000"],["63090.73000000","0.00000000"],["63090.71000000","0.00000000"],["63090.51000000","0.00000000"],["63090.40000000","0.00000000"],["63090.31000000","0.00000000"],["63089.73000000","0.00000000"],["63089.50000000","0.00000000"],["63089.46000000","0.00000000"],["63088.88000000","0.00000000"],["63088.79000000","0.00000000"],["63088.01000000","0.00000000"],["63087.99000000","0.00000000"],["63086.92000000","0.00000000"],["63086.79000000","0.00000000"],["63086.78000000","0.00000000"],["63086.51000000","0.00000000"],["63086.04000000","0.00000000"],["63085.92000000","2.56730000"],["63085.91000000","0.00000000"],["63085.17000000","0.00000000"],["63083.75000000","0.00000000"],["63082.43000000","2.56712000"],["63082.42000000","0.00000000"],["63082.41000000","0.00000000"],["63081.93000000","0.00000000"],["63081.90000000","0.00000000"],["63080.53000000","0.14655000"],["63080.38000000","0.00000000"],["63080.37000000","0.00000000"],["63078.62000000","1.07908000"],["63078.61000000","2.56712000"],["63078.60000000","0.00000000"],["63078.59000000","0.00000000"],["63078.34000000","0.00664000"],["63076.93000000","0.13962000"],["63076.44000000","3.16917000"],["63076.14000000","0.46056000"],["63076.13000000","0.00000000"],["63076.00000000","0.02300000"],["63075.91000000","0.00000000"],["63075.56000000","0.49384000"],["63075.51000000","0.00000000"],["63075.50000000","0.00000000"],["63075.41000000","0.00000000"],["63075.18000000","0.00400000"],["63074.40000000","0.00008000"],["63073.13000000","0.00000000"],["63072.02000000","0.00400000"],["63070.72000000","0.00023000"],["63069.61000000","0.47566000"],["63069.14000000","0.00000000"],["63068.65000000","0.00000000"],["63067.90000000","0.00396000"],["63067.82000000","0.00023000"],["63066.29000000","0.00716000"],["63065.76000000","0.00000000"],["63064.34000000","1.67447000"],["63062.80000000","0.00023000"],["63061.34000000","0.00000000"],["63056.64000000","0.00009000"],["63055.25000000","0.00000000"],["63054.02000000","0.00393000"],["63054.01000000","0.00000000"],["63053.01000000","0.00000000"],["63050.08000000","1.57199000"],["63048.33000000","0.00000000"],["63047.35000000","0.00000000"],["63046.31000000","0.00000000"],["63045.24000000","0.00016000"],["63043.65000000","0.00000000"],["63043.19000000","1.57216000"],["63041.70000000","0.00000000"],["63039.69000000","2.56712000"],["63038.79000000","3.16917000"],["63038.77000000","0.00000000"],["63032.11000000","2.56712000"],["63030.27000000","3.16917000"],["63028.44000000","0.00008000"],["63027.09000000","0.00008000"],["63025.24000000","0.00000000"],["63021.75000000","3.16917000"],["63021.26000000","0.00000000"],["63019.13000000","0.00000000"],["63014.89000000","0.00000000"],["63000.01000000","2.50503000"],["62990.70000000","0.00000000"],["62987.05000000","0.00751000"],["62941.58000000","4.77184000"],["62851.16000000","0.00000000"],["62108.00000000","0.01610000"],["56797.20000000","0.00009000"]],"a":[["63104.97000000","4.20212000"],["63105.15000000","0.00000000"],["63105.16000000","3.22521000"],["63105.17000000","3.06097000"],["63105.18000000","0.00009000"],["63105.24000000","0.00000000"],["63105.34000000","0.00000000"],["63105.65000000","0.00592000"],["63105.66000000","0.05023000"],["63105.67000000","0.57389000"],["63105.68000000","0.01760000"],["63105.97000000","0.14929000"],["63105.98000000","0.45566000"],["63105.99000000","0.00000000"],["63106.00000000","0.00000000"],["63106.01000000","0.13229000"],["63106.02000000","0.00000000"],["63106.25000000","0.00000000"],["63106.26000000","3.16917000"],["63106.27000000","0.00040000"],["63106.49000000","0.00000000"],["63106.50000000","1.27474000"],["63106.68000000","0.01585000"],["63106.78000000","0.00400000"],["63106.84000000","0.62961000"],["63106.85000000","0.62821000"],["63106.86000000","0.00016000"],["63106.87000000","0.00024000"],["63107.05000000","0.00008000"],["63107.10000000","0.00000000"],["63107.13000000","0.00000000"],["63107.20000000","0.00008000"],["63107.21000000","0.00008000"],["63107.31000000","0.00000000"],["63107.32000000","0.00000000"],["63107.33000000","0.52443000"],["63107.80000000","0.00000000"],["63107.81000000","0.00008000"],["63107.82000000","0.00008000"],["63107.87000000","0.00000000"],["63107.94000000","0.01585000"],["63107.99000000","0.00000000"],["63108.00000000","3.67546000"],["63108.01000000","0.96385000"],["63108.02000000","0.00000000"],["63108.03000000","0.00000000"],["63108.36000000","0.00400000"],["63108.69000000","0.03894000"],["63108.90000000","0.00000000"],["63108.91000000","0.00000000"],["63109.73000000","0.00008000"],["63109.98000000","0.00000000"],["63109.99000000","0.02868000"],["63110.00000000","0.02454000"],["63110.01000000","0.00000000"],["63110.16000000","0.00018000"],["63110.17000000","0.47282000"],["63110.44000000","0.00000000"],["63111.48000000","0.00318000"],["63111.54000000","0.00000000"],["63111.78000000","0.18017000"],["63111.79000000","0.00000000"],["63111.80000000","0.00000000"],["63111.93000000","0.00000000"],["63111.94000000","2.16620000"],["63111.96000000","0.46074000"],["63111.97000000","2.56712000"],["63112.00000000","0.49213000"],["63112.32000000","0.00000000"],["63112.47000000","0.00000000"],["63112.56000000","0.02000000"],["63112.65000000","0.00000000"],["63112.98000000","0.00000000"],["63113.06000000","0.00000000"],["63113.36000000","0.79337000"],["63113.37000000","0.25645000"],["63114.29000000","0.00000000"],["63114.32000000","0.00000000"],["63114.33000000","0.00000000"],["63115.52000000","0.16000000"],["63116.61000000","0.38867000"],["63116.98000000","0.00000000"],["63116.99000000","0.02868000"],["63117.00000000","0.00000000"],["63117.10000000","0.16000000"],["63117.36000000","0.00000000"],["63118.21000000","0.00000000"],["63119.51000000","0.00230000"],["63119.68000000","0.00000000"],["63119.79000000","0.00000000"],["63121.29000000","0.00000000"],["63126.91000000","1.57008000"],["63128.84000000","0.00000000"],["63129.23000000","0.00000000"],["63129.55000000","0.00000000"],["63130.12000000","0.15702000"],["63130.87000000","0.00000000"],["63131.75000000","0.00000000"],["63132.06000000","0.00000000"],["63133.63000000","1.56991000"],["63133.64000000","0.00000000"],["63135.76000000","0.00000000"],["63136.61000000","0.00016000"],["63136.73000000","0.13533000"],["63136.95000000","0.00000000"],["63143.82000000","0.00000000"],["63145.58000000","0.00000000"],["63146.81000000","0.00000000"],["63147.09000000","0.00000000"],["63152.69000000","0.00000000"],["63158.41000000","3.16917000"],["63159.43000000","0.00000000"],["63159.71000000","0.00000000"],["63166.94000000","0.00000000"],["63168.90000000","0.00000000"],["63169.96000000","0.00018000"],["63176.48000000","0.00000000"],["63176.76000000","0.00000000"],["63179.92000000","0.00000000"],["63185.50000000","0.00000000"],["63201.61000000","0.00475000"],["63204.59000000","0.00000000"],["63233.06000000","0.00018000"],["63236.40000000","0.00000000"],["63239.60000000","0.00000000"],["63248.09000000","0.20971000"],["63264.25000000","0.00000000"],["63296.17000000","0.00018000"],["63302.71000000","0.00000000"],["63359.28000000","0.00018000"],["63365.82000000","0.00000000"],["63422.38000000","0.00018000"],["63428.94000000","0.00000000"],["63485.49000000","0.00018000"],["63492.05000000","0.00000000"],["63548.60000000","0.00018000"],["63555.16000000","0.00000000"],["63610.52000000","0.00018000"],["64019.66000000","0.00000000"],["64041.09000000","1.66763000"]]}
{"e":"depthUpdate","E":1781816958014,"s":"BTCUSDT","U":96005696782,"u":96005698596,"b":[["63104.96000000","0.00000000"],["63104.95000000","0.00000000"],["63104.85000000","0.00000000"],["63104.23000000","0.00000000"],["63104.12000000","0.00000000"],["63104.01000000","0.00000000"],["63104.00000000","0.00000000"],["63103.99000000","0.00000000"],["63103.96000000","0.00000000"],["63103.95000000","0.00000000"],["63103.94000000","0.00000000"],["63103.92000000","0.00000000"],["63103.90000000","0.00000000"],["63103.70000000","0.00000000"],["63103.69000000","0.00000000"],["63103.68000000","0.00000000"],["63103.66000000","0.00000000"],["63103.50000000","0.00000000"],["63103.49000000","0.00000000"],["63103.22000000","0.00000000"],["63102.72000000","0.00000000"],["63102.35000000","0.00000000"],["63102.29000000","0.00000000"],["63102.17000000","0.00000000"],["63102.01000000","0.00000000"],["63102.00000000","0.00000000"],["63101.99000000","0.00000000"],["63101.01000000","0.00000000"],["63100.84000000","0.00000000"],["63100.78000000","0.00000000"],["63100.68000000","0.00000000"],["63100.64000000","0.00000000"],["63100.54000000","0.00000000"],["63100.53000000","0.00000000"],["63100.52000000","0.00000000"],["63100.20000000","0.00000000"],["63100.19000000","0.00000000"],["63100.01000000","0.00000000"],["63100.00000000","0.00000000"],["63099.93000000","0.00000000"],["63099.64000000","0.00000000"],["63099.59000000","0.00000000"],["63099.58000000","0.00000000"],["63099.57000000","0.00000000"],["63099.56000000","0.00000000"],["63099.41000000","0.00000000"],["63098.98000000","0.00000000"],["63098.88000000","0.00000000"],["63098.87000000","0.00000000"],["63098.84000000","0.00000000"],["63098.70000000","0.00000000"],["63098.66000000","0.00000000"],["63098.65000000","0.00000000"],["63098.64000000","0.00000000"],["63098.45000000","0.00000000"],["63098.12000000","0.00000000"],["63098.06000000","0.00000000"],["63098.05000000","0.00000000"],["63098.02000000","0.00000000"],["63098.01000000","0.00000000"],["63098.00000000","0.16186000"],["63097.99000000","0.00072000"],["63097.95000000","0.00026000"],["63097.93000000","0.00018000"],["63097.92000000","0.00034000"],["63097.88000000","0.00000000"],["63097.84000000","0.00018000"],["63097.70000000","0.00000000"],["63097.69000000","0.00000000"],["63097.62000000","0.00000000"],["63097.59000000","0.00000000"],["63097.38000000","0.00000000"],["63097.37000000","0.00000000"],["63097.30000000","0.00000000"],["63097.12000000","0.00000000"],["63097.07000000","0.00018000"],["63097.06000000","0.00000000"],["63096.86000000","0.00018000"],["63096.85000000","0.00000000"],["63096.69000000","0.00018000"],["63096.58000000","0.00000000"],["63096.43000000","0.00000000"],["63096.40000000","0.00000000"],["63096.16000000","0.00018000"],["63096.15000000","0.00000000"],["63095.99000000","0.00008000"],["63095.68000000","0.00000000"],["63095.59000000","0.00000000"],["63095.21000000","0.00000000"],["63095.08000000","0.00000000"],["63094.80000000","0.00000000"],["63094.49000000","0.00009000"],["63094.48000000","0.00016000"],["63094.35000000","0.00000000"],["63094.22000000","0.00000000"],["63094.21000000","0.00000000"],["63094.14000000","0.00400000"],["63094.00000000","0.02390000"],["63093.95000000","0.00000000"],["63093.52000000","0.00000000"],["63093.08000000","0.00068000"],["63092.75000000","0.00000000"],["63092.74000000","0.00000000"],["63092.57000000","0.00000000"],["63092.54000000","0.00221000"],["63092.43000000","0.00000000"],["63092.41000000","0.00000000"],["63092.35000000","0.30000000"],["63092.33000000","0.00009000"],["63092.32000000","0.00000000"],["63091.84000000","0.00028000"],["63091.77000000","0.00301000"],["63091.69000000","0.00008000"],["63091.48000000","0.00000000"],["63091.47000000","0.02000000"],["63091.40000000","0.00048000"],["63090.62000000","0.00048000"],["63090.00000000","0.02300000"],["63089.27000000","0.00861000"],["63089.07000000","0.00189000"],["63088.88000000","0.00000000"],["63088.51000000","0.00008000"],["63088.36000000","0.16007000"],["63087.53000000","0.00793000"],["63086.80000000","0.00000000"],["63086.79000000","0.16008000"],["63086.68000000","0.00000000"],["63086.45000000","0.00000000"],["63086.29000000","0.00000000"],["63086.11000000","0.00863000"],["63086.00000000","0.02312000"],["63085.94000000","0.00000000"],["63085.93000000","0.00000000"],["63085.92000000","0.00018000"],["63085.58000000","0.00000000"],["63085.38000000","0.00000000"],["63084.79000000","0.00000000"],["63084.42000000","0.00000000"],["63084.41000000","0.48200000"],["63083.75000000","0.00000000"],["63083.56000000","0.00000000"],["63083.54000000","0.00000000"],["63083.53000000","0.00000000"],["63083.49000000","0.00119000"],["63083.03000000","0.00000000"],["63082.95000000","0.00887000"],["63082.44000000","2.56712000"],["63082.43000000","0.00000000"],["63082.33000000","0.00012000"],["63082.28000000","0.00000000"],["63081.70000000","0.13156000"],["63080.53000000","0.09964000"],["63080.52000000","0.00000000"],["63078.62000000","1.78501000"],["63078.31000000","0.00000000"],["63078.01000000","0.38868000"],["63076.76000000","0.00400000"],["63076.45000000","0.46056000"],["63076.14000000","0.00000000"],["63075.56000000","0.32449000"],["63075.55000000","0.00000000"],["63075.00000000","0.00015000"],["63073.00000000","0.00000000"],["63072.00000000","0.02309000"],["63071.12000000","0.00008000"],["63070.76000000","0.00000000"],["63070.00000000","0.02350000"],["63069.61000000","0.00000000"],["63068.86000000","0.00400000"],["63068.77000000","0.00320000"],["63068.00000000","0.02300000"],["63067.89000000","0.00000000"],["63067.84000000","0.02008000"],["63067.69000000","0.00000000"],["63067.65000000","0.57147000"],["63067.00000000","0.00000000"],["63066.50000000","0.47568000"],["63066.00000000","0.03300000"],["63065.60000000","0.00000000"],["63064.63000000","0.00000000"],["63064.50000000","0.00000000"],["63064.44000000","0.00000000"],["63063.48000000","0.00000000"],["63063.39000000","0.01162000"],["63061.29000000","0.00000000"],["63060.12000000","0.57154000"],["63056.89000000","0.00000000"],["63051.14000000","0.00428000"],["63050.99000000","0.00436000"],["63049.11000000","0.00430000"],["63045.24000000","0.00000000"],["63044.69000000","0.00000000"],["63042.41000000","0.36939000"],["63041.46000000","0.00000000"],["63041.00000000","0.00000000"],["63040.69000000","0.00000000"],["63040.29000000","0.00000000"],["63040.12000000","0.00000000"],["63040.06000000","0.00000000"],["63040.01000000","0.00000000"],["63039.03000000","0.00000000"],["63038.99000000","0.00109000"],["63038.84000000","0.00000000"],["63038.78000000","0.00000000"],["63038.31000000","0.00000000"],["63038.00000000","1.59529000"],["63037.87000000","0.00000000"],["63037.65000000","0.00000000"],["63037.54000000","0.00018000"],["63036.97000000","0.02070000"],["63032.54000000","0.04757000"],["63023.87000000","0.00000000"],["63023.42000000","0.00000000"],["63023.06000000","0.00000000"],["63022.86000000","0.00000000"],["63022.27000000","0.00000000"],["63021.76000000","3.16917000"],["63021.75000000","0.00000000"],["63021.38000000","0.04648000"],["63021.24000000","0.00000000"],["63021.05000000","0.00000000"],["63020.51000000","0.00000000"],["63019.69000000","0.00000000"],["63019.18000000","0.00974000"],["63010.17000000","0.00000000"],["63001.23000000","0.00751000"],["62982.01000000","0.04997000"],["62981.58000000","0.00000000"],["62976.71000000","0.00000000"],["62974.44000000","0.00018000"],["62973.15000000","0.00000000"],["62959.19000000","1.20000000"],["62944.51000000","0.00008000"],["62941.36000000","0.00008000"],["62938.30000000","0.00008000"],["62935.15000000","0.00008000"],["62932.01000000","0.00000000"],["62930.01000000","0.00960000"],["62918.48000000","0.00000000"],["62911.34000000","0.00018000"],["62855.37000000","0.00000000"],["62848.24000000","0.00018000"],["62843.98000000","0.00047000"],["62820.00000000","0.01586000"],["62792.26000000","0.00000000"],["62787.01000000","0.00008000"],["62785.14000000","0.00018000"],["62729.15000000","0.00000000"],["62722.04000000","0.00018000"],["62666.05000000","0.00000000"],["62658.94000000","0.00018000"],["62602.94000000","0.00000000"],["62595.83000000","0.00018000"],["56790.48000000","0.00000000"],["50478.40000000","0.00039000"]],"a":[["63098.01000000","4.85497000"],["63098.02000000","0.00034000"],["63098.03000000","0.00016000"],["63098.13000000","0.00000000"],["63098.65000000","0.00000000"],["63098.71000000","0.00000000"],["63098.83000000","0.05000000"],["63098.85000000","0.00000000"],["63098.88000000","5.46814000"],["63098.89000000","3.02727000"],["63098.90000000","0.00000000"],["63098.91000000","0.00000000"],["63099.40000000","0.00018000"],["63099.41000000","0.11792000"],["63099.42000000","0.00000000"],["63099.56000000","0.00000000"],["63099.57000000","0.00008000"],["63099.58000000","0.00018000"],["63099.59000000","0.00000000"],["63099.65000000","0.00000000"],["63099.94000000","0.00000000"],["63100.00000000","0.00018000"],["63100.01000000","0.00000000"],["63100.19000000","0.00000000"],["63100.20000000","0.00008000"],["63100.21000000","0.00000000"],["63100.52000000","0.00009000"],["63100.53000000","0.05008000"],["63100.54000000","0.11199000"],["63100.55000000","0.00000000"],["63100.56000000","0.00000000"],["63100.64000000","0.00008000"],["63100.65000000","0.00000000"],["63100.69000000","0.00000000"],["63100.79000000","0.00000000"],["63100.85000000","0.00000000"],["63101.02000000","0.00000000"],["63101.29000000","0.03894000"],["63101.98000000","1.59879000"],["63101.99000000","0.00000000"],["63102.00000000","2.61735000"],["63102.01000000","0.05727000"],["63102.02000000","0.00000000"],["63102.03000000","0.00000000"],["63102.04000000","0.00400000"],["63102.36000000","0.00000000"],["63102.73000000","0.00000000"],["63103.50000000","0.00000000"],["63103.51000000","0.00000000"],["63103.62000000","0.00400000"],["63103.67000000","0.00000000"],["63103.69000000","0.02868000"],["63103.70000000","0.26115000"],["63103.71000000","0.00000000"],["63103.72000000","0.00000000"],["63103.92000000","0.00008000"],["63103.95000000","0.00000000"],["63103.96000000","0.00000000"],["63104.00000000","0.00000000"],["63104.01000000","0.00000000"],["63104.02000000","0.00010000"],["63104.13000000","0.00000000"],["63104.24000000","0.00000000"],["63104.86000000","0.00000000"],["63104.94000000","0.00000000"],["63104.95000000","3.13540000"],["63104.96000000","0.33179000"],["63104.97000000","0.97764000"],["63104.98000000","0.00000000"],["63104.99000000","0.00000000"],["63105.15000000","0.00000000"],["63105.16000000","2.76730000"],["63105.17000000","1.63752000"],["63105.18000000","0.00000000"],["63105.20000000","0.00400000"],["63105.24000000","0.00000000"],["63105.34000000","0.00000000"],["63105.65000000","0.00000000"],["63105.66000000","0.79327000"],["63105.67000000","0.00026000"],["63105.68000000","0.00000000"],["63105.89000000","0.00008000"],["63105.95000000","0.02000000"],["63105.97000000","0.00000000"],["63105.98000000","0.45557000"],["63106.01000000","0.11644000"],["63106.26000000","3.28917000"],["63106.27000000","0.00040000"],["63106.50000000","0.26814000"],["63106.68000000","0.00000000"],["63106.84000000","0.00000000"],["63106.85000000","0.37621000"],["63106.86000000","0.00000000"],["63106.87000000","0.00000000"],["63106.96000000","0.03000000"],["63107.05000000","0.00000000"],["63107.21000000","0.00000000"],["63107.33000000","0.00034000"],["63107.57000000","0.00155000"],["63107.81000000","0.00000000"],["63107.82000000","0.00000000"],["63107.94000000","0.00000000"],["63107.99000000","0.96109000"],["63108.00000000","2.56712000"],["63108.01000000","0.94057000"],["63108.69000000","0.00000000"],["63109.57000000","0.00012000"],["63109.89000000","0.00008000"],["63109.91000000","0.16002000"],["63109.99000000","0.03432000"],["63110.17000000","0.47266000"],["63110.39000000","0.00319000"],["63110.40000000","0.00009000"],["63110.49000000","0.00000000"],["63110.97000000","0.00000000"],["63110.98000000","0.00975000"],["63111.28000000","0.00000000"],["63111.29000000","0.24750000"],["63111.48000000","0.16001000"],["63111.53000000","0.00855000"],["63111.78000000","0.00000000"],["63111.99000000","0.00000000"],["63112.00000000","0.49197000"],["63112.42000000","0.57107000"],["63112.56000000","0.00000000"],["63112.85000000","0.00008000"],["63113.18000000","0.00000000"],["63113.36000000","0.00018000"],["63113.37000000","0.25628000"],["63113.99000000","0.02397000"],["63114.08000000","0.00000000"],["63114.37000000","0.00000000"],["63114.46000000","0.00000000"],["63115.52000000","0.00000000"],["63116.34000000","0.00000000"],["63116.65000000","0.57103000"],["63117.10000000","0.00000000"],["63117.87000000","0.00008000"],["63118.85000000","0.32379000"],["63119.36000000","0.00000000"],["63119.47000000","0.00158000"],["63119.50000000","0.00000000"],["63120.00000000","0.02359000"],["63120.60000000","1.57024000"],["63122.65000000","0.00000000"],["63123.20000000","0.32379000"],["63123.86000000","0.00000000"],["63123.95000000","0.00012000"],["63124.51000000","0.15703000"],["63124.63000000","0.00000000"],["63124.88000000","0.00126000"],["63125.36000000","0.00000000"],["63125.81000000","0.00000000"],["63125.88000000","0.00000000"],["63126.00000000","0.27050000"],["63126.33000000","0.00000000"],["63126.39000000","0.00008000"],["63127.32000000","0.00000000"],["63127.34000000","0.00433000"],["63128.75000000","0.00619000"],["63128.89000000","0.52246000"],["63128.90000000","0.00000000"],["63130.08000000","0.00000000"],["63130.12000000","0.00000000"],["63130.16000000","0.00000000"],["63130.48000000","0.00000000"],["63130.49000000","0.00000000"],["63130.88000000","0.00018000"],["63131.08000000","0.00431000"],["63131.16000000","0.00193000"],["63131.66000000","0.00436000"],["63132.30000000","0.00015000"],["63133.09000000","0.00000000"],["63133.44000000","0.00009000"],["63134.77000000","0.00000000"],["63135.26000000","0.00000000"],["63135.60000000","0.00000000"],["63136.39000000","0.00000000"],["63136.61000000","0.00000000"],["63136.69000000","0.00000000"],["63136.72000000","0.00000000"],["63137.00000000","0.01000000"],["63137.11000000","0.00000000"],["63138.39000000","0.12909000"],["63139.00000000","3.16890000"],["63140.00000000","0.02350000"],["63140.21000000","0.00000000"],["63141.49000000","0.00000000"],["63142.72000000","0.00000000"],["63143.85000000","0.00000000"],["63146.70000000","0.02000000"],["63151.81000000","0.00000000"],["63154.34000000","3.48137000"],["63155.13000000","0.01131000"],["63156.71000000","0.00000000"],["63158.41000000","0.00000000"],["63158.64000000","0.00000000"],["63158.88000000","0.47764000"],["63162.48000000","0.02000000"],["63162.52000000","0.95193000"],["63163.64000000","0.00018000"],["63164.25000000","0.00000000"],["63164.48000000","0.00000000"],["63166.96000000","0.00000000"],["63169.96000000","0.00000000"],["63171.55000000","0.02048000"],["63171.99000000","0.00000000"],["63177.27000000","0.00000000"],["63179.55000000","0.86030000"],["63181.23000000","0.00000000"],["63182.98000000","0.00000000"],["63187.13000000","0.00000000"],["63187.14000000","0.00000000"],["63187.88000000","0.01005000"],["63194.71000000","0.00000000"],["63194.72000000","0.00000000"],["63201.62000000","0.00000000"],["63203.87000000","0.00000000"],["63204.52000000","0.00000000"],["63206.67000000","0.00000000"],["63210.00000000","0.00050000"],["63211.34000000","0.00000000"],["63217.20000000","0.00000000"],["63217.73000000","0.00000000"],["63220.94000000","0.00000000"],["63224.31000000","0.00000000"],["63226.74000000","0.00018000"],["63229.09000000","0.00000000"],["63231.91000000","0.00000000"],["63233.06000000","0.00000000"],["63236.18000000","0.00000000"],["63263.47000000","0.00000000"],["63269.78000000","0.00000000"],["63276.10000000","0.00000000"],["63282.11000000","0.00000000"],["63289.84000000","0.00018000"],["63296.17000000","0.00000000"],["63315.89000000","0.00000000"],["63352.94000000","0.01727000"],["63359.28000000","0.00000000"],["63416.04000000","0.00018000"],["63422.38000000","0.00000000"],["63479.14000000","0.00018000"],["63485.49000000","0.00000000"],["63542.24000000","0.00018000"],["63548.60000000","0.00000000"],["63603.68000000","0.00018000"],["63610.52000000","0.00000000"],["63616.90000000","0.00000000"],["63724.41000000","1.05834000"],["63727.57000000","0.00000000"]]}
{"e":"depthUpdate","E":1781816958114,"s":"BTCUSDT","U":96005698597,"u":96005698955,"b":[["63098.00000000","0.59779000"],["63097.99000000","0.00063000"],["63097.95000000","0.00000000"],["63097.93000000","0.00000000"],["63097.92000000","0.00000000"],["63097.84000000","0.00000000"],["63096.86000000","0.00000000"],["63096.68000000","0.02728000"],["63096.16000000","0.00000000"],["63096.12000000","0.00000000"],["63096.01000000","0.00018000"],["63096.00000000","0.02318000"],["63095.72000000","0.00000000"],["63095.16000000","0.00009000"],["63094.86000000","0.00903000"],["63094.49000000","0.00000000"],["63094.14000000","0.00000000"],["63094.01000000","0.00041000"],["63094.00000000","0.02408000"],["63093.84000000","0.07613000"],["63093.74000000","0.00099000"],["63092.36000000","0.00018000"],["63092.35000000","0.30018000"],["63092.15000000","0.00009000"],["63092.14000000","0.10569000"],["63092.00000000","0.02318000"],["63091.79000000","0.05982000"],["63091.69000000","0.00000000"],["63091.19000000","0.00852000"],["63088.97000000","0.04000000"],["63088.94000000","0.04000000"],["63088.88000000","0.24411000"],["63088.63000000","0.04985000"],["63087.70000000","0.25388000"],["63087.07000000","0.02000000"],["63086.44000000","0.02000000"],["63086.00000000","0.02312000"],["63085.81000000","0.04000000"],["63085.79000000","0.02000000"],["63085.48000000","0.03988000"],["63085.45000000","0.00153000"],["63084.75000000","0.00793000"],["63082.49000000","2.08935000"],["63082.48000000","3.16967000"],["63082.46000000","0.00000000"],["63082.45000000","3.76265000"],["63082.44000000","0.00000000"],["63082.32000000","0.02991000"],["63081.70000000","0.00000000"],["63081.43000000","0.00000000"],["63080.71000000","0.00000000"],["63080.55000000","0.13068000"],["63079.17000000","0.01994000"],["63078.01000000","0.00000000"],["63076.63000000","0.55026000"],["63076.01000000","0.38869000"],["63075.56000000","0.00000000"],["63069.71000000","0.00000000"],["63067.28000000","0.00400000"],["63066.50000000","0.00000000"],["63064.15000000","0.47570000"],["63064.12000000","0.00400000"],["63063.10000000","0.00000000"],["63057.70000000","1.03946000"],["63057.26000000","0.00000000"],["63055.09000000","0.00000000"],["63051.64000000","0.02200000"],["63051.62000000","0.02000000"],["63048.76000000","0.02000000"],["63048.43000000","0.02000000"],["63048.12000000","0.02000000"],["63047.24000000","0.00622000"],["63047.09000000","0.00793000"],["63045.38000000","0.01740000"],["63039.46000000","0.02000000"],["63039.44000000","0.00000000"],["63039.43000000","0.02000000"],["63037.56000000","0.06650000"],["63036.97000000","0.00000000"],["63036.93000000","0.02000000"],["63036.71000000","0.00000000"],["63036.30000000","0.02000000"],["63036.28000000","0.02000000"],["63035.99000000","0.00000000"],["63035.82000000","0.02055000"],["63032.30000000","0.00000000"],["63029.58000000","0.95193000"],["63022.35000000","0.00015000"],["63021.76000000","0.00000000"],["63019.18000000","0.00000000"],["63018.56000000","0.00000000"],["63018.03000000","0.01001000"],["63003.71000000","0.05109000"],["62980.30000000","0.00000000"],["62980.05000000","6.45117000"],["62968.54000000","0.00000000"],["62961.98000000","0.00827000"],["62932.62000000","0.00008000"],["62929.47000000","0.00000000"],["56788.20000000","0.00040000"]],"a":[["63098.01000000","5.00347000"],["63098.11000000","0.00018000"],["63098.12000000","0.08281000"],["63098.71000000","0.00000000"],["63098.82000000","0.00018000"],["63098.83000000","0.05018000"],["63098.84000000","0.00009000"],["63098.85000000","0.94740000"],["63098.86000000","0.00018000"],["63098.87000000","1.05852000"],["63098.88000000","0.00459000"],["63098.89000000","3.02709000"],["63099.24000000","0.02000000"],["63099.40000000","0.00000000"],["63099.41000000","0.00026000"],["63099.57000000","0.00000000"],["63099.58000000","0.00000000"],["63100.00000000","0.00000000"],["63100.20000000","0.00000000"],["63100.46000000","0.00400000"],["63100.52000000","0.00000000"],["63100.53000000","0.05042000"],["63100.54000000","0.00344000"],["63100.85000000","0.00155000"],["63101.28000000","0.06901000"],["63101.29000000","0.00018000"],["63101.97000000","0.00008000"],["63101.98000000","0.87021000"],["63101.99000000","0.00018000"],["63102.01000000","0.05699000"],["63103.68000000","0.39787000"],["63103.70000000","0.26095000"],["63104.43000000","0.05520000"],["63104.94000000","0.79350000"],["63104.96000000","0.00000000"],["63104.97000000","0.69104000"],["63105.16000000","2.76712000"],["63105.17000000","1.57084000"],["63105.66000000","0.00000000"],["63105.67000000","0.00008000"],["63105.87000000","0.00976000"],["63105.94000000","0.00000000"],["63105.95000000","0.00000000"],["63105.98000000","0.33718000"],["63106.25000000","0.00018000"],["63106.85000000","0.37605000"],["63107.33000000","0.00000000"],["63107.57000000","0.00000000"],["63107.59000000","0.04140000"],["63107.98000000","0.00000000"],["63107.99000000","0.96127000"],["63108.01000000","0.94026000"],["63109.45000000","0.00317000"],["63109.92000000","0.00000000"],["63110.00000000","0.02300000"],["63110.39000000","0.00000000"],["63110.74000000","0.02760000"],["63111.28000000","0.00018000"],["63111.96000000","0.46056000"],["63113.36000000","0.00000000"],["63114.45000000","0.00000000"],["63116.64000000","0.00018000"],["63116.97000000","0.00000000"],["63118.54000000","0.46074000"],["63118.60000000","0.00317000"],["63119.67000000","0.00000000"],["63120.59000000","0.00018000"],["63122.09000000","0.00000000"],["63122.93000000","0.00000000"],["63123.20000000","0.00000000"],["63124.16000000","0.00000000"],["63125.74000000","0.00000000"],["63126.29000000","0.00000000"],["63128.85000000","0.00000000"],["63130.00000000","0.03600000"],["63131.98000000","0.00000000"],["63133.00000000","0.00000000"],["63134.85000000","0.00018000"],["63137.00000000","0.00000000"],["63140.32000000","0.00000000"],["63144.83000000","0.01144000"],["63146.53000000","0.09201000"],["63147.53000000","0.00000000"],["63150.15000000","0.00112000"],["63151.86000000","0.01074000"],["63151.98000000","0.95193000"],["63159.26000000","0.00000000"],["63162.23000000","0.00000000"],["63162.52000000","0.00000000"],["63166.95000000","0.38623000"],["63168.23000000","0.02092000"],["63171.55000000","0.00000000"],["63193.01000000","0.04917000"],["63275.68000000","0.00000000"],["63277.68000000","0.00000000"],["63279.86000000","0.00000000"],["63724.41000000","0.00000000"]]}
{"e":"depthUpdate","E":1781816958214,"s":"BTCUSDT","U":96005698956,"u":96005699115,"b":[["63098.00000000","0.52039000"],["63097.99000000","0.00072000"],["63096.55000000","0.00018000"],["63096.54000000","0.07613000"],["63095.36000000","0.00000000"],["63095.35000000","0.00000000"],["63095.02000000","0.00000000"],["63094.00000000","0.02408000"],["63093.85000000","0.00000000"],["63093.84000000","0.00026000"],["63093.76000000","0.00000000"],["63092.56000000","0.00000000"],["63092.49000000","0.00000000"],["63092.37000000","0.00009000"],["63092.36000000","0.15321000"],["63092.15000000","0.00000000"],["63092.00000000","0.02318000"],["63074.53000000","1.19859000"],["63065.70000000","0.00400000"],["63003.71000000","0.08679000"],["56788.20000000","0.00080000"],["50478.40000000","0.00000000"]],"a":[["63098.01000000","5.66302000"],["63098.12000000","0.08307000"],["63098.80000000","0.00018000"],["63098.81000000","0.97950000"],["63098.82000000","1.51890000"],["63098.83000000","0.00026000"],["63098.84000000","0.00000000"],["63098.85000000","0.00018000"],["63098.86000000","0.00000000"],["63098.87000000","0.00036000"],["63098.88000000","0.00441000"],["63098.89000000","2.67319000"],["63099.24000000","0.02018000"],["63099.41000000","0.00008000"],["63100.53000000","0.05042000"],["63100.54000000","0.00326000"],["63101.29000000","0.00000000"],["63101.97000000","0.00017000"],["63102.59000000","0.00000000"],["63103.68000000","0.11590000"],["63103.70000000","0.26103000"],["63103.85000000","0.00000000"],["63104.32000000","0.24750000"],["63104.42000000","0.00000000"],["63104.94000000","0.00018000"],["63105.11000000","0.00000000"],["63106.01000000","0.11636000"],["63106.27000000","0.00032000"],["63106.50000000","0.26806000"],["63106.84000000","0.79331000"],["63123.77000000","1.19765000"],["63135.91000000","0.00791000"],["63142.91000000","0.00000000"],["63151.98000000","0.00000000"],["63152.99000000","0.95193000"],["63329.71000000","0.12117000"]]}
{"e":"depthUpdate","E":1781816958314,"s":"BTCUSDT","U":96005699116,"u":96005699694,"b":[["63098.00000000","0.00000000"],["63097.99000000","0.00000000"],["63097.67000000","0.00000000"],["63097.36000000","0.00000000"],["63097.07000000","0.00000000"],["63096.69000000","0.00000000"],["63096.68000000","0.00000000"],["63096.67000000","0.00000000"],["63096.55000000","0.00000000"],["63096.54000000","0.00000000"],["63096.01000000","0.00000000"],["63096.00000000","0.16220000"],["63095.99000000","0.00080000"],["63095.79000000","0.00009000"],["63094.12000000","0.00000000"],["63094.00000000","0.02408000"],["63093.84000000","0.00008000"],["63093.08000000","0.00000000"],["63092.75000000","0.01585000"],["63092.56000000","0.00018000"],["63092.55000000","0.16000000"],["63092.54000000","0.00189000"],["63092.37000000","0.00000000"],["63092.36000000","0.00044000"],["63092.35000000","0.14018000"],["63092.15000000","0.00018000"],["63092.12000000","0.00000000"],["63092.00000000","0.02318000"],["63091.80000000","0.00009000"],["63091.79000000","0.06000000"],["63091.49000000","0.01585000"],["63091.47000000","0.00018000"],["63091.16000000","0.00000000"],["63091.05000000","0.00000000"],["63090.23000000","0.01586000"],["63089.55000000","0.02718000"],["63088.88000000","0.00000000"],["63088.77000000","0.02000000"],["63088.36000000","0.00000000"],["63086.79000000","0.00000000"],["63085.84000000","0.00069000"],["63084.41000000","0.00000000"],["63082.49000000","1.14321000"],["63082.48000000","0.00000000"],["63082.46000000","0.00000000"],["63082.45000000","1.19553000"],["63080.55000000","0.00000000"],["63080.19000000","0.00000000"],["63080.06000000","0.00000000"],["63077.75000000","0.00158000"],["63076.28000000","0.48282000"],["63066.00000000","0.02300000"],["63065.91000000","0.15718000"],["63065.00000000","0.00000000"],["63064.56000000","0.00008000"],["63064.00000000","0.03300000"],["63061.59000000","0.57153000"],["63052.03000000","0.15721000"],["63049.41000000","0.57164000"],["63046.00000000","0.02300000"],["63036.30000000","0.00000000"],["63036.28000000","0.00000000"],["63035.82000000","0.00000000"],["63035.40000000","0.00000000"],["63035.23000000","0.02067000"],["63022.35000000","0.00000000"],["63022.15000000","0.00015000"],["63021.75000000","3.16967000"],["63018.03000000","0.00000000"],["63017.61000000","0.46056000"],["63017.43000000","0.01003000"],["62929.77000000","0.00008000"],["62926.62000000","0.00008000"],["56788.20000000","0.00000000"],["56787.02000000","0.00000000"]],"a":[["63096.01000000","5.49545000"],["63096.02000000","0.00034000"],["63096.03000000","0.00016000"],["63096.55000000","0.00000000"],["63096.56000000","0.00000000"],["63096.68000000","2.02029000"],["63096.69000000","0.11086000"],["63096.70000000","0.00237000"],["63096.71000000","0.00000000"],["63097.08000000","0.00000000"],["63097.30000000","0.00400000"],["63097.36000000","0.00008000"],["63097.37000000","0.00000000"],["63097.59000000","0.00010000"],["63097.68000000","0.00000000"],["63097.98000000","1.86022000"],["63097.99000000","0.00018000"],["63098.00000000","0.05008000"],["63098.01000000","0.27819000"],["63098.02000000","0.00000000"],["63098.03000000","0.00000000"],["63098.11000000","0.00000000"],["63098.12000000","0.08307000"],["63098.28000000","0.03894000"],["63098.79000000","0.00018000"],["63098.80000000","1.05834000"],["63098.81000000","0.00026000"],["63098.82000000","0.46074000"],["63098.83000000","0.00000000"],["63098.85000000","0.00000000"],["63098.87000000","0.00000000"],["63098.88000000","0.00436000"],["63098.89000000","2.59706000"],["63099.54000000","0.00032000"],["63100.32000000","0.01585000"],["63101.28000000","0.06901000"],["63101.58000000","0.01585000"],["63101.97000000","0.00008000"],["63101.98000000","0.90381000"],["63102.00000000","2.56735000"],["63102.85000000","0.01585000"],["63103.23000000","0.00012000"],["63103.69000000","0.02886000"],["63104.31000000","0.00000000"],["63105.67000000","0.00000000"],["63105.84000000","0.16003000"],["63105.98000000","0.33710000"],["63106.56000000","0.00009000"],["63107.13000000","0.00892000"],["63107.42000000","0.16002000"],["63107.72000000","0.00008000"],["63108.82000000","0.57110000"],["63109.91000000","0.00000000"],["63110.29000000","0.00880000"],["63111.48000000","0.00000000"],["63117.35000000","0.00317000"],["63117.63000000","0.00018000"],["63118.54000000","0.46056000"],["63118.60000000","0.00000000"],["63122.58000000","0.00000000"],["63129.00000000","0.01000000"],["63130.00000000","0.02600000"],["63134.85000000","0.00000000"],["63152.99000000","0.00000000"],["63153.02000000","0.95193000"],["63213.70000000","0.00000000"],["63257.16000000","0.00000000"],["63271.52000000","0.00008000"],["63272.53000000","0.00000000"],["63411.92000000","0.00000000"]]}
{"e":"depthUpdate","E":1781816958414,"s":"BTCUSDT","U":96005699695,"u":96005699889,"b":[["63096.00000000","0.16199000"],["63095.99000000","0.00080000"],["63094.00000000","0.02408000"],["63092.75000000","0.00018000"],["63092.57000000","0.00018000"],["63092.56000000","0.12982000"],["63092.55000000","0.16018000"],["63092.54000000","0.00000000"],["63092.36000000","0.00026000"],["63092.29000000","0.00032000"],["63091.80000000","0.00000000"],["63091.79000000","0.00018000"],["63091.49000000","0.00000000"],["63091.47000000","0.00000000"],["63090.23000000","0.00000000"],["63088.98000000","0.00000000"],["63088.95000000","0.21424000"],["63088.63000000","0.00000000"],["63085.48000000","0.00000000"],["63082.51000000","0.78634000"],["63082.50000000","2.56712000"],["63082.49000000","0.00000000"],["63082.45000000","0.00564000"],["63082.32000000","0.00000000"],["63081.31000000","0.00190000"],["63080.53000000","0.44804000"],["63080.01000000","1.18989000"],["63079.17000000","0.00000000"],["63074.54000000","0.36517000"],["63067.90000000","0.00000000"],["63056.64000000","0.00403000"],["63054.02000000","0.00000000"],["63053.95000000","0.00827000"],["63050.99000000","0.00000000"],["63044.40000000","0.00395000"],["63040.78000000","0.00431000"],["63039.43000000","0.00000000"],["63036.93000000","0.00000000"],["63032.01000000","0.01073000"],["63006.01000000","0.00000000"],["63001.23000000","0.00000000"],["62994.01000000","0.00158000"],["62993.11000000","0.00000000"],["62987.05000000","0.00000000"],["62981.25000000","0.00158000"],["56786.40000000","0.00040000"]],"a":[["63096.01000000","5.50780000"],["63096.64000000","0.00009000"],["63096.65000000","0.17349000"],["63096.66000000","0.00000000"],["63096.67000000","0.00044000"],["63096.68000000","0.57420000"],["63096.69000000","0.10690000"],["63097.30000000","0.00552000"],["63097.97000000","0.00018000"],["63097.98000000","0.96894000"],["63097.99000000","0.00000000"],["63098.00000000","0.05035000"],["63098.12000000","0.00026000"],["63098.28000000","0.00000000"],["63098.79000000","0.00018000"],["63098.80000000","0.00000000"],["63098.81000000","0.00008000"],["63098.82000000","0.46056000"],["63098.88000000","0.00418000"],["63098.89000000","2.59688000"],["63099.24000000","0.02000000"],["63100.32000000","0.00000000"],["63100.53000000","0.05016000"],["63101.28000000","0.00000000"],["63101.58000000","0.00000000"],["63101.96000000","2.17909000"],["63101.97000000","4.22801000"],["63101.98000000","0.00000000"],["63102.85000000","0.00000000"],["63103.70000000","0.26079000"],["63103.89000000","0.00008000"],["63104.43000000","0.00000000"],["63104.97000000","0.69088000"],["63105.17000000","1.57076000"],["63106.83000000","0.00018000"],["63107.59000000","0.00000000"],["63110.74000000","0.00000000"],["63111.28000000","0.00000000"],["63111.96000000","0.46074000"],["63116.64000000","0.00000000"],["63121.31000000","0.00623000"],["63124.88000000","0.56710000"],["63128.00000000","0.03300000"],["63128.75000000","0.00000000"],["63129.00000000","0.00000000"],["63130.88000000","0.00000000"],["63143.82000000","1.07495000"],["63150.82000000","0.00396000"],["63163.10000000","0.00000000"],["63163.51000000","0.00379000"],["63175.67000000","0.00000000"],["63215.31000000","0.00158000"],["63226.68000000","0.00152000"],["63226.69000000","0.00000000"],["63239.26000000","0.00000000"],["63269.42000000","0.00000000"],["63271.52000000","0.00000000"],["63278.62000000","0.02482000"]]}
{"e":"depthUpdate","E":1781816958514,"s":"BTCUSDT","U":96005699890,"u":96005699970,"b":[["63096.00000000","0.16374000"],["63095.99000000","0.00089000"],["63095.19000000","0.00018000"],["63095.18000000","0.07613000"],["63094.00000000","0.02408000"],["63092.75000000","0.00000000"],["63092.56000000","0.13000000"],["63092.33000000","0.00000000"],["63092.15000000","0.00000000"],["63092.14000000","0.10561000"],["63092.00000000","0.02318000"],["63091.79000000","0.00000000"],["63091.19000000","0.00870000"],["63090.62000000","0.00000000"],["63089.79000000","0.05983000"],["63086.63000000","0.04986000"],["63083.48000000","0.03989000"],["63083.44000000","0.00048000"],["63080.32000000","0.02991000"],["63077.17000000","0.01994000"],["63076.01000000","0.00000000"],["63073.78000000","0.38870000"],["63058.66000000","0.57155000"],["63039.46000000","0.00000000"],["63037.56000000","0.04650000"],["63036.15000000","0.00392000"],["63022.15000000","0.00000000"],["63020.30000000","0.00015000"],["62974.01000000","0.00158000"],["56786.40000000","0.00080000"],["50476.80000000","0.00039000"]],"a":[["63096.01000000","5.45193000"],["63096.11000000","0.00009000"],["63096.12000000","0.08281000"],["63096.65000000","0.17367000"],["63096.69000000","0.10690000"],["63098.00000000","0.05026000"],["63098.01000000","0.01051000"],["63098.12000000","0.00008000"],["63098.82000000","0.46064000"],["63099.28000000","0.06901000"],["63102.01000000","0.05707000"],["63102.43000000","0.05520000"],["63105.59000000","0.04140000"],["63105.64000000","0.13954000"],["63108.74000000","0.02760000"],["63108.82000000","0.00000000"],["63118.12000000","0.00000000"],["63120.64000000","0.00000000"],["63124.88000000","1.13805000"],["63278.62000000","0.00000000"],["63675.97000000","0.00000000"]]}
{"e":"depthUpdate","E":1781816958614,"s":"BTCUSDT","U":96005699971,"u":96005700057,"b":[["63096.00000000","0.96560000"],["63095.16000000","0.00000000"],["63093.90000000","0.00009000"],["63091.19000000","0.00852000"],["63089.50000000","0.01586000"],["63088.24000000","0.01586000"],["63086.98000000","0.01586000"],["62954.41000000","0.09530000"],["62946.37000000","0.00008000"],["62926.62000000","0.00000000"],["62776.10000000","0.00000000"],["62677.17000000","0.01906000"],["56797.20000000","0.00000000"],["56786.40000000","0.00109000"],["50476.80000000","0.00000000"]],"a":[["63096.01000000","6.13437000"],["63096.11000000","0.00018000"],["63096.12000000","0.08299000"],["63096.64000000","0.00018000"],["63096.68000000","0.52402000"],["63096.69000000","0.00050000"],["63097.07000000","0.01585000"],["63097.30000000","0.00570000"],["63098.01000000","0.01056000"],["63098.33000000","0.01585000"],["63099.60000000","0.01585000"],["63103.70000000","0.26063000"],["63108.00000000","2.56822000"],["63255.23000000","0.09485000"]]}
{"e":"depthUpdate","E":1781816958714,"s":"BTCUSDT","U":96005700058,"u":96005700088,"b":[["63096.00000000","1.21326000"],["63089.69000000","0.00300000"],["63083.38000000","0.00300000"],["56786.40000000","0.00149000"]],"a":[["63096.01000000","6.13445000"],["63096.10000000","0.00018000"],["63096.11000000","0.22985000"],["63096.64000000","0.00000000"],["63096.65000000","0.00018000"],["63096.68000000","0.52402000"],["63096.69000000","0.00032000"],["63097.07000000","0.01603000"],["63098.01000000","0.01056000"],["63102.32000000","0.00300000"],["63108.64000000","0.00300000"],["63116.63000000","0.00000000"],["63119.97000000","0.00000000"],["63122.62000000","0.00000000"]]}
{"e":"depthUpdate","E":1781816958815,"s":"BTCUSDT","U":96005700089,"u":96005700142,"b":[["63095.19000000","0.00036000"],["63094.61000000","0.00000000"],["63092.57000000","0.00036000"],["63092.56000000","0.13018000"],["63092.48000000","0.00000000"],["63092.14000000","0.10569000"],["63092.01000000","0.00000000"],["63090.72000000","0.00000000"],["63090.01000000","0.00018000"],["63089.80000000","0.00018000"],["63089.74000000","0.00000000"],["63088.65000000","0.00018000"],["63088.02000000","0.00000000"],["63087.71000000","0.00018000"],["63086.68000000","0.00018000"],["63086.52000000","0.00000000"],["63085.92000000","0.00000000"],["63085.82000000","0.00018000"],["63084.01000000","0.00018000"],["63083.38000000","0.01886000"],["63082.51000000","0.78652000"],["63080.54000000","0.00018000"],["63079.95000000","0.13280000"],["63078.62000000","1.78519000"],["63076.94000000","0.00018000"],["63076.45000000","0.46074000"],["63074.54000000","0.36535000"],["63069.86000000","1.85176000"],["63066.81000000","0.00018000"],["63061.69000000","2.22112000"],["63058.65000000","1.06256000"],["63039.70000000","2.32633000"],["63021.76000000","1.01640000"],["56786.40000000","0.00189000"],["56786.00000000","0.01049000"]],"a":[["63096.01000000","6.13437000"],["63096.11000000","0.23003000"],["63096.12000000","0.08299000"],["63096.65000000","0.00000000"],["63097.30000000","0.00418000"],["63136.73000000","0.00000000"],["63164.25000000","0.91282000"],["63187.74000000","0.08995000"]]}
{"e":"depthUpdate","E":1781816958914,"s":"BTCUSDT","U":96005700143,"u":96005700162,"b":[["63096.00000000","0.33647000"],["63095.79000000","0.00000000"],["63095.16000000","0.00009000"],["63088.51000000","0.00000000"],["63076.48000000","0.10000000"],["56786.40000000","0.00229000"]],"a":[["63096.01000000","6.13454000"],["63097.07000000","0.01603000"],["63097.30000000","0.00400000"],["63098.33000000","0.01603000"],["63102.16000000","0.00008000"],["63104.68000000","0.00008000"],["63126.39000000","0.00000000"]]}
{"e":"depthUpdate","E":1781816959014,"s":"BTCUSDT","U":96005700163,"u":96005700175,"b":[["63096.00000000","0.14248000"],["63089.50000000","0.00000000"],["63085.71000000","0.01586000"],["63079.36000000","0.00008000"],["63004.29000000","2.89288000"],["62930.01000000","0.00000000"],["62840.98000000","0.00962000"],["56786.40000000","0.00269000"],["50476.80000000","0.00039000"]],"a":[["63099.60000000","0.00000000"],["63110.28000000","0.38871000"],["63116.61000000","0.00000000"],["63117.22000000","0.00008000"]]}
{"e":"depthUpdate","E":1781816959114,"s":"BTCUSDT","U":96005700176,"u":96005700236,"b":[["63096.00000000","1.35814000"],["63092.56000000","0.13026000"],["63092.14000000","0.10561000"],["63089.79000000","0.00000000"],["63088.24000000","0.00000000"],["63086.98000000","0.00000000"],["63086.63000000","0.00000000"],["63086.22000000","0.01586000"],["63085.71000000","0.00000000"],["63083.48000000","0.00000000"],["63082.52000000","3.16977000"],["63080.32000000","0.00000000"],["63077.17000000","0.00000000"],["63028.80000000","0.00000000"],["63021.75000000","0.00000000"],["63020.30000000","0.00000000"],["63020.05000000","0.00015000"],["63016.81000000","0.00030000"],["56786.40000000","0.00309000"]],"a":[["63096.11000000","0.15286000"],["63096.12000000","0.00018000"],["63098.33000000","0.00018000"],["63098.81000000","0.00026000"],["63098.82000000","0.46056000"],["63098.89000000","2.59623000"],["63099.28000000","0.00000000"],["63101.97000000","1.05834000"],["63102.01000000","0.05699000"],["63102.43000000","0.00000000"],["63103.86000000","0.02000000"],["63103.89000000","0.02608000"],["63104.49000000","0.04800000"],["63104.52000000","0.04400000"],["63105.59000000","0.00000000"],["63106.38000000","0.02600000"],["63107.02000000","0.04400000"],["63107.36000000","0.02600000"],["63107.65000000","0.05400000"],["63107.67000000","0.03200000"],["63107.68000000","0.03400000"],["63108.17000000","0.00316000"],["63108.74000000","0.00000000"],["63109.45000000","0.00000000"],["63158.41000000","3.16977000"],["63163.11000000","0.02000000"],["63163.14000000","0.00000000"],["63165.98000000","0.00000000"],["63166.27000000","0.02600000"],["63174.55000000","0.00030000"],["63186.57000000","0.00000000"]]}
{"e":"depthUpdate","E":1781816959214,"s":"BTCUSDT","U":96005700237,"u":96005700354,"b":[["63096.00000000","1.49479000"],["63086.53000000","0.03894000"],["63082.53000000","1.72533000"],["63082.51000000","0.00018000"],["63033.60000000","0.17009000"],["63021.76000000","0.00000000"],["56786.40000000","0.00349000"],["50476.80000000","0.00000000"]],"a":[["63096.01000000","3.90873000"],["63096.10000000","0.00000000"],["63096.11000000","0.00018000"],["63096.12000000","0.00000000"],["63096.66000000","0.00018000"],["63096.67000000","0.16370000"],["63096.68000000","0.52410000"],["63097.97000000","0.00000000"],["63097.98000000","0.16590000"],["63098.00000000","0.00526000"],["63098.01000000","0.00255000"],["63098.12000000","0.00000000"],["63098.33000000","0.00000000"],["63098.78000000","0.00793000"],["63098.80000000","0.00018000"],["63098.81000000","0.46056000"],["63098.82000000","0.00018000"],["63098.88000000","0.00418000"],["63098.89000000","0.00061000"],["63099.54000000","0.00000000"],["63100.00000000","0.01300000"],["63100.45000000","0.00793000"],["63100.53000000","0.05016000"],["63100.54000000","0.00127000"],["63101.95000000","0.00018000"],["63101.96000000","0.85758000"],["63101.97000000","0.00000000"],["63102.00000000","2.58035000"],["63102.01000000","0.00371000"],["63103.68000000","0.00000000"],["63103.70000000","0.20743000"],["63104.00000000","0.01300000"],["63104.94000000","1.21299000"],["63104.95000000","2.17966000"],["63105.17000000","1.41499000"],["63106.00000000","0.01300000"],["63106.26000000","0.12000000"],["63106.84000000","0.00000000"],["63107.98000000","2.15846000"],["63107.99000000","3.16995000"],["63108.00000000","2.57622000"],["63110.16000000","0.79346000"],["63110.28000000","0.00000000"],["63112.42000000","0.00000000"],["63112.54000000","0.38870000"],["63120.60000000","0.00000000"],["63129.59000000","0.57091000"],["63153.02000000","0.00000000"],["63153.58000000","0.00000000"],["63154.20000000","0.95210000"],["63162.47000000","0.00000000"],["63165.64000000","0.02000000"],["63215.47000000","4.75117000"],["63257.16000000","0.24750000"]]}
{"e":"depthUpdate","E":1781816959314,"s":"BTCUSDT","U":96005700355,"u":96005700400,"b":[["63096.00000000","1.35830000"],["63086.22000000","0.00000000"],["62954.41000000","0.00000000"],["56786.40000000","0.00369000"]],"a":[["63096.01000000","3.90865000"],["63096.11000000","0.00000000"],["63096.67000000","0.16388000"],["63096.68000000","0.52418000"],["63096.70000000","0.00404000"],["63097.15000000","0.00018000"],["63097.16000000","0.07613000"],["63098.00000000","0.00526000"],["63098.01000000","0.00237000"],["63098.78000000","0.00811000"],["63098.81000000","0.46074000"],["63098.82000000","0.00000000"],["63098.89000000","0.00043000"],["63099.24000000","0.02018000"],["63099.96000000","0.00032000"],["63101.95000000","0.00000000"],["63107.70000000","0.03894000"],["63108.00000000","2.58122000"],["63129.94000000","0.13199000"],["63154.20000000","0.00000000"],["63154.77000000","0.95210000"],["63163.21000000","0.00000000"],["63166.27000000","0.00000000"],["63255.23000000","0.00000000"]]}
{"e":"depthUpdate","E":1781816959414,"s":"BTCUSDT","U":96005700401,"u":96005700448,"b":[["63096.00000000","1.35846000"],["63095.99000000","0.00105000"],["63095.98000000","0.00016000"],["63094.53000000","0.00009000"],["63089.87000000","0.01586000"],["63088.61000000","0.01586000"],["63087.35000000","0.01586000"],["62999.47000000","0.00201000"],["56786.40000000","0.00409000"]],"a":[["63097.07000000","0.01603000"],["63097.15000000","0.00000000"],["63097.16000000","0.00018000"],["63097.97000000","0.00036000"],["63097.98000000","0.16598000"],["63098.23000000","0.07613000"],["63098.70000000","0.01585000"],["63098.79000000","0.00000000"],["63098.80000000","0.00036000"],["63098.88000000","0.00400000"],["63099.24000000","0.02000000"],["63099.97000000","0.01585000"],["63105.15000000","0.00018000"],["63106.25000000","0.00000000"],["63106.49000000","0.00018000"],["63106.83000000","0.00000000"],["63106.84000000","0.00018000"],["63107.98000000","2.15864000"],["63107.99000000","3.16977000"],["63110.15000000","0.00018000"],["63111.96000000","0.46056000"],["63120.59000000","0.00000000"],["63154.77000000","0.00000000"],["63155.39000000","0.95210000"],["63159.42000000","0.00000000"],["63163.89000000","0.00008000"],["63165.64000000","0.00000000"],["63166.29000000","0.00000000"],["77809.74000000","0.00000000"]]}
{"e":"depthUpdate","E":1781816959514,"s":"BTCUSDT","U":96005700449,"u":96005700476,"b":[["63096.00000000","1.35867000"],["63088.08000000","0.00048000"],["56786.40000000","0.00449000"],["50476.80000000","0.00039000"]],"a":[["63096.68000000","0.52410000"],["63097.07000000","0.01603000"],["63097.16000000","0.00000000"],["63098.00000000","0.00526000"],["63098.23000000","0.07631000"],["63098.70000000","0.01603000"],["63098.81000000","0.46056000"],["63112.54000000","0.00000000"],["63114.67000000","0.38869000"],["63162.48000000","0.00000000"],["63163.11000000","0.00000000"],["63165.00000000","0.00000000"],["63663.86000000","0.00010000"]]}
{"e":"depthUpdate","E":1781816959614,"s":"BTCUSDT","U":96005700477,"u":96005700520,"b":[["63096.00000000","1.29291000"],["63095.18000000","0.07621000"],["63094.43000000","0.00000000"],["63087.60000000","0.13954000"],["63077.07000000","0.00015000"],["63076.93000000","0.00008000"],["63075.49000000","0.00000000"],["63073.60000000","0.00400000"],["63064.12000000","0.00000000"],["63058.14000000","0.00015000"],["63056.56000000","1.20800000"],["63039.21000000","0.00015000"],["63037.62000000","0.00000000"],["63020.28000000","0.00015000"],["63018.69000000","0.00000000"],["63001.36000000","0.00015000"],["56786.40000000","0.00449000"],["50476.80000000","0.00000000"]],"a":[["63096.01000000","3.90865000"],["63096.70000000","0.00237000"],["63097.07000000","0.01765000"],["63114.94000000","0.00015000"],["63132.30000000","0.00000000"],["63133.87000000","0.00015000"],["63151.24000000","0.00000000"],["63152.80000000","0.00015000"],["63170.17000000","0.00000000"],["63171.73000000","0.00015000"],["63189.11000000","0.00000000"],["63190.65000000","0.00015000"],["63208.04000000","0.00000000"],["65113.36000000","0.00047000"]]}
{"e":"depthUpdate","E":1781816959714,"s":"BTCUSDT","U":96005700521,"u":96005700528,"b":[["63093.90000000","0.00000000"],["56786.40000000","0.00469000"],["50476.80000000","0.00000000"]],"a":[]}
{"e":"depthUpdate","E":1781816959814,"s":"BTCUSDT","U":96005700529,"u":96005700548,"b":[["63092.57000000","0.00018000"],["63092.36000000","0.00044000"],["63089.80000000","0.00000000"],["63088.88000000","0.00018000"],["63087.71000000","0.00000000"],["63087.61000000","0.00018000"],["63082.53000000","1.72551000"],["63082.51000000","0.00000000"],["63080.02000000","0.00018000"],["63076.94000000","0.00000000"],["56786.40000000","0.00469000"],["56786.00000000","0.01049000"]],"a":[["63096.01000000","3.98461000"],["63098.23000000","0.00018000"],["63108.61000000","0.01586000"]]}
{"e":"depthUpdate","E":1781816959914,"s":"BTCUSDT","U":96005700549,"u":96005700580,"b":[["63096.00000000","1.42627000"],["63032.12000000","0.91619000"],["63031.82000000","0.00000000"],["63008.71000000","1.78109000"],["62988.66000000","0.14559000"],["56786.40000000","0.00449000"]],"a":[["63096.01000000","3.81000000"],["63097.98000000","0.16590000"],["63098.00000000","0.00526000"],["63098.23000000","0.00000000"],["63098.81000000","0.46074000"],["63106.50000000","0.23796000"],["63120.10000000","0.00000000"],["63122.94000000","1.66655000"],["63152.42000000","1.57647000"],["63201.88000000","1.41882000"]]}
{"e":"depthUpdate","E":1781816960014,"s":"BTCUSDT","U":96005700581,"u":96005700678,"b":[["63096.00000000","2.65710000"],["63095.99000000","0.00051000"],["63095.18000000","0.09621000"],["63092.07000000","0.01593000"],["63090.99000000","0.00793000"],["63090.81000000","0.01586000"],["63088.98000000","2.56712000"],["63088.77000000","0.00000000"],["63088.61000000","0.00000000"],["63087.35000000","0.00000000"],["63085.82000000","1.19002000"],["63085.05000000","2.56712000"],["63084.75000000","0.00000000"],["63080.01000000","0.00000000"],["63079.36000000","0.00008000"],["63061.83000000","1.57170000"],["63020.72000000","0.00008000"],["62938.41000000","0.00000000"],["56786.40000000","0.00449000"],["50476.80000000","0.00039000"]],"a":[["63096.01000000","3.24999000"],["63096.67000000","0.00062000"],["63096.68000000","0.00049000"],["63096.69000000","0.00024000"],["63097.07000000","0.00180000"],["63097.67000000","0.00009000"],["63098.70000000","0.00018000"],["63098.78000000","0.00018000"],["63098.84000000","0.00000000"],["63099.24000000","0.00000000"],["63099.96000000","0.00000000"],["63100.45000000","0.00000000"],["63100.53000000","0.00016000"],["63101.95000000","0.00793000"],["63102.00000000","0.01323000"],["63102.01000000","0.00016000"],["63102.17000000","0.01585000"],["63102.75000000","0.02000000"],["63103.22000000","0.00793000"],["63104.94000000","1.05852000"],["63104.97000000","0.58448000"],["63105.18000000","0.00876000"],["63106.50000000","0.18476000"],["63106.85000000","0.32285000"],["63107.20000000","0.00016000"],["63107.35000000","0.11380000"],["63117.22000000","0.00008000"]]}
{"e":"depthUpdate","E":1781816960114,"s":"BTCUSDT","U":96005700679,"u":96005700798,"b":[["63096.00000000","3.04922000"],["63095.99000000","0.00060000"],["63095.18000000","0.09639000"],["63092.65000000","0.00553000"],["63092.56000000","0.13426000"],["63092.14000000","0.10561000"],["63092.00000000","0.02300000"],["63091.40000000","0.00000000"],["63088.99000000","0.97170000"],["63088.95000000","0.00000000"],["63088.08000000","0.00000000"],["63087.70000000","1.33672000"],["63085.84000000","0.00000000"],["63085.06000000","0.46056000"],["63084.56000000","0.00320000"],["63080.53000000","0.24264000"],["63079.73000000","0.38867000"],["63073.78000000","0.00000000"],["63070.44000000","0.00400000"],["63068.77000000","0.00000000"],["63067.28000000","0.00000000"],["63065.70000000","0.00000000"],["63044.15000000","0.57155000"],["62843.98000000","0.00000000"],["56786.40000000","0.00449000"]],"a":[["63096.01000000","3.16403000"],["63096.66000000","0.00000000"],["63096.67000000","0.00026000"],["63096.68000000","0.00008000"],["63097.07000000","0.00000000"],["63097.30000000","0.00185000"],["63097.38000000","0.00000000"],["63097.39000000","0.00000000"],["63097.40000000","0.00000000"],["63097.98000000","0.16598000"],["63098.00000000","0.00526000"],["63098.40000000","0.00018000"],["63098.41000000","0.07613000"],["63098.70000000","0.00000000"],["63098.78000000","0.00000000"],["63098.81000000","0.46074000"],["63098.91000000","0.52359000"],["63099.97000000","0.01603000"],["63100.00000000","0.01318000"],["63101.05000000","0.01585000"],["63101.95000000","0.00829000"],["63101.96000000","0.10495000"],["63102.00000000","0.01341000"],["63102.75000000","0.00000000"],["63103.69000000","0.02886000"],["63106.86000000","0.02000000"],["63107.01000000","0.00319000"],["63108.17000000","0.00000000"],["63114.67000000","0.00000000"],["63116.65000000","0.00000000"],["63117.03000000","0.39744000"],["63125.74000000","0.00400000"],["63128.15000000","0.32546000"],["63133.03000000","0.57088000"],["63134.58000000","0.00023000"],["63155.39000000","0.00000000"],["63155.68000000","0.95210000"],["63291.66000000","2.16418000"]]}
{"e":"depthUpdate","E":1781816960214,"s":"BTCUSDT","U":96005700799,"u":96005700842,"b":[["63096.00000000","3.04970000"],["63094.00000000","0.02408000"],["63090.81000000","0.00000000"],["63089.87000000","0.00000000"],["62837.41000000","0.00034000"],["56786.40000000","0.00449000"],["50476.80000000","0.00000000"]],"a":[["63097.98000000","0.30977000"],["63098.00000000","0.01126000"],["63098.41000000","0.07631000"],["63098.81000000","0.46082000"],["63098.91000000","0.52377000"],["63099.85000000","0.00032000"],["63099.97000000","0.00018000"],["63100.00000000","0.01318000"],["63101.05000000","0.01603000"],["63101.95000000","0.00811000"],["63101.96000000","0.10477000"],["63102.00000000","0.01323000"]]}
{"e":"depthUpdate","E":1781816960314,"s":"BTCUSDT","U":96005700843,"u":96005700872,"b":[["63095.91000000","0.02710000"],["63092.36000000","0.00026000"],["63089.55000000","0.00008000"],["56786.40000000","0.00469000"],["44167.20000000","0.00000000"]],"a":[["63096.01000000","3.16373000"],["63098.00000000","0.01526000"],["63098.90000000","0.00018000"],["63098.91000000","0.52377000"],["63099.97000000","0.00000000"],["63100.00000000","0.02318000"],["63101.95000000","0.00829000"],["63102.00000000","0.02323000"],["63104.00000000","0.01900000"],["63106.00000000","0.01900000"],["63108.00000000","2.58722000"]]}
{"e":"depthUpdate","E":1781816960414,"s":"BTCUSDT","U":96005700873,"u":96005700922,"b":[["63096.00000000","3.04816000"],["63095.92000000","0.00009000"],["63095.91000000","0.02728000"],["63092.14000000","0.10543000"],["63090.97000000","0.01586000"],["63089.71000000","0.01586000"],["58064.29000000","0.00018000"],["56786.40000000","0.00469000"]],"a":[["63096.01000000","3.16420000"],["63096.67000000","0.00008000"],["63096.83000000","0.00009000"],["63096.84000000","0.15708000"],["63096.85000000","0.52361000"],["63097.30000000","0.00000000"],["63097.97000000","0.00018000"],["63097.98000000","0.17618000"],["63098.90000000","0.00018000"],["63098.91000000","0.00018000"],["63101.95000000","0.00829000"],["63101.99000000","0.00000000"],["63104.00000000","0.02300000"],["63104.31000000","0.00018000"],["63104.94000000","1.05834000"],["63105.97000000","0.00018000"],["63106.00000000","0.02300000"],["63106.49000000","0.00000000"],["63107.41000000","0.00018000"],["63108.00000000","2.59122000"],["63110.16000000","0.79328000"],["63111.28000000","0.00018000"]]}
{"e":"depthUpdate","E":1781816960514,"s":"BTCUSDT","U":96005700923,"u":96005700949,"b":[["63096.00000000","3.04825000"],["63095.99000000","0.00069000"],["63083.51000000","0.16008000"],["63081.93000000","0.16009000"],["63035.23000000","0.00000000"],["56786.40000000","0.00469000"],["50476.80000000","0.00039000"]],"a":[["63096.01000000","3.16420000"],["63096.84000000","0.15726000"],["63096.85000000","0.52379000"],["63098.81000000","0.46074000"],["63098.91000000","0.00000000"],["63101.95000000","0.00811000"]]}
{"e":"depthUpdate","E":1781816960614,"s":"BTCUSDT","U":96005700950,"u":96005700963,"b":[["63095.92000000","0.00018000"],["56786.40000000","0.00449000"],["50476.80000000","0.00000000"]],"a":[["63096.83000000","0.00018000"],["63096.85000000","0.52387000"],["63097.04000000","0.00009000"],["63097.67000000","0.00000000"],["63097.92000000","0.13060000"],["63098.80000000","0.00018000"],["63099.80000000","0.01585000"],["63128.94000000","0.00000000"]]}
{"e":"depthUpdate","E":1781816960714,"s":"BTCUSDT","U":96005700964,"u":96005700990,"b":[["63008.53000000","2.89288000"],["63004.29000000","0.00000000"],["56786.40000000","0.00449000"],["50476.80000000","0.00000000"]],"a":[["63096.84000000","0.15899000"],["63096.85000000","0.52387000"],["63097.92000000","0.13078000"],["63098.81000000","0.46074000"],["63099.80000000","0.01603000"],["63100.00000000","0.02300000"],["63101.05000000","0.01585000"]]}
{"e":"depthUpdate","E":1781816960814,"s":"BTCUSDT","U":96005700991,"u":96005701014,"b":[["63094.01000000","0.00059000"],["63092.36000000","0.00008000"],["63090.98000000","0.00418000"],["63090.01000000","0.00000000"],["63088.99000000","0.97188000"],["63088.88000000","0.00000000"],["63088.65000000","0.00000000"],["63087.70000000","1.33690000"],["63087.61000000","0.00000000"],["63086.68000000","0.00000000"],["63085.83000000","0.00018000"],["63085.82000000","1.18984000"],["63085.06000000","0.46074000"],["63080.54000000","0.00000000"],["63080.02000000","0.00000000"],["63079.74000000","0.00018000"],["63076.64000000","0.00018000"],["63069.87000000","0.00018000"],["63061.69000000","2.22094000"],["56786.40000000","0.00449000"],["56786.00000000","0.01069000"]],"a":[]}
{"e":"depthUpdate","E":1781816960914,"s":"BTCUSDT","U":96005701015,"u":96005701028,"b":[["63043.20000000","0.66694000"],["63041.77000000","0.00000000"],["63017.62000000","0.22447000"],["62992.01000000","0.09758000"],["56786.40000000","0.00449000"],["56786.00000000","0.01049000"]],"a":[["63096.01000000","3.00564000"],["63138.09000000","0.80482000"],["63158.40000000","1.30058000"],["63193.99000000","0.08188000"]]}
{"e":"depthUpdate","E":1781816961014,"s":"BTCUSDT","U":96005701029,"u":96005701064,"b":[["63079.95000000","0.00000000"],["63079.36000000","0.00008000"],["63079.02000000","0.13661000"],["63035.22000000","0.02072000"],["63021.45000000","0.00008000"],["58064.29000000","0.00000000"],["56786.40000000","0.00469000"],["50476.80000000","0.00039000"]],"a":[["63096.01000000","3.00690000"],["63096.02000000","0.00097000"],["63117.22000000","0.00008000"],["63129.94000000","0.00000000"],["63133.39000000","0.13710000"],["63168.23000000","0.00000000"]]}
{"e":"depthUpdate","E":1781816961114,"s":"BTCUSDT","U":96005701065,"u":96005701077,"b":[["63035.22000000","0.00000000"],["63017.43000000","0.00000000"],["56786.40000000","0.00469000"],["33000.00000000","41.15052000"]],"a":[["63102.25000000","0.00982000"],["63102.49000000","2.56712000"],["63105.96000000","0.00315000"],["63107.01000000","0.00000000"],["63117.03000000","0.38867000"],["63165.47000000","0.02052000"]]}
{"e":"depthUpdate","E":1781816961214,"s":"BTCUSDT","U":96005701078,"u":96005701084,"b":[["62425.55000000","0.00000000"],["56786.40000000","0.00469000"],["50476.80000000","0.00000000"]],"a":[["63101.96000000","0.85756000"]]}
{"e":"depthUpdate","E":1781816961314,"s":"BTCUSDT","U":96005701085,"u":96005701090,"b":[["56786.40000000","0.00449000"]],"a":[["63096.01000000","2.70945000"],["63103.70000000","0.20000000"]]}
{"e":"depthUpdate","E":1781816961414,"s":"BTCUSDT","U":96005701091,"u":96005701242,"b":[["63096.00000000","3.09791000"],["63095.99000000","0.00042000"],["63095.18000000","0.07639000"],["63093.13000000","0.00000000"],["63092.65000000","0.00571000"],["63090.97000000","0.00000000"],["63089.71000000","0.00000000"],["63087.53000000","0.00000000"],["63085.83000000","0.46074000"],["63085.06000000","0.00018000"],["63077.68000000","0.00219000"],["63071.93000000","0.57143000"],["63049.41000000","0.00000000"],["63036.36000000","0.95210000"],["63035.17000000","0.02117000"],["63032.27000000","0.00000000"],["63029.58000000","0.00000000"],["63017.38000000","0.00964000"],["56786.40000000","0.00449000"]],"a":[["63096.01000000","0.53392000"],["63096.02000000","0.00097000"],["63096.83000000","0.00000000"],["63096.84000000","0.00036000"],["63096.85000000","0.00026000"],["63097.91000000","0.00018000"],["63097.92000000","0.00018000"],["63097.97000000","0.00000000"],["63097.98000000","0.00026000"],["63098.01000000","0.00220000"],["63098.41000000","0.00018000"],["63098.80000000","0.00036000"],["63098.81000000","0.46082000"],["63098.89000000","0.00008000"],["63098.90000000","0.00000000"],["63099.13000000","0.00018000"],["63099.14000000","0.00000000"],["63099.60000000","0.00000000"],["63099.80000000","0.00018000"],["63099.85000000","0.00000000"],["63100.00000000","0.02471000"],["63100.54000000","0.00008000"],["63101.05000000","0.00000000"],["63101.06000000","0.07613000"],["63101.95000000","1.05861000"],["63101.96000000","0.10477000"],["63102.01000000","0.00008000"],["63102.25000000","0.00000000"],["63102.48000000","0.00018000"],["63102.49000000","0.00000000"],["63103.22000000","0.00000000"],["63103.70000000","0.00000000"],["63104.31000000","0.00000000"],["63104.48000000","0.01585000"],["63104.67000000","0.00793000"],["63104.93000000","2.56712000"],["63104.94000000","0.00000000"],["63104.95000000","0.84959000"],["63104.97000000","0.56013000"],["63105.14000000","0.00793000"],["63105.16000000","0.20000000"],["63105.17000000","0.78519000"],["63105.98000000","0.20000000"],["63106.01000000","0.00000000"],["63106.86000000","0.00000000"],["63107.35000000","0.00000000"],["63107.41000000","0.00000000"],["63107.96000000","2.46871000"],["63107.97000000","3.16995000"],["63107.98000000","0.00018000"],["63107.99000000","0.00000000"],["63108.00000000","0.02410000"],["63108.60000000","0.00000000"],["63108.61000000","0.00000000"],["63108.66000000","2.56712000"],["63109.98000000","0.00000000"],["63110.15000000","0.09376000"],["63110.16000000","0.00000000"],["63110.56000000","0.02000000"],["63111.28000000","0.00000000"],["63111.46000000","0.00000000"],["63111.65000000","1.13712000"],["63111.66000000","2.56712000"],["63111.93000000","0.00000000"],["63111.94000000","0.00018000"],["63111.95000000","0.00000000"],["63111.96000000","0.46074000"],["63111.97000000","0.00000000"],["63113.36000000","0.79323000"],["63113.99000000","0.96588000"],["63114.29000000","3.16977000"],["63118.54000000","0.46074000"],["63120.40000000","0.00000000"],["63121.07000000","0.00000000"],["63122.05000000","0.00000000"],["63126.30000000","2.49241000"],["63134.85000000","0.57086000"],["63155.68000000","0.00000000"],["63158.77000000","0.95210000"],["63165.99000000","0.00000000"]]}
{"e":"depthUpdate","E":1781816961514,"s":"BTCUSDT","U":96005701243,"u":96005701630,"b":[["63096.00000000","4.01424000"],["63095.99000000","0.00042000"],["63095.72000000","0.00400000"],["63095.36000000","0.01585000"],["63095.20000000","0.00018000"],["63095.19000000","0.21549000"],["63095.18000000","0.07647000"],["63094.14000000","0.00400000"],["63094.10000000","0.01585000"],["63093.98000000","0.00154000"],["63092.57000000","0.00000000"],["63092.56000000","0.00444000"],["63092.55000000","0.00018000"],["63092.38000000","0.03894000"],["63092.35000000","0.00018000"],["63092.15000000","0.46056000"],["63092.07000000","0.00008000"],["63091.16000000","0.00010000"],["63090.99000000","0.00000000"],["63090.50000000","0.04000000"],["63089.07000000","0.00000000"],["63087.72000000","2.42259000"],["63087.71000000","3.16977000"],["63087.70000000","0.00018000"],["63086.01000000","0.38863000"],["63085.45000000","0.00000000"],["63084.56000000","0.00000000"],["63083.44000000","0.00000000"],["63083.38000000","0.00300000"],["63080.53000000","0.09964000"],["63079.73000000","0.00000000"],["63075.91000000","0.57140000"],["63070.44000000","0.00000000"],["63068.86000000","0.00000000"],["63068.26000000","1.57154000"],["63058.66000000","0.00000000"],["63043.51000000","0.95193000"],["63043.20000000","0.22754000"],["63043.19000000","0.00000000"],["63036.36000000","0.00000000"],["63030.27000000","0.00000000"],["56786.40000000","0.00449000"],["50476.80000000","0.00039000"]],"a":[["63096.01000000","0.18090000"],["63096.02000000","0.00079000"],["63096.69000000","0.00016000"],["63096.84000000","0.00018000"],["63096.85000000","0.00000000"],["63097.03000000","0.00029000"],["63097.59000000","0.00000000"],["63097.91000000","0.00000000"],["63097.92000000","0.00000000"],["63097.98000000","0.00000000"],["63098.00000000","0.01526000"],["63098.40000000","0.00000000"],["63098.41000000","0.00000000"],["63098.80000000","0.00018000"],["63098.81000000","0.00026000"],["63098.88000000","0.00000000"],["63099.13000000","0.00000000"],["63099.80000000","0.00000000"],["63099.99000000","0.00018000"],["63100.00000000","0.02318000"],["63100.46000000","0.00000000"],["63100.85000000","0.00000000"],["63101.05000000","0.00000000"],["63101.06000000","0.00018000"],["63101.93000000","0.00000000"],["63101.94000000","0.00000000"],["63101.95000000","0.00036000"],["63101.96000000","0.00018000"],["63101.99000000","0.00018000"],["63102.00000000","0.02318000"],["63102.04000000","0.00000000"],["63102.17000000","0.00000000"],["63102.57000000","0.00000000"],["63103.56000000","0.00048000"],["63103.57000000","0.00000000"],["63103.62000000","0.00000000"],["63103.68000000","0.00018000"],["63103.74000000","0.00000000"],["63103.85000000","0.00018000"],["63103.88000000","0.00009000"],["63104.31000000","0.00000000"],["63104.32000000","0.00000000"],["63104.61000000","0.00048000"],["63104.67000000","0.00000000"],["63104.76000000","0.00190000"],["63104.91000000","0.58031000"],["63104.92000000","0.00000000"],["63104.93000000","0.00000000"],["63104.95000000","0.00000000"],["63104.97000000","0.36013000"],["63105.14000000","0.00000000"],["63105.17000000","0.32463000"],["63105.18000000","0.00000000"],["63105.46000000","0.01585000"],["63105.62000000","0.00000000"],["63105.64000000","0.00000000"],["63105.87000000","0.00000000"],["63106.26000000","0.00000000"],["63106.50000000","0.13174000"],["63106.72000000","0.01585000"],["63106.96000000","0.00000000"],["63107.12000000","0.00793000"],["63107.13000000","0.00000000"],["63107.70000000","0.00000000"],["63107.94000000","1.43638000"],["63107.95000000","3.62546000"],["63107.96000000","0.00000000"],["63107.97000000","0.00018000"],["63108.66000000","0.00000000"],["63109.01000000","0.00150000"],["63109.56000000","0.00793000"],["63110.15000000","0.00018000"],["63111.63000000","1.18190000"],["63111.64000000","3.02768000"],["63111.65000000","0.00000000"],["63111.66000000","0.00000000"],["63111.96000000","0.00018000"],["63112.16000000","0.15000000"],["63112.54000000","0.00000000"],["63113.36000000","0.00000000"],["63113.99000000","1.68039000"],["63114.28000000","5.73689000"],["63114.29000000","0.00000000"],["63114.83000000","0.22996000"],["63117.02000000","0.79322000"],["63117.03000000","0.00000000"],["63117.62000000","2.08046000"],["63117.63000000","2.56730000"],["63117.64000000","0.00000000"],["63118.10000000","3.16977000"],["63118.20000000","0.00000000"],["63118.55000000","0.00000000"],["63120.31000000","0.00000000"],["63121.07000000","2.56712000"],["63121.08000000","0.00000000"],["63121.31000000","0.00000000"],["63122.58000000","0.00400000"],["63123.45000000","0.38863000"],["63123.52000000","0.00000000"],["63124.16000000","0.00400000"],["63126.91000000","0.00000000"],["63128.90000000","0.00400000"],["63131.25000000","0.00000000"],["63132.06000000","0.00400000"],["63140.50000000","0.00023000"],["63143.63000000","0.00385000"],["63155.42000000","0.00000000"],["63158.77000000","0.00000000"],["63159.03000000","0.00000000"],["63159.82000000","0.00000000"],["63160.83000000","0.00000000"],["63165.47000000","0.00000000"],["63165.94000000","0.95193000"],["63165.99000000","3.16977000"],["63167.19000000","0.00000000"],["63167.56000000","0.00000000"],["63171.45000000","0.00000000"],["63206.67000000","0.00154000"],["63219.05000000","0.00000000"],["63222.17000000","4.75066000"],["63263.47000000","0.24750000"],["63307.86000000","0.00173000"]]}
{"e":"depthUpdate","E":1781816961614,"s":"BTCUSDT","U":96005701631,"u":96005703128,"b":[["63105.99000000","6.58357000"],["63105.98000000","0.00034000"],["63105.97000000","0.00016000"],["63105.83000000","0.00000000"],["63105.16000000","0.00000000"],["63105.15000000","0.00000000"],["63104.96000000","0.00000000"],["63104.90000000","0.00000000"],["63104.52000000","0.00018000"],["63104.51000000","0.20018000"],["63104.48000000","0.00000000"],["63104.47000000","0.00000000"],["63104.01000000","0.00000000"],["63103.99000000","0.00000000"],["63103.92000000","0.00008000"],["63103.91000000","0.00000000"],["63103.88000000","0.00000000"],["63103.87000000","0.00000000"],["63103.86000000","0.05018000"],["63103.85000000","0.72125000"],["63103.84000000","0.00000000"],["63103.83000000","0.00000000"],["63103.69000000","0.00018000"],["63103.68000000","0.00008000"],["63103.62000000","0.00400000"],["63103.22000000","0.00000000"],["63102.96000000","0.00000000"],["63102.95000000","0.06008000"],["63102.47000000","0.00000000"],["63102.31000000","0.00000000"],["63102.15000000","0.00000000"],["63102.04000000","0.00400000"],["63102.01000000","0.00000000"],["63102.00000000","0.05018000"],["63101.99000000","1.93888000"],["63101.98000000","0.00000000"],["63101.97000000","0.00000000"],["63101.94000000","0.00000000"],["63101.05000000","0.00000000"],["63100.64000000","0.00008000"],["63100.63000000","0.00000000"],["63100.54000000","0.00000000"],["63100.53000000","0.20034000"],["63100.52000000","0.00000000"],["63100.46000000","0.00400000"],["63100.00000000","0.00000000"],["63099.99000000","2.92608000"],["63099.98000000","0.00000000"],["63099.74000000","0.04000000"],["63099.40000000","0.00000000"],["63099.17000000","0.00000000"],["63099.16000000","0.00000000"],["63099.03000000","0.00000000"],["63098.88000000","0.00400000"],["63098.80000000","0.00000000"],["63098.74000000","0.00032000"],["63098.13000000","0.00862000"],["63098.00000000","0.00026000"],["63097.99000000","0.00000000"],["63097.62000000","0.00956000"],["63097.36000000","0.00008000"],["63097.30000000","0.00400000"],["63097.26000000","0.00000000"],["63097.12000000","0.00008000"],["63096.83000000","0.00026000"],["63096.69000000","0.00000000"],["63096.68000000","0.00000000"],["63096.67000000","0.00000000"],["63096.66000000","0.00000000"],["63096.11000000","0.00000000"],["63096.02000000","0.00552000"],["63096.01000000","0.24012000"],["63096.00000000","0.75401000"],["63095.99000000","0.00008000"],["63095.98000000","0.00000000"],["63095.92000000","0.00000000"],["63095.91000000","0.02710000"],["63095.68000000","0.00191000"],["63095.36000000","0.00861000"],["63095.20000000","2.56712000"],["63095.19000000","0.00018000"],["63095.18000000","0.00000000"],["63094.86000000","0.00885000"],["63094.48000000","0.00008000"],["63094.21000000","0.00971000"],["63094.12000000","0.00000000"],["63094.11000000","0.00000000"],["63094.10000000","0.00000000"],["63094.01000000","0.00041000"],["63094.00000000","0.02390000"],["63093.84000000","0.00000000"],["63093.58000000","0.00276000"],["63092.95000000","0.00884000"],["63092.65000000","0.00553000"],["63092.56000000","0.00418000"],["63092.55000000","0.00000000"],["63092.36000000","0.00000000"],["63092.35000000","0.00000000"],["63092.32000000","0.00012000"],["63092.17000000","0.89108000"],["63092.16000000","2.56712000"],["63091.77000000","0.00000000"],["63090.67000000","0.16007000"],["63090.00000000","0.02309000"],["63089.09000000","0.16007000"],["63086.75000000","0.13581000"],["63085.82000000","0.00000000"],["63084.50000000","0.57140000"],["63084.44000000","1.67457000"],["63083.99000000","0.60500000"],["63083.51000000","0.00000000"],["63082.95000000","0.00000000"],["63081.93000000","0.00000000"],["63081.31000000","0.00000000"],["63080.48000000","0.57136000"],["63079.02000000","0.00000000"],["63078.34000000","0.00264000"],["63076.76000000","0.00000000"],["63076.48000000","0.00000000"],["63076.28000000","0.00000000"],["63075.27000000","0.36507000"],["63075.26000000","1.57137000"],["63075.18000000","0.00000000"],["63074.54000000","0.00018000"],["63074.53000000","0.00000000"],["63074.40000000","0.00000000"],["63073.60000000","0.00000000"],["63073.13000000","0.15716000"],["63072.02000000","0.00000000"],["63071.12000000","0.00000000"],["63068.00000000","0.03300000"],["63067.84000000","0.02000000"],["63067.82000000","0.00000000"],["63067.03000000","0.00395000"],["63065.91000000","0.00000000"],["63064.78000000","0.31126000"],["63064.56000000","0.00000000"],["63064.34000000","0.00000000"],["63064.00000000","0.02300000"],["63062.93000000","0.00000000"],["63062.80000000","0.00000000"],["63061.59000000","0.00000000"],["63061.29000000","0.57147000"],["63060.12000000","0.00000000"],["63057.76000000","0.36948000"],["63056.64000000","0.00009000"],["63053.68000000","0.00429000"],["63050.55000000","0.95192000"],["63050.08000000","0.00000000"],["63050.01000000","0.00396000"],["63047.24000000","0.00000000"],["63044.40000000","0.00000000"],["63044.15000000","0.00000000"],["63043.51000000","0.00000000"],["63043.20000000","0.00000000"],["63042.41000000","0.00000000"],["63041.54000000","0.02120000"],["63040.78000000","0.00000000"],["63039.71000000","3.16977000"],["63039.70000000","0.00000000"],["63038.79000000","0.00000000"],["63035.17000000","0.00000000"],["63032.01000000","0.00000000"],["63027.09000000","0.00000000"],["63021.45000000","0.00000000"],["63020.72000000","0.00000000"],["63000.75000000","0.00000000"],["63000.16000000","0.00158000"],["62997.84000000","0.00000000"],["62994.01000000","0.00000000"],["62992.01000000","0.00000000"],["62989.24000000","0.00158000"],["62988.66000000","0.00000000"],["62982.01000000","0.00000000"],["62981.25000000","0.00000000"],["62864.59000000","0.17455000"],["62853.08000000","0.00250000"],["62820.00000000","0.01577000"],["62787.01000000","0.00000000"],["62477.84000000","1.18969000"],["62078.10000000","0.00040000"],["56793.47000000","0.00000000"],["56786.40000000","0.00009000"],["50494.39000000","0.00154000"],["50483.08000000","0.00022000"],["50476.80000000","0.00000000"]],"a":[["63096.01000000","0.00000000"],["63096.02000000","0.00000000"],["63096.03000000","0.00000000"],["63096.67000000","0.00000000"],["63096.68000000","0.00000000"],["63096.69000000","0.00000000"],["63096.70000000","0.00000000"],["63096.84000000","0.00000000"],["63097.03000000","0.00000000"],["63097.04000000","0.00000000"],["63097.36000000","0.00000000"],["63098.00000000","0.00000000"],["63098.01000000","0.00000000"],["63098.80000000","0.00000000"],["63098.81000000","0.00000000"],["63098.89000000","0.00000000"],["63099.41000000","0.00000000"],["63099.99000000","0.00000000"],["63100.00000000","0.00000000"],["63100.53000000","0.00000000"],["63100.54000000","0.00000000"],["63100.64000000","0.00000000"],["63101.06000000","0.00000000"],["63101.95000000","0.00000000"],["63101.96000000","0.00000000"],["63101.99000000","0.00000000"],["63102.00000000","0.00000000"],["63102.01000000","0.00000000"],["63102.16000000","0.00000000"],["63102.32000000","0.00000000"],["63102.48000000","0.00000000"],["63103.23000000","0.00000000"],["63103.56000000","0.00000000"],["63103.68000000","0.00000000"],["63103.69000000","0.00000000"],["63103.83000000","0.00000000"],["63103.84000000","0.00000000"],["63103.85000000","0.00000000"],["63103.86000000","0.00000000"],["63103.87000000","0.00000000"],["63103.88000000","0.00000000"],["63103.89000000","0.00000000"],["63103.92000000","0.00000000"],["63103.99000000","0.00000000"],["63104.00000000","0.00000000"],["63104.02000000","0.00000000"],["63104.48000000","0.00000000"],["63104.49000000","0.00000000"],["63104.51000000","0.00000000"],["63104.52000000","0.00000000"],["63104.61000000","0.00000000"],["63104.68000000","0.00000000"],["63104.76000000","0.00000000"],["63104.90000000","0.00000000"],["63104.91000000","0.00000000"],["63104.97000000","0.00000000"],["63105.15000000","0.00000000"],["63105.16000000","0.00000000"],["63105.17000000","0.00000000"],["63105.20000000","0.00000000"],["63105.46000000","0.00000000"],["63105.83000000","0.00000000"],["63105.84000000","0.00000000"],["63105.89000000","0.00000000"],["63105.96000000","0.00000000"],["63105.97000000","0.00000000"],["63105.98000000","0.00000000"],["63105.99000000","0.00000000"],["63106.00000000","0.80250000"],["63106.01000000","0.00063000"],["63106.14000000","0.00000000"],["63106.27000000","0.00000000"],["63106.32000000","0.00000000"],["63106.38000000","0.00000000"],["63106.50000000","0.00000000"],["63106.72000000","0.00000000"],["63106.78000000","0.00000000"],["63106.85000000","0.00000000"],["63107.02000000","0.00000000"],["63107.12000000","0.00000000"],["63107.20000000","0.00008000"],["63107.30000000","0.12246000"],["63107.36000000","0.00000000"],["63107.40000000","0.00000000"],["63107.42000000","0.00008000"],["63107.43000000","0.00000000"],["63107.65000000","0.00008000"],["63107.67000000","0.00000000"],["63107.68000000","0.00000000"],["63107.72000000","0.00000000"],["63107.84000000","0.00000000"],["63107.94000000","0.00000000"],["63107.95000000","0.00000000"],["63107.99000000","0.00018000"],["63108.00000000","0.02428000"],["63108.01000000","0.58487000"],["63108.32000000","0.00000000"],["63108.36000000","0.00000000"],["63108.67000000","0.00000000"],["63109.01000000","0.00000000"],["63109.56000000","0.00000000"],["63109.57000000","0.00000000"],["63109.73000000","0.00000000"],["63109.94000000","0.00000000"],["63109.99000000","0.00564000"],["63110.16000000","0.00018000"],["63110.17000000","0.22275000"],["63110.18000000","0.00000000"],["63110.29000000","0.00000000"],["63110.55000000","0.00000000"],["63110.56000000","0.00000000"],["63110.61000000","0.00000000"],["63110.98000000","0.00000000"],["63111.28000000","0.00018000"],["63111.29000000","0.24758000"],["63111.53000000","0.00000000"],["63111.63000000","0.00000000"],["63111.64000000","0.00000000"],["63111.93000000","0.00000000"],["63111.99000000","0.00009000"],["63112.00000000","0.49205000"],["63112.16000000","0.00000000"],["63112.26000000","0.00000000"],["63112.32000000","0.00318000"],["63112.51000000","0.00048000"],["63112.55000000","0.00000000"],["63112.84000000","0.00000000"],["63112.85000000","0.00196000"],["63113.06000000","0.00000000"],["63113.37000000","0.25636000"],["63113.76000000","0.00008000"],["63113.86000000","0.04000000"],["63113.98000000","2.56712000"],["63113.99000000","0.00000000"],["63114.27000000","0.02868000"],["63114.28000000","0.00000000"],["63114.40000000","0.00000000"],["63114.67000000","0.00000000"],["63114.83000000","0.05346000"],["63115.46000000","0.11000000"],["63115.47000000","0.02000000"],["63115.65000000","0.16000000"],["63115.76000000","0.00793000"],["63115.83000000","0.00023000"],["63116.51000000","2.56712000"],["63116.98000000","0.00000000"],["63117.02000000","0.00000000"],["63117.23000000","0.16000000"],["63117.60000000","0.98686000"],["63117.61000000","3.16977000"],["63117.62000000","0.00000000"],["63117.63000000","0.00018000"],["63118.10000000","0.00000000"],["63118.39000000","0.00793000"],["63118.54000000","0.00018000"],["63118.70000000","0.00000000"],["63119.11000000","2.56712000"],["63119.51000000","0.00000000"],["63119.68000000","0.00000000"],["63120.00000000","0.02350000"],["63121.07000000","0.00000000"],["63121.64000000","3.16977000"],["63121.66000000","2.56712000"],["63121.99000000","0.00221000"],["63122.06000000","0.00000000"],["63122.64000000","0.46056000"],["63122.92000000","0.00000000"],["63123.45000000","0.00000000"],["63123.75000000","1.05852000"],["63123.76000000","0.00000000"],["63123.77000000","0.00000000"],["63124.00000000","0.02450000"],["63124.28000000","2.56712000"],["63124.50000000","0.11127000"],["63124.51000000","0.00000000"],["63124.88000000","0.00126000"],["63125.44000000","3.16977000"],["63126.29000000","0.01100000"],["63126.30000000","0.71922000"],["63126.31000000","0.00000000"],["63126.87000000","0.38861000"],["63126.88000000","2.56720000"],["63127.34000000","0.00000000"],["63128.00000000","0.02300000"],["63128.14000000","0.79306000"],["63128.15000000","0.00000000"],["63128.86000000","0.00000000"],["63128.89000000","0.00000000"],["63129.32000000","1.11987000"],["63129.51000000","0.46056000"],["63129.59000000","0.00000000"],["63130.16000000","0.00008000"],["63130.48000000","0.00400000"],["63130.88000000","3.16977000"],["63130.89000000","0.00000000"],["63131.08000000","0.00000000"],["63131.13000000","0.00630000"],["63131.66000000","0.00000000"],["63131.99000000","0.00000000"],["63133.12000000","1.04058000"],["63133.26000000","0.00000000"],["63133.39000000","0.00000000"],["63133.44000000","0.00017000"],["63133.63000000","0.00000000"],["63134.00000000","0.02300000"],["63134.46000000","2.56712000"],["63134.86000000","0.00000000"],["63135.11000000","0.00000000"],["63135.22000000","0.00400000"],["63135.98000000","0.00000000"],["63136.00000000","0.02300000"],["63136.01000000","0.00000000"],["63136.33000000","0.46056000"],["63136.54000000","0.00000000"],["63136.72000000","0.00008000"],["63136.80000000","0.00400000"],["63137.33000000","1.67457000"],["63138.00000000","0.03300000"],["63138.09000000","0.00000000"],["63138.10000000","0.00000000"],["63138.20000000","0.57083000"],["63138.38000000","0.00400000"],["63138.69000000","1.71999000"],["63139.08000000","0.00000000"],["63140.50000000","0.00000000"],["63143.63000000","0.00000000"],["63143.82000000","0.52257000"],["63146.51000000","0.00539000"],["63148.61000000","0.00023000"],["63150.15000000","0.00000000"],["63150.82000000","0.00000000"],["63151.85000000","0.00384000"],["63156.66000000","0.00000000"],["63158.87000000","0.00395000"],["63163.51000000","0.00000000"],["63165.94000000","0.00000000"],["63166.16000000","4.75487000"],["63167.61000000","0.00000000"],["63167.81000000","0.00000000"],["63169.11000000","0.00000000"],["63169.99000000","0.00000000"],["63171.34000000","0.00000000"],["63171.45000000","0.00000000"],["63171.88000000","0.00000000"],["63172.99000000","0.00000000"],["63173.15000000","0.95192000"],["63173.53000000","0.00379000"],["63173.57000000","3.16977000"],["63174.03000000","0.00000000"],["63174.42000000","0.00000000"],["63178.53000000","3.16977000"],["63185.42000000","0.08320000"],["63186.11000000","0.00000000"],["63187.14000000","2.56712000"],["63187.88000000","0.00000000"],["63189.14000000","0.00000000"],["63189.21000000","0.00000000"],["63189.98000000","0.00000000"],["63191.82000000","0.00000000"],["63192.21000000","0.00000000"],["63194.72000000","2.56712000"],["63206.67000000","0.00000000"],["63210.00000000","0.00059000"],["63211.40000000","0.26425000"],["63215.31000000","0.00154000"],["63219.29000000","0.00000000"],["63221.99000000","0.00158000"],["63223.56000000","0.00000000"],["63226.68000000","0.00000000"],["63232.47000000","0.00000000"],["63236.58000000","0.00152000"],["63270.64000000","0.00008000"],["63273.79000000","0.00008000"],["63278.62000000","0.02482000"],["63307.86000000","0.00129000"],["63357.15000000","4.74054000"],["63411.92000000","0.00008000"],["63459.88000000","0.00250000"],["63603.68000000","0.00000000"],["63610.85000000","0.00018000"]]}
{"e":"depthUpdate","E":1781816961714,"s":"BTCUSDT","U":96005703129,"u":96005703394,"b":[["63105.99000000","6.57088000"],["63104.62000000","0.00018000"],["63104.61000000","0.04000000"],["63104.60000000","0.00009000"],["63104.51000000","0.20026000"],["63103.87000000","0.00018000"],["63103.86000000","0.05062000"],["63103.85000000","0.70081000"],["63103.69000000","0.00000000"],["63102.96000000","0.00009000"],["63102.95000000","0.06026000"],["63102.21000000","0.00000000"],["63102.01000000","1.18964000"],["63102.00000000","0.05018000"],["63101.99000000","1.93189000"],["63100.95000000","0.00000000"],["63100.00000000","0.00018000"],["63099.99000000","2.57013000"],["63099.75000000","0.00018000"],["63099.74000000","0.00000000"],["63099.68000000","0.00000000"],["63099.67000000","0.00300000"],["63098.64000000","0.00012000"],["63098.12000000","0.00008000"],["63098.00000000","0.00008000"],["63096.83000000","0.00008000"],["63096.01000000","0.24012000"],["63096.00000000","0.75332000"],["63095.99000000","0.00000000"],["63095.21000000","0.00018000"],["63095.19000000","0.00000000"],["63095.16000000","0.00000000"],["63094.53000000","0.00000000"],["63094.48000000","0.00000000"],["63094.01000000","0.00023000"],["63092.56000000","0.00400000"],["63092.17000000","0.89126000"],["63092.15000000","0.46074000"],["63090.98000000","0.00400000"],["63090.68000000","0.00018000"],["63087.72000000","2.42277000"],["63087.70000000","0.00000000"],["63087.06000000","0.00015000"],["63085.84000000","0.00018000"],["63085.83000000","0.46056000"],["63085.25000000","0.48178000"],["63084.01000000","0.00000000"],["63084.00000000","0.02318000"],["63083.38000000","0.00000000"],["63079.74000000","0.00000000"],["63078.63000000","0.00018000"],["63077.07000000","0.00000000"],["63076.64000000","0.00000000"],["63074.54000000","0.00000000"],["63074.00000000","0.03300000"],["63069.87000000","0.00000000"],["63068.00000000","0.02300000"],["63066.81000000","0.00000000"],["63058.60000000","0.00628000"],["63058.14000000","0.00000000"],["63049.19000000","0.00015000"],["63045.59000000","0.01074000"],["63039.21000000","0.00000000"],["63030.47000000","0.00015000"],["63030.26000000","0.00015000"],["63020.28000000","0.00000000"],["63020.05000000","0.00000000"],["63009.84000000","0.04919000"],["63003.71000000","0.00000000"],["63001.36000000","0.00000000"],["62932.62000000","0.00000000"],["62929.77000000","0.00000000"],["62477.84000000","0.00000000"],["56795.40000000","0.00040000"],["50484.79000000","0.00000000"]],"a":[["63106.00000000","2.08476000"],["63106.01000000","0.00081000"],["63107.29000000","0.00000000"],["63107.30000000","0.00018000"],["63108.00000000","0.39952000"],["63108.01000000","0.58513000"],["63108.32000000","0.00018000"],["63108.33000000","0.52351000"],["63109.78000000","0.00000000"],["63109.99000000","0.00582000"],["63110.00000000","0.02318000"],["63110.17000000","0.22301000"],["63111.04000000","0.00000000"],["63111.27000000","0.00009000"],["63111.28000000","0.30156000"],["63111.29000000","0.24776000"],["63111.99000000","0.00000000"],["63112.00000000","0.49231000"],["63112.31000000","0.00000000"],["63112.51000000","0.00000000"],["63113.24000000","0.07613000"],["63113.37000000","0.25628000"],["63113.47000000","0.00048000"],["63113.97000000","1.65290000"],["63114.83000000","0.00000000"],["63114.94000000","0.00000000"],["63115.89000000","0.00158000"],["63116.20000000","0.46056000"],["63117.60000000","1.80687000"],["63118.63000000","0.00300000"],["63120.58000000","0.13955000"],["63123.95000000","0.00000000"],["63124.00000000","0.02300000"],["63126.30000000","1.05550000"],["63133.64000000","0.00400000"],["63133.87000000","0.00000000"],["63134.87000000","0.00012000"],["63136.66000000","0.00434000"],["63138.38000000","0.00000000"],["63140.67000000","0.00430000"],["63140.68000000","0.00430000"],["63141.94000000","0.57080000"],["63143.86000000","0.00015000"],["63146.53000000","0.00000000"],["63152.80000000","0.00000000"],["63157.68000000","0.09179000"],["63161.72000000","0.00112000"],["63171.73000000","0.00000000"],["63173.15000000","0.00000000"],["63173.67000000","0.95192000"],["63190.65000000","0.00000000"],["63193.01000000","0.00000000"],["63245.83000000","0.00000000"],["63255.19000000","0.02482000"],["63268.23000000","0.00008000"],["63277.68000000","0.00000000"]]}
{"e":"depthUpdate","E":1781816961814,"s":"BTCUSDT","U":96005703395,"u":96005703462,"b":[["63105.99000000","6.60025000"],["63104.61000000","0.04018000"],["63102.95000000","0.06008000"],["63100.53000000","0.20016000"],["63096.00000000","0.73332000"],["63094.59000000","0.01594000"],["63085.44000000","1.19838000"],["63068.13000000","0.00015000"],["63011.33000000","0.00015000"],["56795.40000000","0.00080000"]],"a":[["63106.00000000","2.08477000"],["63107.30000000","0.00000000"],["63108.01000000","0.58513000"],["63108.33000000","0.52369000"],["63110.17000000","0.22301000"],["63111.28000000","0.30174000"],["63111.29000000","0.24776000"],["63111.74000000","0.00000000"],["63112.00000000","0.49213000"],["63124.93000000","0.00015000"],["63131.13000000","0.00000000"],["63131.16000000","0.00000000"],["63134.68000000","1.19745000"],["63139.06000000","0.00625000"],["63142.49000000","0.00190000"],["63145.38000000","0.57077000"],["63162.80000000","0.00015000"],["63181.73000000","0.00015000"],["63199.16000000","0.04917000"],["63200.66000000","0.00015000"],["69416.60000000","0.00008000"]]}
{"e":"depthUpdate","E":1781816961914,"s":"BTCUSDT","U":96005703463,"u":96005703491,"b":[["63105.99000000","6.58025000"],["63103.79000000","0.02000000"],["63100.53000000","0.20024000"],["63099.46000000","0.13955000"],["63097.59000000","0.00010000"],["63097.05000000","0.00009000"],["63087.60000000","0.00000000"],["63083.99000000","0.00000000"],["63057.70000000","0.00000000"],["63039.72000000","1.31533000"],["63030.47000000","0.00000000"],["63030.33000000","0.00015000"],["63014.88000000","0.09954000"],["56795.40000000","0.00100000"],["56795.00000000","0.00000000"]],"a":[["63107.98000000","0.00170000"],["63109.00000000","0.00009000"],["63137.32000000","0.71866000"],["63139.50000000","0.54382000"],["63158.44000000","1.03062000"],["63164.25000000","3.10729000"],["63183.73000000","0.00000000"],["63187.13000000","0.86491000"],["63187.74000000","0.00000000"],["63206.67000000","0.09768000"],["69416.60000000","0.00000000"]]}
{"e":"depthUpdate","E":1781816962014,"s":"BTCUSDT","U":96005703492,"u":96005703523,"b":[["63103.85000000","0.70081000"],["63103.79000000","0.02018000"],["63103.63000000","0.00793000"],["63103.45000000","0.01585000"],["63102.97000000","0.00793000"],["63102.18000000","0.01585000"],["63101.99000000","1.93171000"],["63100.92000000","0.01585000"],["63099.64000000","0.00008000"],["63079.36000000","0.00000000"],["56795.40000000","0.00140000"],["50484.80000000","0.00039000"]],"a":[["63106.00000000","2.25284000"],["63111.02000000","0.01585000"],["63112.28000000","0.01585000"],["63112.65000000","0.00793000"],["63113.54000000","0.01585000"],["63113.96000000","1.05834000"],["63115.14000000","0.00793000"],["63115.76000000","0.00000000"],["63117.22000000","0.00000000"],["63118.39000000","0.00000000"],["63119.99000000","0.08870000"],["63122.63000000","0.79310000"],["63123.75000000","0.00018000"],["63124.50000000","0.00000000"],["63128.14000000","0.00000000"],["63138.68000000","2.56712000"]]}
{"e":"depthUpdate","E":1781816962114,"s":"BTCUSDT","U":96005703524,"u":96005703590,"b":[["63105.99000000","6.60025000"],["63103.79000000","0.00018000"],["63103.63000000","0.00811000"],["63102.01000000","0.00000000"],["63102.00000000","0.05000000"],["63098.14000000","1.18962000"],["63096.83000000","0.00000000"],["63096.60000000","0.02200000"],["63096.57000000","0.02000000"],["63096.01000000","0.23996000"],["63095.97000000","0.04000000"],["63095.94000000","0.04000000"],["63094.07000000","0.02000000"],["63093.45000000","0.02000000"],["63093.44000000","0.02000000"],["63093.10000000","0.02000000"],["63092.81000000","0.04000000"],["63092.79000000","0.04000000"],["63089.34000000","0.00008000"],["63088.97000000","0.00000000"],["63088.94000000","0.02000000"],["63087.42000000","0.00000000"],["63087.07000000","0.00000000"],["63083.61000000","0.00000000"],["63055.24000000","0.02000000"],["63052.08000000","0.02000000"],["63048.43000000","0.00000000"],["56795.40000000","0.00180000"]],"a":[["63110.17000000","0.22301000"],["63111.02000000","0.01603000"],["63111.29000000","0.24758000"],["63127.22000000","0.00008000"],["63139.33000000","0.13156000"],["63159.43000000","0.02600000"],["63162.48000000","0.02000000"],["63163.11000000","0.04800000"],["63163.14000000","0.02000000"],["63163.22000000","0.03400000"],["63163.89000000","0.02408000"],["63165.01000000","0.02600000"],["63165.63000000","0.02000000"],["63165.64000000","0.02400000"],["63165.98000000","0.02600000"],["63166.27000000","0.05400000"],["63166.30000000","0.03200000"],["63174.67000000","0.02074000"],["63192.46000000","0.00966000"],["63215.32000000","0.00000000"]]}
{"e":"depthUpdate","E":1781816962214,"s":"BTCUSDT","U":96005703591,"u":96005703621,"b":[["63105.99000000","6.60005000"],["63103.85000000","0.70081000"],["63103.79000000","0.00000000"],["63103.45000000","0.01603000"],["63100.53000000","0.20016000"],["63098.00000000","0.00000000"],["63093.86000000","0.00400000"],["63088.94000000","0.00000000"],["63087.76000000","0.54164000"],["63085.81000000","0.00000000"],["63085.79000000","0.00000000"],["63084.30000000","0.00000000"],["63083.93000000","0.00000000"],["63081.18000000","0.00000000"],["63048.76000000","0.00000000"],["62938.01000000","0.00960000"],["62840.98000000","0.00000000"],["56795.40000000","0.00220000"],["50484.80000000","0.00000000"]],"a":[["63106.00000000","2.25293000"],["63110.17000000","0.22309000"],["63110.44000000","0.07613000"],["63112.00000000","0.49205000"],["63113.24000000","0.00000000"],["63124.44000000","0.00400000"]]}
{"e":"depthUpdate","E":1781816962314,"s":"BTCUSDT","U":96005703622,"u":96005703641,"b":[["63105.99000000","6.62723000"],["63098.15000000","0.00552000"],["63096.02000000","0.00000000"],["63095.91000000","0.00000000"],["63095.47000000","0.41151000"],["63086.44000000","0.00000000"],["56795.40000000","0.00260000"]],"a":[["63106.00000000","2.25302000"],["63107.11000000","0.00009000"],["63107.97000000","0.00187000"],["63107.98000000","0.00018000"],["63110.17000000","0.22309000"],["63110.44000000","0.07631000"],["63111.28000000","0.30156000"]]}
{"e":"depthUpdate","E":1781816962414,"s":"BTCUSDT","U":96005703642,"u":96005703678,"b":[["63087.76000000","0.54564000"],["63021.25000000","2.89252000"],["63008.53000000","0.00000000"],["56795.40000000","0.00300000"]],"a":[["63106.00000000","1.76661000"],["63106.01000000","0.00090000"],["63106.84000000","0.00000000"],["63107.97000000","0.00169000"],["63107.98000000","0.00000000"],["63108.00000000","0.39970000"],["63110.15000000","0.00000000"],["63111.27000000","0.00027000"],["63111.94000000","0.00000000"],["63111.96000000","0.00000000"],["63111.99000000","0.00018000"],["63113.97000000","1.65308000"],["63115.45000000","0.00018000"],["63116.50000000","0.00018000"],["63117.60000000","1.80705000"],["63117.63000000","0.00000000"],["63117.73000000","0.00018000"],["63118.19000000","0.00000000"],["63118.54000000","0.00000000"],["63119.10000000","0.00018000"],["63121.63000000","0.00018000"],["63122.93000000","0.00018000"],["63123.75000000","0.00000000"],["63124.27000000","0.00018000"],["63125.43000000","0.00018000"],["63126.87000000","0.38879000"],["63129.31000000","0.00018000"],["63130.87000000","0.00018000"],["63131.07000000","0.00400000"],["63134.45000000","0.00018000"],["63138.67000000","0.00018000"]]}
{"e":"depthUpdate","E":1781816962514,"s":"BTCUSDT","U":96005703679,"u":96005703755,"b":[["63105.99000000","6.62841000"],["63104.17000000","0.00000000"],["63104.00000000","0.00500000"],["63102.18000000","0.00000000"],["63102.00000000","0.06300000"],["63101.90000000","0.03894000"],["63100.92000000","0.00000000"],["63100.00000000","0.00518000"],["63099.67000000","0.00700000"],["63098.00000000","0.00500000"],["63096.02000000","3.16927000"],["63096.00000000","0.73822000"],["63092.18000000","0.46056000"],["63092.15000000","0.00018000"],["63090.50000000","0.00000000"],["63051.14000000","0.00000000"],["63039.71000000","0.00000000"],["56795.40000000","0.00349000"],["56786.40000000","0.00000000"],["50484.80000000","0.00039000"]],"a":[["63106.00000000","0.95593000"],["63106.01000000","0.00081000"],["63108.00000000","0.43193000"],["63111.02000000","0.00018000"],["63112.28000000","0.00000000"],["63112.65000000","0.00000000"],["63113.46000000","0.00000000"],["63113.54000000","0.00000000"],["63113.86000000","0.00000000"],["63113.94000000","2.10202000"],["63113.95000000","3.02768000"],["63113.97000000","0.00018000"],["63113.98000000","0.00000000"],["63114.26000000","0.01585000"],["63114.67000000","0.00793000"],["63115.14000000","0.00000000"],["63115.46000000","0.00000000"],["63115.66000000","0.07000000"],["63116.20000000","0.00000000"],["63116.49000000","0.00793000"],["63118.45000000","0.00000000"],["63118.86000000","0.08000000"],["63119.36000000","0.00400000"],["63119.99000000","0.00000000"],["63120.64000000","0.00009000"],["63121.63000000","0.18409000"],["63139.33000000","0.00000000"],["63142.55000000","0.32542000"],["63151.85000000","0.00000000"],["63151.86000000","0.00000000"],["63174.67000000","0.00000000"],["63192.46000000","0.00000000"],["63215.31000000","0.00000000"],["63663.86000000","0.00000000"]]}
{"e":"depthUpdate","E":1781816962614,"s":"BTCUSDT","U":96005703756,"u":96005703806,"b":[["63105.99000000","6.56849000"],["63105.20000000","0.00400000"],["63104.52000000","0.06145000"],["63104.51000000","0.20026000"],["63104.00000000","0.00518000"],["63103.86000000","0.67616000"],["63102.96000000","0.00000000"],["63102.17000000","0.00008000"],["63101.22000000","0.00962000"],["63100.00000000","1.18874000"],["63098.00000000","0.01300000"],["63096.03000000","1.06992000"],["63096.01000000","0.05338000"],["63096.00000000","0.74622000"],["63086.11000000","0.00000000"],["63079.92000000","0.00000000"],["63060.59000000","0.00427000"],["63000.01000000","0.46056000"],["62976.65000000","0.02481000"],["62958.87000000","0.00000000"],["56795.40000000","0.00369000"],["50484.80000000","0.00000000"]],"a":[["63106.00000000","1.05788000"],["63107.97000000","0.00000000"],["63108.00000000","0.43193000"],["63110.43000000","0.00009000"],["63110.44000000","0.07631000"],["63111.02000000","0.00000000"],["63111.28000000","0.30174000"],["63122.63000000","0.00000000"],["63125.43000000","0.79328000"],["63126.87000000","0.00018000"],["63129.30000000","0.38859000"],["63136.16000000","0.00000000"],["63153.47000000","0.00385000"],["63163.47000000","0.01064000"],["63216.46000000","0.00154000"]]}
{"e":"depthUpdate","E":1781816962714,"s":"BTCUSDT","U":96005703807,"u":96005704410,"b":[["63107.99000000","4.90114000"],["63107.98000000","0.00285000"],["63107.97000000","0.00016000"],["63107.64000000","0.00000000"],["63107.48000000","0.01585000"],["63107.41000000","0.00000000"],["63107.20000000","0.00008000"],["63107.19000000","0.00000000"],["63107.10000000","0.00000000"],["63106.55000000","0.00008000"],["63106.21000000","0.01585000"],["63106.01000000","0.00036000"],["63106.00000000","3.89398000"],["63105.99000000","0.90985000"],["63105.98000000","0.00000000"],["63105.97000000","0.00000000"],["63105.81000000","0.03894000"],["63105.21000000","0.00018000"],["63105.20000000","0.20408000"],["63105.14000000","0.00032000"],["63104.95000000","0.01585000"],["63104.62000000","0.00036000"],["63104.61000000","0.24018000"],["63104.52000000","0.20000000"],["63103.87000000","0.00000000"],["63103.86000000","0.67598000"],["63103.85000000","0.50081000"],["63103.63000000","0.00018000"],["63103.45000000","0.00000000"],["63102.97000000","0.00000000"],["63102.00000000","0.06318000"],["63101.99000000","1.73171000"],["63100.54000000","0.00552000"],["63100.53000000","0.00024000"],["63100.44000000","0.00154000"],["63100.12000000","0.00008000"],["63100.01000000","0.46056000"],["63100.00000000","0.83459000"],["63099.96000000","0.00868000"],["63099.75000000","0.00000000"],["63098.88000000","0.00409000"],["63098.15000000","0.00000000"],["63098.14000000","0.00000000"],["63096.21000000","0.16005000"],["63096.03000000","1.64785000"],["63096.01000000","0.00000000"],["63096.00000000","0.74614000"],["63094.64000000","0.00018000"],["63094.63000000","0.16006000"],["63094.59000000","0.00008000"],["63093.98000000","0.00000000"],["63093.82000000","0.00008000"],["63093.11000000","0.38859000"],["63092.82000000","0.00018000"],["63092.18000000","0.46056000"],["63092.15000000","0.00000000"],["63090.68000000","0.00000000"],["63090.67000000","0.00000000"],["63089.09000000","0.00000000"],["63088.96000000","0.00400000"],["63087.76000000","0.54164000"],["63086.02000000","0.00000000"],["63086.01000000","0.00000000"],["63085.84000000","0.00000000"],["63084.45000000","0.00018000"],["63084.00000000","0.02300000"],["63082.33000000","0.00000000"],["63078.63000000","0.00000000"],["63078.48000000","0.15715000"],["63075.27000000","0.36525000"],["63073.13000000","0.00000000"],["63065.76000000","0.17000000"],["63064.59000000","0.15718000"],["63052.03000000","0.00000000"],["63049.11000000","0.00000000"],["63044.88000000","0.00018000"],["63037.54000000","0.00000000"],["63033.60000000","0.00009000"],["63031.08000000","0.00015000"],["63030.33000000","0.00000000"],["63004.16000000","0.00000000"],["62981.77000000","0.00018000"],["62974.44000000","0.00000000"],["62918.67000000","0.00018000"],["62911.34000000","0.00000000"],["62879.90000000","0.02410000"],["62855.56000000","0.00018000"],["62848.24000000","0.00000000"],["62792.45000000","0.00018000"],["62785.14000000","0.00000000"],["62729.34000000","0.00018000"],["62722.04000000","0.00000000"],["62666.23000000","0.00018000"],["62658.94000000","0.00000000"],["62603.13000000","0.00018000"],["62595.83000000","0.00000000"],["56797.20000000","0.00020000"],["56795.40000000","0.00029000"],["50484.79000000","0.00000000"]],"a":[["63106.00000000","0.00000000"],["63106.01000000","0.00000000"],["63106.56000000","0.00000000"],["63107.11000000","0.00000000"],["63107.20000000","0.00000000"],["63107.42000000","0.00000000"],["63107.65000000","0.00000000"],["63107.99000000","0.00000000"],["63108.00000000","0.91478000"],["63108.01000000","0.58610000"],["63108.02000000","0.00016000"],["63108.32000000","0.00000000"],["63108.33000000","0.00018000"],["63109.89000000","0.00000000"],["63110.16000000","0.00000000"],["63110.17000000","0.00042000"],["63110.43000000","0.00000000"],["63110.44000000","0.00018000"],["63111.27000000","0.00018000"],["63111.28000000","0.00018000"],["63111.29000000","0.00026000"],["63111.52000000","0.00000000"],["63111.99000000","0.00036000"],["63112.00000000","0.49213000"],["63112.16000000","0.00018000"],["63112.17000000","0.52356000"],["63112.31000000","0.00018000"],["63112.32000000","0.24750000"],["63112.66000000","0.00000000"],["63113.36000000","0.00018000"],["63113.94000000","0.00000000"],["63113.95000000","0.00000000"],["63113.96000000","0.00000000"],["63114.26000000","0.00000000"],["63114.27000000","0.00000000"],["63114.32000000","0.00317000"],["63114.67000000","0.00000000"],["63114.84000000","0.00000000"],["63115.04000000","0.12469000"],["63115.05000000","0.01585000"],["63115.47000000","0.00000000"],["63115.64000000","0.00000000"],["63115.65000000","0.00000000"],["63115.91000000","0.00000000"],["63116.31000000","0.01585000"],["63116.48000000","0.00793000"],["63116.49000000","0.00000000"],["63116.50000000","1.05852000"],["63116.51000000","0.00000000"],["63116.99000000","0.00000000"],["63117.23000000","0.00000000"],["63117.35000000","0.00000000"],["63117.37000000","0.00000000"],["63117.57000000","0.01585000"],["63117.60000000","0.00018000"],["63117.61000000","0.00000000"],["63118.84000000","0.00793000"],["63118.85000000","0.00000000"],["63119.04000000","0.00000000"],["63119.10000000","0.46074000"],["63119.11000000","0.00000000"],["63119.36000000","0.00000000"],["63120.02000000","0.00018000"],["63120.03000000","0.00000000"],["63120.26000000","0.08091000"],["63120.27000000","0.06400000"],["63120.58000000","0.00000000"],["63121.59000000","0.00000000"],["63121.63000000","0.00018000"],["63121.64000000","0.00000000"],["63121.66000000","0.00000000"],["63122.64000000","0.00000000"],["63122.90000000","0.00000000"],["63122.93000000","3.16945000"],["63122.94000000","1.03927000"],["63123.19000000","0.00400000"],["63123.81000000","2.56712000"],["63123.99000000","0.24516000"],["63124.28000000","0.00000000"],["63124.44000000","0.00000000"],["63124.88000000","0.00008000"],["63125.42000000","0.46088000"],["63125.43000000","0.00018000"],["63125.44000000","0.00000000"],["63126.30000000","2.50450000"],["63126.44000000","2.56712000"],["63126.87000000","3.16945000"],["63126.88000000","0.00008000"],["63126.95000000","0.00000000"],["63128.92000000","0.00400000"],["63129.01000000","2.56720000"],["63129.29000000","0.79309000"],["63129.30000000","0.00000000"],["63129.51000000","0.00000000"],["63131.07000000","0.00000000"],["63132.31000000","0.38858000"],["63132.37000000","0.00000000"],["63132.40000000","0.00000000"],["63132.47000000","0.00000000"],["63133.36000000","0.00000000"],["63133.63000000","0.15701000"],["63134.25000000","0.00000000"],["63134.42000000","0.00400000"],["63135.94000000","0.00000000"],["63136.04000000","0.00119000"],["63137.00000000","0.02868000"],["63138.00000000","0.02300000"],["63138.39000000","0.00000000"],["63138.85000000","0.00214000"],["63139.72000000","0.13955000"],["63139.96000000","0.00400000"],["63140.00000000","0.03350000"],["63140.86000000","0.00000000"],["63145.28000000","0.02868000"],["63146.51000000","0.00000000"],["63147.98000000","0.00535000"],["63154.12000000","0.02868000"],["63158.87000000","0.00000000"],["63158.88000000","0.46056000"],["63162.95000000","0.00396000"],["63162.96000000","0.02868000"],["63163.64000000","0.00000000"],["63171.11000000","0.00018000"],["63173.67000000","0.00000000"],["63176.20000000","0.00000000"],["63186.11000000","3.16927000"],["63193.69000000","0.00000000"],["63194.00000000","0.02300000"],["63201.27000000","0.00000000"],["63226.74000000","0.00000000"],["63234.22000000","0.00018000"],["63276.53000000","0.00008000"],["63279.68000000","0.00008000"],["63289.84000000","0.00000000"],["63297.32000000","0.00018000"],["63352.94000000","0.01709000"],["63360.43000000","0.00018000"],["63416.04000000","0.00000000"],["63423.54000000","0.00018000"],["63479.14000000","0.00000000"],["63486.65000000","0.00018000"],["63542.24000000","0.00000000"],["63549.76000000","0.00018000"]]}
{"e":"depthUpdate","E":1781816962814,"s":"BTCUSDT","U":96005704411,"u":96005704587,"b":[["63107.99000000","4.92754000"],["63107.49000000","0.00000000"],["63107.48000000","0.00018000"],["63107.12000000","0.00009000"],["63106.78000000","0.00400000"],["63106.22000000","0.00018000"],["63106.21000000","0.01603000"],["63106.00000000","2.70138000"],["63105.99000000","0.88985000"],["63105.81000000","0.03912000"],["63105.21000000","0.00018000"],["63104.62000000","0.00018000"],["63104.60000000","0.00000000"],["63104.51000000","0.20008000"],["63104.00000000","0.00500000"],["63103.87000000","0.00000000"],["63103.86000000","1.04543000"],["63103.85000000","0.50063000"],["63103.63000000","0.00000000"],["63102.19000000","0.00552000"],["63102.18000000","1.18950000"],["63100.54000000","0.00000000"],["63100.12000000","0.01594000"],["63096.04000000","1.31766000"],["63096.03000000","0.00018000"],["63095.03000000","0.00119000"],["63094.03000000","0.00012000"],["63091.99000000","0.04375000"],["63083.49000000","0.00000000"],["63081.50000000","0.00000000"],["63076.00000000","0.03300000"],["63074.00000000","0.02300000"],["63069.71000000","0.00475000"],["63060.70000000","0.00436000"],["63052.56000000","0.00111000"],["63038.99000000","0.00000000"],["63009.84000000","0.00000000"],["62938.30000000","0.00000000"],["62938.01000000","0.00000000"],["62936.01000000","0.00960000"],["62935.15000000","0.00000000"],["56797.20000000","0.00060000"]],"a":[["63108.00000000","0.28271000"],["63108.01000000","0.58602000"],["63108.33000000","0.00000000"],["63110.00000000","0.02318000"],["63110.17000000","0.00008000"],["63110.44000000","0.00000000"],["63111.28000000","0.00000000"],["63111.29000000","0.00008000"],["63112.00000000","0.49231000"],["63112.17000000","0.52374000"],["63112.32000000","0.24768000"],["63113.10000000","0.00000000"],["63113.37000000","0.25662000"],["63114.00000000","0.02318000"],["63114.28000000","0.13424000"],["63115.03000000","0.04415000"],["63115.04000000","0.00008000"],["63115.89000000","0.00008000"],["63116.50000000","0.00018000"],["63116.73000000","0.00032000"],["63117.43000000","0.07613000"],["63117.57000000","0.00000000"],["63117.76000000","0.13417000"],["63119.10000000","0.00018000"],["63120.52000000","0.02868000"],["63122.92000000","3.08741000"],["63122.94000000","0.00000000"],["63123.10000000","0.02868000"],["63125.55000000","0.00150000"],["63126.29000000","0.00000000"],["63128.59000000","0.32651000"],["63132.31000000","0.00000000"],["63134.45000000","0.02886000"],["63135.21000000","0.38856000"],["63141.51000000","0.02868000"],["63141.54000000","0.00400000"],["63142.01000000","0.00000000"],["63172.01000000","0.01709000"],["63174.56000000","0.00020000"],["63174.94000000","0.95185000"],["63177.35000000","0.00000000"],["63195.15000000","0.00000000"],["63199.16000000","0.00000000"],["63279.68000000","0.00000000"],["82071.40000000","0.00000000"]]}
{"e":"depthUpdate","E":1781816962914,"s":"BTCUSDT","U":96005704588,"u":96005704669,"b":[["63107.99000000","4.92443000"],["63107.48000000","0.00000000"],["63107.07000000","0.00154000"],["63106.22000000","0.00000000"],["63106.21000000","0.00018000"],["63104.95000000","0.00000000"],["63104.62000000","0.00036000"],["63100.44000000","0.00000000"],["63096.04000000","1.96858000"],["63080.53000000","0.25626000"],["63041.67000000","0.08342000"],["63032.40000000","0.00015000"],["63031.08000000","0.00000000"],["63015.22000000","0.04918000"],["63014.88000000","1.13917000"],["63008.71000000","0.42559000"],["62976.65000000","0.00000000"],["62958.87000000","0.02481000"],["56797.20000000","0.00100000"],["56797.00000000","0.30000000"]],"a":[["63108.00000000","0.86723000"],["63108.01000000","0.00123000"],["63109.00000000","0.00000000"],["63109.99000000","0.00600000"],["63110.26000000","0.00009000"],["63112.00000000","0.24299000"],["63113.37000000","0.25670000"],["63113.61000000","0.12635000"],["63114.00000000","0.02318000"],["63114.28000000","0.00008000"],["63115.05000000","0.00000000"],["63116.31000000","0.00000000"],["63117.97000000","0.02868000"],["63120.26000000","0.85138000"],["63121.25000000","2.56712000"],["63138.67000000","3.27055000"],["63138.69000000","0.00000000"],["63162.96000000","0.00000000"],["63173.56000000","1.24697000"],["63173.99000000","0.00000000"],["63174.94000000","0.00000000"],["63175.04000000","0.95185000"],["63193.99000000","0.83770000"],["63204.56000000","0.05106000"],["63215.46000000","1.46797000"]]}
{"e":"depthUpdate","E":1781816963014,"s":"BTCUSDT","U":96005704670,"u":96005704767,"b":[["63107.99000000","4.91614000"],["63107.21000000","0.00793000"],["63106.21000000","0.00000000"],["63105.20000000","0.20426000"],["63104.52000000","0.20018000"],["63104.51000000","0.20026000"],["63104.21000000","0.01585000"],["63103.87000000","0.00009000"],["63102.95000000","0.07593000"],["63102.00000000","0.06326000"],["63101.68000000","0.01585000"],["63100.53000000","0.00016000"],["63100.02000000","0.46064000"],["63100.01000000","0.00000000"],["63091.26000000","0.00400000"],["63088.96000000","0.00000000"],["63045.07000000","0.02074000"],["63041.54000000","0.00000000"],["56797.20000000","0.00140000"],["50486.40000000","0.00083000"]],"a":[["63108.00000000","0.86147000"],["63108.01000000","0.00105000"],["63111.78000000","0.01585000"],["63112.00000000","0.24307000"],["63112.15000000","0.00018000"],["63112.16000000","0.30779000"],["63112.31000000","0.00000000"],["63112.32000000","0.00018000"],["63113.04000000","0.01585000"],["63113.36000000","0.00009000"],["63113.37000000","0.25670000"],["63113.60000000","0.08236000"],["63113.61000000","0.12653000"],["63114.00000000","0.02318000"],["63114.28000000","0.00000000"],["63114.31000000","0.01585000"],["63115.03000000","0.00000000"],["63115.66000000","0.01000000"],["63115.80000000","0.00000000"],["63115.91000000","0.00012000"],["63116.48000000","0.00000000"],["63117.13000000","0.00793000"],["63117.76000000","0.28096000"],["63118.46000000","0.06000000"],["63119.08000000","0.46056000"],["63124.30000000","0.13955000"],["63134.42000000","0.00000000"],["63134.90000000","0.00400000"],["63139.72000000","0.00000000"],["63142.62000000","0.13474000"],["63151.81000000","0.10000000"],["63177.95000000","0.00000000"],["63186.42000000","0.00008000"],["63195.75000000","0.00987000"],["63269.79000000","0.24750000"]]}
{"e":"depthUpdate","E":1781816963114,"s":"BTCUSDT","U":96005704768,"u":96005704907,"b":[["63107.99000000","4.90821000"],["63107.21000000","0.00018000"],["63107.13000000","0.00000000"],["63106.02000000","0.01586000"],["63105.81000000","0.00018000"],["63104.51000000","0.20008000"],["63104.02000000","0.00010000"],["63103.87000000","0.00009000"],["63103.78000000","0.02200000"],["63103.65000000","0.02000000"],["63103.12000000","0.04000000"],["63102.19000000","0.00000000"],["63102.00000000","0.06318000"],["63101.99000000","1.73163000"],["63101.67000000","0.00400000"],["63101.15000000","0.02000000"],["63100.62000000","0.02000000"],["63100.53000000","0.00000000"],["63100.19000000","0.00552000"],["63100.18000000","0.02000000"],["63100.03000000","0.46056000"],["63100.02000000","0.00000000"],["63099.97000000","0.02000000"],["63099.89000000","0.02000000"],["63099.67000000","0.00300000"],["63096.60000000","0.00000000"],["63095.94000000","0.02000000"],["63094.07000000","0.00000000"],["63091.34000000","0.00008000"],["63089.34000000","0.00000000"],["63055.24000000","0.04000000"],["63052.08000000","0.02000000"],["63048.76000000","0.02000000"],["63048.43000000","0.00000000"],["63028.79000000","0.00030000"],["63016.81000000","0.00000000"],["62958.87000000","0.00000000"],["56797.20000000","0.00180000"]],"a":[["63108.00000000","1.49119000"],["63108.01000000","0.00114000"],["63110.00000000","0.02318000"],["63111.49000000","0.12752000"],["63111.78000000","0.01603000"],["63111.98000000","0.00009000"],["63111.99000000","0.34154000"],["63112.00000000","0.24307000"],["63112.15000000","0.00000000"],["63112.16000000","0.00036000"],["63112.17000000","0.52374000"],["63112.32000000","0.00000000"],["63112.90000000","0.00018000"],["63112.91000000","0.00000000"],["63113.04000000","0.01603000"],["63113.36000000","0.00000000"],["63113.37000000","0.25654000"],["63113.60000000","0.02607000"],["63113.61000000","0.00000000"],["63114.00000000","0.02300000"],["63115.04000000","0.00000000"],["63115.66000000","0.00000000"],["63117.76000000","1.20819000"],["63117.86000000","0.11000000"],["63118.46000000","0.00000000"],["63118.86000000","0.00000000"],["63119.07000000","3.16917000"],["63120.06000000","0.04000000"],["63120.27000000","0.04400000"],["63121.21000000","0.00400000"],["63122.08000000","0.02000000"],["63123.19000000","0.00000000"],["63124.30000000","0.00000000"],["63127.22000000","0.00000000"],["63129.22000000","0.00008000"],["63142.62000000","0.00000000"],["63143.99000000","0.00000000"],["63174.55000000","0.00000000"],["63178.16000000","0.00000000"],["63186.11000000","0.00000000"],["63186.56000000","0.00030000"],["63195.75000000","0.00000000"],["63197.16000000","0.00973000"]]}
{"e":"depthUpdate","E":1781816963214,"s":"BTCUSDT","U":96005704908,"u":96005705036,"b":[["63107.99000000","4.90821000"],["63107.21000000","0.00000000"],["63106.02000000","0.01604000"],["63105.99000000","0.88985000"],["63105.81000000","0.00000000"],["63104.51000000","0.20026000"],["63103.87000000","0.00000000"],["63096.62000000","0.00400000"],["63096.57000000","0.00000000"],["63095.94000000","0.00000000"],["63093.86000000","0.00000000"],["63093.10000000","0.00000000"],["63092.81000000","0.02000000"],["63092.79000000","0.02000000"],["63056.64000000","0.00404000"],["63050.01000000","0.00000000"],["56797.20000000","0.00220000"],["50486.40000000","0.00044000"],["50486.00000000","0.00699000"]],"a":[["63108.00000000","1.41343000"],["63108.01000000","0.00123000"],["63110.00000000","0.02318000"],["63110.26000000","0.00027000"],["63110.27000000","0.00036000"],["63110.28000000","0.52349000"],["63111.27000000","0.00000000"],["63111.48000000","0.00018000"],["63111.49000000","0.12770000"],["63111.78000000","0.01603000"],["63111.98000000","0.00000000"],["63111.99000000","0.00054000"],["63112.00000000","0.24299000"],["63112.16000000","0.00000000"],["63112.17000000","0.00018000"],["63112.90000000","0.00000000"],["63113.36000000","0.00018000"],["63113.37000000","0.25644000"],["63113.60000000","0.04544000"],["63113.97000000","0.00000000"],["63114.98000000","0.00018000"],["63114.99000000","0.07613000"],["63115.45000000","0.00000000"],["63115.52000000","0.00864000"],["63115.99000000","0.00018000"],["63116.50000000","0.00000000"],["63117.43000000","0.00000000"],["63117.60000000","0.00000000"],["63117.73000000","0.00000000"],["63117.75000000","0.00018000"],["63117.85000000","0.00018000"],["63118.68000000","0.00851000"],["63119.06000000","0.00018000"],["63119.10000000","0.00000000"],["63120.02000000","0.00000000"],["63120.25000000","0.00018000"],["63121.24000000","0.00018000"],["63121.63000000","0.00000000"],["63121.84000000","0.00855000"],["63121.99000000","0.00239000"],["63122.91000000","0.00018000"],["63122.92000000","3.08759000"],["63122.93000000","3.16927000"],["63123.28000000","0.13955000"],["63124.27000000","0.00000000"],["63125.00000000","0.00868000"],["63125.41000000","0.00018000"],["63125.43000000","0.00000000"],["63126.86000000","0.00018000"],["63126.87000000","3.16927000"],["63127.74000000","0.00400000"],["63128.16000000","0.03729000"],["63128.92000000","0.00000000"],["63129.00000000","0.00018000"],["63134.45000000","0.02868000"],["63138.66000000","0.00018000"],["63138.67000000","3.27037000"],["63173.53000000","0.00000000"],["63175.67000000","0.00379000"],["63221.99000000","0.00000000"],["63226.69000000","0.00158000"]]}
{"e":"depthUpdate","E":1781816963314,"s":"BTCUSDT","U":96005705037,"u":96005705083,"b":[["63107.99000000","4.91730000"],["63106.03000000","0.00009000"],["63095.47000000","0.00000000"],["63093.44000000","0.00000000"],["56797.20000000","0.00240000"],["50486.00000000","0.00099000"]],"a":[["63110.00000000","0.02318000"],["63110.26000000","0.00009000"],["63110.28000000","0.52367000"],["63111.78000000","0.01603000"],["63111.99000000","0.00036000"],["63112.00000000","0.24291000"],["63112.17000000","0.00000000"],["63113.36000000","0.00027000"],["63113.37000000","0.25662000"],["63119.12000000","0.00150000"],["63125.55000000","0.00000000"]]}
{"e":"depthUpdate","E":1781816963414,"s":"BTCUSDT","U":96005705084,"u":96005705100,"b":[["63107.12000000","0.00000000"],["63106.49000000","0.00009000"],["63101.67000000","0.00400000"],["63098.88000000","0.00431000"],["63030.26000000","0.00094000"],["56797.20000000","0.00280000"]],"a":[["63108.00000000","1.41334000"],["63108.01000000","0.00114000"],["63121.21000000","0.00000000"],["63121.47000000","0.00400000"],["82071.40000000","0.00010000"]]}
{"e":"depthUpdate","E":1781816963514,"s":"BTCUSDT","U":96005705101,"u":96005705115,"b":[["63107.99000000","4.91740000"],["63105.62000000","0.01585000"],["63104.21000000","0.00000000"],["63102.95000000","0.06008000"],["63101.68000000","0.00000000"],["63082.47000000","0.00000000"],["56797.20000000","0.00320000"],["50486.40000000","0.00083000"]],"a":[["63108.00000000","1.41325000"],["63111.78000000","0.00018000"],["63113.04000000","0.00018000"],["63114.31000000","0.00000000"],["63144.02000000","0.13443000"],["63675.96000000","0.00010000"]]}
{"e":"depthUpdate","E":1781816963614,"s":"BTCUSDT","U":96005705116,"u":96005705172,"b":[["63107.99000000","4.88633000"],["63107.07000000","0.00264000"],["63106.36000000","0.01585000"],["63106.03000000","0.00000000"],["63105.99000000","0.88985000"],["63105.62000000","0.01603000"],["63104.51000000","0.20008000"],["63103.87000000","0.00009000"],["63099.99000000","2.56712000"],["63091.26000000","0.00000000"],["63090.23000000","0.00400000"],["56797.20000000","0.00360000"],["56797.19000000","0.00009000"],["56795.40000000","0.00020000"],["50486.40000000","0.00044000"]],"a":[["63108.00000000","1.41334000"],["63108.01000000","0.00105000"],["63111.49000000","0.12770000"],["63111.78000000","0.00000000"],["63112.00000000","0.24291000"],["63113.04000000","0.00000000"],["63113.19000000","0.03010000"],["63113.37000000","0.25670000"],["63113.58000000","0.07886000"],["63113.59000000","0.07613000"],["63113.60000000","0.00018000"],["63114.00000000","0.02318000"],["63115.20000000","0.01585000"],["63116.46000000","0.01585000"],["63117.72000000","0.01585000"],["63134.09000000","0.00400000"],["63134.90000000","0.00000000"],["63179.36000000","0.02035000"],["63182.98000000","0.00008000"]]}
{"e":"depthUpdate","E":1781816963714,"s":"BTCUSDT","U":96005705173,"u":96005705225,"b":[["63107.64000000","0.00009000"],["63107.63000000","0.01585000"],["63106.01000000","0.42540000"],["63106.00000000","2.61748000"],["63104.00000000","0.01500000"],["63103.87000000","0.00000000"],["63102.00000000","0.07318000"],["63101.67000000","0.00400000"],["63100.00000000","0.84459000"],["63099.24000000","0.60500000"],["63098.00000000","0.02300000"],["63096.00000000","0.75214000"],["63095.36000000","0.01161000"],["63091.19000000","0.00000000"],["63089.69000000","0.00000000"],["63089.27000000","0.00000000"],["63008.71000000","0.00000000"],["62998.74000000","0.00079000"],["56797.20000000","0.00400000"],["50486.39000000","0.00000000"]],"a":[["63108.00000000","1.41334000"],["63108.64000000","0.00000000"],["63112.00000000","0.24291000"],["63113.19000000","0.03028000"],["63113.37000000","0.25670000"],["63113.58000000","0.07904000"],["63113.60000000","0.00000000"],["63114.00000000","0.02300000"],["63120.63000000","0.00300000"],["63121.31000000","0.00400000"],["63121.47000000","0.00000000"]]}
{"e":"depthUpdate","E":1781816963814,"s":"BTCUSDT","U":96005705226,"u":96005705275,"b":[["63107.99000000","4.88659000"],["63107.64000000","0.00036000"],["63107.63000000","0.01603000"],["63106.36000000","0.01603000"],["63106.02000000","0.01595000"],["63106.01000000","0.42540000"],["63105.21000000","0.00000000"],["63104.62000000","0.00018000"],["63104.61000000","0.24000000"],["63104.52000000","0.20000000"],["63103.87000000","0.00018000"],["63103.86000000","1.04525000"],["63102.19000000","0.00018000"],["63099.25000000","0.00018000"],["63098.88000000","0.00409000"],["63096.00000000","0.75614000"],["63094.64000000","0.00000000"],["63093.12000000","0.00018000"],["63092.82000000","0.00000000"],["63075.27000000","0.36507000"],["63061.69000000","2.22112000"],["62968.07000000","0.09528000"],["62107.99000000","0.00040000"],["56797.20000000","0.00440000"]],"a":[["63108.00000000","1.41316000"],["63108.01000000","0.00105000"],["63128.51000000","0.01586000"]]}
{"e":"depthUpdate","E":1781816963914,"s":"BTCUSDT","U":96005705276,"u":96005705299,"b":[["63107.12000000","0.00009000"],["63106.36000000","0.00018000"],["63103.86000000","1.04548000"],["63100.54000000","0.00023000"],["63099.24000000","0.60531000"],["63090.23000000","0.00000000"],["63089.95000000","0.00400000"],["63021.26000000","0.42880000"],["63010.48000000","0.00000000"],["62941.59000000","0.00960000"],["62936.01000000","0.00000000"],["62107.99000000","0.00060000"],["56797.20000000","0.00440000"]],"a":[["63110.28000000","0.52535000"],["63115.42000000","0.02868000"],["63133.87000000","0.00400000"],["63134.09000000","0.00000000"],["63154.12000000","0.00000000"],["63166.95000000","0.57275000"],["63181.72000000","0.00040000"],["63217.73000000","0.29220000"]]}
{"e":"depthUpdate","E":1781816964014,"s":"BTCUSDT","U":96005705300,"u":96005705325,"b":[["63107.99000000","4.88630000"],["63107.63000000","0.01603000"],["63106.36000000","0.00000000"],["63106.03000000","1.18954000"],["63106.02000000","0.01613000"],["63104.63000000","0.01200000"],["63104.62000000","0.00000000"],["63102.18000000","0.00000000"],["56797.20000000","0.00440000"],["56797.00000000","0.30000000"],["50486.40000000","0.00083000"]],"a":[["63115.76000000","0.00793000"],["63117.13000000","0.00000000"],["63117.71000000","0.00793000"],["63117.73000000","1.05834000"],["63118.84000000","0.00000000"],["63122.92000000","2.02925000"],["63125.41000000","0.79325000"],["63129.29000000","0.00000000"],["63147.52000000","0.12907000"],["63264.06000000","0.09484000"]]}
{"e":"depthUpdate","E":1781816964114,"s":"BTCUSDT","U":96005705326,"u":96005705368,"b":[["63107.63000000","0.01603000"],["63106.04000000","0.00018000"],["63106.03000000","1.18972000"],["63105.20000000","0.20408000"],["63104.95000000","0.01585000"],["63103.13000000","0.04000000"],["63100.61000000","0.02000000"],["63099.98000000","0.02000000"],["63099.95000000","0.02000000"],["63096.62000000","0.00000000"],["63096.19000000","0.00400000"],["63095.97000000","0.00000000"],["63092.79000000","0.00000000"],["63091.34000000","0.00008000"],["63087.98000000","0.02200000"],["63087.32000000","0.04000000"],["63084.83000000","0.02000000"],["63084.17000000","0.02000000"],["63055.24000000","0.02000000"],["63055.22000000","0.00000000"],["63052.08000000","0.04000000"],["63048.43000000","0.02000000"],["56797.20000000","0.00440000"]],"a":[["63108.00000000","1.52966000"],["63117.71000000","2.34508000"],["63117.72000000","2.58297000"],["63117.76000000","0.00000000"],["63127.52000000","0.00400000"],["63127.74000000","0.00000000"],["63129.22000000","0.00008000"]]}
{"e":"depthUpdate","E":1781816964214,"s":"BTCUSDT","U":96005705369,"u":96005705430,"b":[["63107.99000000","4.82990000"],["63106.04000000","0.00000000"],["63106.03000000","0.00018000"],["63106.02000000","0.00036000"],["63105.62000000","0.00018000"],["63105.21000000","0.00981000"],["63105.14000000","0.00000000"],["63104.03000000","0.01586000"],["63103.95000000","0.00852000"],["63100.79000000","0.00861000"],["63100.20000000","1.16623000"],["63100.19000000","1.19506000"],["63100.00000000","0.02318000"],["63098.49000000","0.00320000"],["63093.45000000","0.00000000"],["63092.81000000","0.00000000"],["63048.76000000","0.00000000"],["63025.49000000","2.89233000"],["63021.26000000","0.00000000"],["63021.25000000","0.00000000"],["56797.20000000","0.00440000"],["50486.40000000","0.00044000"]],"a":[["63108.00000000","2.99659000"],["63108.28000000","0.52351000"],["63109.99000000","0.00632000"],["63110.26000000","0.00027000"],["63110.27000000","0.34957000"],["63110.28000000","0.00194000"],["63110.39000000","0.00009000"],["63110.40000000","0.11134000"],["63111.24000000","0.07613000"],["63111.48000000","0.00000000"],["63111.49000000","0.00018000"],["63112.30000000","0.07613000"],["63113.18000000","0.00793000"],["63113.36000000","0.00018000"],["63113.59000000","0.00000000"],["63114.99000000","0.00000000"],["63115.76000000","0.00000000"],["63120.51000000","0.08432000"],["63121.24000000","0.00018000"],["63122.91000000","0.00018000"],["63123.99000000","0.00000000"],["63128.89000000","0.38860000"],["63135.21000000","0.00000000"],["63213.31000000","0.00048000"]]}
{"e":"depthUpdate","E":1781816964314,"s":"BTCUSDT","U":96005705431,"u":96005705549,"b":[["63107.99000000","4.83020000"],["63107.63000000","0.01603000"],["63106.03000000","0.00000000"],["63106.02000000","0.00018000"],["63106.01000000","0.42558000"],["63106.00000000","2.63333000"],["63105.99000000","0.88985000"],["63105.62000000","0.00000000"],["63105.21000000","0.00999000"],["63105.20000000","0.20426000"],["63101.67000000","0.00000000"],["63100.66000000","0.00400000"],["63100.19000000","1.18954000"],["63099.47000000","0.00552000"],["63052.06000000","0.00000000"],["56797.20000000","0.00460000"]],"a":[["63108.00000000","2.99703000"],["63108.01000000","0.00132000"],["63108.26000000","0.00009000"],["63108.27000000","0.16546000"],["63108.28000000","0.52369000"],["63109.99000000","0.00614000"],["63110.00000000","0.02318000"],["63110.27000000","0.24091000"],["63110.28000000","0.00008000"],["63110.39000000","0.00018000"],["63110.40000000","0.11160000"],["63111.23000000","0.00009000"],["63111.24000000","0.07631000"],["63111.49000000","0.00000000"],["63111.99000000","0.00027000"],["63112.00000000","0.24299000"],["63112.30000000","0.07631000"],["63113.19000000","0.03010000"],["63113.37000000","0.25636000"],["63113.58000000","0.04187000"],["63117.71000000","2.34526000"],["63117.75000000","0.00000000"],["63119.36000000","0.00400000"],["63120.89000000","0.00018000"],["63121.31000000","0.00000000"],["63121.99000000","0.00221000"],["63122.91000000","0.00000000"],["63123.80000000","0.00018000"],["63125.41000000","0.79307000"],["63129.19000000","0.57091000"],["63129.31000000","0.00000000"],["63133.11000000","0.00018000"],["63138.38000000","0.00400000"],["63141.54000000","0.00000000"],["63141.94000000","0.00000000"]]}
{"e":"depthUpdate","E":1781816964414,"s":"BTCUSDT","U":96005705550,"u":96005705564,"b":[["63055.21000000","0.00000000"],["63052.71000000","0.00000000"],["56797.20000000","0.00440000"]],"a":[["63108.00000000","2.99703000"],["63108.27000000","0.16564000"],["63110.17000000","0.00162000"],["63112.30000000","0.07613000"],["63144.02000000","0.00000000"]]}
{"e":"depthUpdate","E":1781816964514,"s":"BTCUSDT","U":96005705565,"u":96005705588,"b":[["63093.38000000","0.00000000"],["63090.07000000","0.13371000"],["63089.95000000","0.00000000"],["63087.93000000","0.00400000"],["63086.75000000","0.00000000"],["63051.64000000","0.00000000"],["63032.40000000","0.00000000"],["56797.20000000","0.00440000"],["50486.40000000","0.00083000"]],"a":[["63108.00000000","2.26303000"],["63108.26000000","0.00018000"],["63111.23000000","0.00000000"],["63111.24000000","0.00018000"],["63128.89000000","0.00000000"],["63131.78000000","0.38858000"],["63131.87000000","0.00400000"],["63133.87000000","0.00000000"],["63144.50000000","0.13242000"],["63179.36000000","0.00000000"],["63197.16000000","0.00000000"]]}
{"e":"depthUpdate","E":1781816964614,"s":"BTCUSDT","U":96005705589,"u":96005705608,"b":[["63107.99000000","4.74418000"],["63032.37000000","0.00015000"],["56797.20000000","0.00420000"],["56797.19000000","0.00009000"],["50486.40000000","0.00044000"]],"a":[["63109.99000000","0.00582000"],["63110.40000000","0.11152000"],["63111.24000000","0.00000000"],["63112.30000000","0.07631000"]]}
{"e":"depthUpdate","E":1781816964714,"s":"BTCUSDT","U":96005705609,"u":96005705622,"b":[["63096.19000000","0.00000000"],["63094.43000000","0.00400000"],["56797.20000000","0.00420000"],["50486.39000000","0.00000000"]],"a":[["63108.00000000","2.26294000"],["63108.01000000","0.00123000"],["63125.72000000","0.00400000"],["63127.52000000","0.00000000"]]}
{"e":"depthUpdate","E":1781816964814,"s":"BTCUSDT","U":96005705623,"u":96005706405,"b":[["63109.99000000","9.00917000"],["63109.98000000","1.03201000"],["63109.97000000","0.00016000"],["63109.96000000","0.00000000"],["63109.94000000","0.00400000"],["63109.49000000","0.04000000"],["63109.15000000","0.26000000"],["63108.36000000","0.00400000"],["63108.32000000","0.00000000"],["63108.28000000","0.00023000"],["63108.27000000","0.32658000"],["63108.26000000","0.00000000"],["63108.25000000","0.00000000"],["63108.01000000","0.00000000"],["63108.00000000","0.47833000"],["63107.99000000","1.12333000"],["63107.98000000","0.20000000"],["63107.97000000","0.00000000"],["63107.64000000","0.00018000"],["63107.63000000","0.00018000"],["63106.03000000","1.06543000"],["63106.02000000","1.18953000"],["63106.01000000","0.00036000"],["63106.00000000","2.61730000"],["63105.99000000","0.68972000"],["63105.34000000","0.00032000"],["63105.21000000","0.00990000"],["63105.20000000","0.00408000"],["63104.95000000","0.00000000"],["63104.69000000","0.00008000"],["63104.61000000","0.00000000"],["63104.52000000","0.00000000"],["63104.51000000","0.00008000"],["63104.03000000","0.00000000"],["63103.87000000","0.00570000"],["63103.86000000","1.62347000"],["63103.85000000","0.50055000"],["63102.95000000","0.00008000"],["63102.51000000","0.00263000"],["63102.19000000","0.00000000"],["63102.12000000","0.00008000"],["63102.02000000","0.00000000"],["63102.01000000","3.16917000"],["63102.00000000","0.02318000"],["63100.80000000","0.00000000"],["63100.54000000","0.00000000"],["63100.21000000","0.46056000"],["63100.20000000","1.16641000"],["63100.19000000","0.00000000"],["63100.12000000","0.01594000"],["63100.03000000","0.00000000"],["63099.82000000","0.16004000"],["63099.47000000","0.00000000"],["63098.49000000","0.00000000"],["63098.25000000","0.16005000"],["63096.21000000","0.00000000"],["63096.00000000","0.31214000"],["63094.63000000","0.00000000"],["63092.65000000","0.00000000"],["63091.05000000","0.00158000"],["63089.03000000","0.48347000"],["63088.30000000","0.57128000"],["63087.93000000","0.00000000"],["63085.44000000","0.00000000"],["63084.66000000","0.00000000"],["63083.08000000","0.00000000"],["63081.74000000","1.57120000"],["63077.75000000","0.00000000"],["63077.68000000","0.00211000"],["63071.03000000","0.00395000"],["63067.65000000","0.00000000"],["63067.03000000","0.00000000"],["63066.29000000","0.00000000"],["63061.69000000","2.22094000"],["63058.66000000","0.00396000"],["63058.46000000","0.95174000"],["63056.64000000","0.00009000"],["63055.50000000","0.00000000"],["63050.55000000","0.00000000"],["63050.39000000","1.45633000"],["63048.60000000","0.02114000"],["63047.28000000","0.00000000"],["63045.07000000","0.00000000"],["63014.88000000","0.09954000"],["63008.01000000","0.00158000"],["63000.16000000","0.00000000"],["62994.68000000","0.00158000"],["62989.24000000","0.00000000"],["62107.99000000","0.00020000"],["56797.20000000","0.00000000"]],"a":[["63108.00000000","0.00000000"],["63108.01000000","0.00000000"],["63108.02000000","0.00000000"],["63108.26000000","0.00000000"],["63108.27000000","0.00000000"],["63108.28000000","0.00000000"],["63109.99000000","0.00000000"],["63110.00000000","0.01651000"],["63110.01000000","0.00081000"],["63110.17000000","0.00008000"],["63110.26000000","0.00009000"],["63110.27000000","0.00018000"],["63110.39000000","0.00000000"],["63110.40000000","0.00027000"],["63110.45000000","0.00000000"],["63110.94000000","0.00000000"],["63111.99000000","0.00036000"],["63112.00000000","0.02334000"],["63112.29000000","0.00000000"],["63112.30000000","0.00018000"],["63112.85000000","0.00008000"],["63113.18000000","0.00036000"],["63113.19000000","0.03028000"],["63113.36000000","0.00018000"],["63113.37000000","0.00127000"],["63113.49000000","0.00000000"],["63113.58000000","0.00018000"],["63113.99000000","0.00018000"],["63114.32000000","0.00000000"],["63114.37000000","0.00000000"],["63114.68000000","0.00000000"],["63115.20000000","0.00000000"],["63115.41000000","0.00018000"],["63115.42000000","0.00000000"],["63115.52000000","0.00000000"],["63115.77000000","0.00000000"],["63115.87000000","0.00000000"],["63115.88000000","0.00000000"],["63115.91000000","0.00000000"],["63115.99000000","0.00027000"],["63116.26000000","0.00000000"],["63116.31000000","0.00319000"],["63116.46000000","0.00000000"],["63117.03000000","0.00000000"],["63117.04000000","0.52352000"],["63117.32000000","0.00000000"],["63117.33000000","0.00000000"],["63117.70000000","0.00000000"],["63117.71000000","0.00018000"],["63117.72000000","0.00000000"],["63117.73000000","0.00000000"],["63117.86000000","0.00000000"],["63118.65000000","0.00000000"],["63118.68000000","0.00000000"],["63119.06000000","1.05852000"],["63119.07000000","0.00000000"],["63119.08000000","0.00000000"],["63119.12000000","0.00000000"],["63119.14000000","0.00000000"],["63119.16000000","0.00000000"],["63119.18000000","0.00000000"],["63119.35000000","0.00000000"],["63119.36000000","0.00000000"],["63119.64000000","0.02600000"],["63120.26000000","0.00000000"],["63120.46000000","0.03000000"],["63120.51000000","0.00000000"],["63120.76000000","0.00000000"],["63121.24000000","0.00018000"],["63121.25000000","0.00000000"],["63122.07000000","0.00792000"],["63122.08000000","0.00000000"],["63122.88000000","0.00000000"],["63122.91000000","0.00792000"],["63122.92000000","0.99782000"],["63122.93000000","0.00000000"],["63123.28000000","0.00000000"],["63123.80000000","0.00018000"],["63123.81000000","0.00000000"],["63123.88000000","0.00000000"],["63124.97000000","0.08000000"],["63124.99000000","0.00000000"],["63125.41000000","0.00000000"],["63125.42000000","0.00032000"],["63125.68000000","0.02000000"],["63125.72000000","0.00000000"],["63125.99000000","0.00400000"],["63126.29000000","0.46056000"],["63126.86000000","0.00018000"],["63127.46000000","0.19164000"],["63128.51000000","0.00000000"],["63128.58000000","0.00000000"],["63129.19000000","0.00000000"],["63129.63000000","0.00150000"],["63130.87000000","0.79318000"],["63131.58000000","0.01586000"],["63131.76000000","0.00400000"],["63131.78000000","0.00000000"],["63131.87000000","0.00000000"],["63133.03000000","0.00000000"],["63134.68000000","0.00000000"],["63135.64000000","0.38856000"],["63136.32000000","0.32709000"],["63136.66000000","0.00000000"],["63137.32000000","0.00000000"],["63137.33000000","0.00000000"],["63138.51000000","0.00000000"],["63139.50000000","0.00000000"],["63140.00000000","0.02358000"],["63140.55000000","0.00000000"],["63140.67000000","0.00000000"],["63140.68000000","0.00000000"],["63141.54000000","0.00400000"],["63142.00000000","0.03300000"],["63144.50000000","0.00000000"],["63144.65000000","0.57077000"],["63144.70000000","0.00400000"],["63145.18000000","0.00000000"],["63145.48000000","0.13636000"],["63154.34000000","0.00000000"],["63162.95000000","0.00000000"],["63165.00000000","0.00395000"],["63165.87000000","1.56911000"],["63175.04000000","0.00000000"],["63175.32000000","0.00000000"],["63175.67000000","0.00000000"],["63175.85000000","0.00000000"],["63176.55000000","0.00000000"],["63177.99000000","0.00379000"],["63180.24000000","3.48214000"],["63180.32000000","0.00000000"],["63180.86000000","0.00000000"],["63180.91000000","0.95174000"],["63181.06000000","0.00000000"],["63181.36000000","0.02035000"],["63185.50000000","0.00008000"],["63186.10000000","1.81162000"],["63186.11000000","3.16917000"],["63187.13000000","0.00000000"],["63198.12000000","0.00000000"],["63198.66000000","0.00000000"],["63199.09000000","0.00000000"],["63226.69000000","0.00000000"],["63229.09000000","0.00158000"],["63236.58000000","0.00000000"],["63240.95000000","0.00152000"]]}
{"e":"depthUpdate","E":1781816964914,"s":"BTCUSDT","U":96005706406,"u":96005706897,"b":[["63111.99000000","3.88498000"],["63111.98000000","0.00034000"],["63111.97000000","0.00016000"],["63111.75000000","0.00009000"],["63111.74000000","0.01585000"],["63111.52000000","0.00400000"],["63111.28000000","0.00000000"],["63110.48000000","0.00008000"],["63110.47000000","0.01585000"],["63110.39000000","0.00000000"],["63110.27000000","0.00000000"],["63110.26000000","0.00000000"],["63110.25000000","0.00000000"],["63110.16000000","0.00000000"],["63110.01000000","0.00018000"],["63110.00000000","0.05356000"],["63109.99000000","3.11398000"],["63109.98000000","0.93504000"],["63109.97000000","0.00000000"],["63109.49000000","0.04018000"],["63109.21000000","0.01585000"],["63109.16000000","0.00018000"],["63109.15000000","0.26018000"],["63108.27000000","0.33321000"],["63108.00000000","0.05036000"],["63107.99000000","1.09368000"],["63107.64000000","0.00000000"],["63107.63000000","0.00000000"],["63107.07000000","0.00110000"],["63106.64000000","0.00553000"],["63106.04000000","0.00552000"],["63106.01000000","0.00018000"],["63106.00000000","2.56730000"],["63105.99000000","0.68836000"],["63105.67000000","0.00400000"],["63105.21000000","0.00972000"],["63105.20000000","0.00400000"],["63104.96000000","0.00012000"],["63104.12000000","0.00008000"],["63103.87000000","0.00018000"],["63103.85000000","0.50047000"],["63103.68000000","0.00000000"],["63102.95000000","0.00000000"],["63102.72000000","0.00009000"],["63102.02000000","0.00018000"],["63100.66000000","0.00000000"],["63100.20000000","1.16623000"],["63098.26000000","0.00018000"],["63095.36000000","0.00300000"],["63092.95000000","0.00000000"],["63091.34000000","1.19835000"],["63086.24000000","0.00000000"],["63085.25000000","0.00000000"],["63084.45000000","0.00000000"],["63082.54000000","0.00018000"],["63081.75000000","0.25622000"],["63080.53000000","0.00000000"],["63080.00000000","0.08300000"],["63078.62000000","1.78501000"],["63076.45000000","0.46056000"],["63076.00000000","0.02300000"],["63068.37000000","0.00617000"],["63065.07000000","0.00428000"],["63060.48000000","0.01716000"],["63058.60000000","0.00000000"],["63053.68000000","0.00000000"],["63045.38000000","0.00000000"],["63033.45000000","0.00000000"],["63032.37000000","0.00000000"],["63027.62000000","0.16698000"],["63008.71000000","0.12264000"],["63000.01000000","0.80478000"],["62973.15000000","1.20000000"],["62959.19000000","0.00000000"],["62944.51000000","0.00000000"],["62941.59000000","0.00000000"],["62941.36000000","0.00000000"],["62938.01000000","0.00960000"],["62107.99000000","0.00000000"],["56800.80000000","0.00040000"]],"a":[["63110.00000000","0.00000000"],["63110.01000000","0.00000000"],["63110.17000000","0.00000000"],["63110.26000000","0.00000000"],["63110.27000000","0.00000000"],["63110.28000000","0.00000000"],["63110.40000000","0.00000000"],["63110.48000000","0.00000000"],["63111.29000000","0.00000000"],["63111.99000000","0.00000000"],["63112.00000000","0.16138000"],["63112.01000000","0.00081000"],["63112.25000000","0.00000000"],["63112.30000000","0.00000000"],["63112.85000000","0.00000000"],["63113.18000000","0.00018000"],["63113.19000000","0.03028000"],["63113.37000000","0.00109000"],["63113.47000000","0.00000000"],["63113.58000000","0.00000000"],["63114.00000000","0.02318000"],["63114.78000000","0.00000000"],["63115.41000000","0.00000000"],["63115.83000000","0.00000000"],["63115.89000000","0.00000000"],["63115.99000000","0.00036000"],["63116.00000000","0.02318000"],["63116.31000000","0.00000000"],["63117.03000000","0.00018000"],["63117.04000000","0.52378000"],["63117.11000000","0.00018000"],["63117.14000000","0.00018000"],["63117.73000000","0.00000000"],["63117.74000000","0.00018000"],["63117.77000000","0.00018000"],["63117.84000000","0.00000000"],["63118.32000000","0.00317000"],["63119.05000000","0.00000000"],["63119.06000000","0.00018000"],["63119.31000000","0.01585000"],["63119.42000000","0.00000000"],["63119.64000000","0.00000000"],["63119.67000000","0.00000000"],["63119.68000000","0.00009000"],["63120.26000000","0.04591000"],["63120.27000000","0.00000000"],["63120.57000000","0.01585000"],["63120.61000000","0.00000000"],["63120.90000000","0.00000000"],["63120.92000000","0.00000000"],["63120.93000000","0.00494000"],["63121.83000000","0.01585000"],["63122.07000000","0.00000000"],["63122.29000000","0.00187000"],["63122.64000000","0.00048000"],["63122.90000000","1.09772000"],["63122.91000000","3.17709000"],["63122.92000000","0.00018000"],["63123.38000000","0.07613000"],["63124.87000000","0.00792000"],["63125.99000000","0.00000000"],["63126.28000000","1.05834000"],["63127.46000000","0.00000000"],["63128.24000000","0.00400000"],["63129.31000000","0.14718000"],["63131.18000000","0.13955000"],["63131.58000000","0.00000000"],["63139.06000000","0.00000000"],["63140.59000000","1.19733000"],["63142.00000000","0.02300000"],["63143.12000000","0.00400000"],["63143.28000000","0.00008000"],["63143.89000000","1.67460000"],["63144.00000000","0.03300000"],["63144.83000000","0.00000000"],["63145.48000000","0.00000000"],["63145.60000000","0.00431000"],["63146.00000000","0.02300000"],["63147.41000000","0.00617000"],["63147.86000000","0.00400000"],["63149.73000000","0.00453000"],["63149.86000000","0.00436000"],["63152.42000000","0.62589000"],["63153.76000000","0.00023000"],["63162.24000000","0.06228000"],["63163.90000000","0.01145000"],["63179.55000000","2.07895000"],["63180.91000000","0.00000000"],["63181.17000000","0.95174000"],["63181.36000000","0.00000000"],["63181.88000000","0.00000000"],["63199.49000000","0.00000000"],["63199.84000000","0.00988000"],["63224.31000000","1.53472000"],["63255.19000000","0.00000000"],["63279.22000000","0.00008000"],["63282.37000000","0.00008000"]]}
{"e":"depthUpdate","E":1781816965014,"s":"BTCUSDT","U":96005706898,"u":96005707249,"b":[["63113.18000000","5.91420000"],["63113.17000000","0.00034000"],["63113.16000000","0.00016000"],["63113.10000000","0.00400000"],["63112.01000000","0.00018000"],["63112.00000000","1.24284000"],["63111.99000000","0.94356000"],["63111.98000000","0.00000000"],["63111.97000000","0.00000000"],["63111.75000000","0.00000000"],["63111.74000000","0.00018000"],["63110.47000000","0.01603000"],["63110.01000000","0.00009000"],["63110.00000000","0.05054000"],["63109.99000000","3.07698000"],["63109.49000000","0.00018000"],["63109.17000000","0.00858000"],["63109.16000000","0.00000000"],["63109.15000000","0.26008000"],["63108.28000000","0.00023000"],["63108.27000000","0.32622000"],["63108.01000000","0.00000000"],["63108.00000000","0.00018000"],["63107.99000000","0.89342000"],["63107.98000000","0.00000000"],["63106.02000000","0.00000000"],["63106.01000000","0.00894000"],["63105.99000000","0.66119000"],["63104.51000000","0.00000000"],["63103.86000000","1.62339000"],["63099.24000000","0.00031000"],["63095.68000000","0.00000000"],["63092.40000000","0.48347000"],["63092.05000000","0.57125000"],["63087.82000000","0.00000000"],["63087.76000000","0.00009000"],["63080.96000000","0.00000000"],["63076.63000000","0.00000000"],["63071.93000000","0.00000000"],["63034.40000000","0.00015000"],["63033.65000000","0.00998000"],["63023.38000000","0.04918000"],["63017.38000000","0.00000000"],["63015.22000000","0.00000000"],["62968.07000000","0.00000000"],["56801.87000000","0.00020000"],["56800.80000000","0.00000000"],["56800.00000000","33.80351000"],["50490.55000000","0.00039000"]],"a":[["63112.00000000","0.00000000"],["63112.01000000","0.00000000"],["63113.18000000","0.00000000"],["63113.19000000","0.13901000"],["63113.20000000","0.00081000"],["63117.04000000","0.52378000"],["63117.11000000","0.00000000"],["63117.14000000","0.00000000"],["63117.74000000","0.00000000"],["63117.77000000","0.00000000"],["63117.97000000","0.02886000"],["63118.00000000","0.02318000"],["63118.32000000","0.00000000"],["63118.57000000","0.00000000"],["63119.31000000","0.01603000"],["63119.47000000","0.00000000"],["63119.51000000","0.00317000"],["63119.68000000","0.00018000"],["63119.69000000","0.24768000"],["63119.70000000","0.03010000"],["63120.00000000","0.02368000"],["63120.06000000","0.00000000"],["63120.25000000","0.00027000"],["63120.26000000","0.08877000"],["63120.46000000","0.00000000"],["63120.75000000","0.10740000"],["63121.77000000","0.07000000"],["63121.83000000","0.00000000"],["63122.88000000","0.93954000"],["63122.89000000","3.62546000"],["63122.90000000","0.00000000"],["63122.91000000","0.00000000"],["63124.15000000","0.00792000"],["63124.87000000","0.00000000"],["63125.62000000","0.00792000"],["63126.28000000","0.00000000"],["63129.31000000","0.00000000"],["63130.86000000","0.13685000"],["63130.87000000","0.00018000"],["63132.12000000","0.00158000"],["63133.62000000","0.79297000"],["63144.00000000","0.02300000"],["63145.00000000","0.02095000"],["63146.66000000","0.00000000"],["63147.10000000","0.57075000"],["63147.70000000","0.13308000"],["63153.47000000","0.00000000"],["63155.13000000","0.00000000"],["63157.68000000","0.00000000"],["63158.44000000","0.00000000"],["63161.72000000","0.00000000"],["63168.21000000","0.09336000"],["63175.91000000","0.01159000"],["63182.54000000","0.00000000"],["63183.58000000","0.02032000"],["63199.84000000","0.00000000"],["63201.18000000","0.00000000"],["63204.56000000","0.00000000"],["63212.74000000","0.05106000"],["63216.46000000","0.00000000"],["63264.06000000","0.00000000"],["63610.85000000","0.00000000"],["63618.10000000","0.00029000"]]}
{"e":"depthUpdate","E":1781816965114,"s":"BTCUSDT","U":96005707250,"u":96005707413,"b":[["63113.18000000","5.97560000"],["63112.01000000","0.00036000"],["63112.00000000","0.05036000"],["63111.99000000","0.90403000"],["63111.74000000","0.00000000"],["63110.02000000","0.00009000"],["63110.01000000","1.18945000"],["63109.98000000","0.93504000"],["63109.49000000","0.00000000"],["63107.12000000","0.00000000"],["63106.52000000","0.00189000"],["63106.49000000","0.00000000"],["63105.99000000","0.66102000"],["63103.14000000","0.00018000"],["63102.00000000","0.02300000"],["63099.83000000","0.00018000"],["63099.25000000","0.00000000"],["63099.24000000","0.00000000"],["63098.26000000","0.00000000"],["63096.53000000","0.00008000"],["63093.12000000","0.00000000"],["63091.35000000","0.00018000"],["63091.34000000","1.19827000"],["63089.03000000","0.00000000"],["63082.54000000","0.00000000"],["63081.00000000","0.01000000"],["63080.00000000","0.07300000"],["63055.23000000","0.02000000"],["63048.76000000","0.02000000"],["63034.40000000","0.00000000"],["63033.97000000","0.00030000"],["63028.79000000","0.00000000"],["56801.87000000","0.00060000"]],"a":[["63113.19000000","0.13908000"],["63114.03000000","0.00009000"],["63119.69000000","0.24784000"],["63119.70000000","0.03028000"],["63120.00000000","0.02350000"],["63120.09000000","0.10020000"],["63120.10000000","0.12577000"],["63120.26000000","0.00000000"],["63120.75000000","0.00000000"],["63123.92000000","0.02000000"],["63123.95000000","0.02600000"],["63124.56000000","0.04800000"],["63124.58000000","0.04400000"],["63126.45000000","0.02600000"],["63127.08000000","0.04400000"],["63127.42000000","0.02600000"],["63127.71000000","0.05400000"],["63127.74000000","0.06600000"],["63129.22000000","0.00000000"],["63134.41000000","0.00008000"],["63160.47000000","0.00385000"],["63173.02000000","0.00110000"],["63175.21000000","0.02600000"],["63178.26000000","0.02000000"],["63178.89000000","0.02000000"],["63178.90000000","0.00000000"],["63178.92000000","0.00000000"],["63179.00000000","0.03400000"],["63179.68000000","0.02409000"],["63180.79000000","0.02600000"],["63181.42000000","0.04400000"],["63181.76000000","0.00000000"],["63182.05000000","0.02600000"],["63182.08000000","0.03200000"],["63186.56000000","0.00000000"],["63191.76000000","0.00030000"],["63223.63000000","0.00154000"]]}
{"e":"depthUpdate","E":1781816965214,"s":"BTCUSDT","U":96005707414,"u":96005707468,"b":[["63113.18000000","6.17903000"],["63111.99000000","0.65661000"],["63110.62000000","0.00009000"],["63110.61000000","0.13955000"],["63110.47000000","0.00018000"],["63110.27000000","0.00009000"],["63109.99000000","3.07680000"],["63106.88000000","0.01585000"],["63106.86000000","0.00400000"],["63105.67000000","0.00000000"],["63099.46000000","0.00000000"],["63098.88000000","0.00445000"],["63098.63000000","0.00554000"],["63037.66000000","0.00015000"],["56801.87000000","0.00100000"],["50490.55000000","0.00000000"]],"a":[["63113.19000000","0.14167000"],["63113.20000000","0.00090000"],["63117.04000000","0.52386000"],["63118.24000000","0.01585000"],["63119.29000000","0.00018000"],["63119.30000000","0.10631000"],["63119.69000000","0.24776000"],["63120.08000000","0.00000000"],["63120.09000000","0.05790000"],["63120.10000000","0.00000000"],["63120.25000000","0.00018000"],["63120.57000000","0.00000000"],["63120.64000000","0.00000000"],["63125.36000000","0.00009000"],["63128.24000000","0.00000000"],["63128.93000000","0.00400000"],["63181.42000000","0.02000000"]]}
{"e":"depthUpdate","E":1781816965314,"s":"BTCUSDT","U":96005707469,"u":96005707529,"b":[["63113.18000000","6.37911000"],["63111.99000000","0.65661000"],["63110.61000000","0.13973000"],["63110.47000000","0.00000000"],["63103.59000000","0.00400000"],["63102.36000000","0.60500000"],["63097.49000000","0.53914000"],["63094.43000000","0.00000000"],["63078.53000000","1.00778000"],["63037.66000000","0.00000000"],["56801.87000000","0.00120000"]],"a":[["63113.19000000","0.13909000"],["63113.36000000","0.00000000"],["63113.99000000","0.00036000"],["63114.98000000","0.00000000"],["63115.99000000","0.00018000"],["63117.03000000","0.00036000"],["63117.71000000","0.00000000"],["63117.85000000","0.00000000"],["63117.96000000","0.00018000"],["63118.00000000","0.02318000"],["63118.24000000","0.01603000"],["63119.06000000","0.00000000"],["63119.30000000","0.10649000"],["63119.68000000","0.00036000"],["63119.69000000","0.24758000"],["63119.70000000","0.03010000"],["63120.25000000","0.00000000"],["63120.51000000","0.00018000"],["63120.89000000","0.00000000"],["63121.24000000","0.00000000"],["63121.76000000","0.00018000"],["63122.43000000","0.07613000"],["63122.88000000","0.93972000"],["63122.92000000","0.00000000"],["63123.80000000","0.00000000"],["63124.55000000","0.00018000"],["63124.96000000","0.00018000"],["63126.43000000","0.00018000"],["63131.76000000","0.00000000"],["63133.61000000","0.00018000"],["63135.18000000","0.00400000"],["63136.32000000","0.32727000"],["63147.49000000","0.56208000"],["63166.47000000","1.08371000"],["63179.00000000","0.00000000"],["63182.05000000","0.00000000"]]}
{"e":"depthUpdate","E":1781816965414,"s":"BTCUSDT","U":96005707530,"u":96005707543,"b":[["63108.15000000","0.01585000"],["63037.64000000","0.00015000"],["56801.87000000","0.00160000"]],"a":[["63116.98000000","0.01585000"],["63122.43000000","0.00000000"],["63160.47000000","0.00385000"],["63175.21000000","0.00000000"],["63179.68000000","0.00009000"],["63181.42000000","0.00000000"],["63182.08000000","0.00000000"],["63223.63000000","0.00154000"]]}
{"e":"depthUpdate","E":1781816965514,"s":"BTCUSDT","U":96005707544,"u":96005707564,"b":[["63109.98000000","0.94478000"],["63107.99000000","0.89332000"],["63048.60000000","0.00000000"],["62950.30000000","0.00960000"],["62938.01000000","0.00000000"],["56801.87000000","0.00200000"],["50490.55000000","0.00039000"]],"a":[["63116.00000000","0.02318000"],["63116.98000000","0.01603000"],["63119.31000000","0.01585000"],["63120.93000000","0.08107000"],["63178.26000000","0.00000000"],["63178.89000000","0.00000000"],["63180.79000000","0.00000000"],["63201.38000000","0.00981000"],["63675.96000000","0.00000000"]]}
{"e":"depthUpdate","E":1781816965614,"s":"BTCUSDT","U":96005707565,"u":96005707588,"b":[["63094.25000000","0.00015000"],["63087.06000000","0.00000000"],["63075.31000000","0.00015000"],["63068.13000000","0.00000000"],["63056.38000000","0.00015000"],["63049.19000000","0.00000000"],["63037.44000000","0.00024000"],["63030.26000000","0.00079000"],["63018.51000000","0.00015000"],["63011.33000000","0.00000000"],["56801.87000000","0.00240000"],["50490.55000000","0.00000000"]],"a":[["63115.01000000","0.00421000"],["63124.93000000","0.00000000"],["63132.12000000","0.00173000"],["63143.86000000","0.00000000"],["63151.06000000","0.00015000"],["63162.80000000","0.00000000"],["63169.99000000","0.00015000"],["63181.73000000","0.00000000"],["63188.93000000","0.00015000"],["63200.66000000","0.00000000"],["63207.86000000","0.00015000"]]}
{"e":"depthUpdate","E":1781816965714,"s":"BTCUSDT","U":96005707589,"u":96005707603,"b":[["63106.86000000","0.00700000"],["63100.12000000","0.00008000"],["63095.36000000","0.00000000"],["56801.87000000","0.00280000"]],"a":[["63113.19000000","0.13918000"],["63113.20000000","0.00099000"],["63115.29000000","0.00009000"],["63120.63000000","0.00000000"],["63122.86000000","1.29763000"],["63122.87000000","2.56712000"],["63122.88000000","0.00018000"],["63122.89000000","1.05834000"],["63125.82000000","0.00300000"],["63130.08000000","0.00009000"]]}
{"e":"depthUpdate","E":1781816965814,"s":"BTCUSDT","U":96005707604,"u":96005707908,"b":[["63115.14000000","4.41156000"],["63115.13000000","0.00016000"],["63115.12000000","0.00016000"],["63115.00000000","0.00018000"],["63114.23000000","0.11323000"],["63113.99000000","0.00000000"],["63113.98000000","0.00000000"],["63113.76000000","0.00008000"],["63113.75000000","0.00000000"],["63113.68000000","2.56712000"],["63113.36000000","0.00000000"],["63113.19000000","0.05338000"],["63113.18000000","1.59672000"],["63113.17000000","0.00000000"],["63113.16000000","0.00000000"],["63112.01000000","0.00018000"],["63111.98000000","0.00032000"],["63110.62000000","0.00000000"],["63110.02000000","0.00000000"],["63110.01000000","1.18963000"],["63110.00000000","0.05536000"],["63109.99000000","3.02680000"],["63109.74000000","0.00008000"],["63108.15000000","0.00000000"],["63108.00000000","0.00518000"],["63107.99000000","0.89031000"],["63107.21000000","0.00008000"],["63106.88000000","0.00000000"],["63106.86000000","0.00300000"],["63106.56000000","0.00009000"],["63106.00000000","2.57230000"],["63104.84000000","0.01586000"],["63092.40000000","0.00000000"],["63088.87000000","0.13596000"],["63088.64000000","0.23037000"],["63052.02000000","0.00018000"],["63051.95000000","0.02118000"],["63044.88000000","0.00000000"],["63034.05000000","0.00000000"],["62988.91000000","0.00018000"],["62981.77000000","0.00000000"],["62925.79000000","0.00018000"],["62918.67000000","0.00000000"],["62862.68000000","0.00018000"],["62855.56000000","0.00000000"],["62799.56000000","0.00018000"],["62792.45000000","0.00000000"],["62736.45000000","0.00018000"],["62729.34000000","0.00000000"],["62673.33000000","0.00018000"],["62666.23000000","0.00000000"],["62610.22000000","0.00018000"],["62603.13000000","0.00000000"],["56801.87000000","0.00009000"],["56797.19000000","0.00000000"],["50490.54000000","0.00000000"]],"a":[["63113.19000000","0.00000000"],["63113.20000000","0.00000000"],["63113.37000000","0.00000000"],["63113.76000000","0.00000000"],["63113.99000000","0.00000000"],["63114.00000000","0.00000000"],["63114.03000000","0.00000000"],["63114.24000000","0.00000000"],["63115.01000000","0.00000000"],["63115.15000000","0.26088000"],["63115.16000000","0.00097000"],["63115.17000000","0.00016000"],["63116.62000000","0.00000000"],["63116.73000000","0.00000000"],["63116.98000000","0.00018000"],["63117.87000000","0.00000000"],["63118.24000000","0.00018000"],["63118.30000000","0.00032000"],["63119.31000000","0.01603000"],["63119.51000000","0.00000000"],["63120.08000000","0.00009000"],["63120.09000000","0.05798000"],["63120.93000000","0.08115000"],["63121.43000000","0.00000000"],["63121.47000000","0.00000000"],["63127.63000000","0.00009000"],["63128.93000000","0.00000000"],["63135.89000000","0.00000000"],["63145.00000000","0.01095000"],["63146.56000000","0.00008000"],["63147.70000000","0.00000000"],["63148.80000000","0.00009000"],["63171.11000000","0.00000000"],["63178.27000000","0.00018000"],["63183.58000000","0.00000000"],["63201.38000000","0.00000000"],["63210.24000000","0.00009000"],["63234.22000000","0.00000000"],["63241.38000000","0.00018000"],["63286.49000000","0.00008000"],["63289.64000000","0.00008000"],["63297.32000000","0.00000000"],["63304.50000000","0.00018000"],["63360.43000000","0.00000000"],["63367.61000000","0.00018000"],["63423.54000000","0.00000000"],["63430.73000000","0.00018000"],["63486.65000000","0.00000000"],["63493.84000000","0.00018000"],["63549.76000000","0.00000000"],["63556.96000000","0.00030000"]]}
{"e":"depthUpdate","E":1781816965914,"s":"BTCUSDT","U":96005707909,"u":96005708198,"b":[["63115.14000000","4.34855000"],["63115.00000000","0.00000000"],["63114.68000000","0.00400000"],["63114.24000000","0.00018000"],["63114.23000000","0.11365000"],["63113.71000000","0.00018000"],["63113.70000000","0.94617000"],["63113.69000000","0.00036000"],["63113.68000000","2.56730000"],["63113.20000000","0.00018000"],["63113.19000000","0.19977000"],["63113.18000000","1.12579000"],["63112.01000000","0.00000000"],["63112.00000000","0.05036000"],["63110.02000000","1.18949000"],["63110.01000000","0.00018000"],["63110.00000000","0.60724000"],["63109.99000000","3.02662000"],["63109.98000000","0.94460000"],["63109.21000000","0.00000000"],["63108.00000000","0.01318000"],["63107.27000000","0.00008000"],["63106.00000000","2.58030000"],["63105.99000000","0.66086000"],["63104.66000000","0.16003000"],["63104.00000000","0.02300000"],["63103.14000000","0.00000000"],["63103.09000000","0.00018000"],["63103.08000000","0.16003000"],["63100.21000000","0.46074000"],["63100.20000000","0.82132000"],["63099.83000000","0.00000000"],["63099.82000000","0.00000000"],["63098.25000000","0.00000000"],["63097.50000000","0.00018000"],["63096.76000000","0.13535000"],["63095.21000000","0.00000000"],["63094.54000000","0.48381000"],["63090.07000000","0.00000000"],["63089.40000000","0.00000000"],["63086.90000000","0.15713000"],["63083.00000000","0.01000000"],["63082.51000000","0.00018000"],["63081.75000000","0.67985000"],["63081.00000000","0.00000000"],["63078.48000000","0.00000000"],["63073.01000000","0.15716000"],["63070.00000000","0.02783000"],["63069.86000000","1.85158000"],["63064.59000000","0.00000000"],["63060.59000000","0.00000000"],["63038.76000000","0.04647000"],["63037.64000000","0.00000000"],["63029.86000000","0.00000000"],["63027.62000000","0.00000000"],["63026.07000000","0.00000000"],["63024.47000000","0.00000000"],["63021.38000000","0.00000000"],["63017.62000000","0.00000000"],["63014.88000000","0.00000000"],["63008.71000000","0.00000000"],["63000.01000000","0.46056000"],["62977.95000000","0.02481000"],["62946.37000000","0.00000000"],["56803.63000000","0.00020000"]],"a":[["63115.15000000","0.14239000"],["63115.16000000","0.00097000"],["63116.00000000","0.02318000"],["63116.98000000","0.00000000"],["63118.00000000","0.02318000"],["63118.24000000","0.00000000"],["63119.31000000","0.00018000"],["63119.68000000","0.00018000"],["63119.69000000","0.00026000"],["63119.70000000","0.03028000"],["63120.08000000","0.00018000"],["63120.92000000","0.00009000"],["63121.00000000","0.00000000"],["63125.62000000","0.00000000"],["63126.28000000","0.00793000"],["63127.48000000","0.15997000"],["63129.06000000","0.15997000"],["63133.63000000","0.00000000"],["63134.87000000","0.00000000"],["63141.91000000","1.74410000"],["63146.01000000","0.00012000"],["63147.00000000","0.01000000"],["63147.52000000","0.00000000"],["63148.34000000","0.00000000"],["63149.44000000","0.00400000"],["63183.62000000","0.05150000"],["63184.22000000","0.00000000"],["63202.02000000","0.00000000"],["63222.16000000","1.42255000"],["63229.09000000","0.13918000"],["63231.91000000","0.07616000"],["63233.56000000","0.05908000"],["63236.40000000","1.50323000"],["63276.11000000","0.24750000"],["63284.40000000","0.00008000"],["63286.49000000","0.00000000"],["63289.64000000","0.00000000"]]}
{"e":"depthUpdate","E":1781816966014,"s":"BTCUSDT","U":96005708199,"u":96005708274,"b":[["63115.14000000","4.36440000"],["63114.69000000","0.00792000"],["63114.23000000","0.11365000"],["63114.06000000","0.01585000"],["63113.71000000","1.18964000"],["63113.70000000","0.94635000"],["63113.19000000","0.19981000"],["63113.18000000","0.87037000"],["63112.80000000","0.01585000"],["63110.61000000","0.13973000"],["63110.02000000","0.00000000"],["63110.01000000","0.00000000"],["63110.00000000","0.60720000"],["63106.55000000","0.00000000"],["63080.87000000","0.01155000"],["63063.39000000","0.00000000"],["63040.55000000","0.00015000"],["63029.73000000","2.89209000"],["63025.49000000","0.00000000"],["58064.29000000","0.00018000"],["56803.63000000","0.00060000"],["50492.12000000","0.00039000"]],"a":[["63119.30000000","0.10649000"],["63119.31000000","0.00000000"],["63119.69000000","0.00008000"],["63120.00000000","0.02368000"],["63120.09000000","0.05816000"],["63122.90000000","0.01585000"],["63124.15000000","0.00000000"],["63124.16000000","0.01985000"],["63125.13000000","0.00792000"],["63125.42000000","0.01617000"]]}
{"e":"depthUpdate","E":1781816966114,"s":"BTCUSDT","U":96005708275,"u":96005708332,"b":[["63115.14000000","4.34873000"],["63114.69000000","0.00018000"],["63114.23000000","0.11365000"],["63114.06000000","0.01603000"],["63113.77000000","0.00792000"],["63113.73000000","0.00018000"],["63113.72000000","1.18946000"],["63113.71000000","0.00036000"],["63113.20000000","0.00009000"],["63113.19000000","0.43179000"],["63113.18000000","0.87019000"],["63112.00000000","0.05018000"],["63111.99000000","0.65643000"],["63110.61000000","0.13955000"],["63110.01000000","0.00000000"],["63110.00000000","1.29014000"],["63107.99000000","0.89023000"],["63102.51000000","0.00272000"],["63091.37000000","0.00000000"],["63032.12000000","0.00000000"],["56803.63000000","0.00100000"],["56803.00000000","0.08337000"]],"a":[["63115.15000000","0.77202000"],["63121.47000000","0.00316000"]]}
{"e":"depthUpdate","E":1781816966214,"s":"BTCUSDT","U":96005708333,"u":96005708357,"b":[["63114.69000000","0.00000000"],["63114.06000000","0.01603000"],["63113.77000000","0.00810000"],["63113.72000000","1.18964000"],["63113.71000000","0.00018000"],["63113.41000000","0.00009000"],["63103.78000000","0.02600000"],["63103.59000000","0.00000000"],["63098.49000000","0.00008000"],["63096.53000000","0.00000000"],["56803.63000000","0.00140000"],["50492.12000000","0.00000000"]],"a":[["63134.41000000","0.00000000"],["63135.18000000","0.00000000"],["63135.69000000","0.00400000"],["63136.37000000","0.00008000"],["63146.28000000","0.00400000"],["63149.44000000","0.00000000"]]}
{"e":"depthUpdate","E":1781816966314,"s":"BTCUSDT","U":96005708358,"u":96005708394,"b":[["63110.27000000","0.00000000"],["63098.13000000","0.00000000"],["63040.55000000","0.00000000"],["56803.63000000","0.00180000"]],"a":[["63115.15000000","0.77202000"],["63115.16000000","0.00097000"],["63115.27000000","0.00018000"],["63115.28000000","0.52345000"],["63115.29000000","0.00000000"],["63115.99000000","0.00000000"],["63117.03000000","0.00018000"],["63117.04000000","0.00042000"],["63117.81000000","0.00009000"],["63117.96000000","0.00000000"],["63119.29000000","0.00036000"],["63119.68000000","0.00000000"],["63120.08000000","0.00036000"],["63120.51000000","0.00000000"],["63120.92000000","0.00036000"],["63121.76000000","0.00027000"],["63122.86000000","1.29781000"],["63124.55000000","0.00000000"],["63125.62000000","0.00018000"],["63132.31000000","0.00018000"],["63133.61000000","0.00000000"],["63136.32000000","0.32709000"],["63141.51000000","0.02886000"],["63143.24000000","0.00018000"]]}
{"e":"depthUpdate","E":1781816966414,"s":"BTCUSDT","U":96005708395,"u":96005708428,"b":[["63115.14000000","4.34882000"],["63114.72000000","0.00018000"],["63114.71000000","0.01585000"],["63113.20000000","0.00000000"],["63113.19000000","0.43170000"],["63076.01000000","0.00394000"],["63071.03000000","0.00000000"],["63063.91000000","0.00396000"],["63058.66000000","0.00000000"],["63040.06000000","0.00015000"],["63013.30000000","0.00158000"],["63008.01000000","0.00000000"],["63000.16000000","0.00158000"],["62994.68000000","0.00000000"],["56803.63000000","0.00220000"]],"a":[["63115.15000000","0.77202000"],["63115.28000000","0.52363000"],["63116.00000000","0.02318000"],["63117.04000000","0.00175000"],["63148.44000000","0.13405000"],["63163.50000000","0.00275000"],["63165.00000000","0.00000000"],["63169.99000000","0.00411000"],["63177.99000000","0.00000000"],["63183.05000000","0.00379000"],["63184.32000000","0.02127000"],["63202.12000000","0.00987000"],["63229.09000000","0.13760000"],["63233.55000000","0.00158000"],["63240.95000000","0.00000000"],["63245.67000000","0.00152000"]]}
{"e":"depthUpdate","E":1781816966514,"s":"BTCUSDT","U":96005708429,"u":96005708436,"b":[["63115.14000000","4.34892000"],["63040.06000000","0.00000000"],["58064.29000000","0.00000000"],["56803.63000000","0.00260000"],["50492.12000000","0.00039000"]],"a":[["63115.15000000","0.77177000"],["63683.18000000","0.00010000"]]}
{"e":"depthUpdate","E":1781816966614,"s":"BTCUSDT","U":96005708437,"u":96005708442,"b":[["63115.14000000","4.34917000"],["63039.53000000","0.00015000"],["56803.63000000","0.00280000"],["50492.12000000","0.00000000"],["33000.00000000","41.15112000"]],"a":[["63263.02000000","0.02481000"]]}
{"e":"depthUpdate","E":1781816966714,"s":"BTCUSDT","U":96005708443,"u":96005708448,"b":[["62874.22000000","0.02481000"],["62840.97000000","0.00000000"],["56803.63000000","0.00320000"],["33000.00000000","41.15052000"]],"a":[["77809.74000000","0.00019000"]]}
{"e":"depthUpdate","E":1781816966814,"s":"BTCUSDT","U":96005708449,"u":96005708466,"b":[["63111.52000000","0.01280000"],["63103.78000000","0.02200000"],["63103.74000000","0.00400000"],["63012.16000000","0.00000000"],["63011.95000000","0.00068000"],["56803.63000000","0.00350000"],["50492.11000000","0.00000000"]],"a":[["63116.55000000","0.00009000"],["63117.04000000","0.00024000"],["63123.38000000","0.00000000"],["63135.69000000","0.00000000"],["63135.74000000","0.00400000"],["63192.80000000","0.00008000"],["63252.61000000","0.00000000"],["63256.60000000","0.00068000"]]}
{"e":"depthUpdate","E":1781816966914,"s":"BTCUSDT","U":96005708467,"u":96005708469,"b":[["56803.63000000","0.00380000"]],"a":[]}
{"e":"depthUpdate","E":1781816967014,"s":"BTCUSDT","U":96005708470,"u":96005708483,"b":[["63114.24000000","0.00036000"],["63113.36000000","0.00219000"],["63113.19000000","0.43188000"],["63112.00000000","0.05000000"],["63106.00000000","2.58012000"],["63104.67000000","0.00018000"],["63103.09000000","0.00000000"],["63102.37000000","0.00018000"],["63097.50000000","0.00000000"],["63096.05000000","0.00018000"],["63082.51000000","0.00000000"],["56803.63000000","0.00420000"],["50492.12000000","0.00039000"]],"a":[]}
{"e":"depthUpdate","E":1781816967114,"s":"BTCUSDT","U":96005708484,"u":96005708504,"b":[["63112.00000000","0.06000000"],["63110.00000000","1.30014000"],["63108.00000000","0.02318000"],["63106.00000000","2.58412000"],["63103.74000000","0.00000000"],["63103.69000000","0.00400000"],["63035.93000000","0.00030000"],["63033.97000000","0.00000000"],["56803.63000000","0.00440000"],["56803.00000000","0.08337000"]],"a":[["63117.03000000","0.00176000"],["63135.70000000","0.00400000"],["63135.74000000","0.00000000"],["63191.76000000","0.00000000"],["63193.72000000","0.00030000"]]}
{"e":"depthUpdate","E":1781816967214,"s":"BTCUSDT","U":96005708505,"u":96005708515,"b":[["63111.52000000","0.01325000"],["63106.00000000","2.59012000"],["63098.88000000","0.00409000"],["63098.49000000","0.00008000"],["56803.63000000","0.00440000"],["50492.12000000","0.00000000"]],"a":[["63136.37000000","0.00008000"]]}
{"e":"depthUpdate","E":1781816967314,"s":"BTCUSDT","U":96005708516,"u":96005708527,"b":[["56803.63000000","0.00420000"]],"a":[["63115.27000000","0.00036000"],["63117.03000000","0.00158000"],["63125.62000000","0.00000000"],["63125.99000000","0.00018000"],["63126.43000000","0.00000000"],["63127.47000000","0.03920000"],["63132.31000000","0.00000000"],["63133.23000000","0.01586000"],["63138.99000000","0.00018000"]]}
{"e":"depthUpdate","E":1781816967414,"s":"BTCUSDT","U":96005708528,"u":96005708531,"b":[["56803.63000000","0.00420000"]],"a":[]}
{"e":"depthUpdate","E":1781816967514,"s":"BTCUSDT","U":96005708532,"u":96005708538,"b":[["63065.35000000","0.04757000"],["63032.54000000","0.00000000"],["56803.63000000","0.00420000"],["50492.12000000","0.00039000"]],"a":[]}
{"e":"depthUpdate","E":1781816967614,"s":"BTCUSDT","U":96005708539,"u":96005709731,"b":[["63117.99000000","5.51602000"],["63117.98000000","0.00034000"],["63117.97000000","0.00016000"],["63117.96000000","0.53083000"],["63117.95000000","0.00000000"],["63117.94000000","0.00000000"],["63117.84000000","0.00400000"],["63117.80000000","0.00000000"],["63117.29000000","0.00000000"],["63117.04000000","0.00008000"],["63117.03000000","0.00000000"],["63117.02000000","0.00000000"],["63116.87000000","0.00000000"],["63116.54000000","0.00000000"],["63116.26000000","0.00400000"],["63116.00000000","0.00059000"],["63115.99000000","1.70908000"],["63115.98000000","0.00000000"],["63115.97000000","0.00000000"],["63115.28000000","0.00000000"],["63115.27000000","0.42468000"],["63115.26000000","0.00000000"],["63115.25000000","0.00000000"],["63115.16000000","0.00000000"],["63115.15000000","0.00334000"],["63115.14000000","0.34418000"],["63115.13000000","0.00000000"],["63115.12000000","0.00000000"],["63114.72000000","0.00000000"],["63114.71000000","0.00000000"],["63114.24000000","0.00000000"],["63114.23000000","0.00034000"],["63114.06000000","0.00018000"],["63113.77000000","0.00018000"],["63113.73000000","0.00018000"],["63113.72000000","0.00000000"],["63113.71000000","0.00000000"],["63113.70000000","0.00000000"],["63113.69000000","0.00018000"],["63113.68000000","2.56712000"],["63113.20000000","0.00552000"],["63113.19000000","0.42832000"],["63113.18000000","0.87867000"],["63112.80000000","0.00000000"],["63112.26000000","0.00008000"],["63111.28000000","0.00012000"],["63110.61000000","0.13963000"],["63110.45000000","0.00010000"],["63110.09000000","0.00008000"],["63110.01000000","0.00018000"],["63109.99000000","3.02533000"],["63109.15000000","0.00008000"],["63108.27000000","0.24606000"],["63107.99000000","0.73446000"],["63106.87000000","0.46056000"],["63106.04000000","0.00000000"],["63104.84000000","0.00000000"],["63101.23000000","0.38853000"],["63099.96000000","0.00000000"],["63096.05000000","0.00000000"],["63095.70000000","0.57122000"],["63095.21000000","0.00018000"],["63094.03000000","0.00000000"],["63093.11000000","0.00000000"],["63092.56000000","0.00000000"],["63092.14000000","0.00000000"],["63091.35000000","0.00000000"],["63091.34000000","0.00000000"],["63090.98000000","0.00000000"],["63089.57000000","0.00000000"],["63088.06000000","1.57104000"],["63085.06000000","0.00000000"],["63084.24000000","0.00000000"],["63083.02000000","0.00008000"],["63080.48000000","0.00000000"],["63079.73000000","0.00475000"],["63075.91000000","0.00000000"],["63075.27000000","0.58699000"],["63073.62000000","0.36948000"],["63070.72000000","0.00000000"],["63064.78000000","0.28075000"],["63064.73000000","0.95170000"],["63060.06000000","0.01073000"],["63058.46000000","0.00000000"],["63057.76000000","0.00000000"],["63056.49000000","0.02126000"],["63054.09000000","0.00792000"],["63053.03000000","0.00751000"],["63051.95000000","0.00000000"],["63047.09000000","0.00000000"],["63046.50000000","0.05746000"],["63046.49000000","0.00000000"],["63045.59000000","0.00000000"],["63038.84000000","0.00751000"],["63032.12000000","0.21297000"],["63014.88000000","0.00000000"],["62948.48000000","0.00000000"],["62904.65000000","0.00000000"],["62863.73000000","0.00000000"],["62495.72000000","1.18928000"],["56806.17000000","0.00000000"],["56803.75000000","0.00000000"],["56803.63000000","0.00009000"],["56801.87000000","0.00000000"],["50492.12000000","0.00000000"]],"a":[["63115.15000000","0.00000000"],["63115.16000000","0.00000000"],["63115.17000000","0.00000000"],["63115.27000000","0.00000000"],["63115.28000000","0.00000000"],["63115.29000000","0.00000000"],["63115.99000000","0.00000000"],["63116.00000000","0.00000000"],["63116.01000000","0.00000000"],["63116.55000000","0.00000000"],["63116.88000000","0.00000000"],["63117.03000000","0.00000000"],["63117.04000000","0.00000000"],["63117.30000000","0.00000000"],["63117.81000000","0.00000000"],["63117.96000000","0.00000000"],["63117.97000000","0.00000000"],["63117.98000000","0.00000000"],["63117.99000000","0.00000000"],["63118.00000000","0.02541000"],["63118.01000000","0.00081000"],["63118.19000000","0.00000000"],["63118.30000000","0.00000000"],["63119.16000000","0.00008000"],["63119.29000000","0.00018000"],["63119.30000000","0.00018000"],["63119.57000000","0.00000000"],["63119.69000000","0.00026000"],["63119.83000000","0.00000000"],["63119.99000000","0.00018000"],["63120.08000000","0.00018000"],["63120.09000000","0.00026000"],["63120.51000000","0.00000000"],["63120.52000000","0.00018000"],["63120.68000000","0.00549000"],["63120.92000000","0.00018000"],["63120.93000000","0.00512000"],["63121.36000000","0.00581000"],["63121.47000000","0.00000000"],["63121.59000000","0.00000000"],["63121.60000000","0.00000000"],["63121.76000000","0.00018000"],["63121.77000000","0.00000000"],["63121.84000000","0.00000000"],["63121.89000000","0.00000000"],["63121.99000000","0.00239000"],["63122.32000000","0.00158000"],["63122.43000000","0.00000000"],["63122.58000000","0.00000000"],["63122.84000000","0.00008000"],["63122.85000000","0.00000000"],["63122.86000000","0.00018000"],["63122.87000000","0.00000000"],["63122.89000000","0.00000000"],["63122.90000000","0.00000000"],["63123.09000000","0.00018000"],["63123.24000000","0.00000000"],["63123.71000000","0.00996000"],["63123.91000000","0.00009000"],["63123.92000000","0.00000000"],["63123.95000000","0.00000000"],["63123.99000000","0.13341000"],["63124.16000000","0.00000000"],["63124.29000000","0.00000000"],["63124.32000000","0.00317000"],["63124.56000000","0.00000000"],["63124.58000000","0.00000000"],["63124.97000000","0.00000000"],["63125.13000000","0.00000000"],["63125.42000000","0.00032000"],["63125.68000000","0.00000000"],["63126.05000000","0.00000000"],["63126.27000000","1.10893000"],["63126.28000000","2.56712000"],["63126.29000000","0.00000000"],["63126.30000000","0.00000000"],["63126.44000000","0.00000000"],["63126.45000000","0.00000000"],["63126.87000000","0.00000000"],["63127.08000000","0.00000000"],["63127.39000000","0.00000000"],["63127.42000000","0.00000000"],["63127.47000000","0.00026000"],["63127.56000000","0.01585000"],["63127.57000000","0.06000000"],["63127.71000000","0.00000000"],["63127.74000000","0.00000000"],["63128.59000000","0.00000000"],["63128.89000000","0.00000000"],["63129.00000000","0.46074000"],["63129.01000000","0.00008000"],["63129.07000000","0.01008000"],["63129.31000000","0.00792000"],["63129.32000000","0.83400000"],["63129.53000000","0.00000000"],["63129.59000000","0.00000000"],["63130.03000000","0.00965000"],["63130.63000000","2.56712000"],["63130.86000000","0.00000000"],["63130.88000000","0.00000000"],["63131.17000000","0.00792000"],["63131.87000000","0.00000000"],["63132.69000000","0.02000000"],["63133.12000000","1.63921000"],["63133.23000000","0.00000000"],["63133.26000000","2.56712000"],["63133.62000000","0.00000000"],["63133.97000000","0.08000000"],["63133.99000000","0.00000000"],["63134.45000000","3.19749000"],["63134.46000000","0.00000000"],["63134.85000000","0.00000000"],["63135.63000000","0.00000000"],["63135.64000000","0.00000000"],["63135.70000000","0.00000000"],["63135.85000000","2.56712000"],["63136.02000000","0.71189000"],["63136.03000000","1.05834000"],["63136.04000000","0.00000000"],["63136.30000000","0.00000000"],["63136.31000000","0.00000000"],["63136.32000000","0.00000000"],["63136.35000000","0.00961000"],["63137.99000000","0.35645000"],["63138.19000000","0.00000000"],["63138.20000000","0.00317000"],["63138.99000000","0.00018000"],["63140.58000000","0.79289000"],["63140.59000000","0.00000000"],["63140.64000000","0.00400000"],["63142.49000000","0.00000000"],["63142.55000000","0.00000000"],["63142.67000000","0.00981000"],["63143.82000000","0.00000000"],["63143.90000000","0.38850000"],["63145.56000000","0.99535000"],["63147.00000000","0.00000000"],["63147.49000000","0.00000000"],["63147.91000000","0.00000000"],["63148.00000000","0.02300000"],["63148.44000000","0.00000000"],["63148.99000000","0.00949000"],["63150.00000000","0.09715000"],["63151.02000000","0.00400000"],["63151.46000000","0.00000000"],["63151.56000000","0.00000000"],["63152.12000000","0.00000000"],["63152.60000000","0.00400000"],["63152.78000000","0.00000000"],["63153.01000000","0.01503000"],["63153.03000000","0.00000000"],["63153.44000000","0.13365000"],["63154.44000000","0.00751000"],["63155.42000000","0.00191000"],["63155.99000000","0.57067000"],["63157.62000000","0.52257000"],["63159.28000000","0.00000000"],["63160.47000000","0.00000000"],["63162.24000000","0.06228000"],["63163.25000000","0.00000000"],["63163.39000000","0.00000000"],["63163.47000000","0.00000000"],["63163.50000000","0.00000000"],["63165.62000000","0.00385000"],["63166.47000000","0.00000000"],["63166.90000000","0.47493000"],["63169.28000000","0.00000000"],["63170.72000000","0.86551000"],["63171.46000000","0.00000000"],["63174.35000000","1.56890000"],["63181.17000000","0.00000000"],["63181.50000000","0.00000000"],["63182.38000000","0.00000000"],["63183.13000000","0.03524000"],["63183.14000000","0.00000000"],["63183.62000000","0.00000000"],["63184.32000000","0.00000000"],["63184.33000000","0.00000000"],["63185.91000000","0.00000000"],["63187.20000000","0.95167000"],["63187.21000000","0.00000000"],["63187.38000000","0.00000000"],["63187.54000000","0.00000000"],["63188.30000000","0.00000000"],["63188.67000000","0.00000000"],["63188.92000000","0.00000000"],["63193.68000000","1.79468000"],["63193.69000000","3.16881000"],["63193.99000000","0.00000000"],["63199.99000000","1.14839000"],["63201.27000000","3.16881000"],["63201.87000000","2.56712000"],["63202.12000000","0.00000000"],["63203.71000000","0.00000000"],["63204.26000000","0.04571000"],["63205.11000000","0.00000000"],["63205.25000000","0.00000000"],["63205.80000000","0.00000000"],["63206.47000000","0.00000000"],["63206.72000000","0.00000000"],["63223.63000000","0.00000000"],["63229.08000000","0.00154000"],["63241.58000000","1.92627000"],["63241.59000000","0.00000000"],["63241.86000000","0.00000000"],["63242.24000000","6.45117000"],["63242.49000000","0.00000000"],["63263.02000000","0.00000000"],["63270.19000000","0.00000000"],["63270.35000000","0.00000000"],["63286.50000000","0.00008000"],["63289.65000000","0.00008000"],["63309.35000000","0.01935000"],["63309.77000000","0.01895000"]]}
{"e":"depthUpdate","E":1781816967714,"s":"BTCUSDT","U":96005709732,"u":96005710022,"b":[["63117.99000000","5.80165000"],["63117.97000000","0.00034000"],["63117.96000000","0.49748000"],["63116.01000000","0.00018000"],["63116.00000000","1.18992000"],["63115.99000000","1.15158000"],["63115.28000000","0.00018000"],["63115.15000000","0.00041000"],["63115.14000000","0.32418000"],["63114.23000000","0.00016000"],["63114.06000000","0.00000000"],["63113.77000000","0.00000000"],["63113.73000000","0.00000000"],["63113.68000000","2.56730000"],["63113.20000000","0.00570000"],["63113.19000000","0.42850000"],["63113.18000000","0.88612000"],["63112.00000000","0.06018000"],["63111.67000000","0.00300000"],["63110.61000000","0.13955000"],["63110.01000000","0.00000000"],["63108.90000000","0.16002000"],["63107.32000000","0.16002000"],["63106.89000000","1.94198000"],["63106.88000000","3.16881000"],["63106.03000000","0.00000000"],["63105.34000000","0.00044000"],["63104.66000000","0.00000000"],["63103.08000000","0.00000000"],["63099.85000000","1.19811000"],["63099.67000000","0.00000000"],["63096.76000000","0.00000000"],["63086.00000000","0.03312000"],["63083.00000000","0.00000000"],["63072.61000000","0.00426000"],["63064.78000000","0.37603000"],["63061.98000000","2.81723000"],["63060.70000000","0.00000000"],["63053.17000000","0.80742000"],["63053.16000000","0.00000000"],["63037.79000000","0.04606000"],["63029.74000000","0.00000000"],["63023.38000000","0.00000000"],["63018.14000000","0.00000000"],["62905.05000000","0.10000000"],["62495.72000000","0.00000000"],["56806.20000000","0.00040000"]],"a":[["63118.00000000","0.16247000"],["63118.63000000","0.00000000"],["63119.30000000","0.00000000"],["63120.00000000","0.02368000"],["63120.09000000","0.00008000"],["63120.52000000","0.00000000"],["63121.36000000","0.00581000"],["63122.00000000","0.02671000"],["63122.29000000","0.00000000"],["63122.64000000","0.00000000"],["63123.03000000","0.00169000"],["63123.10000000","0.02886000"],["63123.91000000","0.00000000"],["63123.98000000","0.00000000"],["63123.99000000","0.00009000"],["63125.13000000","0.09426000"],["63125.74000000","0.00000000"],["63127.45000000","0.07613000"],["63127.48000000","0.00000000"],["63127.56000000","0.00000000"],["63127.57000000","0.00000000"],["63128.41000000","0.01585000"],["63128.77000000","0.02000000"],["63129.06000000","0.00000000"],["63129.32000000","1.68448000"],["63129.67000000","0.01585000"],["63130.42000000","0.00188000"],["63130.62000000","3.16881000"],["63130.63000000","2.57012000"],["63130.94000000","0.00000000"],["63131.18000000","0.00000000"],["63131.79000000","0.00211000"],["63132.07000000","0.04000000"],["63135.84000000","1.35712000"],["63136.02000000","0.00000000"],["63137.99000000","0.09651000"],["63138.59000000","0.32561000"],["63140.92000000","0.13955000"],["63145.60000000","0.00000000"],["63148.22000000","0.00120000"],["63148.25000000","0.15697000"],["63149.11000000","1.19717000"],["63149.73000000","0.00027000"],["63149.86000000","0.00000000"],["63153.44000000","0.00000000"],["63153.71000000","0.00426000"],["63153.90000000","0.00000000"],["63154.18000000","0.00400000"],["63157.64000000","0.00430000"],["63157.68000000","0.00426000"],["63162.12000000","0.09758000"],["63162.13000000","0.12904000"],["63162.24000000","0.00000000"],["63172.01000000","0.00000000"],["63176.31000000","0.01083000"],["63184.11000000","0.01706000"],["63186.10000000","2.70329000"],["63186.98000000","2.81166000"],["63189.39000000","0.00000000"],["63190.06000000","0.02107000"],["63199.99000000","0.22239000"],["63201.27000000","0.00000000"],["63201.86000000","2.19875000"],["63201.88000000","0.00000000"],["63207.19000000","0.00000000"],["63207.86000000","0.01017000"],["63212.74000000","0.00000000"],["63270.55000000","0.02481000"],["86422.88000000","0.01891000"]]}
{"e":"depthUpdate","E":1781816967814,"s":"BTCUSDT","U":96005710023,"u":96005710117,"b":[["63117.99000000","6.22248000"],["63117.96000000","0.19641000"],["63115.15000000","0.00027000"],["63113.41000000","0.00000000"],["63113.20000000","0.00018000"],["63113.18000000","0.88594000"],["63112.01000000","0.00552000"],["63111.67000000","0.00347000"],["63111.52000000","0.01280000"],["63110.67000000","0.01586000"],["63100.57000000","0.57117000"],["63100.22000000","0.87138000"],["63100.20000000","0.00000000"],["63043.22000000","0.00015000"],["63039.53000000","0.00000000"],["63029.92000000","0.04917000"],["56806.20000000","0.00080000"],["50494.39000000","0.00154000"]],"a":[["63118.00000000","0.93350000"],["63118.01000000","0.00081000"],["63119.69000000","0.00035000"],["63122.68000000","0.00018000"],["63122.69000000","0.00008000"],["63122.70000000","0.00008000"],["63122.81000000","0.09918000"],["63123.09000000","0.00009000"],["63123.62000000","0.14686000"],["63123.63000000","0.00000000"],["63123.71000000","0.01014000"],["63123.99000000","0.00000000"],["63125.05000000","0.07613000"],["63125.13000000","0.00000000"],["63126.07000000","0.00000000"],["63127.45000000","0.00000000"],["63128.41000000","0.00000000"],["63128.99000000","1.05834000"],["63129.67000000","0.00000000"],["63130.44000000","0.00047000"],["63136.03000000","0.00000000"],["63140.66000000","0.57081000"],["63146.40000000","0.56014000"],["63165.38000000","1.04955000"],["63196.33000000","0.00728000"],["63219.30000000","0.29855000"],["86422.88000000","0.03782000"]]}
