{"e":"depthUpdate","E":1781816967914,"s":"BTCUSDT","U":96005710118,"u":96005710169,"b":[["63117.99000000","6.31748000"],["63116.00000000","1.19010000"],["63115.99000000","1.04974000"],["63113.68000000","2.56730000"],["63113.20000000","0.00000000"],["63103.21000000","0.00000000"],["63102.36000000","0.00000000"],["63100.52000000","0.00000000"],["63100.22000000","0.82111000"],["63100.04000000","0.13443000"],["63043.22000000","0.00000000"],["56806.20000000","0.00100000"]],"a":[["63118.00000000","0.93350000"],["63122.00000000","0.02671000"],["63122.68000000","0.00000000"],["63122.70000000","0.00000000"],["63122.80000000","0.00018000"],["63122.81000000","0.09936000"],["63123.10000000","0.02886000"],["63123.71000000","0.00996000"],["63125.36000000","0.00000000"],["63133.99000000","0.08112000"],["63134.80000000","0.00009000"],["63137.99000000","0.00000000"],["63154.40000000","0.00000000"],["63155.52000000","0.00000000"],["63156.22000000","0.13298000"]]}
{"e":"depthUpdate","E":1781816968014,"s":"BTCUSDT","U":96005710170,"u":96005710217,"b":[["63117.99000000","5.82956000"],["63117.96000000","0.19759000"],["63117.05000000","0.00792000"],["63116.00000000","0.00077000"],["63115.52000000","0.01585000"],["63114.25000000","0.01585000"],["63113.69000000","1.18952000"],["63112.99000000","0.01585000"],["63100.22000000","0.82111000"],["63078.63000000","0.00393000"],["63076.01000000","0.00000000"],["63066.01000000","0.00393000"],["63063.91000000","0.00000000"],["63061.83000000","0.00000000"],["63042.36000000","0.00015000"],["63031.85000000","2.89187000"],["63029.73000000","0.00000000"],["62871.77000000","4.77712000"],["56806.20000000","0.00140000"],["50494.40000000","0.00061000"]],"a":[["63118.00000000","0.93367000"],["63122.10000000","0.00018000"],["63122.11000000","0.13581000"],["63122.80000000","0.00000000"],["63122.81000000","0.00018000"],["63123.03000000","0.00000000"],["63123.09000000","0.01594000"],["63124.35000000","0.01585000"],["63125.61000000","0.01585000"],["63125.99000000","1.05852000"],["63128.76000000","0.00792000"],["63128.99000000","0.00000000"],["63131.17000000","0.00000000"],["63136.32000000","0.79296000"],["63140.58000000","0.00000000"],["63169.99000000","0.00015000"],["63173.01000000","0.00395000"],["63183.05000000","0.00000000"],["63185.41000000","0.00379000"],["63233.55000000","0.00000000"],["63236.18000000","0.00158000"],["63244.53000000","0.28050000"],["63245.67000000","0.00000000"],["63248.89000000","0.00152000"],["80298.72000000","0.02508000"]]}
{"e":"depthUpdate","E":1781816968114,"s":"BTCUSDT","U":96005710218,"u":96005710349,"b":[["63117.96000000","0.19759000"],["63117.05000000","0.00810000"],["63116.01000000","0.00000000"],["63116.00000000","0.00059000"],["63115.99000000","1.04974000"],["63115.52000000","0.01603000"],["63115.15000000","0.00036000"],["63115.14000000","0.32418000"],["63114.43000000","0.02200000"],["63114.40000000","0.02000000"],["63114.25000000","0.01603000"],["63113.80000000","0.04000000"],["63113.77000000","0.04000000"],["63113.70000000","0.00009000"],["63113.68000000","2.56712000"],["63113.19000000","0.62657000"],["63111.99000000","0.65627000"],["63111.91000000","0.02000000"],["63111.28000000","0.02012000"],["63111.27000000","0.02000000"],["63110.93000000","0.02000000"],["63110.65000000","0.02000000"],["63110.64000000","0.02000000"],["63110.62000000","0.02000000"],["63110.61000000","0.15955000"],["63109.99000000","3.02517000"],["63109.98000000","0.94452000"],["63109.15000000","0.00000000"],["63103.78000000","0.00000000"],["63103.13000000","0.02000000"],["63103.12000000","0.02000000"],["63101.15000000","0.00000000"],["63100.22000000","0.62293000"],["63091.84000000","0.00000000"],["63078.53000000","0.00000000"],["63055.23000000","0.00000000"],["63052.08000000","0.02000000"],["63048.43000000","0.00000000"],["62956.01000000","0.00960000"],["62950.30000000","0.00000000"],["62874.22000000","0.00000000"],["62850.94000000","0.02481000"],["62837.41000000","0.00000000"],["56806.20000000","0.00180000"]],"a":[["63118.00000000","0.93359000"],["63122.00000000","0.02671000"],["63122.11000000","0.13599000"],["63122.81000000","0.00000000"],["63123.09000000","0.01612000"],["63123.10000000","0.02868000"],["63123.37000000","0.00029000"],["63123.62000000","0.43584000"],["63130.34000000","0.02000000"],["63130.37000000","0.02600000"],["63130.97000000","0.04800000"],["63131.00000000","0.04400000"],["63132.87000000","0.02600000"],["63133.50000000","0.04400000"],["63133.84000000","0.02600000"],["63134.13000000","0.05400000"],["63134.16000000","0.06600000"],["63149.44000000","0.00400000"],["63154.18000000","0.00000000"],["63175.21000000","0.02600000"],["63178.27000000","0.02018000"],["63178.90000000","0.02000000"],["63178.93000000","0.00000000"],["63179.00000000","0.03400000"],["63179.68000000","0.02409000"],["63180.79000000","0.02600000"],["63181.42000000","0.04400000"],["63181.77000000","0.00000000"],["63182.05000000","0.02600000"],["63182.08000000","0.03200000"],["63329.74000000","0.00045000"],["79890.03000000","0.04242000"]]}
{"e":"depthUpdate","E":1781816968214,"s":"BTCUSDT","U":96005710350,"u":96005710393,"b":[["63117.99000000","5.96920000"],["63115.78000000","0.00031000"],["63115.14000000","0.32418000"],["63114.43000000","0.02218000"],["63114.25000000","0.01585000"],["63110.61000000","0.02000000"],["63103.65000000","0.00000000"],["63103.13000000","0.00000000"],["63103.12000000","0.00000000"],["63101.34000000","0.00008000"],["63100.61000000","0.00000000"],["63100.22000000","0.62293000"],["63100.18000000","0.00000000"],["63099.98000000","0.00000000"],["63099.97000000","0.00000000"],["63099.95000000","0.00000000"],["63099.89000000","0.00000000"],["63098.49000000","0.00000000"],["63048.76000000","0.00000000"],["62863.01000000","0.00033000"],["56806.20000000","0.00220000"],["56806.00000000","0.00020000"],["50494.40000000","0.00022000"]],"a":[["63136.37000000","0.00000000"],["63139.22000000","0.00008000"],["63181.42000000","0.02000000"],["63270.55000000","0.00000000"]]}
{"e":"depthUpdate","E":1781816968314,"s":"BTCUSDT","U":96005710394,"u":96005710441,"b":[["63108.39000000","0.60500000"],["63100.62000000","0.00000000"],["63100.22000000","0.62293000"],["56806.20000000","0.00260000"],["56806.00000000","0.00000000"]],"a":[["63119.29000000","0.00000000"],["63119.69000000","0.00053000"],["63120.08000000","0.00000000"],["63120.92000000","0.00000000"],["63121.76000000","0.00000000"],["63122.10000000","0.00036000"],["63122.84000000","0.00000000"],["63122.86000000","0.00000000"],["63122.88000000","0.00000000"],["63123.61000000","0.00018000"],["63124.96000000","0.00000000"],["63125.04000000","0.00018000"],["63125.99000000","1.05834000"],["63126.27000000","1.10911000"],["63126.86000000","0.00000000"],["63127.47000000","0.00008000"],["63128.99000000","0.00018000"],["63129.00000000","0.46056000"],["63129.31000000","0.00810000"],["63130.61000000","0.00018000"],["63130.87000000","0.00000000"],["63133.11000000","0.00000000"],["63133.25000000","0.00018000"],["63134.44000000","0.00018000"],["63135.84000000","1.35730000"],["63135.91000000","0.00000000"],["63136.31000000","0.00018000"],["63145.56000000","0.99553000"],["63149.09000000","1.78005000"],["63179.00000000","0.00000000"],["63182.05000000","0.00000000"]]}
{"e":"depthUpdate","E":1781816968414,"s":"BTCUSDT","U":96005710442,"u":96005710450,"b":[["63116.56000000","0.00009000"],["63104.19000000","0.55601000"],["56806.20000000","0.00300000"]],"a":[["63142.91000000","0.00255000"],["63175.21000000","0.00000000"],["63179.68000000","0.00009000"],["63181.42000000","0.00000000"],["63182.08000000","0.00000000"]]}
{"e":"depthUpdate","E":1781816968514,"s":"BTCUSDT","U":96005710451,"u":96005710459,"b":[["63115.14000000","0.32408000"],["56806.20000000","0.00340000"],["50494.40000000","0.00061000"]],"a":[["63120.00000000","0.02536000"],["63178.27000000","0.00018000"],["63178.90000000","0.00000000"],["63180.79000000","0.00000000"],["63683.18000000","0.00000000"]]}
{"e":"depthUpdate","E":1781816968614,"s":"BTCUSDT","U":96005710460,"u":96005710496,"b":[["63117.99000000","5.90126000"],["63115.99000000","0.44743000"],["63106.86000000","0.00700000"],["63103.69000000","0.00000000"],["63100.22000000","0.31121000"],["63032.12000000","0.00000000"],["56806.20000000","0.00360000"],["56806.19000000","0.00009000"],["56803.63000000","0.00000000"],["50494.40000000","0.00022000"]],"a":[["63118.00000000","0.92766000"],["63121.47000000","0.13877000"],["63122.11000000","0.00018000"],["63123.62000000","0.43592000"],["63123.69000000","0.07613000"],["63140.64000000","0.00000000"]]}
{"e":"depthUpdate","E":1781816968716,"s":"BTCUSDT","U":96005710497,"u":96005710570,"b":[["63117.99000000","5.89334000"],["63117.97000000","0.00052000"],["63116.57000000","0.00792000"],["63116.00000000","0.00041000"],["63115.52000000","0.00018000"],["63115.27000000","0.29535000"],["63115.16000000","0.00027000"],["63115.15000000","1.17719000"],["63113.70000000","0.00000000"],["63113.19000000","0.62675000"],["63112.23000000","0.00000000"],["63112.00000000","0.06000000"],["63111.29000000","0.00018000"],["63108.40000000","0.00018000"],["63108.00000000","0.02300000"],["63106.89000000","1.94216000"],["63104.67000000","0.00000000"],["63104.20000000","0.00018000"],["63102.37000000","0.00000000"],["63100.58000000","0.00018000"],["63100.22000000","1.27865000"],["63100.21000000","0.46056000"],["63039.72000000","0.00010000"],["63039.70000000","0.31783000"],["63037.56000000","0.00000000"],["62956.01000000","0.00000000"],["62952.90000000","0.00960000"],["56806.20000000","0.00400000"]],"a":[["63118.00000000","0.92765000"],["63119.17000000","0.00018000"],["63119.18000000","0.52342000"],["63119.99000000","0.00000000"],["63120.79000000","0.13361000"],["63121.36000000","0.00581000"],["63121.46000000","0.00018000"],["63121.47000000","0.00018000"],["63121.99000000","0.00221000"],["63122.00000000","0.02671000"],["63122.10000000","0.00018000"],["63122.11000000","0.00000000"],["63123.09000000","0.01603000"],["63123.61000000","0.00036000"],["63123.68000000","0.00009000"],["63125.61000000","0.01585000"],["63125.62000000","0.00000000"],["63127.32000000","0.00400000"],["63137.33000000","0.57084000"],["63145.38000000","0.00000000"],["63152.60000000","0.00000000"],["63326.56000000","0.00000000"],["63358.51000000","0.01893000"]]}
{"e":"depthUpdate","E":1781816968814,"s":"BTCUSDT","U":96005710571,"u":96005710867,"b":[["63117.99000000","5.90909000"],["63117.05000000","0.00018000"],["63116.57000000","0.00018000"],["63115.99000000","0.44743000"],["63115.52000000","0.00000000"],["63115.28000000","0.00000000"],["63115.27000000","0.29535000"],["63115.16000000","0.00018000"],["63115.15000000","2.08606000"],["63114.25000000","0.00000000"],["63113.70000000","3.16866000"],["63113.20000000","0.00552000"],["63113.19000000","0.55998000"],["63112.99000000","0.00000000"],["63112.01000000","0.00000000"],["63111.99000000","0.65619000"],["63111.39000000","0.00242000"],["63110.00000000","1.80926000"],["63104.58000000","1.67453000"],["63104.29000000","0.57114000"],["63103.86000000","1.19902000"],["63099.17000000","0.00000000"],["63095.39000000","0.47547000"],["63092.17000000","0.89781000"],["63087.72000000","2.15186000"],["63084.50000000","0.00008000"],["63084.44000000","0.00000000"],["63078.62000000","1.45492000"],["63078.01000000","0.57129000"],["63077.68000000","0.00000000"],["63075.27000000","0.63494000"],["63068.01000000","0.00000000"],["63064.78000000","0.03045000"],["63064.15000000","0.00000000"],["63061.99000000","1.77288000"],["63061.69000000","0.00000000"],["63061.68000000","2.56712000"],["63061.29000000","0.00000000"],["63058.65000000","0.74148000"],["63050.39000000","1.78077000"],["63046.50000000","0.00000000"],["63041.67000000","0.00000000"],["63039.70000000","0.00000000"],["56806.20000000","0.00440000"],["50494.39000000","0.00154000"],["50494.00000000","0.00400000"]],"a":[["63118.00000000","0.02533000"],["63118.01000000","0.00081000"],["63119.17000000","0.00000000"],["63119.18000000","0.00026000"],["63119.70000000","0.00018000"],["63119.99000000","0.00018000"],["63120.00000000","0.02368000"],["63120.68000000","0.00549000"],["63120.78000000","0.00000000"],["63120.79000000","0.00018000"],["63121.36000000","0.00581000"],["63121.46000000","0.00000000"],["63121.47000000","0.00000000"],["63121.99000000","0.00239000"],["63122.25000000","0.00000000"],["63122.35000000","0.00188000"],["63122.69000000","0.00000000"],["63123.09000000","0.00000000"],["63123.10000000","0.00000000"],["63123.61000000","0.00018000"],["63123.62000000","0.00000000"],["63123.68000000","0.00000000"],["63123.69000000","0.00000000"],["63123.99000000","0.00018000"],["63124.31000000","0.00009000"],["63124.32000000","0.00317000"],["63124.35000000","0.00000000"],["63125.05000000","0.00000000"],["63125.63000000","0.00000000"],["63125.99000000","0.00000000"],["63126.00000000","0.02300000"],["63126.27000000","0.00018000"],["63126.28000000","0.00000000"],["63126.47000000","0.03008000"],["63128.16000000","0.00861000"],["63128.76000000","0.00000000"],["63129.00000000","0.00000000"],["63129.32000000","0.00000000"],["63129.63000000","0.00000000"],["63130.61000000","0.46074000"],["63130.62000000","0.00000000"],["63130.63000000","0.00300000"],["63132.69000000","0.00000000"],["63133.12000000","0.00000000"],["63133.25000000","2.56730000"],["63133.26000000","0.00000000"],["63133.99000000","0.00000000"],["63134.44000000","3.28143000"],["63134.45000000","0.00000000"],["63135.50000000","0.02000000"],["63135.82000000","1.26640000"],["63135.83000000","2.56712000"],["63135.84000000","0.00018000"],["63135.85000000","0.00000000"],["63136.31000000","0.00018000"],["63136.32000000","0.00000000"],["63136.33000000","0.00000000"],["63137.14000000","0.46056000"],["63137.33000000","0.00000000"],["63138.25000000","0.00150000"],["63138.58000000","0.79290000"],["63138.65000000","2.37971000"],["63138.66000000","5.73596000"],["63138.67000000","0.00000000"],["63138.68000000","0.00000000"],["63138.85000000","0.00000000"],["63139.00000000","0.00000000"],["63140.66000000","0.00000000"],["63140.92000000","0.00000000"],["63141.91000000","1.36371000"],["63142.56000000","3.16866000"],["63143.25000000","0.00000000"],["63143.85000000","0.46056000"],["63143.89000000","0.00000000"],["63145.29000000","0.00000000"],["63145.56000000","1.97909000"],["63146.56000000","3.16874000"],["63147.43000000","0.03618000"],["63147.98000000","0.00000000"],["63152.37000000","0.57070000"],["63153.84000000","0.13955000"],["63153.95000000","0.00000000"],["63154.12000000","0.02868000"],["63156.43000000","0.00544000"],["63158.40000000","1.33179000"],["63160.52000000","0.57063000"],["63161.49000000","0.00023000"],["63162.25000000","0.00000000"],["63162.96000000","0.02868000"],["63164.25000000","0.00000000"],["63164.32000000","3.43547000"],["63165.37000000","0.00385000"],["63165.52000000","1.67453000"],["63165.62000000","0.00000000"],["63166.19000000","0.47493000"],["63166.90000000","0.00000000"],["63171.80000000","0.02868000"],["63183.13000000","0.00000000"],["63183.99000000","0.04073000"],["63187.20000000","0.00009000"],["63190.06000000","0.00000000"],["63196.11000000","0.04757000"],["63196.33000000","0.00000000"],["63199.99000000","0.00000000"],["63201.26000000","0.94603000"],["63201.27000000","0.00000000"],["63204.67000000","0.00000000"],["63207.86000000","0.00015000"],["63208.83000000","1.23948000"],["63208.84000000","0.00000000"],["63208.85000000","0.00000000"],["63209.45000000","2.56712000"],["63211.01000000","0.00012000"],["63215.45000000","0.00000000"],["63215.46000000","1.46754000"],["63217.35000000","0.00265000"],["63222.14000000","0.00000000"],["63222.15000000","0.00000000"],["63222.16000000","0.00000000"],["63223.69000000","0.00012000"],["63229.08000000","0.00000000"],["63229.09000000","0.00154000"],["63231.91000000","0.07616000"],["63233.56000000","0.00000000"],["63240.45000000","0.13873000"],["63241.58000000","0.00000000"],["63242.24000000","0.00000000"],["63242.93000000","0.00000000"],["63243.62000000","6.45117000"],["63282.43000000","0.24750000"],["63680.35000000","0.00000000"]]}
{"e":"depthUpdate","E":1781816968914,"s":"BTCUSDT","U":96005710868,"u":96005710966,"b":[["63117.99000000","5.90918000"],["63117.96000000","0.19759000"],["63117.86000000","0.01585000"],["63117.05000000","0.00000000"],["63116.59000000","0.00000000"],["63116.57000000","0.00000000"],["63116.56000000","0.00000000"],["63115.33000000","0.00000000"],["63115.28000000","0.00018000"],["63115.16000000","0.00036000"],["63115.15000000","2.08633000"],["63113.70000000","0.00000000"],["63106.70000000","0.00118000"],["63095.03000000","0.00000000"],["63081.09000000","0.01146000"],["63062.01000000","3.16866000"],["63060.66000000","0.00008000"],["56806.20000000","0.00440000"],["50494.00000000","0.00000000"]],"a":[["63118.00000000","0.16483000"],["63118.44000000","0.00009000"],["63119.18000000","0.00000000"],["63119.69000000","0.00035000"],["63119.70000000","0.00000000"],["63120.68000000","0.00549000"],["63120.79000000","0.00000000"],["63122.00000000","0.02671000"],["63123.71000000","0.01014000"],["63124.00000000","0.02318000"],["63124.31000000","0.00018000"],["63124.32000000","0.25067000"],["63125.00000000","0.00886000"],["63125.12000000","0.00000000"],["63125.36000000","0.00009000"],["63125.61000000","0.00000000"],["63125.99000000","0.00000000"],["63126.69000000","0.00000000"],["63127.95000000","0.01585000"],["63128.59000000","0.00012000"],["63129.35000000","0.07613000"],["63130.33000000","0.00792000"],["63130.60000000","5.76446000"],["63133.24000000","2.89528000"],["63134.93000000","0.00165000"],["63141.38000000","0.57089000"],["63147.41000000","0.00000000"],["63155.64000000","0.00627000"],["63160.52000000","0.00000000"],["63193.69000000","0.00000000"],["63196.85000000","0.00000000"],["63201.26000000","0.00000000"],["63208.83000000","0.00000000"],["63218.02000000","0.04585000"]]}
{"e":"depthUpdate","E":1781816969014,"s":"BTCUSDT","U":96005710967,"u":96005711005,"b":[["63117.96000000","0.19759000"],["63117.86000000","0.00000000"],["63115.15000000","1.25610000"],["63043.28000000","0.00015000"],["63042.36000000","0.00000000"],["56806.20000000","0.00460000"],["50494.40000000","0.00061000"]],"a":[["63118.00000000","0.16491000"],["63123.22000000","0.00018000"],["63123.23000000","0.10346000"],["63124.00000000","0.02318000"],["63124.31000000","0.00009000"],["63124.32000000","0.25085000"],["63125.00000000","0.00868000"],["63127.32000000","0.00000000"],["63127.51000000","0.07613000"],["63127.94000000","0.02868000"],["63127.95000000","0.00000000"],["63134.44000000","3.19752000"],["63135.81000000","0.12658000"],["63155.76000000","0.00400000"],["63193.68000000","0.00000000"]]}
{"e":"depthUpdate","E":1781816969114,"s":"BTCUSDT","U":96005711006,"u":96005711062,"b":[["63117.96000000","0.19759000"],["63112.01000000","3.16866000"],["63098.60000000","0.02000000"],["63097.99000000","0.04000000"],["63096.10000000","0.02000000"],["63095.47000000","0.02000000"],["63095.12000000","0.02000000"],["63094.84000000","0.04000000"],["63094.81000000","0.02000000"],["63068.27000000","1.28441000"],["63062.02000000","0.00000000"],["63062.01000000","0.00000000"],["63055.23000000","0.00000000"],["63052.08000000","0.02000000"],["63048.76000000","0.02000000"],["63048.43000000","0.00000000"],["63039.70000000","0.79633000"],["63038.78000000","0.00030000"],["63035.93000000","0.00000000"],["63019.67000000","0.00000000"],["56806.20000000","0.00460000"]],"a":[["63118.00000000","0.16482000"],["63118.01000000","0.00081000"],["63122.00000000","0.02671000"],["63123.22000000","0.12972000"],["63123.23000000","0.10364000"],["63124.32000000","0.25067000"],["63127.50000000","0.05110000"],["63130.59000000","1.90775000"],["63154.18000000","0.00400000"],["63155.76000000","0.00000000"],["63193.72000000","0.00000000"],["63194.71000000","0.76737000"],["63196.57000000","0.00030000"],["63229.09000000","0.13914000"]]}
{"e":"depthUpdate","E":1781816969214,"s":"BTCUSDT","U":96005711063,"u":96005711120,"b":[["63117.99000000","5.93951000"],["63117.31000000","0.01585000"],["63114.40000000","0.02018000"],["63114.00000000","0.01300000"],["63113.19000000","0.05018000"],["63113.18000000","0.88602000"],["63112.02000000","0.90509000"],["63112.00000000","0.07300000"],["63106.86000000","0.00300000"],["63101.34000000","0.00000000"],["63048.76000000","0.00000000"],["63043.28000000","0.00000000"],["63042.57000000","0.00015000"],["63039.70000000","0.40100000"],["62994.46000000","0.00000000"],["62980.34000000","0.09526000"],["62958.01000000","0.00960000"],["62952.90000000","0.00000000"],["56806.20000000","0.00440000"],["50494.40000000","0.00022000"]],"a":[["63118.00000000","0.16472000"],["63122.00000000","0.02671000"],["63123.21000000","0.00018000"],["63123.22000000","0.12990000"],["63123.99000000","0.00000000"],["63124.00000000","0.02300000"],["63126.34000000","0.06962000"],["63126.35000000","0.07613000"],["63127.41000000","0.01585000"],["63127.50000000","0.00000000"],["63127.51000000","0.00000000"],["63128.67000000","0.01585000"],["63129.35000000","0.00000000"],["63129.93000000","0.01585000"],["63137.32000000","0.13951000"],["63139.22000000","0.00000000"],["63153.84000000","0.00000000"],["63273.29000000","0.09482000"]]}
{"e":"depthUpdate","E":1781816969314,"s":"BTCUSDT","U":96005711121,"u":96005711179,"b":[["63117.96000000","0.19759000"],["63117.31000000","0.01603000"],["63114.40000000","0.02000000"],["63108.39000000","0.00000000"],["63101.34000000","0.00008000"],["63056.49000000","0.00000000"],["63052.08000000","0.00000000"],["56806.20000000","0.00420000"]],"a":[["63118.00000000","0.16222000"],["63119.69000000","0.00017000"],["63119.99000000","0.00036000"],["63121.99000000","0.00257000"],["63122.10000000","0.00000000"],["63123.21000000","0.00018000"],["63123.22000000","0.00036000"],["63123.61000000","0.00000000"],["63124.31000000","0.00027000"],["63125.04000000","0.00000000"],["63126.27000000","0.00000000"],["63126.34000000","0.06980000"],["63127.93000000","0.00018000"],["63128.99000000","0.00000000"],["63129.31000000","0.00792000"],["63129.99000000","0.00018000"],["63130.59000000","1.90793000"],["63130.60000000","5.76464000"],["63130.61000000","0.46056000"],["63133.23000000","0.00018000"],["63133.25000000","2.56712000"],["63134.43000000","0.00018000"],["63134.44000000","3.19734000"],["63135.81000000","0.12676000"],["63135.82000000","1.26658000"],["63135.84000000","0.00000000"],["63136.31000000","0.00000000"],["63138.57000000","0.00018000"],["63138.65000000","2.37989000"],["63138.66000000","5.73578000"],["63138.99000000","0.00000000"],["63139.22000000","0.00008000"],["63142.55000000","0.00018000"],["63143.24000000","0.00000000"],["63145.55000000","0.00018000"],["63145.56000000","1.97891000"],["63146.55000000","0.00018000"],["63149.09000000","1.77987000"],["63190.48000000","0.02120000"],["63196.37000000","0.00000000"],["63208.28000000","0.01001000"],["63221.65000000","0.00000000"]]}
{"e":"depthUpdate","E":1781816969414,"s":"BTCUSDT","U":96005711180,"u":96005711212,"b":[["63051.62000000","0.00000000"],["63048.12000000","0.00000000"],["56806.20000000","0.00420000"],["56806.00000000","0.00000000"],["50494.00000000","0.00000000"]],"a":[["63118.00000000","0.16255000"],["63118.01000000","0.00097000"],["63118.02000000","0.00016000"],["63121.80000000","0.00018000"],["63121.81000000","0.52340000"],["63121.99000000","0.00239000"],["63122.00000000","0.02671000"],["63123.22000000","0.00018000"],["63123.99000000","0.00000000"],["63124.00000000","0.02318000"],["63124.31000000","0.00036000"]]}
{"e":"depthUpdate","E":1781816969514,"s":"BTCUSDT","U":96005711213,"u":96005711241,"b":[["63117.99000000","5.93961000"],["63117.19000000","0.00009000"],["63055.24000000","0.00000000"],["63053.34000000","0.00000000"],["56806.20000000","0.00420000"],["50494.40000000","0.00061000"],["50494.00000000","0.00200000"]],"a":[["63118.44000000","0.00000000"],["63119.69000000","0.00008000"],["63121.36000000","0.00581000"],["63121.81000000","0.52358000"],["63123.71000000","0.00018000"],["63124.00000000","0.02300000"],["63125.00000000","0.00000000"],["63125.36000000","0.00000000"],["63126.34000000","0.04707000"],["63126.35000000","0.00000000"],["63131.74000000","0.00150000"],["63138.25000000","0.00000000"],["63686.05000000","0.00010000"]]}
{"e":"depthUpdate","E":1781816969614,"s":"BTCUSDT","U":96005711242,"u":96005711265,"b":[["63117.99000000","5.89396000"],["63112.02000000","0.00000000"],["63111.61000000","0.60500000"],["56806.20000000","0.00420000"],["50494.40000000","0.00022000"],["50494.00000000","0.00000000"]],"a":[["63118.00000000","0.16505000"],["63120.32000000","0.00017000"],["63123.23000000","0.10364000"],["63123.71000000","0.00000000"],["63124.00000000","0.02318000"],["63124.32000000","0.25075000"],["63125.69000000","0.00009000"],["63125.70000000","0.07613000"],["67013.36000000","0.00058000"]]}
{"e":"depthUpdate","E":1781816969714,"s":"BTCUSDT","U":96005711266,"u":96005711294,"b":[["63117.99000000","5.86099000"],["63113.19000000","0.05000000"],["63112.02000000","0.90527000"],["63111.62000000","0.00018000"],["63111.29000000","0.00000000"],["63110.94000000","0.00018000"],["63108.40000000","0.00000000"],["63104.59000000","0.00018000"],["63104.20000000","0.00000000"],["63100.58000000","0.00000000"],["63100.23000000","0.00018000"],["63082.53000000","1.72533000"],["56806.20000000","0.00440000"],["56806.19000000","0.00009000"],["50494.00000000","0.00000000"]],"a":[]}
{"e":"depthUpdate","E":1781816969814,"s":"BTCUSDT","U":96005711295,"u":96005711313,"b":[["63112.02000000","0.90527000"],["63059.96000000","0.02074000"],["62980.34000000","0.00000000"],["62958.01000000","0.00000000"],["62952.90000000","0.00960000"],["56806.20000000","0.00440000"],["50494.39000000","0.00154000"]],"a":[["63123.22000000","0.14677000"],["63125.69000000","0.00000000"],["63138.61000000","0.01585000"],["63273.29000000","0.00000000"]]}
{"e":"depthUpdate","E":1781816969914,"s":"BTCUSDT","U":96005711314,"u":96005711330,"b":[["63112.02000000","0.90527000"],["56806.20000000","0.00420000"]],"a":[["63118.00000000","0.16255000"],["63122.00000000","0.02671000"],["63123.21000000","0.00027000"],["63123.22000000","0.14695000"],["63124.00000000","0.02300000"]]}
{"e":"depthUpdate","E":1781816970014,"s":"BTCUSDT","U":96005711331,"u":96005711336,"b":[["56806.20000000","0.00420000"],["50494.40000000","0.00061000"]],"a":[["63128.16000000","0.00000000"]]}
{"e":"depthUpdate","E":1781816970114,"s":"BTCUSDT","U":96005711337,"u":96005711378,"b":[["63117.99000000","5.86099000"],["63112.02000000","0.90527000"],["63110.00000000","1.81243000"],["63064.78000000","0.39241000"],["63039.70000000","0.00000000"],["63029.64000000","0.00023000"],["56806.20000000","0.00420000"]],"a":[["63118.00000000","0.07370000"],["63199.99000000","0.23093000"],["63222.16000000","1.42209000"],["63243.61000000","2.20572000"],["63244.53000000","0.00000000"]]}
