{"event":"subscribe","arg":{"channel":"books","instId":"BTC-USDT"},"connId":"de355a39"}
{"arg":{"channel":"books","instId":"BTC-USDT"},"action":"snapshot","data":[{"asks":[["62666.2","1.68076525","0","16"],["62666.5","0.00001","0","1"],["62667.2","0.00001501","0","1"],["62668.1","0.0070085","0","1"],["62668.5","0.01955472","0","1"],["62668.6","0.00001","0","1"],["62668.7","0.00001","0","1"],["62668.8","0.05750436","0","1"],["62669.5","0.00798581","0","1"],["62669.6","0.06438626","0","2"],["62670","0.11432732","0","1"],["62670.7","0.00008433","0","1"],["62671.4","0.00040514","0","2"],["62671.7","0.00001605","0","1"],["62672.3","0.11572655","0","1"],["62673.1","0.04","0","1"],["62673.3","0.17564787","0","1"],["62673.5","0.00001501","0","1"],["62673.6","0.08","0","1"],["62674.3","0.0015","0","1"],["62675","0.00012007","0","1"],["62675.5","0.11572655","0","1"],["62675.6","0.31057","0","2"],["62675.7","0.00002","0","2"],["62675.8","0.00002","0","2"],["62676.1","0.84694933","0","1"],["62676.3","0.15539","0","1"],["62676.4","0.00001605","0","1"],["62676.6","0.00286587","0","2"],["62676.7","0.09672725","0","3"],["62676.8","0.00002","0","2"],["62676.9","0.00002066","0","2"],["62677.1","0.00016188","0","1"],["62677.3","0.0000282","0","1"],["62677.4","0.00233166","0","2"],["62677.5","0.15973165","0","1"],["62677.6","0.03193448","0","1"],["62677.7","1.33711014","0","1"],["62677.8","0.1957","0","1"],["62678.1","0.01598563","0","2"],["62678.2","0.44709973","0","1"],["62678.3","0.19619666","0","2"],["62678.5","0.00004989","0","1"],["62678.6","0.00001064","0","1"],["62678.8","0.29469301","0","7"],["62679.2","0.00046015","0","1"],["62679.5","0.00001111","0","1"],["62679.7","0.00010405","0","1"],["62679.8","0.15204279","0","2"],["62679.9","0.09821","0","1"],["62680","0.00003145","0","2"],["62680.2","0.00029999","0","1"],["62680.3","0.04910858","0","1"],["62680.5","0.85881049","0","1"],["62680.6","1.38621873","0","2"],["62680.8","0.00013515","0","2"],["62680.9","1.378412","0","1"],["62681","0.00004788","0","1"],["62681.2","0.00001001","0","1"],["62681.4","0.04912462","0","2"],["62682","1.11535455","0","2"],["62682.1","0.44709973","0","1"],["62682.2","0.00001","0","1"],["62682.9","0.10616827","0","2"],["62683.6","0.00001051","0","1"],["62683.7","0.01947458","0","1"],["62684","0.00001604","0","1"],["62684.2","0.00159283","0","2"],["62684.4","0.11976685","0","2"],["62684.5","0.09823322","0","1"],["62684.8","0.0000635","0","1"],["62684.9","0.00002963","0","1"],["62685","3.33711014","0","2"],["62685.1","1.05187979","0","1"],["62685.3","0.00001","0","1"],["62685.7","0.02024991","0","1"],["62685.8","0.03193448","0","1"],["62686.1","0.44711474","0","2"],["62686.8","0.00001974","0","1"],["62687.2","0.01","0","1"],["62687.4","0.02628291","0","5"],["62687.5","0.00999993","0","2"],["62687.6","1.15272","0","1"],["62687.7","0.19572016","0","3"],["62687.9","1.33711014","0","1"],["62688","0.20147874","0","1"],["62689","0.00018653","0","3"],["62689.1","0.00062708","0","1"],["62689.6","0.00002844","0","1"],["62689.7","0.00004479","0","1"],["62690.1","0.00162048","0","1"],["62690.5","0.00002335","0","1"],["62690.7","0.00001604","0","1"],["62691.2","0.00005407","0","4"],["62691.4","0.60594986","0","1"],["62691.5","1.33711014","0","1"],["62691.7","0.19316","0","1"],["62691.8","0.00002021","0","1"],["62691.9","0.00002561","0","1"],["62692.1","0.00015977","0","1"],["62692.3","0.00994607","0","13"],["62692.4","0.00001501","0","1"],["62692.5","0.00001005","0","1"],["62692.7","0.00001501","0","1"],["62693.1","0.0044121","0","3"],["62693.2","0.00020113","0","2"],["62693.3","0.03894","0","1"],["62693.7","0.44709973","0","1"],["62693.8","0.03203204","0","3"],["62694","0.19571604","0","2"],["62694.4","0.00037301","0","1"],["62694.5","0.00015979","0","1"],["62694.7","0.00006957","0","1"],["62694.9","0.78014778","0","2"],["62695","1.33711014","0","1"],["62695.8","0.01570566","0","1"],["62695.9","0.00059195","0","2"],["62696","0.0005","0","1"],["62696.1","0.00860225","0","2"],["62696.4","0.00040772","0","1"],["62696.5","0.00001604","0","1"],["62696.9","0.00012185","0","1"],["62697.1","0.0001647","0","1"],["62697.2","0.01947458","0","1"],["62697.4","1.40538011","0","2"],["62697.5","0.00029074","0","1"],["62698","0.00001","0","1"],["62698.7","0.00301501","0","2"],["62698.8","0.56127699","0","2"],["62698.9","0.45009973","0","2"],["62699","1.33712618","0","2"],["62699.2","0.00047018","0","2"],["62700","0.10336568","0","7"],["62700.1","0.47846826","0","1"],["62700.2","0.10955","0","1"],["62700.3","0.1957","0","1"],["62700.4","0.0000763","0","3"],["62700.5","0.00010362","0","1"],["62700.7","0.00010093","0","2"],["62700.8","0.55243989","0","1"],["62700.9","0.00001002","0","1"],["62701.5","0.00001604","0","1"],["62701.6","0.00001644","0","1"],["62701.7","0.00029615","0","2"],["62702.1","0.00019241","0","1"],["62702.3","0.00013987","0","1"],["62702.4","1.33711014","0","1"],["62702.6","0.03879414","0","1"],["62702.7","0.026978","0","4"],["62702.9","0.00001008","0","1"],["62703","0.00001748","0","1"],["62703.4","0.00001604","0","1"],["62703.5","0.44709973","0","1"],["62703.6","0.00002335","0","2"],["62703.8","0.09847407","0","2"],["62703.9","0.13438048","0","1"],["62704.6","0.00003023","0","1"],["62704.8","0.00001254","0","1"],["62705","0.00001501","0","1"],["62705.2","0.44163633","0","1"],["62705.3","1.33711014","0","1"],["62705.6","0.00008409","0","2"],["62706.5","0.00001604","0","1"],["62706.6","0.1957","0","1"],["62706.9","0.00004333","0","1"],["62707","0.00003822","0","2"],["62707.6","0.00153679","0","2"],["62707.8","0.00040505","0","2"],["62708.1","1.31176061","0","5"],["62708.2","1.33712042","0","2"],["62708.3","0.45103098","0","9"],["62708.4","2.755612","0","1"],["62708.6","0.00001217","0","1"],["62708.8","0.00001319","0","1"],["62709","0.00005918","0","2"],["62709.6","0.00164624","0","2"],["62709.7","0.00001604","0","1"],["62709.8","0.04351807","0","2"],["62710","0.00002484","0","1"],["62710.2","0.00005791","0","1"],["62710.3","0.00009175","0","3"],["62710.4","0.0046671","0","8"],["62710.7","0.00001001","0","1"],["62710.8","0.00024022","0","3"],["62710.9","0.00001753","0","1"],["62711","0.06383031","0","1"],["62711.1","0.49473113","0","1"],["62711.2","1.33711014","0","1"],["62711.3","0.00012454","0","2"],["62711.6","0.11961","0","1"],["62711.7","0.00069846","0","1"],["62711.8","0.00135604","0","3"],["62711.9","0.00015976","0","1"],["62712","0.00041918","0","1"],["62712.2","0.00221261","0","5"],["62712.9","0.1957","0","1"],["62713.5","0.00002552","0","1"],["62714","0.00128028","0","2"],["62714.1","0.50330136","0","1"],["62714.2","1.23333046","0","5"],["62714.4","0.0000903","0","1"],["62715","0.00043467","0","1"],["62715.3","0.00001614","0","1"],["62715.4","0.00001083","0","1"],["62715.6","0.00001991","0","1"],["62715.8","0.00400387","0","1"],["62715.9","0.44816522","0","3"],["62716","0.00003031","0","2"],["62716.2","0.00003848","0","1"],["62716.4","0.0006","0","1"],["62716.6","0.00001321","0","1"],["62716.7","0.00001104","0","1"],["62716.8","0.00023513","0","1"],["62717.3","0.0000457","0","1"],["62717.5","0.00001272","0","1"],["62717.6","0.000015","0","1"],["62717.8","0.00001048","0","1"],["62718.1","0.00024762","0","1"],["62718.4","0.03989974","0","1"],["62718.7","0.49568917","0","5"],["62718.8","1.3371373","0","3"],["62719.1","0.00001604","0","1"],["62719.2","0.22020364","0","3"],["62719.5","0.17276","0","1"],["62719.8","0.00042881","0","1"],["62720","0.00102927","0","3"],["62720.2","0.03086237","0","1"],["62720.3","0.00021183","0","6"],["62720.5","0.01947458","0","1"],["62720.7","0.00034704","0","1"],["62720.9","0.17698923","0","2"],["62721","0.4472623","0","2"],["62721.1","0.00039106","0","1"],["62721.6","0.00182665","0","2"],["62722","0.00001099","0","1"],["62722.2","0.00003979","0","1"],["62722.4","0.00002605","0","2"],["62722.7","0.00062155","0","12"],["62723.5","0.00027042","0","1"],["62723.7","0.00001038","0","1"],["62723.9","0.000015","0","1"],["62724","0.00001501","0","1"],["62724.2","0.00001149","0","1"],["62724.6","0.00358529","0","1"],["62724.7","0.00009167","0","1"],["62725","0.00056359","0","4"],["62725.5","0.19571861","0","2"],["62726.1","0.00020885","0","4"],["62726.4","1.33711014","0","1"],["62726.6","0.00001604","0","1"],["62727.1","0.00573358","0","1"],["62727.2","0.00077319","0","10"],["62727.4","0.00029999","0","1"],["62727.5","0.02404349","0","1"],["62727.7","0.0001843","0","1"],["62728","0.0093561","0","8"],["62728.2","1.42797978","0","1"],["62728.5","7.67951","0","1"],["62728.6","0.44709973","0","1"],["62728.7","0.0000376","0","3"],["62728.9","0.04018087","0","2"],["62729.2","0.00099034","0","2"],["62729.3","0.55233455","0","1"],["62729.7","0.03272239","0","2"],["62729.8","0.00056729","0","1"],["62729.9","0.00004112","0","4"],["62730","0.00052444","0","1"],["62730.4","0.00006291","0","1"],["62730.7","0.01948599","0","2"],["62731.1","0.12767652","0","1"],["62731.2","0.08004968","0","1"],["62731.4","0.00001028","0","1"],["62731.6","0.00088753","0","2"],["62731.8","0.1957","0","1"],["62732.2","0.02151174","0","1"],["62732.5","0.19943695","0","1"],["62732.8","0.03592862","0","2"],["62732.9","0.00001077","0","1"],["62733.1","0.00063715","0","2"],["62733.3","0.00566984","0","1"],["62733.4","0.00001027","0","1"],["62733.6","0.00001394","0","1"],["62733.7","1.33711014","0","1"],["62733.8","0.00024675","0","3"],["62734.1","0.00001603","0","1"],["62734.2","0.00056738","0","1"],["62734.9","0.00015969","0","1"],["62735.1","0.00003659","0","2"],["62735.3","0.00267385","0","2"],["62735.8","0.00002137","0","2"],["62736.2","0.44709973","0","1"],["62736.4","1.33711014","0","1"],["62736.5","8.21595","0","1"],["62736.6","0.00596078","0","3"],["62736.8","0.00007152","0","1"],["62737.2","0.00038477","0","7"],["62738.1","0.1957","0","1"],["62738.8","0.02404349","0","1"],["62739.1","0.00001603","0","1"],["62739.2","0.00046015","0","1"],["62739.8","0.00015967","0","1"],["62740","0.00001027","0","1"],["62740.2","0.00001492","0","1"],["62740.3","0.00006652","0","1"],["62740.6","0.00108269","0","1"],["62740.7","0.019577","0","3"],["62741.1","0.00029103","0","1"],["62741.2","0.00001207","0","1"],["62741.3","1.33711014","0","1"],["62741.4","0.00001208","0","1"],["62741.6","0.00001603","0","1"],["62742.6","0.02393173","0","1"],["62742.8","0.00091095","0","1"],["62743.2","0.00001065","0","1"],["62743.8","0.44709973","0","1"],["62744.1","0.00001075","0","1"],["62744.4","0.19573856","0","2"],["62744.5","0.03603968","0","4"],["62744.6","0.00002986","0","1"],["62745","0.0000785","0","1"],["62745.3","0.00002116","0","1"],["62745.5","0.00282113","0","3"],["62745.7","0.00022154","0","2"],["62745.9","0.00001024","0","1"],["62746.3","0.00001028","0","1"],["62746.4","0.00001063","0","1"],["62747.3","0.00018616","0","14"],["62747.5","0.0000111","0","1"],["62747.7","0.00008386","0","3"],["62747.8","0.00015922","0","6"],["62748","0.00027202","0","1"],["62748.1","0.11047754","0","1"],["62748.5","0.0016981","0","1"],["62748.6","0.00012225","0","1"],["62748.9","1.33711014","0","1"],["62749","0.00001044","0","1"],["62750","0.05330512","0","53"],["62750.1","0.04378349","0","2"],["62750.2","0.00002831","0","1"],["62750.3","3.72","0","1"],["62750.5","0.00004494","0","2"],["62750.6","0.00001084","0","1"],["62750.7","0.1957","0","1"],["62751","0.00029999","0","1"],["62751.4","0.4555466","0","6"],["62751.5","0.00077051","0","8"],["62751.6","0.00001069","0","1"],["62751.7","0.00001603","0","1"],["62752","0.00168856","0","2"],["62752.1","0.00048974","0","3"],["62752.7","0.00011441","0","2"],["62752.8","0.00004996","0","2"],["62752.9","0.00002846","0","1"],["62753.4","0.00007283","0","1"],["62754","0.00011742","0","4"],["62754.2","0.01947458","0","1"],["62754.4","0.00001058","0","1"],["62754.7","0.00007389","0","1"],["62755.1","0.00023777","0","3"],["62755.3","0.00001501","0","1"],["62755.5","0.00007904","0","2"],["62756.5","1.33711014","0","1"],["62756.7","0.00002611","0","2"],["62756.9","0.00003206","0","1"],["62757","0.1957","0","1"],["62757.1","0.00086695","0","5"],["62757.8","0.00015964","0","1"],["62758.2","0.00033431","0","1"],["62758.5","0.00004927","0","1"],["62758.6","0.00055802","0","1"],["62758.8","0.00022715","0","4"],["62758.9","0.00005065","0","1"],["62759","0.44709973","0","1"],["62759.2","0.00046015","0","1"],["62759.5","0.00014125","0","2"],["62760","0.00042287","0","3"],["62760.3","0.00002662","0","1"],["62760.4","0.00003097","0","1"],["62760.5","0.00003084","0","3"],["62760.6","0.00003084","0","3"],["62760.7","0.00002982","0","1"],["62760.8","0.00027784","0","1"],["62761.3","0.00011314","0","1"],["62761.4","0.02404349","0","1"],["62761.5","0.00038412","0","6"],["62761.7","0.00001601","0","1"],["62761.8","0.0011712","0","6"],["62761.9","0.00002196","0","2"],["62762","0.0005","0","1"],["62762.2","0.02499229","0","1"],["62762.3","0.00001104","0","1"],["62763.1","0.00497645","0","11"],["62763.2","0.003194","0","1"],["62763.3","0.1957","0","1"],["62763.5","0.00285576","0","1"],["62763.6","0.00003205","0","2"],["62764","0.00019795","0","2"],["62764.1","0.00046091","0","6"],["62764.2","0.0003225","0","1"],["62764.7","0.00263276","0","3"]],"bids":[["62666.1","0.9671428","0","10"],["62665.1","0.00132306","0","1"],["62664.9","0.0344229","0","2"],["62664.8","0.05750436","0","1"],["62663.7","0.06516706","0","1"],["62663","0.00035852","0","1"],["62662.4","0.0887024","0","1"],["62662.3","0.11559244","0","1"],["62661.5","0.00001603","0","1"],["62660.6","0.00065675","0","1"],["62660.3","1.72659282","0","3"],["62660.2","1.33711014","0","1"],["62660","2.0464","0","2"],["62659.9","0.00035852","0","1"],["62659.8","0.1957","0","1"],["62659.7","0.00001501","0","1"],["62659.5","0.01597448","0","1"],["62659.3","0.02396257","0","1"],["62659","0.04691603","0","3"],["62658","0.0464","0","1"],["62657.4","1.33711014","0","1"],["62657.2","0.1670162","0","1"],["62657","0.14902034","0","2"],["62656.8","0.00035852","0","1"],["62656.5","0.00001603","0","1"],["62656.4","0.00798581","0","1"],["62656.3","0.04313053","0","3"],["62656.2","0.00038909","0","1"],["62656","0.04678909","0","2"],["62655.5","0.09783","0","1"],["62654.3","0.105404","0","1"],["62654.1","0.69950277","0","1"],["62654","0.00001603","0","1"],["62653.9","0.09804","0","1"],["62653.8","0.036","0","1"],["62653.7","0.00035852","0","1"],["62653.5","0.29454292","0","2"],["62653.4","0.00001501","0","1"],["62653","1.33711014","0","1"],["62652.4","0.09826","0","1"],["62652.2","0.01596897","0","1"],["62651.5","0.00001603","0","1"],["62651.1","0.03193448","0","1"],["62651","0.44709973","0","1"],["62650.9","0.44817054","0","1"],["62650.7","0.2357","0","2"],["62650.6","0.00035852","0","1"],["62650.1","1.33711014","0","1"],["62649.5","0.09823322","0","1"],["62649.3","0.08","0","1"],["62649","0.00145204","0","2"],["62648.9","0.00038909","0","1"],["62648.4","0.003","0","1"],["62648.3","0.003","0","1"],["62648.2","0.003","0","1"],["62647.8","0.15973165","0","1"],["62647.7","0.63859022","0","1"],["62647.5","0.00035852","0","1"],["62647.1","0.44711474","0","2"],["62646.8","0.036","0","1"],["62646.5","0.00001604","0","1"],["62646.2","1.33751014","0","2"],["62646","0.04910858","0","1"],["62645.8","0.036","0","1"],["62644.7","0.01947458","0","1"],["62644.4","0.00035852","0","1"],["62644.1","0.19565072","0","1"],["62644","0.14732524","0","2"],["62643.9","0.00165798","0","2"],["62643.7","0.00638866","0","1"],["62643.6","0.70577431","0","1"],["62643.5","1.33711014","0","1"],["62642.6","0.56685054","0","2"],["62642.5","0.2317","0","2"],["62642.3","0.19875317","0","2"],["62641.8","0.03193448","0","1"],["62641.5","0.036","0","1"],["62641.4","0.00001604","0","1"],["62641.3","0.14227558","0","2"],["62641.2","0.03194","0","1"],["62641","0.54988944","0","1"],["62640.9","1.33711014","0","1"],["62640.8","0.000015","0","1"],["62640.6","0.02677174","0","1"],["62639.3","0.04790662","0","1"],["62639.2","0.00052959","0","7"],["62639.1","0.00003944","0","3"],["62639","0.24431575","0","2"],["62638.9","0.00001604","0","1"],["62638.8","0.92603589","0","2"],["62638.2","0.00035852","0","1"],["62638.1","0.86925857","0","2"],["62638","1.33711014","0","1"],["62637.8","0.036","0","1"],["62637.6","0.00196243","0","1"],["62637.4","0.02394569","0","1"],["62637.1","0.03192995","0","1"],["62637","1.415376","0","2"],["62636.4","0.00001604","0","1"],["62636.2","0.24480859","0","2"],["62635.9","0.01596528","0","1"],["62635.7","0.03591853","0","1"],["62635.6","0.036","0","1"],["62635.4","0.53480459","0","2"],["62635.3","1.33711014","0","1"],["62634.9","0.45505708","0","2"],["62634.6","0.00035861","0","1"],["62634.5","0.00001501","0","1"],["62633.9","0.00001604","0","1"],["62633.3","0.03193448","0","1"],["62633.1","0.00029989","0","1"],["62631.4","0.00001604","0","1"],["62630.6","0.96180984","0","2"],["62630.5","0.44709973","0","1"],["62630.4","1.41524911","0","2"],["62630.3","0.00201988","0","1"],["62630.1","0.00001116","0","1"],["62630","0.00002501","0","2"],["62629.9","1.41516384","0","2"],["62629.3","0.1957","0","1"],["62628.9","0.00001604","0","1"],["62628.5","0.09817408","0","1"],["62628.2","0.00001501","0","1"],["62626.7","0.0001","0","1"],["62626.4","0.00001604","0","1"],["62626.3","0.13345927","0","1"],["62626.2","0.44709973","0","1"],["62626","0.036","0","1"],["62625.9","0.001278","0","1"],["62625.4","0.48571769","0","3"],["62625","0.00265553","0","3"],["62624.8","0.21945","0","1"],["62624.7","1.36904462","0","2"],["62624.6","0.13602235","0","3"],["62624.3","0.00794397","0","1"],["62623.9","0.00001604","0","1"],["62622.8","0.00202057","0","1"],["62622.4","0.1957","0","1"],["62621.9","0.000015","0","1"],["62621.6","0.03591853","0","1"],["62621.4","0.00001604","0","1"],["62621.2","0.54914879","0","1"],["62621.1","1.33711014","0","1"],["62621","0.44709973","0","1"],["62620.9","7.71797656","0","1"],["62620.8","0.036","0","1"],["62620.1","0.01947458","0","1"],["62619.2","0.00046015","0","1"],["62618.9","0.00001604","0","1"],["62617.9","0.01277748","0","1"],["62617.8","0.1","0","1"],["62617.4","0.00049983","0","1"],["62617.1","0.036","0","1"],["62616.9","1.14665033","0","1"],["62616.8","1.33711014","0","1"],["62616.5","0.03193448","0","1"],["62616.4","0.23663206","0","2"],["62615.6","0.00001501","0","1"],["62614.6","0.44709973","0","1"],["62614.5","0.1957","0","1"],["62613.9","0.00001604","0","1"],["62613.8","1.33711014","0","1"],["62613.7","0.01978236","0","1"],["62613.6","0.02862","0","1"],["62611.4","0.00001604","0","1"],["62610.7","0.036","0","1"],["62610.4","1.60871818","0","3"],["62610.3","1.33711014","0","1"],["62610.2","0.03466246","0","2"],["62610.1","0.44709973","0","1"],["62609.9","2.759946","0","1"],["62609.6","0.00029999","0","1"],["62609.3","0.00001501","0","1"],["62608.9","0.00001604","0","1"],["62608.2","0.00147742","0","1"],["62608.1","0.036","0","1"],["62607.7","0.00284661","0","1"],["62607.6","0.23161853","0","2"],["62607.1","0.92922727","0","2"],["62606.5","0.01947458","0","1"],["62606.4","1.33712618","0","2"],["62606.3","0.44709973","0","1"],["62606","0.00001","0","1"],["62605.8","0.04666268","0","2"],["62605.4","1.26878","0","2"],["62604.5","0.036","0","1"],["62603.9","0.00001604","0","1"],["62603.6","0.43377431","0","1"],["62603.5","1.33711014","0","1"],["62603.2","0.031943","0","1"],["62603","0.03601501","0","2"],["62601.7","0.00069999","0","1"],["62601.4","0.00001604","0","1"],["62601.2","0.44709973","0","1"],["62601","0.74131456","0","2"],["62600.9","1.33711014","0","1"],["62600.4","1.19579","0","1"],["62600","0.08015915","0","2"],["62599.2","0.00046015","0","1"],["62598.9","0.00001604","0","1"],["62598.7","0.00001501","0","1"],["62598.4","0.03193448","0","1"],["62598.2","0.1957","0","1"],["62597.5","0.56943381","0","1"],["62597.4","0.44709973","0","1"],["62597.3","1.35308404","0","2"],["62597","0.00793747","0","1"],["62596.4","0.00001604","0","1"],["62595.5","0.01947458","0","1"],["62594.9","0.46768944","0","1"],["62594.8","0.89006564","0","2"],["62594.7","1.33711014","0","1"],["62593.9","0.00001604","0","1"],["62593.7","0.0015","0","1"],["62593.2","0.44709973","0","1"],["62592.1","1.36904462","0","2"],["62591.4","0.00001605","0","1"],["62590.1","0.1957","0","1"],["62589.6","0.00001603","0","1"],["62588.9","0.44709973","0","1"],["62588.8","0.00001605","0","1"],["62588.5","1.33711014","0","1"],["62588.1","0.0015246","0","1"],["62587.8","0.00001","0","1"],["62586.1","0.00029999","0","1"],["62585.9","0.00019173","0","3"],["62585.6","0.02052","0","1"],["62585.4","0.03193448","0","1"],["62585.2","1.33711014","0","1"],["62585","0.44709973","0","1"],["62582.5","0.00394015","0","1"],["62582.4","0.01947458","0","1"],["62581.3","0.19981694","0","2"],["62581.2","1.78420987","0","2"],["62579.6","0.1957","0","1"],["62579.4","0.02352","0","1"],["62579.2","0.00365609","0","3"],["62578.5","0.03193448","0","1"],["62578.2","0.00049999","0","1"],["62578.1","1.41857183","0","2"],["62577","0.44709973","0","1"],["62576.3","0.00001605","0","1"],["62575","0.00012007","0","1"],["62573.7","0.39406105","0","2"],["62573.6","1.33711014","0","1"],["62573.1","0.44709973","0","1"],["62572","0.618966","0","1"],["62571.3","0.1957","0","1"],["62570.5","0.00001","0","1"],["62570.4","1.33711014","0","1"],["62569.9","0.003194","0","1"],["62568.2","0.03193448","0","1"],["62567.9","0.01947458","0","1"],["62567.6","5.05711014","0","2"],["62567.4","0.44711474","0","2"],["62566.5","0.03454981","0","1"],["62566.3","0.00001603","0","1"],["62564.8","0.1957","0","1"],["62563","0.35796825","0","1"],["62562.9","1.33711014","0","1"],["62562.6","0.44739972","0","2"],["62561.9","0.03193448","0","1"],["62561.3","0.00001604","0","1"],["62560.3","1.33711014","0","1"],["62560.2","0.10919289","0","1"],["62559.8","0.11972845","0","1"],["62559.6","0.00015987","0","1"],["62559.2","0.00046015","0","1"],["62558.8","0.44709973","0","1"],["62557.6","1.53281014","0","2"],["62555.8","0.00004907","0","1"],["62555.1","0.03193448","0","1"],["62555","1.33720605","0","2"],["62554.2","0.44709973","0","1"],["62554","0.00001","0","1"],["62553.8","0.00001604","0","1"],["62553.4","0.01596","0","1"],["62552.4","0.01947458","0","1"],["62551.4","1.33711014","0","1"],["62550","0.19901751","0","3"],["62549.4","0.03991197","0","1"],["62548.8","1.81616039","0","4"],["62548.5","0.0031912","0","1"],["62547.9","0.00181061","0","1"],["62546.9","0.00069889","0","1"],["62546.2","1.33711014","0","1"],["62546.1","0.00084138","0","1"],["62545.2","0.01947458","0","1"],["62543.3","0.44709973","0","1"],["62542.9","0.0001599","0","1"],["62542.4","8.22742827","0","2"],["62541.2","0.00792953","0","1"],["62540.5","0.0249924","0","1"],["62540","0.00793103","0","1"],["62539.9","0.00135474","0","1"],["62539.5","0.44709973","0","1"],["62539.4","0.1957","0","1"],["62539.2","0.00046015","0","1"],["62539.1","0.00079998","0","2"],["62539","0.00001604","0","1"],["62538.8","0.10338604","0","2"],["62538.3","0.00001","0","1"],["62537.5","0.03193448","0","1"],["62537.3","0.00792966","0","1"],["62536.7","0.00015993","0","1"],["62536.1","0.00001501","0","1"],["62534.3","0.01947458","0","1"],["62534.2","0.44709973","0","1"],["62533.3","0.00009736","0","1"],["62531.4","0.1957","0","1"],["62531.3","0.00001604","0","1"],["62531.2","0.00010266","0","1"],["62531","0.03193448","0","1"],["62530.1","0.25441672","0","1"],["62526.6","0.0147","0","1"],["62525.8","0.00001845","0","1"],["62525","0.01959465","0","2"],["62524.5","7.98183","0","1"],["62523.8","0.19571604","0","2"],["62523.3","0.00001","0","1"],["62522.2","0.014","0","1"],["62522.1","0.02404349","0","1"],["62521.4","0.00833104","0","1"],["62520.9","0.00078","0","1"],["62520.8","0.00009727","0","1"],["62520","0.00319897","0","1"],["62519.2","0.00046015","0","1"],["62518.1","0.01947458","0","1"],["62517.2","0.00001472","0","1"],["62516.3","0.00001605","0","1"],["62515.6","0.1957","0","1"],["62515.1","0.00029121","0","1"],["62514.7","0.03174755","0","2"],["62513.8","0.00015999","0","1"],["62512.9","0.00003409","0","1"],["62512.2","0.0028","0","1"],["62511.9","0.00063987","0","1"],["62511.5","0.12772932","0","1"],["62511.3","0.00007474","0","2"],["62510","0.00003199","0","1"],["62509.9","0.00001936","0","1"],["62509.1","0.00001","0","1"],["62508.7","0.00010672","0","1"],["62508.3","0.02404349","0","1"],["62507.4","0.00015999","0","1"],["62507.3","0.00007843","0","1"],["62506.7","3.023661","0","1"],["62506.5","0.01947458","0","1"],["62506.1","0.1957","0","1"],["62504.8","0.00001501","0","1"],["62504.3","0.00003406","0","1"],["62504.1","0.00028622","0","4"],["62503.1","0.00285748","0","1"],["62502.9","0.00001631","0","1"],["62502.7","0.000129","0","1"],["62502.2","0.00001501","0","1"],["62501.9","0.02404349","0","1"],["62501.2","0.00041121","0","2"],["62500","1.63587196","0","15"],["62499.9","0.0086082","0","12"],["62499.8","0.1957","0","1"],["62499.2","0.00046015","0","1"],["62498.7","0.18923993","0","3"],["62498","0.00001057","0","1"],["62497.7","0.00016002","0","1"],["62497.5","0.02478","0","1"],["62497","0.00692164","0","1"],["62495.9","0.00001501","0","1"],["62495.6","0.01947458","0","1"],["62495.5","0.00001","0","1"],["62494.8","0.00001605","0","1"],["62493.8","0.00001607","0","1"],["62493.5","0.1957","0","1"],["62493","0.02404349","0","1"],["62492.2","0.00069933","0","1"],["62490.9","0.00016005","0","1"],["62490.7","0.00034809","0","1"],["62490.5","0.00017586","0","1"],["62490.4","0.00006582","0","1"],["62490.2","0.01947458","0","1"],["62490","0.00320051","0","1"],["62489.6","0.00001501","0","1"],["62488.9","0.00030476","0","1"],["62487.6","0.00012785","0","1"],["62487.2","0.1957","0","1"],["62486.3","0.00001608","0","1"],["62485.2","0.00009707","0","1"],["62485.1","0.02404349","0","1"],["62483.3","0.00001501","0","1"],["62482.6","0.00001","0","1"],["62481.4","0.01947458","0","1"],["62480.7","0.03097216","0","1"],["62480.6","5.433549","0","1"],["62480","0.01180773","0","2"],["62479.9","0.00001005","0","1"],["62479.2","0.00046015","0","1"],["62478.8","0.02405955","0","2"],["62478.2","0.00050414","0","1"],["62477.2","0.00003632","0","1"],["62477","0.00001501","0","1"]],"ts":"1781847931208","checksum":1509421807,"seqId":77651173699,"prevSeqId":-1}]}
{"arg":{"channel":"books","instId":"BTC-USDT"},"action":"update","data":[{"asks":[["62669.5","0","0","0"],["62670.6","0.00798583","0","1"],["62678.1","0.16801341","0","3"],["62679.8","0.00001501","0","1"],["62760.6","0.00002056","0","2"]],"bids":[["62657.5","0.00798583","0","1"],["62656.4","0","0","0"],["62644.1","0","0","0"],["62643.6","0.90142739","0","2"],["62475","0.00012007","0","1"]],"ts":"1781847931308","checksum":-899515793,"seqId":77651173712,"prevSeqId":77651173699}]}
{"arg":{"channel":"books","instId":"BTC-USDT"},"action":"update","data":[{"asks":[],"bids":[["62643.6","0.70577431","0","1"],["62642.7","0.19565318","0","1"],["62475","0","0","0"]],"ts":"1781847931408","checksum":-899515793,"seqId":77651173728,"prevSeqId":77651173712}]}
{"arg":{"channel":"books","instId":"BTC-USDT"},"action":"update","data":[{"asks":[["62669.5","0.00798585","0","1"],["62670.6","0","0","0"],["62688","0.22875848","0","2"]],"bids":[["62657.5","0","0","0"],["62656.9","0.00798585","0","1"],["62639.1","0.00004944","0","4"]],"ts":"1781847931508","checksum":-1303686390,"seqId":77651173739,"prevSeqId":77651173728}]}
{"arg":{"channel":"books","instId":"BTC-USDT"},"action":"update","data":[{"asks":[],"bids":[["62639.1","0.00003944","0","3"]],"ts":"1781847931608","checksum":-1303686390,"seqId":77651173747,"prevSeqId":77651173739}]}
{"arg":{"channel":"books","instId":"BTC-USDT"},"action":"update","data":[{"asks":[],"bids":[["62638.8","0.44709973","0","1"]],"ts":"1781847931808","checksum":-1303686390,"seqId":77651173760,"prevSeqId":77651173747}]}
{"arg":{"channel":"books","instId":"BTC-USDT"},"action":"update","data":[{"asks":[["62669.5","0","0","0"],["62670.6","0.00798582","0","1"],["62677.5","0","0","0"],["62678.7","0.1597357","0","1"],["62688","0.20147874","0","1"]],"bids":[["62658.1","0.00798582","0","1"],["62657.2","0.24670723","0","2"],["62656.9","0","0","0"],["62654.8","0.44709973","0","1"],["62650.2","0.1597357","0","1"],["62647.8","0","0","0"],["62635.4","1.0137668","0","3"],["62477","0","0","0"]],"ts":"1781847931908","checksum":-826925748,"seqId":77651173777,"prevSeqId":77651173760}]}
{"arg":{"channel":"books","instId":"BTC-USDT"},"action":"update","data":[{"asks":[["62678.1","0.01598563","0","2"],["62678.2","0.60683584","0","2"],["62678.6","0.15201982","0","2"],["62678.7","0","0","0"],["62765","0.000033","0","1"]],"bids":[["62658.1","0","0","0"],["62657.5","0.00798581","0","1"],["62650.2","0","0","0"],["62649.6","0.15973611","0","1"],["62643.7","0.20204114","0","2"],["62642.7","0","0","0"],["62477","0.00001501","0","1"]],"ts":"1781847932008","checksum":262177645,"seqId":77651173793,"prevSeqId":77651173777}]}
{"arg":{"channel":"books","instId":"BTC-USDT"},"action":"update","data":[{"asks":[["62678.6","0.00001064","0","1"],["62678.7","0.15200918","0","1"],["62765","0","0","0"]],"bids":[["62637.6","0","0","0"],["62621.2","2.78275422","0","3"],["62594.8","0.40386518","0","1"],["62573.7","0.0396277","0","1"],["62563","0","0","0"],["62475","0.00012007","0","1"],["62474.7","0.01947458","0","1"]],"ts":"1781847932108","checksum":262177645,"seqId":77651173817,"prevSeqId":77651173793}]}
{"arg":{"channel":"books","instId":"BTC-USDT"},"action":"update","data":[{"asks":[],"bids":[["62639.1","0.00004944","0","4"],["62637.6","0.00196789","0","1"],["62474.7","0","0","0"]],"ts":"1781847932208","checksum":262177645,"seqId":77651173826,"prevSeqId":77651173817}]}
{"arg":{"channel":"books","instId":"BTC-USDT"},"action":"update","data":[{"asks":[["62666.2","1.48130031","0","13"],["62667.8","0.0456594","0","1"],["62667.9","0.08842995","0","1"],["62668.5","0","0","0"],["62669.6","0.03469527","0","1"],["62670","0","0","0"],["62670.6","0","0","0"],["62672.2","0.00798564","0","1"],["62678.2","0.44709973","0","1"],["62678.7","0","0","0"],["62680.2","0.16003192","0","2"],["62680.4","0.15200918","0","1"],["62687.9","1.3642767","0","2"]],"bids":[["62666.1","1.33977927","0","14"],["62665.1","0.04453462","0","2"],["62665","0.08725799","0","1"],["62664.9","0","0","0"],["62663.7","0","0","0"],["62659.8","0.49024292","0","3"],["62659.4","0.00798564","0","1"],["62657.5","0","0","0"],["62653.5","0","0","0"],["62651.2","0.15973506","0","1"],["62649.6","0","0","0"],["62644.1","0.19564606","0","1"],["62644","0.62622164","0","3"],["62643.7","0.00638866","0","1"],["62641","0.64806352","0","2"],["62635.4","0.53480459","0","2"],["62628.5","0","0","0"],["62601.9","0.08003908","0","1"],["62600","0.00012007","0","1"],["62474.7","0.01947458","0","1"]],"ts":"1781847932308","checksum":-153168928,"seqId":77651173922,"prevSeqId":77651173826}]}
{"arg":{"channel":"books","instId":"BTC-USDT"},"action":"update","data":[{"asks":[["62669.6","0.06351819","0","2"],["62670","0.1034336","0","1"],["62672.2","0.00798563","0","1"],["62679.8","0.15202419","0","2"],["62680.4","0","0","0"],["62687.9","1.33711014","0","1"]],"bids":[["62659.4","0.00798563","0","1"],["62623.1","7.66195807","0","1"],["62621.2","0.54914879","0","1"],["62620.9","0","0","0"]],"ts":"1781847932408","checksum":-830575017,"seqId":77651173948,"prevSeqId":77651173922}]}
{"arg":{"channel":"books","instId":"BTC-USDT"},"action":"update","data":[{"asks":[["62669.6","0.03469527","0","1"],["62670","0","0","0"],["62672.2","0.00798562","0","1"],["62765","0.000033","0","1"]],"bids":[["62659.4","0.00798562","0","1"],["62641","0.54988944","0","1"],["62639.1","0.00003","0","3"],["62628.5","0.09817408","0","1"],["62474.7","0","0","0"]],"ts":"1781847932508","checksum":-646049011,"seqId":77651173969,"prevSeqId":77651173948}]}
{"arg":{"channel":"books","instId":"BTC-USDT"},"action":"update","data":[{"asks":[["62669.6","0.06340755","0","2"],["62670","0.10306296","0","1"],["62679.8","0.00001501","0","1"],["62680.1","0.15199059","0","1"],["62762","0","0","0"],["62765","0","0","0"]],"bids":[["62659","0.04641603","0","2"]],"ts":"1781847932608","checksum":-1045950898,"seqId":77651173979,"prevSeqId":77651173969}]}
{"arg":{"channel":"books","instId":"BTC-USDT"},"action":"update","data":[{"asks":[["62671.3","0.00798552","0","1"],["62672.2","0","0","0"],["62679.8","0.15975103","0","2"],["62680.1","0","0","0"],["62680.2","0.15229058","0","2"],["62765","0.000033","0","1"]],"bids":[["62659.4","0","0","0"],["62658.1","0.00798552","0","1"],["62651.2","0","0","0"],["62650.8","0.15973602","0","1"],["62644.1","0.1956478","0","1"],["62639.1","0.00002","0","2"],["62628.5","0","0","0"],["62474.7","0.01947458","0","1"]],"ts":"1781847932708","checksum":-1960698524,"seqId":77651174007,"prevSeqId":77651173979}]}
{"arg":{"channel":"books","instId":"BTC-USDT"},"action":"update","data":[{"asks":[["62671.3","0","0","0"],["62671.6","0.0079856","0","1"],["62688","0.22875578","0","2"]],"bids":[["62641","0.64806352","0","2"]],"ts":"1781847932808","checksum":1708792320,"seqId":77651174017,"prevSeqId":77651174007}]}
{"arg":{"channel":"books","instId":"BTC-USDT"},"action":"update","data":[{"asks":[["62696.1","0.00027104","0","1"]],"bids":[["62666.1","1.0081328","0","12"],["62646.4","2.231662","0","1"],["62639.2","0.00056025","0","8"],["62630.1","0","0","0"]],"ts":"1781847932908","checksum":-1448875984,"seqId":77651174032,"prevSeqId":77651174017}]}
{"arg":{"channel":"books","instId":"BTC-USDT"},"action":"update","data":[{"asks":[["62666.2","1.61566837","0","14"],["62666.4","0.04459336","0","1"],["62666.5","0.08484361","0","2"],["62667.8","0","0","0"],["62667.9","0","0","0"],["62670.6","0.00798564","0","1"],["62671.6","0","0","0"],["62678.1","0.17572051","0","3"],["62679.8","0.00001501","0","1"],["62688","0.20147874","0","1"],["62701.2","0.008331","0","1"],["62731.4","0","0","0"],["62765.1","0.00001671","0","1"]],"bids":[["62666.1","0.9721328","0","11"],["62659.8","0.1957","0","1"],["62658.1","0","0","0"],["62657.5","0.00798564","0","1"],["62653.5","0.29454292","0","2"],["62650.8","0","0","0"],["62649.6","0.15973415","0","1"],["62646.4","0","0","0"],["62644","0.14732524","0","2"],["62637.6","0","0","0"],["62623.1","0","0","0"],["62620.9","7.63760054","0","1"],["62473.9","0.00001113","0","1"]],"ts":"1781847933008","checksum":-1820668471,"seqId":77651174082,"prevSeqId":77651174032}]}
{"arg":{"channel":"books","instId":"BTC-USDT"},"action":"update","data":[{"asks":[["62666.2","1.62052837","0","15"],["62670.6","0.00798572","0","1"],["62678.1","0.01598563","0","2"],["62678.6","0.1597453","0","2"],["62678.7","0.15199059","0","1"],["62680.2","0.00029999","0","1"],["62687.6","1.17904038","0","2"],["62765.1","0","0","0"]],"bids":[["62646.4","2.048","0","1"],["62641","0.54988944","0","1"],["62639.8","0.47892851","0","1"],["62637.6","0.00196789","0","1"],["62628.5","0.09817408","0","1"],["62621.2","2.75876198","0","2"],["62477","0","0","0"],["62475","0","0","0"],["62474.7","0","0","0"],["62473.9","0","0","0"]],"ts":"1781847933108","checksum":1718092702,"seqId":77651174112,"prevSeqId":77651174082}]}
{"arg":{"channel":"books","instId":"BTC-USDT"},"action":"update","data":[{"asks":[["62666.2","1.48616031","0","14"],["62678.6","0.15974524","0","2"]],"bids":[["62649.7","0.1597346","0","1"],["62649.6","0","0","0"],["62646.4","0","0","0"],["62477","0.00001501","0","1"]],"ts":"1781847933208","checksum":2001685450,"seqId":77651174134,"prevSeqId":77651174112}]}
{"arg":{"channel":"books","instId":"BTC-USDT"},"action":"update","data":[{"asks":[["62678.2","0.59923907","0","2"],["62678.7","0","0","0"],["62765.1","0.00001671","0","1"]],"bids":[["62644.1","0","0","0"],["62643.7","0.20204146","0","2"],["62475","0.00012007","0","1"]],"ts":"1781847933308","checksum":2001685450,"seqId":77651174146,"prevSeqId":77651174134}]}
{"arg":{"channel":"books","instId":"BTC-USDT"},"action":"update","data":[{"asks":[],"bids":[["62601.9","0","0","0"],["62599.9","0.08003908","0","1"]],"ts":"1781847933408","checksum":2001685450,"seqId":77651174152,"prevSeqId":77651174146}]}
{"arg":{"channel":"books","instId":"BTC-USDT"},"action":"update","data":[{"asks":[["62678.1","0.16812497","0","3"],["62678.2","0.44709973","0","1"]],"bids":[["62643.7","0.00638866","0","1"],["62642.7","0.19565325","0","1"],["62475","0","0","0"]],"ts":"1781847933508","checksum":2001685450,"seqId":77651174165,"prevSeqId":77651174152}]}
{"arg":{"channel":"books","instId":"BTC-USDT"},"action":"update","data":[{"asks":[["62764","0.00069795","0","3"]],"bids":[["62659","0.04691603","0","3"]],"ts":"1781847933608","checksum":-1695287415,"seqId":77651174171,"prevSeqId":77651174165}]}
{"arg":{"channel":"books","instId":"BTC-USDT"},"action":"update","data":[{"asks":[["62666.2","1.48442732","0","14"]],"bids":[["62637.6","0","0","0"],["62475","0.00012007","0","1"]],"ts":"1781847933708","checksum":-1595734316,"seqId":77651174179,"prevSeqId":77651174171}]}
{"arg":{"channel":"books","instId":"BTC-USDT"},"action":"update","data":[{"asks":[],"bids":[["62637.6","0.0019875","0","1"],["62475","0","0","0"]],"ts":"1781847933808","checksum":-1595734316,"seqId":77651174184,"prevSeqId":77651174179}]}
{"arg":{"channel":"books","instId":"BTC-USDT"},"action":"update","data":[{"asks":[],"bids":[["62616.4","0.00001604","0","1"]],"ts":"1781847933908","checksum":-1595734316,"seqId":77651174192,"prevSeqId":77651174184}]}
{"arg":{"channel":"books","instId":"BTC-USDT"},"action":"update","data":[{"asks":[["62678.1","0.32785984","0","4"],["62678.6","0.00001064","0","1"]],"bids":[["62649.8","0.15973487","0","1"],["62649.7","0","0","0"],["62641","0.64806352","0","2"],["62628.5","0","0","0"],["62543.3","0.72052149","0","2"],["62475","0.00012007","0","1"]],"ts":"1781847934008","checksum":-1595734316,"seqId":77651174212,"prevSeqId":77651174192}]}
{"arg":{"channel":"books","instId":"BTC-USDT"},"action":"update","data":[{"asks":[["62669.9","0.00798585","0","1"],["62670.6","0","0","0"],["62678.1","0.16812497","0","3"],["62678.2","0.60683464","0","2"]],"bids":[["62666.1","0.97204046","0","12"],["62649.8","0","0","0"],["62649.6","0.15973487","0","1"],["62641","0.54988944","0","1"],["62628.5","0.09817408","0","1"],["62617.9","0.05352268","0","2"],["62475","0","0","0"]],"ts":"1781847934108","checksum":-1094369572,"seqId":77651174239,"prevSeqId":77651174212}]}
{"arg":{"channel":"books","instId":"BTC-USDT"},"action":"update","data":[{"asks":[["62669.9","0","0","0"],["62670.6","0.00798585","0","1"],["62678.1","0.01598563","0","2"],["62678.2","0.44709973","0","1"],["62678.5","0.15978366","0","2"],["62678.6","0.15211279","0","2"]],"bids":[["62666.1","1.1063484","0","13"],["62659.8","0.49024292","0","3"],["62653.5","0","0","0"],["62650.2","0.15973377","0","1"],["62649.6","0","0","0"],["62646.4","2.038081","0","1"],["62643.7","0.20204067","0","2"],["62642.7","0","0","0"],["62641","0.64806352","0","2"],["62628.5","0","0","0"],["62475","0.00012007","0","1"],["62474.7","0.01947458","0","1"]],"ts":"1781847934208","checksum":925537845,"seqId":77651174270,"prevSeqId":77651174239}]}
{"arg":{"channel":"books","instId":"BTC-USDT"},"action":"update","data":[{"asks":[],"bids":[["62650.2","0","0","0"],["62649.6","0.15973417","0","1"],["62646.4","2.194985","0","1"]],"ts":"1781847934308","checksum":925537845,"seqId":77651174290,"prevSeqId":77651174270}]}
{"arg":{"channel":"books","instId":"BTC-USDT"},"action":"update","data":[{"asks":[],"bids":[["62666.1","0.97204046","0","12"],["62649.6","0.15973435","0","1"],["62646.4","0","0","0"],["62473.9","0.00001113","0","1"]],"ts":"1781847934408","checksum":-298711259,"seqId":77651174308,"prevSeqId":77651174290}]}
{"arg":{"channel":"books","instId":"BTC-USDT"},"action":"update","data":[{"asks":[["62670.6","0","0","0"],["62671.3","0.00798585","0","1"],["62678.1","0.16806919","0","3"],["62678.5","0.00004989","0","1"],["62678.6","0.00001064","0","1"],["62679.8","0.15975004","0","2"]],"bids":[["62658.1","0.00798585","0","1"],["62657.5","0","0","0"],["62650.2","0.15973958","0","1"],["62649.6","0","0","0"],["62646.4","1.928312","0","1"],["62643.7","0.00638866","0","1"],["62643.6","0.90142748","0","2"],["62473.9","0","0","0"]],"ts":"1781847934508","checksum":-1862010360,"seqId":77651174352,"prevSeqId":77651174308}]}
{"arg":{"channel":"books","instId":"BTC-USDT"},"action":"update","data":[{"asks":[["62670.6","0.00798582","0","1"],["62671.3","0","0","0"],["62678.1","0.01598563","0","2"],["62678.7","0.15973996","0","1"],["62679.8","0.00001501","0","1"],["62765.1","0","0","0"]],"bids":[["62659.8","0.34297146","0","2"],["62653.5","0.14727146","0","1"],["62646.4","2.230293","0","1"],["62643.7","0.2020414","0","2"],["62643.6","0.70577431","0","1"],["62474.7","0","0","0"]],"ts":"1781847934608","checksum":1715131897,"seqId":77651174377,"prevSeqId":77651174352}]}
{"arg":{"channel":"books","instId":"BTC-USDT"},"action":"update","data":[{"asks":[],"bids":[["62659.8","0.1957","0","1"],["62658.1","0","0","0"],["62657.5","0.00798582","0","1"],["62653.5","0.29454292","0","2"],["62650.2","0","0","0"],["62649.6","0.15974017","0","1"],["62646.4","0","0","0"],["62641","0.54988944","0","1"],["62628.5","0.09817408","0","1"]],"ts":"1781847934708","checksum":-682883644,"seqId":77651174394,"prevSeqId":77651174377}]}
{"arg":{"channel":"books","instId":"BTC-USDT"},"action":"update","data":[{"asks":[],"bids":[["62641","0.64806352","0","2"],["62628.5","0","0","0"],["62474.7","0.01947458","0","1"]],"ts":"1781847935108","checksum":-682883644,"seqId":77651174423,"prevSeqId":77651174394}]}
{"arg":{"channel":"books","instId":"BTC-USDT"},"action":"update","data":[{"asks":[],"bids":[["62637.6","0","0","0"],["62473.9","0.00001113","0","1"]],"ts":"1781847935208","checksum":-682883644,"seqId":77651174430,"prevSeqId":77651174423}]}
{"arg":{"channel":"books","instId":"BTC-USDT"},"action":"update","data":[{"asks":[],"bids":[["62637.6","0.00198501","0","1"],["62473.9","0","0","0"]],"ts":"1781847935308","checksum":-682883644,"seqId":77651174440,"prevSeqId":77651174430}]}
{"arg":{"channel":"books","instId":"BTC-USDT"},"action":"update","data":[{"asks":[["62678.1","0.17572497","0","3"],["62678.7","0","0","0"],["62765.1","0.00001671","0","1"]],"bids":[],"ts":"1781847935408","checksum":-682883644,"seqId":77651174453,"prevSeqId":77651174440}]}
{"arg":{"channel":"books","instId":"BTC-USDT"},"action":"update","data":[{"asks":[],"bids":[["62639.2","0.00057025","0","9"]],"ts":"1781847935508","checksum":-682883644,"seqId":77651174458,"prevSeqId":77651174453}]}
{"arg":{"channel":"books","instId":"BTC-USDT"},"action":"update","data":[{"asks":[["62669.5","0.00798579","0","1"],["62670.6","0","0","0"],["62677.4","0.16207099","0","3"],["62678.1","0.01598563","0","2"],["62747.3","0.00017588","0","13"],["62764","0.00019795","0","2"]],"bids":[["62659","0.04641603","0","2"],["62657.5","0","0","0"],["62656.6","0.00798579","0","1"],["62649.6","0","0","0"],["62647.9","0.15973933","0","1"],["62643.7","0.20204071","0","2"],["62639.2","0.00055081","0","8"],["62639.1","0.00001","0","1"]],"ts":"1781847935708","checksum":-1596841907,"seqId":77651174506,"prevSeqId":77651174458}]}
{"arg":{"channel":"books","instId":"BTC-USDT"},"action":"update","data":[{"asks":[["62669.5","0","0","0"],["62669.9","0.0079858","0","1"],["62677.4","0.00233166","0","2"],["62677.6","0.19166997","0","2"],["62760.6","0.00001028","0","1"]],"bids":[["62666.1","1.08062105","0","13"],["62657.1","0.0079858","0","1"],["62656.6","0","0","0"],["62649.4","0.15973549","0","1"],["62647.9","0","0","0"]],"ts":"1781847935808","checksum":342785228,"seqId":77651174526,"prevSeqId":77651174506}]}
{"arg":{"channel":"books","instId":"BTC-USDT"},"action":"update","data":[{"asks":[["62669.6","0.03469527","0","1"],["62669.9","0","0","0"],["62670","0","0","0"],["62671.3","0.00798583","0","1"],["62677.6","0.03193448","0","1"],["62679.8","0.1597495","0","2"],["62760.6","0.00002056","0","2"],["62765.4","0.00303109","0","1"]],"bids":[["62658.1","0.00798583","0","1"],["62657.1","0","0","0"],["62650.2","0.15973449","0","1"],["62649.4","0","0","0"],["62643.8","0.19565212","0","1"],["62643.7","0.00638866","0","1"],["62637.6","0","0","0"]],"ts":"1781847935908","checksum":174155568,"seqId":77651174559,"prevSeqId":77651174526}]}
{"arg":{"channel":"books","instId":"BTC-USDT"},"action":"update","data":[{"asks":[],"bids":[["62650.8","0.15973461","0","1"],["62650.2","0","0","0"],["62644.1","0.19565022","0","1"],["62643.8","0","0","0"],["62637.6","0.00198501","0","1"],["62539.9","0","0","0"]],"ts":"1781847936008","checksum":174155568,"seqId":77651174577,"prevSeqId":77651174559}]}
{"arg":{"channel":"books","instId":"BTC-USDT"},"action":"update","data":[{"asks":[["62669.6","0.06505805","0","2"],["62670","0.10859205","0","1"],["62671.3","0","0","0"],["62671.6","0.00798572","0","1"],["62747.3","0.0001656","0","12"],["62765.4","0","0","0"]],"bids":[["62659.1","0.00798572","0","1"],["62658.1","0","0","0"],["62651","0.60683443","0","2"],["62650.8","0","0","0"],["62633.7","0.07711318","0","1"],["62629.9","1.33711014","0","1"]],"ts":"1781847936108","checksum":-52243812,"seqId":77651174599,"prevSeqId":77651174577}]}
{"arg":{"channel":"books","instId":"BTC-USDT"},"action":"update","data":[{"asks":[["62671.3","0.00798572","0","1"],["62671.6","0","0","0"]],"bids":[["62666.1","0.97204046","0","12"],["62660.3","1.03692932","0","2"],["62660","0.0464","0","1"],["62659.1","0","0","0"],["62658.1","0.00798572","0","1"],["62651","0.44709973","0","1"],["62650.2","0.15973883","0","1"],["62644.1","0","0","0"],["62643.6","0.90142742","0","2"],["62639.2","0.00056081","0","9"]],"ts":"1781847936208","checksum":-902861340,"seqId":77651174619,"prevSeqId":77651174599}]}
{"arg":{"channel":"books","instId":"BTC-USDT"},"action":"update","data":[{"asks":[],"bids":[["62654.1","1.21183946","0","2"],["62653","3.33711014","0","2"],["62635.3","1.33712014","0","2"],["62625","0.00264553","0","2"],["62621","0.44710973","0","2"],["62607.4","0.00001","0","1"],["62606","0","0","0"],["62594.4","0.00001","0","1"],["62587.8","0","0","0"],["62582","0.00001","0","1"],["62570.5","0","0","0"],["62570.2","0.00001","0","1"],["62559","0.00001","0","1"],["62554","0","0","0"],["62548.4","0.00001","0","1"],["62539.9","0.00135474","0","1"],["62538.3","0","0","0"],["62538.2","0.00001","0","1"],["62528.5","0.00001","0","1"],["62523.3","0","0","0"],["62519.3","0.00001","0","1"],["62510.5","0.00001","0","1"],["62509.1","0","0","0"],["62502.1","0.00001","0","1"],["62495.5","0","0","0"],["62494.2","0.00001","0","1"],["62486.6","0.00001","0","1"],["62482.6","0","0","0"],["62479.3","0.00001","0","1"],["62478.8","0","0","0"],["62478.2","0","0","0"],["62477.2","0","0","0"],["62477","0","0","0"],["62475","0","0","0"],["62474.7","0","0","0"]],"ts":"1781847936308","checksum":-902861340,"seqId":77651174666,"prevSeqId":77651174619}]}
{"arg":{"channel":"books","instId":"BTC-USDT"},"action":"update","data":[{"asks":[],"bids":[["62666.1","1.09540828","0","13"],["62644.1","0.19565156","0","1"],["62643.6","0.70577431","0","1"],["62479.2","0","0","0"]],"ts":"1781847936408","checksum":1584683194,"seqId":77651174673,"prevSeqId":77651174666}]}
{"arg":{"channel":"books","instId":"BTC-USDT"},"action":"update","data":[{"asks":[],"bids":[["62666.1","0.97030921","0","12"]],"ts":"1781847936608","checksum":-288939877,"seqId":77651174685,"prevSeqId":77651174673}]}
{"arg":{"channel":"books","instId":"BTC-USDT"},"action":"update","data":[{"asks":[["62747.3","0.00015532","0","11"]],"bids":[["62666.1","0.97196444","0","13"],["62659","0.04691603","0","3"],["62644.1","0","0","0"],["62643.7","0.20204144","0","2"],["62479.2","0.00046015","0","1"]],"ts":"1781847936708","checksum":-838486193,"seqId":77651174698,"prevSeqId":77651174685}]}
{"arg":{"channel":"books","instId":"BTC-USDT"},"action":"update","data":[{"asks":[["62666.2","1.45442732","0","14"]],"bids":[["62666.1","1.08566936","0","14"],["62641","0.54988944","0","1"]],"ts":"1781847936908","checksum":-810017288,"seqId":77651174719,"prevSeqId":77651174698}]}
{"arg":{"channel":"books","instId":"BTC-USDT"},"action":"update","data":[{"asks":[["62666.2","1.45242732","0","14"],["62670.5","0.00798572","0","1"],["62671.3","0","0","0"],["62678.7","0.15973807","0","1"],["62679.8","0.00001501","0","1"],["62765.1","0","0","0"]],"bids":[["62650.2","0.15973807","0","1"],["62641","0.64806352","0","2"],["62637.6","0","0","0"],["62478.8","0.02405955","0","2"]],"ts":"1781847937008","checksum":430478362,"seqId":77651174753,"prevSeqId":77651174719}]}
{"arg":{"channel":"books","instId":"BTC-USDT"},"action":"update","data":[{"asks":[["62666.2","1.37666732","0","12"],["62666.4","0","0","0"],["62669.6","0","0","0"],["62669.8","0.03465524","0","1"],["62669.9","0.11559244","0","1"],["62670","0","0","0"],["62670.5","0","0","0"],["62672.3","0","0","0"],["62673","0.00798572","0","1"],["62673.2","0.11559244","0","1"],["62676.1","0.65741637","0","2"],["62677.6","1.36904462","0","2"],["62677.7","0","0","0"],["62678.2","0","0","0"],["62678.7","0","0","0"],["62680.2","0.16003789","0","2"],["62687.6","1.15272","0","1"],["62728.2","1.45109352","0","2"],["62765.1","0.00001671","0","1"],["62765.4","0.00303109","0","1"],["62765.8","0.00003067","0","2"],["62765.9","0.00428817","0","3"]],"bids":[["62666.1","1.12486352","0","16"],["62662.4","0.19136839","0","2"],["62660.3","1.48402905","0","3"],["62659.8","0.49024292","0","3"],["62659.6","0.00798572","0","1"],["62658.1","0","0","0"],["62653.5","0","0","0"],["62651.3","0.03193448","0","1"],["62651.2","0.1597379","0","1"],["62651.1","0","0","0"],["62650.2","0","0","0"],["62646.3","0.19564344","0","1"],["62643.7","0.00638866","0","1"],["62637.6","0.00202331","0","1"],["62478.8","0","0","0"]],"ts":"1781847937108","checksum":1881816718,"seqId":77651174808,"prevSeqId":77651174753}]}
{"arg":{"channel":"books","instId":"BTC-USDT"},"action":"update","data":[{"asks":[["62673","0.00798555","0","1"],["62678.2","0.44709973","0","1"],["62765.9","0","0","0"]],"bids":[["62666.1","1.12166936","0","15"],["62659.8","0.1957","0","1"],["62659.6","0.00798555","0","1"],["62646.3","0","0","0"],["62644.1","0.19564612","0","1"],["62625.4","0.00794515","0","1"],["62623.1","7.55602677","0","1"],["62621.2","0.54914879","0","1"],["62620.9","0","0","0"],["62602.3","0.08003908","0","1"],["62599.9","0","0","0"],["62594.8","0.89006862","0","2"],["62579.3","0.00319594","0","2"],["62579.2","0.00046015","0","1"],["62573.7","0.39406105","0","2"],["62557.7","0.61067772","0","1"],["62479.3","0","0","0"],["62479.2","0","0","0"]],"ts":"1781847937208","checksum":1994968651,"seqId":77651174851,"prevSeqId":77651174808}]}
{"arg":{"channel":"books","instId":"BTC-USDT"},"action":"update","data":[{"asks":[["62671.3","0.00798551","0","1"],["62673","0","0","0"]],"bids":[["62666.1","1.00796444","0","14"],["62659.6","0","0","0"],["62658.1","0.00798551","0","1"],["62657.2","0.83113511","0","1"],["62657","2.14902034","0","3"],["62654.1","0.69950277","0","1"],["62653.5","0.29454292","0","2"],["62653","1.33711014","0","1"],["62644.1","0.19564724","0","1"],["62623.1","7.67026276","0","1"],["62479.9","0","0","0"]],"ts":"1781847937308","checksum":-887103021,"seqId":77651174885,"prevSeqId":77651174851}]}
{"arg":{"channel":"books","instId":"BTC-USDT"},"action":"update","data":[{"asks":[["62679.8","0.15975068","0","2"],["62680.2","0.00029999","0","1"],["62713.9","0.00159109","0","1"],["62765.8","0","0","0"]],"bids":[["62651.2","0","0","0"],["62650.8","0.15973567","0","1"]],"ts":"1781847937408","checksum":-887103021,"seqId":77651174896,"prevSeqId":77651174885}]}
{"arg":{"channel":"books","instId":"BTC-USDT"},"action":"update","data":[{"asks":[["62671.3","0","0","0"],["62671.6","0.0079856","0","1"]],"bids":[["62659.1","0.0079856","0","1"],["62658.1","0","0","0"],["62637.6","0","0","0"],["62479.9","0.00001005","0","1"]],"ts":"1781847937508","checksum":-1965496188,"seqId":77651174905,"prevSeqId":77651174896}]}
{"arg":{"channel":"books","instId":"BTC-USDT"},"action":"update","data":[{"asks":[["62671.6","0","0","0"],["62673","0.00798561","0","1"],["62679.8","0.00001501","0","1"],["62680.2","0.16003641","0","2"],["62688","0.22867493","0","2"]],"bids":[["62666.1","1.11090812","0","15"],["62659.8","0.49024292","0","3"],["62659.4","0.00798561","0","1"],["62659.1","0","0","0"],["62653.5","0","0","0"],["62651.4","0.15973642","0","1"],["62650.8","0","0","0"],["62637.6","0.00202331","0","1"]],"ts":"1781847937608","checksum":1071592397,"seqId":77651174926,"prevSeqId":77651174905}]}
