{"arg":{"channel":"books","instId":"BTC-USDT"},"action":"update","data":[{"asks":[["64814.6","0","0","0"],["64815.7","0.15443614","0","1"]],"bids":[["64810","0.03836784","0","4"],["64803","0.12412677","0","1"],["64798","0.1131471","0","1"],["64797.2","0","0","0"],["64793.5","0.00772217","0","1"],["64793.3","0","0","0"],["64785.3","0.15443624","0","1"],["64785.1","0","0","0"],["64639.1","0","0","0"]],"ts":"1784087979502","checksum":0,"seqId":78785108061,"prevSeqId":78785108041}]}
{"arg":{"channel":"books","instId":"BTC-USDT"},"action":"update","data":[{"asks":[],"bids":[["64798","0","0","0"],["64797.2","0.12412677","0","1"],["64795.5","0.26486791","0","1"],["64794.2","0","0","0"]],"ts":"1784087979602","checksum":0,"seqId":78785108069,"prevSeqId":78785108061}]}
{"arg":{"channel":"books","instId":"BTC-USDT"},"action":"update","data":[{"asks":[],"bids":[["64792.9","0.01719823","0","1"],["64782.8","0.00007978","0","2"],["64639.8","0","0","0"],["64639.4","0","0","0"]],"ts":"1784087979702","checksum":0,"seqId":78785108077,"prevSeqId":78785108069}]}
{"arg":{"channel":"books","instId":"BTC-USDT"},"action":"update","data":[{"asks":[],"bids":[["64795.5","0","0","0"],["64794.2","0.26486822","0","1"],["64792.9","0","0","0"],["64782.8","0.00012701","0","3"],["64639.8","0.00045864","0","3"]],"ts":"1784087979802","checksum":0,"seqId":78785108086,"prevSeqId":78785108077}]}
{"arg":{"channel":"books","instId":"BTC-USDT"},"action":"update","data":[{"asks":[["64810.7","0.11994522","0","1"],["64810.8","0","0","0"],["64850.9","0.00009797","0","7"]],"bids":[["64792.9","0.01719823","0","1"],["64639.8","0","0","0"]],"ts":"1784087980002","checksum":0,"seqId":78785108103,"prevSeqId":78785108086}]}
{"arg":{"channel":"books","instId":"BTC-USDT"},"action":"update","data":[{"asks":[],"bids":[["64794.2","0.26486823","0","1"],["64785.5","0.15443595","0","1"],["64785.3","0","0","0"]],"ts":"1784087980102","checksum":0,"seqId":78785108115,"prevSeqId":78785108103}]}
{"arg":{"channel":"books","instId":"BTC-USDT"},"action":"update","data":[{"asks":[["64814.6","0.15443614","0","1"],["64815.7","0","0","0"],["64888.4","0.0030822","0","2"],["64888.8","0.00062349","0","8"],["64903.6","0","0","0"]],"bids":[["64810","0.03706784","0","3"],["64803","0.12237998","0","1"],["64798","0.12412677","0","1"],["64797.2","0","0","0"],["64793.5","0","0","0"],["64792.9","0.00772222","0","1"],["64785.5","0","0","0"],["64785.3","0.15443597","0","1"],["64782.8","0.00017424","0","4"],["64639.8","0.00045864","0","3"]],"ts":"1784087980202","checksum":0,"seqId":78785108152,"prevSeqId":78785108115}]}
{"arg":{"channel":"books","instId":"BTC-USDT"},"action":"update","data":[{"asks":[["64851","0.00063059","0","20"]],"bids":[["64798","0","0","0"],["64797.2","0.1205619","0","1"],["64794.2","0","0","0"],["64793.5","0.27259579","0","2"],["64792.9","0","0","0"],["64686.6","0","0","0"],["64639.4","0.00046015","0","1"],["64639.1","0.00034809","0","1"]],"ts":"1784087980302","checksum":0,"seqId":78785108171,"prevSeqId":78785108152}]}
{"arg":{"channel":"books","instId":"BTC-USDT"},"action":"update","data":[{"asks":[],"bids":[["64793.5","0.26487353","0","1"],["64793.3","0.00772227","0","1"],["64792.9","0.01719823","0","1"],["64785.3","0","0","0"],["64785.1","0.15443664","0","1"],["64782.7","0.00001145","0","1"],["64639.8","0","0","0"],["64639.4","0","0","0"],["64639.1","0","0","0"]],"ts":"1784087980402","checksum":0,"seqId":78785108181,"prevSeqId":78785108171}]}
{"arg":{"channel":"books","instId":"BTC-USDT"},"action":"update","data":[{"asks":[],"bids":[["64793.5","0.26487445","0","1"],["64782.8","0.0001375","0","3"]],"ts":"1784087980502","checksum":0,"seqId":78785108193,"prevSeqId":78785108181}]}
{"arg":{"channel":"books","instId":"BTC-USDT"},"action":"update","data":[{"asks":[["64810.6","0.12412677","0","1"],["64810.7","0","0","0"]],"bids":[["64803","0","0","0"],["64798","0.12412677","0","1"],["64797.2","0","0","0"],["64793.5","0","0","0"],["64792.9","0.28207485","0","2"],["64782.8","0.00009027","0","2"],["64689.8","0.00558383","0","1"],["64639.8","0.00045864","0","3"]],"ts":"1784087980602","checksum":0,"seqId":78785108212,"prevSeqId":78785108193}]}
{"arg":{"channel":"books","instId":"BTC-USDT"},"action":"update","data":[{"asks":[["64850.9","0.0000866","0","6"]],"bids":[["64797.2","0.11189953","0","1"],["64792.9","0.26487662","0","1"],["64782.7","0","0","0"]],"ts":"1784087980702","checksum":0,"seqId":78785108221,"prevSeqId":78785108212}]}
{"arg":{"channel":"books","instId":"BTC-USDT"},"action":"update","data":[{"asks":[["64810.6","0","0","0"],["64810.9","0.12438203","0","3"],["64903.6","0.000015","0","1"]],"bids":[["64810","0.03836784","0","4"],["64803","0.12412677","0","1"],["64798","0","0","0"],["64797.2","0.12273129","0","1"],["64786.7","0.02948995","0","1"],["64639.8","0","0","0"]],"ts":"1784087980802","checksum":0,"seqId":78785108239,"prevSeqId":78785108221}]}
{"arg":{"channel":"trades","instId":"BTC-USDT"},"data":[{"instId":"BTC-USDT","tradeId":"1033093077","px":"64810","sz":"0.009","side":"sell","ts":"1784087980963","count":"1","source":"0","seqId":78785108251}]}
{"arg":{"channel":"trades","instId":"BTC-USDT"},"data":[{"instId":"BTC-USDT","tradeId":"1033093080","px":"64810","sz":"0.02806784","side":"sell","ts":"1784087980974","count":"3","source":"0","seqId":78785108263}]}
{"arg":{"channel":"books","instId":"BTC-USDT"},"action":"update","data":[{"asks":[["64810","2.86105128","0","15"],["64810.1","0.83730253","0","7"],["64810.9","0.00025526","0","2"],["64814.6","0.15443673","0","1"],["64870.6","0.00019221","0","9"],["64903.6","0","0","0"]],"bids":[["64810","0","0","0"],["64807.6","0","0","0"],["64805.7","0.12412697","0","1"],["64805.6","0","0","0"],["64803","0.12412697","0","1"],["64799.4","0.31101103","0","3"],["64797.9","0.12412697","0","1"],["64797.2","0","0","0"],["64797","0.66708881","0","4"],["64785.1","0.15443673","0","1"],["64784","0.51549048","0","4"],["64639.8","0.00045864","0","3"],["64639.4","0.00046015","0","1"]],"ts":"1784087981002","checksum":0,"seqId":78785108323,"prevSeqId":78785108239}]}
{"arg":{"channel":"books","instId":"BTC-USDT"},"action":"update","data":[{"asks":[["64810.1","0.75113281","0","6"],["64810.9","0","0","0"],["64813.9","0.15236915","0","1"],["64814","0.02316206","0","1"],["64814.1","0.0000155","0","1"],["64814.6","0.15443667","0","1"],["64815.9","0","0","0"]],"bids":[["64809.2","0.01983506","0","2"],["64803","0","0","0"],["64797.9","0","0","0"],["64797.2","0.11310177","0","1"],["64796.7","0","0","0"],["64795.4","0.35730439","0","2"],["64793.3","0","0","0"],["64792.9","0.02492054","0","2"],["64791.1","0.26487949","0","1"],["64785.1","0","0","0"],["64784.3","0.15443672","0","1"],["64760.7","0","0","0"],["64760.4","0.0017765","0","1"],["64639.1","0.00034809","0","1"],["64638.5","0.00002272","0","1"]],"ts":"1784087981102","checksum":0,"seqId":78785108371,"prevSeqId":78785108323}]}
{"arg":{"channel":"books","instId":"BTC-USDT"},"action":"update","data":[{"asks":[["64810","2.87305128","0","16"],["64810.1","0.73913281","0","5"],["64810.7","0.00011497","0","2"],["64813.8","0.15443696","0","1"],["64813.9","0.10626979","0","1"],["64814.6","0","0","0"],["64903.4","0","0","0"]],"bids":[["64805.7","0","0","0"],["64797.2","0","0","0"],["64795.4","0.17342","0","1"],["64794","0.18390371","0","2"],["64792.9","0.26487654","0","1"],["64792.6","0.00772229","0","1"],["64791.1","0","0","0"],["64784.3","0","0","0"],["64784.1","0.15443696","0","1"],["64637.9","0.00002665","0","1"],["64637.5","0.00001554","0","1"]],"ts":"1784087981202","checksum":0,"seqId":78785108402,"prevSeqId":78785108371}]}
{"arg":{"channel":"books","instId":"BTC-USDT"},"action":"update","data":[{"asks":[["64813.8","0","0","0"],["64813.9","0.2607067","0","2"],["64903.4","0.00012365","0","1"]],"bids":[["64805.5","0.1335312","0","1"],["64792.9","0.26487884","0","1"],["64784.3","0.15443695","0","1"],["64784.1","0","0","0"],["64637.5","0","0","0"]],"ts":"1784087981302","checksum":0,"seqId":78785108422,"prevSeqId":78785108402}]}
{"arg":{"channel":"books","instId":"BTC-USDT"},"action":"update","data":[{"asks":[["64813.9","0.10626979","0","1"],["64814.5","0.15443689","0","1"],["64853.5","0.01001048","0","2"],["64853.8","0","0","0"]],"bids":[["64788.3","0","0","0"],["64788","0.01","0","1"],["64782.8","0.00012701","0","3"]],"ts":"1784087981402","checksum":0,"seqId":78785108435,"prevSeqId":78785108422}]}
{"arg":{"channel":"books","instId":"BTC-USDT"},"action":"update","data":[{"asks":[["64810.1","0.36753281","0","4"]],"bids":[],"ts":"1784087981502","checksum":0,"seqId":78785108438,"prevSeqId":78785108435}]}
{"arg":{"channel":"books","instId":"BTC-USDT"},"action":"update","data":[{"asks":[["64851","0.00064196","0","21"]],"bids":[["64797.2","0.12058357","0","1"],["64792.9","0.28207707","0","2"],["64637.9","0","0","0"]],"ts":"1784087981602","checksum":0,"seqId":78785108443,"prevSeqId":78785108438}]}
{"arg":{"channel":"books","instId":"BTC-USDT"},"action":"update","data":[{"asks":[],"bids":[["64792.9","0.26487884","0","1"]],"ts":"1784087981702","checksum":0,"seqId":78785108448,"prevSeqId":78785108443}]}
{"arg":{"channel":"books","instId":"BTC-USDT"},"action":"update","data":[{"asks":[],"bids":[["64793.3","0.00772231","0","1"],["64792.6","0","0","0"],["64782.8","0.00009027","0","2"]],"ts":"1784087981802","checksum":0,"seqId":78785108459,"prevSeqId":78785108448}]}
{"arg":{"channel":"books","instId":"BTC-USDT"},"action":"update","data":[{"asks":[["64817.9","0.01598999","0","1"],["64819.5","1.0625945","0","2"],["64821.2","0.0885","0","1"],["64821.3","0","0","0"],["64822.9","0","0","0"],["64824.5","0.036","0","1"]],"bids":[["64806.9","0","0","0"],["64805.5","0","0","0"],["64805.4","0","0","0"],["64805.3","0","0","0"],["64805.1","0.10984894","0","1"],["64804.4","0.64","0","1"],["64803.7","0","0","0"],["64803","0.12412697","0","1"],["64802.9","0.30570804","0","2"],["64802.7","0.08863","0","1"],["64801","0.04621407","0","1"],["64799.4","0.27821976","0","3"],["64797.2","0","0","0"],["64797","0.42637565","0","3"],["64792.9","0.28207707","0","2"],["64784","0.75620364","0","5"],["64700","0.14482632","0","3"],["64637.9","0.00002665","0","1"]],"ts":"1784087981902","checksum":0,"seqId":78785108493,"prevSeqId":78785108459}]}
{"arg":{"channel":"books","instId":"BTC-USDT"},"action":"update","data":[{"asks":[],"bids":[["64799.2","0","0","0"],["64795.1","0.07721378","0","1"],["64792.9","0.26487884","0","1"],["64786.2","0","0","0"],["64782.1","0.13512411","0","1"],["64773.2","0","0","0"],["64769.1","0.19303445","0","1"],["64760.3","0","0","0"],["64756.2","0.25094478","0","1"]],"ts":"1784087982002","checksum":0,"seqId":78785108506,"prevSeqId":78785108493}]}
{"arg":{"channel":"books","instId":"BTC-USDT"},"action":"update","data":[{"asks":[["64814.5","0","0","0"],["64814.6","0.15443673","0","1"]],"bids":[["64804.5","0.12412697","0","1"],["64803","0","0","0"],["64799.2","0.0772089","0","1"],["64795.1","0","0","0"],["64793.5","0.2648758","0","1"],["64792.9","0.01719823","0","1"],["64786.2","0.13511557","0","1"],["64785.1","0.15443675","0","1"],["64784.3","0","0","0"],["64782.1","0","0","0"],["64773.2","0.19302225","0","1"],["64769.1","0","0","0"],["64760.5","0.00177653","0","1"],["64760.4","0","0","0"],["64760.3","0.25092892","0","1"],["64756.2","0","0","0"],["64689.8","0","0","0"]],"ts":"1784087982102","checksum":0,"seqId":78785108546,"prevSeqId":78785108506}]}
{"arg":{"channel":"books","instId":"BTC-USDT"},"action":"update","data":[{"asks":[],"bids":[["64794.2","0.26487207","0","1"],["64793.5","0","0","0"],["64792.9","0","0","0"],["64782.8","0.00004723","0","1"],["64637.5","0.00001554","0","1"]],"ts":"1784087982202","checksum":0,"seqId":78785108560,"prevSeqId":78785108546}]}
{"arg":{"channel":"books","instId":"BTC-USDT"},"action":"update","data":[{"asks":[],"bids":[["64801.6","0.0000155","0","1"],["64801.4","0.10809898","0","2"],["64794.2","0","0","0"],["64793.5","0.26487572","0","1"],["64792.9","0.01719823","0","1"],["64692.2","0.00558363","0","1"],["64637.9","0","0","0"],["64637.5","0","0","0"]],"ts":"1784087982302","checksum":0,"seqId":78785108573,"prevSeqId":78785108560}]}
{"arg":{"channel":"books","instId":"BTC-USDT"},"action":"update","data":[{"asks":[["64814.6","0","0","0"],["64815.7","0.1544367","0","1"]],"bids":[["64793.6","0.00772231","0","1"],["64793.3","0","0","0"],["64792.9","0","0","0"],["64785.5","0.1544367","0","1"],["64785.1","0","0","0"],["64637.9","0.00002665","0","1"]],"ts":"1784087982402","checksum":0,"seqId":78785108588,"prevSeqId":78785108573}]}
{"arg":{"channel":"books","instId":"BTC-USDT"},"action":"update","data":[{"asks":[],"bids":[["64793.6","0","0","0"],["64793.5","0.27259681","0","2"],["64785.5","0","0","0"],["64785.3","0.1544364","0","1"],["64637.5","0.00001554","0","1"]],"ts":"1784087982502","checksum":0,"seqId":78785108600,"prevSeqId":78785108588}]}
{"arg":{"channel":"books","instId":"BTC-USDT"},"action":"update","data":[{"asks":[["64814.6","0.15443664","0","1"],["64815.7","0","0","0"]],"bids":[["64793.5","0.2648746","0","1"],["64793.3","0.00772231","0","1"],["64792.9","0.01719823","0","1"],["64637.9","0","0","0"],["64637.5","0","0","0"]],"ts":"1784087982602","checksum":0,"seqId":78785108609,"prevSeqId":78785108600}]}
{"arg":{"channel":"books","instId":"BTC-USDT"},"action":"update","data":[{"asks":[],"bids":[["64782.8","0.00009027","0","2"]],"ts":"1784087982702","checksum":0,"seqId":78785108617,"prevSeqId":78785108609}]}
{"arg":{"channel":"books","instId":"BTC-USDT"},"action":"update","data":[{"asks":[],"bids":[["64792.9","0","0","0"],["64785.3","0","0","0"],["64785.1","0.15443666","0","1"],["64637.9","0.00002665","0","1"]],"ts":"1784087982802","checksum":0,"seqId":78785108624,"prevSeqId":78785108617}]}
{"arg":{"channel":"books","instId":"BTC-USDT"},"action":"update","data":[{"asks":[],"bids":[["64792.9","0.01719823","0","1"],["64637.9","0","0","0"]],"ts":"1784087982902","checksum":0,"seqId":78785108630,"prevSeqId":78785108624}]}
{"arg":{"channel":"books","instId":"BTC-USDT"},"action":"update","data":[{"asks":[],"bids":[["64795.3","0.16038517","0","1"],["64794","0.0000155","0","1"],["64792.9","0","0","0"]],"ts":"1784087983002","checksum":0,"seqId":78785108637,"prevSeqId":78785108630}]}
{"arg":{"channel":"books","instId":"BTC-USDT"},"action":"update","data":[{"asks":[],"bids":[["64792.9","0.01719823","0","1"],["64638.5","0","0","0"]],"ts":"1784087983102","checksum":0,"seqId":78785108644,"prevSeqId":78785108637}]}
{"arg":{"channel":"books","instId":"BTC-USDT"},"action":"update","data":[{"asks":[],"bids":[["64794.2","0.264873","0","1"],["64793.5","0","0","0"],["64792.9","0","0","0"],["64638.5","0.00002272","0","1"]],"ts":"1784087983202","checksum":0,"seqId":78785108653,"prevSeqId":78785108644}]}
{"arg":{"channel":"books","instId":"BTC-USDT"},"action":"update","data":[{"asks":[],"bids":[["64794.2","0","0","0"],["64793.5","0.26487362","0","1"],["64792.9","0.01719823","0","1"],["64638.5","0","0","0"]],"ts":"1784087983302","checksum":0,"seqId":78785108665,"prevSeqId":78785108653}]}
{"arg":{"channel":"trades","instId":"BTC-USDT"},"data":[{"instId":"BTC-USDT","tradeId":"1033093081","px":"64810","sz":"0.00001542","side":"buy","ts":"1784087983356","count":"1","source":"0","seqId":78785108670}]}
{"arg":{"channel":"books","instId":"BTC-USDT"},"action":"update","data":[{"asks":[["64810","2.87303586","0","16"]],"bids":[["64792.9","0","0","0"],["64638.5","0.00002272","0","1"]],"ts":"1784087983402","checksum":0,"seqId":78785108678,"prevSeqId":78785108665}]}
{"arg":{"channel":"books","instId":"BTC-USDT"},"action":"update","data":[{"asks":[],"bids":[["64804.5","0.11841937","0","1"],["64793.5","0","0","0"],["64793.3","0","0","0"],["64792.9","0.02492063","0","2"],["64791.1","0.26487981","0","1"],["64785.1","0","0","0"],["64784.3","0.15443689","0","1"]],"ts":"1784087983502","checksum":0,"seqId":78785108693,"prevSeqId":78785108678}]}
{"arg":{"channel":"books","instId":"BTC-USDT"},"action":"update","data":[{"asks":[],"bids":[["64792.9","0.27260123","0","2"],["64791.1","0","0","0"],["64637.9","0.00002665","0","1"]],"ts":"1784087983602","checksum":0,"seqId":78785108701,"prevSeqId":78785108693}]}
{"arg":{"channel":"books","instId":"BTC-USDT"},"action":"update","data":[{"asks":[],"bids":[["64792.9","0.28979946","0","3"],["64785.1","0.15443689","0","1"],["64784.3","0","0","0"]],"ts":"1784087983702","checksum":0,"seqId":78785108709,"prevSeqId":78785108701}]}
{"arg":{"channel":"books","instId":"BTC-USDT"},"action":"update","data":[{"asks":[["64816.7","0.08257362","0","3"],["64816.8","0.358104","0","1"]],"bids":[["64793.3","0.00772237","0","1"],["64792.9","0.26487883","0","1"],["64637.9","0","0","0"]],"ts":"1784087983802","checksum":0,"seqId":78785108719,"prevSeqId":78785108709}]}
{"arg":{"channel":"books","instId":"BTC-USDT"},"action":"update","data":[{"asks":[],"bids":[["64795.3","0","0","0"],["64794","0.16040373","0","2"],["64793.3","0","0","0"],["64793","0.00772236","0","1"],["64637.9","0.00002665","0","1"]],"ts":"1784087983902","checksum":0,"seqId":78785108727,"prevSeqId":78785108719}]}
{"arg":{"channel":"books","instId":"BTC-USDT"},"action":"update","data":[{"asks":[],"bids":[["64793.3","0.00772238","0","1"],["64793","0","0","0"],["64792.8","0.32677252","0","2"],["64760.5","0","0","0"],["64760.4","0.00177653","0","1"]],"ts":"1784087984102","checksum":0,"seqId":78785108742,"prevSeqId":78785108727}]}
{"arg":{"channel":"books","instId":"BTC-USDT"},"action":"update","data":[{"asks":[["64810","2.88203586","0","17"]],"bids":[["64792.9","0.26487694","0","1"],["64792.8","0.30957429","0","1"]],"ts":"1784087984202","checksum":0,"seqId":78785108757,"prevSeqId":78785108742}]}
{"arg":{"channel":"books","instId":"BTC-USDT"},"action":"update","data":[{"asks":[],"bids":[["64782.8","0.00004723","0","1"]],"ts":"1784087984302","checksum":0,"seqId":78785108764,"prevSeqId":78785108757}]}
{"arg":{"channel":"books","instId":"BTC-USDT"},"action":"update","data":[{"asks":[],"bids":[["64792.8","0.32677252","0","2"]],"ts":"1784087984402","checksum":0,"seqId":78785108770,"prevSeqId":78785108764}]}
{"arg":{"channel":"books","instId":"BTC-USDT"},"action":"update","data":[{"asks":[],"bids":[["64792.8","0.30957429","0","1"],["64782.8","0.00009446","0","2"]],"ts":"1784087984502","checksum":0,"seqId":78785108778,"prevSeqId":78785108770}]}
{"arg":{"channel":"books","instId":"BTC-USDT"},"action":"update","data":[{"asks":[],"bids":[["64799.2","0","0","0"],["64795.1","0.07721378","0","1"],["64792.8","0.32677252","0","2"],["64786.2","0","0","0"],["64782.1","0.13512411","0","1"],["64773.2","0","0","0"],["64769.1","0.19303445","0","1"],["64760.3","0","0","0"],["64756.2","0.25094478","0","1"]],"ts":"1784087984602","checksum":0,"seqId":78785108792,"prevSeqId":78785108778}]}
{"arg":{"channel":"books","instId":"BTC-USDT"},"action":"update","data":[{"asks":[],"bids":[["64799.2","0.0772089","0","1"],["64795.1","0","0","0"],["64794.2","0.26487311","0","1"],["64792.9","0","0","0"],["64792.8","0.30957429","0","1"],["64786.2","0.13511557","0","1"],["64785.1","0.15443678","0","1"],["64782.1","0","0","0"],["64773.2","0.19302225","0","1"],["64769.1","0","0","0"],["64760.3","0.25092892","0","1"],["64756.2","0","0","0"]],"ts":"1784087984702","checksum":0,"seqId":78785108811,"prevSeqId":78785108792}]}
{"arg":{"channel":"books","instId":"BTC-USDT"},"action":"update","data":[{"asks":[],"bids":[["64794.2","0","0","0"],["64793.5","0.26487408","0","1"]],"ts":"1784087984802","checksum":0,"seqId":78785108817,"prevSeqId":78785108811}]}
{"arg":{"channel":"books","instId":"BTC-USDT"},"action":"update","data":[{"asks":[["64823.8","0.30957429","0","1"]],"bids":[["64793.5","0","0","0"],["64792.9","0.28207627","0","2"],["64782.7","0.00002387","0","1"],["64637.9","0","0","0"]],"ts":"1784087984902","checksum":0,"seqId":78785108827,"prevSeqId":78785108817}]}
{"arg":{"channel":"books","instId":"BTC-USDT"},"action":"update","data":[{"asks":[["64814.6","0.15443721","0","1"]],"bids":[["64793.3","0","0","0"],["64792.9","0.00772242","0","1"],["64791.1","0.26487992","0","1"],["64785.1","0.15443717","0","1"]],"ts":"1784087985002","checksum":0,"seqId":78785108853,"prevSeqId":78785108827}]}
{"arg":{"channel":"books","instId":"BTC-USDT"},"action":"update","data":[{"asks":[],"bids":[["64792.9","0.27260131","0","2"],["64791.1","0","0","0"],["64782.7","0.00006061","0","2"],["64637.9","0.00002665","0","1"]],"ts":"1784087985102","checksum":0,"seqId":78785108864,"prevSeqId":78785108853}]}
{"arg":{"channel":"books","instId":"BTC-USDT"},"action":"update","data":[{"asks":[["64850.9","0.00009797","0","7"],["64888.3","0.0033122","0","3"],["64888.4","0","0","0"],["64903.6","0.000015","0","1"]],"bids":[["64802.9","0.16532551","0","1"],["64802.8","0","0","0"],["64793.4","0.52436956","0","1"],["64791","0.12035665","0","1"],["64637.5","0.00001554","0","1"]],"ts":"1784087985202","checksum":0,"seqId":78785108880,"prevSeqId":78785108864}]}
{"arg":{"channel":"books","instId":"BTC-USDT"},"action":"update","data":[{"asks":[["64810","3.00203586","0","19"],["64810.9","0.12412696","0","1"],["64813.8","0.15443688","0","1"],["64814.6","0","0","0"],["64815.8","0","0","0"],["64817.2","0","0","0"],["64819.2","0.02327635","0","2"],["64823.9","0.04811374","0","2"],["64836.5","0","0","0"],["64903.8","0.00019404","0","4"],["64903.9","0.00007108","0","2"]],"bids":[["64805.1","0","0","0"],["64804.5","0","0","0"],["64804.4","0","0","0"],["64804.3","0","0","0"],["64802.9","0","0","0"],["64801.5","0.12412696","0","1"],["64797.9","0.12412696","0","1"],["64797.6","0","0","0"],["64797.2","0.12412696","0","1"],["64796.2","0.02316236","0","1"],["64796.1","0","0","0"],["64795.5","0.0517705","0","1"],["64794.1","0","0","0"],["64794","0.0000155","0","1"],["64793.6","0.00772251","0","1"],["64793.5","0.12127707","0","1"],["64792.9","0.26487828","0","1"],["64792.8","0.45054978","0","2"],["64792.5","0","0","0"],["64792.4","0.01543391","0","1"],["64790.7","0","0","0"],["64790.3","0","0","0"],["64789.8","0.04","0","1"],["64789.6","0.08","0","1"],["64786.7","0","0","0"],["64786","2","0","1"],["64785.1","0","0","0"],["64784.1","0.15443688","0","1"],["64775.1","0","0","0"],["64636.8","0.00001832","0","1"],["64636.7","0.02417466","0","1"]],"ts":"1784087985302","checksum":0,"seqId":78785108980,"prevSeqId":78785108880}]}
{"arg":{"channel":"books","instId":"BTC-USDT"},"action":"update","data":[{"asks":[["64812.3","0.02316279","0","1"],["64814","0","0","0"],["64833","0.0661266","0","1"],["64903.9","0","0","0"]],"bids":[["64802.8","0.11367589","0","1"],["64798.2","0","0","0"],["64797.9","0","0","0"],["64797.2","0.11830792","0","1"],["64793.6","0","0","0"],["64793","0.00772248","0","1"],["64792.9","0","0","0"],["64789.9","0.26488838","0","1"],["64786.1","1.42044361","0","3"],["64784.1","0","0","0"],["64783.5","0.15443816","0","1"],["64782.7","0.00007206","0","3"],["64764.7","0.6576263","0","3"],["64763.6","0","0","0"],["64738.6","1.20294","0","1"],["64636.3","0.00098767","0","4"]],"ts":"1784087985402","checksum":0,"seqId":78785109012,"prevSeqId":78785108980}]}
{"arg":{"channel":"books","instId":"BTC-USDT"},"action":"update","data":[{"asks":[["64810.8","0.11148175","0","1"],["64810.9","0","0","0"],["64827.3","2.27806684","0","1"],["64828.9","1.55012587","0","1"],["64829.5","0","0","0"]],"bids":[["64801.5","0.12420413","0","2"],["64801.4","0.10802236","0","1"],["64797.3","0.12412696","0","1"],["64797.2","0","0","0"],["64793.5","0","0","0"],["64793","0","0","0"],["64792.5","0.00772268","0","1"],["64791.1","0.2648862","0","1"],["64789.9","0","0","0"],["64784.3","0.15443825","0","1"],["64783.5","0","0","0"],["64765","0","0","0"],["64763.7","0.01670189","0","2"],["64763.2","0","0","0"],["64761.7","0.00136737","0","1"],["64751.4","0","0","0"],["64750.1","0.00259091","0","2"],["64738.9","0.9845936","0","2"],["64738.3","0","0","0"],["64737","0.00154471","0","1"],["64635.4","0.02326085","0","1"],["64635.2","0.00002849","0","1"],["64634.6","0.00010084","0","1"]],"ts":"1784087985502","checksum":0,"seqId":78785109049,"prevSeqId":78785109012}]}
{"arg":{"channel":"books","instId":"BTC-USDT"},"action":"update","data":[{"asks":[["64810.8","0","0","0"],["64813.8","0","0","0"],["64814.6","0.15443817","0","1"],["64870.6","0.44904276","0","10"],["64903.9","0.00007108","0","2"]],"bids":[["64797.3","0","0","0"],["64797.2","0.11898153","0","1"],["64793.5","0.12412696","0","1"],["64791.8","0.01719824","0","1"],["64635.2","0","0","0"],["64634.6","0","0","0"]],"ts":"1784087985602","checksum":0,"seqId":78785109068,"prevSeqId":78785109049}]}
{"arg":{"channel":"books","instId":"BTC-USDT"},"action":"update","data":[{"asks":[["64810.9","0.12412696","0","1"],["64903.9","0","0","0"]],"bids":[["64792.5","0.0154339","0","1"],["64792.4","0","0","0"],["64791.6","0.00772259","0","1"],["64784.9","0.02841297","0","1"],["64782.7","0.00003532","0","2"],["64635.4","0","0","0"]],"ts":"1784087985702","checksum":0,"seqId":78785109085,"prevSeqId":78785109068}]}
{"arg":{"channel":"books","instId":"BTC-USDT"},"action":"update","data":[{"asks":[["64810.9","0","0","0"],["64827.3","0","0","0"],["64829.5","2.27806684","0","1"],["64903.9","0.00007108","0","2"]],"bids":[["64797.9","0.12412696","0","1"],["64797.2","0","0","0"],["64782.7","0.00002387","0","1"],["64774.3","1.00377216","0","2"]],"ts":"1784087985802","checksum":0,"seqId":78785109096,"prevSeqId":78785109085}]}
{"arg":{"channel":"books","instId":"BTC-USDT"},"action":"update","data":[{"asks":[],"bids":[["64797.9","0","0","0"],["64797.2","0.11271517","0","1"],["64793.6","0.12412696","0","1"],["64793.5","0","0","0"],["64792.6","0.00772261","0","1"],["64791.8","0","0","0"],["64791.6","0","0","0"],["64635.4","0.02326085","0","1"]],"ts":"1784087985902","checksum":0,"seqId":78785109109,"prevSeqId":78785109096}]}
{"arg":{"channel":"books","instId":"BTC-USDT"},"action":"update","data":[{"asks":[],"bids":[["64797.9","0.12412696","0","1"],["64795.5","0.08220364","0","2"],["64792.6","0","0","0"],["64791.8","0.01719824","0","1"],["64791.7","0.00772258","0","1"],["64782.8","0.0001312","0","3"],["64636.3","0","0","0"],["64635.4","0","0","0"]],"ts":"1784087986002","checksum":0,"seqId":78785109127,"prevSeqId":78785109109}]}
{"arg":{"channel":"books","instId":"BTC-USDT"},"action":"update","data":[{"asks":[["64814.6","0.15443794","0","1"],["64815.2","0.01542848","0","1"],["64816.7","0.0671455","0","2"],["64850.9","0.0000866","0","6"],["64903.9","0","0","0"]],"bids":[["64797.2","0.12412696","0","1"],["64795.5","0.0517705","0","1"],["64793.6","0","0","0"],["64793.5","0.12412696","0","1"],["64792.9","0.00772255","0","1"],["64791.7","0","0","0"],["64791.1","0","0","0"],["64790.9","0.3852434","0","2"],["64782.7","0.00003532","0","2"],["64636.3","0.00098767","0","4"]],"ts":"1784087986102","checksum":0,"seqId":78785109165,"prevSeqId":78785109127}]}
{"arg":{"channel":"books","instId":"BTC-USDT"},"action":"update","data":[{"asks":[],"bids":[["64803.6","0.12412696","0","1"],["64803.5","0.64","0","1"],["64802.8","0","0","0"],["64801.5","0.00007717","0","1"],["64797.9","0","0","0"],["64797.2","0","0","0"],["64792.9","0","0","0"],["64792.6","0.00772255","0","1"],["64635.4","0.02326085","0","1"]],"ts":"1784087986202","checksum":0,"seqId":78785109183,"prevSeqId":78785109165}]}
{"arg":{"channel":"books","instId":"BTC-USDT"},"action":"update","data":[{"asks":[["64813.8","0.15443794","0","1"],["64814.6","0","0","0"],["64825.1","0.05529732","0","5"],["64826.6","0","0","0"],["64840.7","0.00001","0","1"],["64843.5","0","0","0"],["64843.7","0.00001","0","1"],["64846.3","0","0","0"],["64903.9","0.00007108","0","2"]],"bids":[["64801.5","0","0","0"],["64801.4","0.10809971","0","2"],["64797.3","0.12412696","0","1"],["64792.9","0.00772259","0","1"],["64792.6","0","0","0"],["64782.8","0.00009446","0","2"],["64782.7","0.00004677","0","3"]],"ts":"1784087986302","checksum":0,"seqId":78785109209,"prevSeqId":78785109183}]}
{"arg":{"channel":"books","instId":"BTC-USDT"},"action":"update","data":[{"asks":[["64813.8","0","0","0"],["64814.6","0.15443802","0","1"],["64827.3","2.27820945","0","1"],["64829.5","0","0","0"]],"bids":[["64803.5","0","0","0"],["64801.5","0.12412696","0","1"],["64797.9","0.12412696","0","1"],["64797.3","0","0","0"],["64791.8","0","0","0"],["64635.2","0.00002849","0","1"]],"ts":"1784087986402","checksum":0,"seqId":78785109222,"prevSeqId":78785109209}]}
{"arg":{"channel":"books","instId":"BTC-USDT"},"action":"update","data":[{"asks":[],"bids":[["64801.5","0.12420431","0","2"],["64801.4","0.10802236","0","1"],["64792.9","0","0","0"],["64792.6","0.00772255","0","1"],["64791.8","0.01719824","0","1"],["64635.2","0","0","0"]],"ts":"1784087986502","checksum":0,"seqId":78785109232,"prevSeqId":78785109222}]}
{"arg":{"channel":"books","instId":"BTC-USDT"},"action":"update","data":[{"asks":[],"bids":[["64795.5","0.08220364","0","2"],["64793.7","0.12412696","0","1"],["64793.6","0.86003549","0","1"],["64793.5","0.9740945","0","1"],["64793.4","0","0","0"],["64635.4","0","0","0"]],"ts":"1784087986602","checksum":0,"seqId":78785109242,"prevSeqId":78785109232}]}
{"arg":{"channel":"books","instId":"BTC-USDT"},"action":"update","data":[{"asks":[["64825.8","1.06665363","0","3"]],"bids":[["64805.1","0.12369642","0","1"],["64797.2","0.12412696","0","1"],["64795.5","0.0517705","0","1"],["64793.7","0","0","0"],["64792.9","0.00772253","0","1"],["64792.6","0","0","0"],["64791.8","0","0","0"],["64791.1","0.26487992","0","1"],["64790.9","0.12035646","0","1"],["64784.3","0.15443804","0","1"],["64636.3","0","0","0"]],"ts":"1784087986702","checksum":0,"seqId":78785109268,"prevSeqId":78785109242}]}
{"arg":{"channel":"books","instId":"BTC-USDT"},"action":"update","data":[{"asks":[],"bids":[["64792.9","0","0","0"],["64792.6","0.00772247","0","1"],["64791.8","0.01719824","0","1"],["64636.7","0","0","0"]],"ts":"1784087986802","checksum":0,"seqId":78785109278,"prevSeqId":78785109268}]}
{"arg":{"channel":"books","instId":"BTC-USDT"},"action":"update","data":[{"asks":[],"bids":[["64795.5","0.07902723","0","2"],["64793.7","0.11348573","0","1"],["64792.9","0.0077225","0","1"],["64792.6","0","0","0"],["64636.8","0","0","0"]],"ts":"1784087986902","checksum":0,"seqId":78785109288,"prevSeqId":78785109278}]}
{"arg":{"channel":"books","instId":"BTC-USDT"},"action":"update","data":[{"asks":[],"bids":[["64795.5","0.11818568","0","1"],["64793.8","0.14285817","0","1"],["64793.7","0","0","0"],["64792.9","0","0","0"],["64792.8","0.30957429","0","1"],["64792.6","0.00772251","0","1"],["64791.8","0","0","0"],["64636.8","0.00001832","0","1"]],"ts":"1784087987002","checksum":0,"seqId":78785109302,"prevSeqId":78785109288}]}
{"arg":{"channel":"books","instId":"BTC-USDT"},"action":"update","data":[{"asks":[],"bids":[["64799.5","0.48854931","0","2"],["64799.4","0.4175201","0","3"],["64797.9","0","0","0"],["64797.2","0","0","0"],["64791.8","0.01719824","0","1"]],"ts":"1784087987102","checksum":0,"seqId":78785109313,"prevSeqId":78785109302}]}
{"arg":{"channel":"books","instId":"BTC-USDT"},"action":"update","data":[{"asks":[],"bids":[["64791.8","0","0","0"],["64782.8","0.0001312","0","3"],["64782.7","0.00005822","0","4"],["64636.7","0.02417466","0","1"]],"ts":"1784087987202","checksum":0,"seqId":78785109320,"prevSeqId":78785109313}]}
{"arg":{"channel":"books","instId":"BTC-USDT"},"action":"update","data":[{"asks":[],"bids":[["64801.5","0.12412696","0","1"],["64801.1","0.33156529","0","2"],["64799.6","0.12412696","0","1"],["64799.5","0.36442235","0","1"],["64636.7","0","0","0"]],"ts":"1784087987302","checksum":0,"seqId":78785109331,"prevSeqId":78785109320}]}
{"arg":{"channel":"books","instId":"BTC-USDT"},"action":"update","data":[{"asks":[],"bids":[["64795.3","0.05560128","0","1"],["64636.8","0","0","0"]],"ts":"1784087987402","checksum":0,"seqId":78785109336,"prevSeqId":78785109331}]}
{"arg":{"channel":"trades","instId":"BTC-USDT"},"data":[{"instId":"BTC-USDT","tradeId":"1033093082","px":"64809.9","sz":"0.0000154","side":"sell","ts":"1784087987464","count":"1","source":"0","seqId":78785109342}]}
{"arg":{"channel":"books","instId":"BTC-USDT"},"action":"update","data":[{"asks":[],"bids":[["64809.9","0.1057093","0","2"],["64791.8","0.01719824","0","1"],["64782.7","0.00004677","0","3"],["64637.5","0","0","0"]],"ts":"1784087987502","checksum":0,"seqId":78785109345,"prevSeqId":78785109336}]}
{"arg":{"channel":"books","instId":"BTC-USDT"},"action":"update","data":[{"asks":[],"bids":[["64791.8","0","0","0"],["64637.5","0.00001554","0","1"]],"ts":"1784087987602","checksum":0,"seqId":78785109351,"prevSeqId":78785109345}]}
{"arg":{"channel":"books","instId":"BTC-USDT"},"action":"update","data":[{"asks":[],"bids":[["64799.6","0","0","0"],["64799.5","0.2672717","0","1"],["64799.2","0","0","0"],["64795","0.0772139","0","1"],["64791.8","0.01719824","0","1"],["64786.2","0","0","0"],["64782.8","0.00009446","0","2"],["64782","0.13512432","0","1"],["64773.2","0","0","0"],["64769","0.50260904","0","2"],["64760.3","0","0","0"],["64756.1","0.25096066","0","2"],["64745.1","0","0","0"],["64745","0.20423531","0","2"],["64636.8","0.00001832","0","1"],["64636.7","0.02417466","0","1"],["64636.3","0.00098767","0","4"]],"ts":"1784087987702","checksum":0,"seqId":78785109371,"prevSeqId":78785109351}]}
{"arg":{"channel":"books","instId":"BTC-USDT"},"action":"update","data":[{"asks":[["64814.6","0.15443815","0","1"]],"bids":[["64805.1","0.12773527","0","1"],["64804.3","0.12412696","0","1"],["64804.2","0.64","0","1"],["64803.6","0","0","0"],["64801.5","0","0","0"],["64791.8","0","0","0"],["64782.7","0.00005822","0","4"],["64760.4","0","0","0"],["64759.9","0.00177661","0","1"],["64698.1","0.00001551","0","1"],["64698","0.02327283","0","2"],["64692.1","0.30957429","0","1"],["64690.4","0","0","0"],["64690.3","0.00001197","0","1"],["64689.7","0.11992267","0","4"],["64689.6","0.00001198","0","1"],["64689.1","0","0","0"],["64686.7","0.00001198","0","1"],["64683.3","0","0","0"],["64680.9","0.00001199","0","1"],["64667.8","0","0","0"],["64665.4","0.00001217","0","1"]],"ts":"1784087987802","checksum":0,"seqId":78785109426,"prevSeqId":78785109371}]}
{"arg":{"channel":"books","instId":"BTC-USDT"},"action":"update","data":[{"asks":[],"bids":[["64799.2","0.0772089","0","1"],["64795","0","0","0"],["64792.9","0.00772252","0","1"],["64792.6","0","0","0"],["64786.2","0.13511557","0","1"],["64782","0","0","0"],["64773.2","0.19302225","0","1"],["64769","0.30957429","0","1"],["64760.3","0.25092892","0","1"],["64756.1","0.00001549","0","1"],["64636.7","0","0","0"],["64636.3","0","0","0"]],"ts":"1784087988102","checksum":0,"seqId":78785109457,"prevSeqId":78785109426}]}
{"arg":{"channel":"books","instId":"BTC-USDT"},"action":"update","data":[{"asks":[["64857.6","1.28366879","0","2"]],"bids":[["64791.8","0.01719824","0","1"],["64760.4","0.00177662","0","1"],["64759.9","0","0","0"],["64636.8","0","0","0"]],"ts":"1784087988202","checksum":0,"seqId":78785109465,"prevSeqId":78785109457}]}
{"arg":{"channel":"books","instId":"BTC-USDT"},"action":"update","data":[{"asks":[],"bids":[["64791.8","0","0","0"],["64785","0.46401212","0","2"],["64784.3","0","0","0"],["64636.8","0.00001832","0","1"],["64636.7","0.02417466","0","1"]],"ts":"1784087988302","checksum":0,"seqId":78785109478,"prevSeqId":78785109465}]}
{"arg":{"channel":"books","instId":"BTC-USDT"},"action":"update","data":[{"asks":[],"bids":[["64804.3","0.11893416","0","1"],["64785","0.46401211","0","2"],["64782.7","0.00004677","0","3"]],"ts":"1784087988402","checksum":0,"seqId":78785109490,"prevSeqId":78785109478}]}
{"arg":{"channel":"books","instId":"BTC-USDT"},"action":"update","data":[{"asks":[],"bids":[["64791.8","0.01719824","0","1"],["64785","0.30957429","0","1"],["64784.3","0.15443782","0","1"],["64636.8","0","0","0"],["64636.7","0","0","0"]],"ts":"1784087988502","checksum":0,"seqId":78785109497,"prevSeqId":78785109490}]}
{"arg":{"channel":"books","instId":"BTC-USDT"},"action":"update","data":[{"asks":[["64851","0.00063059","0","20"]],"bids":[["64801.7","0.10802186","0","1"],["64801.4","0","0","0"],["64792.9","0","0","0"],["64792.6","0.00772253","0","1"]],"ts":"1784087988602","checksum":0,"seqId":78785109508,"prevSeqId":78785109497}]}
{"arg":{"channel":"books","instId":"BTC-USDT"},"action":"update","data":[{"asks":[["64811.4","0.01982816","0","1"],["64903.9","0","0","0"]],"bids":[["64791.8","0","0","0"],["64782.7","0.00005822","0","4"],["64636.8","0.00001832","0","1"]],"ts":"1784087988702","checksum":0,"seqId":78785109519,"prevSeqId":78785109508}]}
{"arg":{"channel":"books","instId":"BTC-USDT"},"action":"update","data":[{"asks":[["64813.8","0.15443822","0","1"],["64814.6","0","0","0"]],"bids":[["64805.1","0","0","0"],["64782.7","0.00006967","0","5"],["64636.7","0.02417466","0","1"]],"ts":"1784087988802","checksum":0,"seqId":78785109530,"prevSeqId":78785109519}]}
{"arg":{"channel":"books","instId":"BTC-USDT"},"action":"update","data":[{"asks":[],"bids":[["64784.9","0","0","0"],["64636.3","0.00098767","0","4"]],"ts":"1784087988902","checksum":0,"seqId":78785109536,"prevSeqId":78785109530}]}
{"arg":{"channel":"books","instId":"BTC-USDT"},"action":"update","data":[{"asks":[["64813.8","0","0","0"],["64814.6","0.15443839","0","1"]],"bids":[["64791.8","0.01719824","0","1"],["64698.9","0","0","0"],["64696.4","0.00001198","0","1"],["64636.3","0","0","0"]],"ts":"1784087989002","checksum":0,"seqId":78785109548,"prevSeqId":78785109536}]}
{"arg":{"channel":"books","instId":"BTC-USDT"},"action":"update","data":[{"asks":[["64812.3","0","0","0"],["64813.8","0.02316228","0","1"],["64867.4","0.36730613","0","1"],["64869.6","0.02397734","0","1"]],"bids":[["64804.3","0","0","0"],["64804.2","0","0","0"],["64802.8","0.1482946","0","1"],["64801.2","0.12412696","0","1"],["64795.5","0.06836748","0","1"],["64793.8","0","0","0"],["64793.6","0.49013245","0","1"],["64793.5","0","0","0"],["64793.3","0.00772247","0","1"],["64792.6","0","0","0"],["64792.5","0.12518167","0","1"],["64791.9","0.01543402","0","1"],["64791.8","0","0","0"],["64791.1","0.26487988","0","1"],["64784.4","0.15443827","0","1"],["64784.3","0","0","0"],["64774.3","0.9740945","0","1"],["64771.3","0.97411001","0","2"],["64650.9","0","0","0"],["64636.3","0.00098767","0","4"],["64635.4","0.02326085","0","1"],["64635.2","0.00002849","0","1"]],"ts":"1784087989202","checksum":0,"seqId":78785109621,"prevSeqId":78785109548}]}
{"arg":{"channel":"books","instId":"BTC-USDT"},"action":"update","data":[{"asks":[["64813.7","0.15443893","0","1"],["64814.6","0","0","0"],["64851","0.00061922","0","19"]],"bids":[["64803.6","0.12412696","0","1"],["64803.5","0.64","0","1"],["64802.8","0","0","0"],["64801.2","0","0","0"],["64793.3","0","0","0"],["64792.9","0.00772249","0","1"],["64784.4","0","0","0"],["64784.3","0.15443893","0","1"],["64650.9","0.00066777","0","1"],["64635.2","0","0","0"]],"ts":"1784087989302","checksum":0,"seqId":78785109640,"prevSeqId":78785109621}]}
{"arg":{"channel":"books","instId":"BTC-USDT"},"action":"update","data":[{"asks":[],"bids":[["64801.1","0.33155936","0","2"],["64792.9","0","0","0"],["64792.6","0.00772259","0","1"],["64790.9","0.1375547","0","2"]],"ts":"1784087989402","checksum":0,"seqId":78785109652,"prevSeqId":78785109640}]}
{"arg":{"channel":"books","instId":"BTC-USDT"},"action":"update","data":[{"asks":[["64813.7","0","0","0"],["64814.6","0.15443864","0","1"]],"bids":[["64790.9","0.12035646","0","1"]],"ts":"1784087989502","checksum":0,"seqId":78785109659,"prevSeqId":78785109652}]}
{"arg":{"channel":"books","instId":"BTC-USDT"},"action":"update","data":[{"asks":[["64851","0.00060785","0","18"]],"bids":[],"ts":"1784087989602","checksum":0,"seqId":78785109668,"prevSeqId":78785109659}]}
{"arg":{"channel":"books","instId":"BTC-USDT"},"action":"update","data":[{"asks":[],"bids":[["64805.1","0.11417627","0","1"],["64795.5","0.09699282","0","2"],["64793.8","0.1251792","0","1"],["64792.6","0","0","0"],["64792.5","0","0","0"],["64792.1","0.00772248","0","1"],["64790.6","0.0557725","0","2"],["64784.4","0.02907366","0","1"],["64636.3","0","0","0"],["64635.4","0","0","0"]],"ts":"1784087989702","checksum":0,"seqId":78785109687,"prevSeqId":78785109668}]}
{"arg":{"channel":"trades","instId":"BTC-USDT"},"data":[{"instId":"BTC-USDT","tradeId":"1033093084","px":"64809.9","sz":"0.105","side":"sell","ts":"1784087989714","count":"2","source":"0","seqId":78785109701}]}
{"arg":{"channel":"trades","instId":"BTC-USDT"},"data":[{"instId":"BTC-USDT","tradeId":"1033093085","px":"64809.9","sz":"0.0007093","side":"sell","ts":"1784087989716","count":"1","source":"0","seqId":78785109707}]}
{"arg":{"channel":"trades","instId":"BTC-USDT"},"data":[{"instId":"BTC-USDT","tradeId":"1033093087","px":"64809.8","sz":"0.01811294","side":"sell","ts":"1784087989716","count":"2","source":"0","seqId":78785109723}]}
{"arg":{"channel":"trades","instId":"BTC-USDT"},"data":[{"instId":"BTC-USDT","tradeId":"1033093088","px":"64809.5","sz":"0.01695023","side":"sell","ts":"1784087989716","count":"1","source":"0","seqId":78785109723}]}
{"arg":{"channel":"trades","instId":"BTC-USDT"},"data":[{"instId":"BTC-USDT","tradeId":"1033093090","px":"64809.2","sz":"0.01793683","side":"sell","ts":"1784087989716","count":"2","source":"0","seqId":78785109723}]}
{"arg":{"channel":"trades","instId":"BTC-USDT"},"data":[{"instId":"BTC-USDT","tradeId":"1033093091","px":"64809.2","sz":"0.00189823","side":"sell","ts":"1784087989719","count":"1","source":"0","seqId":78785109817}]}
{"arg":{"channel":"trades","instId":"BTC-USDT"},"data":[{"instId":"BTC-USDT","tradeId":"1033093092","px":"64808.3","sz":"0.02265743","side":"sell","ts":"1784087989721","count":"1","source":"0","seqId":78785109900}]}
{"arg":{"channel":"trades","instId":"BTC-USDT"},"data":[{"instId":"BTC-USDT","tradeId":"1033093093","px":"64806.6","sz":"0.00116271","side":"sell","ts":"1784087989725","count":"1","source":"0","seqId":78785109983}]}
{"arg":{"channel":"trades","instId":"BTC-USDT"},"data":[{"instId":"BTC-USDT","tradeId":"1033093095","px":"64805.2","sz":"0.00208352","side":"sell","ts":"1784087989734","count":"2","source":"0","seqId":78785110108}]}
{"arg":{"channel":"trades","instId":"BTC-USDT"},"data":[{"instId":"BTC-USDT","tradeId":"1033093096","px":"64804.1","sz":"0.0000155","side":"sell","ts":"1784087989734","count":"1","source":"0","seqId":78785110108}]}
{"arg":{"channel":"trades","instId":"BTC-USDT"},"data":[{"instId":"BTC-USDT","tradeId":"1033093097","px":"64803.4","sz":"0.00116271","side":"sell","ts":"1784087989734","count":"1","source":"0","seqId":78785110108}]}
{"arg":{"channel":"books","instId":"BTC-USDT"},"action":"update","data":[{"asks":[["64802.8","2.58278535","0","17"],["64805.3","0.036","0","1"],["64805.6","0.9740945","0","1"],["64806.7","0.036","0","1"],["64806.8","0.1845","0","1"],["64808.3","1.08210536","0","2"],["64808.4","0.2205","0","2"],["64809","0.16077815","0","1"],["64809.1","0.0000155","0","1"],["64809.3","0.57406401","0","4"],["64809.6","0.036","0","1"],["64810","0.2055","0","3"],["64810.1","0.036","0","1"],["64811","0","0","0"],["64811.4","0","0","0"],["64811.6","0.0000155","0","1"],["64812","0.02316283","0","1"],["64813.8","0","0","0"],["64813.9","0","0","0"],["64814.6","0.15443799","0","1"],["64815.8","0.36106941","0","2"],["64816.6","0.1845","0","1"],["64816.7","0.0000155","0","1"],["64817.5","0.17213","0","1"],["64819.9","0","0","0"],["64823.1","0.46121345","0","3"],["64825.8","0.42938725","0","2"],["64827.3","0","0","0"],["64842.7","2.27772643","0","2"],["64858","2.664285","0","1"],["64858.9","0","0","0"],["64870.6","0.00019221","0","9"],["64882.4","0","0","0"],["64884.9","0.00007754","0","2"],["64902.5","0","0","0"],["64902.8","0","0","0"],["64903.1","0","0","0"],["64903.2","0","0","0"],["64903.3","0","0","0"],["64903.4","0","0","0"],["64903.6","0","0","0"],["64903.8","0","0","0"]],"bids":[["64809.9","0","0","0"],["64809.8","0","0","0"],["64809.5","0","0","0"],["64809.2","0","0","0"],["64808.3","0","0","0"],["64806.7","0","0","0"],["64806.6","0","0","0"],["64805.2","0","0","0"],["64805.1","0","0","0"],["64804.1","0","0","0"],["64803.6","0","0","0"],["64803.5","0","0","0"],["64803.4","0","0","0"],["64802.7","0.82962521","0","6"],["64801.9","0.12414075","0","1"],["64801.6","0","0","0"],["64797","0.18566271","0","2"],["64796.2","0","0","0"],["64794.8","0.02316298","0","1"],["64793.8","0","0","0"],["64793.7","0.10968368","0","1"],["64792.4","0.12518197","0","1"],["64792.1","0","0","0"],["64790.6","0.04629671","0","2"],["64790.5","0.1845","0","1"],["64789.7","0.36106941","0","2"],["64786.1","1.53617101","0","4"],["64784.4","0","0","0"],["64784.3","0","0","0"],["64784.2","0","0","0"],["64784","0.18451","0","2"],["64783.5","0.15443952","0","1"],["64772.3","0.23146273","0","1"],["64763.7","0.0015","0","1"],["64762.4","0.9892967","0","2"],["64761.7","0","0","0"],["64760.4","0","0","0"],["64760.3","0.25229633","0","2"],["64753.3","0.00177665","0","1"],["64750.1","0.00029964","0","1"],["64748.7","0.3118656","0","2"],["64747.8","0","0","0"],["64740","0.00138823","0","1"],["64737","0","0","0"],["64735.7","0.00154474","0","1"],["64733.4","0","0","0"],["64696.2","1.60581925","0","3"],["64637.5","0.00771867","0","2"],["64636.3","0.00098767","0","4"],["64635.4","0.02326085","0","1"],["64635.2","0.00002849","0","1"],["64634.6","0.00010084","0","1"],["64633.6","0.0000126","0","1"],["64633.3","0.00023532","0","1"],["64631.9","0.01982816","0","1"],["64630.6","0.00009618","0","3"],["64630.5","0.00004498","0","1"],["64630.4","0.00266407","0","1"],["64630.3","0.00001155","0","1"],["64630","0.00001552","0","1"],["64629.6","0.00007707","0","2"],["64629","0.00044064","0","1"],["64628.8","0.00173973","0","1"]],"ts":"1784087989802","checksum":0,"seqId":78785110324,"prevSeqId":78785109687}]}
{"arg":{"channel":"books","instId":"BTC-USDT"},"action":"update","data":[{"asks":[["64802.8","2.77707735","0","18"],["64805.5","0.29076721","0","1"],["64806.8","0","0","0"],["64808.2","0.69078159","0","1"],["64808.4","0.036","0","1"],["64809.3","0.99927717","0","6"],["64810","0.021","0","2"],["64810.7","0","0","0"],["64811","0.29768594","0","1"],["64812.6","0.00001501","0","1"],["64814.6","0.35923054","0","2"],["64822.6","0.60387554","0","1"],["64824.3","0.0000155","0","1"],["64825.8","0.42473641","0","1"],["64834.2","0.00001199","0","1"],["64838.4","0.00001199","0","1"],["64841.5","0","0","0"],["64842.5","1.05430619","0","2"],["64845.7","0","0","0"],["64857.9","0.89177677","0","1"],["64901.6","0","0","0"],["64901.8","0","0","0"],["64901.9","0","0","0"]],"bids":[["64802.7","0.85296402","0","7"],["64801.9","0.02333881","0","1"],["64801.7","0.13136067","0","2"],["64801.2","0.12415455","0","1"],["64801.1","0.35489817","0","3"],["64795.7","0.07528163","0","1"],["64795.5","0","0","0"],["64793.7","0","0","0"],["64792.4","0","0","0"],["64791.1","0.39006423","0","2"],["64790.9","0.12807897","0","2"],["64790.6","0.03857426","0","1"],["64789.7","0.81240658","0","4"],["64783.5","0","0","0"],["64781.6","0.15444045","0","1"],["64777","0","0","0"],["64771.3","0.99932558","0","5"],["64761","0","0","0"],["64753.7","0.00382222","0","1"],["64628.5","0.00071921","0","1"],["64627.1","0.00004969","0","1"]],"ts":"1784087989902","checksum":0,"seqId":78785110412,"prevSeqId":78785110324}]}
{"arg":{"channel":"books","instId":"BTC-USDT"},"action":"update","data":[{"asks":[["64802.8","2.58278535","0","17"],["64803.5","0.00011507","0","2"],["64814.5","0.15444123","0","1"],["64814.6","0.20479255","0","1"],["64825.1","0.05525547","0","4"],["64825.8","1.06146179","0","2"],["64827.3","2.27639704","0","1"],["64842.5","0.33854325","0","1"],["64842.7","0.00023","0","1"],["64859","0","0","0"],["64901.1","0","0","0"],["64901.3","0","0","0"]],"bids":[["64802.7","0.89823713","0","6"],["64801.2","0","0","0"],["64782.7","0.00008112","0","6"],["64781.6","0.15444123","0","1"],["64696.2","1.63079217","0","2"],["64626.2","0.00001253","0","1"]],"ts":"1784087990002","checksum":0,"seqId":78785110449,"prevSeqId":78785110412}]}
{"arg":{"channel":"books","instId":"BTC-USDT"},"action":"update","data":[{"asks":[["64825.8","1.06960076","0","3"]],"bids":[["64802.7","0.71185956","0","5"],["64801.2","0.12415455","0","1"],["64793.7","0.12415455","0","1"],["64791.2","0.26488391","0","1"],["64791.1","0.12518435","0","1"],["64791","0.12807919","0","2"],["64790.9","0.12035646","0","1"],["64768","0.07640786","0","1"],["64628.8","0","0","0"],["64628.5","0","0","0"],["64627.1","0","0","0"],["64626.2","0","0","0"]],"ts":"1784087990102","checksum":0,"seqId":78785110493,"prevSeqId":78785110449}]}
{"arg":{"channel":"books","instId":"BTC-USDT"},"action":"update","data":[{"asks":[["64803.4","0.012","0","1"],["64803.5","0.10813393","0","3"],["64805.2","0.12415455","0","1"],["64805.4","0.12415455","0","1"],["64808.1","0.15444371","0","1"],["64808.3","0.9740945","0","1"],["64809.2","0.30957429","0","1"],["64809.3","1.23999011","0","7"],["64810","0.009","0","1"],["64812","0","0","0"],["64813","0.015429","0","1"],["64814.3","0.07719091","0","1"],["64814.5","0","0","0"],["64814.6","0.13310734","0","1"],["64814.7","0.32556428","0","2"],["64815.2","0","0","0"],["64815.8","0.12035647","0","1"],["64816.3","1.0625945","0","2"],["64817.9","0.0885","0","1"],["64818","0","0","0"],["64819.5","0.9740945","0","1"],["64821.2","0","0","0"],["64824.5","0.48208","0","2"],["64827.3","2.41148113","0","2"],["64831","0.9740945","0","1"],["64831.1","0","0","0"],["64832.4","0.66798079","0","2"],["64836.8","0.32587","0","1"],["64840.3","0.19297727","0","1"],["64840.6","0","0","0"],["64842.8","0.02397734","0","1"],["64844","0","0","0"],["64846.8","0","0","0"],["64851.2","0","0","0"],["64853.2","0.25088139","0","2"],["64854.2","0.00033431","0","1"],["64857.5","0.07052559","0","1"],["64859.4","0.00046015","0","1"],["64866.2","0.3285918","0","2"],["64872.4","0.0000155","0","1"],["64887.2","0.00308226","0","2"],["64888.3","0.00023","0","1"],["64900.8","0","0","0"]],"bids":[["64802.7","0.02333881","0","1"],["64801.7","0.02333881","0","1"],["64801.2","0","0","0"],["64801","0","0","0"],["64799.5","0","0","0"],["64799.4","0.3289601","0","2"],["64799.2","0","0","0"],["64798.4","0.08863","0","1"],["64797","0.00116271","0","1"],["64796.9","0.10802986","0","1"],["64796.8","0.04621407","0","1"],["64795.3","0","0","0"],["64795.1","0.08856","0","1"],["64794.8","0","0","0"],["64793.7","0","0","0"],["64793.6","0.172126","0","2"],["64793.1","0.12415455","0","1"],["64792.8","0","0","0"],["64792.2","0.02316385","0","1"],["64791.9","0","0","0"],["64791.2","0","0","0"],["64791.1","0.12415455","0","1"],["64791","0.12035665","0","1"],["64790.9","0.07721879","0","1"],["64790.8","0","0","0"],["64790.6","0.17248792","0","3"],["64789.8","1.14800524","0","3"],["64789.7","0.24071294","0","1"],["64789.3","0","0","0"],["64789.2","0","0","0"],["64789","0.1594555","0","3"],["64788.5","0.26489495","0","1"],["64788","0.02543495","0","2"],["64786.9","0.00772264","0","1"],["64786.2","0","0","0"],["64786.1","1.36644425","0","3"],["64785.3","0.12035646","0","1"],["64783.6","0.21178652","0","2"],["64783","0.24071345","0","1"],["64782.2","0.44647","0","1"],["64781.6","0","0","0"],["64780.3","0","0","0"],["64779.9","0","0","0"],["64779.3","0.03596601","0","1"],["64778.5","0","0","0"],["64778.1","0.16974588","0","1"],["64777.9","0.13513288","0","1"],["64777.6","0.15444376","0","1"],["64776.7","0.57169364","0","3"],["64773.2","0","0","0"],["64773","0.001544","0","1"],["64769.9","0.4468","0","1"],["64764.9","0.19304697","0","1"],["64764.7","0.6560833","0","2"],["64760.3","0.00136741","0","1"],["64752","0.25096106","0","1"],["64747.7","0","0","0"],["64747","0.001544","0","1"],["64746","0","0","0"],["64745.2","0","0","0"],["64739","0.30887516","0","1"],["64738.7","0.067145","0","1"],["64715.1","0.00001807","0","1"],["64711.5","0","0","0"],["64704.9","0.00309094","0","2"]],"ts":"1784087990202","checksum":0,"seqId":78785110775,"prevSeqId":78785110493}]}
{"arg":{"channel":"books","instId":"BTC-USDT"},"action":"update","data":[{"asks":[["64802.8","2.63838663","0","18"],["64805.3","0.16015455","0","2"],["64805.4","0","0","0"],["64808.1","0.15444569","0","1"],["64808.3","0.99504708","0","2"],["64808.9","0.01982816","0","1"],["64809.1","0.02327635","0","2"],["64810.2","0.01542967","0","1"],["64812.2","0.01805347","0","1"],["64813","0","0","0"],["64814.9","0.01160758","0","1"],["64819.5","1.00354165","0","2"],["64820.8","0","0","0"],["64822","0.52363388","0","1"],["64822.9","2.27639704","0","1"],["64823","0","0","0"],["64823.9","0.01982816","0","1"],["64827.3","0.13508409","0","1"],["64828.9","0.97884482","0","1"],["64831.7","0","0","0"],["64833","0","0","0"],["64834","0","0","0"],["64861.4","0.0212","0","1"],["64868.5","0.00001065","0","1"]],"bids":[["64801.1","0.02341041","0","2"],["64799.4","0.00046015","0","1"],["64797.8","0","0","0"],["64795.7","0","0","0"],["64795.4","0","0","0"],["64793.7","0.12415455","0","1"],["64793.1","0","0","0"],["64792.2","0","0","0"],["64791.2","0.11342358","0","1"],["64791.1","0","0","0"],["64790.6","0.03857426","0","1"],["64789.8","0.16882815","0","1"],["64789.6","0","0","0"],["64789","0.0000155","0","1"],["64788.9","0","0","0"],["64788.5","0","0","0"],["64788.4","0","0","0"],["64788.1","0.18142","0","2"],["64788","0.01","0","1"],["64786.9","0","0","0"],["64786.1","0","0","0"],["64786","0","0","0"],["64785.9","0.1195846","0","1"],["64785.7","0.38323137","0","1"],["64785.6","0.30957429","0","1"],["64785.5","0.13391975","0","1"],["64785.4","0.28295716","0","2"],["64785.2","0","0","0"],["64785","0","0","0"],["64784.5","0","0","0"],["64783.8","1.04041173","0","2"],["64783.7","0.9740945","0","1"],["64783.5","0.08","0","1"],["64783.4","0","0","0"],["64782.3","0.04","0","1"],["64782","0.08","0","1"],["64781.2","0","0","0"],["64780.8","0","0","0"],["64780.2","0","0","0"],["64780","0.1157274","0","1"],["64778.8","0.14785825","0","1"],["64778","0.02915473","0","1"],["64777.9","0.15839373","0","2"],["64777.6","0.15444569","0","1"],["64774.9","0.22353797","0","1"],["64774.8","0.03860879","0","1"],["64772.6","0.00213689","0","1"],["64768","0","0","0"],["64767.9","0.45858128","0","1"],["64767.3","0","0","0"],["64767.2","0.05318935","0","1"],["64764.4","0.00116271","0","1"],["64752.6","0.40826145","0","1"],["64744.9","0.48415049","0","1"],["64743.4","0","0","0"],["64696.2","0.0236","0","1"],["64628.8","0.00173973","0","1"],["64628.5","0.00071921","0","1"],["64627.1","0.00004969","0","1"],["64626.2","0.00001253","0","1"]],"ts":"1784087990302","checksum":0,"seqId":78785111008,"prevSeqId":78785110775}]}
{"arg":{"channel":"books","instId":"BTC-USDT"},"action":"update","data":[{"asks":[["64802.8","2.74640666","0","19"],["64803.5","0.00011507","0","2"],["64805.1","0.51414605","0","1"],["64805.2","0.30957429","0","1"],["64805.3","0.036","0","1"],["64805.5","0","0","0"],["64808.1","0","0","0"],["64808.3","0.9740945","0","1"],["64808.8","0.15445349","0","1"],["64809.4","0.07719674","0","1"],["64810","0.02442972","0","2"],["64810.2","0","0","0"],["64811.7","0.0200039","0","1"],["64814.3","0","0","0"],["64819.4","0.51315135","0","2"],["64822.3","0.00001","0","1"],["64822.4","0.3457181","0","2"],["64822.6","1.32548594","0","2"],["64825.1","0.05524547","0","3"],["64825.8","0.43287538","0","2"],["64827.3","0","0","0"],["64828.8","0.06612656","0","1"],["64835.5","0.06172577","0","1"],["64836.7","0.45540324","0","1"],["64836.9","0.00001549","0","1"],["64837.4","0.1929859","0","1"],["64838.6","0.00024501","0","2"],["64840.1","0.0948185","0","1"],["64840.3","0","0","0"],["64841.1","0.00001","0","1"],["64843.3","0","0","0"],["64843.7","0","0","0"],["64850.3","0.25088167","0","1"],["64853.2","0.00001094","0","1"],["64853.8","0.00001","0","1"],["64857.7","0.00001005","0","1"],["64861.2","0.16095108","0","1"],["64861.3","0.30878696","0","1"],["64862","0","0","0"],["64866.2","0.01982816","0","1"],["64870.1","0.03102132","0","3"],["64899.9","0","0","0"],["64900","0","0","0"],["64900.1","0","0","0"],["64900.5","0","0","0"],["64900.6","0","0","0"],["64900.7","0","0","0"]],"bids":[["64797.9","0.11681353","0","1"],["64796.9","0","0","0"],["64796.1","0.21899997","0","1"],["64795.6","0.10056005","0","1"],["64795.5","0.12415455","0","1"],["64794.4","0.32849995","0","1"],["64793.2","0.10919881","0","2"],["64788.3","0.12415455","0","1"],["64786.9","0.00772351","0","1"],["64786.5","0.0200039","0","1"],["64786.4","0.76446056","0","3"],["64786.3","0.9740945","0","1"],["64786","0.26489823","0","1"],["64785.9","0","0","0"],["64785.7","0","0","0"],["64785.4","0.03348904","0","2"],["64783.8","1.02046573","0","1"],["64783.5","0","0","0"],["64780.1","0.14955812","0","1"],["64778.8","0","0","0"],["64778.7","0.15445349","0","1"],["64778.1","0","0","0"],["64778","0","0","0"],["64777.6","0","0","0"],["64777.3","0.65931543","0","2"],["64771.1","0","0","0"],["64769.2","0.16974588","0","1"],["64762.4","0.9740945","0","1"],["64760.3","0.06172577","0","1"],["64759.8","0.98929732","0","2"],["64757.5","0.00136747","0","1"],["64753.2","0.53096878","0","2"],["64748.7","0.30957429","0","1"],["64746","0.00229138","0","1"],["64735.7","0","0","0"],["64733.1","0.0015448","0","1"],["64702.7","0","0","0"],["64702.6","0","0","0"],["64696.2","4.31759141","0","2"],["64681.9","2.51750205","0","1"],["64673.7","0","0","0"],["64665.9","0.008025","0","1"],["64629","0","0","0"],["64628.8","0","0","0"],["64628.5","0","0","0"],["64627.1","0","0","0"],["64626.2","0","0","0"]],"ts":"1784087990402","checksum":0,"seqId":78785111201,"prevSeqId":78785111008}]}
{"arg":{"channel":"books","instId":"BTC-USDT"},"action":"update","data":[{"asks":[["64819.4","1.16714531","0","3"],["64820.7","2.27653964","0","1"],["64822.3","0","0","0"],["64822.9","0","0","0"],["64824.6","1.332829","0","1"],["64830.6","0.13801533","0","1"],["64832.4","0.49823491","0","1"],["64835.3","0.00001","0","1"],["64837.2","0.00001","0","1"],["64840.7","0","0","0"],["64841.1","0","0","0"],["64849.9","3.68014795","0","3"],["64853.8","0","0","0"]],"bids":[["64800.3","0.11109697","0","1"],["64795.6","0.18576088","0","2"],["64794.5","0.12415455","0","1"],["64793.7","0","0","0"],["64789","0.05561678","0","2"],["64788.3","0","0","0"],["64786.9","0","0","0"],["64786.4","0.6480291","0","3"],["64760.9","0.77919993","0","3"],["64760.2","1.334151","0","1"],["64759.8","0.9740945","0","1"],["64758.5","0.01590269","0","2"],["64757.5","0","0","0"],["64756","0.00136751","0","1"],["64753.7","0","0","0"],["64746","0","0","0"],["64744.6","0.0022914","0","1"],["64733.1","0","0","0"],["64731.8","1.44052416","0","2"],["64731.7","2.669477","0","1"],["64731.2","0","0","0"],["64696.2","2.71510177","0","2"],["64629","0.00044064","0","1"]],"ts":"1784087990502","checksum":0,"seqId":78785111268,"prevSeqId":78785111201}]}
{"arg":{"channel":"trades","instId":"BTC-USDT"},"data":[{"instId":"BTC-USDT","tradeId":"1033093098","px":"64802.7","sz":"0.02333881","side":"sell","ts":"1784087990558","count":"1","source":"0","seqId":78785111288}]}
{"arg":{"channel":"books","instId":"BTC-USDT"},"action":"update","data":[{"asks":[["64802","3.36021068","0","14"],["64802.6","0.69165476","0","1"],["64802.7","0.3678","0","1"],["64802.8","0.68823981","0","5"],["64805.1","0","0","0"],["64805.3","0.24662401","0","2"],["64808.5","0.4814261","0","2"],["64808.8","0","0","0"],["64809","0.31522793","0","2"],["64809.3","0.54794","0","4"],["64819.4","0.55907338","0","2"],["64820.7","0","0","0"],["64822.6","2.22811851","0","1"],["64825","2","0","1"],["64825.1","2.33178511","0","4"],["64828.9","0.4230424","0","1"],["64829","0","0","0"],["64857.9","0.29085764","0","1"],["64864.3","0.00104357","0","3"],["64867.4","0","0","0"]],"bids":[["64802.7","0","0","0"],["64800.3","0","0","0"],["64797.9","0","0","0"],["64797.2","0.12415608","0","1"],["64796.2","0.31402383","0","2"],["64795.6","0","0","0"],["64795.5","0","0","0"],["64794.5","0","0","0"],["64791.2","0","0","0"],["64791.1","0.12415608","0","1"],["64790.6","0","0","0"],["64789.8","0","0","0"],["64789.7","0","0","0"],["64789","0.22695941","0","3"],["64788.9","0.24071294","0","1"],["64787.1","0.13391638","0","1"],["64786.6","0.00772316","0","1"],["64786.4","0.64030601","0","2"],["64785.5","0","0","0"],["64782.5","0.03857909","0","1"],["64780.1","0.14955674","0","1"],["64779.4","0.15490993","0","2"],["64778.7","0","0","0"],["64776.7","0.12035647","0","1"],["64775.9","0.45133717","0","2"],["64753.7","0.00382248","0","1"],["64628.8","0.00173973","0","1"],["64628.5","0.00071921","0","1"],["64627.1","0.00004969","0","1"]],"ts":"1784087990602","checksum":0,"seqId":78785111406,"prevSeqId":78785111268}]}
{"arg":{"channel":"books","instId":"BTC-USDT"},"action":"update","data":[{"asks":[["64802.7","0","0","0"],["64802.8","0.31953981","0","4"],["64803.5","0","0","0"],["64808.1","0.15444978","0","1"],["64808.5","0.49685619","0","3"],["64809","0.16077815","0","1"],["64810","0.009","0","1"],["64812.5","0.01598999","0","1"],["64814.1","0.0885155","0","2"],["64814.7","0.30957429","0","1"],["64816.3","0.9740945","0","1"],["64819.5","0.9740945","0","1"],["64875.6","0.02940601","0","4"],["64883.7","0.00005115","0","4"]],"bids":[["64798.4","0","0","0"],["64797.2","0","0","0"],["64796.8","0","0","0"],["64796.2","0","0","0"],["64795.1","0","0","0"],["64794.7","0.12415761","0","1"],["64794.5","0.11332167","0","1"],["64791.1","0.11801709","0","1"],["64790.9","0.16584879","0","2"],["64789.3","0.04621407","0","1"],["64787.7","0.08856","0","1"],["64787.1","0","0","0"],["64786.6","0","0","0"],["64786.4","1.07841095","0","3"],["64786","2","0","1"],["64785.9","0.00772326","0","1"],["64785.8","0.13391909","0","1"],["64784.1","0.26490996","0","1"],["64782.2","0","0","0"],["64779.4","0.00046015","0","1"],["64778","0.15444978","0","1"],["64774.8","0.48507879","0","2"],["64769.9","0","0","0"],["64767.9","0.48891124","0","2"],["64764.6","0","0","0"],["64762.5","0.4468","0","1"],["64753.7","0","0","0"],["64753.3","0","0","0"],["64752.9","0.00382258","0","1"],["64752.1","0.00177683","0","1"],["64750.2","0.44684","0","1"],["64655.8","0.0241776","0","1"],["64636.7","0","0","0"]],"ts":"1784087990702","checksum":0,"seqId":78785111487,"prevSeqId":78785111406}]}
{"arg":{"channel":"books","instId":"BTC-USDT"},"action":"update","data":[{"asks":[["64802.7","0.00011508","0","2"],["64806.6","0.0000155","0","1"],["64818","0.00001","0","1"],["64819.4","0.55906338","0","1"],["64851","0.00059648","0","17"],["64878.6","0.00006587","0","2"],["64899.5","0","0","0"],["64899.6","0","0","0"],["64899.7","0","0","0"]],"bids":[["64797.2","0.12415761","0","1"],["64782.7","0.00006967","0","5"],["64627.1","0","0","0"]],"ts":"1784087990802","checksum":0,"seqId":78785111499,"prevSeqId":78785111487}]}
{"arg":{"channel":"books","instId":"BTC-USDT"},"action":"update","data":[{"asks":[],"bids":[["64782.8","0.00004723","0","1"],["64655.8","0","0","0"],["64627.1","0.00004969","0","1"]],"ts":"1784087990902","checksum":0,"seqId":78785111508,"prevSeqId":78785111499}]}
{"arg":{"channel":"books","instId":"BTC-USDT"},"action":"update","data":[{"asks":[["64808.5","0.25614325","0","2"],["64822.9","2.27611183","0","1"],["64825.1","0.05524547","0","3"],["64899.4","0","0","0"]],"bids":[["64800.2","0.02852731","0","2"],["64796.1","0","0","0"],["64794.8","0.16894943","0","1"],["64786.9","0.15316386","0","1"],["64785.8","0","0","0"]],"ts":"1784087991002","checksum":0,"seqId":78785111520,"prevSeqId":78785111508}]}
{"arg":{"channel":"books","instId":"BTC-USDT"},"action":"update","data":[{"asks":[["64814.6","0.1866345","0","2"],["64815","0.24071294","0","1"],["64836.2","0.46270481","0","1"],["64898.7","0","0","0"],["64898.9","0","0","0"]],"bids":[["64793.6","0.2866186","0","1"],["64792.1","0.33596632","0","1"],["64791.1","0","0","0"],["64788.9","0.4814261","0","2"],["64785.9","0","0","0"],["64785.7","0.28210577","0","2"],["64784.9","0.00772322","0","1"],["64784.1","0","0","0"],["64775.9","0.21062401","0","1"],["64771.2","0.48570781","0","2"]],"ts":"1784087991102","checksum":0,"seqId":78785111538,"prevSeqId":78785111520}]}
{"arg":{"channel":"books","instId":"BTC-USDT"},"action":"update","data":[{"asks":[["64802.6","0.49292012","0","1"],["64805.3","0.036","0","1"],["64808.5","0.46676726","0","3"]],"bids":[["64797.1","0.69145632","0","2"],["64794.5","0","0","0"],["64626.2","0.00001253","0","1"]],"ts":"1784087991202","checksum":0,"seqId":78785111547,"prevSeqId":78785111538}]}
{"arg":{"channel":"books","instId":"BTC-USDT"},"action":"update","data":[{"asks":[["64810","0","0","0"],["64857.9","0.43606512","0","2"],["64898.7","0.00027156","0","3"]],"bids":[["64786.5","0.02772713","0","2"],["64785.7","0.2649074","0","1"],["64784.9","0","0","0"],["64626","0.00004524","0","1"]],"ts":"1784087991302","checksum":0,"seqId":78785111560,"prevSeqId":78785111547}]}
{"arg":{"channel":"books","instId":"BTC-USDT"},"action":"update","data":[{"asks":[],"bids":[["64782.7","0.00008112","0","6"]],"ts":"1784087991402","checksum":0,"seqId":78785111566,"prevSeqId":78785111560}]}
{"arg":{"channel":"books","instId":"BTC-USDT"},"action":"update","data":[{"asks":[["64815","0.27037865","0","2"],["64850.9","0.00009797","0","7"]],"bids":[["64775.9","0.23920097","0","2"]],"ts":"1784087991502","checksum":0,"seqId":78785111574,"prevSeqId":78785111566}]}
{"arg":{"channel":"books","instId":"BTC-USDT"},"action":"update","data":[{"asks":[],"bids":[["64698.3","0","0","0"],["64688.1","0.00927601","0","2"],["64625.1","0.00006891","0","1"]],"ts":"1784087991702","checksum":0,"seqId":78785111586,"prevSeqId":78785111574}]}
{"arg":{"channel":"books","instId":"BTC-USDT"},"action":"update","data":[{"asks":[["64809.4","0","0","0"],["64812.7","0.07719281","0","1"],["64822.4","0.21062381","0","1"],["64825.7","0.13508741","0","1"],["64845.8","0","0","0"],["64861.2","0","0","0"],["64861.3","0","0","0"],["64864.6","0.30878625","0","2"],["64898.9","0.00002074","0","1"],["64899.4","0.00046015","0","1"]],"bids":[["64730.9","0.0000155","0","1"],["64728.4","0.0000155","0","1"],["64626","0","0","0"],["64625.1","0","0","0"]],"ts":"1784087991802","checksum":0,"seqId":78785111600,"prevSeqId":78785111586}]}
{"arg":{"channel":"books","instId":"BTC-USDT"},"action":"update","data":[{"asks":[],"bids":[["64782.7","0.00009257","0","7"]],"ts":"1784087991902","checksum":0,"seqId":78785111605,"prevSeqId":78785111600}]}
{"arg":{"channel":"books","instId":"BTC-USDT"},"action":"update","data":[{"asks":[["64802","3.84021068","0","16"],["64803.4","0.03182816","0","2"],["64806.6","0.15446849","0","2"],["64807.9","0.07719853","0","1"],["64808.1","0.02326085","0","1"],["64808.5","0.7074802","0","4"],["64809.1","0.0000155","0","1"],["64809.2","0.33072049","0","2"],["64809.3","0.30794","0","2"],["64811.7","0","0","0"],["64812.7","0","0","0"],["64815","0.02966571","0","1"],["64822.4","0.3457181","0","2"],["64825.7","0","0","0"],["64831.7","0.02947432","0","1"],["64833.9","0.19299632","0","1"],["64837.4","0","0","0"],["64846.8","0.25089522","0","1"],["64849.3","0.00931626","0","4"],["64850.3","0","0","0"],["64861.3","0.30878696","0","1"],["64864.6","0.00001501","0","1"],["64870.1","0.02332256","0","2"]],"bids":[["64797.2","0","0","0"],["64797.1","0.05145632","0","1"],["64794.8","0","0","0"],["64794.7","0.11170275","0","1"],["64793.6","0","0","0"],["64793.2","0.00116278","0","1"],["64792.3","0.55672806","0","2"],["64792.2","0.12414229","0","1"],["64791.8","0.10803837","0","1"],["64789","0.05561678","0","2"],["64788.9","0","0","0"],["64786.9","0","0","0"],["64786.5","0","0","0"],["64786.4","0.64030601","0","2"],["64786.3","0","0","0"],["64785.7","0","0","0"],["64785.6","0","0","0"],["64785.3","0","0","0"],["64785.2","0.18156162","0","1"],["64783.8","0","0","0"],["64783.7","0.02114673","0","1"],["64783.6","0.00116271","0","1"],["64783.1","0.00772324","0","1"],["64783","0","0","0"],["64782.6","0.26492005","0","1"],["64782.3","0","0","0"],["64782","0","0","0"],["64781.6","0.04","0","1"],["64781.2","0.08","0","1"],["64781.1","0.30957429","0","1"],["64780.4","0.12151917","0","2"],["64780.1","0","0","0"],["64778.7","0.21062381","0","1"],["64778.3","0.24072846","0","2"],["64778","0","0","0"],["64777.9","0.13513288","0","1"],["64777.4","0.02326085","0","1"],["64776.2","0.15445299","0","1"],["64775.9","0.72062707","0","4"],["64767.9","0.45858128","0","1"],["64738.7","0","0","0"],["64728.9","0.067145","0","1"],["64626","0.00004524","0","1"],["64625.1","0.00006891","0","1"],["64625","0.00411578","0","2"],["64624.9","0.0002809","0","3"],["64624.5","0.00002529","0","1"]],"ts":"1784087992002","checksum":0,"seqId":78785111730,"prevSeqId":78785111605}]}
{"arg":{"channel":"trades","instId":"BTC-USDT"},"data":[{"instId":"BTC-USDT","tradeId":"1033093099","px":"64801.9","sz":"0.00001501","side":"sell","ts":"1784087992080","count":"1","source":"0","seqId":78785111850}]}
{"arg":{"channel":"trades","instId":"BTC-USDT"},"data":[{"instId":"BTC-USDT","tradeId":"1033093100","px":"64801.9","sz":"0.00001501","side":"sell","ts":"1784087992080","count":"1","source":"0","seqId":78785111856}]}
{"arg":{"channel":"trades","instId":"BTC-USDT"},"data":[{"instId":"BTC-USDT","tradeId":"1033093101","px":"64801.9","sz":"0.00001501","side":"sell","ts":"1784087992080","count":"1","source":"0","seqId":78785111859}]}
{"arg":{"channel":"trades","instId":"BTC-USDT"},"data":[{"instId":"BTC-USDT","tradeId":"1033093102","px":"64801.9","sz":"0.00001501","side":"sell","ts":"1784087992080","count":"1","source":"0","seqId":78785111865}]}
{"arg":{"channel":"trades","instId":"BTC-USDT"},"data":[{"instId":"BTC-USDT","tradeId":"1033093103","px":"64801.9","sz":"0.00001501","side":"sell","ts":"1784087992080","count":"1","source":"0","seqId":78785111867}]}
{"arg":{"channel":"trades","instId":"BTC-USDT"},"data":[{"instId":"BTC-USDT","tradeId":"1033093104","px":"64801.9","sz":"0.00001501","side":"sell","ts":"1784087992081","count":"1","source":"0","seqId":78785111874}]}
{"arg":{"channel":"trades","instId":"BTC-USDT"},"data":[{"instId":"BTC-USDT","tradeId":"1033093105","px":"64801.9","sz":"0.00001501","side":"sell","ts":"1784087992081","count":"1","source":"0","seqId":78785111889}]}
{"arg":{"channel":"trades","instId":"BTC-USDT"},"data":[{"instId":"BTC-USDT","tradeId":"1033093106","px":"64801.9","sz":"0.00001501","side":"sell","ts":"1784087992081","count":"1","source":"0","seqId":78785111893}]}
{"arg":{"channel":"trades","instId":"BTC-USDT"},"data":[{"instId":"BTC-USDT","tradeId":"1033093107","px":"64801.9","sz":"0.00001501","side":"sell","ts":"1784087992083","count":"1","source":"0","seqId":78785111901}]}
{"arg":{"channel":"trades","instId":"BTC-USDT"},"data":[{"instId":"BTC-USDT","tradeId":"1033093108","px":"64801.9","sz":"0.02320372","side":"sell","ts":"1784087992085","count":"1","source":"0","seqId":78785111926}]}
{"arg":{"channel":"trades","instId":"BTC-USDT"},"data":[{"instId":"BTC-USDT","tradeId":"1033093109","px":"64801.7","sz":"0.02279628","side":"sell","ts":"1784087992085","count":"1","source":"0","seqId":78785111926}]}
{"arg":{"channel":"trades","instId":"BTC-USDT"},"data":[{"instId":"BTC-USDT","tradeId":"1033093110","px":"64801.7","sz":"0.00054253","side":"sell","ts":"1784087992088","count":"1","source":"0","seqId":78785111982}]}
{"arg":{"channel":"trades","instId":"BTC-USDT"},"data":[{"instId":"BTC-USDT","tradeId":"1033093112","px":"64801.1","sz":"0.02341041","side":"sell","ts":"1784087992088","count":"2","source":"0","seqId":78785112018}]}
{"arg":{"channel":"trades","instId":"BTC-USDT"},"data":[{"instId":"BTC-USDT","tradeId":"1033093113","px":"64800.3","sz":"0.02627887","side":"buy","ts":"1784087992089","count":"1","source":"0","seqId":78785112044}]}
{"arg":{"channel":"trades","instId":"BTC-USDT"},"data":[{"instId":"BTC-USDT","tradeId":"1033093115","px":"64800.2","sz":"0.02852731","side":"sell","ts":"1784087992094","count":"2","source":"0","seqId":78785112191}]}
{"arg":{"channel":"trades","instId":"BTC-USDT"},"data":[{"instId":"BTC-USDT","tradeId":"1033093116","px":"64800","sz":"0.0001208","side":"sell","ts":"1784087992094","count":"1","source":"0","seqId":78785112191}]}
{"arg":{"channel":"trades","instId":"BTC-USDT"},"data":[{"instId":"BTC-USDT","tradeId":"1033093117","px":"64799.4","sz":"0.00046015","side":"sell","ts":"1784087992094","count":"1","source":"0","seqId":78785112191}]}
{"arg":{"channel":"trades","instId":"BTC-USDT"},"data":[{"instId":"BTC-USDT","tradeId":"1033093118","px":"64799.1","sz":"0.0000155","side":"sell","ts":"1784087992094","count":"1","source":"0","seqId":78785112191}]}
{"arg":{"channel":"books","instId":"BTC-USDT"},"action":"update","data":[{"asks":[["64797.2","3.53949067","0","18"],["64797.3","0.30957429","0","1"],["64799.5","0.28453","0","1"],["64799.9","0.28453","0","1"],["64800.2","0.45216972","0","2"],["64800.3","1.30322886","0","7"],["64800.9","0.18330932","0","1"],["64801.2","0.34557429","0","2"],["64801.6","0.02326085","0","1"],["64801.8","0.1845","0","1"],["64802","1.4900945","0","4"],["64802.6","0","0","0"],["64802.8","0.103145","0","2"],["64803.5","0.15445683","0","1"],["64803.7","0.24071316","0","1"],["64806.5","0.0772002","0","1"],["64806.6","0.0000155","0","1"],["64807.6","0.01543029","0","1"],["64807.9","0","0","0"],["64808.5","0","0","0"],["64809","0","0","0"],["64813.3","0.1157274","0","1"],["64814.7","0.42993094","0","2"],["64816.1","1.16403618","0","2"],["64818.5","2.27334349","0","1"],["64819.4","0.55952353","0","2"],["64819.5","1.10919485","0","2"],["64822.2","0.02397734","0","1"],["64822.4","0.21062381","0","1"],["64822.9","0","0","0"],["64825","2.0001208","0","2"],["64828.5","0.03860159","0","1"],["64831.5","0","0","0"],["64854.4","1.37782872","0","2"],["64857.9","0","0","0"],["64869.6","0","0","0"],["64878.6","0.00005037","0","1"],["64880.3","0.00313886","0","3"],["64887.2","0","0","0"],["64897.6","0","0","0"],["64897.7","0","0","0"],["64897.8","0","0","0"],["64897.9","0","0","0"],["64898.1","0","0","0"],["64898.7","0","0","0"],["64898.9","0","0","0"],["64899.4","0","0","0"]],"bids":[["64801.9","0","0","0"],["64801.7","0","0","0"],["64801.1","0","0","0"],["64800.2","0","0","0"],["64800","0","0","0"],["64799.4","0","0","0"],["64799.1","0","0","0"],["64796.5","0","0","0"],["64794.7","0","0","0"],["64792.3","0.11716759","0","1"],["64792.2","0","0","0"],["64791.8","0","0","0"],["64791.3","0","0","0"],["64791","0","0","0"],["64790.5","0","0","0"],["64790.4","0.1080407","0","1"],["64789","0.0000155","0","1"],["64788.1","0.01","0","1"],["64787.8","0.24830296","0","2"],["64786.4","0.0000155","0","1"],["64786.1","0.10980839","0","1"],["64786","0","0","0"],["64785.4","0","0","0"],["64785.2","0","0","0"],["64784.8","0","0","0"],["64784.7","0","0","0"],["64784.1","0.12414554","0","1"],["64783.1","0","0","0"],["64782.6","0.26491532","0","1"],["64781.3","0.12414554","0","1"],["64781.1","0","0","0"],["64780","0","0","0"],["64779.8","0.01543692","0","1"],["64779.3","0","0","0"],["64778.8","0.14740639","0","2"],["64778.3","0.24071345","0","1"],["64777.4","0","0","0"],["64777.3","0","0","0"],["64777.2","0.00116271","0","1"],["64777.1","0","0","0"],["64776.8","0.12415148","0","1"],["64776.7","0.24071312","0","2"],["64776.2","0","0","0"],["64775.9","0","0","0"],["64775","0.12427228","0","2"],["64774.9","0","0","0"],["64774.4","0","0","0"],["64774.3","0","0","0"],["64774.2","0.01805347","0","1"],["64773.3","0","0","0"],["64773","0","0","0"],["64772.9","0.41966247","0","3"],["64772.2","0","0","0"],["64771.4","0.02326085","0","1"],["64771.3","0.02523108","0","4"],["64771.2","0","0","0"],["64771.1","0.45133717","0","2"],["64770","0","0","0"],["64769","0","0","0"],["64768.7","0.9740945","0","1"],["64768.6","0","0","0"],["64767.9","0.67958963","0","2"],["64766","0.001544","0","1"],["64765.1","0","0","0"],["64764.8","0.30957429","0","1"],["64762.6","0.02326085","0","1"],["64760.9","0.75593908","0","2"],["64758.5","0.00069955","0","1"],["64756","0","0","0"],["64754.6","0.01520406","0","1"],["64754","0","0","0"],["64753.2","0.53233635","0","3"],["64746.1","0","0","0"],["64746","0.03596601","0","1"],["64744.6","0","0","0"],["64740.5","0.00229151","0","1"],["64740","0.00293223","0","2"],["64731.8","1.43897932","0","1"],["64730.5","0.003087","0","1"],["64730.3","0","0","0"],["64728.9","0","0","0"],["64728","0.00154493","0","1"],["64720.3","0.06716001","0","2"],["64707.2","0.84046407","0","2"],["64704.9","0","0","0"],["64704","0.35811","0","1"],["64696.9","0.00309132","0","2"],["64696.2","3.37640024","0","3"],["64685.9","0","0","0"],["64681.9","0","0","0"],["64654.3","0.001852","0","1"],["64623.6","0.02326085","0","1"],["64623.4","0.0176","0","1"],["64622.7","0.00159493","0","1"],["64622.6","0.00029334","0","5"],["64622.2","0.00002025","0","1"],["64621.8","0.00006502","0","2"],["64621.7","0.00173781","0","1"],["64621.6","0.000562","0","1"],["64621.5","0.1845","0","1"],["64620.9","0.00018046","0","3"],["64620.8","0.00010412","0","1"],["64620.7","0.00001218","0","1"],["64620.2","0.00017969","0","3"],["64620","0.02646366","0","5"],["64619.9","0.00002621","0","2"],["64619.8","0.00009869","0","2"],["64619.6","0.01982816","0","1"],["64619.5","0.00001435","0","1"],["64619.4","0.00046015","0","1"],["64618","0.00138862","0","2"],["64617.6","0.00305797","0","4"],["64616.6","0.0000211","0","1"],["64615.7","0.02326085","0","1"],["64615.6","1.26207386","0","1"],["64615.4","0.00001","0","1"]],"ts":"1784087992102","checksum":0,"seqId":78785112320,"prevSeqId":78785111730}]}
{"arg":{"channel":"books","instId":"BTC-USDT"},"action":"update","data":[{"asks":[["64797.2","3.83083981","0","20"],["64797.3","0","0","0"],["64799.5","0","0","0"],["64799.9","0","0","0"],["64800.2","0","0","0"],["64800.3","0.15944","0","2"],["64800.4","0.50614419","0","1"],["64800.5","0.33062401","0","3"],["64800.8","0.02326085","0","1"],["64801.6","0","0","0"],["64802","1.0100945","0","2"],["64802.7","0","0","0"],["64803.3","0.012","0","1"],["64803.4","0.01982816","0","1"],["64803.8","0.01543121","0","1"],["64806.1","0.000015","0","1"],["64806.5","0.09786866","0","2"],["64807.6","0","0","0"],["64808.2","0","0","0"],["64809.2","0.30957429","0","1"],["64809.9","0.01160758","0","1"],["64810.2","0.24071294","0","1"],["64811.8","0.17196","0","1"],["64814.3","0.02916187","0","1"],["64814.9","0","0","0"],["64815","0","0","0"],["64815.3","0.03449378","0","1"],["64817.5","0","0","0"],["64822.6","0","0","0"],["64824.6","0","0","0"],["64828.5","0","0","0"],["64828.6","0.00001199","0","1"],["64828.8","0","0","0"],["64832.8","0.00001199","0","1"],["64833","0.00001","0","1"],["64834.2","0","0","0"],["64838.4","0","0","0"],["64850","12.93091141","0","15"],["64850.7","0.00011717","0","6"],["64856.9","0","0","0"],["64880.8","0.00408629","0","2"],["64893.8","0.01985839","0","2"],["64897.6","0.0000513","0","1"],["64897.7","0.00001825","0","1"],["64897.8","0.00002843","0","1"]],"bids":[["64792.3","0","0","0"],["64787.8","0.12415148","0","1"],["64784","0.1845","0","1"],["64783.7","0","0","0"],["64782.6","0","0","0"],["64782.5","0.20985909","0","2"],["64781.6","0","0","0"],["64781.5","0","0","0"],["64781.4","0.2649377","0","2"],["64781.3","0.1448297","0","2"],["64781.2","0","0","0"],["64780.5","0.00772377","0","1"],["64780.1","0.12415148","0","1"],["64779.9","0.18157658","0","1"],["64779.1","0.55807335","0","1"],["64778.9","1.2836843","0","3"],["64778.8","0","0","0"],["64778.3","0.000015","0","1"],["64776.8","0","0","0"],["64776.7","0.32071312","0","3"],["64776.2","0.53175686","0","1"],["64776.1","0.2391674","0","2"],["64775","0.0001208","0","1"],["64774.9","0.9740945","0","1"],["64774.5","0.24071345","0","1"],["64773","0.42756392","0","2"],["64772.9","0.46403112","0","2"],["64772.6","0","0","0"],["64772.3","0","0","0"],["64771.3","0.97411001","0","2"],["64771.2","0.63242643","0","1"],["64771.1","0.69205011","0","3"],["64768.9","0.30957429","0","1"],["64767","0.00001","0","1"],["64766.1","0.06173111","0","1"],["64765.7","0.02521739","0","3"],["64764.8","0.54106595","0","2"],["64760.9","0.38440775","0","1"],["64760.2","0","0","0"],["64752.9","0","0","0"],["64752.1","0","0","0"],["64750.6","0.00382287","0","1"],["64747.6","0.00177723","0","1"],["64740","0.001544","0","1"],["64733.9","0.00138893","0","1"],["64723.5","0","0","0"],["64720.4","0.02004726","0","1"],["64718.9","0","0","0"],["64710.8","0.00011951","0","1"],["64710.3","0.5908031","0","2"],["64706.1","0.23704424","0","2"],["64698","0.02326085","0","1"],["64693.1","0.1561374","0","1"],["64690.3","0","0","0"],["64686.9","0.81251204","0","1"],["64686.8","2.51750205","0","1"],["64685.3","0.00001198","0","1"],["64677.6","0.00001198","0","1"],["64619.4","0","0","0"],["64618","0","0","0"],["64617.6","0","0","0"],["64616.6","0","0","0"],["64615.7","0","0","0"],["64615.6","0","0","0"],["64615.4","0","0","0"]],"ts":"1784087992202","checksum":0,"seqId":78785112557,"prevSeqId":78785112320}]}
{"arg":{"channel":"books","instId":"BTC-USDT"},"action":"update","data":[{"asks":[["64797.9","0.0001151","0","2"],["64801.8","0","0","0"],["64802.7","0.15446634","0","1"],["64803.5","0","0","0"],["64803.6","0.47038471","0","1"],["64808.2","0.50251056","0","1"],["64808.8","0.01598999","0","1"],["64810.4","0.0885","0","1"],["64812","0.0885","0","1"],["64812.5","0","0","0"],["64814.1","0.0000155","0","1"],["64817.9","0","0","0"],["64818.6","0.44608","0","1"],["64818.7","0.26353194","0","2"],["64822.6","1.18706391","0","1"],["64824","0.06612655","0","1"],["64824.5","0.036","0","1"],["64825.8","0.42473641","0","1"],["64829.3","0.00807273","0","2"],["64841.3","0","0","0"],["64843.2","0.44583","0","1"],["64855.7","0","0","0"],["64857.9","0.79584722","0","1"],["64861.2","0.16095108","0","1"],["64864.3","0.24678759","0","4"],["64897","0","0","0"],["64897.1","0","0","0"],["64897.2","0","0","0"],["64897.4","0","0","0"],["64897.6","0","0","0"],["64897.7","0","0","0"],["64897.8","0","0","0"]],"bids":[["64794.4","0","0","0"],["64792.3","0.11235169","0","1"],["64792.1","0","0","0"],["64790.9","0.07721879","0","1"],["64790.4","0.33201825","0","2"],["64789.9","0.1168469","0","1"],["64789.3","0","0","0"],["64788.7","0.33596632","0","1"],["64787.7","0","0","0"],["64786.4","0.0886455","0","2"],["64784.8","0.04621407","0","1"],["64783.2","0.08856","0","1"],["64782.8","0","0","0"],["64782.6","0.45207913","0","2"],["64781.5","0.9740945","0","1"],["64781.4","0.00001551","0","1"],["64781.3","0","0","0"],["64780.5","0.2726509","0","2"],["64780.1","0","0","0"],["64778.4","0.01400207","0","1"],["64777.7","0.04","0","1"],["64774.8","0.03860879","0","1"],["64772.9","0.30957429","0","1"],["64772.8","0.15446634","0","1"],["64770.3","0.44647","0","1"],["64764.3","0.00213689","0","1"],["64750.6","0","0","0"],["64747.6","0.00560009","0","2"],["64691.2","0.05012544","0","1"],["64684.4","0.1022511","0","1"],["64680.1","0.02677585","0","1"],["64620.7","0","0","0"],["64620.2","0","0","0"],["64620","0","0","0"],["64619.9","0","0","0"],["64619.8","0","0","0"],["64619.6","0","0","0"],["64619.5","0","0","0"]],"ts":"1784087992302","checksum":0,"seqId":78785112637,"prevSeqId":78785112557}]}
{"arg":{"channel":"books","instId":"BTC-USDT"},"action":"update","data":[{"asks":[["64813.7","0.00001","0","1"],["64818","0","0","0"],["64819.2","1.53416927","0","4"],["64819.3","1.64251229","0","2"],["64819.4","0.00046015","0","1"],["64820","2","0","1"],["64822.6","0.60980269","0","1"],["64825","0.0001208","0","1"],["64829.8","0.00001","0","1"],["64832.1","0.00002501","0","2"],["64835.3","0","0","0"],["64837.2","0","0","0"],["64844.7","0.00001","0","1"],["64849.9","3.68013795","0","2"],["64896.9","0","0","0"]],"bids":[["64797.1","0.05152251","0","2"],["64790.4","0.1080407","0","1"],["64788.8","0.14630016","0","1"],["64786.2","0.1387034","0","1"],["64784.8","0.04622907","0","2"],["64781.3","0.18157276","0","1"],["64780.1","1.16920412","0","1"],["64780","2","0","1"],["64779.9","0","0","0"],["64779.1","0","0","0"],["64755","0.9892398","0","1"],["64754.9","1.33426","0","1"],["64754.6","0","0","0"],["64753.2","0","0","0"],["64752","0.26616574","0","2"],["64750.3","0.00136765","0","1"],["64740.5","0","0","0"],["64739.2","0.00229153","0","1"],["64728","0","0","0"],["64725.4","0.00154499","0","1"],["64686.9","0","0","0"],["64684.4","0","0","0"],["64620.9","0","0","0"],["64620.8","0","0","0"]],"ts":"1784087992402","checksum":0,"seqId":78785112681,"prevSeqId":78785112637}]}
{"arg":{"channel":"books","instId":"BTC-USDT"},"action":"update","data":[{"asks":[["64816.3","3.24622947","0","2"],["64818.5","0","0","0"],["64896.9","0.0001544","0","2"]],"bids":[["64790.5","0.12418016","0","1"],["64790","0.64116271","0","2"],["64789.9","0","0","0"],["64788.8","0.10924095","0","1"],["64787.8","0","0","0"],["64786.5","0.11193029","0","1"],["64786.2","0","0","0"],["64786.1","0","0","0"],["64785.1","0.12418016","0","1"],["64784.1","0.12418016","0","1"],["64784","0.24010128","0","2"],["64782.8","0.30957429","0","1"],["64781.4","0.00773943","0","2"],["64780.5","0.26492713","0","1"]],"ts":"1784087992502","checksum":0,"seqId":78785112705,"prevSeqId":78785112681}]}
{"arg":{"channel":"trades","instId":"BTC-USDT"},"data":[{"instId":"BTC-USDT","tradeId":"1033093119","px":"64797.2","sz":"0.00002972","side":"buy","ts":"1784087992506","count":"1","source":"0","seqId":78785112708}]}
{"arg":{"channel":"books","instId":"BTC-USDT"},"action":"update","data":[{"asks":[["64797.2","3.83081009","0","20"]],"bids":[["64790","0.00116271","0","1"],["64788.9","0.10732456","0","1"],["64788.8","0.25109995","0","2"],["64786.5","0.17175578","0","2"],["64621.5","0","0","0"]],"ts":"1784087992602","checksum":0,"seqId":78785112714,"prevSeqId":78785112705}]}
