{"event":"subscribe","arg":{"channel":"books","instId":"BTC-USDT"},"connId":"27e931e5"}
{"event":"subscribe","arg":{"channel":"trades","instId":"BTC-USDT"},"connId":"27e931e5"}
{"arg":{"channel":"books","instId":"BTC-USDT"},"action":"snapshot","data":[{"asks":[["64810.1","0.18247398","0","3"],["64810.9","0.0002677","0","3"],["64812.2","0.05560367","0","1"],["64813.5","0.1080022","0","1"],["64814.1","0.0000155","0","1"],["64816.4","0.12412677","0","1"],["64816.6","0.56112488","0","2"],["64816.7","0.0671455","0","2"],["64816.9","0.9740945","0","1"],["64817.2","0.12","0","2"],["64819.1","0.00001501","0","1"],["64819.2","0.0000155","0","1"],["64819.4","0.3591374","0","1"],["64819.5","0.9740945","0","1"],["64819.9","0.21304039","0","1"],["64821.3","0.01598999","0","1"],["64821.6","0.012","0","1"],["64821.7","0.0000155","0","1"],["64822.6","0.88647237","0","1"],["64822.7","0.9740945","0","1"],["64822.9","0.0885","0","1"],["64823.1","0.91255011","0","5"],["64823.8","0.30957429","0","1"],["64823.9","0.358051","0","1"],["64824.3","0.3130755","0","2"],["64824.4","0.0154263","0","1"],["64824.5","0.20167876","0","3"],["64825.1","0.05528732","0","4"],["64825.6","0.0003149","0","2"],["64825.7","0.15441379","0","1"],["64825.8","0.42938725","0","2"],["64826.1","0.00023","0","1"],["64826.8","0.0000155","0","1"],["64827.9","1.30692964","0","3"],["64828.2","0.02315828","0","1"],["64828.5","0.1157274","0","1"],["64829.3","0.00001549","0","1"],["64829.4","0.00001","0","1"],["64829.6","0.1845","0","1"],["64830.3","0.00023","0","1"],["64830.8","0.02961061","0","1"],["64830.9","0.52821117","0","1"],["64831","0.9740945","0","1"],["64831.1","0.44608","0","1"],["64831.5","0.12035665","0","1"],["64831.8","0.00001549","0","1"],["64832.1","0.00001501","0","1"],["64832.4","0.49823491","0","1"],["64833.5","0.01805347","0","1"],["64833.7","0.03174854","0","1"],["64834","0.38435022","0","1"],["64834.4","0.00024549","0","2"],["64835.2","1.30692964","0","3"],["64835.3","1.39861586","0","2"],["64835.8","0.11700071","0","1"],["64836","0.0012","0","1"],["64836.1","0.30485647","0","2"],["64836.2","1.33259","0","1"],["64836.5","0.06612663","0","1"],["64836.9","0.00001549","0","1"],["64837","0.01982816","0","1"],["64837.3","0.24071345","0","1"],["64837.8","0.01283297","0","1"],["64838","2.21062381","0","2"],["64838.2","0.9740945","0","1"],["64838.6","0.14586655","0","3"],["64839.4","0.00047564","0","2"],["64840.1","0.12035646","0","1"],["64840.2","0.30957429","0","1"],["64840.6","0.12639999","0","1"],["64841.5","0.00001199","0","1"],["64841.8","0.01932231","0","1"],["64842","0.00001549","0","1"],["64842.4","0.02326085","0","1"],["64842.5","0.33854325","0","1"],["64842.6","1.1585945","0","2"],["64842.7","0.00023","0","1"],["64843.4","0.00805531","0","1"],["64844.5","0.00001549","0","1"],["64845.1","1.10759922","0","3"],["64845.2","0.9740945","0","1"],["64845.4","0.30957429","0","1"],["64845.7","0.00001199","0","1"],["64845.8","0.02957693","0","1"],["64846.2","0.00001","0","1"],["64846.8","0.32587","0","1"],["64846.9","0.00023","0","1"],["64847","0.00018027","0","3"],["64847.1","2.27866242","0","1"],["64847.2","0.00001551","0","1"],["64847.3","0.00165447","0","2"],["64847.5","0.01028872","0","4"],["64847.7","0.000067","0","1"],["64847.8","0.00009931","0","2"],["64848","0.00005632","0","1"],["64848.1","0.00001064","0","1"],["64848.3","0.00001","0","1"],["64848.4","0.00031285","0","3"],["64848.5","0.02397734","0","1"],["64848.6","0.00042647","0","1"],["64848.7","0.0001431","0","3"],["64848.8","0.16714387","0","1"],["64849","0.00002086","0","1"],["64849.1","0.18562061","0","4"],["64849.2","0.0006396","0","2"],["64849.3","0.0016175","0","3"],["64849.5","0.32940245","0","2"],["64849.8","0.9740945","0","1"],["64849.9","3.68013795","0","2"],["64850","12.93092141","0","16"],["64850.2","0.00044996","0","8"],["64850.4","0.06171882","0","1"],["64850.7","0.236386","0","7"],["64850.8","0.00848823","0","3"],["64850.9","0.00004112","0","2"],["64851","0.00047141","0","6"],["64851.4","0.00004039","0","2"],["64851.6","0.0001525","0","3"],["64851.9","0.00013177","0","4"],["64852.1","0.00001551","0","1"],["64852.5","0.00016958","0","1"],["64852.8","0.00001592","0","1"],["64852.9","0.00456828","0","2"],["64853.1","0.00002809","0","1"],["64853.2","0.00001094","0","1"],["64853.5","0.00001048","0","1"],["64853.6","0.41983606","0","2"],["64853.7","0.31957429","0","2"],["64853.8","0.01","0","1"],["64854.1","0.000414","0","3"],["64854.2","0.03482706","0","2"],["64854.3","0.02407529","0","5"],["64854.4","1.53177369","0","3"],["64854.5","0.00001019","0","1"],["64854.6","0.00001551","0","1"],["64854.7","0.00512693","0","3"],["64854.8","0.00001861","0","1"],["64855.1","0.00002527","0","1"],["64855.2","0.00023","0","1"],["64855.3","0.0002103","0","3"],["64855.5","0.00005572","0","2"],["64855.6","0.18452021","0","2"],["64855.7","0.44583","0","1"],["64855.9","0.00001096","0","1"],["64856","0.00276496","0","4"],["64856.1","0.00002325","0","1"],["64856.8","0.0013547","0","1"],["64856.9","0.01162717","0","1"],["64857.1","0.01530841","0","18"],["64857.2","0.0000215","0","1"],["64857.5","0.02397734","0","1"],["64857.6","1.28369153","0","4"],["64857.7","0.00001005","0","1"],["64857.8","0.0000302","0","1"],["64858.1","0.00005595","0","3"],["64858.9","0.02159334","0","1"],["64859","0.07052559","0","1"],["64859.1","0.00042426","0","1"],["64859.3","0.00023","0","1"],["64859.4","0.00046015","0","1"],["64859.5","0.00002119","0","1"],["64859.6","0.00048789","0","6"],["64859.7","0.00001551","0","1"],["64859.8","0.00006052","0","1"],["64860","0.00001706","0","1"],["64860.7","0.00008722","0","1"],["64860.8","0.0000101","0","1"],["64860.9","0.00001","0","1"],["64861.3","0.26813834","0","1"],["64861.4","0.46252521","0","1"],["64861.7","0.21728703","0","1"],["64861.9","0.00005823","0","2"],["64862.1","0.1845","0","1"],["64862.2","0.00001551","0","1"],["64862.3","0.009261","0","1"],["64862.4","0.00014125","0","2"],["64862.6","0.02326085","0","1"],["64862.7","0.00001223","0","1"],["64863","0.00001067","0","1"],["64863.1","0.00073079","0","1"],["64863.2","0.00019409","0","2"],["64863.3","0.00002115","0","2"],["64863.4","0.00023","0","1"],["64863.6","0.00002779","0","1"],["64864","0.00001009","0","1"],["64864.1","0.00003853","0","1"],["64864.2","0.02716541","0","2"],["64864.3","0.45651441","0","4"],["64864.4","0.9740945","0","1"],["64864.5","0.31683429","0","2"],["64864.6","0.00001501","0","1"],["64864.7","0.0000155","0","1"],["64864.8","0.00397954","0","4"],["64865.3","0.00011061","0","1"],["64865.6","0.00001748","0","1"],["64865.8","0.00016366","0","2"],["64865.9","0.00012261","0","1"],["64866.1","0.00001551","0","1"],["64866.2","0.01982816","0","1"],["64866.5","0.00075443","0","2"],["64866.6","0.00455955","0","5"],["64867.4","1.10105077","0","1"],["64867.5","0.9740945","0","1"],["64867.6","0.00023","0","1"],["64867.9","0.00131787","0","3"],["64868.1","0.00001083","0","1"],["64868.5","0.00001065","0","1"],["64868.6","0.18533349","0","2"],["64868.9","0.00002831","0","1"],["64869","0.00001402","0","1"],["64869.5","0.00006619","0","3"],["64869.6","2.68778334","0","2"],["64869.8","0.0000155","0","1"],["64869.9","0.00037501","0","1"],["64870","0.0003556","0","2"],["64870.1","0.02332256","0","2"],["64870.2","0.00015442","0","1"],["64870.5","0.00055245","0","1"],["64870.6","0.7466642","0","10"],["64870.7","0.9740945","0","1"],["64870.8","0.00004001","0","1"],["64870.9","0.00012837","0","1"],["64871","0.00002917","0","1"],["64871.1","0.00001501","0","1"],["64871.3","0.00004978","0","2"],["64871.6","0.30957429","0","1"],["64871.7","0.00023","0","1"],["64871.8","1.19362","0","1"],["64872.3","0.00006661","0","4"],["64872.4","0.0000155","0","1"],["64872.8","0.00002488","0","2"],["64873","0.00003106","0","1"],["64873.3","0.00009051","0","2"],["64873.4","0.00030603","0","2"],["64873.5","0.00002796","0","1"],["64873.7","1.21607","0","2"],["64874.1","0.00037256","0","1"],["64874.2","0.00054768","0","3"],["64874.3","0.0035841","0","2"],["64874.5","0.00003128","0","2"],["64874.6","0.00004904","0","2"],["64874.7","0.00001702","0","1"],["64874.9","0.00015668","0","2"],["64875","0.03772279","0","22"],["64875.1","0.1845","0","1"],["64875.3","0.9740945","0","1"],["64875.6","0.00129878","0","1"],["64875.9","0.00073126","0","3"],["64876","0.84684639","0","2"],["64876.1","0.00099998","0","2"],["64876.4","0.30871504","0","1"],["64876.6","0.00006565","0","2"],["64876.9","0.00001004","0","1"],["64877","0.00070486","0","1"],["64877.2","0.33328122","0","6"],["64877.4","0.0000155","0","1"],["64877.5","0.00199665","0","2"],["64877.6","0.00004213","0","2"],["64877.7","0.02397734","0","1"],["64878","0.00003178","0","1"],["64878.3","0.00031995","0","4"],["64878.5","0.00001023","0","1"],["64878.6","0.00005037","0","1"],["64878.7","0.00005197","0","3"],["64878.9","0.00001079","0","1"],["64879","0.00015756","0","2"],["64879.1","0.0017064","0","2"],["64879.2","0.00003344","0","2"],["64879.3","0.00032704","0","1"],["64879.4","0.00046015","0","1"],["64879.5","0.00004797","0","2"],["64879.8","0.00028037","0","2"],["64879.9","0.0000155","0","1"],["64880","0.00887324","0","13"],["64880.1","0.00002173","0","2"],["64880.3","0.00005628","0","1"],["64880.4","0.00070667","0","1"],["64881.2","0.00039484","0","1"],["64881.3","0.00003359","0","1"],["64881.4","0.000015","0","1"],["64881.6","0.18451296","0","2"],["64881.8","0.00121246","0","1"],["64882.2","0.00004815","0","1"],["64882.3","0.0010052","0","2"],["64882.4","0.0000155","0","1"],["64882.5","0.00002698","0","2"],["64882.6","0.00117136","0","4"],["64882.9","0.00078117","0","2"],["64883.1","0.9740945","0","1"],["64883.3","0.00192758","0","1"],["64883.4","0.07138138","0","1"],["64883.5","0.00002895","0","1"],["64883.6","0.00028189","0","3"],["64883.7","0.00005115","0","4"],["64883.8","0.02810372","0","3"],["64883.9","0.00010238","0","5"],["64884.1","0.00002537","0","2"],["64884.2","0.00024072","0","2"],["64884.5","0.00007803","0","2"],["64884.7","0.00002939","0","2"],["64884.9","0.00009304","0","3"],["64885","0.00074251","0","1"],["64885.2","0.00020697","0","4"],["64885.4","0.00001034","0","1"],["64885.7","0.31191134","0","4"],["64886.1","0.00001196","0","1"],["64886.3","0.00001829","0","1"],["64886.6","0.97412388","0","2"],["64886.7","0.00001005","0","1"],["64886.8","0.00015438","0","1"],["64886.9","0.00285576","0","1"],["64887.4","0.00001028","0","1"],["64887.5","0.00205108","0","3"],["64887.7","0.00044813","0","1"],["64888","0.00677942","0","2"],["64888.1","0.18455375","0","2"],["64888.2","0.00061815","0","4"],["64888.3","0.00023","0","1"],["64888.6","0.00005105","0","1"],["64888.8","0.00062349","0","8"],["64889","0.00009779","0","3"],["64889.1","0.02327181","0","2"],["64889.2","0.00007264","0","2"],["64889.6","0.00002974","0","1"],["64889.7","0.00035633","0","1"],["64889.8","0.00003849","0","1"],["64889.9","0.00015683","0","2"],["64890","0.00002282","0","1"],["64890.1","0.00007341","0","2"],["64890.4","0.00007691","0","3"],["64890.5","0.00005688","0","3"],["64890.6","0.30958929","0","2"],["64890.9","0.00042812","0","3"],["64891.3","0.00026946","0","1"],["64891.8","0.00247216","0","3"],["64891.9","0.0002304","0","4"],["64892","0.00001054","0","1"],["64892.2","0.0002","0","1"],["64892.3","0.00001555","0","1"],["64892.5","0.00024002","0","2"],["64892.6","0.9740945","0","1"],["64892.7","0.00015859","0","1"],["64892.8","0.00027302","0","1"],["64892.9","0.00061268","0","3"],["64893","0.0003369","0","1"],["64893.1","0.00015437","0","1"],["64893.2","0.00004205","0","2"],["64893.5","0.0000566","0","2"],["64893.6","0.00541947","0","2"],["64893.7","0.00047336","0","1"],["64893.8","0.02394468","0","4"],["64893.9","0.00039106","0","1"],["64894.2","0.00001129","0","1"],["64894.4","0.00001614","0","1"],["64894.5","0.00002284","0","1"],["64894.6","0.1845","0","1"],["64894.7","0.0000204","0","1"],["64894.9","0.00006105","0","2"],["64895","0.00003489","0","1"],["64895.1","0.00197953","0","2"],["64895.2","0.00022768","0","2"],["64895.9","0.00004867","0","3"],["64896","0.30957429","0","1"],["64896.2","0.0000406","0","2"],["64896.4","0.0232709","0","2"],["64896.5","0.00004548","0","3"],["64896.6","0.00044763","0","2"],["64896.8","0.0030818","0","2"],["64896.9","0.0001544","0","2"],["64897","0.00943195","0","2"],["64897.1","0.00003827","0","2"],["64897.2","0.00004333","0","1"],["64897.4","0.9740945","0","1"],["64897.6","0.0000513","0","1"],["64897.7","0.00001825","0","1"],["64897.8","0.00002843","0","1"],["64897.9","3.72065341","0","4"],["64898.1","0.00024783","0","1"],["64898.7","0.00027156","0","3"],["64898.9","0.00002074","0","1"],["64899.4","0.00046015","0","1"],["64899.5","0.00003677","0","2"],["64899.6","0.00004314","0","1"],["64899.7","0.00001573","0","1"],["64899.9","0.00198526","0","8"],["64900","5.68871255","0","46"],["64900.1","0.0000155","0","1"],["64900.5","0.00009333","0","1"],["64900.6","0.00001732","0","1"],["64900.7","0.00310352","0","2"],["64900.8","0.00023","0","1"],["64901.1","0.18465019","0","5"],["64901.3","0.00029999","0","1"],["64901.6","0.9740945","0","1"],["64901.8","0.00003328","0","1"],["64901.9","0.3096654","0","3"],["64902.5","0.0000415","0","1"],["64902.8","0.00002164","0","1"],["64903.1","0.00002503","0","1"],["64903.2","0.32881826","0","6"]],"bids":[["64810","1.39912667","0","10"],["64809.9","0.1057247","0","2"],["64809.8","0.01811294","0","2"],["64809.5","0.01695023","0","1"],["64809.3","0.28565411","0","2"],["64809.2","0.0000155","0","1"],["64808.6","0.21401927","0","1"],["64808.3","0.35269715","0","3"],["64807.8","0.05560367","0","1"],["64807.7","0.07719877","0","1"],["64807.6","0.12420109","0","2"],["64807","0.12412677","0","1"],["64806.9","0.19664319","0","2"],["64806.7","0.0000155","0","1"],["64806.6","0.00116271","0","1"],["64806.4","0.37153543","0","1"],["64805.9","0.18346488","0","1"],["64805.4","0.26482798","0","1"],["64805.3","0.04621407","0","1"],["64805.2","0.00208352","0","2"],["64805","0.02315842","0","1"],["64804.4","0.00772084","0","1"],["64804.3","0.00001501","0","1"],["64804.1","0.0000155","0","1"],["64803.8","0.01982816","0","1"],["64803.7","0.08856","0","1"],["64803.5","0.42521294","0","2"],["64803.4","0.00116271","0","1"],["64803.2","0.30957429","0","1"],["64803.1","1.59452808","0","2"],["64803","2","0","1"],["64801.6","0.0000155","0","1"],["64800.2","0.00116271","0","1"],["64800","0.0001208","0","1"],["64799.8","0.00213689","0","1"],["64799.4","0.00046015","0","1"],["64799.1","0.0000155","0","1"],["64798.9","0.01543236","0","1"],["64798.3","0.6524861","0","1"],["64798.2","0.9740945","0","1"],["64797.8","0.000015","0","1"],["64797.2","0.02326085","0","1"],["64797.1","0.30957429","0","1"],["64797","0.75735635","0","5"],["64796.5","0.10963566","0","2"],["64796.4","0.17389","0","1"],["64796.1","0.09039751","0","1"],["64796","0.02848073","0","1"],["64795.7","0.06950979","0","2"],["64795.5","0.01982816","0","1"],["64794.7","0.13509784","0","1"],["64794","0.0000155","0","1"],["64793.5","0.04","0","1"],["64793.4","0.52436956","0","1"],["64793.3","0.9740945","0","1"],["64793.2","0.00116278","0","1"],["64792.8","0.30957429","0","1"],["64792.3","0.08","0","1"],["64791.6","0.24278413","0","1"],["64791.5","0.0000155","0","1"],["64791.3","0.00001501","0","1"],["64791","0.12035665","0","1"],["64790.9","0.12035646","0","1"],["64790.8","0.44647","0","1"],["64790.5","0.3002274","0","2"],["64790","0.00116271","0","1"],["64789.9","0.02326085","0","1"],["64789.3","0.57445177","0","1"],["64789.2","1.18471831","0","2"],["64789","0.40016895","0","4"],["64788.9","0.30957429","0","1"],["64788.6","0.01771196","0","1"],["64788.3","0.01","0","1"],["64788.2","0.01","0","1"],["64788.1","0.01","0","1"],["64787.7","0.06175611","0","1"],["64787.2","0.49212139","0","1"],["64786.8","0.00270571","0","2"],["64786.5","0.145684","0","2"],["64786.4","0.0000155","0","1"],["64786.1","0.59758244","0","1"],["64785.2","0.9740945","0","1"],["64785","0.30957429","0","1"],["64784.8","0.00001501","0","1"],["64784.7","0.00001501","0","1"],["64784.2","0.23142202","0","1"],["64784","0.18451","0","2"],["64783.9","0.00001551","0","1"],["64783.6","0.00116271","0","1"],["64783.4","0.02326085","0","1"],["64782.8","0.00004304","0","1"],["64782.7","0.00016297","0","4"],["64781.7","0.19299692","0","1"],["64781.5","0.0617213","0","1"],["64781.4","0.00001551","0","1"],["64781.2","0.38909384","0","1"],["64781.1","1.28366879","0","2"],["64780.8","0.01982816","0","1"],["64780.4","0.00116271","0","1"],["64780.2","0.06171882","0","1"],["64780","0.0220889","0","1"],["64779.9","0.001543","0","1"],["64779.4","0.00046015","0","1"],["64779.3","0.03596601","0","1"],["64778.9","0.00001551","0","1"],["64778.6","0.036","0","1"],["64778.5","0.4468","0","1"],["64778.3","0.00001501","0","1"],["64777.5","0.1845","0","1"],["64777.3","0.46896088","0","2"],["64777.2","0.310737","0","2"],["64777.1","0.9740945","0","1"],["64776.6","0.02521321","0","3"],["64776.3","0.00001551","0","1"],["64776.1","0.12344","0","1"],["64775.2","0.00029999","0","1"],["64775","0.0001208","0","1"],["64774.4","0.87024772","0","1"],["64774.3","0.9740945","0","1"],["64774","0.00116271","0","1"],["64773.8","0.00001551","0","1"],["64773.3","0.30957429","0","1"],["64772.7","0.036","0","1"],["64772.2","0.01982816","0","1"],["64771.9","1.333911","0","1"],["64771.8","0.000015","0","1"],["64771.5","0.01520004","0","1"],["64771.3","1.04840361","0","3"],["64771.2","0.46319047","0","1"],["64771","0.1845","0","1"],["64770.9","0.02825145","0","1"],["64770.8","0.00116271","0","1"],["64770","0.02326085","0","1"],["64769","0.30957429","0","1"],["64768.9","0.00136721","0","1"],["64768.8","0.25091151","0","2"],["64768.6","0.9740945","0","1"],["64767.8","0.6216018","0","2"],["64767.7","0.96349196","0","1"],["64767.6","0.00116271","0","1"],["64766.8","0.00049982","0","1"],["64766.2","0.00001549","0","1"],["64765.8","0.9740945","0","1"],["64765.6","0.00001549","0","1"],["64765.3","0.00001501","0","1"],["64765.1","0.30957429","0","1"],["64764.7","1.48455253","0","4"],["64764.6","0.44684","0","1"],["64764.5","0.1845","0","1"],["64764.4","0.44729603","0","2"],["64764","0.01982816","0","1"],["64763.7","0.0015","0","1"],["64763.6","1.20268","0","1"],["64762.4","0.9740945","0","1"],["64761.6","0.06916283","0","2"],["64761.2","0.00001549","0","1"],["64760.9","0.4076686","0","2"],["64760.8","0.30957429","0","1"],["64760.7","0.00177638","0","1"],["64760.6","0.00116278","0","1"],["64759.8","0.9740945","0","1"],["64759.4","0.00046015","0","1"],["64759.3","0.00001549","0","1"],["64758.8","0.00001501","0","1"],["64758.5","0.00069955","0","1"],["64758.2","0.00229106","0","1"],["64758","0.1845","0","1"],["64756.9","0.38331458","0","1"],["64756.8","0.9740945","0","1"],["64756.7","0.31002597","0","3"],["64756.1","0.00001549","0","1"],["64755.9","0.00382147","0","1"],["64755.8","0.30879508","0","1"],["64754.2","0.01982816","0","1"],["64753.6","0.00183704","0","2"],["64753.2","0.38317961","0","1"],["64753.1","0.9740945","0","1"],["64752.8","0.30957429","0","1"],["64752.5","0.00001501","0","1"],["64751.9","0.02326085","0","1"],["64751.8","0.35822522","0","1"],["64751.5","0.1845","0","1"],["64751.1","0.00001549","0","1"],["64750.5","0.9740945","0","1"],["64750.1","0.00029964","0","1"],["64750","0.0001308","0","2"],["64749.4","0.03596601","0","1"],["64749.3","0.00310214","0","1"],["64749.2","0.00707331","0","1"],["64748.8","0.45033529","0","1"],["64748.7","0.30957429","0","1"],["64748.6","0.00001549","0","1"],["64747.6","0.0013877","0","1"],["64747.5","0.9740945","0","1"],["64747.1","0.02532385","0","1"],["64746.7","0.0000155","0","1"],["64746.1","0.003086","0","1"],["64746","0.05084338","0","1"],["64745.8","0.00001501","0","1"],["64745.1","0.01971986","0","1"],["64745","0.1845","0","1"],["64744.9","1.12492134","0","2"],["64744.8","1.30847417","0","4"],["64743.5","0.0000155","0","1"],["64743.4","2.668998","0","1"],["64741.9","0.38923567","0","1"],["64741.8","0.9740945","0","1"],["64741","0.0000155","0","1"],["64740.4","0.0000155","0","1"],["64739.9","0.30957429","0","1"],["64739.8","0.01982816","0","1"],["64739.4","0.00046015","0","1"],["64739.3","0.00001501","0","1"],["64738.9","0.65596073","0","1"],["64738.5","1.1585945","0","2"],["64738","0.02326085","0","1"],["64736.9","1.19308","0","1"],["64735.9","0.0000155","0","1"],["64734.2","0.0000155","0","1"],["64733.8","0.38318424","0","1"],["64733.7","0.9740945","0","1"],["64733.4","0.00001552","0","1"],["64733","0.30957429","0","1"],["64732.8","0.000015","0","1"],["64732","0.1845","0","1"],["64731.5","0.02326085","0","1"],["64731.2","0.5833824","0","1"],["64731.1","0.9740945","0","1"],["64730.5","0.358099","0","1"],["64730.3","0.79576989","0","1"],["64728.8","0.01982816","0","1"],["64727.8","0.29972221","0","1"],["64727.7","0.9740945","0","1"],["64726.3","0.00001501","0","1"],["64726.2","0.0152","0","1"],["64725.8","0.30958981","0","2"],["64725.7","0.30953335","0","1"],["64725.5","0.1845","0","1"],["64725","0.00019704","0","2"],["64724.9","0.00079948","0","2"],["64724.7","0.03861078","0","1"],["64724.5","0.02326085","0","1"],["64723.5","0.00011951","0","1"],["64723.3","0.9740945","0","1"],["64720.8","0.00001552","0","1"],["64720.3","0.00001501","0","1"],["64719.8","0.000015","0","1"],["64719.4","0.00046015","0","1"],["64719.3","0.3942975","0","1"],["64719.2","0.9740945","0","1"],["64719","0.1845","0","1"],["64718.9","0.00001199","0","1"],["64718.6","0.0030903","0","2"],["64718.5","0.014","0","1"],["64718","0.30957429","0","1"],["64717.3","0.02326085","0","1"],["64716.7","1.41666279","0","2"],["64716.6","3.72","0","1"],["64716","0.01982816","0","1"],["64715.6","0.9740945","0","1"],["64715.1","0.32760407","0","2"],["64714.3","0.00015454","0","1"],["64713.3","0.00001501","0","1"],["64712.6","0.05512401","0","1"],["64712.5","0.1845","0","1"],["64711.2","0.00015454","0","1"],["64710.7","0.0000155","0","1"],["64710.3","0.39264241","0","1"],["64710.2","0.30957429","0","1"],["64710","0.9740945","0","1"],["64708.2","0.02327637","0","2"],["64707.2","0.00285748","0","1"],["64707.1","0.01982816","0","1"],["64706.8","0.000015","0","1"],["64706.1","0.135667","0","2"],["64706","0.49407429","0","2"],["64703.4","0.00013723","0","1"],["64702.7","0.75145908","0","1"],["64702.6","2.51743888","0","1"],["64700.3","0.00001501","0","1"],["64700","0.10162515","0","2"],["64699.9","0.31515725","0","2"],["64699.8","0.00099976","0","2"],["64699.5","0.1845","0","1"],["64699.4","0.00046015","0","1"],["64698.9","0.00001198","0","1"],["64698.4","0.00015456","0","1"],["64698.3","0.009261","0","1"],["64698.1","0.00002749","0","2"],["64698","0.02326085","0","1"],["64696.2","0.98444057","0","2"],["64696.1","8.02631","0","1"],["64695.7","8.04954","0","1"],["64695","0.00029121","0","1"],["64694.7","0.01982816","0","1"],["64694.6","0.00002107","0","1"],["64693.8","0.00001501","0","1"],["64693","0.1845","0","1"],["64692.1","0.30962221","0","5"],["64691.3","0.02341544","0","2"],["64691.1","0.03865","0","1"],["64690.3","0.00001197","0","1"],["64690.2","0.00001551","0","1"],["64689.7","0.11988673","0","1"],["64689.1","0.00001198","0","1"],["64688.6","0.00003272","0","1"],["64688.1","0.00001501","0","1"],["64688","0.00001553","0","1"],["64687.7","0.00015475","0","1"],["64687.5","0.00004557","0","2"],["64686.5","0.1845","0","1"],["64686.2","0.0001292","0","1"],["64685.9","0.001852","0","1"],["64684.9","0.01982816","0","1"],["64684.3","0.3117866","0","2"],["64684.2","0.02326085","0","1"],["64683.3","0.00001199","0","1"],["64683.1","0.00049999","0","1"],["64682.9","0.00001553","0","1"],["64681.8","0.00698677","0","3"],["64680.5","0.0005","0","1"],["64680","0.1845","0","1"],["64679.4","0.00046015","0","1"],["64678.5","0.01991033","0","2"],["64678.2","0.01430853","0","2"],["64678","0.05242543","0","1"],["64677","0.00001113","0","1"],["64676.5","0.30957429","0","1"],["64675.4","0.00001553","0","1"],["64675.3","0.02326085","0","1"],["64675","0.0001208","0","1"],["64674.7","0.00029999","0","1"],["64674.6","2.20435709","0","1"],["64674","0.00001767","0","1"],["64673.7","0.00802671","0","1"],["64673.5","0.1845","0","1"],["64673","0.00362413","0","1"],["64672.4","0.009259","0","1"],["64671","0.00006846","0","1"],["64670.5","0.00108","0","1"],["64670.3","0.00001553","0","1"],["64669.5","0.01982816","0","1"],["64669.3","0.00002707","0","1"],["64668.7","0.33283514","0","2"],["64668.4","0.00015465","0","1"],["64667.8","0.00001217","0","1"],["64667","0.1845","0","1"],["64666.6","0.00430897","0","17"],["64666.5","0.00001403","0","1"],["64666.4","0.00001994","0","1"],["64666.1","0.00015464","0","1"],["64665.8","0.00001845","0","1"],["64663.9","0.00327305","0","4"],["64663.1","0.02417262","0","1"],["64662.8","0.00001553","0","1"],["64662.5","0.0003938","0","1"],["64662.4","0.00001003","0","1"],["64662.3","0.11988673","0","1"],["64662.1","0.00079375","0","2"],["64661.9","0.00008853","0","1"],["64661.6","0.00001106","0","1"],["64661.2","0.00005232","0","2"],["64661","0.0000273","0","1"],["64660.9","0.30957429","0","1"],["64660.5","0.1845","0","1"],["64659.9","0.00087238","0","1"],["64659.8","0.02326085","0","1"],["64659.4","0.00046015","0","1"],["64657.7","0.00001553","0","1"],["64657.1","0.00010277","0","1"],["64656.5","14.65931324","0","1"],["64656.4","0.0212","0","1"],["64656.3","0.01982816","0","1"],["64655.8","0.00066777","0","1"],["64655.4","0.00170132","0","1"],["64654.6","0.00232002","0","1"],["64654","0.1845","0","1"],["64653.8","0.00059394","0","1"],["64653.4","0.00010672","0","1"],["64653.1","0.02326085","0","1"],["64652.2","0.00003209","0","1"],["64650.1","0.00001066","0","1"],["64650","0.00102068","0","4"],["64649.1","0.00019651","0","3"],["64648.2","0.00250903","0","2"],["64647.6","0.00001552","0","1"],["64647.4","0.00013146","0","1"],["64647","0.00085861","0","1"],["64646.2","0.03867","0","1"],["64646.1","0.00023319","0","1"],["64645.7","0.00001614","0","1"],["64645.5","0.0001547","0","1"],["64645.1","0.00001552","0","1"],["64645","0.0000101","0","1"],["64643.8","0.00003406","0","1"],["64643.2","0.04308901","0","2"],["64642.6","0.00086485","0","1"],["64642.4","0.00003657","0","2"],["64641.2","0.00119998","0","2"],["64641.1","0.11988673","0","1"]],"ts":"1784087933402","checksum":0,"seqId":78785100877,"prevSeqId":-1}]}
{"arg":{"channel":"books","instId":"BTC-USDT"},"action":"update","data":[{"asks":[],"bids":[["64803.8","0.14395493","0","2"],["64782.7","0.00011993","0","3"]],"ts":"1784087933602","checksum":0,"seqId":78785100893,"prevSeqId":78785100877}]}
{"arg":{"channel":"books","instId":"BTC-USDT"},"action":"update","data":[{"asks":[["64842.9","0.01","0","1"],["64847.5","0.00028872","0","3"],["64903.2","0","0","0"]],"bids":[["64799.1","0.02571133","0","2"]],"ts":"1784087933702","checksum":0,"seqId":78785100901,"prevSeqId":78785100893}]}
{"arg":{"channel":"books","instId":"BTC-USDT"},"action":"update","data":[{"asks":[["64814.9","0.11978136","0","1"],["64903.1","0","0","0"]],"bids":[["64803.8","0.01982816","0","1"]],"ts":"1784087933802","checksum":0,"seqId":78785100907,"prevSeqId":78785100901}]}
{"arg":{"channel":"books","instId":"BTC-USDT"},"action":"update","data":[{"asks":[],"bids":[["64806","0.26482501","0","1"],["64805.4","0","0","0"],["64799.1","0.0000155","0","1"]],"ts":"1784087933902","checksum":0,"seqId":78785100920,"prevSeqId":78785100907}]}
{"arg":{"channel":"books","instId":"BTC-USDT"},"action":"update","data":[{"asks":[["64851","0.00048278","0","7"]],"bids":[["64806","0","0","0"],["64805.4","0.26482796","0","1"],["64804.4","0","0","0"],["64803.9","0.00772084","0","1"],["64803.5","0.1845","0","1"],["64799.1","0.02571133","0","2"],["64797","0.99806929","0","6"],["64796.1","0","0","0"],["64795.8","0.09241271","0","1"]],"ts":"1784087934002","checksum":0,"seqId":78785100954,"prevSeqId":78785100920}]}
{"arg":{"channel":"books","instId":"BTC-USDT"},"action":"update","data":[{"asks":[],"bids":[["64805.4","0","0","0"],["64803.9","0.00772093","0","1"],["64803.8","0.28465614","0","2"],["64755.9","0","0","0"],["64641","0.1845","0","1"],["64640.8","0.00001428","0","1"]],"ts":"1784087934102","checksum":0,"seqId":78785100976,"prevSeqId":78785100954}]}
{"arg":{"channel":"books","instId":"BTC-USDT"},"action":"update","data":[{"asks":[],"bids":[["64799.1","0.0000155","0","1"],["64780","0.15263468","0","2"],["64755.9","0.0038215","0","1"],["64640.8","0","0","0"]],"ts":"1784087934202","checksum":0,"seqId":78785100987,"prevSeqId":78785100976}]}
{"arg":{"channel":"books","instId":"BTC-USDT"},"action":"update","data":[{"asks":[],"bids":[["64803.9","0.00772095","0","1"],["64782.7","0.00016297","0","4"]],"ts":"1784087934502","checksum":0,"seqId":78785101028,"prevSeqId":78785100987}]}
{"arg":{"channel":"books","instId":"BTC-USDT"},"action":"update","data":[{"asks":[["64810.1","0.18337398","0","4"]],"bids":[["64803.8","0.28465627","0","2"],["64799.1","0.02571133","0","2"]],"ts":"1784087934602","checksum":0,"seqId":78785101042,"prevSeqId":78785101028}]}
{"arg":{"channel":"books","instId":"BTC-USDT"},"action":"update","data":[{"asks":[],"bids":[["64805.4","0.26482795","0","1"],["64803.8","0.01982816","0","1"],["64641","0","0","0"]],"ts":"1784087934702","checksum":0,"seqId":78785101053,"prevSeqId":78785101042}]}
{"arg":{"channel":"books","instId":"BTC-USDT"},"action":"update","data":[{"asks":[["64810.1","0.18247398","0","3"]],"bids":[["64656.5","0","0","0"],["64641","0.1845","0","1"]],"ts":"1784087934802","checksum":0,"seqId":78785101065,"prevSeqId":78785101053}]}
{"arg":{"channel":"books","instId":"BTC-USDT"},"action":"update","data":[{"asks":[],"bids":[["64804.2","0.00772088","0","1"],["64803.9","0","0","0"],["64796.5","0.15154422","0","3"],["64796.1","0.12776236","0","1"],["64795.8","0","0","0"],["64656.6","14.82898319","0","1"],["64641","0","0","0"]],"ts":"1784087935002","checksum":0,"seqId":78785101086,"prevSeqId":78785101065}]}
{"arg":{"channel":"books","instId":"BTC-USDT"},"action":"update","data":[{"asks":[],"bids":[["64804.2","0","0","0"],["64803.9","0.00772088","0","1"],["64799.1","0.0000155","0","1"],["64796.1","0","0","0"],["64795.8","0.12742077","0","1"],["64654.6","0","0","0"],["64641","0.1845","0","1"]],"ts":"1784087935102","checksum":0,"seqId":78785101097,"prevSeqId":78785101086}]}
{"arg":{"channel":"books","instId":"BTC-USDT"},"action":"update","data":[{"asks":[],"bids":[["64799.1","0.02571133","0","2"]],"ts":"1784087935202","checksum":0,"seqId":78785101104,"prevSeqId":78785101097}]}
{"arg":{"channel":"books","instId":"BTC-USDT"},"action":"update","data":[{"asks":[],"bids":[["64799.1","0.0000155","0","1"]],"ts":"1784087935302","checksum":0,"seqId":78785101112,"prevSeqId":78785101104}]}
{"arg":{"channel":"books","instId":"BTC-USDT"},"action":"update","data":[{"asks":[["64814.9","0","0","0"],["64816.6","0.37662488","0","1"],["64903.1","0.00002503","0","1"]],"bids":[["64804.2","0.00772082","0","1"],["64803.9","0","0","0"],["64803.8","0.13703586","0","2"],["64799.1","0.02571133","0","2"],["64796.1","0.12714076","0","1"],["64795.8","0","0","0"],["64782.7","0.00008319","0","2"]],"ts":"1784087935402","checksum":0,"seqId":78785101127,"prevSeqId":78785101112}]}
{"arg":{"channel":"books","instId":"BTC-USDT"},"action":"update","data":[{"asks":[["64814.9","0.13865921","0","1"],["64903.1","0","0","0"]],"bids":[["64806.4","0.25858977","0","1"],["64806","0.26482402","0","1"],["64805.4","0","0","0"],["64803.8","0.14395493","0","2"],["64799.1","0.0000155","0","1"]],"ts":"1784087935602","checksum":0,"seqId":78785101148,"prevSeqId":78785101127}]}
{"arg":{"channel":"books","instId":"BTC-USDT"},"action":"update","data":[{"asks":[["64814.9","0","0","0"],["64857.6","1.28368016","0","3"],["64903.1","0.00002503","0","1"]],"bids":[["64806","0","0","0"],["64805.4","0.26482578","0","1"],["64782.8","0","0","0"],["64640.8","0.00001428","0","1"]],"ts":"1784087935702","checksum":0,"seqId":78785101159,"prevSeqId":78785101148}]}
{"arg":{"channel":"books","instId":"BTC-USDT"},"action":"update","data":[{"asks":[],"bids":[["64805.4","0.26482591","0","1"],["64799.1","0.02571133","0","2"],["64787.2","0","0","0"],["64767.8","0.38863074","0","1"],["64767.7","0","0","0"],["64640.3","0.00016308","0","4"],["64640","0.00438692","0","2"]],"ts":"1784087935802","checksum":0,"seqId":78785101171,"prevSeqId":78785101159}]}
{"arg":{"channel":"books","instId":"BTC-USDT"},"action":"update","data":[{"asks":[["64851","0.00049415","0","8"]],"bids":[["64807.1","0.02315827","0","1"],["64806.5","0.26482239","0","1"],["64805.4","0","0","0"],["64805","0","0","0"],["64787.2","0.4686682","0","1"],["64782.7","0.00012623","0","3"],["64767.8","1.33669354","0","2"],["64640","0","0","0"]],"ts":"1784087935902","checksum":0,"seqId":78785101185,"prevSeqId":78785101171}]}
{"arg":{"channel":"books","instId":"BTC-USDT"},"action":"update","data":[{"asks":[["64814.9","0.15221609","0","1"],["64903.1","0","0","0"]],"bids":[["64806.5","0","0","0"],["64806","0.26482441","0","1"],["64803.8","0.13829354","0","2"],["64799.1","0.0000155","0","1"],["64767.9","0.66668187","0","1"],["64767.8","0.9480628","0","1"],["64640.3","0","0","0"]],"ts":"1784087936002","checksum":0,"seqId":78785101199,"prevSeqId":78785101185}]}
{"arg":{"channel":"books","instId":"BTC-USDT"},"action":"update","data":[{"asks":[["64814.9","0","0","0"],["64903.1","0.00002503","0","1"]],"bids":[["64806.5","0.26482308","0","1"],["64806","0","0","0"],["64804.4","0.00772082","0","1"],["64804.2","0","0","0"],["64799.1","0.02571133","0","2"]],"ts":"1784087936102","checksum":0,"seqId":78785101211,"prevSeqId":78785101199}]}
{"arg":{"channel":"books","instId":"BTC-USDT"},"action":"update","data":[{"asks":[],"bids":[["64806.5","0","0","0"],["64806","0.26482462","0","1"],["64799.1","0.0000155","0","1"]],"ts":"1784087936202","checksum":0,"seqId":78785101224,"prevSeqId":78785101211}]}
{"arg":{"channel":"books","instId":"BTC-USDT"},"action":"update","data":[{"asks":[["64814.9","0.11824817","0","1"],["64903.1","0","0","0"]],"bids":[["64799.1","0.02571133","0","2"],["64655.4","0","0","0"],["64640.3","0.00016308","0","4"]],"ts":"1784087936302","checksum":0,"seqId":78785101235,"prevSeqId":78785101224}]}
{"arg":{"channel":"books","instId":"BTC-USDT"},"action":"update","data":[{"asks":[],"bids":[["64803.8","0.14395493","0","2"],["64799.1","0.0000155","0","1"]],"ts":"1784087936402","checksum":0,"seqId":78785101243,"prevSeqId":78785101235}]}
{"arg":{"channel":"books","instId":"BTC-USDT"},"action":"update","data":[{"asks":[["64814.9","0","0","0"],["64903.1","0.00002503","0","1"]],"bids":[["64806","0.26482348","0","1"],["64782.7","0.00016297","0","4"]],"ts":"1784087936502","checksum":0,"seqId":78785101253,"prevSeqId":78785101243}]}
{"arg":{"channel":"books","instId":"BTC-USDT"},"action":"update","data":[{"asks":[["64814.9","0.1441586","0","1"],["64816.6","0.56112488","0","2"],["64830.8","0","0","0"]],"bids":[["64806","0","0","0"],["64805.4","0.26482617","0","1"],["64804.4","0.00772081","0","1"],["64803.8","0.13325637","0","2"]],"ts":"1784087936602","checksum":0,"seqId":78785101273,"prevSeqId":78785101253}]}
{"arg":{"channel":"books","instId":"BTC-USDT"},"action":"update","data":[{"asks":[["64814.9","0","0","0"],["64816.6","0.37662488","0","1"],["64832.7","0.02397734","0","1"],["64877.7","0","0","0"],["64903.2","0.32881826","0","6"]],"bids":[["64807.1","0.28797918","0","2"],["64805.4","0","0","0"],["64640","0.00438692","0","2"]],"ts":"1784087936702","checksum":0,"seqId":78785101285,"prevSeqId":78785101273}]}
{"arg":{"channel":"books","instId":"BTC-USDT"},"action":"update","data":[{"asks":[],"bids":[["64807.1","0.02315827","0","1"],["64806.5","0.26482145","0","1"],["64663.1","0","0","0"]],"ts":"1784087936802","checksum":0,"seqId":78785101294,"prevSeqId":78785101285}]}
{"arg":{"channel":"books","instId":"BTC-USDT"},"action":"update","data":[{"asks":[],"bids":[["64799.1","0.02571085","0","2"],["64782.7","0.00008319","0","2"],["64680.1","0.02417206","0","1"],["64640","0","0","0"]],"ts":"1784087936902","checksum":0,"seqId":78785101303,"prevSeqId":78785101294}]}
{"arg":{"channel":"books","instId":"BTC-USDT"},"action":"update","data":[{"asks":[],"bids":[["64799.1","0.0000155","0","1"],["64680.1","0","0","0"],["64640","0.00438692","0","2"]],"ts":"1784087937002","checksum":0,"seqId":78785101309,"prevSeqId":78785101303}]}
{"arg":{"channel":"books","instId":"BTC-USDT"},"action":"update","data":[{"asks":[["64814.9","0.12122111","0","1"],["64903.2","0","0","0"]],"bids":[["64782.8","0.00004723","0","1"],["64640","0","0","0"]],"ts":"1784087937202","checksum":0,"seqId":78785101320,"prevSeqId":78785101309}]}
{"arg":{"channel":"books","instId":"BTC-USDT"},"action":"update","data":[{"asks":[],"bids":[["64807.7","0.07727399","0","2"],["64807.6","0.12412677","0","1"],["64803.8","0.14395493","0","2"],["64782.8","0.00009027","0","2"]],"ts":"1784087937302","checksum":0,"seqId":78785101332,"prevSeqId":78785101320}]}
{"arg":{"channel":"books","instId":"BTC-USDT"},"action":"update","data":[{"asks":[["64879.1","0.00001094","0","1"]],"bids":[["64799.1","0.02571085","0","2"]],"ts":"1784087937402","checksum":0,"seqId":78785101339,"prevSeqId":78785101332}]}
{"arg":{"channel":"books","instId":"BTC-USDT"},"action":"update","data":[{"asks":[],"bids":[["64806.5","0","0","0"],["64806","0.26482434","0","1"],["64803.8","0.01982816","0","1"]],"ts":"1784087937502","checksum":0,"seqId":78785101349,"prevSeqId":78785101339}]}
{"arg":{"channel":"books","instId":"BTC-USDT"},"action":"update","data":[{"asks":[["64814.9","0","0","0"],["64903.2","0.32881826","0","6"]],"bids":[["64803.8","0.14395493","0","2"],["64799.1","0.0000155","0","1"]],"ts":"1784087937602","checksum":0,"seqId":78785101357,"prevSeqId":78785101349}]}
{"arg":{"channel":"books","instId":"BTC-USDT"},"action":"update","data":[{"asks":[["64814.9","0.13464911","0","1"],["64816.6","0.56112488","0","2"],["64824.5","0.1245","0","2"],["64830.6","0.0771715","0","1"],["64835.8","0","0","0"],["64843.6","0.13505012","0","1"],["64848.8","0","0","0"],["64856.6","0.19292875","0","1"],["64861.7","0","0","0"],["64869.5","0.25087356","0","4"],["64876.4","0","0","0"],["64882.5","0.30871298","0","3"]],"bids":[["64803.8","0.01982816","0","1"]],"ts":"1784087937702","checksum":0,"seqId":78785101375,"prevSeqId":78785101357}]}
{"arg":{"channel":"books","instId":"BTC-USDT"},"action":"update","data":[{"asks":[["64837.8","0.02283297","0","2"],["64842.9","0","0","0"],["64903.3","0.0003883","0","1"]],"bids":[["64799.1","0.02571085","0","2"],["64680.5","0","0","0"],["64640","0.00438692","0","2"]],"ts":"1784087937802","checksum":0,"seqId":78785101384,"prevSeqId":78785101375}]}
{"arg":{"channel":"books","instId":"BTC-USDT"},"action":"update","data":[{"asks":[["64824.7","0.07717852","0","1"],["64830.6","0","0","0"],["64837.7","0.13506241","0","1"],["64843.6","0","0","0"],["64850.7","0.4293323","0","8"],["64856.6","0","0","0"],["64863.6","0.25085798","0","2"],["64869.5","0.00006619","0","3"],["64876.6","0.30877973","0","3"],["64882.5","0.00002698","0","2"],["64903.4","0.00012365","0","1"]],"bids":[["64680.5","0.0005","0","1"],["64640","0","0","0"]],"ts":"1784087937902","checksum":0,"seqId":78785101401,"prevSeqId":78785101384}]}
{"arg":{"channel":"books","instId":"BTC-USDT"},"action":"update","data":[{"asks":[["64864.1","0","0","0"],["64903.6","0.000015","0","1"]],"bids":[["64799.1","0.0000155","0","1"]],"ts":"1784087938002","checksum":0,"seqId":78785101408,"prevSeqId":78785101401}]}
{"arg":{"channel":"books","instId":"BTC-USDT"},"action":"update","data":[{"asks":[],"bids":[["64806.5","0.2648224","0","1"],["64806","0","0","0"]],"ts":"1784087938102","checksum":0,"seqId":78785101416,"prevSeqId":78785101408}]}
{"arg":{"channel":"books","instId":"BTC-USDT"},"action":"update","data":[{"asks":[],"bids":[["64807","0.38894785","0","2"],["64806.5","0","0","0"],["64806.4","0.36232247","0","2"],["64804.4","0.00772072","0","1"],["64803.5","0.6659261","0","3"],["64799.1","0.02571085","0","2"],["64797","0.51664319","0","4"],["64640","0.00438692","0","2"]],"ts":"1784087938202","checksum":0,"seqId":78785101436,"prevSeqId":78785101416}]}
{"arg":{"channel":"books","instId":"BTC-USDT"},"action":"update","data":[{"asks":[["64814.9","0","0","0"],["64816.6","0.37662488","0","1"],["64903.8","0.00019404","0","4"]],"bids":[["64803.8","0.14141253","0","2"]],"ts":"1784087938302","checksum":0,"seqId":78785101445,"prevSeqId":78785101436}]}
{"arg":{"channel":"books","instId":"BTC-USDT"},"action":"update","data":[{"asks":[["64814.9","0.1352448","0","1"],["64903.8","0","0","0"]],"bids":[["64803.8","0.01982816","0","1"]],"ts":"1784087938402","checksum":0,"seqId":78785101451,"prevSeqId":78785101445}]}
{"arg":{"channel":"books","instId":"BTC-USDT"},"action":"update","data":[{"asks":[["64851","0.00050552","0","9"]],"bids":[["64799.1","0.0000155","0","1"]],"ts":"1784087938502","checksum":0,"seqId":78785101460,"prevSeqId":78785101451}]}
{"arg":{"channel":"books","instId":"BTC-USDT"},"action":"update","data":[{"asks":[["64816.6","0.56112488","0","2"]],"bids":[["64807","0.12412677","0","1"],["64806","0.26482344","0","1"],["64640","0","0","0"]],"ts":"1784087938602","checksum":0,"seqId":78785101469,"prevSeqId":78785101460}]}
{"arg":{"channel":"books","instId":"BTC-USDT"},"action":"update","data":[{"asks":[],"bids":[["64806","0","0","0"],["64805.4","0.26482548","0","1"],["64799.1","0.02571085","0","2"],["64782.8","0.00004723","0","1"]],"ts":"1784087938702","checksum":0,"seqId":78785101478,"prevSeqId":78785101469}]}
{"arg":{"channel":"books","instId":"BTC-USDT"},"action":"update","data":[{"asks":[["64812.2","0","0","0"],["64826.4","0.02315841","0","1"],["64828.2","0","0","0"],["64903.8","0.00019404","0","4"]],"bids":[["64807.7","0.00007522","0","1"],["64805.4","0","0","0"],["64804.5","0.07720258","0","1"],["64804.4","0","0","0"],["64804.2","0.00772093","0","1"],["64803.9","0.12412677","0","1"],["64803.8","0.28466114","0","2"],["64803.5","0.1845","0","1"],["64799.1","0.0000155","0","1"],["64797","0.99806929","0","6"],["64794.7","0","0","0"],["64791.5","0.13512001","0","2"],["64781.7","0","0","0"],["64778.5","0.63980645","0","2"],["64768.8","0.00001551","0","1"],["64765.6","0.25092387","0","2"],["64640","0.00438692","0","2"]],"ts":"1784087938802","checksum":0,"seqId":78785101510,"prevSeqId":78785101478}]}
{"arg":{"channel":"books","instId":"BTC-USDT"},"action":"update","data":[{"asks":[["64812.5","0.1201922","0","1"],["64903.8","0","0","0"]],"bids":[["64807.7","0","0","0"],["64807.6","0.12420236","0","2"],["64804.2","0","0","0"],["64803.9","0.00772095","0","1"],["64803.8","0.28466004","0","2"],["64799.1","0.02571085","0","2"],["64796.1","0","0","0"],["64795.8","0.14204805","0","1"],["64793.4","0.74791351","0","2"],["64639.8","0.00045864","0","3"],["64639.4","0.00046015","0","1"]],"ts":"1784087938902","checksum":0,"seqId":78785101541,"prevSeqId":78785101510}]}
{"arg":{"channel":"books","instId":"BTC-USDT"},"action":"update","data":[{"asks":[],"bids":[["64799.1","0.0000155","0","1"],["64782.8","0.00008397","0","2"]],"ts":"1784087939002","checksum":0,"seqId":78785101548,"prevSeqId":78785101541}]}
{"arg":{"channel":"books","instId":"BTC-USDT"},"action":"update","data":[{"asks":[],"bids":[["64804.6","0.26482992","0","1"],["64803.8","0.01982816","0","1"],["64639.4","0","0","0"]],"ts":"1784087939102","checksum":0,"seqId":78785101554,"prevSeqId":78785101548}]}
{"arg":{"channel":"books","instId":"BTC-USDT"},"action":"update","data":[{"asks":[],"bids":[["64782.7","0.00004645","0","1"]],"ts":"1784087939302","checksum":0,"seqId":78785101566,"prevSeqId":78785101554}]}
{"arg":{"channel":"books","instId":"BTC-USDT"},"action":"update","data":[{"asks":[],"bids":[["64782.8","0.00012071","0","3"]],"ts":"1784087939402","checksum":0,"seqId":78785101573,"prevSeqId":78785101566}]}
{"arg":{"channel":"books","instId":"BTC-USDT"},"action":"update","data":[{"asks":[["64812.5","0","0","0"],["64903.8","0.00019404","0","4"]],"bids":[["64799.1","0.02571085","0","2"],["64782.8","0.00016375","0","4"]],"ts":"1784087939502","checksum":0,"seqId":78785101581,"prevSeqId":78785101573}]}
{"arg":{"channel":"books","instId":"BTC-USDT"},"action":"update","data":[{"asks":[],"bids":[["64799.1","0.0000155","0","1"],["64795.8","0.14761871","0","1"]],"ts":"1784087939602","checksum":0,"seqId":78785101596,"prevSeqId":78785101581}]}
{"arg":{"channel":"books","instId":"BTC-USDT"},"action":"update","data":[{"asks":[],"bids":[["64799.1","0.02571085","0","2"]],"ts":"1784087939702","checksum":0,"seqId":78785101601,"prevSeqId":78785101596}]}
{"arg":{"channel":"books","instId":"BTC-USDT"},"action":"update","data":[{"asks":[],"bids":[["64799.1","0.0000155","0","1"],["64796.1","0.1544123","0","1"],["64795.8","0","0","0"],["64782.8","0.00012701","0","3"]],"ts":"1784087939802","checksum":0,"seqId":78785101609,"prevSeqId":78785101601}]}
{"arg":{"channel":"books","instId":"BTC-USDT"},"action":"update","data":[{"asks":[],"bids":[["64804.6","0","0","0"],["64803.8","0.28466018","0","2"],["64799.1","0.02571085","0","2"],["64639.4","0.00046015","0","1"]],"ts":"1784087939902","checksum":0,"seqId":78785101620,"prevSeqId":78785101609}]}
{"arg":{"channel":"books","instId":"BTC-USDT"},"action":"update","data":[{"asks":[],"bids":[["64804.6","0.26482899","0","1"],["64803.8","0.01982816","0","1"],["64799.1","0.0000155","0","1"],["64782.8","0.00008397","0","2"],["64639.4","0","0","0"]],"ts":"1784087940002","checksum":0,"seqId":78785101633,"prevSeqId":78785101620}]}
{"arg":{"channel":"books","instId":"BTC-USDT"},"action":"update","data":[{"asks":[],"bids":[["64804.2","0.00772095","0","1"],["64803.9","0","0","0"],["64690.3","0.02418463","0","2"]],"ts":"1784087940102","checksum":0,"seqId":78785101651,"prevSeqId":78785101633}]}
{"arg":{"channel":"books","instId":"BTC-USDT"},"action":"update","data":[{"asks":[["64810.1","0.18337398","0","4"]],"bids":[["64804.6","0","0","0"],["64803.8","0.28465936","0","2"],["64799.1","0.02571085","0","2"],["64639.4","0.00046015","0","1"]],"ts":"1784087940202","checksum":0,"seqId":78785101660,"prevSeqId":78785101651}]}
{"arg":{"channel":"books","instId":"BTC-USDT"},"action":"update","data":[{"asks":[["64833.5","0.04639905","0","2"]],"bids":[["64804.4","0.00772107","0","1"],["64804.2","0","0","0"]],"ts":"1784087940302","checksum":0,"seqId":78785101673,"prevSeqId":78785101660}]}
{"arg":{"channel":"books","instId":"BTC-USDT"},"action":"update","data":[{"asks":[["64810.1","0.18247398","0","3"],["64810.9","0.00025526","0","2"]],"bids":[["64809.1","0.00001132","0","1"],["64799.1","0.0000155","0","1"],["64787.2","0","0","0"],["64767.8","0","0","0"],["64639.1","0.00034809","0","1"]],"ts":"1784087940402","checksum":0,"seqId":78785101683,"prevSeqId":78785101673}]}
{"arg":{"channel":"books","instId":"BTC-USDT"},"action":"update","data":[{"asks":[],"bids":[["64767.9","0.45858128","0","1"]],"ts":"1784087940502","checksum":0,"seqId":78785101691,"prevSeqId":78785101683}]}
{"arg":{"channel":"books","instId":"BTC-USDT"},"action":"update","data":[{"asks":[],"bids":[["64804.4","0","0","0"],["64804.2","0.00772112","0","1"],["64786.5","0.61179044","0","3"],["64782.8","0.00004723","0","1"],["64767","0.90672775","0","1"],["64639.1","0","0","0"]],"ts":"1784087940602","checksum":0,"seqId":78785101703,"prevSeqId":78785101691}]}
{"arg":{"channel":"books","instId":"BTC-USDT"},"action":"update","data":[{"asks":[],"bids":[["64804.4","0.00772112","0","1"],["64804.2","0","0","0"],["64799.1","0.02571085","0","2"]],"ts":"1784087940702","checksum":0,"seqId":78785101711,"prevSeqId":78785101703}]}
{"arg":{"channel":"books","instId":"BTC-USDT"},"action":"update","data":[{"asks":[],"bids":[["64799.1","0.0000155","0","1"]],"ts":"1784087940802","checksum":0,"seqId":78785101717,"prevSeqId":78785101711}]}
{"arg":{"channel":"books","instId":"BTC-USDT"},"action":"update","data":[{"asks":[],"bids":[["64799.1","0.02571085","0","2"]],"ts":"1784087940902","checksum":0,"seqId":78785101722,"prevSeqId":78785101717}]}
{"arg":{"channel":"books","instId":"BTC-USDT"},"action":"update","data":[{"asks":[["64810.1","0.18337398","0","4"],["64812.5","0.11083264","0","1"],["64903.8","0","0","0"]],"bids":[["64810","1.39885968","0","9"]],"ts":"1784087941002","checksum":0,"seqId":78785101731,"prevSeqId":78785101722}]}
{"arg":{"channel":"books","instId":"BTC-USDT"},"action":"update","data":[{"asks":[["64810.1","1.535882","0","9"],["64812.4","0.03308354","0","1"],["64819.3","0.30957429","0","1"],["64821.2","0.15441128","0","1"],["64823.1","0.7019261","0","4"],["64825.7","0","0","0"],["64826.4","0","0","0"],["64836.1","0.1845","0","1"],["64892.9","0.00369468","0","5"],["64896.8","0","0","0"]],"bids":[["64810","0.40597968","0","6"],["64807.8","0","0","0"],["64807.6","0.00007559","0","1"],["64807.1","0","0","0"],["64807","0","0","0"],["64805.9","0","0","0"],["64804.4","0","0","0"],["64803.8","0.2648326","0","1"],["64803.2","0","0","0"],["64803.1","0.62043358","0","1"],["64803","0","0","0"],["64800.3","0.00772112","0","1"],["64799.8","0","0","0"],["64798.9","0","0","0"],["64798.4","0.9740945","0","1"],["64798.2","0","0","0"],["64797.2","0","0","0"],["64796.8","0.01543286","0","1"],["64796.1","0","0","0"],["64791.1","0.14074813","0","1"],["64765.2","0.22638084","0","1"],["64764.7","1.24972391","0","3"],["64718.6","0","0","0"],["64711.9","0.00309062","0","2"],["64639.1","0.00034809","0","1"],["64638.5","0.00002272","0","1"],["64637.9","0.00002665","0","1"],["64637.5","0.00001554","0","1"],["64636.9","0.00769914","0","1"],["64636.8","0.00001832","0","1"],["64636.3","0.00098767","0","4"]],"ts":"1784087941102","checksum":0,"seqId":78785101804,"prevSeqId":78785101731}]}
{"arg":{"channel":"books","instId":"BTC-USDT"},"action":"update","data":[{"asks":[["64810.1","1.59148567","0","10"],["64812.4","0","0","0"],["64812.5","0","0","0"],["64813.4","0.06517288","0","2"],["64814.9","0.16323774","0","1"],["64816","0.12412677","0","1"],["64816.1","0.79507953","0","1"],["64816.3","0.9740945","0","1"],["64816.4","0","0","0"],["64816.6","0.87655011","0","4"],["64816.9","0","0","0"],["64819.6","0.02316076","0","1"],["64819.8","0.15442503","0","1"],["64821.1","0.02326085","0","1"],["64821.2","0","0","0"],["64823.1","0.34085647","0","3"],["64830.1","0.01","0","1"],["64837.8","0.01283297","0","1"],["64903.3","0","0","0"],["64903.4","0","0","0"],["64903.6","0","0","0"]],"bids":[["64810","0.6677594","0","8"],["64809.3","0","0","0"],["64808.7","0.35236387","0","2"],["64806.4","0.11932639","0","1"],["64803.8","0.12412677","0","1"],["64803.1","0","0","0"],["64800.7","0.02316076","0","1"],["64800.5","0.11648895","0","1"],["64800.4","0.12412677","0","1"],["64800.3","0","0","0"],["64800.1","0.12412677","0","1"],["64800","0.26495827","0","2"],["64799.9","0.14600613","0","1"],["64799.1","0.0000155","0","1"],["64798.5","0.68571","0","1"],["64798.3","0","0","0"],["64797.9","0.00772133","0","1"],["64797","0.66708881","0","4"],["64796.6","0.02326085","0","1"],["64796.5","0.07859367","0","2"],["64796","0","0","0"],["64791.6","0","0","0"],["64791.1","0","0","0"],["64790.1","0.15442471","0","1"],["64786","0.2332598","0","1"],["64784.5","0.00213689","0","1"],["64784","0.51549048","0","4"],["64637.9","0","0","0"],["64637.5","0","0","0"],["64636.9","0","0","0"],["64636.8","0","0","0"],["64636.3","0","0","0"]],"ts":"1784087941202","checksum":0,"seqId":78785101916,"prevSeqId":78785101804}]}
{"arg":{"channel":"trades","instId":"BTC-USDT"},"data":[{"instId":"BTC-USDT","tradeId":"1033093064","px":"64810.1","sz":"0.01292707","side":"buy","ts":"1784087941234","count":"1","source":"0","seqId":78785101934}]}
{"arg":{"channel":"books","instId":"BTC-USDT"},"action":"update","data":[{"asks":[["64810.1","1.5785586","0","10"],["64812.4","0.0338523","0","1"],["64812.5","0.11340803","0","1"],["64813.4","0.10968937","0","1"],["64816.1","0.53643664","0","1"],["64816.6","0.63583717","0","3"],["64819.2","0.15444262","0","2"],["64819.8","0","0","0"],["64822.4","0.07718126","0","1"],["64823.1","0.58156941","0","4"],["64824.7","0","0","0"],["64832.4","1.06870626","0","2"],["64833","2","0","1"],["64833.5","0.01805347","0","1"],["64835.3","0.95704032","0","1"],["64835.4","0.1350672","0","1"],["64837.7","0","0","0"],["64838","0.21062381","0","1"],["64848.4","0.193266","0","4"],["64850.7","0.236386","0","7"],["64851.5","0.4625955","0","1"],["64861.3","0","0","0"],["64861.4","0","0","0"],["64862","0.14006981","0","1"],["64903.1","0","0","0"],["64903.2","0","0","0"]],"bids":[["64808.8","0.16678404","0","1"],["64808.7","0","0","0"],["64808.3","0.0226971","0","2"],["64807.6","0","0","0"],["64806.9","0.19671914","0","3"],["64805.2","0.12621029","0","3"],["64804.5","0","0","0"],["64802","0.18350564","0","1"],["64801.9","0.26484016","0","1"],["64801.8","0.0772058","0","1"],["64800.5","0","0","0"],["64800.4","0","0","0"],["64800.1","0","0","0"],["64800","0.0001208","0","1"],["64797.9","0","0","0"],["64797.2","0.00772127","0","1"],["64797","0.87771282","0","5"],["64795.7","0.09832143","0","3"],["64791.5","0.0000155","0","1"],["64790.1","0","0","0"],["64789.4","0.15442712","0","1"],["64788.8","0.13511015","0","1"],["64784","0.30486647","0","3"],["64778.5","0.4468","0","1"],["64775.8","0.1930145","0","1"],["64761.5","0.07420197","0","1"],["64755.8","0","0","0"],["64749.9","0.3088232","0","1"],["64638.5","0","0","0"]],"ts":"1784087941302","checksum":0,"seqId":78785101992,"prevSeqId":78785101916}]}
{"arg":{"channel":"books","instId":"BTC-USDT"},"action":"update","data":[{"asks":[["64812.4","0","0","0"],["64812.5","0","0","0"],["64819.6","0","0","0"],["64821.7","0.02317568","0","2"],["64824","0.01542638","0","1"],["64824.4","0","0","0"],["64844.9","2.28935629","0","1"],["64845.1","0.49007121","0","2"],["64847.1","0","0","0"],["64903.1","0.00002503","0","1"],["64903.2","0.32881826","0","6"],["64903.3","0.0003883","0","1"]],"bids":[["64808.9","0.12412677","0","1"],["64806.4","0.25363445","0","2"],["64805.3","0.37621407","0","2"],["64805.2","0.00208352","0","2"],["64803.8","0","0","0"],["64802.1","0.12412677","0","1"],["64802","0.69241514","0","2"],["64801","2","0","1"],["64798.4","0","0","0"],["64797.9","0.0077213","0","1"],["64797.2","0","0","0"],["64755.9","0","0","0"],["64754.3","0.00382152","0","1"],["64639.1","0","0","0"]],"ts":"1784087941402","checksum":0,"seqId":78785102040,"prevSeqId":78785101992}]}
{"arg":{"channel":"books","instId":"BTC-USDT"},"action":"update","data":[{"asks":[["64844.9","0","0","0"],["64847.1","2.28935629","0","1"]],"bids":[["64808.9","0","0","0"],["64808.8","0.09448082","0","2"],["64808.6","0","0","0"],["64807.6","0.12412677","0","1"],["64807","0.12412677","0","1"],["64801.1","0.30957429","0","1"],["64798.6","0.6058942","0","2"],["64798.5","0","0","0"],["64797.9","0","0","0"],["64797.2","0.9818158","0","2"],["64782.8","0","0","0"]],"ts":"1784087941502","checksum":0,"seqId":78785102076,"prevSeqId":78785102040}]}
{"arg":{"channel":"books","instId":"BTC-USDT"},"action":"update","data":[{"asks":[["64844.9","2.28935629","0","1"],["64847.1","0","0","0"]],"bids":[["64807.6","0.12420281","0","2"],["64806.9","0.19664319","0","2"],["64799.1","0.02571085","0","2"]],"ts":"1784087941602","checksum":0,"seqId":78785102085,"prevSeqId":78785102076}]}
{"arg":{"channel":"books","instId":"BTC-USDT"},"action":"update","data":[{"asks":[],"bids":[["64810","0.7240194","0","9"],["64804.3","0.32248558","0","2"],["64802.1","0","0","0"],["64797.9","0.00772131","0","1"],["64797.2","0.9740945","0","1"]],"ts":"1784087941702","checksum":0,"seqId":78785102096,"prevSeqId":78785102085}]}
{"arg":{"channel":"books","instId":"BTC-USDT"},"action":"update","data":[{"asks":[["64812.4","0.03705184","0","1"],["64812.5","0.12412677","0","1"],["64815.9","0.12412677","0","1"],["64816","0","0","0"],["64842.7","2.28915858","0","2"],["64844.9","0","0","0"],["64903.3","0","0","0"]],"bids":[["64807","0","0","0"],["64802.3","0.02316004","0","1"],["64801.9","0","0","0"],["64801.2","0.26484406","0","1"],["64800.7","0","0","0"],["64799.1","0.0000155","0","1"],["64797.9","0","0","0"],["64797.3","0.00772131","0","1"],["64782.8","0.00004304","0","1"]],"ts":"1784087941802","checksum":0,"seqId":78785102115,"prevSeqId":78785102096}]}
{"arg":{"channel":"books","instId":"BTC-USDT"},"action":"update","data":[{"asks":[["64812.4","0","0","0"],["64812.5","0","0","0"],["64813.4","0.08096975","0","1"],["64815.9","0","0","0"],["64816","0.12412677","0","1"],["64903.3","0.0003883","0","1"],["64903.4","0.00012365","0","1"]],"bids":[["64807.7","0.1096493","0","1"],["64807.6","0.00007604","0","1"],["64807","0.12412677","0","1"],["64800.8","0.05560367","0","1"],["64799.1","0.02571085","0","2"],["64797","0.66708881","0","4"],["64784","0.51549048","0","4"],["64640","0","0","0"],["64639.8","0","0","0"],["64639.4","0","0","0"]],"ts":"1784087941902","checksum":0,"seqId":78785102132,"prevSeqId":78785102115}]}
{"arg":{"channel":"books","instId":"BTC-USDT"},"action":"update","data":[{"asks":[["64813.4","0.03224328","0","1"],["64814.9","0","0","0"],["64903.6","0.000015","0","1"]],"bids":[["64807.7","0.10972543","0","2"],["64807.6","0","0","0"],["64804.4","0.12412677","0","1"]],"ts":"1784087942002","checksum":0,"seqId":78785102149,"prevSeqId":78785102132}]}
{"arg":{"channel":"books","instId":"BTC-USDT"},"action":"update","data":[{"asks":[["64813.4","0.06929512","0","1"],["64814.9","0.11015669","0","1"],["64819.2","0.0000155","0","1"],["64819.4","0.51356405","0","2"],["64903.6","0","0","0"]],"bids":[["64804.4","0","0","0"],["64801.9","0.26484142","0","1"],["64801.2","0","0","0"],["64797.9","0.00772132","0","1"],["64797.3","0","0","0"],["64790","0.15558936","0","2"],["64789.4","0","0","0"],["64640","0.00438692","0","2"],["64639.8","0.00045864","0","3"]],"ts":"1784087942102","checksum":0,"seqId":78785102180,"prevSeqId":78785102149}]}
{"arg":{"channel":"books","instId":"BTC-USDT"},"action":"update","data":[{"asks":[["64819.2","0.15444201","0","2"],["64819.4","0.3591374","0","1"]],"bids":[["64799.1","0.0000155","0","1"],["64797.9","0.00772133","0","1"],["64790","0.00116271","0","1"],["64789.4","0.15442651","0","1"],["64648","0.00232025","0","1"],["64640","0","0","0"],["64639.8","0","0","0"]],"ts":"1784087942202","checksum":0,"seqId":78785102201,"prevSeqId":78785102180}]}
{"arg":{"channel":"books","instId":"BTC-USDT"},"action":"update","data":[{"asks":[["64842.5","0.98828134","0","2"]],"bids":[["64801.9","0.26484222","0","1"],["64767.9","0.73818548","0","2"]],"ts":"1784087942402","checksum":0,"seqId":78785102224,"prevSeqId":78785102201}]}
{"arg":{"channel":"books","instId":"BTC-USDT"},"action":"update","data":[{"asks":[],"bids":[["64801.9","0","0","0"],["64801.2","0.26484222","0","1"]],"ts":"1784087942502","checksum":0,"seqId":78785102231,"prevSeqId":78785102224}]}
{"arg":{"channel":"books","instId":"BTC-USDT"},"action":"update","data":[{"asks":[["64812.4","0.03588683","0","1"],["64903.4","0","0","0"]],"bids":[["64799.1","0.02571182","0","2"],["64797.9","0","0","0"],["64797.3","0.00772134","0","1"],["64782.8","0.00008608","0","2"]],"ts":"1784087942602","checksum":0,"seqId":78785102243,"prevSeqId":78785102231}]}
{"arg":{"channel":"books","instId":"BTC-USDT"},"action":"update","data":[{"asks":[["64812.4","0","0","0"],["64903.4","0.00012365","0","1"]],"bids":[["64799.1","0.0000155","0","1"],["64797.9","0.00772136","0","1"],["64797.3","0","0","0"]],"ts":"1784087942702","checksum":0,"seqId":78785102254,"prevSeqId":78785102243}]}
{"arg":{"channel":"books","instId":"BTC-USDT"},"action":"update","data":[{"asks":[],"bids":[["64797.9","0","0","0"],["64797.3","0.00772135","0","1"]],"ts":"1784087942802","checksum":0,"seqId":78785102269,"prevSeqId":78785102254}]}
{"arg":{"channel":"books","instId":"BTC-USDT"},"action":"update","data":[{"asks":[],"bids":[["64797.9","0.00772138","0","1"],["64797.3","0","0","0"]],"ts":"1784087942902","checksum":0,"seqId":78785102275,"prevSeqId":78785102269}]}
{"arg":{"channel":"books","instId":"BTC-USDT"},"action":"update","data":[{"asks":[["64819.2","0.0000155","0","1"],["64819.3","0.46400096","0","2"]],"bids":[["64801.2","0","0","0"],["64800","0.26496712","0","2"],["64790.1","0.15442667","0","1"],["64789.4","0","0","0"],["64640","0.00438692","0","2"]],"ts":"1784087943002","checksum":0,"seqId":78785102290,"prevSeqId":78785102275}]}
{"arg":{"channel":"books","instId":"BTC-USDT"},"action":"update","data":[{"asks":[["64840.5","2.28778801","0","1"],["64842.5","0.33854325","0","1"],["64842.7","0.00023","0","1"],["64873.6","0.37791889","0","1"],["64903.3","0","0","0"],["64903.4","0","0","0"]],"bids":[["64799.1","0.02571182","0","2"]],"ts":"1784087943102","checksum":0,"seqId":78785102300,"prevSeqId":78785102290}]}
{"arg":{"channel":"trades","instId":"BTC-USDT"},"data":[{"instId":"BTC-USDT","tradeId":"1033093065","px":"64810.1","sz":"0.00908614","side":"buy","ts":"1784087943170","count":"1","source":"0","seqId":78785102311}]}
{"arg":{"channel":"books","instId":"BTC-USDT"},"action":"update","data":[{"asks":[["64810.1","1.56947246","0","10"],["64819.2","0.15444202","0","2"],["64819.3","0.30957429","0","1"]],"bids":[["64797","0.87771282","0","5"],["64790.1","0","0","0"],["64789.4","0.15442652","0","1"],["64784","0.30486647","0","3"],["64761.5","0.11762465","0","2"]],"ts":"1784087943202","checksum":0,"seqId":78785102315,"prevSeqId":78785102300}]}
{"arg":{"channel":"books","instId":"BTC-USDT"},"action":"update","data":[{"asks":[],"bids":[["64799.1","0.0000155","0","1"],["64790","0.15558935","0","2"],["64789.4","0","0","0"],["64639.8","0.00045864","0","3"]],"ts":"1784087943302","checksum":0,"seqId":78785102325,"prevSeqId":78785102315}]}
{"arg":{"channel":"books","instId":"BTC-USDT"},"action":"update","data":[{"asks":[["64816.6","0.39512401","0","2"],["64823.1","0.82228257","0","5"],["64838.6","0.83074259","0","4"]],"bids":[["64797","0.99806929","0","6"],["64790","0.00116271","0","1"],["64789.4","0.1544266","0","1"],["64784","0.18451","0","2"],["64639.8","0","0","0"]],"ts":"1784087943402","checksum":0,"seqId":78785102337,"prevSeqId":78785102325}]}
{"arg":{"channel":"books","instId":"BTC-USDT"},"action":"update","data":[{"asks":[],"bids":[["64797.9","0","0","0"],["64797.3","0.00772152","0","1"],["64782.8","0.00004304","0","1"]],"ts":"1784087943502","checksum":0,"seqId":78785102345,"prevSeqId":78785102337}]}
{"arg":{"channel":"books","instId":"BTC-USDT"},"action":"update","data":[{"asks":[],"bids":[["64800","0.2649697","0","2"],["64797.9","0.00772152","0","1"],["64797.3","0","0","0"]],"ts":"1784087943602","checksum":0,"seqId":78785102357,"prevSeqId":78785102345}]}
{"arg":{"channel":"books","instId":"BTC-USDT"},"action":"update","data":[{"asks":[],"bids":[["64655.8","0","0","0"],["64639.8","0.00045864","0","3"]],"ts":"1784087943702","checksum":0,"seqId":78785102363,"prevSeqId":78785102357}]}
{"arg":{"channel":"books","instId":"BTC-USDT"},"action":"update","data":[{"asks":[],"bids":[["64799.1","0.02571182","0","2"]],"ts":"1784087943802","checksum":0,"seqId":78785102369,"prevSeqId":78785102363}]}
{"arg":{"channel":"books","instId":"BTC-USDT"},"action":"update","data":[{"asks":[["64819.2","0.0000155","0","1"],["64819.4","0.51356376","0","2"],["64821.7","0.0000155","0","1"],["64823.5","0.02315945","0","1"],["64903.2","0","0","0"]],"bids":[["64804.3","0.34564503","0","3"],["64802.3","0","0","0"],["64797.9","0","0","0"],["64797.3","0.00772152","0","1"],["64790","0.15558931","0","2"],["64789.4","0","0","0"],["64639.4","0.00046015","0","1"],["64639.1","0.00034809","0","1"]],"ts":"1784087943902","checksum":0,"seqId":78785102386,"prevSeqId":78785102369}]}
{"arg":{"channel":"books","instId":"BTC-USDT"},"action":"update","data":[{"asks":[["64830.8","0.0290781","0","1"],["64903.1","0","0","0"]],"bids":[["64655.9","0.00066777","0","1"],["64639.1","0","0","0"]],"ts":"1784087944002","checksum":0,"seqId":78785102393,"prevSeqId":78785102386}]}
{"arg":{"channel":"books","instId":"BTC-USDT"},"action":"update","data":[{"asks":[["64819.3","0.46400032","0","2"],["64819.4","0.3591374","0","1"]],"bids":[["64797.9","0.00772152","0","1"],["64797.3","0","0","0"]],"ts":"1784087944102","checksum":0,"seqId":78785102403,"prevSeqId":78785102393}]}
{"arg":{"channel":"books","instId":"BTC-USDT"},"action":"update","data":[{"asks":[],"bids":[["64801","2.17204336","0","2"],["64800","0.0001208","0","1"],["64799.9","0","0","0"],["64799.1","0.0000155","0","1"],["64798.7","0.26484844","0","1"]],"ts":"1784087944202","checksum":0,"seqId":78785102424,"prevSeqId":78785102403}]}
{"arg":{"channel":"books","instId":"BTC-USDT"},"action":"update","data":[{"asks":[["64816","0.11606174","0","1"],["64819.3","0.30957429","0","1"],["64819.8","0.15442619","0","1"],["64902.8","0","0","0"]],"bids":[["64804.4","0.12412677","0","1"],["64639.4","0","0","0"]],"ts":"1784087944402","checksum":0,"seqId":78785102441,"prevSeqId":78785102424}]}
{"arg":{"channel":"books","instId":"BTC-USDT"},"action":"update","data":[{"asks":[],"bids":[["64799.1","0.02571182","0","2"],["64782.8","0.00007978","0","2"]],"ts":"1784087944502","checksum":0,"seqId":78785102447,"prevSeqId":78785102441}]}
{"arg":{"channel":"books","instId":"BTC-USDT"},"action":"update","data":[{"asks":[["64816.6","0.63583717","0","3"],["64819.2","0.15444169","0","2"],["64819.8","0","0","0"],["64821.5","0.02316015","0","1"],["64823.1","0.58156941","0","4"],["64823.5","0","0","0"],["64902.8","0.00002164","0","1"]],"bids":[["64804.4","0","0","0"],["64804.3","0.32248558","0","2"],["64802.3","0.02316015","0","1"],["64790","0.15558888","0","2"]],"ts":"1784087944602","checksum":0,"seqId":78785102471,"prevSeqId":78785102447}]}
{"arg":{"channel":"books","instId":"BTC-USDT"},"action":"update","data":[{"asks":[],"bids":[["64799.1","0.0000155","0","1"]],"ts":"1784087944702","checksum":0,"seqId":78785102477,"prevSeqId":78785102471}]}
{"arg":{"channel":"books","instId":"BTC-USDT"},"action":"update","data":[{"asks":[],"bids":[["64799.1","0.02571182","0","2"]],"ts":"1784087944902","checksum":0,"seqId":78785102487,"prevSeqId":78785102477}]}
{"arg":{"channel":"books","instId":"BTC-USDT"},"action":"update","data":[{"asks":[["64819.2","0.0000155","0","1"],["64819.3","0.46400044","0","2"]],"bids":[["64797.9","0.00772151","0","1"],["64786.5","0.145684","0","2"],["64767.9","0.45858128","0","1"],["64767","0","0","0"],["64639.4","0.00046015","0","1"]],"ts":"1784087945102","checksum":0,"seqId":78785102505,"prevSeqId":78785102487}]}
{"arg":{"channel":"books","instId":"BTC-USDT"},"action":"update","data":[{"asks":[["64819.3","0.4640005","0","2"]],"bids":[["64799.1","0.0000155","0","1"],["64790","0.15558892","0","2"],["64782.8","0.49255162","0","3"],["64763.4","0.98343851","0","1"],["64639.4","0","0","0"]],"ts":"1784087945202","checksum":0,"seqId":78785102521,"prevSeqId":78785102505}]}
{"arg":{"channel":"books","instId":"BTC-USDT"},"action":"update","data":[{"asks":[["64819.3","0.30957429","0","1"],["64819.8","0.15442623","0","1"],["64902.8","0","0","0"]],"bids":[["64800.9","0.26484631","0","1"],["64799.1","0.02571182","0","2"],["64798.7","0","0","0"]],"ts":"1784087945302","checksum":0,"seqId":78785102532,"prevSeqId":78785102521}]}
{"arg":{"channel":"books","instId":"BTC-USDT"},"action":"update","data":[{"asks":[["64819.3","0.46400039","0","2"],["64819.8","0","0","0"],["64838.6","0.14586655","0","3"],["64840.5","0","0","0"],["64844.8","1.17156091","0","1"],["64844.9","2.28308286","0","1"],["64845.1","0.00001501","0","1"]],"bids":[["64801.2","0.26484375","0","1"],["64800.9","0","0","0"]],"ts":"1784087945402","checksum":0,"seqId":78785102550,"prevSeqId":78785102532}]}
{"arg":{"channel":"books","instId":"BTC-USDT"},"action":"update","data":[{"asks":[["64819.2","0.15444175","0","2"],["64819.3","0.30957429","0","1"]],"bids":[["64790","0.00116271","0","1"],["64789.4","0.15442625","0","1"],["64782.8","0.49258836","0","4"],["64639.8","0","0","0"]],"ts":"1784087945502","checksum":0,"seqId":78785102560,"prevSeqId":78785102550}]}
{"arg":{"channel":"books","instId":"BTC-USDT"},"action":"update","data":[{"asks":[["64816.6","0.39512401","0","2"],["64823.1","0.82228257","0","5"]],"bids":[["64782.8","0.49259255","0","4"]],"ts":"1784087945602","checksum":0,"seqId":78785102569,"prevSeqId":78785102560}]}
{"arg":{"channel":"books","instId":"BTC-USDT"},"action":"update","data":[{"asks":[["64810.1","1.54129246","0","9"],["64814.9","0","0","0"],["64819.2","0.0000155","0","1"],["64819.8","0.15442625","0","1"],["64844.9","0","0","0"],["64851.5","0","0","0"],["64855.3","0.46277866","0","4"],["64902.8","0.00002164","0","1"],["64903.1","0.00002503","0","1"]],"bids":[["64804.4","0.12412677","0","1"],["64802.1","0.37684761","0","2"],["64801.2","0","0","0"],["64799.1","0.0000155","0","1"],["64790","0.15558897","0","2"],["64789.4","0","0","0"]],"ts":"1784087945802","checksum":0,"seqId":78785102595,"prevSeqId":78785102569}]}
{"arg":{"channel":"books","instId":"BTC-USDT"},"action":"update","data":[{"asks":[["64815.9","0.11781164","0","1"],["64816","0","0","0"],["64842.7","2.28331286","0","2"],["64844.8","0","0","0"],["64873.6","0.86797509","0","2"],["64903.2","0.32881826","0","6"]],"bids":[["64802.1","0.26484133","0","1"],["64799.1","0.02571182","0","2"]],"ts":"1784087945902","checksum":0,"seqId":78785102608,"prevSeqId":78785102595}]}
{"arg":{"channel":"books","instId":"BTC-USDT"},"action":"update","data":[{"asks":[],"bids":[["64799.1","0.0000155","0","1"],["64782.8","0.49250858","0","2"]],"ts":"1784087946002","checksum":0,"seqId":78785102619,"prevSeqId":78785102608}]}
{"arg":{"channel":"books","instId":"BTC-USDT"},"action":"update","data":[{"asks":[["64813.4","0.10467099","0","2"],["64814.9","0.15450645","0","1"],["64819.2","0.15444149","0","2"],["64819.8","0","0","0"]],"bids":[["64804.4","0","0","0"],["64802.1","0","0","0"],["64801.2","0.26484333","0","1"],["64799.1","0.02571182","0","2"],["64797.9","0","0","0"],["64797.3","0.00772132","0","1"],["64790","0.00116271","0","1"],["64789.4","0.15442599","0","1"],["64714.3","0.00324504","0","3"],["64711.9","0","0","0"],["64639.8","0.00045864","0","3"]],"ts":"1784087946102","checksum":0,"seqId":78785102643,"prevSeqId":78785102619}]}
{"arg":{"channel":"trades","instId":"BTC-USDT"},"data":[{"instId":"BTC-USDT","tradeId":"1033093066","px":"64810.1","sz":"0.03077228","side":"buy","ts":"1784087946122","count":"1","source":"0","seqId":78785102646}]}
{"arg":{"channel":"books","instId":"BTC-USDT"},"action":"update","data":[{"asks":[["64810.1","1.51052018","0","9"]],"bids":[["64799.1","0.0000155","0","1"],["64797.9","0.00772137","0","1"],["64797.3","0","0","0"]],"ts":"1784087946202","checksum":0,"seqId":78785102652,"prevSeqId":78785102643}]}
{"arg":{"channel":"books","instId":"BTC-USDT"},"action":"update","data":[{"asks":[["64812.3","0.12412677","0","1"],["64812.4","0.03705184","0","1"],["64903.1","0","0","0"],["64903.2","0","0","0"]],"bids":[["64799.1","0.02571182","0","2"],["64797.9","0.00772136","0","1"]],"ts":"1784087946302","checksum":0,"seqId":78785102668,"prevSeqId":78785102652}]}
{"arg":{"channel":"books","instId":"BTC-USDT"},"action":"update","data":[{"asks":[["64812.3","0","0","0"],["64812.4","0","0","0"],["64903.1","0.00002503","0","1"],["64903.2","0.32881826","0","6"]],"bids":[["64807.1","0.12176827","0","1"],["64807","0","0","0"],["64799.1","0.0000155","0","1"],["64798","0.00772138","0","1"],["64797.9","0","0","0"]],"ts":"1784087946402","checksum":0,"seqId":78785102683,"prevSeqId":78785102668}]}
{"arg":{"channel":"books","instId":"BTC-USDT"},"action":"update","data":[{"asks":[["64842.5","0.98653639","0","2"]],"bids":[["64799.1","0.02571182","0","2"],["64798","0","0","0"],["64797.3","0.00772136","0","1"],["64782.8","0.49254532","0","3"]],"ts":"1784087946502","checksum":0,"seqId":78785102693,"prevSeqId":78785102683}]}
{"arg":{"channel":"books","instId":"BTC-USDT"},"action":"update","data":[{"asks":[["64851","0.00051689","0","10"]],"bids":[["64801.3","0.26484245","0","1"],["64801.2","0","0","0"],["64797.9","0.00772135","0","1"],["64797.3","0","0","0"],["64782.8","0.49259255","0","4"]],"ts":"1784087946602","checksum":0,"seqId":78785102705,"prevSeqId":78785102693}]}
{"arg":{"channel":"books","instId":"BTC-USDT"},"action":"update","data":[{"asks":[],"bids":[["64801.9","0.26484224","0","1"],["64801.3","0","0","0"],["64799.1","0.0000155","0","1"],["64795.7","0.06950979","0","2"]],"ts":"1784087946702","checksum":0,"seqId":78785102714,"prevSeqId":78785102705}]}
{"arg":{"channel":"books","instId":"BTC-USDT"},"action":"update","data":[{"asks":[["64810.1","1.53851018","0","10"],["64812.4","0.03705184","0","1"],["64812.5","0.12412677","0","1"],["64892.7","0.00324059","0","3"],["64892.9","0.00061268","0","3"],["64903.1","0","0","0"],["64903.2","0","0","0"]],"bids":[["64807.7","0.00007613","0","1"],["64807.1","0","0","0"],["64801.9","0","0","0"],["64801.1","0.26484251","0","1"],["64797.9","0","0","0"],["64797.3","0.00772133","0","1"],["64639.4","0.00046015","0","1"],["64639.1","0.00034809","0","1"]],"ts":"1784087946802","checksum":0,"seqId":78785102735,"prevSeqId":78785102714}]}
{"arg":{"channel":"books","instId":"BTC-USDT"},"action":"update","data":[{"asks":[["64812.4","0","0","0"],["64812.5","0","0","0"],["64814.8","0.12412677","0","1"],["64814.9","0","0","0"],["64815.8","0.12029424","0","1"],["64815.9","0","0","0"],["64903.1","0.00002503","0","1"],["64903.2","0.32881826","0","6"]],"bids":[["64808.8","0.13153271","0","2"],["64807.9","0.12412677","0","1"],["64807.7","0","0","0"],["64807","0.12412677","0","1"],["64806.9","0.19672023","0","3"],["64801.1","0.5744168","0","2"],["64797.9","0.00772133","0","1"],["64797.3","0","0","0"],["64639.1","0","0","0"]],"ts":"1784087946902","checksum":0,"seqId":78785102766,"prevSeqId":78785102735}]}
{"arg":{"channel":"books","instId":"BTC-USDT"},"action":"update","data":[{"asks":[],"bids":[["64802.1","0.26484143","0","1"],["64801.1","0.30957429","0","1"],["64799.1","0.02571182","0","2"],["64639.4","0","0","0"]],"ts":"1784087947002","checksum":0,"seqId":78785102773,"prevSeqId":78785102766}]}
{"arg":{"channel":"books","instId":"BTC-USDT"},"action":"update","data":[{"asks":[["64813.4","0.09748772","0","2"],["64815.8","0","0","0"],["64816","0.12412677","0","1"],["64819.2","0.15444165","0","2"]],"bids":[["64807","0.12420381","0","2"],["64806.9","0.19664319","0","2"],["64802","0.98303755","0","1"],["64801.1","1.28366879","0","2"],["64790","0.15558885","0","2"],["64789.4","0","0","0"],["64639.4","0.00046015","0","1"]],"ts":"1784087947102","checksum":0,"seqId":78785102800,"prevSeqId":78785102773}]}
{"arg":{"channel":"books","instId":"BTC-USDT"},"action":"update","data":[{"asks":[],"bids":[["64799.1","0.0000155","0","1"],["64790","0.00116271","0","1"],["64789.4","0.15442611","0","1"],["64639.4","0","0","0"]],"ts":"1784087947202","checksum":0,"seqId":78785102808,"prevSeqId":78785102800}]}
{"arg":{"channel":"books","instId":"BTC-USDT"},"action":"update","data":[{"asks":[],"bids":[["64807","0.12412677","0","1"],["64805.3","0.37629111","0","3"],["64799.1","0.02571182","0","2"]],"ts":"1784087947302","checksum":0,"seqId":78785102818,"prevSeqId":78785102808}]}
{"arg":{"channel":"books","instId":"BTC-USDT"},"action":"update","data":[{"asks":[],"bids":[["64782.8","0.49254532","0","3"]],"ts":"1784087947402","checksum":0,"seqId":78785102825,"prevSeqId":78785102818}]}
{"arg":{"channel":"books","instId":"BTC-USDT"},"action":"update","data":[{"asks":[],"bids":[["64802.1","0","0","0"],["64801.9","0.26484177","0","1"]],"ts":"1784087947502","checksum":0,"seqId":78785102833,"prevSeqId":78785102825}]}
{"arg":{"channel":"books","instId":"BTC-USDT"},"action":"update","data":[{"asks":[["64845.1","0.49007121","0","2"],["64873.6","0.37791889","0","1"]],"bids":[["64799.1","0.0000155","0","1"],["64782.8","0.49250858","0","2"]],"ts":"1784087947602","checksum":0,"seqId":78785102841,"prevSeqId":78785102833}]}
{"arg":{"channel":"books","instId":"BTC-USDT"},"action":"update","data":[{"asks":[],"bids":[["64799.1","0.02571182","0","2"]],"ts":"1784087947702","checksum":0,"seqId":78785102846,"prevSeqId":78785102841}]}
{"arg":{"channel":"books","instId":"BTC-USDT"},"action":"update","data":[{"asks":[],"bids":[["64799.1","0.0000155","0","1"]],"ts":"1784087947802","checksum":0,"seqId":78785102853,"prevSeqId":78785102846}]}
{"arg":{"channel":"books","instId":"BTC-USDT"},"action":"update","data":[{"asks":[["64810.1","1.51052018","0","9"]],"bids":[["64799.1","0.02571182","0","2"],["64797.9","0.00772131","0","1"]],"ts":"1784087947902","checksum":0,"seqId":78785102863,"prevSeqId":78785102853}]}
{"arg":{"channel":"books","instId":"BTC-USDT"},"action":"update","data":[{"asks":[["64819.2","0.15444164","0","2"]],"bids":[["64801.9","0","0","0"],["64801.2","0.26484231","0","1"],["64789.4","0.1544261","0","1"],["64782.8","0.49254532","0","3"]],"ts":"1784087948102","checksum":0,"seqId":78785102896,"prevSeqId":78785102863}]}
{"arg":{"channel":"books","instId":"BTC-USDT"},"action":"update","data":[{"asks":[["64810.1","1.53845018","0","10"]],"bids":[["64808.8","0.12730377","0","2"],["64807.9","0","0","0"],["64807.6","0.11003557","0","1"],["64802","0.68838632","0","1"],["64801.2","0","0","0"],["64801.1","0","0","0"],["64799.1","0.0000155","0","1"],["64798.7","0.26484634","0","1"],["64789.4","0.15442608","0","1"],["64782.8","0.49250858","0","2"],["64639.4","0.00046015","0","1"]],"ts":"1784087948302","checksum":0,"seqId":78785102938,"prevSeqId":78785102896}]}
{"arg":{"channel":"books","instId":"BTC-USDT"},"action":"update","data":[{"asks":[["64812.4","0.03705184","0","1"],["64812.5","0.12412677","0","1"],["64819.2","0.0000155","0","1"],["64903.1","0","0","0"],["64903.2","0","0","0"]],"bids":[["64808.8","0.09398571","0","2"],["64807.6","0.12412677","0","1"],["64807","0.12254408","0","1"],["64801.1","0.30957429","0","1"],["64799.1","0.02571182","0","2"],["64797.9","0","0","0"],["64797.3","0.00772148","0","1"],["64789.4","0","0","0"],["64782.8","0.49255581","0","3"]],"ts":"1784087948402","checksum":0,"seqId":78785102957,"prevSeqId":78785102938}]}
{"arg":{"channel":"trades","instId":"BTC-USDT"},"data":[{"instId":"BTC-USDT","tradeId":"1033093067","px":"64810.1","sz":"0.0016556","side":"buy","ts":"1784087948484","count":"1","source":"0","seqId":78785102977}]}
{"arg":{"channel":"books","instId":"BTC-USDT"},"action":"update","data":[{"asks":[["64810.1","1.53679458","0","10"],["64812.4","0.03419866","0","1"],["64812.5","0.11456839","0","1"]],"bids":[["64810","0.7231194","0","8"],["64808.8","0.09445815","0","2"],["64807","0","0","0"],["64797.9","0.00772152","0","1"],["64797.3","0","0","0"],["64639.1","0.00034809","0","1"]],"ts":"1784087948502","checksum":0,"seqId":78785102982,"prevSeqId":78785102957}]}
{"arg":{"channel":"books","instId":"BTC-USDT"},"action":"update","data":[{"asks":[],"bids":[["64799.1","0.0000155","0","1"],["64797.9","0","0","0"],["64797.3","0.00772152","0","1"],["64782.8","0.49259255","0","4"]],"ts":"1784087948602","checksum":0,"seqId":78785102991,"prevSeqId":78785102982}]}
{"arg":{"channel":"books","instId":"BTC-USDT"},"action":"update","data":[{"asks":[],"bids":[["64799.1","0.02571183","0","2"],["64795.6","0.02942838","0","1"],["64782.7","0","0","0"]],"ts":"1784087948702","checksum":0,"seqId":78785102999,"prevSeqId":78785102991}]}
{"arg":{"channel":"books","instId":"BTC-USDT"},"action":"update","data":[{"asks":[],"bids":[["64801.1","0","0","0"],["64799.1","0.0000155","0","1"],["64638.5","0.00002272","0","1"]],"ts":"1784087948802","checksum":0,"seqId":78785103006,"prevSeqId":78785102999}]}
{"arg":{"channel":"books","instId":"BTC-USDT"},"action":"update","data":[{"asks":[["64812.4","0","0","0"],["64812.5","0","0","0"],["64903.1","0.00002503","0","1"],["64903.2","0.32881826","0","6"]],"bids":[["64807","0.11306102","0","1"],["64799.1","0.02571183","0","2"],["64797.9","0.00772159","0","1"],["64797.3","0","0","0"],["64638.5","0","0","0"]],"ts":"1784087948902","checksum":0,"seqId":78785103017,"prevSeqId":78785103006}]}
{"arg":{"channel":"books","instId":"BTC-USDT"},"action":"update","data":[{"asks":[],"bids":[["64782.8","0.49255581","0","3"]],"ts":"1784087949002","checksum":0,"seqId":78785103022,"prevSeqId":78785103017}]}
{"arg":{"channel":"books","instId":"BTC-USDT"},"action":"update","data":[{"asks":[],"bids":[["64782.8","0.49259885","0","4"]],"ts":"1784087949102","checksum":0,"seqId":78785103028,"prevSeqId":78785103022}]}
{"arg":{"channel":"books","instId":"BTC-USDT"},"action":"update","data":[{"asks":[],"bids":[["64799.1","0.0000155","0","1"]],"ts":"1784087949202","checksum":0,"seqId":78785103037,"prevSeqId":78785103028}]}
{"arg":{"channel":"books","instId":"BTC-USDT"},"action":"update","data":[{"asks":[["64812.4","0.03705184","0","1"],["64812.5","0.12412677","0","1"],["64903.1","0","0","0"],["64903.2","0","0","0"]],"bids":[["64807","0","0","0"],["64799.1","0.02571183","0","2"],["64797.9","0","0","0"],["64797.3","0.0077215","0","1"],["64638.5","0.00002272","0","1"]],"ts":"1784087949302","checksum":0,"seqId":78785103064,"prevSeqId":78785103037}]}
{"arg":{"channel":"trades","instId":"BTC-USDT"},"data":[{"instId":"BTC-USDT","tradeId":"1033093068","px":"64810","sz":"0.168959","side":"sell","ts":"1784087949369","count":"1","source":"0","seqId":78785103125}]}
{"arg":{"channel":"books","instId":"BTC-USDT"},"action":"update","data":[{"asks":[["64810.1","1.34085645","0","12"],["64811.3","0.03705184","0","1"],["64812.4","0","0","0"],["64813.2","0.39711417","0","1"],["64813.3","0.9740945","0","1"],["64813.4","0","0","0"],["64813.5","0","0","0"],["64816.1","0.77715009","0","2"],["64816.6","0.6659261","0","3"],["64817.1","0.21062381","0","1"],["64819","0.02326085","0","1"],["64819.1","0.12037147","0","2"],["64820.5","0.07718352","0","1"],["64821.1","0","0","0"],["64821.4","0.01542701","0","1"],["64821.5","0","0","0"],["64822.4","0","0","0"],["64823","0.01805347","0","1"],["64823.1","0.34085647","0","3"],["64823.9","0.37787916","0","2"],["64824","0","0","0"],["64825.5","0.01","0","1"],["64828.5","0.15432899","0","2"],["64830.1","0","0","0"],["64832.4","0.49823491","0","1"],["64833","0","0","0"],["64833.5","0.13507116","0","1"],["64835.4","0","0","0"],["64837.3","0","0","0"],["64838","0","0","0"],["64840.1","0","0","0"],["64841.8","0","0","0"],["64859.4","0.25130659","0","2"],["64862","0","0","0"],["64863.6","0.00002779","0","1"],["64872.4","0.30874958","0","2"],["64873.6","0","0","0"],["64876.6","0.00006565","0","2"],["64903.1","0.00002503","0","1"],["64903.2","0.32881826","0","6"],["64903.3","0.0003883","0","1"],["64903.4","0.00012365","0","1"],["64903.6","0.000015","0","1"],["64903.8","0.00019404","0","4"],["64903.9","0.00007108","0","2"]],"bids":[["64810","0.06564343","0","2"],["64808.8","0","0","0"],["64807.6","0","0","0"],["64806.9","0.08863","0","1"],["64806.4","0","0","0"],["64805.4","0.162431","0","1"],["64803.5","0","0","0"],["64802.8","0.03263178","0","1"],["64802.3","0","0","0"],["64802.2","0.10802103","0","1"],["64802","0","0","0"],["64801.8","0","0","0"],["64801","0","0","0"],["64800.8","0","0","0"],["64799.3","0.09075334","0","1"],["64799.2","0.0772089","0","1"],["64799.1","0.0000155","0","1"],["64798.7","0","0","0"],["64798.6","0","0","0"],["64798","0.11138572","0","1"],["64797.3","0","0","0"],["64797.2","0","0","0"],["64797.1","0","0","0"],["64797","0.18566271","0","2"],["64796.6","0","0","0"],["64796.5","0.0000155","0","1"],["64796.4","0","0","0"],["64795.8","0.12412677","0","1"],["64795.6","0","0","0"],["64795.5","0","0","0"],["64793.6","0.12412677","0","1"],["64791.1","0.26488572","0","1"],["64790.6","0.00772203","0","1"],["64788.8","0","0","0"],["64788.6","0","0","0"],["64787.7","0","0","0"],["64786.8","0.00116271","0","1"],["64786.2","0.13511557","0","1"],["64786","0","0","0"],["64784","0.99691658","0","6"],["64782.8","0.49256211","0","3"],["64780.8","0.08159333","0","2"],["64780.2","0.2643686","0","2"],["64779.3","0.05515503","0","2"],["64775.8","0","0","0"],["64773.2","0.19302225","0","1"],["64765.6","0.00001549","0","1"],["64760.3","0.25092892","0","1"],["64754","0.001543","0","1"],["64714.3","0.00015454","0","1"],["64707.7","0.00309082","0","2"],["64637.9","0.00002665","0","1"],["64637.5","0.00001554","0","1"],["64636.9","0.00769914","0","1"],["64636.8","0.00001832","0","1"],["64636.3","0.00098767","0","4"],["64635.4","0.02326085","0","1"],["64635.2","0.00002849","0","1"],["64634.6","0.00010084","0","1"]],"ts":"1784087949402","checksum":0,"seqId":78785103262,"prevSeqId":78785103064}]}
{"arg":{"channel":"books","instId":"BTC-USDT"},"action":"update","data":[{"asks":[["64810.1","1.13023244","0","11"],["64818","0.02316212","0","1"],["64818.2","0.01542778","0","1"],["64821.4","0","0","0"],["64831.7","2.28236991","0","1"],["64842.5","0.33854325","0","1"],["64842.7","0.00023","0","1"],["64850.8","0.00079998","0","2"],["64858.9","0.09371033","0","2"],["64877.1","0.10328601","0","1"],["64903.6","0","0","0"],["64903.8","0","0","0"],["64903.9","0","0","0"]],"bids":[["64810","0.09264343","0","3"],["64808.3","0.02265743","0","1"],["64807.6","0.11554194","0","1"],["64805.5","0.12412677","0","1"],["64805.4","0.16250849","0","2"],["64805.3","0.37621407","0","2"],["64802.8","0.06551196","0","2"],["64800.4","0.12412677","0","1"],["64799.3","0.19253021","0","2"],["64797.1","0.30957429","0","1"],["64796.8","0","0","0"],["64796","0.58302773","0","2"],["64795.9","0.9740945","0","1"],["64795.8","0","0","0"],["64795.5","0.2648676","0","1"],["64795.4","0.18885319","0","2"],["64794.5","0.17378845","0","2"],["64793.6","0","0","0"],["64792.9","0.00772234","0","1"],["64791.1","0","0","0"],["64790.6","0","0","0"],["64780.3","0.24010065","0","1"],["64780","0","0","0"],["64761.6","0.00201883","0","1"],["64747.7","0.067145","0","1"],["64636.9","0","0","0"],["64636.8","0","0","0"],["64636.3","0","0","0"],["64635.4","0","0","0"],["64635.2","0","0","0"],["64634.6","0","0","0"]],"ts":"1784087949502","checksum":0,"seqId":78785103333,"prevSeqId":78785103262}]}
{"arg":{"channel":"books","instId":"BTC-USDT"},"action":"update","data":[{"asks":[["64810.1","1.88426244","0","12"],["64813.1","0.12412677","0","1"],["64813.4","0.21062401","0","1"],["64814.8","0","0","0"],["64816","0","0","0"],["64818.9","0.03555837","0","1"],["64828","0.00001","0","1"],["64829.4","0","0","0"],["64830","2","0","1"],["64843.5","0.00001","0","1"],["64846.2","0","0","0"],["64846.3","0.00001","0","1"],["64848.3","0","0","0"],["64903.3","0","0","0"],["64903.4","0","0","0"]],"bids":[["64805.5","0.12420426","0","2"],["64805.4","0.162431","0","1"],["64799.3","0.295631","0","1"],["64797.3","0.12412677","0","1"],["64797.2","0.26486073","0","1"],["64796.2","0.15062221","0","1"],["64796","0.45890096","0","1"],["64795.5","0","0","0"],["64794.5","0.02316212","0","1"],["64793.6","0.00772187","0","1"],["64792.9","0","0","0"],["64771.5","0","0","0"],["64768.9","0","0","0"],["64767.6","0.01636368","0","2"],["64766","0.00136727","0","1"],["64758.2","0","0","0"],["64754.3","0","0","0"],["64754.1","0.00229116","0","1"],["64744.8","1.30692964","0","3"],["64740.9","0.00154462","0","1"],["64637.5","0","0","0"]],"ts":"1784087949602","checksum":0,"seqId":78785103380,"prevSeqId":78785103333}]}
{"arg":{"channel":"books","instId":"BTC-USDT"},"action":"update","data":[{"asks":[["64812.9","0.51482171","0","2"],["64813","0.9740945","0","1"],["64813.1","0","0","0"],["64813.2","0","0","0"],["64813.3","0","0","0"],["64830.8","0","0","0"],["64831.7","0","0","0"],["64842.7","2.28259991","0","2"],["64903.3","0.0003883","0","1"],["64903.4","0.00012365","0","1"],["64903.6","0.000015","0","1"]],"bids":[["64810","0.06694343","0","3"],["64807.6","0.12412677","0","1"],["64805.3","0.04621407","0","1"],["64804.4","0.11507516","0","1"],["64804.3","0.00001501","0","1"],["64799.3","0.29507692","0","2"],["64797.4","0.12152344","0","1"],["64797.3","0.30957429","0","1"],["64797.1","0","0","0"],["64796","0.91544247","0","2"],["64795.9","0","0","0"],["64794.2","0.00772187","0","1"],["64794.1","0.9740945","0","1"],["64794","2.0000155","0","2"],["64793.6","0","0","0"],["64793.4","0.52436956","0","1"],["64793.3","0","0","0"],["64792","0.02849047","0","1"],["64786.5","0.01639244","0","1"],["64780.2","0.20264978","0","1"],["64779.3","0.22488179","0","3"],["64771.1","0.06171882","0","1"],["64754.3","0.00382197","0","1"],["64639.1","0","0","0"],["64638.5","0","0","0"],["64637.9","0","0","0"]],"ts":"1784087949702","checksum":0,"seqId":78785103441,"prevSeqId":78785103380}]}
{"arg":{"channel":"books","instId":"BTC-USDT"},"action":"update","data":[{"asks":[["64811.3","0.32308204","0","2"],["64812.7","0.12412677","0","1"],["64812.8","0.9740945","0","1"],["64812.9","0","0","0"],["64813","0","0","0"],["64840.5","2.28094399","0","1"],["64842.7","0.00023","0","1"],["64846.8","0.78849913","0","2"],["64855.3","0.0002103","0","3"],["64903.6","0","0","0"]],"bids":[["64805.6","0.12676879","0","1"],["64804.4","0","0","0"],["64803","0.10673571","0","1"],["64802.9","0.12412677","0","1"],["64802.8","0","0","0"],["64797.6","0.12412677","0","1"],["64797.5","0.9740945","0","1"],["64797.4","0","0","0"],["64639.8","0","0","0"],["64639.4","0","0","0"]],"ts":"1784087949802","checksum":0,"seqId":78785103465,"prevSeqId":78785103441}]}
{"arg":{"channel":"books","instId":"BTC-USDT"},"action":"update","data":[{"asks":[["64813.3","0.06287589","0","1"],["64851","0.00052826","0","11"],["64903.4","0","0","0"]],"bids":[["64805.6","0.12684628","0","2"],["64805.5","0.12412677","0","1"],["64803.1","0.11352253","0","1"],["64803","0.25800492","0","2"],["64802.9","0","0","0"],["64802.8","0.22099184","0","1"],["64801.1","0.33148776","0","1"],["64800.4","0","0","0"],["64799.3","0.57328782","0","1"],["64798","0","0","0"],["64797.6","0","0","0"],["64639.8","0.00045864","0","3"]],"ts":"1784087949902","checksum":0,"seqId":78785103491,"prevSeqId":78785103465}]}
{"arg":{"channel":"books","instId":"BTC-USDT"},"action":"update","data":[{"asks":[],"bids":[["64807.6","0.11684014","0","1"],["64797.5","1.10796831","0","2"],["64797.2","0","0","0"],["64796.2","0","0","0"],["64796.1","0.26486186","0","1"],["64795.5","0.01543318","0","1"],["64795.4","0.17342","0","1"]],"ts":"1784087950002","checksum":0,"seqId":78785103507,"prevSeqId":78785103491}]}
{"arg":{"channel":"books","instId":"BTC-USDT"},"action":"update","data":[{"asks":[],"bids":[["64810","0.06564343","0","2"],["64794.6","0.00772192","0","1"],["64794.2","0","0","0"],["64747.8","0.00138787","0","1"],["64747.6","0","0","0"]],"ts":"1784087950102","checksum":0,"seqId":78785103520,"prevSeqId":78785103507}]}
{"arg":{"channel":"books","instId":"BTC-USDT"},"action":"update","data":[{"asks":[],"bids":[["64810","0.06694343","0","3"],["64799.4","0.11307097","0","2"],["64795.3","0.01719667","0","1"],["64639.8","0","0","0"]],"ts":"1784087950202","checksum":0,"seqId":78785103533,"prevSeqId":78785103520}]}
{"arg":{"channel":"books","instId":"BTC-USDT"},"action":"update","data":[{"asks":[],"bids":[["64810","0.06564343","0","2"],["64795.5","0","0","0"],["64795.4","0.18885319","0","2"],["64782.8","0.49259885","0","4"],["64639.8","0.00045864","0","3"]],"ts":"1784087950302","checksum":0,"seqId":78785103543,"prevSeqId":78785103533}]}
{"arg":{"channel":"books","instId":"BTC-USDT"},"action":"update","data":[{"asks":[],"bids":[["64810","0.06694343","0","3"],["64799.4","0.00046015","0","1"],["64796.2","0.26486254","0","1"],["64796.1","0","0","0"],["64795.3","0","0","0"],["64794.6","0.00772193","0","1"],["64782.8","0.49255581","0","3"],["64690.3","0.00001197","0","1"],["64666.5","0.02418804","0","2"],["64639.4","0.00046015","0","1"]],"ts":"1784087950402","checksum":0,"seqId":78785103568,"prevSeqId":78785103543}]}
{"arg":{"channel":"books","instId":"BTC-USDT"},"action":"update","data":[{"asks":[],"bids":[["64799.3","0.47465656","0","2"],["64797.6","0.1196671","0","1"],["64797.5","0.13387381","0","1"],["64797.4","0.9740945","0","1"],["64795.3","0.01719667","0","1"],["64666.5","0.00001403","0","1"],["64640","0","0","0"],["64639.8","0","0","0"],["64639.4","0","0","0"]],"ts":"1784087950502","checksum":0,"seqId":78785103581,"prevSeqId":78785103568}]}
{"arg":{"channel":"books","instId":"BTC-USDT"},"action":"update","data":[{"asks":[["64829.9","1.05692183","0","1"],["64830.9","0","0","0"],["64840.5","0","0","0"],["64842.8","2.28080139","0","1"]],"bids":[["64797.6","0","0","0"],["64797","0.42637565","0","3"],["64795.3","0","0","0"],["64784","0.75620364","0","5"],["64640","0.00438692","0","2"],["64639.8","0.00045864","0","3"]],"ts":"1784087950602","checksum":0,"seqId":78785103595,"prevSeqId":78785103581}]}
{"arg":{"channel":"books","instId":"BTC-USDT"},"action":"update","data":[{"asks":[],"bids":[["64810","0.09394343","0","4"],["64799.4","0.11259664","0","2"],["64795.3","0.01719667","0","1"],["64639.8","0","0","0"]],"ts":"1784087950702","checksum":0,"seqId":78785103602,"prevSeqId":78785103595}]}
{"arg":{"channel":"books","instId":"BTC-USDT"},"action":"update","data":[{"asks":[["64840.5","2.28080139","0","1"],["64842.8","0","0","0"],["64862","0.065197","0","1"],["64903.3","0","0","0"]],"bids":[["64797.1","0.02316131","0","1"],["64795.5","0.01543319","0","1"],["64795.4","0.17342","0","1"],["64794.6","0.00772201","0","1"],["64794.5","0","0","0"],["64640","0","0","0"]],"ts":"1784087950802","checksum":0,"seqId":78785103619,"prevSeqId":78785103602}]}
{"arg":{"channel":"books","instId":"BTC-USDT"},"action":"update","data":[{"asks":[["64812.7","0","0","0"],["64903.3","0.0003883","0","1"]],"bids":[["64797.1","0.28802312","0","2"],["64796.2","0","0","0"],["64794.6","0","0","0"],["64794.1","0.98181642","0","2"],["64640","0.00438692","0","2"],["64639.8","0.00045864","0","3"]],"ts":"1784087950902","checksum":0,"seqId":78785103632,"prevSeqId":78785103619}]}
{"arg":{"channel":"books","instId":"BTC-USDT"},"action":"update","data":[{"asks":[],"bids":[["64798.3","0.05560367","0","1"],["64795.3","0","0","0"]],"ts":"1784087951002","checksum":0,"seqId":78785103639,"prevSeqId":78785103632}]}
{"arg":{"channel":"books","instId":"BTC-USDT"},"action":"update","data":[{"asks":[],"bids":[["64810","0.06694343","0","3"],["64799.5","0.12412677","0","1"],["64799.4","0.00046015","0","1"],["64797.6","0.26485979","0","1"],["64797.1","0.02316131","0","1"],["64782.8","0.49250858","0","2"],["64640","0","0","0"],["64639.8","0","0","0"]],"ts":"1784087951102","checksum":0,"seqId":78785103654,"prevSeqId":78785103639}]}
{"arg":{"channel":"books","instId":"BTC-USDT"},"action":"update","data":[{"asks":[["64812.6","0.10995803","0","1"],["64903.3","0","0","0"]],"bids":[["64799.5","0","0","0"],["64799.4","0.10998164","0","2"],["64795.3","0.01719667","0","1"],["64782.8","0.49255162","0","3"]],"ts":"1784087951202","checksum":0,"seqId":78785103668,"prevSeqId":78785103654}]}
{"arg":{"channel":"trades","instId":"BTC-USDT"},"data":[{"instId":"BTC-USDT","tradeId":"1033093069","px":"64810","sz":"0.00165394","side":"sell","ts":"1784087951218","count":"1","source":"0","seqId":78785103671}]}
{"arg":{"channel":"books","instId":"BTC-USDT"},"action":"update","data":[{"asks":[["64812.6","0","0","0"],["64812.7","0.12412677","0","1"],["64840.5","0","0","0"],["64842.7","2.27932022","0","2"],["64903.3","0.0003883","0","1"]],"bids":[["64810","0.06528949","0","3"],["64797.6","0.26485781","0","1"],["64795.3","0","0","0"],["64640","0.00438692","0","2"]],"ts":"1784087951302","checksum":0,"seqId":78785103692,"prevSeqId":78785103668}]}
{"arg":{"channel":"books","instId":"BTC-USDT"},"action":"update","data":[{"asks":[["64812.7","0","0","0"],["64903.4","0.00012365","0","1"]],"bids":[["64795.3","0.01719667","0","1"],["64782.8","0.49259885","0","4"],["64640","0","0","0"]],"ts":"1784087951402","checksum":0,"seqId":78785103699,"prevSeqId":78785103692}]}
{"arg":{"channel":"books","instId":"BTC-USDT"},"action":"update","data":[{"asks":[["64840.5","2.27909022","0","1"],["64842.7","0.00023","0","1"],["64903.4","0","0","0"]],"bids":[],"ts":"1784087951602","checksum":0,"seqId":78785103711,"prevSeqId":78785103699}]}
{"arg":{"channel":"books","instId":"BTC-USDT"},"action":"update","data":[{"asks":[["64838.6","0.79221989","0","4"],["64851","0.00051689","0","10"]],"bids":[["64795.3","0","0","0"],["64782.8","0.49255162","0","3"],["64640","0.00438692","0","2"]],"ts":"1784087951702","checksum":0,"seqId":78785103723,"prevSeqId":78785103711}]}
{"arg":{"channel":"books","instId":"BTC-USDT"},"action":"update","data":[{"asks":[["64812.7","0.11573431","0","1"],["64829.6","2.46359022","0","2"],["64840.5","0","0","0"],["64890.6","0.31267139","0","4"],["64892.7","0.00015859","0","1"]],"bids":[["64799.4","0.12458692","0","2"],["64797.6","0.26485681","0","1"],["64792","0","0","0"],["64782.8","0.49250858","0","2"],["64639.8","0.00045864","0","3"]],"ts":"1784087951802","checksum":0,"seqId":78785103749,"prevSeqId":78785103723}]}
{"arg":{"channel":"books","instId":"BTC-USDT"},"action":"update","data":[{"asks":[["64838.6","0.14586655","0","3"]],"bids":[["64795.3","0.01719667","0","1"],["64639.8","0","0","0"]],"ts":"1784087951902","checksum":0,"seqId":78785103757,"prevSeqId":78785103749}]}
{"arg":{"channel":"books","instId":"BTC-USDT"},"action":"update","data":[{"asks":[],"bids":[["64795.3","0","0","0"],["64782.8","0.49254532","0","3"],["64639.8","0.00045864","0","3"]],"ts":"1784087952002","checksum":0,"seqId":78785103763,"prevSeqId":78785103757}]}
{"arg":{"channel":"books","instId":"BTC-USDT"},"action":"update","data":[{"asks":[],"bids":[["64794.2","0.00772177","0","1"],["64794.1","0.9740945","0","1"],["64782.8","0.49250858","0","2"],["64749.9","0","0","0"],["64745.2","0.3088456","0","1"],["64639.8","0","0","0"]],"ts":"1784087952102","checksum":0,"seqId":78785103782,"prevSeqId":78785103763}]}
{"arg":{"channel":"books","instId":"BTC-USDT"},"action":"update","data":[{"asks":[["64851","0.00052826","0","11"]],"bids":[["64810","0.06398949","0","2"],["64799.4","0.00046015","0","1"]],"ts":"1784087952202","checksum":0,"seqId":78785103789,"prevSeqId":78785103782}]}
{"arg":{"channel":"books","instId":"BTC-USDT"},"action":"update","data":[{"asks":[["64812.7","0","0","0"],["64851","0.00053963","0","12"],["64903.4","0.00012365","0","1"]],"bids":[["64810","0.06528949","0","3"],["64805.6","0.12676879","0","1"],["64804.3","0.00009296","0","2"],["64799.4","0.12458692","0","2"],["64798.4","0.26485638","0","1"],["64797.6","0","0","0"]],"ts":"1784087952302","checksum":0,"seqId":78785103805,"prevSeqId":78785103789}]}
{"arg":{"channel":"books","instId":"BTC-USDT"},"action":"update","data":[{"asks":[],"bids":[["64798.4","0","0","0"],["64797.6","0.26485651","0","1"],["64795.3","0.01719667","0","1"],["64640","0","0","0"]],"ts":"1784087952402","checksum":0,"seqId":78785103821,"prevSeqId":78785103805}]}
{"arg":{"channel":"books","instId":"BTC-USDT"},"action":"update","data":[{"asks":[["64812.6","0.12412677","0","1"],["64851","0.000551","0","13"],["64903.4","0","0","0"]],"bids":[["64799.4","0.00046015","0","1"],["64797.6","0.26485718","0","1"],["64795.3","0","0","0"],["64782.8","0.49255162","0","3"],["64640","0.00438692","0","2"]],"ts":"1784087952502","checksum":0,"seqId":78785103839,"prevSeqId":78785103821}]}
{"arg":{"channel":"books","instId":"BTC-USDT"},"action":"update","data":[{"asks":[["64812.6","0","0","0"],["64812.7","0.12412677","0","1"]],"bids":[],"ts":"1784087952602","checksum":0,"seqId":78785103850,"prevSeqId":78785103839}]}
{"arg":{"channel":"trades","instId":"BTC-USDT"},"data":[{"instId":"BTC-USDT","tradeId":"1033093070","px":"64810","sz":"0.00154112","side":"sell","ts":"1784087952632","count":"1","source":"0","seqId":78785103860}]}
{"arg":{"channel":"books","instId":"BTC-USDT"},"action":"update","data":[{"asks":[["64810.1","1.87526244","0","11"],["64812.6","0.11374969","0","1"],["64812.7","0","0","0"],["64829.5","1.79230351","0","1"],["64829.9","0","0","0"]],"bids":[["64810","0.06374837","0","3"],["64807.6","0","0","0"],["64795.3","0.01719667","0","1"]],"ts":"1784087952702","checksum":0,"seqId":78785103867,"prevSeqId":78785103850}]}
{"arg":{"channel":"books","instId":"BTC-USDT"},"action":"update","data":[{"asks":[["64827.4","0.0289417","0","1"],["64903.3","0","0","0"]],"bids":[["64807.6","0.1179941","0","1"],["64791.8","0.02823821","0","1"],["64640.3","0","0","0"],["64640","0","0","0"]],"ts":"1784087952802","checksum":0,"seqId":78785103875,"prevSeqId":78785103867}]}
{"arg":{"channel":"books","instId":"BTC-USDT"},"action":"update","data":[{"asks":[],"bids":[["64807.6","0.11308978","0","1"],["64795.3","0","0","0"],["64640.3","0.00016308","0","4"]],"ts":"1784087952902","checksum":0,"seqId":78785103882,"prevSeqId":78785103875}]}
{"arg":{"channel":"books","instId":"BTC-USDT"},"action":"update","data":[{"asks":[],"bids":[["64810","0.06244837","0","2"],["64795.3","0.01719667","0","1"],["64640.3","0","0","0"]],"ts":"1784087953002","checksum":0,"seqId":78785103889,"prevSeqId":78785103882}]}
{"arg":{"channel":"books","instId":"BTC-USDT"},"action":"update","data":[{"asks":[["64812.6","0","0","0"],["64903.3","0.0003883","0","1"]],"bids":[["64810","0.06374837","0","3"],["64801.2","0.12412677","0","1"],["64798.4","0.26485618","0","1"],["64797.6","0","0","0"],["64782.8","0.49259885","0","4"],["64640.8","0","0","0"]],"ts":"1784087953102","checksum":0,"seqId":78785103908,"prevSeqId":78785103889}]}
{"arg":{"channel":"books","instId":"BTC-USDT"},"action":"update","data":[{"asks":[],"bids":[["64801.2","0","0","0"],["64799.4","0.12458692","0","2"],["64795.3","0","0","0"],["64640.8","0.00001428","0","1"],["64640.3","0.00016308","0","4"]],"ts":"1784087953202","checksum":0,"seqId":78785103916,"prevSeqId":78785103908}]}
{"arg":{"channel":"books","instId":"BTC-USDT"},"action":"update","data":[{"asks":[],"bids":[["64798.4","0","0","0"],["64797.6","0.2648565","0","1"],["64699.9","0.30957429","0","1"]],"ts":"1784087953302","checksum":0,"seqId":78785103927,"prevSeqId":78785103916}]}
pong
{"arg":{"channel":"books","instId":"BTC-USDT"},"action":"update","data":[{"asks":[],"bids":[["64797.6","0.26485723","0","1"]],"ts":"1784087953502","checksum":0,"seqId":78785103941,"prevSeqId":78785103927}]}
{"arg":{"channel":"books","instId":"BTC-USDT"},"action":"update","data":[{"asks":[],"bids":[["64803","0.21520989","0","2"],["64802.4","0.1080207","0","1"],["64802.2","0","0","0"],["64801.2","0.12412677","0","1"],["64799.4","0.00046015","0","1"],["64795.3","0.01719667","0","1"],["64691.4","0.00558369","0","1"],["64641","0","0","0"],["64640.8","0","0","0"],["64640.3","0","0","0"]],"ts":"1784087953602","checksum":0,"seqId":78785103958,"prevSeqId":78785103941}]}
{"arg":{"channel":"books","instId":"BTC-USDT"},"action":"update","data":[{"asks":[],"bids":[["64795.3","0","0","0"],["64782.8","0.49259466","0","4"],["64641","0.1845","0","1"]],"ts":"1784087953702","checksum":0,"seqId":78785103967,"prevSeqId":78785103958}]}
{"arg":{"channel":"books","instId":"BTC-USDT"},"action":"update","data":[{"asks":[],"bids":[["64797.6","0","0","0"],["64797.5","0.39873357","0","2"],["64782.8","0.49267863","0","6"],["64640.8","0.00001428","0","1"]],"ts":"1784087954302","checksum":0,"seqId":78785104010,"prevSeqId":78785103967}]}
{"arg":{"channel":"books","instId":"BTC-USDT"},"action":"update","data":[{"asks":[],"bids":[["64797.5","0.13387381","0","1"],["64797.1","0.28802189","0","2"],["64795.5","0.02315505","0","2"],["64795.3","0.01719667","0","1"],["64794.2","0","0","0"],["64710.4","0.00309068","0","2"],["64707.7","0","0","0"]],"ts":"1784087954402","checksum":0,"seqId":78785104031,"prevSeqId":78785104010}]}
{"arg":{"channel":"books","instId":"BTC-USDT"},"action":"update","data":[{"asks":[],"bids":[["64797.1","0.02316131","0","1"],["64796.1","0.26486181","0","1"],["64795.5","0.01543319","0","1"],["64794.2","0.00772189","0","1"],["64641","0","0","0"],["64640.8","0","0","0"]],"ts":"1784087954502","checksum":0,"seqId":78785104044,"prevSeqId":78785104031}]}
{"arg":{"channel":"books","instId":"BTC-USDT"},"action":"update","data":[{"asks":[],"bids":[["64795.3","0","0","0"],["64782.8","0.00020679","0","5"],["64763.4","0","0","0"],["64641","0.1845","0","1"],["64640.8","0.00001428","0","1"]],"ts":"1784087954602","checksum":0,"seqId":78785104053,"prevSeqId":78785104044}]}
{"arg":{"channel":"trades","instId":"BTC-USDT"},"data":[{"instId":"BTC-USDT","tradeId":"1033093071","px":"64810","sz":"0.009","side":"sell","ts":"1784087954666","count":"1","source":"0","seqId":78785104061}]}
{"arg":{"channel":"books","instId":"BTC-USDT"},"action":"update","data":[{"asks":[["64812.7","0.12412677","0","1"],["64903.3","0","0","0"]],"bids":[["64810","0.05474837","0","3"],["64805.6","0.07828328","0","1"],["64805.4","0","0","0"],["64805.3","0.20200707","0","2"],["64795.3","0.01719738","0","1"],["64780.3","0.38135203","0","2"],["64780","0.46803151","0","1"],["64760.6","0.91463888","0","2"],["64640.8","0","0","0"]],"ts":"1784087954702","checksum":0,"seqId":78785104072,"prevSeqId":78785104053}]}
{"arg":{"channel":"books","instId":"BTC-USDT"},"action":"update","data":[{"asks":[],"bids":[["64807.6","0","0","0"],["64805.6","0","0","0"],["64801.2","0","0","0"],["64799.4","0.11906075","0","2"],["64796.2","0.26486245","0","1"],["64796.1","0","0","0"],["64795.5","0","0","0"],["64795.4","0.18885319","0","2"],["64794.2","0","0","0"],["64794.1","0.98181649","0","2"],["64760.9","0.70609772","0","3"],["64640.8","0.00001428","0","1"],["64640.3","0.00016308","0","4"],["64640","0.00438692","0","2"],["64639.8","0.00045864","0","3"],["64639.4","0.00046015","0","1"]],"ts":"1784087954802","checksum":0,"seqId":78785104093,"prevSeqId":78785104072}]}
{"arg":{"channel":"books","instId":"BTC-USDT"},"action":"update","data":[{"asks":[],"bids":[["64810","0.05344837","0","2"],["64796.2","0","0","0"],["64795.8","0.26486658","0","1"],["64795.3","0","0","0"],["64639.1","0.00034809","0","1"]],"ts":"1784087954902","checksum":0,"seqId":78785104101,"prevSeqId":78785104093}]}
{"arg":{"channel":"books","instId":"BTC-USDT"},"action":"update","data":[{"asks":[["64818.1","0.01542778","0","1"],["64818.2","0","0","0"]],"bids":[["64799.4","0.00046015","0","1"],["64795.8","0.26486609","0","1"],["64795.3","0.01719738","0","1"],["64782.8","0.00015956","0","4"],["64639.1","0","0","0"]],"ts":"1784087955002","checksum":0,"seqId":78785104119,"prevSeqId":78785104101}]}
{"arg":{"channel":"books","instId":"BTC-USDT"},"action":"update","data":[{"asks":[["64827.4","0","0","0"],["64903.3","0.0003883","0","1"]],"bids":[["64799.4","0.12458692","0","2"],["64796.1","0.26486539","0","1"],["64795.8","0","0","0"]],"ts":"1784087955102","checksum":0,"seqId":78785104130,"prevSeqId":78785104119}]}
{"arg":{"channel":"books","instId":"BTC-USDT"},"action":"update","data":[{"asks":[],"bids":[["64805.3","0.04621407","0","1"],["64801.2","0.12412677","0","1"],["64799.4","0.00046015","0","1"],["64795.3","0","0","0"]],"ts":"1784087955202","checksum":0,"seqId":78785104138,"prevSeqId":78785104130}]}
{"arg":{"channel":"books","instId":"BTC-USDT"},"action":"update","data":[{"asks":[],"bids":[["64803.2","0.15961","0","1"],["64801.2","0","0","0"],["64797.1","0.28802307","0","2"],["64796.1","0","0","0"],["64639.1","0.00034809","0","1"]],"ts":"1784087955302","checksum":0,"seqId":78785104149,"prevSeqId":78785104138}]}
{"arg":{"channel":"books","instId":"BTC-USDT"},"action":"update","data":[{"asks":[["64829","0.02883469","0","1"],["64903.3","0","0","0"]],"bids":[["64799.4","0.12458692","0","2"],["64782.8","0.00016375","0","4"]],"ts":"1784087955402","checksum":0,"seqId":78785104157,"prevSeqId":78785104149}]}
{"arg":{"channel":"books","instId":"BTC-USDT"},"action":"update","data":[{"asks":[],"bids":[["64799.5","0.12042268","0","1"],["64799.4","0.00046015","0","1"],["64639.1","0","0","0"]],"ts":"1784087955502","checksum":0,"seqId":78785104166,"prevSeqId":78785104157}]}
{"arg":{"channel":"books","instId":"BTC-USDT"},"action":"update","data":[{"asks":[],"bids":[["64803.2","0","0","0"],["64801.2","0.12412677","0","1"],["64799.5","0","0","0"],["64797.5","0","0","0"],["64795.9","0.17676056","0","1"],["64639.1","0.00034809","0","1"]],"ts":"1784087955702","checksum":0,"seqId":78785104181,"prevSeqId":78785104166}]}
{"arg":{"channel":"books","instId":"BTC-USDT"},"action":"update","data":[{"asks":[],"bids":[["64795.3","0.01719738","0","1"],["64639.1","0","0","0"]],"ts":"1784087955802","checksum":0,"seqId":78785104187,"prevSeqId":78785104181}]}
{"arg":{"channel":"books","instId":"BTC-USDT"},"action":"update","data":[{"asks":[],"bids":[["64803.3","0.159611","0","1"],["64801.2","0","0","0"],["64799.4","0.11105537","0","2"],["64797.1","0.02316131","0","1"],["64796.1","0.2648618","0","1"],["64795.3","0","0","0"]],"ts":"1784087955902","checksum":0,"seqId":78785104197,"prevSeqId":78785104187}]}
{"arg":{"channel":"books","instId":"BTC-USDT"},"action":"update","data":[{"asks":[["64813.3","0.09188918","0","2"],["64816","0.12412677","0","1"],["64903.2","0","0","0"]],"bids":[["64805.5","0","0","0"],["64803.8","0.07442611","0","1"],["64803.4","0.11533317","0","2"],["64803.1","0","0","0"],["64799.4","0.00046015","0","1"],["64796.1","0","0","0"],["64795.8","0.26486641","0","1"],["64795.4","0.17342","0","1"],["64795.3","0.01719738","0","1"],["64794.1","0.9740945","0","1"],["64793.9","0.01543355","0","1"],["64792.9","0.00772201","0","1"],["64639.8","0","0","0"],["64639.4","0","0","0"]],"ts":"1784087956002","checksum":0,"seqId":78785104219,"prevSeqId":78785104197}]}
{"arg":{"channel":"books","instId":"BTC-USDT"},"action":"update","data":[{"asks":[],"bids":[["64795.8","0.26486656","0","1"],["64795.3","0","0","0"],["64793.6","0.00772201","0","1"],["64792.9","0","0","0"],["64639.8","0.00045864","0","3"]],"ts":"1784087956102","checksum":0,"seqId":78785104233,"prevSeqId":78785104219}]}
{"arg":{"channel":"books","instId":"BTC-USDT"},"action":"update","data":[{"asks":[],"bids":[["64805.2","0.12106308","0","3"],["64803.8","0","0","0"],["64799.4","0.12458692","0","2"],["64795.8","0","0","0"],["64795.5","0.26486717","0","1"],["64794","2.00773754","0","3"],["64793.6","0","0","0"],["64639.4","0.00046015","0","1"],["64639.1","0.00034809","0","1"]],"ts":"1784087956202","checksum":0,"seqId":78785104246,"prevSeqId":78785104233}]}
{"arg":{"channel":"books","instId":"BTC-USDT"},"action":"update","data":[{"asks":[["64813.3","0.06287589","0","1"],["64816","0","0","0"],["64903.2","0.32881826","0","6"]],"bids":[["64799.4","0.00046015","0","1"],["64795.3","0.01719738","0","1"],["64794.2","0.00772205","0","1"],["64794","2.0000155","0","2"],["64782.8","0.00003674","0","1"],["64639.4","0","0","0"],["64639.1","0","0","0"]],"ts":"1784087956302","checksum":0,"seqId":78785104264,"prevSeqId":78785104246}]}
{"arg":{"channel":"books","instId":"BTC-USDT"},"action":"update","data":[{"asks":[],"bids":[["64799.4","0.11699189","0","2"],["64795.3","0","0","0"],["64639.4","0.00046015","0","1"]],"ts":"1784087956402","checksum":0,"seqId":78785104272,"prevSeqId":78785104264}]}
{"arg":{"channel":"books","instId":"BTC-USDT"},"action":"update","data":[{"asks":[["64816","0.12095847","0","1"],["64903.2","0","0","0"]],"bids":[["64799.4","0.00046015","0","1"],["64795.3","0.01719738","0","1"],["64639.4","0","0","0"]],"ts":"1784087956502","checksum":0,"seqId":78785104281,"prevSeqId":78785104272}]}
{"arg":{"channel":"books","instId":"BTC-USDT"},"action":"update","data":[{"asks":[["64816","0","0","0"],["64903.2","0.32881826","0","6"]],"bids":[["64799.4","0.12458692","0","2"],["64795.3","0","0","0"],["64691.4","0","0","0"],["64639.4","0.00046015","0","1"],["64639.1","0.00034809","0","1"]],"ts":"1784087956602","checksum":0,"seqId":78785104298,"prevSeqId":78785104281}]}
{"arg":{"channel":"books","instId":"BTC-USDT"},"action":"update","data":[{"asks":[],"bids":[["64799.4","0.00046015","0","1"],["64795.5","0.26486745","0","1"],["64795.3","0.01719738","0","1"],["64639.1","0","0","0"]],"ts":"1784087956702","checksum":0,"seqId":78785104309,"prevSeqId":78785104298}]}
{"arg":{"channel":"books","instId":"BTC-USDT"},"action":"update","data":[{"asks":[["64813.3","0.09880309","0","2"],["64815.6","0.0231622","0","1"],["64815.9","0.02326085","0","1"],["64816","0.12412677","0","1"],["64816.4","0.01982816","0","1"],["64818","0","0","0"],["64819","0","0","0"],["64890","0.00310494","0","3"],["64890.6","0.30958929","0","2"],["64903.1","0","0","0"],["64903.2","0","0","0"]],"bids":[["64805.2","0.00208352","0","2"],["64803.4","0.12528948","0","2"],["64799.4","0.12458692","0","2"],["64799.3","0.09507398","0","1"],["64797.4","0","0","0"],["64797.3","0","0","0"],["64797.1","0","0","0"],["64797","0.18566271","0","2"],["64795.9","0","0","0"],["64795.5","0","0","0"],["64794.7","0.0231622","0","1"],["64794.2","0","0","0"],["64794.1","0.98181674","0","2"],["64792.9","0.26487676","0","1"],["64791.8","0","0","0"],["64784","0.99691658","0","6"],["64782.8","0.00008397","0","2"],["64777.3","0.43950504","0","1"],["64639.1","0.00034809","0","1"],["64638.5","0.00002272","0","1"],["64637.9","0.00002665","0","1"],["64637.8","0.02417398","0","1"],["64637.5","0.00001554","0","1"]],"ts":"1784087956802","checksum":0,"seqId":78785104357,"prevSeqId":78785104309}]}
{"arg":{"channel":"books","instId":"BTC-USDT"},"action":"update","data":[{"asks":[["64816","0","0","0"],["64903.1","0.00002503","0","1"]],"bids":[["64805.2","0.11450264","0","3"],["64799.4","0.00046015","0","1"],["64798","0.12412677","0","1"],["64796.1","0.12412677","0","1"],["64795.3","0","0","0"],["64794.8","0.2648711","0","1"],["64794.7","0.15602444","0","2"],["64792.9","0","0","0"],["64692.2","0.00558363","0","1"],["64672.4","0","0","0"],["64659.6","0.009261","0","1"],["64637.8","0","0","0"],["64637.5","0","0","0"]],"ts":"1784087956902","checksum":0,"seqId":78785104376,"prevSeqId":78785104357}]}
{"arg":{"channel":"books","instId":"BTC-USDT"},"action":"update","data":[{"asks":[["64826.6","0.00001","0","1"],["64827.4","2.27909022","0","1"],["64828","0","0","0"],["64829.5","1.11199508","0","1"],["64829.6","0.1845","0","1"],["64857.7","0.00002005","0","2"],["64860.9","0","0","0"]],"bids":[["64801.2","0.11341357","0","1"],["64799.3","0.21237872","0","2"],["64797.1","0.30957429","0","1"],["64796.1","0","0","0"],["64794.2","0.00772213","0","1"],["64794.1","0.9740945","0","1"],["64767.6","0.00116271","0","1"],["64766.3","0.01520128","0","1"],["64766","0","0","0"],["64764.6","0.44820731","0","2"],["64754.1","0","0","0"],["64752.8","0.31186548","0","2"],["64740.9","0","0","0"],["64739.6","0.00154465","0","1"],["64637.9","0","0","0"]],"ts":"1784087957002","checksum":0,"seqId":78785104415,"prevSeqId":78785104376}]}
{"arg":{"channel":"books","instId":"BTC-USDT"},"action":"update","data":[{"asks":[["64829","0","0","0"],["64903.2","0.32881826","0","6"]],"bids":[["64807.6","0.12361964","0","1"],["64799.3","0.09507398","0","1"],["64798","0.11858374","0","1"],["64797.1","0","0","0"],["64796.1","0.11139183","0","1"],["64795.9","0.14493916","0","1"],["64795.5","0.26486801","0","1"],["64794.8","0.00772209","0","1"],["64794.7","0.0231622","0","1"],["64794.5","0.01719738","0","1"],["64794.2","0","0","0"],["64789.4","0.02883469","0","1"],["64639.8","0","0","0"],["64639.4","0","0","0"],["64639.1","0","0","0"],["64638.5","0","0","0"]],"ts":"1784087957102","checksum":0,"seqId":78785104443,"prevSeqId":78785104415}]}
{"arg":{"channel":"books","instId":"BTC-USDT"},"action":"update","data":[{"asks":[["64812.7","0","0","0"],["64903.3","0.0003883","0","1"]],"bids":[["64804.3","0.00001501","0","1"],["64803.7","0.248118","0","2"],["64803.5","0.1845","0","1"],["64803.4","0.12536833","0","3"],["64803.3","0","0","0"],["64799.3","0.52375753","0","1"],["64798","0","0","0"],["64797.2","0.9740945","0","1"],["64797.1","0.30957429","0","1"],["64796.7","0.02316152","0","1"],["64796.1","0","0","0"],["64795.6","0.00772206","0","1"],["64794.8","0","0","0"],["64794.7","0","0","0"]],"ts":"1784087957202","checksum":0,"seqId":78785104469,"prevSeqId":78785104443}]}
{"arg":{"channel":"books","instId":"BTC-USDT"},"action":"update","data":[{"asks":[["64812.7","0.12412677","0","1"],["64903.3","0","0","0"]],"bids":[["64810","0.05474837","0","3"],["64803.5","0.18457885","0","2"],["64803.4","0.12528948","0","2"],["64801.2","0","0","0"],["64795.6","0","0","0"],["64795.5","0","0","0"],["64794.2","0.27259141","0","2"],["64782.8","0.00012701","0","3"],["64776.9","0.03074552","0","1"],["64639.8","0.00045864","0","3"]],"ts":"1784087957302","checksum":0,"seqId":78785104492,"prevSeqId":78785104469}]}
{"arg":{"channel":"books","instId":"BTC-USDT"},"action":"update","data":[{"asks":[["64812.7","0","0","0"],["64903.3","0.0003883","0","1"]],"bids":[["64810","0.05344837","0","2"],["64799.4","0.12458692","0","2"]],"ts":"1784087957402","checksum":0,"seqId":78785104499,"prevSeqId":78785104492}]}
{"arg":{"channel":"books","instId":"BTC-USDT"},"action":"update","data":[{"asks":[["64812.7","0.11072188","0","1"],["64903.3","0","0","0"]],"bids":[["64803.5","0.00007885","0","1"],["64794.2","0.27259321","0","2"]],"ts":"1784087957502","checksum":0,"seqId":78785104515,"prevSeqId":78785104499}]}
{"arg":{"channel":"books","instId":"BTC-USDT"},"action":"update","data":[{"asks":[],"bids":[["64807.6","0.11539769","0","1"],["64794.5","0","0","0"],["64782.8","0.00017005","0","4"],["64639.4","0.00046015","0","1"]],"ts":"1784087957602","checksum":0,"seqId":78785104529,"prevSeqId":78785104515}]}
{"arg":{"channel":"books","instId":"BTC-USDT"},"action":"update","data":[{"asks":[],"bids":[["64803.5","0","0","0"],["64803.4","0.12536843","0","3"],["64801.2","0.12412677","0","1"],["64799.4","0.00046015","0","1"],["64794.5","0.01719738","0","1"],["64789.4","0","0","0"],["64690.4","0.00001197","0","1"],["64690.3","0","0","0"]],"ts":"1784087957702","checksum":0,"seqId":78785104561,"prevSeqId":78785104529}]}
{"arg":{"channel":"books","instId":"BTC-USDT"},"action":"update","data":[{"asks":[["64812.7","0","0","0"],["64903.3","0.0003883","0","1"]],"bids":[["64799.4","0.12458692","0","2"],["64794.5","0","0","0"],["64639.1","0.00034809","0","1"]],"ts":"1784087957902","checksum":0,"seqId":78785104572,"prevSeqId":78785104561}]}
{"arg":{"channel":"books","instId":"BTC-USDT"},"action":"update","data":[{"asks":[["64810.1","1.88426244","0","12"],["64815.6","0","0","0"],["64817.8","0.02316139","0","1"]],"bids":[["64810","0.05474837","0","3"]],"ts":"1784087958002","checksum":0,"seqId":78785104580,"prevSeqId":78785104572}]}
{"arg":{"channel":"trades","instId":"BTC-USDT"},"data":[{"instId":"BTC-USDT","tradeId":"1033093072","px":"64810.1","sz":"0.00849713","side":"buy","ts":"1784087958053","count":"1","source":"0","seqId":78785104606}]}
{"arg":{"channel":"books","instId":"BTC-USDT"},"action":"update","data":[{"asks":[["64810.1","1.87576531","0","12"],["64813.3","0.06287589","0","1"],["64816.6","0.42521316","0","2"],["64823.1","0.58156941","0","4"]],"bids":[["64803.5","0.1845","0","1"],["64799.4","0.00046015","0","1"],["64797","0.42637565","0","3"],["64794.3","0.00772209","0","1"],["64794.2","0.26486864","0","1"],["64784","0.75620364","0","5"],["64639.4","0","0","0"],["64639.1","0","0","0"]],"ts":"1784087958102","checksum":0,"seqId":78785104616,"prevSeqId":78785104580}]}
{"arg":{"channel":"books","instId":"BTC-USDT"},"action":"update","data":[{"asks":[["64812.5","0","0","0"],["64873.6","0.05069934","0","1"]],"bids":[["64799.4","0.1165925","0","2"],["64795.5","0.26486729","0","1"],["64794.3","0","0","0"],["64794.2","0.00772212","0","1"],["64782.8","0.00013331","0","3"]],"ts":"1784087958202","checksum":0,"seqId":78785104631,"prevSeqId":78785104616}]}
{"arg":{"channel":"books","instId":"BTC-USDT"},"action":"update","data":[{"asks":[["64812.5","0.12412677","0","1"],["64816.6","0.6659261","0","3"],["64823.1","0.34085647","0","3"],["64903.3","0","0","0"]],"bids":[["64810","0.08174837","0","4"],["64805.3","0.24696116","0","2"],["64803.5","0.18457904","0","2"],["64803.4","0.12528948","0","2"],["64801.2","0","0","0"],["64799.4","0.12458692","0","2"],["64796.1","1.08952557","0","1"],["64796","2","0","1"],["64795.5","0.26486759","0","1"],["64794","0.0000155","0","1"],["64782.8","0.00008608","0","2"]],"ts":"1784087958302","checksum":0,"seqId":78785104660,"prevSeqId":78785104631}]}
{"arg":{"channel":"books","instId":"BTC-USDT"},"action":"update","data":[{"asks":[],"bids":[["64794.6","0.00772209","0","1"],["64794.5","0.01719738","0","1"],["64794.2","0","0","0"],["64692.2","0","0","0"]],"ts":"1784087958402","checksum":0,"seqId":78785104670,"prevSeqId":78785104660}]}
{"arg":{"channel":"books","instId":"BTC-USDT"},"action":"update","data":[{"asks":[["64812.5","0","0","0"],["64903.3","0.0003883","0","1"]],"bids":[["64801.2","0.12412677","0","1"],["64799.4","0.00046015","0","1"],["64794.6","0","0","0"],["64794.5","0","0","0"],["64794.2","0.0077221","0","1"]],"ts":"1784087958502","checksum":0,"seqId":78785104682,"prevSeqId":78785104670}]}
{"arg":{"channel":"books","instId":"BTC-USDT"},"action":"update","data":[{"asks":[["64812.7","0.12412677","0","1"],["64816.2","0.15443314","0","1"],["64903.2","0","0","0"],["64903.3","0","0","0"]],"bids":[["64810","0.05474837","0","3"],["64795.5","0.26486773","0","1"],["64794.6","0.00772208","0","1"],["64794.5","0.01719738","0","1"],["64794.2","0","0","0"],["64786.6","0.15443314","0","1"],["64696.3","0.00558327","0","1"],["64640.3","0","0","0"],["64640","0","0","0"],["64639.8","0","0","0"]],"ts":"1784087958602","checksum":0,"seqId":78785104698,"prevSeqId":78785104682}]}
{"arg":{"channel":"books","instId":"BTC-USDT"},"action":"update","data":[{"asks":[["64812.5","0.12327888","0","1"],["64812.7","0","0","0"]],"bids":[["64801.2","0","0","0"],["64799.4","0.12458692","0","2"],["64640.3","0.00016308","0","4"]],"ts":"1784087958702","checksum":0,"seqId":78785104708,"prevSeqId":78785104698}]}
{"arg":{"channel":"books","instId":"BTC-USDT"},"action":"update","data":[{"asks":[["64825.8","1.06691953","0","3"]],"bids":[["64794.6","0","0","0"],["64794.5","0","0","0"],["64794.2","0.00772209","0","1"],["64640","0.00438692","0","2"]],"ts":"1784087958902","checksum":0,"seqId":78785104721,"prevSeqId":78785104708}]}
{"arg":{"channel":"books","instId":"BTC-USDT"},"action":"update","data":[{"asks":[],"bids":[["64794.6","0.00772209","0","1"],["64794.5","0.01719738","0","1"],["64794.2","0","0","0"],["64655.9","0","0","0"]],"ts":"1784087959002","checksum":0,"seqId":78785104732,"prevSeqId":78785104721}]}
{"arg":{"channel":"books","instId":"BTC-USDT"},"action":"update","data":[{"asks":[],"bids":[["64794.6","0","0","0"],["64794.5","0","0","0"],["64794.2","0.00772209","0","1"],["64639.8","0.00045864","0","3"]],"ts":"1784087959102","checksum":0,"seqId":78785104740,"prevSeqId":78785104732}]}
{"arg":{"channel":"books","instId":"BTC-USDT"},"action":"update","data":[{"asks":[],"bids":[["64652.4","0.00066777","0","1"],["64639.8","0","0","0"]],"ts":"1784087959202","checksum":0,"seqId":78785104748,"prevSeqId":78785104740}]}
{"arg":{"channel":"books","instId":"BTC-USDT"},"action":"update","data":[{"asks":[["64812.7","0.12412677","0","1"],["64815.8","0.15443326","0","1"],["64816.2","0","0","0"],["64903.1","0","0","0"]],"bids":[["64803.8","0.11477473","0","1"],["64803.4","0.00116271","0","1"],["64799.4","0.00046015","0","1"],["64795.5","0","0","0"],["64794.2","0.27259192","0","2"],["64786.6","0","0","0"],["64786.3","0.15443326","0","1"]],"ts":"1784087959302","checksum":0,"seqId":78785104766,"prevSeqId":78785104748}]}
{"arg":{"channel":"books","instId":"BTC-USDT"},"action":"update","data":[{"asks":[["64813.3","0.10787903","0","2"]],"bids":[["64795.7","0.01805347","0","1"],["64786.6","0.15443322","0","1"],["64786.3","0","0","0"]],"ts":"1784087959402","checksum":0,"seqId":78785104776,"prevSeqId":78785104766}]}
{"arg":{"channel":"books","instId":"BTC-USDT"},"action":"update","data":[{"asks":[["64815.8","0","0","0"],["64816","0.1544332","0","1"]],"bids":[["64710.8","0.00309066","0","2"],["64710.4","0","0","0"]],"ts":"1784087959502","checksum":0,"seqId":78785104789,"prevSeqId":78785104776}]}
{"arg":{"channel":"books","instId":"BTC-USDT"},"action":"update","data":[{"asks":[["64812.7","0","0","0"],["64903.1","0.00002503","0","1"]],"bids":[["64810","0.05344837","0","2"],["64805.3","0.04621407","0","1"],["64803.5","0.00007904","0","1"],["64801.2","0.12412677","0","1"],["64799.4","0.11597912","0","2"],["64794.5","0.01719738","0","1"],["64640.3","0","0","0"],["64640","0","0","0"]],"ts":"1784087959602","checksum":0,"seqId":78785104800,"prevSeqId":78785104789}]}
{"arg":{"channel":"books","instId":"BTC-USDT"},"action":"update","data":[{"asks":[],"bids":[["64805.3","0.18909644","0","2"],["64803.5","0","0","0"],["64803.4","0.00124202","0","2"],["64799.4","0.00046015","0","1"],["64794.5","0","0","0"],["64640.3","0.00016308","0","4"],["64640","0.00438692","0","2"]],"ts":"1784087959702","checksum":0,"seqId":78785104812,"prevSeqId":78785104800}]}
{"arg":{"channel":"books","instId":"BTC-USDT"},"action":"update","data":[{"asks":[["64813.3","0.06287589","0","1"],["64816","0","0","0"],["64816.2","0.15443319","0","1"],["64843.3","0.0477","0","1"],["64850.4","0","0","0"]],"bids":[],"ts":"1784087959802","checksum":0,"seqId":78785104823,"prevSeqId":78785104812}]}
{"arg":{"channel":"books","instId":"BTC-USDT"},"action":"update","data":[{"asks":[["64812.7","0.11385284","0","1"],["64828.1","0.02931816","0","1"],["64902.8","0","0","0"],["64903.1","0","0","0"]],"bids":[["64797.1","0.36103061","0","2"],["64789.2","1.21375854","0","3"]],"ts":"1784087959902","checksum":0,"seqId":78785104835,"prevSeqId":78785104823}]}
{"arg":{"channel":"books","instId":"BTC-USDT"},"action":"update","data":[{"asks":[["64812.6","0.30957429","0","1"],["64813.3","0.1406865","0","2"],["64815.5","0.02316212","0","1"],["64815.8","0.15443328","0","1"],["64815.9","0","0","0"],["64816.2","0","0","0"],["64817.8","0","0","0"],["64819","0.02326085","0","1"],["64825.8","0.42938725","0","2"],["64827.4","0","0","0"],["64877.1","0","0","0"],["64902.8","0.00002164","0","1"]],"bids":[["64807.6","0","0","0"],["64805.4","0.12412677","0","1"],["64805.3","0.04621407","0","1"],["64805.2","0.00208352","0","2"],["64803.8","0","0","0"],["64801.2","0","0","0"],["64799.3","0","0","0"],["64798.1","0.40569462","0","2"],["64797.2","0","0","0"],["64797.1","1.02555082","0","2"],["64795.9","0","0","0"],["64794.5","0.17105833","0","1"],["64794.2","0.00772209","0","1"],["64792.9","0.26487891","0","1"],["64792.3","0","0","0"],["64791.1","0.08","0","1"],["64789.9","0","0","0"],["64786.6","0","0","0"],["64785.3","0.15443328","0","1"],["64782.8","0.00013331","0","3"],["64776.9","0","0","0"],["64639.8","0.00045864","0","3"],["64639.4","0.00046015","0","1"],["64639.1","0.00034809","0","1"],["64638.5","0.00002272","0","1"]],"ts":"1784087960002","checksum":0,"seqId":78785104907,"prevSeqId":78785104835}]}
{"arg":{"channel":"books","instId":"BTC-USDT"},"action":"update","data":[{"asks":[["64815.4","0.15443449","0","1"],["64815.8","0","0","0"]],"bids":[["64804","0.12412677","0","1"],["64798.4","0.12412677","0","1"],["64796.1","0.4058987","0","1"],["64796","0","0","0"],["64795.6","0.17105553","0","1"],["64794.5","0","0","0"],["64792.9","0.26487879","0","1"],["64638.5","0","0","0"]],"ts":"1784087960102","checksum":0,"seqId":78785104927,"prevSeqId":78785104907}]}
{"arg":{"channel":"books","instId":"BTC-USDT"},"action":"update","data":[{"asks":[["64815.4","0.1544342","0","1"],["64829.4","1.79230351","0","1"],["64829.5","2.27909022","0","1"],["64902.8","0","0","0"]],"bids":[["64793.4","1.02041286","0","2"],["64791","2.12035665","0","2"],["64785.3","0.1544342","0","1"],["64782.8","0.00018054","0","4"],["64754.3","0","0","0"],["64638.5","0.00002272","0","1"]],"ts":"1784087960202","checksum":0,"seqId":78785104949,"prevSeqId":78785104927}]}
{"arg":{"channel":"books","instId":"BTC-USDT"},"action":"update","data":[{"asks":[["64815.4","0","0","0"],["64816","0.15443406","0","1"],["64827.3","2.27909022","0","1"],["64829.5","0","0","0"],["64850.9","0.00005249","0","3"]],"bids":[["64794.3","0.00772237","0","1"],["64794.2","0.01719738","0","1"],["64793.6","0.26487582","0","1"],["64792.9","0","0","0"],["64786.3","0.15443406","0","1"],["64785.3","0","0","0"],["64754.3","0.00382213","0","1"],["64639.1","0","0","0"],["64638.5","0","0","0"]],"ts":"1784087960302","checksum":0,"seqId":78785104972,"prevSeqId":78785104949}]}
{"arg":{"channel":"books","instId":"BTC-USDT"},"action":"update","data":[{"asks":[["64829.4","0","0","0"],["64873.6","0.96874387","0","2"],["64902.8","0.00002164","0","1"]],"bids":[["64794.4","0.00772232","0","1"],["64794.3","0","0","0"],["64794.2","0","0","0"],["64791.2","0.02326085","0","1"]],"ts":"1784087960402","checksum":0,"seqId":78785104986,"prevSeqId":78785104972}]}
{"arg":{"channel":"books","instId":"BTC-USDT"},"action":"update","data":[{"asks":[["64850.9","0.00006386","0","4"]],"bids":[["64794.4","0","0","0"],["64794.2","0.00772231","0","1"],["64776.7","0.03018119","0","1"],["64639.4","0","0","0"]],"ts":"1784087960502","checksum":0,"seqId":78785105006,"prevSeqId":78785104986}]}
{"arg":{"channel":"books","instId":"BTC-USDT"},"action":"update","data":[{"asks":[],"bids":[["64794.2","0.02491981","0","2"]],"ts":"1784087960702","checksum":0,"seqId":78785105016,"prevSeqId":78785105006}]}
{"arg":{"channel":"books","instId":"BTC-USDT"},"action":"update","data":[{"asks":[],"bids":[["64794.2","0.00772231","0","1"]],"ts":"1784087960802","checksum":0,"seqId":78785105022,"prevSeqId":78785105016}]}
{"arg":{"channel":"books","instId":"BTC-USDT"},"action":"update","data":[{"asks":[],"bids":[["64793.6","0","0","0"],["64792.9","0.26487704","0","1"]],"ts":"1784087961002","checksum":0,"seqId":78785105037,"prevSeqId":78785105022}]}
{"arg":{"channel":"books","instId":"BTC-USDT"},"action":"update","data":[{"asks":[["64812.7","0","0","0"],["64815.5","0","0","0"],["64817.4","0.02316144","0","1"],["64903.1","0.00002503","0","1"]],"bids":[["64807.6","0.12174446","0","1"],["64797.1","1.33512511","0","3"],["64794.2","0.27259419","0","2"],["64792.9","0","0","0"],["64786.6","0.15443343","0","1"],["64786.3","0","0","0"],["64782.7","0.00003674","0","1"],["64639.8","0","0","0"]],"ts":"1784087961102","checksum":0,"seqId":78785105055,"prevSeqId":78785105037}]}
{"arg":{"channel":"books","instId":"BTC-USDT"},"action":"update","data":[{"asks":[],"bids":[["64794.2","0.02491981","0","2"],["64793.6","0.26487363","0","1"],["64640","0","0","0"]],"ts":"1784087961202","checksum":0,"seqId":78785105062,"prevSeqId":78785105055}]}
{"arg":{"channel":"books","instId":"BTC-USDT"},"action":"update","data":[{"asks":[],"bids":[["64794.2","0.28979341","0","3"],["64793.6","0","0","0"],["64640","0.00438692","0","2"]],"ts":"1784087961302","checksum":0,"seqId":78785105070,"prevSeqId":78785105062}]}
{"arg":{"channel":"books","instId":"BTC-USDT"},"action":"update","data":[{"asks":[["64812.7","0.11445467","0","1"],["64903.1","0","0","0"]],"bids":[["64807.6","0","0","0"],["64639.8","0.00045864","0","3"]],"ts":"1784087961502","checksum":0,"seqId":78785105083,"prevSeqId":78785105070}]}
{"arg":{"channel":"books","instId":"BTC-USDT"},"action":"update","data":[{"asks":[],"bids":[["64794.2","0.02491981","0","2"],["64793.6","0.26487445","0","1"],["64782.8","0.00013331","0","3"],["64782.7","0","0","0"]],"ts":"1784087961602","checksum":0,"seqId":78785105093,"prevSeqId":78785105083}]}
{"arg":{"channel":"books","instId":"BTC-USDT"},"action":"update","data":[{"asks":[["64850.9","0.00005249","0","3"],["64889.5","0.009261","0","1"],["64897","0.00017295","0","1"],["64902.8","0","0","0"]],"bids":[],"ts":"1784087961702","checksum":0,"seqId":78785105100,"prevSeqId":78785105093}]}
{"arg":{"channel":"books","instId":"BTC-USDT"},"action":"update","data":[{"asks":[],"bids":[["64782.8","0.00009027","0","2"]],"ts":"1784087961802","checksum":0,"seqId":78785105105,"prevSeqId":78785105100}]}
{"arg":{"channel":"books","instId":"BTC-USDT"},"action":"update","data":[{"asks":[],"bids":[["64794.2","0.00772231","0","1"]],"ts":"1784087961902","checksum":0,"seqId":78785105110,"prevSeqId":78785105105}]}
{"arg":{"channel":"books","instId":"BTC-USDT"},"action":"update","data":[{"asks":[],"bids":[["64802.7","0.1080202","0","1"],["64802.4","0","0","0"],["64794.2","0.02491981","0","2"],["64782.7","0.00003674","0","1"],["64639.8","0","0","0"]],"ts":"1784087962002","checksum":0,"seqId":78785105120,"prevSeqId":78785105110}]}
{"arg":{"channel":"books","instId":"BTC-USDT"},"action":"update","data":[{"asks":[["64829.9","1.05692183","0","1"],["64873.6","0.05069934","0","1"],["64902.5","0","0","0"]],"bids":[["64803.7","0.08856","0","1"],["64794.3","0.00772218","0","1"],["64794.2","0.26487105","0","1"],["64793.6","0","0","0"]],"ts":"1784087962102","checksum":0,"seqId":78785105141,"prevSeqId":78785105120}]}
{"arg":{"channel":"books","instId":"BTC-USDT"},"action":"update","data":[{"asks":[["64841.3","0.00805561","0","1"],["64843.4","0","0","0"]],"bids":[["64801.2","0.12412677","0","1"],["64794.2","0.28206855","0","2"],["64640","0","0","0"]],"ts":"1784087962202","checksum":0,"seqId":78785105151,"prevSeqId":78785105141}]}
{"arg":{"channel":"books","instId":"BTC-USDT"},"action":"update","data":[{"asks":[],"bids":[["64803.4","0.00116271","0","1"],["64801.6","0.00009527","0","2"]],"ts":"1784087962302","checksum":0,"seqId":78785105160,"prevSeqId":78785105151}]}
{"arg":{"channel":"books","instId":"BTC-USDT"},"action":"update","data":[{"asks":[],"bids":[["64794.2","0.26487105","0","1"],["64782.8","0.00004723","0","1"],["64782.7","0.00012701","0","3"]],"ts":"1784087962502","checksum":0,"seqId":78785105174,"prevSeqId":78785105160}]}
{"arg":{"channel":"books","instId":"BTC-USDT"},"action":"update","data":[{"asks":[],"bids":[["64782.8","0","0","0"],["64782.7","0.00017424","0","4"],["64640","0.00438692","0","2"]],"ts":"1784087962602","checksum":0,"seqId":78785105183,"prevSeqId":78785105174}]}
{"arg":{"channel":"books","instId":"BTC-USDT"},"action":"update","data":[{"asks":[],"bids":[["64795.5","0.2648681","0","1"],["64794.2","0.0171975","0","1"],["64640","0","0","0"]],"ts":"1784087962702","checksum":0,"seqId":78785105190,"prevSeqId":78785105183}]}
{"arg":{"channel":"books","instId":"BTC-USDT"},"action":"update","data":[{"asks":[],"bids":[["64795.5","0","0","0"],["64794.2","0.26486838","0","1"],["64793.5","0","0","0"],["64791.9","0.04","0","1"],["64640","0.00438692","0","2"]],"ts":"1784087962802","checksum":0,"seqId":78785105202,"prevSeqId":78785105190}]}
{"arg":{"channel":"books","instId":"BTC-USDT"},"action":"update","data":[{"asks":[["64825.8","1.075671","0","3"]],"bids":[["64801.2","0","0","0"],["64794.3","0","0","0"],["64794.2","0.00772227","0","1"],["64793.5","0.26487361","0","1"],["64786.6","0","0","0"],["64786.3","0.15443339","0","1"],["64639.8","0.00045864","0","3"]],"ts":"1784087963102","checksum":0,"seqId":78785105232,"prevSeqId":78785105202}]}
{"arg":{"channel":"books","instId":"BTC-USDT"},"action":"update","data":[{"asks":[],"bids":[["64805.4","0","0","0"],["64805.2","0.11970666","0","3"],["64801.2","0.12412677","0","1"],["64794.2","0.02491977","0","2"]],"ts":"1784087963302","checksum":0,"seqId":78785105248,"prevSeqId":78785105232}]}
{"arg":{"channel":"books","instId":"BTC-USDT"},"action":"update","data":[{"asks":[["64812.7","0","0","0"],["64816","0","0","0"],["64816.2","0.15443357","0","1"],["64819.1","0.00001501","0","1"],["64824.7","0.12035646","0","1"]],"bids":[["64807.6","0.11236856","0","1"],["64803.5","0.1845","0","1"],["64801.2","0","0","0"],["64798.6","0.02316108","0","1"],["64798.1","0.40924718","0","2"],["64797.1","1.02555082","0","2"],["64796.7","0","0","0"],["64794.2","0.98181677","0","2"],["64794.1","0","0","0"],["64793.5","0.26487319","0","1"],["64786.6","0.15443357","0","1"],["64786.3","0","0","0"]],"ts":"1784087963402","checksum":0,"seqId":78785105279,"prevSeqId":78785105248}]}
{"arg":{"channel":"books","instId":"BTC-USDT"},"action":"update","data":[{"asks":[["64812.4","0.9740945","0","1"],["64812.5","0","0","0"],["64812.6","0","0","0"],["64812.8","0","0","0"],["64813.3","0.06287589","0","1"],["64816.2","0","0","0"],["64818.8","0.15443205","0","1"],["64825.8","0.42938725","0","2"],["64827.3","0","0","0"],["64846.8","0.32587","0","1"],["64851.2","0.46259771","0","1"],["64873.6","0.10577259","0","2"],["64902.5","0.0000415","0","1"],["64902.8","0.00002164","0","1"]],"bids":[["64810","0.20673406","0","5"],["64805.3","0.20086294","0","2"],["64801.2","0.11239358","0","1"],["64797.1","1.33512511","0","3"],["64796.6","0.0077221","0","1"],["64795.7","0.28292062","0","2"],["64794.2","0.991292","0","2"],["64793.5","0","0","0"],["64786.6","0.15443189","0","1"],["64639.8","0","0","0"]],"ts":"1784087963502","checksum":0,"seqId":78785105327,"prevSeqId":78785105279}]}
{"arg":{"channel":"books","instId":"BTC-USDT"},"action":"update","data":[{"asks":[["64817.3","0.15443166","0","1"],["64818.7","0.03555837","0","1"],["64818.8","0","0","0"],["64818.9","0","0","0"],["64829.5","2.27894762","0","1"],["64850.9","0.00006386","0","4"],["64902.8","0","0","0"]],"bids":[["64796.6","0","0","0"],["64795.7","0.29064257","0","3"],["64794.2","0.9740945","0","1"],["64639.8","0.00045864","0","3"]],"ts":"1784087963602","checksum":0,"seqId":78785105345,"prevSeqId":78785105327}]}
{"arg":{"channel":"books","instId":"BTC-USDT"},"action":"update","data":[{"asks":[],"bids":[["64795.7","0.28292062","0","2"],["64794.3","0.00772201","0","1"],["64794.2","0.991292","0","2"],["64794","2.0000155","0","2"],["64660.5","0.20867383","0","2"],["64639.8","0","0","0"]],"ts":"1784087963702","checksum":0,"seqId":78785105356,"prevSeqId":78785105345}]}
{"arg":{"channel":"books","instId":"BTC-USDT"},"action":"update","data":[{"asks":[["64816.6","0.82035855","0","4"],["64817.3","0","0","0"],["64902.8","0.00002164","0","1"]],"bids":[["64805.5","0.158674","0","1"],["64796.1","1.03520163","0","2"],["64794.2","0.9740945","0","1"],["64793.4","0.52436956","0","1"],["64791","0.12035665","0","1"],["64789.2","1.18471831","0","2"],["64640","0","0","0"]],"ts":"1784087963802","checksum":0,"seqId":78785105368,"prevSeqId":78785105356}]}
{"arg":{"channel":"books","instId":"BTC-USDT"},"action":"update","data":[{"asks":[["64811.2","0.12412677","0","1"],["64813.3","0.10093546","0","2"],["64816","0.15443259","0","1"],["64816.6","0.6659261","0","3"],["64902.5","0","0","0"],["64902.8","0","0","0"]],"bids":[["64810","0.05474837","0","3"],["64807.7","0.12412677","0","1"],["64807.6","0","0","0"],["64805.6","0.12412677","0","1"],["64805.2","0.00208352","0","2"],["64804.1","0.12414227","0","2"],["64804","0","0","0"],["64801.2","0","0","0"],["64798.4","0","0","0"],["64795.7","0.01805347","0","1"],["64795.5","0.26486826","0","1"],["64794.2","0.991292","0","2"],["64786.6","0","0","0"],["64786.2","0.28954816","0","2"],["64786.1","0.7673092","0","2"],["64779.3","0.05515503","0","2"],["64660.5","0.1845","0","1"],["64640","0.00438692","0","2"],["64639.8","0.00045864","0","3"]],"ts":"1784087963902","checksum":0,"seqId":78785105397,"prevSeqId":78785105368}]}
{"arg":{"channel":"books","instId":"BTC-USDT"},"action":"update","data":[{"asks":[],"bids":[["64798.4","0.12412677","0","1"],["64794.2","0.9740945","0","1"],["64639.8","0","0","0"]],"ts":"1784087964002","checksum":0,"seqId":78785105403,"prevSeqId":78785105397}]}
{"arg":{"channel":"books","instId":"BTC-USDT"},"action":"update","data":[{"asks":[["64811.2","0","0","0"],["64813.3","0.06287589","0","1"],["64816","0","0","0"],["64817","0.15443304","0","1"],["64829.4","1.79226094","0","1"],["64829.9","0","0","0"],["64902.5","0.0000415","0","1"]],"bids":[["64810","0.16458837","0","4"],["64798.5","0.12412677","0","1"],["64798.4","0","0","0"],["64796.2","0.26486394","0","1"],["64795.5","0","0","0"],["64794.3","0.00772203","0","1"],["64786.6","0.15443304","0","1"],["64786.2","0.13511557","0","1"],["64782.7","0.0001312","0","3"],["64640","0","0","0"]],"ts":"1784087964102","checksum":0,"seqId":78785105437,"prevSeqId":78785105403}]}
{"arg":{"channel":"books","instId":"BTC-USDT"},"action":"update","data":[{"asks":[["64816.3","1.1285275","0","2"],["64817","0","0","0"],["64902.8","0.00002164","0","1"]],"bids":[["64696.3","0","0","0"],["64640","0.00438692","0","2"]],"ts":"1784087964302","checksum":0,"seqId":78785105453,"prevSeqId":78785105437}]}
{"arg":{"channel":"books","instId":"BTC-USDT"},"action":"update","data":[{"asks":[],"bids":[["64797","0.66708881","0","4"],["64784","0.51549048","0","4"]],"ts":"1784087964402","checksum":0,"seqId":78785105461,"prevSeqId":78785105453}]}
{"arg":{"channel":"books","instId":"BTC-USDT"},"action":"update","data":[{"asks":[],"bids":[["64711.3","0.00309064","0","2"],["64710.8","0","0","0"]],"ts":"1784087964502","checksum":0,"seqId":78785105469,"prevSeqId":78785105461}]}
{"arg":{"channel":"books","instId":"BTC-USDT"},"action":"update","data":[{"asks":[],"bids":[["64810","0.19158837","0","5"],["64798.1","0.62440521","0","1"],["64796.7","0.1474575","0","1"],["64796.2","0.26486509","0","1"],["64795.6","0","0","0"],["64794.2","0.991292","0","2"],["64698.1","0.00561061","0","3"]],"ts":"1784087964602","checksum":0,"seqId":78785105487,"prevSeqId":78785105469}]}
{"arg":{"channel":"books","instId":"BTC-USDT"},"action":"update","data":[{"asks":[],"bids":[["64797.1","1.59998666","0","4"],["64796.2","0","0","0"],["64639.8","0.00045864","0","3"]],"ts":"1784087964702","checksum":0,"seqId":78785105494,"prevSeqId":78785105487}]}
{"arg":{"channel":"books","instId":"BTC-USDT"},"action":"update","data":[{"asks":[],"bids":[["64794.2","0.9740945","0","1"]],"ts":"1784087964802","checksum":0,"seqId":78785105499,"prevSeqId":78785105494}]}
{"arg":{"channel":"books","instId":"BTC-USDT"},"action":"update","data":[{"asks":[],"bids":[["64810","0.16458837","0","4"],["64789.1","0.02920525","0","1"],["64639.8","0","0","0"]],"ts":"1784087964902","checksum":0,"seqId":78785105509,"prevSeqId":78785105499}]}
{"arg":{"channel":"books","instId":"BTC-USDT"},"action":"update","data":[{"asks":[["64850.9","0.00007523","0","5"]],"bids":[["64810","0.19158837","0","5"],["64797.1","1.33512511","0","3"],["64797","0.42637565","0","3"],["64796.8","0.26486224","0","1"],["64794.2","0.991292","0","2"],["64640","0","0","0"]],"ts":"1784087965002","checksum":0,"seqId":78785105519,"prevSeqId":78785105509}]}
{"arg":{"channel":"books","instId":"BTC-USDT"},"action":"update","data":[{"asks":[["64816.1","0.53643664","0","1"],["64816.3","0.9740945","0","1"],["64817.1","0","0","0"],["64817.3","0.1544327","0","1"],["64822.4","0.21062381","0","1"],["64823.1","0.58156992","0","4"],["64850.9","0.0000866","0","6"],["64902.8","0","0","0"]],"bids":[["64801.2","0.11101132","0","1"],["64795.5","0.00772183","0","1"],["64794.3","0","0","0"],["64794.2","0.9740945","0","1"],["64784","0.75620364","0","5"],["64640.3","0","0","0"]],"ts":"1784087965102","checksum":0,"seqId":78785105542,"prevSeqId":78785105519}]}
{"arg":{"channel":"books","instId":"BTC-USDT"},"action":"update","data":[{"asks":[["64816.6","0.8203583","0","4"],["64817.3","0","0","0"],["64902.8","0.00002164","0","1"]],"bids":[["64795.5","0","0","0"],["64794.3","0.00772183","0","1"],["64782.7","0.00009446","0","2"]],"ts":"1784087965202","checksum":0,"seqId":78785105553,"prevSeqId":78785105542}]}
{"arg":{"channel":"books","instId":"BTC-USDT"},"action":"update","data":[{"asks":[],"bids":[["64798.2","0.2648572","0","1"],["64796.8","0","0","0"],["64794.3","0.0077218","0","1"]],"ts":"1784087965302","checksum":0,"seqId":78785105565,"prevSeqId":78785105553}]}
{"arg":{"channel":"books","instId":"BTC-USDT"},"action":"update","data":[{"asks":[],"bids":[["64801.2","0.12412677","0","1"],["64798.7","0.12412677","0","1"],["64798.5","0","0","0"],["64798.2","0.26485702","0","1"],["64794.2","0.991292","0","2"]],"ts":"1784087965402","checksum":0,"seqId":78785105584,"prevSeqId":78785105565}]}
{"arg":{"channel":"books","instId":"BTC-USDT"},"action":"update","data":[{"asks":[],"bids":[["64794.2","0.9740945","0","1"]],"ts":"1784087965502","checksum":0,"seqId":78785105590,"prevSeqId":78785105584}]}
{"arg":{"channel":"books","instId":"BTC-USDT"},"action":"update","data":[{"asks":[],"bids":[["64797","0.66708881","0","4"],["64794.2","0.991292","0","2"],["64784","0.51549048","0","4"],["64782.7","0.00004723","0","1"]],"ts":"1784087965602","checksum":0,"seqId":78785105598,"prevSeqId":78785105590}]}
{"arg":{"channel":"books","instId":"BTC-USDT"},"action":"update","data":[{"asks":[],"bids":[["64810","0.34851337","0","6"],["64805.5","0","0","0"],["64640.3","0.00016308","0","4"]],"ts":"1784087965702","checksum":0,"seqId":78785105606,"prevSeqId":78785105598}]}
{"arg":{"channel":"books","instId":"BTC-USDT"},"action":"update","data":[{"asks":[],"bids":[["64798.2","0","0","0"],["64797.2","0.26485727","0","1"]],"ts":"1784087965802","checksum":0,"seqId":78785105613,"prevSeqId":78785105606}]}
{"arg":{"channel":"books","instId":"BTC-USDT"},"action":"update","data":[{"asks":[["64816.6","0.6659261","0","3"],["64817.1","0.15443157","0","1"],["64902.8","0","0","0"]],"bids":[["64795.5","0.0077218","0","1"],["64794.3","0","0","0"],["64794.2","0.9740945","0","1"]],"ts":"1784087965902","checksum":0,"seqId":78785105622,"prevSeqId":78785105613}]}
{"arg":{"channel":"trades","instId":"BTC-USDT"},"data":[{"instId":"BTC-USDT","tradeId":"1033093073","px":"64810.1","sz":"0.04611782","side":"buy","ts":"1784087965973","count":"1","source":"0","seqId":78785105629}]}
{"arg":{"channel":"books","instId":"BTC-USDT"},"action":"update","data":[{"asks":[["64810.1","1.93888868","0","12"],["64813.3","0","0","0"],["64813.4","0","0","0"],["64816.6","0.63583717","0","3"],["64823.1","0.82228286","0","5"],["64902.8","0.00002164","0","1"],["64903.1","0.00002503","0","1"]],"bids":[["64810","0.48171209","0","7"],["64794.2","0.991292","0","2"]],"ts":"1784087966002","checksum":0,"seqId":78785105638,"prevSeqId":78785105622}]}
{"arg":{"channel":"books","instId":"BTC-USDT"},"action":"update","data":[{"asks":[],"bids":[["64801.2","0","0","0"],["64798.7","0","0","0"],["64798.4","0.12412677","0","1"],["64795.5","0.00772182","0","1"],["64794.2","0.9740945","0","1"],["64640","0.00438692","0","2"]],"ts":"1784087966102","checksum":0,"seqId":78785105654,"prevSeqId":78785105638}]}
{"arg":{"channel":"books","instId":"BTC-USDT"},"action":"update","data":[{"asks":[],"bids":[["64798.5","0.26485576","0","1"],["64797.2","0","0","0"],["64795.8","0.00772176","0","1"],["64795.5","0","0","0"],["64794.2","0.991292","0","2"],["64782.7","0","0","0"],["64639.8","0.00045864","0","3"]],"ts":"1784087966202","checksum":0,"seqId":78785105667,"prevSeqId":78785105654}]}
{"arg":{"channel":"books","instId":"BTC-USDT"},"action":"update","data":[{"asks":[["64817.1","0","0","0"],["64817.3","0.15443086","0","1"]],"bids":[],"ts":"1784087966402","checksum":0,"seqId":78785105682,"prevSeqId":78785105667}]}
{"arg":{"channel":"books","instId":"BTC-USDT"},"action":"update","data":[{"asks":[["64816.8","0.358104","0","1"],["64817.1","0.15443082","0","1"],["64817.3","0","0","0"],["64823.9","0.01982816","0","1"],["64903.1","0","0","0"]],"bids":[["64798.5","0.2648549","0","1"],["64782.7","0.00004304","0","1"],["64639.8","0","0","0"]],"ts":"1784087966502","checksum":0,"seqId":78785105695,"prevSeqId":78785105682}]}
{"arg":{"channel":"books","instId":"BTC-USDT"},"action":"update","data":[{"asks":[["64817.1","0","0","0"],["64817.4","0","0","0"],["64818.6","0.15443081","0","1"],["64819.4","0.38229787","0","2"],["64903.1","0.00002503","0","1"]],"bids":[["64801.2","0.12143342","0","1"],["64800.7","0.02316047","0","1"],["64798.6","0.12356783","0","1"],["64798.4","0","0","0"],["64795.9","0.00772169","0","1"],["64795.8","0","0","0"],["64640","0","0","0"]],"ts":"1784087966602","checksum":0,"seqId":78785105718,"prevSeqId":78785105695}]}
{"arg":{"channel":"books","instId":"BTC-USDT"},"action":"update","data":[{"asks":[],"bids":[["64798.6","0","0","0"],["64798.5","0","0","0"],["64798.4","0.26485564","0","1"],["64795.9","0","0","0"],["64795.8","0.0077217","0","1"],["64794.2","0.9740945","0","1"],["64640","0.00438692","0","2"]],"ts":"1784087966702","checksum":0,"seqId":78785105732,"prevSeqId":78785105718}]}
{"arg":{"channel":"books","instId":"BTC-USDT"},"action":"update","data":[{"asks":[["64817.1","0.15443075","0","1"],["64818.6","0","0","0"]],"bids":[["64794.2","0.99129202","0","2"]],"ts":"1784087966802","checksum":0,"seqId":78785105743,"prevSeqId":78785105732}]}
{"arg":{"channel":"books","instId":"BTC-USDT"},"action":"update","data":[{"asks":[["64850.9","0.00009797","0","7"]],"bids":[["64798.5","0.12412677","0","1"],["64794.2","0.9740945","0","1"],["64640","0","0","0"]],"ts":"1784087967002","checksum":0,"seqId":78785105758,"prevSeqId":78785105743}]}
{"arg":{"channel":"books","instId":"BTC-USDT"},"action":"update","data":[{"asks":[],"bids":[["64660.2","0.02417383","0","1"],["64640.3","0","0","0"]],"ts":"1784087967102","checksum":0,"seqId":78785105767,"prevSeqId":78785105758}]}
{"arg":{"channel":"books","instId":"BTC-USDT"},"action":"update","data":[{"asks":[],"bids":[["64798.5","0","0","0"],["64798.4","0.26485281","0","1"],["64794.2","0.99129202","0","2"],["64782.7","0.00008608","0","2"],["64640.3","0.00016308","0","4"]],"ts":"1784087967202","checksum":0,"seqId":78785105778,"prevSeqId":78785105767}]}
{"arg":{"channel":"books","instId":"BTC-USDT"},"action":"update","data":[{"asks":[],"bids":[["64801.2","0","0","0"],["64798.5","0.12412677","0","1"],["64794.2","0.9740945","0","1"]],"ts":"1784087967302","checksum":0,"seqId":78785105792,"prevSeqId":78785105778}]}
{"arg":{"channel":"books","instId":"BTC-USDT"},"action":"update","data":[{"asks":[],"bids":[["64799.2","0","0","0"],["64797.1","1.41233651","0","4"],["64786.2","0","0","0"],["64784.1","0.13511995","0","1"],["64640","0.00438692","0","2"]],"ts":"1784087967602","checksum":0,"seqId":78785105809,"prevSeqId":78785105792}]}
{"arg":{"channel":"books","instId":"BTC-USDT"},"action":"update","data":[{"asks":[["64816.7","0.22157649","0","3"],["64817.1","0","0","0"],["64903.2","0.32881826","0","6"]],"bids":[["64810","0.34860012","0","7"],["64801.2","0.12412677","0","1"],["64799.2","0.0772089","0","1"],["64798.4","0","0","0"],["64798.2","0.26485721","0","1"],["64797.1","1.33512511","0","3"],["64795.8","0","0","0"],["64795.5","0.00772174","0","1"],["64794.2","0.99129202","0","2"],["64786.2","0.13511557","0","1"],["64784.1","0","0","0"],["64724.7","0","0","0"],["64640","0","0","0"]],"ts":"1784087967702","checksum":0,"seqId":78785105834,"prevSeqId":78785105809}]}
{"arg":{"channel":"books","instId":"BTC-USDT"},"action":"update","data":[{"asks":[],"bids":[["64810","0.19167512","0","6"],["64806.6","0.15867371","0","2"],["64795.5","0","0","0"],["64794.3","0.00772176","0","1"],["64794.2","0.9740945","0","1"],["64790.6","0.03857426","0","1"],["64640.3","0","0","0"]],"ts":"1784087967802","checksum":0,"seqId":78785105846,"prevSeqId":78785105834}]}
{"arg":{"channel":"books","instId":"BTC-USDT"},"action":"update","data":[{"asks":[["64816.2","0.1544315","0","1"],["64816.7","0.0671455","0","2"],["64903.2","0","0","0"]],"bids":[["64801.2","0","0","0"],["64798.5","0","0","0"],["64798.2","0","0","0"],["64797.2","0.26485748","0","1"],["64794.4","0.00772175","0","1"],["64794.3","0","0","0"],["64640.3","0.00016308","0","4"],["64640","0.00438692","0","2"]],"ts":"1784087967902","checksum":0,"seqId":78785105860,"prevSeqId":78785105846}]}
{"arg":{"channel":"books","instId":"BTC-USDT"},"action":"update","data":[{"asks":[["64816.2","0","0","0"],["64816.5","0.15443154","0","1"],["64851","0.00056237","0","14"]],"bids":[["64802.9","0.10801986","0","1"],["64802.7","0","0","0"],["64798.4","0.11936683","0","1"],["64798.2","0.26485721","0","1"],["64797.2","0","0","0"],["64794.2","0.99129202","0","2"],["64761","0.00382206","0","1"],["64754.3","0","0","0"],["64640","0","0","0"]],"ts":"1784087968002","checksum":0,"seqId":78785105878,"prevSeqId":78785105860}]}
{"arg":{"channel":"books","instId":"BTC-USDT"},"action":"update","data":[{"asks":[],"bids":[["64798.2","0","0","0"],["64797.2","0.26485722","0","1"],["64794.4","0","0","0"],["64794.3","0.0077218","0","1"],["64794.2","0.9740945","0","1"]],"ts":"1784087968102","checksum":0,"seqId":78785105896,"prevSeqId":78785105878}]}
{"arg":{"channel":"books","instId":"BTC-USDT"},"action":"update","data":[{"asks":[["64816.5","0","0","0"],["64816.6","0.79026873","0","4"],["64903.2","0.32881826","0","6"]],"bids":[["64798.2","0.2648572","0","1"],["64797.2","0","0","0"],["64761.1","0.00382206","0","1"],["64761","0","0","0"]],"ts":"1784087968202","checksum":0,"seqId":78785105907,"prevSeqId":78785105896}]}
{"arg":{"channel":"books","instId":"BTC-USDT"},"action":"update","data":[{"asks":[],"bids":[["64801.2","0.11383704","0","1"],["64795.5","0.00772175","0","1"],["64794.3","0","0","0"],["64640.3","0","0","0"]],"ts":"1784087968302","checksum":0,"seqId":78785105918,"prevSeqId":78785105907}]}
{"arg":{"channel":"books","instId":"BTC-USDT"},"action":"update","data":[{"asks":[],"bids":[["64798.5","0.26485598","0","1"],["64798.4","0","0","0"],["64798.2","0","0","0"],["64795.5","0","0","0"],["64794.3","0.00772175","0","1"],["64640.3","0.00016308","0","4"]],"ts":"1784087968402","checksum":0,"seqId":78785105929,"prevSeqId":78785105918}]}
{"arg":{"channel":"books","instId":"BTC-USDT"},"action":"update","data":[{"asks":[["64810.1","1.92988868","0","11"],["64816.6","0.63583717","0","3"],["64818.6","0.15443155","0","1"],["64903.2","0","0","0"]],"bids":[["64810","0.30955904","0","7"],["64798.7","0.26485275","0","1"],["64798.6","0.12412677","0","1"],["64798.5","0","0","0"],["64796.2","0.00772173","0","1"],["64794.3","0","0","0"],["64794.2","0.99129202","0","2"],["64640.3","0","0","0"]],"ts":"1784087968502","checksum":0,"seqId":78785105955,"prevSeqId":78785105929}]}
{"arg":{"channel":"books","instId":"BTC-USDT"},"action":"update","data":[{"asks":[],"bids":[["64798.8","0.12412677","0","1"],["64798.6","0","0","0"],["64796.2","0","0","0"],["64795.8","0.00772167","0","1"]],"ts":"1784087968602","checksum":0,"seqId":78785105964,"prevSeqId":78785105955}]}
{"arg":{"channel":"books","instId":"BTC-USDT"},"action":"update","data":[{"asks":[["64817.1","0.15443101","0","1"],["64818.6","0","0","0"]],"bids":[["64798.7","0","0","0"],["64798.4","0.26485435","0","1"]],"ts":"1784087968702","checksum":0,"seqId":78785105972,"prevSeqId":78785105964}]}
{"arg":{"channel":"trades","instId":"BTC-USDT"},"data":[{"instId":"BTC-USDT","tradeId":"1033093074","px":"64810","sz":"0.00745956","side":"sell","ts":"1784087968768","count":"1","source":"0","seqId":78785105979}]}
{"arg":{"channel":"books","instId":"BTC-USDT"},"action":"update","data":[{"asks":[],"bids":[["64810","0.30209948","0","7"],["64798.8","0","0","0"],["64795.8","0","0","0"],["64795.5","0.00772171","0","1"],["64780","0","0","0"],["64760.6","0.00116278","0","1"],["64640.3","0.00016308","0","4"],["64640","0.00438692","0","2"]],"ts":"1784087968802","checksum":0,"seqId":78785105985,"prevSeqId":78785105972}]}
{"arg":{"channel":"books","instId":"BTC-USDT"},"action":"update","data":[{"asks":[["64823.1","0.58156992","0","4"]],"bids":[["64810","0.43337548","0","7"],["64806.6","0.00116271","0","1"],["64801.2","0","0","0"],["64798.5","0.11086861","0","1"],["64798.1","0.75019573","0","2"],["64796.7","0","0","0"],["64795.8","0.00772172","0","1"],["64795.5","0","0","0"],["64780.3","0.24010065","0","1"],["64760.9","0.4076686","0","2"],["64680.5","0","0","0"],["64639.8","0.00045864","0","3"],["64639.4","0.00046015","0","1"]],"ts":"1784087968902","checksum":0,"seqId":78785106004,"prevSeqId":78785105985}]}
{"arg":{"channel":"books","instId":"BTC-USDT"},"action":"update","data":[{"asks":[["64811.2","0.12412677","0","1"],["64816.5","0.15443131","0","1"],["64816.6","0.87655011","0","4"],["64817.1","0","0","0"],["64903.1","0","0","0"]],"bids":[["64810","0.04737556","0","4"],["64807.8","0.10999081","0","1"],["64807.7","0","0","0"],["64806.2","0.158873","0","1"],["64798.5","0","0","0"],["64798.4","0","0","0"],["64797.2","0.26485822","0","1"],["64797","0.42637565","0","3"],["64795.8","0","0","0"],["64794.3","0.00772173","0","1"],["64794.2","0.9740945","0","1"],["64780.3","0.3382352","0","2"],["64779.7","0.49331325","0","1"],["64760.9","0.72933417","0","3"],["64760.2","0.99132016","0","1"],["64656.6","0","0","0"],["64639.4","0","0","0"]],"ts":"1784087969002","checksum":0,"seqId":78785106036,"prevSeqId":78785106004}]}
{"arg":{"channel":"books","instId":"BTC-USDT"},"action":"update","data":[{"asks":[["64811.2","0.11272917","0","1"],["64816.2","0.15443183","0","1"],["64816.5","0","0","0"],["64817.4","0.0231611","0","1"],["64819.4","0.3591374","0","1"],["64902.8","0","0","0"]],"bids":[["64810","0.04607556","0","3"],["64800.7","0","0","0"],["64799.1","0.0231766","0","2"],["64784","0.75620364","0","5"],["64782.7","0.00013331","0","3"],["64761.1","0","0","0"],["64761","0.00382207","0","1"],["64649.3","14.01625452","0","1"],["64647.5","0.1845","0","1"],["64639.8","0","0","0"]],"ts":"1784087969102","checksum":0,"seqId":78785106065,"prevSeqId":78785106036}]}
{"arg":{"channel":"books","instId":"BTC-USDT"},"action":"update","data":[{"asks":[],"bids":[["64798.4","0.12412677","0","1"],["64797.2","0","0","0"],["64796.2","0.26486171","0","1"],["64680.5","0.0005","0","1"],["64640.3","0","0","0"],["64640","0","0","0"]],"ts":"1784087969202","checksum":0,"seqId":78785106074,"prevSeqId":78785106065}]}
{"arg":{"channel":"books","instId":"BTC-USDT"},"action":"update","data":[{"asks":[["64812.3","0.30957429","0","1"],["64814.7","0.04609849","0","1"],["64816","0.15443373","0","1"],["64816.2","0","0","0"],["64827.3","2.27909022","0","1"],["64829.4","1.11199508","0","1"],["64829.5","0","0","0"],["64901.9","0","0","0"],["64902.5","0","0","0"]],"bids":[["64807.8","0","0","0"],["64805.6","0","0","0"],["64805.3","0.04621407","0","1"],["64805.2","0.12621029","0","3"],["64804.1","0.0000155","0","1"],["64803.5","0","0","0"],["64803.1","0.12412677","0","1"],["64801.2","0.12412677","0","1"],["64798.1","0.14263732","0","1"],["64797.1","0.05145632","0","1"],["64796.7","0.17062044","0","1"],["64796.2","0","0","0"],["64796.1","0.68593719","0","2"],["64794.3","0","0","0"],["64794.2","0.98181659","0","2"],["64794.1","0.26487158","0","1"],["64786.6","0","0","0"],["64785.3","0.15443373","0","1"],["64640.3","0.00016308","0","4"]],"ts":"1784087969302","checksum":0,"seqId":78785106163,"prevSeqId":78785106074}]}
{"arg":{"channel":"books","instId":"BTC-USDT"},"action":"update","data":[{"asks":[],"bids":[["64810","0.04737556","0","4"],["64807.6","0.1112146","0","1"],["64801.2","0.11457907","0","1"],["64798.6","0.12412677","0","1"],["64798.5","0.15923502","0","1"],["64798.4","0","0","0"],["64798.1","0","0","0"],["64796.7","0","0","0"],["64796.4","0.17062111","0","1"],["64796.1","0.9941385","0","1"],["64794.3","0.26487113","0","1"],["64794.1","0","0","0"],["64786.3","0.1544341","0","1"],["64785.3","0","0","0"],["64782.7","0.00018054","0","4"],["64640.3","0","0","0"]],"ts":"1784087969402","checksum":0,"seqId":78785106198,"prevSeqId":78785106163}]}
{"arg":{"channel":"books","instId":"BTC-USDT"},"action":"update","data":[{"asks":[],"bids":[["64810","0.04607556","0","3"],["64794.2","0.99901411","0","3"],["64782.8","0.00003674","0","1"],["64711.5","0.00309064","0","2"],["64711.3","0","0","0"],["64640.8","0","0","0"]],"ts":"1784087969502","checksum":0,"seqId":78785106211,"prevSeqId":78785106198}]}
{"arg":{"channel":"books","instId":"BTC-USDT"},"action":"update","data":[{"asks":[["64814.6","0.15443362","0","1"],["64814.7","0.11359521","0","2"],["64815.3","0.02316181","0","1"],["64815.8","0.02326085","0","1"],["64816","0","0","0"],["64817.4","0","0","0"],["64819","0","0","0"],["64827.3","0","0","0"],["64828.1","0","0","0"],["64829.5","2.27909022","0","1"],["64835.3","0","0","0"],["64836.2","0","0","0"],["64873.6","0.95702034","0","1"],["64901.9","0.3096654","0","3"],["64902.5","0.0000415","0","1"],["64902.8","0.00002164","0","1"]],"bids":[["64807.6","0","0","0"],["64806.2","0","0","0"],["64805.2","0.00208352","0","2"],["64803.1","0.1226897","0","1"],["64803","0","0","0"],["64801.2","0.12412677","0","1"],["64799.1","0.0000155","0","1"],["64798.7","0.2402525","0","1"],["64798.5","0","0","0"],["64797.3","0.12412677","0","1"],["64797","0.44953746","0","4"],["64796.4","0","0","0"],["64796.1","0.74013545","0","1"],["64794.7","0.17062553","0","1"],["64794.3","0","0","0"],["64794.2","0","0","0"],["64794.1","0.9740945","0","1"],["64792.9","0.0077221","0","1"],["64791.9","0","0","0"],["64791.2","0.26488411","0","1"],["64791.1","0","0","0"],["64790.7","0.04","0","1"],["64790.3","0.08","0","1"],["64789.1","0","0","0"],["64788.4","0.03860236","0","1"],["64786.5","0","0","0"],["64786.3","0","0","0"],["64784.3","0.15443362","0","1"],["64776.7","0","0","0"],["64771.9","0","0","0"],["64640.8","0.00001428","0","1"],["64640.3","0.00016308","0","4"],["64640","0.00438692","0","2"],["64639.8","0.00045864","0","3"],["64639.4","0.00046015","0","1"]],"ts":"1784087969602","checksum":0,"seqId":78785106291,"prevSeqId":78785106211}]}
{"arg":{"channel":"books","instId":"BTC-USDT"},"action":"update","data":[{"asks":[["64814.3","0.08934224","0","2"],["64814.7","0","0","0"],["64816","0.12412677","0","1"],["64816.8","0.37353212","0","2"],["64818.1","0","0","0"],["64868.5","0.02121065","0","2"]],"bids":[["64798.8","0.12412677","0","1"],["64798.7","0.16614882","0","1"],["64798.6","0","0","0"],["64797.3","0","0","0"],["64797.2","0.12412677","0","1"]],"ts":"1784087969702","checksum":0,"seqId":78785106325,"prevSeqId":78785106291}]}
{"arg":{"channel":"books","instId":"BTC-USDT"},"action":"update","data":[{"asks":[["64814.3","0.0599556","0","1"],["64814.6","0","0","0"],["64815.2","0.15443561","0","1"],["64827.3","2.27909022","0","1"],["64829.5","0","0","0"]],"bids":[["64794.2","0.9740945","0","1"],["64794.1","0","0","0"],["64794","2.00773791","0","3"],["64792.9","0.26487877","0","1"],["64791.2","0","0","0"],["64766.3","0","0","0"],["64765","0.01520158","0","1"],["64764.6","0.44684","0","1"],["64763.2","0.00136734","0","1"],["64761","0","0","0"],["64752.8","0.30957429","0","1"],["64751.4","0.00229124","0","1"],["64739.6","0","0","0"],["64738.3","0.00154468","0","1"]],"ts":"1784087969802","checksum":0,"seqId":78785106355,"prevSeqId":78785106325}]}
{"arg":{"channel":"books","instId":"BTC-USDT"},"action":"update","data":[{"asks":[["64814.3","0.08934283","0","2"],["64814.9","0.1230985","0","1"],["64816","0","0","0"]],"bids":[["64794","2.0000155","0","2"],["64793.5","0.00772237","0","1"],["64761","0.00382221","0","1"],["64639.8","0","0","0"],["64639.4","0","0","0"]],"ts":"1784087969902","checksum":0,"seqId":78785106371,"prevSeqId":78785106355}]}
{"arg":{"channel":"books","instId":"BTC-USDT"},"action":"update","data":[{"asks":[["64810.9","0.12438203","0","3"],["64811","0.33446129","0","1"],["64811.1","0.9740945","0","1"],["64811.2","0","0","0"],["64811.3","0","0","0"],["64812.3","0","0","0"],["64812.4","0","0","0"],["64813.6","0.02316238","0","1"],["64814.3","0.2147382","0","1"],["64814.6","0.12412677","0","1"],["64814.7","0.30957429","0","1"],["64814.8","0.1544344","0","1"],["64814.9","0","0","0"],["64815.2","0","0","0"],["64815.3","0","0","0"],["64818","0.0771865","0","1"],["64820.5","0","0","0"],["64825.8","0.45780505","0","3"],["64831","1.10917087","0","2"],["64833.5","0","0","0"],["64836","0","0","0"],["64844","0.19296625","0","1"],["64848.4","0.00031285","0","3"],["64889.8","0.00312063","0","3"],["64890","0.00002282","0","1"],["64903.1","0.00002503","0","1"],["64903.2","0.32881826","0","6"]],"bids":[["64803.3","0.12412677","0","1"],["64803.1","0","0","0"],["64802.9","0","0","0"],["64800.9","0.1080232","0","1"],["64799.4","0.11089384","0","2"],["64798.8","0","0","0"],["64798.7","0","0","0"],["64798","0.12412677","0","1"],["64797.2","0","0","0"],["64797","0.18566271","0","2"],["64796.2","0.12412677","0","1"],["64795.7","0","0","0"],["64795.4","0.19658238","0","2"],["64794.7","0","0","0"],["64794.2","0","0","0"],["64793.9","0","0","0"],["64793.5","0.26487463","0","1"],["64793.3","0.13414755","0","1"],["64792.9","0","0","0"],["64792.5","0.01543389","0","1"],["64791.6","0.00772233","0","1"],["64785.4","0.01805347","0","1"],["64784.3","0.1544344","0","1"],["64784","0.99691658","0","6"],["64639.8","0.00045864","0","3"],["64639.4","0.00046015","0","1"]],"ts":"1784087970002","checksum":0,"seqId":78785106510,"prevSeqId":78785106371}]}
{"arg":{"channel":"books","instId":"BTC-USDT"},"action":"update","data":[{"asks":[["64813.9","0.11605713","0","1"],["64814.1","0.13641863","0","2"],["64814.3","0","0","0"],["64814.5","0.15443797","0","1"],["64814.6","0","0","0"],["64814.8","0","0","0"],["64829","2","0","1"],["64830","0","0","0"],["64831.7","1.332683","0","1"]],"bids":[["64792.6","0.00772233","0","1"],["64791.6","0","0","0"],["64767.3","1.334005","0","1"],["64639.4","0","0","0"]],"ts":"1784087970102","checksum":0,"seqId":78785106537,"prevSeqId":78785106510}]}
{"arg":{"channel":"books","instId":"BTC-USDT"},"action":"update","data":[{"asks":[["64814.4","0.012","0","1"],["64821.6","0","0","0"],["64883.7","0.02815487","0","7"],["64883.8","0","0","0"],["64903.3","0.0003883","0","1"]],"bids":[["64798.3","0","0","0"],["64777","0.02521321","0","3"],["64776.6","0","0","0"],["64767.9","0.79536926","0","2"],["64749.7","0.00707331","0","1"],["64749.2","0","0","0"],["64698.1","0.00002749","0","2"],["64639.4","0.00046015","0","1"]],"ts":"1784087970202","checksum":0,"seqId":78785106562,"prevSeqId":78785106537}]}
{"arg":{"channel":"books","instId":"BTC-USDT"},"action":"update","data":[{"asks":[["64814","0.15443813","0","1"],["64814.5","0","0","0"]],"bids":[["64799.4","0.18908207","0","3"],["64797.2","0.12128894","0","1"],["64797","0.42637565","0","3"],["64796.2","0","0","0"],["64793.5","0.26487397","0","1"],["64784","0.75620364","0","5"]],"ts":"1784087970302","checksum":0,"seqId":78785106583,"prevSeqId":78785106562}]}
{"arg":{"channel":"books","instId":"BTC-USDT"},"action":"update","data":[{"asks":[],"bids":[["64793.5","0","0","0"],["64792.9","0.28979771","0","3"],["64792.6","0","0","0"],["64698.4","0.00573765","0","2"],["64639.1","0.00034809","0","1"]],"ts":"1784087970402","checksum":0,"seqId":78785106593,"prevSeqId":78785106583}]}
{"arg":{"channel":"trades","instId":"BTC-USDT"},"data":[{"instId":"BTC-USDT","tradeId":"1033093075","px":"64810","sz":"0.009","side":"sell","ts":"1784087970462","count":"1","source":"0","seqId":78785106611}]}
{"arg":{"channel":"books","instId":"BTC-USDT"},"action":"update","data":[{"asks":[["64813.9","0","0","0"],["64814","0.12412677","0","1"],["64814.6","0.15443824","0","1"],["64820.8","0.01082381","0","1"],["64825.5","0","0","0"]],"bids":[["64810","0.03707556","0","3"],["64805.2","0.12621029","0","3"],["64803.3","0","0","0"],["64802.9","0.11299196","0","1"],["64797","0.18566271","0","2"],["64793.3","0.14186993","0","2"],["64792.9","0.26487792","0","1"],["64785.1","0.15443824","0","1"],["64784.3","0","0","0"],["64784","0.99691658","0","6"],["64775.1","0.03082791","0","1"],["64639.1","0","0","0"]],"ts":"1784087970502","checksum":0,"seqId":78785106623,"prevSeqId":78785106593}]}
{"arg":{"channel":"books","instId":"BTC-USDT"},"action":"update","data":[{"asks":[["64814","0","0","0"],["64903.4","0.00012365","0","1"]],"bids":[["64793.3","0.13414755","0","1"],["64793","0.00772235","0","1"],["64785.1","0","0","0"],["64784.3","0.15443817","0","1"],["64639.4","0","0","0"]],"ts":"1784087970602","checksum":0,"seqId":78785106635,"prevSeqId":78785106623}]}
{"arg":{"channel":"books","instId":"BTC-USDT"},"action":"update","data":[{"asks":[["64814","0.11235574","0","1"],["64903.4","0","0","0"]],"bids":[["64805.2","0.00208352","0","2"],["64802.9","0.34761545","0","2"],["64799.4","0.11089384","0","2"],["64797.2","0","0","0"],["64796.2","0.12412677","0","1"],["64793","0","0","0"],["64792.9","0.26487724","0","1"],["64792.6","0.00772238","0","1"]],"ts":"1784087970702","checksum":0,"seqId":78785106660,"prevSeqId":78785106635}]}
{"arg":{"channel":"books","instId":"BTC-USDT"},"action":"update","data":[{"asks":[["64814","0.26679405","0","2"],["64814.6","0","0","0"],["64903.4","0.00012365","0","1"]],"bids":[["64792.9","0.28207476","0","2"],["64782.7","0.00013331","0","3"]],"ts":"1784087970802","checksum":0,"seqId":78785106668,"prevSeqId":78785106660}]}
{"arg":{"channel":"books","instId":"BTC-USDT"},"action":"update","data":[{"asks":[["64814","0.15443831","0","1"]],"bids":[["64805.2","0.12621029","0","3"],["64796.2","0","0","0"],["64792.9","0.26487724","0","1"],["64639.4","0.00046015","0","1"]],"ts":"1784087970902","checksum":0,"seqId":78785106678,"prevSeqId":78785106668}]}
{"arg":{"channel":"books","instId":"BTC-USDT"},"action":"update","data":[{"asks":[["64810.9","0.00025526","0","2"],["64813.6","0","0","0"],["64814","0","0","0"],["64815.3","0.02316227","0","1"],["64815.7","0.15443661","0","1"],["64827.3","0","0","0"],["64829.5","2.27909022","0","1"]],"bids":[["64810","0.03837556","0","4"],["64807.6","0.12412677","0","1"],["64796.2","0.12412677","0","1"],["64795.5","0.26486808","0","1"],["64794.6","0.14215259","0","1"],["64794.1","0.9740945","0","1"],["64793.5","0.00772214","0","1"],["64793.3","0","0","0"],["64792.9","0","0","0"],["64792.6","0","0","0"],["64785.5","0.15443661","0","1"],["64784.3","0","0","0"],["64784","0.75620364","0","5"],["64782.8","0","0","0"],["64639.8","0","0","0"],["64639.4","0","0","0"]],"ts":"1784087971002","checksum":0,"seqId":78785106717,"prevSeqId":78785106678}]}
{"arg":{"channel":"books","instId":"BTC-USDT"},"action":"update","data":[{"asks":[["64815.2","0.15443671","0","1"],["64815.7","0","0","0"]],"bids":[["64799.4","0.18908207","0","3"],["64797.2","0.12412677","0","1"],["64797","0.42637565","0","3"],["64796.8","0.14214767","0","1"],["64796.2","0","0","0"],["64795.5","0","0","0"],["64794.6","0","0","0"],["64794.2","0.26486824","0","1"],["64793.5","0","0","0"],["64793","0.00772212","0","1"],["64792.9","0.01719752","0","1"],["64785.5","0.15443671","0","1"],["64640","0","0","0"]],"ts":"1784087971102","checksum":0,"seqId":78785106742,"prevSeqId":78785106717}]}
{"arg":{"channel":"books","instId":"BTC-USDT"},"action":"update","data":[{"asks":[["64810.9","0.12438203","0","3"],["64814.6","0.15443697","0","1"],["64815.2","0","0","0"]],"bids":[["64803.5","0.170819","0","1"],["64798","0","0","0"],["64792.9","0","0","0"],["64785.5","0","0","0"],["64784.3","0.15443697","0","1"],["64640","0.00438692","0","2"]],"ts":"1784087971202","checksum":0,"seqId":78785106759,"prevSeqId":78785106742}]}
{"arg":{"channel":"books","instId":"BTC-USDT"},"action":"update","data":[{"asks":[["64828.9","2.2304343","0","1"],["64829.4","0","0","0"],["64856.7","0.009261","0","1"],["64862.3","0","0","0"],["64873.6","0","0","0"],["64903.6","0.000015","0","1"]],"bids":[["64810","0.03707556","0","3"],["64798","0.11032869","0","1"],["64785.1","0.15443677","0","1"],["64784.3","0","0","0"],["64640","0","0","0"]],"ts":"1784087971302","checksum":0,"seqId":78785106774,"prevSeqId":78785106759}]}
{"arg":{"channel":"books","instId":"BTC-USDT"},"action":"update","data":[{"asks":[["64810.9","0.00025526","0","2"],["64814.6","0","0","0"],["64815.2","0.15443689","0","1"]],"bids":[["64809.1","0","0","0"],["64785.5","0.15443689","0","1"],["64785.1","0","0","0"],["64782.7","0.00018054","0","4"],["64640","0.00438692","0","2"]],"ts":"1784087971402","checksum":0,"seqId":78785106787,"prevSeqId":78785106774}]}
{"arg":{"channel":"books","instId":"BTC-USDT"},"action":"update","data":[{"asks":[],"bids":[["64810","0.03837556","0","4"],["64803.5","0.355319","0","2"]],"ts":"1784087971502","checksum":0,"seqId":78785106795,"prevSeqId":78785106787}]}
{"arg":{"channel":"books","instId":"BTC-USDT"},"action":"update","data":[{"asks":[["64815.2","0","0","0"],["64815.7","0.15443649","0","1"]],"bids":[["64810","0.1753598","0","6"],["64805.3","0.2167419","0","2"],["64798","0","0","0"],["64797.5","0.02316168","0","1"],["64797.2","0.11043438","0","1"],["64795.5","0.26486774","0","1"],["64795.4","0.17342","0","1"],["64794.2","0.00772209","0","1"],["64793","0","0","0"],["64786.2","0.28955186","0","2"],["64785.5","0","0","0"],["64639.8","0.00045864","0","3"]],"ts":"1784087971602","checksum":0,"seqId":78785106815,"prevSeqId":78785106795}]}
{"arg":{"channel":"books","instId":"BTC-USDT"},"action":"update","data":[{"asks":[],"bids":[["64794.2","0","0","0"],["64793.5","0.007722","0","1"],["64792.9","0.01719752","0","1"],["64786.2","0.13511557","0","1"],["64785.5","0.1544355","0","1"],["64782.7","0.00021728","0","5"],["64640","0","0","0"],["64639.8","0","0","0"]],"ts":"1784087971702","checksum":0,"seqId":78785106827,"prevSeqId":78785106815}]}
{"arg":{"channel":"books","instId":"BTC-USDT"},"action":"update","data":[{"asks":[],"bids":[["64805.5","0.18291441","0","1"],["64805.4","0.166101","0","1"],["64805.3","0.04621407","0","1"],["64803.5","0.1845","0","1"],["64799.4","0.27982871","0","2"],["64798.2","0.05560128","0","1"],["64797.2","0","0","0"],["64797","0.66708881","0","4"],["64794.2","0.00772198","0","1"],["64793.5","0","0","0"],["64792.9","0","0","0"],["64784","0.51549048","0","4"],["64640.3","0","0","0"]],"ts":"1784087971802","checksum":0,"seqId":78785106846,"prevSeqId":78785106827}]}
{"arg":{"channel":"books","instId":"BTC-USDT"},"action":"update","data":[{"asks":[],"bids":[["64805.7","0.165592","0","1"],["64805.5","0.13333326","0","1"],["64805.4","0","0","0"],["64796.2","0.26486251","0","1"],["64795.5","0","0","0"],["64792.9","0.01719752","0","1"],["64640.8","0","0","0"]],"ts":"1784087971902","checksum":0,"seqId":78785106860,"prevSeqId":78785106846}]}
{"arg":{"channel":"books","instId":"BTC-USDT"},"action":"update","data":[{"asks":[],"bids":[["64801.2","0","0","0"],["64797.2","0.12412677","0","1"],["64782.7","0.00017005","0","4"]],"ts":"1784087972002","checksum":0,"seqId":78785106870,"prevSeqId":78785106860}]}
{"arg":{"channel":"books","instId":"BTC-USDT"},"action":"update","data":[{"asks":[["64815.3","0","0","0"],["64817.1","0.02316168","0","1"]],"bids":[["64801.2","0.11132928","0","1"],["64797.2","0","0","0"],["64796.9","0.26486251","0","1"],["64796.2","0","0","0"],["64792.9","0","0","0"],["64640.8","0.00001428","0","1"]],"ts":"1784087972102","checksum":0,"seqId":78785106887,"prevSeqId":78785106870}]}
{"arg":{"channel":"books","instId":"BTC-USDT"},"action":"update","data":[{"asks":[],"bids":[["64810","0.1483598","0","5"],["64792.9","0.01719752","0","1"],["64785.5","0.15443511","0","1"],["64640.8","0","0","0"]],"ts":"1784087972202","checksum":0,"seqId":78785106897,"prevSeqId":78785106887}]}
{"arg":{"channel":"books","instId":"BTC-USDT"},"action":"update","data":[{"asks":[["64836.9","0.30053205","0","2"]],"bids":[["64810","0.1753598","0","6"],["64802.9","0.34769695","0","3"],["64801.6","0.0000155","0","1"],["64801.2","0","0","0"],["64797.2","0.12412677","0","1"],["64786.2","0.28955062","0","2"],["64785.5","0","0","0"],["64782.8","0.00004723","0","1"],["64782.7","0.00020679","0","5"]],"ts":"1784087972302","checksum":0,"seqId":78785106915,"prevSeqId":78785106897}]}
{"arg":{"channel":"books","instId":"BTC-USDT"},"action":"update","data":[{"asks":[],"bids":[["64801.2","0.11783788","0","1"],["64797.2","0","0","0"],["64796.9","0.2648625","0","1"],["64641","0","0","0"],["64640.8","0.00001428","0","1"]],"ts":"1784087972402","checksum":0,"seqId":78785106932,"prevSeqId":78785106915}]}
{"arg":{"channel":"books","instId":"BTC-USDT"},"action":"update","data":[{"asks":[],"bids":[["64792.9","0","0","0"],["64641","0.1845","0","1"]],"ts":"1784087972502","checksum":0,"seqId":78785106939,"prevSeqId":78785106932}]}
{"arg":{"channel":"books","instId":"BTC-USDT"},"action":"update","data":[{"asks":[],"bids":[["64792.9","0.01719752","0","1"],["64782.7","0.00016375","0","4"],["64640.8","0","0","0"]],"ts":"1784087972602","checksum":0,"seqId":78785106945,"prevSeqId":78785106939}]}
{"arg":{"channel":"books","instId":"BTC-USDT"},"action":"update","data":[{"asks":[["64810.9","0.12438203","0","3"]],"bids":[["64810","0.03837556","0","4"],["64801.2","0","0","0"],["64797.2","0.12412677","0","1"],["64796.9","0","0","0"],["64796.2","0.2648641","0","1"],["64794.2","0","0","0"],["64793.5","0.00772192","0","1"],["64786.2","0.13511557","0","1"],["64785.5","0.1544347","0","1"],["64782.7","0.00011652","0","3"],["64641","0","0","0"]],"ts":"1784087972702","checksum":0,"seqId":78785106974,"prevSeqId":78785106945}]}
{"arg":{"channel":"books","instId":"BTC-USDT"},"action":"update","data":[{"asks":[],"bids":[["64797","0.42637565","0","3"],["64792.9","0","0","0"],["64784","0.75620364","0","5"],["64641","0.1845","0","1"]],"ts":"1784087972802","checksum":0,"seqId":78785106983,"prevSeqId":78785106974}]}
{"arg":{"channel":"books","instId":"BTC-USDT"},"action":"update","data":[{"asks":[["64810.9","0.00025526","0","2"]],"bids":[["64810","0.17521556","0","6"],["64794.1","0.98181646","0","2"],["64793.5","0","0","0"],["64792.9","0.01719792","0","1"],["64786.2","0.28955085","0","2"],["64785.5","0","0","0"],["64784","0.51549048","0","4"],["64640.8","0.00001428","0","1"]],"ts":"1784087972902","checksum":0,"seqId":78785107003,"prevSeqId":78785106983}]}
{"arg":{"channel":"books","instId":"BTC-USDT"},"action":"update","data":[{"asks":[],"bids":[["64801.2","0.12412677","0","1"],["64797","0.66708881","0","4"],["64786.2","0.28955058","0","2"],["64782.7","0.00007978","0","2"],["64640.8","0","0","0"]],"ts":"1784087973002","checksum":0,"seqId":78785107017,"prevSeqId":78785107003}]}
{"arg":{"channel":"books","instId":"BTC-USDT"},"action":"update","data":[{"asks":[],"bids":[["64801.2","0.11802148","0","1"],["64796.9","0.264862","0","1"],["64796.2","0","0","0"],["64792.9","0","0","0"],["64786.2","0.28955054","0","2"],["64782.8","0.00003674","0","1"],["64640.8","0.00001428","0","1"]],"ts":"1784087973102","checksum":0,"seqId":78785107036,"prevSeqId":78785107017}]}
{"arg":{"channel":"books","instId":"BTC-USDT"},"action":"update","data":[{"asks":[["64825.8","0.42938725","0","2"]],"bids":[["64797.2","0","0","0"],["64785.9","0.02962215","0","1"]],"ts":"1784087973202","checksum":0,"seqId":78785107052,"prevSeqId":78785107036}]}
{"arg":{"channel":"books","instId":"BTC-USDT"},"action":"update","data":[{"asks":[],"bids":[["64796.9","0","0","0"],["64796.2","0.26486253","0","1"],["64786.2","0.13511557","0","1"],["64786","0.15443491","0","1"],["64782.7","0.00012701","0","3"],["64640.8","0","0","0"]],"ts":"1784087973302","checksum":0,"seqId":78785107073,"prevSeqId":78785107052}]}
pong
{"arg":{"channel":"books","instId":"BTC-USDT"},"action":"update","data":[{"asks":[],"bids":[["64796.2","0","0","0"],["64795.5","0.26486537","0","1"],["64794.1","0.9740945","0","1"],["64793.5","0.00772202","0","1"],["64792.9","0.01719792","0","1"],["64782.7","0.00017424","0","4"],["64641.1","0","0","0"],["64641","0","0","0"]],"ts":"1784087973402","checksum":0,"seqId":78785107091,"prevSeqId":78785107073}]}
{"arg":{"channel":"books","instId":"BTC-USDT"},"action":"update","data":[{"asks":[],"bids":[["64794.1","0.98181652","0","2"],["64793.5","0","0","0"],["64641.1","0.11988673","0","1"]],"ts":"1784087973502","checksum":0,"seqId":78785107104,"prevSeqId":78785107091}]}
{"arg":{"channel":"books","instId":"BTC-USDT"},"action":"update","data":[{"asks":[["64815.7","0","0","0"],["64816","0.15443375","0","1"],["64816.6","0.63583717","0","3"],["64823.1","0.82228286","0","5"]],"bids":[["64801.2","0","0","0"],["64797.2","0.12412677","0","1"],["64792.9","0","0","0"],["64786.3","0.15443375","0","1"],["64786","0","0","0"],["64641","0.1845","0","1"]],"ts":"1784087973602","checksum":0,"seqId":78785107120,"prevSeqId":78785107104}]}
{"arg":{"channel":"books","instId":"BTC-USDT"},"action":"update","data":[{"asks":[["64810.1","1.93888868","0","12"],["64815.7","0.15443459","0","1"],["64816","0","0","0"],["64823.8","0.33814843","0","2"]],"bids":[["64810","0.14821556","0","5"],["64797.3","0.12412677","0","1"],["64797.2","0","0","0"],["64795.5","0.26486728","0","1"],["64792.9","0.01719792","0","1"],["64786.3","0","0","0"],["64786","0.15443459","0","1"],["64641","0","0","0"]],"ts":"1784087973702","checksum":0,"seqId":78785107140,"prevSeqId":78785107120}]}
{"arg":{"channel":"books","instId":"BTC-USDT"},"action":"update","data":[{"asks":[],"bids":[["64810","0.17521556","0","6"],["64807","0.12412677","0","1"],["64806.7","0.6400155","0","2"],["64805.7","0","0","0"],["64805.5","0.09628142","0","1"],["64805.2","0.00208352","0","2"],["64802.9","0.23470499","0","2"],["64797.3","0","0","0"],["64792.9","0","0","0"],["64641","0.1845","0","1"],["64640.8","0.00001428","0","1"]],"ts":"1784087973802","checksum":0,"seqId":78785107160,"prevSeqId":78785107140}]}
{"arg":{"channel":"books","instId":"BTC-USDT"},"action":"update","data":[{"asks":[],"bids":[["64797.2","0.11757057","0","1"],["64792.9","0.01719792","0","1"],["64641","0","0","0"],["64640.8","0","0","0"]],"ts":"1784087973902","checksum":0,"seqId":78785107168,"prevSeqId":78785107160}]}
{"arg":{"channel":"books","instId":"BTC-USDT"},"action":"update","data":[{"asks":[["64810.9","0.12438203","0","3"],["64814.6","0.15443454","0","1"],["64815.7","0","0","0"]],"bids":[["64810","0.03837556","0","4"],["64807.6","0.11409949","0","1"],["64805.5","0","0","0"],["64803.5","0","0","0"],["64797.2","0","0","0"],["64795.5","0","0","0"],["64794.2","0.26486934","0","1"],["64794.1","0.9740945","0","1"],["64792.9","0","0","0"],["64792.6","0.00772207","0","1"],["64786","0","0","0"],["64784.3","0.15443456","0","1"],["64641","0.1845","0","1"],["64640.8","0.00001428","0","1"],["64640.3","0.00016308","0","4"]],"ts":"1784087974002","checksum":0,"seqId":78785107211,"prevSeqId":78785107168}]}
{"arg":{"channel":"books","instId":"BTC-USDT"},"action":"update","data":[{"asks":[],"bids":[["64807.6","0","0","0"],["64803","0.12412677","0","1"],["64797.3","0.12412677","0","1"],["64795.5","0.2648682","0","1"],["64794.2","0","0","0"],["64793.3","0.00772213","0","1"],["64792.6","0","0","0"],["64785.1","0.15443634","0","1"],["64784.3","0","0","0"],["64782.7","0.0001375","0","3"],["64640.3","0","0","0"]],"ts":"1784087974102","checksum":0,"seqId":78785107241,"prevSeqId":78785107211}]}
{"arg":{"channel":"books","instId":"BTC-USDT"},"action":"update","data":[{"asks":[],"bids":[["64807.6","0.11107036","0","1"],["64803","0","0","0"],["64797.3","0","0","0"],["64793.5","0.00772209","0","1"],["64793.3","0","0","0"],["64652.4","0","0","0"],["64650.9","0.00066777","0","1"],["64640.3","0.00016308","0","4"]],"ts":"1784087974202","checksum":0,"seqId":78785107262,"prevSeqId":78785107241}]}
{"arg":{"channel":"books","instId":"BTC-USDT"},"action":"update","data":[{"asks":[["64814","0.15443653","0","1"],["64814.6","0","0","0"],["64815.1","0.02316222","0","1"],["64816.6","0.87655011","0","4"],["64817.1","0","0","0"],["64823.1","0.58156992","0","4"]],"bids":[["64810","0.03707556","0","3"],["64807.6","0","0","0"],["64807","0","0","0"],["64806.7","0.0000155","0","1"],["64805.2","0.12621029","0","3"],["64804.2","0.169459","0","1"],["64803.1","0.12412677","0","1"],["64799.4","0.11780688","0","2"],["64797","0.18566271","0","2"],["64796.8","0","0","0"],["64796.2","0.12412677","0","1"],["64795.5","0.13147772","0","1"],["64794.2","0.26487053","0","1"],["64793.5","0","0","0"],["64793","0.00772205","0","1"],["64792.9","0.01719792","0","1"],["64785.1","0","0","0"],["64784.1","0.15443653","0","1"],["64784","0.99691658","0","6"],["64640.8","0","0","0"],["64640.3","0","0","0"]],"ts":"1784087974302","checksum":0,"seqId":78785107329,"prevSeqId":78785107262}]}
{"arg":{"channel":"books","instId":"BTC-USDT"},"action":"update","data":[{"asks":[["64814","0","0","0"],["64814.6","0.15443879","0","1"],["64851","0.00057374","0","15"]],"bids":[["64805.5","0.12412677","0","1"],["64805.4","0.64","0","1"],["64805.2","0.00208352","0","2"],["64804.2","0","0","0"],["64803.1","0","0","0"],["64793.5","0.00772227","0","1"],["64793","0","0","0"],["64792.9","0","0","0"],["64784.3","0.15443879","0","1"],["64784.1","0","0","0"],["64640.8","0.00001428","0","1"]],"ts":"1784087974402","checksum":0,"seqId":78785107362,"prevSeqId":78785107329}]}
{"arg":{"channel":"books","instId":"BTC-USDT"},"action":"update","data":[{"asks":[],"bids":[["64807.6","0.12412677","0","1"],["64798","0.11419569","0","1"],["64796.2","0","0","0"],["64793.5","0","0","0"],["64793.3","0.00772223","0","1"],["64785.1","0.15443827","0","1"],["64784.3","0","0","0"],["64641","0","0","0"]],"ts":"1784087974502","checksum":0,"seqId":78785107388,"prevSeqId":78785107362}]}
{"arg":{"channel":"books","instId":"BTC-USDT"},"action":"update","data":[{"asks":[["64814.6","0","0","0"],["64815","0.15443633","0","1"]],"bids":[["64810","0.03837556","0","4"],["64807.6","0.1099164","0","1"],["64803","0.12412677","0","1"],["64798","0","0","0"],["64796.7","0.13147529","0","1"],["64795.5","0","0","0"],["64793.3","0","0","0"],["64792.9","0.02492008","0","2"],["64785.5","0.15443633","0","1"],["64785.1","0","0","0"],["64782.7","0.00009446","0","2"]],"ts":"1784087974602","checksum":0,"seqId":78785107418,"prevSeqId":78785107388}]}
{"arg":{"channel":"books","instId":"BTC-USDT"},"action":"update","data":[{"asks":[["64815","0","0","0"],["64815.7","0.15443635","0","1"],["64851","0.00058511","0","16"]],"bids":[["64803","0","0","0"],["64799.4","0.21170899","0","3"],["64797.2","0.12412677","0","1"],["64797","0.42637565","0","3"],["64794.3","0.26486828","0","1"],["64794.2","0","0","0"],["64793.5","0.00772212","0","1"],["64792.9","0","0","0"],["64784","0.75620364","0","5"]],"ts":"1784087974702","checksum":0,"seqId":78785107439,"prevSeqId":78785107418}]}
{"arg":{"channel":"books","instId":"BTC-USDT"},"action":"update","data":[{"asks":[],"bids":[["64798","0.11060639","0","1"],["64792.9","0.01719792","0","1"],["64641.1","0","0","0"],["64640.8","0","0","0"]],"ts":"1784087974802","checksum":0,"seqId":78785107449,"prevSeqId":78785107439}]}
{"arg":{"channel":"books","instId":"BTC-USDT"},"action":"update","data":[{"asks":[],"bids":[["64810","0.03707556","0","3"],["64801.2","0.1080227","0","1"],["64800.9","0","0","0"],["64797.2","0","0","0"],["64795.5","0.26486799","0","1"],["64794.3","0","0","0"],["64792.9","0","0","0"],["64782.7","0.00004723","0","1"],["64641.1","0.11988673","0","1"],["64641","0.1845","0","1"]],"ts":"1784087974902","checksum":0,"seqId":78785107465,"prevSeqId":78785107449}]}
{"arg":{"channel":"books","instId":"BTC-USDT"},"action":"update","data":[{"asks":[["64888.8","0.00370567","0","10"],["64889.8","0.00003849","0","1"]],"bids":[["64792.9","0.01719792","0","1"],["64782.8","0.00007348","0","2"],["64641","0","0","0"]],"ts":"1784087975002","checksum":0,"seqId":78785107477,"prevSeqId":78785107465}]}
{"arg":{"channel":"books","instId":"BTC-USDT"},"action":"update","data":[{"asks":[["64815","0.15443635","0","1"],["64815.7","0","0","0"],["64851","0.00059648","0","17"]],"bids":[["64803","0.11322819","0","1"],["64798","0","0","0"],["64792.9","0","0","0"],["64641","0.1845","0","1"]],"ts":"1784087975102","checksum":0,"seqId":78785107491,"prevSeqId":78785107477}]}
{"arg":{"channel":"books","instId":"BTC-USDT"},"action":"update","data":[{"asks":[],"bids":[["64792.9","0.01719792","0","1"],["64641","0","0","0"]],"ts":"1784087975202","checksum":0,"seqId":78785107497,"prevSeqId":78785107491}]}
{"arg":{"channel":"books","instId":"BTC-USDT"},"action":"update","data":[{"asks":[],"bids":[["64792.9","0","0","0"],["64782.8","0.00003674","0","1"],["64641","0.1845","0","1"]],"ts":"1784087975302","checksum":0,"seqId":78785107507,"prevSeqId":78785107497}]}
{"arg":{"channel":"books","instId":"BTC-USDT"},"action":"update","data":[{"asks":[["64810.1","1.93315083","0","11"]],"bids":[["64803","0","0","0"],["64798","0.11334429","0","1"],["64795.5","0","0","0"],["64794.2","0.26487023","0","1"],["64782.7","0","0","0"],["64640.8","0.00001428","0","1"]],"ts":"1784087975402","checksum":0,"seqId":78785107525,"prevSeqId":78785107507}]}
{"arg":{"channel":"books","instId":"BTC-USDT"},"action":"update","data":[{"asks":[],"bids":[["64795.5","0.26486664","0","1"],["64794.2","0","0","0"],["64785.5","0","0","0"],["64785.3","0.15443627","0","1"]],"ts":"1784087975502","checksum":0,"seqId":78785107534,"prevSeqId":78785107525}]}
{"arg":{"channel":"books","instId":"BTC-USDT"},"action":"update","data":[{"asks":[],"bids":[["64802.9","0.23462349","0","1"],["64795.5","0","0","0"],["64794.2","0.26486825","0","1"]],"ts":"1784087975602","checksum":0,"seqId":78785107541,"prevSeqId":78785107534}]}
{"arg":{"channel":"books","instId":"BTC-USDT"},"action":"update","data":[{"asks":[],"bids":[["64798","0","0","0"],["64797.2","0.12412677","0","1"],["64792.9","0.01719792","0","1"],["64640.8","0","0","0"]],"ts":"1784087975702","checksum":0,"seqId":78785107551,"prevSeqId":78785107541}]}
{"arg":{"channel":"books","instId":"BTC-USDT"},"action":"update","data":[{"asks":[],"bids":[["64802.9","0.23469893","0","2"]],"ts":"1784087975802","checksum":0,"seqId":78785107557,"prevSeqId":78785107551}]}
{"arg":{"channel":"books","instId":"BTC-USDT"},"action":"update","data":[{"asks":[],"bids":[["64798","0.11833753","0","1"],["64794.2","0.26486984","0","1"],["64792.9","0","0","0"]],"ts":"1784087976002","checksum":0,"seqId":78785107576,"prevSeqId":78785107557}]}
{"arg":{"channel":"books","instId":"BTC-USDT"},"action":"update","data":[{"asks":[["64851","0.00060785","0","18"]],"bids":[["64810","0.03837556","0","4"],["64803","0.12412677","0","1"],["64798","0","0","0"],["64797.2","0","0","0"],["64795.5","0.26486821","0","1"],["64794.2","0","0","0"],["64785.3","0.15443623","0","1"],["64782.8","0.00007348","0","2"],["64640.8","0.00001428","0","1"]],"ts":"1784087976102","checksum":0,"seqId":78785107596,"prevSeqId":78785107576}]}
{"arg":{"channel":"books","instId":"BTC-USDT"},"action":"update","data":[{"asks":[["64810.8","0.1120309","0","1"],["64810.9","0.00025526","0","2"],["64851","0.00061922","0","19"],["64903.6","0","0","0"]],"bids":[["64810","0.03707556","0","3"],["64797.2","0.12412677","0","1"],["64640.8","0","0","0"]],"ts":"1784087976202","checksum":0,"seqId":78785107605,"prevSeqId":78785107596}]}
{"arg":{"channel":"books","instId":"BTC-USDT"},"action":"update","data":[{"asks":[],"bids":[["64810","0.03837556","0","4"],["64795.5","0.26486802","0","1"],["64785.9","0","0","0"],["64640.8","0.00001428","0","1"]],"ts":"1784087976302","checksum":0,"seqId":78785107617,"prevSeqId":78785107605}]}
{"arg":{"channel":"books","instId":"BTC-USDT"},"action":"update","data":[{"asks":[],"bids":[["64795.5","0","0","0"],["64794.2","0.26486822","0","1"],["64792.9","0.01719792","0","1"],["64640.8","0","0","0"]],"ts":"1784087976402","checksum":0,"seqId":78785107625,"prevSeqId":78785107617}]}
{"arg":{"channel":"trades","instId":"BTC-USDT"},"data":[{"instId":"BTC-USDT","tradeId":"1033093076","px":"64810","sz":"0.00000772","side":"sell","ts":"1784087976440","count":"1","source":"0","seqId":78785107630}]}
{"arg":{"channel":"books","instId":"BTC-USDT"},"action":"update","data":[{"asks":[],"bids":[["64810","0.03836784","0","4"],["64803","0","0","0"],["64782.8","0.00003674","0","1"],["64640.8","0.00001428","0","1"]],"ts":"1784087976502","checksum":0,"seqId":78785107637,"prevSeqId":78785107625}]}
{"arg":{"channel":"books","instId":"BTC-USDT"},"action":"update","data":[{"asks":[],"bids":[["64810","0.03706784","0","3"],["64794.2","0.26486908","0","1"],["64792.9","0","0","0"],["64640.3","0.00016308","0","4"]],"ts":"1784087976602","checksum":0,"seqId":78785107648,"prevSeqId":78785107637}]}
{"arg":{"channel":"books","instId":"BTC-USDT"},"action":"update","data":[{"asks":[],"bids":[["64795.5","0.26486821","0","1"],["64794.2","0","0","0"]],"ts":"1784087976702","checksum":0,"seqId":78785107654,"prevSeqId":78785107648}]}
{"arg":{"channel":"books","instId":"BTC-USDT"},"action":"update","data":[{"asks":[],"bids":[["64792.9","0.01719792","0","1"],["64649.3","0","0","0"]],"ts":"1784087976802","checksum":0,"seqId":78785107669,"prevSeqId":78785107654}]}
{"arg":{"channel":"books","instId":"BTC-USDT"},"action":"update","data":[{"asks":[["64810.8","0","0","0"],["64810.9","0.1115068","0","3"],["64903.6","0.000015","0","1"]],"bids":[["64810","0.03836784","0","4"],["64803","0.12412677","0","1"],["64795.5","0","0","0"],["64794.2","0.2648701","0","1"],["64793.5","0","0","0"],["64793.3","0.00772216","0","1"],["64792.9","0","0","0"],["64782.8","0.00008397","0","2"]],"ts":"1784087976902","checksum":0,"seqId":78785107687,"prevSeqId":78785107669}]}
{"arg":{"channel":"books","instId":"BTC-USDT"},"action":"update","data":[{"asks":[["64810.9","0.00025526","0","2"],["64815","0","0","0"],["64815.1","0","0","0"],["64815.7","0.15443608","0","1"],["64816.6","0.39512401","0","2"],["64817.6","0.02316139","0","1"],["64823.1","1.06299602","0","6"]],"bids":[["64810","0.67836784","0","5"],["64807.6","0.12412677","0","1"],["64803.5","0.1845","0","1"],["64803","0","0","0"],["64799.1","0.02317689","0","2"],["64797.5","0","0","0"],["64797","0.66708881","0","4"],["64794.2","0.27259223","0","2"],["64793.3","0","0","0"],["64785.5","0.15443608","0","1"],["64785.3","0","0","0"],["64784","0.51549048","0","4"],["64640","0.00438692","0","2"],["64639.8","0.00045864","0","3"]],"ts":"1784087977002","checksum":0,"seqId":78785107719,"prevSeqId":78785107687}]}
{"arg":{"channel":"books","instId":"BTC-USDT"},"action":"update","data":[{"asks":[["64815.7","0","0","0"],["64816","0.15443516","0","1"]],"bids":[["64797.2","0","0","0"],["64786.3","0.15443605","0","1"],["64785.5","0","0","0"],["64782.8","0.00003674","0","1"],["64639.4","0.00046015","0","1"]],"ts":"1784087977102","checksum":0,"seqId":78785107732,"prevSeqId":78785107719}]}
{"arg":{"channel":"books","instId":"BTC-USDT"},"action":"update","data":[{"asks":[],"bids":[["64802.9","0.23462349","0","1"],["64801.6","0.00009121","0","2"],["64795.5","0.2648682","0","1"],["64794.2","0.00772213","0","1"],["64673.1","0.02417469","0","1"],["64660.2","0","0","0"],["64639.4","0","0","0"]],"ts":"1784087977202","checksum":0,"seqId":78785107743,"prevSeqId":78785107732}]}
{"arg":{"channel":"books","instId":"BTC-USDT"},"action":"update","data":[{"asks":[],"bids":[["64805.5","0.41144819","0","2"],["64795.5","0.26486709","0","1"]],"ts":"1784087977302","checksum":0,"seqId":78785107755,"prevSeqId":78785107743}]}
{"arg":{"channel":"books","instId":"BTC-USDT"},"action":"update","data":[{"asks":[],"bids":[["64673.1","0","0","0"],["64639.4","0.00046015","0","1"]],"ts":"1784087977402","checksum":0,"seqId":78785107760,"prevSeqId":78785107755}]}
{"arg":{"channel":"books","instId":"BTC-USDT"},"action":"update","data":[{"asks":[["64816","0","0","0"],["64816.2","0.1544334","0","1"]],"bids":[["64792.9","0.01719792","0","1"],["64639.4","0","0","0"]],"ts":"1784087977502","checksum":0,"seqId":78785107770,"prevSeqId":78785107760}]}
{"arg":{"channel":"books","instId":"BTC-USDT"},"action":"update","data":[{"asks":[],"bids":[["64807.6","0","0","0"],["64792.9","0","0","0"],["64782.8","0.00008397","0","2"],["64639.4","0.00046015","0","1"],["64639.1","0.00034809","0","1"]],"ts":"1784087977602","checksum":0,"seqId":78785107779,"prevSeqId":78785107770}]}
{"arg":{"channel":"books","instId":"BTC-USDT"},"action":"update","data":[{"asks":[["64810.1","1.94515083","0","12"],["64814.4","0","0","0"],["64815.7","0.15443439","0","1"],["64816.2","0","0","0"],["64903.8","0.00019404","0","4"]],"bids":[["64807.6","0.12412677","0","1"],["64795","2","0","1"],["64794","0.0000155","0","1"],["64779.7","0","0","0"],["64760.2","0","0","0"],["64756.7","0.30963219","0","2"]],"ts":"1784087977702","checksum":0,"seqId":78785107794,"prevSeqId":78785107779}]}
{"arg":{"channel":"books","instId":"BTC-USDT"},"action":"update","data":[{"asks":[],"bids":[["64807.6","0","0","0"],["64792.9","0.01719792","0","1"],["64780.3","0.24010065","0","1"],["64760.9","0.4076686","0","2"]],"ts":"1784087977802","checksum":0,"seqId":78785107802,"prevSeqId":78785107794}]}
{"arg":{"channel":"books","instId":"BTC-USDT"},"action":"update","data":[{"asks":[],"bids":[["64807.6","0.11812729","0","1"],["64796","2","0","1"],["64795","0","0","0"],["64792.9","0","0","0"]],"ts":"1784087977902","checksum":0,"seqId":78785107811,"prevSeqId":78785107802}]}
{"arg":{"channel":"books","instId":"BTC-USDT"},"action":"update","data":[{"asks":[["64810.9","0.12438203","0","3"],["64814.6","0.15443453","0","1"],["64815.7","0","0","0"],["64815.9","0.02316188","0","1"],["64817.6","0","0","0"],["64823.1","0.82228286","0","5"],["64850.9","0.00010934","0","8"]],"bids":[["64810","0.03836784","0","4"],["64805.5","0.12412677","0","1"],["64799.1","0.0000155","0","1"],["64797.6","0.02316188","0","1"],["64795.5","0","0","0"],["64794.2","0.26487038","0","1"],["64792.9","0.00772216","0","1"],["64786.3","0","0","0"],["64785.3","0.15443453","0","1"],["64782.8","0.00012701","0","3"],["64639.1","0","0","0"]],"ts":"1784087978102","checksum":0,"seqId":78785107844,"prevSeqId":78785107811}]}
{"arg":{"channel":"books","instId":"BTC-USDT"},"action":"update","data":[{"asks":[["64814.6","0","0","0"],["64815.7","0.15443552","0","1"],["64816.6","0.63583717","0","3"]],"bids":[["64793.3","0.00772212","0","1"],["64792.9","0.01719792","0","1"],["64782.8","0.00007978","0","2"],["64639.4","0","0","0"]],"ts":"1784087978202","checksum":0,"seqId":78785107866,"prevSeqId":78785107844}]}
{"arg":{"channel":"books","instId":"BTC-USDT"},"action":"update","data":[{"asks":[["64814.6","0.15443585","0","1"],["64815.7","0","0","0"]],"bids":[["64792.9","0","0","0"],["64639.4","0.00046015","0","1"]],"ts":"1784087978302","checksum":0,"seqId":78785107876,"prevSeqId":78785107866}]}
{"arg":{"channel":"books","instId":"BTC-USDT"},"action":"update","data":[{"asks":[["64814.6","0.15443598","0","1"]],"bids":[["64810","0.03706784","0","3"],["64803.5","0","0","0"],["64639.1","0.00034809","0","1"]],"ts":"1784087978402","checksum":0,"seqId":78785107891,"prevSeqId":78785107876}]}
{"arg":{"channel":"books","instId":"BTC-USDT"},"action":"update","data":[{"asks":[["64814.6","0","0","0"],["64815.7","0.15443601","0","1"]],"bids":[["64810","0.03836784","0","4"],["64797.2","0.12271374","0","1"],["64792.9","0.01719792","0","1"],["64782.8","0","0","0"],["64639.1","0","0","0"]],"ts":"1784087978502","checksum":0,"seqId":78785107910,"prevSeqId":78785107891}]}
{"arg":{"channel":"books","instId":"BTC-USDT"},"action":"update","data":[{"asks":[],"bids":[["64797.2","0.12412677","0","1"],["64796.1","0.42160151","0","1"],["64796","0","0","0"],["64792.9","0","0","0"],["64698.4","0.00015456","0","1"],["64639.1","0.00034809","0","1"],["64638.5","0.00002272","0","1"]],"ts":"1784087978602","checksum":0,"seqId":78785107922,"prevSeqId":78785107910}]}
{"arg":{"channel":"books","instId":"BTC-USDT"},"action":"update","data":[{"asks":[],"bids":[["64803","0.11300109","0","1"],["64799.4","0.30576964","0","2"],["64797.2","0","0","0"],["64793.4","0.94783303","0","2"],["64792.9","0.01719792","0","1"],["64791","2.12035665","0","2"],["64638.5","0","0","0"]],"ts":"1784087978702","checksum":0,"seqId":78785107940,"prevSeqId":78785107922}]}
{"arg":{"channel":"books","instId":"BTC-USDT"},"action":"update","data":[{"asks":[],"bids":[["64792.9","0","0","0"],["64686.6","0.00558411","0","1"]],"ts":"1784087978802","checksum":0,"seqId":78785107946,"prevSeqId":78785107940}]}
{"arg":{"channel":"books","instId":"BTC-USDT"},"action":"update","data":[{"asks":[],"bids":[["64794.2","0.26487091","0","1"]],"ts":"1784087978902","checksum":0,"seqId":78785107954,"prevSeqId":78785107946}]}
{"arg":{"channel":"books","instId":"BTC-USDT"},"action":"update","data":[{"asks":[["64810.1","1.93615083","0","11"],["64810.8","0.12412677","0","1"],["64810.9","0.00025526","0","2"],["64903.8","0","0","0"]],"bids":[["64810","0.03706784","0","3"],["64792.9","0.01719823","0","1"],["64639.1","0","0","0"]],"ts":"1784087979002","checksum":0,"seqId":78785107967,"prevSeqId":78785107954}]}
{"arg":{"channel":"books","instId":"BTC-USDT"},"action":"update","data":[{"asks":[["64823.1","0.58156992","0","4"]],"bids":[["64807.6","0","0","0"],["64803","0","0","0"],["64797","0.42637565","0","3"],["64792.9","0","0","0"],["64639.1","0.00034809","0","1"],["64638.5","0.00002272","0","1"],["64637.9","0.00002665","0","1"]],"ts":"1784087979102","checksum":0,"seqId":78785107977,"prevSeqId":78785107967}]}
{"arg":{"channel":"books","instId":"BTC-USDT"},"action":"update","data":[{"asks":[["64814.6","0.15443594","0","1"],["64815.7","0","0","0"],["64816.6","0.87655011","0","4"]],"bids":[["64807.6","0.11049338","0","1"],["64805.6","0.12412677","0","1"],["64805.5","0","0","0"],["64799.4","0.18965976","0","2"],["64797.2","0.12412677","0","1"],["64792.9","0.01719823","0","1"],["64785.3","0","0","0"],["64785.1","0.15443576","0","1"],["64784","0.75620364","0","5"],["64639.1","0","0","0"],["64638.5","0","0","0"],["64637.9","0","0","0"]],"ts":"1784087979202","checksum":0,"seqId":78785108013,"prevSeqId":78785107977}]}
{"arg":{"channel":"books","instId":"BTC-USDT"},"action":"update","data":[{"asks":[],"bids":[["64802.9","0.16532551","0","1"],["64801.4","0.10802236","0","1"],["64801.2","0","0","0"],["64794.2","0.26487352","0","1"],["64792.9","0","0","0"],["64761","0","0","0"],["64639.1","0.00034809","0","1"],["64638.5","0.00002272","0","1"]],"ts":"1784087979302","checksum":0,"seqId":78785108035,"prevSeqId":78785108013}]}
{"arg":{"channel":"books","instId":"BTC-USDT"},"action":"update","data":[{"asks":[],"bids":[["64761","0.00382212","0","1"],["64638.5","0","0","0"]],"ts":"1784087979402","checksum":0,"seqId":78785108041,"prevSeqId":78785108035}]}
