{"channel":"status","type":"update","data":[{"version":"2.0.10","system":"online","api_version":"v2","connection_id":8449421496178335765}]}
{"method":"subscribe","result":{"channel":"book","depth":10,"snapshot":true,"symbol":"BTC/USD"},"success":true,"time_in":"2026-06-19T05:45:47.485356Z","time_out":"2026-06-19T05:45:47.485399Z"}
{"channel":"heartbeat"}
{"channel":"book","type":"snapshot","data":[{"symbol":"BTC/USD","bids":[{"price":62593.7,"qty":0.00150001},{"price":62593.6,"qty":0.00181271},{"price":62591.4,"qty":0.01300000},{"price":62591.3,"qty":0.00005100},{"price":62588.2,"qty":0.00005100},{"price":62587.6,"qty":0.61734926},{"price":62585.1,"qty":0.00005100},{"price":62583.1,"qty":0.79893666},{"price":62582.1,"qty":0.40000000},{"price":62581.9,"qty":0.00005100}],"asks":[{"price":62593.8,"qty":3.94860754},{"price":62594.4,"qty":0.00005100},{"price":62595.6,"qty":0.79877935},{"price":62596.9,"qty":0.53391620},{"price":62597.0,"qty":1.78861300},{"price":62597.5,"qty":0.00005100},{"price":62598.9,"qty":0.23843780},{"price":62599.0,"qty":0.79873560},{"price":62600.7,"qty":0.00005100},{"price":62602.7,"qty":0.00159700}],"checksum":2235048171,"timestamp":"2026-06-19T05:45:47.808678Z"}]}
{"channel":"book","type":"update","data":[{"symbol":"BTC/USD","bids":[{"price":62583.1,"qty":0.00000000},{"price":62581.4,"qty":0.79895861}],"asks":[],"checksum":105375843,"timestamp":"2026-06-19T05:45:47.859908Z"}]}
{"channel":"book","type":"update","data":[{"symbol":"BTC/USD","bids":[{"price":62584.2,"qty":0.79892306}],"asks":[],"checksum":268859092,"timestamp":"2026-06-19T05:45:47.861648Z"}]}
{"channel":"book","type":"update","data":[{"symbol":"BTC/USD","bids":[{"price":62584.2,"qty":0.00000000},{"price":62581.4,"qty":0.79895861}],"asks":[],"checksum":105375843,"timestamp":"2026-06-19T05:45:47.884456Z"}]}
{"channel":"book","type":"update","data":[{"symbol":"BTC/USD","bids":[{"price":62581.4,"qty":0.00000000},{"price":62578.8,"qty":0.00005100}],"asks":[],"checksum":3273102455,"timestamp":"2026-06-19T05:45:47.884797Z"}]}
{"channel":"book","type":"update","data":[{"symbol":"BTC/USD","bids":[],"asks":[{"price":62593.8,"qty":4.00810754}],"checksum":3989770065,"timestamp":"2026-06-19T05:45:47.934770Z"}]}
{"channel":"book","type":"update","data":[{"symbol":"BTC/USD","bids":[],"asks":[{"price":62593.8,"qty":3.94860754}],"checksum":3273102455,"timestamp":"2026-06-19T05:45:47.937042Z"}]}
{"channel":"book","type":"update","data":[{"symbol":"BTC/USD","bids":[{"price":62584.1,"qty":0.79892394}],"asks":[],"checksum":1766025911,"timestamp":"2026-06-19T05:45:47.965932Z"}]}
{"channel":"book","type":"update","data":[{"symbol":"BTC/USD","bids":[{"price":62593.7,"qty":0.00160001}],"asks":[],"checksum":994786038,"timestamp":"2026-06-19T05:45:48.015293Z"}]}
{"channel":"book","type":"update","data":[{"symbol":"BTC/USD","bids":[],"asks":[{"price":62593.8,"qty":4.00810754}],"checksum":3663978461,"timestamp":"2026-06-19T05:45:48.074112Z"}]}
{"channel":"book","type":"update","data":[{"symbol":"BTC/USD","bids":[],"asks":[{"price":62593.8,"qty":3.94860754}],"checksum":994786038,"timestamp":"2026-06-19T05:45:48.075067Z"}]}
{"channel":"book","type":"update","data":[{"symbol":"BTC/USD","bids":[{"price":62584.1,"qty":0.00000000},{"price":62578.8,"qty":0.00005100}],"asks":[],"checksum":1387910142,"timestamp":"2026-06-19T05:45:48.180146Z"}]}
{"channel":"book","type":"update","data":[{"symbol":"BTC/USD","bids":[{"price":62584.7,"qty":0.79891629}],"asks":[],"checksum":1429513977,"timestamp":"2026-06-19T05:45:48.181438Z"}]}
{"channel":"book","type":"update","data":[{"symbol":"BTC/USD","bids":[{"price":62582.6,"qty":0.79894373}],"asks":[],"checksum":3000898263,"timestamp":"2026-06-19T05:45:48.181710Z"}]}
{"channel":"book","type":"update","data":[{"symbol":"BTC/USD","bids":[{"price":62584.7,"qty":0.00000000},{"price":62581.9,"qty":0.00005100}],"asks":[],"checksum":3246402672,"timestamp":"2026-06-19T05:45:48.226912Z"}]}
{"channel":"book","type":"update","data":[{"symbol":"BTC/USD","bids":[],"asks":[{"price":62593.8,"qty":4.00810754}],"checksum":547932507,"timestamp":"2026-06-19T05:45:48.318399Z"}]}
{"channel":"book","type":"update","data":[{"symbol":"BTC/USD","bids":[],"asks":[{"price":62593.8,"qty":3.94860754}],"checksum":3246402672,"timestamp":"2026-06-19T05:45:48.320613Z"}]}
{"channel":"book","type":"update","data":[{"symbol":"BTC/USD","bids":[{"price":62587.6,"qty":0.00000000},{"price":62578.8,"qty":0.00005100}],"asks":[],"checksum":1343369906,"timestamp":"2026-06-19T05:45:48.365125Z"}]}
{"channel":"book","type":"update","data":[{"symbol":"BTC/USD","bids":[{"price":62582.6,"qty":0.00000000},{"price":62578.5,"qty":0.05642275}],"asks":[],"checksum":2734962328,"timestamp":"2026-06-19T05:45:48.536565Z"}]}
{"channel":"book","type":"update","data":[{"symbol":"BTC/USD","bids":[{"price":62582.3,"qty":0.79894721}],"asks":[],"checksum":1459743368,"timestamp":"2026-06-19T05:45:48.538503Z"}]}
{"channel":"book","type":"update","data":[{"symbol":"BTC/USD","bids":[{"price":62581.1,"qty":0.79896226}],"asks":[],"checksum":3261757074,"timestamp":"2026-06-19T05:45:48.538919Z"}]}
{"channel":"book","type":"update","data":[{"symbol":"BTC/USD","bids":[{"price":62581.1,"qty":0.00000000},{"price":62578.8,"qty":0.00005100}],"asks":[],"checksum":1459743368,"timestamp":"2026-06-19T05:45:48.541147Z"}]}
{"channel":"heartbeat"}
{"channel":"book","type":"update","data":[{"symbol":"BTC/USD","bids":[{"price":62582.1,"qty":0.00000000},{"price":62577.7,"qty":0.10643220}],"asks":[],"checksum":246117514,"timestamp":"2026-06-19T05:45:48.650555Z"}]}
{"channel":"book","type":"update","data":[{"symbol":"BTC/USD","bids":[{"price":62587.8,"qty":0.61734926}],"asks":[],"checksum":3581927677,"timestamp":"2026-06-19T05:45:48.674075Z"}]}
{"channel":"book","type":"update","data":[{"symbol":"BTC/USD","bids":[{"price":62582.3,"qty":0.00000000},{"price":62577.7,"qty":0.10643220}],"asks":[],"checksum":2526438577,"timestamp":"2026-06-19T05:45:48.718476Z"}]}
{"channel":"book","type":"update","data":[{"symbol":"BTC/USD","bids":[{"price":62583.3,"qty":0.79893403}],"asks":[],"checksum":1685505346,"timestamp":"2026-06-19T05:45:48.720575Z"}]}
{"channel":"book","type":"update","data":[{"symbol":"BTC/USD","bids":[{"price":62581.0,"qty":0.79896334}],"asks":[],"checksum":3599358227,"timestamp":"2026-06-19T05:45:48.858705Z"}]}
{"channel":"book","type":"update","data":[{"symbol":"BTC/USD","bids":[{"price":62583.3,"qty":0.00000000},{"price":62578.8,"qty":0.00005100}],"asks":[],"checksum":1747696836,"timestamp":"2026-06-19T05:45:49.118994Z"}]}
{"channel":"book","type":"update","data":[{"symbol":"BTC/USD","bids":[{"price":62583.9,"qty":0.79892628}],"asks":[],"checksum":126409784,"timestamp":"2026-06-19T05:45:49.121270Z"}]}
{"channel":"book","type":"update","data":[{"symbol":"BTC/USD","bids":[],"asks":[{"price":62593.8,"qty":4.00810754}],"checksum":3869260051,"timestamp":"2026-06-19T05:45:49.232980Z"}]}
{"channel":"book","type":"update","data":[{"symbol":"BTC/USD","bids":[{"price":62581.0,"qty":0.00000000},{"price":62578.8,"qty":0.00005100}],"asks":[],"checksum":1047715157,"timestamp":"2026-06-19T05:45:49.541660Z"}]}
{"channel":"book","type":"update","data":[{"symbol":"BTC/USD","bids":[{"price":62582.2,"qty":0.79894883}],"asks":[],"checksum":1373824333,"timestamp":"2026-06-19T05:45:49.543304Z"}]}
{"channel":"book","type":"update","data":[{"symbol":"BTC/USD","bids":[{"price":62583.9,"qty":0.00000000},{"price":62578.8,"qty":0.00005100}],"asks":[],"checksum":2641860490,"timestamp":"2026-06-19T05:45:49.558442Z"}]}
{"channel":"book","type":"update","data":[{"symbol":"BTC/USD","bids":[{"price":62584.8,"qty":0.79891502}],"asks":[],"checksum":2163349085,"timestamp":"2026-06-19T05:45:49.560028Z"}]}
{"channel":"heartbeat"}
{"channel":"book","type":"update","data":[{"symbol":"BTC/USD","bids":[{"price":62584.8,"qty":0.00000000},{"price":62578.8,"qty":0.00005100}],"asks":[],"checksum":2641860490,"timestamp":"2026-06-19T05:45:49.681029Z"}]}
{"channel":"book","type":"update","data":[{"symbol":"BTC/USD","bids":[{"price":62585.5,"qty":0.79890646}],"asks":[],"checksum":1785280094,"timestamp":"2026-06-19T05:45:49.682794Z"}]}
{"channel":"book","type":"update","data":[{"symbol":"BTC/USD","bids":[{"price":62585.5,"qty":0.00000000},{"price":62578.8,"qty":0.00005100}],"asks":[],"checksum":2641860490,"timestamp":"2026-06-19T05:45:49.751329Z"}]}
{"channel":"book","type":"update","data":[{"symbol":"BTC/USD","bids":[{"price":62582.2,"qty":0.00000000},{"price":62577.9,"qty":0.79900288}],"asks":[],"checksum":3240932114,"timestamp":"2026-06-19T05:45:49.751402Z"}]}
{"channel":"book","type":"update","data":[{"symbol":"BTC/USD","bids":[{"price":62581.1,"qty":0.06240000}],"asks":[],"checksum":3683379898,"timestamp":"2026-06-19T05:45:49.770177Z"}]}
{"channel":"book","type":"update","data":[{"symbol":"BTC/USD","bids":[{"price":62583.8,"qty":0.01597496}],"asks":[],"checksum":4213129338,"timestamp":"2026-06-19T05:45:49.773594Z"}]}
{"channel":"book","type":"update","data":[{"symbol":"BTC/USD","bids":[{"price":62582.5,"qty":0.01597496}],"asks":[],"checksum":3274918833,"timestamp":"2026-06-19T05:45:49.773646Z"}]}
{"channel":"book","type":"update","data":[{"symbol":"BTC/USD","bids":[],"asks":[{"price":62593.8,"qty":3.39075828}],"checksum":1291228705,"timestamp":"2026-06-19T05:45:49.786613Z"}]}
{"channel":"book","type":"update","data":[{"symbol":"BTC/USD","bids":[{"price":62587.8,"qty":0.00000000},{"price":62581.1,"qty":0.06240000}],"asks":[],"checksum":2205926633,"timestamp":"2026-06-19T05:45:49.786637Z"}]}
{"channel":"book","type":"update","data":[{"symbol":"BTC/USD","bids":[{"price":62586.8,"qty":0.79888943}],"asks":[],"checksum":1370673178,"timestamp":"2026-06-19T05:45:49.791308Z"}]}
{"channel":"book","type":"update","data":[{"symbol":"BTC/USD","bids":[],"asks":[{"price":62593.8,"qty":3.09075828}],"checksum":2474994776,"timestamp":"2026-06-19T05:45:49.792973Z"}]}
{"channel":"book","type":"update","data":[{"symbol":"BTC/USD","bids":[],"asks":[{"price":62595.6,"qty":0.00000000},{"price":62603.0,"qty":0.06071248}],"checksum":1957929310,"timestamp":"2026-06-19T05:45:49.802564Z"}]}
{"channel":"book","type":"update","data":[{"symbol":"BTC/USD","bids":[],"asks":[{"price":62593.8,"qty":2.29195713}],"checksum":1587353157,"timestamp":"2026-06-19T05:45:49.803555Z"}]}
{"channel":"book","type":"update","data":[{"symbol":"BTC/USD","bids":[],"asks":[{"price":62593.8,"qty":1.85087380}],"checksum":1063631282,"timestamp":"2026-06-19T05:45:49.804633Z"}]}
{"channel":"book","type":"update","data":[{"symbol":"BTC/USD","bids":[],"asks":[{"price":62602.9,"qty":0.01813790}],"checksum":3641062910,"timestamp":"2026-06-19T05:45:49.806737Z"}]}
{"channel":"book","type":"update","data":[{"symbol":"BTC/USD","bids":[],"asks":[{"price":62594.6,"qty":0.79879157}],"checksum":899260472,"timestamp":"2026-06-19T05:45:49.807440Z"}]}
{"channel":"book","type":"update","data":[{"symbol":"BTC/USD","bids":[],"asks":[{"price":62596.8,"qty":0.79876319}],"checksum":1959865722,"timestamp":"2026-06-19T05:45:49.807786Z"}]}
{"channel":"book","type":"update","data":[{"symbol":"BTC/USD","bids":[],"asks":[{"price":62593.8,"qty":1.78847380}],"checksum":4023326092,"timestamp":"2026-06-19T05:45:49.808133Z"}]}
{"channel":"book","type":"update","data":[{"symbol":"BTC/USD","bids":[{"price":62583.9,"qty":0.01597775}],"asks":[],"checksum":3717421480,"timestamp":"2026-06-19T05:45:49.821491Z"}]}
{"channel":"book","type":"update","data":[{"symbol":"BTC/USD","bids":[{"price":62582.6,"qty":0.02396663}],"asks":[],"checksum":4167564416,"timestamp":"2026-06-19T05:45:49.821746Z"}]}
{"channel":"book","type":"update","data":[{"symbol":"BTC/USD","bids":[{"price":62590.1,"qty":0.61734926}],"asks":[],"checksum":4070401556,"timestamp":"2026-06-19T05:45:49.827247Z"}]}
{"channel":"book","type":"update","data":[{"symbol":"BTC/USD","bids":[],"asks":[{"price":62595.8,"qty":0.61734926}],"checksum":4196738141,"timestamp":"2026-06-19T05:45:49.827460Z"}]}
{"channel":"book","type":"update","data":[{"symbol":"BTC/USD","bids":[{"price":62590.1,"qty":0.00000000},{"price":62582.6,"qty":0.02396663}],"asks":[],"checksum":756586701,"timestamp":"2026-06-19T05:45:49.833805Z"}]}
{"channel":"book","type":"update","data":[{"symbol":"BTC/USD","bids":[],"asks":[{"price":62595.8,"qty":0.00000000},{"price":62600.7,"qty":0.00005100}],"checksum":4167564416,"timestamp":"2026-06-19T05:45:49.834041Z"}]}
{"channel":"book","type":"update","data":[{"symbol":"BTC/USD","bids":[{"price":62583.8,"qty":0.81490257}],"asks":[],"checksum":3054126170,"timestamp":"2026-06-19T05:45:49.859187Z"}]}
{"channel":"book","type":"update","data":[{"symbol":"BTC/USD","bids":[],"asks":[{"price":62597.3,"qty":0.61734926}],"checksum":470226806,"timestamp":"2026-06-19T05:45:49.974030Z"}]}
{"channel":"book","type":"update","data":[{"symbol":"BTC/USD","bids":[{"price":62591.8,"qty":0.61734926}],"asks":[],"checksum":585623812,"timestamp":"2026-06-19T05:45:49.974346Z"}]}
{"channel":"book","type":"update","data":[{"symbol":"BTC/USD","bids":[],"asks":[{"price":62598.5,"qty":0.98376900}],"checksum":2724390014,"timestamp":"2026-06-19T05:45:50.086828Z"}]}
{"channel":"book","type":"update","data":[{"symbol":"BTC/USD","bids":[],"asks":[{"price":62598.9,"qty":0.00000000},{"price":62599.0,"qty":0.79873560}],"checksum":1748863151,"timestamp":"2026-06-19T05:45:50.087861Z"}]}
{"channel":"book","type":"update","data":[{"symbol":"BTC/USD","bids":[],"asks":[{"price":62598.4,"qty":0.53209285}],"checksum":1560769871,"timestamp":"2026-06-19T05:45:50.089216Z"}]}
{"channel":"book","type":"update","data":[{"symbol":"BTC/USD","bids":[],"asks":[{"price":62594.6,"qty":0.00000000},{"price":62599.0,"qty":0.79873560}],"checksum":4018081739,"timestamp":"2026-06-19T05:45:50.121563Z"}]}
{"channel":"book","type":"update","data":[{"symbol":"BTC/USD","bids":[],"asks":[{"price":62593.9,"qty":0.79880113}],"checksum":3615873789,"timestamp":"2026-06-19T05:45:50.123004Z"}]}
{"channel":"book","type":"update","data":[{"symbol":"BTC/USD","bids":[],"asks":[{"price":62597.3,"qty":0.00000000},{"price":62599.0,"qty":0.79873560}],"checksum":2903562413,"timestamp":"2026-06-19T05:45:50.138477Z"}]}
{"channel":"book","type":"update","data":[{"symbol":"BTC/USD","bids":[{"price":62591.8,"qty":0.00000000},{"price":62582.6,"qty":0.02396663}],"asks":[],"checksum":2393391530,"timestamp":"2026-06-19T05:45:50.138720Z"}]}
{"channel":"book","type":"update","data":[{"symbol":"BTC/USD","bids":[{"price":62590.7,"qty":0.61734926}],"asks":[],"checksum":2172878153,"timestamp":"2026-06-19T05:45:50.281371Z"}]}
{"channel":"book","type":"update","data":[{"symbol":"BTC/USD","bids":[],"asks":[{"price":62599.0,"qty":0.00000000},{"price":62600.7,"qty":0.00005100}],"checksum":3130493116,"timestamp":"2026-06-19T05:45:50.498730Z"}]}
{"channel":"book","type":"update","data":[{"symbol":"BTC/USD","bids":[{"price":62583.8,"qty":0.01597496}],"asks":[],"checksum":593911055,"timestamp":"2026-06-19T05:45:50.498812Z"}]}
{"channel":"book","type":"update","data":[{"symbol":"BTC/USD","bids":[],"asks":[{"price":62593.9,"qty":0.00000000},{"price":62602.7,"qty":0.00159700}],"checksum":1505094040,"timestamp":"2026-06-19T05:45:50.498974Z"}]}
{"channel":"book","type":"update","data":[{"symbol":"BTC/USD","bids":[],"asks":[{"price":62598.4,"qty":0.00000000},{"price":62602.9,"qty":0.01813790}],"checksum":2403582673,"timestamp":"2026-06-19T05:45:50.499883Z"}]}
{"channel":"book","type":"update","data":[{"symbol":"BTC/USD","bids":[],"asks":[{"price":62595.1,"qty":0.79878554}],"checksum":1131110604,"timestamp":"2026-06-19T05:45:50.500764Z"}]}
{"channel":"book","type":"update","data":[{"symbol":"BTC/USD","bids":[],"asks":[{"price":62598.4,"qty":0.29367027}],"checksum":2511708526,"timestamp":"2026-06-19T05:45:50.501105Z"}]}
{"channel":"book","type":"update","data":[{"symbol":"BTC/USD","bids":[{"price":62585.0,"qty":0.79891225}],"asks":[],"checksum":1462653412,"timestamp":"2026-06-19T05:45:50.501470Z"}]}
{"channel":"heartbeat"}
{"channel":"book","type":"update","data":[{"symbol":"BTC/USD","bids":[{"price":62586.8,"qty":0.00000000},{"price":62583.8,"qty":0.01597496}],"asks":[],"checksum":1915270569,"timestamp":"2026-06-19T05:45:50.649450Z"}]}
{"channel":"book","type":"update","data":[{"symbol":"BTC/USD","bids":[{"price":62587.7,"qty":0.79887826}],"asks":[],"checksum":256018130,"timestamp":"2026-06-19T05:45:50.652692Z"}]}
{"channel":"book","type":"update","data":[{"symbol":"BTC/USD","bids":[],"asks":[{"price":62596.8,"qty":0.00000000},{"price":62601.5,"qty":0.25702724}],"checksum":1057612197,"timestamp":"2026-06-19T05:45:50.656595Z"}]}
{"channel":"book","type":"update","data":[{"symbol":"BTC/USD","bids":[],"asks":[{"price":62595.1,"qty":0.00000000},{"price":62601.6,"qty":0.79870230}],"checksum":830124215,"timestamp":"2026-06-19T05:45:50.657551Z"}]}
{"channel":"book","type":"update","data":[{"symbol":"BTC/USD","bids":[],"asks":[{"price":62593.8,"qty":1.27055893}],"checksum":3571073825,"timestamp":"2026-06-19T05:45:50.658028Z"}]}
{"channel":"book","type":"update","data":[{"symbol":"BTC/USD","bids":[{"price":62585.0,"qty":0.00000000},{"price":62583.8,"qty":0.01597496}],"asks":[],"checksum":2988614521,"timestamp":"2026-06-19T05:45:50.658105Z"}]}
{"channel":"book","type":"update","data":[{"symbol":"BTC/USD","bids":[{"price":62587.7,"qty":0.00000000},{"price":62582.6,"qty":0.02396663}],"asks":[],"checksum":685515371,"timestamp":"2026-06-19T05:45:50.658162Z"}]}
{"channel":"book","type":"update","data":[{"symbol":"BTC/USD","bids":[],"asks":[{"price":62593.8,"qty":1.11240148}],"checksum":1991953111,"timestamp":"2026-06-19T05:45:50.661063Z"}]}
{"channel":"book","type":"update","data":[{"symbol":"BTC/USD","bids":[],"asks":[{"price":62593.8,"qty":0.75032061}],"checksum":921342721,"timestamp":"2026-06-19T05:45:50.661315Z"}]}
{"channel":"book","type":"update","data":[{"symbol":"BTC/USD","bids":[],"asks":[{"price":62598.1,"qty":0.79874663}],"checksum":2792835027,"timestamp":"2026-06-19T05:45:50.665079Z"}]}
{"channel":"book","type":"update","data":[{"symbol":"BTC/USD","bids":[{"price":62583.1,"qty":0.79893756}],"asks":[],"checksum":1287495703,"timestamp":"2026-06-19T05:45:50.665277Z"}]}
{"channel":"book","type":"update","data":[{"symbol":"BTC/USD","bids":[],"asks":[{"price":62598.1,"qty":0.00000000},{"price":62602.7,"qty":0.00159700}],"checksum":1106108474,"timestamp":"2026-06-19T05:45:50.667180Z"}]}
{"channel":"book","type":"update","data":[{"symbol":"BTC/USD","bids":[],"asks":[{"price":62596.9,"qty":1.15126546}],"checksum":493148607,"timestamp":"2026-06-19T05:45:50.667492Z"}]}
{"channel":"book","type":"update","data":[{"symbol":"BTC/USD","bids":[],"asks":[{"price":62597.5,"qty":0.79880606}],"checksum":393513092,"timestamp":"2026-06-19T05:45:50.668942Z"}]}
{"channel":"book","type":"update","data":[{"symbol":"BTC/USD","bids":[],"asks":[{"price":62601.5,"qty":0.00000000},{"price":62603.0,"qty":0.06071248}],"checksum":2465967097,"timestamp":"2026-06-19T05:45:50.669107Z"}]}
{"channel":"book","type":"update","data":[{"symbol":"BTC/USD","bids":[],"asks":[{"price":62601.5,"qty":0.01861460}],"checksum":917155322,"timestamp":"2026-06-19T05:45:50.669192Z"}]}
{"channel":"book","type":"update","data":[{"symbol":"BTC/USD","bids":[],"asks":[{"price":62593.8,"qty":0.74791438}],"checksum":4052467015,"timestamp":"2026-06-19T05:45:50.705800Z"}]}
{"channel":"book","type":"update","data":[{"symbol":"BTC/USD","bids":[],"asks":[{"price":62597.5,"qty":0.00005100}],"checksum":2738069858,"timestamp":"2026-06-19T05:45:50.766123Z"}]}
{"channel":"book","type":"update","data":[{"symbol":"BTC/USD","bids":[{"price":62589.3,"qty":0.79885822}],"asks":[],"checksum":4220855850,"timestamp":"2026-06-19T05:45:50.767509Z"}]}
{"channel":"book","type":"update","data":[{"symbol":"BTC/USD","bids":[],"asks":[{"price":62596.6,"qty":0.79876654}],"checksum":4220543345,"timestamp":"2026-06-19T05:45:50.769613Z"}]}
{"channel":"book","type":"update","data":[{"symbol":"BTC/USD","bids":[],"asks":[{"price":62596.9,"qty":0.61734926}],"checksum":3971582542,"timestamp":"2026-06-19T05:45:50.771117Z"}]}
{"channel":"book","type":"update","data":[{"symbol":"BTC/USD","bids":[],"asks":[{"price":62596.5,"qty":0.95662677}],"checksum":3443778855,"timestamp":"2026-06-19T05:45:50.772677Z"}]}
{"channel":"book","type":"update","data":[{"symbol":"BTC/USD","bids":[{"price":62587.7,"qty":0.79887851}],"asks":[],"checksum":139990747,"timestamp":"2026-06-19T05:45:50.859758Z"}]}
{"channel":"book","type":"update","data":[{"symbol":"BTC/USD","bids":[{"price":62589.3,"qty":0.00000000},{"price":62583.8,"qty":0.01597496}],"asks":[],"checksum":2351195433,"timestamp":"2026-06-19T05:45:51.122147Z"}]}
{"channel":"book","type":"update","data":[{"symbol":"BTC/USD","bids":[],"asks":[{"price":62598.3,"qty":0.79874440}],"checksum":1828531340,"timestamp":"2026-06-19T05:45:51.123974Z"}]}
{"channel":"book","type":"update","data":[{"symbol":"BTC/USD","bids":[],"asks":[{"price":62598.3,"qty":0.00000000},{"price":62600.7,"qty":0.00005100}],"checksum":2351195433,"timestamp":"2026-06-19T05:45:51.124251Z"}]}
{"channel":"book","type":"update","data":[{"symbol":"BTC/USD","bids":[],"asks":[{"price":62595.4,"qty":0.79878190}],"checksum":481749316,"timestamp":"2026-06-19T05:45:51.189175Z"}]}
{"channel":"book","type":"update","data":[{"symbol":"BTC/USD","bids":[],"asks":[{"price":62596.6,"qty":0.00000000},{"price":62600.7,"qty":0.00005100}],"checksum":130536439,"timestamp":"2026-06-19T05:45:51.189271Z"}]}
{"channel":"book","type":"update","data":[{"symbol":"BTC/USD","bids":[{"price":62585.8,"qty":0.79890278}],"asks":[],"checksum":3899188626,"timestamp":"2026-06-19T05:45:51.189546Z"}]}
{"channel":"book","type":"update","data":[{"symbol":"BTC/USD","bids":[],"asks":[{"price":62593.8,"qty":0.81031438}],"checksum":1040582566,"timestamp":"2026-06-19T05:45:51.294119Z"}]}
{"channel":"heartbeat"}
{"channel":"book","type":"update","data":[{"symbol":"BTC/USD","bids":[],"asks":[{"price":62600.2,"qty":0.01326617}],"checksum":374734082,"timestamp":"2026-06-19T05:45:51.840485Z"}]}
{"channel":"book","type":"update","data":[{"symbol":"BTC/USD","bids":[{"price":62593.7,"qty":0.00242405}],"asks":[],"checksum":3984116452,"timestamp":"2026-06-19T05:45:51.856812Z"}]}
{"channel":"book","type":"update","data":[{"symbol":"BTC/USD","bids":[],"asks":[{"price":62598.1,"qty":0.79874712}],"checksum":3453167393,"timestamp":"2026-06-19T05:45:51.859007Z"}]}
{"channel":"book","type":"update","data":[{"symbol":"BTC/USD","bids":[{"price":62587.7,"qty":0.00000000},{"price":62583.8,"qty":0.01597496}],"asks":[],"checksum":3866564457,"timestamp":"2026-06-19T05:45:51.952682Z"}]}
{"channel":"book","type":"update","data":[{"symbol":"BTC/USD","bids":[{"price":62588.6,"qty":0.79886681}],"asks":[],"checksum":2859299594,"timestamp":"2026-06-19T05:45:51.954213Z"}]}
{"channel":"book","type":"update","data":[{"symbol":"BTC/USD","bids":[{"price":62593.7,"qty":0.00160001}],"asks":[],"checksum":1363166444,"timestamp":"2026-06-19T05:45:51.969216Z"}]}
{"channel":"book","type":"update","data":[{"symbol":"BTC/USD","bids":[{"price":62590.7,"qty":0.00000000},{"price":62583.8,"qty":0.01597496}],"asks":[],"checksum":136914080,"timestamp":"2026-06-19T05:45:51.983943Z"}]}
{"channel":"book","type":"update","data":[{"symbol":"BTC/USD","bids":[],"asks":[{"price":62593.8,"qty":0.74791438}],"checksum":3976836107,"timestamp":"2026-06-19T05:45:51.995243Z"}]}
{"channel":"book","type":"update","data":[{"symbol":"BTC/USD","bids":[],"asks":[{"price":62595.4,"qty":0.00000000},{"price":62600.2,"qty":0.01326617}],"checksum":2997372258,"timestamp":"2026-06-19T05:45:51.999251Z"}]}
{"channel":"book","type":"update","data":[{"symbol":"BTC/USD","bids":[{"price":62588.6,"qty":0.00000000},{"price":62583.1,"qty":0.79893756}],"asks":[],"checksum":3641500716,"timestamp":"2026-06-19T05:45:51.999517Z"}]}
{"channel":"book","type":"update","data":[{"symbol":"BTC/USD","bids":[{"price":62585.8,"qty":0.00000000},{"price":62582.6,"qty":0.02396663}],"asks":[],"checksum":72539433,"timestamp":"2026-06-19T05:45:51.999842Z"}]}
{"channel":"book","type":"update","data":[{"symbol":"BTC/USD","bids":[],"asks":[{"price":62596.5,"qty":1.75539351}],"checksum":2857519438,"timestamp":"2026-06-19T05:45:52.001538Z"}]}
{"channel":"book","type":"update","data":[{"symbol":"BTC/USD","bids":[{"price":62587.0,"qty":0.79888693}],"asks":[],"checksum":2184405599,"timestamp":"2026-06-19T05:45:52.001981Z"}]}
{"channel":"book","type":"update","data":[{"symbol":"BTC/USD","bids":[{"price":62583.2,"qty":0.03484611}],"asks":[],"checksum":1463068609,"timestamp":"2026-06-19T05:45:52.002280Z"}]}
{"channel":"book","type":"update","data":[{"symbol":"BTC/USD","bids":[],"asks":[{"price":62596.5,"qty":0.95662677}],"checksum":4180947878,"timestamp":"2026-06-19T05:45:52.052900Z"}]}
{"channel":"book","type":"update","data":[{"symbol":"BTC/USD","bids":[{"price":62589.3,"qty":0.79885779}],"asks":[],"checksum":2687633846,"timestamp":"2026-06-19T05:45:52.054437Z"}]}
{"channel":"book","type":"update","data":[{"symbol":"BTC/USD","bids":[{"price":62589.3,"qty":0.00000000},{"price":62583.2,"qty":0.03484611}],"asks":[],"checksum":4180947878,"timestamp":"2026-06-19T05:45:52.117657Z"}]}
{"channel":"book","type":"update","data":[{"symbol":"BTC/USD","bids":[],"asks":[{"price":62596.1,"qty":0.79877242}],"checksum":230011329,"timestamp":"2026-06-19T05:45:52.119138Z"}]}
{"channel":"book","type":"update","data":[{"symbol":"BTC/USD","bids":[{"price":62591.5,"qty":0.61734926}],"asks":[],"checksum":3590680114,"timestamp":"2026-06-19T05:45:52.179538Z"}]}
{"channel":"book","type":"update","data":[{"symbol":"BTC/USD","bids":[{"price":62591.4,"qty":0.00000000},{"price":62583.2,"qty":0.03484611},{"price":62591.6,"qty":0.01300000}],"asks":[],"checksum":2818916582,"timestamp":"2026-06-19T05:45:52.532662Z"}]}
{"channel":"heartbeat"}
{"channel":"book","type":"update","data":[{"symbol":"BTC/USD","bids":[],"asks":[{"price":62596.1,"qty":0.00000000},{"price":62600.2,"qty":0.01326617}],"checksum":2066167199,"timestamp":"2026-06-19T05:45:52.650902Z"}]}
{"channel":"book","type":"update","data":[{"symbol":"BTC/USD","bids":[],"asks":[{"price":62595.3,"qty":0.79878274}],"checksum":1059569168,"timestamp":"2026-06-19T05:45:52.652769Z"}]}
{"channel":"book","type":"update","data":[{"symbol":"BTC/USD","bids":[{"price":62588.3,"qty":0.79887021}],"asks":[],"checksum":468247970,"timestamp":"2026-06-19T05:45:52.652939Z"}]}
{"channel":"book","type":"update","data":[{"symbol":"BTC/USD","bids":[],"asks":[{"price":62593.8,"qty":0.81031438}],"checksum":1510588242,"timestamp":"2026-06-19T05:45:52.711045Z"}]}
{"channel":"book","type":"update","data":[{"symbol":"BTC/USD","bids":[{"price":62591.5,"qty":0.00000000},{"price":62583.8,"qty":0.01597496}],"asks":[],"checksum":2388471212,"timestamp":"2026-06-19T05:45:53.297244Z"}]}
{"channel":"book","type":"update","data":[{"symbol":"BTC/USD","bids":[],"asks":[{"price":62593.8,"qty":0.74791438}],"checksum":1803402503,"timestamp":"2026-06-19T05:45:53.383263Z"}]}
{"channel":"heartbeat"}
{"channel":"book","type":"update","data":[{"symbol":"BTC/USD","bids":[{"price":62590.5,"qty":0.61734926}],"asks":[],"checksum":2307898486,"timestamp":"2026-06-19T05:45:53.606221Z"}]}
{"channel":"book","type":"update","data":[{"symbol":"BTC/USD","bids":[],"asks":[{"price":62593.8,"qty":0.68841438}],"checksum":457374825,"timestamp":"2026-06-19T05:45:53.963637Z"}]}
{"channel":"book","type":"update","data":[{"symbol":"BTC/USD","bids":[],"asks":[{"price":62593.8,"qty":0.74791438}],"checksum":2307898486,"timestamp":"2026-06-19T05:45:54.026260Z"}]}
{"channel":"book","type":"update","data":[{"symbol":"BTC/USD","bids":[],"asks":[{"price":62593.8,"qty":0.68841438}],"checksum":457374825,"timestamp":"2026-06-19T05:45:54.033826Z"}]}
{"channel":"book","type":"update","data":[{"symbol":"BTC/USD","bids":[],"asks":[{"price":62593.8,"qty":0.71851438}],"checksum":4036207242,"timestamp":"2026-06-19T05:45:54.034545Z"}]}
