{"channel":"status","type":"update","data":[{"version":"2.0.10","system":"online","api_version":"v2","connection_id":16318054270093320166}]}
{"method":"subscribe","result":{"channel":"book","depth":10,"snapshot":true,"symbol":"BTC/USD"},"success":true,"time_in":"2026-07-15T03:58:57.932918Z","time_out":"2026-07-15T03:58:57.932958Z"}
{"method":"subscribe","result":{"channel":"trade","snapshot":false,"symbol":"BTC/USD"},"success":true,"time_in":"2026-07-15T03:58:57.941601Z","time_out":"2026-07-15T03:58:57.941632Z"}
{"channel":"book","type":"snapshot","data":[{"symbol":"BTC/USD","bids":[{"price":64760.4,"qty":0.10077301},{"price":64757.4,"qty":0.00005100},{"price":64756.7,"qty":0.01094531},{"price":64755.0,"qty":0.00308857},{"price":64754.9,"qty":0.04217440},{"price":64754.7,"qty":0.77214427},{"price":64754.1,"qty":0.00005100},{"price":64753.9,"qty":0.05820000},{"price":64752.8,"qty":0.77216687},{"price":64751.2,"qty":0.43171818}],"asks":[{"price":64760.5,"qty":0.46356875},{"price":64761.2,"qty":0.77206752},{"price":64762.4,"qty":0.59681263},{"price":64763.4,"qty":0.00154409},{"price":64763.6,"qty":0.77203954},{"price":64763.7,"qty":0.00005100},{"price":64764.1,"qty":0.00308813},{"price":64764.5,"qty":0.03088110},{"price":64765.2,"qty":0.04246989},{"price":64765.6,"qty":0.27044128}],"checksum":730304764,"timestamp":"2026-07-15T03:58:57.870683Z"}]}
{"channel":"heartbeat"}
{"channel":"book","type":"update","data":[{"symbol":"BTC/USD","bids":[{"price":64755.0,"qty":0.00154428}],"asks":[],"checksum":343207134,"timestamp":"2026-07-15T03:58:58.994997Z"}]}
{"channel":"heartbeat"}
{"channel":"book","type":"update","data":[{"symbol":"BTC/USD","bids":[{"price":64754.1,"qty":0.00159531}],"asks":[],"checksum":2211660835,"timestamp":"2026-07-15T03:59:00.101543Z"}]}
{"channel":"book","type":"update","data":[{"symbol":"BTC/USD","bids":[],"asks":[{"price":64763.4,"qty":0.00000000},{"price":64765.7,"qty":0.09385982}],"checksum":1981330277,"timestamp":"2026-07-15T03:59:00.101799Z"}]}
{"channel":"book","type":"update","data":[{"symbol":"BTC/USD","bids":[],"asks":[{"price":64762.3,"qty":0.00154411}],"checksum":2626603659,"timestamp":"2026-07-15T03:59:00.102677Z"}]}
{"channel":"heartbeat"}
{"channel":"book","type":"update","data":[{"symbol":"BTC/USD","bids":[{"price":64753.9,"qty":0.00000000},{"price":64751.1,"qty":0.60881263}],"asks":[],"checksum":4291359830,"timestamp":"2026-07-15T03:59:01.141659Z"}]}
{"channel":"book","type":"update","data":[{"symbol":"BTC/USD","bids":[{"price":64754.9,"qty":0.00000000},{"price":64750.9,"qty":0.00005100}],"asks":[],"checksum":4008844498,"timestamp":"2026-07-15T03:59:01.141808Z"}]}
{"channel":"book","type":"update","data":[{"symbol":"BTC/USD","bids":[{"price":64751.2,"qty":0.00000000},{"price":64750.1,"qty":0.77219929}],"asks":[],"checksum":2984148139,"timestamp":"2026-07-15T03:59:01.141924Z"}]}
{"channel":"book","type":"update","data":[{"symbol":"BTC/USD","bids":[],"asks":[{"price":64762.4,"qty":0.00000000},{"price":64765.7,"qty":0.09385982}],"checksum":2789792634,"timestamp":"2026-07-15T03:59:01.142211Z"}]}
{"channel":"book","type":"update","data":[{"symbol":"BTC/USD","bids":[{"price":64751.1,"qty":0.01200000}],"asks":[],"checksum":3523847910,"timestamp":"2026-07-15T03:59:01.142394Z"}]}
{"channel":"book","type":"update","data":[{"symbol":"BTC/USD","bids":[{"price":64754.1,"qty":0.00005100}],"asks":[],"checksum":1719794865,"timestamp":"2026-07-15T03:59:01.142872Z"}]}
{"channel":"book","type":"update","data":[{"symbol":"BTC/USD","bids":[{"price":64756.7,"qty":0.00000000},{"price":64749.6,"qty":0.40000000}],"asks":[],"checksum":3173427612,"timestamp":"2026-07-15T03:59:01.142884Z"}]}
{"channel":"book","type":"update","data":[{"symbol":"BTC/USD","bids":[{"price":64754.7,"qty":0.00000000},{"price":64748.1,"qty":0.03085927}],"asks":[],"checksum":1455700366,"timestamp":"2026-07-15T03:59:01.143316Z"}]}
{"channel":"book","type":"update","data":[{"symbol":"BTC/USD","bids":[{"price":64752.8,"qty":0.00000000},{"price":64748.0,"qty":0.63219848}],"asks":[],"checksum":1362322684,"timestamp":"2026-07-15T03:59:01.143365Z"}]}
{"channel":"book","type":"update","data":[{"symbol":"BTC/USD","bids":[],"asks":[{"price":64761.1,"qty":0.64968048}],"checksum":1448655777,"timestamp":"2026-07-15T03:59:01.143430Z"}]}
{"channel":"book","type":"update","data":[{"symbol":"BTC/USD","bids":[{"price":64750.1,"qty":0.00000000},{"price":64747.7,"qty":0.00005100}],"asks":[],"checksum":2545673741,"timestamp":"2026-07-15T03:59:01.143467Z"}]}
{"channel":"book","type":"update","data":[{"symbol":"BTC/USD","bids":[],"asks":[{"price":64761.1,"qty":0.00000000},{"price":64765.7,"qty":0.09385982}],"checksum":219152967,"timestamp":"2026-07-15T03:59:01.143689Z"}]}
{"channel":"book","type":"update","data":[{"symbol":"BTC/USD","bids":[],"asks":[{"price":64761.2,"qty":0.00000000},{"price":64767.0,"qty":0.05825100}],"checksum":3394228654,"timestamp":"2026-07-15T03:59:01.143742Z"}]}
{"channel":"book","type":"update","data":[{"symbol":"BTC/USD","bids":[],"asks":[{"price":64760.5,"qty":0.52176875}],"checksum":216435943,"timestamp":"2026-07-15T03:59:01.144820Z"}]}
{"channel":"book","type":"update","data":[{"symbol":"BTC/USD","bids":[],"asks":[{"price":64763.6,"qty":0.00000000},{"price":64767.2,"qty":0.00154300}],"checksum":526522882,"timestamp":"2026-07-15T03:59:01.144936Z"}]}
{"channel":"book","type":"update","data":[{"symbol":"BTC/USD","bids":[],"asks":[{"price":64761.1,"qty":0.47153191}],"checksum":2389150880,"timestamp":"2026-07-15T03:59:01.145120Z"}]}
{"channel":"book","type":"update","data":[{"symbol":"BTC/USD","bids":[],"asks":[{"price":64761.1,"qty":0.00000000},{"price":64767.2,"qty":0.00154300}],"checksum":526522882,"timestamp":"2026-07-15T03:59:01.145468Z"}]}
{"channel":"book","type":"update","data":[{"symbol":"BTC/USD","bids":[{"price":64754.8,"qty":0.00038235}],"asks":[],"checksum":1438724748,"timestamp":"2026-07-15T03:59:01.147047Z"}]}
{"channel":"book","type":"update","data":[{"symbol":"BTC/USD","bids":[{"price":64755.0,"qty":0.00000000},{"price":64747.7,"qty":0.00005100}],"asks":[],"checksum":3135611369,"timestamp":"2026-07-15T03:59:01.147326Z"}]}
{"channel":"book","type":"update","data":[{"symbol":"BTC/USD","bids":[{"price":64750.2,"qty":0.01179642}],"asks":[],"checksum":1005697376,"timestamp":"2026-07-15T03:59:01.147375Z"}]}
{"channel":"book","type":"update","data":[{"symbol":"BTC/USD","bids":[],"asks":[{"price":64760.5,"qty":0.52886922}],"checksum":748469600,"timestamp":"2026-07-15T03:59:01.149082Z"}]}
{"channel":"book","type":"update","data":[{"symbol":"BTC/USD","bids":[{"price":64754.8,"qty":0.00000000},{"price":64747.7,"qty":0.00005100}],"asks":[],"checksum":3601266231,"timestamp":"2026-07-15T03:59:01.149862Z"}]}
{"channel":"book","type":"update","data":[{"symbol":"BTC/USD","bids":[{"price":64751.2,"qty":0.00154437}],"asks":[],"checksum":985384289,"timestamp":"2026-07-15T03:59:01.150214Z"}]}
{"channel":"book","type":"update","data":[{"symbol":"BTC/USD","bids":[],"asks":[{"price":64760.5,"qty":0.52176875}],"checksum":984393829,"timestamp":"2026-07-15T03:59:01.152267Z"}]}
{"channel":"book","type":"update","data":[{"symbol":"BTC/USD","bids":[],"asks":[{"price":64765.6,"qty":0.04586567}],"checksum":643306996,"timestamp":"2026-07-15T03:59:01.153834Z"}]}
{"channel":"book","type":"update","data":[{"symbol":"BTC/USD","bids":[],"asks":[{"price":64760.5,"qty":1.29384432}],"checksum":2893062575,"timestamp":"2026-07-15T03:59:01.156225Z"}]}
{"channel":"book","type":"update","data":[{"symbol":"BTC/USD","bids":[],"asks":[{"price":64762.5,"qty":0.77205204}],"checksum":3208160435,"timestamp":"2026-07-15T03:59:01.156265Z"}]}
{"channel":"book","type":"update","data":[{"symbol":"BTC/USD","bids":[],"asks":[{"price":64764.8,"qty":0.77202461}],"checksum":3216194364,"timestamp":"2026-07-15T03:59:01.156658Z"}]}
{"channel":"book","type":"update","data":[{"symbol":"BTC/USD","bids":[],"asks":[{"price":64760.5,"qty":1.33258853}],"checksum":4240437338,"timestamp":"2026-07-15T03:59:01.156677Z"}]}
{"channel":"book","type":"update","data":[{"symbol":"BTC/USD","bids":[{"price":64749.3,"qty":0.77220911}],"asks":[],"checksum":2993182643,"timestamp":"2026-07-15T03:59:01.157099Z"}]}
{"channel":"book","type":"update","data":[{"symbol":"BTC/USD","bids":[],"asks":[{"price":64765.2,"qty":0.00000000},{"price":64767.0,"qty":0.05825100}],"checksum":233524270,"timestamp":"2026-07-15T03:59:01.158307Z"}]}
{"channel":"book","type":"update","data":[{"symbol":"BTC/USD","bids":[],"asks":[{"price":64762.4,"qty":0.19968751}],"checksum":3886415917,"timestamp":"2026-07-15T03:59:01.158584Z"}]}
{"channel":"book","type":"update","data":[{"symbol":"BTC/USD","bids":[],"asks":[{"price":64762.4,"qty":0.44030008}],"checksum":4280337717,"timestamp":"2026-07-15T03:59:01.158768Z"}]}
{"channel":"book","type":"update","data":[{"symbol":"BTC/USD","bids":[],"asks":[{"price":64760.5,"qty":1.33968900}],"checksum":953532022,"timestamp":"2026-07-15T03:59:01.160782Z"}]}
{"channel":"book","type":"update","data":[{"symbol":"BTC/USD","bids":[],"asks":[{"price":64760.5,"qty":1.93650163}],"checksum":187536185,"timestamp":"2026-07-15T03:59:01.170825Z"}]}
{"channel":"book","type":"update","data":[{"symbol":"BTC/USD","bids":[{"price":64748.1,"qty":0.00000000},{"price":64747.7,"qty":0.00005100},{"price":64747.8,"qty":0.03086225}],"asks":[],"checksum":993355488,"timestamp":"2026-07-15T03:59:01.179610Z"}]}
{"channel":"heartbeat"}
{"channel":"book","type":"update","data":[{"symbol":"BTC/USD","bids":[{"price":64749.3,"qty":0.00000000},{"price":64747.7,"qty":0.00005100}],"asks":[],"checksum":2847711611,"timestamp":"2026-07-15T03:59:01.918533Z"}]}
{"channel":"book","type":"update","data":[{"symbol":"BTC/USD","bids":[{"price":64748.3,"qty":0.77222057}],"asks":[],"checksum":3686743288,"timestamp":"2026-07-15T03:59:01.920363Z"}]}
{"channel":"book","type":"update","data":[{"symbol":"BTC/USD","bids":[{"price":64747.8,"qty":0.00000000},{"price":64747.7,"qty":0.00005100},{"price":64748.4,"qty":0.03086225}],"asks":[],"checksum":4018610952,"timestamp":"2026-07-15T03:59:01.921539Z"}]}
{"channel":"book","type":"update","data":[{"symbol":"BTC/USD","bids":[{"price":64748.3,"qty":0.00000000},{"price":64747.7,"qty":0.00005100}],"asks":[],"checksum":4141502143,"timestamp":"2026-07-15T03:59:02.239150Z"}]}
{"channel":"book","type":"update","data":[{"symbol":"BTC/USD","bids":[{"price":64748.4,"qty":0.00000000},{"price":64747.4,"qty":0.15820000},{"price":64747.8,"qty":0.03086225}],"asks":[],"checksum":2847711611,"timestamp":"2026-07-15T03:59:02.240577Z"}]}
{"channel":"book","type":"update","data":[{"symbol":"BTC/USD","bids":[{"price":64749.1,"qty":0.77221118}],"asks":[],"checksum":1334182956,"timestamp":"2026-07-15T03:59:02.241241Z"}]}
{"channel":"book","type":"update","data":[{"symbol":"BTC/USD","bids":[{"price":64747.8,"qty":0.00000000},{"price":64747.7,"qty":0.00005100},{"price":64749.1,"qty":0.80307343}],"asks":[],"checksum":3025181164,"timestamp":"2026-07-15T03:59:02.242568Z"}]}
{"channel":"heartbeat"}
{"channel":"book","type":"update","data":[{"symbol":"BTC/USD","bids":[{"price":64749.5,"qty":0.00154442}],"asks":[],"checksum":3542621699,"timestamp":"2026-07-15T03:59:02.503126Z"}]}
{"channel":"book","type":"update","data":[{"symbol":"BTC/USD","bids":[{"price":64749.5,"qty":0.00000000},{"price":64747.7,"qty":0.00005100}],"asks":[],"checksum":3025181164,"timestamp":"2026-07-15T03:59:02.745320Z"}]}
{"channel":"book","type":"update","data":[{"symbol":"BTC/USD","bids":[{"price":64749.1,"qty":0.77221118},{"price":64749.2,"qty":0.03086225}],"asks":[],"checksum":546688424,"timestamp":"2026-07-15T03:59:02.803802Z"}]}
{"channel":"book","type":"update","data":[{"symbol":"BTC/USD","bids":[{"price":64749.1,"qty":0.77375561}],"asks":[],"checksum":2648670357,"timestamp":"2026-07-15T03:59:03.109189Z"}]}
{"channel":"heartbeat"}
{"channel":"book","type":"update","data":[{"symbol":"BTC/USD","bids":[],"asks":[{"price":64760.5,"qty":1.33968900}],"checksum":2921835994,"timestamp":"2026-07-15T03:59:03.861572Z"}]}
{"channel":"heartbeat"}
{"channel":"book","type":"update","data":[{"symbol":"BTC/USD","bids":[{"price":64749.1,"qty":0.00154443}],"asks":[],"checksum":3626320485,"timestamp":"2026-07-15T03:59:04.440936Z"}]}
{"channel":"book","type":"update","data":[{"symbol":"BTC/USD","bids":[{"price":64749.8,"qty":0.77220266}],"asks":[],"checksum":2096364810,"timestamp":"2026-07-15T03:59:04.442542Z"}]}
{"channel":"heartbeat"}
{"channel":"book","type":"update","data":[{"symbol":"BTC/USD","bids":[],"asks":[{"price":64760.5,"qty":1.33258853}],"checksum":3137766985,"timestamp":"2026-07-15T03:59:05.268826Z"}]}
{"channel":"book","type":"update","data":[{"symbol":"BTC/USD","bids":[],"asks":[{"price":64760.5,"qty":1.33968900}],"checksum":2096364810,"timestamp":"2026-07-15T03:59:05.271490Z"}]}
{"channel":"book","type":"update","data":[{"symbol":"BTC/USD","bids":[],"asks":[{"price":64760.5,"qty":1.33258853}],"checksum":3137766985,"timestamp":"2026-07-15T03:59:05.327116Z"}]}
{"channel":"book","type":"update","data":[{"symbol":"BTC/USD","bids":[],"asks":[{"price":64760.5,"qty":1.92940116}],"checksum":3531800192,"timestamp":"2026-07-15T03:59:05.857005Z"}]}
{"channel":"book","type":"update","data":[{"symbol":"BTC/USD","bids":[],"asks":[{"price":64760.5,"qty":1.93650163}],"checksum":1326174277,"timestamp":"2026-07-15T03:59:05.860847Z"}]}
{"channel":"book","type":"update","data":[{"symbol":"BTC/USD","bids":[],"asks":[{"price":64763.7,"qty":0.00000000},{"price":64767.0,"qty":0.05825100}],"checksum":3887181604,"timestamp":"2026-07-15T03:59:05.921813Z"}]}
{"channel":"book","type":"update","data":[{"symbol":"BTC/USD","bids":[],"asks":[{"price":64763.7,"qty":0.00005100}],"checksum":1326174277,"timestamp":"2026-07-15T03:59:06.209827Z"}]}
{"channel":"heartbeat"}
{"channel":"trade","type":"update","data":[{"symbol":"BTC/USD","side":"buy","price":64760.5,"qty":0.00726128,"ord_type":"market","trade_id":103746743,"timestamp":"2026-07-15T03:59:06.676181Z"}]}
{"channel":"book","type":"update","data":[{"symbol":"BTC/USD","bids":[],"asks":[{"price":64760.5,"qty":1.92924035}],"checksum":2500611498,"timestamp":"2026-07-15T03:59:06.676181Z"}]}
{"channel":"heartbeat"}
{"channel":"book","type":"update","data":[{"symbol":"BTC/USD","bids":[{"price":64749.2,"qty":0.03240668}],"asks":[],"checksum":629886745,"timestamp":"2026-07-15T03:59:07.401179Z"}]}
{"channel":"book","type":"update","data":[{"symbol":"BTC/USD","bids":[{"price":64749.2,"qty":0.00154443}],"asks":[],"checksum":1363839590,"timestamp":"2026-07-15T03:59:07.402110Z"}]}
{"channel":"book","type":"update","data":[{"symbol":"BTC/USD","bids":[{"price":64749.3,"qty":0.03086225}],"asks":[],"checksum":1504070964,"timestamp":"2026-07-15T03:59:07.403252Z"}]}
{"channel":"heartbeat"}
{"channel":"book","type":"update","data":[{"symbol":"BTC/USD","bids":[{"price":64749.8,"qty":0.00000000},{"price":64749.2,"qty":0.00154443}],"asks":[],"checksum":2419707002,"timestamp":"2026-07-15T03:59:08.327740Z"}]}
{"channel":"book","type":"update","data":[{"symbol":"BTC/USD","bids":[{"price":64749.4,"qty":0.77220713}],"asks":[],"checksum":3501142157,"timestamp":"2026-07-15T03:59:08.429831Z"}]}
{"channel":"book","type":"update","data":[{"symbol":"BTC/USD","bids":[{"price":64749.3,"qty":0.00000000},{"price":64749.2,"qty":0.00154443},{"price":64749.4,"qty":0.80306938}],"asks":[],"checksum":1050018860,"timestamp":"2026-07-15T03:59:08.431118Z"}]}
{"channel":"book","type":"update","data":[{"symbol":"BTC/USD","bids":[{"price":64749.2,"qty":0.00000000},{"price":64747.7,"qty":0.00005100}],"asks":[],"checksum":1832521488,"timestamp":"2026-07-15T03:59:08.722389Z"}]}
{"channel":"book","type":"update","data":[{"symbol":"BTC/USD","bids":[],"asks":[{"price":64765.6,"qty":0.55605072}],"checksum":4048510574,"timestamp":"2026-07-15T03:59:08.924949Z"}]}
{"channel":"trade","type":"update","data":[{"symbol":"BTC/USD","side":"buy","price":64760.5,"qty":0.00030130,"ord_type":"limit","trade_id":103746744,"timestamp":"2026-07-15T03:59:08.925456Z"}]}
{"channel":"book","type":"update","data":[{"symbol":"BTC/USD","bids":[],"asks":[{"price":64760.5,"qty":1.92893905}],"checksum":2215091350,"timestamp":"2026-07-15T03:59:08.925456Z"}]}
{"channel":"heartbeat"}
{"channel":"book","type":"update","data":[{"symbol":"BTC/USD","bids":[{"price":64749.4,"qty":0.03086225}],"asks":[],"checksum":3242386303,"timestamp":"2026-07-15T03:59:09.407883Z"}]}
{"channel":"book","type":"update","data":[{"symbol":"BTC/USD","bids":[{"price":64749.4,"qty":0.00000000},{"price":64747.4,"qty":0.10000000},{"price":64747.8,"qty":0.03086225}],"asks":[],"checksum":1237748963,"timestamp":"2026-07-15T03:59:09.411178Z"}]}
{"channel":"book","type":"update","data":[{"symbol":"BTC/USD","bids":[],"asks":[{"price":64765.6,"qty":0.51018505}],"checksum":1773665448,"timestamp":"2026-07-15T03:59:09.416427Z"}]}
{"channel":"book","type":"update","data":[{"symbol":"BTC/USD","bids":[],"asks":[{"price":64765.6,"qty":0.00000000},{"price":64767.0,"qty":0.05825100}],"checksum":1019127434,"timestamp":"2026-07-15T03:59:09.416782Z"}]}
{"channel":"book","type":"update","data":[{"symbol":"BTC/USD","bids":[],"asks":[{"price":64765.6,"qty":1.18214167}],"checksum":3506491260,"timestamp":"2026-07-15T03:59:09.417216Z"}]}
{"channel":"book","type":"update","data":[{"symbol":"BTC/USD","bids":[{"price":64750.2,"qty":0.00000000},{"price":64747.4,"qty":0.10000000}],"asks":[],"checksum":1970037924,"timestamp":"2026-07-15T03:59:09.419799Z"}]}
{"channel":"book","type":"update","data":[{"symbol":"BTC/USD","bids":[{"price":64751.2,"qty":0.00000000},{"price":64747.2,"qty":1.72853000}],"asks":[],"checksum":2259257372,"timestamp":"2026-07-15T03:59:09.435055Z"}]}
{"channel":"book","type":"update","data":[{"symbol":"BTC/USD","bids":[],"asks":[{"price":64765.6,"qty":2.19933235}],"checksum":3045282589,"timestamp":"2026-07-15T03:59:09.460364Z"}]}
{"channel":"book","type":"update","data":[{"symbol":"BTC/USD","bids":[],"asks":[{"price":64765.5,"qty":3.67594119}],"checksum":1388360938,"timestamp":"2026-07-15T03:59:09.472190Z"}]}
{"channel":"book","type":"update","data":[{"symbol":"BTC/USD","bids":[],"asks":[{"price":64765.6,"qty":1.01719068}],"checksum":2179422296,"timestamp":"2026-07-15T03:59:09.475018Z"}]}
{"channel":"book","type":"update","data":[{"symbol":"BTC/USD","bids":[],"asks":[{"price":64765.6,"qty":0.00000000},{"price":64765.7,"qty":0.09385982}],"checksum":3226991007,"timestamp":"2026-07-15T03:59:09.475590Z"}]}
{"channel":"book","type":"update","data":[{"symbol":"BTC/USD","bids":[],"asks":[{"price":64765.4,"qty":2.35050010}],"checksum":4149739088,"timestamp":"2026-07-15T03:59:09.477071Z"}]}
{"channel":"book","type":"update","data":[{"symbol":"BTC/USD","bids":[],"asks":[{"price":64760.5,"qty":2.22893905}],"checksum":703963951,"timestamp":"2026-07-15T03:59:09.484347Z"}]}
{"channel":"book","type":"update","data":[{"symbol":"BTC/USD","bids":[{"price":64747.8,"qty":0.00000000},{"price":64745.1,"qty":0.00029694}],"asks":[],"checksum":4057961241,"timestamp":"2026-07-15T03:59:09.484796Z"}]}
{"channel":"book","type":"update","data":[{"symbol":"BTC/USD","bids":[{"price":64745.2,"qty":0.03086225}],"asks":[],"checksum":3828717454,"timestamp":"2026-07-15T03:59:09.486503Z"}]}
{"channel":"book","type":"update","data":[{"symbol":"BTC/USD","bids":[],"asks":[{"price":64765.5,"qty":0.00000000},{"price":64765.7,"qty":0.09385982}],"checksum":2821616623,"timestamp":"2026-07-15T03:59:09.501759Z"}]}
{"channel":"book","type":"update","data":[{"symbol":"BTC/USD","bids":[{"price":64745.2,"qty":0.00000000},{"price":64745.1,"qty":0.00029694}],"asks":[],"checksum":42416095,"timestamp":"2026-07-15T03:59:09.510031Z"}]}
{"channel":"book","type":"update","data":[{"symbol":"BTC/USD","bids":[],"asks":[{"price":64765.4,"qty":3.60373176}],"checksum":711182603,"timestamp":"2026-07-15T03:59:09.533100Z"}]}
{"channel":"book","type":"update","data":[{"symbol":"BTC/USD","bids":[],"asks":[{"price":64765.4,"qty":1.25323166}],"checksum":3927905899,"timestamp":"2026-07-15T03:59:09.533675Z"}]}
{"channel":"book","type":"update","data":[{"symbol":"BTC/USD","bids":[],"asks":[{"price":64764.5,"qty":0.01544055}],"checksum":1205233182,"timestamp":"2026-07-15T03:59:09.543106Z"}]}
{"channel":"book","type":"update","data":[{"symbol":"BTC/USD","bids":[],"asks":[{"price":64764.5,"qty":0.00000000},{"price":64767.0,"qty":0.05825100}],"checksum":2484251330,"timestamp":"2026-07-15T03:59:09.543167Z"}]}
{"channel":"book","type":"update","data":[{"symbol":"BTC/USD","bids":[],"asks":[{"price":64764.3,"qty":0.01544060}],"checksum":3243071503,"timestamp":"2026-07-15T03:59:09.543183Z"}]}
{"channel":"book","type":"update","data":[{"symbol":"BTC/USD","bids":[],"asks":[{"price":64764.3,"qty":0.03088120}],"checksum":323275725,"timestamp":"2026-07-15T03:59:09.543252Z"}]}
{"channel":"book","type":"update","data":[{"symbol":"BTC/USD","bids":[{"price":64749.6,"qty":0.00000000},{"price":64745.0,"qty":0.18274124}],"asks":[],"checksum":1145282075,"timestamp":"2026-07-15T03:59:09.553567Z"}]}
{"channel":"book","type":"update","data":[{"symbol":"BTC/USD","bids":[],"asks":[{"price":64760.5,"qty":2.52893905}],"checksum":1267702889,"timestamp":"2026-07-15T03:59:09.660529Z"}]}
{"channel":"book","type":"update","data":[{"symbol":"BTC/USD","bids":[],"asks":[{"price":64765.2,"qty":0.06000000}],"checksum":1304924002,"timestamp":"2026-07-15T03:59:09.678261Z"}]}
{"channel":"book","type":"update","data":[{"symbol":"BTC/USD","bids":[{"price":64745.8,"qty":0.77225038}],"asks":[],"checksum":1435288191,"timestamp":"2026-07-15T03:59:09.834412Z"}]}
{"channel":"book","type":"update","data":[{"symbol":"BTC/USD","bids":[{"price":64747.4,"qty":0.00000000},{"price":64745.0,"qty":0.18274124}],"asks":[],"checksum":4275471141,"timestamp":"2026-07-15T03:59:10.014822Z"}]}
{"channel":"book","type":"update","data":[{"symbol":"BTC/USD","bids":[{"price":64751.2,"qty":0.00154437}],"asks":[],"checksum":974703300,"timestamp":"2026-07-15T03:59:10.038583Z"}]}
{"channel":"book","type":"update","data":[{"symbol":"BTC/USD","bids":[],"asks":[{"price":64763.4,"qty":0.56803100}],"checksum":4246486921,"timestamp":"2026-07-15T03:59:10.085032Z"}]}
{"channel":"heartbeat"}
{"channel":"trade","type":"update","data":[{"symbol":"BTC/USD","side":"buy","price":64760.5,"qty":0.00371673,"ord_type":"market","trade_id":103746745,"timestamp":"2026-07-15T03:59:10.582378Z"}]}
{"channel":"book","type":"update","data":[{"symbol":"BTC/USD","bids":[],"asks":[{"price":64760.5,"qty":2.52522232}],"checksum":1346763450,"timestamp":"2026-07-15T03:59:10.582378Z"}]}
{"channel":"book","type":"update","data":[{"symbol":"BTC/USD","bids":[{"price":64747.3,"qty":0.10000000}],"asks":[],"checksum":3172792407,"timestamp":"2026-07-15T03:59:11.016975Z"}]}
{"channel":"heartbeat"}
{"channel":"book","type":"update","data":[{"symbol":"BTC/USD","bids":[{"price":64745.8,"qty":0.00000000},{"price":64745.1,"qty":0.00029694}],"asks":[],"checksum":2741269870,"timestamp":"2026-07-15T03:59:11.835066Z"}]}
{"channel":"book","type":"update","data":[{"symbol":"BTC/USD","bids":[{"price":64746.4,"qty":0.77224305}],"asks":[],"checksum":1601783298,"timestamp":"2026-07-15T03:59:11.837576Z"}]}
{"channel":"heartbeat"}
{"channel":"heartbeat"}
{"channel":"book","type":"update","data":[{"symbol":"BTC/USD","bids":[],"asks":[{"price":64760.5,"qty":2.51812185}],"checksum":3270038545,"timestamp":"2026-07-15T03:59:14.011316Z"}]}
{"channel":"book","type":"update","data":[{"symbol":"BTC/USD","bids":[],"asks":[{"price":64760.5,"qty":2.52522232}],"checksum":1601783298,"timestamp":"2026-07-15T03:59:14.014019Z"}]}
{"channel":"heartbeat"}
{"channel":"book","type":"update","data":[{"symbol":"BTC/USD","bids":[],"asks":[{"price":64760.5,"qty":2.51812185}],"checksum":3270038545,"timestamp":"2026-07-15T03:59:14.653175Z"}]}
{"channel":"book","type":"update","data":[{"symbol":"BTC/USD","bids":[{"price":64746.4,"qty":0.00000000},{"price":64745.1,"qty":0.00029694}],"asks":[],"checksum":637005360,"timestamp":"2026-07-15T03:59:14.973610Z"}]}
{"channel":"book","type":"update","data":[{"symbol":"BTC/USD","bids":[{"price":64745.2,"qty":0.77225730}],"asks":[],"checksum":3191307885,"timestamp":"2026-07-15T03:59:14.975254Z"}]}
{"channel":"book","type":"update","data":[{"symbol":"BTC/USD","bids":[{"price":64745.2,"qty":0.00000000},{"price":64745.1,"qty":0.00029694}],"asks":[],"checksum":637005360,"timestamp":"2026-07-15T03:59:15.063316Z"}]}
{"channel":"heartbeat"}
{"channel":"book","type":"update","data":[{"symbol":"BTC/USD","bids":[],"asks":[{"price":64760.5,"qty":2.52522232}],"checksum":2741269870,"timestamp":"2026-07-15T03:59:15.333771Z"}]}
{"channel":"book","type":"update","data":[{"symbol":"BTC/USD","bids":[],"asks":[{"price":64760.5,"qty":2.51812185}],"checksum":637005360,"timestamp":"2026-07-15T03:59:15.634052Z"}]}
{"channel":"book","type":"update","data":[{"symbol":"BTC/USD","bids":[],"asks":[{"price":64760.5,"qty":2.52522232}],"checksum":2741269870,"timestamp":"2026-07-15T03:59:15.637256Z"}]}
{"channel":"trade","type":"update","data":[{"symbol":"BTC/USD","side":"buy","price":64760.5,"qty":0.00047618,"ord_type":"limit","trade_id":103746746,"timestamp":"2026-07-15T03:59:16.207512Z"}]}
{"channel":"book","type":"update","data":[{"symbol":"BTC/USD","bids":[],"asks":[{"price":64760.5,"qty":2.52474614}],"checksum":366135712,"timestamp":"2026-07-15T03:59:16.207512Z"}]}
{"channel":"heartbeat"}
{"channel":"book","type":"update","data":[{"symbol":"BTC/USD","bids":[],"asks":[{"price":64760.5,"qty":2.51764567}],"checksum":2655928309,"timestamp":"2026-07-15T03:59:16.371820Z"}]}
{"channel":"book","type":"update","data":[{"symbol":"BTC/USD","bids":[{"price":64747.2,"qty":0.00000000},{"price":64745.0,"qty":0.18274124}],"asks":[],"checksum":618854139,"timestamp":"2026-07-15T03:59:16.840964Z"}]}
{"channel":"book","type":"update","data":[{"symbol":"BTC/USD","bids":[],"asks":[{"price":64760.5,"qty":2.52474614}],"checksum":111954337,"timestamp":"2026-07-15T03:59:16.845659Z"}]}
{"channel":"book","type":"update","data":[{"symbol":"BTC/USD","bids":[],"asks":[{"price":64760.5,"qty":2.63474614}],"checksum":1613354630,"timestamp":"2026-07-15T03:59:16.848093Z"}]}
{"channel":"book","type":"update","data":[{"symbol":"BTC/USD","bids":[{"price":64751.2,"qty":0.00000000},{"price":64743.9,"qty":0.03086225}],"asks":[],"checksum":2336541399,"timestamp":"2026-07-15T03:59:16.865349Z"}]}
{"channel":"book","type":"update","data":[{"symbol":"BTC/USD","bids":[{"price":64743.9,"qty":0.80313516}],"asks":[],"checksum":1503067592,"timestamp":"2026-07-15T03:59:16.997515Z"}]}
{"channel":"book","type":"update","data":[{"symbol":"BTC/USD","bids":[{"price":64743.9,"qty":0.77227291},{"price":64744.0,"qty":0.03086225}],"asks":[],"checksum":4033526837,"timestamp":"2026-07-15T03:59:16.998705Z"}]}
{"channel":"book","type":"update","data":[{"symbol":"BTC/USD","bids":[{"price":64744.0,"qty":0.00000000},{"price":64743.8,"qty":0.59681263},{"price":64743.9,"qty":0.03086225}],"asks":[],"checksum":2336541399,"timestamp":"2026-07-15T03:59:17.019263Z"}]}
{"channel":"book","type":"update","data":[{"symbol":"BTC/USD","bids":[{"price":64745.0,"qty":0.00000000},{"price":64743.8,"qty":0.59681263}],"asks":[],"checksum":215563760,"timestamp":"2026-07-15T03:59:17.095866Z"}]}
{"channel":"book","type":"update","data":[{"symbol":"BTC/USD","bids":[{"price":64744.2,"qty":0.77226900}],"asks":[],"checksum":1178258561,"timestamp":"2026-07-15T03:59:17.098981Z"}]}
{"channel":"book","type":"update","data":[{"symbol":"BTC/USD","bids":[{"price":64744.2,"qty":0.00000000},{"price":64743.8,"qty":0.59681263}],"asks":[],"checksum":215563760,"timestamp":"2026-07-15T03:59:17.155223Z"}]}
{"channel":"book","type":"update","data":[{"symbol":"BTC/USD","bids":[{"price":64744.0,"qty":0.01123723}],"asks":[],"checksum":2331248604,"timestamp":"2026-07-15T03:59:17.175493Z"}]}
{"channel":"book","type":"update","data":[{"symbol":"BTC/USD","bids":[{"price":64743.9,"qty":0.00000000},{"price":64743.8,"qty":0.59681263},{"price":64744.1,"qty":0.03086225}],"asks":[],"checksum":3650745878,"timestamp":"2026-07-15T03:59:17.176751Z"}]}
{"channel":"heartbeat"}
{"channel":"book","type":"update","data":[{"symbol":"BTC/USD","bids":[{"price":64745.8,"qty":0.77224977}],"asks":[],"checksum":3309525681,"timestamp":"2026-07-15T03:59:18.053893Z"}]}
{"channel":"book","type":"update","data":[{"symbol":"BTC/USD","bids":[{"price":64745.1,"qty":0.00000000},{"price":64744.0,"qty":0.01123723},{"price":64744.2,"qty":0.00029694}],"asks":[],"checksum":57861982,"timestamp":"2026-07-15T03:59:18.056435Z"}]}
{"channel":"book","type":"update","data":[{"symbol":"BTC/USD","bids":[{"price":64744.1,"qty":0.00000000},{"price":64744.0,"qty":0.01123723},{"price":64744.2,"qty":0.03115919}],"asks":[],"checksum":3254224236,"timestamp":"2026-07-15T03:59:18.057904Z"}]}
{"channel":"heartbeat"}
{"channel":"book","type":"update","data":[{"symbol":"BTC/USD","bids":[{"price":64744.2,"qty":0.00029694},{"price":64744.3,"qty":0.03086225}],"asks":[],"checksum":872756945,"timestamp":"2026-07-15T03:59:18.263746Z"}]}
{"channel":"book","type":"update","data":[{"symbol":"BTC/USD","bids":[],"asks":[{"price":64760.5,"qty":2.62764567}],"checksum":2948520136,"timestamp":"2026-07-15T03:59:18.268806Z"}]}
{"channel":"book","type":"update","data":[{"symbol":"BTC/USD","bids":[],"asks":[{"price":64760.5,"qty":2.63474614}],"checksum":872756945,"timestamp":"2026-07-15T03:59:18.273719Z"}]}
{"channel":"book","type":"update","data":[{"symbol":"BTC/USD","bids":[],"asks":[{"price":64760.5,"qty":2.62764567}],"checksum":2948520136,"timestamp":"2026-07-15T03:59:18.315303Z"}]}
{"channel":"heartbeat"}
{"channel":"book","type":"update","data":[{"symbol":"BTC/USD","bids":[{"price":64745.8,"qty":0.00000000},{"price":64744.0,"qty":0.01123723}],"asks":[],"checksum":3832385546,"timestamp":"2026-07-15T03:59:20.009911Z"}]}
{"channel":"book","type":"update","data":[{"symbol":"BTC/USD","bids":[{"price":64744.3,"qty":0.80312986}],"asks":[],"checksum":1318443434,"timestamp":"2026-07-15T03:59:20.011745Z"}]}
{"channel":"book","type":"update","data":[{"symbol":"BTC/USD","bids":[{"price":64744.3,"qty":0.03086225}],"asks":[],"checksum":3832385546,"timestamp":"2026-07-15T03:59:20.012627Z"}]}
{"channel":"book","type":"update","data":[{"symbol":"BTC/USD","bids":[],"asks":[{"price":64760.5,"qty":2.63474614}],"checksum":994130378,"timestamp":"2026-07-15T03:59:20.018375Z"}]}
{"channel":"heartbeat"}
{"channel":"book","type":"update","data":[{"symbol":"BTC/USD","bids":[{"price":64744.5,"qty":0.77226542}],"asks":[],"checksum":2643674617,"timestamp":"2026-07-15T03:59:20.886503Z"}]}
{"channel":"book","type":"update","data":[{"symbol":"BTC/USD","bids":[{"price":64744.5,"qty":0.00000000},{"price":64744.0,"qty":0.01123723}],"asks":[],"checksum":994130378,"timestamp":"2026-07-15T03:59:20.929064Z"}]}
{"channel":"book","type":"update","data":[{"symbol":"BTC/USD","bids":[{"price":64747.3,"qty":0.00000000},{"price":64742.9,"qty":1.17228531}],"asks":[],"checksum":1271252593,"timestamp":"2026-07-15T03:59:21.014963Z"}]}
{"channel":"book","type":"update","data":[{"symbol":"BTC/USD","bids":[{"price":64745.1,"qty":0.77225865}],"asks":[],"checksum":2263666191,"timestamp":"2026-07-15T03:59:21.055768Z"}]}
{"channel":"book","type":"update","data":[{"symbol":"BTC/USD","bids":[],"asks":[{"price":64760.5,"qty":2.62764567}],"checksum":1505781711,"timestamp":"2026-07-15T03:59:21.121995Z"}]}
{"channel":"book","type":"update","data":[{"symbol":"BTC/USD","bids":[],"asks":[{"price":64760.5,"qty":2.63474614}],"checksum":2263666191,"timestamp":"2026-07-15T03:59:21.161190Z"}]}
{"channel":"heartbeat"}
{"channel":"book","type":"update","data":[{"symbol":"BTC/USD","bids":[],"asks":[{"price":64760.5,"qty":2.62764567}],"checksum":1505781711,"timestamp":"2026-07-15T03:59:21.334171Z"}]}
{"channel":"book","type":"update","data":[{"symbol":"BTC/USD","bids":[],"asks":[{"price":64760.5,"qty":2.63474614}],"checksum":2263666191,"timestamp":"2026-07-15T03:59:21.598859Z"}]}
{"channel":"book","type":"update","data":[{"symbol":"BTC/USD","bids":[],"asks":[{"price":64760.5,"qty":2.62764567}],"checksum":1505781711,"timestamp":"2026-07-15T03:59:21.627204Z"}]}
{"channel":"book","type":"update","data":[{"symbol":"BTC/USD","bids":[{"price":64746.3,"qty":1.72878200}],"asks":[],"checksum":726144043,"timestamp":"2026-07-15T03:59:21.894393Z"}]}
{"channel":"book","type":"update","data":[{"symbol":"BTC/USD","bids":[{"price":64746.4,"qty":0.10000000}],"asks":[],"checksum":1646652440,"timestamp":"2026-07-15T03:59:22.015896Z"}]}
{"channel":"heartbeat"}
{"channel":"book","type":"update","data":[{"symbol":"BTC/USD","bids":[{"price":64760.4,"qty":0.10423089}],"asks":[],"checksum":3689110531,"timestamp":"2026-07-15T03:59:22.516297Z"}]}
{"channel":"book","type":"update","data":[{"symbol":"BTC/USD","bids":[],"asks":[{"price":64760.5,"qty":2.63474614}],"checksum":895648771,"timestamp":"2026-07-15T03:59:22.748843Z"}]}
{"channel":"heartbeat"}
{"channel":"book","type":"update","data":[{"symbol":"BTC/USD","bids":[],"asks":[{"price":64760.5,"qty":2.62764567}],"checksum":3689110531,"timestamp":"2026-07-15T03:59:23.584154Z"}]}
{"channel":"book","type":"update","data":[{"symbol":"BTC/USD","bids":[],"asks":[{"price":64760.5,"qty":2.63474614}],"checksum":895648771,"timestamp":"2026-07-15T03:59:23.689589Z"}]}
{"channel":"heartbeat"}
{"channel":"book","type":"update","data":[{"symbol":"BTC/USD","bids":[],"asks":[{"price":64760.5,"qty":2.62764567}],"checksum":3689110531,"timestamp":"2026-07-15T03:59:24.440456Z"}]}
{"channel":"book","type":"update","data":[{"symbol":"BTC/USD","bids":[{"price":64744.3,"qty":0.03240679}],"asks":[],"checksum":91774823,"timestamp":"2026-07-15T03:59:24.451555Z"}]}
{"channel":"book","type":"update","data":[{"symbol":"BTC/USD","bids":[{"price":64744.3,"qty":0.00154454},{"price":64744.4,"qty":0.03086225}],"asks":[],"checksum":3508950298,"timestamp":"2026-07-15T03:59:24.452809Z"}]}
{"channel":"book","type":"update","data":[{"symbol":"BTC/USD","bids":[],"asks":[{"price":64760.5,"qty":2.63474614}],"checksum":1067945242,"timestamp":"2026-07-15T03:59:24.453757Z"}]}
{"channel":"book","type":"update","data":[{"symbol":"BTC/USD","bids":[],"asks":[{"price":64760.5,"qty":2.62764567}],"checksum":3508950298,"timestamp":"2026-07-15T03:59:24.496796Z"}]}
{"channel":"book","type":"update","data":[{"symbol":"BTC/USD","bids":[{"price":64745.1,"qty":0.00000000},{"price":64744.3,"qty":0.00154454}],"asks":[],"checksum":2296122593,"timestamp":"2026-07-15T03:59:24.536660Z"}]}
{"channel":"book","type":"update","data":[{"symbol":"BTC/USD","bids":[{"price":64745.7,"qty":0.77225137}],"asks":[],"checksum":2890234722,"timestamp":"2026-07-15T03:59:24.538360Z"}]}
{"channel":"book","type":"update","data":[{"symbol":"BTC/USD","bids":[],"asks":[{"price":64760.5,"qty":2.63474614}],"checksum":1120183138,"timestamp":"2026-07-15T03:59:24.628655Z"}]}
{"channel":"book","type":"update","data":[{"symbol":"BTC/USD","bids":[],"asks":[{"price":64760.5,"qty":2.62764567}],"checksum":2890234722,"timestamp":"2026-07-15T03:59:24.658683Z"}]}
{"channel":"book","type":"update","data":[{"symbol":"BTC/USD","bids":[],"asks":[{"price":64764.3,"qty":0.01544060}],"checksum":3871521286,"timestamp":"2026-07-15T03:59:25.011348Z"}]}
{"channel":"book","type":"update","data":[{"symbol":"BTC/USD","bids":[],"asks":[{"price":64764.3,"qty":0.00000000},{"price":64765.4,"qty":1.25323166}],"checksum":2900417361,"timestamp":"2026-07-15T03:59:25.011386Z"}]}
{"channel":"book","type":"update","data":[{"symbol":"BTC/USD","bids":[],"asks":[{"price":64764.2,"qty":0.01544062}],"checksum":3874129074,"timestamp":"2026-07-15T03:59:25.011435Z"}]}
{"channel":"book","type":"update","data":[{"symbol":"BTC/USD","bids":[],"asks":[{"price":64764.2,"qty":0.03088124}],"checksum":1312786806,"timestamp":"2026-07-15T03:59:25.011502Z"}]}
{"channel":"book","type":"update","data":[{"symbol":"BTC/USD","bids":[{"price":64746.7,"qty":0.01111418}],"asks":[],"checksum":4146940297,"timestamp":"2026-07-15T03:59:25.168315Z"}]}
{"channel":"heartbeat"}
{"channel":"book","type":"update","data":[{"symbol":"BTC/USD","bids":[{"price":64745.7,"qty":0.00000000},{"price":64744.4,"qty":0.03086225}],"asks":[],"checksum":840551435,"timestamp":"2026-07-15T03:59:25.341472Z"}]}
{"channel":"book","type":"update","data":[{"symbol":"BTC/USD","bids":[{"price":64746.3,"qty":2.50102591}],"asks":[],"checksum":1051611190,"timestamp":"2026-07-15T03:59:25.343575Z"}]}
{"channel":"book","type":"update","data":[{"symbol":"BTC/USD","bids":[{"price":64746.3,"qty":1.72878200}],"asks":[],"checksum":840551435,"timestamp":"2026-07-15T03:59:25.366566Z"}]}
{"channel":"book","type":"update","data":[{"symbol":"BTC/USD","bids":[],"asks":[{"price":64760.5,"qty":2.63474614}],"checksum":3181436937,"timestamp":"2026-07-15T03:59:25.416494Z"}]}
{"channel":"book","type":"update","data":[{"symbol":"BTC/USD","bids":[],"asks":[{"price":64760.5,"qty":2.62764567}],"checksum":840551435,"timestamp":"2026-07-15T03:59:25.424381Z"}]}
{"channel":"trade","type":"update","data":[{"symbol":"BTC/USD","side":"sell","price":64760.4,"qty":0.00000093,"ord_type":"limit","trade_id":103746747,"timestamp":"2026-07-15T03:59:25.426812Z"},{"symbol":"BTC/USD","side":"sell","price":64760.4,"qty":0.00077208,"ord_type":"limit","trade_id":103746748,"timestamp":"2026-07-15T03:59:25.426812Z"},{"symbol":"BTC/USD","side":"sell","price":64760.4,"qty":0.05819799,"ord_type":"limit","trade_id":103746749,"timestamp":"2026-07-15T03:59:25.426812Z"}]}
{"channel":"book","type":"update","data":[{"symbol":"BTC/USD","bids":[{"price":64760.4,"qty":0.10422996},{"price":64760.4,"qty":0.10345788},{"price":64760.4,"qty":0.04525989}],"asks":[],"checksum":2653708930,"timestamp":"2026-07-15T03:59:25.426812Z"}]}
{"channel":"book","type":"update","data":[{"symbol":"BTC/USD","bids":[],"asks":[{"price":64760.5,"qty":2.63474614}],"checksum":1117691742,"timestamp":"2026-07-15T03:59:25.430482Z"}]}
{"channel":"book","type":"update","data":[{"symbol":"BTC/USD","bids":[],"asks":[{"price":64760.5,"qty":2.62764567}],"checksum":2653708930,"timestamp":"2026-07-15T03:59:25.434054Z"}]}
{"channel":"book","type":"update","data":[{"symbol":"BTC/USD","bids":[{"price":64760.4,"qty":0.04603197}],"asks":[],"checksum":3113163309,"timestamp":"2026-07-15T03:59:25.440000Z"}]}
{"channel":"book","type":"update","data":[{"symbol":"BTC/USD","bids":[],"asks":[{"price":64760.5,"qty":2.03083304}],"checksum":3567425124,"timestamp":"2026-07-15T03:59:25.483789Z"}]}
{"channel":"book","type":"update","data":[{"symbol":"BTC/USD","bids":[{"price":64746.1,"qty":0.03770924}],"asks":[],"checksum":1943574340,"timestamp":"2026-07-15T03:59:25.643430Z"}]}
{"channel":"book","type":"update","data":[{"symbol":"BTC/USD","bids":[{"price":64760.4,"qty":0.04611228}],"asks":[],"checksum":3574786688,"timestamp":"2026-07-15T03:59:25.845563Z"}]}
{"channel":"heartbeat"}
{"channel":"book","type":"update","data":[{"symbol":"BTC/USD","bids":[],"asks":[{"price":64760.5,"qty":2.54977826}],"checksum":3293273548,"timestamp":"2026-07-15T03:59:26.977293Z"}]}
{"channel":"book","type":"update","data":[{"symbol":"BTC/USD","bids":[],"asks":[{"price":64760.5,"qty":2.55687873}],"checksum":484525,"timestamp":"2026-07-15T03:59:26.981089Z"}]}
{"channel":"heartbeat"}
{"channel":"heartbeat"}
{"channel":"heartbeat"}
{"channel":"book","type":"update","data":[{"symbol":"BTC/USD","bids":[{"price":64746.7,"qty":0.00000000},{"price":64744.4,"qty":0.54980747}],"asks":[],"checksum":3872017861,"timestamp":"2026-07-15T03:59:29.630885Z"}]}
{"channel":"book","type":"update","data":[{"symbol":"BTC/USD","bids":[{"price":64744.4,"qty":0.03086225}],"asks":[],"checksum":2322697548,"timestamp":"2026-07-15T03:59:29.633636Z"}]}
{"channel":"book","type":"update","data":[{"symbol":"BTC/USD","bids":[{"price":64744.4,"qty":0.00000000},{"price":64744.2,"qty":0.00029694},{"price":64744.3,"qty":0.03086225}],"asks":[],"checksum":2159314005,"timestamp":"2026-07-15T03:59:29.639180Z"}]}
{"channel":"book","type":"update","data":[{"symbol":"BTC/USD","bids":[{"price":64746.1,"qty":0.00000000},{"price":64744.2,"qty":0.00029694}],"asks":[],"checksum":875485930,"timestamp":"2026-07-15T03:59:29.645078Z"}]}
{"channel":"book","type":"update","data":[{"symbol":"BTC/USD","bids":[],"asks":[{"price":64765.2,"qty":2.51462823}],"checksum":127330708,"timestamp":"2026-07-15T03:59:29.684238Z"}]}
{"channel":"book","type":"update","data":[{"symbol":"BTC/USD","bids":[],"asks":[{"price":64765.2,"qty":0.06000000}],"checksum":875485930,"timestamp":"2026-07-15T03:59:29.997043Z"}]}
{"channel":"heartbeat"}
{"channel":"book","type":"update","data":[{"symbol":"BTC/USD","bids":[{"price":64745.1,"qty":0.77225844}],"asks":[],"checksum":140426316,"timestamp":"2026-07-15T03:59:31.116873Z"}]}
{"channel":"book","type":"update","data":[{"symbol":"BTC/USD","bids":[{"price":64747.7,"qty":0.00159545}],"asks":[],"checksum":1448583279,"timestamp":"2026-07-15T03:59:31.120778Z"}]}
{"channel":"heartbeat"}
{"channel":"book","type":"update","data":[{"symbol":"BTC/USD","bids":[],"asks":[{"price":64760.5,"qty":2.55774712}],"checksum":1784739677,"timestamp":"2026-07-15T03:59:31.348932Z"}]}
{"channel":"book","type":"update","data":[{"symbol":"BTC/USD","bids":[{"price":64746.4,"qty":0.11155844}],"asks":[],"checksum":3884157502,"timestamp":"2026-07-15T03:59:31.840616Z"}]}
{"channel":"book","type":"update","data":[{"symbol":"BTC/USD","bids":[{"price":64747.7,"qty":0.00005100}],"asks":[],"checksum":1485248838,"timestamp":"2026-07-15T03:59:32.015908Z"}]}
{"channel":"heartbeat"}
{"channel":"book","type":"update","data":[{"symbol":"BTC/USD","bids":[],"asks":[{"price":64760.5,"qty":2.55064665}],"checksum":2665786796,"timestamp":"2026-07-15T03:59:32.651708Z"}]}
{"channel":"book","type":"update","data":[{"symbol":"BTC/USD","bids":[],"asks":[{"price":64762.1,"qty":0.06015446}],"checksum":2029781857,"timestamp":"2026-07-15T03:59:32.755753Z"}]}
{"channel":"book","type":"update","data":[{"symbol":"BTC/USD","bids":[{"price":64744.6,"qty":0.00154454}],"asks":[],"checksum":3435195043,"timestamp":"2026-07-15T03:59:32.757779Z"}]}
{"channel":"book","type":"update","data":[{"symbol":"BTC/USD","bids":[],"asks":[{"price":64762.3,"qty":0.00000000},{"price":64767.0,"qty":0.05825100}],"checksum":1279625419,"timestamp":"2026-07-15T03:59:32.757879Z"}]}
{"channel":"book","type":"update","data":[{"symbol":"BTC/USD","bids":[],"asks":[{"price":64760.5,"qty":2.55219081}],"checksum":3796278081,"timestamp":"2026-07-15T03:59:32.758268Z"}]}
{"channel":"book","type":"update","data":[{"symbol":"BTC/USD","bids":[],"asks":[{"price":64760.5,"qty":2.55929128}],"checksum":3251228363,"timestamp":"2026-07-15T03:59:32.759351Z"}]}
{"channel":"book","type":"update","data":[{"symbol":"BTC/USD","bids":[],"asks":[{"price":64760.5,"qty":2.55219081}],"checksum":3796278081,"timestamp":"2026-07-15T03:59:33.116981Z"}]}
{"channel":"heartbeat"}
{"channel":"book","type":"update","data":[{"symbol":"BTC/USD","bids":[],"asks":[{"price":64760.5,"qty":2.55929128}],"checksum":3251228363,"timestamp":"2026-07-15T03:59:33.271718Z"}]}
{"channel":"book","type":"update","data":[{"symbol":"BTC/USD","bids":[{"price":64745.1,"qty":0.00000000},{"price":64744.3,"qty":0.03086225}],"asks":[],"checksum":1399426591,"timestamp":"2026-07-15T03:59:34.034122Z"}]}
{"channel":"book","type":"update","data":[{"symbol":"BTC/USD","bids":[{"price":64744.6,"qty":0.00000000},{"price":64744.2,"qty":0.00029694}],"asks":[],"checksum":3948088119,"timestamp":"2026-07-15T03:59:34.042694Z"}]}
{"channel":"book","type":"update","data":[{"symbol":"BTC/USD","bids":[{"price":64747.7,"qty":0.00159545}],"asks":[],"checksum":1275224274,"timestamp":"2026-07-15T03:59:34.142772Z"}]}
{"channel":"book","type":"update","data":[{"symbol":"BTC/USD","bids":[{"price":64744.2,"qty":0.77256657}],"asks":[],"checksum":744677045,"timestamp":"2026-07-15T03:59:34.206195Z"}]}
{"channel":"heartbeat"}
{"channel":"book","type":"update","data":[{"symbol":"BTC/USD","bids":[{"price":64746.4,"qty":0.10000000}],"asks":[],"checksum":2709627862,"timestamp":"2026-07-15T03:59:34.329493Z"}]}
{"channel":"book","type":"update","data":[{"symbol":"BTC/USD","bids":[{"price":64744.2,"qty":0.00029694}],"asks":[],"checksum":1566447839,"timestamp":"2026-07-15T03:59:34.332352Z"}]}
{"channel":"book","type":"update","data":[{"symbol":"BTC/USD","bids":[],"asks":[{"price":64766.9,"qty":3.67590518}],"checksum":2687202749,"timestamp":"2026-07-15T03:59:34.340245Z"}]}
{"channel":"book","type":"update","data":[{"symbol":"BTC/USD","bids":[],"asks":[{"price":64766.8,"qty":2.45462143}],"checksum":2370205942,"timestamp":"2026-07-15T03:59:34.342031Z"}]}
{"channel":"book","type":"update","data":[{"symbol":"BTC/USD","bids":[{"price":64747.7,"qty":0.00005100}],"asks":[],"checksum":2333619314,"timestamp":"2026-07-15T03:59:34.386693Z"}]}
{"channel":"book","type":"update","data":[{"symbol":"BTC/USD","bids":[],"asks":[{"price":64766.8,"qty":3.81198516}],"checksum":3771230287,"timestamp":"2026-07-15T03:59:34.435314Z"}]}
{"channel":"book","type":"update","data":[{"symbol":"BTC/USD","bids":[],"asks":[{"price":64766.8,"qty":1.35736373}],"checksum":3468488734,"timestamp":"2026-07-15T03:59:34.435399Z"}]}
{"channel":"book","type":"update","data":[{"symbol":"BTC/USD","bids":[{"price":64744.8,"qty":0.77226264}],"asks":[],"checksum":4048462295,"timestamp":"2026-07-15T03:59:34.617053Z"}]}
{"channel":"book","type":"update","data":[{"symbol":"BTC/USD","bids":[{"price":64747.7,"qty":0.01196895}],"asks":[],"checksum":379560458,"timestamp":"2026-07-15T03:59:34.881617Z"}]}
{"channel":"book","type":"update","data":[{"symbol":"BTC/USD","bids":[{"price":64744.3,"qty":0.00000000},{"price":64744.2,"qty":0.00029694}],"asks":[],"checksum":1586290976,"timestamp":"2026-07-15T03:59:35.005552Z"}]}
{"channel":"book","type":"update","data":[{"symbol":"BTC/USD","bids":[],"asks":[{"price":64762.9,"qty":0.01544093}],"checksum":3627305900,"timestamp":"2026-07-15T03:59:35.013493Z"}]}
{"channel":"book","type":"update","data":[{"symbol":"BTC/USD","bids":[],"asks":[{"price":64762.9,"qty":0.03088186}],"checksum":1937763894,"timestamp":"2026-07-15T03:59:35.013516Z"}]}
{"channel":"book","type":"update","data":[{"symbol":"BTC/USD","bids":[],"asks":[{"price":64764.2,"qty":0.01544062}],"checksum":3967898801,"timestamp":"2026-07-15T03:59:35.013529Z"}]}
{"channel":"book","type":"update","data":[{"symbol":"BTC/USD","bids":[],"asks":[{"price":64764.2,"qty":0.00000000},{"price":64766.8,"qty":1.35736373}],"checksum":469592080,"timestamp":"2026-07-15T03:59:35.013553Z"}]}
{"channel":"heartbeat"}
{"channel":"trade","type":"update","data":[{"symbol":"BTC/USD","side":"sell","price":64760.4,"qty":0.04180201,"ord_type":"limit","trade_id":103746750,"timestamp":"2026-07-15T03:59:35.367113Z"},{"symbol":"BTC/USD","side":"sell","price":64760.4,"qty":0.00345788,"ord_type":"limit","trade_id":103746751,"timestamp":"2026-07-15T03:59:35.367113Z"},{"symbol":"BTC/USD","side":"sell","price":64760.4,"qty":0.00077208,"ord_type":"limit","trade_id":103746752,"timestamp":"2026-07-15T03:59:35.367113Z"},{"symbol":"BTC/USD","side":"sell","price":64760.4,"qty":0.00008031,"ord_type":"limit","trade_id":103746753,"timestamp":"2026-07-15T03:59:35.367113Z"}]}
{"channel":"book","type":"update","data":[{"symbol":"BTC/USD","bids":[{"price":64760.4,"qty":0.00431027},{"price":64760.4,"qty":0.00085239},{"price":64760.4,"qty":0.00008031},{"price":64760.4,"qty":0.00000000},{"price":64743.3,"qty":0.03086225}],"asks":[{"price":64760.4,"qty":0.03289841}],"checksum":1103117268,"timestamp":"2026-07-15T03:59:35.367113Z"}]}
{"channel":"book","type":"update","data":[{"symbol":"BTC/USD","bids":[{"price":64757.4,"qty":0.00000000},{"price":64743.2,"qty":0.77228186}],"asks":[],"checksum":664009830,"timestamp":"2026-07-15T03:59:35.368553Z"}]}
{"channel":"book","type":"update","data":[{"symbol":"BTC/USD","bids":[],"asks":[{"price":64757.5,"qty":0.05820000}],"checksum":2430908035,"timestamp":"2026-07-15T03:59:35.368683Z"}]}
{"channel":"book","type":"update","data":[{"symbol":"BTC/USD","bids":[],"asks":[{"price":64760.4,"qty":0.04620158}],"checksum":1436552857,"timestamp":"2026-07-15T03:59:35.368781Z"}]}
{"channel":"book","type":"update","data":[{"symbol":"BTC/USD","bids":[],"asks":[{"price":64760.5,"qty":2.04034606}],"checksum":2688774595,"timestamp":"2026-07-15T03:59:35.368897Z"}]}
{"channel":"book","type":"update","data":[{"symbol":"BTC/USD","bids":[],"asks":[{"price":64760.3,"qty":0.11000000}],"checksum":1398221344,"timestamp":"2026-07-15T03:59:35.368927Z"}]}
{"channel":"book","type":"update","data":[{"symbol":"BTC/USD","bids":[],"asks":[{"price":64762.5,"qty":0.00000000},{"price":64764.1,"qty":0.00308813}],"checksum":539870481,"timestamp":"2026-07-15T03:59:35.368943Z"}]}
{"channel":"book","type":"update","data":[{"symbol":"BTC/USD","bids":[],"asks":[{"price":64760.5,"qty":2.02124228},{"price":64760.3,"qty":0.14086225}],"checksum":3120874713,"timestamp":"2026-07-15T03:59:35.369041Z"}]}
{"channel":"book","type":"update","data":[{"symbol":"BTC/USD","bids":[],"asks":[{"price":64760.5,"qty":1.98249807}],"checksum":3291519705,"timestamp":"2026-07-15T03:59:35.369672Z"}]}
{"channel":"book","type":"update","data":[{"symbol":"BTC/USD","bids":[],"asks":[{"price":64760.3,"qty":0.18054750}],"checksum":3272568010,"timestamp":"2026-07-15T03:59:35.369776Z"}]}
{"channel":"book","type":"update","data":[{"symbol":"BTC/USD","bids":[],"asks":[{"price":64760.3,"qty":0.07054750}],"checksum":711376865,"timestamp":"2026-07-15T03:59:35.369906Z"}]}
{"channel":"book","type":"update","data":[{"symbol":"BTC/USD","bids":[],"asks":[{"price":64760.5,"qty":1.95509807}],"checksum":4114608614,"timestamp":"2026-07-15T03:59:35.369913Z"}]}
{"channel":"book","type":"update","data":[{"symbol":"BTC/USD","bids":[],"asks":[{"price":64760.5,"qty":1.18302250}],"checksum":1097660770,"timestamp":"2026-07-15T03:59:35.369929Z"}]}
{"channel":"book","type":"update","data":[{"symbol":"BTC/USD","bids":[],"asks":[{"price":64757.5,"qty":0.08560000}],"checksum":2630953578,"timestamp":"2026-07-15T03:59:35.369937Z"}]}
{"channel":"book","type":"update","data":[{"symbol":"BTC/USD","bids":[],"asks":[{"price":64757.4,"qty":0.03968525}],"checksum":697160784,"timestamp":"2026-07-15T03:59:35.370013Z"}]}
{"channel":"book","type":"update","data":[{"symbol":"BTC/USD","bids":[{"price":64754.1,"qty":0.00000000},{"price":64742.9,"qty":0.40000000}],"asks":[],"checksum":3548708924,"timestamp":"2026-07-15T03:59:35.370025Z"}]}
{"channel":"book","type":"update","data":[{"symbol":"BTC/USD","bids":[],"asks":[{"price":64760.5,"qty":0.88302250}],"checksum":1255420268,"timestamp":"2026-07-15T03:59:35.370103Z"}]}
{"channel":"book","type":"update","data":[{"symbol":"BTC/USD","bids":[],"asks":[{"price":64760.3,"qty":0.03086225}],"checksum":3122381199,"timestamp":"2026-07-15T03:59:35.370115Z"}]}
{"channel":"book","type":"update","data":[{"symbol":"BTC/USD","bids":[],"asks":[{"price":64754.2,"qty":0.02740000}],"checksum":2972181899,"timestamp":"2026-07-15T03:59:35.370560Z"}]}
{"channel":"book","type":"update","data":[{"symbol":"BTC/USD","bids":[],"asks":[{"price":64760.5,"qty":0.58302250}],"checksum":567910593,"timestamp":"2026-07-15T03:59:35.370691Z"}]}
{"channel":"book","type":"update","data":[{"symbol":"BTC/USD","bids":[],"asks":[{"price":64762.4,"qty":0.19968751}],"checksum":1577405211,"timestamp":"2026-07-15T03:59:35.370750Z"}]}
{"channel":"book","type":"update","data":[{"symbol":"BTC/USD","bids":[],"asks":[{"price":64752.9,"qty":0.05820000}],"checksum":1874905590,"timestamp":"2026-07-15T03:59:35.371245Z"}]}
{"channel":"book","type":"update","data":[{"symbol":"BTC/USD","bids":[],"asks":[{"price":64760.3,"qty":0.03279244}],"checksum":280127439,"timestamp":"2026-07-15T03:59:35.371577Z"}]}
{"channel":"book","type":"update","data":[{"symbol":"BTC/USD","bids":[],"asks":[{"price":64754.2,"qty":0.79955068}],"checksum":1044025149,"timestamp":"2026-07-15T03:59:35.371648Z"}]}
{"channel":"book","type":"update","data":[{"symbol":"BTC/USD","bids":[],"asks":[{"price":64752.4,"qty":0.51894522}],"checksum":2500016068,"timestamp":"2026-07-15T03:59:35.371717Z"}]}
{"channel":"book","type":"update","data":[{"symbol":"BTC/USD","bids":[],"asks":[{"price":64760.3,"qty":0.03989293}],"checksum":3794633084,"timestamp":"2026-07-15T03:59:35.371825Z"}]}
{"channel":"book","type":"update","data":[{"symbol":"BTC/USD","bids":[],"asks":[{"price":64757.4,"qty":0.81179778}],"checksum":2850224393,"timestamp":"2026-07-15T03:59:35.371909Z"}]}
{"channel":"book","type":"update","data":[{"symbol":"BTC/USD","bids":[],"asks":[{"price":64760.5,"qty":0.57592203}],"checksum":3699554527,"timestamp":"2026-07-15T03:59:35.371931Z"}]}
{"channel":"book","type":"update","data":[{"symbol":"BTC/USD","bids":[],"asks":[{"price":64757.3,"qty":0.03739765}],"checksum":1017427327,"timestamp":"2026-07-15T03:59:35.371983Z"}]}
{"channel":"book","type":"update","data":[{"symbol":"BTC/USD","bids":[],"asks":[{"price":64754.2,"qty":0.02740000}],"checksum":3721433147,"timestamp":"2026-07-15T03:59:35.372090Z"}]}
{"channel":"book","type":"update","data":[{"symbol":"BTC/USD","bids":[],"asks":[{"price":64760.4,"qty":0.03289841}],"checksum":2854008759,"timestamp":"2026-07-15T03:59:35.373052Z"}]}
{"channel":"book","type":"update","data":[{"symbol":"BTC/USD","bids":[],"asks":[{"price":64760.3,"qty":0.03796274}],"checksum":3521167605,"timestamp":"2026-07-15T03:59:35.373334Z"}]}
{"channel":"book","type":"update","data":[{"symbol":"BTC/USD","bids":[],"asks":[{"price":64752.9,"qty":0.07150471}],"checksum":954574263,"timestamp":"2026-07-15T03:59:35.373355Z"}]}
{"channel":"book","type":"update","data":[{"symbol":"BTC/USD","bids":[{"price":64747.8,"qty":0.00154445}],"asks":[],"checksum":1580514289,"timestamp":"2026-07-15T03:59:35.374058Z"}]}
{"channel":"book","type":"update","data":[{"symbol":"BTC/USD","bids":[],"asks":[{"price":64754.1,"qty":0.00193037}],"checksum":38151437,"timestamp":"2026-07-15T03:59:35.374846Z"}]}
{"channel":"book","type":"update","data":[{"symbol":"BTC/USD","bids":[],"asks":[{"price":64752.3,"qty":0.00710101}],"checksum":659195299,"timestamp":"2026-07-15T03:59:35.375744Z"}]}
{"channel":"book","type":"update","data":[{"symbol":"BTC/USD","bids":[],"asks":[{"price":64760.3,"qty":0.03086225}],"checksum":2807041563,"timestamp":"2026-07-15T03:59:35.377266Z"}]}
{"channel":"book","type":"update","data":[{"symbol":"BTC/USD","bids":[],"asks":[{"price":64754.1,"qty":0.00000000},{"price":64760.5,"qty":0.57592203}],"checksum":1497338184,"timestamp":"2026-07-15T03:59:35.377414Z"}]}
{"channel":"book","type":"update","data":[{"symbol":"BTC/USD","bids":[],"asks":[{"price":64757.5,"qty":0.05820000}],"checksum":4169029876,"timestamp":"2026-07-15T03:59:35.380175Z"}]}
{"channel":"book","type":"update","data":[{"symbol":"BTC/USD","bids":[],"asks":[{"price":64754.2,"qty":0.00000000},{"price":64762.1,"qty":0.06015446}],"checksum":4063546166,"timestamp":"2026-07-15T03:59:35.380929Z"}]}
{"channel":"book","type":"update","data":[{"symbol":"BTC/USD","bids":[],"asks":[{"price":64751.2,"qty":0.02740000}],"checksum":4188253181,"timestamp":"2026-07-15T03:59:35.380954Z"}]}
{"channel":"book","type":"update","data":[{"symbol":"BTC/USD","bids":[{"price":64751.1,"qty":0.01277219}],"asks":[],"checksum":1817490309,"timestamp":"2026-07-15T03:59:35.381309Z"}]}
{"channel":"book","type":"update","data":[{"symbol":"BTC/USD","bids":[],"asks":[{"price":64751.2,"qty":0.05480000}],"checksum":538354538,"timestamp":"2026-07-15T03:59:35.381353Z"}]}
{"channel":"book","type":"update","data":[{"symbol":"BTC/USD","bids":[],"asks":[{"price":64760.5,"qty":0.57514995},{"price":64752.3,"qty":0.00787319}],"checksum":3941384691,"timestamp":"2026-07-15T03:59:35.381751Z"}]}
{"channel":"book","type":"update","data":[{"symbol":"BTC/USD","bids":[],"asks":[{"price":64751.2,"qty":0.02740000}],"checksum":2796474652,"timestamp":"2026-07-15T03:59:35.382231Z"}]}
{"channel":"book","type":"update","data":[{"symbol":"BTC/USD","bids":[],"asks":[{"price":64751.2,"qty":0.00000000},{"price":64762.1,"qty":0.06015446}],"checksum":883100028,"timestamp":"2026-07-15T03:59:35.383446Z"}]}
{"channel":"book","type":"update","data":[{"symbol":"BTC/USD","bids":[{"price":64751.1,"qty":0.04017219}],"asks":[],"checksum":3302180094,"timestamp":"2026-07-15T03:59:35.383465Z"}]}
{"channel":"book","type":"update","data":[{"symbol":"BTC/USD","bids":[],"asks":[{"price":64751.2,"qty":0.02740000}],"checksum":1457429662,"timestamp":"2026-07-15T03:59:35.383662Z"}]}
{"channel":"book","type":"update","data":[{"symbol":"BTC/USD","bids":[{"price":64751.1,"qty":0.01277219}],"asks":[],"checksum":2796474652,"timestamp":"2026-07-15T03:59:35.384753Z"}]}
{"channel":"book","type":"update","data":[{"symbol":"BTC/USD","bids":[],"asks":[{"price":64751.2,"qty":0.03450108}],"checksum":1444613350,"timestamp":"2026-07-15T03:59:35.384892Z"}]}
{"channel":"book","type":"update","data":[{"symbol":"BTC/USD","bids":[],"asks":[{"price":64751.2,"qty":0.09650108}],"checksum":706054228,"timestamp":"2026-07-15T03:59:35.384946Z"}]}
{"channel":"book","type":"update","data":[{"symbol":"BTC/USD","bids":[],"asks":[{"price":64751.2,"qty":0.06910108}],"checksum":1280342151,"timestamp":"2026-07-15T03:59:35.384987Z"}]}
{"channel":"book","type":"update","data":[{"symbol":"BTC/USD","bids":[],"asks":[{"price":64752.3,"qty":0.00077218}],"checksum":3196218606,"timestamp":"2026-07-15T03:59:35.385176Z"}]}
{"channel":"book","type":"update","data":[{"symbol":"BTC/USD","bids":[],"asks":[{"price":64760.5,"qty":0.17514995},{"price":64752.9,"qty":0.47150471}],"checksum":1737589423,"timestamp":"2026-07-15T03:59:35.385599Z"}]}
{"channel":"book","type":"update","data":[{"symbol":"BTC/USD","bids":[],"asks":[{"price":64751.2,"qty":0.00710108}],"checksum":3234936747,"timestamp":"2026-07-15T03:59:35.386309Z"}]}
{"channel":"book","type":"update","data":[{"symbol":"BTC/USD","bids":[{"price":64751.1,"qty":0.00077219}],"asks":[],"checksum":4271521269,"timestamp":"2026-07-15T03:59:35.386402Z"}]}
{"channel":"book","type":"update","data":[{"symbol":"BTC/USD","bids":[],"asks":[{"price":64751.2,"qty":0.03450108}],"checksum":2882465994,"timestamp":"2026-07-15T03:59:35.386756Z"}]}
{"channel":"book","type":"update","data":[{"symbol":"BTC/USD","bids":[],"asks":[{"price":64752.3,"qty":0.00000000},{"price":64762.1,"qty":0.06015446},{"price":64751.2,"qty":0.03527327}],"checksum":4059353005,"timestamp":"2026-07-15T03:59:35.387530Z"}]}
{"channel":"book","type":"update","data":[{"symbol":"BTC/USD","bids":[],"asks":[{"price":64751.2,"qty":0.06267327}],"checksum":1272195703,"timestamp":"2026-07-15T03:59:35.388191Z"}]}
{"channel":"book","type":"update","data":[{"symbol":"BTC/USD","bids":[],"asks":[{"price":64751.2,"qty":0.03527327}],"checksum":4059353005,"timestamp":"2026-07-15T03:59:35.388355Z"}]}
{"channel":"book","type":"update","data":[{"symbol":"BTC/USD","bids":[],"asks":[{"price":64751.2,"qty":0.03450108},{"price":64752.3,"qty":0.00077218}],"checksum":2882465994,"timestamp":"2026-07-15T03:59:35.390076Z"}]}
{"channel":"book","type":"update","data":[{"symbol":"BTC/USD","bids":[],"asks":[{"price":64752.3,"qty":0.00000000},{"price":64762.1,"qty":0.06015446},{"price":64751.2,"qty":0.03527327}],"checksum":4059353005,"timestamp":"2026-07-15T03:59:35.392878Z"}]}
{"channel":"book","type":"update","data":[{"symbol":"BTC/USD","bids":[],"asks":[{"price":64751.2,"qty":0.03836202}],"checksum":3159949928,"timestamp":"2026-07-15T03:59:35.402439Z"}]}
{"channel":"book","type":"update","data":[{"symbol":"BTC/USD","bids":[],"asks":[{"price":64760.5,"qty":0.06514995}],"checksum":874039456,"timestamp":"2026-07-15T03:59:35.470171Z"}]}
{"channel":"book","type":"update","data":[{"symbol":"BTC/USD","bids":[{"price":64743.2,"qty":0.00000000},{"price":64742.9,"qty":0.40000000}],"asks":[],"checksum":3227753376,"timestamp":"2026-07-15T03:59:35.511183Z"}]}
{"channel":"book","type":"update","data":[{"symbol":"BTC/USD","bids":[],"asks":[{"price":64751.6,"qty":0.77218255}],"checksum":3253387581,"timestamp":"2026-07-15T03:59:35.512755Z"}]}
{"channel":"book","type":"update","data":[{"symbol":"BTC/USD","bids":[{"price":64743.3,"qty":0.00000000},{"price":64742.8,"qty":0.54983668},{"price":64743.0,"qty":0.03086225}],"asks":[],"checksum":4170345597,"timestamp":"2026-07-15T03:59:35.513153Z"}]}
{"channel":"book","type":"update","data":[{"symbol":"BTC/USD","bids":[],"asks":[{"price":64757.5,"qty":0.00000000},{"price":64762.1,"qty":0.06015446}],"checksum":3044046283,"timestamp":"2026-07-15T03:59:35.524311Z"}]}
{"channel":"book","type":"update","data":[{"symbol":"BTC/USD","bids":[],"asks":[{"price":64760.3,"qty":0.00000000},{"price":64762.4,"qty":0.19968751},{"price":64751.2,"qty":0.06922427}],"checksum":589661323,"timestamp":"2026-07-15T03:59:35.545798Z"}]}
{"channel":"book","type":"update","data":[{"symbol":"BTC/USD","bids":[{"price":64744.4,"qty":0.00005100}],"asks":[],"checksum":1350265458,"timestamp":"2026-07-15T03:59:35.725572Z"}]}
{"channel":"book","type":"update","data":[{"symbol":"BTC/USD","bids":[],"asks":[{"price":64760.5,"qty":0.06315035}],"checksum":4008209203,"timestamp":"2026-07-15T03:59:35.778899Z"}]}
{"channel":"book","type":"update","data":[{"symbol":"BTC/USD","bids":[],"asks":[{"price":64760.5,"qty":0.06160619}],"checksum":3541856414,"timestamp":"2026-07-15T03:59:36.002010Z"}]}
{"channel":"book","type":"update","data":[{"symbol":"BTC/USD","bids":[],"asks":[{"price":64751.2,"qty":0.07076865}],"checksum":3203731839,"timestamp":"2026-07-15T03:59:36.002328Z"}]}
{"channel":"book","type":"update","data":[{"symbol":"BTC/USD","bids":[{"price":64746.4,"qty":0.00000000},{"price":64742.9,"qty":0.40000000}],"asks":[],"checksum":2236721916,"timestamp":"2026-07-15T03:59:36.014962Z"}]}
{"channel":"book","type":"update","data":[{"symbol":"BTC/USD","bids":[{"price":64751.1,"qty":0.00777219}],"asks":[],"checksum":1832665150,"timestamp":"2026-07-15T03:59:36.051425Z"}]}
{"channel":"book","type":"update","data":[{"symbol":"BTC/USD","bids":[],"asks":[{"price":64760.5,"qty":0.06060619}],"checksum":479238265,"timestamp":"2026-07-15T03:59:36.052173Z"}]}
{"channel":"book","type":"update","data":[{"symbol":"BTC/USD","bids":[],"asks":[{"price":64753.0,"qty":0.77216501}],"checksum":483430627,"timestamp":"2026-07-15T03:59:36.059992Z"}]}
{"channel":"heartbeat"}
{"channel":"book","type":"update","data":[{"symbol":"BTC/USD","bids":[],"asks":[{"price":64757.4,"qty":0.77211253}],"checksum":2162856188,"timestamp":"2026-07-15T03:59:36.279483Z"}]}
{"channel":"book","type":"update","data":[{"symbol":"BTC/USD","bids":[],"asks":[{"price":64753.5,"qty":0.03968525}],"checksum":1475378166,"timestamp":"2026-07-15T03:59:36.279661Z"}]}
{"channel":"book","type":"update","data":[{"symbol":"BTC/USD","bids":[{"price":64747.8,"qty":0.00000000},{"price":64742.8,"qty":0.55138126}],"asks":[],"checksum":3767950463,"timestamp":"2026-07-15T03:59:36.464421Z"}]}
{"channel":"book","type":"update","data":[{"symbol":"BTC/USD","bids":[],"asks":[{"price":64751.9,"qty":0.04491928}],"checksum":652013933,"timestamp":"2026-07-15T03:59:36.566002Z"}]}
{"channel":"book","type":"update","data":[{"symbol":"BTC/USD","bids":[{"price":64751.1,"qty":0.00784763}],"asks":[],"checksum":3548613257,"timestamp":"2026-07-15T03:59:36.844760Z"}]}
{"channel":"book","type":"update","data":[{"symbol":"BTC/USD","bids":[],"asks":[{"price":64760.4,"qty":0.03489801}],"checksum":3360834660,"timestamp":"2026-07-15T03:59:36.854904Z"}]}
{"channel":"book","type":"update","data":[{"symbol":"BTC/USD","bids":[],"asks":[{"price":64754.0,"qty":0.00005100}],"checksum":3981419887,"timestamp":"2026-07-15T03:59:36.871163Z"}]}
{"channel":"book","type":"update","data":[{"symbol":"BTC/USD","bids":[],"asks":[{"price":64751.2,"qty":0.07176865}],"checksum":2723531501,"timestamp":"2026-07-15T03:59:37.015551Z"}]}
{"channel":"book","type":"update","data":[{"symbol":"BTC/USD","bids":[],"asks":[{"price":64751.5,"qty":0.78190673}],"checksum":81808018,"timestamp":"2026-07-15T03:59:37.019853Z"}]}
{"channel":"book","type":"update","data":[{"symbol":"BTC/USD","bids":[],"asks":[{"price":64752.9,"qty":0.45820000}],"checksum":215602616,"timestamp":"2026-07-15T03:59:37.021281Z"}]}
{"channel":"book","type":"update","data":[{"symbol":"BTC/USD","bids":[],"asks":[{"price":64752.9,"qty":0.40000000}],"checksum":1715237317,"timestamp":"2026-07-15T03:59:37.073762Z"}]}
{"channel":"heartbeat"}
{"channel":"book","type":"update","data":[{"symbol":"BTC/USD","bids":[],"asks":[{"price":64757.3,"qty":0.22569437}],"checksum":3653967080,"timestamp":"2026-07-15T03:59:37.271773Z"}]}
{"channel":"trade","type":"update","data":[{"symbol":"BTC/USD","side":"sell","price":64751.1,"qty":0.00022526,"ord_type":"limit","trade_id":103746754,"timestamp":"2026-07-15T03:59:37.310034Z"}]}
{"channel":"book","type":"update","data":[{"symbol":"BTC/USD","bids":[{"price":64751.1,"qty":0.00762237}],"asks":[],"checksum":2594679755,"timestamp":"2026-07-15T03:59:37.310034Z"}]}
{"channel":"book","type":"update","data":[{"symbol":"BTC/USD","bids":[],"asks":[{"price":64751.2,"qty":0.07022427}],"checksum":2259720774,"timestamp":"2026-07-15T03:59:37.409148Z"}]}
{"channel":"book","type":"update","data":[{"symbol":"BTC/USD","bids":[],"asks":[{"price":64757.3,"qty":0.22574537}],"checksum":2456367271,"timestamp":"2026-07-15T03:59:37.411259Z"}]}
{"channel":"book","type":"update","data":[{"symbol":"BTC/USD","bids":[{"price":64751.1,"qty":0.02062237}],"asks":[],"checksum":4113939144,"timestamp":"2026-07-15T03:59:37.576165Z"}]}
{"channel":"book","type":"update","data":[{"symbol":"BTC/USD","bids":[],"asks":[{"price":64751.2,"qty":0.04282427}],"checksum":1117968887,"timestamp":"2026-07-15T03:59:37.578018Z"}]}
{"channel":"trade","type":"update","data":[{"symbol":"BTC/USD","side":"buy","price":64751.2,"qty":0.00009037,"ord_type":"limit","trade_id":103746755,"timestamp":"2026-07-15T03:59:38.064064Z"}]}
{"channel":"book","type":"update","data":[{"symbol":"BTC/USD","bids":[],"asks":[{"price":64751.2,"qty":0.04273390}],"checksum":1405820211,"timestamp":"2026-07-15T03:59:38.064064Z"}]}
{"channel":"heartbeat"}
{"channel":"book","type":"update","data":[{"symbol":"BTC/USD","bids":[{"price":64742.8,"qty":0.54983668}],"asks":[],"checksum":1067834492,"timestamp":"2026-07-15T03:59:38.700755Z"}]}
{"channel":"book","type":"update","data":[{"symbol":"BTC/USD","bids":[{"price":64743.1,"qty":0.00154457}],"asks":[],"checksum":1133728276,"timestamp":"2026-07-15T03:59:38.701079Z"}]}
{"channel":"book","type":"update","data":[{"symbol":"BTC/USD","bids":[],"asks":[{"price":64751.2,"qty":0.04427828}],"checksum":1940803585,"timestamp":"2026-07-15T03:59:38.701344Z"}]}
{"channel":"book","type":"update","data":[{"symbol":"BTC/USD","bids":[{"price":64743.0,"qty":0.00000000},{"price":64742.8,"qty":0.54983668},{"price":64743.2,"qty":0.03086225}],"asks":[],"checksum":4144221543,"timestamp":"2026-07-15T03:59:38.702599Z"}]}
{"channel":"book","type":"update","data":[{"symbol":"BTC/USD","bids":[{"price":64743.1,"qty":0.00000000},{"price":64742.8,"qty":0.54983668}],"asks":[],"checksum":395232274,"timestamp":"2026-07-15T03:59:39.002021Z"}]}
{"channel":"book","type":"update","data":[{"symbol":"BTC/USD","bids":[{"price":64743.2,"qty":0.03240682}],"asks":[],"checksum":698663356,"timestamp":"2026-07-15T03:59:39.002353Z"}]}
{"channel":"book","type":"update","data":[{"symbol":"BTC/USD","bids":[{"price":64743.2,"qty":0.00154457},{"price":64743.0,"qty":0.03086225}],"asks":[],"checksum":505979739,"timestamp":"2026-07-15T03:59:39.003054Z"}]}
{"channel":"book","type":"update","data":[{"symbol":"BTC/USD","bids":[{"price":64743.0,"qty":0.00000000},{"price":64742.8,"qty":0.54983668},{"price":64743.3,"qty":0.03086225}],"asks":[],"checksum":2829000370,"timestamp":"2026-07-15T03:59:39.003898Z"}]}
{"channel":"book","type":"update","data":[{"symbol":"BTC/USD","bids":[{"price":64747.7,"qty":0.00005100}],"asks":[],"checksum":3738891290,"timestamp":"2026-07-15T03:59:39.150952Z"}]}
{"channel":"book","type":"update","data":[{"symbol":"BTC/USD","bids":[{"price":64743.2,"qty":0.00000000},{"price":64742.8,"qty":0.54983668}],"asks":[],"checksum":2768198469,"timestamp":"2026-07-15T03:59:39.151045Z"}]}
{"channel":"book","type":"update","data":[{"symbol":"BTC/USD","bids":[{"price":64743.3,"qty":0.00000000},{"price":64742.2,"qty":0.33273746},{"price":64743.0,"qty":0.03086225}],"asks":[],"checksum":3223265467,"timestamp":"2026-07-15T03:59:39.152415Z"}]}
{"channel":"heartbeat"}
{"channel":"book","type":"update","data":[{"symbol":"BTC/USD","bids":[{"price":64743.0,"qty":0.03240682}],"asks":[],"checksum":4264895765,"timestamp":"2026-07-15T03:59:39.824816Z"}]}
{"channel":"book","type":"update","data":[{"symbol":"BTC/USD","bids":[{"price":64743.0,"qty":0.00154457},{"price":64743.1,"qty":0.03086225}],"asks":[],"checksum":1931106059,"timestamp":"2026-07-15T03:59:39.826005Z"}]}
{"channel":"book","type":"update","data":[{"symbol":"BTC/USD","bids":[{"price":64747.8,"qty":0.01332383}],"asks":[],"checksum":1019109839,"timestamp":"2026-07-15T03:59:39.944524Z"}]}
{"channel":"book","type":"update","data":[{"symbol":"BTC/USD","bids":[{"price":64747.8,"qty":0.00000000},{"price":64742.9,"qty":0.40000000}],"asks":[],"checksum":1931106059,"timestamp":"2026-07-15T03:59:40.193218Z"}]}
{"channel":"heartbeat"}
{"channel":"book","type":"update","data":[{"symbol":"BTC/USD","bids":[],"asks":[{"price":64751.2,"qty":0.03726757}],"checksum":2310034346,"timestamp":"2026-07-15T03:59:40.642758Z"}]}
{"channel":"book","type":"update","data":[{"symbol":"BTC/USD","bids":[{"price":64743.0,"qty":0.00000000},{"price":64742.8,"qty":0.54983668}],"asks":[],"checksum":3843966773,"timestamp":"2026-07-15T03:59:40.663728Z"}]}
{"channel":"book","type":"update","data":[{"symbol":"BTC/USD","bids":[{"price":64743.1,"qty":0.00000000},{"price":64742.2,"qty":0.33273746},{"price":64743.0,"qty":0.03086388}],"asks":[],"checksum":2760629559,"timestamp":"2026-07-15T03:59:40.664834Z"}]}
{"channel":"book","type":"update","data":[{"symbol":"BTC/USD","bids":[{"price":64744.8,"qty":0.00000000},{"price":64742.5,"qty":0.00154459}],"asks":[],"checksum":3626973277,"timestamp":"2026-07-15T03:59:41.102280Z"}]}
{"channel":"book","type":"update","data":[{"symbol":"BTC/USD","bids":[{"price":64744.1,"qty":0.77227052}],"asks":[],"checksum":2684871906,"timestamp":"2026-07-15T03:59:41.103839Z"}]}
{"channel":"book","type":"update","data":[{"symbol":"BTC/USD","bids":[{"price":64744.1,"qty":0.00000000},{"price":64742.5,"qty":0.00154459}],"asks":[],"checksum":3626973277,"timestamp":"2026-07-15T03:59:41.115074Z"}]}
{"channel":"book","type":"update","data":[{"symbol":"BTC/USD","bids":[],"asks":[{"price":64751.2,"qty":0.09546757}],"checksum":4222243355,"timestamp":"2026-07-15T03:59:41.117249Z"}]}
{"channel":"book","type":"update","data":[{"symbol":"BTC/USD","bids":[],"asks":[{"price":64751.2,"qty":0.12286757}],"checksum":3530543886,"timestamp":"2026-07-15T03:59:41.119677Z"}]}
{"channel":"book","type":"update","data":[{"symbol":"BTC/USD","bids":[],"asks":[{"price":64751.2,"qty":0.12996865}],"checksum":1353510305,"timestamp":"2026-07-15T03:59:41.121385Z"}]}
{"channel":"book","type":"update","data":[{"symbol":"BTC/USD","bids":[{"price":64742.5,"qty":0.00000000},{"price":64741.9,"qty":0.11000000}],"asks":[],"checksum":2125665294,"timestamp":"2026-07-15T03:59:41.199851Z"}]}
{"channel":"book","type":"update","data":[{"symbol":"BTC/USD","bids":[],"asks":[{"price":64751.2,"qty":0.14351332}],"checksum":3836526560,"timestamp":"2026-07-15T03:59:41.259634Z"}]}
{"channel":"heartbeat"}
{"channel":"trade","type":"update","data":[{"symbol":"BTC/USD","side":"buy","price":64751.2,"qty":0.00075304,"ord_type":"market","trade_id":103746756,"timestamp":"2026-07-15T03:59:41.563254Z"}]}
{"channel":"book","type":"update","data":[{"symbol":"BTC/USD","bids":[],"asks":[{"price":64751.2,"qty":0.14276028}],"checksum":551423956,"timestamp":"2026-07-15T03:59:41.563254Z"}]}
{"channel":"book","type":"update","data":[{"symbol":"BTC/USD","bids":[{"price":64742.8,"qty":1.32212238}],"asks":[],"checksum":4136655330,"timestamp":"2026-07-15T03:59:42.062323Z"}]}
{"channel":"book","type":"update","data":[{"symbol":"BTC/USD","bids":[],"asks":[{"price":64751.2,"qty":0.13565920}],"checksum":3129281442,"timestamp":"2026-07-15T03:59:42.065717Z"}]}
{"channel":"heartbeat"}
{"channel":"book","type":"update","data":[{"symbol":"BTC/USD","bids":[],"asks":[{"price":64751.2,"qty":0.07745920}],"checksum":3210378123,"timestamp":"2026-07-15T03:59:42.492263Z"}]}
{"channel":"book","type":"update","data":[{"symbol":"BTC/USD","bids":[{"price":64742.8,"qty":0.54983668}],"asks":[],"checksum":2210081586,"timestamp":"2026-07-15T03:59:42.770671Z"}]}
{"channel":"book","type":"update","data":[{"symbol":"BTC/USD","bids":[{"price":64743.5,"qty":0.77227776}],"asks":[],"checksum":3293133609,"timestamp":"2026-07-15T03:59:42.772405Z"}]}
{"channel":"book","type":"update","data":[{"symbol":"BTC/USD","bids":[{"price":64743.0,"qty":0.00000000},{"price":64741.9,"qty":0.11000000},{"price":64743.6,"qty":0.03086388}],"asks":[],"checksum":675728466,"timestamp":"2026-07-15T03:59:42.773983Z"}]}
{"channel":"book","type":"update","data":[{"symbol":"BTC/USD","bids":[],"asks":[{"price":64751.2,"qty":0.06391453}],"checksum":293711129,"timestamp":"2026-07-15T03:59:42.956931Z"}]}
{"channel":"book","type":"update","data":[{"symbol":"BTC/USD","bids":[],"asks":[{"price":64751.2,"qty":0.03651453}],"checksum":2802743582,"timestamp":"2026-07-15T03:59:42.958818Z"}]}
{"channel":"book","type":"update","data":[{"symbol":"BTC/USD","bids":[{"price":64751.1,"qty":0.04802237}],"asks":[],"checksum":2042111407,"timestamp":"2026-07-15T03:59:42.958897Z"}]}
{"channel":"book","type":"update","data":[{"symbol":"BTC/USD","bids":[{"price":64751.1,"qty":0.08972237}],"asks":[],"checksum":1388310934,"timestamp":"2026-07-15T03:59:42.960544Z"}]}
{"channel":"book","type":"update","data":[{"symbol":"BTC/USD","bids":[{"price":64751.1,"qty":0.11712237}],"asks":[],"checksum":2070441071,"timestamp":"2026-07-15T03:59:42.960708Z"}]}
{"channel":"book","type":"update","data":[{"symbol":"BTC/USD","bids":[{"price":64751.1,"qty":0.08972237}],"asks":[],"checksum":1388310934,"timestamp":"2026-07-15T03:59:42.960722Z"}]}
{"channel":"book","type":"update","data":[{"symbol":"BTC/USD","bids":[],"asks":[{"price":64751.2,"qty":0.06391453}],"checksum":3828360593,"timestamp":"2026-07-15T03:59:42.960734Z"}]}
{"channel":"book","type":"update","data":[{"symbol":"BTC/USD","bids":[],"asks":[{"price":64751.2,"qty":0.03651453}],"checksum":1388310934,"timestamp":"2026-07-15T03:59:42.962238Z"}]}
{"channel":"book","type":"update","data":[{"symbol":"BTC/USD","bids":[{"price":64751.1,"qty":0.04802237}],"asks":[],"checksum":2042111407,"timestamp":"2026-07-15T03:59:42.965870Z"}]}
{"channel":"book","type":"update","data":[{"symbol":"BTC/USD","bids":[{"price":64751.1,"qty":0.08972237}],"asks":[],"checksum":1388310934,"timestamp":"2026-07-15T03:59:42.965878Z"}]}
{"channel":"book","type":"update","data":[{"symbol":"BTC/USD","bids":[{"price":64751.1,"qty":0.13142237}],"asks":[],"checksum":1216137583,"timestamp":"2026-07-15T03:59:42.967609Z"}]}
{"channel":"book","type":"update","data":[{"symbol":"BTC/USD","bids":[{"price":64751.1,"qty":0.08972237}],"asks":[],"checksum":1388310934,"timestamp":"2026-07-15T03:59:42.967740Z"}]}
{"channel":"book","type":"update","data":[{"symbol":"BTC/USD","bids":[],"asks":[{"price":64751.2,"qty":0.05007831}],"checksum":4065969492,"timestamp":"2026-07-15T03:59:43.051799Z"}]}
{"channel":"book","type":"update","data":[{"symbol":"BTC/USD","bids":[{"price":64751.1,"qty":0.04802237}],"asks":[],"checksum":3646820717,"timestamp":"2026-07-15T03:59:43.053684Z"}]}
{"channel":"book","type":"update","data":[{"symbol":"BTC/USD","bids":[],"asks":[{"price":64751.2,"qty":0.07747831}],"checksum":3984884003,"timestamp":"2026-07-15T03:59:43.055845Z"}]}
{"channel":"book","type":"update","data":[{"symbol":"BTC/USD","bids":[{"price":64751.1,"qty":0.02062237}],"asks":[],"checksum":858971538,"timestamp":"2026-07-15T03:59:43.055890Z"}]}
{"channel":"book","type":"update","data":[{"symbol":"BTC/USD","bids":[{"price":64751.1,"qty":0.04802237}],"asks":[],"checksum":3984884003,"timestamp":"2026-07-15T03:59:43.057626Z"}]}
{"channel":"book","type":"update","data":[{"symbol":"BTC/USD","bids":[],"asks":[{"price":64751.2,"qty":0.05007831}],"checksum":3646820717,"timestamp":"2026-07-15T03:59:43.057703Z"}]}
{"channel":"book","type":"update","data":[{"symbol":"BTC/USD","bids":[],"asks":[{"price":64751.2,"qty":0.07747831}],"checksum":3984884003,"timestamp":"2026-07-15T03:59:43.057797Z"}]}
{"channel":"book","type":"update","data":[{"symbol":"BTC/USD","bids":[{"price":64751.1,"qty":0.02062237}],"asks":[],"checksum":858971538,"timestamp":"2026-07-15T03:59:43.058845Z"}]}
{"channel":"book","type":"update","data":[{"symbol":"BTC/USD","bids":[{"price":64751.1,"qty":0.04802237}],"asks":[],"checksum":3984884003,"timestamp":"2026-07-15T03:59:43.059211Z"}]}
{"channel":"book","type":"update","data":[{"symbol":"BTC/USD","bids":[],"asks":[{"price":64751.2,"qty":0.05007831}],"checksum":3646820717,"timestamp":"2026-07-15T03:59:43.059313Z"}]}
{"channel":"book","type":"update","data":[{"symbol":"BTC/USD","bids":[],"asks":[{"price":64751.2,"qty":0.07747831}],"checksum":3984884003,"timestamp":"2026-07-15T03:59:43.059346Z"}]}
{"channel":"book","type":"update","data":[{"symbol":"BTC/USD","bids":[{"price":64751.1,"qty":0.02062237}],"asks":[],"checksum":858971538,"timestamp":"2026-07-15T03:59:43.060380Z"}]}
{"channel":"book","type":"update","data":[{"symbol":"BTC/USD","bids":[],"asks":[{"price":64751.2,"qty":0.05007831}],"checksum":132664796,"timestamp":"2026-07-15T03:59:43.061389Z"}]}
{"channel":"book","type":"update","data":[{"symbol":"BTC/USD","bids":[],"asks":[{"price":64751.2,"qty":0.07747831}],"checksum":858971538,"timestamp":"2026-07-15T03:59:43.061447Z"}]}
{"channel":"book","type":"update","data":[{"symbol":"BTC/USD","bids":[{"price":64751.1,"qty":0.04802237}],"asks":[],"checksum":3984884003,"timestamp":"2026-07-15T03:59:43.061459Z"}]}
{"channel":"book","type":"update","data":[{"symbol":"BTC/USD","bids":[{"price":64751.1,"qty":0.02062237}],"asks":[],"checksum":858971538,"timestamp":"2026-07-15T03:59:43.062849Z"}]}
{"channel":"heartbeat"}
{"channel":"book","type":"update","data":[{"symbol":"BTC/USD","bids":[],"asks":[{"price":64751.4,"qty":0.00193046}],"checksum":1176269457,"timestamp":"2026-07-15T03:59:43.662889Z"}]}
{"channel":"book","type":"update","data":[{"symbol":"BTC/USD","bids":[],"asks":[{"price":64751.2,"qty":0.06391453}],"checksum":734519466,"timestamp":"2026-07-15T03:59:43.664228Z"}]}
{"channel":"book","type":"update","data":[{"symbol":"BTC/USD","bids":[],"asks":[{"price":64751.4,"qty":0.01551168}],"checksum":3957024792,"timestamp":"2026-07-15T03:59:43.664477Z"}]}
{"channel":"book","type":"update","data":[{"symbol":"BTC/USD","bids":[],"asks":[{"price":64751.2,"qty":0.03651453}],"checksum":35803687,"timestamp":"2026-07-15T03:59:43.665720Z"}]}
{"channel":"book","type":"update","data":[{"symbol":"BTC/USD","bids":[{"price":64751.1,"qty":0.04802237}],"asks":[],"checksum":3700690582,"timestamp":"2026-07-15T03:59:43.665804Z"}]}
{"channel":"book","type":"update","data":[{"symbol":"BTC/USD","bids":[{"price":64751.1,"qty":0.02062237}],"asks":[],"checksum":35803687,"timestamp":"2026-07-15T03:59:43.667451Z"}]}
{"channel":"book","type":"update","data":[{"symbol":"BTC/USD","bids":[{"price":64751.1,"qty":0.06232237}],"asks":[],"checksum":1255259442,"timestamp":"2026-07-15T03:59:43.667468Z"}]}
{"channel":"book","type":"update","data":[{"symbol":"BTC/USD","bids":[],"asks":[{"price":64751.2,"qty":0.06391453}],"checksum":2737342221,"timestamp":"2026-07-15T03:59:43.667487Z"}]}
{"channel":"book","type":"update","data":[{"symbol":"BTC/USD","bids":[{"price":64751.1,"qty":0.08972237}],"asks":[],"checksum":510320784,"timestamp":"2026-07-15T03:59:43.667672Z"}]}
{"channel":"book","type":"update","data":[{"symbol":"BTC/USD","bids":[],"asks":[{"price":64751.2,"qty":0.03651453}],"checksum":4153662127,"timestamp":"2026-07-15T03:59:43.668738Z"}]}
{"channel":"book","type":"update","data":[{"symbol":"BTC/USD","bids":[{"price":64751.1,"qty":0.06232237}],"asks":[],"checksum":1255259442,"timestamp":"2026-07-15T03:59:43.669059Z"}]}
{"channel":"book","type":"update","data":[{"symbol":"BTC/USD","bids":[{"price":64751.1,"qty":0.02062237}],"asks":[],"checksum":35803687,"timestamp":"2026-07-15T03:59:43.669145Z"}]}
{"channel":"book","type":"update","data":[{"symbol":"BTC/USD","bids":[],"asks":[{"price":64751.2,"qty":0.06391453}],"checksum":3957024792,"timestamp":"2026-07-15T03:59:43.669173Z"}]}
{"channel":"book","type":"update","data":[{"symbol":"BTC/USD","bids":[{"price":64751.1,"qty":0.04802237}],"asks":[],"checksum":896349353,"timestamp":"2026-07-15T03:59:43.669263Z"}]}
{"channel":"book","type":"update","data":[{"symbol":"BTC/USD","bids":[],"asks":[{"price":64751.2,"qty":0.03651453}],"checksum":3700690582,"timestamp":"2026-07-15T03:59:43.670282Z"}]}
{"channel":"book","type":"update","data":[{"symbol":"BTC/USD","bids":[{"price":64751.1,"qty":0.08972237}],"asks":[],"checksum":4153662127,"timestamp":"2026-07-15T03:59:43.670580Z"}]}
{"channel":"book","type":"update","data":[{"symbol":"BTC/USD","bids":[{"price":64751.1,"qty":0.04802237}],"asks":[],"checksum":3700690582,"timestamp":"2026-07-15T03:59:43.670613Z"}]}
{"channel":"book","type":"update","data":[{"symbol":"BTC/USD","bids":[],"asks":[{"price":64751.2,"qty":0.06391453}],"checksum":896349353,"timestamp":"2026-07-15T03:59:43.670649Z"}]}
{"channel":"book","type":"update","data":[{"symbol":"BTC/USD","bids":[{"price":64751.1,"qty":0.02062237}],"asks":[],"checksum":3957024792,"timestamp":"2026-07-15T03:59:43.670835Z"}]}
{"channel":"book","type":"update","data":[{"symbol":"BTC/USD","bids":[{"price":64751.1,"qty":0.04802237}],"asks":[],"checksum":896349353,"timestamp":"2026-07-15T03:59:43.671014Z"}]}
{"channel":"book","type":"update","data":[{"symbol":"BTC/USD","bids":[],"asks":[{"price":64751.4,"qty":0.01358122}],"checksum":4293634279,"timestamp":"2026-07-15T03:59:43.671186Z"}]}
{"channel":"book","type":"update","data":[{"symbol":"BTC/USD","bids":[{"price":64751.1,"qty":0.08972237}],"asks":[],"checksum":3572268254,"timestamp":"2026-07-15T03:59:43.671910Z"}]}
{"channel":"book","type":"update","data":[{"symbol":"BTC/USD","bids":[],"asks":[{"price":64751.2,"qty":0.03651453}],"checksum":1024804577,"timestamp":"2026-07-15T03:59:43.672007Z"}]}
{"channel":"book","type":"update","data":[{"symbol":"BTC/USD","bids":[{"price":64751.1,"qty":0.04802237}],"asks":[],"checksum":370315992,"timestamp":"2026-07-15T03:59:43.672132Z"}]}
{"channel":"book","type":"update","data":[{"symbol":"BTC/USD","bids":[],"asks":[{"price":64751.2,"qty":0.06391453}],"checksum":4293634279,"timestamp":"2026-07-15T03:59:43.672443Z"}]}
{"channel":"book","type":"update","data":[{"symbol":"BTC/USD","bids":[{"price":64751.1,"qty":0.02062237}],"asks":[],"checksum":559805526,"timestamp":"2026-07-15T03:59:43.672517Z"}]}
{"channel":"book","type":"update","data":[{"symbol":"BTC/USD","bids":[{"price":64751.1,"qty":0.04802237}],"asks":[],"checksum":4293634279,"timestamp":"2026-07-15T03:59:43.672628Z"}]}
{"channel":"book","type":"update","data":[{"symbol":"BTC/USD","bids":[{"price":64751.1,"qty":0.08972237}],"asks":[],"checksum":3572268254,"timestamp":"2026-07-15T03:59:43.673555Z"}]}
{"channel":"book","type":"update","data":[{"symbol":"BTC/USD","bids":[],"asks":[{"price":64751.2,"qty":0.03651453}],"checksum":1024804577,"timestamp":"2026-07-15T03:59:43.673761Z"}]}
{"channel":"book","type":"update","data":[{"symbol":"BTC/USD","bids":[{"price":64751.1,"qty":0.04802237}],"asks":[],"checksum":370315992,"timestamp":"2026-07-15T03:59:43.674465Z"}]}
{"channel":"book","type":"update","data":[{"symbol":"BTC/USD","bids":[],"asks":[{"price":64751.2,"qty":0.06391453}],"checksum":4293634279,"timestamp":"2026-07-15T03:59:43.674570Z"}]}
{"channel":"book","type":"update","data":[{"symbol":"BTC/USD","bids":[{"price":64751.1,"qty":0.07542237}],"asks":[],"checksum":2713798028,"timestamp":"2026-07-15T03:59:43.674671Z"}]}
{"channel":"book","type":"update","data":[{"symbol":"BTC/USD","bids":[{"price":64751.1,"qty":0.04802237}],"asks":[],"checksum":4293634279,"timestamp":"2026-07-15T03:59:43.674761Z"}]}
{"channel":"book","type":"update","data":[{"symbol":"BTC/USD","bids":[{"price":64751.1,"qty":0.08972237}],"asks":[],"checksum":3572268254,"timestamp":"2026-07-15T03:59:43.676228Z"}]}
{"channel":"book","type":"update","data":[{"symbol":"BTC/USD","bids":[],"asks":[{"price":64751.2,"qty":0.03651453}],"checksum":1024804577,"timestamp":"2026-07-15T03:59:43.676276Z"}]}
{"channel":"book","type":"update","data":[{"symbol":"BTC/USD","bids":[{"price":64751.1,"qty":0.04802237}],"asks":[],"checksum":370315992,"timestamp":"2026-07-15T03:59:43.676309Z"}]}
{"channel":"book","type":"update","data":[{"symbol":"BTC/USD","bids":[{"price":64751.1,"qty":0.08972237}],"asks":[],"checksum":1024804577,"timestamp":"2026-07-15T03:59:43.677617Z"}]}
{"channel":"book","type":"update","data":[{"symbol":"BTC/USD","bids":[{"price":64751.1,"qty":0.04802237}],"asks":[],"checksum":370315992,"timestamp":"2026-07-15T03:59:43.678412Z"}]}
{"channel":"book","type":"update","data":[{"symbol":"BTC/USD","bids":[{"price":64751.1,"qty":0.08972237}],"asks":[],"checksum":1024804577,"timestamp":"2026-07-15T03:59:43.678999Z"}]}
{"channel":"book","type":"update","data":[{"symbol":"BTC/USD","bids":[{"price":64751.1,"qty":0.04802237}],"asks":[],"checksum":370315992,"timestamp":"2026-07-15T03:59:43.680025Z"}]}
{"channel":"book","type":"update","data":[{"symbol":"BTC/USD","bids":[{"price":64751.1,"qty":0.08972237}],"asks":[],"checksum":1024804577,"timestamp":"2026-07-15T03:59:43.680485Z"}]}
{"channel":"book","type":"update","data":[{"symbol":"BTC/USD","bids":[{"price":64743.5,"qty":0.00000000},{"price":64741.9,"qty":0.11000000}],"asks":[],"checksum":950860069,"timestamp":"2026-07-15T03:59:43.681184Z"}]}
{"channel":"book","type":"update","data":[{"symbol":"BTC/USD","bids":[{"price":64751.1,"qty":0.04802237}],"asks":[],"checksum":329985308,"timestamp":"2026-07-15T03:59:43.681579Z"}]}
{"channel":"book","type":"update","data":[{"symbol":"BTC/USD","bids":[{"price":64751.1,"qty":0.08972237}],"asks":[],"checksum":950860069,"timestamp":"2026-07-15T03:59:43.682007Z"}]}
{"channel":"book","type":"update","data":[{"symbol":"BTC/USD","bids":[{"price":64743.6,"qty":0.00000000},{"price":64741.6,"qty":0.00154461},{"price":64743.0,"qty":0.03086388}],"asks":[],"checksum":2531828097,"timestamp":"2026-07-15T03:59:43.682488Z"}]}
{"channel":"book","type":"update","data":[{"symbol":"BTC/USD","bids":[{"price":64742.3,"qty":0.77229180}],"asks":[],"checksum":3461738879,"timestamp":"2026-07-15T03:59:43.682693Z"}]}
{"channel":"book","type":"update","data":[{"symbol":"BTC/USD","bids":[{"price":64751.1,"qty":0.04802237}],"asks":[],"checksum":3847365958,"timestamp":"2026-07-15T03:59:43.683054Z"}]}
{"channel":"book","type":"update","data":[{"symbol":"BTC/USD","bids":[{"price":64751.1,"qty":0.08972237}],"asks":[],"checksum":3461738879,"timestamp":"2026-07-15T03:59:43.683728Z"}]}
{"channel":"book","type":"update","data":[{"symbol":"BTC/USD","bids":[{"price":64751.1,"qty":0.04802237}],"asks":[],"checksum":3847365958,"timestamp":"2026-07-15T03:59:43.684660Z"}]}
{"channel":"book","type":"update","data":[{"symbol":"BTC/USD","bids":[{"price":64751.1,"qty":0.08972237}],"asks":[],"checksum":3461738879,"timestamp":"2026-07-15T03:59:43.685270Z"}]}
{"channel":"book","type":"update","data":[{"symbol":"BTC/USD","bids":[{"price":64751.1,"qty":0.04802237}],"asks":[],"checksum":3847365958,"timestamp":"2026-07-15T03:59:43.686071Z"}]}
{"channel":"book","type":"update","data":[{"symbol":"BTC/USD","bids":[{"price":64751.1,"qty":0.08972237}],"asks":[],"checksum":3461738879,"timestamp":"2026-07-15T03:59:43.686772Z"}]}
{"channel":"book","type":"update","data":[{"symbol":"BTC/USD","bids":[{"price":64751.1,"qty":0.04802237}],"asks":[],"checksum":3847365958,"timestamp":"2026-07-15T03:59:43.687498Z"}]}
{"channel":"book","type":"update","data":[{"symbol":"BTC/USD","bids":[{"price":64751.1,"qty":0.08972237}],"asks":[],"checksum":3461738879,"timestamp":"2026-07-15T03:59:43.688471Z"}]}
{"channel":"book","type":"update","data":[{"symbol":"BTC/USD","bids":[{"price":64751.1,"qty":0.04802237}],"asks":[],"checksum":3847365958,"timestamp":"2026-07-15T03:59:43.688828Z"}]}
{"channel":"book","type":"update","data":[{"symbol":"BTC/USD","bids":[{"price":64751.1,"qty":0.08972237}],"asks":[],"checksum":3461738879,"timestamp":"2026-07-15T03:59:43.690083Z"}]}
{"channel":"book","type":"update","data":[{"symbol":"BTC/USD","bids":[{"price":64751.1,"qty":0.04802237}],"asks":[],"checksum":3847365958,"timestamp":"2026-07-15T03:59:43.690180Z"}]}
{"channel":"book","type":"update","data":[{"symbol":"BTC/USD","bids":[{"price":64751.1,"qty":0.08972237}],"asks":[],"checksum":3461738879,"timestamp":"2026-07-15T03:59:43.691565Z"}]}
{"channel":"book","type":"update","data":[{"symbol":"BTC/USD","bids":[{"price":64751.1,"qty":0.04802237}],"asks":[],"checksum":3847365958,"timestamp":"2026-07-15T03:59:43.692881Z"}]}
{"channel":"book","type":"update","data":[{"symbol":"BTC/USD","bids":[{"price":64751.1,"qty":0.08972237}],"asks":[],"checksum":3461738879,"timestamp":"2026-07-15T03:59:43.693221Z"}]}
{"channel":"book","type":"update","data":[{"symbol":"BTC/USD","bids":[{"price":64751.1,"qty":0.04802237}],"asks":[],"checksum":3847365958,"timestamp":"2026-07-15T03:59:43.694447Z"}]}
{"channel":"book","type":"update","data":[{"symbol":"BTC/USD","bids":[{"price":64742.3,"qty":0.00000000},{"price":64741.9,"qty":0.11000000}],"asks":[],"checksum":3186587064,"timestamp":"2026-07-15T03:59:43.756415Z"}]}
{"channel":"book","type":"update","data":[{"symbol":"BTC/USD","bids":[{"price":64742.9,"qty":1.17228506}],"asks":[],"checksum":258956049,"timestamp":"2026-07-15T03:59:43.805063Z"}]}
{"channel":"book","type":"update","data":[{"symbol":"BTC/USD","bids":[{"price":64742.9,"qty":0.40000000}],"asks":[],"checksum":3186587064,"timestamp":"2026-07-15T03:59:43.932950Z"}]}
{"channel":"book","type":"update","data":[{"symbol":"BTC/USD","bids":[],"asks":[{"price":64751.2,"qty":0.03851413}],"checksum":882794661,"timestamp":"2026-07-15T03:59:43.934307Z"}]}
{"channel":"book","type":"update","data":[{"symbol":"BTC/USD","bids":[{"price":64742.1,"qty":0.77229450}],"asks":[],"checksum":4054885499,"timestamp":"2026-07-15T03:59:43.934729Z"}]}
{"channel":"book","type":"update","data":[{"symbol":"BTC/USD","bids":[{"price":64751.1,"qty":0.02062237}],"asks":[],"checksum":788986058,"timestamp":"2026-07-15T03:59:43.936877Z"}]}
{"channel":"book","type":"update","data":[{"symbol":"BTC/USD","bids":[],"asks":[{"price":64751.4,"qty":0.01551168}],"checksum":3850396804,"timestamp":"2026-07-15T03:59:44.045095Z"}]}
{"channel":"book","type":"update","data":[{"symbol":"BTC/USD","bids":[{"price":64742.1,"qty":0.00000000},{"price":64741.9,"qty":0.11000000}],"asks":[],"checksum":548315226,"timestamp":"2026-07-15T03:59:44.230610Z"}]}
{"channel":"book","type":"update","data":[{"symbol":"BTC/USD","bids":[{"price":64742.7,"qty":0.77228742}],"asks":[],"checksum":3681915999,"timestamp":"2026-07-15T03:59:44.232539Z"}]}
{"channel":"heartbeat"}
{"channel":"book","type":"update","data":[{"symbol":"BTC/USD","bids":[],"asks":[{"price":64751.4,"qty":0.01358122}],"checksum":301139985,"timestamp":"2026-07-15T03:59:44.702412Z"}]}
{"channel":"heartbeat"}
{"channel":"book","type":"update","data":[{"symbol":"BTC/USD","bids":[],"asks":[{"price":64751.2,"qty":0.09671413}],"checksum":3866669561,"timestamp":"2026-07-15T03:59:45.292955Z"}]}
{"channel":"book","type":"update","data":[{"symbol":"BTC/USD","bids":[],"asks":[{"price":64751.2,"qty":0.12411413}],"checksum":489051108,"timestamp":"2026-07-15T03:59:45.294754Z"}]}
{"channel":"book","type":"update","data":[{"symbol":"BTC/USD","bids":[{"price":64742.7,"qty":0.00000000},{"price":64741.9,"qty":0.11000000}],"asks":[],"checksum":3875366881,"timestamp":"2026-07-15T03:59:45.295082Z"}]}
{"channel":"book","type":"update","data":[{"symbol":"BTC/USD","bids":[{"price":64741.9,"qty":0.88229723}],"asks":[],"checksum":2287640901,"timestamp":"2026-07-15T03:59:45.299235Z"}]}
{"channel":"book","type":"update","data":[{"symbol":"BTC/USD","bids":[],"asks":[{"price":64751.2,"qty":0.13121521}],"checksum":690916599,"timestamp":"2026-07-15T03:59:45.299333Z"}]}
{"channel":"book","type":"update","data":[{"symbol":"BTC/USD","bids":[{"price":64741.9,"qty":0.11000000}],"asks":[],"checksum":1200179795,"timestamp":"2026-07-15T03:59:45.299986Z"}]}
{"channel":"book","type":"update","data":[{"symbol":"BTC/USD","bids":[],"asks":[{"price":64753.5,"qty":0.00000000},{"price":64755.0,"qty":0.77214183}],"checksum":3032837444,"timestamp":"2026-07-15T03:59:45.354783Z"}]}
{"channel":"book","type":"update","data":[{"symbol":"BTC/USD","bids":[],"asks":[{"price":64751.2,"qty":0.16865952}],"checksum":1765540489,"timestamp":"2026-07-15T03:59:45.354940Z"}]}
{"channel":"book","type":"update","data":[{"symbol":"BTC/USD","bids":[{"price":64742.8,"qty":0.03089146}],"asks":[],"checksum":3869613937,"timestamp":"2026-07-15T03:59:45.382863Z"}]}
{"channel":"book","type":"update","data":[{"symbol":"BTC/USD","bids":[],"asks":[{"price":64751.2,"qty":0.11045952}],"checksum":1040674809,"timestamp":"2026-07-15T03:59:45.736851Z"}]}
{"channel":"book","type":"update","data":[{"symbol":"BTC/USD","bids":[],"asks":[{"price":64751.2,"qty":0.11238998}],"checksum":3543281662,"timestamp":"2026-07-15T03:59:46.076769Z"}]}
{"channel":"book","type":"update","data":[{"symbol":"BTC/USD","bids":[],"asks":[{"price":64751.2,"qty":0.10528890}],"checksum":4023599363,"timestamp":"2026-07-15T03:59:46.248972Z"}]}
{"channel":"heartbeat"}
{"channel":"book","type":"update","data":[{"symbol":"BTC/USD","bids":[],"asks":[{"price":64751.2,"qty":0.11238998}],"checksum":3543281662,"timestamp":"2026-07-15T03:59:46.312377Z"}]}
{"channel":"book","type":"update","data":[{"symbol":"BTC/USD","bids":[],"asks":[{"price":64751.2,"qty":0.10528890}],"checksum":4023599363,"timestamp":"2026-07-15T03:59:46.315170Z"}]}
{"channel":"book","type":"update","data":[{"symbol":"BTC/USD","bids":[{"price":64743.0,"qty":0.00000000},{"price":64741.8,"qty":0.77229744},{"price":64744.2,"qty":0.03116082}],"asks":[],"checksum":3502299882,"timestamp":"2026-07-15T03:59:47.165635Z"}]}
{"channel":"heartbeat"}
{"channel":"heartbeat"}
{"channel":"book","type":"update","data":[{"symbol":"BTC/USD","bids":[{"price":64741.8,"qty":0.00000000},{"price":64741.4,"qty":0.03770924}],"asks":[],"checksum":332984085,"timestamp":"2026-07-15T03:59:48.895038Z"}]}
{"channel":"book","type":"update","data":[{"symbol":"BTC/USD","bids":[{"price":64742.0,"qty":0.77229590}],"asks":[],"checksum":1727958323,"timestamp":"2026-07-15T03:59:49.059978Z"}]}
{"channel":"book","type":"update","data":[{"symbol":"BTC/USD","bids":[],"asks":[{"price":64751.2,"qty":0.16348890}],"checksum":2177320875,"timestamp":"2026-07-15T03:59:49.179993Z"}]}
{"channel":"book","type":"update","data":[{"symbol":"BTC/USD","bids":[{"price":64741.9,"qty":0.00000000},{"price":64741.4,"qty":0.03770924}],"asks":[],"checksum":609398819,"timestamp":"2026-07-15T03:59:49.180206Z"}]}
{"channel":"trade","type":"update","data":[{"symbol":"BTC/USD","side":"sell","price":64751.1,"qty":0.00054693,"ord_type":"limit","trade_id":103746757,"timestamp":"2026-07-15T03:59:49.182343Z"},{"symbol":"BTC/USD","side":"sell","price":64751.1,"qty":0.00700000,"ord_type":"limit","trade_id":103746758,"timestamp":"2026-07-15T03:59:49.182343Z"},{"symbol":"BTC/USD","side":"sell","price":64751.1,"qty":0.00007544,"ord_type":"limit","trade_id":103746759,"timestamp":"2026-07-15T03:59:49.182343Z"},{"symbol":"BTC/USD","side":"sell","price":64751.1,"qty":0.01299963,"ord_type":"limit","trade_id":103746760,"timestamp":"2026-07-15T03:59:49.182343Z"}]}
{"channel":"book","type":"update","data":[{"symbol":"BTC/USD","bids":[{"price":64751.1,"qty":0.02007544},{"price":64751.1,"qty":0.01307544},{"price":64751.1,"qty":0.01300000},{"price":64751.1,"qty":0.00000037}],"asks":[],"checksum":3056827993,"timestamp":"2026-07-15T03:59:49.182343Z"}]}
{"channel":"book","type":"update","data":[{"symbol":"BTC/USD","bids":[{"price":64742.0,"qty":0.00000000},{"price":64741.2,"qty":0.51899622}],"asks":[],"checksum":2533732755,"timestamp":"2026-07-15T03:59:49.184844Z"}]}
{"channel":"book","type":"update","data":[{"symbol":"BTC/USD","bids":[{"price":64751.1,"qty":0.00077256}],"asks":[],"checksum":610191425,"timestamp":"2026-07-15T03:59:49.194547Z"}]}
{"channel":"heartbeat"}
{"channel":"book","type":"update","data":[{"symbol":"BTC/USD","bids":[{"price":64751.1,"qty":0.00084417}],"asks":[],"checksum":1791831731,"timestamp":"2026-07-15T03:59:49.422953Z"}]}
{"channel":"book","type":"update","data":[{"symbol":"BTC/USD","bids":[{"price":64741.8,"qty":0.77229782}],"asks":[],"checksum":1533592674,"timestamp":"2026-07-15T03:59:49.441703Z"}]}
{"channel":"book","type":"update","data":[{"symbol":"BTC/USD","bids":[{"price":64746.4,"qty":0.00154448}],"asks":[],"checksum":440764539,"timestamp":"2026-07-15T03:59:49.733879Z"}]}
{"channel":"book","type":"update","data":[{"symbol":"BTC/USD","bids":[{"price":64741.8,"qty":0.00000000},{"price":64741.4,"qty":0.03770924}],"asks":[],"checksum":637450441,"timestamp":"2026-07-15T03:59:49.772531Z"}]}
{"channel":"book","type":"update","data":[{"symbol":"BTC/USD","bids":[{"price":64742.7,"qty":0.77228724}],"asks":[],"checksum":2247874163,"timestamp":"2026-07-15T03:59:49.774196Z"}]}
{"channel":"book","type":"update","data":[{"symbol":"BTC/USD","bids":[{"price":64742.7,"qty":0.00000000},{"price":64741.4,"qty":0.03770924}],"asks":[],"checksum":637450441,"timestamp":"2026-07-15T03:59:49.825993Z"}]}
{"channel":"book","type":"update","data":[{"symbol":"BTC/USD","bids":[{"price":64751.1,"qty":0.00084380}],"asks":[],"checksum":2720601894,"timestamp":"2026-07-15T03:59:49.828453Z"}]}
{"channel":"book","type":"update","data":[{"symbol":"BTC/USD","bids":[{"price":64746.5,"qty":0.01000000}],"asks":[],"checksum":3665150642,"timestamp":"2026-07-15T03:59:49.831516Z"}]}
{"channel":"book","type":"update","data":[{"symbol":"BTC/USD","bids":[{"price":64746.5,"qty":0.00000000},{"price":64741.4,"qty":0.03770924}],"asks":[],"checksum":2720601894,"timestamp":"2026-07-15T03:59:49.929404Z"}]}
{"channel":"book","type":"update","data":[{"symbol":"BTC/USD","bids":[],"asks":[{"price":64751.2,"qty":0.17058998}],"checksum":1856124919,"timestamp":"2026-07-15T03:59:50.211524Z"}]}
{"channel":"book","type":"update","data":[{"symbol":"BTC/USD","bids":[{"price":64746.4,"qty":0.00000000},{"price":64741.2,"qty":0.00005100}],"asks":[],"checksum":935184550,"timestamp":"2026-07-15T03:59:50.217570Z"}]}
{"channel":"book","type":"update","data":[{"symbol":"BTC/USD","bids":[{"price":64744.2,"qty":0.00029694}],"asks":[],"checksum":2321492962,"timestamp":"2026-07-15T03:59:50.257102Z"}]}
{"channel":"book","type":"update","data":[{"symbol":"BTC/USD","bids":[{"price":64746.3,"qty":0.00000000},{"price":64740.4,"qty":0.25816900}],"asks":[],"checksum":1167987087,"timestamp":"2026-07-15T03:59:50.258082Z"}]}
{"channel":"book","type":"update","data":[{"symbol":"BTC/USD","bids":[{"price":64741.4,"qty":0.00000000},{"price":64739.9,"qty":1.72880400}],"asks":[],"checksum":2043700799,"timestamp":"2026-07-15T03:59:50.260696Z"}]}
{"channel":"heartbeat"}
{"channel":"book","type":"update","data":[{"symbol":"BTC/USD","bids":[{"price":64740.4,"qty":0.00000000},{"price":64738.2,"qty":0.03086388}],"asks":[],"checksum":3580189416,"timestamp":"2026-07-15T03:59:50.276553Z"}]}
{"channel":"book","type":"update","data":[{"symbol":"BTC/USD","bids":[{"price":64742.8,"qty":0.01544573}],"asks":[],"checksum":2341061005,"timestamp":"2026-07-15T03:59:50.285534Z"}]}
{"channel":"book","type":"update","data":[{"symbol":"BTC/USD","bids":[{"price":64742.8,"qty":0.00000000},{"price":64738.1,"qty":0.10000000}],"asks":[],"checksum":3922306353,"timestamp":"2026-07-15T03:59:50.287167Z"}]}
{"channel":"book","type":"update","data":[{"symbol":"BTC/USD","bids":[],"asks":[{"price":64751.2,"qty":0.28058998}],"checksum":2193747915,"timestamp":"2026-07-15T03:59:50.288722Z"}]}
{"channel":"book","type":"update","data":[{"symbol":"BTC/USD","bids":[],"asks":[{"price":64751.2,"qty":0.27865952}],"checksum":732017144,"timestamp":"2026-07-15T03:59:50.301567Z"}]}
{"channel":"book","type":"update","data":[{"symbol":"BTC/USD","bids":[{"price":64738.2,"qty":0.00000000},{"price":64734.8,"qty":0.00154400}],"asks":[],"checksum":3321995401,"timestamp":"2026-07-15T03:59:50.334821Z"}]}
{"channel":"book","type":"update","data":[{"symbol":"BTC/USD","bids":[{"price":64742.9,"qty":0.00000000},{"price":64734.6,"qty":0.11000000}],"asks":[],"checksum":3620386810,"timestamp":"2026-07-15T03:59:50.378835Z"}]}
{"channel":"book","type":"update","data":[{"symbol":"BTC/USD","bids":[],"asks":[{"price":64751.2,"qty":0.57865952}],"checksum":456257971,"timestamp":"2026-07-15T03:59:50.411718Z"}]}
{"channel":"book","type":"update","data":[{"symbol":"BTC/USD","bids":[],"asks":[{"price":64751.2,"qty":0.87865952}],"checksum":678399525,"timestamp":"2026-07-15T03:59:50.411987Z"}]}
{"channel":"book","type":"update","data":[{"symbol":"BTC/USD","bids":[{"price":64751.0,"qty":0.00306034}],"asks":[],"checksum":1608838226,"timestamp":"2026-07-15T03:59:50.427848Z"}]}
{"channel":"book","type":"update","data":[{"symbol":"BTC/USD","bids":[{"price":64740.0,"qty":0.01200000}],"asks":[],"checksum":856939130,"timestamp":"2026-07-15T03:59:50.433691Z"}]}
{"channel":"heartbeat"}
{"channel":"book","type":"update","data":[{"symbol":"BTC/USD","bids":[{"price":64739.9,"qty":0.00000000},{"price":64735.1,"qty":0.51894522}],"asks":[],"checksum":958785479,"timestamp":"2026-07-15T03:59:52.033176Z"}]}
{"channel":"book","type":"update","data":[{"symbol":"BTC/USD","bids":[],"asks":[{"price":64754.2,"qty":0.06030142}],"checksum":326976302,"timestamp":"2026-07-15T03:59:52.036431Z"}]}
{"channel":"book","type":"update","data":[{"symbol":"BTC/USD","bids":[{"price":64751.0,"qty":0.00000000},{"price":64734.8,"qty":0.00154400}],"asks":[],"checksum":3865651276,"timestamp":"2026-07-15T03:59:52.049342Z"}]}
{"channel":"book","type":"update","data":[{"symbol":"BTC/USD","bids":[{"price":64735.1,"qty":0.00000000},{"price":64734.3,"qty":0.77238797}],"asks":[],"checksum":2480432621,"timestamp":"2026-07-15T03:59:52.057961Z"}]}
{"channel":"book","type":"update","data":[{"symbol":"BTC/USD","bids":[{"price":64734.3,"qty":0.00000000},{"price":64734.2,"qty":0.40000000}],"asks":[],"checksum":1253999512,"timestamp":"2026-07-15T03:59:52.067910Z"}]}
{"channel":"book","type":"update","data":[{"symbol":"BTC/USD","bids":[{"price":64740.0,"qty":0.00000000},{"price":64727.9,"qty":0.05820000}],"asks":[],"checksum":3201143383,"timestamp":"2026-07-15T03:59:52.217535Z"}]}
{"channel":"book","type":"update","data":[{"symbol":"BTC/USD","bids":[{"price":64751.1,"qty":0.00077219}],"asks":[],"checksum":495286997,"timestamp":"2026-07-15T03:59:52.246386Z"}]}
{"channel":"heartbeat"}
{"channel":"book","type":"update","data":[{"symbol":"BTC/USD","bids":[{"price":64728.1,"qty":0.77246174}],"asks":[],"checksum":1707357172,"timestamp":"2026-07-15T03:59:52.282079Z"}]}
{"channel":"book","type":"update","data":[{"symbol":"BTC/USD","bids":[],"asks":[{"price":64754.1,"qty":3.67656284}],"checksum":3451683525,"timestamp":"2026-07-15T03:59:52.292587Z"}]}
{"channel":"book","type":"update","data":[{"symbol":"BTC/USD","bids":[],"asks":[{"price":64751.2,"qty":1.71078381}],"checksum":3594043273,"timestamp":"2026-07-15T03:59:52.303632Z"}]}
{"channel":"book","type":"update","data":[{"symbol":"BTC/USD","bids":[],"asks":[{"price":64751.4,"qty":0.00000000},{"price":64754.2,"qty":0.06030142}],"checksum":1170822661,"timestamp":"2026-07-15T03:59:52.309397Z"}]}
{"channel":"book","type":"update","data":[{"symbol":"BTC/USD","bids":[],"asks":[{"price":64751.2,"qty":0.87865952}],"checksum":1582132041,"timestamp":"2026-07-15T03:59:52.309542Z"}]}
{"channel":"book","type":"update","data":[{"symbol":"BTC/USD","bids":[],"asks":[{"price":64751.5,"qty":1.99468961}],"checksum":1431035265,"timestamp":"2026-07-15T03:59:52.309984Z"}]}
{"channel":"book","type":"update","data":[{"symbol":"BTC/USD","bids":[{"price":64728.1,"qty":0.00000000},{"price":64727.9,"qty":0.05820000}],"asks":[],"checksum":664069690,"timestamp":"2026-07-15T03:59:52.327716Z"}]}
{"channel":"book","type":"update","data":[{"symbol":"BTC/USD","bids":[],"asks":[{"price":64754.1,"qty":0.00000000},{"price":64755.0,"qty":0.77214183},{"price":64754.9,"qty":3.67652720}],"checksum":2644905157,"timestamp":"2026-07-15T03:59:52.362056Z"}]}
{"channel":"book","type":"update","data":[{"symbol":"BTC/USD","bids":[{"price":64729.3,"qty":0.77244748}],"asks":[],"checksum":903407759,"timestamp":"2026-07-15T03:59:52.380815Z"}]}
{"channel":"book","type":"update","data":[{"symbol":"BTC/USD","bids":[{"price":64751.1,"qty":0.00083837}],"asks":[],"checksum":191548047,"timestamp":"2026-07-15T03:59:52.490303Z"}]}
{"channel":"book","type":"update","data":[{"symbol":"BTC/USD","bids":[],"asks":[{"price":64751.2,"qty":1.00975354}],"checksum":2402016443,"timestamp":"2026-07-15T03:59:52.493065Z"}]}
{"channel":"book","type":"update","data":[{"symbol":"BTC/USD","bids":[{"price":64729.3,"qty":0.00000000},{"price":64727.9,"qty":0.05820000}],"asks":[],"checksum":3198434609,"timestamp":"2026-07-15T03:59:52.493364Z"}]}
{"channel":"book","type":"update","data":[{"symbol":"BTC/USD","bids":[{"price":64730.0,"qty":0.77243894}],"asks":[],"checksum":2712557974,"timestamp":"2026-07-15T03:59:52.497027Z"}]}
{"channel":"book","type":"update","data":[{"symbol":"BTC/USD","bids":[],"asks":[{"price":64754.9,"qty":3.78328270}],"checksum":3543120902,"timestamp":"2026-07-15T03:59:52.497329Z"}]}
{"channel":"book","type":"update","data":[{"symbol":"BTC/USD","bids":[],"asks":[{"price":64754.2,"qty":0.00000000},{"price":64755.0,"qty":0.77214183}],"checksum":4036519414,"timestamp":"2026-07-15T03:59:52.582039Z"}]}
{"channel":"book","type":"update","data":[{"symbol":"BTC/USD","bids":[{"price":64738.2,"qty":0.01000000}],"asks":[],"checksum":2911482906,"timestamp":"2026-07-15T03:59:52.722658Z"}]}
{"channel":"book","type":"update","data":[{"symbol":"BTC/USD","bids":[],"asks":[{"price":64754.9,"qty":3.67652720}],"checksum":755104981,"timestamp":"2026-07-15T03:59:52.788835Z"}]}
{"channel":"trade","type":"update","data":[{"symbol":"BTC/USD","side":"sell","price":64751.1,"qty":0.00077219,"ord_type":"market","trade_id":103746761,"timestamp":"2026-07-15T03:59:52.991425Z"},{"symbol":"BTC/USD","side":"sell","price":64751.1,"qty":0.00006618,"ord_type":"market","trade_id":103746762,"timestamp":"2026-07-15T03:59:52.991425Z"},{"symbol":"BTC/USD","side":"sell","price":64750.9,"qty":0.00005100,"ord_type":"market","trade_id":103746763,"timestamp":"2026-07-15T03:59:52.991425Z"},{"symbol":"BTC/USD","side":"sell","price":64747.7,"qty":0.00005100,"ord_type":"market","trade_id":103746764,"timestamp":"2026-07-15T03:59:52.991425Z"},{"symbol":"BTC/USD","side":"sell","price":64744.4,"qty":0.00005100,"ord_type":"market","trade_id":103746765,"timestamp":"2026-07-15T03:59:52.991425Z"},{"symbol":"BTC/USD","side":"sell","price":64744.2,"qty":0.00029694,"ord_type":"market","trade_id":103746766,"timestamp":"2026-07-15T03:59:52.991425Z"},{"symbol":"BTC/USD","side":"sell","price":64741.2,"qty":0.00005100,"ord_type":"market","trade_id":103746767,"timestamp":"2026-07-15T03:59:52.991425Z"}]}
{"channel":"book","type":"update","data":[{"symbol":"BTC/USD","bids":[{"price":64751.1,"qty":0.00006618},{"price":64751.1,"qty":0.00000000},{"price":64730.6,"qty":0.51894522},{"price":64750.9,"qty":0.00000000},{"price":64730.0,"qty":0.77243894},{"price":64747.7,"qty":0.00000000},{"price":64727.9,"qty":0.05820000},{"price":64744.4,"qty":0.00000000},{"price":64727.3,"qty":0.24147767},{"price":64744.2,"qty":0.00000000},{"price":64727.2,"qty":0.77247275},{"price":64741.2,"qty":0.00000000},{"price":64726.6,"qty":0.03649768}],"asks":[],"checksum":3145588423,"timestamp":"2026-07-15T03:59:52.991425Z"}]}
{"channel":"book","type":"update","data":[{"symbol":"BTC/USD","bids":[],"asks":[{"price":64744.8,"qty":0.05820000}],"checksum":1169211062,"timestamp":"2026-07-15T03:59:52.993060Z"}]}
{"channel":"book","type":"update","data":[{"symbol":"BTC/USD","bids":[],"asks":[{"price":64751.5,"qty":1.21278288}],"checksum":3986444692,"timestamp":"2026-07-15T03:59:52.993242Z"}]}
{"channel":"book","type":"update","data":[{"symbol":"BTC/USD","bids":[],"asks":[{"price":64751.2,"qty":0.97230923}],"checksum":230349388,"timestamp":"2026-07-15T03:59:52.993332Z"}]}
{"channel":"book","type":"update","data":[{"symbol":"BTC/USD","bids":[],"asks":[{"price":64751.4,"qty":0.00772185}],"checksum":2288996082,"timestamp":"2026-07-15T03:59:52.993358Z"}]}
{"channel":"book","type":"update","data":[{"symbol":"BTC/USD","bids":[],"asks":[{"price":64751.2,"qty":0.94144698},{"price":64751.1,"qty":0.03086388}],"checksum":1441779654,"timestamp":"2026-07-15T03:59:52.993581Z"}]}
{"channel":"book","type":"update","data":[{"symbol":"BTC/USD","bids":[],"asks":[{"price":64751.6,"qty":0.00000000},{"price":64754.0,"qty":0.00005100}],"checksum":3091268232,"timestamp":"2026-07-15T03:59:52.993609Z"}]}
{"channel":"book","type":"update","data":[{"symbol":"BTC/USD","bids":[],"asks":[{"price":64751.5,"qty":0.00000000},{"price":64754.9,"qty":3.67652720}],"checksum":2339922526,"timestamp":"2026-07-15T03:59:52.993641Z"}]}
{"channel":"book","type":"update","data":[{"symbol":"BTC/USD","bids":[],"asks":[{"price":64751.1,"qty":0.16195790}],"checksum":1385626961,"timestamp":"2026-07-15T03:59:52.993652Z"}]}
{"channel":"book","type":"update","data":[{"symbol":"BTC/USD","bids":[],"asks":[{"price":64752.4,"qty":0.00000000},{"price":64755.0,"qty":0.77214183}],"checksum":2104421439,"timestamp":"2026-07-15T03:59:52.993765Z"}]}
{"channel":"book","type":"update","data":[{"symbol":"BTC/USD","bids":[],"asks":[{"price":64751.1,"qty":0.19940221}],"checksum":1071090274,"timestamp":"2026-07-15T03:59:52.993870Z"}]}
{"channel":"book","type":"update","data":[{"symbol":"BTC/USD","bids":[],"asks":[{"price":64753.0,"qty":0.00000000},{"price":64756.8,"qty":0.10675550}],"checksum":1324502610,"timestamp":"2026-07-15T03:59:52.993894Z"}]}
{"channel":"book","type":"update","data":[{"symbol":"BTC/USD","bids":[],"asks":[{"price":64751.1,"qty":0.30940221}],"checksum":3478973919,"timestamp":"2026-07-15T03:59:52.993904Z"}]}
{"channel":"book","type":"update","data":[{"symbol":"BTC/USD","bids":[],"asks":[{"price":64755.0,"qty":0.00000000},{"price":64756.9,"qty":0.56803500}],"checksum":4152617293,"timestamp":"2026-07-15T03:59:52.993962Z"}]}
{"channel":"book","type":"update","data":[{"symbol":"BTC/USD","bids":[],"asks":[{"price":64751.2,"qty":0.91404698}],"checksum":1001363363,"timestamp":"2026-07-15T03:59:52.993971Z"}]}
{"channel":"book","type":"update","data":[{"symbol":"BTC/USD","bids":[{"price":64738.3,"qty":0.00029697}],"asks":[],"checksum":3207675507,"timestamp":"2026-07-15T03:59:52.994170Z"}]}
{"channel":"book","type":"update","data":[{"symbol":"BTC/USD","bids":[],"asks":[{"price":64744.7,"qty":0.03911676}],"checksum":3998664858,"timestamp":"2026-07-15T03:59:52.994446Z"}]}
{"channel":"book","type":"update","data":[{"symbol":"BTC/USD","bids":[],"asks":[{"price":64751.1,"qty":0.27195790}],"checksum":56019105,"timestamp":"2026-07-15T03:59:52.994600Z"}]}
{"channel":"book","type":"update","data":[{"symbol":"BTC/USD","bids":[],"asks":[{"price":64751.1,"qty":0.14086388}],"checksum":1416048340,"timestamp":"2026-07-15T03:59:52.994607Z"}]}
{"channel":"book","type":"update","data":[{"symbol":"BTC/USD","bids":[],"asks":[{"price":64752.9,"qty":1.95843418}],"checksum":89703988,"timestamp":"2026-07-15T03:59:52.995164Z"}]}
{"channel":"book","type":"update","data":[{"symbol":"BTC/USD","bids":[],"asks":[{"price":64752.9,"qty":0.40000000}],"checksum":1416048340,"timestamp":"2026-07-15T03:59:52.995414Z"}]}
{"channel":"book","type":"update","data":[{"symbol":"BTC/USD","bids":[],"asks":[{"price":64751.1,"qty":0.14796496}],"checksum":331088933,"timestamp":"2026-07-15T03:59:52.995778Z"}]}
{"channel":"book","type":"update","data":[{"symbol":"BTC/USD","bids":[],"asks":[{"price":64740.7,"qty":0.05820000}],"checksum":3798653622,"timestamp":"2026-07-15T03:59:52.995797Z"}]}
{"channel":"book","type":"update","data":[{"symbol":"BTC/USD","bids":[],"asks":[{"price":64751.2,"qty":0.61404698}],"checksum":3103178525,"timestamp":"2026-07-15T03:59:52.995843Z"}]}
{"channel":"book","type":"update","data":[{"symbol":"BTC/USD","bids":[],"asks":[{"price":64740.7,"qty":0.57714522}],"checksum":135183971,"timestamp":"2026-07-15T03:59:52.995867Z"}]}
{"channel":"book","type":"update","data":[{"symbol":"BTC/USD","bids":[],"asks":[{"price":64751.1,"qty":0.14989542}],"checksum":2229546249,"timestamp":"2026-07-15T03:59:52.995962Z"}]}
{"channel":"book","type":"update","data":[{"symbol":"BTC/USD","bids":[],"asks":[{"price":64751.2,"qty":0.60694590}],"checksum":1125989378,"timestamp":"2026-07-15T03:59:52.996171Z"}]}
{"channel":"book","type":"update","data":[{"symbol":"BTC/USD","bids":[],"asks":[{"price":64738.4,"qty":0.77233913}],"checksum":3800449953,"timestamp":"2026-07-15T03:59:52.996221Z"}]}
{"channel":"book","type":"update","data":[{"symbol":"BTC/USD","bids":[],"asks":[{"price":64751.2,"qty":0.30694590}],"checksum":3321564735,"timestamp":"2026-07-15T03:59:52.996340Z"}]}
{"channel":"book","type":"update","data":[{"symbol":"BTC/USD","bids":[],"asks":[{"price":64751.1,"qty":0.43845182}],"checksum":550499039,"timestamp":"2026-07-15T03:59:52.996387Z"}]}
{"channel":"book","type":"update","data":[{"symbol":"BTC/USD","bids":[],"asks":[{"price":64740.5,"qty":0.77231431}],"checksum":1692734212,"timestamp":"2026-07-15T03:59:52.996573Z"}]}
{"channel":"book","type":"update","data":[{"symbol":"BTC/USD","bids":[],"asks":[{"price":64751.1,"qty":0.98376815}],"checksum":279330528,"timestamp":"2026-07-15T03:59:52.996649Z"}]}
{"channel":"book","type":"update","data":[{"symbol":"BTC/USD","bids":[],"asks":[{"price":64751.1,"qty":0.43845182}],"checksum":1692734212,"timestamp":"2026-07-15T03:59:52.996806Z"}]}
{"channel":"book","type":"update","data":[{"symbol":"BTC/USD","bids":[],"asks":[{"price":64745.0,"qty":0.77226134}],"checksum":3716698699,"timestamp":"2026-07-15T03:59:52.997028Z"}]}
{"channel":"book","type":"update","data":[{"symbol":"BTC/USD","bids":[],"asks":[{"price":64744.7,"qty":0.00000000},{"price":64752.9,"qty":0.40000000}],"checksum":2947430591,"timestamp":"2026-07-15T03:59:52.997244Z"}]}
{"channel":"book","type":"update","data":[{"symbol":"BTC/USD","bids":[],"asks":[{"price":64740.7,"qty":0.51894522}],"checksum":1755546605,"timestamp":"2026-07-15T03:59:52.997295Z"}]}
{"channel":"book","type":"update","data":[{"symbol":"BTC/USD","bids":[],"asks":[{"price":64751.1,"qty":0.14989542}],"checksum":1084114656,"timestamp":"2026-07-15T03:59:52.997303Z"}]}
{"channel":"book","type":"update","data":[{"symbol":"BTC/USD","bids":[],"asks":[{"price":64740.6,"qty":0.03911676}],"checksum":2189415251,"timestamp":"2026-07-15T03:59:52.997322Z"}]}
{"channel":"book","type":"update","data":[{"symbol":"BTC/USD","bids":[],"asks":[{"price":64744.6,"qty":0.02904905}],"checksum":2427852545,"timestamp":"2026-07-15T03:59:52.997516Z"}]}
{"channel":"book","type":"update","data":[{"symbol":"BTC/USD","bids":[],"asks":[{"price":64740.5,"qty":0.83051431}],"checksum":1568581063,"timestamp":"2026-07-15T03:59:52.997598Z"}]}
{"channel":"book","type":"update","data":[{"symbol":"BTC/USD","bids":[],"asks":[{"price":64751.4,"qty":0.00000000},{"price":64751.9,"qty":0.04491928}],"checksum":3531150895,"timestamp":"2026-07-15T03:59:52.997655Z"}]}
{"channel":"book","type":"update","data":[{"symbol":"BTC/USD","bids":[],"asks":[{"price":64740.5,"qty":0.05820000}],"checksum":2966259326,"timestamp":"2026-07-15T03:59:52.997668Z"}]}
{"channel":"book","type":"update","data":[{"symbol":"BTC/USD","bids":[],"asks":[{"price":64751.1,"qty":0.14796496}],"checksum":2270952855,"timestamp":"2026-07-15T03:59:52.997898Z"}]}
{"channel":"book","type":"update","data":[{"symbol":"BTC/USD","bids":[],"asks":[{"price":64740.4,"qty":0.40281367}],"checksum":2456783314,"timestamp":"2026-07-15T03:59:52.998395Z"}]}
{"channel":"book","type":"update","data":[{"symbol":"BTC/USD","bids":[],"asks":[{"price":64744.6,"qty":0.24417885}],"checksum":3643421285,"timestamp":"2026-07-15T03:59:52.998653Z"}]}
{"channel":"book","type":"update","data":[{"symbol":"BTC/USD","bids":[],"asks":[{"price":64744.6,"qty":0.25128036}],"checksum":2434822449,"timestamp":"2026-07-15T03:59:52.998857Z"}]}
{"channel":"book","type":"update","data":[{"symbol":"BTC/USD","bids":[],"asks":[{"price":64751.1,"qty":0.14086388}],"checksum":1873219028,"timestamp":"2026-07-15T03:59:52.999039Z"}]}
{"channel":"book","type":"update","data":[{"symbol":"BTC/USD","bids":[],"asks":[{"price":64740.4,"qty":0.00000000},{"price":64751.9,"qty":0.04491928}],"checksum":779062128,"timestamp":"2026-07-15T03:59:52.999866Z"}]}
{"channel":"book","type":"update","data":[{"symbol":"BTC/USD","bids":[],"asks":[{"price":64751.2,"qty":0.30540152}],"checksum":1943122220,"timestamp":"2026-07-15T03:59:53.000328Z"}]}
{"channel":"book","type":"update","data":[{"symbol":"BTC/USD","bids":[],"asks":[{"price":64740.6,"qty":0.04104754}],"checksum":3702236763,"timestamp":"2026-07-15T03:59:53.000497Z"}]}
{"channel":"book","type":"update","data":[{"symbol":"BTC/USD","bids":[{"price":64738.2,"qty":0.00000000},{"price":64726.6,"qty":0.03649768}],"asks":[],"checksum":3919365774,"timestamp":"2026-07-15T03:59:53.000542Z"}]}
{"channel":"book","type":"update","data":[{"symbol":"BTC/USD","bids":[],"asks":[{"price":64738.4,"qty":0.77388381}],"checksum":3502352907,"timestamp":"2026-07-15T03:59:53.000759Z"}]}
{"channel":"book","type":"update","data":[{"symbol":"BTC/USD","bids":[{"price":64732.9,"qty":1.72882300}],"asks":[],"checksum":2668439639,"timestamp":"2026-07-15T03:59:53.001126Z"}]}
{"channel":"book","type":"update","data":[{"symbol":"BTC/USD","bids":[],"asks":[{"price":64744.6,"qty":0.24417885}],"checksum":2852183044,"timestamp":"2026-07-15T03:59:53.001463Z"}]}
{"channel":"book","type":"update","data":[{"symbol":"BTC/USD","bids":[],"asks":[{"price":64740.6,"qty":0.19595269}],"checksum":3168187458,"timestamp":"2026-07-15T03:59:53.001478Z"}]}
{"channel":"book","type":"update","data":[{"symbol":"BTC/USD","bids":[],"asks":[{"price":64738.4,"qty":0.78098572}],"checksum":1333189259,"timestamp":"2026-07-15T03:59:53.002365Z"}]}
{"channel":"book","type":"update","data":[{"symbol":"BTC/USD","bids":[],"asks":[{"price":64740.6,"qty":0.19402191}],"checksum":600390877,"timestamp":"2026-07-15T03:59:53.002424Z"}]}
{"channel":"book","type":"update","data":[{"symbol":"BTC/USD","bids":[{"price":64738.3,"qty":0.00000000},{"price":64726.6,"qty":0.03649768},{"price":64738.2,"qty":0.00029697}],"asks":[],"checksum":443903105,"timestamp":"2026-07-15T03:59:53.002838Z"}]}
{"channel":"book","type":"update","data":[{"symbol":"BTC/USD","bids":[],"asks":[{"price":64744.8,"qty":0.45820000}],"checksum":2399016528,"timestamp":"2026-07-15T03:59:53.003367Z"}]}
{"channel":"book","type":"update","data":[{"symbol":"BTC/USD","bids":[],"asks":[{"price":64744.6,"qty":0.21512980}],"checksum":3204375175,"timestamp":"2026-07-15T03:59:53.004593Z"}]}
{"channel":"book","type":"update","data":[{"symbol":"BTC/USD","bids":[],"asks":[{"price":64744.6,"qty":0.00000000},{"price":64753.1,"qty":2.31649496}],"checksum":534216761,"timestamp":"2026-07-15T03:59:53.004683Z"}]}
{"channel":"book","type":"update","data":[{"symbol":"BTC/USD","bids":[],"asks":[{"price":64738.4,"qty":0.80838572}],"checksum":1254258015,"timestamp":"2026-07-15T03:59:53.004851Z"}]}
{"channel":"book","type":"update","data":[{"symbol":"BTC/USD","bids":[],"asks":[{"price":64738.3,"qty":0.02740000}],"checksum":2788377571,"timestamp":"2026-07-15T03:59:53.005082Z"}]}
{"channel":"book","type":"update","data":[{"symbol":"BTC/USD","bids":[],"asks":[{"price":64744.7,"qty":0.36729271}],"checksum":2600761828,"timestamp":"2026-07-15T03:59:53.005792Z"}]}
{"channel":"book","type":"update","data":[{"symbol":"BTC/USD","bids":[],"asks":[{"price":64738.3,"qty":0.03450192}],"checksum":428626959,"timestamp":"2026-07-15T03:59:53.006109Z"}]}
{"channel":"book","type":"update","data":[{"symbol":"BTC/USD","bids":[],"asks":[{"price":64738.4,"qty":0.78098572}],"checksum":2208477971,"timestamp":"2026-07-15T03:59:53.006268Z"}]}
{"channel":"book","type":"update","data":[{"symbol":"BTC/USD","bids":[],"asks":[{"price":64738.4,"qty":0.77388381}],"checksum":3724052646,"timestamp":"2026-07-15T03:59:53.006287Z"}]}
{"channel":"book","type":"update","data":[{"symbol":"BTC/USD","bids":[],"asks":[{"price":64738.3,"qty":0.48467545}],"checksum":613852741,"timestamp":"2026-07-15T03:59:53.006531Z"}]}
{"channel":"book","type":"update","data":[{"symbol":"BTC/USD","bids":[],"asks":[{"price":64738.3,"qty":0.45727545}],"checksum":1380910680,"timestamp":"2026-07-15T03:59:53.007063Z"}]}
{"channel":"book","type":"update","data":[{"symbol":"BTC/USD","bids":[],"asks":[{"price":64738.3,"qty":0.48467545}],"checksum":613852741,"timestamp":"2026-07-15T03:59:53.007689Z"}]}
{"channel":"book","type":"update","data":[{"symbol":"BTC/USD","bids":[],"asks":[{"price":64751.2,"qty":0.30538237},{"price":64738.4,"qty":0.77390311}],"checksum":3889044901,"timestamp":"2026-07-15T03:59:53.010643Z"}]}
{"channel":"book","type":"update","data":[{"symbol":"BTC/USD","bids":[{"price":64738.1,"qty":0.10306064}],"asks":[],"checksum":2843583317,"timestamp":"2026-07-15T03:59:53.011870Z"}]}
{"channel":"book","type":"update","data":[{"symbol":"BTC/USD","bids":[],"asks":[{"price":64751.2,"qty":0.30229362}],"checksum":1813559458,"timestamp":"2026-07-15T03:59:53.012773Z"}]}
{"channel":"book","type":"update","data":[{"symbol":"BTC/USD","bids":[],"asks":[{"price":64746.1,"qty":0.04492034}],"checksum":1114402315,"timestamp":"2026-07-15T03:59:53.013839Z"}]}
{"channel":"book","type":"update","data":[{"symbol":"BTC/USD","bids":[],"asks":[{"price":64738.4,"qty":0.77388381},{"price":64738.3,"qty":0.48469475}],"checksum":1706811738,"timestamp":"2026-07-15T03:59:53.013883Z"}]}
{"channel":"book","type":"update","data":[{"symbol":"BTC/USD","bids":[{"price":64738.1,"qty":0.00306064}],"asks":[],"checksum":76458845,"timestamp":"2026-07-15T03:59:53.017591Z"}]}
{"channel":"book","type":"update","data":[{"symbol":"BTC/USD","bids":[{"price":64738.2,"qty":0.00106932}],"asks":[],"checksum":2565954083,"timestamp":"2026-07-15T03:59:53.019014Z"}]}
{"channel":"book","type":"update","data":[{"symbol":"BTC/USD","bids":[],"asks":[{"price":64744.8,"qty":0.05820000},{"price":64738.3,"qty":0.88469475}],"checksum":2752623340,"timestamp":"2026-07-15T03:59:53.027168Z"}]}
{"channel":"book","type":"update","data":[{"symbol":"BTC/USD","bids":[],"asks":[{"price":64744.7,"qty":0.00000000},{"price":64751.2,"qty":0.30229362}],"checksum":1853738376,"timestamp":"2026-07-15T03:59:53.028718Z"}]}
{"channel":"book","type":"update","data":[{"symbol":"BTC/USD","bids":[],"asks":[{"price":64738.3,"qty":0.88778411}],"checksum":1356041713,"timestamp":"2026-07-15T03:59:53.029859Z"}]}
{"channel":"book","type":"update","data":[{"symbol":"BTC/USD","bids":[],"asks":[{"price":64751.2,"qty":0.17119960}],"checksum":3634449099,"timestamp":"2026-07-15T03:59:53.094954Z"}]}
{"channel":"book","type":"update","data":[{"symbol":"BTC/USD","bids":[],"asks":[{"price":64751.2,"qty":0.06119960}],"checksum":2029017066,"timestamp":"2026-07-15T03:59:53.095172Z"}]}
{"channel":"book","type":"update","data":[{"symbol":"BTC/USD","bids":[],"asks":[{"price":64744.8,"qty":0.00000000},{"price":64751.9,"qty":0.04491928}],"checksum":4260474610,"timestamp":"2026-07-15T03:59:53.151981Z"}]}
{"channel":"book","type":"update","data":[{"symbol":"BTC/USD","bids":[],"asks":[{"price":64751.1,"qty":0.11000000},{"price":64738.3,"qty":0.91864799}],"checksum":2497589780,"timestamp":"2026-07-15T03:59:53.231223Z"}]}
{"channel":"book","type":"update","data":[{"symbol":"BTC/USD","bids":[{"price":64737.9,"qty":0.00005100}],"asks":[],"checksum":2333359085,"timestamp":"2026-07-15T03:59:53.265692Z"}]}
{"channel":"heartbeat"}
{"channel":"book","type":"update","data":[{"symbol":"BTC/USD","bids":[{"price":64730.0,"qty":0.00000000},{"price":64727.2,"qty":0.77247275}],"asks":[],"checksum":4096345395,"timestamp":"2026-07-15T03:59:53.610916Z"}]}
{"channel":"book","type":"update","data":[{"symbol":"BTC/USD","bids":[],"asks":[{"price":64738.3,"qty":0.93007571}],"checksum":1382870379,"timestamp":"2026-07-15T03:59:53.612497Z"}]}
{"channel":"book","type":"update","data":[{"symbol":"BTC/USD","bids":[],"asks":[{"price":64740.6,"qty":0.96633480}],"checksum":2437580667,"timestamp":"2026-07-15T03:59:53.612668Z"}]}
{"channel":"book","type":"update","data":[{"symbol":"BTC/USD","bids":[{"price":64729.1,"qty":0.77244918}],"asks":[],"checksum":464177842,"timestamp":"2026-07-15T03:59:53.613002Z"}]}
{"channel":"book","type":"update","data":[{"symbol":"BTC/USD","bids":[],"asks":[{"price":64740.6,"qty":0.81142965}],"checksum":3315650703,"timestamp":"2026-07-15T03:59:53.613870Z"}]}
{"channel":"book","type":"update","data":[{"symbol":"BTC/USD","bids":[],"asks":[{"price":64738.3,"qty":1.22611072}],"checksum":3310614716,"timestamp":"2026-07-15T03:59:53.615347Z"}]}
{"channel":"book","type":"update","data":[{"symbol":"BTC/USD","bids":[{"price":64734.7,"qty":0.00005100}],"asks":[],"checksum":1128582486,"timestamp":"2026-07-15T03:59:53.834451Z"}]}
{"channel":"book","type":"update","data":[{"symbol":"BTC/USD","bids":[{"price":64729.1,"qty":0.00000000},{"price":64727.3,"qty":0.24147767}],"asks":[],"checksum":2251302155,"timestamp":"2026-07-15T03:59:53.860775Z"}]}
{"channel":"book","type":"update","data":[{"symbol":"BTC/USD","bids":[{"price":64729.9,"qty":0.77244054}],"asks":[],"checksum":2280985030,"timestamp":"2026-07-15T03:59:53.862270Z"}]}
{"channel":"book","type":"update","data":[{"symbol":"BTC/USD","bids":[],"asks":[{"price":64751.2,"qty":0.05920000}],"checksum":2809553897,"timestamp":"2026-07-15T03:59:53.997257Z"}]}
{"channel":"book","type":"update","data":[{"symbol":"BTC/USD","bids":[],"asks":[{"price":64751.2,"qty":0.05820000}],"checksum":4281899252,"timestamp":"2026-07-15T03:59:54.052313Z"}]}
{"channel":"heartbeat"}
{"channel":"book","type":"update","data":[{"symbol":"BTC/USD","bids":[{"price":64731.5,"qty":0.00005100}],"asks":[],"checksum":1392969085,"timestamp":"2026-07-15T03:59:54.424652Z"}]}
{"channel":"book","type":"update","data":[{"symbol":"BTC/USD","bids":[{"price":64738.1,"qty":0.00312150}],"asks":[],"checksum":2401042116,"timestamp":"2026-07-15T03:59:54.471237Z"}]}
{"channel":"book","type":"update","data":[{"symbol":"BTC/USD","bids":[],"asks":[{"price":64749.2,"qty":0.06037600}],"checksum":3573334848,"timestamp":"2026-07-15T03:59:54.879447Z"}]}
{"channel":"book","type":"update","data":[{"symbol":"BTC/USD","bids":[],"asks":[{"price":64738.4,"qty":0.77233913}],"checksum":1886289751,"timestamp":"2026-07-15T03:59:54.954202Z"}]}
{"channel":"book","type":"update","data":[{"symbol":"BTC/USD","bids":[],"asks":[{"price":64738.3,"qty":1.22765541}],"checksum":692758600,"timestamp":"2026-07-15T03:59:54.954466Z"}]}
{"channel":"book","type":"update","data":[{"symbol":"BTC/USD","bids":[],"asks":[{"price":64738.3,"qty":1.22865541}],"checksum":171759188,"timestamp":"2026-07-15T03:59:55.015708Z"}]}
{"channel":"book","type":"update","data":[{"symbol":"BTC/USD","bids":[],"asks":[{"price":64744.7,"qty":0.00199960}],"checksum":56519143,"timestamp":"2026-07-15T03:59:55.075121Z"}]}
{"channel":"book","type":"update","data":[{"symbol":"BTC/USD","bids":[{"price":64729.9,"qty":0.00000000},{"price":64728.2,"qty":0.00005100}],"asks":[],"checksum":3522786971,"timestamp":"2026-07-15T03:59:55.092945Z"}]}
{"channel":"book","type":"update","data":[{"symbol":"BTC/USD","bids":[{"price":64728.9,"qty":0.77245166}],"asks":[],"checksum":2428583268,"timestamp":"2026-07-15T03:59:55.094701Z"}]}
{"channel":"book","type":"update","data":[{"symbol":"BTC/USD","bids":[{"price":64728.9,"qty":0.00000000},{"price":64728.2,"qty":0.00005100}],"asks":[],"checksum":3522786971,"timestamp":"2026-07-15T03:59:55.160875Z"}]}
{"channel":"heartbeat"}
{"channel":"book","type":"update","data":[{"symbol":"BTC/USD","bids":[],"asks":[{"price":64738.3,"qty":1.21722769}],"checksum":3940445806,"timestamp":"2026-07-15T03:59:55.363686Z"}]}
{"channel":"book","type":"update","data":[{"symbol":"BTC/USD","bids":[],"asks":[{"price":64741.1,"qty":0.00005100}],"checksum":3397683246,"timestamp":"2026-07-15T03:59:55.471454Z"}]}
{"channel":"book","type":"update","data":[{"symbol":"BTC/USD","bids":[{"price":64730.7,"qty":0.77243036}],"asks":[],"checksum":2933742617,"timestamp":"2026-07-15T03:59:55.595276Z"}]}
{"channel":"book","type":"update","data":[{"symbol":"BTC/USD","bids":[{"price":64730.7,"qty":0.00000000},{"price":64728.3,"qty":0.03086388}],"asks":[],"checksum":3163572984,"timestamp":"2026-07-15T03:59:55.602489Z"}]}
{"channel":"book","type":"update","data":[{"symbol":"BTC/USD","bids":[{"price":64729.0,"qty":0.77245050}],"asks":[],"checksum":2502841061,"timestamp":"2026-07-15T03:59:55.604870Z"}]}
{"channel":"book","type":"update","data":[{"symbol":"BTC/USD","bids":[],"asks":[{"price":64740.5,"qty":0.45533212}],"checksum":1019942738,"timestamp":"2026-07-15T03:59:55.613489Z"}]}
{"channel":"book","type":"update","data":[{"symbol":"BTC/USD","bids":[],"asks":[{"price":64738.4,"qty":0.00000000},{"price":64751.1,"qty":0.11000000}],"checksum":4225026165,"timestamp":"2026-07-15T03:59:55.678413Z"}]}
{"channel":"book","type":"update","data":[{"symbol":"BTC/USD","bids":[],"asks":[{"price":64739.2,"qty":0.77232969}],"checksum":771449779,"timestamp":"2026-07-15T03:59:55.679885Z"}]}
{"channel":"book","type":"update","data":[{"symbol":"BTC/USD","bids":[{"price":64731.4,"qty":0.77242162}],"asks":[],"checksum":2031744130,"timestamp":"2026-07-15T03:59:55.736317Z"}]}
{"channel":"book","type":"update","data":[{"symbol":"BTC/USD","bids":[],"asks":[{"price":64744.3,"qty":0.00005100}],"checksum":1937834715,"timestamp":"2026-07-15T03:59:55.985080Z"}]}
{"channel":"book","type":"update","data":[{"symbol":"BTC/USD","bids":[{"price":64738.2,"qty":0.01106932}],"asks":[],"checksum":1786670755,"timestamp":"2026-07-15T03:59:56.185951Z"}]}
{"channel":"heartbeat"}
{"channel":"book","type":"update","data":[{"symbol":"BTC/USD","bids":[],"asks":[{"price":64738.3,"qty":1.22422769}],"checksum":492893964,"timestamp":"2026-07-15T03:59:56.306312Z"}]}
{"channel":"book","type":"update","data":[{"symbol":"BTC/USD","bids":[],"asks":[{"price":64740.5,"qty":0.39713212}],"checksum":952520456,"timestamp":"2026-07-15T03:59:56.407086Z"}]}
{"channel":"book","type":"update","data":[{"symbol":"BTC/USD","bids":[],"asks":[{"price":64738.3,"qty":0.77405416}],"checksum":3690995712,"timestamp":"2026-07-15T03:59:56.415105Z"}]}
{"channel":"book","type":"update","data":[{"symbol":"BTC/USD","bids":[],"asks":[{"price":64738.3,"qty":0.77250947}],"checksum":2623623370,"timestamp":"2026-07-15T03:59:56.416105Z"}]}
{"channel":"book","type":"update","data":[{"symbol":"BTC/USD","bids":[],"asks":[{"price":64739.2,"qty":0.00000000},{"price":64749.2,"qty":0.06037600}],"checksum":3731676069,"timestamp":"2026-07-15T03:59:56.416530Z"}]}
{"channel":"book","type":"update","data":[{"symbol":"BTC/USD","bids":[],"asks":[{"price":64740.6,"qty":0.03911676}],"checksum":119112868,"timestamp":"2026-07-15T03:59:56.416591Z"}]}
{"channel":"book","type":"update","data":[{"symbol":"BTC/USD","bids":[],"asks":[{"price":64738.3,"qty":0.47647446}],"checksum":3614161011,"timestamp":"2026-07-15T03:59:56.416644Z"}]}
{"channel":"book","type":"update","data":[{"symbol":"BTC/USD","bids":[{"price":64731.4,"qty":0.00000000},{"price":64729.2,"qty":0.03086388}],"asks":[],"checksum":2901654778,"timestamp":"2026-07-15T03:59:56.417548Z"}]}
{"channel":"book","type":"update","data":[{"symbol":"BTC/USD","bids":[{"price":64730.6,"qty":0.55550696}],"asks":[],"checksum":1414792270,"timestamp":"2026-07-15T03:59:56.418666Z"}]}
{"channel":"book","type":"update","data":[{"symbol":"BTC/USD","bids":[{"price":64729.2,"qty":0.00000000},{"price":64729.1,"qty":0.26807182},{"price":64733.0,"qty":0.03086388}],"asks":[],"checksum":2261323057,"timestamp":"2026-07-15T03:59:56.418764Z"}]}
{"channel":"book","type":"update","data":[{"symbol":"BTC/USD","bids":[],"asks":[{"price":64740.5,"qty":0.00000000},{"price":64751.1,"qty":0.11000000}],"checksum":2606922059,"timestamp":"2026-07-15T03:59:56.419613Z"}]}
{"channel":"book","type":"update","data":[{"symbol":"BTC/USD","bids":[],"asks":[{"price":64740.5,"qty":0.16659672}],"checksum":200767125,"timestamp":"2026-07-15T03:59:56.424164Z"}]}
{"channel":"book","type":"update","data":[{"symbol":"BTC/USD","bids":[],"asks":[{"price":64738.3,"qty":0.46937254}],"checksum":2694583532,"timestamp":"2026-07-15T03:59:56.424477Z"}]}
{"channel":"book","type":"update","data":[{"symbol":"BTC/USD","bids":[],"asks":[{"price":64738.3,"qty":0.43850866}],"checksum":3269053913,"timestamp":"2026-07-15T03:59:56.425272Z"}]}
{"channel":"book","type":"update","data":[{"symbol":"BTC/USD","bids":[{"price":64730.7,"qty":0.16581883}],"asks":[],"checksum":1136887533,"timestamp":"2026-07-15T03:59:56.426151Z"}]}
{"channel":"book","type":"update","data":[{"symbol":"BTC/USD","bids":[],"asks":[{"price":64740.5,"qty":0.00000000},{"price":64751.1,"qty":0.11000000}],"checksum":3545663795,"timestamp":"2026-07-15T03:59:56.426938Z"}]}
{"channel":"book","type":"update","data":[{"symbol":"BTC/USD","bids":[],"asks":[{"price":64740.5,"qty":0.77231509}],"checksum":1977642621,"timestamp":"2026-07-15T03:59:56.427104Z"}]}
{"channel":"book","type":"update","data":[{"symbol":"BTC/USD","bids":[],"asks":[{"price":64743.2,"qty":0.77228226}],"checksum":2701959364,"timestamp":"2026-07-15T03:59:56.427150Z"}]}
{"channel":"book","type":"update","data":[{"symbol":"BTC/USD","bids":[{"price":64732.4,"qty":0.77241017}],"asks":[],"checksum":2655878278,"timestamp":"2026-07-15T03:59:56.427217Z"}]}
{"channel":"book","type":"update","data":[{"symbol":"BTC/USD","bids":[{"price":64733.0,"qty":0.54521047}],"asks":[],"checksum":1843209371,"timestamp":"2026-07-15T03:59:56.428930Z"}]}
{"channel":"book","type":"update","data":[{"symbol":"BTC/USD","bids":[],"asks":[{"price":64745.0,"qty":0.00000000},{"price":64749.2,"qty":0.06037600}],"checksum":645871260,"timestamp":"2026-07-15T03:59:56.430955Z"}]}
{"channel":"book","type":"update","data":[{"symbol":"BTC/USD","bids":[],"asks":[{"price":64738.3,"qty":0.46937254}],"checksum":1890498406,"timestamp":"2026-07-15T03:59:56.431379Z"}]}
{"channel":"book","type":"update","data":[{"symbol":"BTC/USD","bids":[],"asks":[{"price":64740.5,"qty":0.00000000},{"price":64751.1,"qty":0.11000000}],"checksum":1578096189,"timestamp":"2026-07-15T03:59:56.431682Z"}]}
{"channel":"book","type":"update","data":[{"symbol":"BTC/USD","bids":[],"asks":[{"price":64740.6,"qty":0.19403713}],"checksum":1845892930,"timestamp":"2026-07-15T03:59:56.433219Z"}]}
{"channel":"book","type":"update","data":[{"symbol":"BTC/USD","bids":[],"asks":[{"price":64738.3,"qty":0.47647446}],"checksum":860323554,"timestamp":"2026-07-15T03:59:56.436216Z"}]}
{"channel":"book","type":"update","data":[{"symbol":"BTC/USD","bids":[],"asks":[{"price":64740.7,"qty":0.00000000},{"price":64751.2,"qty":0.05820000}],"checksum":673785335,"timestamp":"2026-07-15T03:59:56.437105Z"}]}
{"channel":"book","type":"update","data":[{"symbol":"BTC/USD","bids":[],"asks":[{"price":64740.6,"qty":0.03911676}],"checksum":370045851,"timestamp":"2026-07-15T03:59:56.437248Z"}]}
{"channel":"book","type":"update","data":[{"symbol":"BTC/USD","bids":[],"asks":[{"price":64748.1,"qty":0.77222370}],"checksum":4162788936,"timestamp":"2026-07-15T03:59:56.437356Z"}]}
{"channel":"book","type":"update","data":[{"symbol":"BTC/USD","bids":[],"asks":[{"price":64743.1,"qty":0.23113836}],"checksum":3876739770,"timestamp":"2026-07-15T03:59:56.439050Z"}]}
{"channel":"book","type":"update","data":[{"symbol":"BTC/USD","bids":[],"asks":[{"price":64738.3,"qty":0.46937254}],"checksum":3462461504,"timestamp":"2026-07-15T03:59:56.440359Z"}]}
{"channel":"book","type":"update","data":[{"symbol":"BTC/USD","bids":[{"price":64734.9,"qty":0.00154476}],"asks":[],"checksum":3423357077,"timestamp":"2026-07-15T03:59:56.447110Z"}]}
{"channel":"book","type":"update","data":[{"symbol":"BTC/USD","bids":[],"asks":[{"price":64738.3,"qty":0.43850866}],"checksum":3101729989,"timestamp":"2026-07-15T03:59:56.447475Z"}]}
{"channel":"book","type":"update","data":[{"symbol":"BTC/USD","bids":[{"price":64732.5,"qty":0.24149334}],"asks":[],"checksum":1019900767,"timestamp":"2026-07-15T03:59:56.454335Z"}]}
{"channel":"book","type":"update","data":[{"symbol":"BTC/USD","bids":[],"asks":[{"price":64747.6,"qty":0.00005100}],"checksum":4229935015,"timestamp":"2026-07-15T03:59:56.504231Z"}]}
{"channel":"book","type":"update","data":[{"symbol":"BTC/USD","bids":[],"asks":[{"price":64741.3,"qty":0.77230521}],"checksum":2317356127,"timestamp":"2026-07-15T03:59:56.535479Z"}]}
{"channel":"book","type":"update","data":[{"symbol":"BTC/USD","bids":[],"asks":[{"price":64738.3,"qty":0.44561058}],"checksum":1911827973,"timestamp":"2026-07-15T03:59:56.539510Z"}]}
{"channel":"book","type":"update","data":[{"symbol":"BTC/USD","bids":[{"price":64733.0,"qty":0.51434659}],"asks":[],"checksum":745315353,"timestamp":"2026-07-15T03:59:56.575032Z"}]}
{"channel":"book","type":"update","data":[{"symbol":"BTC/USD","bids":[{"price":64733.8,"qty":0.77239300}],"asks":[],"checksum":2387824529,"timestamp":"2026-07-15T03:59:56.584890Z"}]}
{"channel":"book","type":"update","data":[{"symbol":"BTC/USD","bids":[],"asks":[{"price":64738.3,"qty":0.43850866}],"checksum":1971809739,"timestamp":"2026-07-15T03:59:56.588202Z"}]}
{"channel":"book","type":"update","data":[{"symbol":"BTC/USD","bids":[],"asks":[{"price":64738.3,"qty":0.46937254}],"checksum":398636286,"timestamp":"2026-07-15T03:59:56.631689Z"}]}
{"channel":"book","type":"update","data":[{"symbol":"BTC/USD","bids":[{"price":64733.8,"qty":0.00000000},{"price":64731.5,"qty":0.00005100}],"asks":[],"checksum":1103452195,"timestamp":"2026-07-15T03:59:56.798468Z"}]}
{"channel":"book","type":"update","data":[{"symbol":"BTC/USD","bids":[],"asks":[{"price":64741.2,"qty":0.23053311}],"checksum":4174216067,"timestamp":"2026-07-15T03:59:56.798595Z"}]}
{"channel":"book","type":"update","data":[{"symbol":"BTC/USD","bids":[],"asks":[{"price":64741.3,"qty":0.00000000},{"price":64747.6,"qty":0.00005100}],"checksum":3748692335,"timestamp":"2026-07-15T03:59:56.798753Z"}]}
{"channel":"book","type":"update","data":[{"symbol":"BTC/USD","bids":[],"asks":[{"price":64738.3,"qty":0.47647446}],"checksum":3077431016,"timestamp":"2026-07-15T03:59:56.799525Z"}]}
{"channel":"book","type":"update","data":[{"symbol":"BTC/USD","bids":[],"asks":[{"price":64741.2,"qty":0.00000000},{"price":64748.1,"qty":0.77222370}],"checksum":1625365195,"timestamp":"2026-07-15T03:59:56.799933Z"}]}
{"channel":"book","type":"update","data":[{"symbol":"BTC/USD","bids":[],"asks":[{"price":64740.3,"qty":0.77231735}],"checksum":1641942930,"timestamp":"2026-07-15T03:59:56.800201Z"}]}
{"channel":"book","type":"update","data":[{"symbol":"BTC/USD","bids":[{"price":64732.9,"qty":2.50122751}],"asks":[],"checksum":813745137,"timestamp":"2026-07-15T03:59:56.800516Z"}]}
{"channel":"book","type":"update","data":[{"symbol":"BTC/USD","bids":[],"asks":[{"price":64740.2,"qty":0.24222831}],"checksum":3921151040,"timestamp":"2026-07-15T03:59:56.801767Z"}]}
{"channel":"book","type":"update","data":[{"symbol":"BTC/USD","bids":[],"asks":[{"price":64738.3,"qty":0.46937254}],"checksum":1121150521,"timestamp":"2026-07-15T03:59:56.802175Z"}]}
{"channel":"book","type":"update","data":[{"symbol":"BTC/USD","bids":[{"price":64734.9,"qty":0.00000000},{"price":64730.9,"qty":0.80329159}],"asks":[],"checksum":3563291170,"timestamp":"2026-07-15T03:59:56.803645Z"}]}
{"channel":"book","type":"update","data":[{"symbol":"BTC/USD","bids":[],"asks":[{"price":64738.3,"qty":0.47647446}],"checksum":2300767106,"timestamp":"2026-07-15T03:59:56.804867Z"}]}
{"channel":"book","type":"update","data":[{"symbol":"BTC/USD","bids":[{"price":64731.9,"qty":0.51894522}],"asks":[],"checksum":2891175774,"timestamp":"2026-07-15T03:59:57.139933Z"}]}
{"channel":"book","type":"update","data":[{"symbol":"BTC/USD","bids":[],"asks":[{"price":64742.1,"qty":0.51894522}],"checksum":841016364,"timestamp":"2026-07-15T03:59:57.140443Z"}]}
{"channel":"book","type":"update","data":[{"symbol":"BTC/USD","bids":[{"price":64734.7,"qty":0.01299170}],"asks":[],"checksum":2328442454,"timestamp":"2026-07-15T03:59:57.193244Z"}]}
{"channel":"book","type":"update","data":[{"symbol":"BTC/USD","bids":[],"asks":[{"price":64740.2,"qty":0.36616504}],"checksum":2992339805,"timestamp":"2026-07-15T03:59:57.194929Z"}]}
{"channel":"heartbeat"}
{"channel":"book","type":"update","data":[{"symbol":"BTC/USD","bids":[{"price":64733.0,"qty":0.00000000},{"price":64730.9,"qty":0.80329159}],"asks":[],"checksum":3876644250,"timestamp":"2026-07-15T03:59:57.476166Z"}]}
{"channel":"book","type":"update","data":[{"symbol":"BTC/USD","bids":[{"price":64730.9,"qty":0.03086388}],"asks":[],"checksum":4294139279,"timestamp":"2026-07-15T03:59:57.705110Z"}]}
{"channel":"book","type":"update","data":[{"symbol":"BTC/USD","bids":[{"price":64732.9,"qty":1.72882300}],"asks":[],"checksum":3354868380,"timestamp":"2026-07-15T03:59:57.705436Z"}]}
{"channel":"book","type":"update","data":[{"symbol":"BTC/USD","bids":[],"asks":[{"price":64743.2,"qty":0.00000000},{"price":64746.1,"qty":0.04492034}],"checksum":3397960528,"timestamp":"2026-07-15T03:59:57.705492Z"}]}
{"channel":"book","type":"update","data":[{"symbol":"BTC/USD","bids":[],"asks":[{"price":64740.3,"qty":0.00000000},{"price":64747.6,"qty":0.00005100}],"checksum":1673571387,"timestamp":"2026-07-15T03:59:57.705704Z"}]}
{"channel":"book","type":"update","data":[{"symbol":"BTC/USD","bids":[],"asks":[{"price":64743.1,"qty":0.00000000},{"price":64748.1,"qty":0.77222370}],"checksum":3613041374,"timestamp":"2026-07-15T03:59:57.706926Z"}]}
{"channel":"book","type":"update","data":[{"symbol":"BTC/USD","bids":[],"asks":[{"price":64740.2,"qty":0.12393673}],"checksum":2951673106,"timestamp":"2026-07-15T03:59:57.706966Z"}]}
{"channel":"book","type":"update","data":[{"symbol":"BTC/USD","bids":[{"price":64730.9,"qty":0.00000000},{"price":64730.6,"qty":0.03656174},{"price":64730.7,"qty":0.03086388}],"asks":[],"checksum":3127174944,"timestamp":"2026-07-15T03:59:57.706975Z"}]}
{"channel":"book","type":"update","data":[{"symbol":"BTC/USD","bids":[],"asks":[{"price":64739.5,"qty":0.77232677}],"checksum":3714496255,"timestamp":"2026-07-15T03:59:57.707460Z"}]}
{"channel":"book","type":"update","data":[{"symbol":"BTC/USD","bids":[],"asks":[{"price":64741.9,"qty":0.77229808}],"checksum":2118847852,"timestamp":"2026-07-15T03:59:57.707866Z"}]}
{"channel":"book","type":"update","data":[{"symbol":"BTC/USD","bids":[{"price":64731.9,"qty":1.29136147}],"asks":[],"checksum":3561228200,"timestamp":"2026-07-15T03:59:57.708159Z"}]}
{"channel":"book","type":"update","data":[{"symbol":"BTC/USD","bids":[],"asks":[{"price":64743.6,"qty":0.01283776}],"checksum":1303858298,"timestamp":"2026-07-15T03:59:57.708456Z"}]}
{"channel":"book","type":"update","data":[{"symbol":"BTC/USD","bids":[],"asks":[{"price":64739.4,"qty":0.39713627}],"checksum":1686116021,"timestamp":"2026-07-15T03:59:57.708694Z"}]}
{"channel":"book","type":"update","data":[{"symbol":"BTC/USD","bids":[],"asks":[{"price":64740.2,"qty":0.00000000},{"price":64744.7,"qty":0.00199960}],"checksum":1160644424,"timestamp":"2026-07-15T03:59:57.708728Z"}]}
{"channel":"book","type":"update","data":[{"symbol":"BTC/USD","bids":[],"asks":[{"price":64743.6,"qty":0.00000000},{"price":64746.1,"qty":0.04492034}],"checksum":3705490586,"timestamp":"2026-07-15T03:59:57.708889Z"}]}
{"channel":"book","type":"update","data":[{"symbol":"BTC/USD","bids":[],"asks":[{"price":64739.4,"qty":0.57689415}],"checksum":581761041,"timestamp":"2026-07-15T03:59:57.709294Z"}]}
{"channel":"book","type":"update","data":[{"symbol":"BTC/USD","bids":[],"asks":[{"price":64738.3,"qty":0.46937254}],"checksum":1311769796,"timestamp":"2026-07-15T03:59:57.710355Z"}]}
{"channel":"book","type":"update","data":[{"symbol":"BTC/USD","bids":[],"asks":[{"price":64738.3,"qty":0.47647446}],"checksum":581761041,"timestamp":"2026-07-15T03:59:57.713155Z"}]}
{"channel":"heartbeat"}
{"channel":"book","type":"update","data":[{"symbol":"BTC/USD","bids":[{"price":64732.8,"qty":0.51184600}],"asks":[],"checksum":1101485328,"timestamp":"2026-07-15T03:59:58.738560Z"}]}
{"channel":"book","type":"update","data":[{"symbol":"BTC/USD","bids":[],"asks":[{"price":64739.5,"qty":0.00000000},{"price":64747.6,"qty":0.00005100}],"checksum":952633415,"timestamp":"2026-07-15T03:59:58.869622Z"}]}
{"channel":"book","type":"update","data":[{"symbol":"BTC/USD","bids":[],"asks":[{"price":64739.4,"qty":0.39713627}],"checksum":2056143968,"timestamp":"2026-07-15T03:59:58.870968Z"}]}
{"channel":"book","type":"update","data":[{"symbol":"BTC/USD","bids":[],"asks":[{"price":64738.6,"qty":0.77233710}],"checksum":1775925108,"timestamp":"2026-07-15T03:59:58.871404Z"}]}
{"channel":"book","type":"update","data":[{"symbol":"BTC/USD","bids":[],"asks":[{"price":64745.4,"qty":0.77225668}],"checksum":2788653826,"timestamp":"2026-07-15T03:59:58.871735Z"}]}
{"channel":"book","type":"update","data":[{"symbol":"BTC/USD","bids":[],"asks":[{"price":64738.5,"qty":0.62767033}],"checksum":1072068897,"timestamp":"2026-07-15T03:59:58.872689Z"}]}
{"channel":"book","type":"update","data":[{"symbol":"BTC/USD","bids":[],"asks":[{"price":64739.4,"qty":0.00000000},{"price":64745.4,"qty":0.77225668}],"checksum":3173923714,"timestamp":"2026-07-15T03:59:58.872810Z"}]}
{"channel":"book","type":"update","data":[{"symbol":"BTC/USD","bids":[],"asks":[{"price":64745.3,"qty":0.23051862}],"checksum":2190045769,"timestamp":"2026-07-15T03:59:58.873123Z"}]}
{"channel":"book","type":"update","data":[{"symbol":"BTC/USD","bids":[],"asks":[{"price":64738.3,"qty":0.46937254}],"checksum":3402469816,"timestamp":"2026-07-15T03:59:58.874199Z"}]}
{"channel":"book","type":"update","data":[{"symbol":"BTC/USD","bids":[],"asks":[{"price":64738.3,"qty":0.47647446}],"checksum":2190045769,"timestamp":"2026-07-15T03:59:58.876875Z"}]}
{"channel":"heartbeat"}
{"channel":"book","type":"update","data":[{"symbol":"BTC/USD","bids":[{"price":64738.2,"qty":0.01113127}],"asks":[],"checksum":3918560274,"timestamp":"2026-07-15T03:59:59.472937Z"}]}
{"channel":"book","type":"update","data":[{"symbol":"BTC/USD","bids":[{"price":64738.1,"qty":0.00306064}],"asks":[],"checksum":371766358,"timestamp":"2026-07-15T03:59:59.472989Z"}]}
{"channel":"book","type":"update","data":[{"symbol":"BTC/USD","bids":[{"price":64734.7,"qty":0.00005100}],"asks":[],"checksum":2524178416,"timestamp":"2026-07-15T03:59:59.519206Z"}]}
{"channel":"book","type":"update","data":[{"symbol":"BTC/USD","bids":[{"price":64734.9,"qty":0.00154476}],"asks":[],"checksum":1236470080,"timestamp":"2026-07-15T03:59:59.644708Z"}]}
{"channel":"book","type":"update","data":[{"symbol":"BTC/USD","bids":[],"asks":[{"price":64738.6,"qty":0.00000000},{"price":64745.4,"qty":0.77225668}],"checksum":166907052,"timestamp":"2026-07-15T03:59:59.689476Z"}]}
{"channel":"book","type":"update","data":[{"symbol":"BTC/USD","bids":[],"asks":[{"price":64738.5,"qty":0.00000000},{"price":64746.1,"qty":0.04492034}],"checksum":4116760125,"timestamp":"2026-07-15T03:59:59.690791Z"}]}
{"channel":"book","type":"update","data":[{"symbol":"BTC/USD","bids":[],"asks":[{"price":64739.4,"qty":0.77232795}],"checksum":3219317024,"timestamp":"2026-07-15T03:59:59.691086Z"}]}
{"channel":"book","type":"update","data":[{"symbol":"BTC/USD","bids":[],"asks":[{"price":64741.8,"qty":0.38543613}],"checksum":406171366,"timestamp":"2026-07-15T03:59:59.691992Z"}]}
{"channel":"book","type":"update","data":[{"symbol":"BTC/USD","bids":[],"asks":[{"price":64741.8,"qty":0.00000000},{"price":64745.4,"qty":0.77225668}],"checksum":3219317024,"timestamp":"2026-07-15T03:59:59.692985Z"}]}
{"channel":"book","type":"update","data":[{"symbol":"BTC/USD","bids":[],"asks":[{"price":64738.3,"qty":0.46937254}],"checksum":1228364679,"timestamp":"2026-07-15T03:59:59.694173Z"}]}
{"channel":"book","type":"update","data":[{"symbol":"BTC/USD","bids":[],"asks":[{"price":64739.3,"qty":0.62766759}],"checksum":4080493945,"timestamp":"2026-07-15T03:59:59.694294Z"}]}
{"channel":"book","type":"update","data":[{"symbol":"BTC/USD","bids":[],"asks":[{"price":64738.3,"qty":0.47647446}],"checksum":98754526,"timestamp":"2026-07-15T03:59:59.696833Z"}]}
{"channel":"book","type":"update","data":[{"symbol":"BTC/USD","bids":[{"price":64731.9,"qty":0.51894522}],"asks":[],"checksum":4273160643,"timestamp":"2026-07-15T03:59:59.729500Z"}]}
{"channel":"book","type":"update","data":[{"symbol":"BTC/USD","bids":[{"price":64732.6,"qty":0.77240814}],"asks":[],"checksum":4147581555,"timestamp":"2026-07-15T03:59:59.731130Z"}]}
{"channel":"book","type":"update","data":[{"symbol":"BTC/USD","bids":[{"price":64734.7,"qty":0.01275484}],"asks":[],"checksum":1628391811,"timestamp":"2026-07-15T03:59:59.820337Z"}]}
{"channel":"book","type":"update","data":[{"symbol":"BTC/USD","bids":[],"asks":[{"price":64738.3,"qty":0.88740361}],"checksum":313629995,"timestamp":"2026-07-15T04:00:00.046214Z"}]}
{"channel":"book","type":"update","data":[{"symbol":"BTC/USD","bids":[],"asks":[{"price":64744.7,"qty":0.00000000},{"price":64745.4,"qty":0.77225668}],"checksum":866299835,"timestamp":"2026-07-15T04:00:00.070932Z"}]}
{"channel":"book","type":"update","data":[{"symbol":"BTC/USD","bids":[],"asks":[{"price":64738.3,"qty":0.90561843}],"checksum":2072912154,"timestamp":"2026-07-15T04:00:00.105165Z"}]}
{"channel":"trade","type":"update","data":[{"symbol":"BTC/USD","side":"buy","price":64738.3,"qty":0.00015370,"ord_type":"limit","trade_id":103746768,"timestamp":"2026-07-15T04:00:00.262911Z"}]}
{"channel":"book","type":"update","data":[{"symbol":"BTC/USD","bids":[],"asks":[{"price":64738.3,"qty":0.90546473}],"checksum":1273522695,"timestamp":"2026-07-15T04:00:00.262911Z"}]}
{"channel":"trade","type":"update","data":[{"symbol":"BTC/USD","side":"buy","price":64738.3,"qty":0.00009175,"ord_type":"limit","trade_id":103746769,"timestamp":"2026-07-15T04:00:00.276998Z"}]}
{"channel":"book","type":"update","data":[{"symbol":"BTC/USD","bids":[],"asks":[{"price":64738.3,"qty":0.90537298}],"checksum":861206761,"timestamp":"2026-07-15T04:00:00.276998Z"}]}
{"channel":"heartbeat"}
{"channel":"book","type":"update","data":[{"symbol":"BTC/USD","bids":[],"asks":[{"price":64738.3,"qty":0.90691767}],"checksum":3093225137,"timestamp":"2026-07-15T04:00:00.351653Z"}]}
{"channel":"book","type":"update","data":[{"symbol":"BTC/USD","bids":[],"asks":[{"price":64738.3,"qty":0.90537298}],"checksum":861206761,"timestamp":"2026-07-15T04:00:00.416986Z"}]}
{"channel":"book","type":"update","data":[{"symbol":"BTC/USD","bids":[],"asks":[{"price":64739.4,"qty":0.00000000},{"price":64746.1,"qty":0.04492034}],"checksum":1151742211,"timestamp":"2026-07-15T04:00:00.431335Z"}]}
{"channel":"book","type":"update","data":[{"symbol":"BTC/USD","bids":[],"asks":[{"price":64740.3,"qty":0.77231728}],"checksum":3213064279,"timestamp":"2026-07-15T04:00:00.432949Z"}]}
{"channel":"book","type":"update","data":[{"symbol":"BTC/USD","bids":[],"asks":[{"price":64739.3,"qty":0.00000000},{"price":64746.1,"qty":0.04492034}],"checksum":354619299,"timestamp":"2026-07-15T04:00:00.433189Z"}]}
{"channel":"book","type":"update","data":[{"symbol":"BTC/USD","bids":[],"asks":[{"price":64740.2,"qty":0.62766441}],"checksum":2002464835,"timestamp":"2026-07-15T04:00:00.434873Z"}]}
{"channel":"book","type":"update","data":[{"symbol":"BTC/USD","bids":[{"price":64734.9,"qty":0.03240864}],"asks":[],"checksum":2477011833,"timestamp":"2026-07-15T04:00:00.679272Z"}]}
{"channel":"trade","type":"update","data":[{"symbol":"BTC/USD","side":"buy","price":64738.3,"qty":0.00037860,"ord_type":"limit","trade_id":103746770,"timestamp":"2026-07-15T04:00:00.743271Z"}]}
{"channel":"book","type":"update","data":[{"symbol":"BTC/USD","bids":[],"asks":[{"price":64738.3,"qty":0.90499438}],"checksum":1751966171,"timestamp":"2026-07-15T04:00:00.743271Z"}]}
{"channel":"trade","type":"update","data":[{"symbol":"BTC/USD","side":"buy","price":64738.3,"qty":0.00015292,"ord_type":"limit","trade_id":103746771,"timestamp":"2026-07-15T04:00:00.751411Z"}]}
{"channel":"book","type":"update","data":[{"symbol":"BTC/USD","bids":[],"asks":[{"price":64738.3,"qty":0.90484146}],"checksum":2033294156,"timestamp":"2026-07-15T04:00:00.751411Z"}]}
{"channel":"trade","type":"update","data":[{"symbol":"BTC/USD","side":"buy","price":64738.3,"qty":0.00037860,"ord_type":"limit","trade_id":103746772,"timestamp":"2026-07-15T04:00:00.755267Z"}]}
{"channel":"book","type":"update","data":[{"symbol":"BTC/USD","bids":[],"asks":[{"price":64738.3,"qty":0.90446286}],"checksum":427789337,"timestamp":"2026-07-15T04:00:00.755267Z"}]}
{"channel":"trade","type":"update","data":[{"symbol":"BTC/USD","side":"buy","price":64738.3,"qty":0.00302879,"ord_type":"limit","trade_id":103746773,"timestamp":"2026-07-15T04:00:00.779237Z"}]}
{"channel":"book","type":"update","data":[{"symbol":"BTC/USD","bids":[],"asks":[{"price":64738.3,"qty":0.90143407}],"checksum":2087627483,"timestamp":"2026-07-15T04:00:00.779237Z"}]}
{"channel":"trade","type":"update","data":[{"symbol":"BTC/USD","side":"buy","price":64738.3,"qty":0.00302879,"ord_type":"limit","trade_id":103746774,"timestamp":"2026-07-15T04:00:00.974549Z"}]}
{"channel":"book","type":"update","data":[{"symbol":"BTC/USD","bids":[],"asks":[{"price":64738.3,"qty":0.89840528}],"checksum":464949569,"timestamp":"2026-07-15T04:00:00.974549Z"}]}
{"channel":"book","type":"update","data":[{"symbol":"BTC/USD","bids":[],"asks":[{"price":64740.3,"qty":0.00000000},{"price":64746.1,"qty":0.04492034}],"checksum":929765668,"timestamp":"2026-07-15T04:00:00.976722Z"}]}
{"channel":"book","type":"update","data":[{"symbol":"BTC/USD","bids":[{"price":64732.6,"qty":0.00000000},{"price":64731.9,"qty":0.51894522}],"asks":[],"checksum":1055869588,"timestamp":"2026-07-15T04:00:00.976735Z"}]}
{"channel":"book","type":"update","data":[{"symbol":"BTC/USD","bids":[],"asks":[{"price":64740.2,"qty":0.00000000},{"price":64747.6,"qty":0.00005100}],"checksum":2260877353,"timestamp":"2026-07-15T04:00:00.978536Z"}]}
{"channel":"book","type":"update","data":[{"symbol":"BTC/USD","bids":[],"asks":[{"price":64739.6,"qty":0.77232483}],"checksum":3028490652,"timestamp":"2026-07-15T04:00:00.992463Z"}]}
{"channel":"book","type":"update","data":[{"symbol":"BTC/USD","bids":[{"price":64732.0,"qty":0.22785555}],"asks":[],"checksum":1838544932,"timestamp":"2026-07-15T04:00:01.155617Z"}]}
{"channel":"book","type":"update","data":[{"symbol":"BTC/USD","bids":[],"asks":[{"price":64738.3,"qty":0.90040488}],"checksum":1092702615,"timestamp":"2026-07-15T04:00:01.161089Z"}]}
{"channel":"trade","type":"update","data":[{"symbol":"BTC/USD","side":"buy","price":64738.3,"qty":0.00015000,"ord_type":"limit","trade_id":103746775,"timestamp":"2026-07-15T04:00:01.173778Z"}]}
{"channel":"book","type":"update","data":[{"symbol":"BTC/USD","bids":[],"asks":[{"price":64738.3,"qty":0.90025488}],"checksum":1560651895,"timestamp":"2026-07-15T04:00:01.173778Z"}]}
{"channel":"heartbeat"}
{"channel":"book","type":"update","data":[{"symbol":"BTC/USD","bids":[{"price":64732.6,"qty":0.77240768}],"asks":[],"checksum":3225192366,"timestamp":"2026-07-15T04:00:01.347096Z"}]}
{"channel":"book","type":"update","data":[{"symbol":"BTC/USD","bids":[],"asks":[{"price":64739.5,"qty":0.62766666}],"checksum":2938463173,"timestamp":"2026-07-15T04:00:01.349385Z"}]}
{"channel":"book","type":"update","data":[{"symbol":"BTC/USD","bids":[],"asks":[{"price":64738.3,"qty":0.89325488}],"checksum":650657778,"timestamp":"2026-07-15T04:00:01.584727Z"}]}
{"channel":"book","type":"update","data":[{"symbol":"BTC/USD","bids":[],"asks":[{"price":64738.3,"qty":0.95145488}],"checksum":3456430184,"timestamp":"2026-07-15T04:00:01.691324Z"}]}
{"channel":"book","type":"update","data":[{"symbol":"BTC/USD","bids":[{"price":64732.6,"qty":0.00000000},{"price":64731.5,"qty":0.00005100}],"asks":[],"checksum":1968910760,"timestamp":"2026-07-15T04:00:01.692714Z"}]}
{"channel":"book","type":"update","data":[{"symbol":"BTC/USD","bids":[{"price":64734.7,"qty":0.00005100}],"asks":[],"checksum":692566586,"timestamp":"2026-07-15T04:00:01.692902Z"}]}
{"channel":"book","type":"update","data":[{"symbol":"BTC/USD","bids":[{"price":64734.9,"qty":0.00154476}],"asks":[],"checksum":2048411292,"timestamp":"2026-07-15T04:00:01.693088Z"}]}
{"channel":"book","type":"update","data":[{"symbol":"BTC/USD","bids":[],"asks":[{"price":64745.4,"qty":0.00000000},{"price":64746.1,"qty":0.04492034}],"checksum":1977811391,"timestamp":"2026-07-15T04:00:01.693338Z"}]}
{"channel":"book","type":"update","data":[{"symbol":"BTC/USD","bids":[],"asks":[{"price":64741.9,"qty":0.00000000},{"price":64747.6,"qty":0.00005100}],"checksum":3275372680,"timestamp":"2026-07-15T04:00:01.693916Z"}]}
{"channel":"book","type":"update","data":[{"symbol":"BTC/USD","bids":[{"price":64738.2,"qty":0.01083430}],"asks":[],"checksum":1792894842,"timestamp":"2026-07-15T04:00:01.694277Z"}]}
{"channel":"book","type":"update","data":[{"symbol":"BTC/USD","bids":[{"price":64732.8,"qty":0.00000000},{"price":64730.6,"qty":0.03656174}],"asks":[],"checksum":3534747893,"timestamp":"2026-07-15T04:00:01.694357Z"}]}
{"channel":"book","type":"update","data":[{"symbol":"BTC/USD","bids":[{"price":64732.9,"qty":0.00000000},{"price":64728.2,"qty":0.00005100}],"asks":[],"checksum":3368538729,"timestamp":"2026-07-15T04:00:01.697788Z"}]}
{"channel":"book","type":"update","data":[{"symbol":"BTC/USD","bids":[],"asks":[{"price":64739.5,"qty":0.00000000},{"price":64749.2,"qty":0.06037600}],"checksum":2009884117,"timestamp":"2026-07-15T04:00:01.698007Z"}]}
{"channel":"book","type":"update","data":[{"symbol":"BTC/USD","bids":[{"price":64730.8,"qty":0.03086388}],"asks":[],"checksum":1831487880,"timestamp":"2026-07-15T04:00:01.700162Z"}]}
{"channel":"book","type":"update","data":[{"symbol":"BTC/USD","bids":[],"asks":[{"price":64745.3,"qty":0.00000000},{"price":64750.8,"qty":0.00005100}],"checksum":1066363531,"timestamp":"2026-07-15T04:00:01.700774Z"}]}
{"channel":"book","type":"update","data":[{"symbol":"BTC/USD","bids":[{"price":64730.6,"qty":0.00000000},{"price":64728.2,"qty":0.00005100}],"asks":[],"checksum":2252563606,"timestamp":"2026-07-15T04:00:01.704347Z"}]}
{"channel":"book","type":"update","data":[{"symbol":"BTC/USD","bids":[],"asks":[{"price":64739.5,"qty":0.39713569}],"checksum":2460848623,"timestamp":"2026-07-15T04:00:01.706882Z"}]}
{"channel":"book","type":"update","data":[{"symbol":"BTC/USD","bids":[],"asks":[{"price":64742.1,"qty":0.00000000},{"price":64750.8,"qty":0.00005100}],"checksum":1245874567,"timestamp":"2026-07-15T04:00:01.708105Z"}]}
{"channel":"book","type":"update","data":[{"symbol":"BTC/USD","bids":[{"price":64730.8,"qty":0.00000000},{"price":64726.4,"qty":0.03656174}],"asks":[],"checksum":1553794508,"timestamp":"2026-07-15T04:00:01.708612Z"}]}
{"channel":"book","type":"update","data":[{"symbol":"BTC/USD","bids":[],"asks":[{"price":64739.5,"qty":0.00000000},{"price":64751.0,"qty":0.07283598}],"checksum":4152542432,"timestamp":"2026-07-15T04:00:01.711219Z"}]}
{"channel":"book","type":"update","data":[{"symbol":"BTC/USD","bids":[],"asks":[{"price":64738.3,"qty":1.47040010}],"checksum":3585575617,"timestamp":"2026-07-15T04:00:01.713292Z"}]}
{"channel":"book","type":"update","data":[{"symbol":"BTC/USD","bids":[],"asks":[{"price":64739.5,"qty":0.24223054}],"checksum":2831941200,"timestamp":"2026-07-15T04:00:01.713590Z"}]}
{"channel":"book","type":"update","data":[{"symbol":"BTC/USD","bids":[{"price":64734.9,"qty":0.00000000},{"price":64726.0,"qty":0.11000000}],"asks":[],"checksum":2524851908,"timestamp":"2026-07-15T04:00:01.715815Z"}]}
{"channel":"book","type":"update","data":[{"symbol":"BTC/USD","bids":[{"price":64738.1,"qty":0.00000000},{"price":64725.3,"qty":0.10000000}],"asks":[],"checksum":1705494075,"timestamp":"2026-07-15T04:00:01.717916Z"}]}
{"channel":"book","type":"update","data":[{"symbol":"BTC/USD","bids":[],"asks":[{"price":64738.3,"qty":2.24274043}],"checksum":388463154,"timestamp":"2026-07-15T04:00:01.724733Z"}]}
{"channel":"book","type":"update","data":[{"symbol":"BTC/USD","bids":[],"asks":[{"price":64741.9,"qty":0.77229854}],"checksum":3153239439,"timestamp":"2026-07-15T04:00:01.724880Z"}]}
{"channel":"book","type":"update","data":[{"symbol":"BTC/USD","bids":[],"asks":[{"price":64748.4,"qty":2.31666181}],"checksum":2928714359,"timestamp":"2026-07-15T04:00:01.725048Z"}]}
{"channel":"book","type":"update","data":[{"symbol":"BTC/USD","bids":[],"asks":[{"price":64739.5,"qty":0.44179296}],"checksum":918084596,"timestamp":"2026-07-15T04:00:01.730005Z"}]}
{"channel":"book","type":"update","data":[{"symbol":"BTC/USD","bids":[],"asks":[{"price":64738.3,"qty":2.28185719}],"checksum":2370443220,"timestamp":"2026-07-15T04:00:01.732491Z"}]}
{"channel":"book","type":"update","data":[{"symbol":"BTC/USD","bids":[],"asks":[{"price":64740.6,"qty":0.00000000},{"price":64749.2,"qty":0.06037600}],"checksum":211862406,"timestamp":"2026-07-15T04:00:01.732538Z"}]}
{"channel":"book","type":"update","data":[{"symbol":"BTC/USD","bids":[],"asks":[{"price":64738.3,"qty":2.28885719}],"checksum":1915922948,"timestamp":"2026-07-15T04:00:01.757649Z"}]}
{"channel":"book","type":"update","data":[{"symbol":"BTC/USD","bids":[{"price":64734.2,"qty":0.00000000},{"price":64725.1,"qty":0.03089990}],"asks":[],"checksum":2557191995,"timestamp":"2026-07-15T04:00:01.760400Z"}]}
{"channel":"book","type":"update","data":[{"symbol":"BTC/USD","bids":[{"price":64726.4,"qty":0.00000000},{"price":64724.9,"qty":0.40000000}],"asks":[],"checksum":3665456961,"timestamp":"2026-07-15T04:00:01.770192Z"}]}
{"channel":"book","type":"update","data":[{"symbol":"BTC/USD","bids":[{"price":64726.0,"qty":0.00000000},{"price":64723.6,"qty":0.00801086}],"asks":[],"checksum":3716476020,"timestamp":"2026-07-15T04:00:01.798754Z"}]}
{"channel":"book","type":"update","data":[{"symbol":"BTC/USD","bids":[],"asks":[{"price":64748.3,"qty":0.69152355}],"checksum":3233501963,"timestamp":"2026-07-15T04:00:01.799251Z"}]}
{"channel":"book","type":"update","data":[{"symbol":"BTC/USD","bids":[{"price":64738.2,"qty":0.00083430}],"asks":[],"checksum":1018666222,"timestamp":"2026-07-15T04:00:01.806311Z"}]}
{"channel":"book","type":"update","data":[{"symbol":"BTC/USD","bids":[{"price":64738.2,"qty":0.00077235}],"asks":[],"checksum":125922166,"timestamp":"2026-07-15T04:00:01.809395Z"}]}
{"channel":"book","type":"update","data":[{"symbol":"BTC/USD","bids":[{"price":64723.7,"qty":0.03086388}],"asks":[],"checksum":929147351,"timestamp":"2026-07-15T04:00:01.860823Z"}]}
{"channel":"book","type":"update","data":[{"symbol":"BTC/USD","bids":[],"asks":[{"price":64738.3,"qty":2.39885719}],"checksum":3081515734,"timestamp":"2026-07-15T04:00:01.897932Z"}]}
{"channel":"book","type":"update","data":[{"symbol":"BTC/USD","bids":[{"price":64725.2,"qty":0.14022773}],"asks":[],"checksum":1683948906,"timestamp":"2026-07-15T04:00:01.910433Z"}]}
{"channel":"book","type":"update","data":[{"symbol":"BTC/USD","bids":[{"price":64726.4,"qty":0.00154497}],"asks":[],"checksum":2871570989,"timestamp":"2026-07-15T04:00:02.000252Z"}]}
{"channel":"book","type":"update","data":[{"symbol":"BTC/USD","bids":[],"asks":[{"price":64738.3,"qty":2.40040188}],"checksum":423744329,"timestamp":"2026-07-15T04:00:02.000460Z"}]}
{"channel":"book","type":"update","data":[{"symbol":"BTC/USD","bids":[{"price":64738.2,"qty":0.03389534}],"asks":[],"checksum":2553962316,"timestamp":"2026-07-15T04:00:02.043126Z"}]}
{"channel":"book","type":"update","data":[{"symbol":"BTC/USD","bids":[{"price":64738.2,"qty":0.03395256}],"asks":[],"checksum":2167396001,"timestamp":"2026-07-15T04:00:02.050033Z"}]}
{"channel":"book","type":"update","data":[{"symbol":"BTC/USD","bids":[{"price":64725.2,"qty":0.00000000},{"price":64724.9,"qty":0.40000000}],"asks":[],"checksum":192848950,"timestamp":"2026-07-15T04:00:02.070348Z"}]}
{"channel":"book","type":"update","data":[{"symbol":"BTC/USD","bids":[{"price":64725.0,"qty":0.27920143}],"asks":[],"checksum":3938431611,"timestamp":"2026-07-15T04:00:02.070508Z"}]}
{"channel":"book","type":"update","data":[{"symbol":"BTC/USD","bids":[{"price":64725.0,"qty":0.00000000},{"price":64724.9,"qty":0.40000000}],"asks":[],"checksum":192848950,"timestamp":"2026-07-15T04:00:02.096382Z"}]}
{"channel":"book","type":"update","data":[{"symbol":"BTC/USD","bids":[{"price":64725.0,"qty":0.13100411}],"asks":[],"checksum":2472417028,"timestamp":"2026-07-15T04:00:02.096847Z"}]}
{"channel":"book","type":"update","data":[{"symbol":"BTC/USD","bids":[{"price":64725.4,"qty":0.77249316}],"asks":[],"checksum":1004468663,"timestamp":"2026-07-15T04:00:02.222478Z"}]}
{"channel":"book","type":"update","data":[{"symbol":"BTC/USD","bids":[{"price":64725.5,"qty":0.38906283}],"asks":[],"checksum":1781830074,"timestamp":"2026-07-15T04:00:02.223949Z"}]}
{"channel":"heartbeat"}
{"channel":"book","type":"update","data":[{"symbol":"BTC/USD","bids":[{"price":64731.6,"qty":0.01400000}],"asks":[],"checksum":444987919,"timestamp":"2026-07-15T04:00:02.311326Z"}]}
{"channel":"book","type":"update","data":[{"symbol":"BTC/USD","bids":[{"price":64726.5,"qty":0.03086388}],"asks":[],"checksum":2191991956,"timestamp":"2026-07-15T04:00:02.834871Z"}]}
{"channel":"book","type":"update","data":[{"symbol":"BTC/USD","bids":[{"price":64726.1,"qty":0.77248585}],"asks":[],"checksum":3586793992,"timestamp":"2026-07-15T04:00:02.936018Z"}]}
{"channel":"book","type":"update","data":[{"symbol":"BTC/USD","bids":[],"asks":[{"price":64738.3,"qty":2.34220188}],"checksum":1804970162,"timestamp":"2026-07-15T04:00:02.937491Z"}]}
{"channel":"book","type":"update","data":[{"symbol":"BTC/USD","bids":[{"price":64726.2,"qty":0.38906065}],"asks":[],"checksum":3351913521,"timestamp":"2026-07-15T04:00:02.977093Z"}]}
{"channel":"book","type":"update","data":[{"symbol":"BTC/USD","bids":[{"price":64726.4,"qty":0.00000000},{"price":64726.1,"qty":0.77248585}],"asks":[],"checksum":334086945,"timestamp":"2026-07-15T04:00:03.101737Z"}]}
{"channel":"book","type":"update","data":[{"symbol":"BTC/USD","bids":[{"price":64728.8,"qty":0.00154491}],"asks":[],"checksum":1314097273,"timestamp":"2026-07-15T04:00:03.101794Z"}]}
{"channel":"book","type":"update","data":[{"symbol":"BTC/USD","bids":[{"price":64726.5,"qty":0.00000000},{"price":64726.1,"qty":0.77248585},{"price":64726.3,"qty":0.03086388}],"asks":[],"checksum":1017303801,"timestamp":"2026-07-15T04:00:03.103391Z"}]}
{"channel":"heartbeat"}
{"channel":"book","type":"update","data":[{"symbol":"BTC/USD","bids":[{"price":64728.2,"qty":0.01409824}],"asks":[],"checksum":2532206458,"timestamp":"2026-07-15T04:00:03.343666Z"}]}
{"channel":"book","type":"update","data":[{"symbol":"BTC/USD","bids":[],"asks":[{"price":64738.3,"qty":2.35624693}],"checksum":2828954964,"timestamp":"2026-07-15T04:00:03.343942Z"}]}
{"channel":"book","type":"update","data":[{"symbol":"BTC/USD","bids":[],"asks":[{"price":64738.3,"qty":2.34220188}],"checksum":2532206458,"timestamp":"2026-07-15T04:00:03.345127Z"}]}
{"channel":"book","type":"update","data":[{"symbol":"BTC/USD","bids":[],"asks":[{"price":64738.3,"qty":2.35624370}],"checksum":827882819,"timestamp":"2026-07-15T04:00:03.654676Z"}]}
{"channel":"book","type":"update","data":[{"symbol":"BTC/USD","bids":[],"asks":[{"price":64738.3,"qty":2.34220188}],"checksum":2532206458,"timestamp":"2026-07-15T04:00:03.655876Z"}]}
{"channel":"book","type":"update","data":[{"symbol":"BTC/USD","bids":[],"asks":[{"price":64738.3,"qty":2.35624370}],"checksum":827882819,"timestamp":"2026-07-15T04:00:03.804893Z"}]}
{"channel":"book","type":"update","data":[{"symbol":"BTC/USD","bids":[],"asks":[{"price":64738.3,"qty":2.34220188}],"checksum":2532206458,"timestamp":"2026-07-15T04:00:03.806121Z"}]}
{"channel":"book","type":"update","data":[{"symbol":"BTC/USD","bids":[{"price":64726.9,"qty":0.03656174}],"asks":[],"checksum":2942414338,"timestamp":"2026-07-15T04:00:03.906050Z"}]}
{"channel":"book","type":"update","data":[{"symbol":"BTC/USD","bids":[],"asks":[{"price":64738.3,"qty":2.35624190}],"checksum":2289294414,"timestamp":"2026-07-15T04:00:03.947549Z"}]}
{"channel":"book","type":"update","data":[{"symbol":"BTC/USD","bids":[],"asks":[{"price":64738.3,"qty":2.34220188}],"checksum":2942414338,"timestamp":"2026-07-15T04:00:03.948916Z"}]}
{"channel":"book","type":"update","data":[{"symbol":"BTC/USD","bids":[],"asks":[{"price":64738.3,"qty":2.35628337}],"checksum":3767605888,"timestamp":"2026-07-15T04:00:04.011267Z"}]}
{"channel":"book","type":"update","data":[{"symbol":"BTC/USD","bids":[],"asks":[{"price":64738.3,"qty":2.34220188}],"checksum":2942414338,"timestamp":"2026-07-15T04:00:04.012644Z"}]}
{"channel":"book","type":"update","data":[{"symbol":"BTC/USD","bids":[{"price":64726.3,"qty":0.21554404}],"asks":[],"checksum":3504353867,"timestamp":"2026-07-15T04:00:04.183146Z"}]}
{"channel":"book","type":"update","data":[{"symbol":"BTC/USD","bids":[{"price":64726.3,"qty":0.18468016},{"price":64726.4,"qty":0.03086388}],"asks":[],"checksum":2779031323,"timestamp":"2026-07-15T04:00:04.184367Z"}]}
{"channel":"book","type":"update","data":[{"symbol":"BTC/USD","bids":[{"price":64727.0,"qty":0.02012655}],"asks":[],"checksum":2024380362,"timestamp":"2026-07-15T04:00:04.185964Z"}]}
{"channel":"heartbeat"}
{"channel":"book","type":"update","data":[{"symbol":"BTC/USD","bids":[],"asks":[{"price":64738.3,"qty":2.35625262}],"checksum":2345344768,"timestamp":"2026-07-15T04:00:04.948697Z"}]}
{"channel":"book","type":"update","data":[{"symbol":"BTC/USD","bids":[],"asks":[{"price":64738.3,"qty":2.34220188}],"checksum":2024380362,"timestamp":"2026-07-15T04:00:04.948933Z"}]}
{"channel":"book","type":"update","data":[{"symbol":"BTC/USD","bids":[{"price":64727.0,"qty":0.24813797}],"asks":[],"checksum":1507801873,"timestamp":"2026-07-15T04:00:04.950198Z"}]}
{"channel":"book","type":"update","data":[{"symbol":"BTC/USD","bids":[{"price":64728.8,"qty":0.00000000},{"price":64726.8,"qty":0.21554404}],"asks":[],"checksum":1360230528,"timestamp":"2026-07-15T04:00:04.956818Z"}]}
{"channel":"book","type":"update","data":[{"symbol":"BTC/USD","bids":[],"asks":[{"price":64746.7,"qty":0.01544480}],"checksum":375383738,"timestamp":"2026-07-15T04:00:05.020833Z"}]}
{"channel":"book","type":"update","data":[{"symbol":"BTC/USD","bids":[{"price":64726.8,"qty":0.03086388}],"asks":[],"checksum":476900664,"timestamp":"2026-07-15T04:00:05.021700Z"}]}
{"channel":"book","type":"update","data":[{"symbol":"BTC/USD","bids":[],"asks":[{"price":64746.7,"qty":0.03088960}],"checksum":1920931827,"timestamp":"2026-07-15T04:00:05.022944Z"}]}
{"channel":"book","type":"update","data":[{"symbol":"BTC/USD","bids":[],"asks":[{"price":64738.3,"qty":2.30308512}],"checksum":581774309,"timestamp":"2026-07-15T04:00:05.190581Z"}]}
{"channel":"book","type":"update","data":[{"symbol":"BTC/USD","bids":[{"price":64730.3,"qty":0.03656174}],"asks":[],"checksum":3028356056,"timestamp":"2026-07-15T04:00:05.190693Z"}]}
{"channel":"book","type":"update","data":[{"symbol":"BTC/USD","bids":[{"price":64726.9,"qty":0.00000000},{"price":64726.8,"qty":0.03086388}],"asks":[],"checksum":3678972000,"timestamp":"2026-07-15T04:00:05.190745Z"}]}
{"channel":"book","type":"update","data":[{"symbol":"BTC/USD","bids":[],"asks":[{"price":64743.7,"qty":0.03911676}],"checksum":3194937691,"timestamp":"2026-07-15T04:00:05.191699Z"}]}
{"channel":"book","type":"update","data":[{"symbol":"BTC/USD","bids":[{"price":64727.0,"qty":0.02012655}],"asks":[],"checksum":1732452522,"timestamp":"2026-07-15T04:00:05.200155Z"}]}
{"channel":"book","type":"update","data":[{"symbol":"BTC/USD","bids":[{"price":64727.0,"qty":0.00000000},{"price":64726.2,"qty":0.38906065}],"asks":[],"checksum":2662176200,"timestamp":"2026-07-15T04:00:05.200540Z"}]}
{"channel":"book","type":"update","data":[{"symbol":"BTC/USD","bids":[{"price":64726.8,"qty":0.00000000},{"price":64726.0,"qty":0.77248709},{"price":64726.3,"qty":0.03086388}],"asks":[],"checksum":513154696,"timestamp":"2026-07-15T04:00:05.201304Z"}]}
{"channel":"book","type":"update","data":[{"symbol":"BTC/USD","bids":[{"price":64726.2,"qty":0.72481936}],"asks":[],"checksum":3292180970,"timestamp":"2026-07-15T04:00:05.205077Z"}]}
{"channel":"trade","type":"update","data":[{"symbol":"BTC/USD","side":"buy","price":64738.3,"qty":0.00772340,"ord_type":"limit","trade_id":103746776,"timestamp":"2026-07-15T04:00:05.205814Z"}]}
{"channel":"book","type":"update","data":[{"symbol":"BTC/USD","bids":[],"asks":[{"price":64738.3,"qty":2.29536172}],"checksum":3449074029,"timestamp":"2026-07-15T04:00:05.205814Z"}]}
{"channel":"heartbeat"}
{"channel":"book","type":"update","data":[{"symbol":"BTC/USD","bids":[{"price":64726.2,"qty":0.38906065}],"asks":[],"checksum":389553679,"timestamp":"2026-07-15T04:00:05.507614Z"}]}
{"channel":"book","type":"update","data":[{"symbol":"BTC/USD","bids":[],"asks":[{"price":64743.7,"qty":0.00000000},{"price":64748.3,"qty":0.69152355}],"checksum":140898096,"timestamp":"2026-07-15T04:00:05.568739Z"}]}
{"channel":"book","type":"update","data":[{"symbol":"BTC/USD","bids":[],"asks":[{"price":64739.3,"qty":0.03911676}],"checksum":1419861701,"timestamp":"2026-07-15T04:00:05.568794Z"}]}
{"channel":"book","type":"update","data":[{"symbol":"BTC/USD","bids":[{"price":64730.3,"qty":0.00000000},{"price":64725.6,"qty":0.77249130}],"asks":[],"checksum":1241717677,"timestamp":"2026-07-15T04:00:05.758175Z"}]}
{"channel":"book","type":"update","data":[{"symbol":"BTC/USD","bids":[{"price":64726.9,"qty":0.03656174}],"asks":[],"checksum":351338792,"timestamp":"2026-07-15T04:00:05.761112Z"}]}
{"channel":"book","type":"update","data":[{"symbol":"BTC/USD","bids":[{"price":64726.3,"qty":0.00000000},{"price":64725.6,"qty":0.77249130},{"price":64726.9,"qty":0.06742562}],"asks":[],"checksum":1252687618,"timestamp":"2026-07-15T04:00:05.764495Z"}]}
{"channel":"book","type":"update","data":[{"symbol":"BTC/USD","bids":[{"price":64727.0,"qty":0.02012655}],"asks":[],"checksum":3738581645,"timestamp":"2026-07-15T04:00:05.766087Z"}]}
{"channel":"book","type":"update","data":[{"symbol":"BTC/USD","bids":[{"price":64728.2,"qty":0.00005100}],"asks":[],"checksum":3063356812,"timestamp":"2026-07-15T04:00:05.769454Z"}]}
{"channel":"trade","type":"update","data":[{"symbol":"BTC/USD","side":"buy","price":64738.3,"qty":0.00075720,"ord_type":"limit","trade_id":103746777,"timestamp":"2026-07-15T04:00:06.088663Z"}]}
{"channel":"book","type":"update","data":[{"symbol":"BTC/USD","bids":[],"asks":[{"price":64738.3,"qty":2.29460452}],"checksum":1975013167,"timestamp":"2026-07-15T04:00:06.088663Z"}]}
{"channel":"book","type":"update","data":[{"symbol":"BTC/USD","bids":[{"price":64726.8,"qty":0.51894522}],"asks":[],"checksum":602366710,"timestamp":"2026-07-15T04:00:06.193864Z"}]}
{"channel":"book","type":"update","data":[{"symbol":"BTC/USD","bids":[{"price":64727.0,"qty":0.03453803}],"asks":[],"checksum":589521789,"timestamp":"2026-07-15T04:00:06.277206Z"}]}
{"channel":"book","type":"update","data":[{"symbol":"BTC/USD","bids":[],"asks":[{"price":64738.3,"qty":2.30901348}],"checksum":1674055493,"timestamp":"2026-07-15T04:00:06.277522Z"}]}
{"channel":"book","type":"update","data":[{"symbol":"BTC/USD","bids":[],"asks":[{"price":64738.3,"qty":2.29460452}],"checksum":589521789,"timestamp":"2026-07-15T04:00:06.278481Z"}]}
{"channel":"heartbeat"}
{"channel":"book","type":"update","data":[{"symbol":"BTC/USD","bids":[],"asks":[{"price":64738.3,"qty":2.28750260}],"checksum":4171722099,"timestamp":"2026-07-15T04:00:06.368203Z"}]}
{"channel":"book","type":"update","data":[{"symbol":"BTC/USD","bids":[],"asks":[{"price":64738.3,"qty":2.30172189}],"checksum":2779293950,"timestamp":"2026-07-15T04:00:06.369671Z"}]}
{"channel":"book","type":"update","data":[{"symbol":"BTC/USD","bids":[],"asks":[{"price":64738.3,"qty":2.28750260}],"checksum":4171722099,"timestamp":"2026-07-15T04:00:06.370919Z"}]}
{"channel":"book","type":"update","data":[{"symbol":"BTC/USD","bids":[],"asks":[{"price":64738.3,"qty":2.29460452}],"checksum":589521789,"timestamp":"2026-07-15T04:00:06.372934Z"}]}
{"channel":"book","type":"update","data":[{"symbol":"BTC/USD","bids":[],"asks":[{"price":64738.3,"qty":2.28750260}],"checksum":4171722099,"timestamp":"2026-07-15T04:00:06.375218Z"}]}
{"channel":"book","type":"update","data":[{"symbol":"BTC/USD","bids":[],"asks":[{"price":64738.3,"qty":2.30173209}],"checksum":2131361281,"timestamp":"2026-07-15T04:00:06.507969Z"}]}
{"channel":"book","type":"update","data":[{"symbol":"BTC/USD","bids":[],"asks":[{"price":64738.3,"qty":2.28750260}],"checksum":4171722099,"timestamp":"2026-07-15T04:00:06.509347Z"}]}
{"channel":"book","type":"update","data":[{"symbol":"BTC/USD","bids":[],"asks":[{"price":64738.3,"qty":2.29460452}],"checksum":589521789,"timestamp":"2026-07-15T04:00:06.511548Z"}]}
{"channel":"book","type":"update","data":[{"symbol":"BTC/USD","bids":[],"asks":[{"price":64738.3,"qty":2.28750260}],"checksum":4171722099,"timestamp":"2026-07-15T04:00:06.514022Z"}]}
{"channel":"book","type":"update","data":[{"symbol":"BTC/USD","bids":[],"asks":[{"price":64738.3,"qty":2.30173209}],"checksum":2131361281,"timestamp":"2026-07-15T04:00:06.558152Z"}]}
{"channel":"book","type":"update","data":[{"symbol":"BTC/USD","bids":[],"asks":[{"price":64738.3,"qty":2.28750260}],"checksum":4171722099,"timestamp":"2026-07-15T04:00:06.562223Z"}]}
{"channel":"book","type":"update","data":[{"symbol":"BTC/USD","bids":[],"asks":[{"price":64738.3,"qty":2.29460452}],"checksum":589521789,"timestamp":"2026-07-15T04:00:06.562611Z"}]}
{"channel":"book","type":"update","data":[{"symbol":"BTC/USD","bids":[],"asks":[{"price":64738.3,"qty":2.28750260}],"checksum":4171722099,"timestamp":"2026-07-15T04:00:06.565530Z"}]}
{"channel":"book","type":"update","data":[{"symbol":"BTC/USD","bids":[],"asks":[{"price":64738.3,"qty":2.30173209}],"checksum":2131361281,"timestamp":"2026-07-15T04:00:06.600837Z"}]}
{"channel":"book","type":"update","data":[{"symbol":"BTC/USD","bids":[{"price":64728.5,"qty":0.00154492}],"asks":[],"checksum":404594987,"timestamp":"2026-07-15T04:00:06.601007Z"}]}
{"channel":"book","type":"update","data":[{"symbol":"BTC/USD","bids":[],"asks":[{"price":64738.3,"qty":2.28750260}],"checksum":2498385806,"timestamp":"2026-07-15T04:00:06.602007Z"}]}
{"channel":"book","type":"update","data":[{"symbol":"BTC/USD","bids":[],"asks":[{"price":64738.3,"qty":2.29460452}],"checksum":3862208552,"timestamp":"2026-07-15T04:00:06.604213Z"}]}
{"channel":"book","type":"update","data":[{"symbol":"BTC/USD","bids":[],"asks":[{"price":64738.3,"qty":2.28750260}],"checksum":2498385806,"timestamp":"2026-07-15T04:00:06.607476Z"}]}
{"channel":"book","type":"update","data":[{"symbol":"BTC/USD","bids":[],"asks":[{"price":64738.3,"qty":2.30169361}],"checksum":1841607871,"timestamp":"2026-07-15T04:00:06.639947Z"}]}
{"channel":"book","type":"update","data":[{"symbol":"BTC/USD","bids":[],"asks":[{"price":64738.3,"qty":2.28750260}],"checksum":2498385806,"timestamp":"2026-07-15T04:00:06.641255Z"}]}
{"channel":"book","type":"update","data":[{"symbol":"BTC/USD","bids":[],"asks":[{"price":64738.3,"qty":2.29460452}],"checksum":3862208552,"timestamp":"2026-07-15T04:00:06.643417Z"}]}
{"channel":"book","type":"update","data":[{"symbol":"BTC/USD","bids":[],"asks":[{"price":64738.3,"qty":2.28750260}],"checksum":2498385806,"timestamp":"2026-07-15T04:00:06.646054Z"}]}
{"channel":"book","type":"update","data":[{"symbol":"BTC/USD","bids":[],"asks":[{"price":64738.3,"qty":2.30169361}],"checksum":1841607871,"timestamp":"2026-07-15T04:00:06.805206Z"}]}
{"channel":"book","type":"update","data":[{"symbol":"BTC/USD","bids":[],"asks":[{"price":64738.3,"qty":2.28750260}],"checksum":2498385806,"timestamp":"2026-07-15T04:00:06.806826Z"}]}
{"channel":"book","type":"update","data":[{"symbol":"BTC/USD","bids":[],"asks":[{"price":64742.3,"qty":0.06054267}],"checksum":712731369,"timestamp":"2026-07-15T04:00:07.113437Z"}]}
{"channel":"book","type":"update","data":[{"symbol":"BTC/USD","bids":[],"asks":[{"price":64738.3,"qty":2.30164237}],"checksum":2322036787,"timestamp":"2026-07-15T04:00:07.191541Z"}]}
{"channel":"book","type":"update","data":[{"symbol":"BTC/USD","bids":[],"asks":[{"price":64738.3,"qty":2.28750260}],"checksum":712731369,"timestamp":"2026-07-15T04:00:07.193135Z"}]}
{"channel":"book","type":"update","data":[{"symbol":"BTC/USD","bids":[],"asks":[{"price":64738.3,"qty":2.30163015}],"checksum":4197677462,"timestamp":"2026-07-15T04:00:07.241167Z"}]}
{"channel":"book","type":"update","data":[{"symbol":"BTC/USD","bids":[],"asks":[{"price":64738.3,"qty":2.28750260}],"checksum":712731369,"timestamp":"2026-07-15T04:00:07.242606Z"}]}
{"channel":"heartbeat"}
{"channel":"book","type":"update","data":[{"symbol":"BTC/USD","bids":[],"asks":[{"price":64738.3,"qty":2.30163015}],"checksum":4197677462,"timestamp":"2026-07-15T04:00:07.367196Z"}]}
{"channel":"book","type":"update","data":[{"symbol":"BTC/USD","bids":[],"asks":[{"price":64738.3,"qty":2.28750260}],"checksum":712731369,"timestamp":"2026-07-15T04:00:07.368450Z"}]}
{"channel":"book","type":"update","data":[{"symbol":"BTC/USD","bids":[],"asks":[{"price":64738.3,"qty":2.30176432}],"checksum":1967251440,"timestamp":"2026-07-15T04:00:07.643129Z"}]}
{"channel":"book","type":"update","data":[{"symbol":"BTC/USD","bids":[],"asks":[{"price":64738.3,"qty":2.28750260}],"checksum":712731369,"timestamp":"2026-07-15T04:00:07.644484Z"}]}
{"channel":"book","type":"update","data":[{"symbol":"BTC/USD","bids":[{"price":64727.0,"qty":0.39904771}],"asks":[],"checksum":3319689780,"timestamp":"2026-07-15T04:00:07.715047Z"}]}
{"channel":"book","type":"update","data":[{"symbol":"BTC/USD","bids":[],"asks":[{"price":64738.3,"qty":2.30176895}],"checksum":1377831081,"timestamp":"2026-07-15T04:00:07.867848Z"}]}
{"channel":"book","type":"update","data":[{"symbol":"BTC/USD","bids":[],"asks":[{"price":64738.3,"qty":2.28750260}],"checksum":3319689780,"timestamp":"2026-07-15T04:00:07.869027Z"}]}
{"channel":"book","type":"update","data":[{"symbol":"BTC/USD","bids":[],"asks":[{"price":64738.3,"qty":2.30176895}],"checksum":1377831081,"timestamp":"2026-07-15T04:00:07.869426Z"}]}
{"channel":"book","type":"update","data":[{"symbol":"BTC/USD","bids":[],"asks":[{"price":64738.3,"qty":2.28750260}],"checksum":3319689780,"timestamp":"2026-07-15T04:00:07.870183Z"}]}
{"channel":"book","type":"update","data":[{"symbol":"BTC/USD","bids":[],"asks":[{"price":64738.3,"qty":2.30176895}],"checksum":1377831081,"timestamp":"2026-07-15T04:00:07.920154Z"}]}
{"channel":"book","type":"update","data":[{"symbol":"BTC/USD","bids":[],"asks":[{"price":64738.3,"qty":2.28750260}],"checksum":3319689780,"timestamp":"2026-07-15T04:00:07.920561Z"}]}
{"channel":"book","type":"update","data":[{"symbol":"BTC/USD","bids":[],"asks":[{"price":64738.3,"qty":2.30177107}],"checksum":3145921750,"timestamp":"2026-07-15T04:00:08.074063Z"}]}
{"channel":"book","type":"update","data":[{"symbol":"BTC/USD","bids":[],"asks":[{"price":64738.3,"qty":2.28750260}],"checksum":3319689780,"timestamp":"2026-07-15T04:00:08.075361Z"}]}
{"channel":"book","type":"update","data":[{"symbol":"BTC/USD","bids":[],"asks":[{"price":64738.3,"qty":2.30177107}],"checksum":3145921750,"timestamp":"2026-07-15T04:00:08.075623Z"}]}
{"channel":"book","type":"update","data":[{"symbol":"BTC/USD","bids":[],"asks":[{"price":64738.3,"qty":2.28750260}],"checksum":3319689780,"timestamp":"2026-07-15T04:00:08.076700Z"}]}
{"channel":"heartbeat"}
{"channel":"trade","type":"update","data":[{"symbol":"BTC/USD","side":"buy","price":64738.3,"qty":0.00030288,"ord_type":"limit","trade_id":103746778,"timestamp":"2026-07-15T04:00:08.319470Z"}]}
{"channel":"book","type":"update","data":[{"symbol":"BTC/USD","bids":[],"asks":[{"price":64738.3,"qty":2.28719972}],"checksum":2241557620,"timestamp":"2026-07-15T04:00:08.319470Z"}]}
{"channel":"book","type":"update","data":[{"symbol":"BTC/USD","bids":[{"price":64726.9,"qty":0.03656174},{"price":64727.0,"qty":0.42991159}],"asks":[],"checksum":3338282299,"timestamp":"2026-07-15T04:00:08.320984Z"}]}
{"channel":"trade","type":"update","data":[{"symbol":"BTC/USD","side":"buy","price":64738.3,"qty":0.00151439,"ord_type":"limit","trade_id":103746779,"timestamp":"2026-07-15T04:00:08.325216Z"}]}
{"channel":"book","type":"update","data":[{"symbol":"BTC/USD","bids":[],"asks":[{"price":64738.3,"qty":2.28568533}],"checksum":2621902289,"timestamp":"2026-07-15T04:00:08.325216Z"}]}
{"channel":"trade","type":"update","data":[{"symbol":"BTC/USD","side":"buy","price":64738.3,"qty":0.00075720,"ord_type":"limit","trade_id":103746780,"timestamp":"2026-07-15T04:00:08.325738Z"}]}
{"channel":"book","type":"update","data":[{"symbol":"BTC/USD","bids":[],"asks":[{"price":64738.3,"qty":2.28492813}],"checksum":2023589234,"timestamp":"2026-07-15T04:00:08.325738Z"}]}
{"channel":"book","type":"update","data":[{"symbol":"BTC/USD","bids":[],"asks":[{"price":64738.3,"qty":2.29911305}],"checksum":4033346550,"timestamp":"2026-07-15T04:00:08.387262Z"}]}
{"channel":"book","type":"update","data":[{"symbol":"BTC/USD","bids":[],"asks":[{"price":64738.3,"qty":2.28492813}],"checksum":2023589234,"timestamp":"2026-07-15T04:00:08.388465Z"}]}
{"channel":"book","type":"update","data":[{"symbol":"BTC/USD","bids":[],"asks":[{"price":64738.3,"qty":2.29909350}],"checksum":1443218362,"timestamp":"2026-07-15T04:00:08.581291Z"}]}
{"channel":"book","type":"update","data":[{"symbol":"BTC/USD","bids":[],"asks":[{"price":64738.3,"qty":2.28492813}],"checksum":2023589234,"timestamp":"2026-07-15T04:00:08.582456Z"}]}
{"channel":"book","type":"update","data":[{"symbol":"BTC/USD","bids":[],"asks":[{"price":64738.3,"qty":2.29909350}],"checksum":1443218362,"timestamp":"2026-07-15T04:00:08.582814Z"}]}
{"channel":"book","type":"update","data":[{"symbol":"BTC/USD","bids":[],"asks":[{"price":64738.3,"qty":2.28492813}],"checksum":2023589234,"timestamp":"2026-07-15T04:00:08.584275Z"}]}
{"channel":"book","type":"update","data":[{"symbol":"BTC/USD","bids":[],"asks":[{"price":64738.3,"qty":2.29917603}],"checksum":2804937701,"timestamp":"2026-07-15T04:00:08.756268Z"}]}
{"channel":"book","type":"update","data":[{"symbol":"BTC/USD","bids":[],"asks":[{"price":64738.3,"qty":2.28492813}],"checksum":2023589234,"timestamp":"2026-07-15T04:00:08.758541Z"}]}
{"channel":"book","type":"update","data":[{"symbol":"BTC/USD","bids":[],"asks":[{"price":64738.3,"qty":2.29917603}],"checksum":2804937701,"timestamp":"2026-07-15T04:00:08.759153Z"}]}
{"channel":"book","type":"update","data":[{"symbol":"BTC/USD","bids":[],"asks":[{"price":64738.3,"qty":2.28492813}],"checksum":2023589234,"timestamp":"2026-07-15T04:00:08.759885Z"}]}
{"channel":"book","type":"update","data":[{"symbol":"BTC/USD","bids":[],"asks":[{"price":64738.3,"qty":2.29917603}],"checksum":2804937701,"timestamp":"2026-07-15T04:00:08.759998Z"}]}
{"channel":"book","type":"update","data":[{"symbol":"BTC/USD","bids":[],"asks":[{"price":64738.3,"qty":2.28492813}],"checksum":2023589234,"timestamp":"2026-07-15T04:00:08.760786Z"}]}
{"channel":"book","type":"update","data":[{"symbol":"BTC/USD","bids":[],"asks":[{"price":64738.3,"qty":2.29917603}],"checksum":2804937701,"timestamp":"2026-07-15T04:00:08.761142Z"}]}
{"channel":"book","type":"update","data":[{"symbol":"BTC/USD","bids":[],"asks":[{"price":64738.3,"qty":2.28492813}],"checksum":2023589234,"timestamp":"2026-07-15T04:00:08.761430Z"}]}
{"channel":"book","type":"update","data":[{"symbol":"BTC/USD","bids":[],"asks":[{"price":64738.3,"qty":2.29914337}],"checksum":311938588,"timestamp":"2026-07-15T04:00:08.887850Z"}]}
{"channel":"book","type":"update","data":[{"symbol":"BTC/USD","bids":[],"asks":[{"price":64738.3,"qty":2.28492813}],"checksum":2023589234,"timestamp":"2026-07-15T04:00:08.889153Z"}]}
{"channel":"book","type":"update","data":[{"symbol":"BTC/USD","bids":[],"asks":[{"price":64738.3,"qty":2.29914337}],"checksum":311938588,"timestamp":"2026-07-15T04:00:08.889548Z"}]}
{"channel":"book","type":"update","data":[{"symbol":"BTC/USD","bids":[],"asks":[{"price":64738.3,"qty":2.28492813}],"checksum":2023589234,"timestamp":"2026-07-15T04:00:08.890533Z"}]}
{"channel":"trade","type":"update","data":[{"symbol":"BTC/USD","side":"buy","price":64738.3,"qty":0.00030288,"ord_type":"limit","trade_id":103746781,"timestamp":"2026-07-15T04:00:08.933111Z"}]}
{"channel":"book","type":"update","data":[{"symbol":"BTC/USD","bids":[],"asks":[{"price":64738.3,"qty":2.28462525}],"checksum":1743519858,"timestamp":"2026-07-15T04:00:08.933111Z"}]}
{"channel":"book","type":"update","data":[{"symbol":"BTC/USD","bids":[],"asks":[{"price":64738.3,"qty":2.29890003}],"checksum":3264899871,"timestamp":"2026-07-15T04:00:08.934944Z"}]}
{"channel":"book","type":"update","data":[{"symbol":"BTC/USD","bids":[],"asks":[{"price":64738.3,"qty":2.28462525}],"checksum":1743519858,"timestamp":"2026-07-15T04:00:08.935292Z"}]}
{"channel":"trade","type":"update","data":[{"symbol":"BTC/USD","side":"buy","price":64738.3,"qty":0.00151439,"ord_type":"limit","trade_id":103746782,"timestamp":"2026-07-15T04:00:08.946683Z"}]}
{"channel":"book","type":"update","data":[{"symbol":"BTC/USD","bids":[],"asks":[{"price":64738.3,"qty":2.28311086}],"checksum":2930711856,"timestamp":"2026-07-15T04:00:08.946683Z"}]}
{"channel":"trade","type":"update","data":[{"symbol":"BTC/USD","side":"buy","price":64738.3,"qty":0.00015144,"ord_type":"limit","trade_id":103746783,"timestamp":"2026-07-15T04:00:08.952278Z"}]}
{"channel":"book","type":"update","data":[{"symbol":"BTC/USD","bids":[],"asks":[{"price":64738.3,"qty":2.28295942}],"checksum":1786970773,"timestamp":"2026-07-15T04:00:08.952278Z"}]}
{"channel":"book","type":"update","data":[{"symbol":"BTC/USD","bids":[],"asks":[{"price":64738.3,"qty":2.29728183}],"checksum":363698120,"timestamp":"2026-07-15T04:00:09.075316Z"}]}
{"channel":"book","type":"update","data":[{"symbol":"BTC/USD","bids":[],"asks":[{"price":64738.3,"qty":2.28295942}],"checksum":1786970773,"timestamp":"2026-07-15T04:00:09.076191Z"}]}
{"channel":"book","type":"update","data":[{"symbol":"BTC/USD","bids":[],"asks":[{"price":64738.3,"qty":2.29728183}],"checksum":363698120,"timestamp":"2026-07-15T04:00:09.076448Z"}]}
{"channel":"book","type":"update","data":[{"symbol":"BTC/USD","bids":[],"asks":[{"price":64738.3,"qty":2.28295942}],"checksum":1786970773,"timestamp":"2026-07-15T04:00:09.079350Z"}]}
{"channel":"book","type":"update","data":[{"symbol":"BTC/USD","bids":[],"asks":[{"price":64738.3,"qty":2.29728183}],"checksum":363698120,"timestamp":"2026-07-15T04:00:09.080079Z"}]}
{"channel":"book","type":"update","data":[{"symbol":"BTC/USD","bids":[],"asks":[{"price":64738.3,"qty":2.28295942}],"checksum":1786970773,"timestamp":"2026-07-15T04:00:09.081069Z"}]}
{"channel":"book","type":"update","data":[{"symbol":"BTC/USD","bids":[{"price":64727.0,"qty":0.06540191}],"asks":[],"checksum":2742598747,"timestamp":"2026-07-15T04:00:09.121392Z"}]}
{"channel":"book","type":"update","data":[{"symbol":"BTC/USD","bids":[{"price":64727.0,"qty":0.04527536}],"asks":[],"checksum":2443940168,"timestamp":"2026-07-15T04:00:09.121582Z"}]}
{"channel":"book","type":"update","data":[{"symbol":"BTC/USD","bids":[{"price":64727.1,"qty":0.77247385}],"asks":[],"checksum":1325196781,"timestamp":"2026-07-15T04:00:09.121822Z"}]}
{"channel":"book","type":"update","data":[{"symbol":"BTC/USD","bids":[],"asks":[{"price":64738.3,"qty":2.29728023}],"checksum":2990535146,"timestamp":"2026-07-15T04:00:09.122890Z"}]}
{"channel":"book","type":"update","data":[{"symbol":"BTC/USD","bids":[],"asks":[{"price":64738.3,"qty":2.28295942}],"checksum":1325196781,"timestamp":"2026-07-15T04:00:09.123311Z"}]}
{"channel":"book","type":"update","data":[{"symbol":"BTC/USD","bids":[{"price":64727.0,"qty":0.03086388}],"asks":[],"checksum":693878122,"timestamp":"2026-07-15T04:00:09.180079Z"}]}
{"channel":"book","type":"update","data":[{"symbol":"BTC/USD","bids":[{"price":64728.2,"qty":0.01450937}],"asks":[],"checksum":4017413020,"timestamp":"2026-07-15T04:00:09.180429Z"}]}
{"channel":"book","type":"update","data":[{"symbol":"BTC/USD","bids":[],"asks":[{"price":64738.3,"qty":2.29741554}],"checksum":2037834098,"timestamp":"2026-07-15T04:00:09.180641Z"}]}
{"channel":"book","type":"update","data":[{"symbol":"BTC/USD","bids":[],"asks":[{"price":64738.3,"qty":2.28295942}],"checksum":4017413020,"timestamp":"2026-07-15T04:00:09.181302Z"}]}
{"channel":"book","type":"update","data":[{"symbol":"BTC/USD","bids":[{"price":64727.2,"qty":0.40561514}],"asks":[],"checksum":224378977,"timestamp":"2026-07-15T04:00:09.266307Z"}]}
{"channel":"heartbeat"}
{"channel":"trade","type":"update","data":[{"symbol":"BTC/USD","side":"buy","price":64738.3,"qty":0.00037860,"ord_type":"limit","trade_id":103746784,"timestamp":"2026-07-15T04:00:09.375126Z"}]}
{"channel":"book","type":"update","data":[{"symbol":"BTC/USD","bids":[],"asks":[{"price":64738.3,"qty":2.28258082}],"checksum":1642364545,"timestamp":"2026-07-15T04:00:09.375126Z"}]}
{"channel":"trade","type":"update","data":[{"symbol":"BTC/USD","side":"buy","price":64738.3,"qty":0.00075720,"ord_type":"limit","trade_id":103746785,"timestamp":"2026-07-15T04:00:09.382011Z"}]}
{"channel":"book","type":"update","data":[{"symbol":"BTC/USD","bids":[],"asks":[{"price":64738.3,"qty":2.28182362}],"checksum":1291465373,"timestamp":"2026-07-15T04:00:09.382011Z"}]}
{"channel":"book","type":"update","data":[{"symbol":"BTC/USD","bids":[],"asks":[{"price":64738.3,"qty":2.29637339}],"checksum":1799443237,"timestamp":"2026-07-15T04:00:09.421655Z"}]}
{"channel":"book","type":"update","data":[{"symbol":"BTC/USD","bids":[],"asks":[{"price":64738.3,"qty":2.28182362}],"checksum":1291465373,"timestamp":"2026-07-15T04:00:09.421903Z"}]}
{"channel":"book","type":"update","data":[{"symbol":"BTC/USD","bids":[],"asks":[{"price":64738.3,"qty":2.29642732}],"checksum":1968092230,"timestamp":"2026-07-15T04:00:09.442588Z"}]}
{"channel":"book","type":"update","data":[{"symbol":"BTC/USD","bids":[],"asks":[{"price":64738.3,"qty":2.28182362}],"checksum":1291465373,"timestamp":"2026-07-15T04:00:09.443872Z"}]}
{"channel":"book","type":"update","data":[{"symbol":"BTC/USD","bids":[],"asks":[{"price":64739.5,"qty":0.24223054}],"checksum":2885923757,"timestamp":"2026-07-15T04:00:09.450616Z"}]}
{"channel":"book","type":"update","data":[{"symbol":"BTC/USD","bids":[],"asks":[{"price":64739.5,"qty":0.00000000},{"price":64747.6,"qty":0.00005100}],"checksum":4039567871,"timestamp":"2026-07-15T04:00:09.450721Z"}]}
{"channel":"book","type":"update","data":[{"symbol":"BTC/USD","bids":[],"asks":[{"price":64738.3,"qty":1.76287840}],"checksum":3393355612,"timestamp":"2026-07-15T04:00:09.450933Z"}]}
{"channel":"book","type":"update","data":[{"symbol":"BTC/USD","bids":[{"price":64727.1,"qty":0.00000000},{"price":64727.0,"qty":0.03086388}],"asks":[],"checksum":3597865962,"timestamp":"2026-07-15T04:00:09.450968Z"}]}
{"channel":"book","type":"update","data":[{"symbol":"BTC/USD","bids":[],"asks":[{"price":64739.5,"qty":0.47915729}],"checksum":722671348,"timestamp":"2026-07-15T04:00:09.453020Z"}]}
{"channel":"book","type":"update","data":[{"symbol":"BTC/USD","bids":[],"asks":[{"price":64738.3,"qty":1.76133371}],"checksum":2163018187,"timestamp":"2026-07-15T04:00:09.453402Z"}]}
{"channel":"book","type":"update","data":[{"symbol":"BTC/USD","bids":[],"asks":[{"price":64739.6,"qty":0.00000000},{"price":64747.6,"qty":0.00005100}],"checksum":3775578984,"timestamp":"2026-07-15T04:00:09.453817Z"}]}
{"channel":"book","type":"update","data":[{"symbol":"BTC/USD","bids":[{"price":64727.2,"qty":0.58064684}],"asks":[],"checksum":1989498095,"timestamp":"2026-07-15T04:00:09.453875Z"}]}
{"channel":"book","type":"update","data":[{"symbol":"BTC/USD","bids":[{"price":64727.2,"qty":0.17503170}],"asks":[],"checksum":3091913202,"timestamp":"2026-07-15T04:00:09.454003Z"}]}
{"channel":"book","type":"update","data":[{"symbol":"BTC/USD","bids":[{"price":64727.0,"qty":0.00000000},{"price":64726.9,"qty":0.03656174},{"price":64731.7,"qty":0.03086388}],"asks":[],"checksum":3483712909,"timestamp":"2026-07-15T04:00:09.454028Z"}]}
{"channel":"book","type":"update","data":[{"symbol":"BTC/USD","bids":[],"asks":[{"price":64738.3,"qty":1.65133371}],"checksum":3638251056,"timestamp":"2026-07-15T04:00:09.454096Z"}]}
{"channel":"book","type":"update","data":[{"symbol":"BTC/USD","bids":[],"asks":[{"price":64739.5,"qty":0.00000000},{"price":64748.3,"qty":0.69152355}],"checksum":1039071883,"timestamp":"2026-07-15T04:00:09.457471Z"}]}
{"channel":"book","type":"update","data":[{"symbol":"BTC/USD","bids":[],"asks":[{"price":64738.3,"qty":1.65843563}],"checksum":3277101877,"timestamp":"2026-07-15T04:00:09.457529Z"}]}
{"channel":"book","type":"update","data":[{"symbol":"BTC/USD","bids":[],"asks":[{"price":64741.8,"qty":0.24860310}],"checksum":1077582790,"timestamp":"2026-07-15T04:00:09.458046Z"}]}
{"channel":"book","type":"update","data":[{"symbol":"BTC/USD","bids":[],"asks":[{"price":64746.0,"qty":0.02264449}],"checksum":1325466400,"timestamp":"2026-07-15T04:00:09.458093Z"}]}
{"channel":"book","type":"update","data":[{"symbol":"BTC/USD","bids":[],"asks":[{"price":64738.3,"qty":0.88609530}],"checksum":2012795620,"timestamp":"2026-07-15T04:00:09.458214Z"}]}
{"channel":"book","type":"update","data":[{"symbol":"BTC/USD","bids":[],"asks":[{"price":64741.9,"qty":0.00000000},{"price":64747.6,"qty":0.00005100}],"checksum":2956127758,"timestamp":"2026-07-15T04:00:09.459814Z"}]}
{"channel":"book","type":"update","data":[{"symbol":"BTC/USD","bids":[],"asks":[{"price":64741.8,"qty":0.00000000},{"price":64748.3,"qty":0.69152355}],"checksum":1618487848,"timestamp":"2026-07-15T04:00:09.459823Z"}]}
{"channel":"book","type":"update","data":[{"symbol":"BTC/USD","bids":[],"asks":[{"price":64748.3,"qty":0.00000000},{"price":64749.7,"qty":0.13109402}],"checksum":1793488131,"timestamp":"2026-07-15T04:00:09.459878Z"}]}
{"channel":"book","type":"update","data":[{"symbol":"BTC/USD","bids":[],"asks":[{"price":64738.3,"qty":0.87899338}],"checksum":1708062560,"timestamp":"2026-07-15T04:00:09.462610Z"}]}
{"channel":"book","type":"update","data":[{"symbol":"BTC/USD","bids":[],"asks":[{"price":64749.6,"qty":0.06992789}],"checksum":2524134782,"timestamp":"2026-07-15T04:00:09.463022Z"}]}
{"channel":"book","type":"update","data":[{"symbol":"BTC/USD","bids":[],"asks":[{"price":64739.3,"qty":0.00000000},{"price":64749.7,"qty":0.13109402}],"checksum":368874407,"timestamp":"2026-07-15T04:00:09.463804Z"}]}
{"channel":"book","type":"update","data":[{"symbol":"BTC/USD","bids":[],"asks":[{"price":64742.2,"qty":0.01807199}],"checksum":4289889315,"timestamp":"2026-07-15T04:00:09.465654Z"}]}
{"channel":"book","type":"update","data":[{"symbol":"BTC/USD","bids":[{"price":64732.3,"qty":0.51894522}],"asks":[],"checksum":2303152256,"timestamp":"2026-07-15T04:00:09.471470Z"}]}
{"channel":"book","type":"update","data":[{"symbol":"BTC/USD","bids":[{"price":64731.8,"qty":0.03656174}],"asks":[],"checksum":1214223836,"timestamp":"2026-07-15T04:00:09.471661Z"}]}
{"channel":"book","type":"update","data":[{"symbol":"BTC/USD","bids":[{"price":64732.4,"qty":0.00154482}],"asks":[],"checksum":655818858,"timestamp":"2026-07-15T04:00:09.476336Z"}]}
{"channel":"book","type":"update","data":[{"symbol":"BTC/USD","bids":[],"asks":[{"price":64743.9,"qty":0.03911676}],"checksum":3953849870,"timestamp":"2026-07-15T04:00:09.476649Z"}]}
{"channel":"book","type":"update","data":[{"symbol":"BTC/USD","bids":[{"price":64732.4,"qty":0.18077074}],"asks":[],"checksum":1670786738,"timestamp":"2026-07-15T04:00:09.476788Z"}]}
{"channel":"book","type":"update","data":[{"symbol":"BTC/USD","bids":[],"asks":[{"price":64742.6,"qty":0.77228926}],"checksum":270819660,"timestamp":"2026-07-15T04:00:09.479824Z"}]}
{"channel":"book","type":"update","data":[{"symbol":"BTC/USD","bids":[{"price":64735.1,"qty":0.77237761}],"asks":[],"checksum":1020327122,"timestamp":"2026-07-15T04:00:09.480113Z"}]}
{"channel":"book","type":"update","data":[{"symbol":"BTC/USD","bids":[{"price":64731.7,"qty":0.08906388}],"asks":[],"checksum":3350223995,"timestamp":"2026-07-15T04:00:09.481944Z"}]}
