{"channel":"book","type":"update","data":[{"symbol":"BTC/USD","bids":[],"asks":[{"price":64738.3,"qty":0.84812950},{"price":64741.0,"qty":0.03086388}],"checksum":2948124611,"timestamp":"2026-07-15T04:00:09.482365Z"}]}
{"channel":"book","type":"update","data":[{"symbol":"BTC/USD","bids":[{"price":64738.2,"qty":0.05444384}],"asks":[],"checksum":2964930859,"timestamp":"2026-07-15T04:00:09.485513Z"}]}
{"channel":"book","type":"update","data":[{"symbol":"BTC/USD","bids":[],"asks":[{"price":64742.5,"qty":0.24221992}],"checksum":2607980431,"timestamp":"2026-07-15T04:00:09.485888Z"}]}
{"channel":"book","type":"update","data":[{"symbol":"BTC/USD","bids":[{"price":64732.4,"qty":0.17922592}],"asks":[],"checksum":1592672467,"timestamp":"2026-07-15T04:00:09.489555Z"}]}
{"channel":"book","type":"update","data":[{"symbol":"BTC/USD","bids":[{"price":64738.1,"qty":0.00305848}],"asks":[],"checksum":976215337,"timestamp":"2026-07-15T04:00:09.493323Z"}]}
{"channel":"book","type":"update","data":[{"symbol":"BTC/USD","bids":[{"price":64738.2,"qty":0.03395256}],"asks":[],"checksum":3777125370,"timestamp":"2026-07-15T04:00:09.493430Z"}]}
{"channel":"book","type":"update","data":[{"symbol":"BTC/USD","bids":[],"asks":[{"price":64742.2,"qty":0.00000000},{"price":64746.1,"qty":0.04492034}],"checksum":3741085667,"timestamp":"2026-07-15T04:00:09.493560Z"}]}
{"channel":"book","type":"update","data":[{"symbol":"BTC/USD","bids":[],"asks":[{"price":64742.5,"qty":0.00000000},{"price":64746.7,"qty":0.03088960}],"checksum":1278258611,"timestamp":"2026-07-15T04:00:09.495221Z"}]}
{"channel":"book","type":"update","data":[{"symbol":"BTC/USD","bids":[{"price":64738.2,"qty":0.05444384}],"asks":[],"checksum":2537368416,"timestamp":"2026-07-15T04:00:09.500002Z"}]}
{"channel":"book","type":"update","data":[{"symbol":"BTC/USD","bids":[],"asks":[{"price":64742.5,"qty":0.24221992}],"checksum":99739952,"timestamp":"2026-07-15T04:00:09.501454Z"}]}
{"channel":"book","type":"update","data":[{"symbol":"BTC/USD","bids":[{"price":64738.2,"qty":0.03395256}],"asks":[],"checksum":3741085667,"timestamp":"2026-07-15T04:00:09.505523Z"}]}
{"channel":"book","type":"update","data":[{"symbol":"BTC/USD","bids":[],"asks":[{"price":64742.6,"qty":0.00000000},{"price":64746.7,"qty":0.03088960}],"checksum":3156869270,"timestamp":"2026-07-15T04:00:09.529527Z"}]}
{"channel":"book","type":"update","data":[{"symbol":"BTC/USD","bids":[],"asks":[{"price":64742.5,"qty":0.00000000},{"price":64747.6,"qty":0.00005100}],"checksum":3390266825,"timestamp":"2026-07-15T04:00:09.530731Z"}]}
{"channel":"book","type":"update","data":[{"symbol":"BTC/USD","bids":[],"asks":[{"price":64745.9,"qty":0.77225051}],"checksum":3701226974,"timestamp":"2026-07-15T04:00:09.531082Z"}]}
{"channel":"book","type":"update","data":[{"symbol":"BTC/USD","bids":[{"price":64735.2,"qty":0.23103082}],"asks":[],"checksum":2369815055,"timestamp":"2026-07-15T04:00:09.532331Z"}]}
{"channel":"book","type":"update","data":[{"symbol":"BTC/USD","bids":[],"asks":[{"price":64746.0,"qty":0.00000000},{"price":64747.6,"qty":0.00005100}],"checksum":1236283447,"timestamp":"2026-07-15T04:00:09.532519Z"}]}
{"channel":"book","type":"update","data":[{"symbol":"BTC/USD","bids":[{"price":64738.2,"qty":0.05444384}],"asks":[],"checksum":1454489311,"timestamp":"2026-07-15T04:00:09.532931Z"}]}
{"channel":"book","type":"update","data":[{"symbol":"BTC/USD","bids":[],"asks":[{"price":64745.8,"qty":0.25316127}],"checksum":1944396112,"timestamp":"2026-07-15T04:00:09.534133Z"}]}
{"channel":"book","type":"update","data":[{"symbol":"BTC/USD","bids":[{"price":64732.4,"qty":0.68984935}],"asks":[],"checksum":686696871,"timestamp":"2026-07-15T04:00:09.535861Z"}]}
{"channel":"book","type":"update","data":[{"symbol":"BTC/USD","bids":[],"asks":[{"price":64745.4,"qty":0.11000000}],"checksum":47327296,"timestamp":"2026-07-15T04:00:09.553803Z"}]}
{"channel":"book","type":"update","data":[{"symbol":"BTC/USD","bids":[],"asks":[{"price":64743.8,"qty":0.04452658}],"checksum":849610889,"timestamp":"2026-07-15T04:00:09.555627Z"}]}
{"channel":"book","type":"update","data":[{"symbol":"BTC/USD","bids":[],"asks":[{"price":64745.9,"qty":0.00000000},{"price":64746.1,"qty":0.04492034}],"checksum":1732508004,"timestamp":"2026-07-15T04:00:09.563844Z"}]}
{"channel":"book","type":"update","data":[{"symbol":"BTC/USD","bids":[],"asks":[{"price":64745.8,"qty":0.00000000},{"price":64746.7,"qty":0.03088960}],"checksum":4229140805,"timestamp":"2026-07-15T04:00:09.565250Z"}]}
{"channel":"book","type":"update","data":[{"symbol":"BTC/USD","bids":[],"asks":[{"price":64742.9,"qty":0.77228621}],"checksum":1822038576,"timestamp":"2026-07-15T04:00:09.565708Z"}]}
{"channel":"book","type":"update","data":[{"symbol":"BTC/USD","bids":[{"price":64733.2,"qty":0.77240112}],"asks":[],"checksum":569853379,"timestamp":"2026-07-15T04:00:09.565990Z"}]}
{"channel":"book","type":"update","data":[{"symbol":"BTC/USD","bids":[],"asks":[{"price":64746.0,"qty":0.02264449}],"checksum":1577484475,"timestamp":"2026-07-15T04:00:09.566931Z"}]}
{"channel":"book","type":"update","data":[{"symbol":"BTC/USD","bids":[],"asks":[{"price":64743.8,"qty":0.00000000},{"price":64746.1,"qty":0.04492034}],"checksum":612977866,"timestamp":"2026-07-15T04:00:09.567544Z"}]}
{"channel":"book","type":"update","data":[{"symbol":"BTC/USD","bids":[],"asks":[{"price":64742.9,"qty":0.00000000},{"price":64746.7,"qty":0.03088960}],"checksum":1363790643,"timestamp":"2026-07-15T04:00:09.582464Z"}]}
{"channel":"book","type":"update","data":[{"symbol":"BTC/USD","bids":[{"price":64735.1,"qty":0.00000000},{"price":64731.8,"qty":0.03656174}],"asks":[],"checksum":2051760561,"timestamp":"2026-07-15T04:00:09.582700Z"}]}
{"channel":"book","type":"update","data":[{"symbol":"BTC/USD","bids":[],"asks":[{"price":64740.9,"qty":0.02730008}],"checksum":4079882922,"timestamp":"2026-07-15T04:00:09.585439Z"}]}
{"channel":"book","type":"update","data":[{"symbol":"BTC/USD","bids":[],"asks":[{"price":64741.0,"qty":0.00000000},{"price":64746.7,"qty":0.03088960},{"price":64740.8,"qty":0.03086388}],"checksum":184975493,"timestamp":"2026-07-15T04:00:09.588084Z"}]}
{"channel":"book","type":"update","data":[{"symbol":"BTC/USD","bids":[],"asks":[{"price":64740.9,"qty":0.00000000},{"price":64746.7,"qty":0.03088960}],"checksum":3526140448,"timestamp":"2026-07-15T04:00:09.589917Z"}]}
{"channel":"book","type":"update","data":[{"symbol":"BTC/USD","bids":[],"asks":[{"price":64743.8,"qty":0.04452658}],"checksum":1148968004,"timestamp":"2026-07-15T04:00:09.599086Z"}]}
{"channel":"book","type":"update","data":[{"symbol":"BTC/USD","bids":[{"price":64731.8,"qty":0.06742562}],"asks":[],"checksum":2557256201,"timestamp":"2026-07-15T04:00:09.614260Z"}]}
{"channel":"book","type":"update","data":[{"symbol":"BTC/USD","bids":[],"asks":[{"price":64740.8,"qty":0.00000000},{"price":64746.7,"qty":0.03088960},{"price":64741.0,"qty":0.03086388}],"checksum":806052248,"timestamp":"2026-07-15T04:00:09.614530Z"}]}
{"channel":"book","type":"update","data":[{"symbol":"BTC/USD","bids":[{"price":64733.2,"qty":0.00000000},{"price":64731.7,"qty":0.05820000}],"asks":[],"checksum":2124239337,"timestamp":"2026-07-15T04:00:09.636991Z"}]}
{"channel":"book","type":"update","data":[{"symbol":"BTC/USD","bids":[{"price":64735.2,"qty":0.00000000},{"price":64731.6,"qty":0.01400000}],"asks":[],"checksum":1471828101,"timestamp":"2026-07-15T04:00:09.638534Z"}]}
{"channel":"book","type":"update","data":[{"symbol":"BTC/USD","bids":[],"asks":[{"price":64744.2,"qty":0.51894522}],"checksum":2072313042,"timestamp":"2026-07-15T04:00:09.667196Z"}]}
{"channel":"book","type":"update","data":[{"symbol":"BTC/USD","bids":[{"price":64732.3,"qty":0.00000000},{"price":64731.5,"qty":0.77247202}],"asks":[],"checksum":2719709495,"timestamp":"2026-07-15T04:00:09.667707Z"}]}
{"channel":"book","type":"update","data":[{"symbol":"BTC/USD","bids":[],"asks":[{"price":64743.8,"qty":0.19373909}],"checksum":4087694438,"timestamp":"2026-07-15T04:00:09.668830Z"}]}
{"channel":"book","type":"update","data":[{"symbol":"BTC/USD","bids":[{"price":64731.8,"qty":0.03086388}],"asks":[],"checksum":18485943,"timestamp":"2026-07-15T04:00:09.671792Z"}]}
{"channel":"book","type":"update","data":[{"symbol":"BTC/USD","bids":[{"price":64735.0,"qty":0.03656174}],"asks":[],"checksum":1115526821,"timestamp":"2026-07-15T04:00:09.672007Z"}]}
{"channel":"book","type":"update","data":[{"symbol":"BTC/USD","bids":[{"price":64738.2,"qty":0.03395256}],"asks":[],"checksum":1800765850,"timestamp":"2026-07-15T04:00:09.672108Z"}]}
{"channel":"book","type":"update","data":[{"symbol":"BTC/USD","bids":[],"asks":[{"price":64742.0,"qty":0.77229731}],"checksum":293786814,"timestamp":"2026-07-15T04:00:09.672535Z"}]}
{"channel":"book","type":"update","data":[{"symbol":"BTC/USD","bids":[{"price":64733.1,"qty":0.77240124}],"asks":[],"checksum":2803444048,"timestamp":"2026-07-15T04:00:09.672800Z"}]}
{"channel":"book","type":"update","data":[{"symbol":"BTC/USD","bids":[],"asks":[{"price":64741.9,"qty":0.24860273}],"checksum":2636109824,"timestamp":"2026-07-15T04:00:09.674811Z"}]}
{"channel":"book","type":"update","data":[{"symbol":"BTC/USD","bids":[{"price":64738.2,"qty":0.05444384}],"asks":[],"checksum":726719786,"timestamp":"2026-07-15T04:00:09.675559Z"}]}
{"channel":"book","type":"update","data":[{"symbol":"BTC/USD","bids":[{"price":64738.2,"qty":0.03395256}],"asks":[],"checksum":2636109824,"timestamp":"2026-07-15T04:00:09.677782Z"}]}
{"channel":"book","type":"update","data":[{"symbol":"BTC/USD","bids":[{"price":64732.5,"qty":0.51894522}],"asks":[],"checksum":3974696425,"timestamp":"2026-07-15T04:00:09.677998Z"}]}
{"channel":"book","type":"update","data":[{"symbol":"BTC/USD","bids":[{"price":64733.2,"qty":0.23056177}],"asks":[],"checksum":3058303239,"timestamp":"2026-07-15T04:00:09.697714Z"}]}
{"channel":"book","type":"update","data":[{"symbol":"BTC/USD","bids":[],"asks":[{"price":64742.0,"qty":0.00000000},{"price":64745.4,"qty":0.11000000}],"checksum":4104354259,"timestamp":"2026-07-15T04:00:09.707864Z"}]}
{"channel":"book","type":"update","data":[{"symbol":"BTC/USD","bids":[],"asks":[{"price":64741.9,"qty":0.00000000},{"price":64746.7,"qty":0.03088960}],"checksum":1295282492,"timestamp":"2026-07-15T04:00:09.709272Z"}]}
{"channel":"book","type":"update","data":[{"symbol":"BTC/USD","bids":[{"price":64738.2,"qty":0.05444384}],"asks":[],"checksum":1379270612,"timestamp":"2026-07-15T04:00:09.710987Z"}]}
{"channel":"book","type":"update","data":[{"symbol":"BTC/USD","bids":[],"asks":[{"price":64741.0,"qty":0.00000000},{"price":64747.6,"qty":0.00005100},{"price":64742.2,"qty":0.03086388}],"checksum":595856759,"timestamp":"2026-07-15T04:00:09.748489Z"}]}
{"channel":"book","type":"update","data":[{"symbol":"BTC/USD","bids":[],"asks":[{"price":64742.1,"qty":0.02728486}],"checksum":808799574,"timestamp":"2026-07-15T04:00:09.749892Z"}]}
{"channel":"book","type":"update","data":[{"symbol":"BTC/USD","bids":[],"asks":[{"price":64742.2,"qty":0.00000000},{"price":64746.7,"qty":0.03088960},{"price":64742.0,"qty":0.03086388}],"checksum":4266775932,"timestamp":"2026-07-15T04:00:09.751391Z"}]}
{"channel":"book","type":"update","data":[{"symbol":"BTC/USD","bids":[],"asks":[{"price":64742.1,"qty":0.00000000},{"price":64746.7,"qty":0.03088960}],"checksum":667646488,"timestamp":"2026-07-15T04:00:09.752611Z"}]}
{"channel":"book","type":"update","data":[{"symbol":"BTC/USD","bids":[],"asks":[{"price":64741.9,"qty":0.02728486}],"checksum":1962593949,"timestamp":"2026-07-15T04:00:09.754150Z"}]}
{"channel":"book","type":"update","data":[{"symbol":"BTC/USD","bids":[],"asks":[{"price":64743.6,"qty":0.04492032}],"checksum":2431477559,"timestamp":"2026-07-15T04:00:09.762266Z"}]}
{"channel":"book","type":"update","data":[{"symbol":"BTC/USD","bids":[{"price":64733.1,"qty":0.00000000},{"price":64731.8,"qty":0.03086388}],"asks":[],"checksum":2253014833,"timestamp":"2026-07-15T04:00:09.793148Z"}]}
{"channel":"book","type":"update","data":[{"symbol":"BTC/USD","bids":[{"price":64731.8,"qty":0.00000000},{"price":64731.6,"qty":0.01400000},{"price":64731.7,"qty":0.03086388}],"asks":[],"checksum":1600804253,"timestamp":"2026-07-15T04:00:09.793912Z"}]}
{"channel":"book","type":"update","data":[{"symbol":"BTC/USD","bids":[{"price":64733.2,"qty":0.00000000},{"price":64731.6,"qty":0.01400000}],"asks":[],"checksum":2570143336,"timestamp":"2026-07-15T04:00:09.794594Z"}]}
{"channel":"book","type":"update","data":[{"symbol":"BTC/USD","bids":[],"asks":[{"price":64740.2,"qty":0.77231806}],"checksum":1296535942,"timestamp":"2026-07-15T04:00:09.794738Z"}]}
{"channel":"book","type":"update","data":[{"symbol":"BTC/USD","bids":[{"price":64732.1,"qty":0.77241321}],"asks":[],"checksum":3860354513,"timestamp":"2026-07-15T04:00:09.795524Z"}]}
{"channel":"book","type":"update","data":[{"symbol":"BTC/USD","bids":[],"asks":[{"price":64741.9,"qty":0.00000000},{"price":64744.3,"qty":0.00005100}],"checksum":106372746,"timestamp":"2026-07-15T04:00:09.796298Z"}]}
{"channel":"book","type":"update","data":[{"symbol":"BTC/USD","bids":[],"asks":[{"price":64740.1,"qty":0.25783702}],"checksum":2472452550,"timestamp":"2026-07-15T04:00:09.796392Z"}]}
{"channel":"book","type":"update","data":[{"symbol":"BTC/USD","bids":[{"price":64738.2,"qty":0.03395256}],"asks":[],"checksum":1213409045,"timestamp":"2026-07-15T04:00:09.796732Z"}]}
{"channel":"book","type":"update","data":[{"symbol":"BTC/USD","bids":[],"asks":[{"price":64738.3,"qty":0.85523142}],"checksum":2088565296,"timestamp":"2026-07-15T04:00:09.798236Z"}]}
{"channel":"book","type":"update","data":[{"symbol":"BTC/USD","bids":[],"asks":[{"price":64742.3,"qty":0.00000000},{"price":64744.3,"qty":0.00005100}],"checksum":1103027134,"timestamp":"2026-07-15T04:00:09.799971Z"}]}
{"channel":"book","type":"update","data":[{"symbol":"BTC/USD","bids":[{"price":64732.6,"qty":0.01400000}],"asks":[],"checksum":3903637468,"timestamp":"2026-07-15T04:00:09.817372Z"}]}
{"channel":"book","type":"update","data":[{"symbol":"BTC/USD","bids":[{"price":64732.1,"qty":0.00000000},{"price":64731.8,"qty":0.03086388}],"asks":[],"checksum":887986308,"timestamp":"2026-07-15T04:00:09.838726Z"}]}
{"channel":"book","type":"update","data":[{"symbol":"BTC/USD","bids":[],"asks":[{"price":64743.3,"qty":0.77228185}],"checksum":759081201,"timestamp":"2026-07-15T04:00:09.840476Z"}]}
{"channel":"book","type":"update","data":[{"symbol":"BTC/USD","bids":[],"asks":[{"price":64743.8,"qty":0.14921251}],"checksum":2075826427,"timestamp":"2026-07-15T04:00:09.841740Z"}]}
{"channel":"book","type":"update","data":[{"symbol":"BTC/USD","bids":[],"asks":[{"price":64743.8,"qty":0.00000000},{"price":64744.3,"qty":0.00005100}],"checksum":3208453347,"timestamp":"2026-07-15T04:00:09.841749Z"}]}
{"channel":"book","type":"update","data":[{"symbol":"BTC/USD","bids":[],"asks":[{"price":64743.2,"qty":0.44336657}],"checksum":659316814,"timestamp":"2026-07-15T04:00:09.843368Z"}]}
{"channel":"book","type":"update","data":[{"symbol":"BTC/USD","bids":[],"asks":[{"price":64744.2,"qty":0.00000000},{"price":64744.3,"qty":0.00005100}],"checksum":1346995725,"timestamp":"2026-07-15T04:00:09.898369Z"}]}
{"channel":"book","type":"update","data":[{"symbol":"BTC/USD","bids":[],"asks":[{"price":64743.2,"qty":0.00000000},{"price":64745.4,"qty":0.11000000}],"checksum":3515134538,"timestamp":"2026-07-15T04:00:09.899654Z"}]}
{"channel":"book","type":"update","data":[{"symbol":"BTC/USD","bids":[],"asks":[{"price":64743.2,"qty":0.28846142}],"checksum":1756476601,"timestamp":"2026-07-15T04:00:09.899743Z"}]}
{"channel":"book","type":"update","data":[{"symbol":"BTC/USD","bids":[],"asks":[{"price":64742.0,"qty":0.00000000},{"price":64745.4,"qty":0.11000000},{"price":64738.3,"qty":0.88609530}],"checksum":4248491823,"timestamp":"2026-07-15T04:00:09.944001Z"}]}
{"channel":"book","type":"update","data":[{"symbol":"BTC/USD","bids":[{"price":64734.6,"qty":0.01446739}],"asks":[],"checksum":4230427431,"timestamp":"2026-07-15T04:00:10.011215Z"}]}
{"channel":"book","type":"update","data":[{"symbol":"BTC/USD","bids":[{"price":64734.7,"qty":0.00159576}],"asks":[],"checksum":1619882898,"timestamp":"2026-07-15T04:00:10.029286Z"}]}
{"channel":"book","type":"update","data":[{"symbol":"BTC/USD","bids":[{"price":64732.7,"qty":0.77240607}],"asks":[],"checksum":1933745449,"timestamp":"2026-07-15T04:00:10.072422Z"}]}
{"channel":"book","type":"update","data":[{"symbol":"BTC/USD","bids":[],"asks":[{"price":64738.3,"qty":0.85523142},{"price":64740.0,"qty":0.03086388}],"checksum":1982332122,"timestamp":"2026-07-15T04:00:10.073888Z"}]}
{"channel":"book","type":"update","data":[{"symbol":"BTC/USD","bids":[{"price":64732.7,"qty":0.00000000},{"price":64732.4,"qty":0.68984935}],"asks":[],"checksum":1709707873,"timestamp":"2026-07-15T04:00:10.108031Z"}]}
{"channel":"book","type":"update","data":[{"symbol":"BTC/USD","bids":[],"asks":[{"price":64740.1,"qty":0.00000000},{"price":64745.4,"qty":0.11000000}],"checksum":3727768729,"timestamp":"2026-07-15T04:00:10.182589Z"}]}
{"channel":"book","type":"update","data":[{"symbol":"BTC/USD","bids":[{"price":64735.1,"qty":0.01616941}],"asks":[],"checksum":1180459046,"timestamp":"2026-07-15T04:00:10.183949Z"}]}
{"channel":"book","type":"update","data":[{"symbol":"BTC/USD","bids":[{"price":64734.7,"qty":0.00005100}],"asks":[],"checksum":4179879331,"timestamp":"2026-07-15T04:00:10.187785Z"}]}
{"channel":"book","type":"update","data":[{"symbol":"BTC/USD","bids":[{"price":64738.1,"qty":0.00000000},{"price":64732.4,"qty":0.68984935}],"asks":[],"checksum":4193292345,"timestamp":"2026-07-15T04:00:10.200006Z"}]}
{"channel":"book","type":"update","data":[{"symbol":"BTC/USD","bids":[],"asks":[{"price":64740.0,"qty":0.00000000},{"price":64746.6,"qty":0.23974958},{"price":64740.1,"qty":0.03086388}],"checksum":1277563328,"timestamp":"2026-07-15T04:00:10.254211Z"}]}
{"channel":"heartbeat"}
{"channel":"book","type":"update","data":[{"symbol":"BTC/USD","bids":[{"price":64732.4,"qty":1.46225924}],"asks":[],"checksum":2344848793,"timestamp":"2026-07-15T04:00:10.478620Z"}]}
{"channel":"book","type":"update","data":[{"symbol":"BTC/USD","bids":[],"asks":[{"price":64738.3,"qty":0.84812950}],"checksum":2338358322,"timestamp":"2026-07-15T04:00:10.482196Z"}]}
{"channel":"book","type":"update","data":[{"symbol":"BTC/USD","bids":[{"price":64738.1,"qty":0.00305848}],"asks":[],"checksum":2061833307,"timestamp":"2026-07-15T04:00:10.494884Z"}]}
{"channel":"book","type":"update","data":[{"symbol":"BTC/USD","bids":[{"price":64738.1,"qty":0.00000000},{"price":64732.4,"qty":1.46225924}],"asks":[],"checksum":2338358322,"timestamp":"2026-07-15T04:00:10.511760Z"}]}
{"channel":"book","type":"update","data":[{"symbol":"BTC/USD","bids":[],"asks":[{"price":64738.3,"qty":0.85523142}],"checksum":2344848793,"timestamp":"2026-07-15T04:00:10.650246Z"}]}
{"channel":"book","type":"update","data":[{"symbol":"BTC/USD","bids":[],"asks":[{"price":64738.3,"qty":0.84812950}],"checksum":2338358322,"timestamp":"2026-07-15T04:00:10.655536Z"}]}
{"channel":"book","type":"update","data":[{"symbol":"BTC/USD","bids":[{"price":64738.1,"qty":0.00305848}],"asks":[],"checksum":2061833307,"timestamp":"2026-07-15T04:00:10.666361Z"}]}
{"channel":"book","type":"update","data":[{"symbol":"BTC/USD","bids":[{"price":64738.1,"qty":0.00000000},{"price":64732.4,"qty":1.46225924}],"asks":[],"checksum":2338358322,"timestamp":"2026-07-15T04:00:10.683926Z"}]}
{"channel":"book","type":"update","data":[{"symbol":"BTC/USD","bids":[{"price":64732.4,"qty":0.68984935}],"asks":[],"checksum":4012882624,"timestamp":"2026-07-15T04:00:10.715298Z"}]}
{"channel":"book","type":"update","data":[{"symbol":"BTC/USD","bids":[],"asks":[{"price":64740.2,"qty":0.00000000},{"price":64746.6,"qty":0.23974958}],"checksum":3007786061,"timestamp":"2026-07-15T04:00:10.716004Z"}]}
{"channel":"book","type":"update","data":[{"symbol":"BTC/USD","bids":[],"asks":[{"price":64738.3,"qty":0.85523142}],"checksum":273581901,"timestamp":"2026-07-15T04:00:10.718816Z"}]}
{"channel":"book","type":"update","data":[{"symbol":"BTC/USD","bids":[],"asks":[{"price":64740.1,"qty":0.00000000},{"price":64746.7,"qty":0.80313016},{"price":64741.0,"qty":0.03086388}],"checksum":1632410253,"timestamp":"2026-07-15T04:00:10.718846Z"}]}
{"channel":"book","type":"update","data":[{"symbol":"BTC/USD","bids":[],"asks":[{"price":64741.2,"qty":0.77230641}],"checksum":773408422,"timestamp":"2026-07-15T04:00:10.719586Z"}]}
{"channel":"book","type":"update","data":[{"symbol":"BTC/USD","bids":[{"price":64733.0,"qty":0.77240289}],"asks":[],"checksum":3067753295,"timestamp":"2026-07-15T04:00:10.719897Z"}]}
{"channel":"book","type":"update","data":[{"symbol":"BTC/USD","bids":[],"asks":[{"price":64738.3,"qty":0.84812950}],"checksum":366188623,"timestamp":"2026-07-15T04:00:10.722376Z"}]}
{"channel":"book","type":"update","data":[{"symbol":"BTC/USD","bids":[],"asks":[{"price":64741.0,"qty":0.00000000},{"price":64746.6,"qty":0.23974958},{"price":64738.3,"qty":0.87899338}],"checksum":4200632312,"timestamp":"2026-07-15T04:00:10.723110Z"}]}
{"channel":"book","type":"update","data":[{"symbol":"BTC/USD","bids":[],"asks":[{"price":64738.3,"qty":0.88609530}],"checksum":152187307,"timestamp":"2026-07-15T04:00:10.724807Z"}]}
{"channel":"book","type":"update","data":[{"symbol":"BTC/USD","bids":[{"price":64733.0,"qty":0.00000000},{"price":64732.4,"qty":0.68984935}],"asks":[],"checksum":2446410818,"timestamp":"2026-07-15T04:00:10.748755Z"}]}
{"channel":"book","type":"update","data":[{"symbol":"BTC/USD","bids":[],"asks":[{"price":64741.2,"qty":0.00000000},{"price":64746.7,"qty":0.80313016}],"checksum":4176269166,"timestamp":"2026-07-15T04:00:10.749962Z"}]}
{"channel":"book","type":"update","data":[{"symbol":"BTC/USD","bids":[],"asks":[{"price":64738.3,"qty":0.87899338}],"checksum":194933053,"timestamp":"2026-07-15T04:00:10.753070Z"}]}
{"channel":"book","type":"update","data":[{"symbol":"BTC/USD","bids":[],"asks":[{"price":64740.7,"qty":0.77231178}],"checksum":3075141549,"timestamp":"2026-07-15T04:00:10.948573Z"}]}
{"channel":"book","type":"update","data":[{"symbol":"BTC/USD","bids":[{"price":64733.7,"qty":0.77239458}],"asks":[],"checksum":2687945883,"timestamp":"2026-07-15T04:00:10.948798Z"}]}
{"channel":"book","type":"update","data":[{"symbol":"BTC/USD","bids":[],"asks":[{"price":64738.3,"qty":0.88609530}],"checksum":1396994760,"timestamp":"2026-07-15T04:00:10.952272Z"}]}
{"channel":"book","type":"update","data":[{"symbol":"BTC/USD","bids":[{"price":64735.2,"qty":0.00154475}],"asks":[],"checksum":2570984061,"timestamp":"2026-07-15T04:00:11.046785Z"}]}
{"channel":"trade","type":"update","data":[{"symbol":"BTC/USD","side":"buy","price":64738.3,"qty":0.00015144,"ord_type":"limit","trade_id":103746786,"timestamp":"2026-07-15T04:00:11.080660Z"}]}
{"channel":"book","type":"update","data":[{"symbol":"BTC/USD","bids":[],"asks":[{"price":64738.3,"qty":0.88594386}],"checksum":3511459992,"timestamp":"2026-07-15T04:00:11.080660Z"}]}
{"channel":"heartbeat"}
{"channel":"book","type":"update","data":[{"symbol":"BTC/USD","bids":[],"asks":[{"price":64738.3,"qty":0.87884194}],"checksum":3059857259,"timestamp":"2026-07-15T04:00:11.473330Z"}]}
{"channel":"book","type":"update","data":[{"symbol":"BTC/USD","bids":[],"asks":[{"price":64742.7,"qty":0.51894522}],"checksum":304657094,"timestamp":"2026-07-15T04:00:12.239367Z"}]}
{"channel":"book","type":"update","data":[{"symbol":"BTC/USD","bids":[],"asks":[{"price":64743.2,"qty":0.00000000},{"price":64746.6,"qty":0.23974958}],"checksum":2858880562,"timestamp":"2026-07-15T04:00:12.241624Z"}]}
{"channel":"book","type":"update","data":[{"symbol":"BTC/USD","bids":[{"price":64735.1,"qty":0.24420086}],"asks":[],"checksum":3320244226,"timestamp":"2026-07-15T04:00:12.242438Z"}]}
{"channel":"book","type":"update","data":[{"symbol":"BTC/USD","bids":[],"asks":[{"price":64738.3,"qty":0.88594386}],"checksum":3778373299,"timestamp":"2026-07-15T04:00:12.243029Z"}]}
{"channel":"book","type":"update","data":[{"symbol":"BTC/USD","bids":[],"asks":[{"price":64742.6,"qty":0.44336657}],"checksum":2091597371,"timestamp":"2026-07-15T04:00:12.243100Z"}]}
{"channel":"book","type":"update","data":[{"symbol":"BTC/USD","bids":[],"asks":[{"price":64738.3,"qty":0.87884194}],"checksum":1484304522,"timestamp":"2026-07-15T04:00:12.245593Z"}]}
{"channel":"book","type":"update","data":[{"symbol":"BTC/USD","bids":[],"asks":[{"price":64738.3,"qty":0.88594386}],"checksum":2091597371,"timestamp":"2026-07-15T04:00:12.248061Z"}]}
{"channel":"heartbeat"}
{"channel":"book","type":"update","data":[{"symbol":"BTC/USD","bids":[],"asks":[{"price":64738.3,"qty":0.87884194}],"checksum":1484304522,"timestamp":"2026-07-15T04:00:12.646934Z"}]}
{"channel":"heartbeat"}
{"channel":"trade","type":"update","data":[{"symbol":"BTC/USD","side":"buy","price":64738.3,"qty":0.00022941,"ord_type":"limit","trade_id":103746787,"timestamp":"2026-07-15T04:00:13.294918Z"}]}
{"channel":"book","type":"update","data":[{"symbol":"BTC/USD","bids":[],"asks":[{"price":64738.3,"qty":0.87861253}],"checksum":3450189133,"timestamp":"2026-07-15T04:00:13.294918Z"}]}
{"channel":"trade","type":"update","data":[{"symbol":"BTC/USD","side":"buy","price":64738.3,"qty":0.00188710,"ord_type":"limit","trade_id":103746788,"timestamp":"2026-07-15T04:00:13.297256Z"}]}
{"channel":"book","type":"update","data":[{"symbol":"BTC/USD","bids":[],"asks":[{"price":64738.3,"qty":0.87672543}],"checksum":3466441884,"timestamp":"2026-07-15T04:00:13.297256Z"}]}
{"channel":"book","type":"update","data":[{"symbol":"BTC/USD","bids":[{"price":64733.7,"qty":0.00000000},{"price":64732.5,"qty":0.51894522}],"asks":[],"checksum":1167027059,"timestamp":"2026-07-15T04:00:13.569995Z"}]}
{"channel":"book","type":"update","data":[{"symbol":"BTC/USD","bids":[{"price":64735.1,"qty":0.01616941}],"asks":[],"checksum":2180410898,"timestamp":"2026-07-15T04:00:13.571442Z"}]}
{"channel":"book","type":"update","data":[{"symbol":"BTC/USD","bids":[{"price":64734.5,"qty":0.77238546}],"asks":[],"checksum":161690729,"timestamp":"2026-07-15T04:00:13.574095Z"}]}
{"channel":"book","type":"update","data":[{"symbol":"BTC/USD","bids":[],"asks":[{"price":64742.6,"qty":0.00000000},{"price":64746.6,"qty":0.23974958}],"checksum":1166808044,"timestamp":"2026-07-15T04:00:13.574307Z"}]}
{"channel":"book","type":"update","data":[{"symbol":"BTC/USD","bids":[],"asks":[{"price":64740.7,"qty":0.00000000},{"price":64746.7,"qty":0.80313016}],"checksum":453064429,"timestamp":"2026-07-15T04:00:13.576607Z"}]}
{"channel":"book","type":"update","data":[{"symbol":"BTC/USD","bids":[{"price":64735.1,"qty":0.24419814}],"asks":[],"checksum":1172098952,"timestamp":"2026-07-15T04:00:13.578028Z"}]}
{"channel":"book","type":"update","data":[{"symbol":"BTC/USD","bids":[],"asks":[{"price":64741.8,"qty":0.77229919}],"checksum":2840736164,"timestamp":"2026-07-15T04:00:13.578818Z"}]}
{"channel":"book","type":"update","data":[{"symbol":"BTC/USD","bids":[{"price":64738.2,"qty":0.05444384}],"asks":[],"checksum":522007694,"timestamp":"2026-07-15T04:00:13.581404Z"}]}
{"channel":"book","type":"update","data":[{"symbol":"BTC/USD","bids":[{"price":64738.2,"qty":0.03395256}],"asks":[],"checksum":2840736164,"timestamp":"2026-07-15T04:00:13.584464Z"}]}
{"channel":"book","type":"update","data":[{"symbol":"BTC/USD","bids":[],"asks":[{"price":64741.8,"qty":0.00000000},{"price":64746.7,"qty":0.80313016}],"checksum":1172098952,"timestamp":"2026-07-15T04:00:13.622343Z"}]}
{"channel":"book","type":"update","data":[{"symbol":"BTC/USD","bids":[{"price":64738.2,"qty":0.05444384}],"asks":[],"checksum":4086549154,"timestamp":"2026-07-15T04:00:13.625631Z"}]}
{"channel":"book","type":"update","data":[{"symbol":"BTC/USD","bids":[{"price":64734.5,"qty":0.00000000},{"price":64732.5,"qty":0.51894522}],"asks":[],"checksum":2076610777,"timestamp":"2026-07-15T04:00:13.750145Z"}]}
{"channel":"book","type":"update","data":[{"symbol":"BTC/USD","bids":[{"price":64735.1,"qty":0.01616941}],"asks":[],"checksum":3128720297,"timestamp":"2026-07-15T04:00:13.752003Z"}]}
{"channel":"book","type":"update","data":[{"symbol":"BTC/USD","bids":[],"asks":[{"price":64741.1,"qty":0.77235890}],"checksum":3349614764,"timestamp":"2026-07-15T04:00:13.752059Z"}]}
{"channel":"book","type":"update","data":[{"symbol":"BTC/USD","bids":[{"price":64733.6,"qty":0.77239529}],"asks":[],"checksum":4093367422,"timestamp":"2026-07-15T04:00:13.752177Z"}]}
{"channel":"book","type":"update","data":[{"symbol":"BTC/USD","bids":[{"price":64738.2,"qty":0.03395256}],"asks":[],"checksum":3671311169,"timestamp":"2026-07-15T04:00:13.753450Z"}]}
{"channel":"book","type":"update","data":[{"symbol":"BTC/USD","bids":[{"price":64735.1,"qty":0.24420107}],"asks":[],"checksum":556606960,"timestamp":"2026-07-15T04:00:13.753774Z"}]}
{"channel":"book","type":"update","data":[{"symbol":"BTC/USD","bids":[],"asks":[{"price":64738.3,"qty":0.88382735}],"checksum":3891928604,"timestamp":"2026-07-15T04:00:13.755595Z"}]}
{"channel":"book","type":"update","data":[{"symbol":"BTC/USD","bids":[],"asks":[{"price":64738.3,"qty":0.87672543}],"checksum":556606960,"timestamp":"2026-07-15T04:00:13.757976Z"}]}
{"channel":"heartbeat"}
{"channel":"trade","type":"update","data":[{"symbol":"BTC/USD","side":"sell","price":64738.2,"qty":0.00003604,"ord_type":"limit","trade_id":103746789,"timestamp":"2026-07-15T04:00:14.316888Z"}]}
{"channel":"book","type":"update","data":[{"symbol":"BTC/USD","bids":[{"price":64738.2,"qty":0.03391652}],"asks":[],"checksum":311357864,"timestamp":"2026-07-15T04:00:14.316888Z"}]}
{"channel":"book","type":"update","data":[{"symbol":"BTC/USD","bids":[],"asks":[{"price":64741.1,"qty":0.00005100}],"checksum":1654251084,"timestamp":"2026-07-15T04:00:14.466623Z"}]}
{"channel":"book","type":"update","data":[{"symbol":"BTC/USD","bids":[],"asks":[{"price":64740.4,"qty":0.77231633}],"checksum":3231255518,"timestamp":"2026-07-15T04:00:14.469563Z"}]}
{"channel":"book","type":"update","data":[{"symbol":"BTC/USD","bids":[],"asks":[{"price":64738.3,"qty":0.88382735}],"checksum":2768752941,"timestamp":"2026-07-15T04:00:14.473412Z"}]}
{"channel":"book","type":"update","data":[{"symbol":"BTC/USD","bids":[{"price":64733.6,"qty":0.00000000},{"price":64732.5,"qty":0.51894522}],"asks":[],"checksum":2438665727,"timestamp":"2026-07-15T04:00:14.593323Z"}]}
{"channel":"book","type":"update","data":[{"symbol":"BTC/USD","bids":[],"asks":[{"price":64743.3,"qty":0.00000000},{"price":64746.7,"qty":0.80313016}],"checksum":2707810361,"timestamp":"2026-07-15T04:00:14.593339Z"}]}
{"channel":"book","type":"update","data":[{"symbol":"BTC/USD","bids":[],"asks":[{"price":64740.4,"qty":0.00000000},{"price":64747.6,"qty":0.00005100}],"checksum":3899844947,"timestamp":"2026-07-15T04:00:14.593912Z"}]}
{"channel":"book","type":"update","data":[{"symbol":"BTC/USD","bids":[{"price":64735.1,"qty":0.01616941}],"asks":[],"checksum":2407402633,"timestamp":"2026-07-15T04:00:14.594779Z"}]}
{"channel":"book","type":"update","data":[{"symbol":"BTC/USD","bids":[],"asks":[{"price":64739.4,"qty":0.77232744}],"checksum":1758971475,"timestamp":"2026-07-15T04:00:14.595798Z"}]}
{"channel":"book","type":"update","data":[{"symbol":"BTC/USD","bids":[],"asks":[{"price":64742.2,"qty":0.77229421}],"checksum":2857366454,"timestamp":"2026-07-15T04:00:14.596038Z"}]}
{"channel":"book","type":"update","data":[{"symbol":"BTC/USD","bids":[{"price":64732.7,"qty":0.77240671}],"asks":[],"checksum":3150324614,"timestamp":"2026-07-15T04:00:14.596394Z"}]}
{"channel":"book","type":"update","data":[{"symbol":"BTC/USD","bids":[],"asks":[{"price":64738.3,"qty":0.87672543}],"checksum":2512721630,"timestamp":"2026-07-15T04:00:14.597510Z"}]}
{"channel":"book","type":"update","data":[{"symbol":"BTC/USD","bids":[],"asks":[{"price":64738.3,"qty":0.88382735}],"checksum":3150324614,"timestamp":"2026-07-15T04:00:14.600429Z"}]}
{"channel":"book","type":"update","data":[{"symbol":"BTC/USD","bids":[],"asks":[{"price":64742.6,"qty":0.21284044}],"checksum":2186623256,"timestamp":"2026-07-15T04:00:14.642229Z"}]}
{"channel":"book","type":"update","data":[{"symbol":"BTC/USD","bids":[],"asks":[{"price":64739.4,"qty":0.00000000},{"price":64746.6,"qty":0.23974958}],"checksum":2264129300,"timestamp":"2026-07-15T04:00:14.709968Z"}]}
{"channel":"book","type":"update","data":[{"symbol":"BTC/USD","bids":[],"asks":[{"price":64740.2,"qty":0.77231793}],"checksum":494481990,"timestamp":"2026-07-15T04:00:14.711473Z"}]}
{"channel":"book","type":"update","data":[{"symbol":"BTC/USD","bids":[],"asks":[{"price":64738.3,"qty":0.87672543}],"checksum":863635230,"timestamp":"2026-07-15T04:00:14.713416Z"}]}
{"channel":"book","type":"update","data":[{"symbol":"BTC/USD","bids":[],"asks":[{"price":64738.3,"qty":0.88382735}],"checksum":494481990,"timestamp":"2026-07-15T04:00:14.716042Z"}]}
{"channel":"trade","type":"update","data":[{"symbol":"BTC/USD","side":"sell","price":64738.2,"qty":0.00073631,"ord_type":"market","trade_id":103746790,"timestamp":"2026-07-15T04:00:15.002774Z"},{"symbol":"BTC/USD","side":"sell","price":64738.2,"qty":0.00230488,"ord_type":"market","trade_id":103746791,"timestamp":"2026-07-15T04:00:15.002774Z"}]}
{"channel":"book","type":"update","data":[{"symbol":"BTC/USD","bids":[{"price":64738.2,"qty":0.03318021},{"price":64738.2,"qty":0.03087533}],"asks":[],"checksum":2961343348,"timestamp":"2026-07-15T04:00:15.002774Z"}]}
{"channel":"book","type":"update","data":[{"symbol":"BTC/USD","bids":[{"price":64738.2,"qty":0.03164768}],"asks":[],"checksum":1486502133,"timestamp":"2026-07-15T04:00:15.015630Z"}]}
{"channel":"heartbeat"}
{"channel":"book","type":"update","data":[{"symbol":"BTC/USD","bids":[{"price":64732.7,"qty":0.00000000},{"price":64732.5,"qty":0.51894522}],"asks":[],"checksum":1226041541,"timestamp":"2026-07-15T04:00:15.377311Z"}]}
{"channel":"book","type":"update","data":[{"symbol":"BTC/USD","bids":[{"price":64733.5,"qty":0.77239672}],"asks":[],"checksum":289452227,"timestamp":"2026-07-15T04:00:15.379694Z"}]}
{"channel":"book","type":"update","data":[{"symbol":"BTC/USD","bids":[],"asks":[{"price":64740.2,"qty":0.00000000},{"price":64746.6,"qty":0.23974958}],"checksum":2328518033,"timestamp":"2026-07-15T04:00:15.390690Z"}]}
{"channel":"book","type":"update","data":[{"symbol":"BTC/USD","bids":[{"price":64733.5,"qty":0.00000000},{"price":64732.5,"qty":0.51894522}],"asks":[],"checksum":3533243799,"timestamp":"2026-07-15T04:00:15.390845Z"}]}
{"channel":"book","type":"update","data":[{"symbol":"BTC/USD","bids":[],"asks":[{"price":64741.1,"qty":0.77235874}],"checksum":4230532805,"timestamp":"2026-07-15T04:00:15.392441Z"}]}
{"channel":"book","type":"update","data":[{"symbol":"BTC/USD","bids":[],"asks":[{"price":64738.3,"qty":0.87672543}],"checksum":667586815,"timestamp":"2026-07-15T04:00:15.394147Z"}]}
{"channel":"book","type":"update","data":[{"symbol":"BTC/USD","bids":[],"asks":[{"price":64738.3,"qty":0.88382735}],"checksum":4230532805,"timestamp":"2026-07-15T04:00:15.396895Z"}]}
{"channel":"book","type":"update","data":[{"symbol":"BTC/USD","bids":[],"asks":[{"price":64741.1,"qty":0.00005100}],"checksum":3533243799,"timestamp":"2026-07-15T04:00:15.434905Z"}]}
{"channel":"book","type":"update","data":[{"symbol":"BTC/USD","bids":[],"asks":[{"price":64738.3,"qty":0.87672543}],"checksum":4237963471,"timestamp":"2026-07-15T04:00:15.438188Z"}]}
{"channel":"book","type":"update","data":[{"symbol":"BTC/USD","bids":[],"asks":[{"price":64744.3,"qty":0.77232058}],"checksum":2681003056,"timestamp":"2026-07-15T04:00:16.002410Z"}]}
{"channel":"book","type":"update","data":[{"symbol":"BTC/USD","bids":[{"price":64733.4,"qty":0.77239846}],"asks":[],"checksum":4175754047,"timestamp":"2026-07-15T04:00:16.002697Z"}]}
{"channel":"trade","type":"update","data":[{"symbol":"BTC/USD","side":"buy","price":64738.3,"qty":0.00189299,"ord_type":"limit","trade_id":103746792,"timestamp":"2026-07-15T04:00:16.026690Z"}]}
{"channel":"book","type":"update","data":[{"symbol":"BTC/USD","bids":[],"asks":[{"price":64738.3,"qty":0.87483244}],"checksum":2757471639,"timestamp":"2026-07-15T04:00:16.026690Z"}]}
{"channel":"heartbeat"}
{"channel":"trade","type":"update","data":[{"symbol":"BTC/USD","side":"sell","price":64738.2,"qty":0.00116181,"ord_type":"limit","trade_id":103746793,"timestamp":"2026-07-15T04:00:16.304954Z"}]}
{"channel":"book","type":"update","data":[{"symbol":"BTC/USD","bids":[{"price":64738.2,"qty":0.03048587}],"asks":[],"checksum":942591872,"timestamp":"2026-07-15T04:00:16.304954Z"}]}
{"channel":"book","type":"update","data":[{"symbol":"BTC/USD","bids":[],"asks":[{"price":64744.3,"qty":0.00005100}],"checksum":2695642596,"timestamp":"2026-07-15T04:00:16.936863Z"}]}
{"channel":"book","type":"update","data":[{"symbol":"BTC/USD","bids":[],"asks":[{"price":64740.0,"qty":0.77232088}],"checksum":3300832223,"timestamp":"2026-07-15T04:00:16.938436Z"}]}
{"channel":"book","type":"update","data":[{"symbol":"BTC/USD","bids":[],"asks":[{"price":64738.3,"qty":0.88193436}],"checksum":4265527554,"timestamp":"2026-07-15T04:00:16.942013Z"}]}
{"channel":"trade","type":"update","data":[{"symbol":"BTC/USD","side":"buy","price":64738.3,"qty":0.00038944,"ord_type":"limit","trade_id":103746794,"timestamp":"2026-07-15T04:00:17.034544Z"}]}
{"channel":"book","type":"update","data":[{"symbol":"BTC/USD","bids":[],"asks":[{"price":64738.3,"qty":0.88154492}],"checksum":1758500739,"timestamp":"2026-07-15T04:00:17.034544Z"}]}
{"channel":"book","type":"update","data":[{"symbol":"BTC/USD","bids":[{"price":64735.1,"qty":0.00000000},{"price":64732.5,"qty":0.51894522}],"asks":[],"checksum":1681549622,"timestamp":"2026-07-15T04:00:17.076545Z"}]}
{"channel":"book","type":"update","data":[{"symbol":"BTC/USD","bids":[{"price":64733.4,"qty":0.00000000},{"price":64732.4,"qty":0.68984935}],"asks":[],"checksum":3041369181,"timestamp":"2026-07-15T04:00:17.079819Z"}]}
{"channel":"book","type":"update","data":[{"symbol":"BTC/USD","bids":[],"asks":[{"price":64740.0,"qty":0.00000000},{"price":64746.6,"qty":0.23974958}],"checksum":69756919,"timestamp":"2026-07-15T04:00:17.080013Z"}]}
{"channel":"book","type":"update","data":[{"symbol":"BTC/USD","bids":[{"price":64733.5,"qty":0.17116908}],"asks":[],"checksum":3551869882,"timestamp":"2026-07-15T04:00:17.080285Z"}]}
{"channel":"book","type":"update","data":[{"symbol":"BTC/USD","bids":[],"asks":[{"price":64742.2,"qty":0.00000000},{"price":64746.7,"qty":0.80313016}],"checksum":3080059027,"timestamp":"2026-07-15T04:00:17.080438Z"}]}
{"channel":"book","type":"update","data":[{"symbol":"BTC/USD","bids":[{"price":64733.5,"qty":0.00000000},{"price":64732.4,"qty":0.68984935}],"asks":[],"checksum":1611179230,"timestamp":"2026-07-15T04:00:17.081208Z"}]}
{"channel":"book","type":"update","data":[{"symbol":"BTC/USD","bids":[],"asks":[{"price":64738.3,"qty":0.87444300}],"checksum":983586136,"timestamp":"2026-07-15T04:00:17.083970Z"}]}
{"channel":"book","type":"update","data":[{"symbol":"BTC/USD","bids":[{"price":64735.1,"qty":0.00038313}],"asks":[],"checksum":1888778234,"timestamp":"2026-07-15T04:00:17.084266Z"}]}
{"channel":"book","type":"update","data":[{"symbol":"BTC/USD","bids":[{"price":64735.2,"qty":0.00000000},{"price":64732.4,"qty":0.68984935}],"asks":[],"checksum":482820227,"timestamp":"2026-07-15T04:00:17.084629Z"}]}
{"channel":"book","type":"update","data":[{"symbol":"BTC/USD","bids":[],"asks":[{"price":64738.4,"qty":0.77233989}],"checksum":1014605310,"timestamp":"2026-07-15T04:00:17.090566Z"}]}
{"channel":"book","type":"update","data":[{"symbol":"BTC/USD","bids":[],"asks":[{"price":64740.8,"qty":0.77231117}],"checksum":3887234002,"timestamp":"2026-07-15T04:00:17.090680Z"}]}
{"channel":"book","type":"update","data":[{"symbol":"BTC/USD","bids":[{"price":64735.1,"qty":0.00000000},{"price":64731.8,"qty":0.03086388}],"asks":[],"checksum":1820277607,"timestamp":"2026-07-15T04:00:17.092055Z"}]}
{"channel":"book","type":"update","data":[{"symbol":"BTC/USD","bids":[],"asks":[{"price":64738.3,"qty":0.88154492}],"checksum":1761523075,"timestamp":"2026-07-15T04:00:17.095815Z"}]}
{"channel":"book","type":"update","data":[{"symbol":"BTC/USD","bids":[],"asks":[{"price":64738.3,"qty":0.97025005}],"checksum":3617731370,"timestamp":"2026-07-15T04:00:17.097302Z"}]}
{"channel":"book","type":"update","data":[{"symbol":"BTC/USD","bids":[{"price":64731.8,"qty":0.00000000},{"price":64731.5,"qty":0.00005100},{"price":64731.6,"qty":0.03086388}],"asks":[],"checksum":3257409816,"timestamp":"2026-07-15T04:00:17.108556Z"}]}
{"channel":"book","type":"update","data":[{"symbol":"BTC/USD","bids":[],"asks":[{"price":64738.3,"qty":0.88154492}],"checksum":2104797105,"timestamp":"2026-07-15T04:00:17.127653Z"}]}
{"channel":"book","type":"update","data":[{"symbol":"BTC/USD","bids":[],"asks":[{"price":64738.3,"qty":0.90376132}],"checksum":3115549921,"timestamp":"2026-07-15T04:00:17.128993Z"}]}
{"channel":"book","type":"update","data":[{"symbol":"BTC/USD","bids":[],"asks":[{"price":64738.3,"qty":0.88154492}],"checksum":2104797105,"timestamp":"2026-07-15T04:00:17.131831Z"}]}
{"channel":"book","type":"update","data":[{"symbol":"BTC/USD","bids":[],"asks":[{"price":64740.7,"qty":0.23055011}],"checksum":392082950,"timestamp":"2026-07-15T04:00:17.133297Z"}]}
{"channel":"book","type":"update","data":[{"symbol":"BTC/USD","bids":[],"asks":[{"price":64740.8,"qty":0.00000000},{"price":64745.4,"qty":0.11000000}],"checksum":1022373990,"timestamp":"2026-07-15T04:00:17.171243Z"}]}
{"channel":"book","type":"update","data":[{"symbol":"BTC/USD","bids":[],"asks":[{"price":64744.1,"qty":0.77227159}],"checksum":781902774,"timestamp":"2026-07-15T04:00:17.174273Z"}]}
{"channel":"book","type":"update","data":[{"symbol":"BTC/USD","bids":[],"asks":[{"price":64740.7,"qty":0.00000000},{"price":64745.4,"qty":0.11000000}],"checksum":1106321011,"timestamp":"2026-07-15T04:00:17.175978Z"}]}
{"channel":"book","type":"update","data":[{"symbol":"BTC/USD","bids":[],"asks":[{"price":64738.3,"qty":0.93754235}],"checksum":2439027605,"timestamp":"2026-07-15T04:00:17.176840Z"}]}
{"channel":"book","type":"update","data":[{"symbol":"BTC/USD","bids":[],"asks":[{"price":64742.6,"qty":0.41615228}],"checksum":389616972,"timestamp":"2026-07-15T04:00:17.177232Z"}]}
{"channel":"book","type":"update","data":[{"symbol":"BTC/USD","bids":[],"asks":[{"price":64738.3,"qty":0.88154492}],"checksum":3349713066,"timestamp":"2026-07-15T04:00:17.184512Z"}]}
{"channel":"heartbeat"}
{"channel":"book","type":"update","data":[{"symbol":"BTC/USD","bids":[{"price":64732.5,"qty":0.00000000},{"price":64731.5,"qty":0.00005100}],"asks":[],"checksum":667108461,"timestamp":"2026-07-15T04:00:17.329390Z"}]}
{"channel":"book","type":"update","data":[{"symbol":"BTC/USD","bids":[],"asks":[{"price":64742.7,"qty":0.00000000},{"price":64746.7,"qty":0.03088960}],"checksum":3573724636,"timestamp":"2026-07-15T04:00:17.329482Z"}]}
{"channel":"book","type":"update","data":[{"symbol":"BTC/USD","bids":[],"asks":[{"price":64742.6,"qty":0.21284044}],"checksum":3424247777,"timestamp":"2026-07-15T04:00:17.331534Z"}]}
{"channel":"book","type":"update","data":[{"symbol":"BTC/USD","bids":[],"asks":[{"price":64738.3,"qty":0.92161503}],"checksum":997547716,"timestamp":"2026-07-15T04:00:17.512287Z"}]}
{"channel":"book","type":"update","data":[{"symbol":"BTC/USD","bids":[],"asks":[{"price":64738.3,"qty":0.88154492}],"checksum":3424247777,"timestamp":"2026-07-15T04:00:17.550053Z"}]}
{"channel":"book","type":"update","data":[{"symbol":"BTC/USD","bids":[{"price":64733.5,"qty":0.00154480}],"asks":[],"checksum":928986983,"timestamp":"2026-07-15T04:00:17.551776Z"}]}
{"channel":"book","type":"update","data":[{"symbol":"BTC/USD","bids":[],"asks":[{"price":64741.1,"qty":0.00159562}],"checksum":1325916476,"timestamp":"2026-07-15T04:00:17.551989Z"}]}
{"channel":"book","type":"update","data":[{"symbol":"BTC/USD","bids":[{"price":64734.6,"qty":0.00000000},{"price":64731.5,"qty":0.00005100}],"asks":[],"checksum":2797574987,"timestamp":"2026-07-15T04:00:17.553496Z"}]}
{"channel":"book","type":"update","data":[{"symbol":"BTC/USD","bids":[{"price":64733.5,"qty":0.01798777}],"asks":[],"checksum":3381635862,"timestamp":"2026-07-15T04:00:17.553574Z"}]}
{"channel":"book","type":"update","data":[{"symbol":"BTC/USD","bids":[{"price":64738.2,"qty":0.03129337}],"asks":[],"checksum":4251572867,"timestamp":"2026-07-15T04:00:17.573216Z"}]}
{"channel":"book","type":"update","data":[{"symbol":"BTC/USD","bids":[],"asks":[{"price":64739.6,"qty":0.77232515}],"checksum":2215125028,"timestamp":"2026-07-15T04:00:18.074257Z"}]}
{"channel":"heartbeat"}
{"channel":"book","type":"update","data":[{"symbol":"BTC/USD","bids":[],"asks":[{"price":64740.0,"qty":0.51894522}],"checksum":871379274,"timestamp":"2026-07-15T04:00:18.314476Z"}]}
{"channel":"trade","type":"update","data":[{"symbol":"BTC/USD","side":"buy","price":64738.3,"qty":0.00132689,"ord_type":"market","trade_id":103746795,"timestamp":"2026-07-15T04:00:18.822204Z"},{"symbol":"BTC/USD","side":"buy","price":64738.3,"qty":0.00001930,"ord_type":"market","trade_id":103746796,"timestamp":"2026-07-15T04:00:18.822204Z"},{"symbol":"BTC/USD","side":"buy","price":64738.3,"qty":0.00289764,"ord_type":"market","trade_id":103746797,"timestamp":"2026-07-15T04:00:18.822204Z"}]}
{"channel":"book","type":"update","data":[{"symbol":"BTC/USD","bids":[],"asks":[{"price":64738.3,"qty":0.88021803},{"price":64738.3,"qty":0.88019873},{"price":64738.3,"qty":0.87730109}],"checksum":4113414186,"timestamp":"2026-07-15T04:00:18.822204Z"}]}
{"channel":"book","type":"update","data":[{"symbol":"BTC/USD","bids":[],"asks":[{"price":64738.3,"qty":0.87807343}],"checksum":2447108257,"timestamp":"2026-07-15T04:00:18.834038Z"}]}
{"channel":"book","type":"update","data":[{"symbol":"BTC/USD","bids":[],"asks":[{"price":64739.5,"qty":0.38592050}],"checksum":2823073464,"timestamp":"2026-07-15T04:00:19.013423Z"}]}
{"channel":"book","type":"update","data":[{"symbol":"BTC/USD","bids":[{"price":64735.1,"qty":0.00154475}],"asks":[],"checksum":4067013029,"timestamp":"2026-07-15T04:00:19.047803Z"}]}
{"channel":"book","type":"update","data":[{"symbol":"BTC/USD","bids":[],"asks":[{"price":64738.3,"qty":0.93627343}],"checksum":353382314,"timestamp":"2026-07-15T04:00:19.132973Z"}]}
{"channel":"book","type":"update","data":[{"symbol":"BTC/USD","bids":[{"price":64733.5,"qty":0.01644297}],"asks":[],"checksum":3979561983,"timestamp":"2026-07-15T04:00:19.134782Z"}]}
{"channel":"book","type":"update","data":[{"symbol":"BTC/USD","bids":[{"price":64732.4,"qty":0.17922592}],"asks":[],"checksum":3894070047,"timestamp":"2026-07-15T04:00:19.143056Z"}]}
{"channel":"book","type":"update","data":[{"symbol":"BTC/USD","bids":[{"price":64732.4,"qty":0.00000000},{"price":64731.5,"qty":0.00005100}],"asks":[],"checksum":4217889760,"timestamp":"2026-07-15T04:00:19.143721Z"}]}
{"channel":"book","type":"update","data":[{"symbol":"BTC/USD","bids":[],"asks":[{"price":64738.3,"qty":1.33278914}],"checksum":2854569796,"timestamp":"2026-07-15T04:00:19.144630Z"}]}
{"channel":"book","type":"update","data":[{"symbol":"BTC/USD","bids":[{"price":64735.0,"qty":0.00000000},{"price":64730.3,"qty":1.72919400}],"asks":[],"checksum":2578583459,"timestamp":"2026-07-15T04:00:19.150270Z"}]}
{"channel":"book","type":"update","data":[{"symbol":"BTC/USD","bids":[{"price":64732.3,"qty":0.03656174}],"asks":[],"checksum":338733737,"timestamp":"2026-07-15T04:00:19.151832Z"}]}
{"channel":"book","type":"update","data":[{"symbol":"BTC/USD","bids":[{"price":64733.5,"qty":0.00000000},{"price":64730.3,"qty":1.72919400}],"asks":[],"checksum":1286575118,"timestamp":"2026-07-15T04:00:19.152256Z"}]}
{"channel":"book","type":"update","data":[{"symbol":"BTC/USD","bids":[],"asks":[{"price":64740.0,"qty":0.00000000},{"price":64744.3,"qty":0.00005100}],"checksum":3829943674,"timestamp":"2026-07-15T04:00:19.179861Z"}]}
{"channel":"book","type":"update","data":[{"symbol":"BTC/USD","bids":[],"asks":[{"price":64739.5,"qty":0.00000000},{"price":64745.4,"qty":0.11000000}],"checksum":2634979816,"timestamp":"2026-07-15T04:00:19.183057Z"}]}
{"channel":"book","type":"update","data":[{"symbol":"BTC/USD","bids":[{"price":64735.1,"qty":0.00000000},{"price":64729.2,"qty":0.15492037}],"asks":[],"checksum":2127713357,"timestamp":"2026-07-15T04:00:19.184079Z"}]}
{"channel":"book","type":"update","data":[{"symbol":"BTC/USD","bids":[],"asks":[{"price":64739.5,"qty":0.23101535}],"checksum":1699194606,"timestamp":"2026-07-15T04:00:19.184370Z"}]}
{"channel":"book","type":"update","data":[{"symbol":"BTC/USD","bids":[],"asks":[{"price":64738.3,"qty":1.27458914}],"checksum":3557347656,"timestamp":"2026-07-15T04:00:19.231604Z"}]}
{"channel":"book","type":"update","data":[{"symbol":"BTC/USD","bids":[],"asks":[{"price":64738.3,"qty":1.42467792}],"checksum":3059137061,"timestamp":"2026-07-15T04:00:19.233073Z"}]}
{"channel":"book","type":"update","data":[{"symbol":"BTC/USD","bids":[],"asks":[{"price":64738.3,"qty":1.02816221}],"checksum":4197156004,"timestamp":"2026-07-15T04:00:19.233809Z"}]}
{"channel":"book","type":"update","data":[{"symbol":"BTC/USD","bids":[{"price":64730.4,"qty":0.51616441}],"asks":[],"checksum":3233651568,"timestamp":"2026-07-15T04:00:19.264840Z"}]}
{"channel":"book","type":"update","data":[{"symbol":"BTC/USD","bids":[{"price":64738.1,"qty":0.00307083}],"asks":[],"checksum":1075820589,"timestamp":"2026-07-15T04:00:19.280798Z"}]}
{"channel":"heartbeat"}
{"channel":"book","type":"update","data":[{"symbol":"BTC/USD","bids":[{"price":64738.1,"qty":0.00000000},{"price":64730.3,"qty":1.72919400}],"asks":[],"checksum":3233651568,"timestamp":"2026-07-15T04:00:19.297389Z"}]}
{"channel":"book","type":"update","data":[{"symbol":"BTC/USD","bids":[],"asks":[{"price":64739.9,"qty":0.51894522}],"checksum":2249192646,"timestamp":"2026-07-15T04:00:19.669665Z"}]}
{"channel":"book","type":"update","data":[{"symbol":"BTC/USD","bids":[{"price":64738.1,"qty":0.00307083}],"asks":[],"checksum":4131807292,"timestamp":"2026-07-15T04:00:19.685833Z"}]}
{"channel":"book","type":"update","data":[{"symbol":"BTC/USD","bids":[{"price":64732.6,"qty":0.03043855}],"asks":[],"checksum":975767709,"timestamp":"2026-07-15T04:00:19.687409Z"}]}
{"channel":"book","type":"update","data":[{"symbol":"BTC/USD","bids":[{"price":64732.6,"qty":0.01400000}],"asks":[],"checksum":4131807292,"timestamp":"2026-07-15T04:00:19.688384Z"}]}
{"channel":"book","type":"update","data":[{"symbol":"BTC/USD","bids":[{"price":64738.1,"qty":0.00000000},{"price":64730.3,"qty":1.72919400}],"asks":[],"checksum":2249192646,"timestamp":"2026-07-15T04:00:19.702650Z"}]}
{"channel":"book","type":"update","data":[{"symbol":"BTC/USD","bids":[],"asks":[{"price":64738.3,"qty":0.87807343}],"checksum":3317030251,"timestamp":"2026-07-15T04:00:19.840493Z"}]}
{"channel":"book","type":"update","data":[{"symbol":"BTC/USD","bids":[],"asks":[{"price":64738.3,"qty":0.92185678}],"checksum":1006804741,"timestamp":"2026-07-15T04:00:19.841663Z"}]}
{"channel":"book","type":"update","data":[{"symbol":"BTC/USD","bids":[],"asks":[{"price":64738.3,"qty":0.94925678}],"checksum":3947349446,"timestamp":"2026-07-15T04:00:19.842250Z"}]}
{"channel":"book","type":"update","data":[{"symbol":"BTC/USD","bids":[{"price":64738.1,"qty":0.00307083}],"asks":[],"checksum":3891354157,"timestamp":"2026-07-15T04:00:19.856528Z"}]}
{"channel":"book","type":"update","data":[{"symbol":"BTC/USD","bids":[{"price":64738.1,"qty":0.00000000},{"price":64730.3,"qty":1.72919400}],"asks":[],"checksum":3947349446,"timestamp":"2026-07-15T04:00:19.873027Z"}]}
{"channel":"book","type":"update","data":[{"symbol":"BTC/USD","bids":[],"asks":[{"price":64738.3,"qty":0.90547343}],"checksum":121049678,"timestamp":"2026-07-15T04:00:19.975567Z"}]}
{"channel":"book","type":"update","data":[{"symbol":"BTC/USD","bids":[],"asks":[{"price":64739.5,"qty":0.35638564}],"checksum":3380333728,"timestamp":"2026-07-15T04:00:19.976934Z"}]}
{"channel":"book","type":"update","data":[{"symbol":"BTC/USD","bids":[{"price":64738.1,"qty":0.00307083}],"asks":[],"checksum":4263064681,"timestamp":"2026-07-15T04:00:19.991701Z"}]}
{"channel":"book","type":"update","data":[{"symbol":"BTC/USD","bids":[{"price":64738.1,"qty":0.00000000},{"price":64730.3,"qty":1.72919400}],"asks":[],"checksum":3380333728,"timestamp":"2026-07-15T04:00:20.008636Z"}]}
{"channel":"book","type":"update","data":[{"symbol":"BTC/USD","bids":[{"price":64734.8,"qty":0.00308876}],"asks":[],"checksum":1219945684,"timestamp":"2026-07-15T04:00:20.121333Z"}]}
{"channel":"book","type":"update","data":[{"symbol":"BTC/USD","bids":[],"asks":[{"price":64738.4,"qty":0.00000000},{"price":64744.3,"qty":0.00005100}],"checksum":1732425316,"timestamp":"2026-07-15T04:00:20.152054Z"}]}
{"channel":"book","type":"update","data":[{"symbol":"BTC/USD","bids":[],"asks":[{"price":64741.7,"qty":0.77230092}],"checksum":1428684273,"timestamp":"2026-07-15T04:00:20.153745Z"}]}
{"channel":"book","type":"update","data":[{"symbol":"BTC/USD","bids":[],"asks":[{"price":64739.5,"qty":0.12537029}],"checksum":817621365,"timestamp":"2026-07-15T04:00:20.155308Z"}]}
{"channel":"book","type":"update","data":[{"symbol":"BTC/USD","bids":[],"asks":[{"price":64739.5,"qty":0.00000000},{"price":64744.3,"qty":0.00005100}],"checksum":2898301994,"timestamp":"2026-07-15T04:00:20.155378Z"}]}
{"channel":"book","type":"update","data":[{"symbol":"BTC/USD","bids":[],"asks":[{"price":64739.5,"qty":0.61645232}],"checksum":547057317,"timestamp":"2026-07-15T04:00:20.157431Z"}]}
{"channel":"book","type":"update","data":[{"symbol":"BTC/USD","bids":[],"asks":[{"price":64739.5,"qty":0.00000000},{"price":64744.3,"qty":0.00005100}],"checksum":2898301994,"timestamp":"2026-07-15T04:00:20.170709Z"}]}
{"channel":"book","type":"update","data":[{"symbol":"BTC/USD","bids":[],"asks":[{"price":64739.6,"qty":0.00000000},{"price":64745.4,"qty":0.11000000}],"checksum":2549549893,"timestamp":"2026-07-15T04:00:20.170867Z"}]}
{"channel":"book","type":"update","data":[{"symbol":"BTC/USD","bids":[],"asks":[{"price":64744.1,"qty":0.00000000},{"price":64746.7,"qty":0.03088960}],"checksum":2846685235,"timestamp":"2026-07-15T04:00:20.171078Z"}]}
{"channel":"book","type":"update","data":[{"symbol":"BTC/USD","bids":[],"asks":[{"price":64741.7,"qty":0.00000000},{"price":64747.6,"qty":0.00005100}],"checksum":3711391619,"timestamp":"2026-07-15T04:00:20.171095Z"}]}
{"channel":"book","type":"update","data":[{"symbol":"BTC/USD","bids":[],"asks":[{"price":64742.6,"qty":0.27077573}],"checksum":4194617194,"timestamp":"2026-07-15T04:00:20.172645Z"}]}
{"channel":"book","type":"update","data":[{"symbol":"BTC/USD","bids":[],"asks":[{"price":64742.6,"qty":0.05793529}],"checksum":94038100,"timestamp":"2026-07-15T04:00:20.172728Z"}]}
{"channel":"book","type":"update","data":[{"symbol":"BTC/USD","bids":[],"asks":[{"price":64741.6,"qty":0.77230168}],"checksum":3849622361,"timestamp":"2026-07-15T04:00:20.173182Z"}]}
{"channel":"book","type":"update","data":[{"symbol":"BTC/USD","bids":[{"price":64731.4,"qty":0.77242259}],"asks":[],"checksum":2147947235,"timestamp":"2026-07-15T04:00:20.173769Z"}]}
{"channel":"book","type":"update","data":[{"symbol":"BTC/USD","bids":[{"price":64734.0,"qty":0.77239067}],"asks":[],"checksum":1934070353,"timestamp":"2026-07-15T04:00:20.175644Z"}]}
{"channel":"book","type":"update","data":[{"symbol":"BTC/USD","bids":[],"asks":[{"price":64746.7,"qty":0.26141817}],"checksum":800439488,"timestamp":"2026-07-15T04:00:20.176498Z"}]}
{"channel":"book","type":"update","data":[{"symbol":"BTC/USD","bids":[{"price":64731.7,"qty":0.05820000}],"asks":[],"checksum":1475540701,"timestamp":"2026-07-15T04:00:20.178426Z"}]}
{"channel":"book","type":"update","data":[{"symbol":"BTC/USD","bids":[{"price":64731.6,"qty":0.00000000},{"price":64731.4,"qty":0.77242259},{"price":64731.8,"qty":0.03086388}],"asks":[],"checksum":882244455,"timestamp":"2026-07-15T04:00:20.180083Z"}]}
{"channel":"book","type":"update","data":[{"symbol":"BTC/USD","bids":[],"asks":[{"price":64741.6,"qty":0.00000000},{"price":64746.8,"qty":0.77223903}],"checksum":3102558902,"timestamp":"2026-07-15T04:00:20.180855Z"}]}
{"channel":"book","type":"update","data":[{"symbol":"BTC/USD","bids":[],"asks":[{"price":64738.3,"qty":0.89837151}],"checksum":684669924,"timestamp":"2026-07-15T04:00:20.184044Z"}]}
{"channel":"book","type":"update","data":[{"symbol":"BTC/USD","bids":[{"price":64734.7,"qty":0.01653140}],"asks":[],"checksum":1496377540,"timestamp":"2026-07-15T04:00:20.186541Z"}]}
{"channel":"book","type":"update","data":[{"symbol":"BTC/USD","bids":[],"asks":[{"price":64741.1,"qty":0.00005100}],"checksum":3398993977,"timestamp":"2026-07-15T04:00:20.209790Z"}]}
{"channel":"book","type":"update","data":[{"symbol":"BTC/USD","bids":[{"price":64734.0,"qty":0.00000000},{"price":64731.4,"qty":0.77242259}],"asks":[],"checksum":3000779500,"timestamp":"2026-07-15T04:00:20.223319Z"}]}
{"channel":"book","type":"update","data":[{"symbol":"BTC/USD","bids":[{"price":64734.7,"qty":0.00005100}],"asks":[],"checksum":2818245843,"timestamp":"2026-07-15T04:00:20.224960Z"}]}
{"channel":"book","type":"update","data":[{"symbol":"BTC/USD","bids":[],"asks":[{"price":64738.3,"qty":0.90547343}],"checksum":424649814,"timestamp":"2026-07-15T04:00:20.227313Z"}]}
{"channel":"book","type":"update","data":[{"symbol":"BTC/USD","bids":[],"asks":[{"price":64741.8,"qty":0.77229861}],"checksum":4024006757,"timestamp":"2026-07-15T04:00:20.273781Z"}]}
{"channel":"heartbeat"}
{"channel":"book","type":"update","data":[{"symbol":"BTC/USD","bids":[{"price":64732.3,"qty":0.00000000},{"price":64730.4,"qty":0.51616441}],"asks":[],"checksum":371634212,"timestamp":"2026-07-15T04:00:20.314618Z"}]}
{"channel":"book","type":"update","data":[{"symbol":"BTC/USD","bids":[{"price":64735.0,"qty":0.03656174}],"asks":[],"checksum":1369019244,"timestamp":"2026-07-15T04:00:20.314661Z"}]}
{"channel":"book","type":"update","data":[{"symbol":"BTC/USD","bids":[{"price":64733.9,"qty":0.77239214}],"asks":[],"checksum":4077212355,"timestamp":"2026-07-15T04:00:20.316409Z"}]}
{"channel":"book","type":"update","data":[{"symbol":"BTC/USD","bids":[{"price":64733.9,"qty":0.00000000},{"price":64731.4,"qty":0.77242259}],"asks":[],"checksum":1369019244,"timestamp":"2026-07-15T04:00:20.326183Z"}]}
{"channel":"book","type":"update","data":[{"symbol":"BTC/USD","bids":[{"price":64738.1,"qty":0.00307083}],"asks":[],"checksum":2627153954,"timestamp":"2026-07-15T04:00:20.331842Z"}]}
{"channel":"book","type":"update","data":[{"symbol":"BTC/USD","bids":[{"price":64738.1,"qty":0.00000000},{"price":64731.4,"qty":0.77242259}],"asks":[],"checksum":1369019244,"timestamp":"2026-07-15T04:00:20.348588Z"}]}
{"channel":"book","type":"update","data":[{"symbol":"BTC/USD","bids":[{"price":64733.9,"qty":0.77239278}],"asks":[],"checksum":2783561315,"timestamp":"2026-07-15T04:00:20.433484Z"}]}
{"channel":"book","type":"update","data":[{"symbol":"BTC/USD","bids":[],"asks":[{"price":64741.8,"qty":0.00000000},{"price":64746.8,"qty":0.77223903}],"checksum":1400838736,"timestamp":"2026-07-15T04:00:20.471017Z"}]}
{"channel":"book","type":"update","data":[{"symbol":"BTC/USD","bids":[],"asks":[{"price":64740.9,"qty":0.77230937}],"checksum":2054293626,"timestamp":"2026-07-15T04:00:20.472510Z"}]}
{"channel":"book","type":"update","data":[{"symbol":"BTC/USD","bids":[],"asks":[{"price":64743.2,"qty":0.77228242}],"checksum":899306117,"timestamp":"2026-07-15T04:00:20.472934Z"}]}
{"channel":"book","type":"update","data":[{"symbol":"BTC/USD","bids":[],"asks":[{"price":64738.3,"qty":0.89837151}],"checksum":2335109632,"timestamp":"2026-07-15T04:00:20.475127Z"}]}
{"channel":"book","type":"update","data":[{"symbol":"BTC/USD","bids":[],"asks":[{"price":64738.3,"qty":0.90547343}],"checksum":899306117,"timestamp":"2026-07-15T04:00:20.477973Z"}]}
{"channel":"book","type":"update","data":[{"symbol":"BTC/USD","bids":[],"asks":[{"price":64739.9,"qty":0.00000000},{"price":64746.7,"qty":0.26141817}],"checksum":864974597,"timestamp":"2026-07-15T04:00:20.505496Z"}]}
{"channel":"book","type":"update","data":[{"symbol":"BTC/USD","bids":[{"price":64734.0,"qty":0.23055924}],"asks":[],"checksum":3926042290,"timestamp":"2026-07-15T04:00:20.508751Z"}]}
{"channel":"book","type":"update","data":[{"symbol":"BTC/USD","bids":[{"price":64734.7,"qty":0.01653485}],"asks":[],"checksum":3533581658,"timestamp":"2026-07-15T04:00:20.817055Z"}]}
{"channel":"book","type":"update","data":[{"symbol":"BTC/USD","bids":[],"asks":[{"price":64738.3,"qty":0.89837151}],"checksum":155610780,"timestamp":"2026-07-15T04:00:20.866761Z"}]}
{"channel":"book","type":"update","data":[{"symbol":"BTC/USD","bids":[{"price":64734.8,"qty":0.00154400}],"asks":[],"checksum":1114308145,"timestamp":"2026-07-15T04:00:21.035401Z"}]}
{"channel":"book","type":"update","data":[{"symbol":"BTC/USD","bids":[{"price":64735.1,"qty":0.00154475}],"asks":[],"checksum":3709921055,"timestamp":"2026-07-15T04:00:21.037122Z"}]}
{"channel":"trade","type":"update","data":[{"symbol":"BTC/USD","side":"buy","price":64738.3,"qty":0.00015294,"ord_type":"limit","trade_id":103746798,"timestamp":"2026-07-15T04:00:21.066634Z"}]}
{"channel":"book","type":"update","data":[{"symbol":"BTC/USD","bids":[],"asks":[{"price":64738.3,"qty":0.89821857}],"checksum":3773548978,"timestamp":"2026-07-15T04:00:21.066634Z"}]}
{"channel":"book","type":"update","data":[{"symbol":"BTC/USD","bids":[],"asks":[{"price":64743.7,"qty":0.51894522}],"checksum":952879020,"timestamp":"2026-07-15T04:00:21.148463Z"}]}
{"channel":"book","type":"update","data":[{"symbol":"BTC/USD","bids":[],"asks":[{"price":64738.3,"qty":0.90532049}],"checksum":4227719980,"timestamp":"2026-07-15T04:00:21.152154Z"}]}
{"channel":"book","type":"update","data":[{"symbol":"BTC/USD","bids":[{"price":64733.9,"qty":0.00000000},{"price":64731.7,"qty":0.05820000}],"asks":[],"checksum":2916426878,"timestamp":"2026-07-15T04:00:21.165901Z"}]}
{"channel":"book","type":"update","data":[{"symbol":"BTC/USD","bids":[],"asks":[{"price":64740.9,"qty":0.00000000},{"price":64746.7,"qty":0.26141817}],"checksum":2413545831,"timestamp":"2026-07-15T04:00:21.166246Z"}]}
{"channel":"book","type":"update","data":[{"symbol":"BTC/USD","bids":[{"price":64734.0,"qty":0.00000000},{"price":64731.5,"qty":0.00005100}],"asks":[],"checksum":825326765,"timestamp":"2026-07-15T04:00:21.167200Z"}]}
{"channel":"book","type":"update","data":[{"symbol":"BTC/USD","bids":[],"asks":[{"price":64741.6,"qty":0.77230111}],"checksum":3074710590,"timestamp":"2026-07-15T04:00:21.167752Z"}]}
{"channel":"book","type":"update","data":[{"symbol":"BTC/USD","bids":[{"price":64734.6,"qty":0.77238443}],"asks":[],"checksum":3815451318,"timestamp":"2026-07-15T04:00:21.168049Z"}]}
{"channel":"book","type":"update","data":[{"symbol":"BTC/USD","bids":[{"price":64735.1,"qty":0.01785497}],"asks":[],"checksum":3275872647,"timestamp":"2026-07-15T04:00:21.168489Z"}]}
{"channel":"book","type":"update","data":[{"symbol":"BTC/USD","bids":[],"asks":[{"price":64738.3,"qty":0.89821857}],"checksum":7863559,"timestamp":"2026-07-15T04:00:21.170311Z"}]}
{"channel":"book","type":"update","data":[{"symbol":"BTC/USD","bids":[],"asks":[{"price":64738.3,"qty":0.90532049}],"checksum":3275872647,"timestamp":"2026-07-15T04:00:21.172809Z"}]}
{"channel":"book","type":"update","data":[{"symbol":"BTC/USD","bids":[{"price":64732.6,"qty":0.78640825}],"asks":[],"checksum":556992615,"timestamp":"2026-07-15T04:00:21.174311Z"}]}
{"channel":"book","type":"update","data":[{"symbol":"BTC/USD","bids":[],"asks":[{"price":64738.3,"qty":0.89821857}],"checksum":3427319139,"timestamp":"2026-07-15T04:00:21.177545Z"}]}
{"channel":"book","type":"update","data":[{"symbol":"BTC/USD","bids":[{"price":64738.1,"qty":0.00307083}],"asks":[],"checksum":4259829517,"timestamp":"2026-07-15T04:00:21.190561Z"}]}
{"channel":"trade","type":"update","data":[{"symbol":"BTC/USD","side":"buy","price":64738.3,"qty":0.00003045,"ord_type":"limit","trade_id":103746799,"timestamp":"2026-07-15T04:00:21.195431Z"}]}
{"channel":"book","type":"update","data":[{"symbol":"BTC/USD","bids":[],"asks":[{"price":64738.3,"qty":0.89818812}],"checksum":517656150,"timestamp":"2026-07-15T04:00:21.195431Z"}]}
{"channel":"book","type":"update","data":[{"symbol":"BTC/USD","bids":[],"asks":[{"price":64743.2,"qty":0.00000000},{"price":64746.7,"qty":0.26141817}],"checksum":39716493,"timestamp":"2026-07-15T04:00:21.230911Z"}]}
{"channel":"book","type":"update","data":[{"symbol":"BTC/USD","bids":[],"asks":[{"price":64741.6,"qty":0.00000000},{"price":64746.8,"qty":0.77223903}],"checksum":4159066429,"timestamp":"2026-07-15T04:00:21.231192Z"}]}
{"channel":"book","type":"update","data":[{"symbol":"BTC/USD","bids":[{"price":64734.6,"qty":0.00000000},{"price":64731.7,"qty":0.05820000}],"asks":[],"checksum":2833456511,"timestamp":"2026-07-15T04:00:21.231331Z"}]}
{"channel":"book","type":"update","data":[{"symbol":"BTC/USD","bids":[],"asks":[{"price":64744.6,"qty":0.77226536}],"checksum":747741252,"timestamp":"2026-07-15T04:00:21.233205Z"}]}
{"channel":"book","type":"update","data":[{"symbol":"BTC/USD","bids":[],"asks":[{"price":64742.6,"qty":0.43595474}],"checksum":1575548212,"timestamp":"2026-07-15T04:00:21.235129Z"}]}
{"channel":"book","type":"update","data":[{"symbol":"BTC/USD","bids":[{"price":64738.1,"qty":0.00000000},{"price":64731.5,"qty":0.00005100}],"asks":[],"checksum":2364252237,"timestamp":"2026-07-15T04:00:21.251018Z"}]}
{"channel":"book","type":"update","data":[{"symbol":"BTC/USD","bids":[],"asks":[{"price":64741.6,"qty":0.77230193}],"checksum":2078587067,"timestamp":"2026-07-15T04:00:21.286860Z"}]}
{"channel":"book","type":"update","data":[{"symbol":"BTC/USD","bids":[{"price":64734.8,"qty":0.77392520}],"asks":[],"checksum":3164131310,"timestamp":"2026-07-15T04:00:21.287131Z"}]}
{"channel":"heartbeat"}
{"channel":"book","type":"update","data":[{"symbol":"BTC/USD","bids":[{"price":64734.7,"qty":0.00005100}],"asks":[],"checksum":1020501037,"timestamp":"2026-07-15T04:00:21.290052Z"}]}
{"channel":"book","type":"update","data":[{"symbol":"BTC/USD","bids":[],"asks":[{"price":64738.3,"qty":0.90529004}],"checksum":2768679245,"timestamp":"2026-07-15T04:00:21.290181Z"}]}
{"channel":"book","type":"update","data":[{"symbol":"BTC/USD","bids":[{"price":64735.1,"qty":0.03428113}],"asks":[],"checksum":922298171,"timestamp":"2026-07-15T04:00:21.290348Z"}]}
{"channel":"book","type":"update","data":[{"symbol":"BTC/USD","bids":[{"price":64735.1,"qty":0.01785497}],"asks":[],"checksum":2768679245,"timestamp":"2026-07-15T04:00:21.291331Z"}]}
{"channel":"book","type":"update","data":[{"symbol":"BTC/USD","bids":[],"asks":[{"price":64738.3,"qty":0.89818812}],"checksum":1020501037,"timestamp":"2026-07-15T04:00:21.292705Z"}]}
{"channel":"book","type":"update","data":[{"symbol":"BTC/USD","bids":[{"price":64732.6,"qty":0.77240825},{"price":64732.7,"qty":0.01400000}],"asks":[],"checksum":2859752047,"timestamp":"2026-07-15T04:00:21.321961Z"}]}
{"channel":"book","type":"update","data":[{"symbol":"BTC/USD","bids":[{"price":64732.8,"qty":0.51894522}],"asks":[],"checksum":3628670139,"timestamp":"2026-07-15T04:00:21.334495Z"}]}
{"channel":"book","type":"update","data":[{"symbol":"BTC/USD","bids":[{"price":64738.1,"qty":0.00307083}],"asks":[],"checksum":88754074,"timestamp":"2026-07-15T04:00:21.350413Z"}]}
{"channel":"book","type":"update","data":[{"symbol":"BTC/USD","bids":[{"price":64737.4,"qty":0.00154471}],"asks":[],"checksum":3895433521,"timestamp":"2026-07-15T04:00:21.351828Z"}]}
{"channel":"book","type":"update","data":[{"symbol":"BTC/USD","bids":[],"asks":[{"price":64744.9,"qty":0.00154453}],"checksum":462661034,"timestamp":"2026-07-15T04:00:21.352125Z"}]}
{"channel":"trade","type":"update","data":[{"symbol":"BTC/USD","side":"buy","price":64738.3,"qty":0.00410436,"ord_type":"market","trade_id":103746800,"timestamp":"2026-07-15T04:00:21.383120Z"}]}
{"channel":"book","type":"update","data":[{"symbol":"BTC/USD","bids":[],"asks":[{"price":64738.3,"qty":0.89408376}],"checksum":1981570520,"timestamp":"2026-07-15T04:00:21.383120Z"}]}
{"channel":"book","type":"update","data":[{"symbol":"BTC/USD","bids":[{"price":64735.1,"qty":0.03425228}],"asks":[],"checksum":349330982,"timestamp":"2026-07-15T04:00:21.437329Z"}]}
{"channel":"book","type":"update","data":[{"symbol":"BTC/USD","bids":[],"asks":[{"price":64744.6,"qty":0.00000000},{"price":64745.4,"qty":0.11000000}],"checksum":2308352178,"timestamp":"2026-07-15T04:00:21.681074Z"}]}
{"channel":"book","type":"update","data":[{"symbol":"BTC/USD","bids":[],"asks":[{"price":64742.6,"qty":0.05793529}],"checksum":4282697661,"timestamp":"2026-07-15T04:00:21.682322Z"}]}
{"channel":"book","type":"update","data":[{"symbol":"BTC/USD","bids":[],"asks":[{"price":64742.6,"qty":0.00000000},{"price":64746.7,"qty":0.26141817}],"checksum":3953141625,"timestamp":"2026-07-15T04:00:21.682497Z"}]}
{"channel":"book","type":"update","data":[{"symbol":"BTC/USD","bids":[],"asks":[{"price":64743.4,"qty":0.77228040}],"checksum":2629434265,"timestamp":"2026-07-15T04:00:21.682674Z"}]}
{"channel":"book","type":"update","data":[{"symbol":"BTC/USD","bids":[],"asks":[{"price":64743.6,"qty":0.24481309}],"checksum":50686912,"timestamp":"2026-07-15T04:00:21.683670Z"}]}
{"channel":"book","type":"update","data":[{"symbol":"BTC/USD","bids":[],"asks":[{"price":64743.6,"qty":0.04492032}],"checksum":2629434265,"timestamp":"2026-07-15T04:00:21.683873Z"}]}
{"channel":"book","type":"update","data":[{"symbol":"BTC/USD","bids":[],"asks":[{"price":64743.3,"qty":0.44382718}],"checksum":2600041525,"timestamp":"2026-07-15T04:00:21.684272Z"}]}
{"channel":"book","type":"update","data":[{"symbol":"BTC/USD","bids":[{"price":64737.4,"qty":0.00000000},{"price":64732.6,"qty":0.77240825}],"asks":[],"checksum":202397926,"timestamp":"2026-07-15T04:00:21.749526Z"}]}
{"channel":"book","type":"update","data":[{"symbol":"BTC/USD","bids":[{"price":64735.1,"qty":0.41270755}],"asks":[],"checksum":1952393532,"timestamp":"2026-07-15T04:00:21.753052Z"}]}
{"channel":"book","type":"update","data":[{"symbol":"BTC/USD","bids":[{"price":64735.1,"qty":0.41116280}],"asks":[],"checksum":1725113207,"timestamp":"2026-07-15T04:00:21.756864Z"}]}
{"channel":"book","type":"update","data":[{"symbol":"BTC/USD","bids":[{"price":64736.6,"qty":0.00154473}],"asks":[],"checksum":2563988835,"timestamp":"2026-07-15T04:00:22.001755Z"}]}
{"channel":"heartbeat"}
{"channel":"book","type":"update","data":[{"symbol":"BTC/USD","bids":[{"price":64735.2,"qty":0.00154475}],"asks":[],"checksum":1283668372,"timestamp":"2026-07-15T04:00:23.046967Z"}]}
{"channel":"heartbeat"}
{"channel":"trade","type":"update","data":[{"symbol":"BTC/USD","side":"buy","price":64738.3,"qty":0.00152185,"ord_type":"limit","trade_id":103746801,"timestamp":"2026-07-15T04:00:23.382201Z"}]}
{"channel":"book","type":"update","data":[{"symbol":"BTC/USD","bids":[],"asks":[{"price":64738.3,"qty":0.89256191}],"checksum":2737485906,"timestamp":"2026-07-15T04:00:23.382201Z"}]}
{"channel":"book","type":"update","data":[{"symbol":"BTC/USD","bids":[],"asks":[{"price":64741.6,"qty":0.00000000},{"price":64745.4,"qty":0.11000000}],"checksum":71157910,"timestamp":"2026-07-15T04:00:24.193562Z"}]}
{"channel":"book","type":"update","data":[{"symbol":"BTC/USD","bids":[],"asks":[{"price":64740.8,"qty":0.77231135}],"checksum":823187534,"timestamp":"2026-07-15T04:00:24.195411Z"}]}
{"channel":"book","type":"update","data":[{"symbol":"BTC/USD","bids":[],"asks":[{"price":64738.3,"qty":0.89966383}],"checksum":51999726,"timestamp":"2026-07-15T04:00:24.199199Z"}]}
{"channel":"heartbeat"}
{"channel":"book","type":"update","data":[{"symbol":"BTC/USD","bids":[{"price":64736.6,"qty":0.00000000},{"price":64732.7,"qty":0.01400000}],"asks":[],"checksum":293619799,"timestamp":"2026-07-15T04:00:24.539721Z"}]}
{"channel":"book","type":"update","data":[{"symbol":"BTC/USD","bids":[{"price":64734.8,"qty":0.00154400}],"asks":[],"checksum":392793820,"timestamp":"2026-07-15T04:00:24.666617Z"}]}
{"channel":"book","type":"update","data":[{"symbol":"BTC/USD","bids":[{"price":64735.1,"qty":0.39485258}],"asks":[],"checksum":78230514,"timestamp":"2026-07-15T04:00:24.667855Z"}]}
{"channel":"book","type":"update","data":[{"symbol":"BTC/USD","bids":[{"price":64735.1,"qty":0.01639731}],"asks":[],"checksum":2560257636,"timestamp":"2026-07-15T04:00:24.668088Z"}]}
{"channel":"book","type":"update","data":[{"symbol":"BTC/USD","bids":[{"price":64734.1,"qty":0.77239022}],"asks":[],"checksum":3709474629,"timestamp":"2026-07-15T04:00:24.668372Z"}]}
{"channel":"book","type":"update","data":[{"symbol":"BTC/USD","bids":[{"price":64735.1,"qty":0.00000000},{"price":64732.7,"qty":0.01400000}],"asks":[],"checksum":1335607048,"timestamp":"2026-07-15T04:00:24.669426Z"}]}
{"channel":"book","type":"update","data":[{"symbol":"BTC/USD","bids":[{"price":64732.9,"qty":0.15490515}],"asks":[],"checksum":4163549252,"timestamp":"2026-07-15T04:00:24.669440Z"}]}
{"channel":"book","type":"update","data":[{"symbol":"BTC/USD","bids":[],"asks":[{"price":64740.7,"qty":0.23055016}],"checksum":69549204,"timestamp":"2026-07-15T04:00:24.669657Z"}]}
{"channel":"book","type":"update","data":[{"symbol":"BTC/USD","bids":[{"price":64734.7,"qty":0.01679767}],"asks":[],"checksum":2894119593,"timestamp":"2026-07-15T04:00:24.669957Z"}]}
{"channel":"book","type":"update","data":[{"symbol":"BTC/USD","bids":[],"asks":[{"price":64738.3,"qty":0.89256191}],"checksum":2758585541,"timestamp":"2026-07-15T04:00:24.671664Z"}]}
{"channel":"book","type":"update","data":[{"symbol":"BTC/USD","bids":[{"price":64735.2,"qty":0.00000000},{"price":64732.7,"qty":0.01400000}],"asks":[],"checksum":3648689097,"timestamp":"2026-07-15T04:00:24.673720Z"}]}
{"channel":"book","type":"update","data":[{"symbol":"BTC/USD","bids":[{"price":64735.1,"qty":0.00038313}],"asks":[],"checksum":150547999,"timestamp":"2026-07-15T04:00:24.673880Z"}]}
{"channel":"book","type":"update","data":[{"symbol":"BTC/USD","bids":[{"price":64735.1,"qty":0.00000000},{"price":64732.7,"qty":0.01400000}],"asks":[],"checksum":3648689097,"timestamp":"2026-07-15T04:00:24.676088Z"}]}
{"channel":"book","type":"update","data":[{"symbol":"BTC/USD","bids":[{"price":64738.1,"qty":0.00000000},{"price":64732.6,"qty":0.77240825}],"asks":[],"checksum":4224653589,"timestamp":"2026-07-15T04:00:24.682599Z"}]}
{"channel":"heartbeat"}
{"channel":"book","type":"update","data":[{"symbol":"BTC/USD","bids":[],"asks":[{"price":64743.7,"qty":0.00000000},{"price":64744.9,"qty":0.00154453}],"checksum":3301840899,"timestamp":"2026-07-15T04:00:25.483708Z"}]}
{"channel":"book","type":"update","data":[{"symbol":"BTC/USD","bids":[{"price":64732.8,"qty":0.00000000},{"price":64731.8,"qty":0.03086388}],"asks":[],"checksum":796658401,"timestamp":"2026-07-15T04:00:25.483817Z"}]}
{"channel":"book","type":"update","data":[{"symbol":"BTC/USD","bids":[],"asks":[{"price":64743.3,"qty":0.00000000},{"price":64745.4,"qty":0.11000000}],"checksum":3957827734,"timestamp":"2026-07-15T04:00:25.484979Z"}]}
{"channel":"book","type":"update","data":[{"symbol":"BTC/USD","bids":[{"price":64732.9,"qty":0.00000000},{"price":64731.7,"qty":0.05820000}],"asks":[],"checksum":1103715850,"timestamp":"2026-07-15T04:00:25.485630Z"}]}
{"channel":"book","type":"update","data":[{"symbol":"BTC/USD","bids":[],"asks":[{"price":64743.3,"qty":0.28892203}],"checksum":1452404211,"timestamp":"2026-07-15T04:00:25.487688Z"}]}
{"channel":"book","type":"update","data":[{"symbol":"BTC/USD","bids":[{"price":64731.7,"qty":0.00000000},{"price":64731.5,"qty":0.00005100}],"asks":[],"checksum":1762707353,"timestamp":"2026-07-15T04:00:25.492352Z"}]}
{"channel":"book","type":"update","data":[{"symbol":"BTC/USD","bids":[{"price":64731.8,"qty":0.00000000},{"price":64730.4,"qty":0.51616441},{"price":64731.6,"qty":0.03086388}],"asks":[],"checksum":1883100432,"timestamp":"2026-07-15T04:00:25.494112Z"}]}
{"channel":"book","type":"update","data":[{"symbol":"BTC/USD","bids":[{"price":64734.1,"qty":0.00000000},{"price":64730.4,"qty":0.51616441}],"asks":[],"checksum":4136096397,"timestamp":"2026-07-15T04:00:25.499072Z"}]}
{"channel":"book","type":"update","data":[{"symbol":"BTC/USD","bids":[],"asks":[{"price":64740.8,"qty":0.00000000},{"price":64745.4,"qty":0.11000000}],"checksum":280075935,"timestamp":"2026-07-15T04:00:25.499386Z"}]}
{"channel":"book","type":"update","data":[{"symbol":"BTC/USD","bids":[{"price":64732.6,"qty":0.00000000},{"price":64730.3,"qty":1.72919400}],"asks":[],"checksum":3754584065,"timestamp":"2026-07-15T04:00:25.499566Z"}]}
{"channel":"book","type":"update","data":[{"symbol":"BTC/USD","bids":[{"price":64734.7,"qty":0.00005100}],"asks":[],"checksum":345171439,"timestamp":"2026-07-15T04:00:25.500612Z"}]}
{"channel":"book","type":"update","data":[{"symbol":"BTC/USD","bids":[],"asks":[{"price":64740.7,"qty":0.00000000},{"price":64746.7,"qty":0.26141817}],"checksum":1236057124,"timestamp":"2026-07-15T04:00:25.500733Z"}]}
{"channel":"book","type":"update","data":[{"symbol":"BTC/USD","bids":[{"price":64732.7,"qty":0.03076821}],"asks":[],"checksum":3683427817,"timestamp":"2026-07-15T04:00:25.500915Z"}]}
{"channel":"book","type":"update","data":[{"symbol":"BTC/USD","bids":[],"asks":[{"price":64740.2,"qty":0.77231818}],"checksum":4134221348,"timestamp":"2026-07-15T04:00:25.501732Z"}]}
{"channel":"book","type":"update","data":[{"symbol":"BTC/USD","bids":[{"price":64733.2,"qty":0.77240065}],"asks":[],"checksum":3895707823,"timestamp":"2026-07-15T04:00:25.501998Z"}]}
{"channel":"book","type":"update","data":[{"symbol":"BTC/USD","bids":[{"price":64730.9,"qty":0.77242756}],"asks":[],"checksum":1638096181,"timestamp":"2026-07-15T04:00:25.502284Z"}]}
{"channel":"book","type":"update","data":[{"symbol":"BTC/USD","bids":[],"asks":[{"price":64738.3,"qty":0.89966383}],"checksum":495419537,"timestamp":"2026-07-15T04:00:25.502751Z"}]}
{"channel":"book","type":"update","data":[{"symbol":"BTC/USD","bids":[],"asks":[{"price":64740.1,"qty":0.23055220}],"checksum":2249910451,"timestamp":"2026-07-15T04:00:25.503297Z"}]}
{"channel":"book","type":"update","data":[{"symbol":"BTC/USD","bids":[{"price":64732.7,"qty":0.01400000}],"asks":[],"checksum":3006387608,"timestamp":"2026-07-15T04:00:25.503461Z"}]}
{"channel":"book","type":"update","data":[{"symbol":"BTC/USD","bids":[{"price":64734.7,"qty":0.01681869}],"asks":[],"checksum":925428214,"timestamp":"2026-07-15T04:00:25.503738Z"}]}
{"channel":"book","type":"update","data":[{"symbol":"BTC/USD","bids":[{"price":64731.7,"qty":0.05820000}],"asks":[],"checksum":2364097234,"timestamp":"2026-07-15T04:00:25.731596Z"}]}
{"channel":"book","type":"update","data":[{"symbol":"BTC/USD","bids":[{"price":64731.6,"qty":0.00000000},{"price":64730.9,"qty":0.77242756},{"price":64731.8,"qty":0.03086388}],"asks":[],"checksum":4019081064,"timestamp":"2026-07-15T04:00:25.732887Z"}]}
{"channel":"book","type":"update","data":[{"symbol":"BTC/USD","bids":[{"price":64733.2,"qty":0.00000000},{"price":64730.9,"qty":0.77242756}],"asks":[],"checksum":937615315,"timestamp":"2026-07-15T04:00:26.015131Z"}]}
{"channel":"book","type":"update","data":[{"symbol":"BTC/USD","bids":[{"price":64734.7,"qty":0.00005100}],"asks":[],"checksum":2426367936,"timestamp":"2026-07-15T04:00:26.016486Z"}]}
{"channel":"book","type":"update","data":[{"symbol":"BTC/USD","bids":[{"price":64732.7,"qty":0.03076339}],"asks":[],"checksum":671730698,"timestamp":"2026-07-15T04:00:26.016590Z"}]}
{"channel":"book","type":"update","data":[{"symbol":"BTC/USD","bids":[{"price":64734.1,"qty":0.77239040}],"asks":[],"checksum":3677998532,"timestamp":"2026-07-15T04:00:26.016681Z"}]}
{"channel":"book","type":"update","data":[{"symbol":"BTC/USD","bids":[{"price":64732.7,"qty":0.01400000}],"asks":[],"checksum":3737257728,"timestamp":"2026-07-15T04:00:26.017880Z"}]}
{"channel":"book","type":"update","data":[{"symbol":"BTC/USD","bids":[{"price":64734.7,"qty":0.01681387}],"asks":[],"checksum":3747863227,"timestamp":"2026-07-15T04:00:26.018175Z"}]}
{"channel":"book","type":"update","data":[{"symbol":"BTC/USD","bids":[{"price":64735.1,"qty":0.00154475}],"asks":[],"checksum":2900201752,"timestamp":"2026-07-15T04:00:26.030620Z"}]}
{"channel":"trade","type":"update","data":[{"symbol":"BTC/USD","side":"buy","price":64738.3,"qty":0.00458816,"ord_type":"limit","trade_id":103746802,"timestamp":"2026-07-15T04:00:26.127322Z"}]}
{"channel":"book","type":"update","data":[{"symbol":"BTC/USD","bids":[],"asks":[{"price":64738.3,"qty":0.89507567}],"checksum":2741866866,"timestamp":"2026-07-15T04:00:26.127322Z"}]}
{"channel":"heartbeat"}
{"channel":"book","type":"update","data":[{"symbol":"BTC/USD","bids":[],"asks":[{"price":64738.3,"qty":0.88797375}],"checksum":1658604539,"timestamp":"2026-07-15T04:00:26.496861Z"}]}
{"channel":"heartbeat"}
{"channel":"book","type":"update","data":[{"symbol":"BTC/USD","bids":[{"price":64734.8,"qty":0.00308877}],"asks":[],"checksum":4047704924,"timestamp":"2026-07-15T04:00:27.350351Z"}]}
{"channel":"book","type":"update","data":[{"symbol":"BTC/USD","bids":[],"asks":[{"price":64744.9,"qty":0.00000000},{"price":64745.4,"qty":0.11000000}],"checksum":3600635066,"timestamp":"2026-07-15T04:00:27.350539Z"}]}
{"channel":"book","type":"update","data":[{"symbol":"BTC/USD","bids":[],"asks":[{"price":64742.2,"qty":0.00154459}],"checksum":3177995745,"timestamp":"2026-07-15T04:00:27.350946Z"}]}
{"channel":"book","type":"update","data":[{"symbol":"BTC/USD","bids":[],"asks":[{"price":64742.0,"qty":0.59689488}],"checksum":3739109448,"timestamp":"2026-07-15T04:00:27.377490Z"}]}
{"channel":"book","type":"update","data":[{"symbol":"BTC/USD","bids":[],"asks":[{"price":64738.3,"qty":0.89507567}],"checksum":3744230592,"timestamp":"2026-07-15T04:00:27.381058Z"}]}
{"channel":"book","type":"update","data":[{"symbol":"BTC/USD","bids":[],"asks":[{"price":64738.3,"qty":0.88797375}],"checksum":3739109448,"timestamp":"2026-07-15T04:00:27.743039Z"}]}
{"channel":"book","type":"update","data":[{"symbol":"BTC/USD","bids":[],"asks":[{"price":64740.2,"qty":0.00000000},{"price":64744.3,"qty":0.00005100}],"checksum":2060807524,"timestamp":"2026-07-15T04:00:28.104614Z"}]}
{"channel":"book","type":"update","data":[{"symbol":"BTC/USD","bids":[],"asks":[{"price":64742.2,"qty":0.00000000},{"price":64745.4,"qty":0.11000000}],"checksum":3065040801,"timestamp":"2026-07-15T04:00:28.104831Z"}]}
{"channel":"book","type":"update","data":[{"symbol":"BTC/USD","bids":[],"asks":[{"price":64741.0,"qty":0.77230908}],"checksum":1303233465,"timestamp":"2026-07-15T04:00:28.106882Z"}]}
{"channel":"book","type":"update","data":[{"symbol":"BTC/USD","bids":[{"price":64732.0,"qty":0.77241463}],"asks":[],"checksum":3445519599,"timestamp":"2026-07-15T04:00:28.107158Z"}]}
{"channel":"book","type":"update","data":[{"symbol":"BTC/USD","bids":[{"price":64731.8,"qty":0.00000000},{"price":64731.7,"qty":0.05820000},{"price":64732.0,"qty":0.80327851}],"asks":[],"checksum":3030971774,"timestamp":"2026-07-15T04:00:28.108656Z"}]}
{"channel":"book","type":"update","data":[{"symbol":"BTC/USD","bids":[],"asks":[{"price":64738.3,"qty":0.89507567}],"checksum":2650635071,"timestamp":"2026-07-15T04:00:28.110416Z"}]}
{"channel":"trade","type":"update","data":[{"symbol":"BTC/USD","side":"buy","price":64738.3,"qty":0.00029458,"ord_type":"market","trade_id":103746803,"timestamp":"2026-07-15T04:00:28.142845Z"}]}
{"channel":"book","type":"update","data":[{"symbol":"BTC/USD","bids":[],"asks":[{"price":64738.3,"qty":0.89478109}],"checksum":242537035,"timestamp":"2026-07-15T04:00:28.142845Z"}]}
{"channel":"book","type":"update","data":[{"symbol":"BTC/USD","bids":[],"asks":[{"price":64741.0,"qty":0.00000000},{"price":64745.4,"qty":0.11000000}],"checksum":501438225,"timestamp":"2026-07-15T04:00:28.239745Z"}]}
{"channel":"book","type":"update","data":[{"symbol":"BTC/USD","bids":[],"asks":[{"price":64740.4,"qty":0.77231616}],"checksum":2174840977,"timestamp":"2026-07-15T04:00:28.241964Z"}]}
{"channel":"book","type":"update","data":[{"symbol":"BTC/USD","bids":[],"asks":[{"price":64738.3,"qty":0.88767917}],"checksum":1440653362,"timestamp":"2026-07-15T04:00:28.243322Z"}]}
{"channel":"book","type":"update","data":[{"symbol":"BTC/USD","bids":[],"asks":[{"price":64738.3,"qty":0.89478109}],"checksum":2174840977,"timestamp":"2026-07-15T04:00:28.246076Z"}]}
{"channel":"heartbeat"}
{"channel":"book","type":"update","data":[{"symbol":"BTC/USD","bids":[],"asks":[{"price":64740.4,"qty":0.00000000},{"price":64745.4,"qty":0.11000000}],"checksum":501438225,"timestamp":"2026-07-15T04:00:29.071842Z"}]}
{"channel":"book","type":"update","data":[{"symbol":"BTC/USD","bids":[],"asks":[{"price":64741.8,"qty":0.77229971}],"checksum":29605709,"timestamp":"2026-07-15T04:00:29.073907Z"}]}
{"channel":"book","type":"update","data":[{"symbol":"BTC/USD","bids":[],"asks":[{"price":64738.3,"qty":0.88767917}],"checksum":3585896430,"timestamp":"2026-07-15T04:00:29.075196Z"}]}
{"channel":"book","type":"update","data":[{"symbol":"BTC/USD","bids":[],"asks":[{"price":64738.3,"qty":0.89478109}],"checksum":29605709,"timestamp":"2026-07-15T04:00:29.078186Z"}]}
{"channel":"book","type":"update","data":[{"symbol":"BTC/USD","bids":[],"asks":[{"price":64741.8,"qty":0.00000000},{"price":64745.4,"qty":0.11000000}],"checksum":501438225,"timestamp":"2026-07-15T04:00:29.171453Z"}]}
{"channel":"book","type":"update","data":[{"symbol":"BTC/USD","bids":[],"asks":[{"price":64738.3,"qty":0.88767917}],"checksum":3382478770,"timestamp":"2026-07-15T04:00:29.174770Z"}]}
{"channel":"heartbeat"}
{"channel":"book","type":"update","data":[{"symbol":"BTC/USD","bids":[],"asks":[{"price":64740.1,"qty":0.00000000},{"price":64746.7,"qty":0.26141817}],"checksum":3481267103,"timestamp":"2026-07-15T04:00:29.423179Z"}]}
{"channel":"book","type":"update","data":[{"symbol":"BTC/USD","bids":[],"asks":[{"price":64741.9,"qty":0.17817312}],"checksum":3872017953,"timestamp":"2026-07-15T04:00:29.425761Z"}]}
{"channel":"book","type":"update","data":[{"symbol":"BTC/USD","bids":[{"price":64734.1,"qty":0.00000000},{"price":64731.5,"qty":0.00005100}],"asks":[],"checksum":657810890,"timestamp":"2026-07-15T04:00:29.430623Z"}]}
{"channel":"book","type":"update","data":[{"symbol":"BTC/USD","bids":[],"asks":[{"price":64741.7,"qty":0.77230002}],"checksum":1762361705,"timestamp":"2026-07-15T04:00:29.433450Z"}]}
{"channel":"book","type":"update","data":[{"symbol":"BTC/USD","bids":[{"price":64735.0,"qty":0.80894142}],"asks":[],"checksum":3298334229,"timestamp":"2026-07-15T04:00:29.433727Z"}]}
{"channel":"book","type":"update","data":[{"symbol":"BTC/USD","bids":[],"asks":[{"price":64741.9,"qty":0.00000000},{"price":64745.4,"qty":0.11000000}],"checksum":682010024,"timestamp":"2026-07-15T04:00:29.434979Z"}]}
{"channel":"book","type":"update","data":[{"symbol":"BTC/USD","bids":[],"asks":[{"price":64738.3,"qty":0.89478109}],"checksum":2641072508,"timestamp":"2026-07-15T04:00:29.436823Z"}]}
{"channel":"book","type":"update","data":[{"symbol":"BTC/USD","bids":[],"asks":[{"price":64741.6,"qty":0.40870468}],"checksum":4016132510,"timestamp":"2026-07-15T04:00:29.438172Z"}]}
{"channel":"book","type":"update","data":[{"symbol":"BTC/USD","bids":[],"asks":[{"price":64738.3,"qty":0.88767917}],"checksum":1521247562,"timestamp":"2026-07-15T04:00:29.439051Z"}]}
{"channel":"book","type":"update","data":[{"symbol":"BTC/USD","bids":[{"price":64734.7,"qty":0.00005100}],"asks":[],"checksum":1360138471,"timestamp":"2026-07-15T04:00:29.540315Z"}]}
{"channel":"book","type":"update","data":[{"symbol":"BTC/USD","bids":[{"price":64735.1,"qty":0.01841254}],"asks":[],"checksum":2395744101,"timestamp":"2026-07-15T04:00:29.540633Z"}]}
{"channel":"book","type":"update","data":[{"symbol":"BTC/USD","bids":[],"asks":[{"price":64742.0,"qty":0.00000000},{"price":64745.4,"qty":0.11000000}],"checksum":1420560051,"timestamp":"2026-07-15T04:00:29.887710Z"}]}
{"channel":"book","type":"update","data":[{"symbol":"BTC/USD","bids":[{"price":64732.0,"qty":0.03086388}],"asks":[],"checksum":3436251337,"timestamp":"2026-07-15T04:00:29.887933Z"}]}
{"channel":"book","type":"update","data":[{"symbol":"BTC/USD","bids":[],"asks":[{"price":64741.6,"qty":0.00000000},{"price":64746.7,"qty":0.26141817}],"checksum":2601690991,"timestamp":"2026-07-15T04:00:29.888583Z"}]}
{"channel":"book","type":"update","data":[{"symbol":"BTC/USD","bids":[{"price":64732.0,"qty":0.00000000},{"price":64730.4,"qty":0.51616441},{"price":64732.8,"qty":0.03086388}],"asks":[],"checksum":3662299322,"timestamp":"2026-07-15T04:00:29.889382Z"}]}
{"channel":"book","type":"update","data":[{"symbol":"BTC/USD","bids":[{"price":64733.3,"qty":0.77239974}],"asks":[],"checksum":891672149,"timestamp":"2026-07-15T04:00:29.889680Z"}]}
{"channel":"book","type":"update","data":[{"symbol":"BTC/USD","bids":[{"price":64735.1,"qty":0.26081878}],"asks":[],"checksum":213461396,"timestamp":"2026-07-15T04:00:29.890121Z"}]}
{"channel":"book","type":"update","data":[{"symbol":"BTC/USD","bids":[],"asks":[{"price":64741.7,"qty":0.00000000},{"price":64746.8,"qty":0.77223903}],"checksum":1484412098,"timestamp":"2026-07-15T04:00:29.890440Z"}]}
{"channel":"book","type":"update","data":[{"symbol":"BTC/USD","bids":[],"asks":[{"price":64743.4,"qty":0.00000000},{"price":64747.6,"qty":0.00005100}],"checksum":1795123908,"timestamp":"2026-07-15T04:00:29.890584Z"}]}
{"channel":"book","type":"update","data":[{"symbol":"BTC/USD","bids":[{"price":64735.0,"qty":0.03656174}],"asks":[],"checksum":2715606069,"timestamp":"2026-07-15T04:00:29.890715Z"}]}
{"channel":"book","type":"update","data":[{"symbol":"BTC/USD","bids":[],"asks":[{"price":64746.8,"qty":0.00000000},{"price":64749.6,"qty":0.06992789}],"checksum":3820232670,"timestamp":"2026-07-15T04:00:29.891166Z"}]}
{"channel":"book","type":"update","data":[{"symbol":"BTC/USD","bids":[],"asks":[{"price":64743.3,"qty":0.00000000},{"price":64749.7,"qty":0.13109402}],"checksum":3095454950,"timestamp":"2026-07-15T04:00:29.891904Z"}]}
{"channel":"book","type":"update","data":[{"symbol":"BTC/USD","bids":[],"asks":[{"price":64746.7,"qty":0.03088960}],"checksum":79547492,"timestamp":"2026-07-15T04:00:29.892761Z"}]}
{"channel":"book","type":"update","data":[{"symbol":"BTC/USD","bids":[{"price":64738.2,"qty":0.05178465}],"asks":[],"checksum":570148962,"timestamp":"2026-07-15T04:00:29.893762Z"}]}
{"channel":"book","type":"update","data":[{"symbol":"BTC/USD","bids":[],"asks":[{"price":64743.5,"qty":0.05793529}],"checksum":2133715984,"timestamp":"2026-07-15T04:00:29.894053Z"}]}
{"channel":"book","type":"update","data":[{"symbol":"BTC/USD","bids":[],"asks":[{"price":64744.2,"qty":0.77227111}],"checksum":1152036274,"timestamp":"2026-07-15T04:00:29.894706Z"}]}
{"channel":"book","type":"update","data":[{"symbol":"BTC/USD","bids":[],"asks":[{"price":64746.4,"qty":0.77224431}],"checksum":496854057,"timestamp":"2026-07-15T04:00:29.894921Z"}]}
{"channel":"book","type":"update","data":[{"symbol":"BTC/USD","bids":[{"price":64736.5,"qty":0.77236066}],"asks":[],"checksum":3696029459,"timestamp":"2026-07-15T04:00:29.895964Z"}]}
{"channel":"book","type":"update","data":[{"symbol":"BTC/USD","bids":[{"price":64738.2,"qty":0.03129337}],"asks":[],"checksum":889850914,"timestamp":"2026-07-15T04:00:29.898122Z"}]}
{"channel":"book","type":"update","data":[{"symbol":"BTC/USD","bids":[],"asks":[{"price":64743.5,"qty":0.28105131}],"checksum":3060827628,"timestamp":"2026-07-15T04:00:29.899628Z"}]}
{"channel":"book","type":"update","data":[{"symbol":"BTC/USD","bids":[{"price":64735.1,"qty":0.25927403}],"asks":[],"checksum":833852388,"timestamp":"2026-07-15T04:00:29.899860Z"}]}
{"channel":"book","type":"update","data":[{"symbol":"BTC/USD","bids":[{"price":64736.6,"qty":0.00038312}],"asks":[],"checksum":3332098265,"timestamp":"2026-07-15T04:00:29.900473Z"}]}
{"channel":"book","type":"update","data":[{"symbol":"BTC/USD","bids":[{"price":64738.2,"qty":0.05178465}],"asks":[],"checksum":4014829163,"timestamp":"2026-07-15T04:00:29.900790Z"}]}
{"channel":"book","type":"update","data":[{"symbol":"BTC/USD","bids":[{"price":64736.6,"qty":0.00000000},{"price":64732.7,"qty":0.01400000}],"asks":[],"checksum":3639963861,"timestamp":"2026-07-15T04:00:29.906207Z"}]}
{"channel":"book","type":"update","data":[{"symbol":"BTC/USD","bids":[{"price":64736.6,"qty":0.00154472}],"asks":[],"checksum":528229991,"timestamp":"2026-07-15T04:00:29.907954Z"}]}
{"channel":"book","type":"update","data":[{"symbol":"BTC/USD","bids":[],"asks":[{"price":64746.3,"qty":0.23975070}],"checksum":2052440499,"timestamp":"2026-07-15T04:00:29.924339Z"}]}
{"channel":"book","type":"update","data":[{"symbol":"BTC/USD","bids":[],"asks":[{"price":64738.3,"qty":0.88067917}],"checksum":3293650337,"timestamp":"2026-07-15T04:00:29.925606Z"}]}
{"channel":"book","type":"update","data":[{"symbol":"BTC/USD","bids":[{"price":64733.3,"qty":0.00000000},{"price":64732.7,"qty":0.01400000}],"asks":[],"checksum":2692356062,"timestamp":"2026-07-15T04:00:29.936265Z"}]}
{"channel":"book","type":"update","data":[{"symbol":"BTC/USD","bids":[],"asks":[{"price":64744.2,"qty":0.00000000},{"price":64746.7,"qty":0.03088960}],"checksum":3771700033,"timestamp":"2026-07-15T04:00:29.936524Z"}]}
{"channel":"book","type":"update","data":[{"symbol":"BTC/USD","bids":[{"price":64735.1,"qty":0.01686779}],"asks":[],"checksum":3573632982,"timestamp":"2026-07-15T04:00:29.937594Z"}]}
{"channel":"book","type":"update","data":[{"symbol":"BTC/USD","bids":[],"asks":[{"price":64743.5,"qty":0.05793529}],"checksum":107459724,"timestamp":"2026-07-15T04:00:29.937856Z"}]}
{"channel":"book","type":"update","data":[{"symbol":"BTC/USD","bids":[{"price":64736.5,"qty":0.00000000},{"price":64731.7,"qty":0.05820000}],"asks":[],"checksum":3716249031,"timestamp":"2026-07-15T04:00:29.938224Z"}]}
{"channel":"book","type":"update","data":[{"symbol":"BTC/USD","bids":[{"price":64735.1,"qty":0.03793156}],"asks":[],"checksum":3576466184,"timestamp":"2026-07-15T04:00:29.939811Z"}]}
{"channel":"book","type":"update","data":[{"symbol":"BTC/USD","bids":[{"price":64738.2,"qty":0.03129337}],"asks":[],"checksum":3137324609,"timestamp":"2026-07-15T04:00:29.941405Z"}]}
{"channel":"book","type":"update","data":[{"symbol":"BTC/USD","bids":[],"asks":[{"price":64746.4,"qty":0.00000000},{"price":64747.6,"qty":0.00005100}],"checksum":1843854882,"timestamp":"2026-07-15T04:00:30.005447Z"}]}
{"channel":"book","type":"update","data":[{"symbol":"BTC/USD","bids":[],"asks":[{"price":64743.5,"qty":0.83021388}],"checksum":1582000910,"timestamp":"2026-07-15T04:00:30.007062Z"}]}
{"channel":"book","type":"update","data":[{"symbol":"BTC/USD","bids":[],"asks":[{"price":64746.3,"qty":0.00000000},{"price":64749.4,"qty":0.30043184}],"checksum":1524161618,"timestamp":"2026-07-15T04:00:30.007099Z"}]}
{"channel":"book","type":"update","data":[{"symbol":"BTC/USD","bids":[{"price":64735.8,"qty":0.77237004}],"asks":[],"checksum":3544117153,"timestamp":"2026-07-15T04:00:30.007506Z"}]}
{"channel":"book","type":"update","data":[{"symbol":"BTC/USD","bids":[],"asks":[{"price":64743.4,"qty":0.28846045}],"checksum":1690173965,"timestamp":"2026-07-15T04:00:30.008553Z"}]}
{"channel":"book","type":"update","data":[{"symbol":"BTC/USD","bids":[],"asks":[{"price":64743.5,"qty":0.77227859}],"checksum":2649857355,"timestamp":"2026-07-15T04:00:30.008568Z"}]}
{"channel":"book","type":"update","data":[{"symbol":"BTC/USD","bids":[{"price":64738.2,"qty":0.05178465}],"asks":[],"checksum":2459875122,"timestamp":"2026-07-15T04:00:30.011118Z"}]}
{"channel":"book","type":"update","data":[{"symbol":"BTC/USD","bids":[{"price":64735.1,"qty":0.02106377}],"asks":[],"checksum":960810616,"timestamp":"2026-07-15T04:00:30.012322Z"}]}
{"channel":"book","type":"update","data":[{"symbol":"BTC/USD","bids":[{"price":64736.6,"qty":0.02069291}],"asks":[],"checksum":2419900090,"timestamp":"2026-07-15T04:00:30.012567Z"}]}
{"channel":"book","type":"update","data":[{"symbol":"BTC/USD","bids":[{"price":64738.2,"qty":0.03129337}],"asks":[],"checksum":3119126536,"timestamp":"2026-07-15T04:00:30.013461Z"}]}
{"channel":"book","type":"update","data":[{"symbol":"BTC/USD","bids":[{"price":64738.2,"qty":0.05178465}],"asks":[],"checksum":2419900090,"timestamp":"2026-07-15T04:00:30.016493Z"}]}
{"channel":"book","type":"update","data":[{"symbol":"BTC/USD","bids":[{"price":64738.2,"qty":0.03129337}],"asks":[],"checksum":3119126536,"timestamp":"2026-07-15T04:00:30.039323Z"}]}
{"channel":"book","type":"update","data":[{"symbol":"BTC/USD","bids":[{"price":64735.8,"qty":0.00000000},{"price":64731.7,"qty":0.05820000}],"asks":[],"checksum":3073546653,"timestamp":"2026-07-15T04:00:30.099457Z"}]}
{"channel":"book","type":"update","data":[{"symbol":"BTC/USD","bids":[],"asks":[{"price":64743.5,"qty":0.00000000},{"price":64749.4,"qty":0.30043184}],"checksum":3879318634,"timestamp":"2026-07-15T04:00:30.099710Z"}]}
{"channel":"book","type":"update","data":[{"symbol":"BTC/USD","bids":[{"price":64736.6,"qty":0.00154472}],"asks":[],"checksum":487367729,"timestamp":"2026-07-15T04:00:30.101487Z"}]}
{"channel":"book","type":"update","data":[{"symbol":"BTC/USD","bids":[],"asks":[{"price":64743.4,"qty":0.00000000},{"price":64749.5,"qty":0.77220753}],"checksum":2609576036,"timestamp":"2026-07-15T04:00:30.101519Z"}]}
{"channel":"book","type":"update","data":[{"symbol":"BTC/USD","bids":[],"asks":[{"price":64743.5,"qty":0.05793529}],"checksum":3943449743,"timestamp":"2026-07-15T04:00:30.103593Z"}]}
{"channel":"book","type":"update","data":[{"symbol":"BTC/USD","bids":[{"price":64734.7,"qty":0.01919686}],"asks":[],"checksum":729738510,"timestamp":"2026-07-15T04:00:30.143089Z"}]}
{"channel":"book","type":"update","data":[{"symbol":"BTC/USD","bids":[],"asks":[{"price":64747.7,"qty":0.01914202}],"checksum":2486617948,"timestamp":"2026-07-15T04:00:30.143563Z"}]}
{"channel":"book","type":"update","data":[{"symbol":"BTC/USD","bids":[],"asks":[{"price":64742.5,"qty":0.77229047}],"checksum":1794506115,"timestamp":"2026-07-15T04:00:30.252916Z"}]}
{"channel":"book","type":"update","data":[{"symbol":"BTC/USD","bids":[],"asks":[{"price":64745.3,"qty":0.77225700}],"checksum":1285242178,"timestamp":"2026-07-15T04:00:30.253147Z"}]}
{"channel":"book","type":"update","data":[{"symbol":"BTC/USD","bids":[{"price":64735.8,"qty":0.77236902}],"asks":[],"checksum":325558382,"timestamp":"2026-07-15T04:00:30.253484Z"}]}
{"channel":"book","type":"update","data":[{"symbol":"BTC/USD","bids":[{"price":64733.1,"qty":0.77240137}],"asks":[],"checksum":608512852,"timestamp":"2026-07-15T04:00:30.253783Z"}]}
{"channel":"book","type":"update","data":[{"symbol":"BTC/USD","bids":[],"asks":[{"price":64742.5,"qty":0.00000000},{"price":64747.6,"qty":0.00005100}],"checksum":1546249087,"timestamp":"2026-07-15T04:00:30.256887Z"}]}
{"channel":"book","type":"update","data":[{"symbol":"BTC/USD","bids":[],"asks":[{"price":64743.5,"qty":0.00000000},{"price":64749.4,"qty":0.30043184}],"checksum":1729205483,"timestamp":"2026-07-15T04:00:30.256978Z"}]}
{"channel":"book","type":"update","data":[{"symbol":"BTC/USD","bids":[],"asks":[{"price":64738.3,"qty":0.88778109}],"checksum":2616062408,"timestamp":"2026-07-15T04:00:30.257106Z"}]}
{"channel":"book","type":"update","data":[{"symbol":"BTC/USD","bids":[{"price":64735.1,"qty":0.00000000},{"price":64732.7,"qty":0.01400000}],"asks":[],"checksum":4190176010,"timestamp":"2026-07-15T04:00:30.257408Z"}]}
{"channel":"book","type":"update","data":[{"symbol":"BTC/USD","bids":[{"price":64738.2,"qty":0.05178465}],"asks":[],"checksum":2834712019,"timestamp":"2026-07-15T04:00:30.257706Z"}]}
{"channel":"book","type":"update","data":[{"symbol":"BTC/USD","bids":[{"price":64738.2,"qty":0.10998465}],"asks":[],"checksum":446793653,"timestamp":"2026-07-15T04:00:30.259721Z"}]}
{"channel":"book","type":"update","data":[{"symbol":"BTC/USD","bids":[],"asks":[{"price":64738.3,"qty":0.88067917}],"checksum":3090811554,"timestamp":"2026-07-15T04:00:30.262398Z"}]}
{"channel":"book","type":"update","data":[{"symbol":"BTC/USD","bids":[],"asks":[{"price":64745.2,"qty":0.26335371}],"checksum":85043087,"timestamp":"2026-07-15T04:00:30.263758Z"}]}
{"channel":"book","type":"update","data":[{"symbol":"BTC/USD","bids":[{"price":64732.8,"qty":0.00000000},{"price":64731.7,"qty":0.05820000},{"price":64733.2,"qty":0.03086388}],"asks":[],"checksum":1531816,"timestamp":"2026-07-15T04:00:30.265597Z"}]}
{"channel":"book","type":"update","data":[{"symbol":"BTC/USD","bids":[{"price":64735.9,"qty":0.37434039}],"asks":[],"checksum":3788041751,"timestamp":"2026-07-15T04:00:30.265886Z"}]}
{"channel":"book","type":"update","data":[{"symbol":"BTC/USD","bids":[{"price":64738.1,"qty":0.00308937}],"asks":[],"checksum":2133304642,"timestamp":"2026-07-15T04:00:30.270876Z"}]}
{"channel":"book","type":"update","data":[{"symbol":"BTC/USD","bids":[{"price":64735.8,"qty":0.00000000},{"price":64733.1,"qty":0.77240137}],"asks":[],"checksum":3867958869,"timestamp":"2026-07-15T04:00:30.274650Z"}]}
{"channel":"book","type":"update","data":[{"symbol":"BTC/USD","bids":[{"price":64733.1,"qty":0.00000000},{"price":64732.7,"qty":0.01400000}],"asks":[],"checksum":2710100674,"timestamp":"2026-07-15T04:00:30.274709Z"}]}
{"channel":"book","type":"update","data":[{"symbol":"BTC/USD","bids":[{"price":64735.9,"qty":0.00000000},{"price":64731.7,"qty":0.05820000}],"asks":[],"checksum":3307350395,"timestamp":"2026-07-15T04:00:30.276705Z"}]}
{"channel":"book","type":"update","data":[{"symbol":"BTC/USD","bids":[{"price":64738.2,"qty":0.08949337}],"asks":[],"checksum":4067604346,"timestamp":"2026-07-15T04:00:30.278177Z"}]}
{"channel":"book","type":"update","data":[{"symbol":"BTC/USD","bids":[{"price":64735.1,"qty":0.02677881}],"asks":[],"checksum":2284624573,"timestamp":"2026-07-15T04:00:30.278221Z"}]}
{"channel":"book","type":"update","data":[{"symbol":"BTC/USD","bids":[{"price":64733.2,"qty":0.00000000},{"price":64731.7,"qty":0.05820000},{"price":64732.8,"qty":0.03086388}],"asks":[],"checksum":1580398198,"timestamp":"2026-07-15T04:00:30.278704Z"}]}
{"channel":"book","type":"update","data":[{"symbol":"BTC/USD","bids":[{"price":64738.1,"qty":0.00000000},{"price":64731.7,"qty":0.05820000}],"asks":[],"checksum":2131872823,"timestamp":"2026-07-15T04:00:30.291271Z"}]}
{"channel":"heartbeat"}
{"channel":"book","type":"update","data":[{"symbol":"BTC/USD","bids":[{"price":64732.5,"qty":0.59689488}],"asks":[],"checksum":944578408,"timestamp":"2026-07-15T04:00:30.299612Z"}]}
{"channel":"book","type":"update","data":[{"symbol":"BTC/USD","bids":[{"price":64738.2,"qty":0.03129337}],"asks":[],"checksum":1287225200,"timestamp":"2026-07-15T04:00:30.321624Z"}]}
{"channel":"book","type":"update","data":[{"symbol":"BTC/USD","bids":[],"asks":[{"price":64743.8,"qty":0.59689488}],"checksum":307431272,"timestamp":"2026-07-15T04:00:30.397102Z"}]}
{"channel":"book","type":"update","data":[{"symbol":"BTC/USD","bids":[],"asks":[{"price":64745.2,"qty":0.00000000},{"price":64747.6,"qty":0.00005100}],"checksum":3730296342,"timestamp":"2026-07-15T04:00:30.398514Z"}]}
{"channel":"book","type":"update","data":[{"symbol":"BTC/USD","bids":[],"asks":[{"price":64743.7,"qty":0.45321841}],"checksum":1512892861,"timestamp":"2026-07-15T04:00:30.400794Z"}]}
{"channel":"book","type":"update","data":[{"symbol":"BTC/USD","bids":[{"price":64736.6,"qty":0.00000000},{"price":64731.7,"qty":0.05820000}],"asks":[],"checksum":519969054,"timestamp":"2026-07-15T04:00:31.042373Z"}]}
{"channel":"book","type":"update","data":[{"symbol":"BTC/USD","bids":[{"price":64735.1,"qty":0.02832356}],"asks":[],"checksum":1749223800,"timestamp":"2026-07-15T04:00:31.044114Z"}]}
{"channel":"book","type":"update","data":[{"symbol":"BTC/USD","bids":[],"asks":[{"price":64742.1,"qty":0.77229507}],"checksum":2463011705,"timestamp":"2026-07-15T04:00:31.053294Z"}]}
{"channel":"book","type":"update","data":[{"symbol":"BTC/USD","bids":[{"price":64735.7,"qty":0.77237086}],"asks":[],"checksum":1267594451,"timestamp":"2026-07-15T04:00:31.053558Z"}]}
{"channel":"book","type":"update","data":[{"symbol":"BTC/USD","bids":[{"price":64734.2,"qty":0.77238825}],"asks":[],"checksum":4076763561,"timestamp":"2026-07-15T04:00:31.053798Z"}]}
{"channel":"book","type":"update","data":[{"symbol":"BTC/USD","bids":[{"price":64734.7,"qty":0.00005100}],"asks":[],"checksum":73441361,"timestamp":"2026-07-15T04:00:31.055637Z"}]}
{"channel":"book","type":"update","data":[{"symbol":"BTC/USD","bids":[{"price":64735.1,"qty":0.00154475}],"asks":[],"checksum":1748751897,"timestamp":"2026-07-15T04:00:31.055695Z"}]}
{"channel":"book","type":"update","data":[{"symbol":"BTC/USD","bids":[{"price":64737.9,"qty":0.01904913}],"asks":[],"checksum":300760555,"timestamp":"2026-07-15T04:00:31.055762Z"}]}
{"channel":"book","type":"update","data":[{"symbol":"BTC/USD","bids":[],"asks":[{"price":64738.3,"qty":0.88778109}],"checksum":2678278923,"timestamp":"2026-07-15T04:00:31.057097Z"}]}
{"channel":"book","type":"update","data":[{"symbol":"BTC/USD","bids":[{"price":64735.1,"qty":0.00000000},{"price":64732.5,"qty":0.59689488}],"asks":[],"checksum":4131794688,"timestamp":"2026-07-15T04:00:31.057565Z"}]}
{"channel":"book","type":"update","data":[{"symbol":"BTC/USD","bids":[{"price":64735.8,"qty":0.24078176}],"asks":[],"checksum":1427214165,"timestamp":"2026-07-15T04:00:31.057576Z"}]}
{"channel":"book","type":"update","data":[{"symbol":"BTC/USD","bids":[{"price":64738.2,"qty":0.05178465}],"asks":[],"checksum":2589213841,"timestamp":"2026-07-15T04:00:31.057736Z"}]}
{"channel":"book","type":"update","data":[{"symbol":"BTC/USD","bids":[{"price":64735.8,"qty":0.24116489}],"asks":[],"checksum":3666234779,"timestamp":"2026-07-15T04:00:31.057881Z"}]}
{"channel":"book","type":"update","data":[{"symbol":"BTC/USD","bids":[{"price":64735.8,"qty":0.24078176}],"asks":[],"checksum":2589213841,"timestamp":"2026-07-15T04:00:31.059121Z"}]}
{"channel":"book","type":"update","data":[{"symbol":"BTC/USD","bids":[],"asks":[{"price":64738.3,"qty":0.88067917}],"checksum":2102193466,"timestamp":"2026-07-15T04:00:31.059915Z"}]}
{"channel":"book","type":"update","data":[{"symbol":"BTC/USD","bids":[{"price":64735.8,"qty":0.24232650}],"asks":[],"checksum":3060472913,"timestamp":"2026-07-15T04:00:31.060644Z"}]}
{"channel":"trade","type":"update","data":[{"symbol":"BTC/USD","side":"buy","price":64738.3,"qty":0.00019300,"ord_type":"limit","trade_id":103746804,"timestamp":"2026-07-15T04:00:31.160380Z"}]}
{"channel":"book","type":"update","data":[{"symbol":"BTC/USD","bids":[],"asks":[{"price":64738.3,"qty":0.88048617}],"checksum":565903335,"timestamp":"2026-07-15T04:00:31.160380Z"}]}
{"channel":"book","type":"update","data":[{"symbol":"BTC/USD","bids":[{"price":64734.2,"qty":0.00000000},{"price":64732.5,"qty":0.59689488}],"asks":[],"checksum":2563338909,"timestamp":"2026-07-15T04:00:31.293864Z"}]}
{"channel":"book","type":"update","data":[{"symbol":"BTC/USD","bids":[],"asks":[{"price":64745.3,"qty":0.00000000},{"price":64746.7,"qty":0.03088960}],"checksum":2214326268,"timestamp":"2026-07-15T04:00:31.294006Z"}]}
{"channel":"heartbeat"}
{"channel":"book","type":"update","data":[{"symbol":"BTC/USD","bids":[],"asks":[{"price":64743.7,"qty":0.00000000},{"price":64747.6,"qty":0.00005100}],"checksum":1642978652,"timestamp":"2026-07-15T04:00:31.295401Z"}]}
{"channel":"book","type":"update","data":[{"symbol":"BTC/USD","bids":[],"asks":[{"price":64744.1,"qty":0.77227121}],"checksum":977245043,"timestamp":"2026-07-15T04:00:31.295555Z"}]}
{"channel":"book","type":"update","data":[{"symbol":"BTC/USD","bids":[],"asks":[{"price":64742.0,"qty":0.23053008}],"checksum":1235447025,"timestamp":"2026-07-15T04:00:31.297086Z"}]}
{"channel":"book","type":"update","data":[{"symbol":"BTC/USD","bids":[{"price":64738.2,"qty":0.03129337}],"asks":[],"checksum":2263263029,"timestamp":"2026-07-15T04:00:31.298862Z"}]}
{"channel":"book","type":"update","data":[{"symbol":"BTC/USD","bids":[{"price":64735.7,"qty":0.00000000},{"price":64731.7,"qty":0.05820000}],"asks":[],"checksum":2823211562,"timestamp":"2026-07-15T04:00:31.388455Z"}]}
{"channel":"book","type":"update","data":[{"symbol":"BTC/USD","bids":[],"asks":[{"price":64742.1,"qty":0.00000000},{"price":64746.7,"qty":0.03088960}],"checksum":2167914883,"timestamp":"2026-07-15T04:00:31.388717Z"}]}
{"channel":"book","type":"update","data":[{"symbol":"BTC/USD","bids":[{"price":64735.8,"qty":0.00154474}],"asks":[],"checksum":1785090296,"timestamp":"2026-07-15T04:00:31.389646Z"}]}
{"channel":"book","type":"update","data":[{"symbol":"BTC/USD","bids":[],"asks":[{"price":64742.0,"qty":0.00000000},{"price":64747.6,"qty":0.00005100}],"checksum":4189514678,"timestamp":"2026-07-15T04:00:31.389995Z"}]}
{"channel":"book","type":"update","data":[{"symbol":"BTC/USD","bids":[],"asks":[{"price":64741.3,"qty":0.77230485}],"checksum":1848531266,"timestamp":"2026-07-15T04:00:31.390946Z"}]}
{"channel":"book","type":"update","data":[{"symbol":"BTC/USD","bids":[{"price":64737.9,"qty":0.00005100}],"asks":[],"checksum":2811376188,"timestamp":"2026-07-15T04:00:31.390986Z"}]}
{"channel":"book","type":"update","data":[{"symbol":"BTC/USD","bids":[{"price":64734.8,"qty":0.77546977}],"asks":[],"checksum":2601508010,"timestamp":"2026-07-15T04:00:31.391275Z"}]}
{"channel":"book","type":"update","data":[{"symbol":"BTC/USD","bids":[{"price":64733.0,"qty":0.77240304}],"asks":[],"checksum":1253237019,"timestamp":"2026-07-15T04:00:31.391588Z"}]}
{"channel":"book","type":"update","data":[{"symbol":"BTC/USD","bids":[],"asks":[{"price":64741.2,"qty":0.23053300}],"checksum":1288969371,"timestamp":"2026-07-15T04:00:31.392330Z"}]}
{"channel":"book","type":"update","data":[{"symbol":"BTC/USD","bids":[],"asks":[{"price":64738.3,"qty":0.88758809}],"checksum":1109668046,"timestamp":"2026-07-15T04:00:31.392726Z"}]}
{"channel":"book","type":"update","data":[{"symbol":"BTC/USD","bids":[{"price":64732.8,"qty":0.00000000},{"price":64731.7,"qty":0.05820000},{"price":64733.1,"qty":0.03086388}],"asks":[],"checksum":4001994244,"timestamp":"2026-07-15T04:00:31.392991Z"}]}
{"channel":"book","type":"update","data":[{"symbol":"BTC/USD","bids":[],"asks":[{"price":64738.3,"qty":0.88048617}],"checksum":3766073937,"timestamp":"2026-07-15T04:00:31.395954Z"}]}
{"channel":"book","type":"update","data":[{"symbol":"BTC/USD","bids":[],"asks":[{"price":64743.7,"qty":0.45322265}],"checksum":3072714851,"timestamp":"2026-07-15T04:00:31.401911Z"}]}
{"channel":"book","type":"update","data":[{"symbol":"BTC/USD","bids":[],"asks":[{"price":64738.3,"qty":0.88758809}],"checksum":3117794358,"timestamp":"2026-07-15T04:00:31.405284Z"}]}
{"channel":"book","type":"update","data":[{"symbol":"BTC/USD","bids":[{"price":64735.0,"qty":0.05560027}],"asks":[],"checksum":1676770559,"timestamp":"2026-07-15T04:00:31.475458Z"}]}
{"channel":"book","type":"update","data":[{"symbol":"BTC/USD","bids":[],"asks":[{"price":64738.3,"qty":0.88048617}],"checksum":1828802730,"timestamp":"2026-07-15T04:00:31.527581Z"}]}
{"channel":"heartbeat"}
{"channel":"book","type":"update","data":[{"symbol":"BTC/USD","bids":[],"asks":[{"price":64741.8,"qty":0.00154460}],"checksum":3151322386,"timestamp":"2026-07-15T04:00:32.454858Z"}]}
{"channel":"book","type":"update","data":[{"symbol":"BTC/USD","bids":[{"price":64732.5,"qty":0.00000000},{"price":64731.7,"qty":0.05820000}],"asks":[],"checksum":886468896,"timestamp":"2026-07-15T04:00:32.495972Z"}]}
{"channel":"book","type":"update","data":[{"symbol":"BTC/USD","bids":[{"price":64734.8,"qty":0.77392500}],"asks":[],"checksum":3144644206,"timestamp":"2026-07-15T04:00:32.502052Z"}]}
{"channel":"book","type":"update","data":[{"symbol":"BTC/USD","bids":[],"asks":[{"price":64743.8,"qty":0.00000000},{"price":64744.3,"qty":0.00005100}],"checksum":2192534618,"timestamp":"2026-07-15T04:00:32.505542Z"}]}
{"channel":"book","type":"update","data":[{"symbol":"BTC/USD","bids":[],"asks":[{"price":64743.7,"qty":0.00000000},{"price":64745.4,"qty":0.11000000}],"checksum":1509823778,"timestamp":"2026-07-15T04:00:32.506713Z"}]}
{"channel":"book","type":"update","data":[{"symbol":"BTC/USD","bids":[],"asks":[{"price":64744.0,"qty":0.26337318}],"checksum":1084115419,"timestamp":"2026-07-15T04:00:32.508063Z"}]}
{"channel":"book","type":"update","data":[{"symbol":"BTC/USD","bids":[],"asks":[{"price":64744.1,"qty":0.00000000},{"price":64745.4,"qty":0.11000000}],"checksum":3621903406,"timestamp":"2026-07-15T04:00:32.522083Z"}]}
{"channel":"book","type":"update","data":[{"symbol":"BTC/USD","bids":[],"asks":[{"price":64743.0,"qty":0.77228465}],"checksum":1670048777,"timestamp":"2026-07-15T04:00:32.523791Z"}]}
{"channel":"book","type":"update","data":[{"symbol":"BTC/USD","bids":[{"price":64734.8,"qty":0.00154400}],"asks":[],"checksum":1459170361,"timestamp":"2026-07-15T04:00:32.526000Z"}]}
{"channel":"book","type":"update","data":[{"symbol":"BTC/USD","bids":[],"asks":[{"price":64741.3,"qty":0.00000000},{"price":64745.4,"qty":0.11000000}],"checksum":241263308,"timestamp":"2026-07-15T04:00:32.526035Z"}]}
{"channel":"book","type":"update","data":[{"symbol":"BTC/USD","bids":[],"asks":[{"price":64738.3,"qty":0.88758809}],"checksum":2880470513,"timestamp":"2026-07-15T04:00:32.527609Z"}]}
{"channel":"book","type":"update","data":[{"symbol":"BTC/USD","bids":[{"price":64735.0,"qty":0.03656174}],"asks":[],"checksum":1150157943,"timestamp":"2026-07-15T04:00:32.528012Z"}]}
{"channel":"book","type":"update","data":[{"symbol":"BTC/USD","bids":[],"asks":[{"price":64740.5,"qty":0.77231477}],"checksum":3290777765,"timestamp":"2026-07-15T04:00:32.528151Z"}]}
{"channel":"book","type":"update","data":[{"symbol":"BTC/USD","bids":[],"asks":[{"price":64744.0,"qty":0.00000000},{"price":64745.4,"qty":0.11000000}],"checksum":2060549512,"timestamp":"2026-07-15T04:00:32.528445Z"}]}
{"channel":"book","type":"update","data":[{"symbol":"BTC/USD","bids":[],"asks":[{"price":64738.3,"qty":0.88048617}],"checksum":3741344437,"timestamp":"2026-07-15T04:00:32.531025Z"}]}
{"channel":"book","type":"update","data":[{"symbol":"BTC/USD","bids":[{"price":64733.1,"qty":0.23877402}],"asks":[],"checksum":4261003971,"timestamp":"2026-07-15T04:00:32.533713Z"}]}
{"channel":"book","type":"update","data":[{"symbol":"BTC/USD","bids":[],"asks":[{"price":64738.3,"qty":0.88758809}],"checksum":2771673037,"timestamp":"2026-07-15T04:00:32.533879Z"}]}
{"channel":"book","type":"update","data":[{"symbol":"BTC/USD","bids":[],"asks":[{"price":64742.9,"qty":0.28846226}],"checksum":3768714616,"timestamp":"2026-07-15T04:00:32.535703Z"}]}
{"channel":"book","type":"update","data":[{"symbol":"BTC/USD","bids":[{"price":64733.1,"qty":0.20791014},{"price":64733.2,"qty":0.03086388}],"asks":[],"checksum":1779629628,"timestamp":"2026-07-15T04:00:32.536767Z"}]}
{"channel":"book","type":"update","data":[{"symbol":"BTC/USD","bids":[],"asks":[{"price":64741.2,"qty":0.00000000},{"price":64745.4,"qty":0.11000000}],"checksum":4163186034,"timestamp":"2026-07-15T04:00:32.539608Z"}]}
{"channel":"book","type":"update","data":[{"symbol":"BTC/USD","bids":[],"asks":[{"price":64740.4,"qty":0.23101225}],"checksum":732421744,"timestamp":"2026-07-15T04:00:32.543036Z"}]}
{"channel":"book","type":"update","data":[{"symbol":"BTC/USD","bids":[],"asks":[{"price":64740.5,"qty":0.00000000},{"price":64745.4,"qty":0.11000000}],"checksum":4116292271,"timestamp":"2026-07-15T04:00:32.546892Z"}]}
{"channel":"book","type":"update","data":[{"symbol":"BTC/USD","bids":[],"asks":[{"price":64740.4,"qty":0.00000000},{"price":64746.7,"qty":0.03088960}],"checksum":1920805053,"timestamp":"2026-07-15T04:00:32.548406Z"}]}
{"channel":"book","type":"update","data":[{"symbol":"BTC/USD","bids":[],"asks":[{"price":64738.3,"qty":0.88048617}],"checksum":3618387840,"timestamp":"2026-07-15T04:00:32.551781Z"}]}
{"channel":"book","type":"update","data":[{"symbol":"BTC/USD","bids":[{"price":64734.7,"qty":0.01872393}],"asks":[],"checksum":1232827148,"timestamp":"2026-07-15T04:00:32.865838Z"}]}
{"channel":"book","type":"update","data":[{"symbol":"BTC/USD","bids":[],"asks":[{"price":64740.5,"qty":0.77231491}],"checksum":1898518536,"timestamp":"2026-07-15T04:00:32.906433Z"}]}
{"channel":"book","type":"update","data":[{"symbol":"BTC/USD","bids":[],"asks":[{"price":64738.3,"qty":0.88758809}],"checksum":1519222528,"timestamp":"2026-07-15T04:00:32.910415Z"}]}
{"channel":"heartbeat"}
{"channel":"book","type":"update","data":[{"symbol":"BTC/USD","bids":[],"asks":[{"price":64740.5,"qty":0.00000000},{"price":64746.7,"qty":0.03088960}],"checksum":1497819574,"timestamp":"2026-07-15T04:00:33.407477Z"}]}
{"channel":"book","type":"update","data":[{"symbol":"BTC/USD","bids":[],"asks":[{"price":64743.0,"qty":0.00000000},{"price":64746.8,"qty":0.23052834}],"checksum":88481876,"timestamp":"2026-07-15T04:00:33.407640Z"}]}
{"channel":"book","type":"update","data":[{"symbol":"BTC/USD","bids":[],"asks":[{"price":64742.9,"qty":0.00000000},{"price":64746.9,"qty":0.77223826}],"checksum":2397385758,"timestamp":"2026-07-15T04:00:33.409314Z"}]}
{"channel":"book","type":"update","data":[{"symbol":"BTC/USD","bids":[],"asks":[{"price":64739.5,"qty":0.77232659}],"checksum":4137105481,"timestamp":"2026-07-15T04:00:33.409869Z"}]}
{"channel":"book","type":"update","data":[{"symbol":"BTC/USD","bids":[],"asks":[{"price":64741.7,"qty":0.77229991}],"checksum":1478637179,"timestamp":"2026-07-15T04:00:33.410208Z"}]}
{"channel":"book","type":"update","data":[{"symbol":"BTC/USD","bids":[],"asks":[{"price":64738.3,"qty":0.88048617}],"checksum":1210035393,"timestamp":"2026-07-15T04:00:33.411197Z"}]}
{"channel":"book","type":"update","data":[{"symbol":"BTC/USD","bids":[],"asks":[{"price":64743.5,"qty":0.05793529}],"checksum":3744392180,"timestamp":"2026-07-15T04:00:33.413190Z"}]}
{"channel":"book","type":"update","data":[{"symbol":"BTC/USD","bids":[],"asks":[{"price":64738.3,"qty":0.88758809}],"checksum":3474159950,"timestamp":"2026-07-15T04:00:33.414471Z"}]}
{"channel":"book","type":"update","data":[{"symbol":"BTC/USD","bids":[],"asks":[{"price":64741.1,"qty":0.59694588}],"checksum":1098843680,"timestamp":"2026-07-15T04:00:33.520397Z"}]}
{"channel":"book","type":"update","data":[{"symbol":"BTC/USD","bids":[{"price":64733.0,"qty":0.00000000},{"price":64731.7,"qty":0.05820000}],"asks":[],"checksum":262508896,"timestamp":"2026-07-15T04:00:33.594368Z"}]}
{"channel":"book","type":"update","data":[{"symbol":"BTC/USD","bids":[{"price":64733.1,"qty":0.00000000},{"price":64731.5,"qty":0.00005100}],"asks":[],"checksum":1291768707,"timestamp":"2026-07-15T04:00:33.595568Z"}]}
{"channel":"book","type":"update","data":[{"symbol":"BTC/USD","bids":[{"price":64733.7,"qty":0.77239495}],"asks":[],"checksum":1298459481,"timestamp":"2026-07-15T04:00:33.595715Z"}]}
{"channel":"book","type":"update","data":[{"symbol":"BTC/USD","bids":[{"price":64733.2,"qty":0.00000000},{"price":64731.5,"qty":0.00005100},{"price":64732.8,"qty":0.03086388}],"asks":[],"checksum":882757900,"timestamp":"2026-07-15T04:00:33.596977Z"}]}
{"channel":"book","type":"update","data":[{"symbol":"BTC/USD","bids":[],"asks":[{"price":64739.4,"qty":0.63972042}],"checksum":2633647013,"timestamp":"2026-07-15T04:00:33.597099Z"}]}
{"channel":"book","type":"update","data":[{"symbol":"BTC/USD","bids":[],"asks":[{"price":64739.5,"qty":0.00000000},{"price":64745.4,"qty":0.11000000}],"checksum":3939965233,"timestamp":"2026-07-15T04:00:34.126614Z"}]}
{"channel":"book","type":"update","data":[{"symbol":"BTC/USD","bids":[],"asks":[{"price":64739.4,"qty":0.00000000},{"price":64746.7,"qty":0.03088960}],"checksum":307540982,"timestamp":"2026-07-15T04:00:34.128003Z"}]}
{"channel":"book","type":"update","data":[{"symbol":"BTC/USD","bids":[],"asks":[{"price":64740.4,"qty":0.77231620}],"checksum":606922234,"timestamp":"2026-07-15T04:00:34.128305Z"}]}
{"channel":"book","type":"update","data":[{"symbol":"BTC/USD","bids":[],"asks":[{"price":64741.0,"qty":0.40918093}],"checksum":642238435,"timestamp":"2026-07-15T04:00:34.129516Z"}]}
{"channel":"book","type":"update","data":[{"symbol":"BTC/USD","bids":[{"price":64735.8,"qty":0.00000000},{"price":64731.5,"qty":0.00005100}],"asks":[],"checksum":3866479238,"timestamp":"2026-07-15T04:00:34.130448Z"}]}
{"channel":"book","type":"update","data":[{"symbol":"BTC/USD","bids":[],"asks":[{"price":64738.3,"qty":0.88048617}],"checksum":3453070734,"timestamp":"2026-07-15T04:00:34.131410Z"}]}
{"channel":"book","type":"update","data":[{"symbol":"BTC/USD","bids":[{"price":64735.1,"qty":0.00038313}],"asks":[],"checksum":1409159330,"timestamp":"2026-07-15T04:00:34.131803Z"}]}
{"channel":"book","type":"update","data":[{"symbol":"BTC/USD","bids":[{"price":64735.1,"qty":0.00000000},{"price":64731.5,"qty":0.00005100}],"asks":[],"checksum":3453070734,"timestamp":"2026-07-15T04:00:34.133401Z"}]}
{"channel":"book","type":"update","data":[{"symbol":"BTC/USD","bids":[],"asks":[{"price":64738.3,"qty":0.88758809}],"checksum":3866479238,"timestamp":"2026-07-15T04:00:34.134723Z"}]}
{"channel":"book","type":"update","data":[{"symbol":"BTC/USD","bids":[{"price":64735.1,"qty":0.00154475}],"asks":[],"checksum":3159807935,"timestamp":"2026-07-15T04:00:34.135101Z"}]}
{"channel":"heartbeat"}
{"channel":"book","type":"update","data":[{"symbol":"BTC/USD","bids":[{"price":64731.7,"qty":0.00000000},{"price":64731.5,"qty":0.00005100}],"asks":[],"checksum":1325798504,"timestamp":"2026-07-15T04:00:34.475106Z"}]}
{"channel":"book","type":"update","data":[{"symbol":"BTC/USD","bids":[],"asks":[{"price":64741.0,"qty":0.00000000},{"price":64745.4,"qty":0.11000000}],"checksum":2216577132,"timestamp":"2026-07-15T04:00:34.476421Z"}]}
{"channel":"book","type":"update","data":[{"symbol":"BTC/USD","bids":[],"asks":[{"price":64740.3,"qty":0.63971732}],"checksum":1126664248,"timestamp":"2026-07-15T04:00:34.477585Z"}]}
{"channel":"book","type":"update","data":[{"symbol":"BTC/USD","bids":[],"asks":[{"price":64740.4,"qty":0.00000000},{"price":64745.4,"qty":0.11000000}],"checksum":811225966,"timestamp":"2026-07-15T04:00:34.482732Z"}]}
{"channel":"book","type":"update","data":[{"symbol":"BTC/USD","bids":[{"price":64733.7,"qty":0.00000000},{"price":64731.1,"qty":0.77242548}],"asks":[],"checksum":1561565796,"timestamp":"2026-07-15T04:00:34.483578Z"}]}
{"channel":"book","type":"update","data":[{"symbol":"BTC/USD","bids":[],"asks":[{"price":64740.3,"qty":0.00000000},{"price":64746.7,"qty":0.03088960}],"checksum":1608191244,"timestamp":"2026-07-15T04:00:34.483949Z"}]}
{"channel":"book","type":"update","data":[{"symbol":"BTC/USD","bids":[],"asks":[{"price":64739.2,"qty":0.77233064}],"checksum":3478997053,"timestamp":"2026-07-15T04:00:34.485063Z"}]}
{"channel":"book","type":"update","data":[{"symbol":"BTC/USD","bids":[{"price":64732.7,"qty":0.78640657}],"asks":[],"checksum":365449910,"timestamp":"2026-07-15T04:00:34.485391Z"}]}
{"channel":"book","type":"update","data":[{"symbol":"BTC/USD","bids":[],"asks":[{"price":64741.0,"qty":0.40918093}],"checksum":309235443,"timestamp":"2026-07-15T04:00:34.485421Z"}]}
{"channel":"book","type":"update","data":[{"symbol":"BTC/USD","bids":[],"asks":[{"price":64741.0,"qty":0.00000000},{"price":64745.4,"qty":0.11000000}],"checksum":365449910,"timestamp":"2026-07-15T04:00:34.632029Z"}]}
{"channel":"book","type":"update","data":[{"symbol":"BTC/USD","bids":[],"asks":[{"price":64739.1,"qty":0.63972163}],"checksum":372117715,"timestamp":"2026-07-15T04:00:34.633315Z"}]}
{"channel":"book","type":"update","data":[{"symbol":"BTC/USD","bids":[{"price":64731.1,"qty":0.00000000},{"price":64730.4,"qty":0.51616441}],"asks":[],"checksum":914588743,"timestamp":"2026-07-15T04:00:34.847914Z"}]}
{"channel":"book","type":"update","data":[{"symbol":"BTC/USD","bids":[],"asks":[{"price":64739.2,"qty":0.00000000},{"price":64745.4,"qty":0.11000000}],"checksum":3144535054,"timestamp":"2026-07-15T04:00:34.924140Z"}]}
{"channel":"book","type":"update","data":[{"symbol":"BTC/USD","bids":[],"asks":[{"price":64739.1,"qty":0.00000000},{"price":64746.7,"qty":0.03088960}],"checksum":1680556125,"timestamp":"2026-07-15T04:00:34.925362Z"}]}
{"channel":"book","type":"update","data":[{"symbol":"BTC/USD","bids":[],"asks":[{"price":64738.5,"qty":0.77233841}],"checksum":3122823084,"timestamp":"2026-07-15T04:00:34.925558Z"}]}
{"channel":"book","type":"update","data":[{"symbol":"BTC/USD","bids":[],"asks":[{"price":64741.0,"qty":0.40918093}],"checksum":3179586537,"timestamp":"2026-07-15T04:00:34.926617Z"}]}
{"channel":"book","type":"update","data":[{"symbol":"BTC/USD","bids":[{"price":64738.1,"qty":0.00308937}],"asks":[],"checksum":1038297925,"timestamp":"2026-07-15T04:00:34.941491Z"}]}
{"channel":"trade","type":"update","data":[{"symbol":"BTC/USD","side":"buy","price":64738.3,"qty":0.00035358,"ord_type":"market","trade_id":103746805,"timestamp":"2026-07-15T04:00:34.946374Z"}]}
{"channel":"book","type":"update","data":[{"symbol":"BTC/USD","bids":[],"asks":[{"price":64738.3,"qty":0.88723451}],"checksum":2103252502,"timestamp":"2026-07-15T04:00:34.946374Z"}]}
{"channel":"book","type":"update","data":[{"symbol":"BTC/USD","bids":[{"price":64738.1,"qty":0.00000000},{"price":64730.4,"qty":0.51616441}],"asks":[],"checksum":1954193873,"timestamp":"2026-07-15T04:00:34.958260Z"}]}
{"channel":"book","type":"update","data":[{"symbol":"BTC/USD","bids":[{"price":64732.7,"qty":0.01400000}],"asks":[],"checksum":4109192962,"timestamp":"2026-07-15T04:00:35.199476Z"}]}
{"channel":"book","type":"update","data":[{"symbol":"BTC/USD","bids":[{"price":64731.9,"qty":0.77241665}],"asks":[],"checksum":4205654709,"timestamp":"2026-07-15T04:00:35.201256Z"}]}
{"channel":"heartbeat"}
{"channel":"heartbeat"}
{"channel":"book","type":"update","data":[{"symbol":"BTC/USD","bids":[{"price":64731.9,"qty":0.00000000},{"price":64730.4,"qty":0.51616441}],"asks":[],"checksum":4109192962,"timestamp":"2026-07-15T04:00:36.784465Z"}]}
{"channel":"book","type":"update","data":[{"symbol":"BTC/USD","bids":[{"price":64732.5,"qty":0.77240886}],"asks":[],"checksum":2734110657,"timestamp":"2026-07-15T04:00:36.786066Z"}]}
{"channel":"book","type":"update","data":[{"symbol":"BTC/USD","bids":[{"price":64731.7,"qty":0.05820000}],"asks":[],"checksum":518784086,"timestamp":"2026-07-15T04:00:36.823099Z"}]}
{"channel":"book","type":"update","data":[{"symbol":"BTC/USD","bids":[],"asks":[{"price":64738.5,"qty":0.00000000},{"price":64745.4,"qty":0.11000000}],"checksum":3293865036,"timestamp":"2026-07-15T04:00:37.026988Z"}]}
{"channel":"book","type":"update","data":[{"symbol":"BTC/USD","bids":[],"asks":[{"price":64739.2,"qty":0.77233018}],"checksum":81665349,"timestamp":"2026-07-15T04:00:37.028516Z"}]}
{"channel":"book","type":"update","data":[{"symbol":"BTC/USD","bids":[],"asks":[{"price":64741.0,"qty":0.00000000},{"price":64745.4,"qty":0.11000000}],"checksum":112541532,"timestamp":"2026-07-15T04:00:37.029788Z"}]}
{"channel":"book","type":"update","data":[{"symbol":"BTC/USD","bids":[],"asks":[{"price":64738.3,"qty":0.88013259}],"checksum":4190937555,"timestamp":"2026-07-15T04:00:37.030659Z"}]}
{"channel":"book","type":"update","data":[{"symbol":"BTC/USD","bids":[],"asks":[{"price":64739.1,"qty":0.63972149}],"checksum":3866833945,"timestamp":"2026-07-15T04:00:37.031094Z"}]}
{"channel":"book","type":"update","data":[{"symbol":"BTC/USD","bids":[],"asks":[{"price":64738.3,"qty":0.88723451}],"checksum":419605142,"timestamp":"2026-07-15T04:00:37.033694Z"}]}
{"channel":"book","type":"update","data":[{"symbol":"BTC/USD","bids":[{"price":64732.5,"qty":0.00000000},{"price":64731.5,"qty":0.00005100}],"asks":[],"checksum":2520312835,"timestamp":"2026-07-15T04:00:37.097600Z"}]}
{"channel":"book","type":"update","data":[{"symbol":"BTC/USD","bids":[],"asks":[{"price":64739.2,"qty":0.00000000},{"price":64745.4,"qty":0.11000000}],"checksum":3637280551,"timestamp":"2026-07-15T04:00:37.097832Z"}]}
{"channel":"book","type":"update","data":[{"symbol":"BTC/USD","bids":[],"asks":[{"price":64739.1,"qty":0.00000000},{"price":64746.7,"qty":0.03088960}],"checksum":1882132946,"timestamp":"2026-07-15T04:00:37.099291Z"}]}
{"channel":"book","type":"update","data":[{"symbol":"BTC/USD","bids":[{"price":64733.6,"qty":0.77239590}],"asks":[],"checksum":1136876700,"timestamp":"2026-07-15T04:00:37.099842Z"}]}
{"channel":"book","type":"update","data":[{"symbol":"BTC/USD","bids":[],"asks":[{"price":64741.0,"qty":0.40918093}],"checksum":4052447202,"timestamp":"2026-07-15T04:00:37.101819Z"}]}
{"channel":"book","type":"update","data":[{"symbol":"BTC/USD","bids":[],"asks":[{"price":64738.3,"qty":0.88013259}],"checksum":250802541,"timestamp":"2026-07-15T04:00:37.102534Z"}]}
{"channel":"book","type":"update","data":[{"symbol":"BTC/USD","bids":[{"price":64738.2,"qty":0.05178465}],"asks":[],"checksum":3887338076,"timestamp":"2026-07-15T04:00:37.103454Z"}]}
{"channel":"book","type":"update","data":[{"symbol":"BTC/USD","bids":[{"price":64738.2,"qty":0.03129337}],"asks":[],"checksum":250802541,"timestamp":"2026-07-15T04:00:37.105674Z"}]}
{"channel":"heartbeat"}
{"channel":"book","type":"update","data":[{"symbol":"BTC/USD","bids":[{"price":64733.6,"qty":0.00000000},{"price":64731.5,"qty":0.00005100}],"asks":[],"checksum":3983579399,"timestamp":"2026-07-15T04:00:37.373243Z"}]}
{"channel":"book","type":"update","data":[{"symbol":"BTC/USD","bids":[],"asks":[{"price":64739.3,"qty":0.77232940}],"checksum":774784454,"timestamp":"2026-07-15T04:00:37.374852Z"}]}
{"channel":"book","type":"update","data":[{"symbol":"BTC/USD","bids":[{"price":64732.7,"qty":0.78640643}],"asks":[],"checksum":3688004678,"timestamp":"2026-07-15T04:00:37.375171Z"}]}
{"channel":"book","type":"update","data":[{"symbol":"BTC/USD","bids":[],"asks":[{"price":64741.0,"qty":0.00000000},{"price":64745.4,"qty":0.11000000}],"checksum":281681986,"timestamp":"2026-07-15T04:00:37.377460Z"}]}
{"channel":"book","type":"update","data":[{"symbol":"BTC/USD","bids":[],"asks":[{"price":64738.3,"qty":0.88723451}],"checksum":2889612922,"timestamp":"2026-07-15T04:00:37.378243Z"}]}
{"channel":"book","type":"update","data":[{"symbol":"BTC/USD","bids":[],"asks":[{"price":64739.2,"qty":0.63972126}],"checksum":1727705602,"timestamp":"2026-07-15T04:00:37.378990Z"}]}
{"channel":"book","type":"update","data":[{"symbol":"BTC/USD","bids":[{"price":64731.7,"qty":0.00000000},{"price":64731.3,"qty":0.77242266}],"asks":[],"checksum":1737967278,"timestamp":"2026-07-15T04:00:37.694870Z"}]}
{"channel":"book","type":"update","data":[{"symbol":"BTC/USD","bids":[{"price":64731.7,"qty":0.05820000}],"asks":[],"checksum":1727705602,"timestamp":"2026-07-15T04:00:37.724780Z"}]}
{"channel":"book","type":"update","data":[{"symbol":"BTC/USD","bids":[{"price":64731.8,"qty":0.00154484}],"asks":[],"checksum":2735933301,"timestamp":"2026-07-15T04:00:37.754969Z"}]}
{"channel":"book","type":"update","data":[{"symbol":"BTC/USD","bids":[],"asks":[{"price":64741.8,"qty":0.00000000},{"price":64745.4,"qty":0.11000000}],"checksum":2623882402,"timestamp":"2026-07-15T04:00:37.755072Z"}]}
{"channel":"book","type":"update","data":[{"symbol":"BTC/USD","bids":[],"asks":[{"price":64739.5,"qty":0.00154466}],"checksum":1495717213,"timestamp":"2026-07-15T04:00:37.755487Z"}]}
{"channel":"book","type":"update","data":[{"symbol":"BTC/USD","bids":[{"price":64735.0,"qty":0.00000000},{"price":64731.5,"qty":0.00005100}],"asks":[],"checksum":1318714218,"timestamp":"2026-07-15T04:00:37.952652Z"}]}
{"channel":"book","type":"update","data":[{"symbol":"BTC/USD","bids":[{"price":64734.7,"qty":0.00005100}],"asks":[],"checksum":1505684933,"timestamp":"2026-07-15T04:00:37.954178Z"}]}
{"channel":"book","type":"update","data":[{"symbol":"BTC/USD","bids":[{"price":64732.8,"qty":0.04911494}],"asks":[],"checksum":3289972297,"timestamp":"2026-07-15T04:00:37.954583Z"}]}
{"channel":"book","type":"update","data":[{"symbol":"BTC/USD","bids":[{"price":64732.8,"qty":0.01825106},{"price":64732.9,"qty":0.03086388}],"asks":[],"checksum":484232290,"timestamp":"2026-07-15T04:00:37.956265Z"}]}
{"channel":"heartbeat"}
{"channel":"book","type":"update","data":[{"symbol":"BTC/USD","bids":[{"price":64732.7,"qty":0.01400000}],"asks":[],"checksum":1106941472,"timestamp":"2026-07-15T04:00:38.523828Z"}]}
{"channel":"book","type":"update","data":[{"symbol":"BTC/USD","bids":[],"asks":[{"price":64739.3,"qty":0.00000000},{"price":64745.4,"qty":0.11000000}],"checksum":3132822124,"timestamp":"2026-07-15T04:00:38.524114Z"}]}
{"channel":"book","type":"update","data":[{"symbol":"BTC/USD","bids":[],"asks":[{"price":64739.5,"qty":0.00000000},{"price":64746.7,"qty":0.03088960}],"checksum":2866659365,"timestamp":"2026-07-15T04:00:38.524945Z"}]}
{"channel":"book","type":"update","data":[{"symbol":"BTC/USD","bids":[{"price":64732.8,"qty":0.00000000},{"price":64731.5,"qty":0.00005100}],"asks":[],"checksum":625657068,"timestamp":"2026-07-15T04:00:38.525280Z"}]}
{"channel":"book","type":"update","data":[{"symbol":"BTC/USD","bids":[{"price":64731.8,"qty":0.01993201}],"asks":[],"checksum":4284310050,"timestamp":"2026-07-15T04:00:38.525674Z"}]}
{"channel":"book","type":"update","data":[{"symbol":"BTC/USD","bids":[],"asks":[{"price":64740.6,"qty":0.77231360}],"checksum":3223830359,"timestamp":"2026-07-15T04:00:38.525726Z"}]}
{"channel":"book","type":"update","data":[{"symbol":"BTC/USD","bids":[],"asks":[{"price":64739.2,"qty":0.00000000},{"price":64746.7,"qty":0.03088960}],"checksum":2874711445,"timestamp":"2026-07-15T04:00:38.525806Z"}]}
{"channel":"book","type":"update","data":[{"symbol":"BTC/USD","bids":[{"price":64733.3,"qty":0.77239924}],"asks":[],"checksum":1756645693,"timestamp":"2026-07-15T04:00:38.526211Z"}]}
{"channel":"book","type":"update","data":[{"symbol":"BTC/USD","bids":[],"asks":[{"price":64741.7,"qty":0.00000000},{"price":64746.8,"qty":0.23052834}],"checksum":3609820502,"timestamp":"2026-07-15T04:00:38.526262Z"}]}
{"channel":"book","type":"update","data":[{"symbol":"BTC/USD","bids":[],"asks":[{"price":64741.0,"qty":0.40871987}],"checksum":2382689574,"timestamp":"2026-07-15T04:00:38.527524Z"}]}
{"channel":"book","type":"update","data":[{"symbol":"BTC/USD","bids":[{"price":64732.9,"qty":0.00000000},{"price":64731.5,"qty":0.00005100},{"price":64732.8,"qty":0.03086388}],"asks":[],"checksum":3883793987,"timestamp":"2026-07-15T04:00:38.527556Z"}]}
{"channel":"book","type":"update","data":[{"symbol":"BTC/USD","bids":[],"asks":[{"price":64741.0,"qty":0.00000000},{"price":64746.8,"qty":0.23052834}],"checksum":3192944179,"timestamp":"2026-07-15T04:00:38.527764Z"}]}
{"channel":"book","type":"update","data":[{"symbol":"BTC/USD","bids":[{"price":64731.8,"qty":0.00154484}],"asks":[],"checksum":4218498660,"timestamp":"2026-07-15T04:00:38.527826Z"}]}
{"channel":"book","type":"update","data":[{"symbol":"BTC/USD","bids":[{"price":64735.1,"qty":0.00000000},{"price":64731.5,"qty":0.00005100}],"asks":[],"checksum":607363490,"timestamp":"2026-07-15T04:00:38.528017Z"}]}
{"channel":"book","type":"update","data":[{"symbol":"BTC/USD","bids":[{"price":64734.7,"qty":0.01843735}],"asks":[],"checksum":243261210,"timestamp":"2026-07-15T04:00:38.528082Z"}]}
{"channel":"book","type":"update","data":[{"symbol":"BTC/USD","bids":[],"asks":[{"price":64742.9,"qty":0.77228603}],"checksum":719873400,"timestamp":"2026-07-15T04:00:38.528427Z"}]}
{"channel":"book","type":"update","data":[{"symbol":"BTC/USD","bids":[{"price":64734.8,"qty":0.00192714}],"asks":[],"checksum":100869633,"timestamp":"2026-07-15T04:00:38.528647Z"}]}
